Workbook
Name shtlist: #REF!

Sheet เย็น  
B1: ยอดจริง ออนไลน์ วันที่ 2/12/2567 - เย็น
K2: ยอดรวมผลิต
K3: จำนวน
B4: รหัสสินค้า | C4: สินค้า | D4: ปณ | E4: ชอปปี้ | F4: ลาซาด้า | G4: ติ๊กตอก | H4: ติ๊กตอก2 | I4: ติ๊กตอก3 | J4: ชอยส์ | K4: (กล่อง)
B6: ชิฟฟอนรวมรส
B7: 1111002 | C7: ชิฟฟอนรวมรส 8 ชิ้น | K7: =SUM(D7:J7) -> 0
B8: 1111086 | C8: ชิฟฟอน 8 ชิ้น มะพร้าวล้วน | K8: =SUM(D8:J8) -> 0
B9: 1111056 | C9: ชิฟฟอน 8 ชิ้น รวมรสยอดฮิต | K9: =SUM(D9:J9) -> 0
B10: 1004055 | C10: ชิฟฟอนรวมรส 4 ชิ้น | K10: =SUM(D10:J10) -> 0
B11: 1111057 | C11: ชิฟฟอนแยกชิ้น กาแฟ | K11: =SUM(D11:J11) -> 0
B12: 1111058 | C12: ชิฟฟอนแยกชิ้น ชาเขียว | K12: =SUM(D12:J12) -> 0
B13: 1111059 | C13: ชิฟฟอนแยกชิ้น ใบเตย | K13: =SUM(D13:J13) -> 0
B14: 1111060 | C14: ชิฟฟอนแยกชิ้น กล้วยหอม | K14: =SUM(D14:J14) -> 0
B15: 1111061 | C15: ชิฟฟอนแยกชิ้น ชาไทย | K15: =SUM(D15:J15) -> 0
B16: 1111062 | C16: ชิฟฟอนแยกชิ้น โกโก้ | K16: =SUM(D16:J16) -> 0
B17: 1111063 | C17: ชิฟฟอนแยกชิ้น ส้ม | K17: =SUM(D17:J17) -> 0
B18: 1111064 | C18: ชิฟฟอนแยกชิ้น เผือก | K18: =SUM(D18:J18) -> 0
... B35: 1111083 | C35: ชิฟฟอนไส้แยมแยกชิ้น เมล่อน | K35: =SUM(D35:J35) -> 0
B36: ชิฟฟอนไส้แยม 6 ชิ้น
B37: 1111009 | C37: ชิฟฟอนไส้แยมรวมรส 6 ชิ้น | K37: =SUM(D37:J37) -> 0
B38: ชิฟฟอนไส้แยม 3 ชิ้น
B39: 1111008 | C39: ชิฟฟอนไส้แยมรวมรส 3 ชิ้น | K39: =SUM(D39:J39) -> 0
B44: เบาหวิว ล 110 กรัม
B45: 1112009 | C45: มะพร้าว | K45: =SUM(D45:J45) -> 0
B46: 1112011 | C46: ฝอยทอง | K46: =SUM(D46:J46) -> 0
B47: 1112003 | C47: กาแฟ | K47: =SUM(D47:J47) -> 0
B48: 1112005 | C48: เนยนม | K48: =SUM(D48:J48) -> 0
B49: 1112007 | C49: ใบเตย | K49: =SUM(D49:J49) -> 0
B50: 1112019 | C50: ทุเรียน | K50: =SUM(D50:J50) -> 0
B51: 1112017 | C51: ตาลหอม | K51: =SUM(D51:J51) -> 0
B52: 1112015 | C52: กล้วยหอมมะพร้าวเผา | K52: =SUM(D52:J52) -> 0
B53: 1112013 | C53: เผือกมะพร้าวอ่อน | K53: =SUM(D53:J53) -> 0
B54: 1124043 | C54: เบาหวิว คละรส | K54: =SUM(D54:J54) -> 0
B55: อื่นๆ
B56: 1113170 | C56: ขนมเปี๊ยะถั่วฝอยทองไข่เค็ม 450 กรัม | K56: =SUM(D56:J56) -> 0
B57: 1113171 | C57: ขนมเปี๊ยะฟักถั่วไข่เค็ม 450 กรัม | K57: =SUM(D57:J57) -> 0
B58: 1113172 | C58: ขนมเปี๊ยะเผือกฝอยทองไข่เค็ม 450 กรัม | K58: =SUM(D58:J58) -> 0
B59: 1100003 | C59: เมอแรงค์ กระปุก | K59: =SUM(D59:J59) -> 0
B60: 1100001 | C60: พายสับปรด 1 ชิ้น | K60: =SUM(D60:J60) -> 0
B61: 1100002 | C61: พายสับปรด 1 กล่อง | K61: =SUM(D61:J61) -> 0
...

Sheet เช้า
B1: ยอดจริง ออนไลน์ วันที่ 2/12/2567 - เช้า
K2: ยอดรวมผลิต
K3: จำนวน
B4: รหัสสินค้า | C4: สินค้า | D4: ปณ | E4: ชอปปี้ | F4: ลาซาด้า | G4: ติ๊กตอก | H4: ติ๊กตอก2 | I4: ติ๊กตอก3 | J4: ติ๊กตอก4 | K4: (กล่อง)
B6: ชิฟฟอนรวมรส
B7: 1111002 | C7: ชิฟฟอนรวมรส 8 ชิ้น | E7: 44 | F7: 49 | G7: 1 | K7: =SUM(D7:J7) -> 94
B8: 1111086 | C8: ชิฟฟอน 8 ชิ้น มะพร้าวล้วน | K8: =SUM(D8:J8) -> 0
B9: 1111056 | C9: ชิฟฟอน 8 ชิ้น รวมรสยอดฮิต | E9: 5 | F9: 8 | I9: 4 | K9: =SUM(D9:J9) -> 17
B10: 1004055 | C10: ชิฟฟอนรวมรส 4 ชิ้น | D10: 14 | F10: 1 | G10: 81 | H10: 90 | I10: 72 | J10: 39 | K10: =SUM(D10:J10) -> 297
B11: 1111057 | C11: ชิฟฟอนแยกชิ้น กาแฟ | G11: 6 | H11: 3 | I11: 1 | J11: 1 | K11: =SUM(D11:J11) -> 11
B12: 1111058 | C12: ชิฟฟอนแยกชิ้น ชาเขียว | G12: 6 | H12: 3 | I12: 1 | J12: 1 | K12: =SUM(D12:J12) -> 11
B13: 1111059 | C13: ชิฟฟอนแยกชิ้น ใบเตย | G13: 6 | H13: 3 | I13: 6 | K13: =SUM(D13:J13) -> 15
B14: 1111060 | C14: ชิฟฟอนแยกชิ้น กล้วยหอม | G14: 6 | H14: 3 | I14: 1 | K14: =SUM(D14:J14) -> 10
B15: 1111061 | C15: ชิฟฟอนแยกชิ้น ชาไทย | G15: 6 | H15: 3 | K15: =SUM(D15:J15) -> 9
B16: 1111062 | C16: ชิฟฟอนแยกชิ้น โกโก้ | G16: 6 | H16: 3 | K16: =SUM(D16:J16) -> 9
B17: 1111063 | C17: ชิฟฟอนแยกชิ้น ส้ม | G17: 6 | H17: 3 | I17: 1 | K17: =SUM(D17:J17) -> 10
B18: 1111064 | C18: ชิฟฟอนแยกชิ้น เผือก | G18: 6 | H18: 3 | K18: =SUM(D18:J18) -> 9
B19: 1111065 | C19: ชิฟฟอนแยกชิ้น สับปะรด | G19: 6 | H19: 3 | I19: 1 | K19: =SUM(D19:J19) -> 10
B20: 1111066 | C20: ชิฟฟอนแยกชิ้น สตอเบอรี่ | G20: 5 | H20: 3 | I20: 1 | K20: =SUM(D20:J20) -> 9
B21: 1111067 | C21: ชิฟฟอนแยกชิ้น มะพร้าว | G21: 5 | H21: 3 | I21: 6 | K21: =SUM(D21:J21) -> 14
B22: 1111068 | C22: ชิฟฟอนแยกชิ้น เนย | G22: 5 | H22: 3 | I22: 1 | K22: =SUM(D22:J22) -> 9
B23: 1111069 | C23: ชิฟฟอนแยกชิ้น บลูเบอรี่ | G23: 5 | H23: 2 | I23: 1 | K23: =SUM(D23:J23) -> 8
B24: 1111070 | C24: ชิฟฟอนแยกชิ้น ทุเรียน | G24: 5 | H24: 2 | K24: =SUM(D24:J24) -> 7
B25: 1111071 | C25: ชิฟฟอนแยกชิ้น ตาล | G25: 5 | H25: 2 | K25: =SUM(D25:J25) -> 7
B26: 1111074 | C26: ชิฟฟอนไส้แยมแยกชิ้น มะพร้าว | E26: 5 | F26: 3 | H26: 1 | J26: 11 | K26: =SUM(D26:J26) -> 20
B27: 1111075 | C27: ชิฟฟอนไส้แยมแยกชิ้น สตอเบอรี่ | E27: 5 | F27: 3 | J27: 11 | K27: =SUM(D27:J27) -> 19
B28: 1111076 | C28: ชิฟฟอนไส้แยมแยกชิ้น ส้ม | E28: 5 | F28: 3 | J28: 10 | K28: =SUM(D28:J28) -> 18
B29: 1111077 | C29: ชิฟฟอนไส้แยมแยกชิ้น บลูเบอรี่ | E29: 5 | F29: 3 | J29: 10 | K29: =SUM(D29:J29) -> 18
B30: 1111078 | C30: ชิฟฟอนไส้แยมแยกชิ้น นมชมพู | E30: 5 | F30: 3 | J30: 10 | K30: =SUM(D30:J30) -> 18
B31: 1111079 | C31: ชิฟฟอนไส้แยมแยกชิ้น ชอคโกแลต | E31: 5 | F31: 3 | J31: 10 | K31: =SUM(D31:J31) -> 18
B32: 1111080 | C32: ชิฟฟอนไส้แยมแยกชิ้น ฝอยทอง | E32: 5 | F32: 3 | J32: 10 | K32: =SUM(D32:J32) -> 18
B33: 1111081 | C33: ชิฟฟอนไส้แยมแยกชิ้น วนิลา | E33: 5 | F33: 3 | J33: 10 | K33: =SUM(D33:J33) -> 18
B34: 1111082 | C34: ชิฟฟอนไส้แยมแยกชิ้น ใบเตย | E34: 5 | F34: 3 | J34: 10 | K34: =SUM(D34:J34) -> 18
B35: 1111083 | C35: ชิฟฟอนไส้แยมแยกชิ้น เมล่อน | E35: 5 | F35: 3 | J35: 10 | K35: =SUM(D35:J35) -> 18
B36: ชิฟฟอนไส้แยม 6 ชิ้น
B37: 1111009 | C37: ชิฟฟอนไส้แยมรวมรส 6 ชิ้น | E37: 3 | F37: 4 | G37: 1 | H37: 1 | J37: 2 | K37: =SUM(D37:J37) -> 11
B38: ชิฟฟอนไส้แยม 3 ชิ้น
B39: 1111008 | C39: ชิฟฟอนไส้แยมรวมรส 3 ชิ้น | D39: 5 | E39: 6 | G39: 102 | H39: 114 | I39: 90 | J39: 9 | K39: =SUM(D39:J39) -> 326
B40: 1111017 | C40: ชิฟฟอนไส้แยมบลูเบอรี่ 3 ชิ้น | K40: =SUM(D40:J40) -> 0
B41: 1111019 | C41: ชิฟฟอนไส้แยมฝอยทอง 3 ชิ้น | D41: 5 | K41: =SUM(D41:J41) -> 5
...

Sheet บ่าย
B1: ยอดจริง ออนไลน์ วันที่ 29/11/2567 - เย็น
K2: ยอดรวมผลิต
K3: จำนวน
B4: รหัสสินค้า | C4: สินค้า | D4: ปณ | E4: ชอปปี้ | F4: ลาซาด้า | G4: ติ๊กตอก | H4: ติ๊กตอก2 | I4: ติ๊กตอก3 | J4: ชอยส์ | K4: (กล่อง)
B6: ชิฟฟอนรวมรส
B7: 1111002 | C7: ชิฟฟอนรวมรส 8 ชิ้น | K7: =SUM(D7:J7) -> 0
B8: 1111043 | C8: ชิฟฟอน 8 ชิ้น มะลิ | K8: =SUM(D8:J8) -> 0
B9: 1111056 | C9: ชิฟฟอน 8 ชิ้น รวมรสยอดฮิต | K9: =SUM(D9:J9) -> 0
B10: 1004055 | C10: ชิฟฟอนรวมรส 4 ชิ้น | K10: =SUM(D10:J10) -> 0
B11: 1111057 | C11: ชิฟฟอนแยกชิ้น กาแฟ | K11: =SUM(D11:J11) -> 0
B12: 1111058 | C12: ชิฟฟอนแยกชิ้น ชาเขียว | K12: =SUM(D12:J12) -> 0
B13: 1111059 | C13: ชิฟฟอนแยกชิ้น ใบเตย | K13: =SUM(D13:J13) -> 0
B14: 1111060 | C14: ชิฟฟอนแยกชิ้น กล้วยหอม | K14: =SUM(D14:J14) -> 0
B15: 1111061 | C15: ชิฟฟอนแยกชิ้น ชาไทย | K15: =SUM(D15:J15) -> 0
B16: 1111062 | C16: ชิฟฟอนแยกชิ้น โกโก้ | K16: =SUM(D16:J16) -> 0
B17: 1111063 | C17: ชิฟฟอนแยกชิ้น ส้ม | K17: =SUM(D17:J17) -> 0
B18: 1111064 | C18: ชิฟฟอนแยกชิ้น เผือก | K18: =SUM(D18:J18) -> 0
... B37: 1111010 | C37: ชิฟฟอนไส้แยมแยกชิ้น คละรส | K37: =SUM(D37:J37) -> 0
C38: รวม | K38: =SUM(D38:I38) -> 0
B39: ชิฟฟอนไส้แยม 6 ชิ้น
B40: 1111009 | C40: ชิฟฟอนไส้แยมรวมรส 6 ชิ้น | K40: =SUM(D40:J40) -> 0
B41: ชิฟฟอนไส้แยม 3 ชิ้น
B42: 1111008 | C42: ชิฟฟอนไส้แยมรวมรส 3 ชิ้น | K42: =SUM(D42:J42) -> 0
B43: 1111011 | C43: ชิฟฟอนไส้แยมนมชมพู 3 ชิ้น | K43: =SUM(D43:J43) -> 0
B44: 1111013 | C44: ชิฟฟอนไส้แยมชอคโกแลต 3 ชิ้น | K44: =SUM(D44:J44) -> 0
B45: 1111017 | C45: ชิฟฟอนไส้แยมบลูเบอรี่ 3 ชิ้น | K45: =SUM(D45:J45) -> 0
B46: 1111022 | C46: ชิฟฟอนไส้แยมสตอเบอรี่ 3 ชิ้น | K46: =SUM(D46:J46) -> 0
B47: เบาหวิว ล 110 กรัม
B48: 1112009 | C48: มะพร้าว | K48: =SUM(D48:J48) -> 0
B49: 1112011 | C49: ฝอยทอง | K49: =SUM(D49:J49) -> 0
B50: 1112003 | C50: กาแฟ | K50: =SUM(D50:J50) -> 0
B51: 1112005 | C51: เนยนม | K51: =SUM(D51:J51) -> 0
B52: 1112007 | C52: ใบเตย | K52: =SUM(D52:J52) -> 0
B53: 1112019 | C53: ทุเรียน | K53: =SUM(D53:J53) -> 0
B54: 1112017 | C54: ตาลหอม | K54: =SUM(D54:J54) -> 0
B55: 1112015 | C55: กล้วยหอมมะพร้าวเผา | K55: =SUM(D55:J55) -> 0
B56: 1112013 | C56: เผือกมะพร้าวอ่อน | K56: =SUM(D56:J56) -> 0
B57: 1124043 | C57: เบาหวิว คละรส | K57: =SUM(D57:J57) -> 0
C58: รวม
B59: อื่นๆ
...

Sheet รวม
B1: ยอดจริง ออนไลน์ วันที่ 2/12/2567 - รวม
K2: ยอดรวมผลิต | L2: ยอดสตอค | M2: ยอดฟอแคส | N2: รับเกิน | O2: ยังไม่ได้รับเข้า | Q2: รวม
K3: จำนวน | P3: บิลค้าง
B4: รหัสสินค้า | C4: สินค้า | D4: ปณ | E4: ชอปปี้ | F4: ลาซาด้า | G4: ติ๊กตอก | H4: ติ๊กตอก2 | I4: ติ๊กตอก3 | J4: ติ๊กตอก4 | K4: (กล่อง)
B6: ชิฟฟอนรวมรส
B7: 1111002 | C7: ชิฟฟอนรวมรส 8 ชิ้น | D7: ='เย็น '!D7+เช้า!D7 -> 0 | E7: ='เย็น '!E7+เช้า!E7 -> 44 | F7: ='เย็น '!F7+เช้า!F7 -> 49 | G7: ='เย็น '!G7+เช้า!G7 -> 1 | H7: ='เย็น '!H7+เช้า!H7 -> 0 | I7: ='เย็น '!I7+เช้า!I7 -> 0 | J7: ='เย็น '!J7+เช้า!J7 -> 0 | K7: =SUM(D7:J7) -> 94 | M7: 114 | Q7: =(L7+M7+N7+O7)-K7-P7 -> 20
B8: 1111086 | C8: ชิฟฟอน 8 ชิ้น มะพร้าวล้วน | D8: ='เย็น '!D8+เช้า!D8 -> 0 | E8: ='เย็น '!E8+เช้า!E8 -> 0 | F8: ='เย็น '!F8+เช้า!F8 -> 0 | G8: ='เย็น '!G8+เช้า!G8 -> 0 | H8: ='เย็น '!H8+เช้า!H8 -> 0 | I8: ='เย็น '!I8+เช้า!I8 -> 0 | J8: ='เย็น '!J8+เช้า!J8 -> 0 | K8: =SUM(D8:J8) -> 0 | Q8: =(L8+M8+N8+O8)-K8-P8 -> 0
B9: 1111056 | C9: ชิฟฟอน 8 ชิ้น รวมรสยอดฮิต | D9: ='เย็น '!D9+เช้า!D9 -> 0 | E9: ='เย็น '!E9+เช้า!E9 -> 5 | F9: ='เย็น '!F9+เช้า!F9 -> 8 | G9: ='เย็น '!G9+เช้า!G9 -> 0 | H9: ='เย็น '!H9+เช้า!H9 -> 0 | I9: ='เย็น '!I9+เช้า!I9 -> 4 | J9: ='เย็น '!J9+เช้า!J9 -> 0 | K9: =SUM(D9:J9) -> 17 | M9: 36 | Q9: =(L9+M9+N9+O9)-K9-P9 -> 19
B10: 1004055 | C10: ชิฟฟอนรวมรส 4 ชิ้น | D10: ='เย็น '!D10+เช้า!D10 -> 14 | E10: ='เย็น '!E10+เช้า!E10 -> 0 | F10: ='เย็น '!F10+เช้า!F10 -> 1 | G10: ='เย็น '!G10+เช้า!G10 -> 81 | H10: ='เย็น '!H10+เช้า!H10 -> 90 | I10: ='เย็น '!I10+เช้า!I10 -> 72 | J10: ='เย็น '!J10+เช้า!J10 -> 39 | K10: =SUM(D10:J10) -> 297 | M10: 165 | Q10: =(L10+M10+N10+O10)-K10-P10 -> -132
B11: 1111057 | C11: ชิฟฟอนแยกชิ้น กาแฟ | D11: ='เย็น '!D11+เช้า!D11 -> 0 | E11: ='เย็น '!E11+เช้า!E11 -> 0 | F11: ='เย็น '!F11+เช้า!F11 -> 0 | G11: ='เย็น '!G11+เช้า!G11 -> 6 | H11: ='เย็น '!H11+เช้า!H11 -> 3 | I11: ='เย็น '!I11+เช้า!I11 -> 1 | J11: ='เย็น '!J11+เช้า!J11 -> 1 | K11: =SUM(D11:J11) -> 11 | M11: 27 | Q11: =(L11+M11+N11+O11)-K11-P11 -> 16
B12: 1111058 | C12: ชิฟฟอนแยกชิ้น ชาเขียว | D12: ='เย็น '!D12+เช้า!D12 -> 0 | E12: ='เย็น '!E12+เช้า!E12 -> 0 | F12: ='เย็น '!F12+เช้า!F12 -> 0 | G12: ='เย็น '!G12+เช้า!G12 -> 6 | H12: ='เย็น '!H12+เช้า!H12 -> 3 | I12: ='เย็น '!I12+เช้า!I12 -> 1 | J12: ='เย็น '!J12+เช้า!J12 -> 1 | K12: =SUM(D12:J12) -> 11 | M12: 20 | Q12: =(L12+M12+N12+O12)-K12-P12 -> 9
B13: 1111059 | C13: ชิฟฟอนแยกชิ้น ใบเตย | D13: ='เย็น '!D13+เช้า!D13 -> 0 | E13: ='เย็น '!E13+เช้า!E13 -> 0 | F13: ='เย็น '!F13+เช้า!F13 -> 0 | G13: ='เย็น '!G13+เช้า!G13 -> 6 | H13: ='เย็น '!H13+เช้า!H13 -> 3 | I13: ='เย็น '!I13+เช้า!I13 -> 6 | J13: ='เย็น '!J13+เช้า!J13 -> 0 | K13: =SUM(D13:J13) -> 15 | M13: 20 | Q13: =(L13+M13+N13+O13)-K13-P13 -> 5
B14: 1111060 | C14: ชิฟฟอนแยกชิ้น กล้วยหอม | D14: ='เย็น '!D14+เช้า!D14 -> 0 | E14: ='เย็น '!E14+เช้า!E14 -> 0 | F14: ='เย็น '!F14+เช้า!F14 -> 0 | G14: ='เย็น '!G14+เช้า!G14 -> 6 | H14: ='เย็น '!H14+เช้า!H14 -> 3 | I14: ='เย็น '!I14+เช้า!I14 -> 1 | J14: ='เย็น '!J14+เช้า!J14 -> 0 | K14: =SUM(D14:J14) -> 10 | M14: 20 | Q14: =(L14+M14+N14+O14)-K14-P14 -> 10
B15: 1111061 | C15: ชิฟฟอนแยกชิ้น ชาไทย | D15: ='เย็น '!D15+เช้า!D15 -> 0 | E15: ='เย็น '!E15+เช้า!E15 -> 0 | F15: ='เย็น '!F15+เช้า!F15 -> 0 | G15: ='เย็น '!G15+เช้า!G15 -> 6 | H15: ='เย็น '!H15+เช้า!H15 -> 3 | I15: ='เย็น '!I15+เช้า!I15 -> 0 | J15: ='เย็น '!J15+เช้า!J15 -> 0 | K15: =SUM(D15:J15) -> 9 | M15: 22 | Q15: =(L15+M15+N15+O15)-K15-P15 -> 13
B16: 1111062 | C16: ชิฟฟอนแยกชิ้น โกโก้ | D16: ='เย็น '!D16+เช้า!D16 -> 0 | E16: ='เย็น '!E16+เช้า!E16 -> 0 | F16: ='เย็น '!F16+เช้า!F16 -> 0 | G16: ='เย็น '!G16+เช้า!G16 -> 6 | H16: ='เย็น '!H16+เช้า!H16 -> 3 | I16: ='เย็น '!I16+เช้า!I16 -> 0 | J16: ='เย็น '!J16+เช้า!J16 -> 0 | K16: =SUM(D16:J16) -> 9 | M16: 20 | Q16: =(L16+M16+N16+O16)-K16-P16 -> 11
B17: 1111063 | C17: ชิฟฟอนแยกชิ้น ส้ม | D17: ='เย็น '!D17+เช้า!D17 -> 0 | E17: ='เย็น '!E17+เช้า!E17 -> 0 | F17: ='เย็น '!F17+เช้า!F17 -> 0 | G17: ='เย็น '!G17+เช้า!G17 -> 6 | H17: ='เย็น '!H17+เช้า!H17 -> 3 | I17: ='เย็น '!I17+เช้า!I17 -> 1 | J17: ='เย็น '!J17+เช้า!J17 -> 0 | K17: =SUM(D17:J17) -> 10 | M17: 24 | Q17: =(L17+M17+N17+O17)-K17-P17 -> 14
B18: 1111064 | C18: ชิฟฟอนแยกชิ้น เผือก | D18: ='เย็น '!D18+เช้า!D18 -> 0 | E18: ='เย็น '!E18+เช้า!E18 -> 0 | F18: ='เย็น '!F18+เช้า!F18 -> 0 | G18: ='เย็น '!G18+เช้า!G18 -> 6 | H18: ='เย็น '!H18+เช้า!H18 -> 3 | I18: ='เย็น '!I18+เช้า!I18 -> 0 | J18: ='เย็น '!J18+เช้า!J18 -> 0 | K18: =SUM(D18:J18) -> 9 | M18: 20 | Q18: =(L18+M18+N18+O18)-K18-P18 -> 11
B19: 1111065 | C19: ชิฟฟอนแยกชิ้น สับปะรด | D19: ='เย็น '!D19+เช้า!D19 -> 0 | E19: ='เย็น '!E19+เช้า!E19 -> 0 | F19: ='เย็น '!F19+เช้า!F19 -> 0 | G19: ='เย็น '!G19+เช้า!G19 -> 6 | H19: ='เย็น '!H19+เช้า!H19 -> 3 | I19: ='เย็น '!I19+เช้า!I19 -> 1 | J19: ='เย็น '!J19+เช้า!J19 -> 0 | K19: =SUM(D19:J19) -> 10 | M19: 10 | Q19: =(L19+M19+N19+O19)-K19-P19 -> 0
B20: 1111066 | C20: ชิฟฟอนแยกชิ้น สตอเบอรี่ | D20: ='เย็น '!D20+เช้า!D20 -> 0 | E20: ='เย็น '!E20+เช้า!E20 -> 0 | F20: ='เย็น '!F20+เช้า!F20 -> 0 | G20: ='เย็น '!G20+เช้า!G20 -> 5 | H20: ='เย็น '!H20+เช้า!H20 -> 3 | I20: ='เย็น '!I20+เช้า!I20 -> 1 | J20: ='เย็น '!J20+เช้า!J20 -> 0 | K20: =SUM(D20:J20) -> 9 | M20: 10 | Q20: =(L20+M20+N20+O20)-K20-P20 -> 1
... B23: 1111069 | C23: ชิฟฟอนแยกชิ้น บลูเบอรี่ | D23: ='เย็น '!D23+เช้า!D23 -> 0 | E23: ='เย็น '!E23+เช้า!E23 -> 0 | F23: ='เย็น '!F23+เช้า!F23 -> 0 | G23: ='เย็น '!G23+เช้า!G23 -> 5 | H23: ='เย็น '!H23+เช้า!H23 -> 2 | I23: ='เย็น '!I23+เช้า!I23 -> 1 | J23: ='เย็น '!J23+เช้า!J23 -> 0 | K23: =SUM(D23:J23) -> 8 | M23: 22 | Q23: =(L23+M23+N23+O23)-K23-P23 -> 14
B24: 1111070 | C24: ชิฟฟอนแยกชิ้น ทุเรียน | D24: ='เย็น '!D24+เช้า!D24 -> 0 | E24: ='เย็น '!E24+เช้า!E24 -> 0 | F24: ='เย็น '!F24+เช้า!F24 -> 0 | G24: ='เย็น '!G24+เช้า!G24 -> 5 | H24: ='เย็น '!H24+เช้า!H24 -> 2 | I24: ='เย็น '!I24+เช้า!I24 -> 0 | J24: ='เย็น '!J24+เช้า!J24 -> 0 | K24: =SUM(D24:J24) -> 7 | Q24: =(L24+M24+N24+O24)-K24-P24 -> -7
B25: 1111071 | C25: ชิฟฟอนแยกชิ้น ตาล | D25: ='เย็น '!D25+เช้า!D25 -> 0 | E25: ='เย็น '!E25+เช้า!E25 -> 0 | F25: ='เย็น '!F25+เช้า!F25 -> 0 | G25: ='เย็น '!G25+เช้า!G25 -> 5 | H25: ='เย็น '!H25+เช้า!H25 -> 2 | I25: ='เย็น '!I25+เช้า!I25 -> 0 | J25: ='เย็น '!J25+เช้า!J25 -> 0 | K25: =SUM(D25:J25) -> 7 | M25: 10 | Q25: =(L25+M25+N25+O25)-K25-P25 -> 3
B26: 1111074 | C26: ชิฟฟอนไส้แยมแยกชิ้น มะพร้าว | D26: ='เย็น '!D26+เช้า!D26 -> 0 | E26: ='เย็น '!E26+เช้า!E26 -> 5 | F26: ='เย็น '!F26+เช้า!F26 -> 3 | G26: ='เย็น '!G26+เช้า!G26 -> 0 | H26: ='เย็น '!H26+เช้า!H26 -> 1 | I26: ='เย็น '!I26+เช้า!I26 -> 0 | J26: ='เย็น '!J26+เช้า!J26 -> 11 | K26: =SUM(D26:J26) -> 20 | M26: 10 | Q26: =(L26+M26+N26+O26)-K26-P26 -> -10
B27: 1111075 | C27: ชิฟฟอนไส้แยมแยกชิ้น สตอเบอรี่ | D27: ='เย็น '!D27+เช้า!D27 -> 0 | E27: ='เย็น '!E27+เช้า!E27 -> 5 | F27: ='เย็น '!F27+เช้า!F27 -> 3 | G27: ='เย็น '!G27+เช้า!G27 -> 0 | H27: ='เย็น '!H27+เช้า!H27 -> 0 | I27: ='เย็น '!I27+เช้า!I27 -> 0 | J27: ='เย็น '!J27+เช้า!J27 -> 11 | K27: =SUM(D27:J27) -> 19 | M27: 20 | Q27: =(L27+M27+N27+O27)-K27-P27 -> 1
B28: 1111076 | C28: ชิฟฟอนไส้แยมแยกชิ้น ส้ม | D28: ='เย็น '!D28+เช้า!D28 -> 0 | E28: ='เย็น '!E28+เช้า!E28 -> 5 | F28: ='เย็น '!F28+เช้า!F28 -> 3 | G28: ='เย็น '!G28+เช้า!G28 -> 0 | H28: ='เย็น '!H28+เช้า!H28 -> 0 | I28: ='เย็น '!I28+เช้า!I28 -> 0 | J28: ='เย็น '!J28+เช้า!J28 -> 10 | K28: =SUM(D28:J28) -> 18 | M28: 26 | Q28: =(L28+M28+N28+O28)-K28-P28 -> 8
B29: 1111077 | C29: ชิฟฟอนไส้แยมแยกชิ้น บลูเบอรี่ | D29: ='เย็น '!D29+เช้า!D29 -> 0 | E29: ='เย็น '!E29+เช้า!E29 -> 5 | F29: ='เย็น '!F29+เช้า!F29 -> 3 | G29: ='เย็น '!G29+เช้า!G29 -> 0 | H29: ='เย็น '!H29+เช้า!H29 -> 0 | I29: ='เย็น '!I29+เช้า!I29 -> 0 | J29: ='เย็น '!J29+เช้า!J29 -> 10 | K29: =SUM(D29:J29) -> 18 | M29: 22 | Q29: =(L29+M29+N29+O29)-K29-P29 -> 4
B30: 1111078 | C30: ชิฟฟอนไส้แยมแยกชิ้น นมชมพู | D30: ='เย็น '!D30+เช้า!D30 -> 0 | E30: ='เย็น '!E30+เช้า!E30 -> 5 | F30: ='เย็น '!F30+เช้า!F30 -> 3 | G30: ='เย็น '!G30+เช้า!G30 -> 0 | H30: ='เย็น '!H30+เช้า!H30 -> 0 | I30: ='เย็น '!I30+เช้า!I30 -> 0 | J30: ='เย็น '!J30+เช้า!J30 -> 10 | K30: =SUM(D30:J30) -> 18 | M30: 22 | Q30: =(L30+M30+N30+O30)-K30-P30 -> 4
B31: 1111079 | C31: ชิฟฟอนไส้แยมแยกชิ้น ชอคโกแลต | D31: ='เย็น '!D31+เช้า!D31 -> 0 | E31: ='เย็น '!E31+เช้า!E31 -> 5 | F31: ='เย็น '!F31+เช้า!F31 -> 3 | G31: ='เย็น '!G31+เช้า!G31 -> 0 | H31: ='เย็น '!H31+เช้า!H31 -> 0 | I31: ='เย็น '!I31+เช้า!I31 -> 0 | J31: ='เย็น '!J31+เช้า!J31 -> 10 | K31: =SUM(D31:J31) -> 18 | M31: 15 | Q31: =(L31+M31+N31+O31)-K31-P31 -> -3
B32: 1111080 | C32: ชิฟฟอนไส้แยมแยกชิ้น ฝอยทอง | D32: ='เย็น '!D32+เช้า!D32 -> 0 | E32: ='เย็น '!E32+เช้า!E32 -> 5 | F32: ='เย็น '!F32+เช้า!F32 -> 3 | G32: ='เย็น '!G32+เช้า!G32 -> 0 | H32: ='เย็น '!H32+เช้า!H32 -> 0 | I32: ='เย็น '!I32+เช้า!I32 -> 0 | J32: ='เย็น '!J32+เช้า!J32 -> 10 | K32: =SUM(D32:J32) -> 18 | M32: 24 | Q32: =(L32+M32+N32+O32)-K32-P32 -> 6
B33: 1111081 | C33: ชิฟฟอนไส้แยมแยกชิ้น วนิลา | D33: ='เย็น '!D33+เช้า!D33 -> 0 | E33: ='เย็น '!E33+เช้า!E33 -> 5 | F33: ='เย็น '!F33+เช้า!F33 -> 3 | G33: ='เย็น '!G33+เช้า!G33 -> 0 | H33: ='เย็น '!H33+เช้า!H33 -> 0 | I33: ='เย็น '!I33+เช้า!I33 -> 0 | J33: ='เย็น '!J33+เช้า!J33 -> 10 | K33: =SUM(D33:J33) -> 18 | M33: 13 | Q33: =(L33+M33+N33+O33)-K33-P33 -> -5
B34: 1111082 | C34: ชิฟฟอนไส้แยมแยกชิ้น ใบเตย | D34: ='เย็น '!D34+เช้า!D34 -> 0 | E34: ='เย็น '!E34+เช้า!E34 -> 5 | F34: ='เย็น '!F34+เช้า!F34 -> 3 | G34: ='เย็น '!G34+เช้า!G34 -> 0 | H34: ='เย็น '!H34+เช้า!H34 -> 0 | I34: ='เย็น '!I34+เช้า!I34 -> 0 | J34: ='เย็น '!J34+เช้า!J34 -> 10 | K34: =SUM(D34:J34) -> 18 | M34: 12 | Q34: =(L34+M34+N34+O34)-K34-P34 -> -6
B35: 1111083 | C35: ชิฟฟอนไส้แยมแยกชิ้น เมล่อน | D35: ='เย็น '!D35+เช้า!D35 -> 0 | E35: ='เย็น '!E35+เช้า!E35 -> 5 | F35: ='เย็น '!F35+เช้า!F35 -> 3 | G35: ='เย็น '!G35+เช้า!G35 -> 0 | H35: ='เย็น '!H35+เช้า!H35 -> 0 | I35: ='เย็น '!I35+เช้า!I35 -> 0 | J35: ='เย็น '!J35+เช้า!J35 -> 10 | K35: =SUM(D35:J35) -> 18 | M35: 11 | Q35: =(L35+M35+N35+O35)-K35-P35 -> -7
B36: ชิฟฟอนไส้แยม 6 ชิ้น
B37: 1111009 | C37: ชิฟฟอนไส้แยมรวมรส 6 ชิ้น | D37: ='เย็น '!D37+เช้า!D37 -> 0 | E37: ='เย็น '!E37+เช้า!E37 -> 3 | F37: ='เย็น '!F37+เช้า!F37 -> 4 | G37: ='เย็น '!G37+เช้า!G37 -> 1 | H37: ='เย็น '!H37+เช้า!H37 -> 1 | I37: ='เย็น '!I37+เช้า!I37 -> 0 | J37: ='เย็น '!J37+เช้า!J37 -> 2 | K37: =SUM(D37:J37) -> 11 | M37: 30 | Q37: =(L37+M37+N37+O37)-K37-P37 -> 19
B38: ชิฟฟอนไส้แยม 3 ชิ้น
B39: 1111008 | C39: ชิฟฟอนไส้แยมรวมรส 3 ชิ้น | D39: ='เย็น '!D39+เช้า!D39 -> 5 | E39: ='เย็น '!E39+เช้า!E39 -> 6 | F39: ='เย็น '!F39+เช้า!F39 -> 0 | G39: ='เย็น '!G39+เช้า!G39 -> 102 | H39: ='เย็น '!H39+เช้า!H39 -> 114 | I39: ='เย็น '!I39+เช้า!I39 -> 90 | J39: ='เย็น '!J39+เช้า!J39 -> 9 | K39: =SUM(D39:J39) -> 326 | M39: 125 | Q39: =(L39+M39+N39+O39)-K39-P39 -> -201
B40: 1111017 | C40: ชิฟฟอนไส้แยมบลูเบอรี่ 3 ชิ้น | D40: ='เย็น '!D40+เช้า!D40 -> 0 | E40: ='เย็น '!E40+เช้า!E40 -> 0 | F40: ='เย็น '!F40+เช้า!F40 -> 0 | G40: ='เย็น '!G40+เช้า!G40 -> 0 | H40: ='เย็น '!H40+เช้า!H40 -> 0 | I40: ='เย็น '!I40+เช้า!I40 -> 0 | J40: ='เย็น '!J40+เช้า!J40 -> 0 | K40: =SUM(D40:J40) -> 0 | M40: 5 | Q40: =(L40+M40+N40+O40)-K40-P40 -> 5
B41: 1111019 | C41: ชิฟฟอนไส้แยมฝอยทอง 3 ชิ้น | D41: ='เย็น '!D41+เช้า!D41 -> 5 | E41: ='เย็น '!E41+เช้า!E41 -> 0 | F41: ='เย็น '!F41+เช้า!F41 -> 0 | G41: ='เย็น '!G41+เช้า!G41 -> 0 | H41: ='เย็น '!H41+เช้า!H41 -> 0 | I41: ='เย็น '!I41+เช้า!I41 -> 0 | J41: ='เย็น '!J41+เช้า!J41 -> 0 | K41: =SUM(D41:J41) -> 5 | M41: 5 | Q41: =(L41+M41+N41+O41)-K41-P41 -> 0
B42: 1111022 | C42: ชิฟฟอนไส้แยมสตอเบอรี่ 3 ชิ้น | D42: ='เย็น '!D42+เช้า!D42 -> 0 | E42: ='เย็น '!E42+เช้า!E42 -> 0 | F42: ='เย็น '!F42+เช้า!F42 -> 0 | G42: ='เย็น '!G42+เช้า!G42 -> 0 | H42: ='เย็น '!H42+เช้า!H42 -> 0 | I42: ='เย็น '!I42+เช้า!I42 -> 0 | J42: ='เย็น '!J42+เช้า!J42 -> 0 | K42: =SUM(D42:J42) -> 0 | M42: 5 | Q42: =(L42+M42+N42+O42)-K42-P42 -> 5
B43: 1111024 | C43: ชิฟฟอนไส้แยมส้ม 3 ชิ้น | D43: ='เย็น '!D43+เช้า!D43 -> 0 | E43: ='เย็น '!E43+เช้า!E43 -> 0 | F43: ='เย็น '!F43+เช้า!F43 -> 0 | G43: ='เย็น '!G43+เช้า!G43 -> 0 | H43: ='เย็น '!H43+เช้า!H43 -> 0 | I43: ='เย็น '!I43+เช้า!I43 -> 0 | J43: ='เย็น '!J43+เช้า!J43 -> 0 | K43: =SUM(D43:J43) -> 0 | M43: 5 | Q43: =(L43+M43+N43+O43)-K43-P43 -> 5
...
