Workbook
Name shtlist: #REF!

Sheet เย็น  
B1: ยอดจริง ออนไลน์ วันที่ 4/12/2567 - เย็น
L2: ยอดรวมผลิต
L3: จำนวน
B4: รหัสสินค้า | C4: สินค้า | D4: ปณ | E4: ชอปปี้ | F4: ลาซาด้า | G4: ติ๊กตอก | H4: ติ๊กตอก2 | I4: ติ๊กตอก3 | J4: ชอยส์ | K4: บิลเส้น | L4: (กล่อง)
B6: ชิฟฟอนรวมรส
B7: 1111002 | C7: ชิฟฟอนรวมรส 8 ชิ้น | E7: 12 | F7: 4 | K7: 10 | L7: =SUM(D7:K7) -> 26
B8: 1111086 | C8: ชิฟฟอน 8 ชิ้น มะพร้าวล้วน | L8: =SUM(D8:K8) -> 0
B9: 1111056 | C9: ชิฟฟอน 8 ชิ้น รวมรสยอดฮิต | E9: 3 | F9: 5 | G9: 8 | H9: 1 | L9: =SUM(D9:K9) -> 17
B10: 1004055 | C10: ชิฟฟอนรวมรส 4 ชิ้น | E10: 2 | G10: 33 | H10: 49 | K10: 25 | L10: =SUM(D10:K10) -> 109
B11: 1111057 | C11: ชิฟฟอนแยกชิ้น กาแฟ | L11: =SUM(D11:K11) -> 0
B12: 1111058 | C12: ชิฟฟอนแยกชิ้น ชาเขียว | L12: =SUM(D12:K12) -> 0
B13: 1111059 | C13: ชิฟฟอนแยกชิ้น ใบเตย | H13: 5 | L13: =SUM(D13:K13) -> 5
B14: 1111060 | C14: ชิฟฟอนแยกชิ้น กล้วยหอม | L14: =SUM(D14:K14) -> 0
B15: 1111061 | C15: ชิฟฟอนแยกชิ้น ชาไทย | L15: =SUM(D15:K15) -> 0
B16: 1111062 | C16: ชิฟฟอนแยกชิ้น โกโก้ | L16: =SUM(D16:K16) -> 0
B17: 1111063 | C17: ชิฟฟอนแยกชิ้น ส้ม | L17: =SUM(D17:K17) -> 0
B18: 1111064 | C18: ชิฟฟอนแยกชิ้น เผือก | L18: =SUM(D18:K18) -> 0
B19: 1111065 | C19: ชิฟฟอนแยกชิ้น สับปะรด | L19: =SUM(D19:K19) -> 0
B20: 1111066 | C20: ชิฟฟอนแยกชิ้น สตอเบอรี่ | L20: =SUM(D20:K20) -> 0
B21: 1111067 | C21: ชิฟฟอนแยกชิ้น มะพร้าว | H21: 5 | L21: =SUM(D21:K21) -> 5
B22: 1111068 | C22: ชิฟฟอนแยกชิ้น เนย | L22: =SUM(D22:K22) -> 0
B23: 1111069 | C23: ชิฟฟอนแยกชิ้น บลูเบอรี่ | L23: =SUM(D23:K23) -> 0
B24: 1111070 | C24: ชิฟฟอนแยกชิ้น ทุเรียน | L24: =SUM(D24:K24) -> 0
B25: 1111071 | C25: ชิฟฟอนแยกชิ้น ตาล | L25: =SUM(D25:K25) -> 0
B26: 1111074 | C26: ชิฟฟอนไส้แยมแยกชิ้น มะพร้าว | G26: 1 | H26: 2 | L26: =SUM(D26:K26) -> 3
B27: 1111075 | C27: ชิฟฟอนไส้แยมแยกชิ้น สตอเบอรี่ | H27: 2 | L27: =SUM(D27:K27) -> 2
B28: 1111076 | C28: ชิฟฟอนไส้แยมแยกชิ้น ส้ม | H28: 2 | L28: =SUM(D28:K28) -> 2
B29: 1111077 | C29: ชิฟฟอนไส้แยมแยกชิ้น บลูเบอรี่ | H29: 2 | L29: =SUM(D29:K29) -> 2
B30: 1111078 | C30: ชิฟฟอนไส้แยมแยกชิ้น นมชมพู | H30: 2 | L30: =SUM(D30:K30) -> 2
B31: 1111079 | C31: ชิฟฟอนไส้แยมแยกชิ้น ชอคโกแลต | H31: 1 | L31: =SUM(D31:K31) -> 1
B32: 1111080 | C32: ชิฟฟอนไส้แยมแยกชิ้น ฝอยทอง | H32: 1 | L32: =SUM(D32:K32) -> 1
B33: 1111081 | C33: ชิฟฟอนไส้แยมแยกชิ้น วนิลา | H33: 1 | L33: =SUM(D33:K33) -> 1
B34: 1111082 | C34: ชิฟฟอนไส้แยมแยกชิ้น ใบเตย | H34: 1 | L34: =SUM(D34:K34) -> 1
B35: 1111083 | C35: ชิฟฟอนไส้แยมแยกชิ้น เมล่อน | H35: 1 | L35: =SUM(D35:K35) -> 1
B36: ชิฟฟอนไส้แยม 6 ชิ้น
B37: 1111009 | C37: ชิฟฟอนไส้แยมรวมรส 6 ชิ้น | F37: 5 | L37: =SUM(D37:K37) -> 5
L38: =SUM(D38:K38) -> 0
B39: ชิฟฟอนไส้แยม 3 ชิ้น
B40: 1111008 | C40: ชิฟฟอนไส้แยมรวมรส 3 ชิ้น | G40: 59 | H40: 34 | L40: =SUM(D40:K40) -> 93
L41: =SUM(D41:K41) -> 0
...

Sheet เช้า
B1: ยอดจริง ออนไลน์ วันที่ 4/12/2567 - เช้า
L2: ยอดรวมผลิต
L3: จำนวน
B4: รหัสสินค้า | C4: สินค้า | D4: ปณ | E4: ชอปปี้ | F4: ลาซาด้า | G4: ติ๊กตอก | H4: ติ๊กตอก2 | I4: ติ๊กตอก3 | J4: ชอยส์ | K4: บิลเส้น | L4: (กล่อง)
B6: ชิฟฟอนรวมรส
B7: 1111002 | C7: ชิฟฟอนรวมรส 8 ชิ้น | D7: 10 | E7: 25 | F7: 20 | L7: =SUM(D7:J7) -> 55
B8: 1111086 | C8: ชิฟฟอน 8 ชิ้น มะพร้าวล้วน | L8: =SUM(D8:J8) -> 0
B9: 1111056 | C9: ชิฟฟอน 8 ชิ้น รวมรสยอดฮิต | E9: 3 | F9: 5 | L9: =SUM(D9:J9) -> 8
B10: 1004055 | C10: ชิฟฟอนรวมรส 4 ชิ้น | D10: 21 | F10: 6 | G10: 6 | L10: =SUM(D10:J10) -> 33
B11: 1111057 | C11: ชิฟฟอนแยกชิ้น กาแฟ | G11: 1 | L11: =SUM(D11:J11) -> 1
B12: 1111058 | C12: ชิฟฟอนแยกชิ้น ชาเขียว | G12: 1 | L12: =SUM(D12:J12) -> 1
B13: 1111059 | C13: ชิฟฟอนแยกชิ้น ใบเตย | D13: 3 | G13: 1 | L13: =SUM(D13:J13) -> 4
B14: 1111060 | C14: ชิฟฟอนแยกชิ้น กล้วยหอม | G14: 1 | L14: =SUM(D14:J14) -> 1
B15: 1111061 | C15: ชิฟฟอนแยกชิ้น ชาไทย | G15: 1 | L15: =SUM(D15:J15) -> 1
B16: 1111062 | C16: ชิฟฟอนแยกชิ้น โกโก้ | G16: 1 | L16: =SUM(D16:J16) -> 1
B17: 1111063 | C17: ชิฟฟอนแยกชิ้น ส้ม | G17: 1 | L17: =SUM(D17:J17) -> 1
B18: 1111064 | C18: ชิฟฟอนแยกชิ้น เผือก | D18: 5 | G18: 1 | L18: =SUM(D18:J18) -> 6
B19: 1111065 | C19: ชิฟฟอนแยกชิ้น สับปะรด | G19: 1 | L19: =SUM(D19:J19) -> 1
B20: 1111066 | C20: ชิฟฟอนแยกชิ้น สตอเบอรี่ | G20: 1 | L20: =SUM(D20:J20) -> 1
B21: 1111067 | C21: ชิฟฟอนแยกชิ้น มะพร้าว | D21: 3 | L21: =SUM(D21:J21) -> 3
B22: 1111068 | C22: ชิฟฟอนแยกชิ้น เนย | L22: =SUM(D22:J22) -> 0
B23: 1111069 | C23: ชิฟฟอนแยกชิ้น บลูเบอรี่ | L23: =SUM(D23:J23) -> 0
B24: 1111070 | C24: ชิฟฟอนแยกชิ้น ทุเรียน | L24: =SUM(D24:J24) -> 0
B25: 1111071 | C25: ชิฟฟอนแยกชิ้น ตาล | L25: =SUM(D25:J25) -> 0
B26: 1111074 | C26: ชิฟฟอนไส้แยมแยกชิ้น มะพร้าว | G26: 1 | L26: =SUM(D26:J26) -> 1
B27: 1111075 | C27: ชิฟฟอนไส้แยมแยกชิ้น สตอเบอรี่ | G27: 1 | L27: =SUM(D27:J27) -> 1
B28: 1111076 | C28: ชิฟฟอนไส้แยมแยกชิ้น ส้ม | G28: 1 | L28: =SUM(D28:J28) -> 1
B29: 1111077 | C29: ชิฟฟอนไส้แยมแยกชิ้น บลูเบอรี่ | G29: 1 | L29: =SUM(D29:J29) -> 1
B30: 1111078 | C30: ชิฟฟอนไส้แยมแยกชิ้น นมชมพู | G30: 1 | L30: =SUM(D30:J30) -> 1
B31: 1111079 | C31: ชิฟฟอนไส้แยมแยกชิ้น ชอคโกแลต | G31: 1 | L31: =SUM(D31:J31) -> 1
B32: 1111080 | C32: ชิฟฟอนไส้แยมแยกชิ้น ฝอยทอง | G32: 1 | L32: =SUM(D32:J32) -> 1
B33: 1111081 | C33: ชิฟฟอนไส้แยมแยกชิ้น วนิลา | L33: =SUM(D33:J33) -> 0
B34: 1111082 | C34: ชิฟฟอนไส้แยมแยกชิ้น ใบเตย | L34: =SUM(D34:J34) -> 0
B35: 1111083 | C35: ชิฟฟอนไส้แยมแยกชิ้น เมล่อน | L35: =SUM(D35:J35) -> 0
B36: ชิฟฟอนไส้แยม 6 ชิ้น
B37: 1111009 | C37: ชิฟฟอนไส้แยมรวมรส 6 ชิ้น | E37: 3 | F37: 5 | G37: 9 | L37: =SUM(D37:J37) -> 17
B38: 1111020 | C38: ชิฟฟอนไส้แยมฝอยทอง 6 ชิ้น | L38: =SUM(D38:J38) -> 0
B39: ชิฟฟอนไส้แยม 3 ชิ้น
B40: 1111008 | C40: ชิฟฟอนไส้แยมรวมรส 3 ชิ้น | D40: 6 | E40: 3 | L40: =SUM(D40:J40) -> 9
B41: 1111017 | C41: ชิฟฟอนไส้แยมบลูเบอรี่ 3 ชิ้น | L41: =SUM(D41:J41) -> 0
...

Sheet บ่าย
B1: ยอดจริง ออนไลน์ วันที่ 3/12/2567 - เย็น
L2: ยอดรวมผลิต
L3: จำนวน
B4: รหัสสินค้า | C4: สินค้า | D4: ปณ | E4: ชอปปี้ | F4: ลาซาด้า | G4: ติ๊กตอก | H4: ติ๊กตอก2 | I4: ติ๊กตอก3 | J4: ชอยส์ | K4: บิลเส้น | L4: (กล่อง)
B6: ชิฟฟอนรวมรส
B7: 1111002 | C7: ชิฟฟอนรวมรส 8 ชิ้น | L7: =SUM(D7:K7) -> 0
B8: 1111043 | C8: ชิฟฟอน 8 ชิ้น มะลิ | L8: =SUM(D8:K8) -> 0
B9: 1111056 | C9: ชิฟฟอน 8 ชิ้น รวมรสยอดฮิต | L9: =SUM(D9:K9) -> 0
B10: 1004055 | C10: ชิฟฟอนรวมรส 4 ชิ้น | L10: =SUM(D10:K10) -> 0
B11: 1111057 | C11: ชิฟฟอนแยกชิ้น กาแฟ | L11: =SUM(D11:K11) -> 0
B12: 1111058 | C12: ชิฟฟอนแยกชิ้น ชาเขียว | L12: =SUM(D12:K12) -> 0
B13: 1111059 | C13: ชิฟฟอนแยกชิ้น ใบเตย | L13: =SUM(D13:K13) -> 0
B14: 1111060 | C14: ชิฟฟอนแยกชิ้น กล้วยหอม | L14: =SUM(D14:K14) -> 0
B15: 1111061 | C15: ชิฟฟอนแยกชิ้น ชาไทย | L15: =SUM(D15:K15) -> 0
B16: 1111062 | C16: ชิฟฟอนแยกชิ้น โกโก้ | L16: =SUM(D16:K16) -> 0
B17: 1111063 | C17: ชิฟฟอนแยกชิ้น ส้ม | L17: =SUM(D17:K17) -> 0
B18: 1111064 | C18: ชิฟฟอนแยกชิ้น เผือก | L18: =SUM(D18:K18) -> 0
... B35: 1111083 | C35: ชิฟฟอนไส้แยมแยกชิ้น เมล่อน | L35: =SUM(D35:K35) -> 0
B36: ชิฟฟอนไส้แยม 6 ชิ้น
B37: 1111009 | C37: ชิฟฟอนไส้แยมรวมรส 6 ชิ้น | L37: =SUM(D37:K37) -> 0
B38: 1111020 | C38: ชิฟฟอนไส้แยมฝอยทอง 6 ชิ้น | L38: =SUM(D38:K38) -> 0
B39: ชิฟฟอนไส้แยม 3 ชิ้น
B40: 1111008 | C40: ชิฟฟอนไส้แยมรวมรส 3 ชิ้น | L40: =SUM(D40:K40) -> 0
B41: 1111011 | C41: ชิฟฟอนไส้แยมนมชมพู 3 ชิ้น | L41: =SUM(D41:K41) -> 0
B42: 1111013 | C42: ชิฟฟอนไส้แยมชอคโกแลต 3 ชิ้น | L42: =SUM(D42:K42) -> 0
B43: 1111017 | C43: ชิฟฟอนไส้แยมบลูเบอรี่ 3 ชิ้น | L43: =SUM(D43:K43) -> 0
B44: 1111022 | C44: ชิฟฟอนไส้แยมสตอเบอรี่ 3 ชิ้น | L44: =SUM(D44:K44) -> 0
B45: เบาหวิว ล 110 กรัม
B46: 1112009 | C46: มะพร้าว | L46: =SUM(D46:K46) -> 0
B47: 1112011 | C47: ฝอยทอง | L47: =SUM(D47:K47) -> 0
B48: 1112003 | C48: กาแฟ | L48: =SUM(D48:K48) -> 0
B49: 1112005 | C49: เนยนม | L49: =SUM(D49:K49) -> 0
B50: 1112007 | C50: ใบเตย | L50: =SUM(D50:K50) -> 0
B51: 1112019 | C51: ทุเรียน | L51: =SUM(D51:K51) -> 0
B52: 1112017 | C52: ตาลหอม | L52: =SUM(D52:K52) -> 0
B53: 1112015 | C53: กล้วยหอมมะพร้าวเผา | L53: =SUM(D53:K53) -> 0
B54: 1112013 | C54: เผือกมะพร้าวอ่อน | L54: =SUM(D54:K54) -> 0
B55: 1124043 | C55: เบาหวิว คละรส | L55: =SUM(D55:K55) -> 0
B56: อื่นๆ
B57: 1113170 | C57: ขนมเปี๊ยะถั่วฝอยทองไข่เค็ม 450 กรัม | L57: =SUM(D57:K57) -> 0
...

Sheet รวม
B1: ยอดจริง ออนไลน์ วันที่ 4/12/2567 - รวม
L2: ยอดรวมผลิต | M2: ยอดสตอค | N2: ยอดฟอแคส | O2: รับเกิน | P2: ยังไม่ได้รับเข้า | R2: รวม
L3: จำนวน | Q3: บิลค้าง
B4: รหัสสินค้า | C4: สินค้า | D4: ปณ | E4: ชอปปี้ | F4: ลาซาด้า | G4: ติ๊กตอก | H4: ติ๊กตอก2 | I4: ติ๊กตอก3 | J4: ชอยส์ | K4: บิลเส้น | L4: (กล่อง)
B6: ชิฟฟอนรวมรส
B7: 1111002 | C7: ชิฟฟอนรวมรส 8 ชิ้น | D7: ='เย็น '!D7+เช้า!D7+บ่าย!D7 -> 10 | E7: ='เย็น '!E7+เช้า!E7+บ่าย!E7 -> 37 | F7: ='เย็น '!F7+เช้า!F7+บ่าย!F7 -> 24 | G7: ='เย็น '!G7+เช้า!G7+บ่าย!G7 -> 0 | H7: ='เย็น '!H7+เช้า!H7+บ่าย!H7 -> 0 | I7: ='เย็น '!I7+เช้า!I7+บ่าย!I7 -> 0 | J7: ='เย็น '!J7+เช้า!J7+บ่าย!J7 -> 0 | K7: ='เย็น '!K7+เช้า!K7+บ่าย!K7 -> 10 | L7: =SUM(D7:K7) -> 81 | M7: 169 | R7: =(M7+N7+O7+P7)-L7-Q7 -> 88
B8: 1111086 | C8: ชิฟฟอน 8 ชิ้น มะพร้าวล้วน | D8: ='เย็น '!D8+เช้า!D8+บ่าย!D8 -> 0 | E8: ='เย็น '!E8+เช้า!E8+บ่าย!E8 -> 0 | F8: ='เย็น '!F8+เช้า!F8+บ่าย!F8 -> 0 | G8: ='เย็น '!G8+เช้า!G8+บ่าย!G8 -> 0 | H8: ='เย็น '!H8+เช้า!H8+บ่าย!H8 -> 0 | I8: ='เย็น '!I8+เช้า!I8+บ่าย!I8 -> 0 | J8: ='เย็น '!J8+เช้า!J8+บ่าย!J8 -> 0 | K8: ='เย็น '!K8+เช้า!K8+บ่าย!K8 -> 0 | L8: =SUM(D8:K8) -> 0 | R8: =(M8+N8+O8+P8)-L8-Q8 -> 0
B9: 1111056 | C9: ชิฟฟอน 8 ชิ้น รวมรสยอดฮิต | D9: ='เย็น '!D9+เช้า!D9+บ่าย!D9 -> 0 | E9: ='เย็น '!E9+เช้า!E9+บ่าย!E9 -> 6 | F9: ='เย็น '!F9+เช้า!F9+บ่าย!F9 -> 10 | G9: ='เย็น '!G9+เช้า!G9+บ่าย!G9 -> 8 | H9: ='เย็น '!H9+เช้า!H9+บ่าย!H9 -> 1 | I9: ='เย็น '!I9+เช้า!I9+บ่าย!I9 -> 0 | J9: ='เย็น '!J9+เช้า!J9+บ่าย!J9 -> 0 | K9: ='เย็น '!K9+เช้า!K9+บ่าย!K9 -> 0 | L9: =SUM(D9:K9) -> 25 | M9: 13 | R9: =(M9+N9+O9+P9)-L9-Q9 -> -12
B10: 1004055 | C10: ชิฟฟอนรวมรส 4 ชิ้น | D10: ='เย็น '!D10+เช้า!D10+บ่าย!D10 -> 21 | E10: ='เย็น '!E10+เช้า!E10+บ่าย!E10 -> 2 | F10: ='เย็น '!F10+เช้า!F10+บ่าย!F10 -> 6 | G10: ='เย็น '!G10+เช้า!G10+บ่าย!G10 -> 39 | H10: ='เย็น '!H10+เช้า!H10+บ่าย!H10 -> 49 | I10: ='เย็น '!I10+เช้า!I10+บ่าย!I10 -> 0 | J10: ='เย็น '!J10+เช้า!J10+บ่าย!J10 -> 0 | K10: ='เย็น '!K10+เช้า!K10+บ่าย!K10 -> 25 | L10: =SUM(D10:K10) -> 142 | M10: 110 | R10: =(M10+N10+O10+P10)-L10-Q10 -> -32
B11: 1111057 | C11: ชิฟฟอนแยกชิ้น กาแฟ | D11: ='เย็น '!D11+เช้า!D11+บ่าย!D11 -> 0 | E11: ='เย็น '!E11+เช้า!E11+บ่าย!E11 -> 0 | F11: ='เย็น '!F11+เช้า!F11+บ่าย!F11 -> 0 | G11: ='เย็น '!G11+เช้า!G11+บ่าย!G11 -> 1 | H11: ='เย็น '!H11+เช้า!H11+บ่าย!H11 -> 0 | I11: ='เย็น '!I11+เช้า!I11+บ่าย!I11 -> 0 | J11: ='เย็น '!J11+เช้า!J11+บ่าย!J11 -> 0 | K11: ='เย็น '!K11+เช้า!K11+บ่าย!K11 -> 0 | L11: =SUM(D11:K11) -> 1 | R11: =(M11+N11+O11+P11)-L11-Q11 -> -1
B12: 1111058 | C12: ชิฟฟอนแยกชิ้น ชาเขียว | D12: ='เย็น '!D12+เช้า!D12+บ่าย!D12 -> 0 | E12: ='เย็น '!E12+เช้า!E12+บ่าย!E12 -> 0 | F12: ='เย็น '!F12+เช้า!F12+บ่าย!F12 -> 0 | G12: ='เย็น '!G12+เช้า!G12+บ่าย!G12 -> 1 | H12: ='เย็น '!H12+เช้า!H12+บ่าย!H12 -> 0 | I12: ='เย็น '!I12+เช้า!I12+บ่าย!I12 -> 0 | J12: ='เย็น '!J12+เช้า!J12+บ่าย!J12 -> 0 | K12: ='เย็น '!K12+เช้า!K12+บ่าย!K12 -> 0 | L12: =SUM(D12:K12) -> 1 | R12: =(M12+N12+O12+P12)-L12-Q12 -> -1
B13: 1111059 | C13: ชิฟฟอนแยกชิ้น ใบเตย | D13: ='เย็น '!D13+เช้า!D13+บ่าย!D13 -> 3 | E13: ='เย็น '!E13+เช้า!E13+บ่าย!E13 -> 0 | F13: ='เย็น '!F13+เช้า!F13+บ่าย!F13 -> 0 | G13: ='เย็น '!G13+เช้า!G13+บ่าย!G13 -> 1 | H13: ='เย็น '!H13+เช้า!H13+บ่าย!H13 -> 5 | I13: ='เย็น '!I13+เช้า!I13+บ่าย!I13 -> 0 | J13: ='เย็น '!J13+เช้า!J13+บ่าย!J13 -> 0 | K13: ='เย็น '!K13+เช้า!K13+บ่าย!K13 -> 0 | L13: =SUM(D13:K13) -> 9 | R13: =(M13+N13+O13+P13)-L13-Q13 -> -9
B14: 1111060 | C14: ชิฟฟอนแยกชิ้น กล้วยหอม | D14: ='เย็น '!D14+เช้า!D14+บ่าย!D14 -> 0 | E14: ='เย็น '!E14+เช้า!E14+บ่าย!E14 -> 0 | F14: ='เย็น '!F14+เช้า!F14+บ่าย!F14 -> 0 | G14: ='เย็น '!G14+เช้า!G14+บ่าย!G14 -> 1 | H14: ='เย็น '!H14+เช้า!H14+บ่าย!H14 -> 0 | I14: ='เย็น '!I14+เช้า!I14+บ่าย!I14 -> 0 | J14: ='เย็น '!J14+เช้า!J14+บ่าย!J14 -> 0 | K14: ='เย็น '!K14+เช้า!K14+บ่าย!K14 -> 0 | L14: =SUM(D14:K14) -> 1 | R14: =(M14+N14+O14+P14)-L14-Q14 -> -1
B15: 1111061 | C15: ชิฟฟอนแยกชิ้น ชาไทย | D15: ='เย็น '!D15+เช้า!D15+บ่าย!D15 -> 0 | E15: ='เย็น '!E15+เช้า!E15+บ่าย!E15 -> 0 | F15: ='เย็น '!F15+เช้า!F15+บ่าย!F15 -> 0 | G15: ='เย็น '!G15+เช้า!G15+บ่าย!G15 -> 1 | H15: ='เย็น '!H15+เช้า!H15+บ่าย!H15 -> 0 | I15: ='เย็น '!I15+เช้า!I15+บ่าย!I15 -> 0 | J15: ='เย็น '!J15+เช้า!J15+บ่าย!J15 -> 0 | K15: ='เย็น '!K15+เช้า!K15+บ่าย!K15 -> 0 | L15: =SUM(D15:K15) -> 1 | M15: 2 | R15: =(M15+N15+O15+P15)-L15-Q15 -> 1
B16: 1111062 | C16: ชิฟฟอนแยกชิ้น โกโก้ | D16: ='เย็น '!D16+เช้า!D16+บ่าย!D16 -> 0 | E16: ='เย็น '!E16+เช้า!E16+บ่าย!E16 -> 0 | F16: ='เย็น '!F16+เช้า!F16+บ่าย!F16 -> 0 | G16: ='เย็น '!G16+เช้า!G16+บ่าย!G16 -> 1 | H16: ='เย็น '!H16+เช้า!H16+บ่าย!H16 -> 0 | I16: ='เย็น '!I16+เช้า!I16+บ่าย!I16 -> 0 | J16: ='เย็น '!J16+เช้า!J16+บ่าย!J16 -> 0 | K16: ='เย็น '!K16+เช้า!K16+บ่าย!K16 -> 0 | L16: =SUM(D16:K16) -> 1 | M16: 1 | R16: =(M16+N16+O16+P16)-L16-Q16 -> 0
B17: 1111063 | C17: ชิฟฟอนแยกชิ้น ส้ม | D17: ='เย็น '!D17+เช้า!D17+บ่าย!D17 -> 0 | E17: ='เย็น '!E17+เช้า!E17+บ่าย!E17 -> 0 | F17: ='เย็น '!F17+เช้า!F17+บ่าย!F17 -> 0 | G17: ='เย็น '!G17+เช้า!G17+บ่าย!G17 -> 1 | H17: ='เย็น '!H17+เช้า!H17+บ่าย!H17 -> 0 | I17: ='เย็น '!I17+เช้า!I17+บ่าย!I17 -> 0 | J17: ='เย็น '!J17+เช้า!J17+บ่าย!J17 -> 0 | K17: ='เย็น '!K17+เช้า!K17+บ่าย!K17 -> 0 | L17: =SUM(D17:K17) -> 1 | M17: 17 | R17: =(M17+N17+O17+P17)-L17-Q17 -> 16
B18: 1111064 | C18: ชิฟฟอนแยกชิ้น เผือก | D18: ='เย็น '!D18+เช้า!D18+บ่าย!D18 -> 5 | E18: ='เย็น '!E18+เช้า!E18+บ่าย!E18 -> 0 | F18: ='เย็น '!F18+เช้า!F18+บ่าย!F18 -> 0 | G18: ='เย็น '!G18+เช้า!G18+บ่าย!G18 -> 1 | H18: ='เย็น '!H18+เช้า!H18+บ่าย!H18 -> 0 | I18: ='เย็น '!I18+เช้า!I18+บ่าย!I18 -> 0 | J18: ='เย็น '!J18+เช้า!J18+บ่าย!J18 -> 0 | K18: ='เย็น '!K18+เช้า!K18+บ่าย!K18 -> 0 | L18: =SUM(D18:K18) -> 6 | R18: =(M18+N18+O18+P18)-L18-Q18 -> -6
B19: 1111065 | C19: ชิฟฟอนแยกชิ้น สับปะรด | D19: ='เย็น '!D19+เช้า!D19+บ่าย!D19 -> 0 | E19: ='เย็น '!E19+เช้า!E19+บ่าย!E19 -> 0 | F19: ='เย็น '!F19+เช้า!F19+บ่าย!F19 -> 0 | G19: ='เย็น '!G19+เช้า!G19+บ่าย!G19 -> 1 | H19: ='เย็น '!H19+เช้า!H19+บ่าย!H19 -> 0 | I19: ='เย็น '!I19+เช้า!I19+บ่าย!I19 -> 0 | J19: ='เย็น '!J19+เช้า!J19+บ่าย!J19 -> 0 | K19: ='เย็น '!K19+เช้า!K19+บ่าย!K19 -> 0 | L19: =SUM(D19:K19) -> 1 | R19: =(M19+N19+O19+P19)-L19-Q19 -> -1
B20: 1111066 | C20: ชิฟฟอนแยกชิ้น สตอเบอรี่ | D20: ='เย็น '!D20+เช้า!D20+บ่าย!D20 -> 0 | E20: ='เย็น '!E20+เช้า!E20+บ่าย!E20 -> 0 | F20: ='เย็น '!F20+เช้า!F20+บ่าย!F20 -> 0 | G20: ='เย็น '!G20+เช้า!G20+บ่าย!G20 -> 1 | H20: ='เย็น '!H20+เช้า!H20+บ่าย!H20 -> 0 | I20: ='เย็น '!I20+เช้า!I20+บ่าย!I20 -> 0 | J20: ='เย็น '!J20+เช้า!J20+บ่าย!J20 -> 0 | K20: ='เย็น '!K20+เช้า!K20+บ่าย!K20 -> 0 | L20: =SUM(D20:K20) -> 1 | M20: 11 | R20: =(M20+N20+O20+P20)-L20-Q20 -> 10
B21: 1111067 | C21: ชิฟฟอนแยกชิ้น มะพร้าว | D21: ='เย็น '!D21+เช้า!D21+บ่าย!D21 -> 3 | E21: ='เย็น '!E21+เช้า!E21+บ่าย!E21 -> 0 | F21: ='เย็น '!F21+เช้า!F21+บ่าย!F21 -> 0 | G21: ='เย็น '!G21+เช้า!G21+บ่าย!G21 -> 0 | H21: ='เย็น '!H21+เช้า!H21+บ่าย!H21 -> 5 | I21: ='เย็น '!I21+เช้า!I21+บ่าย!I21 -> 0 | J21: ='เย็น '!J21+เช้า!J21+บ่าย!J21 -> 0 | K21: ='เย็น '!K21+เช้า!K21+บ่าย!K21 -> 0 | L21: =SUM(D21:K21) -> 8 | M21: 8 | R21: =(M21+N21+O21+P21)-L21-Q21 -> 0
B22: 1111068 | C22: ชิฟฟอนแยกชิ้น เนย | D22: ='เย็น '!D22+เช้า!D22+บ่าย!D22 -> 0 | E22: ='เย็น '!E22+เช้า!E22+บ่าย!E22 -> 0 | F22: ='เย็น '!F22+เช้า!F22+บ่าย!F22 -> 0 | G22: ='เย็น '!G22+เช้า!G22+บ่าย!G22 -> 0 | H22: ='เย็น '!H22+เช้า!H22+บ่าย!H22 -> 0 | I22: ='เย็น '!I22+เช้า!I22+บ่าย!I22 -> 0 | J22: ='เย็น '!J22+เช้า!J22+บ่าย!J22 -> 0 | K22: ='เย็น '!K22+เช้า!K22+บ่าย!K22 -> 0 | L22: =SUM(D22:K22) -> 0 | M22: 38 | R22: =(M22+N22+O22+P22)-L22-Q22 -> 38
B23: 1111069 | C23: ชิฟฟอนแยกชิ้น บลูเบอรี่ | D23: ='เย็น '!D23+เช้า!D23+บ่าย!D23 -> 0 | E23: ='เย็น '!E23+เช้า!E23+บ่าย!E23 -> 0 | F23: ='เย็น '!F23+เช้า!F23+บ่าย!F23 -> 0 | G23: ='เย็น '!G23+เช้า!G23+บ่าย!G23 -> 0 | H23: ='เย็น '!H23+เช้า!H23+บ่าย!H23 -> 0 | I23: ='เย็น '!I23+เช้า!I23+บ่าย!I23 -> 0 | J23: ='เย็น '!J23+เช้า!J23+บ่าย!J23 -> 0 | K23: ='เย็น '!K23+เช้า!K23+บ่าย!K23 -> 0 | L23: =SUM(D23:K23) -> 0 | R23: =(M23+N23+O23+P23)-L23-Q23 -> 0
B24: 1111070 | C24: ชิฟฟอนแยกชิ้น ทุเรียน | D24: ='เย็น '!D24+เช้า!D24+บ่าย!D24 -> 0 | E24: ='เย็น '!E24+เช้า!E24+บ่าย!E24 -> 0 | F24: ='เย็น '!F24+เช้า!F24+บ่าย!F24 -> 0 | G24: ='เย็น '!G24+เช้า!G24+บ่าย!G24 -> 0 | H24: ='เย็น '!H24+เช้า!H24+บ่าย!H24 -> 0 | I24: ='เย็น '!I24+เช้า!I24+บ่าย!I24 -> 0 | J24: ='เย็น '!J24+เช้า!J24+บ่าย!J24 -> 0 | K24: ='เย็น '!K24+เช้า!K24+บ่าย!K24 -> 0 | L24: =SUM(D24:K24) -> 0 | M24: 8 | R24: =(M24+N24+O24+P24)-L24-Q24 -> 8
B25: 1111071 | C25: ชิฟฟอนแยกชิ้น ตาล | D25: ='เย็น '!D25+เช้า!D25+บ่าย!D25 -> 0 | E25: ='เย็น '!E25+เช้า!E25+บ่าย!E25 -> 0 | F25: ='เย็น '!F25+เช้า!F25+บ่าย!F25 -> 0 | G25: ='เย็น '!G25+เช้า!G25+บ่าย!G25 -> 0 | H25: ='เย็น '!H25+เช้า!H25+บ่าย!H25 -> 0 | I25: ='เย็น '!I25+เช้า!I25+บ่าย!I25 -> 0 | J25: ='เย็น '!J25+เช้า!J25+บ่าย!J25 -> 0 | K25: ='เย็น '!K25+เช้า!K25+บ่าย!K25 -> 0 | L25: =SUM(D25:K25) -> 0 | R25: =(M25+N25+O25+P25)-L25-Q25 -> 0
B26: 1111074 | C26: ชิฟฟอนไส้แยมแยกชิ้น มะพร้าว | D26: ='เย็น '!D26+เช้า!D26+บ่าย!D26 -> 0 | E26: ='เย็น '!E26+เช้า!E26+บ่าย!E26 -> 0 | F26: ='เย็น '!F26+เช้า!F26+บ่าย!F26 -> 0 | G26: ='เย็น '!G26+เช้า!G26+บ่าย!G26 -> 2 | H26: ='เย็น '!H26+เช้า!H26+บ่าย!H26 -> 2 | I26: ='เย็น '!I26+เช้า!I26+บ่าย!I26 -> 0 | J26: ='เย็น '!J26+เช้า!J26+บ่าย!J26 -> 0 | K26: ='เย็น '!K26+เช้า!K26+บ่าย!K26 -> 0 | L26: =SUM(D26:K26) -> 4 | M26: 11 | R26: =(M26+N26+O26+P26)-L26-Q26 -> 7
B27: 1111075 | C27: ชิฟฟอนไส้แยมแยกชิ้น สตอเบอรี่ | D27: ='เย็น '!D27+เช้า!D27+บ่าย!D27 -> 0 | E27: ='เย็น '!E27+เช้า!E27+บ่าย!E27 -> 0 | F27: ='เย็น '!F27+เช้า!F27+บ่าย!F27 -> 0 | G27: ='เย็น '!G27+เช้า!G27+บ่าย!G27 -> 1 | H27: ='เย็น '!H27+เช้า!H27+บ่าย!H27 -> 2 | I27: ='เย็น '!I27+เช้า!I27+บ่าย!I27 -> 0 | J27: ='เย็น '!J27+เช้า!J27+บ่าย!J27 -> 0 | K27: ='เย็น '!K27+เช้า!K27+บ่าย!K27 -> 0 | L27: =SUM(D27:K27) -> 3 | R27: =(M27+N27+O27+P27)-L27-Q27 -> -3
B28: 1111076 | C28: ชิฟฟอนไส้แยมแยกชิ้น ส้ม | D28: ='เย็น '!D28+เช้า!D28+บ่าย!D28 -> 0 | E28: ='เย็น '!E28+เช้า!E28+บ่าย!E28 -> 0 | F28: ='เย็น '!F28+เช้า!F28+บ่าย!F28 -> 0 | G28: ='เย็น '!G28+เช้า!G28+บ่าย!G28 -> 1 | H28: ='เย็น '!H28+เช้า!H28+บ่าย!H28 -> 2 | I28: ='เย็น '!I28+เช้า!I28+บ่าย!I28 -> 0 | J28: ='เย็น '!J28+เช้า!J28+บ่าย!J28 -> 0 | K28: ='เย็น '!K28+เช้า!K28+บ่าย!K28 -> 0 | L28: =SUM(D28:K28) -> 3 | M28: 2 | R28: =(M28+N28+O28+P28)-L28-Q28 -> -1
B29: 1111077 | C29: ชิฟฟอนไส้แยมแยกชิ้น บลูเบอรี่ | D29: ='เย็น '!D29+เช้า!D29+บ่าย!D29 -> 0 | E29: ='เย็น '!E29+เช้า!E29+บ่าย!E29 -> 0 | F29: ='เย็น '!F29+เช้า!F29+บ่าย!F29 -> 0 | G29: ='เย็น '!G29+เช้า!G29+บ่าย!G29 -> 1 | H29: ='เย็น '!H29+เช้า!H29+บ่าย!H29 -> 2 | I29: ='เย็น '!I29+เช้า!I29+บ่าย!I29 -> 0 | J29: ='เย็น '!J29+เช้า!J29+บ่าย!J29 -> 0 | K29: ='เย็น '!K29+เช้า!K29+บ่าย!K29 -> 0 | L29: =SUM(D29:K29) -> 3 | R29: =(M29+N29+O29+P29)-L29-Q29 -> -3
B30: 1111078 | C30: ชิฟฟอนไส้แยมแยกชิ้น นมชมพู | D30: ='เย็น '!D30+เช้า!D30+บ่าย!D30 -> 0 | E30: ='เย็น '!E30+เช้า!E30+บ่าย!E30 -> 0 | F30: ='เย็น '!F30+เช้า!F30+บ่าย!F30 -> 0 | G30: ='เย็น '!G30+เช้า!G30+บ่าย!G30 -> 1 | H30: ='เย็น '!H30+เช้า!H30+บ่าย!H30 -> 2 | I30: ='เย็น '!I30+เช้า!I30+บ่าย!I30 -> 0 | J30: ='เย็น '!J30+เช้า!J30+บ่าย!J30 -> 0 | K30: ='เย็น '!K30+เช้า!K30+บ่าย!K30 -> 0 | L30: =SUM(D30:K30) -> 3 | M30: 4 | R30: =(M30+N30+O30+P30)-L30-Q30 -> 1
B31: 1111079 | C31: ชิฟฟอนไส้แยมแยกชิ้น ชอคโกแลต | D31: ='เย็น '!D31+เช้า!D31+บ่าย!D31 -> 0 | E31: ='เย็น '!E31+เช้า!E31+บ่าย!E31 -> 0 | F31: ='เย็น '!F31+เช้า!F31+บ่าย!F31 -> 0 | G31: ='เย็น '!G31+เช้า!G31+บ่าย!G31 -> 1 | H31: ='เย็น '!H31+เช้า!H31+บ่าย!H31 -> 1 | I31: ='เย็น '!I31+เช้า!I31+บ่าย!I31 -> 0 | J31: ='เย็น '!J31+เช้า!J31+บ่าย!J31 -> 0 | K31: ='เย็น '!K31+เช้า!K31+บ่าย!K31 -> 0 | L31: =SUM(D31:K31) -> 2 | M31: 10 | R31: =(M31+N31+O31+P31)-L31-Q31 -> 8
B32: 1111080 | C32: ชิฟฟอนไส้แยมแยกชิ้น ฝอยทอง | D32: ='เย็น '!D32+เช้า!D32+บ่าย!D32 -> 0 | E32: ='เย็น '!E32+เช้า!E32+บ่าย!E32 -> 0 | F32: ='เย็น '!F32+เช้า!F32+บ่าย!F32 -> 0 | G32: ='เย็น '!G32+เช้า!G32+บ่าย!G32 -> 1 | H32: ='เย็น '!H32+เช้า!H32+บ่าย!H32 -> 1 | I32: ='เย็น '!I32+เช้า!I32+บ่าย!I32 -> 0 | J32: ='เย็น '!J32+เช้า!J32+บ่าย!J32 -> 0 | K32: ='เย็น '!K32+เช้า!K32+บ่าย!K32 -> 0 | L32: =SUM(D32:K32) -> 2 | M32: 2 | R32: =(M32+N32+O32+P32)-L32-Q32 -> 0
B33: 1111081 | C33: ชิฟฟอนไส้แยมแยกชิ้น วนิลา | D33: ='เย็น '!D33+เช้า!D33+บ่าย!D33 -> 0 | E33: ='เย็น '!E33+เช้า!E33+บ่าย!E33 -> 0 | F33: ='เย็น '!F33+เช้า!F33+บ่าย!F33 -> 0 | G33: ='เย็น '!G33+เช้า!G33+บ่าย!G33 -> 0 | H33: ='เย็น '!H33+เช้า!H33+บ่าย!H33 -> 1 | I33: ='เย็น '!I33+เช้า!I33+บ่าย!I33 -> 0 | J33: ='เย็น '!J33+เช้า!J33+บ่าย!J33 -> 0 | K33: ='เย็น '!K33+เช้า!K33+บ่าย!K33 -> 0 | L33: =SUM(D33:K33) -> 1 | M33: 10 | R33: =(M33+N33+O33+P33)-L33-Q33 -> 9
B34: 1111082 | C34: ชิฟฟอนไส้แยมแยกชิ้น ใบเตย | D34: ='เย็น '!D34+เช้า!D34+บ่าย!D34 -> 0 | E34: ='เย็น '!E34+เช้า!E34+บ่าย!E34 -> 0 | F34: ='เย็น '!F34+เช้า!F34+บ่าย!F34 -> 0 | G34: ='เย็น '!G34+เช้า!G34+บ่าย!G34 -> 0 | H34: ='เย็น '!H34+เช้า!H34+บ่าย!H34 -> 1 | I34: ='เย็น '!I34+เช้า!I34+บ่าย!I34 -> 0 | J34: ='เย็น '!J34+เช้า!J34+บ่าย!J34 -> 0 | K34: ='เย็น '!K34+เช้า!K34+บ่าย!K34 -> 0 | L34: =SUM(D34:K34) -> 1 | M34: 10 | R34: =(M34+N34+O34+P34)-L34-Q34 -> 9
B35: 1111083 | C35: ชิฟฟอนไส้แยมแยกชิ้น เมล่อน | D35: ='เย็น '!D35+เช้า!D35+บ่าย!D35 -> 0 | E35: ='เย็น '!E35+เช้า!E35+บ่าย!E35 -> 0 | F35: ='เย็น '!F35+เช้า!F35+บ่าย!F35 -> 0 | G35: ='เย็น '!G35+เช้า!G35+บ่าย!G35 -> 0 | H35: ='เย็น '!H35+เช้า!H35+บ่าย!H35 -> 1 | I35: ='เย็น '!I35+เช้า!I35+บ่าย!I35 -> 0 | J35: ='เย็น '!J35+เช้า!J35+บ่าย!J35 -> 0 | K35: ='เย็น '!K35+เช้า!K35+บ่าย!K35 -> 0 | L35: =SUM(D35:K35) -> 1 | M35: 10 | R35: =(M35+N35+O35+P35)-L35-Q35 -> 9
B36: ชิฟฟอนไส้แยม 6 ชิ้น
B37: 1111009 | C37: ชิฟฟอนไส้แยมรวมรส 6 ชิ้น | D37: ='เย็น '!D37+เช้า!D37+บ่าย!D37 -> 0 | E37: ='เย็น '!E37+เช้า!E37+บ่าย!E37 -> 3 | F37: ='เย็น '!F37+เช้า!F37+บ่าย!F37 -> 10 | G37: ='เย็น '!G37+เช้า!G37+บ่าย!G37 -> 9 | H37: ='เย็น '!H37+เช้า!H37+บ่าย!H37 -> 0 | I37: ='เย็น '!I37+เช้า!I37+บ่าย!I37 -> 0 | J37: ='เย็น '!J37+เช้า!J37+บ่าย!J37 -> 0 | K37: ='เย็น '!K37+เช้า!K37+บ่าย!K37 -> 0 | L37: =SUM(D37:K37) -> 22 | M37: 19 | R37: =(M37+N37+O37+P37)-L37-Q37 -> -3
B38: 1111020 | C38: ชิฟฟอนไส้แยมฝอยทอง 6 ชิ้น | D38: ='เย็น '!D38+เช้า!D38+บ่าย!D38 -> 0 | E38: ='เย็น '!E38+เช้า!E38+บ่าย!E38 -> 0 | F38: ='เย็น '!F38+เช้า!F38+บ่าย!F38 -> 0 | G38: ='เย็น '!G38+เช้า!G38+บ่าย!G38 -> 0 | H38: ='เย็น '!H38+เช้า!H38+บ่าย!H38 -> 0 | I38: ='เย็น '!I38+เช้า!I38+บ่าย!I38 -> 0 | J38: ='เย็น '!J38+เช้า!J38+บ่าย!J38 -> 0 | K38: ='เย็น '!K38+เช้า!K38+บ่าย!K38 -> 0 | L38: =SUM(D38:K38) -> 0 | R38: =(M38+N38+O38+P38)-L38-Q38 -> 0
B39: ชิฟฟอนไส้แยม 3 ชิ้น
B40: 1111008 | C40: ชิฟฟอนไส้แยมรวมรส 3 ชิ้น | D40: ='เย็น '!D40+เช้า!D40+บ่าย!D40 -> 6 | E40: ='เย็น '!E40+เช้า!E40+บ่าย!E40 -> 3 | F40: ='เย็น '!F40+เช้า!F40+บ่าย!F40 -> 0 | G40: ='เย็น '!G40+เช้า!G40+บ่าย!G40 -> 59 | H40: ='เย็น '!H40+เช้า!H40+บ่าย!H40 -> 34 | I40: ='เย็น '!I40+เช้า!I40+บ่าย!I40 -> 0 | J40: ='เย็น '!J40+เช้า!J40+บ่าย!J40 -> 0 | K40: ='เย็น '!K40+เช้า!K40+บ่าย!K40 -> 0 | L40: =SUM(D40:K40) -> 102 | M40: 100 | R40: =(M40+N40+O40+P40)-L40-Q40 -> -2
B41: 1111017 | C41: ชิฟฟอนไส้แยมบลูเบอรี่ 3 ชิ้น | D41: ='เย็น '!D41+เช้า!D41+บ่าย!D41 -> 0 | E41: ='เย็น '!E41+เช้า!E41+บ่าย!E41 -> 0 | F41: ='เย็น '!F41+เช้า!F41+บ่าย!F41 -> 0 | G41: ='เย็น '!G41+เช้า!G41+บ่าย!G41 -> 0 | H41: ='เย็น '!H41+เช้า!H41+บ่าย!H41 -> 0 | I41: ='เย็น '!I41+เช้า!I41+บ่าย!I41 -> 0 | J41: ='เย็น '!J41+เช้า!J41+บ่าย!J41 -> 0 | K41: ='เย็น '!K41+เช้า!K41+บ่าย!K41 -> 0 | L41: =SUM(D41:K41) -> 0 | R41: =(M41+N41+O41+P41)-L41-Q41 -> 0
...
