Workbook

Sheet เย็น 
B1: ยอดจริง ออนไลน์ วันที่ - เย็น
K2: ยอดรวมผลิต
K3: จำนวน
B4: รหัสสินค้า | C4: สินค้า | D4: ปณ | E4: ชอปปี้ | F4: ลาซาด้า | G4: ติ๊กตอก | H4: ติ๊กตอก2 | I4: ติ๊กตอก3 | J4: ชอยส์ | K4: (กล่อง)
B6: ชิฟฟอนรวมรส
B7: 1111002 | C7: ชิฟฟอนรวมรส 8 ชิ้น | K7: =SUM(D7:J7) -> 0
C8: ชิฟฟอนแบบกล่องสุ่มอะไรก็ได้ที่มี | K8: =SUM(D8:J8) -> 0
B9: 1111084 | C9: ชิฟฟอน 8 ชิ้น กาแฟล้วน | K9: =SUM(D9:J9) -> 0
B10: 1111085 | C10: ชิฟฟอน 8 ชิ้น บลูเบอรี่ล้วน | K10: =SUM(D10:J10) -> 0
B11: 1111086 | C11: ชิฟฟอน 8 ชิ้น มะพร้าวล้วน | K11: =SUM(D11:J11) -> 0
B12: 1111087 | C12: ชิฟฟอน 8 ชิ้น สตอเบอรี่ล้วน | K12: =SUM(D12:J12) -> 0
B13: 1111088 | C13: ชิฟฟอน 8 ชิ้น ส้มล้วน | K13: =SUM(D13:J13) -> 0
B14: 1111089 | C14: ชิฟฟอน 8 ชิ้น เนยล้วน | K14: =SUM(D14:J14) -> 0
B15: 1111090 | C15: ชิฟฟอน 8 ชิ้น เผือกล้วน | K15: =SUM(D15:J15) -> 0
B16: 1111091 | C16: ชิฟฟอน 8 ชิ้น ใบเตยล้วน | K16: =SUM(D16:J16) -> 0
B17: 1111092 | C17: ชิฟฟอน 8 ชิ้น กล้วยหอม | K17: =SUM(D17:J17) -> 0
B18: 1111093 | C18: ชิฟฟอน 8 ชิ้น โกโก้ล้วน | K18: =SUM(D18:J18) -> 0
B19: 1111094 | C19: ชิฟฟอน 8 ชิ้น ชาไทยล้วน | K19: =SUM(D19:J19) -> 0
B20: 1111095 | C20: ชิฟฟอน 8 ชิ้น ชาเขียวล้วน | K20: =SUM(D20:J20) -> 0
... B66: 1111010 | C66: ชิฟฟอนไส้แยมแยกชิ้น คละรส | K66: =SUM(D66:J66) -> 0
C67: รวม | K67: =SUM(D67:I67) -> 0
B68: ชิฟฟอนไส้แยม 6 ชิ้น
B69: 1111009 | C69: ชิฟฟอนไส้แยมรวมรส 6 ชิ้น | K69: =SUM(D69:J69) -> 0
B70: 1111023 | C70: ชิฟฟอนไส้แยมรสสตอเบอร์รี่ล้วน 6 ชิ้น | K70: =SUM(D70:J70) -> 0
B71: 1111016 | C71: ชิฟฟอนไส้แยมรสมะพร้าวล้วน 6 ชิ้น | K71: =SUM(D71:J71) -> 0
B72: 1111014 | C72: ชิฟฟอนไส้แยมรสช็อกโกแลตนูเทลล่าล้วน 6 ชิ้น | K72: =SUM(D72:J72) -> 0
B73: 1111025 | C73: ชิฟฟอนไส้แยมรสส้มล้วน 6 ชิ้น | K73: =SUM(D73:J73) -> 0
B74: 1111018 | C74: ชิฟฟอนไส้แยมรสบลูเบอร์รี่ล้วน 6 ชิ้น | K74: =SUM(D74:J74) -> 0
B75: 1111012 | C75: ชิฟฟอนไส้แยมรสนมชมพูฮอกไกโดล้วน 6 ชิ้น | K75: =SUM(D75:J75) -> 0
B76: 1111020 | C76: ชิฟฟอนไส้แยมฝอยทองไส้ทะลัก 6 ชิ้น | K76: =SUM(D76:J76) -> 0
C77: รวม
B78: ชิฟฟอนไส้แยม 3 ชิ้น
B79: 1111022 | C79: ชิฟฟอนไส้แยมรสสตอเบอร์รี่ล้วน 3 ชิ้น | K79: =SUM(D79:J79) -> 0
B80: 1111015 | C80: ชิฟฟอนไส้แยมรสมะพร้าวล้วน 3 ชิ้น | K80: =SUM(D80:J80) -> 0
B81: 1111013 | C81: ชิฟฟอนไส้แยมรสช็อกโกแลตนูเทลล่าล้วน 3 ชิ้น | K81: =SUM(D81:J81) -> 0
B82: 1111024 | C82: ชิฟฟอนไส้แยมรสส้มล้วน 3 ชิ้น | K82: =SUM(D82:J82) -> 0
B83: 1111017 | C83: ชิฟฟอนไส้แยมรสบลูเบอร์รี่ล้วน 3 ชิ้น | K83: =SUM(D83:J83) -> 0
B84: 1111011 | C84: ชิฟฟอนไส้แยมรสนมชมพูฮอกไกโดล้วน 3 ชิ้น | K84: =SUM(D84:J84) -> 0
B85: 1111019 | C85: ชิฟฟอนไส้แยมฝอยทองไส้ทะลัก 3 ชิ้น | K85: =SUM(D85:J85) -> 0
B86: 1113081 | C86: ชิฟฟอนไส้แยม วนิลา/ใบเตย/เมล่อน | K86: =SUM(D86:J86) -> 0
...

Sheet เช้า 
B1: ยอดจริง ออนไลน์ วันที่ 1/12/2567 - เช้า
K2: ยอดรวมผลิต
K3: จำนวน
B4: รหัสสินค้า | C4: สินค้า | D4: ปณ | E4: ชอปปี้ | F4: ลาซาด้า | G4: ติ๊กตอก | H4: ติ๊กตอก2 | I4: ติ๊กตอก3 | J4: ชอยส์ | K4: (กล่อง)
B6: ชิฟฟอนรวมรส
B7: 1111002 | C7: ชิฟฟอนรวมรส 8 ชิ้น | D7: 30 | E7: 52 | F7: 70 | G7: 2 | K7: =SUM(D7:J7) -> 154
C8: ชิฟฟอนแบบกล่องสุ่มอะไรก็ได้ที่มี | K8: =SUM(D8:J8) -> 0
B9: 1111084 | C9: ชิฟฟอน 8 ชิ้น กาแฟล้วน | K9: =SUM(D9:J9) -> 0
B10: 1111085 | C10: ชิฟฟอน 8 ชิ้น บลูเบอรี่ล้วน | K10: =SUM(D10:J10) -> 0
B11: 1111086 | C11: ชิฟฟอน 8 ชิ้น มะพร้าวล้วน | K11: =SUM(D11:J11) -> 0
B12: 1111087 | C12: ชิฟฟอน 8 ชิ้น สตอเบอรี่ล้วน | K12: =SUM(D12:J12) -> 0
B13: 1111088 | C13: ชิฟฟอน 8 ชิ้น ส้มล้วน | K13: =SUM(D13:J13) -> 0
B14: 1111089 | C14: ชิฟฟอน 8 ชิ้น เนยล้วน | K14: =SUM(D14:J14) -> 0
B15: 1111090 | C15: ชิฟฟอน 8 ชิ้น เผือกล้วน | K15: =SUM(D15:J15) -> 0
B16: 1111091 | C16: ชิฟฟอน 8 ชิ้น ใบเตยล้วน | K16: =SUM(D16:J16) -> 0
B17: 1111092 | C17: ชิฟฟอน 8 ชิ้น กล้วยหอม | K17: =SUM(D17:J17) -> 0
B18: 1111093 | C18: ชิฟฟอน 8 ชิ้น โกโก้ล้วน | K18: =SUM(D18:J18) -> 0
B19: 1111094 | C19: ชิฟฟอน 8 ชิ้น ชาไทยล้วน | K19: =SUM(D19:J19) -> 0
B20: 1111095 | C20: ชิฟฟอน 8 ชิ้น ชาเขียวล้วน | K20: =SUM(D20:J20) -> 0
... B24: 1111043 | C24: ชิฟฟอน 8 ชิ้น มะลิ | K24: =SUM(D24:J24) -> 0
B25: 1111056 | C25: ชิฟฟอน 8 ชิ้น รวมรสยอดฮิต | E25: 4 | F25: 19 | G25: 1 | K25: =SUM(D25:J25) -> 24
B26: 1004055 | C26: ชิฟฟอนรวมรส 4 ชิ้น | E26: 6 | G26: 74 | H26: 3 | K26: =SUM(D26:J26) -> 83
B27: 1004055 | C27: ชิฟฟอน 4 ชิ้น โกโก้ล้วน | K27: =SUM(D27:J27) -> 0
B28: 1004055 | C28: ชิฟฟอน 4 ชิ้น มะพร้าวล้วน | K28: =SUM(D28:J28) -> 0
B29: 1004055 | C29: ชิฟฟอน 4 ชิ้น เนยล้วน | K29: =SUM(D29:J29) -> 0
B30: 1004055 | C30: ชิฟฟอน 4 ชิ้น กาแฟล้วน | K30: =SUM(D30:J30) -> 0
B31: 1004055 | C31: ชิฟฟอน 4 ชิ้น ใบเตยล้วน | K31: =SUM(D31:J31) -> 0
B32: 1004055 | C32: ชิฟฟอน 4 ชิ้น บลูเบอร์รี่ล้วน | K32: =SUM(D32:J32) -> 0
B33: 1004055 | C33: ชิฟฟอน 4 ชิ้น ส้มล้วน | K33: =SUM(D33:J33) -> 0
B34: 1004055 | C34: ชิฟฟอน 4 ชิ้น เผือกล้วน | K34: =SUM(D34:J34) -> 0
B35: 1004055 | C35: ชิฟฟอน 4 ชิ้น สตอเบอรี่ล้วน | K35: =SUM(D35:J35) -> 0
B36: 1004055 | C36: ชิฟฟอน 4 ชิ้น กล้วยหอมล้วน | K36: =SUM(D36:J36) -> 0
B37: 1004055 | C37: ชิฟฟอน 4 ชิ้น ชาเขียวล้วน | K37: =SUM(D37:J37) -> 0
B38: 1004055 | C38: ชิฟฟอน 4 ชิ้น ชาไทยล้วน | K38: =SUM(D38:J38) -> 0
B39: 1004055 | C39: ชิฟฟอน 4 ชิ้น สับปะรดล้วน | K39: =SUM(D39:J39) -> 0
B40: 1111057 | C40: ชิฟฟอนแยกชิ้น กาแฟ | F40: 1 | G40: 1 | K40: =SUM(D40:J40) -> 2
B41: 1111058 | C41: ชิฟฟอนแยกชิ้น ชาเขียว | F41: 1 | G41: 1 | K41: =SUM(D41:J41) -> 2
B42: 1111059 | C42: ชิฟฟอนแยกชิ้น ใบเตย | F42: 1 | G42: 1 | K42: =SUM(D42:J42) -> 2
B43: 1111060 | C43: ชิฟฟอนแยกชิ้น กล้วยหอม | F43: 1 | G43: 1 | K43: =SUM(D43:J43) -> 2
B44: 1111061 | C44: ชิฟฟอนแยกชิ้น ชาไทย | G44: 1 | K44: =SUM(D44:J44) -> 1
...

Sheet บ่าย
B1: ยอดจริง ออนไลน์ วันที่ - บ่าย
K2: ยอดรวมผลิต
K3: จำนวน
B4: รหัสสินค้า | C4: สินค้า | D4: ปณ | E4: ชอปปี้ | F4: ลาซาด้า | G4: ติ๊กตอก | H4: ติ๊กตอก 2 | I4: ติ๊กตอก3 | J4: ชอยส์ | K4: (กล่อง)
B6: ชิฟฟอนรวมรส
B7: 1111002 | C7: ชิฟฟอนรวมรส 8 ชิ้น | K7: =SUM(D7:J7) -> 0
C8: ชิฟฟอนแบบกล่องสุ่มอะไรก็ได้ที่มี | K8: =SUM(D8:J8) -> 0
B9: 1111084 | C9: ชิฟฟอน 8 ชิ้น กาแฟล้วน | K9: =SUM(D9:J9) -> 0
B10: 1111085 | C10: ชิฟฟอน 8 ชิ้น บลูเบอรี่ล้วน | K10: =SUM(D10:J10) -> 0
B11: 1111086 | C11: ชิฟฟอน 8 ชิ้น มะพร้าวล้วน | K11: =SUM(D11:J11) -> 0
B12: 1111087 | C12: ชิฟฟอน 8 ชิ้น สตอเบอรี่ล้วน | K12: =SUM(D12:J12) -> 0
B13: 1111088 | C13: ชิฟฟอน 8 ชิ้น ส้มล้วน | K13: =SUM(D13:J13) -> 0
B14: 1111089 | C14: ชิฟฟอน 8 ชิ้น เนยล้วน | K14: =SUM(D14:J14) -> 0
B15: 1111090 | C15: ชิฟฟอน 8 ชิ้น เผือกล้วน | K15: =SUM(D15:J15) -> 0
B16: 1111091 | C16: ชิฟฟอน 8 ชิ้น ใบเตยล้วน | K16: =SUM(D16:J16) -> 0
B17: 1111092 | C17: ชิฟฟอน 8 ชิ้น กล้วยหอม | K17: =SUM(D17:J17) -> 0
B18: 1111093 | C18: ชิฟฟอน 8 ชิ้น โกโก้ล้วน | K18: =SUM(D18:J18) -> 0
B19: 1111094 | C19: ชิฟฟอน 8 ชิ้น ชาไทยล้วน | K19: =SUM(D19:J19) -> 0
B20: 1111095 | C20: ชิฟฟอน 8 ชิ้น ชาเขียวล้วน | K20: =SUM(D20:J20) -> 0
... B66: 1111010 | C66: ชิฟฟอนไส้แยมแยกชิ้น คละรส | K66: =SUM(D66:J66) -> 0
C67: รวม
B68: ชิฟฟอนไส้แยม 6 ชิ้น
B69: 1111009 | C69: ชิฟฟอนไส้แยมรวมรส 6 ชิ้น | K69: =SUM(D69:J69) -> 0
B70: 1111023 | C70: ชิฟฟอนไส้แยมรสสตอเบอร์รี่ล้วน 6 ชิ้น | K70: =SUM(D70:J70) -> 0
B71: 1111016 | C71: ชิฟฟอนไส้แยมรสมะพร้าวล้วน 6 ชิ้น | K71: =SUM(D71:J71) -> 0
B72: 1111014 | C72: ชิฟฟอนไส้แยมรสช็อกโกแลตนูเทลล่าล้วน 6 ชิ้น | K72: =SUM(D72:J72) -> 0
B73: 1111025 | C73: ชิฟฟอนไส้แยมรสส้มล้วน 6 ชิ้น | K73: =SUM(D73:J73) -> 0
B74: 1111018 | C74: ชิฟฟอนไส้แยมรสบลูเบอร์รี่ล้วน 6 ชิ้น | K74: =SUM(D74:J74) -> 0
B75: 1111012 | C75: ชิฟฟอนไส้แยมรสนมชมพูฮอกไกโดล้วน 6 ชิ้น | K75: =SUM(D75:J75) -> 0
B76: 1111020 | C76: ชิฟฟอนไส้แยมฝอยทองไส้ทะลัก 6 ชิ้น | K76: =SUM(D76:J76) -> 0
C77: รวม
B78: ชิฟฟอนไส้แยม 3 ชิ้น
B79: 1111022 | C79: ชิฟฟอนไส้แยมรสสตอเบอร์รี่ล้วน 3 ชิ้น | K79: =SUM(D79:J79) -> 0
B80: 1111015 | C80: ชิฟฟอนไส้แยมรสมะพร้าวล้วน 3 ชิ้น | K80: =SUM(D80:J80) -> 0
B81: 1111013 | C81: ชิฟฟอนไส้แยมรสช็อกโกแลตนูเทลล่าล้วน 3 ชิ้น | K81: =SUM(D81:J81) -> 0
B82: 1111024 | C82: ชิฟฟอนไส้แยมรสส้มล้วน 3 ชิ้น | K82: =SUM(D82:J82) -> 0
B83: 1111017 | C83: ชิฟฟอนไส้แยมรสบลูเบอร์รี่ล้วน 3 ชิ้น | K83: =SUM(D83:J83) -> 0
B84: 1111011 | C84: ชิฟฟอนไส้แยมรสนมชมพูฮอกไกโดล้วน 3 ชิ้น | K84: =SUM(D84:J84) -> 0
B85: 1111019 | C85: ชิฟฟอนไส้แยมฝอยทองไส้ทะลัก 3 ชิ้น | K85: =SUM(D85:J85) -> 0
B86: 1113081 | C86: ชิฟฟอนไส้แยม วนิลา/ใบเตย/เมล่อน | K86: =SUM(D86:J86) -> 0
...

Sheet รวม
B1: ยอดจริง ออนไลน์ วันที่ 1/12/2567 รวม
K2: ยอดรวมผลิต | L2: ยอดฟอแคส | M2: ค้างรับ | N2: ยอดสตอค | O2: รวม
K3: จำนวน
B4: รหัสสินค้า | C4: สินค้า | D4: ปณ | E4: ชอปปี้ | F4: ลาซาด้า | G4: ติ๊กตอก | H4: ติ๊กตอก2 | I4: ติ๊กตอก3 | J4: ชอยส์ | K4: (กล่อง)
B6: ชิฟฟอนรวมรส
B7: 1111002 | C7: ชิฟฟอนรวมรส 8 ชิ้น | D7: =บ่าย!D7+'เช้า '!D7+'เย็น '!D7 -> 30 | E7: =บ่าย!E7+'เช้า '!E7+'เย็น '!E7 -> 52 | F7: =บ่าย!F7+'เช้า '!F7+'เย็น '!F7 -> 70 | G7: =บ่าย!G7+'เช้า '!G7+'เย็น '!G7 -> 2 | H7: =บ่าย!H7+'เช้า '!H7+'เย็น '!H7 -> 0 | I7: =บ่าย!I7+'เช้า '!I7+'เย็น '!I7 -> 0 | J7: =บ่าย!J7+'เช้า '!J7+'เย็น '!J7 -> 0 | K7: =SUM(D7:J7) -> 154 | L7: 100 | N7: 4 | O7: =(L7+M7+N7)-K7 -> -50
C8: ชิฟฟอนแบบกล่องสุ่มอะไรก็ได้ที่มี | D8: =บ่าย!D8+'เช้า '!D8+'เย็น '!D8 -> 0 | E8: =บ่าย!E8+'เช้า '!E8+'เย็น '!E8 -> 0 | F8: =บ่าย!F8+'เช้า '!F8+'เย็น '!F8 -> 0 | G8: =บ่าย!G8+'เช้า '!G8+'เย็น '!G8 -> 0 | H8: =บ่าย!H8+'เช้า '!H8+'เย็น '!H8 -> 0 | I8: =บ่าย!I8+'เช้า '!I8+'เย็น '!I8 -> 0 | J8: =บ่าย!J8+'เช้า '!J8+'เย็น '!J8 -> 0 | K8: =SUM(D8:J8) -> 0 | O8: =(L8+M8+N8)-K8 -> 0
B9: 1111084 | C9: ชิฟฟอน 8 ชิ้น กาแฟล้วน | D9: =บ่าย!D9+'เช้า '!D9+'เย็น '!D9 -> 0 | E9: =บ่าย!E9+'เช้า '!E9+'เย็น '!E9 -> 0 | F9: =บ่าย!F9+'เช้า '!F9+'เย็น '!F9 -> 0 | G9: =บ่าย!G9+'เช้า '!G9+'เย็น '!G9 -> 0 | H9: =บ่าย!H9+'เช้า '!H9+'เย็น '!H9 -> 0 | I9: =บ่าย!I9+'เช้า '!I9+'เย็น '!I9 -> 0 | J9: =บ่าย!J9+'เช้า '!J9+'เย็น '!J9 -> 0 | K9: =SUM(D9:J9) -> 0 | O9: =(L9+M9+N9)-K9 -> 0
B10: 1111085 | C10: ชิฟฟอน 8 ชิ้น บลูเบอรี่ล้วน | D10: =บ่าย!D10+'เช้า '!D10+'เย็น '!D10 -> 0 | E10: =บ่าย!E10+'เช้า '!E10+'เย็น '!E10 -> 0 | F10: =บ่าย!F10+'เช้า '!F10+'เย็น '!F10 -> 0 | G10: =บ่าย!G10+'เช้า '!G10+'เย็น '!G10 -> 0 | H10: =บ่าย!H10+'เช้า '!H10+'เย็น '!H10 -> 0 | I10: =บ่าย!I10+'เช้า '!I10+'เย็น '!I10 -> 0 | J10: =บ่าย!J10+'เช้า '!J10+'เย็น '!J10 -> 0 | K10: =SUM(D10:J10) -> 0 | O10: =(L10+M10+N10)-K10 -> 0
B11: 1111086 | C11: ชิฟฟอน 8 ชิ้น มะพร้าวล้วน | D11: =บ่าย!D11+'เช้า '!D11+'เย็น '!D11 -> 0 | E11: =บ่าย!E11+'เช้า '!E11+'เย็น '!E11 -> 0 | F11: =บ่าย!F11+'เช้า '!F11+'เย็น '!F11 -> 0 | G11: =บ่าย!G11+'เช้า '!G11+'เย็น '!G11 -> 0 | H11: =บ่าย!H11+'เช้า '!H11+'เย็น '!H11 -> 0 | I11: =บ่าย!I11+'เช้า '!I11+'เย็น '!I11 -> 0 | J11: =บ่าย!J11+'เช้า '!J11+'เย็น '!J11 -> 0 | K11: =SUM(D11:J11) -> 0 | O11: =(L11+M11+N11)-K11 -> 0
B12: 1111087 | C12: ชิฟฟอน 8 ชิ้น สตอเบอรี่ล้วน | D12: =บ่าย!D12+'เช้า '!D12+'เย็น '!D12 -> 0 | E12: =บ่าย!E12+'เช้า '!E12+'เย็น '!E12 -> 0 | F12: =บ่าย!F12+'เช้า '!F12+'เย็น '!F12 -> 0 | G12: =บ่าย!G12+'เช้า '!G12+'เย็น '!G12 -> 0 | H12: =บ่าย!H12+'เช้า '!H12+'เย็น '!H12 -> 0 | I12: =บ่าย!I12+'เช้า '!I12+'เย็น '!I12 -> 0 | J12: =บ่าย!J12+'เช้า '!J12+'เย็น '!J12 -> 0 | K12: =SUM(D12:J12) -> 0 | O12: =(L12+M12+N12)-K12 -> 0
B13: 1111088 | C13: ชิฟฟอน 8 ชิ้น ส้มล้วน | D13: =บ่าย!D13+'เช้า '!D13+'เย็น '!D13 -> 0 | E13: =บ่าย!E13+'เช้า '!E13+'เย็น '!E13 -> 0 | F13: =บ่าย!F13+'เช้า '!F13+'เย็น '!F13 -> 0 | G13: =บ่าย!G13+'เช้า '!G13+'เย็น '!G13 -> 0 | H13: =บ่าย!H13+'เช้า '!H13+'เย็น '!H13 -> 0 | I13: =บ่าย!I13+'เช้า '!I13+'เย็น '!I13 -> 0 | J13: =บ่าย!J13+'เช้า '!J13+'เย็น '!J13 -> 0 | K13: =SUM(D13:J13) -> 0 | O13: =(L13+M13+N13)-K13 -> 0
B14: 1111089 | C14: ชิฟฟอน 8 ชิ้น เนยล้วน | D14: =บ่าย!D14+'เช้า '!D14+'เย็น '!D14 -> 0 | E14: =บ่าย!E14+'เช้า '!E14+'เย็น '!E14 -> 0 | F14: =บ่าย!F14+'เช้า '!F14+'เย็น '!F14 -> 0 | G14: =บ่าย!G14+'เช้า '!G14+'เย็น '!G14 -> 0 | H14: =บ่าย!H14+'เช้า '!H14+'เย็น '!H14 -> 0 | I14: =บ่าย!I14+'เช้า '!I14+'เย็น '!I14 -> 0 | J14: =บ่าย!J14+'เช้า '!J14+'เย็น '!J14 -> 0 | K14: =SUM(D14:J14) -> 0 | O14: =(L14+M14+N14)-K14 -> 0
B15: 1111090 | C15: ชิฟฟอน 8 ชิ้น เผือกล้วน | D15: =บ่าย!D15+'เช้า '!D15+'เย็น '!D15 -> 0 | E15: =บ่าย!E15+'เช้า '!E15+'เย็น '!E15 -> 0 | F15: =บ่าย!F15+'เช้า '!F15+'เย็น '!F15 -> 0 | G15: =บ่าย!G15+'เช้า '!G15+'เย็น '!G15 -> 0 | H15: =บ่าย!H15+'เช้า '!H15+'เย็น '!H15 -> 0 | I15: =บ่าย!I15+'เช้า '!I15+'เย็น '!I15 -> 0 | J15: =บ่าย!J15+'เช้า '!J15+'เย็น '!J15 -> 0 | K15: =SUM(D15:J15) -> 0 | O15: =(L15+M15+N15)-K15 -> 0
B16: 1111091 | C16: ชิฟฟอน 8 ชิ้น ใบเตยล้วน | D16: =บ่าย!D16+'เช้า '!D16+'เย็น '!D16 -> 0 | E16: =บ่าย!E16+'เช้า '!E16+'เย็น '!E16 -> 0 | F16: =บ่าย!F16+'เช้า '!F16+'เย็น '!F16 -> 0 | G16: =บ่าย!G16+'เช้า '!G16+'เย็น '!G16 -> 0 | H16: =บ่าย!H16+'เช้า '!H16+'เย็น '!H16 -> 0 | I16: =บ่าย!I16+'เช้า '!I16+'เย็น '!I16 -> 0 | J16: =บ่าย!J16+'เช้า '!J16+'เย็น '!J16 -> 0 | K16: =SUM(D16:J16) -> 0 | O16: =(L16+M16+N16)-K16 -> 0
B17: 1111092 | C17: ชิฟฟอน 8 ชิ้น กล้วยหอม | D17: =บ่าย!D17+'เช้า '!D17+'เย็น '!D17 -> 0 | E17: =บ่าย!E17+'เช้า '!E17+'เย็น '!E17 -> 0 | F17: =บ่าย!F17+'เช้า '!F17+'เย็น '!F17 -> 0 | G17: =บ่าย!G17+'เช้า '!G17+'เย็น '!G17 -> 0 | H17: =บ่าย!H17+'เช้า '!H17+'เย็น '!H17 -> 0 | I17: =บ่าย!I17+'เช้า '!I17+'เย็น '!I17 -> 0 | J17: =บ่าย!J17+'เช้า '!J17+'เย็น '!J17 -> 0 | K17: =SUM(D17:J17) -> 0 | O17: =(L17+M17+N17)-K17 -> 0
B18: 1111093 | C18: ชิฟฟอน 8 ชิ้น โกโก้ล้วน | D18: =บ่าย!D18+'เช้า '!D18+'เย็น '!D18 -> 0 | E18: =บ่าย!E18+'เช้า '!E18+'เย็น '!E18 -> 0 | F18: =บ่าย!F18+'เช้า '!F18+'เย็น '!F18 -> 0 | G18: =บ่าย!G18+'เช้า '!G18+'เย็น '!G18 -> 0 | H18: =บ่าย!H18+'เช้า '!H18+'เย็น '!H18 -> 0 | I18: =บ่าย!I18+'เช้า '!I18+'เย็น '!I18 -> 0 | J18: =บ่าย!J18+'เช้า '!J18+'เย็น '!J18 -> 0 | K18: =SUM(D18:J18) -> 0 | O18: =(L18+M18+N18)-K18 -> 0
B19: 1111094 | C19: ชิฟฟอน 8 ชิ้น ชาไทยล้วน | D19: =บ่าย!D19+'เช้า '!D19+'เย็น '!D19 -> 0 | E19: =บ่าย!E19+'เช้า '!E19+'เย็น '!E19 -> 0 | F19: =บ่าย!F19+'เช้า '!F19+'เย็น '!F19 -> 0 | G19: =บ่าย!G19+'เช้า '!G19+'เย็น '!G19 -> 0 | H19: =บ่าย!H19+'เช้า '!H19+'เย็น '!H19 -> 0 | I19: =บ่าย!I19+'เช้า '!I19+'เย็น '!I19 -> 0 | J19: =บ่าย!J19+'เช้า '!J19+'เย็น '!J19 -> 0 | K19: =SUM(D19:J19) -> 0 | O19: =(L19+M19+N19)-K19 -> 0
B20: 1111095 | C20: ชิฟฟอน 8 ชิ้น ชาเขียวล้วน | D20: =บ่าย!D20+'เช้า '!D20+'เย็น '!D20 -> 0 | E20: =บ่าย!E20+'เช้า '!E20+'เย็น '!E20 -> 0 | F20: =บ่าย!F20+'เช้า '!F20+'เย็น '!F20 -> 0 | G20: =บ่าย!G20+'เช้า '!G20+'เย็น '!G20 -> 0 | H20: =บ่าย!H20+'เช้า '!H20+'เย็น '!H20 -> 0 | I20: =บ่าย!I20+'เช้า '!I20+'เย็น '!I20 -> 0 | J20: =บ่าย!J20+'เช้า '!J20+'เย็น '!J20 -> 0 | K20: =SUM(D20:J20) -> 0 | O20: =(L20+M20+N20)-K20 -> 0
... B24: 1111043 | C24: ชิฟฟอน 8 ชิ้น มะลิ | D24: =บ่าย!D24+'เช้า '!D24+'เย็น '!D24 -> 0 | E24: =บ่าย!E24+'เช้า '!E24+'เย็น '!E24 -> 0 | F24: =บ่าย!F24+'เช้า '!F24+'เย็น '!F24 -> 0 | G24: =บ่าย!G24+'เช้า '!G24+'เย็น '!G24 -> 0 | H24: =บ่าย!H24+'เช้า '!H24+'เย็น '!H24 -> 0 | I24: =บ่าย!I24+'เช้า '!I24+'เย็น '!I24 -> 0 | J24: =บ่าย!J24+'เช้า '!J24+'เย็น '!J24 -> 0 | K24: =SUM(D24:J24) -> 0 | O24: =(L24+M24+N24)-K24 -> 0
B25: 1111056 | C25: ชิฟฟอน 8 ชิ้น รวมรสยอดฮิต | D25: =บ่าย!D25+'เช้า '!D25+'เย็น '!D25 -> 0 | E25: =บ่าย!E25+'เช้า '!E25+'เย็น '!E25 -> 4 | F25: =บ่าย!F25+'เช้า '!F25+'เย็น '!F25 -> 19 | G25: =บ่าย!G25+'เช้า '!G25+'เย็น '!G25 -> 1 | H25: =บ่าย!H25+'เช้า '!H25+'เย็น '!H25 -> 0 | I25: =บ่าย!I25+'เช้า '!I25+'เย็น '!I25 -> 0 | J25: =บ่าย!J25+'เช้า '!J25+'เย็น '!J25 -> 0 | K25: =SUM(D25:J25) -> 24 | L25: 15 | N25: 2 | O25: =(L25+M25+N25)-K25 -> -7
B26: 1004055 | C26: ชิฟฟอนรวมรส 4 ชิ้น | D26: =บ่าย!D26+'เช้า '!D26+'เย็น '!D26 -> 0 | E26: =บ่าย!E26+'เช้า '!E26+'เย็น '!E26 -> 6 | F26: =บ่าย!F26+'เช้า '!F26+'เย็น '!F26 -> 0 | G26: =บ่าย!G26+'เช้า '!G26+'เย็น '!G26 -> 74 | H26: =บ่าย!H26+'เช้า '!H26+'เย็น '!H26 -> 3 | I26: =บ่าย!I26+'เช้า '!I26+'เย็น '!I26 -> 0 | J26: =บ่าย!J26+'เช้า '!J26+'เย็น '!J26 -> 0 | K26: =SUM(D26:J26) -> 83 | L26: 100 | N26: 60 | O26: =(L26+M26+N26)-K26 -> 77
B27: 1004055 | C27: ชิฟฟอน 4 ชิ้น โกโก้ล้วน | D27: =บ่าย!D27+'เช้า '!D27+'เย็น '!D27 -> 0 | E27: =บ่าย!E27+'เช้า '!E27+'เย็น '!E27 -> 0 | F27: =บ่าย!F27+'เช้า '!F27+'เย็น '!F27 -> 0 | G27: =บ่าย!G27+'เช้า '!G27+'เย็น '!G27 -> 0 | H27: =บ่าย!H27+'เช้า '!H27+'เย็น '!H27 -> 0 | I27: =บ่าย!I27+'เช้า '!I27+'เย็น '!I27 -> 0 | J27: =บ่าย!J27+'เช้า '!J27+'เย็น '!J27 -> 0 | K27: =SUM(D27:J27) -> 0 | O27: =(L27+M27+N27)-K27 -> 0
B28: 1004055 | C28: ชิฟฟอน 4 ชิ้น มะพร้าวล้วน | D28: =บ่าย!D28+'เช้า '!D28+'เย็น '!D28 -> 0 | E28: =บ่าย!E28+'เช้า '!E28+'เย็น '!E28 -> 0 | F28: =บ่าย!F28+'เช้า '!F28+'เย็น '!F28 -> 0 | G28: =บ่าย!G28+'เช้า '!G28+'เย็น '!G28 -> 0 | H28: =บ่าย!H28+'เช้า '!H28+'เย็น '!H28 -> 0 | I28: =บ่าย!I28+'เช้า '!I28+'เย็น '!I28 -> 0 | J28: =บ่าย!J28+'เช้า '!J28+'เย็น '!J28 -> 0 | K28: =SUM(D28:J28) -> 0 | O28: =(L28+M28+N28)-K28 -> 0
B29: 1004055 | C29: ชิฟฟอน 4 ชิ้น เนยล้วน | D29: =บ่าย!D29+'เช้า '!D29+'เย็น '!D29 -> 0 | E29: =บ่าย!E29+'เช้า '!E29+'เย็น '!E29 -> 0 | F29: =บ่าย!F29+'เช้า '!F29+'เย็น '!F29 -> 0 | G29: =บ่าย!G29+'เช้า '!G29+'เย็น '!G29 -> 0 | H29: =บ่าย!H29+'เช้า '!H29+'เย็น '!H29 -> 0 | I29: =บ่าย!I29+'เช้า '!I29+'เย็น '!I29 -> 0 | J29: =บ่าย!J29+'เช้า '!J29+'เย็น '!J29 -> 0 | K29: =SUM(D29:J29) -> 0 | O29: =(L29+M29+N29)-K29 -> 0
B30: 1004055 | C30: ชิฟฟอน 4 ชิ้น กาแฟล้วน | D30: =บ่าย!D30+'เช้า '!D30+'เย็น '!D30 -> 0 | E30: =บ่าย!E30+'เช้า '!E30+'เย็น '!E30 -> 0 | F30: =บ่าย!F30+'เช้า '!F30+'เย็น '!F30 -> 0 | G30: =บ่าย!G30+'เช้า '!G30+'เย็น '!G30 -> 0 | H30: =บ่าย!H30+'เช้า '!H30+'เย็น '!H30 -> 0 | I30: =บ่าย!I30+'เช้า '!I30+'เย็น '!I30 -> 0 | J30: =บ่าย!J30+'เช้า '!J30+'เย็น '!J30 -> 0 | K30: =SUM(D30:J30) -> 0 | O30: =(L30+M30+N30)-K30 -> 0
B31: 1004055 | C31: ชิฟฟอน 4 ชิ้น ใบเตยล้วน | D31: =บ่าย!D31+'เช้า '!D31+'เย็น '!D31 -> 0 | E31: =บ่าย!E31+'เช้า '!E31+'เย็น '!E31 -> 0 | F31: =บ่าย!F31+'เช้า '!F31+'เย็น '!F31 -> 0 | G31: =บ่าย!G31+'เช้า '!G31+'เย็น '!G31 -> 0 | H31: =บ่าย!H31+'เช้า '!H31+'เย็น '!H31 -> 0 | I31: =บ่าย!I31+'เช้า '!I31+'เย็น '!I31 -> 0 | J31: =บ่าย!J31+'เช้า '!J31+'เย็น '!J31 -> 0 | K31: =SUM(D31:J31) -> 0 | O31: =(L31+M31+N31)-K31 -> 0
B32: 1004055 | C32: ชิฟฟอน 4 ชิ้น บลูเบอร์รี่ล้วน | D32: =บ่าย!D32+'เช้า '!D32+'เย็น '!D32 -> 0 | E32: =บ่าย!E32+'เช้า '!E32+'เย็น '!E32 -> 0 | F32: =บ่าย!F32+'เช้า '!F32+'เย็น '!F32 -> 0 | G32: =บ่าย!G32+'เช้า '!G32+'เย็น '!G32 -> 0 | H32: =บ่าย!H32+'เช้า '!H32+'เย็น '!H32 -> 0 | I32: =บ่าย!I32+'เช้า '!I32+'เย็น '!I32 -> 0 | J32: =บ่าย!J32+'เช้า '!J32+'เย็น '!J32 -> 0 | K32: =SUM(D32:J32) -> 0 | O32: =(L32+M32+N32)-K32 -> 0
B33: 1004055 | C33: ชิฟฟอน 4 ชิ้น ส้มล้วน | D33: =บ่าย!D33+'เช้า '!D33+'เย็น '!D33 -> 0 | E33: =บ่าย!E33+'เช้า '!E33+'เย็น '!E33 -> 0 | F33: =บ่าย!F33+'เช้า '!F33+'เย็น '!F33 -> 0 | G33: =บ่าย!G33+'เช้า '!G33+'เย็น '!G33 -> 0 | H33: =บ่าย!H33+'เช้า '!H33+'เย็น '!H33 -> 0 | I33: =บ่าย!I33+'เช้า '!I33+'เย็น '!I33 -> 0 | J33: =บ่าย!J33+'เช้า '!J33+'เย็น '!J33 -> 0 | K33: =SUM(D33:J33) -> 0 | O33: =(L33+M33+N33)-K33 -> 0
B34: 1004055 | C34: ชิฟฟอน 4 ชิ้น เผือกล้วน | D34: =บ่าย!D34+'เช้า '!D34+'เย็น '!D34 -> 0 | E34: =บ่าย!E34+'เช้า '!E34+'เย็น '!E34 -> 0 | F34: =บ่าย!F34+'เช้า '!F34+'เย็น '!F34 -> 0 | G34: =บ่าย!G34+'เช้า '!G34+'เย็น '!G34 -> 0 | H34: =บ่าย!H34+'เช้า '!H34+'เย็น '!H34 -> 0 | I34: =บ่าย!I34+'เช้า '!I34+'เย็น '!I34 -> 0 | J34: =บ่าย!J34+'เช้า '!J34+'เย็น '!J34 -> 0 | K34: =SUM(D34:J34) -> 0 | O34: =(L34+M34+N34)-K34 -> 0
B35: 1004055 | C35: ชิฟฟอน 4 ชิ้น สตอเบอรี่ล้วน | D35: =บ่าย!D35+'เช้า '!D35+'เย็น '!D35 -> 0 | E35: =บ่าย!E35+'เช้า '!E35+'เย็น '!E35 -> 0 | F35: =บ่าย!F35+'เช้า '!F35+'เย็น '!F35 -> 0 | G35: =บ่าย!G35+'เช้า '!G35+'เย็น '!G35 -> 0 | H35: =บ่าย!H35+'เช้า '!H35+'เย็น '!H35 -> 0 | I35: =บ่าย!I35+'เช้า '!I35+'เย็น '!I35 -> 0 | J35: =บ่าย!J35+'เช้า '!J35+'เย็น '!J35 -> 0 | K35: =SUM(D35:J35) -> 0 | O35: =(L35+M35+N35)-K35 -> 0
B36: 1004055 | C36: ชิฟฟอน 4 ชิ้น กล้วยหอมล้วน | D36: =บ่าย!D36+'เช้า '!D36+'เย็น '!D36 -> 0 | E36: =บ่าย!E36+'เช้า '!E36+'เย็น '!E36 -> 0 | F36: =บ่าย!F36+'เช้า '!F36+'เย็น '!F36 -> 0 | G36: =บ่าย!G36+'เช้า '!G36+'เย็น '!G36 -> 0 | H36: =บ่าย!H36+'เช้า '!H36+'เย็น '!H36 -> 0 | I36: =บ่าย!I36+'เช้า '!I36+'เย็น '!I36 -> 0 | J36: =บ่าย!J36+'เช้า '!J36+'เย็น '!J36 -> 0 | K36: =SUM(D36:J36) -> 0 | O36: =(L36+M36+N36)-K36 -> 0
B37: 1004055 | C37: ชิฟฟอน 4 ชิ้น ชาเขียวล้วน | D37: =บ่าย!D37+'เช้า '!D37+'เย็น '!D37 -> 0 | E37: =บ่าย!E37+'เช้า '!E37+'เย็น '!E37 -> 0 | F37: =บ่าย!F37+'เช้า '!F37+'เย็น '!F37 -> 0 | G37: =บ่าย!G37+'เช้า '!G37+'เย็น '!G37 -> 0 | H37: =บ่าย!H37+'เช้า '!H37+'เย็น '!H37 -> 0 | I37: =บ่าย!I37+'เช้า '!I37+'เย็น '!I37 -> 0 | J37: =บ่าย!J37+'เช้า '!J37+'เย็น '!J37 -> 0 | K37: =SUM(D37:J37) -> 0 | O37: =(L37+M37+N37)-K37 -> 0
B38: 1004055 | C38: ชิฟฟอน 4 ชิ้น ชาไทยล้วน | D38: =บ่าย!D38+'เช้า '!D38+'เย็น '!D38 -> 0 | E38: =บ่าย!E38+'เช้า '!E38+'เย็น '!E38 -> 0 | F38: =บ่าย!F38+'เช้า '!F38+'เย็น '!F38 -> 0 | G38: =บ่าย!G38+'เช้า '!G38+'เย็น '!G38 -> 0 | H38: =บ่าย!H38+'เช้า '!H38+'เย็น '!H38 -> 0 | I38: =บ่าย!I38+'เช้า '!I38+'เย็น '!I38 -> 0 | J38: =บ่าย!J38+'เช้า '!J38+'เย็น '!J38 -> 0 | K38: =SUM(D38:J38) -> 0 | O38: =(L38+M38+N38)-K38 -> 0
B39: 1004055 | C39: ชิฟฟอน 4 ชิ้น สับปะรดล้วน | D39: =บ่าย!D39+'เช้า '!D39+'เย็น '!D39 -> 0 | E39: =บ่าย!E39+'เช้า '!E39+'เย็น '!E39 -> 0 | F39: =บ่าย!F39+'เช้า '!F39+'เย็น '!F39 -> 0 | G39: =บ่าย!G39+'เช้า '!G39+'เย็น '!G39 -> 0 | H39: =บ่าย!H39+'เช้า '!H39+'เย็น '!H39 -> 0 | I39: =บ่าย!I39+'เช้า '!I39+'เย็น '!I39 -> 0 | J39: =บ่าย!J39+'เช้า '!J39+'เย็น '!J39 -> 0 | K39: =SUM(D39:J39) -> 0 | O39: =(L39+M39+N39)-K39 -> 0
B40: 1111057 | C40: ชิฟฟอนแยกชิ้น กาแฟ | D40: =บ่าย!D40+'เช้า '!D40+'เย็น '!D40 -> 0 | E40: =บ่าย!E40+'เช้า '!E40+'เย็น '!E40 -> 0 | F40: =บ่าย!F40+'เช้า '!F40+'เย็น '!F40 -> 1 | G40: =บ่าย!G40+'เช้า '!G40+'เย็น '!G40 -> 1 | H40: =บ่าย!H40+'เช้า '!H40+'เย็น '!H40 -> 0 | I40: =บ่าย!I40+'เช้า '!I40+'เย็น '!I40 -> 0 | J40: =บ่าย!J40+'เช้า '!J40+'เย็น '!J40 -> 0 | K40: =SUM(D40:J40) -> 2 | L40: 10 | N40: 8 | O40: =(L40+M40+N40)-K40 -> 16
B41: 1111058 | C41: ชิฟฟอนแยกชิ้น ชาเขียว | D41: =บ่าย!D41+'เช้า '!D41+'เย็น '!D41 -> 0 | E41: =บ่าย!E41+'เช้า '!E41+'เย็น '!E41 -> 0 | F41: =บ่าย!F41+'เช้า '!F41+'เย็น '!F41 -> 1 | G41: =บ่าย!G41+'เช้า '!G41+'เย็น '!G41 -> 1 | H41: =บ่าย!H41+'เช้า '!H41+'เย็น '!H41 -> 0 | I41: =บ่าย!I41+'เช้า '!I41+'เย็น '!I41 -> 0 | J41: =บ่าย!J41+'เช้า '!J41+'เย็น '!J41 -> 0 | K41: =SUM(D41:J41) -> 2 | L41: 10 | O41: =(L41+M41+N41)-K41 -> 8
B42: 1111059 | C42: ชิฟฟอนแยกชิ้น ใบเตย | D42: =บ่าย!D42+'เช้า '!D42+'เย็น '!D42 -> 0 | E42: =บ่าย!E42+'เช้า '!E42+'เย็น '!E42 -> 0 | F42: =บ่าย!F42+'เช้า '!F42+'เย็น '!F42 -> 1 | G42: =บ่าย!G42+'เช้า '!G42+'เย็น '!G42 -> 1 | H42: =บ่าย!H42+'เช้า '!H42+'เย็น '!H42 -> 0 | I42: =บ่าย!I42+'เช้า '!I42+'เย็น '!I42 -> 0 | J42: =บ่าย!J42+'เช้า '!J42+'เย็น '!J42 -> 0 | K42: =SUM(D42:J42) -> 2 | L42: 10 | O42: =(L42+M42+N42)-K42 -> 8
B43: 1111060 | C43: ชิฟฟอนแยกชิ้น กล้วยหอม | D43: =บ่าย!D43+'เช้า '!D43+'เย็น '!D43 -> 0 | E43: =บ่าย!E43+'เช้า '!E43+'เย็น '!E43 -> 0 | F43: =บ่าย!F43+'เช้า '!F43+'เย็น '!F43 -> 1 | G43: =บ่าย!G43+'เช้า '!G43+'เย็น '!G43 -> 1 | H43: =บ่าย!H43+'เช้า '!H43+'เย็น '!H43 -> 0 | I43: =บ่าย!I43+'เช้า '!I43+'เย็น '!I43 -> 0 | J43: =บ่าย!J43+'เช้า '!J43+'เย็น '!J43 -> 0 | K43: =SUM(D43:J43) -> 2 | L43: 10 | O43: =(L43+M43+N43)-K43 -> 8
B44: 1111061 | C44: ชิฟฟอนแยกชิ้น ชาไทย | D44: =บ่าย!D44+'เช้า '!D44+'เย็น '!D44 -> 0 | E44: =บ่าย!E44+'เช้า '!E44+'เย็น '!E44 -> 0 | F44: =บ่าย!F44+'เช้า '!F44+'เย็น '!F44 -> 0 | G44: =บ่าย!G44+'เช้า '!G44+'เย็น '!G44 -> 1 | H44: =บ่าย!H44+'เช้า '!H44+'เย็น '!H44 -> 0 | I44: =บ่าย!I44+'เช้า '!I44+'เย็น '!I44 -> 0 | J44: =บ่าย!J44+'เช้า '!J44+'เย็น '!J44 -> 0 | K44: =SUM(D44:J44) -> 1 | L44: 10 | N44: 4 | O44: =(L44+M44+N44)-K44 -> 13
...
