Workbook

Sheet ALL
A1: ข้อมูลการยิง ADS ของแผนกออนไลน์ทุกแพลตฟอร์ม ปี 2568
A2: Total 2568 | E2: Tiktok | H2: Facebook | K2: Lazada | N2: Shopee
A3: เดือน | B3: ยอดขาย | C3: ค่าแอด | D3: คิดเป็น% | E3: ยอดขาย | F3: ค่าแอด | G3: คิดเป็น% | H3: ยอดขาย | I3: ค่าแอด | J3: คิดเป็น% | K3: ยอดขาย | L3: ค่าแอด | M3: คิดเป็น% | N3: ยอดขาย | O3: ค่าแอด | P3: คิดเป็น%
A4: มกราคม | B4: =+E4+H4+K4+N4 -> 2509427.4 | C4: =+F4+I4+L4+O4 -> 227189.96 | D4: =+C4/B4 -> 0.09053458 | E4: =+'ม.ค.'!B35 -> 1419580.7 | F4: =+'ม.ค.'!C35 -> 163049.04 | G4: =+F4/E4 -> 0.11485718 | H4: =+'ม.ค.'!F35 -> 529399.4 | I4: =+'ม.ค.'!G35 -> 37660.35 | J4: =+I4/H4 -> 0.071137878 | K4: =+'ม.ค.'!J35 -> 218333.31 | L4: =+'ม.ค.'!K35 -> 15354.7 | M4: =+L4/K4 -> 0.070326878 | N4: =+'ม.ค.'!N35 -> 342114 | O4: =+'ม.ค.'!O35 -> 11125.87 | P4: =+O4/N4 -> 0.032520943
A5: กุมภาพันธ์ | B5: =+E5+H5+K5+N5 -> 878016.19 | C5: =+F5+I5+L5+O5 -> 132588.03 | D5: =+C5/B5 -> 0.15100864 | E5: =+'ก.พ.'!B35 -> 272957.09 | F5: =+'ก.พ.'!C35 -> 57441.68 | G5: =+F5/E5 -> 0.21044216 | H5: =+'ก.พ.'!F35 -> 290703.87 | I5: =+'ก.พ.'!G35 -> 46570.17 | J5: =+I5/H5 -> 0.16019797 | K5: =+'ก.พ.'!J35 -> 184722.23 | L5: =+'ก.พ.'!K35 -> 17170.88 | M5: =+L5/K5 -> 0.092955136 | N5: =+'ก.พ.'!N35 -> 129633 | O5: =+'ก.พ.'!O35 -> 11405.3 | P5: =+O5/N5 -> 0.087981455
A6: มีนาคม | B6: =+E6+H6+K6+N6 -> 1155265.2 | C6: =+F6+I6+L6+O6 -> 115630.92 | D6: =+C6/B6 -> 0.10009037 | E6: =+'มี.ค.'!B35 -> 451899.91 | F6: =+'มี.ค.'!C35 -> 42906.22 | G6: =+F6/E6 -> 0.09494629 | H6: =+'มี.ค.'!F35 -> 355955 | I6: =+'มี.ค.'!G35 -> 46673.42 | J6: =+I6/H6 -> 0.13112169 | K6: =+'มี.ค.'!J35 -> 218333.31 | L6: =+'มี.ค.'!K35 -> 15354.7 | M6: =+L6/K6 -> 0.070326878 | N6: =+'มี.ค.'!N35 -> 129077 | O6: =+'มี.ค.'!O35 -> 10696.58 | P6: =+O6/N6 -> 0.08286976
A7: เมษายน | B7: =+E7+H7+K7+N7 -> 1723910.5 | C7: =+F7+I7+L7+O7 -> 256594.61 | D7: =+C7/B7 -> 0.14884451 | E7: =+'เม.ย.'!B35 -> 1075941.8 | F7: =+'เม.ย.'!C35 -> 190448.68 | G7: =+F7/E7 -> 0.17700649 | H7: =+'เม.ย.'!F35 -> 371081 | I7: =+'เม.ย.'!G35 -> 43938.24 | J7: =+I7/H7 -> 0.11840606 | K7: =+'เม.ย.'!J35 -> 93014.71 | L7: =+'เม.ย.'!K35 -> 7149.93 | M7: =+L7/K7 -> 0.076868809 | N7: =+'เม.ย.'!N35 -> 183873 | O7: =+'เม.ย.'!O35 -> 15057.76 | P7: =+O7/N7 -> 0.081892176
A8: พฤษภาคม | B8: =+E8+H8+K8+N8 -> 1963780.1 | C8: =+F8+I8+L8+O8 -> 241636.03 | D8: =+C8/B8 -> 0.12304638 | E8: =+'พ.ค.'!B35 -> 1306217.9 | F8: =+'พ.ค.'!C35 -> 180851.38 | G8: =+F8/E8 -> 0.13845422 | H8: =+'พ.ค.'!F35 -> 473804 | I8: =+'พ.ค.'!G35 -> 39036.33 | J8: =+I8/H8 -> 0.082389195 | K8: =+'พ.ค.'!J35 -> 75200.22 | L8: =+'พ.ค.'!K35 -> 6115.24 | M8: =+L8/K8 -> 0.081319443 | N8: =+'พ.ค.'!N35 -> 108558 | O8: =+'พ.ค.'!O35 -> 15633.08 | P8: =+O8/N8 -> 0.14400671
A9: มิถุนายน | B9: =+E9+H9+K9+N9 -> 1719188.3 | C9: =+F9+I9+L9+O9 -> 259343.4 | D9: =+C9/B9 -> 0.15085224 | E9: =+'มิ.ย.'!B35 -> 1117036.2 | F9: =+'มิ.ย.'!C35 -> 187551.71 | G9: =+F9/E9 -> 0.16790119 | H9: =+'มิ.ย.'!F35 -> 438380.5 | I9: =+'มิ.ย.'!G35 -> 52417.1 | J9: =+I9/H9 -> 0.11956987 | K9: =+'มิ.ย.'!J35 -> 64033.6 | L9: =+'มิ.ย.'!K35 -> 4663.62 | M9: =+L9/K9 -> 0.072830826 | N9: =+'มิ.ย.'!N35 -> 99738 | O9: =+'มิ.ย.'!O35 -> 14710.97 | P9: =+O9/N9 -> 0.14749614
A10: กรกฎาคม | B10: =+E10+H10+K10+N10 -> 1703967.8 | C10: =+F10+I10+L10+O10 -> 159985.99 | D10: =+C10/B10 -> 0.093890264 | E10: =+'ก.ค.'!C39 -> 816485.93 | F10: =+'ก.ค.'!C35 -> 108539.42 | G10: =+F10/E10 -> 0.13293483 | H10: =+'ก.ค.'!C40 -> 684586 | I10: =+'ก.ค.'!G35 -> 30166.44 | J10: =+I10/H10 -> 0.044065231 | K10: =+'ก.ค.'!J35 -> 93199.9 | L10: =+'ก.ค.'!K35 -> 2565.8 | M10: =+L10/K10 -> 0.027530072 | N10: =+'ก.ค.'!N35 -> 109696 | O10: =+'ก.ค.'!O35 -> 18714.33 | P10: =+O10/N10 -> 0.17060175
A11: สิงหาคม | B11: =+E11+H11+K11+N11 -> 1460210.6 | C11: =+F11+I11+L11+O11 -> 145123.34 | D11: =+C11/B11 -> 0.099385211 | E11: =+'ส.ค.'!B35 -> 744295.08 | F11: =+'ส.ค.'!C35 -> 116493.69 | G11: =+F11/E11 -> 0.15651546 | H11: =+'ส.ค.'!F35 -> 428177.66 | I11: =+'ส.ค.'!G35 -> 8548.96 | J11: =+I11/H11 -> 0.019965918 | K11: =+'ส.ค.'!J35 -> 108192.88 | L11: =+'ส.ค.'!K35 -> 4404.2 | M11: =+L11/K11 -> 0.04070693 | N11: =+'ส.ค.'!N35 -> 179545 | O11: =+'ส.ค.'!O35 -> 15676.49 | P11: =+O11/N11 -> 0.087312317
A12: กันยายน | B12: =+E12+H12+K12+N12 -> 1655450.4 | C12: =+F12+I12+L12+O12 -> 231423.02 | D12: =+C12/B12 -> 0.1397946 | E12: =+'ก.ย.'!B35 -> 937399.29 | F12: =+'ก.ย.'!C35 -> 150724.24 | G12: =+F12/E12 -> 0.1607898 | H12: =+'ก.ย.'!F35 -> 362846 | I12: =+'ก.ย.'!G35 -> 40171.39 | J12: =+I12/H12 -> 0.11071195 | K12: =+'ก.ย.'!J35 -> 131041.06 | L12: =+'ก.ย.'!K35 -> 14726.07 | M12: =+L12/K12 -> 0.11237753 | N12: =+'ก.ย.'!N35 -> 224164 | O12: =+'ก.ย.'!O35 -> 25801.32 | P12: =+O12/N12 -> 0.11510019
A13: ตุลาคม | B13: =+E13+H13+K13+N13 -> 851664 | C13: =+F13+I13+L13+O13 -> 118702.52 | D13: =+C13/B13 -> 0.13937717 | E13: 361442 | F13: 52171.85 | G13: =+F13/E13 -> 0.14434363 | H13: 82999 | I13: 18186.23 | J13: =+I13/H13 -> 0.21911384 | K13: 53979 | L13: 4922.51 | M13: =+L13/K13 -> 0.091193057 | N13: =+'ต.ค.'!N35 -> 353244 | O13: =+'ต.ค.'!O35 -> 43421.93 | P13: =+O13/N13 -> 0.12292333
A14: พฤศจิกายน | B14: =+E14+H14+K14+N14 -> 1706744.7 | C14: =+F14+I14+L14+O14 -> 217420.78 | D14: =+C14/B14 -> 0.12738917 | E14: =+'พ.ย.'!B35 -> 1063180.6 | F14: =+'พ.ย.'!C35 -> 146915.09 | G14: =+F14/E14 -> 0.13818451 | H14: =+'พ.ย.'!F35 -> 324577 | I14: =+'พ.ย.'!G35 -> 27974.77 | J14: =+I14/H14 -> 0.086188393 | K14: =+'พ.ย.'!J35 -> 137225.07 | L14: =+'พ.ย.'!K35 -> 15358.81 | M14: =+L14/K14 -> 0.11192423 | N14: =+'พ.ย.'!N35 -> 181762 | O14: =+'พ.ย.'!O35 -> 27172.11 | P14: =+O14/N14 -> 0.1494928
A15: ธันวาคม | B15: =+E15+H15+K15+N15 -> 7342719.9 | C15: =+F15+I15+L15+O15 -> 492416.67 | D15: =+C15/B15 -> 0.06706189 | E15: =+'ธ.ค.'!B35 -> 5428550.7 | F15: =+'ธ.ค.'!C35 -> 419092.68 | G15: =+F15/E15 -> 0.077201579 | H15: =+'ธ.ค.'!F35 -> 880595 | I15: =+'ธ.ค.'!G35 -> 12298.98 | J15: =+I15/H15 -> 0.01396667 | K15: =+'ธ.ค.'!J35 -> 288592.2 | L15: =+'ธ.ค.'!K35 -> 19998.57 | M15: =+L15/K15 -> 0.069296987 | N15: =+'ธ.ค.'!N35 -> 744982 | O15: =+'ธ.ค.'!O35 -> 41026.44 | P15: =+O15/N15 -> 0.055070378
A16: Total | B16: =SUM(B4:B15) -> 24670345 | C16: =SUM(C4:C15) -> 2598055.3 | D16: บาท | E16: =SUM(E4:E15) -> 14994987 | F16: =SUM(F4:F15) -> 1816185.7 | G16: บาท | H16: =SUM(H4:H15) -> 5223104.4 | I16: =SUM(I4:I15) -> 403642.38 | J16: บาท | K16: =SUM(K4:K15) -> 1665867.5 | L16: =SUM(L4:L15) -> 127785.03 | M16: บาท | N16: =SUM(N4:N15) -> 2786386 | O16: =SUM(O4:O15) -> 250442.18 | P16: บาท
B18: ตารางสรุป ปี 2568
B19: แพลตฟอร์ม | C19: ยอดขาย | D19: ค่าแอด | E19: คิดเป็น%
B20: Tiktok | C20: =+E16 -> 14994987 | D20: =+F16 -> 1816185.7 | E20: =+D20/C20 -> 0.12111952
B21: Facebook | C21: =+H16 -> 5223104.4 | D21: =+I16 -> 403642.38 | E21: =+D21/C21 -> 0.077280167
B22: Lazada | C22: =+K16 -> 1665867.5 | D22: =+L16 -> 127785.03 | E22: =+D22/C22 -> 0.0767078
B23: Shopee | C23: =+N16 -> 2786386 | D23: =+O16 -> 250442.18 | E23: =+D23/C23 -> 0.089880648
B24: รวม | C24: =SUM(C20:C23) -> 24670345 | D24: =SUM(D20:D23) -> 2598055.3 | E24: =+D24/C24 -> 0.10531086

Sheet ก.พ.
A1: ข้อมูลการยิง ADS ของแผนกออนไลน์ทุกแพลตฟอร์ม เดือนกุมภาพันธ์ 2568
A2: Tiktok | E2: Facebook | I2: Lazada | M2: Shopee
A3: ว/ด/ป | B3: ยอดขาย | C3: ค่าแอด | D3: คิดเป็น% | E3: ว/ด/ป | F3: ยอดขาย | G3: ค่าแอด | H3: คิดเป็น% | I3: ว/ด/ป | J3: ยอดขาย | K3: ค่าแอด | L3: คิดเป็น% | M3: ว/ด/ป | N3: ยอดขาย | O3: ค่าแอด | P3: คิดเป็น%
A4: 45689 | B4: 0 | C4: 0 | D4: 0 | E4: 45689 | F4: 0 | G4: 0 | H4: 0 | I4: 45689 | J4: 0 | K4: 0 | L4: 0 | M4: 45689 | N4: 0 | O4: 0 | P4: 0
A5: 45690 | B5: 9146.32 | C5: 709.22 | D5: =+C5/B5 -> 0.077541569 | E5: 45690 | F5: 6480 | G5: 643.62 | H5: =+G5/F5 -> 0.099324074 | I5: 45690 | J5: 612.7 | K5: 27 | L5: =+K5/J5 -> 0.044067243 | M5: 45690 | N5: 6044 | O5: 598.37 | P5: =+O5/N5 -> 0.099002316
A6: 45691 | B6: 7533 | C6: 945.46 | D6: =+C6/B6 -> 0.12550909 | E6: 45691 | F6: 3732 | G6: 1211.17 | H6: =+G6/F6 -> 0.32453644 | I6: 45691 | J6: 3277.36 | K6: 106 | L6: =+K6/J6 -> 0.032343105 | M6: 45691 | N6: 3723 | O6: 417.69 | P6: =+O6/N6 -> 0.11219178
A7: 45692 | B7: 3554 | C7: 662.3 | D7: =+C7/B7 -> 0.1863534 | E7: 45692 | F7: 15052 | G7: 1213.71 | H7: =+G7/F7 -> 0.080634467 | I7: 45692 | J7: 2471.59 | K7: 420 | L7: =+K7/J7 -> 0.1699311 | M7: 45692 | N7: 4237 | O7: 337.84 | P7: =+O7/N7 -> 0.079735662
A8: 45693 | B8: 3326 | C8: 631.93 | D8: =+C8/B8 -> 0.18999699 | E8: 45693 | F8: 6279 | G8: 2150.73 | H8: =+G8/F8 -> 0.34252747 | I8: 45693 | J8: 3832.16 | K8: 2383 | L8: =+K8/J8 -> 0.62184251 | M8: 45693 | N8: 6396 | O8: 252.67 | P8: =+O8/N8 -> 0.039504378
A9: 45694 | B9: 4319 | C9: 685.39 | D9: =+C9/B9 -> 0.15869183 | E9: 45694 | F9: 26190 | G9: 1975.44 | H9: =+G9/F9 -> 0.075427262 | I9: 45694 | J9: 3886.34 | K9: 1432.55 | L9: =+K9/J9 -> 0.3686116 | M9: 45694 | N9: 6518 | O9: 700.96 | P9: =+O9/N9 -> 0.10754219
A10: 45695 | B10: 13538.2 | C10: 3504.42 | D10: =+C10/B10 -> 0.25885421 | E10: 45695 | F10: 20594 | G10: 1182.87 | H10: =+G10/F10 -> 0.057437603 | I10: 45695 | J10: 5499.1 | K10: 1820 | L10: =+K10/J10 -> 0.33096325 | M10: 45695 | N10: 4643 | O10: 708.82 | P10: =+O10/N10 -> 0.15266423
A11: 45696 | B11: 10243.7 | C11: 1965.16 | D11: =+C11/B11 -> 0.19184084 | E11: 45696 | F11: 12600 | G11: 1161 | H11: =+G11/F11 -> 0.092142857 | I11: 45696 | J11: 3774.86 | K11: 752.94 | L11: =+K11/J11 -> 0.1994617 | M11: 45696 | N11: 4422 | O11: 560.85 | P11: =+O11/N11 -> 0.12683175
A12: 45697 | B12: 22572.45 | C12: 7322 | D12: =+C12/B12 -> 0.32437773 | E12: 45697 | F12: 28040 | G12: 1176 | H12: =+G12/F12 -> 0.041940086 | I12: 45697 | J12: 3436.65 | K12: 0 | L12: =+K12/J12 -> 0 | M12: 45697 | N12: 5801 | O12: 523.7 | P12: =+O12/N12 -> 0.090277538
A13: 45698 | B13: 12801.45 | C13: 2744.06 | D13: =+C13/B13 -> 0.21435541 | E13: 45698 | F13: 7089 | G13: 1295.45 | H13: =+G13/F13 -> 0.18274087 | I13: 45698 | J13: 5924.35 | K13: 1000.13 | L13: =+K13/J13 -> 0.16881683 | M13: 45698 | N13: 5008 | O13: 869.35 | P13: =+O13/N13 -> 0.17359225
A14: 45699 | B14: 24133.3 | C14: 9369.73 | D14: =+C14/B14 -> 0.38824902 | E14: 45699 | F14: 5521 | G14: 1102.08 | H14: =+G14/F14 -> 0.19961601 | I14: 45699 | J14: 5582.22 | K14: 677.28 | L14: =+K14/J14 -> 0.12132807 | M14: 45699 | N14: 3793 | O14: 592.75 | P14: =+O14/N14 -> 0.15627472
A15: 45700 | B15: 11638 | C15: 1002.01 | D15: =+C15/B15 -> 0.086098127 | E15: 45700 | F15: 5379 | G15: 1738.97 | H15: =+G15/F15 -> 0.32328872 | I15: 45700 | J15: 1860.44 | K15: 601.11 | L15: =+K15/J15 -> 0.32310099 | M15: 45700 | N15: 5006 | O15: 574.17 | P15: =+O15/N15 -> 0.11469636
A16: 45701 | B16: 11991 | C16: 2298.98 | D16: =+C16/B16 -> 0.19172546 | E16: 45701 | F16: 11705 | G16: 2455.1 | H16: =+G16/F16 -> 0.20974797 | I16: 45701 | J16: 3469.15 | K16: 600.31 | L16: =+K16/J16 -> 0.17304239 | M16: 45701 | N16: 2805 | O16: 529.57 | P16: =+O16/N16 -> 0.18879501
... A31: 45716 | B31: 5941.6 | C31: 268.23 | D31: =+C31/B31 -> 0.045144406 | E31: 45716 | F31: 0 | G31: 2806.49 | H31: =+G31/F31 -> #DIV/0! | I31: 45716 | J31: 1405.42 | K31: 0 | L31: =+K31/J31 -> 0 | M31: 45716 | N31: 6454 | O31: 197.03 | P31: =+O31/N31 -> 0.030528355
A32: 45717 | B32: 0 | C32: 0 | D32: 0 | E32: 45717 | F32: 0 | G32: 0 | H32: 0 | I32: 45717 | J32: 0 | K32: 0 | L32: 0 | M32: 45717 | N32: 0 | O32: 0 | P32: 0
A33: 45718 | B33: 0 | C33: 0 | D33: 0 | E33: 45718 | F33: 0 | G33: 0 | H33: 0 | I33: 45718 | J33: 0 | K33: 0 | L33: 0 | M33: 45718 | N33: 0 | O33: 0 | P33: 0
A34: 45719 | B34: 0 | C34: 0 | D34: 0 | E34: 45719 | F34: 0 | G34: 0 | H34: 0 | I34: 45719 | J34: 0 | K34: 0 | L34: 0 | M34: 45719 | N34: 0 | O34: 0 | P34: 0
A35: Total | B35: =SUM(B4:B34) -> 272957.09 | C35: =SUM(C4:C34) -> 57441.68 | D35: บาท | E35: Total | F35: =SUM(F4:F34) -> 290703.87 | G35: =SUM(G4:G34) -> 46570.17 | H35: บาท | I35: Total | J35: =SUM(J4:J34) -> 184722.23 | K35: =SUM(K4:K34) -> 17170.88 | L35: บาท | M35: Total | N35: =SUM(N4:N34) -> 129633 | O35: =SUM(O4:O34) -> 11405.3 | P35: บาท | XFD35: =SUM(A35:XFC35) -> 1010604.2
B37: ตารางสรุป 1- 28 กุมภาพันธ์ 2568
B38: แพลตฟอร์ม | C38: ยอดขาย | D38: ค่าแอด | E38: คิดเป็น%
B39: Tiktok | C39: =+B35 -> 272957.09 | D39: =+C35 -> 57441.68 | E39: =+D39/C39 -> 0.21044216
B40: Facebook | C40: =+F35 -> 290703.87 | D40: =+G35 -> 46570.17 | E40: =+D40/C40 -> 0.16019797
B41: Lazada | C41: =+J35 -> 184722.23 | D41: =+K35 -> 17170.88 | E41: =+D41/C41 -> 0.092955136
B42: Shopee | C42: =+N35 -> 129633 | D42: =+O35 -> 11405.3 | E42: =+D42/C42 -> 0.087981455
B43: รวม | C43: =SUM(C39:C42) -> 878016.19 | D43: =SUM(D39:D42) -> 132588.03 | E43: =+D43/C43 -> 0.15100864

Sheet ม.ค.
A1: ข้อมูลการยิง ADS ของแผนกออนไลน์ทุกแพลตฟอร์ม เดือนมกราคม 2568
A2: Tiktok | E2: Facebook | I2: Lazada | M2: Shopee
A3: ว/ด/ป | B3: ยอดขาย | C3: ค่าแอด | D3: คิดเป็น% | E3: ว/ด/ป | F3: ยอดขาย | G3: ค่าแอด | H3: คิดเป็น% | I3: ว/ด/ป | J3: ยอดขาย | K3: ค่าแอด | L3: คิดเป็น% | M3: ว/ด/ป | N3: ยอดขาย | O3: ค่าแอด | P3: คิดเป็น%
A4: 45658 | B4: 111283.57 | C4: 10027.26 | D4: =+C4/B4 -> 0.090105485 | E4: 45658 | F4: 42643 | G4: 2696.93 | H4: =+G4/F4 -> 0.063244378 | I4: 45658 | J4: 3248.05 | K4: 0 | L4: =+K4/J4 -> 0 | M4: 45658 | N4: 23636 | O4: 545 | P4: =+O4/N4 -> 0.023058047
A5: 45659 | B5: 120292.22 | C5: 10335.98 | D5: =+C5/B5 -> 0.085923928 | E5: 45659 | F5: 112985 | G5: 2318.73 | H5: =+G5/F5 -> 0.020522459 | I5: 45659 | J5: 6582.43 | K5: 1058.49 | L5: =+K5/J5 -> 0.16080536 | M5: 45659 | N5: 20441 | O5: 538.28 | P5: =+O5/N5 -> 0.02633335
A6: 45660 | B6: 117235.48 | C6: 10765.86 | D6: =+C6/B6 -> 0.091831074 | E6: 45660 | F6: 3835 | G6: 1781.11 | H6: =+G6/F6 -> 0.46443546 | I6: 45660 | J6: 14405.15 | K6: 1685.89 | L6: =+K6/J6 -> 0.11703384 | M6: 45660 | N6: 26810 | O6: 448.89 | P6: =+O6/N6 -> 0.016743379
A7: 45661 | B7: 78638.21 | C7: 7627.51 | D7: =+C7/B7 -> 0.09699496 | E7: 45661 | F7: 20648 | G7: 1333.61 | H7: =+G7/F7 -> 0.064587854 | I7: 45661 | J7: 8530.4 | K7: 1595.24 | L7: =+K7/J7 -> 0.18700647 | M7: 45661 | N7: 13524 | O7: 410 | P7: =+O7/N7 -> 0.030316474
A8: 45662 | B8: 66020 | C8: 6541.19 | D8: =+C8/B8 -> 0.099078915 | E8: 45662 | F8: 18810 | G8: 1123.87 | H8: =+G8/F8 -> 0.059748538 | I8: 45662 | J8: 9456.52 | K8: 1466.72 | L8: =+K8/J8 -> 0.15510145 | M8: 45662 | N8: 10052 | O8: 457.88 | P8: =+O8/N8 -> 0.045551134
A9: 45663 | B9: 63343.64 | C9: 7000.89 | D9: =+C9/B9 -> 0.11052238 | E9: 45663 | F9: 26650 | G9: 1186.42 | H9: =+G9/F9 -> 0.044518574 | I9: 45663 | J9: 4217.29 | K9: 800.3 | L9: =+K9/J9 -> 0.18976641 | M9: 45663 | N9: 7981 | O9: 410 | P9: =+O9/N9 -> 0.051372009
A10: 45664 | B10: 46840.3 | C10: 4979.28 | D10: =+C10/B10 -> 0.10630333 | E10: 45664 | F10: 27953 | G10: 1105.19 | H10: =+G10/F10 -> 0.039537438 | I10: 45664 | J10: 2994.55 | K10: 801.76 | L10: =+K10/J10 -> 0.26773973 | M10: 45664 | N10: 16229 | O10: 450 | P10: =+O10/N10 -> 0.027728141
A11: 45665 | B11: 45468.85 | C11: 5031.41 | D11: =+C11/B11 -> 0.1106562 | E11: 45665 | F11: 3767 | G11: 961.54 | H11: =+G11/F11 -> 0.25525352 | I11: 45665 | J11: 4595.32 | K11: 805.26 | L11: =+K11/J11 -> 0.1752348 | M11: 45665 | N11: 5116 | O11: 464.99 | P11: =+O11/N11 -> 0.090889367
A12: 45666 | B12: 41611 | C12: 5095.69 | D12: =+C12/B12 -> 0.12246017 | E12: 45666 | F12: 30259 | G12: 756.71 | H12: =+G12/F12 -> 0.025007766 | I12: 45666 | J12: 4624.13 | K12: 781.29 | L12: =+K12/J12 -> 0.16895935 | M12: 45666 | N12: 13297 | O12: 521.96 | P12: =+O12/N12 -> 0.039253967
A13: 45667 | B13: 28129 | C13: 3193.86 | D13: =+C13/B13 -> 0.11354332 | E13: 45667 | F13: 10840 | G13: 705.31 | H13: =+G13/F13 -> 0.065065498 | I13: 45667 | J13: 4641.4 | K13: 708.97 | L13: =+K13/J13 -> 0.15274917 | M13: 45667 | N13: 6115 | O13: 568.22 | P13: =+O13/N13 -> 0.092922322
A14: 45668 | B14: 39511.72 | C14: 4554.39 | D14: =+C14/B14 -> 0.11526681 | E14: 45668 | F14: 7915 | G14: 838.47 | H14: =+G14/F14 -> 0.1059343 | I14: 45668 | J14: 8290.8 | K14: 202.22 | L14: =+K14/J14 -> 0.024390891 | M14: 45668 | N14: 5454 | O14: 520 | P14: =+O14/N14 -> 0.095342868
A15: 45669 | B15: 52184 | C15: 8617.15 | D15: =+C15/B15 -> 0.16513012 | E15: 45669 | F15: 7873 | G15: 764.22 | H15: =+G15/F15 -> 0.097068462 | I15: 45669 | J15: 4912.34 | K15: 201.69 | L15: =+K15/J15 -> 0.041057826 | M15: 45669 | N15: 7318 | O15: 582.66 | P15: =+O15/N15 -> 0.079620115
... A22: 45676 | B22: 77446.96 | C22: 10211.84 | D22: =+C22/B22 -> 0.13185592 | E22: 45676 | F22: 13865 | G22: 777.3 | H22: =+G22/F22 -> 0.056062027 | I22: 45676 | J22: 6957.21 | K22: 200.46 | L22: =+K22/J22 -> 0.028813274 | M22: 45676 | N22: 8745 | O22: 284.39 | P22: =+O22/N22 -> 0.032520297
A23: 45677 | B23: 82570 | C23: 11478.44 | D23: =+C23/B23 -> 0.13901465 | E23: 45677 | F23: 7127 | G23: 3342.77 | H23: 0 | I23: 45677 | J23: 4131.35 | K23: 200.64 | L23: =+K23/J23 -> 0.048565239 | M23: 45677 | N23: 10786 | O23: 271.97 | P23: =+O23/N23 -> 0.025215094
A24: 45678 | B24: 87009.6 | C24: 14502.71 | D24: =+C24/B24 -> 0.16667942 | E24: 45678 | F24: 17870 | G24: 4037.18 | H24: =+G24/F24 -> 0.22591942 | I24: 45678 | J24: 5340.52 | K24: 200.67 | L24: =+K24/J24 -> 0.037574993 | M24: 45678 | N24: 35475 | O24: 675.98 | P24: =+O24/N24 -> 0.019055109
A25: 45679 | B25: 44854.25 | C25: 4506.41 | D25: =+C25/B25 -> 0.10046785 | E25: 45679 | F25: 25452.4 | G25: 3212.57 | H25: =+G25/F25 -> 0.12621875 | I25: 45679 | J25: 4291.02 | K25: 200.16 | L25: =+K25/J25 -> 0.046646252 | M25: 45679 | N25: 19337 | O25: 412.04 | P25: =+O25/N25 -> 0.021308373
A26: 45680 | B26: 44346.35 | C26: 4361.59 | D26: =+C26/B26 -> 0.098352852 | E26: 45680 | F26: 15836 | G26: 1165.63 | H26: =+G26/F26 -> 0.07360634 | I26: 45680 | J26: 7006.76 | K26: 200.48 | L26: =+K26/J26 -> 0.028612369 | M26: 45680 | N26: 15606 | O26: 585.17 | P26: =+O26/N26 -> 0.037496476
A27: 45681 | B27: 14403 | C27: 1537.52 | D27: =+C27/B27 -> 0.10674998 | E27: 45681 | F27: 18885 | G27: 741.65 | H27: =+G27/F27 -> 0.039271909 | I27: 45681 | J27: 9896.8 | K27: 200.6 | L27: =+K27/J27 -> 0.020269178 | M27: 45681 | N27: 13965 | O27: 516.96 | P27: =+O27/N27 -> 0.03701826
A28: 45682 | B28: 2682 | C28: 949.2 | D28: =+C28/B28 -> 0.35391499 | E28: 45682 | F28: 5350 | G28: 106.28 | H28: =+G28/F28 -> 0.019865421 | I28: 45682 | J28: 19339.14 | K28: 200.92 | L28: =+K28/J28 -> 0.010389293 | M28: 45682 | N28: 3275 | O28: 240 | P28: =+O28/N28 -> 0.073282443
A29: 45683 | B29: 4075 | C29: 471.61 | D29: =+C29/B29 -> 0.11573252 | E29: 45683 | F29: 2090 | G29: 0 | H29: 0 | I29: 45683 | J29: 6062.96 | K29: 200.3 | L29: 0 | M29: 45683 | N29: 1425 | O29: 31.42 | P29: =+O29/N29 -> 0.022049123
A30: 45684 | B30: 2907 | C30: 0.1 | D30: =+C30/B30 -> 3.4399725e-05 | E30: 45684 | F30: 4110 | G30: 0 | H30: 0 | I30: 45684 | J30: 6427.01 | K30: 200.2 | L30: =+K30/J30 -> 0.031149788 | M30: 45684 | N30: 1156 | O30: 0 | P30: =+O30/N30 -> 0
A31: 45685 | B31: 469 | C31: 0 | D31: =+C31/B31 -> 0 | E31: 45685 | F31: 3150 | G31: 0 | H31: =+G31/F31 -> 0 | I31: 45685 | J31: 1941.61 | K31: 184.21 | L31: 0 | M31: 45685 | N31: 449 | O31: 0 | P31: =+O31/N31 -> 0
A32: 45686 | B32: 179 | C32: 0 | D32: =+C32/B32 -> 0 | E32: 45686 | F32: 0 | G32: 0 | H32: 0 | I32: 45686 | J32: 4756.67 | K32: 200.39 | L32: =+K32/J32 -> 0.042128212 | M32: 45686 | N32: 141 | O32: 0 | P32: =+O32/N32 -> 0
A33: 45687 | B33: 0 | C33: 0 | D33: 0 | E33: 45687 | F33: 300 | G33: 0 | H33: 0 | I33: 45687 | J33: 4775.01 | K33: 200.69 | L33: 0 | M33: 45687 | N33: 0 | O33: 0 | P33: 0
A34: 45688 | B34: 0 | C34: 0 | D34: 0 | E34: 45688 | F34: 0 | G34: 0 | H34: 0 | I34: 45688 | J34: 8998.56 | K34: 200.01 | L34: 0 | M34: 45688 | N34: 296 | O34: 0 | P34: =+O34/N34 -> 0
A35: Total | B35: =SUM(B4:B34) -> 1419580.7 | C35: =SUM(C4:C34) -> 163049.04 | D35: บาท | E35: Total | F35: =SUM(F4:F34) -> 529399.4 | G35: =SUM(G4:G34) -> 37660.35 | H35: บาท | I35: Total | J35: =SUM(J4:J34) -> 218333.31 | K35: =SUM(K4:K34) -> 15354.7 | L35: บาท | M35: Total | N35: =SUM(N4:N34) -> 342114 | O35: =SUM(O4:O34) -> 11125.87 | P35: บาท | XFD35: =SUM(A35:XFC35) -> 2736617.4
B38: ตารางสรุป 1- 31 มกราคม 2568
B39: แพลตฟอร์ม | C39: ยอดขาย | D39: ค่าแอด | E39: คิดเป็น%
B40: Tiktok | C40: =+B35 -> 1419580.7 | D40: =+C35 -> 163049.04 | E40: =+D40/C40 -> 0.11485718
B41: Facebook | C41: =+F35 -> 529399.4 | D41: =+G35 -> 37660.35 | E41: =+D41/C41 -> 0.071137878
B42: Lazada | C42: =+J35 -> 218333.31 | D42: =+K35 -> 15354.7 | E42: =+D42/C42 -> 0.070326878
B43: Shopee | C43: =+N35 -> 342114 | D43: =+O35 -> 11125.87 | E43: =+D43/C43 -> 0.032520943
B44: รวม | C44: =SUM(C40:C43) -> 2509427.4 | D44: =SUM(D40:D43) -> 227189.96 | E44: =+D44/C44 -> 0.09053458

Sheet มี.ค.
A1: ข้อมูลการยิง ADS ของแผนกออนไลน์ทุกแพลตฟอร์ม เดือนมีนาคม 2568
A2: Tiktok | E2: Facebook | I2: Lazada | M2: Shopee
A3: ว/ด/ป | B3: ยอดขาย | C3: ค่าแอด | D3: คิดเป็น% | E3: ว/ด/ป | F3: ยอดขาย | G3: ค่าแอด | H3: คิดเป็น% | I3: ว/ด/ป | J3: ยอดขาย | K3: ค่าแอด | L3: คิดเป็น% | M3: ว/ด/ป | N3: ยอดขาย | O3: ค่าแอด | P3: คิดเป็น%
A4: 45717 | B4: 5312.12 | C4: 213.23 | D4: =+C4/B4 -> 0.040140283 | E4: 45717 | F4: 26225 | G4: 2186.19 | H4: =+G4/F4 -> 0.083362822 | I4: 45717 | J4: 3248.05 | K4: 0 | L4: =+K4/J4 -> 0 | M4: 45717 | N4: 3783 | O4: 166.21 | P4: =+O4/N4 -> 0.04393603
A5: 45718 | B5: 12712.09 | C5: 964.8 | D5: =+C5/B5 -> 0.075896253 | E5: 45718 | F5: 17189 | G5: 1436.59 | H5: =+G5/F5 -> 0.083576124 | I5: 45718 | J5: 6582.43 | K5: 1058.49 | L5: =+K5/J5 -> 0.16080536 | M5: 45718 | N5: 5371 | O5: 306.77 | P5: =+O5/N5 -> 0.057115993
A6: 45719 | B6: 6262.89 | C6: 624.02 | D6: =+C6/B6 -> 0.099637707 | E6: 45719 | F6: 5887 | G6: 1709.6 | H6: =+G6/F6 -> 0.29040258 | I6: 45719 | J6: 14405.15 | K6: 1685.89 | L6: =+K6/J6 -> 0.11703384 | M6: 45719 | N6: 8950 | O6: 692 | P6: =+O6/N6 -> 0.077318436
A7: 45720 | B7: 10316.5 | C7: 1406.73 | D7: =+C7/B7 -> 0.13635729 | E7: 45720 | F7: 19520 | G7: 1831.31 | H7: =+G7/F7 -> 0.093817111 | I7: 45720 | J7: 8530.4 | K7: 1595.24 | L7: =+K7/J7 -> 0.18700647 | M7: 45720 | N7: 3436 | O7: 276.26 | P7: =+O7/N7 -> 0.08040163
A8: 45721 | B8: 8164 | C8: 824.79 | D8: =+C8/B8 -> 0.10102768 | E8: 45721 | F8: 3943 | G8: 1902.1 | H8: =+G8/F8 -> 0.48239919 | I8: 45721 | J8: 9456.52 | K8: 1466.72 | L8: =+K8/J8 -> 0.15510145 | M8: 45721 | N8: 2465 | O8: 242.39 | P8: =+O8/N8 -> 0.098332657
A9: 45722 | B9: 11793 | C9: 1571.39 | D9: =+C9/B9 -> 0.13324769 | E9: 45722 | F9: 19656 | G9: 1252.68 | H9: =+G9/F9 -> 0.063730159 | I9: 45722 | J9: 4217.29 | K9: 800.3 | L9: =+K9/J9 -> 0.18976641 | M9: 45722 | N9: 2062 | O9: 343.33 | P9: =+O9/N9 -> 0.16650339
A10: 45723 | B10: 8819 | C10: 596.35 | D10: =+C10/B10 -> 0.067621045 | E10: 45723 | F10: 7545 | G10: 1257.44 | H10: =+G10/F10 -> 0.16665871 | I10: 45723 | J10: 2994.55 | K10: 801.76 | L10: =+K10/J10 -> 0.26773973 | M10: 45723 | N10: 4304 | O10: 355.04 | P10: =+O10/N10 -> 0.082490706
A11: 45724 | B11: 7247 | C11: 786.41 | D11: =+C11/B11 -> 0.10851525 | E11: 45724 | F11: 9630 | G11: 1441.59 | H11: =+G11/F11 -> 0.14969782 | I11: 45724 | J11: 4595.32 | K11: 805.26 | L11: =+K11/J11 -> 0.1752348 | M11: 45724 | N11: 2766 | O11: 370.28 | P11: =+O11/N11 -> 0.1338684
A12: 45725 | B12: 9679 | C12: 1774.91 | D12: =+C12/B12 -> 0.18337742 | E12: 45725 | F12: 11986 | G12: 1492.15 | H12: =+G12/F12 -> 0.12449107 | I12: 45725 | J12: 4624.13 | K12: 781.29 | L12: =+K12/J12 -> 0.16895935 | M12: 45725 | N12: 3763 | O12: 413.64 | P12: =+O12/N12 -> 0.10992293
A13: 45726 | B13: 7458 | C13: 999.78 | D13: =+C13/B13 -> 0.13405471 | E13: 45726 | F13: 12070 | G13: 1361.48 | H13: =+G13/F13 -> 0.11279867 | I13: 45726 | J13: 4641.4 | K13: 708.97 | L13: =+K13/J13 -> 0.15274917 | M13: 45726 | N13: 775 | O13: 381.79 | P13: =+O13/N13 -> 0.49263226
A14: 45727 | B14: 12093.4 | C14: 1636.02 | D14: =+C14/B14 -> 0.13528205 | E14: 45727 | F14: 5271 | G14: 1312.38 | H14: =+G14/F14 -> 0.24898122 | I14: 45727 | J14: 8290.8 | K14: 202.22 | L14: =+K14/J14 -> 0.024390891 | M14: 45727 | N14: 4034 | O14: 325.29 | P14: =+O14/N14 -> 0.080637085
A15: 45728 | B15: 7757 | C15: 1162.86 | D15: =+C15/B15 -> 0.14991105 | E15: 45728 | F15: 10247 | G15: 2252.78 | H15: =+G15/F15 -> 0.21984776 | I15: 45728 | J15: 4912.34 | K15: 201.69 | L15: =+K15/J15 -> 0.041057826 | M15: 45728 | N15: 3858 | O15: 376.74 | P15: =+O15/N15 -> 0.097651633
... A34: 45747 | B34: 22061.92 | C34: 0 | D34: =+C34/B34 -> 0 | E34: 45747 | F34: 7303 | G34: 1443.57 | H34: =+G34/F34 -> 0.19766808 | I34: 45747 | J34: 8998.56 | K34: 200.01 | L34: =+K34/J34 -> 0.02222689 | M34: 45747 | N34: 2817 | O34: 352.71 | P34: =+O34/N34 -> 0.12520767
A35: Total | B35: =SUM(B4:B34) -> 451899.91 | C35: =SUM(C4:C34) -> 42906.22 | D35: บาท | E35: Total | F35: =SUM(F4:F34) -> 355955 | G35: =SUM(G4:G34) -> 46673.42 | H35: บาท | I35: Total | J35: =SUM(J4:J34) -> 218333.31 | K35: =SUM(K4:K34) -> 15354.7 | L35: บาท | M35: Total | N35: =SUM(N4:N34) -> 129077 | O35: =SUM(O4:O34) -> 10696.58 | P35: บาท | XFD35: =SUM(A35:XFC35) -> 1270896.1
B37: ตารางสรุป 1- 31 มีนาคม 2568
B38: แพลตฟอร์ม | C38: ยอดขาย | D38: ค่าแอด | E38: คิดเป็น%
B39: Tiktok | C39: =+B35 -> 451899.91 | D39: =+C35 -> 42906.22 | E39: =+D39/C39 -> 0.09494629
B40: Facebook | C40: =+F35 -> 355955 | D40: =+G35 -> 46673.42 | E40: =+D40/C40 -> 0.13112169
B41: Lazada | C41: =+J35 -> 218333.31 | D41: =+K35 -> 15354.7 | E41: =+D41/C41 -> 0.070326878
B42: Shopee | C42: =+N35 -> 129077 | D42: =+O35 -> 10696.58 | E42: =+D42/C42 -> 0.08286976
B43: รวม | C43: =SUM(C39:C42) -> 1155265.2 | D43: =SUM(D39:D42) -> 115630.92 | E43: =+D43/C43 -> 0.10009037

Sheet เม.ย.
A1: ข้อมูลการยิง ADS ของแผนกออนไลน์ทุกแพลตฟอร์ม เดือนเมษายน 2568
A2: Tiktok | E2: Facebook | I2: Lazada | M2: Shopee
A3: ว/ด/ป | B3: ยอดขาย | C3: ค่าแอด | D3: คิดเป็น% | E3: ว/ด/ป | F3: ยอดขาย | G3: ค่าแอด | H3: คิดเป็น% | I3: ว/ด/ป | J3: ยอดขาย | K3: ค่าแอด | L3: คิดเป็น% | M3: ว/ด/ป | N3: ยอดขาย | O3: ค่าแอด | P3: คิดเป็น%
A4: 45748 | B4: 11795.41 | C4: 3940.61 | D4: =+C4/B4 -> 0.33407995 | E4: 45748 | F4: 6463 | G4: 1505.62 | H4: =+G4/F4 -> 0.23295993 | I4: 45748 | J4: 3045.42 | K4: 200.62 | L4: =+K4/J4 -> 0.065875971 | M4: 45748 | N4: 4446 | O4: 418.18 | P4: =+O4/N4 -> 0.09405758
A5: 45749 | B5: 12048.82 | C5: 4357.3 | D5: =+C5/B5 -> 0.36163707 | E5: 45749 | F5: 400 | G5: 1663.47 | H5: =+G5/F5 -> 4.158675 | I5: 45749 | J5: 3416.59 | K5: 200.94 | L5: =+K5/J5 -> 0.058813027 | M5: 45749 | N5: 6209 | O5: 540 | P5: =+O5/N5 -> 0.086970527
A6: 45750 | B6: 19297.89 | C6: 4629.98 | D6: =+C6/B6 -> 0.23992157 | E6: 45750 | F6: 25742 | G6: 1893.13 | H6: =+G6/F6 -> 0.07354246 | I6: 45750 | J6: 4036.62 | K6: 198.99 | L6: =+K6/J6 -> 0.049296193 | M6: 45750 | N6: 4253 | O6: 530.07 | P6: =+O6/N6 -> 0.12463438
A7: 45751 | B7: 17118.4 | C7: 5764.49 | D7: =+C7/B7 -> 0.33674234 | E7: 45751 | F7: 8709 | G7: 2070.5 | H7: =+G7/F7 -> 0.23774257 | I7: 45751 | J7: 2432.51 | K7: 199.09 | L7: =+K7/J7 -> 0.081845501 | M7: 45751 | N7: 5822 | O7: 535.54 | P7: =+O7/N7 -> 0.091985572
A8: 45752 | B8: 11374.19 | C8: 3697.64 | D8: =+C8/B8 -> 0.3250904 | E8: 45752 | F8: 16845 | G8: 2210.9 | H8: =+G8/F8 -> 0.13124963 | I8: 45752 | J8: 4729.26 | K8: 200.92 | L8: =+K8/J8 -> 0.042484448 | M8: 45752 | N8: 7187 | O8: 392.38 | P8: =+O8/N8 -> 0.054595798
A9: 45753 | B9: 12722.13 | C9: 5253.32 | D9: =+C9/B9 -> 0.41292771 | E9: 45753 | F9: 15909 | G9: 2411.31 | H9: =+G9/F9 -> 0.15156892 | I9: 45753 | J9: 2852.69 | K9: 197.95 | L9: =+K9/J9 -> 0.069390645 | M9: 45753 | N9: 6924 | O9: 452.62 | P9: =+O9/N9 -> 0.065369728
A10: 45754 | B10: 8522.21 | C10: 4818.54 | D10: =+C10/B10 -> 0.56540968 | E10: 45754 | F10: 7501 | G10: 2361.42 | H10: =+G10/F10 -> 0.31481402 | I10: 45754 | J10: 5307.14 | K10: 200.19 | L10: =+K10/J10 -> 0.037720882 | M10: 45754 | N10: 8855 | O10: 340 | P10: =+O10/N10 -> 0.038396386
A11: 45755 | B11: 11611.32 | C11: 5784.78 | D11: =+C11/B11 -> 0.49820175 | E11: 45755 | F11: 12182 | G11: 1555.79 | H11: =+G11/F11 -> 0.1277122 | I11: 45755 | J11: 7057.61 | K11: 200.31 | L11: =+K11/J11 -> 0.028382129 | M11: 45755 | N11: 8524 | O11: 356.61 | P11: =+O11/N11 -> 0.041835992
A12: 45756 | B12: 19793.45 | C12: 26023.37 | D12: =+C12/B12 -> 1.3147465 | E12: 45756 | F12: 4786 | G12: 1621.93 | H12: =+G12/F12 -> 0.33889051 | I12: 45756 | J12: 2980.08 | K12: 200.01 | L12: =+K12/J12 -> 0.067115648 | M12: 45756 | N12: 6433 | O12: 407.43 | P12: =+O12/N12 -> 0.06333437
A13: 45757 | B13: 13120.83 | C13: 13719.68 | D13: =+C13/B13 -> 1.0456412 | E13: 45757 | F13: 32788 | G13: 1799.88 | H13: =+G13/F13 -> 0.054894474 | I13: 45757 | J13: 4225.17 | K13: 382.11 | L13: =+K13/J13 -> 0.090436598 | M13: 45757 | N13: 12774 | O13: 466.29 | P13: =+O13/N13 -> 0.036503053
A14: 45758 | B14: 24107.13 | C14: 4599.89 | D14: =+C14/B14 -> 0.19081035 | E14: 45758 | F14: 7289 | G14: 1840.23 | H14: =+G14/F14 -> 0.25246673 | I14: 45758 | J14: 3446.15 | K14: 181.83 | L14: =+K14/J14 -> 0.052763229 | M14: 45758 | N14: 8832 | O14: 390.67 | P14: =+O14/N14 -> 0.044233469
A15: 45759 | B15: 25417.07 | C15: 7564.59 | D15: =+C15/B15 -> 0.29761849 | E15: 45759 | F15: 9937 | G15: 2492.77 | H15: =+G15/F15 -> 0.2508574 | I15: 45759 | J15: 4276.93 | K15: 170.81 | L15: =+K15/J15 -> 0.039937525 | M15: 45759 | N15: 6857 | O15: 557.28 | P15: =+O15/N15 -> 0.081271693
... A33: 45777 | B33: 43379.56 | C33: 6558.14 | D33: =+C33/B33 -> 0.15118042 | E33: 45777 | F33: 5029 | G33: 824.38 | H33: =+G33/F33 -> 0.16392523 | I33: 45777 | J33: 4522.31 | K33: 1232.21 | L33: =+K33/J33 -> 0.27247358 | M33: 45777 | N33: 4207 | O33: 589.12 | P33: =+O33/N33 -> 0.14003328
A34: 45778 | B34: 0 | C34: 0 | D34: 0 | E34: 45778 | F34: 0 | G34: 0 | H34: 0 | I34: 45778 | J34: 0 | K34: 0 | L34: 0 | M34: 45778 | N34: 0 | O34: 0 | P34: 0
A35: Total | B35: =SUM(B4:B34) -> 1075941.8 | C35: =SUM(C4:C34) -> 190448.68 | D35: บาท | E35: Total | F35: =SUM(F4:F34) -> 371081 | G35: =SUM(G4:G34) -> 43938.24 | H35: บาท | I35: Total | J35: =SUM(J4:J34) -> 93014.71 | K35: =SUM(K4:K34) -> 7149.93 | L35: บาท | M35: Total | N35: =SUM(N4:N34) -> 183873 | O35: =SUM(O4:O34) -> 15057.76 | P35: บาท | XFD35: =SUM(A35:XFC35) -> 1980505.1
O36: 0
B37: ตารางสรุป 1- 30 เมษายน 2568
B38: แพลตฟอร์ม | C38: ยอดขาย | D38: ค่าแอด | E38: คิดเป็น%
B39: Tiktok | C39: =+B35 -> 1075941.8 | D39: =+C35 -> 190448.68 | E39: =+D39/C39 -> 0.17700649
B40: Facebook | C40: =+F35 -> 371081 | D40: =+G35 -> 43938.24 | E40: =+D40/C40 -> 0.11840606
B41: Lazada | C41: =+J35 -> 93014.71 | D41: =+K35 -> 7149.93 | E41: =+D41/C41 -> 0.076868809
B42: Shopee | C42: =+N35 -> 183873 | D42: =+O35 -> 15057.76 | E42: =+D42/C42 -> 0.081892176
B43: รวม | C43: =SUM(C39:C42) -> 1723910.5 | D43: =SUM(D39:D42) -> 256594.61 | E43: =+D43/C43 -> 0.14884451

Sheet พ.ค.
A1: ข้อมูลการยิง ADS ของแผนกออนไลน์ทุกแพลตฟอร์ม เดือนพฤษภาคม 2568
A2: Tiktok | E2: Facebook | I2: Lazada | M2: Shopee
A3: ว/ด/ป | B3: ยอดขาย | C3: ค่าแอด | D3: คิดเป็น% | E3: ว/ด/ป | F3: ยอดขาย | G3: ค่าแอด | H3: คิดเป็น% | I3: ว/ด/ป | J3: ยอดขาย | K3: ค่าแอด | L3: คิดเป็น% | M3: ว/ด/ป | N3: ยอดขาย | O3: ค่าแอด | P3: คิดเป็น%
A4: 45778 | B4: 43278.42 | C4: 6275.02 | D4: =+C4/B4 -> 0.14499189 | E4: 45778 | F4: 33307 | G4: 867.63 | H4: =+G4/F4 -> 0.026049479 | I4: 45778 | J4: 3532.58 | K4: 201.42 | L4: =+K4/J4 -> 0.057017817 | M4: 45778 | N4: 3886 | O4: 552.52 | P4: =+O4/N4 -> 0.14218219
A5: 45779 | B5: 61457.83 | C5: 2620.59 | D5: =+C5/B5 -> 0.042640458 | E5: 45779 | F5: 13145 | G5: 811.38 | H5: =+G5/F5 -> 0.061725371 | I5: 45779 | J5: 3895.05 | K5: 197.96 | L5: =+K5/J5 -> 0.050823481 | M5: 45779 | N5: 3513 | O5: 545.46 | P5: =+O5/N5 -> 0.155269
A6: 45780 | B6: 41129.35 | C6: 5387.55 | D6: =+C6/B6 -> 0.1309904 | E6: 45780 | F6: 24980 | G6: 1004.35 | H6: =+G6/F6 -> 0.040206165 | I6: 45780 | J6: 4712.79 | K6: 196.07 | L6: =+K6/J6 -> 0.041603806 | M6: 45780 | N6: 3991 | O6: 597.85 | P6: =+O6/N6 -> 0.14979955
A7: 45781 | B7: 22422.05 | C7: 6117.47 | D7: =+C7/B7 -> 0.27283277 | E7: 45781 | F7: 7454 | G7: 996.94 | H7: =+G7/F7 -> 0.13374564 | I7: 45781 | J7: 1843.89 | K7: 208.17 | L7: =+K7/J7 -> 0.11289719 | M7: 45781 | N7: 5927 | O7: 710.41 | P7: =+O7/N7 -> 0.11985996
A8: 45782 | B8: 11889.41 | C8: 5659.4 | D8: =+C8/B8 -> 0.47600343 | E8: 45782 | F8: 7332 | G8: 1066.5 | H8: =+G8/F8 -> 0.14545827 | I8: 45782 | J8: 1409.57 | K8: 198.07 | L8: =+K8/J8 -> 0.14051803 | M8: 45782 | N8: 3257 | O8: 840 | P8: =+O8/N8 -> 0.25790605
A9: 45783 | B9: 22151.61 | C9: 6686.99 | D9: =+C9/B9 -> 0.30187377 | E9: 45783 | F9: 19720 | G9: 911.56 | H9: =+G9/F9 -> 0.046225152 | I9: 45783 | J9: 1787.62 | K9: 202.22 | L9: =+K9/J9 -> 0.11312248 | M9: 45783 | N9: 5484 | O9: 537.96 | P9: =+O9/N9 -> 0.09809628
A10: 45784 | B10: 31570.59 | C10: 6980.15 | D10: =+C10/B10 -> 0.2210966 | E10: 45784 | F10: 27922 | G10: 854.65 | H10: =+G10/F10 -> 0.030608481 | I10: 45784 | J10: 2677.99 | K10: 186.39 | L10: =+K10/J10 -> 0.069600708 | M10: 45784 | N10: 5878 | O10: 467.06 | P10: =+O10/N10 -> 0.079459
A11: 45785 | B11: 26460.99 | C11: 2752.16 | D11: =+C11/B11 -> 0.1040082 | E11: 45785 | F11: 29662 | G11: 944.64 | H11: =+G11/F11 -> 0.031846807 | I11: 45785 | J11: 1588.82 | K11: 200.67 | L11: =+K11/J11 -> 0.12630128 | M11: 45785 | N11: 4293 | O11: 441.03 | P11: =+O11/N11 -> 0.10273235
A12: 45786 | B12: 34821.91 | C12: 6897.11 | D12: =+C12/B12 -> 0.19806811 | E12: 45786 | F12: 3434 | G12: 1147.49 | H12: =+G12/F12 -> 0.3341555 | I12: 45786 | J12: 4149.3 | K12: 202.4 | L12: =+K12/J12 -> 0.048779312 | M12: 45786 | N12: 1871 | O12: 527.25 | P12: =+O12/N12 -> 0.28180118
A13: 45787 | B13: 50159.45 | C13: 7751.24 | D13: =+C13/B13 -> 0.154532 | E13: 45787 | F13: 9654 | G13: 1320.02 | H13: =+G13/F13 -> 0.13673296 | I13: 45787 | J13: 3197.48 | K13: 200.62 | L13: =+K13/J13 -> 0.06274316 | M13: 45787 | N13: 1956 | O13: 484.74 | P13: =+O13/N13 -> 0.24782209
A14: 45788 | B14: 48695.86 | C14: 11771.37 | D14: =+C14/B14 -> 0.24173246 | E14: 45788 | F14: 6254 | G14: 958.96 | H14: =+G14/F14 -> 0.15333547 | I14: 45788 | J14: 3081.29 | K14: 195.37 | L14: =+K14/J14 -> 0.063405262 | M14: 45788 | N14: 4570 | O14: 507.91 | P14: =+O14/N14 -> 0.11114004
A15: 45789 | B15: 29464.95 | C15: 7622.77 | D15: =+C15/B15 -> 0.25870636 | E15: 45789 | F15: 4343 | G15: 896.6 | H15: =+G15/F15 -> 0.20644716 | I15: 45789 | J15: 5827.56 | K15: 200.65 | L15: =+K15/J15 -> 0.03443122 | M15: 45789 | N15: 2660 | O15: 503.06 | P15: =+O15/N15 -> 0.1891203
... A34: 45808 | B34: 22800.83 | C34: 7624 | D34: =+C34/B34 -> 0.33437379 | E34: 45808 | F34: 6250 | G34: 1533.6 | H34: =+G34/F34 -> 0.245376 | I34: 45808 | J34: 2242.3 | K34: 201.04 | L34: =+K34/J34 -> 0.089657941 | M34: 45808 | N34: 1873 | O34: 540 | P34: =+O34/N34 -> 0.28830753
A35: Total | B35: =SUM(B4:B34) -> 1306217.9 | C35: =SUM(C4:C34) -> 180851.38 | D35: บาท | E35: Total | F35: =SUM(F4:F34) -> 473804 | G35: =SUM(G4:G34) -> 39036.33 | H35: บาท | I35: Total | J35: =SUM(J4:J34) -> 75200.22 | K35: =SUM(K4:K34) -> 6115.24 | L35: บาท | M35: Total | N35: =SUM(N4:N34) -> 108558 | O35: =SUM(O4:O34) -> 15633.08 | P35: บาท | XFD35: =SUM(A35:XFC35) -> 2205416.1
B37: ตารางสรุป 1- 31 พฤษภาคม 2568
B38: แพลตฟอร์ม | C38: ยอดขาย | D38: ค่าแอด | E38: คิดเป็น%
B39: Tiktok | C39: =+B35 -> 1306217.9 | D39: =+C35 -> 180851.38 | E39: =+D39/C39 -> 0.13845422
B40: Facebook | C40: =+F35 -> 473804 | D40: =+G35 -> 39036.33 | E40: =+D40/C40 -> 0.082389195
B41: Lazada | C41: =+J35 -> 75200.22 | D41: =+K35 -> 6115.24 | E41: =+D41/C41 -> 0.081319443
B42: Shopee | C42: =+N35 -> 108558 | D42: =+O35 -> 15633.08 | E42: =+D42/C42 -> 0.14400671
B43: รวม | C43: =SUM(C39:C42) -> 1963780.1 | D43: =SUM(D39:D42) -> 241636.03 | E43: =+D43/C43 -> 0.12304638

Sheet มิ.ย.
A1: ข้อมูลการยิง ADS ของแผนกออนไลน์ทุกแพลตฟอร์ม เดือนมิถุนายน 2568
A2: Tiktok | E2: Facebook | I2: Lazada | M2: Shopee
A3: ว/ด/ป | B3: ยอดขาย | C3: ค่าแอด | D3: คิดเป็น% | E3: ว/ด/ป | F3: ยอดขาย | G3: ค่าแอด | H3: คิดเป็น% | I3: ว/ด/ป | J3: ยอดขาย | K3: ค่าแอด | L3: คิดเป็น% | M3: ว/ด/ป | N3: ยอดขาย | O3: ค่าแอด | P3: คิดเป็น%
A4: 45809 | B4: 20448.26 | C4: 8947.98 | D4: =+C4/B4 -> 0.43759127 | E4: 45809 | F4: 16761 | G4: 1669.1 | H4: =+G4/F4 -> 0.099582364 | I4: 45809 | J4: 1868.99 | K4: 202.65 | L4: =+K4/J4 -> 0.10842755 | M4: 45809 | N4: 3910 | O4: 437.33 | P4: =+O4/N4 -> 0.1118491
A5: 45810 | B5: 9602.07 | C5: 7194.4 | D5: =+C5/B5 -> 0.74925511 | E5: 45810 | F5: 3874 | G5: 1458.63 | H5: =+G5/F5 -> 0.37651781 | I5: 45810 | J5: 2615.24 | K5: 200.17 | L5: =+K5/J5 -> 0.07653982 | M5: 45810 | N5: 4769 | O5: 490.86 | P5: =+O5/N5 -> 0.10292724
A6: 45811 | B6: 15993.89 | C6: 8464.1 | D6: =+C6/B6 -> 0.52920834 | E6: 45811 | F6: 2340 | G6: 1479.25 | H6: =+G6/F6 -> 0.63215812 | I6: 45811 | J6: 1895.99 | K6: 200.66 | L6: =+K6/J6 -> 0.10583389 | M6: 45811 | N6: 3066 | O6: 456.16 | P6: =+O6/N6 -> 0.14878017
A7: 45812 | B7: 34761.22 | C7: 6206.39 | D7: =+C7/B7 -> 0.1785435 | E7: 45812 | F7: 13909 | G7: 1269.25 | H7: =+G7/F7 -> 0.091253864 | I7: 45812 | J7: 2123.47 | K7: 193.08 | L7: =+K7/J7 -> 0.090926644 | M7: 45812 | N7: 3240 | O7: 415.03 | P7: =+O7/N7 -> 0.12809568
A8: 45813 | B8: 34551.25 | C8: 10978.93 | D8: =+C8/B8 -> 0.31775782 | E8: 45813 | F8: 36420.5 | G8: 2256.29 | H8: =+G8/F8 -> 0.061951099 | I8: 45813 | J8: 1465.2 | K8: 195.86 | L8: =+K8/J8 -> 0.13367458 | M8: 45813 | N8: 1136 | O8: 409.04 | P8: =+O8/N8 -> 0.36007042
A9: 45814 | B9: 46431.79 | C9: 8926.2 | D9: =+C9/B9 -> 0.19224329 | E9: 45814 | F9: 5078 | G9: 2951.9 | H9: =+G9/F9 -> 0.58131154 | I9: 45814 | J9: 2354.03 | K9: 202.5 | L9: =+K9/J9 -> 0.086022693 | M9: 45814 | N9: 1472 | O9: 616.41 | P9: =+O9/N9 -> 0.41875679
A10: 45815 | B10: 48404.38 | C10: 7282.82 | D10: =+C10/B10 -> 0.15045787 | E10: 45815 | F10: 15573 | G10: 2449.8 | H10: =+G10/F10 -> 0.15731073 | I10: 45815 | J10: 2500.09 | K10: 189.09 | L10: =+K10/J10 -> 0.075633277 | M10: 45815 | N10: 1934 | O10: 386.74 | P10: =+O10/N10 -> 0.19996898
A11: 45816 | B11: 44105.67 | C11: 8950.89 | D11: =+C11/B11 -> 0.20294193 | E11: 45816 | F11: 11270 | G11: 1975.12 | H11: =+G11/F11 -> 0.17525466 | I11: 45816 | J11: 3923.15 | K11: 195.91 | L11: =+K11/J11 -> 0.049936913 | M11: 45816 | N11: 3305 | O11: 442.22 | P11: =+O11/N11 -> 0.13380333
A12: 45817 | B12: 36056.65 | C12: 5015.56 | D12: =+C12/B12 -> 0.13910222 | E12: 45817 | F12: 4666 | G12: 1898.16 | H12: =+G12/F12 -> 0.40680669 | I12: 45817 | J12: 1716.7 | K12: 199.48 | L12: =+K12/J12 -> 0.11619969 | M12: 45817 | N12: 2362 | O12: 458.96 | P12: =+O12/N12 -> 0.19430991
A13: 45818 | B13: 45800.15 | C13: 5327.49 | D13: =+C13/B13 -> 0.11632036 | E13: 45818 | F13: 17622 | G13: 1793.54 | H13: =+G13/F13 -> 0.10177846 | I13: 45818 | J13: 1496.4 | K13: 190.06 | L13: =+K13/J13 -> 0.12701149 | M13: 45818 | N13: 4036 | O13: 517.44 | P13: =+O13/N13 -> 0.12820614
A14: 45819 | B14: 49496.09 | C14: 10983.46 | D14: =+C14/B14 -> 0.22190561 | E14: 45819 | F14: 7025 | G14: 1906.71 | H14: =+G14/F14 -> 0.27141779 | I14: 45819 | J14: 4251.49 | K14: 197.97 | L14: =+K14/J14 -> 0.046564851 | M14: 45819 | N14: 3881 | O14: 514.26 | P14: =+O14/N14 -> 0.13250709
A15: 45820 | B15: 48656.62 | C15: 7493.54 | D15: =+C15/B15 -> 0.15400864 | E15: 45820 | F15: 24048 | G15: 1928.38 | H15: =+G15/F15 -> 0.080188789 | I15: 45820 | J15: 3490.62 | K15: 200.49 | L15: =+K15/J15 -> 0.057436788 | M15: 45820 | N15: 3922 | O15: 470 | P15: =+O15/N15 -> 0.11983682
... A33: 45838 | B33: 20254.74 | C33: 6158.53 | D33: =+C33/B33 -> 0.30405377 | E33: 45838 | F33: 23795 | G33: 1144.96 | H33: =+G33/F33 -> 0.048117672 | I33: 45838 | J33: 1607.33 | K33: 0 | L33: =+K33/J33 -> 0 | M33: 45838 | N33: 3375 | O33: 578.34 | P33: =+O33/N33 -> 0.17136
A34: 45839 | B34: 0 | C34: 0 | D34: 0 | E34: 45839 | F34: 0 | H34: 0 | I34: 45839 | J34: 0 | K34: 0 | L34: 0 | M34: 45839 | N34: 0 | O34: 0 | P34: 0
A35: Total | B35: =SUM(B4:B34) -> 1117036.2 | C35: =SUM(C4:C34) -> 187551.71 | D35: บาท | E35: Total | F35: =SUM(F4:F34) -> 438380.5 | G35: =SUM(G4:G34) -> 52417.1 | H35: บาท | I35: Total | J35: =SUM(J4:J34) -> 64033.6 | K35: =SUM(K4:K34) -> 4663.62 | L35: บาท | M35: Total | N35: =SUM(N4:N34) -> 99738 | O35: =SUM(O4:O34) -> 14710.97 | P35: บาท | XFD35: =SUM(A35:XFC35) -> 1978531.7
B37: ตารางสรุป 1- 30 มิถุนายน 2568
B38: แพลตฟอร์ม | C38: ยอดขาย | D38: ค่าแอด | E38: คิดเป็น%
B39: Tiktok | C39: =+B35 -> 1117036.2 | D39: =+C35 -> 187551.71 | E39: =+D39/C39 -> 0.16790119
B40: Facebook | C40: =+F35 -> 438380.5 | D40: =+G35 -> 52417.1 | E40: =+D40/C40 -> 0.11956987
B41: Lazada | C41: =+J35 -> 64033.6 | D41: =+K35 -> 4663.62 | E41: =+D41/C41 -> 0.072830826
B42: Shopee | C42: =+N35 -> 99738 | D42: =+O35 -> 14710.97 | E42: =+D42/C42 -> 0.14749614
B43: รวม | C43: =SUM(C39:C42) -> 1719188.3 | D43: =SUM(D39:D42) -> 259343.4 | E43: =+D43/C43 -> 0.15085224

Sheet ก.ค.
A1: ข้อมูลการยิง ADS ของแผนกออนไลน์ทุกแพลตฟอร์ม เดือนกรกฎาคม 2568
A2: Tiktok | E2: Facebook | I2: Lazada | M2: Shopee
A3: ว/ด/ป | B3: ยอดขาย | C3: ค่าแอด | D3: คิดเป็น% | E3: ว/ด/ป | F3: ยอดขาย | G3: ค่าแอด | H3: คิดเป็น% | I3: ว/ด/ป | J3: ยอดขาย | K3: ค่าแอด | L3: คิดเป็น% | M3: ว/ด/ป | N3: ยอดขาย | O3: ค่าแอด | P3: คิดเป็น%
A4: 45839 | B4: 28787.51 | C4: 8496.1 | D4: =+C4/B4 -> 0.29513146 | E4: 45839 | F4: 7387 | G4: 1114.43 | H4: =+G4/F4 -> 0.15086368 | I4: 45839 | J4: 2739.09 | K4: 0 | L4: =+K4/J4 -> 0 | M4: 45839 | N4: 3006 | O4: 640 | P4: =+O4/N4 -> 0.21290752
A5: 45840 | B5: 42606.74 | C5: 4401.46 | D5: =+C5/B5 -> 0.10330431 | E5: 45840 | F5: 4038 | G5: 1126.01 | H5: =+G5/F5 -> 0.27885339 | I5: 45840 | J5: 2942.09 | K5: 9.26 | L5: =+K5/J5 -> 0.0031474224 | M5: 45840 | N5: 4530 | O5: 627.79 | P5: =+O5/N5 -> 0.13858499
A6: 45841 | B6: 36674.23 | C6: 3496.1 | D6: =+C6/B6 -> 0.095328518 | E6: 45841 | F6: 47069 | G6: 1049 | H6: =+G6/F6 -> 0.022286431 | I6: 45841 | J6: 2837.09 | K6: 100.11 | L6: =+K6/J6 -> 0.035286156 | M6: 45841 | N6: 3670 | O6: 590.6 | P6: =+O6/N6 -> 0.16092643
A7: 45842 | B7: 44096.74 | C7: 4942.14 | D7: =+C7/B7 -> 0.11207495 | E7: 45842 | F7: 8020 | G7: 918.96 | H7: =+G7/F7 -> 0.11458354 | I7: 45842 | J7: 5397.31 | K7: 102.5 | L7: =+K7/J7 -> 0.018990942 | M7: 45842 | N7: 4390 | O7: 613.34 | P7: =+O7/N7 -> 0.13971298
A8: 45843 | B8: 37468.23 | C8: 4481.57 | D8: =+C8/B8 -> 0.11960987 | E8: 45843 | F8: 10238 | G8: 911.75 | H8: =+G8/F8 -> 0.08905548 | I8: 45843 | J8: 1885.44 | K8: 103.14 | L8: =+K8/J8 -> 0.054703411 | M8: 45843 | N8: 3368 | O8: 595.67 | P8: =+O8/N8 -> 0.17686164
A9: 45844 | B9: 40571.06 | C9: 5494.84 | D9: =+C9/B9 -> 0.13543743 | E9: 45844 | F9: 5902 | G9: 873.6 | H9: =+G9/F9 -> 0.14801762 | I9: 45844 | J9: 3789.75 | K9: 103 | L9: =+K9/J9 -> 0.027178574 | M9: 45844 | N9: 3448 | O9: 651.76 | P9: =+O9/N9 -> 0.18902552
A10: 45845 | B10: 26490.93 | C10: 5205.95 | D10: =+C10/B10 -> 0.1965182 | E10: 45845 | F10: 10403 | G10: 1134.87 | H10: =+G10/F10 -> 0.10909065 | I10: 45845 | J10: 2237.61 | K10: 72.24 | L10: =+K10/J10 -> 0.032284446 | M10: 45845 | N10: 5384 | O10: 649.27 | P10: =+O10/N10 -> 0.1205925
A11: 45846 | B11: 26220.95 | C11: 5968.02 | D11: =+C11/B11 -> 0.22760503 | E11: 45846 | F11: 8026 | G11: 734.3 | H11: =+G11/F11 -> 0.091490157 | I11: 45846 | J11: 3283.97 | K11: 91.22 | L11: =+K11/J11 -> 0.027777355 | M11: 45846 | N11: 6164 | O11: 716.45 | P11: =+O11/N11 -> 0.11623134
A12: 45847 | B12: 20841.28 | C12: 3555.51 | D12: =+C12/B12 -> 0.17059941 | E12: 45847 | F12: 11795 | G12: 810.4 | H12: =+G12/F12 -> 0.068707079 | I12: 45847 | J12: 6302.06 | K12: 93 | L12: =+K12/J12 -> 0.014757079 | M12: 45847 | N12: 2727 | O12: 550.87 | P12: =+O12/N12 -> 0.20200587
A13: 45848 | B13: 42203.57 | C13: 3722.4 | D13: =+C13/B13 -> 0.088201069 | E13: 45848 | F13: 33459 | G13: 756.56 | H13: =+G13/F13 -> 0.022611554 | I13: 45848 | J13: 3740.35 | K13: 100.32 | L13: =+K13/J13 -> 0.026821019 | M13: 45848 | N13: 2871 | O13: 544.28 | P13: =+O13/N13 -> 0.18957854
A14: 45849 | B14: 41316.62 | C14: 5116.45 | D14: =+C14/B14 -> 0.12383515 | E14: 45849 | F14: 4373 | G14: 936.73 | H14: =+G14/F14 -> 0.21420764 | I14: 45849 | J14: 4609.77 | K14: 80.66 | L14: =+K14/J14 -> 0.017497619 | M14: 45849 | N14: 2237 | O14: 519.3 | P14: =+O14/N14 -> 0.23214126
A15: 45850 | B15: 44573.06 | C15: 2078.5 | D15: =+C15/B15 -> 0.046631306 | E15: 45850 | F15: 7697 | G15: 1002.69 | H15: =+G15/F15 -> 0.13027024 | I15: 45850 | J15: 5995.41 | K15: 92.7 | L15: =+K15/J15 -> 0.015461828 | M15: 45850 | N15: 5745 | O15: 471.99 | P15: =+O15/N15 -> 0.082156658
... A34: 45869 | B34: 6517.78 | C34: 978.83 | D34: =+C34/B34 -> 0.15017843 | E34: 45869 | F34: 25656 | G34: 826.52 | H34: =+G34/F34 -> 0.032215466 | I34: 45869 | J34: 1559.38 | K34: 89.66 | L34: =+K34/J34 -> 0.05749721 | M34: 45869 | N34: 2955 | O34: 580.3 | P34: =+O34/N34 -> 0.19637902
A35: Total | B35: =SUM(B4:B34) -> 816485.93 | C35: =SUM(C4:C34) -> 108539.42 | D35: บาท | E35: Total | F35: =SUM(F4:F34) -> 684586 | G35: =SUM(G4:G34) -> 30166.44 | H35: บาท | I35: Total | J35: =SUM(J4:J34) -> 93199.9 | K35: =SUM(K4:K34) -> 2565.8 | L35: บาท | M35: Total | N35: =SUM(N4:N34) -> 109696 | O35: =SUM(O4:O34) -> 18714.33 | P35: บาท | XFD35: =SUM(A35:XFC35) -> 1863953.8
B37: ตารางสรุป 1- 31 กรกฏาคม 2568
B38: แพลตฟอร์ม | C38: ยอดขาย | D38: ค่าแอด | E38: คิดเป็น%
B39: Tiktok | C39: =+B35 -> 816485.93 | D39: =+C35 -> 108539.42 | E39: =+D39/C39 -> 0.13293483
B40: Facebook | C40: =+F35 -> 684586 | D40: =+G35 -> 30166.44 | E40: =+D40/C40 -> 0.044065231
B41: Lazada | C41: =+J35 -> 93199.9 | D41: =+K35 -> 2565.8 | E41: =+D41/C41 -> 0.027530072
B42: Shopee | C42: =+N35 -> 109696 | D42: =+O35 -> 18714.33 | E42: =+D42/C42 -> 0.17060175
B43: รวม | C43: =SUM(C39:C42) -> 1703967.8 | D43: =SUM(D39:D42) -> 159985.99 | E43: =+D43/C43 -> 0.093890264

Sheet ส.ค.
A1: ข้อมูลการยิง ADS ของแผนกออนไลน์ทุกแพลตฟอร์ม เดือนสิงหาคม 2568
A2: Tiktok | E2: Facebook | I2: Lazada | M2: Shopee
A3: ว/ด/ป | B3: ยอดขาย | C3: ค่าแอด | D3: คิดเป็น% | E3: ว/ด/ป | F3: ยอดขาย | G3: ค่าแอด | H3: คิดเป็น% | I3: ว/ด/ป | J3: ยอดขาย | K3: ค่าแอด | L3: คิดเป็น% | M3: ว/ด/ป | N3: ยอดขาย | O3: ค่าแอด | P3: คิดเป็น%
A4: 45870 | B4: 17520 | C4: 2086.64 | D4: =+C4/B4 -> 0.11910046 | E4: 45870 | F4: 9116 | G4: 863.04 | H4: =+G4/F4 -> 0.094673102 | I4: 45870 | J4: 2193.25 | K4: 83.17 | L4: =+K4/J4 -> 0.037920894 | M4: 45870 | N4: 2411 | O4: 546.3 | P4: =+O4/N4 -> 0.22658648
A5: 45871 | B5: 8629 | C5: 999.49 | D5: =+C5/B5 -> 0.11582918 | E5: 45871 | F5: 13410 | G5: 1044.95 | H5: =+G5/F5 -> 0.077923192 | I5: 45871 | J5: 4160.55 | K5: 88.96 | L5: =+K5/J5 -> 0.021381788 | M5: 45871 | N5: 1373 | O5: 395.19 | P5: =+O5/N5 -> 0.28782957
A6: 45872 | B6: 18474 | C6: 2376.03 | D6: =+C6/B6 -> 0.12861481 | E6: 45872 | F6: 2765 | G6: 933.84 | H6: =+G6/F6 -> 0.33773599 | I6: 45872 | J6: 4281.45 | K6: 71.14 | L6: =+K6/J6 -> 0.016615866 | M6: 45872 | N6: 4575 | O6: 461 | P6: =+O6/N6 -> 0.10076503
A7: 45873 | B7: 11722 | C7: 2544.04 | D7: =+C7/B7 -> 0.21703122 | E7: 45873 | F7: 5387 | G7: 873.31 | H7: =+G7/F7 -> 0.16211435 | I7: 45873 | J7: 5295.71 | K7: 96.46 | L7: =+K7/J7 -> 0.018214744 | M7: 45873 | N7: 3308 | O7: 583 | P7: =+O7/N7 -> 0.17623942
A8: 45874 | B8: 15044.7 | C8: 2418.73 | D8: =+C8/B8 -> 0.16076957 | E8: 45874 | F8: 6162 | G8: 1301.89 | H8: =+G8/F8 -> 0.21127718 | I8: 45874 | J8: 4694.2 | K8: 90.16 | L8: =+K8/J8 -> 0.019206681 | M8: 45874 | N8: 4622 | O8: 930 | P8: =+O8/N8 -> 0.2012116
A9: 45875 | B9: 25554.95 | C9: 3772.6 | D9: =+C9/B9 -> 0.14762698 | E9: 45875 | F9: 20521 | G9: 724.29 | H9: =+G9/F9 -> 0.035295064 | I9: 45875 | J9: 5293.6 | K9: 123.26 | L9: =+K9/J9 -> 0.023284721 | M9: 45875 | N9: 5951 | O9: 618 | P9: =+O9/N9 -> 0.10384809
A10: 45876 | B10: 36102.08 | C10: 4936.32 | D10: =+C10/B10 -> 0.13673229 | E10: 45876 | F10: 40282 | G10: 651.43 | H10: =+G10/F10 -> 0.016171739 | I10: 45876 | J10: 2617.71 | K10: 170.32 | L10: =+K10/J10 -> 0.065064503 | M10: 45876 | N10: 9179 | O10: 352 | P10: =+O10/N10 -> 0.038348404
A11: 45877 | B11: 39997 | C11: 5179.61 | D11: =+C11/B11 -> 0.12949996 | E11: 45877 | F11: 24804 | G11: (เข้าสู่ระบบไม่ได้) | H11: =+G11/F11 -> #VALUE! | I11: 45877 | J11: 3169.74 | K11: 150.52 | L11: =+K11/J11 -> 0.047486545 | M11: 45877 | N11: 12105 | O11: 795 | P11: =+O11/N11 -> 0.065675341
A12: 45878 | B12: 8759.75 | C12: 1268.95 | D12: =+C12/B12 -> 0.14486144 | E12: 45878 | F12: 14056 | G12: (เข้าสู่ระบบไม่ได้) | H12: =+G12/F12 -> #VALUE! | I12: 45878 | J12: 4044.65 | K12: 150.31 | L12: =+K12/J12 -> 0.037162672 | M12: 45878 | N12: 8320 | O12: 651 | P12: =+O12/N12 -> 0.078245192
A13: 45879 | B13: 25189.21 | C13: 4155.67 | D13: =+C13/B13 -> 0.16497818 | E13: 45879 | F13: 6374 | G13: (เข้าสู่ระบบไม่ได้) | H13: =+G13/F13 -> #VALUE! | I13: 45879 | J13: 4282.14 | K13: 150.2 | L13: =+K13/J13 -> 0.03507592 | M13: 45879 | N13: 3301 | O13: 391 | P13: =+O13/N13 -> 0.11844895
A14: 45880 | B14: 23087.54 | C14: 4271.44 | D14: =+C14/B14 -> 0.18501062 | E14: 45880 | F14: 9104 | G14: (เข้าสู่ระบบไม่ได้) | H14: =+G14/F14 -> #VALUE! | I14: 45880 | J14: 4113.95 | K14: 150.04 | L14: =+K14/J14 -> 0.036471031 | M14: 45880 | N14: 3813 | O14: 465 | P14: =+O14/N14 -> 0.12195122
A15: 45881 | B15: 16046 | C15: 2348.97 | D15: =+C15/B15 -> 0.14638975 | E15: 45881 | F15: 2014 | G15: (เข้าสู่ระบบไม่ได้) | H15: =+G15/F15 -> #VALUE! | I15: 45881 | J15: 1500.4 | K15: 150.34 | L15: =+K15/J15 -> 0.10019995 | M15: 45881 | N15: 3568 | O15: 521 | P15: =+O15/N15 -> 0.14602018
A16: 45882 | B16: 23920.81 | C16: 3576.83 | D16: =+C16/B16 -> 0.14952796 | E16: 45882 | F16: 35880 | G16: (เข้าสู่ระบบไม่ได้) | H16: =+G16/F16 -> #VALUE! | I16: 45882 | J16: 2246 | K16: 154.05 | L16: =+K16/J16 -> 0.068588602 | M16: 45882 | N16: 6272 | O16: 742 | P16: =+O16/N16 -> 0.11830357
A17: 45883 | B17: 16880.62 | C17: 2396.2 | D17: =+C17/B17 -> 0.14194976 | E17: 45883 | F17: 24840 | G17: (เข้าสู่ระบบไม่ได้) | H17: =+G17/F17 -> #VALUE! | I17: 45883 | J17: 3201.3 | K17: 150.09 | L17: =+K17/J17 -> 0.046884078 | M17: 45883 | N17: 3733 | O17: 675 | P17: =+O17/N17 -> 0.18081972
A18: 45884 | B18: 12253.33 | C18: 1467.8 | D18: =+C18/B18 -> 0.11978785 | E18: 45884 | F18: 1200 | G18: (เข้าสู่ระบบไม่ได้) | H18: =+G18/F18 -> #VALUE! | I18: 45884 | J18: 1492.01 | K18: 153.17 | L18: =+K18/J18 -> 0.10266017 | M18: 45884 | N18: 6582 | O18: 681 | P18: =+O18/N18 -> 0.10346399
A19: 45885 | B19: 26972.73 | C19: 4132.86 | D19: =+C19/B19 -> 0.15322364 | E19: 45885 | F19: 6150 | G19: (เข้าสู่ระบบไม่ได้) | H19: =+G19/F19 -> #VALUE! | I19: 45885 | J19: 2661.74 | K19: 139.5 | L19: =+K19/J19 -> 0.052409326 | M19: 45885 | N19: 3865 | O19: 705 | P19: =+O19/N19 -> 0.18240621
A20: 45886 | B20: 21727.25 | C20: 3037.35 | D20: =+C20/B20 -> 0.1397945 | E20: 45886 | F20: 61005 | G20: (เข้าสู่ระบบไม่ได้) | H20: =+G20/F20 -> #VALUE! | I20: 45886 | J20: 2920.71 | K20: 150.06 | L20: =+K20/J20 -> 0.051377918 | M20: 45886 | N20: 8273 | O20: 1877 | P20: =+O20/N20 -> 0.22688263
A21: 45887 | B21: 16602.89 | C21: 3054.1 | D21: =+C21/B21 -> 0.1839499 | E21: 45887 | F21: 36435 | G21: (เข้าสู่ระบบไม่ได้) | H21: =+G21/F21 -> #VALUE! | I21: 45887 | J21: 4135.8 | K21: 151.41 | L21: =+K21/J21 -> 0.036609604 | M21: 45887 | N21: 4880 | O21: 765 | P21: =+O21/N21 -> 0.1567623
A22: 45888 | B22: 22824.98 | C22: 3285.48 | D22: =+C22/B22 -> 0.14394229 | E22: 45888 | F22: 2440 | G22: (เข้าสู่ระบบไม่ได้) | H22: =+G22/F22 -> #VALUE! | I22: 45888 | J22: 4431.3 | K22: 150.09 | L22: =+K22/J22 -> 0.033870422 | M22: 45888 | N22: 7292 | O22: 194 | P22: =+O22/N22 -> 0.026604498
... A30: 45896 | B30: 41042.77 | C30: 6512.51 | D30: =+C30/B30 -> 0.15867618 | E30: 45896 | F30: 3252 | G30: (เข้าสู่ระบบไม่ได้) | H30: =+G30/F30 -> #VALUE! | I30: 45896 | J30: 1955.31 | K30: 150.2 | L30: =+K30/J30 -> 0.076816464 | M30: 45896 | N30: 9132 | O30: 87 | P30: =+O30/N30 -> 0.0095269382
A31: 45897 | B31: 38335.43 | C31: 7629.89 | D31: =+C31/B31 -> 0.19902972 | E31: 45897 | F31: 19595 | G31: 345.55 | H31: =+G31/F31 -> 0.017634601 | I31: 45897 | J31: 3858.34 | K31: 170.39 | L31: =+K31/J31 -> 0.044161479 | M31: 45897 | N31: 5876 | O31: 844 | P31: =+O31/N31 -> 0.14363513
A32: 45898 | B32: 29155.43 | C32: 4543.72 | D32: =+C32/B32 -> 0.15584473 | E32: 45898 | F32: 1150 | G32: 548.8 | H32: =+G32/F32 -> 0.47721739 | I32: 45898 | J32: 2634.95 | K32: 169.94 | L32: =+K32/J32 -> 0.064494582 | M32: 45898 | N32: 3582 | O32: 340 | P32: =+O32/N32 -> 0.09491904
A33: 45899 | B33: 2755 | C33: 2738.53 | D33: =+C33/B33 -> 0.99402178 | E33: 45899 | F33: 6254 | G33: 550.71 | H33: =+G33/F33 -> 0.088057243 | I33: 45899 | J33: 4179.6 | K33: 166.73 | L33: =+K33/J33 -> 0.039891377 | M33: 45899 | N33: 7752 | O33: 767 | P33: =+O33/N33 -> 0.098942208
A34: 45900 | B34: 44007.29 | C34: 7903.06 | D34: =+C34/B34 -> 0.17958525 | E34: 45900 | F34: 8128 | G34: 711.15 | H34: =+G34/F34 -> 0.087493848 | I34: 45900 | J34: 3553.14 | K34: 170.86 | L34: =+K34/J34 -> 0.048087044 | M34: 45900 | N34: 7455 | O34: 791 | P34: =+O34/N34 -> 0.10610329
A35: Total | B35: =SUM(B4:B34) -> 744295.08 | C35: =SUM(C4:C34) -> 116493.69 | D35: บาท | E35: Total | F35: =SUM(F4:F34) -> 428177.66 | G35: =SUM(G4:G34) -> 8548.96 | H35: บาท | I35: Total | J35: =SUM(J4:J34) -> 108192.88 | K35: =SUM(K4:K34) -> 4404.2 | L35: บาท | M35: Total | N35: =SUM(N4:N34) -> 179545 | O35: =SUM(O4:O34) -> 15676.49 | P35: บาท | XFD35: =SUM(A35:XFC35) -> 1605334
B37: ตารางสรุป 1- 31 สิงหาคม 2568
B38: แพลตฟอร์ม | C38: ยอดขาย | D38: ค่าแอด | E38: คิดเป็น%
B39: Tiktok | C39: =+B35 -> 744295.08 | D39: =+C35 -> 116493.69 | E39: =+D39/C39 -> 0.15651546
B40: Facebook | C40: =+F35 -> 428177.66 | D40: =+G35 -> 8548.96 | E40: =+D40/C40 -> 0.019965918
B41: Lazada | C41: =+J35 -> 108192.88 | D41: =+K35 -> 4404.2 | E41: =+D41/C41 -> 0.04070693
B42: Shopee | C42: =+N35 -> 179545 | D42: =+O35 -> 15676.49 | E42: =+D42/C42 -> 0.087312317
B43: รวม | C43: =SUM(C39:C42) -> 1460210.6 | D43: =SUM(D39:D42) -> 145123.34 | E43: =+D43/C43 -> 0.099385211

Sheet ก.ย.
A1: ข้อมูลการยิง ADS ของแผนกออนไลน์ทุกแพลตฟอร์ม เดือนกันยายน 2568
A2: Tiktok | E2: Facebook | I2: Lazada | M2: Shopee
A3: ว/ด/ป | B3: ยอดขาย | C3: ค่าแอด | D3: คิดเป็น% | E3: ว/ด/ป | F3: ยอดขาย | G3: ค่าแอด | H3: คิดเป็น% | I3: ว/ด/ป | J3: ยอดขาย | K3: ค่าแอด | L3: คิดเป็น% | M3: ว/ด/ป | N3: ยอดขาย | O3: ค่าแอด | P3: คิดเป็น%
A4: 45901 | B4: 31350.76 | C4: 4562.29 | D4: =+C4/B4 -> 0.14552406 | E4: 45901 | F4: 12372 | G4: 766.11 | H4: =+G4/F4 -> 0.06192289 | I4: 45901 | J4: 7515 | K4: 280.44 | L4: =+K4/J4 -> 0.037317365 | M4: 45901 | N4: 8483 | O4: 649.55 | P4: =+O4/N4 -> 0.076570789
A5: 45902 | B5: 33116.75 | C5: 4471.49 | D5: =+C5/B5 -> 0.13502201 | E5: 45902 | F5: 42816 | G5: 579.08 | H5: =+G5/F5 -> 0.013524851 | I5: 45902 | J5: 6296.1 | K5: 300.65 | L5: =+K5/J5 -> 0.047751783 | M5: 45902 | N5: 9980 | O5: 1367.95 | P5: =+O5/N5 -> 0.13706914
A6: 45903 | B6: 33583.96 | C6: 5331.82 | D6: =+C6/B6 -> 0.15876091 | E6: 45903 | F6: 8914 | G6: 789.95 | H6: =+G6/F6 -> 0.088619026 | I6: 45903 | J6: 7476.35 | K6: 299.54 | L6: =+K6/J6 -> 0.040065005 | M6: 45903 | N6: 5973 | O6: 636.32 | P6: =+O6/N6 -> 0.10653273
A7: 45904 | B7: 29609.61 | C7: 6495.69 | D7: =+C7/B7 -> 0.21937776 | E7: 45904 | F7: 25498 | G7: 1434.9 | H7: =+G7/F7 -> 0.056275002 | I7: 45904 | J7: 3977.2 | K7: 377 | L7: =+K7/J7 -> 0.094790305 | M7: 45904 | N7: 6068 | O7: 637.8 | P7: =+O7/N7 -> 0.10510877
A8: 45905 | B8: 17401.69 | C8: 2375.75 | D8: =+C8/B8 -> 0.1365241 | E8: 45905 | F8: 3344 | G8: 1658.45 | H8: =+G8/F8 -> 0.49594797 | I8: 45905 | J8: 4734.45 | K8: 299.54 | L8: =+K8/J8 -> 0.063268173 | M8: 45905 | N8: 6998 | O8: 576.21 | P8: =+O8/N8 -> 0.08233924
A9: 45906 | B9: 28281.23 | C9: 5705.14 | D9: =+C9/B9 -> 0.20172885 | E9: 45906 | F9: 9663 | G9: 1772.35 | H9: =+G9/F9 -> 0.18341612 | I9: 45906 | J9: 3635.6 | K9: 339.76 | L9: =+K9/J9 -> 0.093453625 | M9: 45906 | N9: 10472 | O9: 772.24 | P9: =+O9/N9 -> 0.073743316
A10: 45907 | B10: 43595.43 | C10: 8199.86 | D10: =+C10/B10 -> 0.1880899 | E10: 45907 | F10: 11342 | G10: 1747.27 | H10: =+G10/F10 -> 0.15405308 | I10: 45907 | J10: 4532.45 | K10: 639.92 | L10: =+K10/J10 -> 0.14118633 | M10: 45907 | N10: 12230 | O10: 1138.25 | P10: =+O10/N10 -> 0.093070319
A11: 45908 | B11: 34618.1 | C11: 8553.49 | D11: =+C11/B11 -> 0.24708144 | E11: 45908 | F11: 27819 | G11: 1726.87 | H11: =+G11/F11 -> 0.0620752 | I11: 45908 | J11: 5749.29 | K11: 722.17 | L11: =+K11/J11 -> 0.12561029 | M11: 45908 | N11: 10122 | O11: 1246.39 | P11: =+O11/N11 -> 0.12313673
A12: 45909 | B12: 22227.89 | C12: 3842.81 | D12: =+C12/B12 -> 0.17288236 | E12: 45909 | F12: 8727 | G12: 1739.83 | H12: =+G12/F12 -> 0.19936175 | I12: 45909 | J12: 8216 | K12: 1389.07 | L12: =+K12/J12 -> 0.16906889 | M12: 45909 | N12: 17860 | O12: 2507.1 | P12: =+O12/N12 -> 0.14037514
A13: 45910 | B13: 24417.99 | C13: 3703.75 | D13: =+C13/B13 -> 0.1516812 | E13: 45910 | F13: 5466 | G13: 1818.71 | H13: =+G13/F13 -> 0.33273143 | I13: 45910 | J13: 4723.42 | K13: 657.25 | L13: =+K13/J13 -> 0.13914706 | M13: 45910 | N13: 5247 | O13: 414 | P13: =+O13/N13 -> 0.07890223
A14: 45911 | B14: 29923.26 | C14: 3851.95 | D14: =+C14/B14 -> 0.12872762 | E14: 45911 | F14: 31243 | G14: 1807.46 | H14: =+G14/F14 -> 0.057851679 | I14: 45911 | J14: 8374.47 | K14: 659.09 | L14: =+K14/J14 -> 0.078702294 | M14: 45911 | N14: 5248 | O14: 775.9 | P14: =+O14/N14 -> 0.1478468
A15: 45912 | B15: 25499.06 | C15: 3190.78 | D15: =+C15/B15 -> 0.12513324 | E15: 45912 | F15: 2112 | G15: 1938.22 | H15: =+G15/F15 -> 0.9177178 | I15: 45912 | J15: 4667.91 | K15: 295.19 | L15: =+K15/J15 -> 0.063238152 | M15: 45912 | N15: 9508 | O15: 1045.24 | P15: =+O15/N15 -> 0.10993269
... A26: 45923 | B26: 28268 | C26: 4022.9 | D26: =+C26/B26 -> 0.14231286 | E26: 45923 | F26: 3481 | G26: 0 | H26: =+G26/F26 -> 0 | I26: 45923 | J26: 1877.7 | K26: 500.9 | L26: =+K26/J26 -> 0.26676253 | M26: 45923 | N26: 5378 | O26: 420 | P26: =+O26/N26 -> 0.078095946
A27: 45924 | B27: 15616 | C27: 1848.85 | D27: =+C27/B27 -> 0.1183946 | E27: 45924 | F27: - | G27: 0 | H27: =+G27/F27 -> #VALUE! | I27: 45924 | J27: 3095.9 | K27: 497.58 | L27: =+K27/J27 -> 0.16072225 | M27: 45924 | N27: 7071 | O27: 746 | P27: =+O27/N27 -> 0.10550134
A28: 45925 | B28: 26410.8 | C28: 3400.61 | D28: =+C28/B28 -> 0.12875831 | E28: 45925 | F28: 28229 | G28: 1387.31 | H28: =+G28/F28 -> 0.049144851 | I28: 45925 | J28: 2939.37 | K28: 492.14 | L28: =+K28/J28 -> 0.16743044 | M28: 45925 | N28: 6239 | O28: 802.38 | P28: =+O28/N28 -> 0.12860715
A29: 45926 | B29: 28896.17 | C29: 4768.15 | D29: =+C29/B29 -> 0.16500976 | E29: 45926 | F29: 9233 | G29: 1674.77 | H29: =+G29/F29 -> 0.18138958 | I29: 45926 | J29: 3976.23 | K29: 488.63 | L29: =+K29/J29 -> 0.12288776 | M29: 45926 | N29: 5903 | O29: 883.1 | P29: =+O29/N29 -> 0.1496019
A30: 45927 | B30: 24900.81 | C30: 3173.9 | D30: =+C30/B30 -> 0.12746172 | E30: 45927 | F30: 9444 | G30: 2047.28 | H30: =+G30/F30 -> 0.21678102 | I30: 45927 | J30: 2432.43 | K30: 494.01 | L30: =+K30/J30 -> 0.2030932 | M30: 45927 | N30: 7834 | O30: 804.67 | P30: =+O30/N30 -> 0.10271509
A31: 45928 | B31: 34752.98 | C31: 4109.44 | D31: =+C31/B31 -> 0.11824713 | E31: 45928 | F31: 9614 | G31: 2323.89 | H31: =+G31/F31 -> 0.24171937 | I31: 45928 | J31: 2964.63 | K31: 493.95 | L31: =+K31/J31 -> 0.16661438 | M31: 45928 | N31: 5110 | O31: 759.56 | P31: =+O31/N31 -> 0.14864188
A32: 45929 | B32: 35815.62 | C32: 6157.58 | D32: =+C32/B32 -> 0.17192443 | E32: 45929 | F32: 2547 | G32: 2235.07 | H32: =+G32/F32 -> 0.87753043 | I32: 45929 | J32: 3951.81 | K32: 494.9 | L32: =+K32/J32 -> 0.12523375 | M32: 45929 | N32: 4994 | O32: 637.34 | P32: =+O32/N32 -> 0.12762115
A33: 45930 | B33: 41585.13 | C33: 5692.69 | D33: =+C33/B33 -> 0.13689244 | E33: 45930 | F33: 10689 | G33: 2240.99 | H33: =+G33/F33 -> 0.20965385 | I33: 45930 | J33: 4969.01 | K33: 500.51 | L33: =+K33/J33 -> 0.1007263 | M33: 45930 | N33: 6793 | O33: 690.03 | P33: =+O33/N33 -> 0.10157957
A34: 45931 | B34: 0 | C34: 0 | D34: =+C34/B34 -> #DIV/0! | E34: 45931 | H34: =+G34/F34 -> #DIV/0! | I34: 45931 | J34: 0 | K34: 0 | L34: =+K34/J34 -> #DIV/0! | M34: 45931 | N34: 0 | O34: 0 | P34: =+O34/N34 -> #DIV/0!
A35: Total | B35: =SUM(B4:B34) -> 937399.29 | C35: =SUM(C4:C34) -> 150724.24 | D35: บาท | E35: Total | F35: =SUM(F4:F34) -> 362846 | G35: =SUM(G4:G34) -> 40171.39 | H35: บาท | I35: Total | J35: =SUM(J4:J34) -> 131041.06 | K35: =SUM(K4:K34) -> 14726.07 | L35: บาท | M35: Total | N35: =SUM(N4:N34) -> 224164 | O35: =SUM(O4:O34) -> 25801.32 | P35: บาท | XFD35: =SUM(A35:XFC35) -> 1886873.4
B37: ตารางสรุป 1- 30 กันยายน 2568
B38: แพลตฟอร์ม | C38: ยอดขาย | D38: ค่าแอด | E38: คิดเป็น%
B39: Tiktok | C39: =+B35 -> 937399.29 | D39: =+C35 -> 150724.24 | E39: =+D39/C39 -> 0.1607898
B40: Facebook | C40: =+F35 -> 362846 | D40: =+G35 -> 40171.39 | E40: =+D40/C40 -> 0.11071195
B41: Lazada | C41: =+J35 -> 131041.06 | D41: =+K35 -> 14726.07 | E41: =+D41/C41 -> 0.11237753
