Workbook

Sheet เช้า 
B1: ยอดจริง ออนไลน์ วันที่ 11-3-68 เช้า
L2: ยอดรวมผลิต
L3: จำนวน
B4: รหัสสินค้า | C4: สินค้า | D4: ปณ | E4: ชอปปี้ | F4: ลาซาด้า | G4: ติ๊กตอก | H4: ติ๊กตอก 2 | I4: ติ๊กตอก3 | J4: ชอยส์ | K4: ยอดเส้น | L4: (กล่อง)
B6: ชิฟฟอนรวมรส
B7: 1111002 | C7: ชิฟฟอนรวมรส 8 ชิ้น | D7: 3 | E7: 14 | F7: 3 | G7: 11 | L7: =SUM(D7:K7) -> 31
C8: ชิฟฟอนแบบกล่องสุ่มอะไรก็ได้ที่มี | L8: =SUM(D8:K8) -> 0
B9: 1111084 | C9: ชิฟฟอน 8 ชิ้น กาแฟล้วน | L9: =SUM(D9:K9) -> 0
B10: 1111085 | C10: ชิฟฟอน 8 ชิ้น บลูเบอรี่ล้วน | L10: =SUM(D10:K10) -> 0
B11: 1111086 | C11: ชิฟฟอน 8 ชิ้น มะพร้าวล้วน | L11: =SUM(D11:K11) -> 0
B12: 1111087 | C12: ชิฟฟอน 8 ชิ้น สตอเบอรี่ล้วน | L12: =SUM(D12:K12) -> 0
B13: 1111088 | C13: ชิฟฟอน 8 ชิ้น ส้มล้วน | L13: =SUM(D13:K13) -> 0
B14: 1111089 | C14: ชิฟฟอน 8 ชิ้น เนยล้วน | L14: =SUM(D14:K14) -> 0
B15: 1111090 | C15: ชิฟฟอน 8 ชิ้น เผือกล้วน | L15: =SUM(D15:K15) -> 0
B16: 1111091 | C16: ชิฟฟอน 8 ชิ้น ใบเตยล้วน | L16: =SUM(D16:K16) -> 0
B17: 1111092 | C17: ชิฟฟอน 8 ชิ้น กล้วยหอม | L17: =SUM(D17:K17) -> 0
B18: 1111093 | C18: ชิฟฟอน 8 ชิ้น โกโก้ล้วน | L18: =SUM(D18:K18) -> 0
B19: 1111094 | C19: ชิฟฟอน 8 ชิ้น ชาไทยล้วน | L19: =SUM(D19:K19) -> 0
B20: 1111095 | C20: ชิฟฟอน 8 ชิ้น ชาเขียวล้วน | L20: =SUM(D20:K20) -> 0
... B24: 1111043 | C24: ชิฟฟอน 8 ชิ้น มะลิ | L24: =SUM(D24:K24) -> 0
B25: 1111056 | C25: ชิฟฟอน 8 ชิ้น รวมรสยอดฮิต | D25: 1 | E25: 9 | F25: 1 | G25: 1 | L25: =SUM(D25:K25) -> 12
B26: 1004055 | C26: ชิฟฟอนรวมรส 4 ชิ้น | G26: 1 | L26: =SUM(D26:K26) -> 1
B27: 1004055 | C27: ชิฟฟอน 4 ชิ้น โกโก้ล้วน | L27: =SUM(D27:K27) -> 0
B28: 1004055 | C28: ชิฟฟอน 4 ชิ้น มะพร้าวล้วน | L28: =SUM(D28:K28) -> 0
B29: 1004055 | C29: ชิฟฟอน 4 ชิ้น เนยล้วน | L29: =SUM(D29:K29) -> 0
B30: 1004055 | C30: ชิฟฟอน 4 ชิ้น กาแฟล้วน | L30: =SUM(D30:K30) -> 0
B31: 1004055 | C31: ชิฟฟอน 4 ชิ้น ใบเตยล้วน | L31: =SUM(D31:K31) -> 0
B32: 1004055 | C32: ชิฟฟอน 4 ชิ้น บลูเบอร์รี่ล้วน | L32: =SUM(D32:K32) -> 0
B33: 1004055 | C33: ชิฟฟอน 4 ชิ้น ส้มล้วน | L33: =SUM(D33:K33) -> 0
B34: 1004055 | C34: ชิฟฟอน 4 ชิ้น เผือกล้วน | L34: =SUM(D34:K34) -> 0
B35: 1004055 | C35: ชิฟฟอน 4 ชิ้น สตอเบอรี่ล้วน | L35: =SUM(D35:K35) -> 0
B36: 1004055 | C36: ชิฟฟอน 4 ชิ้น กล้วยหอมล้วน | L36: =SUM(D36:K36) -> 0
B37: 1004055 | C37: ชิฟฟอน 4 ชิ้น ชาเขียวล้วน | L37: =SUM(D37:K37) -> 0
B38: 1004055 | C38: ชิฟฟอน 4 ชิ้น ชาไทยล้วน | L38: =SUM(D38:K38) -> 0
... B54: 1111071 | C54: ชิฟฟอนแยกชิ้น ตาล | L54: =SUM(D54:K54) -> 0
B55: 1111001 | C55: ชิฟฟอนแยกชิ้น คละรส | D55: 40 | L55: =SUM(D55:K55) -> 40
B56: 1111074 | C56: ชิฟฟอนไส้แยมแยกชิ้น มะพร้าว | L56: =SUM(D56:K56) -> 0
B57: 1111075 | C57: ชิฟฟอนไส้แยมแยกชิ้น สตอเบอรี่ | L57: =SUM(D57:K57) -> 0
B58: 1111076 | C58: ชิฟฟอนไส้แยมแยกชิ้น ส้ม | L58: =SUM(D58:K58) -> 0
B59: 1111077 | C59: ชิฟฟอนไส้แยมแยกชิ้น บลูเบอรี่ | L59: =SUM(D59:K59) -> 0
...

Sheet บ่าย
B1: ยอดจริง ออนไลน์ วันที่ - บ่าย
L2: ยอดรวมผลิต
L3: จำนวน
B4: รหัสสินค้า | C4: สินค้า | D4: ปณ | E4: ชอปปี้ | F4: ลาซาด้า | G4: ติ๊กตอก | H4: ติ๊กตอก 2 | I4: ติ๊กตอก3 | J4: ชอยส์ | K4: ยอดเส้น | L4: (กล่อง)
B6: ชิฟฟอนรวมรส
B7: 1111002 | C7: ชิฟฟอนรวมรส 8 ชิ้น | D7: 6 | E7: 4 | F7: 14 | G7: 12 | L7: =SUM(D7:K7) -> 36
C8: ชิฟฟอนแบบกล่องสุ่มอะไรก็ได้ที่มี | L8: =SUM(D8:K8) -> 0
B9: 1111084 | C9: ชิฟฟอน 8 ชิ้น กาแฟล้วน | L9: =SUM(D9:K9) -> 0
B10: 1111085 | C10: ชิฟฟอน 8 ชิ้น บลูเบอรี่ล้วน | L10: =SUM(D10:K10) -> 0
B11: 1111086 | C11: ชิฟฟอน 8 ชิ้น มะพร้าวล้วน | L11: =SUM(D11:K11) -> 0
B12: 1111087 | C12: ชิฟฟอน 8 ชิ้น สตอเบอรี่ล้วน | L12: =SUM(D12:K12) -> 0
B13: 1111088 | C13: ชิฟฟอน 8 ชิ้น ส้มล้วน | L13: =SUM(D13:K13) -> 0
B14: 1111089 | C14: ชิฟฟอน 8 ชิ้น เนยล้วน | L14: =SUM(D14:K14) -> 0
B15: 1111090 | C15: ชิฟฟอน 8 ชิ้น เผือกล้วน | L15: =SUM(D15:K15) -> 0
B16: 1111091 | C16: ชิฟฟอน 8 ชิ้น ใบเตยล้วน | L16: =SUM(D16:K16) -> 0
B17: 1111092 | C17: ชิฟฟอน 8 ชิ้น กล้วยหอม | L17: =SUM(D17:K17) -> 0
B18: 1111093 | C18: ชิฟฟอน 8 ชิ้น โกโก้ล้วน | L18: =SUM(D18:K18) -> 0
B19: 1111094 | C19: ชิฟฟอน 8 ชิ้น ชาไทยล้วน | L19: =SUM(D19:K19) -> 0
B20: 1111095 | C20: ชิฟฟอน 8 ชิ้น ชาเขียวล้วน | L20: =SUM(D20:K20) -> 0
... B24: 1111043 | C24: ชิฟฟอน 8 ชิ้น มะลิ | L24: =SUM(D24:K24) -> 0
B25: 1111056 | C25: ชิฟฟอน 8 ชิ้น รวมรสยอดฮิต | D25: 1 | F25: 1 | G25: 1 | L25: =SUM(D25:K25) -> 3
B26: 1004055 | C26: ชิฟฟอนรวมรส 4 ชิ้น | L26: =SUM(D26:K26) -> 0
B27: 1004055 | C27: ชิฟฟอน 4 ชิ้น โกโก้ล้วน | L27: =SUM(D27:K27) -> 0
B28: 1004055 | C28: ชิฟฟอน 4 ชิ้น มะพร้าวล้วน | L28: =SUM(D28:K28) -> 0
B29: 1004055 | C29: ชิฟฟอน 4 ชิ้น เนยล้วน | L29: =SUM(D29:K29) -> 0
B30: 1004055 | C30: ชิฟฟอน 4 ชิ้น กาแฟล้วน | L30: =SUM(D30:K30) -> 0
B31: 1004055 | C31: ชิฟฟอน 4 ชิ้น ใบเตยล้วน | L31: =SUM(D31:K31) -> 0
B32: 1004055 | C32: ชิฟฟอน 4 ชิ้น บลูเบอร์รี่ล้วน | L32: =SUM(D32:K32) -> 0
B33: 1004055 | C33: ชิฟฟอน 4 ชิ้น ส้มล้วน | L33: =SUM(D33:K33) -> 0
B34: 1004055 | C34: ชิฟฟอน 4 ชิ้น เผือกล้วน | L34: =SUM(D34:K34) -> 0
B35: 1004055 | C35: ชิฟฟอน 4 ชิ้น สตอเบอรี่ล้วน | L35: =SUM(D35:K35) -> 0
B36: 1004055 | C36: ชิฟฟอน 4 ชิ้น กล้วยหอมล้วน | L36: =SUM(D36:K36) -> 0
B37: 1004055 | C37: ชิฟฟอน 4 ชิ้น ชาเขียวล้วน | L37: =SUM(D37:K37) -> 0
... B39: 1004055 | C39: ชิฟฟอน 4 ชิ้น สับปะรดล้วน | L39: =SUM(D39:K39) -> 0
B40: 1111057 | C40: ชิฟฟอนแยกชิ้น กาแฟ | D40: 2 | L40: =SUM(D40:K40) -> 2
B41: 1111058 | C41: ชิฟฟอนแยกชิ้น ชาเขียว | D41: 2 | L41: =SUM(D41:K41) -> 2
B42: 1111059 | C42: ชิฟฟอนแยกชิ้น ใบเตย | D42: 2 | L42: =SUM(D42:K42) -> 2
B43: 1111060 | C43: ชิฟฟอนแยกชิ้น กล้วยหอม | D43: 2 | L43: =SUM(D43:K43) -> 2
B44: 1111061 | C44: ชิฟฟอนแยกชิ้น ชาไทย | D44: 2 | L44: =SUM(D44:K44) -> 2
B45: 1111062 | C45: ชิฟฟอนแยกชิ้น โกโก้ | D45: 2 | L45: =SUM(D45:K45) -> 2
...

Sheet เย็น 
B1: ยอดจริง ออนไลน์ วันที่ - เย็น
L2: ยอดรวมผลิต
L3: จำนวน
B4: รหัสสินค้า | C4: สินค้า | D4: ปณ | E4: ชอปปี้ | F4: ลาซาด้า | G4: ติ๊กตอก | H4: ติ๊กตอก 2 | I4: ติ๊กตอก3 | J4: ชอยส์ | K4: ยอดเส้น | L4: (กล่อง)
B6: ชิฟฟอนรวมรส
B7: 1111002 | C7: ชิฟฟอนรวมรส 8 ชิ้น | L7: =SUM(D7:K7) -> 0
C8: ชิฟฟอนแบบกล่องสุ่มอะไรก็ได้ที่มี | L8: =SUM(D8:K8) -> 0
B9: 1111084 | C9: ชิฟฟอน 8 ชิ้น กาแฟล้วน | L9: =SUM(D9:K9) -> 0
B10: 1111085 | C10: ชิฟฟอน 8 ชิ้น บลูเบอรี่ล้วน | L10: =SUM(D10:K10) -> 0
B11: 1111086 | C11: ชิฟฟอน 8 ชิ้น มะพร้าวล้วน | L11: =SUM(D11:K11) -> 0
B12: 1111087 | C12: ชิฟฟอน 8 ชิ้น สตอเบอรี่ล้วน | L12: =SUM(D12:K12) -> 0
B13: 1111088 | C13: ชิฟฟอน 8 ชิ้น ส้มล้วน | L13: =SUM(D13:K13) -> 0
B14: 1111089 | C14: ชิฟฟอน 8 ชิ้น เนยล้วน | L14: =SUM(D14:K14) -> 0
B15: 1111090 | C15: ชิฟฟอน 8 ชิ้น เผือกล้วน | L15: =SUM(D15:K15) -> 0
B16: 1111091 | C16: ชิฟฟอน 8 ชิ้น ใบเตยล้วน | L16: =SUM(D16:K16) -> 0
B17: 1111092 | C17: ชิฟฟอน 8 ชิ้น กล้วยหอม | L17: =SUM(D17:K17) -> 0
B18: 1111093 | C18: ชิฟฟอน 8 ชิ้น โกโก้ล้วน | L18: =SUM(D18:K18) -> 0
B19: 1111094 | C19: ชิฟฟอน 8 ชิ้น ชาไทยล้วน | L19: =SUM(D19:K19) -> 0
B20: 1111095 | C20: ชิฟฟอน 8 ชิ้น ชาเขียวล้วน | L20: =SUM(D20:K20) -> 0
... B66: 1111010 | C66: ชิฟฟอนไส้แยมแยกชิ้น คละรส | L66: =SUM(D66:K66) -> 0
C67: รวม
B68: ชิฟฟอนไส้แยม 6 ชิ้น
B69: 1111009 | C69: ชิฟฟอนไส้แยมรวมรส 6 ชิ้น | L69: =SUM(D69:K69) -> 0
B70: 1111023 | C70: ชิฟฟอนไส้แยมรสสตอเบอร์รี่ล้วน 6 ชิ้น | L70: =SUM(D70:K70) -> 0
B71: 1111016 | C71: ชิฟฟอนไส้แยมรสมะพร้าวล้วน 6 ชิ้น | L71: =SUM(D71:K71) -> 0
B72: 1111014 | C72: ชิฟฟอนไส้แยมรสช็อกโกแลตนูเทลล่าล้วน 6 ชิ้น | L72: =SUM(D72:K72) -> 0
B73: 1111025 | C73: ชิฟฟอนไส้แยมรสส้มล้วน 6 ชิ้น | L73: =SUM(D73:K73) -> 0
B74: 1111018 | C74: ชิฟฟอนไส้แยมรสบลูเบอร์รี่ล้วน 6 ชิ้น | L74: =SUM(D74:K74) -> 0
B75: 1111012 | C75: ชิฟฟอนไส้แยมรสนมชมพูฮอกไกโดล้วน 6 ชิ้น | L75: =SUM(D75:K75) -> 0
B76: 1111020 | C76: ชิฟฟอนไส้แยมฝอยทองไส้ทะลัก 6 ชิ้น | L76: =SUM(D76:K76) -> 0
C77: รวม
B78: ชิฟฟอนไส้แยม 3 ชิ้น
B79: 1111022 | C79: ชิฟฟอนไส้แยมรสสตอเบอร์รี่ล้วน 3 ชิ้น | L79: =SUM(D79:K79) -> 0
B80: 1111015 | C80: ชิฟฟอนไส้แยมรสมะพร้าวล้วน 3 ชิ้น | L80: =SUM(D80:K80) -> 0
B81: 1111013 | C81: ชิฟฟอนไส้แยมรสช็อกโกแลตนูเทลล่าล้วน 3 ชิ้น | L81: =SUM(D81:K81) -> 0
B82: 1111024 | C82: ชิฟฟอนไส้แยมรสส้มล้วน 3 ชิ้น | L82: =SUM(D82:K82) -> 0
B83: 1111017 | C83: ชิฟฟอนไส้แยมรสบลูเบอร์รี่ล้วน 3 ชิ้น | L83: =SUM(D83:K83) -> 0
B84: 1111011 | C84: ชิฟฟอนไส้แยมรสนมชมพูฮอกไกโดล้วน 3 ชิ้น | L84: =SUM(D84:K84) -> 0
B85: 1111019 | C85: ชิฟฟอนไส้แยมฝอยทองไส้ทะลัก 3 ชิ้น | L85: =SUM(D85:K85) -> 0
B86: 1113081 | C86: ชิฟฟอนไส้แยม วนิลา/ใบเตย/เมล่อน | L86: =SUM(D86:K86) -> 0
...

Sheet รวม
B1: ยอดจริง ออนไลน์ วันที่ 11-3-68
L2: ยอดรวมผลิต | M2: ยอดฟอแคส | N2: ยอดสตอค | O2: ยอดเมโม่ | P2: ยอดฟอแคสวันพรุ่งนี้ | Q2: รวม
L3: จำนวน
B4: รหัสสินค้า | C4: สินค้า | D4: ปณ | E4: ชอปปี้ | F4: ลาซาด้า | G4: ติ๊กตอก | H4: ติ๊กตอก2 | I4: ติ๊กตอก3 | J4: ชอยส์ | K4: ยอดเส้น | L4: (กล่อง)
B6: ชิฟฟอนรวมรส
B7: 1111002 | C7: ชิฟฟอนรวมรส 8 ชิ้น | D7: ='เย็น '!D7+'เช้า '!D7+บ่าย!D7 -> 9 | E7: ='เย็น '!E7+'เช้า '!E7+บ่าย!E7 -> 18 | F7: ='เย็น '!F7+'เช้า '!F7+บ่าย!F7 -> 17 | G7: ='เย็น '!G7+'เช้า '!G7+บ่าย!G7 -> 23 | H7: ='เย็น '!H7+'เช้า '!H7+บ่าย!H7 -> 0 | I7: ='เย็น '!I7+'เช้า '!I7+บ่าย!I7 -> 0 | J7: ='เย็น '!J7+'เช้า '!J7+บ่าย!J7 -> 0 | K7: ='เย็น '!K7+'เช้า '!K7+บ่าย!K7 -> 0 | L7: =SUM(D7:K7) -> 67 | M7: 200 | N7: 376 | P7: 50 | Q7: =(M7+N7+O7+P7)-L7 -> 559
C8: ชิฟฟอนแบบกล่องสุ่มอะไรก็ได้ที่มี | D8: ='เย็น '!D8+'เช้า '!D8+บ่าย!D8 -> 0 | E8: ='เย็น '!E8+'เช้า '!E8+บ่าย!E8 -> 0 | F8: ='เย็น '!F8+'เช้า '!F8+บ่าย!F8 -> 0 | G8: ='เย็น '!G8+'เช้า '!G8+บ่าย!G8 -> 0 | H8: ='เย็น '!H8+'เช้า '!H8+บ่าย!H8 -> 0 | I8: ='เย็น '!I8+'เช้า '!I8+บ่าย!I8 -> 0 | J8: ='เย็น '!J8+'เช้า '!J8+บ่าย!J8 -> 0 | K8: ='เย็น '!K8+'เช้า '!K8+บ่าย!K8 -> 0 | L8: =SUM(D8:K8) -> 0 | Q8: =(M8+N8+O8+P8)-L8 -> 0
B9: 1111084 | C9: ชิฟฟอน 8 ชิ้น กาแฟล้วน | D9: ='เย็น '!D9+'เช้า '!D9+บ่าย!D9 -> 0 | E9: ='เย็น '!E9+'เช้า '!E9+บ่าย!E9 -> 0 | F9: ='เย็น '!F9+'เช้า '!F9+บ่าย!F9 -> 0 | G9: ='เย็น '!G9+'เช้า '!G9+บ่าย!G9 -> 0 | H9: ='เย็น '!H9+'เช้า '!H9+บ่าย!H9 -> 0 | I9: ='เย็น '!I9+'เช้า '!I9+บ่าย!I9 -> 0 | J9: ='เย็น '!J9+'เช้า '!J9+บ่าย!J9 -> 0 | K9: ='เย็น '!K9+'เช้า '!K9+บ่าย!K9 -> 0 | L9: =SUM(D9:K9) -> 0 | Q9: =(M9+N9+O9+P9)-L9 -> 0
B10: 1111085 | C10: ชิฟฟอน 8 ชิ้น บลูเบอรี่ล้วน | D10: ='เย็น '!D10+'เช้า '!D10+บ่าย!D10 -> 0 | E10: ='เย็น '!E10+'เช้า '!E10+บ่าย!E10 -> 0 | F10: ='เย็น '!F10+'เช้า '!F10+บ่าย!F10 -> 0 | G10: ='เย็น '!G10+'เช้า '!G10+บ่าย!G10 -> 0 | H10: ='เย็น '!H10+'เช้า '!H10+บ่าย!H10 -> 0 | I10: ='เย็น '!I10+'เช้า '!I10+บ่าย!I10 -> 0 | J10: ='เย็น '!J10+'เช้า '!J10+บ่าย!J10 -> 0 | K10: ='เย็น '!K10+'เช้า '!K10+บ่าย!K10 -> 0 | L10: =SUM(D10:K10) -> 0 | Q10: =(M10+N10+O10+P10)-L10 -> 0
B11: 1111086 | C11: ชิฟฟอน 8 ชิ้น มะพร้าวล้วน | D11: ='เย็น '!D11+'เช้า '!D11+บ่าย!D11 -> 0 | E11: ='เย็น '!E11+'เช้า '!E11+บ่าย!E11 -> 0 | F11: ='เย็น '!F11+'เช้า '!F11+บ่าย!F11 -> 0 | G11: ='เย็น '!G11+'เช้า '!G11+บ่าย!G11 -> 0 | H11: ='เย็น '!H11+'เช้า '!H11+บ่าย!H11 -> 0 | I11: ='เย็น '!I11+'เช้า '!I11+บ่าย!I11 -> 0 | J11: ='เย็น '!J11+'เช้า '!J11+บ่าย!J11 -> 0 | K11: ='เย็น '!K11+'เช้า '!K11+บ่าย!K11 -> 0 | L11: =SUM(D11:K11) -> 0 | Q11: =(M11+N11+O11+P11)-L11 -> 0
B12: 1111087 | C12: ชิฟฟอน 8 ชิ้น สตอเบอรี่ล้วน | D12: ='เย็น '!D12+'เช้า '!D12+บ่าย!D12 -> 0 | E12: ='เย็น '!E12+'เช้า '!E12+บ่าย!E12 -> 0 | F12: ='เย็น '!F12+'เช้า '!F12+บ่าย!F12 -> 0 | G12: ='เย็น '!G12+'เช้า '!G12+บ่าย!G12 -> 0 | H12: ='เย็น '!H12+'เช้า '!H12+บ่าย!H12 -> 0 | I12: ='เย็น '!I12+'เช้า '!I12+บ่าย!I12 -> 0 | J12: ='เย็น '!J12+'เช้า '!J12+บ่าย!J12 -> 0 | K12: ='เย็น '!K12+'เช้า '!K12+บ่าย!K12 -> 0 | L12: =SUM(D12:K12) -> 0 | Q12: =(M12+N12+O12+P12)-L12 -> 0
B13: 1111088 | C13: ชิฟฟอน 8 ชิ้น ส้มล้วน | D13: ='เย็น '!D13+'เช้า '!D13+บ่าย!D13 -> 0 | E13: ='เย็น '!E13+'เช้า '!E13+บ่าย!E13 -> 0 | F13: ='เย็น '!F13+'เช้า '!F13+บ่าย!F13 -> 0 | G13: ='เย็น '!G13+'เช้า '!G13+บ่าย!G13 -> 0 | H13: ='เย็น '!H13+'เช้า '!H13+บ่าย!H13 -> 0 | I13: ='เย็น '!I13+'เช้า '!I13+บ่าย!I13 -> 0 | J13: ='เย็น '!J13+'เช้า '!J13+บ่าย!J13 -> 0 | K13: ='เย็น '!K13+'เช้า '!K13+บ่าย!K13 -> 0 | L13: =SUM(D13:K13) -> 0 | Q13: =(M13+N13+O13+P13)-L13 -> 0
B14: 1111089 | C14: ชิฟฟอน 8 ชิ้น เนยล้วน | D14: ='เย็น '!D14+'เช้า '!D14+บ่าย!D14 -> 0 | E14: ='เย็น '!E14+'เช้า '!E14+บ่าย!E14 -> 0 | F14: ='เย็น '!F14+'เช้า '!F14+บ่าย!F14 -> 0 | G14: ='เย็น '!G14+'เช้า '!G14+บ่าย!G14 -> 0 | H14: ='เย็น '!H14+'เช้า '!H14+บ่าย!H14 -> 0 | I14: ='เย็น '!I14+'เช้า '!I14+บ่าย!I14 -> 0 | J14: ='เย็น '!J14+'เช้า '!J14+บ่าย!J14 -> 0 | K14: ='เย็น '!K14+'เช้า '!K14+บ่าย!K14 -> 0 | L14: =SUM(D14:K14) -> 0 | Q14: =(M14+N14+O14+P14)-L14 -> 0
B15: 1111090 | C15: ชิฟฟอน 8 ชิ้น เผือกล้วน | D15: ='เย็น '!D15+'เช้า '!D15+บ่าย!D15 -> 0 | E15: ='เย็น '!E15+'เช้า '!E15+บ่าย!E15 -> 0 | F15: ='เย็น '!F15+'เช้า '!F15+บ่าย!F15 -> 0 | G15: ='เย็น '!G15+'เช้า '!G15+บ่าย!G15 -> 0 | H15: ='เย็น '!H15+'เช้า '!H15+บ่าย!H15 -> 0 | I15: ='เย็น '!I15+'เช้า '!I15+บ่าย!I15 -> 0 | J15: ='เย็น '!J15+'เช้า '!J15+บ่าย!J15 -> 0 | K15: ='เย็น '!K15+'เช้า '!K15+บ่าย!K15 -> 0 | L15: =SUM(D15:K15) -> 0 | Q15: =(M15+N15+O15+P15)-L15 -> 0
B16: 1111091 | C16: ชิฟฟอน 8 ชิ้น ใบเตยล้วน | D16: ='เย็น '!D16+'เช้า '!D16+บ่าย!D16 -> 0 | E16: ='เย็น '!E16+'เช้า '!E16+บ่าย!E16 -> 0 | F16: ='เย็น '!F16+'เช้า '!F16+บ่าย!F16 -> 0 | G16: ='เย็น '!G16+'เช้า '!G16+บ่าย!G16 -> 0 | H16: ='เย็น '!H16+'เช้า '!H16+บ่าย!H16 -> 0 | I16: ='เย็น '!I16+'เช้า '!I16+บ่าย!I16 -> 0 | J16: ='เย็น '!J16+'เช้า '!J16+บ่าย!J16 -> 0 | K16: ='เย็น '!K16+'เช้า '!K16+บ่าย!K16 -> 0 | L16: =SUM(D16:K16) -> 0 | Q16: =(M16+N16+O16+P16)-L16 -> 0
B17: 1111092 | C17: ชิฟฟอน 8 ชิ้น กล้วยหอม | D17: ='เย็น '!D17+'เช้า '!D17+บ่าย!D17 -> 0 | E17: ='เย็น '!E17+'เช้า '!E17+บ่าย!E17 -> 0 | F17: ='เย็น '!F17+'เช้า '!F17+บ่าย!F17 -> 0 | G17: ='เย็น '!G17+'เช้า '!G17+บ่าย!G17 -> 0 | H17: ='เย็น '!H17+'เช้า '!H17+บ่าย!H17 -> 0 | I17: ='เย็น '!I17+'เช้า '!I17+บ่าย!I17 -> 0 | J17: ='เย็น '!J17+'เช้า '!J17+บ่าย!J17 -> 0 | K17: ='เย็น '!K17+'เช้า '!K17+บ่าย!K17 -> 0 | L17: =SUM(D17:K17) -> 0 | Q17: =(M17+N17+O17+P17)-L17 -> 0
B18: 1111093 | C18: ชิฟฟอน 8 ชิ้น โกโก้ล้วน | D18: ='เย็น '!D18+'เช้า '!D18+บ่าย!D18 -> 0 | E18: ='เย็น '!E18+'เช้า '!E18+บ่าย!E18 -> 0 | F18: ='เย็น '!F18+'เช้า '!F18+บ่าย!F18 -> 0 | G18: ='เย็น '!G18+'เช้า '!G18+บ่าย!G18 -> 0 | H18: ='เย็น '!H18+'เช้า '!H18+บ่าย!H18 -> 0 | I18: ='เย็น '!I18+'เช้า '!I18+บ่าย!I18 -> 0 | J18: ='เย็น '!J18+'เช้า '!J18+บ่าย!J18 -> 0 | K18: ='เย็น '!K18+'เช้า '!K18+บ่าย!K18 -> 0 | L18: =SUM(D18:K18) -> 0 | Q18: =(M18+N18+O18+P18)-L18 -> 0
B19: 1111094 | C19: ชิฟฟอน 8 ชิ้น ชาไทยล้วน | D19: ='เย็น '!D19+'เช้า '!D19+บ่าย!D19 -> 0 | E19: ='เย็น '!E19+'เช้า '!E19+บ่าย!E19 -> 0 | F19: ='เย็น '!F19+'เช้า '!F19+บ่าย!F19 -> 0 | G19: ='เย็น '!G19+'เช้า '!G19+บ่าย!G19 -> 0 | H19: ='เย็น '!H19+'เช้า '!H19+บ่าย!H19 -> 0 | I19: ='เย็น '!I19+'เช้า '!I19+บ่าย!I19 -> 0 | J19: ='เย็น '!J19+'เช้า '!J19+บ่าย!J19 -> 0 | K19: ='เย็น '!K19+'เช้า '!K19+บ่าย!K19 -> 0 | L19: =SUM(D19:K19) -> 0 | Q19: =(M19+N19+O19+P19)-L19 -> 0
B20: 1111095 | C20: ชิฟฟอน 8 ชิ้น ชาเขียวล้วน | D20: ='เย็น '!D20+'เช้า '!D20+บ่าย!D20 -> 0 | E20: ='เย็น '!E20+'เช้า '!E20+บ่าย!E20 -> 0 | F20: ='เย็น '!F20+'เช้า '!F20+บ่าย!F20 -> 0 | G20: ='เย็น '!G20+'เช้า '!G20+บ่าย!G20 -> 0 | H20: ='เย็น '!H20+'เช้า '!H20+บ่าย!H20 -> 0 | I20: ='เย็น '!I20+'เช้า '!I20+บ่าย!I20 -> 0 | J20: ='เย็น '!J20+'เช้า '!J20+บ่าย!J20 -> 0 | K20: ='เย็น '!K20+'เช้า '!K20+บ่าย!K20 -> 0 | L20: =SUM(D20:K20) -> 0 | Q20: =(M20+N20+O20+P20)-L20 -> 0
... B24: 1111043 | C24: ชิฟฟอน 8 ชิ้น มะลิ | D24: ='เย็น '!D24+'เช้า '!D24+บ่าย!D24 -> 0 | E24: ='เย็น '!E24+'เช้า '!E24+บ่าย!E24 -> 0 | F24: ='เย็น '!F24+'เช้า '!F24+บ่าย!F24 -> 0 | G24: ='เย็น '!G24+'เช้า '!G24+บ่าย!G24 -> 0 | H24: ='เย็น '!H24+'เช้า '!H24+บ่าย!H24 -> 0 | I24: ='เย็น '!I24+'เช้า '!I24+บ่าย!I24 -> 0 | J24: ='เย็น '!J24+'เช้า '!J24+บ่าย!J24 -> 0 | K24: ='เย็น '!K24+'เช้า '!K24+บ่าย!K24 -> 0 | L24: =SUM(D24:K24) -> 0 | Q24: =(M24+N24+O24+P24)-L24 -> 0
B25: 1111056 | C25: ชิฟฟอน 8 ชิ้น รวมรสยอดฮิต | D25: ='เย็น '!D25+'เช้า '!D25+บ่าย!D25 -> 2 | E25: ='เย็น '!E25+'เช้า '!E25+บ่าย!E25 -> 9 | F25: ='เย็น '!F25+'เช้า '!F25+บ่าย!F25 -> 2 | G25: ='เย็น '!G25+'เช้า '!G25+บ่าย!G25 -> 2 | H25: ='เย็น '!H25+'เช้า '!H25+บ่าย!H25 -> 0 | I25: ='เย็น '!I25+'เช้า '!I25+บ่าย!I25 -> 0 | J25: ='เย็น '!J25+'เช้า '!J25+บ่าย!J25 -> 0 | K25: ='เย็น '!K25+'เช้า '!K25+บ่าย!K25 -> 0 | L25: =SUM(D25:K25) -> 15 | M25: 10 | N25: 2 | P25: 20 | Q25: =(M25+N25+O25+P25)-L25 -> 17
B26: 1004055 | C26: ชิฟฟอนรวมรส 4 ชิ้น | D26: ='เย็น '!D26+'เช้า '!D26+บ่าย!D26 -> 0 | E26: ='เย็น '!E26+'เช้า '!E26+บ่าย!E26 -> 0 | F26: ='เย็น '!F26+'เช้า '!F26+บ่าย!F26 -> 0 | G26: ='เย็น '!G26+'เช้า '!G26+บ่าย!G26 -> 1 | H26: ='เย็น '!H26+'เช้า '!H26+บ่าย!H26 -> 0 | I26: ='เย็น '!I26+'เช้า '!I26+บ่าย!I26 -> 0 | J26: ='เย็น '!J26+'เช้า '!J26+บ่าย!J26 -> 0 | K26: ='เย็น '!K26+'เช้า '!K26+บ่าย!K26 -> 0 | L26: =SUM(D26:K26) -> 1 | N26: 8 | Q26: =(M26+N26+O26+P26)-L26 -> 7
B27: 1004055 | C27: ชิฟฟอน 4 ชิ้น โกโก้ล้วน | D27: ='เย็น '!D27+'เช้า '!D27+บ่าย!D27 -> 0 | E27: ='เย็น '!E27+'เช้า '!E27+บ่าย!E27 -> 0 | F27: ='เย็น '!F27+'เช้า '!F27+บ่าย!F27 -> 0 | G27: ='เย็น '!G27+'เช้า '!G27+บ่าย!G27 -> 0 | H27: ='เย็น '!H27+'เช้า '!H27+บ่าย!H27 -> 0 | I27: ='เย็น '!I27+'เช้า '!I27+บ่าย!I27 -> 0 | J27: ='เย็น '!J27+'เช้า '!J27+บ่าย!J27 -> 0 | K27: ='เย็น '!K27+'เช้า '!K27+บ่าย!K27 -> 0 | L27: =SUM(D27:K27) -> 0 | Q27: =(M27+N27+O27+P27)-L27 -> 0
B28: 1004055 | C28: ชิฟฟอน 4 ชิ้น มะพร้าวล้วน | D28: ='เย็น '!D28+'เช้า '!D28+บ่าย!D28 -> 0 | E28: ='เย็น '!E28+'เช้า '!E28+บ่าย!E28 -> 0 | F28: ='เย็น '!F28+'เช้า '!F28+บ่าย!F28 -> 0 | G28: ='เย็น '!G28+'เช้า '!G28+บ่าย!G28 -> 0 | H28: ='เย็น '!H28+'เช้า '!H28+บ่าย!H28 -> 0 | I28: ='เย็น '!I28+'เช้า '!I28+บ่าย!I28 -> 0 | J28: ='เย็น '!J28+'เช้า '!J28+บ่าย!J28 -> 0 | K28: ='เย็น '!K28+'เช้า '!K28+บ่าย!K28 -> 0 | L28: =SUM(D28:K28) -> 0 | Q28: =(M28+N28+O28+P28)-L28 -> 0
B29: 1004055 | C29: ชิฟฟอน 4 ชิ้น เนยล้วน | D29: ='เย็น '!D29+'เช้า '!D29+บ่าย!D29 -> 0 | E29: ='เย็น '!E29+'เช้า '!E29+บ่าย!E29 -> 0 | F29: ='เย็น '!F29+'เช้า '!F29+บ่าย!F29 -> 0 | G29: ='เย็น '!G29+'เช้า '!G29+บ่าย!G29 -> 0 | H29: ='เย็น '!H29+'เช้า '!H29+บ่าย!H29 -> 0 | I29: ='เย็น '!I29+'เช้า '!I29+บ่าย!I29 -> 0 | J29: ='เย็น '!J29+'เช้า '!J29+บ่าย!J29 -> 0 | K29: ='เย็น '!K29+'เช้า '!K29+บ่าย!K29 -> 0 | L29: =SUM(D29:K29) -> 0 | Q29: =(M29+N29+O29+P29)-L29 -> 0
B30: 1004055 | C30: ชิฟฟอน 4 ชิ้น กาแฟล้วน | D30: ='เย็น '!D30+'เช้า '!D30+บ่าย!D30 -> 0 | E30: ='เย็น '!E30+'เช้า '!E30+บ่าย!E30 -> 0 | F30: ='เย็น '!F30+'เช้า '!F30+บ่าย!F30 -> 0 | G30: ='เย็น '!G30+'เช้า '!G30+บ่าย!G30 -> 0 | H30: ='เย็น '!H30+'เช้า '!H30+บ่าย!H30 -> 0 | I30: ='เย็น '!I30+'เช้า '!I30+บ่าย!I30 -> 0 | J30: ='เย็น '!J30+'เช้า '!J30+บ่าย!J30 -> 0 | K30: ='เย็น '!K30+'เช้า '!K30+บ่าย!K30 -> 0 | L30: =SUM(D30:K30) -> 0 | Q30: =(M30+N30+O30+P30)-L30 -> 0
B31: 1004055 | C31: ชิฟฟอน 4 ชิ้น ใบเตยล้วน | D31: ='เย็น '!D31+'เช้า '!D31+บ่าย!D31 -> 0 | E31: ='เย็น '!E31+'เช้า '!E31+บ่าย!E31 -> 0 | F31: ='เย็น '!F31+'เช้า '!F31+บ่าย!F31 -> 0 | G31: ='เย็น '!G31+'เช้า '!G31+บ่าย!G31 -> 0 | H31: ='เย็น '!H31+'เช้า '!H31+บ่าย!H31 -> 0 | I31: ='เย็น '!I31+'เช้า '!I31+บ่าย!I31 -> 0 | J31: ='เย็น '!J31+'เช้า '!J31+บ่าย!J31 -> 0 | K31: ='เย็น '!K31+'เช้า '!K31+บ่าย!K31 -> 0 | L31: =SUM(D31:K31) -> 0 | Q31: =(M31+N31+O31+P31)-L31 -> 0
B32: 1004055 | C32: ชิฟฟอน 4 ชิ้น บลูเบอร์รี่ล้วน | D32: ='เย็น '!D32+'เช้า '!D32+บ่าย!D32 -> 0 | E32: ='เย็น '!E32+'เช้า '!E32+บ่าย!E32 -> 0 | F32: ='เย็น '!F32+'เช้า '!F32+บ่าย!F32 -> 0 | G32: ='เย็น '!G32+'เช้า '!G32+บ่าย!G32 -> 0 | H32: ='เย็น '!H32+'เช้า '!H32+บ่าย!H32 -> 0 | I32: ='เย็น '!I32+'เช้า '!I32+บ่าย!I32 -> 0 | J32: ='เย็น '!J32+'เช้า '!J32+บ่าย!J32 -> 0 | K32: ='เย็น '!K32+'เช้า '!K32+บ่าย!K32 -> 0 | L32: =SUM(D32:K32) -> 0 | Q32: =(M32+N32+O32+P32)-L32 -> 0
B33: 1004055 | C33: ชิฟฟอน 4 ชิ้น ส้มล้วน | D33: ='เย็น '!D33+'เช้า '!D33+บ่าย!D33 -> 0 | E33: ='เย็น '!E33+'เช้า '!E33+บ่าย!E33 -> 0 | F33: ='เย็น '!F33+'เช้า '!F33+บ่าย!F33 -> 0 | G33: ='เย็น '!G33+'เช้า '!G33+บ่าย!G33 -> 0 | H33: ='เย็น '!H33+'เช้า '!H33+บ่าย!H33 -> 0 | I33: ='เย็น '!I33+'เช้า '!I33+บ่าย!I33 -> 0 | J33: ='เย็น '!J33+'เช้า '!J33+บ่าย!J33 -> 0 | K33: ='เย็น '!K33+'เช้า '!K33+บ่าย!K33 -> 0 | L33: =SUM(D33:K33) -> 0 | Q33: =(M33+N33+O33+P33)-L33 -> 0
B34: 1004055 | C34: ชิฟฟอน 4 ชิ้น เผือกล้วน | D34: ='เย็น '!D34+'เช้า '!D34+บ่าย!D34 -> 0 | E34: ='เย็น '!E34+'เช้า '!E34+บ่าย!E34 -> 0 | F34: ='เย็น '!F34+'เช้า '!F34+บ่าย!F34 -> 0 | G34: ='เย็น '!G34+'เช้า '!G34+บ่าย!G34 -> 0 | H34: ='เย็น '!H34+'เช้า '!H34+บ่าย!H34 -> 0 | I34: ='เย็น '!I34+'เช้า '!I34+บ่าย!I34 -> 0 | J34: ='เย็น '!J34+'เช้า '!J34+บ่าย!J34 -> 0 | K34: ='เย็น '!K34+'เช้า '!K34+บ่าย!K34 -> 0 | L34: =SUM(D34:K34) -> 0 | Q34: =(M34+N34+O34+P34)-L34 -> 0
B35: 1004055 | C35: ชิฟฟอน 4 ชิ้น สตอเบอรี่ล้วน | D35: ='เย็น '!D35+'เช้า '!D35+บ่าย!D35 -> 0 | E35: ='เย็น '!E35+'เช้า '!E35+บ่าย!E35 -> 0 | F35: ='เย็น '!F35+'เช้า '!F35+บ่าย!F35 -> 0 | G35: ='เย็น '!G35+'เช้า '!G35+บ่าย!G35 -> 0 | H35: ='เย็น '!H35+'เช้า '!H35+บ่าย!H35 -> 0 | I35: ='เย็น '!I35+'เช้า '!I35+บ่าย!I35 -> 0 | J35: ='เย็น '!J35+'เช้า '!J35+บ่าย!J35 -> 0 | K35: ='เย็น '!K35+'เช้า '!K35+บ่าย!K35 -> 0 | L35: =SUM(D35:K35) -> 0 | Q35: =(M35+N35+O35+P35)-L35 -> 0
B36: 1004055 | C36: ชิฟฟอน 4 ชิ้น กล้วยหอมล้วน | D36: ='เย็น '!D36+'เช้า '!D36+บ่าย!D36 -> 0 | E36: ='เย็น '!E36+'เช้า '!E36+บ่าย!E36 -> 0 | F36: ='เย็น '!F36+'เช้า '!F36+บ่าย!F36 -> 0 | G36: ='เย็น '!G36+'เช้า '!G36+บ่าย!G36 -> 0 | H36: ='เย็น '!H36+'เช้า '!H36+บ่าย!H36 -> 0 | I36: ='เย็น '!I36+'เช้า '!I36+บ่าย!I36 -> 0 | J36: ='เย็น '!J36+'เช้า '!J36+บ่าย!J36 -> 0 | K36: ='เย็น '!K36+'เช้า '!K36+บ่าย!K36 -> 0 | L36: =SUM(D36:K36) -> 0 | Q36: =(M36+N36+O36+P36)-L36 -> 0
B37: 1004055 | C37: ชิฟฟอน 4 ชิ้น ชาเขียวล้วน | D37: ='เย็น '!D37+'เช้า '!D37+บ่าย!D37 -> 0 | E37: ='เย็น '!E37+'เช้า '!E37+บ่าย!E37 -> 0 | F37: ='เย็น '!F37+'เช้า '!F37+บ่าย!F37 -> 0 | G37: ='เย็น '!G37+'เช้า '!G37+บ่าย!G37 -> 0 | H37: ='เย็น '!H37+'เช้า '!H37+บ่าย!H37 -> 0 | I37: ='เย็น '!I37+'เช้า '!I37+บ่าย!I37 -> 0 | J37: ='เย็น '!J37+'เช้า '!J37+บ่าย!J37 -> 0 | K37: ='เย็น '!K37+'เช้า '!K37+บ่าย!K37 -> 0 | L37: =SUM(D37:K37) -> 0 | Q37: =(M37+N37+O37+P37)-L37 -> 0
B38: 1004055 | C38: ชิฟฟอน 4 ชิ้น ชาไทยล้วน | D38: ='เย็น '!D38+'เช้า '!D38+บ่าย!D38 -> 0 | E38: ='เย็น '!E38+'เช้า '!E38+บ่าย!E38 -> 0 | F38: ='เย็น '!F38+'เช้า '!F38+บ่าย!F38 -> 0 | G38: ='เย็น '!G38+'เช้า '!G38+บ่าย!G38 -> 0 | H38: ='เย็น '!H38+'เช้า '!H38+บ่าย!H38 -> 0 | I38: ='เย็น '!I38+'เช้า '!I38+บ่าย!I38 -> 0 | J38: ='เย็น '!J38+'เช้า '!J38+บ่าย!J38 -> 0 | K38: ='เย็น '!K38+'เช้า '!K38+บ่าย!K38 -> 0 | L38: =SUM(D38:K38) -> 0 | Q38: =(M38+N38+O38+P38)-L38 -> 0
... B49: 1111066 | C49: ชิฟฟอนแยกชิ้น สตอเบอรี่ | D49: ='เย็น '!D49+'เช้า '!D49+บ่าย!D49 -> 0 | E49: ='เย็น '!E49+'เช้า '!E49+บ่าย!E49 -> 0 | F49: ='เย็น '!F49+'เช้า '!F49+บ่าย!F49 -> 0 | G49: ='เย็น '!G49+'เช้า '!G49+บ่าย!G49 -> 0 | H49: ='เย็น '!H49+'เช้า '!H49+บ่าย!H49 -> 0 | I49: ='เย็น '!I49+'เช้า '!I49+บ่าย!I49 -> 0 | J49: ='เย็น '!J49+'เช้า '!J49+บ่าย!J49 -> 0 | K49: ='เย็น '!K49+'เช้า '!K49+บ่าย!K49 -> 0 | L49: =SUM(D49:K49) -> 0 | Q49: =(M49+N49+O49+P49)-L49 -> 0
B50: 1111067 | C50: ชิฟฟอนแยกชิ้น มะพร้าว | D50: ='เย็น '!D50+'เช้า '!D50+บ่าย!D50 -> 0 | E50: ='เย็น '!E50+'เช้า '!E50+บ่าย!E50 -> 0 | F50: ='เย็น '!F50+'เช้า '!F50+บ่าย!F50 -> 0 | G50: ='เย็น '!G50+'เช้า '!G50+บ่าย!G50 -> 0 | H50: ='เย็น '!H50+'เช้า '!H50+บ่าย!H50 -> 0 | I50: ='เย็น '!I50+'เช้า '!I50+บ่าย!I50 -> 0 | J50: ='เย็น '!J50+'เช้า '!J50+บ่าย!J50 -> 0 | K50: ='เย็น '!K50+'เช้า '!K50+บ่าย!K50 -> 0 | L50: =SUM(D50:K50) -> 0 | N50: 2 | Q50: =(M50+N50+O50+P50)-L50 -> 2
B51: 1111068 | C51: ชิฟฟอนแยกชิ้น เนย | D51: ='เย็น '!D51+'เช้า '!D51+บ่าย!D51 -> 0 | E51: ='เย็น '!E51+'เช้า '!E51+บ่าย!E51 -> 0 | F51: ='เย็น '!F51+'เช้า '!F51+บ่าย!F51 -> 0 | G51: ='เย็น '!G51+'เช้า '!G51+บ่าย!G51 -> 0 | H51: ='เย็น '!H51+'เช้า '!H51+บ่าย!H51 -> 0 | I51: ='เย็น '!I51+'เช้า '!I51+บ่าย!I51 -> 0 | J51: ='เย็น '!J51+'เช้า '!J51+บ่าย!J51 -> 0 | K51: ='เย็น '!K51+'เช้า '!K51+บ่าย!K51 -> 0 | L51: =SUM(D51:K51) -> 0 | Q51: =(M51+N51+O51+P51)-L51 -> 0
B52: 1111069 | C52: ชิฟฟอนแยกชิ้น บลูเบอรี่ | D52: ='เย็น '!D52+'เช้า '!D52+บ่าย!D52 -> 0 | E52: ='เย็น '!E52+'เช้า '!E52+บ่าย!E52 -> 0 | F52: ='เย็น '!F52+'เช้า '!F52+บ่าย!F52 -> 0 | G52: ='เย็น '!G52+'เช้า '!G52+บ่าย!G52 -> 0 | H52: ='เย็น '!H52+'เช้า '!H52+บ่าย!H52 -> 0 | I52: ='เย็น '!I52+'เช้า '!I52+บ่าย!I52 -> 0 | J52: ='เย็น '!J52+'เช้า '!J52+บ่าย!J52 -> 0 | K52: ='เย็น '!K52+'เช้า '!K52+บ่าย!K52 -> 0 | L52: =SUM(D52:K52) -> 0 | Q52: =(M52+N52+O52+P52)-L52 -> 0
B53: 1111070 | C53: ชิฟฟอนแยกชิ้น ทุเรียน | D53: ='เย็น '!D53+'เช้า '!D53+บ่าย!D53 -> 0 | E53: ='เย็น '!E53+'เช้า '!E53+บ่าย!E53 -> 0 | F53: ='เย็น '!F53+'เช้า '!F53+บ่าย!F53 -> 0 | G53: ='เย็น '!G53+'เช้า '!G53+บ่าย!G53 -> 0 | H53: ='เย็น '!H53+'เช้า '!H53+บ่าย!H53 -> 0 | I53: ='เย็น '!I53+'เช้า '!I53+บ่าย!I53 -> 0 | J53: ='เย็น '!J53+'เช้า '!J53+บ่าย!J53 -> 0 | K53: ='เย็น '!K53+'เช้า '!K53+บ่าย!K53 -> 0 | L53: =SUM(D53:K53) -> 0 | Q53: =(M53+N53+O53+P53)-L53 -> 0
B54: 1111071 | C54: ชิฟฟอนแยกชิ้น ตาล | D54: ='เย็น '!D54+'เช้า '!D54+บ่าย!D54 -> 0 | E54: ='เย็น '!E54+'เช้า '!E54+บ่าย!E54 -> 0 | F54: ='เย็น '!F54+'เช้า '!F54+บ่าย!F54 -> 0 | G54: ='เย็น '!G54+'เช้า '!G54+บ่าย!G54 -> 0 | H54: ='เย็น '!H54+'เช้า '!H54+บ่าย!H54 -> 0 | I54: ='เย็น '!I54+'เช้า '!I54+บ่าย!I54 -> 0 | J54: ='เย็น '!J54+'เช้า '!J54+บ่าย!J54 -> 0 | K54: ='เย็น '!K54+'เช้า '!K54+บ่าย!K54 -> 0 | L54: =SUM(D54:K54) -> 0 | Q54: =(M54+N54+O54+P54)-L54 -> 0
...
