Workbook

Sheet บ่าย
B1: ยอดจริง ออนไลน์ วันที่ - บ่าย
L2: ยอดรวมผลิต
L3: จำนวน
B4: รหัสสินค้า | C4: สินค้า | D4: ปณ | E4: ชอปปี้ | F4: ลาซาด้า | G4: ติ๊กตอก | H4: ติ๊กตอก 2 | I4: ติ๊กตอก3 | J4: ชอยส์ | K4: ยอดเส้น | L4: (กล่อง)
B6: ชิฟฟอนรวมรส
B7: 1111002 | C7: ชิฟฟอนรวมรส 8 ชิ้น | L7: =SUM(D7:K7) -> 0
C8: ชิฟฟอนแบบกล่องสุ่มอะไรก็ได้ที่มี | L8: =SUM(D8:K8) -> 0
B9: 1111084 | C9: ชิฟฟอน 8 ชิ้น กาแฟล้วน | L9: =SUM(D9:K9) -> 0
B10: 1111085 | C10: ชิฟฟอน 8 ชิ้น บลูเบอรี่ล้วน | L10: =SUM(D10:K10) -> 0
B11: 1111086 | C11: ชิฟฟอน 8 ชิ้น มะพร้าวล้วน | L11: =SUM(D11:K11) -> 0
B12: 1111087 | C12: ชิฟฟอน 8 ชิ้น สตอเบอรี่ล้วน | L12: =SUM(D12:K12) -> 0
B13: 1111088 | C13: ชิฟฟอน 8 ชิ้น ส้มล้วน | L13: =SUM(D13:K13) -> 0
B14: 1111089 | C14: ชิฟฟอน 8 ชิ้น เนยล้วน | L14: =SUM(D14:K14) -> 0
B15: 1111090 | C15: ชิฟฟอน 8 ชิ้น เผือกล้วน | L15: =SUM(D15:K15) -> 0
B16: 1111091 | C16: ชิฟฟอน 8 ชิ้น ใบเตยล้วน | L16: =SUM(D16:K16) -> 0
B17: 1111092 | C17: ชิฟฟอน 8 ชิ้น กล้วยหอม | L17: =SUM(D17:K17) -> 0
B18: 1111093 | C18: ชิฟฟอน 8 ชิ้น โกโก้ล้วน | L18: =SUM(D18:K18) -> 0
B19: 1111094 | C19: ชิฟฟอน 8 ชิ้น ชาไทยล้วน | L19: =SUM(D19:K19) -> 0
B20: 1111095 | C20: ชิฟฟอน 8 ชิ้น ชาเขียวล้วน | L20: =SUM(D20:K20) -> 0
... B66: 1111010 | C66: ชิฟฟอนไส้แยมแยกชิ้น คละรส | L66: =SUM(D66:K66) -> 0
C67: รวม | L67: =SUM(L7:L66) -> 0
B68: ชิฟฟอนไส้แยม 6 ชิ้น
B69: 1111009 | C69: ชิฟฟอนไส้แยมรวมรส 6 ชิ้น | L69: =SUM(D69:K69) -> 0
B70: 1111023 | C70: ชิฟฟอนไส้แยมรสสตอเบอร์รี่ล้วน 6 ชิ้น | L70: =SUM(D70:K70) -> 0
B71: 1111016 | C71: ชิฟฟอนไส้แยมรสมะพร้าวล้วน 6 ชิ้น | L71: =SUM(D71:K71) -> 0
B72: 1111014 | C72: ชิฟฟอนไส้แยมรสช็อกโกแลตนูเทลล่าล้วน 6 ชิ้น | L72: =SUM(D72:K72) -> 0
B73: 1111025 | C73: ชิฟฟอนไส้แยมรสส้มล้วน 6 ชิ้น | L73: =SUM(D73:K73) -> 0
B74: 1111018 | C74: ชิฟฟอนไส้แยมรสบลูเบอร์รี่ล้วน 6 ชิ้น | L74: =SUM(D74:K74) -> 0
B75: 1111012 | C75: ชิฟฟอนไส้แยมรสนมชมพูฮอกไกโดล้วน 6 ชิ้น | L75: =SUM(D75:K75) -> 0
B76: 1111020 | C76: ชิฟฟอนไส้แยมฝอยทองไส้ทะลัก 6 ชิ้น | L76: =SUM(D76:K76) -> 0
C77: รวม | L77: =SUM(L69:L76) -> 0
B78: ชิฟฟอนไส้แยม 3 ชิ้น
B79: 1111022 | C79: ชิฟฟอนไส้แยมรสสตอเบอร์รี่ล้วน 3 ชิ้น | L79: =SUM(D79:K79) -> 0
B80: 1111015 | C80: ชิฟฟอนไส้แยมรสมะพร้าวล้วน 3 ชิ้น | L80: =SUM(D80:K80) -> 0
B81: 1111013 | C81: ชิฟฟอนไส้แยมรสช็อกโกแลตนูเทลล่าล้วน 3 ชิ้น | L81: =SUM(D81:K81) -> 0
B82: 1111024 | C82: ชิฟฟอนไส้แยมรสส้มล้วน 3 ชิ้น | L82: =SUM(D82:K82) -> 0
B83: 1111017 | C83: ชิฟฟอนไส้แยมรสบลูเบอร์รี่ล้วน 3 ชิ้น | L83: =SUM(D83:K83) -> 0
B84: 1111011 | C84: ชิฟฟอนไส้แยมรสนมชมพูฮอกไกโดล้วน 3 ชิ้น | L84: =SUM(D84:K84) -> 0
B85: 1111019 | C85: ชิฟฟอนไส้แยมฝอยทองไส้ทะลัก 3 ชิ้น | L85: =SUM(D85:K85) -> 0
B86: 1113081 | C86: ชิฟฟอนไส้แยม วนิลา/ใบเตย/เมล่อน | L86: =SUM(D86:K86) -> 0
...

Sheet เย็น 
B1: ยอดจริง ออนไลน์ วันที่ - เย็น
L2: ยอดรวมผลิต
L3: จำนวน
B4: รหัสสินค้า | C4: สินค้า | D4: ปณ | E4: ชอปปี้ | F4: ลาซาด้า | G4: ติ๊กตอก | H4: ติ๊กตอก 2 | I4: ติ๊กตอก3 | J4: ชอยส์ | K4: ยอดเส้น | L4: (กล่อง)
B6: ชิฟฟอนรวมรส
B7: 1111002 | C7: ชิฟฟอนรวมรส 8 ชิ้น | L7: =SUM(D7:K7) -> 0
C8: ชิฟฟอนแบบกล่องสุ่มอะไรก็ได้ที่มี | L8: =SUM(D8:K8) -> 0
B9: 1111084 | C9: ชิฟฟอน 8 ชิ้น กาแฟล้วน | L9: =SUM(D9:K9) -> 0
B10: 1111085 | C10: ชิฟฟอน 8 ชิ้น บลูเบอรี่ล้วน | L10: =SUM(D10:K10) -> 0
B11: 1111086 | C11: ชิฟฟอน 8 ชิ้น มะพร้าวล้วน | L11: =SUM(D11:K11) -> 0
B12: 1111087 | C12: ชิฟฟอน 8 ชิ้น สตอเบอรี่ล้วน | L12: =SUM(D12:K12) -> 0
B13: 1111088 | C13: ชิฟฟอน 8 ชิ้น ส้มล้วน | L13: =SUM(D13:K13) -> 0
B14: 1111089 | C14: ชิฟฟอน 8 ชิ้น เนยล้วน | L14: =SUM(D14:K14) -> 0
B15: 1111090 | C15: ชิฟฟอน 8 ชิ้น เผือกล้วน | L15: =SUM(D15:K15) -> 0
B16: 1111091 | C16: ชิฟฟอน 8 ชิ้น ใบเตยล้วน | L16: =SUM(D16:K16) -> 0
B17: 1111092 | C17: ชิฟฟอน 8 ชิ้น กล้วยหอม | L17: =SUM(D17:K17) -> 0
B18: 1111093 | C18: ชิฟฟอน 8 ชิ้น โกโก้ล้วน | L18: =SUM(D18:K18) -> 0
B19: 1111094 | C19: ชิฟฟอน 8 ชิ้น ชาไทยล้วน | L19: =SUM(D19:K19) -> 0
B20: 1111095 | C20: ชิฟฟอน 8 ชิ้น ชาเขียวล้วน | L20: =SUM(D20:K20) -> 0
... B66: 1111010 | C66: ชิฟฟอนไส้แยมแยกชิ้น คละรส | L66: =SUM(D66:K66) -> 0
C67: รวม | L67: =SUM(L7:L66) -> 0
B68: ชิฟฟอนไส้แยม 6 ชิ้น
B69: 1111009 | C69: ชิฟฟอนไส้แยมรวมรส 6 ชิ้น | L69: =SUM(D69:K69) -> 0
B70: 1111023 | C70: ชิฟฟอนไส้แยมรสสตอเบอร์รี่ล้วน 6 ชิ้น | L70: =SUM(D70:K70) -> 0
B71: 1111016 | C71: ชิฟฟอนไส้แยมรสมะพร้าวล้วน 6 ชิ้น | L71: =SUM(D71:K71) -> 0
B72: 1111014 | C72: ชิฟฟอนไส้แยมรสช็อกโกแลตนูเทลล่าล้วน 6 ชิ้น | L72: =SUM(D72:K72) -> 0
B73: 1111025 | C73: ชิฟฟอนไส้แยมรสส้มล้วน 6 ชิ้น | L73: =SUM(D73:K73) -> 0
B74: 1111018 | C74: ชิฟฟอนไส้แยมรสบลูเบอร์รี่ล้วน 6 ชิ้น | L74: =SUM(D74:K74) -> 0
B75: 1111012 | C75: ชิฟฟอนไส้แยมรสนมชมพูฮอกไกโดล้วน 6 ชิ้น | L75: =SUM(D75:K75) -> 0
B76: 1111020 | C76: ชิฟฟอนไส้แยมฝอยทองไส้ทะลัก 6 ชิ้น | L76: =SUM(D76:K76) -> 0
C77: รวม | L77: =SUM(L69:L76) -> 0
B78: ชิฟฟอนไส้แยม 3 ชิ้น
B79: 1111022 | C79: ชิฟฟอนไส้แยมรสสตอเบอร์รี่ล้วน 3 ชิ้น | L79: =SUM(D79:K79) -> 0
B80: 1111015 | C80: ชิฟฟอนไส้แยมรสมะพร้าวล้วน 3 ชิ้น | L80: =SUM(D80:K80) -> 0
B81: 1111013 | C81: ชิฟฟอนไส้แยมรสช็อกโกแลตนูเทลล่าล้วน 3 ชิ้น | L81: =SUM(D81:K81) -> 0
B82: 1111024 | C82: ชิฟฟอนไส้แยมรสส้มล้วน 3 ชิ้น | L82: =SUM(D82:K82) -> 0
B83: 1111017 | C83: ชิฟฟอนไส้แยมรสบลูเบอร์รี่ล้วน 3 ชิ้น | L83: =SUM(D83:K83) -> 0
B84: 1111011 | C84: ชิฟฟอนไส้แยมรสนมชมพูฮอกไกโดล้วน 3 ชิ้น | L84: =SUM(D84:K84) -> 0
B85: 1111019 | C85: ชิฟฟอนไส้แยมฝอยทองไส้ทะลัก 3 ชิ้น | L85: =SUM(D85:K85) -> 0
B86: 1113081 | C86: ชิฟฟอนไส้แยม วนิลา/ใบเตย/เมล่อน | L86: =SUM(D86:K86) -> 0
...

Sheet 01.12.68
B1: ยอดจริง ออนไลน์ วันที่ 1/12/2568
B2: รหัสสินค้า | C2: สินค้า | D2: ปณ | G2: ชอปปี้ | J2: ลาซาด้า | M2: ติ๊กตอก | P2: ติ๊กตอก2 | S2: ติ๊กตอก3 | V2: ชอยส์ | Y2: ยอดเส้น | Z2: ยอดรวมผลิต(กล่อง) | AA2: ยอดForcast | AB2: ยอดStock | AC2: ยอดMemo | AD2: ยอดForcastวันพรุ่งนี้ | AE2: สินค้าที่ขายได้
D3: เช้า | E3: บ่าย | F3: รวม | G3: เช้า | H3: บ่าย | I3: รวม | J3: เช้า | K3: บ่าย | L3: รวม | M3: เช้า | N3: บ่าย | O3: รวม | P3: เช้า | Q3: บ่าย | R3: รวม | S3: เช้า | T3: บ่าย | U3: รวม | V3: เช้า | W3: บ่าย | X3: รวม
B4: 1004055 | C4: ชิฟฟ่อนเค้ก วรรณวนัช (รวมรส 4 ชิ้น) | F4: =SUM(D4:E4) -> 0 | I4: =SUM(G4:H4) -> 0 | L4: =SUM(J4:K4) -> 0 | M4: 392 | O4: =SUM(M4:N4) -> 392 | P4: 6 | R4: =SUM(P4:Q4) -> 6 | U4: =SUM(S4:T4) -> 0 | X4: =SUM(V4:W4) -> 0 | Z4: =+F4+I4+L4+O4+R4+U4+X4+Y4 -> 398 | AA4: 250 | AB4: 4 | AC4: =+AA4+AB4-Z4 -> -144 | AD4: 250 | AE4: =AC4+AD4 -> 106
B5: 1111002 | C5: ชิฟฟ่อนเค้ก วรรณวนัช (รวมรส 8 ชิ้น) | D5: 20 | F5: =SUM(D5:E5) -> 20 | G5: 76 | I5: =SUM(G5:H5) -> 76 | J5: 19 | L5: =SUM(J5:K5) -> 19 | M5: 15 | O5: =SUM(M5:N5) -> 15 | P5: 9 | R5: =SUM(P5:Q5) -> 9 | U5: =SUM(S5:T5) -> 0 | X5: =SUM(V5:W5) -> 0 | Z5: =+F5+I5+L5+O5+R5+U5+X5+Y5 -> 139 | AA5: 250 | AB5: 32 | AC5: =+AA5+AB5-Z5 -> 143 | AD5: 150 | AE5: =AC5+AD5 -> 293
B6: 1111001 | C6: ชิฟฟ่อนแยกชิ้นไม่มีไส้ คละรส | F6: =SUM(D6:E6) -> 0 | I6: =SUM(G6:H6) -> 0 | L6: =SUM(J6:K6) -> 0 | O6: =SUM(M6:N6) -> 0 | R6: =SUM(P6:Q6) -> 0 | U6: =SUM(S6:T6) -> 0 | X6: =SUM(V6:W6) -> 0 | Z6: =+F6+I6+L6+O6+R6+U6+X6+Y6 -> 0 | AC6: =+AA6+AB6-Z6 -> 0 | AE6: =AC6+AD6 -> 0
B7: 1111084 | C7: ชิฟฟ่อนเค้ก รสกาแฟ (8 ชิ้น) | F7: =SUM(D7:E7) -> 0 | I7: =SUM(G7:H7) -> 0 | L7: =SUM(J7:K7) -> 0 | O7: =SUM(M7:N7) -> 0 | R7: =SUM(P7:Q7) -> 0 | U7: =SUM(S7:T7) -> 0 | X7: =SUM(V7:W7) -> 0 | Z7: =+F7+I7+L7+O7+R7+U7+X7+Y7 -> 0 | AC7: =+AA7+AB7-Z7 -> 0 | AE7: =AC7+AD7 -> 0
B8: 1111043 | C8: ชิฟฟอนรสมะลิ 8 ชิ้น ห่อ ซีน | F8: =SUM(D8:E8) -> 0 | I8: =SUM(G8:H8) -> 0 | L8: =SUM(J8:K8) -> 0 | O8: =SUM(M8:N8) -> 0 | R8: =SUM(P8:Q8) -> 0 | U8: =SUM(S8:T8) -> 0 | X8: =SUM(V8:W8) -> 0 | Z8: =+F8+I8+L8+O8+R8+U8+X8+Y8 -> 0 | AC8: =+AA8+AB8-Z8 -> 0 | AE8: =AC8+AD8 -> 0
B9: 1111057 | C9: ชิฟฟอนแยกชิ้น กาแฟ | F9: =SUM(D9:E9) -> 0 | I9: =SUM(G9:H9) -> 0 | L9: =SUM(J9:K9) -> 0 | O9: =SUM(M9:N9) -> 0 | R9: =SUM(P9:Q9) -> 0 | U9: =SUM(S9:T9) -> 0 | X9: =SUM(V9:W9) -> 0 | Z9: =+F9+I9+L9+O9+R9+U9+X9+Y9 -> 0 | AB9: 1 | AC9: =+AA9+AB9-Z9 -> 1 | AE9: =AC9+AD9 -> 1
B10: 1111058 | C10: ชิฟฟอนแยกชิ้น มะลิ | F10: =SUM(D10:E10) -> 0 | I10: =SUM(G10:H10) -> 0 | L10: =SUM(J10:K10) -> 0 | O10: =SUM(M10:N10) -> 0 | R10: =SUM(P10:Q10) -> 0 | U10: =SUM(S10:T10) -> 0 | X10: =SUM(V10:W10) -> 0 | Z10: =+F10+I10+L10+O10+R10+U10+X10+Y10 -> 0 | AC10: =+AA10+AB10-Z10 -> 0 | AE10: =AC10+AD10 -> 0
B11: 1111059 | C11: ชิฟฟอนแยกชิ้น ใบเตย | F11: =SUM(D11:E11) -> 0 | I11: =SUM(G11:H11) -> 0 | L11: =SUM(J11:K11) -> 0 | O11: =SUM(M11:N11) -> 0 | R11: =SUM(P11:Q11) -> 0 | U11: =SUM(S11:T11) -> 0 | X11: =SUM(V11:W11) -> 0 | Z11: =+F11+I11+L11+O11+R11+U11+X11+Y11 -> 0 | AB11: 1 | AC11: =+AA11+AB11-Z11 -> 1 | AE11: =AC11+AD11 -> 1
B12: 1111060 | C12: ชิฟฟอนแยกชิ้น กล้วยหอม | F12: =SUM(D12:E12) -> 0 | I12: =SUM(G12:H12) -> 0 | L12: =SUM(J12:K12) -> 0 | O12: =SUM(M12:N12) -> 0 | R12: =SUM(P12:Q12) -> 0 | U12: =SUM(S12:T12) -> 0 | X12: =SUM(V12:W12) -> 0 | Z12: =+F12+I12+L12+O12+R12+U12+X12+Y12 -> 0 | AC12: =+AA12+AB12-Z12 -> 0 | AE12: =AC12+AD12 -> 0
B13: 1111061 | C13: ชิฟฟอนแยกชิ้น ชาไทย | F13: =SUM(D13:E13) -> 0 | I13: =SUM(G13:H13) -> 0 | L13: =SUM(J13:K13) -> 0 | O13: =SUM(M13:N13) -> 0 | R13: =SUM(P13:Q13) -> 0 | U13: =SUM(S13:T13) -> 0 | X13: =SUM(V13:W13) -> 0 | Z13: =+F13+I13+L13+O13+R13+U13+X13+Y13 -> 0 | AC13: =+AA13+AB13-Z13 -> 0 | AE13: =AC13+AD13 -> 0
B14: 1111062 | C14: ชิฟฟอนแยกชิ้น โกโก้ | F14: =SUM(D14:E14) -> 0 | I14: =SUM(G14:H14) -> 0 | L14: =SUM(J14:K14) -> 0 | O14: =SUM(M14:N14) -> 0 | R14: =SUM(P14:Q14) -> 0 | U14: =SUM(S14:T14) -> 0 | X14: =SUM(V14:W14) -> 0 | Z14: =+F14+I14+L14+O14+R14+U14+X14+Y14 -> 0 | AC14: =+AA14+AB14-Z14 -> 0 | AE14: =AC14+AD14 -> 0
B15: 1111063 | C15: ชิฟฟอนแยกชิ้น ส้ม | F15: =SUM(D15:E15) -> 0 | I15: =SUM(G15:H15) -> 0 | L15: =SUM(J15:K15) -> 0 | O15: =SUM(M15:N15) -> 0 | R15: =SUM(P15:Q15) -> 0 | U15: =SUM(S15:T15) -> 0 | X15: =SUM(V15:W15) -> 0 | Z15: =+F15+I15+L15+O15+R15+U15+X15+Y15 -> 0 | AC15: =+AA15+AB15-Z15 -> 0 | AE15: =AC15+AD15 -> 0
B16: 1111064 | C16: ชิฟฟอนแยกชิ้น เผือก | F16: =SUM(D16:E16) -> 0 | I16: =SUM(G16:H16) -> 0 | L16: =SUM(J16:K16) -> 0 | O16: =SUM(M16:N16) -> 0 | R16: =SUM(P16:Q16) -> 0 | U16: =SUM(S16:T16) -> 0 | X16: =SUM(V16:W16) -> 0 | Z16: =+F16+I16+L16+O16+R16+U16+X16+Y16 -> 0 | AC16: =+AA16+AB16-Z16 -> 0 | AE16: =AC16+AD16 -> 0
B17: 1111065 | C17: ชิฟฟอนแยกชิ้น สับปะรด | F17: =SUM(D17:E17) -> 0 | I17: =SUM(G17:H17) -> 0 | L17: =SUM(J17:K17) -> 0 | O17: =SUM(M17:N17) -> 0 | R17: =SUM(P17:Q17) -> 0 | U17: =SUM(S17:T17) -> 0 | X17: =SUM(V17:W17) -> 0 | Z17: =+F17+I17+L17+O17+R17+U17+X17+Y17 -> 0 | AC17: =+AA17+AB17-Z17 -> 0 | AE17: =AC17+AD17 -> 0
B18: 1111066 | C18: ชิฟฟอนแยกชิ้น สตอเบอรี่ | F18: =SUM(D18:E18) -> 0 | I18: =SUM(G18:H18) -> 0 | L18: =SUM(J18:K18) -> 0 | O18: =SUM(M18:N18) -> 0 | R18: =SUM(P18:Q18) -> 0 | U18: =SUM(S18:T18) -> 0 | X18: =SUM(V18:W18) -> 0 | Z18: =+F18+I18+L18+O18+R18+U18+X18+Y18 -> 0 | AC18: =+AA18+AB18-Z18 -> 0 | AE18: =AC18+AD18 -> 0
B19: 1111067 | C19: ชิฟฟอนแยกชิ้น มะพร้าว | F19: =SUM(D19:E19) -> 0 | I19: =SUM(G19:H19) -> 0 | L19: =SUM(J19:K19) -> 0 | O19: =SUM(M19:N19) -> 0 | R19: =SUM(P19:Q19) -> 0 | U19: =SUM(S19:T19) -> 0 | X19: =SUM(V19:W19) -> 0 | Z19: =+F19+I19+L19+O19+R19+U19+X19+Y19 -> 0 | AC19: =+AA19+AB19-Z19 -> 0 | AE19: =AC19+AD19 -> 0
B20: 1111068 | C20: ชิฟฟอนแยกชิ้น เนย | F20: =SUM(D20:E20) -> 0 | I20: =SUM(G20:H20) -> 0 | L20: =SUM(J20:K20) -> 0 | O20: =SUM(M20:N20) -> 0 | R20: =SUM(P20:Q20) -> 0 | U20: =SUM(S20:T20) -> 0 | X20: =SUM(V20:W20) -> 0 | Z20: =+F20+I20+L20+O20+R20+U20+X20+Y20 -> 0 | AC20: =+AA20+AB20-Z20 -> 0 | AE20: =AC20+AD20 -> 0
B21: 1111069 | C21: ชิฟฟอนแยกชิ้น บลูเบอรี่ | F21: =SUM(D21:E21) -> 0 | I21: =SUM(G21:H21) -> 0 | L21: =SUM(J21:K21) -> 0 | O21: =SUM(M21:N21) -> 0 | R21: =SUM(P21:Q21) -> 0 | U21: =SUM(S21:T21) -> 0 | X21: =SUM(V21:W21) -> 0 | Z21: =+F21+I21+L21+O21+R21+U21+X21+Y21 -> 0 | AC21: =+AA21+AB21-Z21 -> 0 | AE21: =AC21+AD21 -> 0
B22: 1111070 | C22: ชิฟฟอนแยกชิ้น ทุเรียน | F22: =SUM(D22:E22) -> 0 | I22: =SUM(G22:H22) -> 0 | L22: =SUM(J22:K22) -> 0 | O22: =SUM(M22:N22) -> 0 | R22: =SUM(P22:Q22) -> 0 | U22: =SUM(S22:T22) -> 0 | X22: =SUM(V22:W22) -> 0 | Z22: =+F22+I22+L22+O22+R22+U22+X22+Y22 -> 0 | AC22: =+AA22+AB22-Z22 -> 0 | AE22: =AC22+AD22 -> 0
B23: 1111071 | C23: ชิฟฟอนแยกชิ้น ตาล | F23: =SUM(D23:E23) -> 0 | I23: =SUM(G23:H23) -> 0 | L23: =SUM(J23:K23) -> 0 | O23: =SUM(M23:N23) -> 0 | R23: =SUM(P23:Q23) -> 0 | U23: =SUM(S23:T23) -> 0 | X23: =SUM(V23:W23) -> 0 | Z23: =+F23+I23+L23+O23+R23+U23+X23+Y23 -> 0 | AC23: =+AA23+AB23-Z23 -> 0 | AE23: =AC23+AD23 -> 0
B24: 1111010 | C24: ชิฟฟ่อนเค้กสอดไส้แยม (1 ชิ้น) | F24: =SUM(D24:E24) -> 0 | I24: =SUM(G24:H24) -> 0 | L24: =SUM(J24:K24) -> 0 | O24: =SUM(M24:N24) -> 0 | R24: =SUM(P24:Q24) -> 0 | U24: =SUM(S24:T24) -> 0 | X24: =SUM(V24:W24) -> 0 | Z24: =+F24+I24+L24+O24+R24+U24+X24+Y24 -> 0 | AC24: =+AA24+AB24-Z24 -> 0 | AE24: =AC24+AD24 -> 0
B25: 1111008 | C25: ชิฟฟ่อนเค้ก สอดไส้ (รวมรส 3 ชิ้น) | F25: =SUM(D25:E25) -> 0 | G25: 3 | I25: =SUM(G25:H25) -> 3 | L25: =SUM(J25:K25) -> 0 | M25: 150 | O25: =SUM(M25:N25) -> 150 | P25: 96 | R25: =SUM(P25:Q25) -> 96 | U25: =SUM(S25:T25) -> 0 | X25: =SUM(V25:W25) -> 0 | Z25: =+F25+I25+L25+O25+R25+U25+X25+Y25 -> 249 | AA25: 106 | AB25: 171 | AC25: =+AA25+AB25-Z25 -> 28 | AE25: =AC25+AD25 -> 28
B26: 1111009 | C26: ชิฟฟ่อนเค้ก สอดไส้ (รวมรส 6 ชิ้น) | F26: =SUM(D26:E26) -> 0 | G26: 5 | I26: =SUM(G26:H26) -> 5 | J26: 1 | L26: =SUM(J26:K26) -> 1 | O26: =SUM(M26:N26) -> 0 | R26: =SUM(P26:Q26) -> 0 | U26: =SUM(S26:T26) -> 0 | X26: =SUM(V26:W26) -> 0 | Z26: =+F26+I26+L26+O26+R26+U26+X26+Y26 -> 6 | AA26: 20 | AB26: 66 | AC26: =+AA26+AB26-Z26 -> 80 | AE26: =AC26+AD26 -> 80
B27: 1111011 | C27: ชิฟฟ่อนเค้กสอดไส้ นมชมพูฮอกไกโด (3 ชิ้น) | F27: =SUM(D27:E27) -> 0 | I27: =SUM(G27:H27) -> 0 | L27: =SUM(J27:K27) -> 0 | O27: =SUM(M27:N27) -> 0 | R27: =SUM(P27:Q27) -> 0 | U27: =SUM(S27:T27) -> 0 | X27: =SUM(V27:W27) -> 0 | Z27: =+F27+I27+L27+O27+R27+U27+X27+Y27 -> 0 | AC27: =+AA27+AB27-Z27 -> 0 | AE27: =AC27+AD27 -> 0
B28: 1111012 | C28: ชิฟฟ่อนเค้กสอดไส้ นมชมพูฮอกไกโด (6 ชิ้น) | F28: =SUM(D28:E28) -> 0 | I28: =SUM(G28:H28) -> 0 | L28: =SUM(J28:K28) -> 0 | O28: =SUM(M28:N28) -> 0 | R28: =SUM(P28:Q28) -> 0 | U28: =SUM(S28:T28) -> 0 | X28: =SUM(V28:W28) -> 0 | Z28: =+F28+I28+L28+O28+R28+U28+X28+Y28 -> 0 | AC28: =+AA28+AB28-Z28 -> 0 | AE28: =AC28+AD28 -> 0
B29: 1111013 | C29: ชิฟฟ่อนเค้กสอดไส้ ช็อคโกแลตนูเทลล่า (3 ชิ้น) | F29: =SUM(D29:E29) -> 0 | I29: =SUM(G29:H29) -> 0 | L29: =SUM(J29:K29) -> 0 | O29: =SUM(M29:N29) -> 0 | R29: =SUM(P29:Q29) -> 0 | U29: =SUM(S29:T29) -> 0 | X29: =SUM(V29:W29) -> 0 | Z29: =+F29+I29+L29+O29+R29+U29+X29+Y29 -> 0 | AC29: =+AA29+AB29-Z29 -> 0 | AE29: =AC29+AD29 -> 0
B30: 1111014 | C30: ชิฟฟ่อนเค้กสอดไส้ ช็อคโกแลตนูเทลล่า (6 ชิ้น) | F30: =SUM(D30:E30) -> 0 | I30: =SUM(G30:H30) -> 0 | L30: =SUM(J30:K30) -> 0 | O30: =SUM(M30:N30) -> 0 | R30: =SUM(P30:Q30) -> 0 | U30: =SUM(S30:T30) -> 0 | X30: =SUM(V30:W30) -> 0 | Z30: =+F30+I30+L30+O30+R30+U30+X30+Y30 -> 0 | AC30: =+AA30+AB30-Z30 -> 0 | AE30: =AC30+AD30 -> 0
B31: 1111015 | C31: ชิฟฟ่อนเค้กสอดไส้เนย รสมะพร้าว (3 ชิ้น) | F31: =SUM(D31:E31) -> 0 | I31: =SUM(G31:H31) -> 0 | L31: =SUM(J31:K31) -> 0 | O31: =SUM(M31:N31) -> 0 | R31: =SUM(P31:Q31) -> 0 | U31: =SUM(S31:T31) -> 0 | X31: =SUM(V31:W31) -> 0 | Z31: =+F31+I31+L31+O31+R31+U31+X31+Y31 -> 0 | AC31: =+AA31+AB31-Z31 -> 0 | AE31: =AC31+AD31 -> 0
B32: 1111016 | C32: ชิฟฟ่อนเค้กสอดไส้เนย รสมะพร้าว (6 ชิ้น) | F32: =SUM(D32:E32) -> 0 | I32: =SUM(G32:H32) -> 0 | L32: =SUM(J32:K32) -> 0 | O32: =SUM(M32:N32) -> 0 | R32: =SUM(P32:Q32) -> 0 | U32: =SUM(S32:T32) -> 0 | X32: =SUM(V32:W32) -> 0 | Z32: =+F32+I32+L32+O32+R32+U32+X32+Y32 -> 0 | AC32: =+AA32+AB32-Z32 -> 0 | AE32: =AC32+AD32 -> 0
B33: 1111017 | C33: ชิฟฟ่อนเค้กสอดไส้แยม รสบลูเบอร์รี่ (3 ชิ้น) | F33: =SUM(D33:E33) -> 0 | I33: =SUM(G33:H33) -> 0 | L33: =SUM(J33:K33) -> 0 | O33: =SUM(M33:N33) -> 0 | R33: =SUM(P33:Q33) -> 0 | U33: =SUM(S33:T33) -> 0 | X33: =SUM(V33:W33) -> 0 | Z33: =+F33+I33+L33+O33+R33+U33+X33+Y33 -> 0 | AC33: =+AA33+AB33-Z33 -> 0 | AE33: =AC33+AD33 -> 0
B34: 1111018 | C34: ชิฟฟ่อนเค้กสอดไส้แยม รสบลูเบอร์รี่ (6 ชิ้น) | F34: =SUM(D34:E34) -> 0 | I34: =SUM(G34:H34) -> 0 | L34: =SUM(J34:K34) -> 0 | O34: =SUM(M34:N34) -> 0 | R34: =SUM(P34:Q34) -> 0 | U34: =SUM(S34:T34) -> 0 | X34: =SUM(V34:W34) -> 0 | Z34: =+F34+I34+L34+O34+R34+U34+X34+Y34 -> 0 | AC34: =+AA34+AB34-Z34 -> 0 | AE34: =AC34+AD34 -> 0
B35: 1111019 | C35: ชิฟฟ่อนเค้กหน้าฝอยทอง สอดไส้แยมส้ม (3 ชิ้น) | F35: =SUM(D35:E35) -> 0 | I35: =SUM(G35:H35) -> 0 | L35: =SUM(J35:K35) -> 0 | O35: =SUM(M35:N35) -> 0 | R35: =SUM(P35:Q35) -> 0 | U35: =SUM(S35:T35) -> 0 | X35: =SUM(V35:W35) -> 0 | Z35: =+F35+I35+L35+O35+R35+U35+X35+Y35 -> 0 | AC35: =+AA35+AB35-Z35 -> 0 | AE35: =AC35+AD35 -> 0
B36: 1111020 | C36: ชิฟฟ่อนเค้กหน้าฝอยทอง สอดไส้แยมส้ม (6 ชิ้น) | F36: =SUM(D36:E36) -> 0 | I36: =SUM(G36:H36) -> 0 | L36: =SUM(J36:K36) -> 0 | O36: =SUM(M36:N36) -> 0 | R36: =SUM(P36:Q36) -> 0 | U36: =SUM(S36:T36) -> 0 | X36: =SUM(V36:W36) -> 0 | Z36: =+F36+I36+L36+O36+R36+U36+X36+Y36 -> 0 | AC36: =+AA36+AB36-Z36 -> 0 | AE36: =AC36+AD36 -> 0
B37: 1111022 | C37: ชิฟฟ่อนเค้กสอดไส้แยม รสสตรอว์เบอร์รี (3 ชิ้น) | F37: =SUM(D37:E37) -> 0 | I37: =SUM(G37:H37) -> 0 | L37: =SUM(J37:K37) -> 0 | O37: =SUM(M37:N37) -> 0 | R37: =SUM(P37:Q37) -> 0 | U37: =SUM(S37:T37) -> 0 | X37: =SUM(V37:W37) -> 0 | Z37: =+F37+I37+L37+O37+R37+U37+X37+Y37 -> 0 | AC37: =+AA37+AB37-Z37 -> 0 | AE37: =AC37+AD37 -> 0
B38: 1111023 | C38: ชิฟฟ่อนเค้กสอดไส้แยม รสสตรอว์เบอร์รี (6 ชิ้น) | F38: =SUM(D38:E38) -> 0 | I38: =SUM(G38:H38) -> 0 | L38: =SUM(J38:K38) -> 0 | O38: =SUM(M38:N38) -> 0 | R38: =SUM(P38:Q38) -> 0 | U38: =SUM(S38:T38) -> 0 | X38: =SUM(V38:W38) -> 0 | Z38: =+F38+I38+L38+O38+R38+U38+X38+Y38 -> 0 | AC38: =+AA38+AB38-Z38 -> 0 | AE38: =AC38+AD38 -> 0
... B40: 1111025 | C40: ชิฟฟ่อนเค้กสอดไส้แยม รสส้ม (6 ชิ้น) | F40: =SUM(D40:E40) -> 0 | I40: =SUM(G40:H40) -> 0 | L40: =SUM(J40:K40) -> 0 | O40: =SUM(M40:N40) -> 0 | R40: =SUM(P40:Q40) -> 0 | U40: =SUM(S40:T40) -> 0 | X40: =SUM(V40:W40) -> 0 | Z40: =+F40+I40+L40+O40+R40+U40+X40+Y40 -> 0 | AC40: =+AA40+AB40-Z40 -> 0 | AE40: =AC40+AD40 -> 0
B41: 1111056 | C41: ชิฟฟอนรวมรสยอดฮิต 8 ชิ้น | F41: =SUM(D41:E41) -> 0 | G41: 6 | I41: =SUM(G41:H41) -> 6 | L41: =SUM(J41:K41) -> 0 | O41: =SUM(M41:N41) -> 0 | R41: =SUM(P41:Q41) -> 0 | U41: =SUM(S41:T41) -> 0 | X41: =SUM(V41:W41) -> 0 | Z41: =+F41+I41+L41+O41+R41+U41+X41+Y41 -> 6 | AB41: 22 | AC41: =+AA41+AB41-Z41 -> 16 | AE41: =AC41+AD41 -> 16
...

Sheet 02.12.68
B1: ยอดจริง ออนไลน์ วันที่ 2/12/2568
B2: รหัสสินค้า | C2: สินค้า | D2: ปณ | G2: ชอปปี้ | J2: ลาซาด้า | M2: ติ๊กตอก | P2: ติ๊กตอก2 | S2: ติ๊กตอก3 | V2: ชอยส์ | Y2: ยอดเส้น | Z2: ยอดรวมผลิต(กล่อง) | AA2: ยอดForcast | AB2: ยอดStock | AC2: ยอดMemo | AD2: ยอดForcastวันพรุ่งนี้ | AE2: สินค้าที่ขายได้
D3: เช้า | E3: บ่าย | F3: รวม | G3: เช้า | H3: บ่าย | I3: รวม | J3: เช้า | K3: บ่าย | L3: รวม | M3: เช้า | N3: บ่าย | O3: รวม | P3: เช้า | Q3: บ่าย | R3: รวม | S3: เช้า | T3: บ่าย | U3: รวม | V3: เช้า | W3: บ่าย | X3: รวม
B4: 1004055 | C4: ชิฟฟ่อนเค้ก วรรณวนัช (รวมรส 4 ชิ้น) | D4: 11 | E4: 11 | F4: =SUM(D4:E4) -> 22 | H4: 3 | I4: =SUM(G4:H4) -> 3 | L4: =SUM(J4:K4) -> 0 | M4: 360 | N4: 136 | O4: =SUM(M4:N4) -> 496 | P4: 9 | R4: =SUM(P4:Q4) -> 9 | U4: =SUM(S4:T4) -> 0 | X4: =SUM(V4:W4) -> 0 | Z4: =+F4+I4+L4+O4+R4+U4+X4+Y4 -> 530 | AA4: 250 | AB4: 9 | AC4: =+AA4+AB4-Z4 -> -271 | AD4: 500 | AE4: =AC4+AD4 -> 229
B5: 1111002 | C5: ชิฟฟ่อนเค้ก วรรณวนัช (รวมรส 8 ชิ้น) | D5: 10 | F5: =SUM(D5:E5) -> 10 | G5: 61 | H5: 25 | I5: =SUM(G5:H5) -> 86 | J5: 29 | L5: =SUM(J5:K5) -> 29 | M5: 21 | N5: 30 | O5: =SUM(M5:N5) -> 51 | P5: 33 | R5: =SUM(P5:Q5) -> 33 | U5: =SUM(S5:T5) -> 0 | X5: =SUM(V5:W5) -> 0 | Z5: =+F5+I5+L5+O5+R5+U5+X5+Y5 -> 209 | AA5: 250 | AB5: 61 | AC5: =+AA5+AB5-Z5 -> 102 | AD5: 150 | AE5: =AC5+AD5 -> 252
B6: 1111001 | C6: ชิฟฟ่อนแยกชิ้นไม่มีไส้ คละรส | F6: =SUM(D6:E6) -> 0 | I6: =SUM(G6:H6) -> 0 | L6: =SUM(J6:K6) -> 0 | O6: =SUM(M6:N6) -> 0 | R6: =SUM(P6:Q6) -> 0 | U6: =SUM(S6:T6) -> 0 | X6: =SUM(V6:W6) -> 0 | Z6: =+F6+I6+L6+O6+R6+U6+X6+Y6 -> 0 | AC6: =+AA6+AB6-Z6 -> 0 | AE6: =AC6+AD6 -> 0
B7: 1111084 | C7: ชิฟฟ่อนเค้ก รสกาแฟ (8 ชิ้น) | F7: =SUM(D7:E7) -> 0 | I7: =SUM(G7:H7) -> 0 | L7: =SUM(J7:K7) -> 0 | O7: =SUM(M7:N7) -> 0 | R7: =SUM(P7:Q7) -> 0 | U7: =SUM(S7:T7) -> 0 | X7: =SUM(V7:W7) -> 0 | Z7: =+F7+I7+L7+O7+R7+U7+X7+Y7 -> 0 | AC7: =+AA7+AB7-Z7 -> 0 | AE7: =AC7+AD7 -> 0
B8: 1111043 | C8: ชิฟฟอนรสมะลิ 8 ชิ้น ห่อ ซีน | F8: =SUM(D8:E8) -> 0 | I8: =SUM(G8:H8) -> 0 | L8: =SUM(J8:K8) -> 0 | O8: =SUM(M8:N8) -> 0 | R8: =SUM(P8:Q8) -> 0 | U8: =SUM(S8:T8) -> 0 | X8: =SUM(V8:W8) -> 0 | Z8: =+F8+I8+L8+O8+R8+U8+X8+Y8 -> 0 | AC8: =+AA8+AB8-Z8 -> 0 | AE8: =AC8+AD8 -> 0
B9: 1111057 | C9: ชิฟฟอนแยกชิ้น กาแฟ | F9: =SUM(D9:E9) -> 0 | I9: =SUM(G9:H9) -> 0 | L9: =SUM(J9:K9) -> 0 | O9: =SUM(M9:N9) -> 0 | R9: =SUM(P9:Q9) -> 0 | U9: =SUM(S9:T9) -> 0 | X9: =SUM(V9:W9) -> 0 | Z9: =+F9+I9+L9+O9+R9+U9+X9+Y9 -> 0 | AC9: =+AA9+AB9-Z9 -> 0 | AE9: =AC9+AD9 -> 0
B10: 1111058 | C10: ชิฟฟอนแยกชิ้น มะลิ | F10: =SUM(D10:E10) -> 0 | I10: =SUM(G10:H10) -> 0 | L10: =SUM(J10:K10) -> 0 | O10: =SUM(M10:N10) -> 0 | R10: =SUM(P10:Q10) -> 0 | U10: =SUM(S10:T10) -> 0 | X10: =SUM(V10:W10) -> 0 | Z10: =+F10+I10+L10+O10+R10+U10+X10+Y10 -> 0 | AC10: =+AA10+AB10-Z10 -> 0 | AE10: =AC10+AD10 -> 0
B11: 1111059 | C11: ชิฟฟอนแยกชิ้น ใบเตย | F11: =SUM(D11:E11) -> 0 | I11: =SUM(G11:H11) -> 0 | L11: =SUM(J11:K11) -> 0 | O11: =SUM(M11:N11) -> 0 | R11: =SUM(P11:Q11) -> 0 | U11: =SUM(S11:T11) -> 0 | X11: =SUM(V11:W11) -> 0 | Z11: =+F11+I11+L11+O11+R11+U11+X11+Y11 -> 0 | AC11: =+AA11+AB11-Z11 -> 0 | AE11: =AC11+AD11 -> 0
B12: 1111060 | C12: ชิฟฟอนแยกชิ้น กล้วยหอม | F12: =SUM(D12:E12) -> 0 | I12: =SUM(G12:H12) -> 0 | L12: =SUM(J12:K12) -> 0 | O12: =SUM(M12:N12) -> 0 | R12: =SUM(P12:Q12) -> 0 | U12: =SUM(S12:T12) -> 0 | X12: =SUM(V12:W12) -> 0 | Z12: =+F12+I12+L12+O12+R12+U12+X12+Y12 -> 0 | AC12: =+AA12+AB12-Z12 -> 0 | AE12: =AC12+AD12 -> 0
B13: 1111061 | C13: ชิฟฟอนแยกชิ้น ชาไทย | F13: =SUM(D13:E13) -> 0 | I13: =SUM(G13:H13) -> 0 | L13: =SUM(J13:K13) -> 0 | O13: =SUM(M13:N13) -> 0 | R13: =SUM(P13:Q13) -> 0 | U13: =SUM(S13:T13) -> 0 | X13: =SUM(V13:W13) -> 0 | Z13: =+F13+I13+L13+O13+R13+U13+X13+Y13 -> 0 | AC13: =+AA13+AB13-Z13 -> 0 | AE13: =AC13+AD13 -> 0
B14: 1111062 | C14: ชิฟฟอนแยกชิ้น โกโก้ | F14: =SUM(D14:E14) -> 0 | I14: =SUM(G14:H14) -> 0 | L14: =SUM(J14:K14) -> 0 | O14: =SUM(M14:N14) -> 0 | R14: =SUM(P14:Q14) -> 0 | U14: =SUM(S14:T14) -> 0 | X14: =SUM(V14:W14) -> 0 | Z14: =+F14+I14+L14+O14+R14+U14+X14+Y14 -> 0 | AC14: =+AA14+AB14-Z14 -> 0 | AE14: =AC14+AD14 -> 0
B15: 1111063 | C15: ชิฟฟอนแยกชิ้น ส้ม | F15: =SUM(D15:E15) -> 0 | G15: 1 | I15: =SUM(G15:H15) -> 1 | L15: =SUM(J15:K15) -> 0 | O15: =SUM(M15:N15) -> 0 | R15: =SUM(P15:Q15) -> 0 | U15: =SUM(S15:T15) -> 0 | X15: =SUM(V15:W15) -> 0 | Z15: =+F15+I15+L15+O15+R15+U15+X15+Y15 -> 1 | AB15: 1 | AC15: =+AA15+AB15-Z15 -> 0 | AE15: =AC15+AD15 -> 0
B16: 1111064 | C16: ชิฟฟอนแยกชิ้น เผือก | F16: =SUM(D16:E16) -> 0 | I16: =SUM(G16:H16) -> 0 | L16: =SUM(J16:K16) -> 0 | O16: =SUM(M16:N16) -> 0 | R16: =SUM(P16:Q16) -> 0 | U16: =SUM(S16:T16) -> 0 | X16: =SUM(V16:W16) -> 0 | Z16: =+F16+I16+L16+O16+R16+U16+X16+Y16 -> 0 | AC16: =+AA16+AB16-Z16 -> 0 | AE16: =AC16+AD16 -> 0
B17: 1111065 | C17: ชิฟฟอนแยกชิ้น สับปะรด | F17: =SUM(D17:E17) -> 0 | I17: =SUM(G17:H17) -> 0 | L17: =SUM(J17:K17) -> 0 | O17: =SUM(M17:N17) -> 0 | R17: =SUM(P17:Q17) -> 0 | U17: =SUM(S17:T17) -> 0 | X17: =SUM(V17:W17) -> 0 | Z17: =+F17+I17+L17+O17+R17+U17+X17+Y17 -> 0 | AC17: =+AA17+AB17-Z17 -> 0 | AE17: =AC17+AD17 -> 0
B18: 1111066 | C18: ชิฟฟอนแยกชิ้น สตอเบอรี่ | F18: =SUM(D18:E18) -> 0 | I18: =SUM(G18:H18) -> 0 | L18: =SUM(J18:K18) -> 0 | O18: =SUM(M18:N18) -> 0 | R18: =SUM(P18:Q18) -> 0 | U18: =SUM(S18:T18) -> 0 | X18: =SUM(V18:W18) -> 0 | Z18: =+F18+I18+L18+O18+R18+U18+X18+Y18 -> 0 | AB18: 1 | AC18: =+AA18+AB18-Z18 -> 1 | AE18: =AC18+AD18 -> 1
B19: 1111067 | C19: ชิฟฟอนแยกชิ้น มะพร้าว | F19: =SUM(D19:E19) -> 0 | I19: =SUM(G19:H19) -> 0 | L19: =SUM(J19:K19) -> 0 | O19: =SUM(M19:N19) -> 0 | R19: =SUM(P19:Q19) -> 0 | U19: =SUM(S19:T19) -> 0 | X19: =SUM(V19:W19) -> 0 | Z19: =+F19+I19+L19+O19+R19+U19+X19+Y19 -> 0 | AC19: =+AA19+AB19-Z19 -> 0 | AE19: =AC19+AD19 -> 0
B20: 1111068 | C20: ชิฟฟอนแยกชิ้น เนย | F20: =SUM(D20:E20) -> 0 | I20: =SUM(G20:H20) -> 0 | L20: =SUM(J20:K20) -> 0 | O20: =SUM(M20:N20) -> 0 | R20: =SUM(P20:Q20) -> 0 | U20: =SUM(S20:T20) -> 0 | X20: =SUM(V20:W20) -> 0 | Z20: =+F20+I20+L20+O20+R20+U20+X20+Y20 -> 0 | AC20: =+AA20+AB20-Z20 -> 0 | AE20: =AC20+AD20 -> 0
B21: 1111069 | C21: ชิฟฟอนแยกชิ้น บลูเบอรี่ | F21: =SUM(D21:E21) -> 0 | I21: =SUM(G21:H21) -> 0 | L21: =SUM(J21:K21) -> 0 | O21: =SUM(M21:N21) -> 0 | R21: =SUM(P21:Q21) -> 0 | U21: =SUM(S21:T21) -> 0 | X21: =SUM(V21:W21) -> 0 | Z21: =+F21+I21+L21+O21+R21+U21+X21+Y21 -> 0 | AC21: =+AA21+AB21-Z21 -> 0 | AE21: =AC21+AD21 -> 0
B22: 1111070 | C22: ชิฟฟอนแยกชิ้น ทุเรียน | F22: =SUM(D22:E22) -> 0 | I22: =SUM(G22:H22) -> 0 | L22: =SUM(J22:K22) -> 0 | O22: =SUM(M22:N22) -> 0 | R22: =SUM(P22:Q22) -> 0 | U22: =SUM(S22:T22) -> 0 | X22: =SUM(V22:W22) -> 0 | Z22: =+F22+I22+L22+O22+R22+U22+X22+Y22 -> 0 | AC22: =+AA22+AB22-Z22 -> 0 | AE22: =AC22+AD22 -> 0
B23: 1111071 | C23: ชิฟฟอนแยกชิ้น ตาล | F23: =SUM(D23:E23) -> 0 | I23: =SUM(G23:H23) -> 0 | L23: =SUM(J23:K23) -> 0 | O23: =SUM(M23:N23) -> 0 | R23: =SUM(P23:Q23) -> 0 | U23: =SUM(S23:T23) -> 0 | X23: =SUM(V23:W23) -> 0 | Z23: =+F23+I23+L23+O23+R23+U23+X23+Y23 -> 0 | AC23: =+AA23+AB23-Z23 -> 0 | AE23: =AC23+AD23 -> 0
B24: 1111010 | C24: ชิฟฟ่อนเค้กสอดไส้แยม (1 ชิ้น) | F24: =SUM(D24:E24) -> 0 | I24: =SUM(G24:H24) -> 0 | L24: =SUM(J24:K24) -> 0 | O24: =SUM(M24:N24) -> 0 | R24: =SUM(P24:Q24) -> 0 | U24: =SUM(S24:T24) -> 0 | X24: =SUM(V24:W24) -> 0 | Z24: =+F24+I24+L24+O24+R24+U24+X24+Y24 -> 0 | AC24: =+AA24+AB24-Z24 -> 0 | AE24: =AC24+AD24 -> 0
B25: 1111008 | C25: ชิฟฟ่อนเค้ก สอดไส้ (รวมรส 3 ชิ้น) | D25: 10 | E25: 11 | F25: =SUM(D25:E25) -> 21 | H25: 3 | I25: =SUM(G25:H25) -> 3 | L25: =SUM(J25:K25) -> 0 | M25: 235 | N25: 39 | O25: =SUM(M25:N25) -> 274 | P25: 27 | R25: =SUM(P25:Q25) -> 27 | U25: =SUM(S25:T25) -> 0 | X25: =SUM(V25:W25) -> 0 | Z25: =+F25+I25+L25+O25+R25+U25+X25+Y25 -> 325 | AA25: 100 | AB25: 103 | AC25: =+AA25+AB25-Z25 -> -122 | AD25: 150 | AE25: =AC25+AD25 -> 28
B26: 1111009 | C26: ชิฟฟ่อนเค้ก สอดไส้ (รวมรส 6 ชิ้น) | D26: 10 | F26: =SUM(D26:E26) -> 10 | G26: 7 | I26: =SUM(G26:H26) -> 7 | J26: 2 | L26: =SUM(J26:K26) -> 2 | O26: =SUM(M26:N26) -> 0 | R26: =SUM(P26:Q26) -> 0 | U26: =SUM(S26:T26) -> 0 | X26: =SUM(V26:W26) -> 0 | Z26: =+F26+I26+L26+O26+R26+U26+X26+Y26 -> 19 | AA26: 50 | AB26: 42 | AC26: =+AA26+AB26-Z26 -> 73 | AD26: 50 | AE26: =AC26+AD26 -> 123
B27: 1111011 | C27: ชิฟฟ่อนเค้กสอดไส้ นมชมพูฮอกไกโด (3 ชิ้น) | F27: =SUM(D27:E27) -> 0 | I27: =SUM(G27:H27) -> 0 | L27: =SUM(J27:K27) -> 0 | O27: =SUM(M27:N27) -> 0 | R27: =SUM(P27:Q27) -> 0 | U27: =SUM(S27:T27) -> 0 | X27: =SUM(V27:W27) -> 0 | Z27: =+F27+I27+L27+O27+R27+U27+X27+Y27 -> 0 | AC27: =+AA27+AB27-Z27 -> 0 | AE27: =AC27+AD27 -> 0
B28: 1111012 | C28: ชิฟฟ่อนเค้กสอดไส้ นมชมพูฮอกไกโด (6 ชิ้น) | F28: =SUM(D28:E28) -> 0 | I28: =SUM(G28:H28) -> 0 | L28: =SUM(J28:K28) -> 0 | O28: =SUM(M28:N28) -> 0 | R28: =SUM(P28:Q28) -> 0 | U28: =SUM(S28:T28) -> 0 | X28: =SUM(V28:W28) -> 0 | Z28: =+F28+I28+L28+O28+R28+U28+X28+Y28 -> 0 | AC28: =+AA28+AB28-Z28 -> 0 | AE28: =AC28+AD28 -> 0
B29: 1111013 | C29: ชิฟฟ่อนเค้กสอดไส้ ช็อคโกแลตนูเทลล่า (3 ชิ้น) | F29: =SUM(D29:E29) -> 0 | I29: =SUM(G29:H29) -> 0 | L29: =SUM(J29:K29) -> 0 | O29: =SUM(M29:N29) -> 0 | R29: =SUM(P29:Q29) -> 0 | U29: =SUM(S29:T29) -> 0 | X29: =SUM(V29:W29) -> 0 | Z29: =+F29+I29+L29+O29+R29+U29+X29+Y29 -> 0 | AC29: =+AA29+AB29-Z29 -> 0 | AE29: =AC29+AD29 -> 0
B30: 1111014 | C30: ชิฟฟ่อนเค้กสอดไส้ ช็อคโกแลตนูเทลล่า (6 ชิ้น) | F30: =SUM(D30:E30) -> 0 | I30: =SUM(G30:H30) -> 0 | L30: =SUM(J30:K30) -> 0 | O30: =SUM(M30:N30) -> 0 | R30: =SUM(P30:Q30) -> 0 | U30: =SUM(S30:T30) -> 0 | X30: =SUM(V30:W30) -> 0 | Z30: =+F30+I30+L30+O30+R30+U30+X30+Y30 -> 0 | AC30: =+AA30+AB30-Z30 -> 0 | AE30: =AC30+AD30 -> 0
B31: 1111015 | C31: ชิฟฟ่อนเค้กสอดไส้เนย รสมะพร้าว (3 ชิ้น) | F31: =SUM(D31:E31) -> 0 | I31: =SUM(G31:H31) -> 0 | L31: =SUM(J31:K31) -> 0 | O31: =SUM(M31:N31) -> 0 | R31: =SUM(P31:Q31) -> 0 | U31: =SUM(S31:T31) -> 0 | X31: =SUM(V31:W31) -> 0 | Z31: =+F31+I31+L31+O31+R31+U31+X31+Y31 -> 0 | AC31: =+AA31+AB31-Z31 -> 0 | AE31: =AC31+AD31 -> 0
B32: 1111016 | C32: ชิฟฟ่อนเค้กสอดไส้เนย รสมะพร้าว (6 ชิ้น) | F32: =SUM(D32:E32) -> 0 | I32: =SUM(G32:H32) -> 0 | L32: =SUM(J32:K32) -> 0 | O32: =SUM(M32:N32) -> 0 | R32: =SUM(P32:Q32) -> 0 | U32: =SUM(S32:T32) -> 0 | X32: =SUM(V32:W32) -> 0 | Z32: =+F32+I32+L32+O32+R32+U32+X32+Y32 -> 0 | AC32: =+AA32+AB32-Z32 -> 0 | AE32: =AC32+AD32 -> 0
B33: 1111017 | C33: ชิฟฟ่อนเค้กสอดไส้แยม รสบลูเบอร์รี่ (3 ชิ้น) | F33: =SUM(D33:E33) -> 0 | I33: =SUM(G33:H33) -> 0 | L33: =SUM(J33:K33) -> 0 | O33: =SUM(M33:N33) -> 0 | R33: =SUM(P33:Q33) -> 0 | U33: =SUM(S33:T33) -> 0 | X33: =SUM(V33:W33) -> 0 | Z33: =+F33+I33+L33+O33+R33+U33+X33+Y33 -> 0 | AC33: =+AA33+AB33-Z33 -> 0 | AE33: =AC33+AD33 -> 0
B34: 1111018 | C34: ชิฟฟ่อนเค้กสอดไส้แยม รสบลูเบอร์รี่ (6 ชิ้น) | F34: =SUM(D34:E34) -> 0 | I34: =SUM(G34:H34) -> 0 | L34: =SUM(J34:K34) -> 0 | O34: =SUM(M34:N34) -> 0 | R34: =SUM(P34:Q34) -> 0 | U34: =SUM(S34:T34) -> 0 | X34: =SUM(V34:W34) -> 0 | Z34: =+F34+I34+L34+O34+R34+U34+X34+Y34 -> 0 | AC34: =+AA34+AB34-Z34 -> 0 | AE34: =AC34+AD34 -> 0
B35: 1111019 | C35: ชิฟฟ่อนเค้กหน้าฝอยทอง สอดไส้แยมส้ม (3 ชิ้น) | F35: =SUM(D35:E35) -> 0 | I35: =SUM(G35:H35) -> 0 | L35: =SUM(J35:K35) -> 0 | O35: =SUM(M35:N35) -> 0 | R35: =SUM(P35:Q35) -> 0 | U35: =SUM(S35:T35) -> 0 | X35: =SUM(V35:W35) -> 0 | Z35: =+F35+I35+L35+O35+R35+U35+X35+Y35 -> 0 | AC35: =+AA35+AB35-Z35 -> 0 | AE35: =AC35+AD35 -> 0
B36: 1111020 | C36: ชิฟฟ่อนเค้กหน้าฝอยทอง สอดไส้แยมส้ม (6 ชิ้น) | F36: =SUM(D36:E36) -> 0 | I36: =SUM(G36:H36) -> 0 | L36: =SUM(J36:K36) -> 0 | O36: =SUM(M36:N36) -> 0 | R36: =SUM(P36:Q36) -> 0 | U36: =SUM(S36:T36) -> 0 | X36: =SUM(V36:W36) -> 0 | Y36: 1 | Z36: =+F36+I36+L36+O36+R36+U36+X36+Y36 -> 1 | AA36: 1 | AC36: =+AA36+AB36-Z36 -> 0 | AE36: =AC36+AD36 -> 0
B37: 1111022 | C37: ชิฟฟ่อนเค้กสอดไส้แยม รสสตรอว์เบอร์รี (3 ชิ้น) | F37: =SUM(D37:E37) -> 0 | I37: =SUM(G37:H37) -> 0 | L37: =SUM(J37:K37) -> 0 | O37: =SUM(M37:N37) -> 0 | R37: =SUM(P37:Q37) -> 0 | U37: =SUM(S37:T37) -> 0 | X37: =SUM(V37:W37) -> 0 | Z37: =+F37+I37+L37+O37+R37+U37+X37+Y37 -> 0 | AC37: =+AA37+AB37-Z37 -> 0 | AE37: =AC37+AD37 -> 0
B38: 1111023 | C38: ชิฟฟ่อนเค้กสอดไส้แยม รสสตรอว์เบอร์รี (6 ชิ้น) | F38: =SUM(D38:E38) -> 0 | I38: =SUM(G38:H38) -> 0 | L38: =SUM(J38:K38) -> 0 | O38: =SUM(M38:N38) -> 0 | R38: =SUM(P38:Q38) -> 0 | U38: =SUM(S38:T38) -> 0 | X38: =SUM(V38:W38) -> 0 | Z38: =+F38+I38+L38+O38+R38+U38+X38+Y38 -> 0 | AC38: =+AA38+AB38-Z38 -> 0 | AE38: =AC38+AD38 -> 0
B39: 1111024 | C39: ชิฟฟ่อนเค้กสอดไส้แยม รสส้ม (3 ชิ้น) | F39: =SUM(D39:E39) -> 0 | I39: =SUM(G39:H39) -> 0 | L39: =SUM(J39:K39) -> 0 | O39: =SUM(M39:N39) -> 0 | R39: =SUM(P39:Q39) -> 0 | U39: =SUM(S39:T39) -> 0 | X39: =SUM(V39:W39) -> 0 | Z39: =+F39+I39+L39+O39+R39+U39+X39+Y39 -> 0 | AC39: =+AA39+AB39-Z39 -> 0 | AE39: =AC39+AD39 -> 0
B40: 1111025 | C40: ชิฟฟ่อนเค้กสอดไส้แยม รสส้ม (6 ชิ้น) | F40: =SUM(D40:E40) -> 0 | I40: =SUM(G40:H40) -> 0 | L40: =SUM(J40:K40) -> 0 | O40: =SUM(M40:N40) -> 0 | R40: =SUM(P40:Q40) -> 0 | U40: =SUM(S40:T40) -> 0 | X40: =SUM(V40:W40) -> 0 | Z40: =+F40+I40+L40+O40+R40+U40+X40+Y40 -> 0 | AC40: =+AA40+AB40-Z40 -> 0 | AE40: =AC40+AD40 -> 0
...

Sheet 03.12.68
B1: ยอดจริง ออนไลน์ วันที่ 3/12/2568
B2: รหัสสินค้า | C2: สินค้า | D2: ปณ | G2: ชอปปี้ | J2: ลาซาด้า | M2: ติ๊กตอก | P2: ติ๊กตอก2 | S2: ติ๊กตอก3 | V2: ชอยส์ | Y2: ยอดเส้น | Z2: ยอดรวมผลิต(กล่อง) | AA2: ยอดForcast | AB2: ยอดStock | AC2: ยอดMemo | AD2: ยอดForcastวันพรุ่งนี้ | AE2: สินค้าที่ขายได้
D3: เช้า | E3: บ่าย | F3: รวม | G3: เช้า | H3: บ่าย | I3: รวม | J3: เช้า | K3: บ่าย | L3: รวม | M3: เช้า | N3: บ่าย | O3: รวม | P3: เช้า | Q3: บ่าย | R3: รวม | S3: เช้า | T3: บ่าย | U3: รวม | V3: เช้า | W3: บ่าย | X3: รวม
B4: 1004055 | C4: ชิฟฟ่อนเค้ก วรรณวนัช (รวมรส 4 ชิ้น) | D4: 10 | F4: =SUM(D4:E4) -> 10 | G4: 3 | I4: =SUM(G4:H4) -> 3 | L4: =SUM(J4:K4) -> 0 | M4: 450 | O4: =SUM(M4:N4) -> 450 | R4: =SUM(P4:Q4) -> 0 | U4: =SUM(S4:T4) -> 0 | X4: =SUM(V4:W4) -> 0 | Y4: 18 | Z4: =+F4+I4+L4+O4+R4+U4+X4+Y4 -> 481 | AA4: 518 | AB4: 3 | AC4: =+AA4+AB4-Z4 -> 40 | AD4: 500 | AE4: =AC4+AD4 -> 540
B5: 1111002 | C5: ชิฟฟ่อนเค้ก วรรณวนัช (รวมรส 8 ชิ้น) | E5: 20 | F5: =SUM(D5:E5) -> 20 | G5: 40 | I5: =SUM(G5:H5) -> 40 | J5: 12 | L5: =SUM(J5:K5) -> 12 | M5: 12 | O5: =SUM(M5:N5) -> 12 | R5: =SUM(P5:Q5) -> 0 | U5: =SUM(S5:T5) -> 0 | X5: =SUM(V5:W5) -> 0 | Y5: 20 | Z5: =+F5+I5+L5+O5+R5+U5+X5+Y5 -> 104 | AA5: 170 | AB5: 5 | AC5: =+AA5+AB5-Z5 -> 71 | AD5: 150 | AE5: =AC5+AD5 -> 221
B6: 1111001 | C6: ชิฟฟ่อนแยกชิ้นไม่มีไส้ คละรส | F6: =SUM(D6:E6) -> 0 | I6: =SUM(G6:H6) -> 0 | L6: =SUM(J6:K6) -> 0 | O6: =SUM(M6:N6) -> 0 | R6: =SUM(P6:Q6) -> 0 | U6: =SUM(S6:T6) -> 0 | X6: =SUM(V6:W6) -> 0 | Z6: =+F6+I6+L6+O6+R6+U6+X6+Y6 -> 0 | AC6: =+AA6+AB6-Z6 -> 0 | AE6: =AC6+AD6 -> 0
B7: 1111084 | C7: ชิฟฟ่อนเค้ก รสกาแฟ (8 ชิ้น) | F7: =SUM(D7:E7) -> 0 | I7: =SUM(G7:H7) -> 0 | L7: =SUM(J7:K7) -> 0 | O7: =SUM(M7:N7) -> 0 | R7: =SUM(P7:Q7) -> 0 | U7: =SUM(S7:T7) -> 0 | X7: =SUM(V7:W7) -> 0 | Z7: =+F7+I7+L7+O7+R7+U7+X7+Y7 -> 0 | AC7: =+AA7+AB7-Z7 -> 0 | AE7: =AC7+AD7 -> 0
B8: 1111043 | C8: ชิฟฟอนรสมะลิ 8 ชิ้น ห่อ ซีน | F8: =SUM(D8:E8) -> 0 | I8: =SUM(G8:H8) -> 0 | L8: =SUM(J8:K8) -> 0 | O8: =SUM(M8:N8) -> 0 | R8: =SUM(P8:Q8) -> 0 | U8: =SUM(S8:T8) -> 0 | X8: =SUM(V8:W8) -> 0 | Z8: =+F8+I8+L8+O8+R8+U8+X8+Y8 -> 0 | AC8: =+AA8+AB8-Z8 -> 0 | AE8: =AC8+AD8 -> 0
B9: 1111057 | C9: ชิฟฟอนแยกชิ้น กาแฟ | F9: =SUM(D9:E9) -> 0 | I9: =SUM(G9:H9) -> 0 | L9: =SUM(J9:K9) -> 0 | O9: =SUM(M9:N9) -> 0 | R9: =SUM(P9:Q9) -> 0 | U9: =SUM(S9:T9) -> 0 | X9: =SUM(V9:W9) -> 0 | Z9: =+F9+I9+L9+O9+R9+U9+X9+Y9 -> 0 | AC9: =+AA9+AB9-Z9 -> 0 | AE9: =AC9+AD9 -> 0
B10: 1111058 | C10: ชิฟฟอนแยกชิ้น มะลิ | F10: =SUM(D10:E10) -> 0 | I10: =SUM(G10:H10) -> 0 | L10: =SUM(J10:K10) -> 0 | O10: =SUM(M10:N10) -> 0 | R10: =SUM(P10:Q10) -> 0 | U10: =SUM(S10:T10) -> 0 | X10: =SUM(V10:W10) -> 0 | Z10: =+F10+I10+L10+O10+R10+U10+X10+Y10 -> 0 | AC10: =+AA10+AB10-Z10 -> 0 | AE10: =AC10+AD10 -> 0
B11: 1111059 | C11: ชิฟฟอนแยกชิ้น ใบเตย | F11: =SUM(D11:E11) -> 0 | I11: =SUM(G11:H11) -> 0 | L11: =SUM(J11:K11) -> 0 | O11: =SUM(M11:N11) -> 0 | R11: =SUM(P11:Q11) -> 0 | U11: =SUM(S11:T11) -> 0 | X11: =SUM(V11:W11) -> 0 | Z11: =+F11+I11+L11+O11+R11+U11+X11+Y11 -> 0 | AC11: =+AA11+AB11-Z11 -> 0 | AE11: =AC11+AD11 -> 0
B12: 1111060 | C12: ชิฟฟอนแยกชิ้น กล้วยหอม | F12: =SUM(D12:E12) -> 0 | I12: =SUM(G12:H12) -> 0 | L12: =SUM(J12:K12) -> 0 | O12: =SUM(M12:N12) -> 0 | R12: =SUM(P12:Q12) -> 0 | U12: =SUM(S12:T12) -> 0 | X12: =SUM(V12:W12) -> 0 | Z12: =+F12+I12+L12+O12+R12+U12+X12+Y12 -> 0 | AC12: =+AA12+AB12-Z12 -> 0 | AE12: =AC12+AD12 -> 0
B13: 1111061 | C13: ชิฟฟอนแยกชิ้น ชาไทย | F13: =SUM(D13:E13) -> 0 | I13: =SUM(G13:H13) -> 0 | L13: =SUM(J13:K13) -> 0 | O13: =SUM(M13:N13) -> 0 | R13: =SUM(P13:Q13) -> 0 | U13: =SUM(S13:T13) -> 0 | X13: =SUM(V13:W13) -> 0 | Z13: =+F13+I13+L13+O13+R13+U13+X13+Y13 -> 0 | AC13: =+AA13+AB13-Z13 -> 0 | AE13: =AC13+AD13 -> 0
B14: 1111062 | C14: ชิฟฟอนแยกชิ้น โกโก้ | F14: =SUM(D14:E14) -> 0 | I14: =SUM(G14:H14) -> 0 | L14: =SUM(J14:K14) -> 0 | O14: =SUM(M14:N14) -> 0 | R14: =SUM(P14:Q14) -> 0 | U14: =SUM(S14:T14) -> 0 | X14: =SUM(V14:W14) -> 0 | Z14: =+F14+I14+L14+O14+R14+U14+X14+Y14 -> 0 | AC14: =+AA14+AB14-Z14 -> 0 | AE14: =AC14+AD14 -> 0
B15: 1111063 | C15: ชิฟฟอนแยกชิ้น ส้ม | F15: =SUM(D15:E15) -> 0 | I15: =SUM(G15:H15) -> 0 | L15: =SUM(J15:K15) -> 0 | O15: =SUM(M15:N15) -> 0 | R15: =SUM(P15:Q15) -> 0 | U15: =SUM(S15:T15) -> 0 | X15: =SUM(V15:W15) -> 0 | Z15: =+F15+I15+L15+O15+R15+U15+X15+Y15 -> 0 | AC15: =+AA15+AB15-Z15 -> 0 | AE15: =AC15+AD15 -> 0
B16: 1111064 | C16: ชิฟฟอนแยกชิ้น เผือก | F16: =SUM(D16:E16) -> 0 | I16: =SUM(G16:H16) -> 0 | L16: =SUM(J16:K16) -> 0 | O16: =SUM(M16:N16) -> 0 | R16: =SUM(P16:Q16) -> 0 | U16: =SUM(S16:T16) -> 0 | X16: =SUM(V16:W16) -> 0 | Z16: =+F16+I16+L16+O16+R16+U16+X16+Y16 -> 0 | AC16: =+AA16+AB16-Z16 -> 0 | AE16: =AC16+AD16 -> 0
B17: 1111065 | C17: ชิฟฟอนแยกชิ้น สับปะรด | F17: =SUM(D17:E17) -> 0 | I17: =SUM(G17:H17) -> 0 | L17: =SUM(J17:K17) -> 0 | O17: =SUM(M17:N17) -> 0 | R17: =SUM(P17:Q17) -> 0 | U17: =SUM(S17:T17) -> 0 | X17: =SUM(V17:W17) -> 0 | Z17: =+F17+I17+L17+O17+R17+U17+X17+Y17 -> 0 | AC17: =+AA17+AB17-Z17 -> 0 | AE17: =AC17+AD17 -> 0
... B24: 1111010 | C24: ชิฟฟ่อนเค้กสอดไส้แยม (1 ชิ้น) | F24: =SUM(D24:E24) -> 0 | I24: =SUM(G24:H24) -> 0 | L24: =SUM(J24:K24) -> 0 | O24: =SUM(M24:N24) -> 0 | R24: =SUM(P24:Q24) -> 0 | U24: =SUM(S24:T24) -> 0 | X24: =SUM(V24:W24) -> 0 | Z24: =+F24+I24+L24+O24+R24+U24+X24+Y24 -> 0 | AC24: =+AA24+AB24-Z24 -> 0 | AE24: =AC24+AD24 -> 0
B25: 1111008 | C25: ชิฟฟ่อนเค้ก สอดไส้ (รวมรส 3 ชิ้น) | D25: 10 | F25: =SUM(D25:E25) -> 10 | I25: =SUM(G25:H25) -> 0 | L25: =SUM(J25:K25) -> 0 | M25: 127 | O25: =SUM(M25:N25) -> 127 | R25: =SUM(P25:Q25) -> 0 | U25: =SUM(S25:T25) -> 0 | X25: =SUM(V25:W25) -> 0 | Z25: =+F25+I25+L25+O25+R25+U25+X25+Y25 -> 137 | AA25: 150 | AB25: 5 | AC25: =+AA25+AB25-Z25 -> 18 | AD25: 150 | AE25: =AC25+AD25 -> 168
B26: 1111009 | C26: ชิฟฟ่อนเค้ก สอดไส้ (รวมรส 6 ชิ้น) | F26: =SUM(D26:E26) -> 0 | G26: 15 | I26: =SUM(G26:H26) -> 15 | L26: =SUM(J26:K26) -> 0 | O26: =SUM(M26:N26) -> 0 | R26: =SUM(P26:Q26) -> 0 | U26: =SUM(S26:T26) -> 0 | X26: =SUM(V26:W26) -> 0 | Y26: 5 | Z26: =+F26+I26+L26+O26+R26+U26+X26+Y26 -> 20 | AA26: 55 | AC26: =+AA26+AB26-Z26 -> 35 | AD26: 50 | AE26: =AC26+AD26 -> 85
B27: 1111011 | C27: ชิฟฟ่อนเค้กสอดไส้ นมชมพูฮอกไกโด (3 ชิ้น) | F27: =SUM(D27:E27) -> 0 | I27: =SUM(G27:H27) -> 0 | L27: =SUM(J27:K27) -> 0 | O27: =SUM(M27:N27) -> 0 | R27: =SUM(P27:Q27) -> 0 | U27: =SUM(S27:T27) -> 0 | X27: =SUM(V27:W27) -> 0 | Z27: =+F27+I27+L27+O27+R27+U27+X27+Y27 -> 0 | AC27: =+AA27+AB27-Z27 -> 0 | AE27: =AC27+AD27 -> 0
B28: 1111012 | C28: ชิฟฟ่อนเค้กสอดไส้ นมชมพูฮอกไกโด (6 ชิ้น) | F28: =SUM(D28:E28) -> 0 | I28: =SUM(G28:H28) -> 0 | L28: =SUM(J28:K28) -> 0 | O28: =SUM(M28:N28) -> 0 | R28: =SUM(P28:Q28) -> 0 | U28: =SUM(S28:T28) -> 0 | X28: =SUM(V28:W28) -> 0 | Z28: =+F28+I28+L28+O28+R28+U28+X28+Y28 -> 0 | AC28: =+AA28+AB28-Z28 -> 0 | AE28: =AC28+AD28 -> 0
B29: 1111013 | C29: ชิฟฟ่อนเค้กสอดไส้ ช็อคโกแลตนูเทลล่า (3 ชิ้น) | F29: =SUM(D29:E29) -> 0 | I29: =SUM(G29:H29) -> 0 | L29: =SUM(J29:K29) -> 0 | O29: =SUM(M29:N29) -> 0 | R29: =SUM(P29:Q29) -> 0 | U29: =SUM(S29:T29) -> 0 | X29: =SUM(V29:W29) -> 0 | Z29: =+F29+I29+L29+O29+R29+U29+X29+Y29 -> 0 | AC29: =+AA29+AB29-Z29 -> 0 | AE29: =AC29+AD29 -> 0
B30: 1111014 | C30: ชิฟฟ่อนเค้กสอดไส้ ช็อคโกแลตนูเทลล่า (6 ชิ้น) | F30: =SUM(D30:E30) -> 0 | I30: =SUM(G30:H30) -> 0 | L30: =SUM(J30:K30) -> 0 | O30: =SUM(M30:N30) -> 0 | R30: =SUM(P30:Q30) -> 0 | U30: =SUM(S30:T30) -> 0 | X30: =SUM(V30:W30) -> 0 | Z30: =+F30+I30+L30+O30+R30+U30+X30+Y30 -> 0 | AC30: =+AA30+AB30-Z30 -> 0 | AE30: =AC30+AD30 -> 0
B31: 1111015 | C31: ชิฟฟ่อนเค้กสอดไส้เนย รสมะพร้าว (3 ชิ้น) | F31: =SUM(D31:E31) -> 0 | I31: =SUM(G31:H31) -> 0 | L31: =SUM(J31:K31) -> 0 | O31: =SUM(M31:N31) -> 0 | R31: =SUM(P31:Q31) -> 0 | U31: =SUM(S31:T31) -> 0 | X31: =SUM(V31:W31) -> 0 | Z31: =+F31+I31+L31+O31+R31+U31+X31+Y31 -> 0 | AC31: =+AA31+AB31-Z31 -> 0 | AE31: =AC31+AD31 -> 0
B32: 1111016 | C32: ชิฟฟ่อนเค้กสอดไส้เนย รสมะพร้าว (6 ชิ้น) | F32: =SUM(D32:E32) -> 0 | I32: =SUM(G32:H32) -> 0 | L32: =SUM(J32:K32) -> 0 | O32: =SUM(M32:N32) -> 0 | R32: =SUM(P32:Q32) -> 0 | U32: =SUM(S32:T32) -> 0 | X32: =SUM(V32:W32) -> 0 | Z32: =+F32+I32+L32+O32+R32+U32+X32+Y32 -> 0 | AC32: =+AA32+AB32-Z32 -> 0 | AE32: =AC32+AD32 -> 0
B33: 1111017 | C33: ชิฟฟ่อนเค้กสอดไส้แยม รสบลูเบอร์รี่ (3 ชิ้น) | F33: =SUM(D33:E33) -> 0 | I33: =SUM(G33:H33) -> 0 | L33: =SUM(J33:K33) -> 0 | O33: =SUM(M33:N33) -> 0 | R33: =SUM(P33:Q33) -> 0 | U33: =SUM(S33:T33) -> 0 | X33: =SUM(V33:W33) -> 0 | Z33: =+F33+I33+L33+O33+R33+U33+X33+Y33 -> 0 | AC33: =+AA33+AB33-Z33 -> 0 | AE33: =AC33+AD33 -> 0
B34: 1111018 | C34: ชิฟฟ่อนเค้กสอดไส้แยม รสบลูเบอร์รี่ (6 ชิ้น) | F34: =SUM(D34:E34) -> 0 | I34: =SUM(G34:H34) -> 0 | L34: =SUM(J34:K34) -> 0 | O34: =SUM(M34:N34) -> 0 | R34: =SUM(P34:Q34) -> 0 | U34: =SUM(S34:T34) -> 0 | X34: =SUM(V34:W34) -> 0 | Z34: =+F34+I34+L34+O34+R34+U34+X34+Y34 -> 0 | AC34: =+AA34+AB34-Z34 -> 0 | AE34: =AC34+AD34 -> 0
B35: 1111019 | C35: ชิฟฟ่อนเค้กหน้าฝอยทอง สอดไส้แยมส้ม (3 ชิ้น) | F35: =SUM(D35:E35) -> 0 | I35: =SUM(G35:H35) -> 0 | L35: =SUM(J35:K35) -> 0 | O35: =SUM(M35:N35) -> 0 | R35: =SUM(P35:Q35) -> 0 | U35: =SUM(S35:T35) -> 0 | X35: =SUM(V35:W35) -> 0 | Z35: =+F35+I35+L35+O35+R35+U35+X35+Y35 -> 0 | AC35: =+AA35+AB35-Z35 -> 0 | AE35: =AC35+AD35 -> 0
B36: 1111020 | C36: ชิฟฟ่อนเค้กหน้าฝอยทอง สอดไส้แยมส้ม (6 ชิ้น) | F36: =SUM(D36:E36) -> 0 | I36: =SUM(G36:H36) -> 0 | L36: =SUM(J36:K36) -> 0 | O36: =SUM(M36:N36) -> 0 | R36: =SUM(P36:Q36) -> 0 | U36: =SUM(S36:T36) -> 0 | X36: =SUM(V36:W36) -> 0 | Z36: =+F36+I36+L36+O36+R36+U36+X36+Y36 -> 0 | AC36: =+AA36+AB36-Z36 -> 0 | AE36: =AC36+AD36 -> 0
B37: 1111022 | C37: ชิฟฟ่อนเค้กสอดไส้แยม รสสตรอว์เบอร์รี (3 ชิ้น) | F37: =SUM(D37:E37) -> 0 | I37: =SUM(G37:H37) -> 0 | L37: =SUM(J37:K37) -> 0 | O37: =SUM(M37:N37) -> 0 | R37: =SUM(P37:Q37) -> 0 | U37: =SUM(S37:T37) -> 0 | X37: =SUM(V37:W37) -> 0 | Z37: =+F37+I37+L37+O37+R37+U37+X37+Y37 -> 0 | AC37: =+AA37+AB37-Z37 -> 0 | AE37: =AC37+AD37 -> 0
B38: 1111023 | C38: ชิฟฟ่อนเค้กสอดไส้แยม รสสตรอว์เบอร์รี (6 ชิ้น) | F38: =SUM(D38:E38) -> 0 | I38: =SUM(G38:H38) -> 0 | L38: =SUM(J38:K38) -> 0 | O38: =SUM(M38:N38) -> 0 | R38: =SUM(P38:Q38) -> 0 | U38: =SUM(S38:T38) -> 0 | X38: =SUM(V38:W38) -> 0 | Z38: =+F38+I38+L38+O38+R38+U38+X38+Y38 -> 0 | AC38: =+AA38+AB38-Z38 -> 0 | AE38: =AC38+AD38 -> 0
... B40: 1111025 | C40: ชิฟฟ่อนเค้กสอดไส้แยม รสส้ม (6 ชิ้น) | F40: =SUM(D40:E40) -> 0 | I40: =SUM(G40:H40) -> 0 | L40: =SUM(J40:K40) -> 0 | O40: =SUM(M40:N40) -> 0 | R40: =SUM(P40:Q40) -> 0 | U40: =SUM(S40:T40) -> 0 | X40: =SUM(V40:W40) -> 0 | Z40: =+F40+I40+L40+O40+R40+U40+X40+Y40 -> 0 | AC40: =+AA40+AB40-Z40 -> 0 | AE40: =AC40+AD40 -> 0
B41: 1111056 | C41: ชิฟฟอนรวมรสยอดฮิต 8 ชิ้น | F41: =SUM(D41:E41) -> 0 | G41: 2 | I41: =SUM(G41:H41) -> 2 | L41: =SUM(J41:K41) -> 0 | O41: =SUM(M41:N41) -> 0 | R41: =SUM(P41:Q41) -> 0 | U41: =SUM(S41:T41) -> 0 | X41: =SUM(V41:W41) -> 0 | Z41: =+F41+I41+L41+O41+R41+U41+X41+Y41 -> 2 | AB41: 8 | AC41: =+AA41+AB41-Z41 -> 6 | AE41: =AC41+AD41 -> 6
B42: 1111074 | C42: ชิฟฟอนไส้แยมแยกชิ้น มะพร้าว | F42: =SUM(D42:E42) -> 0 | I42: =SUM(G42:H42) -> 0 | L42: =SUM(J42:K42) -> 0 | O42: =SUM(M42:N42) -> 0 | R42: =SUM(P42:Q42) -> 0 | U42: =SUM(S42:T42) -> 0 | X42: =SUM(V42:W42) -> 0 | Z42: =+F42+I42+L42+O42+R42+U42+X42+Y42 -> 0 | AC42: =+AA42+AB42-Z42 -> 0 | AE42: =AC42+AD42 -> 0
B43: 1111075 | C43: ชิฟฟอนไส้แยมแยกชิ้น สตอเบอรี่ | F43: =SUM(D43:E43) -> 0 | I43: =SUM(G43:H43) -> 0 | L43: =SUM(J43:K43) -> 0 | O43: =SUM(M43:N43) -> 0 | R43: =SUM(P43:Q43) -> 0 | U43: =SUM(S43:T43) -> 0 | X43: =SUM(V43:W43) -> 0 | Z43: =+F43+I43+L43+O43+R43+U43+X43+Y43 -> 0 | AC43: =+AA43+AB43-Z43 -> 0 | AE43: =AC43+AD43 -> 0
B44: 1111076 | C44: ชิฟฟอนไส้แยมแยกชิ้น ส้ม | F44: =SUM(D44:E44) -> 0 | I44: =SUM(G44:H44) -> 0 | L44: =SUM(J44:K44) -> 0 | O44: =SUM(M44:N44) -> 0 | R44: =SUM(P44:Q44) -> 0 | U44: =SUM(S44:T44) -> 0 | X44: =SUM(V44:W44) -> 0 | Z44: =+F44+I44+L44+O44+R44+U44+X44+Y44 -> 0 | AC44: =+AA44+AB44-Z44 -> 0 | AE44: =AC44+AD44 -> 0
B45: 1111077 | C45: ชิฟฟอนไส้แยมแยกชิ้น บลูเบอรี่ | F45: =SUM(D45:E45) -> 0 | I45: =SUM(G45:H45) -> 0 | L45: =SUM(J45:K45) -> 0 | O45: =SUM(M45:N45) -> 0 | R45: =SUM(P45:Q45) -> 0 | U45: =SUM(S45:T45) -> 0 | X45: =SUM(V45:W45) -> 0 | Z45: =+F45+I45+L45+O45+R45+U45+X45+Y45 -> 0 | AB45: 1 | AC45: =+AA45+AB45-Z45 -> 1 | AE45: =AC45+AD45 -> 1
B46: 1111078 | C46: ชิฟฟอนไส้แยมแยกชิ้น นมชมพู | F46: =SUM(D46:E46) -> 0 | I46: =SUM(G46:H46) -> 0 | L46: =SUM(J46:K46) -> 0 | O46: =SUM(M46:N46) -> 0 | R46: =SUM(P46:Q46) -> 0 | U46: =SUM(S46:T46) -> 0 | X46: =SUM(V46:W46) -> 0 | Z46: =+F46+I46+L46+O46+R46+U46+X46+Y46 -> 0 | AC46: =+AA46+AB46-Z46 -> 0 | AE46: =AC46+AD46 -> 0
B47: 1111079 | C47: ชิฟฟอนไส้แยมแยกชิ้น ชอคโกแลต | F47: =SUM(D47:E47) -> 0 | I47: =SUM(G47:H47) -> 0 | L47: =SUM(J47:K47) -> 0 | O47: =SUM(M47:N47) -> 0 | R47: =SUM(P47:Q47) -> 0 | U47: =SUM(S47:T47) -> 0 | X47: =SUM(V47:W47) -> 0 | Z47: =+F47+I47+L47+O47+R47+U47+X47+Y47 -> 0 | AC47: =+AA47+AB47-Z47 -> 0 | AE47: =AC47+AD47 -> 0
...

Sheet 04.12.68
B1: ยอดจริง ออนไลน์ วันที่ 4/12/2568
B2: รหัสสินค้า | C2: สินค้า | D2: ปณ | G2: ชอปปี้ | J2: ลาซาด้า | M2: ติ๊กตอก | P2: ติ๊กตอก2 | S2: ติ๊กตอก3 | V2: ชอยส์ | Y2: ยอดเส้น | Z2: ยอดรวมผลิต(กล่อง) | AA2: ยอดForcast | AB2: ยอดStock | AC2: ยอดMemo | AD2: ยอดForcastวันพรุ่งนี้ | AE2: สินค้าที่ขายได้
D3: เช้า | E3: บ่าย | F3: รวม | G3: เช้า | H3: บ่าย | I3: รวม | J3: เช้า | K3: บ่าย | L3: รวม | M3: เช้า | N3: บ่าย | O3: รวม | P3: เช้า | Q3: บ่าย | R3: รวม | S3: เช้า | T3: บ่าย | U3: รวม | V3: เช้า | W3: บ่าย | X3: รวม
B4: 1004055 | C4: ชิฟฟ่อนเค้ก วรรณวนัช (รวมรส 4 ชิ้น) | D4: 18 | F4: =SUM(D4:E4) -> 18 | G4: 7 | I4: =SUM(G4:H4) -> 7 | L4: =SUM(J4:K4) -> 0 | M4: 481 | O4: =SUM(M4:N4) -> 481 | P4: 90 | R4: =SUM(P4:Q4) -> 90 | U4: =SUM(S4:T4) -> 0 | X4: =SUM(V4:W4) -> 0 | Z4: =+F4+I4+L4+O4+R4+U4+X4+Y4 -> 596 | AA4: 510 | AB4: 48 | AC4: =+AA4+AB4-Z4 -> -38 | AD4: 605 | AE4: =AC4+AD4 -> 567
B5: 1111002 | C5: ชิฟฟ่อนเค้ก วรรณวนัช (รวมรส 8 ชิ้น) | D5: 2 | F5: =SUM(D5:E5) -> 2 | G5: 42 | I5: =SUM(G5:H5) -> 42 | J5: 6 | L5: =SUM(J5:K5) -> 6 | M5: 15 | O5: =SUM(M5:N5) -> 15 | R5: =SUM(P5:Q5) -> 0 | U5: =SUM(S5:T5) -> 0 | X5: =SUM(V5:W5) -> 0 | Y5: 13 | Z5: =+F5+I5+L5+O5+R5+U5+X5+Y5 -> 78 | AA5: 153 | AB5: 60 | AC5: =+AA5+AB5-Z5 -> 135 | AD5: 150 | AE5: =AC5+AD5 -> 285
B6: 1111001 | C6: ชิฟฟ่อนแยกชิ้นไม่มีไส้ คละรส | F6: =SUM(D6:E6) -> 0 | I6: =SUM(G6:H6) -> 0 | L6: =SUM(J6:K6) -> 0 | O6: =SUM(M6:N6) -> 0 | R6: =SUM(P6:Q6) -> 0 | U6: =SUM(S6:T6) -> 0 | X6: =SUM(V6:W6) -> 0 | Z6: =+F6+I6+L6+O6+R6+U6+X6+Y6 -> 0 | AC6: =+AA6+AB6-Z6 -> 0 | AE6: =AC6+AD6 -> 0
B7: 1111084 | C7: ชิฟฟ่อนเค้ก รสกาแฟ (8 ชิ้น) | F7: =SUM(D7:E7) -> 0 | I7: =SUM(G7:H7) -> 0 | L7: =SUM(J7:K7) -> 0 | O7: =SUM(M7:N7) -> 0 | R7: =SUM(P7:Q7) -> 0 | U7: =SUM(S7:T7) -> 0 | X7: =SUM(V7:W7) -> 0 | Z7: =+F7+I7+L7+O7+R7+U7+X7+Y7 -> 0 | AC7: =+AA7+AB7-Z7 -> 0 | AE7: =AC7+AD7 -> 0
B8: 1111043 | C8: ชิฟฟอนรสมะลิ 8 ชิ้น ห่อ ซีน | F8: =SUM(D8:E8) -> 0 | I8: =SUM(G8:H8) -> 0 | L8: =SUM(J8:K8) -> 0 | O8: =SUM(M8:N8) -> 0 | R8: =SUM(P8:Q8) -> 0 | U8: =SUM(S8:T8) -> 0 | X8: =SUM(V8:W8) -> 0 | Z8: =+F8+I8+L8+O8+R8+U8+X8+Y8 -> 0 | AC8: =+AA8+AB8-Z8 -> 0 | AE8: =AC8+AD8 -> 0
B9: 1111057 | C9: ชิฟฟอนแยกชิ้น กาแฟ | F9: =SUM(D9:E9) -> 0 | G9: 30 | I9: =SUM(G9:H9) -> 30 | L9: =SUM(J9:K9) -> 0 | O9: =SUM(M9:N9) -> 0 | R9: =SUM(P9:Q9) -> 0 | U9: =SUM(S9:T9) -> 0 | X9: =SUM(V9:W9) -> 0 | Z9: =+F9+I9+L9+O9+R9+U9+X9+Y9 -> 30 | AC9: =+AA9+AB9-Z9 -> -30 | AE9: =AC9+AD9 -> -30
B10: 1111058 | C10: ชิฟฟอนแยกชิ้น มะลิ | F10: =SUM(D10:E10) -> 0 | G10: 30 | I10: =SUM(G10:H10) -> 30 | L10: =SUM(J10:K10) -> 0 | O10: =SUM(M10:N10) -> 0 | R10: =SUM(P10:Q10) -> 0 | U10: =SUM(S10:T10) -> 0 | X10: =SUM(V10:W10) -> 0 | Z10: =+F10+I10+L10+O10+R10+U10+X10+Y10 -> 30 | AC10: =+AA10+AB10-Z10 -> -30 | AE10: =AC10+AD10 -> -30
B11: 1111059 | C11: ชิฟฟอนแยกชิ้น ใบเตย | F11: =SUM(D11:E11) -> 0 | G11: 30 | I11: =SUM(G11:H11) -> 30 | L11: =SUM(J11:K11) -> 0 | O11: =SUM(M11:N11) -> 0 | R11: =SUM(P11:Q11) -> 0 | U11: =SUM(S11:T11) -> 0 | X11: =SUM(V11:W11) -> 0 | Z11: =+F11+I11+L11+O11+R11+U11+X11+Y11 -> 30 | AC11: =+AA11+AB11-Z11 -> -30 | AE11: =AC11+AD11 -> -30
B12: 1111060 | C12: ชิฟฟอนแยกชิ้น กล้วยหอม | F12: =SUM(D12:E12) -> 0 | G12: 30 | I12: =SUM(G12:H12) -> 30 | L12: =SUM(J12:K12) -> 0 | O12: =SUM(M12:N12) -> 0 | R12: =SUM(P12:Q12) -> 0 | U12: =SUM(S12:T12) -> 0 | X12: =SUM(V12:W12) -> 0 | Z12: =+F12+I12+L12+O12+R12+U12+X12+Y12 -> 30 | AC12: =+AA12+AB12-Z12 -> -30 | AE12: =AC12+AD12 -> -30
B13: 1111061 | C13: ชิฟฟอนแยกชิ้น ชาไทย | F13: =SUM(D13:E13) -> 0 | G13: 30 | I13: =SUM(G13:H13) -> 30 | L13: =SUM(J13:K13) -> 0 | O13: =SUM(M13:N13) -> 0 | R13: =SUM(P13:Q13) -> 0 | U13: =SUM(S13:T13) -> 0 | X13: =SUM(V13:W13) -> 0 | Z13: =+F13+I13+L13+O13+R13+U13+X13+Y13 -> 30 | AC13: =+AA13+AB13-Z13 -> -30 | AE13: =AC13+AD13 -> -30
B14: 1111062 | C14: ชิฟฟอนแยกชิ้น โกโก้ | F14: =SUM(D14:E14) -> 0 | G14: 30 | I14: =SUM(G14:H14) -> 30 | L14: =SUM(J14:K14) -> 0 | O14: =SUM(M14:N14) -> 0 | R14: =SUM(P14:Q14) -> 0 | U14: =SUM(S14:T14) -> 0 | X14: =SUM(V14:W14) -> 0 | Z14: =+F14+I14+L14+O14+R14+U14+X14+Y14 -> 30 | AC14: =+AA14+AB14-Z14 -> -30 | AE14: =AC14+AD14 -> -30
B15: 1111063 | C15: ชิฟฟอนแยกชิ้น ส้ม | F15: =SUM(D15:E15) -> 0 | G15: 30 | I15: =SUM(G15:H15) -> 30 | L15: =SUM(J15:K15) -> 0 | O15: =SUM(M15:N15) -> 0 | R15: =SUM(P15:Q15) -> 0 | U15: =SUM(S15:T15) -> 0 | X15: =SUM(V15:W15) -> 0 | Z15: =+F15+I15+L15+O15+R15+U15+X15+Y15 -> 30 | AC15: =+AA15+AB15-Z15 -> -30 | AE15: =AC15+AD15 -> -30
B16: 1111064 | C16: ชิฟฟอนแยกชิ้น เผือก | F16: =SUM(D16:E16) -> 0 | G16: 30 | I16: =SUM(G16:H16) -> 30 | L16: =SUM(J16:K16) -> 0 | O16: =SUM(M16:N16) -> 0 | R16: =SUM(P16:Q16) -> 0 | U16: =SUM(S16:T16) -> 0 | X16: =SUM(V16:W16) -> 0 | Z16: =+F16+I16+L16+O16+R16+U16+X16+Y16 -> 30 | AC16: =+AA16+AB16-Z16 -> -30 | AE16: =AC16+AD16 -> -30
B17: 1111065 | C17: ชิฟฟอนแยกชิ้น สับปะรด | F17: =SUM(D17:E17) -> 0 | G17: 30 | I17: =SUM(G17:H17) -> 30 | L17: =SUM(J17:K17) -> 0 | O17: =SUM(M17:N17) -> 0 | R17: =SUM(P17:Q17) -> 0 | U17: =SUM(S17:T17) -> 0 | X17: =SUM(V17:W17) -> 0 | Z17: =+F17+I17+L17+O17+R17+U17+X17+Y17 -> 30 | AC17: =+AA17+AB17-Z17 -> -30 | AE17: =AC17+AD17 -> -30
B18: 1111066 | C18: ชิฟฟอนแยกชิ้น สตอเบอรี่ | F18: =SUM(D18:E18) -> 0 | G18: 30 | I18: =SUM(G18:H18) -> 30 | L18: =SUM(J18:K18) -> 0 | O18: =SUM(M18:N18) -> 0 | R18: =SUM(P18:Q18) -> 0 | U18: =SUM(S18:T18) -> 0 | X18: =SUM(V18:W18) -> 0 | Z18: =+F18+I18+L18+O18+R18+U18+X18+Y18 -> 30 | AC18: =+AA18+AB18-Z18 -> -30 | AE18: =AC18+AD18 -> -30
B19: 1111067 | C19: ชิฟฟอนแยกชิ้น มะพร้าว | F19: =SUM(D19:E19) -> 0 | I19: =SUM(G19:H19) -> 0 | L19: =SUM(J19:K19) -> 0 | O19: =SUM(M19:N19) -> 0 | R19: =SUM(P19:Q19) -> 0 | U19: =SUM(S19:T19) -> 0 | X19: =SUM(V19:W19) -> 0 | Z19: =+F19+I19+L19+O19+R19+U19+X19+Y19 -> 0 | AC19: =+AA19+AB19-Z19 -> 0 | AE19: =AC19+AD19 -> 0
B20: 1111068 | C20: ชิฟฟอนแยกชิ้น เนย | F20: =SUM(D20:E20) -> 0 | I20: =SUM(G20:H20) -> 0 | L20: =SUM(J20:K20) -> 0 | O20: =SUM(M20:N20) -> 0 | R20: =SUM(P20:Q20) -> 0 | U20: =SUM(S20:T20) -> 0 | X20: =SUM(V20:W20) -> 0 | Z20: =+F20+I20+L20+O20+R20+U20+X20+Y20 -> 0 | AC20: =+AA20+AB20-Z20 -> 0 | AE20: =AC20+AD20 -> 0
B21: 1111069 | C21: ชิฟฟอนแยกชิ้น บลูเบอรี่ | F21: =SUM(D21:E21) -> 0 | I21: =SUM(G21:H21) -> 0 | L21: =SUM(J21:K21) -> 0 | O21: =SUM(M21:N21) -> 0 | R21: =SUM(P21:Q21) -> 0 | U21: =SUM(S21:T21) -> 0 | X21: =SUM(V21:W21) -> 0 | Z21: =+F21+I21+L21+O21+R21+U21+X21+Y21 -> 0 | AC21: =+AA21+AB21-Z21 -> 0 | AE21: =AC21+AD21 -> 0
B22: 1111070 | C22: ชิฟฟอนแยกชิ้น ทุเรียน | F22: =SUM(D22:E22) -> 0 | I22: =SUM(G22:H22) -> 0 | L22: =SUM(J22:K22) -> 0 | O22: =SUM(M22:N22) -> 0 | R22: =SUM(P22:Q22) -> 0 | U22: =SUM(S22:T22) -> 0 | X22: =SUM(V22:W22) -> 0 | Z22: =+F22+I22+L22+O22+R22+U22+X22+Y22 -> 0 | AC22: =+AA22+AB22-Z22 -> 0 | AE22: =AC22+AD22 -> 0
B23: 1111071 | C23: ชิฟฟอนแยกชิ้น ตาล | F23: =SUM(D23:E23) -> 0 | I23: =SUM(G23:H23) -> 0 | L23: =SUM(J23:K23) -> 0 | O23: =SUM(M23:N23) -> 0 | R23: =SUM(P23:Q23) -> 0 | U23: =SUM(S23:T23) -> 0 | X23: =SUM(V23:W23) -> 0 | Z23: =+F23+I23+L23+O23+R23+U23+X23+Y23 -> 0 | AC23: =+AA23+AB23-Z23 -> 0 | AE23: =AC23+AD23 -> 0
B24: 1111010 | C24: ชิฟฟ่อนเค้กสอดไส้แยม (1 ชิ้น) | F24: =SUM(D24:E24) -> 0 | I24: =SUM(G24:H24) -> 0 | L24: =SUM(J24:K24) -> 0 | O24: =SUM(M24:N24) -> 0 | R24: =SUM(P24:Q24) -> 0 | U24: =SUM(S24:T24) -> 0 | X24: =SUM(V24:W24) -> 0 | Z24: =+F24+I24+L24+O24+R24+U24+X24+Y24 -> 0 | AC24: =+AA24+AB24-Z24 -> 0 | AE24: =AC24+AD24 -> 0
B25: 1111008 | C25: ชิฟฟ่อนเค้ก สอดไส้ (รวมรส 3 ชิ้น) | D25: 18 | F25: =SUM(D25:E25) -> 18 | G25: 5 | I25: =SUM(G25:H25) -> 5 | L25: =SUM(J25:K25) -> 0 | M25: 102 | O25: =SUM(M25:N25) -> 102 | P25: 49 | R25: =SUM(P25:Q25) -> 49 | U25: =SUM(S25:T25) -> 0 | X25: =SUM(V25:W25) -> 0 | Z25: =+F25+I25+L25+O25+R25+U25+X25+Y25 -> 174 | AA25: 150 | AB25: 8 | AC25: =+AA25+AB25-Z25 -> -16 | AD25: 200 | AE25: =AC25+AD25 -> 184
B26: 1111009 | C26: ชิฟฟ่อนเค้ก สอดไส้ (รวมรส 6 ชิ้น) | D26: 1 | F26: =SUM(D26:E26) -> 1 | G26: 3 | I26: =SUM(G26:H26) -> 3 | J26: 2 | L26: =SUM(J26:K26) -> 2 | O26: =SUM(M26:N26) -> 0 | R26: =SUM(P26:Q26) -> 0 | U26: =SUM(S26:T26) -> 0 | X26: =SUM(V26:W26) -> 0 | Y26: 10 | Z26: =+F26+I26+L26+O26+R26+U26+X26+Y26 -> 16 | AA26: 60 | AB26: 33 | AC26: =+AA26+AB26-Z26 -> 77 | AD26: 60 | AE26: =AC26+AD26 -> 137
B27: 1111011 | C27: ชิฟฟ่อนเค้กสอดไส้ นมชมพูฮอกไกโด (3 ชิ้น) | F27: =SUM(D27:E27) -> 0 | I27: =SUM(G27:H27) -> 0 | L27: =SUM(J27:K27) -> 0 | O27: =SUM(M27:N27) -> 0 | R27: =SUM(P27:Q27) -> 0 | U27: =SUM(S27:T27) -> 0 | X27: =SUM(V27:W27) -> 0 | Z27: =+F27+I27+L27+O27+R27+U27+X27+Y27 -> 0 | AC27: =+AA27+AB27-Z27 -> 0 | AE27: =AC27+AD27 -> 0
B28: 1111012 | C28: ชิฟฟ่อนเค้กสอดไส้ นมชมพูฮอกไกโด (6 ชิ้น) | F28: =SUM(D28:E28) -> 0 | I28: =SUM(G28:H28) -> 0 | L28: =SUM(J28:K28) -> 0 | O28: =SUM(M28:N28) -> 0 | R28: =SUM(P28:Q28) -> 0 | U28: =SUM(S28:T28) -> 0 | X28: =SUM(V28:W28) -> 0 | Z28: =+F28+I28+L28+O28+R28+U28+X28+Y28 -> 0 | AC28: =+AA28+AB28-Z28 -> 0 | AE28: =AC28+AD28 -> 0
B29: 1111013 | C29: ชิฟฟ่อนเค้กสอดไส้ ช็อคโกแลตนูเทลล่า (3 ชิ้น) | F29: =SUM(D29:E29) -> 0 | I29: =SUM(G29:H29) -> 0 | L29: =SUM(J29:K29) -> 0 | O29: =SUM(M29:N29) -> 0 | R29: =SUM(P29:Q29) -> 0 | U29: =SUM(S29:T29) -> 0 | X29: =SUM(V29:W29) -> 0 | Z29: =+F29+I29+L29+O29+R29+U29+X29+Y29 -> 0 | AC29: =+AA29+AB29-Z29 -> 0 | AE29: =AC29+AD29 -> 0
B30: 1111014 | C30: ชิฟฟ่อนเค้กสอดไส้ ช็อคโกแลตนูเทลล่า (6 ชิ้น) | F30: =SUM(D30:E30) -> 0 | I30: =SUM(G30:H30) -> 0 | L30: =SUM(J30:K30) -> 0 | O30: =SUM(M30:N30) -> 0 | R30: =SUM(P30:Q30) -> 0 | U30: =SUM(S30:T30) -> 0 | X30: =SUM(V30:W30) -> 0 | Z30: =+F30+I30+L30+O30+R30+U30+X30+Y30 -> 0 | AC30: =+AA30+AB30-Z30 -> 0 | AE30: =AC30+AD30 -> 0
B31: 1111015 | C31: ชิฟฟ่อนเค้กสอดไส้เนย รสมะพร้าว (3 ชิ้น) | F31: =SUM(D31:E31) -> 0 | I31: =SUM(G31:H31) -> 0 | L31: =SUM(J31:K31) -> 0 | O31: =SUM(M31:N31) -> 0 | R31: =SUM(P31:Q31) -> 0 | U31: =SUM(S31:T31) -> 0 | X31: =SUM(V31:W31) -> 0 | Z31: =+F31+I31+L31+O31+R31+U31+X31+Y31 -> 0 | AC31: =+AA31+AB31-Z31 -> 0 | AE31: =AC31+AD31 -> 0
B32: 1111016 | C32: ชิฟฟ่อนเค้กสอดไส้เนย รสมะพร้าว (6 ชิ้น) | F32: =SUM(D32:E32) -> 0 | I32: =SUM(G32:H32) -> 0 | L32: =SUM(J32:K32) -> 0 | O32: =SUM(M32:N32) -> 0 | R32: =SUM(P32:Q32) -> 0 | U32: =SUM(S32:T32) -> 0 | X32: =SUM(V32:W32) -> 0 | Z32: =+F32+I32+L32+O32+R32+U32+X32+Y32 -> 0 | AC32: =+AA32+AB32-Z32 -> 0 | AE32: =AC32+AD32 -> 0
B33: 1111017 | C33: ชิฟฟ่อนเค้กสอดไส้แยม รสบลูเบอร์รี่ (3 ชิ้น) | F33: =SUM(D33:E33) -> 0 | I33: =SUM(G33:H33) -> 0 | L33: =SUM(J33:K33) -> 0 | O33: =SUM(M33:N33) -> 0 | R33: =SUM(P33:Q33) -> 0 | U33: =SUM(S33:T33) -> 0 | X33: =SUM(V33:W33) -> 0 | Z33: =+F33+I33+L33+O33+R33+U33+X33+Y33 -> 0 | AC33: =+AA33+AB33-Z33 -> 0 | AE33: =AC33+AD33 -> 0
B34: 1111018 | C34: ชิฟฟ่อนเค้กสอดไส้แยม รสบลูเบอร์รี่ (6 ชิ้น) | F34: =SUM(D34:E34) -> 0 | I34: =SUM(G34:H34) -> 0 | L34: =SUM(J34:K34) -> 0 | O34: =SUM(M34:N34) -> 0 | R34: =SUM(P34:Q34) -> 0 | U34: =SUM(S34:T34) -> 0 | X34: =SUM(V34:W34) -> 0 | Z34: =+F34+I34+L34+O34+R34+U34+X34+Y34 -> 0 | AC34: =+AA34+AB34-Z34 -> 0 | AE34: =AC34+AD34 -> 0
B35: 1111019 | C35: ชิฟฟ่อนเค้กหน้าฝอยทอง สอดไส้แยมส้ม (3 ชิ้น) | F35: =SUM(D35:E35) -> 0 | I35: =SUM(G35:H35) -> 0 | L35: =SUM(J35:K35) -> 0 | O35: =SUM(M35:N35) -> 0 | R35: =SUM(P35:Q35) -> 0 | U35: =SUM(S35:T35) -> 0 | X35: =SUM(V35:W35) -> 0 | Z35: =+F35+I35+L35+O35+R35+U35+X35+Y35 -> 0 | AC35: =+AA35+AB35-Z35 -> 0 | AE35: =AC35+AD35 -> 0
B36: 1111020 | C36: ชิฟฟ่อนเค้กหน้าฝอยทอง สอดไส้แยมส้ม (6 ชิ้น) | F36: =SUM(D36:E36) -> 0 | I36: =SUM(G36:H36) -> 0 | L36: =SUM(J36:K36) -> 0 | O36: =SUM(M36:N36) -> 0 | R36: =SUM(P36:Q36) -> 0 | U36: =SUM(S36:T36) -> 0 | X36: =SUM(V36:W36) -> 0 | Y36: 5 | Z36: =+F36+I36+L36+O36+R36+U36+X36+Y36 -> 5 | AC36: =+AA36+AB36-Z36 -> -5 | AE36: =AC36+AD36 -> -5
B37: 1111022 | C37: ชิฟฟ่อนเค้กสอดไส้แยม รสสตรอว์เบอร์รี (3 ชิ้น) | F37: =SUM(D37:E37) -> 0 | I37: =SUM(G37:H37) -> 0 | L37: =SUM(J37:K37) -> 0 | O37: =SUM(M37:N37) -> 0 | R37: =SUM(P37:Q37) -> 0 | U37: =SUM(S37:T37) -> 0 | X37: =SUM(V37:W37) -> 0 | Z37: =+F37+I37+L37+O37+R37+U37+X37+Y37 -> 0 | AC37: =+AA37+AB37-Z37 -> 0 | AE37: =AC37+AD37 -> 0
B38: 1111023 | C38: ชิฟฟ่อนเค้กสอดไส้แยม รสสตรอว์เบอร์รี (6 ชิ้น) | F38: =SUM(D38:E38) -> 0 | I38: =SUM(G38:H38) -> 0 | L38: =SUM(J38:K38) -> 0 | O38: =SUM(M38:N38) -> 0 | R38: =SUM(P38:Q38) -> 0 | U38: =SUM(S38:T38) -> 0 | X38: =SUM(V38:W38) -> 0 | Z38: =+F38+I38+L38+O38+R38+U38+X38+Y38 -> 0 | AC38: =+AA38+AB38-Z38 -> 0 | AE38: =AC38+AD38 -> 0
B39: 1111024 | C39: ชิฟฟ่อนเค้กสอดไส้แยม รสส้ม (3 ชิ้น) | F39: =SUM(D39:E39) -> 0 | I39: =SUM(G39:H39) -> 0 | L39: =SUM(J39:K39) -> 0 | O39: =SUM(M39:N39) -> 0 | R39: =SUM(P39:Q39) -> 0 | U39: =SUM(S39:T39) -> 0 | X39: =SUM(V39:W39) -> 0 | Z39: =+F39+I39+L39+O39+R39+U39+X39+Y39 -> 0 | AC39: =+AA39+AB39-Z39 -> 0 | AE39: =AC39+AD39 -> 0
B40: 1111025 | C40: ชิฟฟ่อนเค้กสอดไส้แยม รสส้ม (6 ชิ้น) | F40: =SUM(D40:E40) -> 0 | I40: =SUM(G40:H40) -> 0 | L40: =SUM(J40:K40) -> 0 | O40: =SUM(M40:N40) -> 0 | R40: =SUM(P40:Q40) -> 0 | U40: =SUM(S40:T40) -> 0 | X40: =SUM(V40:W40) -> 0 | Z40: =+F40+I40+L40+O40+R40+U40+X40+Y40 -> 0 | AC40: =+AA40+AB40-Z40 -> 0 | AE40: =AC40+AD40 -> 0
...

Sheet 05.12.68
B1: ยอดจริง ออนไลน์ วันที่ 5/12/2568
B2: รหัสสินค้า | C2: สินค้า | D2: ปณ | G2: ชอปปี้ | J2: ลาซาด้า | M2: ติ๊กตอก | P2: ติ๊กตอก2 | S2: ติ๊กตอก3 | V2: ชอยส์ | Y2: ยอดเส้น | Z2: ยอดรวมผลิต(กล่อง) | AA2: ยอดForcast | AB2: ยอดStock | AC2: ยอดMemo | AD2: ยอดForcastวันพรุ่งนี้ | AE2: สินค้าที่ขายได้
D3: เช้า | E3: บ่าย | F3: รวม | G3: เช้า | H3: บ่าย | I3: รวม | J3: เช้า | K3: บ่าย | L3: รวม | M3: เช้า | N3: บ่าย | O3: รวม | P3: เช้า | Q3: บ่าย | R3: รวม | S3: เช้า | T3: บ่าย | U3: รวม | V3: เช้า | W3: บ่าย | X3: รวม
B4: 1004055 | C4: ชิฟฟ่อนเค้ก วรรณวนัช (รวมรส 4 ชิ้น) | D4: 8 | F4: =SUM(D4:E4) -> 8 | G4: 1 | I4: =SUM(G4:H4) -> 1 | L4: =SUM(J4:K4) -> 0 | M4: 469 | O4: =SUM(M4:N4) -> 469 | P4: 210 | R4: =SUM(P4:Q4) -> 210 | U4: =SUM(S4:T4) -> 0 | X4: =SUM(V4:W4) -> 0 | Y4: 11 | Z4: =+F4+I4+L4+O4+R4+U4+X4+Y4 -> 699 | AA4: 605 | AB4: 29 | AC4: =+AA4+AB4-Z4 -> -65 | AD4: 600 | AE4: =AC4+AD4 -> 535
B5: 1111002 | C5: ชิฟฟ่อนเค้ก วรรณวนัช (รวมรส 8 ชิ้น) | D5: 6 | F5: =SUM(D5:E5) -> 6 | I5: =SUM(G5:H5) -> 0 | J5: 15 | L5: =SUM(J5:K5) -> 15 | M5: 3 | O5: =SUM(M5:N5) -> 3 | P5: 1 | R5: =SUM(P5:Q5) -> 1 | U5: =SUM(S5:T5) -> 0 | X5: =SUM(V5:W5) -> 0 | Y5: 6 | Z5: =+F5+I5+L5+O5+R5+U5+X5+Y5 -> 31 | AA5: 160 | AB5: 88 | AC5: =+AA5+AB5-Z5 -> 217 | AD5: 150 | AE5: =AC5+AD5 -> 367
B6: 1111001 | C6: ชิฟฟ่อนแยกชิ้นไม่มีไส้ คละรส | F6: =SUM(D6:E6) -> 0 | I6: =SUM(G6:H6) -> 0 | L6: =SUM(J6:K6) -> 0 | O6: =SUM(M6:N6) -> 0 | R6: =SUM(P6:Q6) -> 0 | U6: =SUM(S6:T6) -> 0 | X6: =SUM(V6:W6) -> 0 | Z6: =+F6+I6+L6+O6+R6+U6+X6+Y6 -> 0 | AC6: =+AA6+AB6-Z6 -> 0 | AE6: =AC6+AD6 -> 0
B7: 1111084 | C7: ชิฟฟ่อนเค้ก รสกาแฟ (8 ชิ้น) | F7: =SUM(D7:E7) -> 0 | I7: =SUM(G7:H7) -> 0 | L7: =SUM(J7:K7) -> 0 | O7: =SUM(M7:N7) -> 0 | R7: =SUM(P7:Q7) -> 0 | U7: =SUM(S7:T7) -> 0 | X7: =SUM(V7:W7) -> 0 | Z7: =+F7+I7+L7+O7+R7+U7+X7+Y7 -> 0 | AC7: =+AA7+AB7-Z7 -> 0 | AE7: =AC7+AD7 -> 0
B8: 1111043 | C8: ชิฟฟอนรสมะลิ 8 ชิ้น ห่อ ซีน | F8: =SUM(D8:E8) -> 0 | I8: =SUM(G8:H8) -> 0 | L8: =SUM(J8:K8) -> 0 | O8: =SUM(M8:N8) -> 0 | R8: =SUM(P8:Q8) -> 0 | U8: =SUM(S8:T8) -> 0 | X8: =SUM(V8:W8) -> 0 | Z8: =+F8+I8+L8+O8+R8+U8+X8+Y8 -> 0 | AC8: =+AA8+AB8-Z8 -> 0 | AE8: =AC8+AD8 -> 0
B9: 1111057 | C9: ชิฟฟอนแยกชิ้น กาแฟ | F9: =SUM(D9:E9) -> 0 | G9: 12 | I9: =SUM(G9:H9) -> 12 | L9: =SUM(J9:K9) -> 0 | O9: =SUM(M9:N9) -> 0 | R9: =SUM(P9:Q9) -> 0 | U9: =SUM(S9:T9) -> 0 | X9: =SUM(V9:W9) -> 0 | Z9: =+F9+I9+L9+O9+R9+U9+X9+Y9 -> 12 | AC9: =+AA9+AB9-Z9 -> -12 | AE9: =AC9+AD9 -> -12
