Workbook

Sheet DATA POS
A1: รหัสสินค้า | B1: ชื่อสินค้า | C1: หมวดหมู่สินค้า | D1: หน่วยสินค้า | E1: ราคาขาย | F1: ราคาซื้อ | G1: Min | H1: Max | I1: หมายเหตุ | J1: สถานะ
B2: มะม่วงหนึบ | C2: หมวดอื่นๆ | D2: กล่อง | E2: 40.00 | F2: 0.00 | G2: 0 | H2: 0 | J2: ใช้งาน
A3: 0109256601 | B3: กระเช้าสำเร็จรูป | C3: หมวดอื่นๆ | D3: กระเช้า | E3: 800.00 | F3: 0.00 | G3: 0 | H3: 0 | J3: ใช้งาน
A4: 0109256602 | B4: เซ็ตของขวัญ | C4: หมวดอื่นๆ | D4: กล่อง | E4: 260.00 | F4: 0.00 | G4: 0 | H4: 0 | J4: ใช้งาน
A5: 01-SU-0025-1 | B5: น้ำแดงเฮลบลูบอย | C5: เครื่องดื่ม | D5: ขวด | E5: 58.00 | F5: 0.00 | G5: 0 | H5: 0 | J5: ใช้งาน
A6: 02102566 | B6: เปี๊ยะมินิ | C6: หมวดอื่นๆ | D6: กล่อง | E6: 25.00 | F6: 0.00 | G6: 0 | H6: 0 | J6: ใช้งาน
A7: 02-BB01 | B7: กล่องเค้กเบาหวิวทุเรียน 100g. New | C7: กล่องโมเดล | D7: กล่อง | E7: 20.00 | F7: 0.00 | G7: 0 | H7: 0 | J7: ใช้งาน
A8: 02-BB02 | B8: กล่องเค้กเบาหวิวเผือกมะพร้าวอ่อน 100g. New | C8: กล่องโมเดล | D8: กล่อง | E8: 20.00 | F8: 0.00 | G8: 0 | H8: 0 | J8: ใช้งาน
A9: 02-BB03 | B9: กล่องเค้กเบาหวิวกล้วยมะพร้าวเผา 100g. New | C9: กล่องโมเดล | D9: กล่อง | E9: 20.00 | F9: 0.00 | G9: 0 | H9: 0 | J9: ใช้งาน
A10: 02-BB05 | B10: กล่องเค้กเบาหวิวรสกาแฟ 100g New | C10: กล่องโมเดล | D10: กล่อง | E10: 20.00 | F10: 0.00 | G10: 0 | H10: 0 | J10: ใช้งาน
A11: 02-BB07 | B11: กล่องเค้กเบาหวิวรสกาแฟ 300g. New | C11: กล่องโมเดล | D11: กล่อง | E11: 20.00 | F11: 0.00 | G11: 0 | H11: 0 | J11: ใช้งาน
A12: 02-BB09 | B12: กล่องเค้กเบาหวิวรสเนยนม 110g. New | C12: กล่องโมเดล | D12: กล่อง | E12: 20.00 | F12: 0.00 | G12: 0 | H12: 0 | J12: ใช้งาน
A13: 02-BB11 | B13: กล่องเค้กเบาหวิวรสเนยนม 300g. New | C13: กล่องโมเดล | D13: กล่อง | E13: 20.00 | F13: 0.00 | G13: 0 | H13: 0 | J13: ใช้งาน
A14: 02-BB14 | B14: กล่องเค้กเบาหวิวรสใบเตย 300g. New | C14: กล่องโมเดล | D14: กล่อง | E14: 20.00 | F14: 0.00 | G14: 0 | H14: 0 | J14: ใช้งาน
... A76: 1113178 | B76: เค้กลอดช่องกล่องกลม 1 ปอนด์ 265 กรัม | C76: เค้ก | D76: กล่อง | E76: 0.00 | F76: 0.00 | G76: 0 | H76: 0 | J76: ใช้งาน
A77: 1113179 | B77: เค้กลอดช่องกล่องกลม 2 ปอนด์ 325 กรัม | C77: เค้ก | D77: กล่อง | E77: 240.00 | F77: 0.00 | G77: 0 | H77: 0 | I77: สินค้าระบายจากทางออนไลน์ ขาย 120 บาท | J77: ใช้งาน
A78: 1113185 | B78: ข้าวเกรียบว่าว (กระปุก) | C78: ขนมปัง แซนวิส | D78: กระปุก | E78: 40.00 | F78: 0.00 | G78: 0 | H78: 0 | J78: ใช้งาน
A79: 1113191 | B79: เค้กตะโก้เผือกหอม 120 กรัม | C79: เค้ก | D79: กล่อง | E79: 35.00 | F79: 0.00 | G79: 0 | H79: 0 | J79: ใช้งาน
A80: 1113192 | B80: ปังนุ่มมะพร้าว 100 กรัม | C80: ขนมปัง แซนวิส | D80: กล่อง | E80: 35.00 | F80: 0.00 | G80: 0 | H80: 0 | I80: บิ๊กซี | J80: ใช้งาน
A81: 1113193 | B81: ปังนุ่มชาไทย 100 กรัม | C81: ขนมปัง แซนวิส | D81: กล่อง | E81: 35.00 | F81: 0.00 | G81: 0 | H81: 0 | I81: บิ๊กซี | J81: ใช้งาน
A82: 1113194 | B82: บานอฟฟี่ 140 กรัม | C82: เค้ก | D82: กล่อง | E82: 45.00 | F82: 0.00 | G82: 0 | H82: 0 | I82: ราคาเต็ม 45 บาท , ราคาของระบาย 20 บาท | J82: ใช้งาน
A83: 1114024 | B83: สังขยา 1 ชิ้น | C83: ขนมปัง แซนวิส | D83: ชิ้น | E83: 10.00 | F83: 0.00 | G83: 0 | H83: 0 | J83: ใช้งาน
A84: 11140500 | B84: ขนมปังเลเยอร์ | C84: ขนมปัง แซนวิส | D84: ถุง | E84: 65.00 | F84: 0.00 | G84: 0 | H84: 0 | J84: ใช้งาน
A85: 1114056 | B85: ขนมปุยฝ้าย คละรส (4 ชิ้น) | C85: ขนมปัง แซนวิส | D85: กล่อง | E85: 50.00 | F85: 0.00 | G85: 0 | H85: 0 | J85: ใช้งาน
A86: 1114057 | B86: ขนมปุยฝ้าย สีชมพู (1 ปอนด์) | C86: ขนมปัง แซนวิส | D86: กล่อง | E86: 60.00 | F86: 0.00 | G86: 0 | H86: 0 | J86: ใช้งาน
A87: 1114058 | B87: ขนมปุยฝ้าย สีชมพู (4 ชิ้น) | C87: ขนมปัง แซนวิส | D87: กล่อง | E87: 50.00 | F87: 0.00 | G87: 0 | H87: 0 | J87: ใช้งาน
A88: 1114059 | B88: ขนมปุยฝ้าย สีขาว (1 ปอนด์) | C88: ขนมปัง แซนวิส | D88: กล่อง | E88: 60.00 | F88: 0.00 | G88: 0 | H88: 0 | J88: ใช้งาน
A89: 1114060 | B89: ขนมปุยฝ้าย สีขาว (4 ชิ้น) | C89: ขนมปัง แซนวิส | D89: กล่อง | E89: 50.00 | F89: 0.00 | G89: 0 | H89: 0 | J89: ใช้งาน
A90: 1124024 | B90: ขนมปังไส้ฝอยทอง (ชิ้น) | C90: ขนมปัง แซนวิส | D90: ชิ้น | E90: 30.00 | F90: 0.00 | G90: 0 | H90: 0 | J90: ใช้งาน
A91: 1124037 | B91: ขนมปังไส้พริกเผาไก่หยอง (ชิ้น) | C91: ขนมปัง แซนวิส | D91: ชิ้น | E91: 30.00 | F91: 0.00 | G91: 0 | H91: 0 | J91: ใช้งาน
A92: 1124038 | B92: ขนมปังไส้แยมบลูเบอร์รี่ (ชิ้น) | C92: ขนมปัง แซนวิส | D92: ชิ้น | E92: 30.00 | F92: 0.00 | G92: 0 | H92: 0 | J92: ใช้งาน
A93: 1124039 | B93: ขนมปังไส้แยมสตรอเบอร์รี่ (ชิ้น) | C93: ขนมปัง แซนวิส | D93: ชิ้น | E93: 30.00 | F93: 0.00 | G93: 0 | H93: 0 | J93: ใช้งาน
A94: 1124040 | B94: ขนมปังไส้ลูกเกดฝอยทอง (ชิ้น) | C94: ขนมปัง แซนวิส | D94: ชิ้น | E94: 30.00 | F94: 0.00 | G94: 0 | H94: 0 | J94: ใช้งาน
... A96: 1200032 | B96: (NP)มาม่อนคัฟ รวมรส (6ชิ้น) | C96: หนองพงนก | D96: กล่อง | E96: 80.00 | F96: 0.00 | G96: 0 | H96: 0 | J96: ใช้งาน
A97: 1200092 | B97: ท๊อฟฟี่ถั่ว (กิโล) | D97: กิโลกรัม | E97: 200.00 | F97: 0.00 | G97: 0 | H97: 0 | J97: ใช้งาน
A98: 1300005 | B98: เค้กมะพร้าวลาวา 85 กรัม | C98: เค้ก | D98: กล่อง | E98: 35.00 | F98: 0.00 | G98: 0 | H98: 0 | J98: ใช้งาน
A99: 1300006 | B99: แซนด์วิช แฮมไข่ดาว | C99: ขนมปัง แซนวิส | D99: กล่อง | E99: 35.00 | F99: 0.00 | G99: 0 | H99: 0 | J99: ใช้งาน
A100: 13082000 | B100: หนังสือนิทาน วาดภาพ | C100: รพ.สินแพทย์ | D100: ชิ้น | E100: 20.00 | F100: 0.00 | G100: 0 | H100: 0 | J100: ใช้งาน
A101: 13082001 | B101: ห้องครัว | C101: รพ.สินแพทย์ | D101: กล่อง | E101: 450.00 | F101: 0.00 | G101: 0 | H101: 0 | J101: ใช้งาน
A102: 13082002 | B102: ฮีโร่แผง 150 | C102: รพ.สินแพทย์ | D102: ชิ้น | E102: 150.00 | F102: 0.00 | G102: 0 | H102: 0 | J102: ใช้งาน
...

Sheet ต้นทุนพี่ตุ๊ก
A1: รหัสสินค้า | B1: ชื่อสินค้า | C1: ราคาต้นทุน
A2: 1111001 | B2: ชิฟฟ่อนเค้ก 1 ชิ้น
A3: 1111010 | B3: ชิฟฟ่อนเค้กสอดไส้แยม 1 ชิ้น
A4: 1112539 | B4: ชิฟฟ่อนเค้กสอดไส้ เมล่อน (3 ชิ้น)
A5: 20055116 | B5: ชิฟฟ่อนเค้กสอดไส้ครีมมะพร้าว 120g.
A6: 20055119 | B6: ชิฟฟ่อนเค้กฝอยทอง 95g.
A7: 1124027 | B7: ครีมฮอร์นใบเตย จัมโบ้ 65g.
A8: 1124029 | B8: ครีมฮอร์นชาไทย จัมโบ้ 65g.
A9: 20055115 | B9: ครีมฮอร์นคิทแคท 70g.
A10: 1200019 | B10: NP เค้กโบราณครีม 6 ชิ้น
A11: 1200020 | B11: NP เเค้กโบราณผลไม้ 6 ชิ้น
A12: 5002400 | B12: เค้กลาวา ฝอยทอง เล็ก
A13: 1113011 | B13: เค้กลาวา ฝอยทอง ใหญ่
A14: 1113010 | B14: เค้กลาวา ฝอยทองทูโทน ใหญ่
A15: 20054637 | B15: เอแคลร์คิทแคท 55g.
A16: 20056257 | B16: เอแคลร์ชาไทย 125g.
A17: 20054638 | B17: เครปเค้กคิทแคท 65g.
A18: 1113194 | B18: บานอฟฟี่ 140 กรัม
A19: 1006979 | B19: คัพเค้กไส้คัสตาร์ด
A20: 1300005 | B20: เค้กมะพร้าวลาวา 85 กรัม
A21: 1113157 | B21: เค้กลอดช่อง 85 กรัม
A22: 1113178 | B22: เค้กลอดช่องกล่องกลม 1 ปอนด์ 265 กรัม
A23: 1113179 | B23: เค้กลอดช่องกล่องกลม 2 ปอนด์ 325 กรัม
A24: 20053053 | B24: เค้กทุเรียน 90 กรัม
A25: 20055951 | B25: เค้กบัวลอยมะพร้าวอ่อน 100 กรัม
A26: 1113004 | B26: เค้กสามเหลี่ยม รสฝอยทองใบเตย
A27: 1111410 | B27: เค้กวันเกิดมะพร้าวอ่อน 1/2 ปอนด์
A28: 1111406 | B28: เค้กวันเกิดมะพร้าวอ่อน 1 ปอนด์
A29: 1111410 | B29: เค้กวันเกิด 1/2 ปอนด์ ธรรมดา
A30: 1113114 | B30: เค้กวันเกิด 1 ปอนด์ ธรรมดา
A31: 1200003 | B31: ท๊อฟฟี่ถั่ว (กระเช้า)
A32: 1200002 | B32: ท๊อฟฟี่ถั่ว (กล่อง)
A33: 1200001 | B33: คอนเฟลกคาราเมล (เล็ก)
A34: 1006002 | B34: วุ้นฝอยทอง (N)
A35: 25661201 | B35: วุ้นแฟนซี (N)
A36: 1113192 | B36: ปังนุ่มมะพร้าว 100 กรัม
A37: 1113193 | B37: ปังนุ่มชาไทย 100 กรัม
A38: 1113084 | B38: ขนมปังเนยนิ่ม (2 ชิ้น)
A39: 1124002 | B39: ขนมปังสังขยาใบเตยนมสด 4 ชิ้น
A40: 1113110 | B40: ขนมปังไก่หยองน้ำสลัด
...

Sheet สรุป
A2: บูธ EVENT งานเกษตรแฟร์กำแพงแสน 30 พ.ย. 67 - 10 ธ.ค. 67 | Q2: บูธ EVENT งานเกษตรแฟร์กำแพงแสน 30 พ.ย. 67 - 10 ธ.ค. 67
A3: ลำดับ | B3: รหัสสินค้า (POS) | C3: รายการ | D3: หน่วย | E3: ยกมา | F3: รับ | G3: รวม | H3: เปลี่ยน/ | I3: โยกย้าย / ระบาย | J3: คงเหลือ | K3: รายการขาย | N3: หมายเหตุ | O3: ราคาต้นทุน | P3: ยอดรวมต้นทุนสินค้า | Q3: วันที่ | R3: ยอดเงิน | S3: ส่วนลด | T3: สแกนใช้สิทธิ์ | U3: ค่าโอนเงิน | V3: ค่าใช้จ่ายอื่นๆ | W3: โอนหน้าร้าน | X3: รับสุทธิ | Y3: ยอดเงินสด | Z3: โอนเกิน/โอนขาด | AA3: วัน | AB3: รวมยอดขายหลังหักค่าใช้จ่าย
H4: คืน/เสีย | K4: จำนวน | L4: @ | M4: เป็นเงิน
A5: 1 | B5: 1004055 | C5: ชิฟฟ่อนเค้ก รวมรส (4 ชิ้น) | D5: กล่อง | F5: =+ยกมา!F5+'29'!F5+'30'!F5+'1'!F5+'2'!F5+'3'!F5+'4'!F5+'5'!F5+'6'!F5+'7'!F5+'8'!F5+'9'!F5+'10'!F5 -> 210 | G5: =+E5+F5 -> 210 | H5: =+ยกมา!H5+'29'!H5+'30'!H5+'1'!H5+'2'!H5+'3'!H5+'4'!H5+'5'!H5+'6'!H5+'7'!H5+'8'!H5+'9'!H5+'10'!H5 -> 0 | I5: =+ยกมา!I5+'29'!I5+'30'!I5+'1'!I5+'2'!I5+'3'!I5+'4'!I5+'5'!I5+'6'!I5+'7'!I5+'8'!I5+'9'!I5+'10'!I5 -> 0 | J5: =E5+F5-H5-K5-I5 -> 1 | K5: =ยกมา!K5+'29'!K5+'30'!K5+'1'!K5+'2'!K5+'3'!K5+'4'!K5+'5'!K5+'6'!K5+'7'!K5+'8'!K5+'9'!K5+'10'!K5 -> 209 | L5: 50 | M5: =ยกมา!M5+'29'!M5+'30'!M5+'1'!M5+'2'!M5+'3'!M5+'4'!M5+'5'!M5+'6'!M5+'7'!M5+'8'!M5+'9'!M5+'10'!M5 -> 10450 | O5: 18.97 | P5: =+K5*O5 -> 3964.73 | Q5: 29 | R5: =+'29'!N68 -> 12138 | S5: =+'29'!N73 -> 70 | T5: =+'29'!N71 -> 0 | U5: =+'29'!N69 -> 0 | V5: =+'29'!N72 -> 0 | W5: =+'29'!N70 -> 4434 | X5: =R5-S5-T5-U5-V5-W5 -> 7634 | Y5: =+'29'!N75 -> 7539 | Z5: =+Y5-X5 -> -95 | AA5: เสาร์ | AB5: =+W5+Y5 -> 11973 | AC5: =+W5+Y5+Z5 -> 11878
A6: 2 | B6: 1111002 | C6: ชิฟฟ่อนเค้ก รวมรส (8 ชิ้น) | D6: กล่อง | F6: =+ยกมา!F6+'29'!F6+'30'!F6+'1'!F6+'2'!F6+'3'!F6+'4'!F6+'5'!F6+'6'!F6+'7'!F6+'8'!F6+'9'!F6+'10'!F6 -> 403 | G6: =+E6+F6 -> 403 | H6: =+ยกมา!H6+'29'!H6+'30'!H6+'1'!H6+'2'!H6+'3'!H6+'4'!H6+'5'!H6+'6'!H6+'7'!H6+'8'!H6+'9'!H6+'10'!H6 -> 0 | I6: =+ยกมา!I6+'29'!I6+'30'!I6+'1'!I6+'2'!I6+'3'!I6+'4'!I6+'5'!I6+'6'!I6+'7'!I6+'8'!I6+'9'!I6+'10'!I6 -> 0 | J6: =E6+F6-H6-K6-I6 -> 23 | K6: =ยกมา!K6+'29'!K6+'30'!K6+'1'!K6+'2'!K6+'3'!K6+'4'!K6+'5'!K6+'6'!K6+'7'!K6+'8'!K6+'9'!K6+'10'!K6 -> 380 | L6: 100 | M6: =ยกมา!M6+'29'!M6+'30'!M6+'1'!M6+'2'!M6+'3'!M6+'4'!M6+'5'!M6+'6'!M6+'7'!M6+'8'!M6+'9'!M6+'10'!M6 -> 38000 | O6: 36.43 | P6: =+K6*O6 -> 13843.4 | Q6: 30 | R6: =+'30'!N68 -> 17420 | S6: =+'30'!N73 -> 60 | T6: =+'30'!N71 -> 0 | U6: =+'30'!N69 -> 0 | V6: =+'30'!N72 -> 1190 | W6: =+'30'!N70 -> 8076 | X6: =R6-S6-T6-U6-V6-W6 -> 8094 | Y6: =+'30'!N75 -> 9393 | Z6: =+Y6-X6 -> 1299 | AA6: อาทิตย์ | AB6: =+W6+Y6 -> 17469 | AC6: =+W6+Y6+Z6 -> 18768
A7: 3 | B7: 1111008 | C7: ชิฟฟ่อนเค้ก รวมรส (3 ชิ้น) | D7: กล่อง | F7: =+ยกมา!F7+'29'!F7+'30'!F7+'1'!F7+'2'!F7+'3'!F7+'4'!F7+'5'!F7+'6'!F7+'7'!F7+'8'!F7+'9'!F7+'10'!F7 -> 150 | G7: =+E7+F7 -> 150 | H7: =+ยกมา!H7+'29'!H7+'30'!H7+'1'!H7+'2'!H7+'3'!H7+'4'!H7+'5'!H7+'6'!H7+'7'!H7+'8'!H7+'9'!H7+'10'!H7 -> 0 | I7: =+ยกมา!I7+'29'!I7+'30'!I7+'1'!I7+'2'!I7+'3'!I7+'4'!I7+'5'!I7+'6'!I7+'7'!I7+'8'!I7+'9'!I7+'10'!I7 -> 0 | J7: =E7+F7-H7-K7-I7 -> 31 | K7: =ยกมา!K7+'29'!K7+'30'!K7+'1'!K7+'2'!K7+'3'!K7+'4'!K7+'5'!K7+'6'!K7+'7'!K7+'8'!K7+'9'!K7+'10'!K7 -> 119 | L7: 50 | M7: =ยกมา!M7+'29'!M7+'30'!M7+'1'!M7+'2'!M7+'3'!M7+'4'!M7+'5'!M7+'6'!M7+'7'!M7+'8'!M7+'9'!M7+'10'!M7 -> 5950 | O7: 19.36 | P7: =+K7*O7 -> 2303.84 | Q7: 1 | R7: =+'1'!N68 -> 18897 | S7: =+'1'!N73 -> 456 | T7: =+'1'!N71 -> 0 | U7: =+'30'!N69 -> 0 | V7: =+'1'!N72 -> 0 | W7: =+'1'!N70 -> 9424 | X7: =R7-S7-T7-U7-V7-W7 -> 9017 | Y7: =+'1'!N75 -> 9017 | Z7: =+Y7-X7 -> 0 | AA7: จันทร์ | AB7: =+W7+Y7 -> 18441 | AC7: =+W7+Y7+Z7 -> 18441
A8: 4 | B8: 1111004 | C8: ชิฟฟ่อน สอดไส้ (ล) 4 ชิ้น ครีมมะพร้าว | D8: กล่อง | F8: =+ยกมา!F8+'29'!F8+'30'!F8+'1'!F8+'2'!F8+'3'!F8+'4'!F8+'5'!F8+'6'!F8+'7'!F8+'8'!F8+'9'!F8+'10'!F8 -> 35 | G8: =+E8+F8 -> 35 | H8: =+ยกมา!H8+'29'!H8+'30'!H8+'1'!H8+'2'!H8+'3'!H8+'4'!H8+'5'!H8+'6'!H8+'7'!H8+'8'!H8+'9'!H8+'10'!H8 -> 0 | I8: =+ยกมา!I8+'29'!I8+'30'!I8+'1'!I8+'2'!I8+'3'!I8+'4'!I8+'5'!I8+'6'!I8+'7'!I8+'8'!I8+'9'!I8+'10'!I8 -> 0 | J8: =E8+F8-H8-K8-I8 -> 0 | K8: =ยกมา!K8+'29'!K8+'30'!K8+'1'!K8+'2'!K8+'3'!K8+'4'!K8+'5'!K8+'6'!K8+'7'!K8+'8'!K8+'9'!K8+'10'!K8 -> 35 | L8: 65 | M8: =ยกมา!M8+'29'!M8+'30'!M8+'1'!M8+'2'!M8+'3'!M8+'4'!M8+'5'!M8+'6'!M8+'7'!M8+'8'!M8+'9'!M8+'10'!M8 -> 2275 | O8: 22.25 | P8: =+K8*O8 -> 778.75 | Q8: 2 | R8: =+'2'!N68 -> 18081 | S8: =+'2'!N73 -> 546 | T8: =+'2'!N71 -> 0 | U8: =+'2'!N69 -> 0 | V8: =+'2'!N72 -> 2830 | W8: =+'2'!N70 -> 3989 | X8: =R8-S8-T8-U8-V8-W8 -> 10716 | Y8: =+'2'!N75 -> 10675 | Z8: =+Y8-X8 -> -41 | AA8: อังคาร | AB8: =+W8+Y8 -> 14664 | AC8: =+W8+Y8+Z8 -> 14623
A9: 5 | B9: 1111005 | C9: ชิฟฟ่อน สอดไส้ (ล) 5 ชิ้น ครีมมะพร้าว | D9: กล่อง | F9: =+ยกมา!F9+'29'!F9+'30'!F9+'1'!F9+'2'!F9+'3'!F9+'4'!F9+'5'!F9+'6'!F9+'7'!F9+'8'!F9+'9'!F9+'10'!F9 -> 30 | G9: =+E9+F9 -> 30 | H9: =+ยกมา!H9+'29'!H9+'30'!H9+'1'!H9+'2'!H9+'3'!H9+'4'!H9+'5'!H9+'6'!H9+'7'!H9+'8'!H9+'9'!H9+'10'!H9 -> 0 | I9: =+ยกมา!I9+'29'!I9+'30'!I9+'1'!I9+'2'!I9+'3'!I9+'4'!I9+'5'!I9+'6'!I9+'7'!I9+'8'!I9+'9'!I9+'10'!I9 -> 0 | J9: =E9+F9-H9-K9-I9 -> 0 | K9: =ยกมา!K9+'29'!K9+'30'!K9+'1'!K9+'2'!K9+'3'!K9+'4'!K9+'5'!K9+'6'!K9+'7'!K9+'8'!K9+'9'!K9+'10'!K9 -> 30 | L9: 85 | M9: =ยกมา!M9+'29'!M9+'30'!M9+'1'!M9+'2'!M9+'3'!M9+'4'!M9+'5'!M9+'6'!M9+'7'!M9+'8'!M9+'9'!M9+'10'!M9 -> 2550 | O9: 22.65 | P9: =+K9*O9 -> 679.5 | Q9: 3 | R9: =+'3'!N68 -> 12897 | S9: =+'3'!N73 -> 422 | T9: =+'3'!N71 -> 0 | U9: =+'3'!N69 -> 15 | V9: =+'3'!N72 -> 1400 | W9: =+'3'!N70 -> 4579 | X9: =R9-S9-T9-U9-V9-W9 -> 6481 | Y9: =+'3'!N75 -> 6421 | Z9: =+Y9-X9 -> -60 | AA9: พุธ | AB9: =+W9+Y9 -> 11000 | AC9: =+W9+Y9+Z9 -> 10940
A10: 6 | B10: 1111009 | C10: ชิฟฟ่อนเค้ก รวมรส (6 ชิ้น) | D10: กล่อง | F10: =+ยกมา!F10+'29'!F10+'30'!F10+'1'!F10+'2'!F10+'3'!F10+'4'!F10+'5'!F10+'6'!F10+'7'!F10+'8'!F10+'9'!F10+'10'!F10 -> 270 | G10: =+E10+F10 -> 270 | H10: =+ยกมา!H10+'29'!H10+'30'!H10+'1'!H10+'2'!H10+'3'!H10+'4'!H10+'5'!H10+'6'!H10+'7'!H10+'8'!H10+'9'!H10+'10'!H10 -> 0 | I10: =+ยกมา!I10+'29'!I10+'30'!I10+'1'!I10+'2'!I10+'3'!I10+'4'!I10+'5'!I10+'6'!I10+'7'!I10+'8'!I10+'9'!I10+'10'!I10 -> 0 | J10: =E10+F10-H10-K10-I10 -> 14 | K10: =ยกมา!K10+'29'!K10+'30'!K10+'1'!K10+'2'!K10+'3'!K10+'4'!K10+'5'!K10+'6'!K10+'7'!K10+'8'!K10+'9'!K10+'10'!K10 -> 256 | L10: 100 | M10: =ยกมา!M10+'29'!M10+'30'!M10+'1'!M10+'2'!M10+'3'!M10+'4'!M10+'5'!M10+'6'!M10+'7'!M10+'8'!M10+'9'!M10+'10'!M10 -> 25600 | O10: 27.98 | P10: =+K10*O10 -> 7162.88 | Q10: 4 | R10: =+'4'!N68 -> 15627 | S10: =+'4'!N73 -> 289 | T10: =+'4'!N71 -> 0 | U10: =+'4'!N69 -> 15 | V10: =+'4'!N72 -> 1400 | W10: =+'4'!N70 -> 6772 | X10: =R10-S10-T10-U10-V10-W10 -> 7151 | Y10: =+'4'!N75 -> 7019 | Z10: =+Y10-X10 -> -132 | AA10: พฤหัสบดี | AB10: =+W10+Y10 -> 13791 | AC10: =+W10+Y10+Z10 -> 13659
A11: 7 | B11: 1111056 | C11: ชิฟฟ่อนรวมรส ยอดฮิต (8 ชิ้น) | D11: กล่อง | F11: =+ยกมา!F11+'29'!F11+'30'!F11+'1'!F11+'2'!F11+'3'!F11+'4'!F11+'5'!F11+'6'!F11+'7'!F11+'8'!F11+'9'!F11+'10'!F11 -> 300 | G11: =+E11+F11 -> 300 | H11: =+ยกมา!H11+'29'!H11+'30'!H11+'1'!H11+'2'!H11+'3'!H11+'4'!H11+'5'!H11+'6'!H11+'7'!H11+'8'!H11+'9'!H11+'10'!H11 -> 0 | I11: =+ยกมา!I11+'29'!I11+'30'!I11+'1'!I11+'2'!I11+'3'!I11+'4'!I11+'5'!I11+'6'!I11+'7'!I11+'8'!I11+'9'!I11+'10'!I11 -> 0 | J11: =E11+F11-H11-K11-I11 -> 37 | K11: =ยกมา!K11+'29'!K11+'30'!K11+'1'!K11+'2'!K11+'3'!K11+'4'!K11+'5'!K11+'6'!K11+'7'!K11+'8'!K11+'9'!K11+'10'!K11 -> 263 | L11: 100 | M11: =ยกมา!M11+'29'!M11+'30'!M11+'1'!M11+'2'!M11+'3'!M11+'4'!M11+'5'!M11+'6'!M11+'7'!M11+'8'!M11+'9'!M11+'10'!M11 -> 26300 | O11: 34.64 | P11: =+K11*O11 -> 9110.32 | Q11: 5 | R11: =+'5'!N68 -> 31734 | S11: =+'5'!N73 -> 823 | T11: =+'5'!N71 -> 0 | U11: =+'5'!N69 -> 15 | V11: =+'5'!N72 -> 1428 | W11: =+'5'!N70 -> 9969 | X11: =R11-S11-T11-U11-V11-W11 -> 19499 | Y11: =+'5'!N75 -> 19499 | Z11: =+Y11-X11 -> 0 | AA11: ศุกร์ | AB11: =+W11+Y11 -> 29468 | AC11: =+W11+Y11+Z11 -> 29468
A12: 8 | B12: 1111006 | C12: ชิฟฟ่อนเค้ก วรรณวนัช (สอดไส้รวมรส 8 ชิ้น) | D12: กล่อง | F12: =+ยกมา!F12+'29'!F12+'30'!F12+'1'!F12+'2'!F12+'3'!F12+'4'!F12+'5'!F12+'6'!F12+'7'!F12+'8'!F12+'9'!F12+'10'!F12 -> 68 | G12: =+E12+F12 -> 68 | H12: =+ยกมา!H12+'29'!H12+'30'!H12+'1'!H12+'2'!H12+'3'!H12+'4'!H12+'5'!H12+'6'!H12+'7'!H12+'8'!H12+'9'!H12+'10'!H12 -> 0 | I12: =+ยกมา!I12+'29'!I12+'30'!I12+'1'!I12+'2'!I12+'3'!I12+'4'!I12+'5'!I12+'6'!I12+'7'!I12+'8'!I12+'9'!I12+'10'!I12 -> 0 | J12: =E12+F12-H12-K12-I12 -> 0 | K12: =ยกมา!K12+'29'!K12+'30'!K12+'1'!K12+'2'!K12+'3'!K12+'4'!K12+'5'!K12+'6'!K12+'7'!K12+'8'!K12+'9'!K12+'10'!K12 -> 68 | L12: 130 | M12: =ยกมา!M12+'29'!M12+'30'!M12+'1'!M12+'2'!M12+'3'!M12+'4'!M12+'5'!M12+'6'!M12+'7'!M12+'8'!M12+'9'!M12+'10'!M12 -> 8840 | O12: 46.37 | P12: =+K12*O12 -> 3153.16 | Q12: 6 | R12: =+'6'!N68 -> 24197 | S12: =+'6'!N73 -> 397 | T12: =+'6'!N71 -> 0 | U12: =+'6'!N69 -> 15 | V12: =+'6'!N72 -> 1400 | W12: =+'6'!N70 -> 8778 | X12: =R12-S12-T12-U12-V12-W12 -> 13607 | Y12: =+'6'!N75 -> 13607 | Z12: =+Y12-X12 -> 0 | AA12: เสาร์ | AB12: =+W12+Y12 -> 22385 | AC12: =+W12+Y12+Z12 -> 22385
A13: 9 | B13: 1111035 | C13: ชิฟฟ่อนเค้กมะพร้าวสอดไส้ครีมมะพร้าวล้วน (8 ชิ้น) | D13: กล่อง | F13: =+ยกมา!F13+'29'!F13+'30'!F13+'1'!F13+'2'!F13+'3'!F13+'4'!F13+'5'!F13+'6'!F13+'7'!F13+'8'!F13+'9'!F13+'10'!F13 -> 5 | G13: =+E13+F13 -> 5 | H13: =+ยกมา!H13+'29'!H13+'30'!H13+'1'!H13+'2'!H13+'3'!H13+'4'!H13+'5'!H13+'6'!H13+'7'!H13+'8'!H13+'9'!H13+'10'!H13 -> 0 | I13: =+ยกมา!I13+'29'!I13+'30'!I13+'1'!I13+'2'!I13+'3'!I13+'4'!I13+'5'!I13+'6'!I13+'7'!I13+'8'!I13+'9'!I13+'10'!I13 -> 0 | J13: =E13+F13-H13-K13-I13 -> 0 | K13: =ยกมา!K13+'29'!K13+'30'!K13+'1'!K13+'2'!K13+'3'!K13+'4'!K13+'5'!K13+'6'!K13+'7'!K13+'8'!K13+'9'!K13+'10'!K13 -> 5 | L13: 130 | M13: =ยกมา!M13+'29'!M13+'30'!M13+'1'!M13+'2'!M13+'3'!M13+'4'!M13+'5'!M13+'6'!M13+'7'!M13+'8'!M13+'9'!M13+'10'!M13 -> 650 | O13: 38.9 | P13: =+K13*O13 -> 194.5 | Q13: 7 | R13: =+'7'!N68 -> 19601 | S13: =+'7'!N73 -> 330 | T13: =+'7'!N71 -> 0 | U13: =+'7'!N69 -> 15 | V13: =+'7'!N72 -> 700 | W13: =+'7'!N70 -> 7657 | X13: =R13-S13-T13-U13-V13-W13 -> 10899 | Y13: =+'7'!N75 -> 10899 | Z13: =+Y13-X13 -> 0 | AA13: อาทิตย์ | AB13: =+W13+Y13 -> 18556 | AC13: =+W13+Y13+Z13 -> 18556
A14: 10 | B14: 1004080 | C14: ครีมฮอร์น วนิลา | D14: กล่อง | F14: =+ยกมา!F14+'29'!F14+'30'!F14+'1'!F14+'2'!F14+'3'!F14+'4'!F14+'5'!F14+'6'!F14+'7'!F14+'8'!F14+'9'!F14+'10'!F14 -> 70 | G14: =+E14+F14 -> 70 | H14: =+ยกมา!H14+'29'!H14+'30'!H14+'1'!H14+'2'!H14+'3'!H14+'4'!H14+'5'!H14+'6'!H14+'7'!H14+'8'!H14+'9'!H14+'10'!H14 -> 0 | I14: =+ยกมา!I14+'29'!I14+'30'!I14+'1'!I14+'2'!I14+'3'!I14+'4'!I14+'5'!I14+'6'!I14+'7'!I14+'8'!I14+'9'!I14+'10'!I14 -> 0 | J14: =E14+F14-H14-K14-I14 -> 0 | K14: =ยกมา!K14+'29'!K14+'30'!K14+'1'!K14+'2'!K14+'3'!K14+'4'!K14+'5'!K14+'6'!K14+'7'!K14+'8'!K14+'9'!K14+'10'!K14 -> 70 | L14: 50 | M14: =ยกมา!M14+'29'!M14+'30'!M14+'1'!M14+'2'!M14+'3'!M14+'4'!M14+'5'!M14+'6'!M14+'7'!M14+'8'!M14+'9'!M14+'10'!M14 -> 3500 | O14: 27.84 | P14: =+K14*O14 -> 1948.8 | Q14: 8 | R14: =+'8'!N68 -> 9495 | S14: =+'8'!N73 -> 44 | T14: =+'8'!N71 -> 0 | U14: =+'8'!N69 -> 15 | V14: =+'8'!N72 -> 5906 | W14: =+'8'!N70 -> 2485 | X14: =R14-S14-T14-U14-V14-W14 -> 1045 | Y14: =+'8'!N75 -> 1045 | Z14: =+Y14-X14 -> 0 | AA14: จันทร์ | AB14: =+W14+Y14 -> 3530 | AC14: =+W14+Y14+Z14 -> 3530
A15: 11 | B15: 1004081 | C15: ครีมฮอร์น ใบเตย | D15: กล่อง | F15: =+ยกมา!F15+'29'!F15+'30'!F15+'1'!F15+'2'!F15+'3'!F15+'4'!F15+'5'!F15+'6'!F15+'7'!F15+'8'!F15+'9'!F15+'10'!F15 -> 45 | G15: =+E15+F15 -> 45 | H15: =+ยกมา!H15+'29'!H15+'30'!H15+'1'!H15+'2'!H15+'3'!H15+'4'!H15+'5'!H15+'6'!H15+'7'!H15+'8'!H15+'9'!H15+'10'!H15 -> 0 | I15: =+ยกมา!I15+'29'!I15+'30'!I15+'1'!I15+'2'!I15+'3'!I15+'4'!I15+'5'!I15+'6'!I15+'7'!I15+'8'!I15+'9'!I15+'10'!I15 -> 0 | J15: =E15+F15-H15-K15-I15 -> 0 | K15: =ยกมา!K15+'29'!K15+'30'!K15+'1'!K15+'2'!K15+'3'!K15+'4'!K15+'5'!K15+'6'!K15+'7'!K15+'8'!K15+'9'!K15+'10'!K15 -> 45 | L15: 50 | M15: =ยกมา!M15+'29'!M15+'30'!M15+'1'!M15+'2'!M15+'3'!M15+'4'!M15+'5'!M15+'6'!M15+'7'!M15+'8'!M15+'9'!M15+'10'!M15 -> 2250 | O15: 27.12 | P15: =+K15*O15 -> 1220.4 | Q15: 9 | R15: =+'9'!N68 -> 14879 | S15: =+'9'!N73 -> 728 | T15: =+'9'!N71 -> 0 | U15: =+'9'!N69 -> 15 | V15: =+'9'!N72 -> 1400 | W15: =+'9'!N70 -> 5522 | X15: =R15-S15-T15-U15-V15-W15 -> 7214 | Y15: =+'9'!N75 -> 7214 | Z15: =+Y15-X15 -> 0 | AA15: อังคาร | AB15: =+W15+Y15 -> 12736 | AC15: =+W15+Y15+Z15 -> 12736
A16: 12 | B16: 3001200 | C16: ครีมฮอร์น ช็อคโกแลต | D16: กล่อง | F16: =+ยกมา!F16+'29'!F16+'30'!F16+'1'!F16+'2'!F16+'3'!F16+'4'!F16+'5'!F16+'6'!F16+'7'!F16+'8'!F16+'9'!F16+'10'!F16 -> 44 | G16: =+E16+F16 -> 44 | H16: =+ยกมา!H16+'29'!H16+'30'!H16+'1'!H16+'2'!H16+'3'!H16+'4'!H16+'5'!H16+'6'!H16+'7'!H16+'8'!H16+'9'!H16+'10'!H16 -> 0 | I16: =+ยกมา!I16+'29'!I16+'30'!I16+'1'!I16+'2'!I16+'3'!I16+'4'!I16+'5'!I16+'6'!I16+'7'!I16+'8'!I16+'9'!I16+'10'!I16 -> 0 | J16: =E16+F16-H16-K16-I16 -> 0 | K16: =ยกมา!K16+'29'!K16+'30'!K16+'1'!K16+'2'!K16+'3'!K16+'4'!K16+'5'!K16+'6'!K16+'7'!K16+'8'!K16+'9'!K16+'10'!K16 -> 44 | L16: 50 | M16: =ยกมา!M16+'29'!M16+'30'!M16+'1'!M16+'2'!M16+'3'!M16+'4'!M16+'5'!M16+'6'!M16+'7'!M16+'8'!M16+'9'!M16+'10'!M16 -> 2200 | O16: 15.42 | P16: =+K16*O16 -> 678.48 | Q16: 10 | R16: =+'10'!N68 -> 28790 | S16: =+'10'!N73 -> 2994 | T16: =+'10'!N71 -> 0 | U16: =+'10'!N69 -> 0 | V16: =+'10'!N72 -> 1400 | W16: =+'10'!N70 -> 7599 | X16: =R16-S16-T16-U16-V16-W16 -> 16797 | Y16: =+'10'!N75 -> 16797 | Z16: =+Y16-X16 -> 0 | AA16: พุธ | AB16: =+W16+Y16 -> 24396 | AC16: =+W16+Y16+Z16 -> 24396
A17: 13 | B17: 1112015 | C17: เค้กเบาหวิว รสกล้วยหอมหน้ามะพร้าวเผา 110 กรัม | D17: กล่อง | F17: =+ยกมา!F17+'29'!F17+'30'!F17+'1'!F17+'2'!F17+'3'!F17+'4'!F17+'5'!F17+'6'!F17+'7'!F17+'8'!F17+'9'!F17+'10'!F17 -> 45 | G17: =+E17+F17 -> 45 | H17: =+ยกมา!H17+'29'!H17+'30'!H17+'1'!H17+'2'!H17+'3'!H17+'4'!H17+'5'!H17+'6'!H17+'7'!H17+'8'!H17+'9'!H17+'10'!H17 -> 0 | I17: =+ยกมา!I17+'29'!I17+'30'!I17+'1'!I17+'2'!I17+'3'!I17+'4'!I17+'5'!I17+'6'!I17+'7'!I17+'8'!I17+'9'!I17+'10'!I17 -> 0 | J17: =E17+F17-H17-K17-I17 -> 6 | K17: =ยกมา!K17+'29'!K17+'30'!K17+'1'!K17+'2'!K17+'3'!K17+'4'!K17+'5'!K17+'6'!K17+'7'!K17+'8'!K17+'9'!K17+'10'!K17 -> 39 | L17: 50 | M17: =ยกมา!M17+'29'!M17+'30'!M17+'1'!M17+'2'!M17+'3'!M17+'4'!M17+'5'!M17+'6'!M17+'7'!M17+'8'!M17+'9'!M17+'10'!M17 -> 1950 | O17: 17.78 | P17: =+K17*O17 -> 693.42 | R17: =SUM(R5:R16) -> 223756 | S17: =SUM(S5:S16) -> 7159 | T17: =SUM(T5:T15) -> 0 | U17: =SUM(U5:U16) -> 105 | V17: =SUM(V5:V16) -> 19054 | W17: =SUM(W5:W16) -> 79284 | X17: =SUM(X5:X16) -> 118154 | Y17: =SUM(Y5:Y16) -> 119125 | Z17: =SUM(Z5:Z16) -> 971 | AA17: =SUM(AA5:AA15) -> 0 | AB17: =SUM(AB5:AB16) -> 198409
A18: 14 | B18: 1112013 | C18: เค้กเบาหวิว เผือกมะพร้าวอ่อน110 กรัม | D18: กล่อง | F18: =+ยกมา!F18+'29'!F18+'30'!F18+'1'!F18+'2'!F18+'3'!F18+'4'!F18+'5'!F18+'6'!F18+'7'!F18+'8'!F18+'9'!F18+'10'!F18 -> 45 | G18: =+E18+F18 -> 45 | H18: =+ยกมา!H18+'29'!H18+'30'!H18+'1'!H18+'2'!H18+'3'!H18+'4'!H18+'5'!H18+'6'!H18+'7'!H18+'8'!H18+'9'!H18+'10'!H18 -> 0 | I18: =+ยกมา!I18+'29'!I18+'30'!I18+'1'!I18+'2'!I18+'3'!I18+'4'!I18+'5'!I18+'6'!I18+'7'!I18+'8'!I18+'9'!I18+'10'!I18 -> 0 | J18: =E18+F18-H18-K18-I18 -> 0 | K18: =ยกมา!K18+'29'!K18+'30'!K18+'1'!K18+'2'!K18+'3'!K18+'4'!K18+'5'!K18+'6'!K18+'7'!K18+'8'!K18+'9'!K18+'10'!K18 -> 45 | L18: 50 | M18: =ยกมา!M18+'29'!M18+'30'!M18+'1'!M18+'2'!M18+'3'!M18+'4'!M18+'5'!M18+'6'!M18+'7'!M18+'8'!M18+'9'!M18+'10'!M18 -> 2250 | O18: 17.99 | P18: =+K18*O18 -> 809.55
A19: 15 | B19: 1112003 | C19: เค้กเบาหวิว รสกาแฟ 110 กรัม | D19: กล่อง | F19: =+ยกมา!F19+'29'!F19+'30'!F19+'1'!F19+'2'!F19+'3'!F19+'4'!F19+'5'!F19+'6'!F19+'7'!F19+'8'!F19+'9'!F19+'10'!F19 -> 35 | G19: =+E19+F19 -> 35 | H19: =+ยกมา!H19+'29'!H19+'30'!H19+'1'!H19+'2'!H19+'3'!H19+'4'!H19+'5'!H19+'6'!H19+'7'!H19+'8'!H19+'9'!H19+'10'!H19 -> 0 | I19: =+ยกมา!I19+'29'!I19+'30'!I19+'1'!I19+'2'!I19+'3'!I19+'4'!I19+'5'!I19+'6'!I19+'7'!I19+'8'!I19+'9'!I19+'10'!I19 -> 0 | J19: =E19+F19-H19-K19-I19 -> 7 | K19: =ยกมา!K19+'29'!K19+'30'!K19+'1'!K19+'2'!K19+'3'!K19+'4'!K19+'5'!K19+'6'!K19+'7'!K19+'8'!K19+'9'!K19+'10'!K19 -> 28 | L19: 50 | M19: =ยกมา!M19+'29'!M19+'30'!M19+'1'!M19+'2'!M19+'3'!M19+'4'!M19+'5'!M19+'6'!M19+'7'!M19+'8'!M19+'9'!M19+'10'!M19 -> 1400 | O19: 20.06 | P19: =+K19*O19 -> 561.68
A20: 16 | B20: 1112003 | C20: เค้กเบาหวิว รสเนยนม 110 กรัม | D20: กล่อง | F20: =+ยกมา!F20+'29'!F20+'30'!F20+'1'!F20+'2'!F20+'3'!F20+'4'!F20+'5'!F20+'6'!F20+'7'!F20+'8'!F20+'9'!F20+'10'!F20 -> 30 | G20: =+E20+F20 -> 30 | H20: =+ยกมา!H20+'29'!H20+'30'!H20+'1'!H20+'2'!H20+'3'!H20+'4'!H20+'5'!H20+'6'!H20+'7'!H20+'8'!H20+'9'!H20+'10'!H20 -> 0 | I20: =+ยกมา!I20+'29'!I20+'30'!I20+'1'!I20+'2'!I20+'3'!I20+'4'!I20+'5'!I20+'6'!I20+'7'!I20+'8'!I20+'9'!I20+'10'!I20 -> 1 | J20: =E20+F20-H20-K20-I20 -> 0 | K20: =ยกมา!K20+'29'!K20+'30'!K20+'1'!K20+'2'!K20+'3'!K20+'4'!K20+'5'!K20+'6'!K20+'7'!K20+'8'!K20+'9'!K20+'10'!K20 -> 29 | L20: 50 | M20: =ยกมา!M20+'29'!M20+'30'!M20+'1'!M20+'2'!M20+'3'!M20+'4'!M20+'5'!M20+'6'!M20+'7'!M20+'8'!M20+'9'!M20+'10'!M20 -> 1450 | O20: 20.32 | P20: =+K20*O20 -> 589.28
A21: 17 | B21: 1112011 | C21: เค้กเบาหวิว หน้าฝอยทอง 110 กรัม | D21: กล่อง | F21: =+ยกมา!F21+'29'!F21+'30'!F21+'1'!F21+'2'!F21+'3'!F21+'4'!F21+'5'!F21+'6'!F21+'7'!F21+'8'!F21+'9'!F21+'10'!F21 -> 80 | G21: =+E21+F21 -> 80 | H21: =+ยกมา!H21+'29'!H21+'30'!H21+'1'!H21+'2'!H21+'3'!H21+'4'!H21+'5'!H21+'6'!H21+'7'!H21+'8'!H21+'9'!H21+'10'!H21 -> 0 | I21: =+ยกมา!I21+'29'!I21+'30'!I21+'1'!I21+'2'!I21+'3'!I21+'4'!I21+'5'!I21+'6'!I21+'7'!I21+'8'!I21+'9'!I21+'10'!I21 -> 1 | J21: =E21+F21-H21-K21-I21 -> 22 | K21: =ยกมา!K21+'29'!K21+'30'!K21+'1'!K21+'2'!K21+'3'!K21+'4'!K21+'5'!K21+'6'!K21+'7'!K21+'8'!K21+'9'!K21+'10'!K21 -> 57 | L21: 50 | M21: =ยกมา!M21+'29'!M21+'30'!M21+'1'!M21+'2'!M21+'3'!M21+'4'!M21+'5'!M21+'6'!M21+'7'!M21+'8'!M21+'9'!M21+'10'!M21 -> 2850 | O21: 16.37 | P21: =+K21*O21 -> 933.09
A22: 18 | B22: 1112015 | C22: เค้กเบาหวิว รสกล้วยหอมหน้ามะพร้าวเผา 300 กรัม | D22: กล่อง | F22: =+ยกมา!F22+'29'!F22+'30'!F22+'1'!F22+'2'!F22+'3'!F22+'4'!F22+'5'!F22+'6'!F22+'7'!F22+'8'!F22+'9'!F22+'10'!F22 -> 14 | G22: =+E22+F22 -> 14 | H22: =+ยกมา!H22+'29'!H22+'30'!H22+'1'!H22+'2'!H22+'3'!H22+'4'!H22+'5'!H22+'6'!H22+'7'!H22+'8'!H22+'9'!H22+'10'!H22 -> 0 | I22: =+ยกมา!I22+'29'!I22+'30'!I22+'1'!I22+'2'!I22+'3'!I22+'4'!I22+'5'!I22+'6'!I22+'7'!I22+'8'!I22+'9'!I22+'10'!I22 -> 0 | J22: =E22+F22-H22-K22-I22 -> 6 | K22: =ยกมา!K22+'29'!K22+'30'!K22+'1'!K22+'2'!K22+'3'!K22+'4'!K22+'5'!K22+'6'!K22+'7'!K22+'8'!K22+'9'!K22+'10'!K22 -> 8 | L22: 120 | M22: =ยกมา!M22+'29'!M22+'30'!M22+'1'!M22+'2'!M22+'3'!M22+'4'!M22+'5'!M22+'6'!M22+'7'!M22+'8'!M22+'9'!M22+'10'!M22 -> 960 | O22: 25.99 | P22: =+K22*O22 -> 207.92
A23: 19 | B23: 1112012 | C23: เค้กเบาหวิว รสเผือกหน้ามะพร้าวเผา 300 กรัม | D23: กล่อง | F23: =+ยกมา!F23+'29'!F23+'30'!F23+'1'!F23+'2'!F23+'3'!F23+'4'!F23+'5'!F23+'6'!F23+'7'!F23+'8'!F23+'9'!F23+'10'!F23 -> 19 | G23: =+E23+F23 -> 19 | H23: =+ยกมา!H23+'29'!H23+'30'!H23+'1'!H23+'2'!H23+'3'!H23+'4'!H23+'5'!H23+'6'!H23+'7'!H23+'8'!H23+'9'!H23+'10'!H23 -> 0 | I23: =+ยกมา!I23+'29'!I23+'30'!I23+'1'!I23+'2'!I23+'3'!I23+'4'!I23+'5'!I23+'6'!I23+'7'!I23+'8'!I23+'9'!I23+'10'!I23 -> 0 | J23: =E23+F23-H23-K23-I23 -> 0 | K23: =ยกมา!K23+'29'!K23+'30'!K23+'1'!K23+'2'!K23+'3'!K23+'4'!K23+'5'!K23+'6'!K23+'7'!K23+'8'!K23+'9'!K23+'10'!K23 -> 19 | L23: 120 | M23: =ยกมา!M23+'29'!M23+'30'!M23+'1'!M23+'2'!M23+'3'!M23+'4'!M23+'5'!M23+'6'!M23+'7'!M23+'8'!M23+'9'!M23+'10'!M23 -> 2280 | O23: 28.31 | P23: =+K23*O23 -> 537.89
A24: 20 | B24: 1112002 | C24: เค้กเบาหวิว รสกาแฟ 300 กรัม | D24: กล่อง | F24: =+ยกมา!F24+'29'!F24+'30'!F24+'1'!F24+'2'!F24+'3'!F24+'4'!F24+'5'!F24+'6'!F24+'7'!F24+'8'!F24+'9'!F24+'10'!F24 -> 15 | G24: =+E24+F24 -> 15 | H24: =+ยกมา!H24+'29'!H24+'30'!H24+'1'!H24+'2'!H24+'3'!H24+'4'!H24+'5'!H24+'6'!H24+'7'!H24+'8'!H24+'9'!H24+'10'!H24 -> 0 | I24: =+ยกมา!I24+'29'!I24+'30'!I24+'1'!I24+'2'!I24+'3'!I24+'4'!I24+'5'!I24+'6'!I24+'7'!I24+'8'!I24+'9'!I24+'10'!I24 -> 0 | J24: =E24+F24-H24-K24-I24 -> 10 | K24: =ยกมา!K24+'29'!K24+'30'!K24+'1'!K24+'2'!K24+'3'!K24+'4'!K24+'5'!K24+'6'!K24+'7'!K24+'8'!K24+'9'!K24+'10'!K24 -> 5 | L24: 120 | M24: =ยกมา!M24+'29'!M24+'30'!M24+'1'!M24+'2'!M24+'3'!M24+'4'!M24+'5'!M24+'6'!M24+'7'!M24+'8'!M24+'9'!M24+'10'!M24 -> 600 | O24: 31.07 | P24: =+K24*O24 -> 155.35
A25: 21 | B25: 1112004 | C25: เค้กเบาหวิว รสเนยนม 300 กรัม | D25: กล่อง | F25: =+ยกมา!F25+'29'!F25+'30'!F25+'1'!F25+'2'!F25+'3'!F25+'4'!F25+'5'!F25+'6'!F25+'7'!F25+'8'!F25+'9'!F25+'10'!F25 -> 15 | G25: =+E25+F25 -> 15 | H25: =+ยกมา!H25+'29'!H25+'30'!H25+'1'!H25+'2'!H25+'3'!H25+'4'!H25+'5'!H25+'6'!H25+'7'!H25+'8'!H25+'9'!H25+'10'!H25 -> 0 | I25: =+ยกมา!I25+'29'!I25+'30'!I25+'1'!I25+'2'!I25+'3'!I25+'4'!I25+'5'!I25+'6'!I25+'7'!I25+'8'!I25+'9'!I25+'10'!I25 -> 0 | J25: =E25+F25-H25-K25-I25 -> 3 | K25: =ยกมา!K25+'29'!K25+'30'!K25+'1'!K25+'2'!K25+'3'!K25+'4'!K25+'5'!K25+'6'!K25+'7'!K25+'8'!K25+'9'!K25+'10'!K25 -> 12 | L25: 120 | M25: =ยกมา!M25+'29'!M25+'30'!M25+'1'!M25+'2'!M25+'3'!M25+'4'!M25+'5'!M25+'6'!M25+'7'!M25+'8'!M25+'9'!M25+'10'!M25 -> 1440 | O25: 29.83 | P25: =+K25*O25 -> 357.96
A26: 22 | B26: 1112010 | C26: เค้กเบาหวิว หน้าฝอยทอง 300 กรัม | D26: กล่อง | F26: =+ยกมา!F26+'29'!F26+'30'!F26+'1'!F26+'2'!F26+'3'!F26+'4'!F26+'5'!F26+'6'!F26+'7'!F26+'8'!F26+'9'!F26+'10'!F26 -> 24 | G26: =+E26+F26 -> 24 | H26: =+ยกมา!H26+'29'!H26+'30'!H26+'1'!H26+'2'!H26+'3'!H26+'4'!H26+'5'!H26+'6'!H26+'7'!H26+'8'!H26+'9'!H26+'10'!H26 -> 0 | I26: =+ยกมา!I26+'29'!I26+'30'!I26+'1'!I26+'2'!I26+'3'!I26+'4'!I26+'5'!I26+'6'!I26+'7'!I26+'8'!I26+'9'!I26+'10'!I26 -> 0 | J26: =E26+F26-H26-K26-I26 -> 0 | K26: =ยกมา!K26+'29'!K26+'30'!K26+'1'!K26+'2'!K26+'3'!K26+'4'!K26+'5'!K26+'6'!K26+'7'!K26+'8'!K26+'9'!K26+'10'!K26 -> 24 | L26: 120 | M26: =ยกมา!M26+'29'!M26+'30'!M26+'1'!M26+'2'!M26+'3'!M26+'4'!M26+'5'!M26+'6'!M26+'7'!M26+'8'!M26+'9'!M26+'10'!M26 -> 2880 | O26: 26.39 | P26: =+K26*O26 -> 633.36
A27: 23 | B27: 1113008 | C27: เค้กโบราณรวมรส 4 ชิ้น | D27: กล่อง | F27: =+ยกมา!F27+'29'!F27+'30'!F27+'1'!F27+'2'!F27+'3'!F27+'4'!F27+'5'!F27+'6'!F27+'7'!F27+'8'!F27+'9'!F27+'10'!F27 -> 13 | G27: =+E27+F27 -> 13 | H27: =+ยกมา!H27+'29'!H27+'30'!H27+'1'!H27+'2'!H27+'3'!H27+'4'!H27+'5'!H27+'6'!H27+'7'!H27+'8'!H27+'9'!H27+'10'!H27 -> 0 | I27: =+ยกมา!I27+'29'!I27+'30'!I27+'1'!I27+'2'!I27+'3'!I27+'4'!I27+'5'!I27+'6'!I27+'7'!I27+'8'!I27+'9'!I27+'10'!I27 -> 0 | J27: =E27+F27-H27-K27-I27 -> 7 | K27: =ยกมา!K27+'29'!K27+'30'!K27+'1'!K27+'2'!K27+'3'!K27+'4'!K27+'5'!K27+'6'!K27+'7'!K27+'8'!K27+'9'!K27+'10'!K27 -> 6 | L27: 50 | M27: =ยกมา!M27+'29'!M27+'30'!M27+'1'!M27+'2'!M27+'3'!M27+'4'!M27+'5'!M27+'6'!M27+'7'!M27+'8'!M27+'9'!M27+'10'!M27 -> 300 | O27: 23.69 | P27: =+K27*O27 -> 142.14
A28: 24 | B28: 1113006 | C28: เค้กโบราณครีม 4 ชิ้น | D28: กล่อง | F28: =+ยกมา!F28+'29'!F28+'30'!F28+'1'!F28+'2'!F28+'3'!F28+'4'!F28+'5'!F28+'6'!F28+'7'!F28+'8'!F28+'9'!F28+'10'!F28 -> 30 | G28: =+E28+F28 -> 30 | H28: =+ยกมา!H28+'29'!H28+'30'!H28+'1'!H28+'2'!H28+'3'!H28+'4'!H28+'5'!H28+'6'!H28+'7'!H28+'8'!H28+'9'!H28+'10'!H28 -> 0 | I28: =+ยกมา!I28+'29'!I28+'30'!I28+'1'!I28+'2'!I28+'3'!I28+'4'!I28+'5'!I28+'6'!I28+'7'!I28+'8'!I28+'9'!I28+'10'!I28 -> 0 | J28: =E28+F28-H28-K28-I28 -> 0 | K28: =ยกมา!K28+'29'!K28+'30'!K28+'1'!K28+'2'!K28+'3'!K28+'4'!K28+'5'!K28+'6'!K28+'7'!K28+'8'!K28+'9'!K28+'10'!K28 -> 30 | L28: 50 | M28: =ยกมา!M28+'29'!M28+'30'!M28+'1'!M28+'2'!M28+'3'!M28+'4'!M28+'5'!M28+'6'!M28+'7'!M28+'8'!M28+'9'!M28+'10'!M28 -> 1500 | O28: 22.49 | P28: =+K28*O28 -> 674.7
A29: 25 | B29: 1004062 | C29: เค้กลาวา ฝอยทองทูโทน เล็ก | D29: กล่อง | F29: =+ยกมา!F29+'29'!F29+'30'!F29+'1'!F29+'2'!F29+'3'!F29+'4'!F29+'5'!F29+'6'!F29+'7'!F29+'8'!F29+'9'!F29+'10'!F29 -> 25 | G29: =+E29+F29 -> 25 | H29: =+ยกมา!H29+'29'!H29+'30'!H29+'1'!H29+'2'!H29+'3'!H29+'4'!H29+'5'!H29+'6'!H29+'7'!H29+'8'!H29+'9'!H29+'10'!H29 -> 0 | I29: =+ยกมา!I29+'29'!I29+'30'!I29+'1'!I29+'2'!I29+'3'!I29+'4'!I29+'5'!I29+'6'!I29+'7'!I29+'8'!I29+'9'!I29+'10'!I29 -> 0 | J29: =E29+F29-H29-K29-I29 -> 0 | K29: =ยกมา!K29+'29'!K29+'30'!K29+'1'!K29+'2'!K29+'3'!K29+'4'!K29+'5'!K29+'6'!K29+'7'!K29+'8'!K29+'9'!K29+'10'!K29 -> 25 | L29: 50 | M29: =ยกมา!M29+'29'!M29+'30'!M29+'1'!M29+'2'!M29+'3'!M29+'4'!M29+'5'!M29+'6'!M29+'7'!M29+'8'!M29+'9'!M29+'10'!M29 -> 1250 | O29: 17.09 | P29: =+K29*O29 -> 427.25
... A42: 38 | B42: 1113208 | C42: คุกกี้ฮ่องกงหอมเจียว | D42: ชิ้น | F42: =+ยกมา!F42+'29'!F42+'30'!F42+'1'!F42+'2'!F42+'3'!F42+'4'!F42+'5'!F42+'6'!F42+'7'!F42+'8'!F42+'9'!F42+'10'!F42 -> 928 | G42: =+E42+F42 -> 928 | H42: =+ยกมา!H42+'29'!H42+'30'!H42+'1'!H42+'2'!H42+'3'!H42+'4'!H42+'5'!H42+'6'!H42+'7'!H42+'8'!H42+'9'!H42+'10'!H42 -> 262 | I42: =+ยกมา!I42+'29'!I42+'30'!I42+'1'!I42+'2'!I42+'3'!I42+'4'!I42+'5'!I42+'6'!I42+'7'!I42+'8'!I42+'9'!I42+'10'!I42 -> 0 | J42: =E42+F42-H42-K42-I42 -> 0 | K42: =ยกมา!K42+'29'!K42+'30'!K42+'1'!K42+'2'!K42+'3'!K42+'4'!K42+'5'!K42+'6'!K42+'7'!K42+'8'!K42+'9'!K42+'10'!K42 -> 666 | L42: 10 | M42: =ยกมา!M42+'29'!M42+'30'!M42+'1'!M42+'2'!M42+'3'!M42+'4'!M42+'5'!M42+'6'!M42+'7'!M42+'8'!M42+'9'!M42+'10'!M42 -> 770 | O42: 6.3 | P42: =+K42*O42 -> 4195.8
A43: 39 | B43: 1112400 | C43: ขนมปังกรอบรสคาราเมล 65 กรัม | D43: กล่อง | F43: =+ยกมา!F43+'29'!F43+'30'!F43+'1'!F43+'2'!F43+'3'!F43+'4'!F43+'5'!F43+'6'!F43+'7'!F43+'8'!F43+'9'!F43+'10'!F43 -> 173 | G43: =+E43+F43 -> 173 | H43: =+ยกมา!H43+'29'!H43+'30'!H43+'1'!H43+'2'!H43+'3'!H43+'4'!H43+'5'!H43+'6'!H43+'7'!H43+'8'!H43+'9'!H43+'10'!H43 -> 0 | I43: =+ยกมา!I43+'29'!I43+'30'!I43+'1'!I43+'2'!I43+'3'!I43+'4'!I43+'5'!I43+'6'!I43+'7'!I43+'8'!I43+'9'!I43+'10'!I43 -> 95 | J43: =E43+F43-H43-K43-I43 -> 20 | K43: =ยกมา!K43+'29'!K43+'30'!K43+'1'!K43+'2'!K43+'3'!K43+'4'!K43+'5'!K43+'6'!K43+'7'!K43+'8'!K43+'9'!K43+'10'!K43 -> 58 | L43: 10 | M43: =ยกมา!M43+'29'!M43+'30'!M43+'1'!M43+'2'!M43+'3'!M43+'4'!M43+'5'!M43+'6'!M43+'7'!M43+'8'!M43+'9'!M43+'10'!M43 -> 580 | P43: =+K43*O43 -> 0
A44: 40 | B44: 1113171 | C44: ขนมเปี๊ยะฟักถั่วไข่เค็ม 450 กรัม | D44: กล่อง | F44: =+ยกมา!F44+'29'!F44+'30'!F44+'1'!F44+'2'!F44+'3'!F44+'4'!F44+'5'!F44+'6'!F44+'7'!F44+'8'!F44+'9'!F44+'10'!F44 -> 20 | G44: =+E44+F44 -> 20 | H44: =+ยกมา!H44+'29'!H44+'30'!H44+'1'!H44+'2'!H44+'3'!H44+'4'!H44+'5'!H44+'6'!H44+'7'!H44+'8'!H44+'9'!H44+'10'!H44 -> 0 | I44: =+ยกมา!I44+'29'!I44+'30'!I44+'1'!I44+'2'!I44+'3'!I44+'4'!I44+'5'!I44+'6'!I44+'7'!I44+'8'!I44+'9'!I44+'10'!I44 -> 0 | J44: =E44+F44-H44-K44-I44 -> 3 | K44: =ยกมา!K44+'29'!K44+'30'!K44+'1'!K44+'2'!K44+'3'!K44+'4'!K44+'5'!K44+'6'!K44+'7'!K44+'8'!K44+'9'!K44+'10'!K44 -> 17 | L44: 150 | M44: =ยกมา!M44+'29'!M44+'30'!M44+'1'!M44+'2'!M44+'3'!M44+'4'!M44+'5'!M44+'6'!M44+'7'!M44+'8'!M44+'9'!M44+'10'!M44 -> 2550 | P44: =+K44*O44 -> 0
A45: 41 | B45: 1113170 | C45: ขนมเปี๊ยะถั่วฝอยทองไข่เค็ม 450 กรัม | D45: กล่อง | F45: =+ยกมา!F45+'29'!F45+'30'!F45+'1'!F45+'2'!F45+'3'!F45+'4'!F45+'5'!F45+'6'!F45+'7'!F45+'8'!F45+'9'!F45+'10'!F45 -> 10 | G45: =+E45+F45 -> 10 | H45: =+ยกมา!H45+'29'!H45+'30'!H45+'1'!H45+'2'!H45+'3'!H45+'4'!H45+'5'!H45+'6'!H45+'7'!H45+'8'!H45+'9'!H45+'10'!H45 -> 0 | I45: =+ยกมา!I45+'29'!I45+'30'!I45+'1'!I45+'2'!I45+'3'!I45+'4'!I45+'5'!I45+'6'!I45+'7'!I45+'8'!I45+'9'!I45+'10'!I45 -> 1 | J45: =E45+F45-H45-K45-I45 -> 5 | K45: =ยกมา!K45+'29'!K45+'30'!K45+'1'!K45+'2'!K45+'3'!K45+'4'!K45+'5'!K45+'6'!K45+'7'!K45+'8'!K45+'9'!K45+'10'!K45 -> 4 | L45: 150 | M45: =ยกมา!M45+'29'!M45+'30'!M45+'1'!M45+'2'!M45+'3'!M45+'4'!M45+'5'!M45+'6'!M45+'7'!M45+'8'!M45+'9'!M45+'10'!M45 -> 600 | P45: =+K45*O45 -> 0
A46: 42 | B46: 20054646 | C46: ขนมปังพิซซ่าโบโลน่า 80 กรัม | D46: กล่อง | F46: =+ยกมา!F46+'29'!F46+'30'!F46+'1'!F46+'2'!F46+'3'!F46+'4'!F46+'5'!F46+'6'!F46+'7'!F46+'8'!F46+'9'!F46+'10'!F46 -> 36 | G46: =+E46+F46 -> 36 | H46: =+ยกมา!H46+'29'!H46+'30'!H46+'1'!H46+'2'!H46+'3'!H46+'4'!H46+'5'!H46+'6'!H46+'7'!H46+'8'!H46+'9'!H46+'10'!H46 -> 1 | I46: =+ยกมา!I46+'29'!I46+'30'!I46+'1'!I46+'2'!I46+'3'!I46+'4'!I46+'5'!I46+'6'!I46+'7'!I46+'8'!I46+'9'!I46+'10'!I46 -> 0 | J46: =E46+F46-H46-K46-I46 -> 1 | K46: =ยกมา!K46+'29'!K46+'30'!K46+'1'!K46+'2'!K46+'3'!K46+'4'!K46+'5'!K46+'6'!K46+'7'!K46+'8'!K46+'9'!K46+'10'!K46 -> 34 | L46: 25 | M46: =ยกมา!M46+'29'!M46+'30'!M46+'1'!M46+'2'!M46+'3'!M46+'4'!M46+'5'!M46+'6'!M46+'7'!M46+'8'!M46+'9'!M46+'10'!M46 -> 850 | P46: =+K46*O46 -> 0
A47: 43 | B47: 1113234 | C47: เค้กลอดช่องน้ำตาลโตนด 100 กรัม | D47: กล่อง | F47: =+ยกมา!F47+'29'!F47+'30'!F47+'1'!F47+'2'!F47+'3'!F47+'4'!F47+'5'!F47+'6'!F47+'7'!F47+'8'!F47+'9'!F47+'10'!F47 -> 53 | G47: =+E47+F47 -> 53 | H47: =+ยกมา!H47+'29'!H47+'30'!H47+'1'!H47+'2'!H47+'3'!H47+'4'!H47+'5'!H47+'6'!H47+'7'!H47+'8'!H47+'9'!H47+'10'!H47 -> 0 | I47: =+ยกมา!I47+'29'!I47+'30'!I47+'1'!I47+'2'!I47+'3'!I47+'4'!I47+'5'!I47+'6'!I47+'7'!I47+'8'!I47+'9'!I47+'10'!I47 -> 1 | J47: =E47+F47-H47-K47-I47 -> 0 | K47: =ยกมา!K47+'29'!K47+'30'!K47+'1'!K47+'2'!K47+'3'!K47+'4'!K47+'5'!K47+'6'!K47+'7'!K47+'8'!K47+'9'!K47+'10'!K47 -> 52 | L47: 25 | M47: =ยกมา!M47+'29'!M47+'30'!M47+'1'!M47+'2'!M47+'3'!M47+'4'!M47+'5'!M47+'6'!M47+'7'!M47+'8'!M47+'9'!M47+'10'!M47 -> 1820 | P47: =+K47*O47 -> 0
A48: 45 | B48: 20058428 | C48: ทาร์ตไข่คาราเมล 50 กรัม | D48: กล่อง | F48: =+ยกมา!F48+'29'!F48+'30'!F48+'1'!F48+'2'!F48+'3'!F48+'4'!F48+'5'!F48+'6'!F48+'7'!F48+'8'!F48+'9'!F48+'10'!F48 -> 759 | G48: =+E48+F48 -> 759 | H48: =+ยกมา!H48+'29'!H48+'30'!H48+'1'!H48+'2'!H48+'3'!H48+'4'!H48+'5'!H48+'6'!H48+'7'!H48+'8'!H48+'9'!H48+'10'!H48 -> 0 | I48: =+ยกมา!I48+'29'!I48+'30'!I48+'1'!I48+'2'!I48+'3'!I48+'4'!I48+'5'!I48+'6'!I48+'7'!I48+'8'!I48+'9'!I48+'10'!I48 -> 19 | J48: =E48+F48-H48-K48-I48 -> 17 | K48: =ยกมา!K48+'29'!K48+'30'!K48+'1'!K48+'2'!K48+'3'!K48+'4'!K48+'5'!K48+'6'!K48+'7'!K48+'8'!K48+'9'!K48+'10'!K48 -> 723 | L48: 19 | M48: =ยกมา!M48+'29'!M48+'30'!M48+'1'!M48+'2'!M48+'3'!M48+'4'!M48+'5'!M48+'6'!M48+'7'!M48+'8'!M48+'9'!M48+'10'!M48 -> 8721 | P48: =+K48*O48 -> 0
A49: 46 | B49: 1300047 | C49: ทาร์ตทุเรียนครีมกะทิ 65 กรัม | D49: กล่อง | F49: =+ยกมา!F49+'29'!F49+'30'!F49+'1'!F49+'2'!F49+'3'!F49+'4'!F49+'5'!F49+'6'!F49+'7'!F49+'8'!F49+'9'!F49+'10'!F49 -> 208 | G49: =+E49+F49 -> 208 | H49: =+ยกมา!H49+'29'!H49+'30'!H49+'1'!H49+'2'!H49+'3'!H49+'4'!H49+'5'!H49+'6'!H49+'7'!H49+'8'!H49+'9'!H49+'10'!H49 -> 27 | I49: =+ยกมา!I49+'29'!I49+'30'!I49+'1'!I49+'2'!I49+'3'!I49+'4'!I49+'5'!I49+'6'!I49+'7'!I49+'8'!I49+'9'!I49+'10'!I49 -> 58 | J49: =E49+F49-H49-K49-I49 -> 0 | K49: =ยกมา!K49+'29'!K49+'30'!K49+'1'!K49+'2'!K49+'3'!K49+'4'!K49+'5'!K49+'6'!K49+'7'!K49+'8'!K49+'9'!K49+'10'!K49 -> 123 | L49: 25 | M49: =ยกมา!M49+'29'!M49+'30'!M49+'1'!M49+'2'!M49+'3'!M49+'4'!M49+'5'!M49+'6'!M49+'7'!M49+'8'!M49+'9'!M49+'10'!M49 -> 3075 | P49: =+K49*O49 -> 0
A50: 47 | B50: 1113190 | C50: เค้กทุเรียน 90 กรัม | D50: กล่อง | F50: =+ยกมา!F50+'29'!F50+'30'!F50+'1'!F50+'2'!F50+'3'!F50+'4'!F50+'5'!F50+'6'!F50+'7'!F50+'8'!F50+'9'!F50+'10'!F50 -> 141 | G50: =+E50+F50 -> 141 | H50: =+ยกมา!H50+'29'!H50+'30'!H50+'1'!H50+'2'!H50+'3'!H50+'4'!H50+'5'!H50+'6'!H50+'7'!H50+'8'!H50+'9'!H50+'10'!H50 -> 0 | I50: =+ยกมา!I50+'29'!I50+'30'!I50+'1'!I50+'2'!I50+'3'!I50+'4'!I50+'5'!I50+'6'!I50+'7'!I50+'8'!I50+'9'!I50+'10'!I50 -> 51 | J50: =E50+F50-H50-K50-I50 -> 3 | K50: =ยกมา!K50+'29'!K50+'30'!K50+'1'!K50+'2'!K50+'3'!K50+'4'!K50+'5'!K50+'6'!K50+'7'!K50+'8'!K50+'9'!K50+'10'!K50 -> 87 | L50: 25 | M50: =ยกมา!M50+'29'!M50+'30'!M50+'1'!M50+'2'!M50+'3'!M50+'4'!M50+'5'!M50+'6'!M50+'7'!M50+'8'!M50+'9'!M50+'10'!M50 -> 2175 | P50: =+K50*O50 -> 0
A51: 48 | B51: 1113229 | C51: ทุเรียนชีสพาย 85 กรัม | D51: กล่อง | F51: =+ยกมา!F51+'29'!F51+'30'!F51+'1'!F51+'2'!F51+'3'!F51+'4'!F51+'5'!F51+'6'!F51+'7'!F51+'8'!F51+'9'!F51+'10'!F51 -> 126 | G51: =+E51+F51 -> 126 | H51: =+ยกมา!H51+'29'!H51+'30'!H51+'1'!H51+'2'!H51+'3'!H51+'4'!H51+'5'!H51+'6'!H51+'7'!H51+'8'!H51+'9'!H51+'10'!H51 -> 0 | I51: =+ยกมา!I51+'29'!I51+'30'!I51+'1'!I51+'2'!I51+'3'!I51+'4'!I51+'5'!I51+'6'!I51+'7'!I51+'8'!I51+'9'!I51+'10'!I51 -> 31 | J51: =E51+F51-H51-K51-I51 -> 0 | K51: =ยกมา!K51+'29'!K51+'30'!K51+'1'!K51+'2'!K51+'3'!K51+'4'!K51+'5'!K51+'6'!K51+'7'!K51+'8'!K51+'9'!K51+'10'!K51 -> 95 | L51: 25 | M51: =ยกมา!M51+'29'!M51+'30'!M51+'1'!M51+'2'!M51+'3'!M51+'4'!M51+'5'!M51+'6'!M51+'7'!M51+'8'!M51+'9'!M51+'10'!M51 -> 2375 | P51: =+K51*O51 -> 0
A52: 49 | B52: 1113226 | C52: เค้กโมลเทนช็อกโกแลต 75 กรัม | D52: กล่อง | F52: =+ยกมา!F52+'29'!F52+'30'!F52+'1'!F52+'2'!F52+'3'!F52+'4'!F52+'5'!F52+'6'!F52+'7'!F52+'8'!F52+'9'!F52+'10'!F52 -> 64 | G52: =+E52+F52 -> 64 | H52: =+ยกมา!H52+'29'!H52+'30'!H52+'1'!H52+'2'!H52+'3'!H52+'4'!H52+'5'!H52+'6'!H52+'7'!H52+'8'!H52+'9'!H52+'10'!H52 -> 0 | I52: =+ยกมา!I52+'29'!I52+'30'!I52+'1'!I52+'2'!I52+'3'!I52+'4'!I52+'5'!I52+'6'!I52+'7'!I52+'8'!I52+'9'!I52+'10'!I52 -> 30 | J52: =E52+F52-H52-K52-I52 -> 1 | K52: =ยกมา!K52+'29'!K52+'30'!K52+'1'!K52+'2'!K52+'3'!K52+'4'!K52+'5'!K52+'6'!K52+'7'!K52+'8'!K52+'9'!K52+'10'!K52 -> 33 | L52: 35 | M52: =ยกมา!M52+'29'!M52+'30'!M52+'1'!M52+'2'!M52+'3'!M52+'4'!M52+'5'!M52+'6'!M52+'7'!M52+'8'!M52+'9'!M52+'10'!M52 -> 1085 | P52: =+K52*O52 -> 0
A53: 50 | B53: 1113227 | C53: เค้กแอปเปิ้ล 70 กรัม | D53: กล่อง | F53: =+ยกมา!F53+'29'!F53+'30'!F53+'1'!F53+'2'!F53+'3'!F53+'4'!F53+'5'!F53+'6'!F53+'7'!F53+'8'!F53+'9'!F53+'10'!F53 -> 50 | G53: =+E53+F53 -> 50 | H53: =+ยกมา!H53+'29'!H53+'30'!H53+'1'!H53+'2'!H53+'3'!H53+'4'!H53+'5'!H53+'6'!H53+'7'!H53+'8'!H53+'9'!H53+'10'!H53 -> 0 | I53: =+ยกมา!I53+'29'!I53+'30'!I53+'1'!I53+'2'!I53+'3'!I53+'4'!I53+'5'!I53+'6'!I53+'7'!I53+'8'!I53+'9'!I53+'10'!I53 -> 1 | J53: =E53+F53-H53-K53-I53 -> 21 | K53: =ยกมา!K53+'29'!K53+'30'!K53+'1'!K53+'2'!K53+'3'!K53+'4'!K53+'5'!K53+'6'!K53+'7'!K53+'8'!K53+'9'!K53+'10'!K53 -> 28 | L53: 35 | M53: =ยกมา!M53+'29'!M53+'30'!M53+'1'!M53+'2'!M53+'3'!M53+'4'!M53+'5'!M53+'6'!M53+'7'!M53+'8'!M53+'9'!M53+'10'!M53 -> 980 | P53: =+K53*O53 -> 0
...

Sheet สรุปการขาย
A1: สรุปค่าใช้จ่าย คำนวนกำไร
A2: NO | B2: รายการ | C2: ยอดเงิน | D2: หมายเหตุ | F2: ยอดขาย | G2: =+สรุป!AB17 -> 198409 | H2: บาท
A3: 1 | B3: ต้นทุนขนม | C3: =+สรุป!P66 -> 65850.29 | F3: ยอดค่าใช้จ่าย | G3: =+C8 -> 139850.29 | H3: บาท
A4: 2 | B4: ค่าแรงพนักงาน | C4: =+ค่าแรงพนักงาน!C6 -> 15200 | F4: สรุปกำไร | G4: =+G2-G3 -> 58558.71 | H4: บาท
A5: 3 | B5: ค่าเช่า OTOP | C5: 45000
A6: 4 | B6: ค่าไฟ | C6: 2800
A7: 5 | B7: ค่าอินฟลูเอนเซอร์ | C7: =7000+4000 -> 11000
C8: =SUM(C3:C7) -> 139850.29

Sheet ค่าเช่าบูธ
A1: รายการเช่า - ขาย ล็อคงานเกษตรแฟร์
A2: NO | B2: รายการ | C2: ค่าเช่าบูธ | D2: ขายบูธ | E2: กำไร | F2: หมายเหตุ | H2: ค่าใช้จ่าย + ค่าเช่า | I2: =+C8+C15 -> 125870 | J2: บาท
A3: 1 | B3: ค่าเช่า 1 | C3: 16500 | D3: 28000 | E3: =+D3-C3 -> 11500 | H3: รายได้ขายล็อค | I3: =+D8 -> 158000 | J3: บาท
A4: 2 | B4: ค่าเช่า 2 | C4: 16500 | D4: 25000 | E4: =+D4-C4 -> 8500 | H4: สรุปกำไรขายล็อค | I4: =+I3-I2 -> 32130 | J4: บาท
A5: 3 | B5: ค่าเช่า 3 | C5: 16500 | D5: 27000 | E5: =+D5-C5 -> 10500
A6: 4 | B6: ค่าเช่า 4 | C6: 16500 | D6: 28000 | E6: =+D6-C6 -> 11500
A7: 5 | B7: ค่าเช่า 5 | C7: 24000 | D7: 50000 | E7: =+D7-C7 -> 26000 | F7: โซน 1
B8: ยอดรวม | C8: =SUM(C3:C7) -> 90000 | D8: =SUM(D3:D7) -> 158000 | E8: =SUM(E3:E7) -> 68000 | F8: บาท
A10: ค่าใช้จ่ายเพิ่มเติม การประมูลล็อค
A11: 1 | B11: ค่าเข้างานประมูลล็อค 19 คน | C11: 22800
A12: 2 | B12: ค่านายหน้า | C12: 1000
A13: 3 | B13: ค่าไฟ | C13: 2570
A14: 4 | B14: ค่าแรง 19 คน เฉลี่ยคนล่ะ 500 บาท | C14: =500*19 -> 9500
C15: =SUM(C11:C14) -> 35870

Sheet ค่าแรงพนักงาน
A1: รายชื่อพนักงานที่ทำงานเกษตรแฟร์ ปี 2567
A2: No. | B2: ชื่อ | C2: ค่าแรง | D2: หมายเหตุ
A3: 1 | B3: แจม | C3: =600*11 -> 6600 | D3: วันละ 600 บาท = 11 วัน
A4: 2 | B4: พี่น้อย | C4: =600*7 -> 4200 | D4: วันละ 600 บาท = 7 วัน
A5: 3 | B5: กาน | C5: =400*11 -> 4400 | D5: วันละ 400 บาท = 11 วัน
B6: ยอดรวม | C6: =SUM(C3:C5) -> 15200 | D6: บาท

Sheet ยกมา
A2: บูธ EVENT งานเกษตรแฟร์กำแพงแสน 30 พ.ย. 67 - 10 ธ.ค. 67
A3: ลำดับ | B3: รหัสสินค้า (POS) | C3: รายการ | D3: หน่วย | E3: ยกมา | F3: รับ | G3: รวม | H3: เปลี่ยน/ | I3: โยกย้าย / ระบาย | J3: คงเหลือ | K3: รายการขาย | N3: หมายเหตุ | O3: ส่วนลด | Q3: ราคาต้นทุน | R3: ยอดรวมต้นทุนสินค้า
H4: คืน/เสีย | K4: จำนวน | L4: @ | M4: เป็นเงิน
A5: 1 | B5: 1004055 | C5: ชิฟฟ่อนเค้ก รวมรส (4 ชิ้น) | D5: กล่อง | E5: =+สรุป!E5 -> 0 | G5: =E5+F5 -> 0 | H5: 0 | I5: 0 | J5: =+G5-H5-K5-I5 -> 0 | L5: 50 | M5: =+L5*K5 -> 0 | N5: - | P5: =SUM(M5-O5) -> 0 | Q5: 18.97 | R5: =+K5*Q5 -> 0
A6: 2 | B6: 1111002 | C6: ชิฟฟ่อนเค้ก รวมรส (8 ชิ้น) | D6: กล่อง | E6: =+สรุป!E6 -> 0 | G6: =E6+F6 -> 0 | H6: 0 | I6: 0 | J6: =+G6-H6-K6-I6 -> 0 | L6: 100 | M6: =+L6*K6 -> 0 | N6: - | P6: =SUM(M6-O6) -> 0 | Q6: 36.43 | R6: =+K6*Q6 -> 0
A7: 3 | B7: 1111008 | C7: ชิฟฟ่อนเค้ก รวมรส (3 ชิ้น) | D7: กล่อง | E7: =+สรุป!E7 -> 0 | G7: =E7+F7 -> 0 | H7: 0 | I7: 0 | J7: =+G7-H7-K7-I7 -> 0 | L7: 50 | M7: =+L7*K7 -> 0 | N7: - | P7: =SUM(M7-O7) -> 0 | Q7: 19.36 | R7: =+K7*Q7 -> 0
A8: 4 | B8: 1111004 | C8: ชิฟฟ่อน สอดไส้ (ล) 4 ชิ้น ครีมมะพร้าว | D8: กล่อง | E8: =+สรุป!E8 -> 0 | G8: =E8+F8 -> 0 | H8: 0 | I8: 0 | J8: =+G8-H8-K8-I8 -> 0 | L8: 65 | M8: =+L8*K8 -> 0 | N8: - | P8: =SUM(M8-O8) -> 0 | Q8: 22.25 | R8: =+K8*Q8 -> 0
A9: 5 | B9: 1111005 | C9: ชิฟฟ่อน สอดไส้ (ล) 5 ชิ้น ครีมมะพร้าว | D9: กล่อง | E9: =+สรุป!E9 -> 0 | G9: =E9+F9 -> 0 | H9: 0 | I9: 0 | J9: =+G9-H9-K9-I9 -> 0 | L9: 85 | M9: =+L9*K9 -> 0 | N9: - | P9: =SUM(M9-O9) -> 0 | Q9: 22.65 | R9: =+K9*Q9 -> 0
A10: 6 | B10: 1111009 | C10: ชิฟฟ่อนเค้ก รวมรส (6 ชิ้น) | D10: กล่อง | E10: =+สรุป!E10 -> 0 | G10: =E10+F10 -> 0 | H10: 0 | I10: 0 | J10: =+G10-H10-K10-I10 -> 0 | L10: 100 | M10: =+L10*K10 -> 0 | N10: - | P10: =SUM(M10-O10) -> 0 | Q10: 27.98 | R10: =+K10*Q10 -> 0
A11: 7 | B11: 1111056 | C11: ชิฟฟ่อนรวมรส ยอดฮิต (8 ชิ้น) | D11: กล่อง | E11: =+สรุป!E11 -> 0 | G11: =E11+F11 -> 0 | H11: 0 | I11: 0 | J11: =+G11-H11-K11-I11 -> 0 | L11: 100 | M11: =+L11*K11 -> 0 | N11: - | P11: =SUM(M11-O11) -> 0 | Q11: 34.64 | R11: =+K11*Q11 -> 0
A12: 8 | B12: 1111006 | C12: ชิฟฟ่อนเค้ก วรรณวนัช (สอดไส้รวมรส 8 ชิ้น) | D12: กล่อง | E12: =+สรุป!E12 -> 0 | G12: =E12+F12 -> 0 | H12: 0 | I12: 0 | J12: =+G12-H12-K12-I12 -> 0 | L12: 130 | M12: =+L12*K12 -> 0 | N12: - | P12: =SUM(M12-O12) -> 0 | Q12: 46.37 | R12: =+K12*Q12 -> 0
A13: 9 | B13: 1111035 | C13: ชิฟฟ่อนเค้กมะพร้าวสอดไส้ครีมมะพร้าวล้วน (8 ชิ้น) | D13: กล่อง | E13: =+สรุป!E13 -> 0 | G13: =E13+F13 -> 0 | H13: 0 | I13: 0 | J13: =+G13-H13-K13-I13 -> 0 | L13: 130 | M13: =+L13*K13 -> 0 | N13: - | P13: =SUM(M13-O13) -> 0 | Q13: 38.9 | R13: =+K13*Q13 -> 0
A14: 10 | B14: 1004080 | C14: ครีมฮอร์น วนิลา | D14: กล่อง | E14: =+สรุป!E14 -> 0 | G14: =E14+F14 -> 0 | H14: 0 | I14: 0 | J14: =+G14-H14-K14-I14 -> 0 | L14: 50 | M14: =+L14*K14 -> 0 | N14: - | P14: =SUM(M14-O14) -> 0 | Q14: 27.84 | R14: =+K14*Q14 -> 0
A15: 11 | B15: 1004081 | C15: ครีมฮอร์น ใบเตย | D15: กล่อง | E15: =+สรุป!E15 -> 0 | G15: =E15+F15 -> 0 | H15: 0 | I15: 0 | J15: =+G15-H15-K15-I15 -> 0 | L15: 50 | M15: =+L15*K15 -> 0 | N15: - | P15: =SUM(M15-O15) -> 0 | Q15: 27.12 | R15: =+K15*Q15 -> 0
A16: 12 | B16: 3001200 | C16: ครีมฮอร์น ช็อคโกแลต | D16: กล่อง | E16: =+สรุป!E16 -> 0 | G16: =E16+F16 -> 0 | H16: 0 | I16: 0 | J16: =+G16-H16-K16-I16 -> 0 | L16: 50 | M16: =+L16*K16 -> 0 | N16: - | P16: =SUM(M16-O16) -> 0 | Q16: 15.42 | R16: =+K16*Q16 -> 0
A17: 13 | B17: 1112015 | C17: เค้กเบาหวิว รสกล้วยหอมหน้ามะพร้าวเผา 110 กรัม | D17: กล่อง | E17: =+สรุป!E17 -> 0 | G17: =E17+F17 -> 0 | H17: 0 | I17: 0 | J17: =+G17-H17-K17-I17 -> 0 | L17: 50 | M17: =+L17*K17 -> 0 | N17: - | P17: =SUM(M17-O17) -> 0 | Q17: 17.78 | R17: =+K17*Q17 -> 0
... A42: 38 | B42: 1113208 | C42: คุกกี้ฮ่องกงหอมเจียว | D42: ชิ้น | E42: =+สรุป!E42 -> 0 | G42: =E42+F42 -> 0 | H42: 0 | I42: 0 | J42: =+G42-H42-K42-I42 -> 0 | L42: 10 | M42: =+L42*K42 -> 0 | N42: - | P42: =SUM(M42-O42) -> 0 | Q42: 6.3 | R42: =+K42*Q42 -> 0
A43: 39 | B43: 1112400 | C43: ขนมปังกรอบรสคาราเมล 65 กรัม | D43: กล่อง | E43: =+สรุป!E43 -> 0 | G43: =E43+F43 -> 0 | H43: 0 | I43: 0 | J43: =+G43-H43-K43-I43 -> 0 | L43: 10 | M43: =+L43*K43 -> 0 | N43: - | P43: =SUM(M43-O43) -> 0 | R43: =+K43*Q43 -> 0
A44: 40 | B44: 1113171 | C44: ขนมเปี๊ยะฟักถั่วไข่เค็ม 450 กรัม | D44: กล่อง | E44: =+สรุป!E44 -> 0 | G44: =E44+F44 -> 0 | H44: 0 | I44: 0 | J44: =+G44-H44-K44-I44 -> 0 | L44: 150 | M44: =+L44*K44 -> 0 | N44: - | P44: =SUM(M44-O44) -> 0 | R44: =+K44*Q44 -> 0
A45: 41 | B45: 1113170 | C45: ขนมเปี๊ยะถั่วฝอยทองไข่เค็ม 450 กรัม | D45: กล่อง | E45: =+สรุป!E45 -> 0 | G45: =E45+F45 -> 0 | H45: 0 | I45: 0 | J45: =+G45-H45-K45-I45 -> 0 | L45: 150 | M45: =+L45*K45 -> 0 | N45: - | P45: =SUM(M45-O45) -> 0
A46: 42 | B46: 20054646 | C46: ขนมปังพิซซ่าโบโลน่า 80 กรัม | D46: กล่อง | E46: =+สรุป!E46 -> 0 | G46: =E46+F46 -> 0 | H46: 0 | I46: 0 | J46: =+G46-H46-K46-I46 -> 0 | L46: 25 | M46: =+L46*K46 -> 0 | N46: - | P46: =SUM(M46-O46) -> 0 | R46: =+K46*Q46 -> 0
A47: 43 | B47: 1113234 | C47: เค้กลอดช่องน้ำตาลโตนด 100 กรัม | D47: กล่อง | E47: =+สรุป!E47 -> 0 | G47: =E47+F47 -> 0 | H47: 0 | I47: 0 | J47: =+G47-H47-K47-I47 -> 0 | L47: 25 | M47: =+L47*K47 -> 0 | N47: - | P47: =SUM(M47-O47) -> 0 | R47: =+K47*Q47 -> 0
A48: 45 | B48: 20058428 | C48: ทาร์ตไข่คาราเมล 50 กรัม | D48: กล่อง | E48: =+สรุป!E48 -> 0 | G48: =E48+F48 -> 0 | H48: 0 | I48: 0 | J48: =+G48-H48-K48-I48 -> 0 | L48: 19 | M48: =+L48*K48 -> 0 | N48: - | P48: =SUM(M48-O48) -> 0 | R48: =+K48*Q48 -> 0
A49: 46 | B49: 1300047 | C49: ทาร์ตทุเรียนครีมกะทิ 65 กรัม | D49: กล่อง | E49: =+สรุป!E49 -> 0 | G49: =E49+F49 -> 0 | H49: 0 | I49: 0 | J49: =+G49-H49-K49-I49 -> 0 | L49: 25 | M49: =+L49*K49 -> 0 | N49: - | P49: =SUM(M49-O49) -> 0 | R49: =+K49*Q49 -> 0
A50: 47 | B50: 1113190 | C50: เค้กทุเรียน 90 กรัม | D50: กล่อง | E50: =+สรุป!E50 -> 0 | G50: =E50+F50 -> 0 | H50: 0 | I50: 0 | J50: =+G50-H50-K50-I50 -> 0 | L50: 25 | M50: =+L50*K50 -> 0 | N50: - | P50: =SUM(M50-O50) -> 0 | R50: =+K50*Q50 -> 0
A51: 48 | B51: 1113229 | C51: ทุเรียนชีสพาย 85 กรัม | D51: กล่อง | E51: =+สรุป!E51 -> 0 | G51: =E51+F51 -> 0 | H51: 0 | I51: 0 | J51: =+G51-H51-K51-I51 -> 0 | L51: 25 | M51: =+L51*K51 -> 0 | N51: - | P51: =SUM(M51-O51) -> 0 | R51: =+K51*Q51 -> 0
A52: 49 | B52: 1113226 | C52: เค้กโมลเทนช็อกโกแลต 75 กรัม | D52: กล่อง | E52: =+สรุป!E52 -> 0 | G52: =E52+F52 -> 0 | H52: 0 | I52: 0 | J52: =+G52-H52-K52-I52 -> 0 | L52: 35 | M52: =+L52*K52 -> 0 | N52: - | P52: =SUM(M52-O52) -> 0 | R52: =+K52*Q52 -> 0
A53: 50 | B53: 1113227 | C53: เค้กแอปเปิ้ล 70 กรัม | D53: กล่อง | E53: =+สรุป!E53 -> 0 | G53: =E53+F53 -> 0 | H53: 0 | I53: 0 | J53: =+G53-H53-K53-I53 -> 0 | L53: 35 | M53: =+L53*K53 -> 0 | N53: - | P53: =SUM(M53-O53) -> 0 | R53: =+K53*Q53 -> 0
A54: 51 | B54: 1113228 | C54: เค้กทอร์ต้าเทเนรินา 50 กรัม | D54: กล่อง | E54: =+สรุป!E54 -> 0 | G54: =E54+F54 -> 0 | H54: 0 | I54: 0 | J54: =+G54-H54-K54-I54 -> 0 | L54: 35 | M54: =+L54*K54 -> 0 | N54: - | P54: =SUM(M54-O54) -> 0 | R54: =+K54*Q54 -> 0
A55: 52 | B55: 1004111 | C55: ชิฟฟ่อนเค้กทุเรียน 240 กรัม | D55: กล่อง | E55: =+สรุป!E55 -> 0 | G55: =E55+F55 -> 0 | H55: 0 | I55: 0 | J55: =+G55-H55-K55-I55 -> 0 | L55: 120 | M55: =+L55*K55 -> 0 | N55: - | P55: =SUM(M55-O55) -> 0 | R55: =+K55*Q55 -> 0
A56: 53 | B56: 1004113 | C56: ชิฟฟ่อนเค้กรสสับปรด 240 กรัม | D56: กล่อง | E56: =+สรุป!E56 -> 0 | G56: =E56+F56 -> 0 | H56: 0 | I56: 0 | J56: =+G56-H56-K56-I56 -> 0 | L56: 120 | M56: =+L56*K56 -> 0 | N56: - | P56: =SUM(M56-O56) -> 0 | R56: =+K56*Q56 -> 0
A57: 54 | B57: 1004112 | C57: ชิฟฟ่อนเค้กรสเผือก 240 กรัม | D57: กล่อง | E57: =+สรุป!E57 -> 0 | G57: =E57+F57 -> 0 | H57: 0 | I57: 0 | J57: =+G57-H57-K57-I57 -> 0 | L57: 120 | M57: =+L57*K57 -> 0 | N57: - | P57: =SUM(M57-O57) -> 0 | R57: =+K57*Q57 -> 0
A58: 55 | B58: 1100045 | C58: ชิฟฟ่อน 8 ชิ้น ขนุนล้วน | D58: กล่อง | E58: =+สรุป!E58 -> 0 | G58: =E58+F58 -> 0 | H58: 0 | I58: 0 | J58: =+G58-H58-K58-I58 -> 0 | L58: 120 | M58: =+L58*K58 -> 0 | N58: - | P58: =SUM(M58-O58) -> 0 | R58: =+K58*Q58 -> 0
E59: =+สรุป!E59 -> 0 | G59: =E59+F59 -> 0 | H59: 0 | J59: =+G59-H59-K59-I59 -> 0 | R59: =+K59*Q59 -> 0
E60: =+สรุป!E60 -> 0 | G60: =E60+F60 -> 0 | H60: 0 | J60: =+G60-H60-K60-I60 -> 0 | R60: =+K60*Q60 -> 0
E61: =+สรุป!E61 -> 0 | G61: =E61+F61 -> 0 | H61: 0 | J61: =+G61-H61-K61-I61 -> 0 | R61: =+K61*Q61 -> 0
E62: =+สรุป!E62 -> 0 | G62: =E62+F62 -> 0 | H62: 0 | J62: =+G62-H62-K62-I62 -> 0 | R62: =+K62*Q62 -> 0
E63: =+สรุป!E63 -> 0 | G63: =E63+F63 -> 0 | H63: 0 | J63: =+G63-H63-K63-I63 -> 0 | R63: =+K63*Q63 -> 0
E64: =+สรุป!E64 -> 0 | G64: =E64+F64 -> 0 | H64: 0 | J64: =+G64-H64-K64-I64 -> 0 | R64: =+K64*Q64 -> 0
E65: =+สรุป!E65 -> 0 | G65: =E65+F65 -> 0 | J65: =+G65-H65-K65-I65 -> 0 | R65: =+K65*Q65 -> 0
...

Sheet 29
A2: บูธ EVENT งานเกษตรแฟร์กำแพงแสน 30 พ.ย. 67 - 10 ธ.ค. 67
A3: ลำดับ | B3: รหัสสินค้า (POS) | C3: รายการ | D3: หน่วย | E3: ยกมา | F3: รับ | G3: รวม | H3: เปลี่ยน/ | I3: โยกย้าย / ระบาย | J3: คงเหลือ | K3: รายการขาย | N3: หมายเหตุ | O3: ส่วนลด | Q3: ราคาต้นทุน | R3: ยอดรวมต้นทุนสินค้า
H4: คืน/เสีย | K4: จำนวน | L4: @ | M4: เป็นเงิน
A5: 1 | B5: 1004055 | C5: ชิฟฟ่อนเค้ก รวมรส (4 ชิ้น) | D5: กล่อง | E5: =+สรุป!E5 -> 0 | F5: 50 | G5: =E5+F5 -> 50 | H5: 0 | I5: 0 | J5: =+G5-H5-K5-I5 -> 32 | K5: 18 | L5: 50 | M5: =+L5*K5 -> 900 | N5: - | P5: =SUM(M5-O5) -> 900 | Q5: 18.97 | R5: =+K5*Q5 -> 341.46
A6: 2 | B6: 1111002 | C6: ชิฟฟ่อนเค้ก รวมรส (8 ชิ้น) | D6: กล่อง | E6: =+สรุป!E6 -> 0 | F6: 50 | G6: =E6+F6 -> 50 | H6: 0 | I6: 0 | J6: =+G6-H6-K6-I6 -> 32 | K6: 18 | L6: 100 | M6: =+L6*K6 -> 1800 | N6: - | P6: =SUM(M6-O6) -> 1800 | Q6: 36.43 | R6: =+K6*Q6 -> 655.74
A7: 3 | B7: 1111008 | C7: ชิฟฟ่อนเค้ก รวมรส (3 ชิ้น) | D7: กล่อง | E7: =+สรุป!E7 -> 0 | F7: 50 | G7: =E7+F7 -> 50 | H7: 0 | I7: 0 | J7: =+G7-H7-K7-I7 -> 43 | K7: 7 | L7: 50 | M7: =+L7*K7 -> 350 | N7: - | P7: =SUM(M7-O7) -> 350 | Q7: 19.36 | R7: =+K7*Q7 -> 135.52
A8: 4 | B8: 1111004 | C8: ชิฟฟ่อน สอดไส้ (ล) 4 ชิ้น ครีมมะพร้าว | D8: กล่อง | E8: =+สรุป!E8 -> 0 | F8: 5 | G8: =E8+F8 -> 5 | H8: 0 | I8: 0 | J8: =+G8-H8-K8-I8 -> 5 | L8: 65 | M8: =+L8*K8 -> 0 | N8: - | P8: =SUM(M8-O8) -> 0 | Q8: 22.25 | R8: =+K8*Q8 -> 0
A9: 5 | B9: 1111005 | C9: ชิฟฟ่อน สอดไส้ (ล) 5 ชิ้น ครีมมะพร้าว | D9: กล่อง | E9: =+สรุป!E9 -> 0 | F9: 5 | G9: =E9+F9 -> 5 | H9: 0 | I9: 0 | J9: =+G9-H9-K9-I9 -> 4 | K9: 1 | L9: 85 | M9: =+L9*K9 -> 85 | N9: - | P9: =SUM(M9-O9) -> 85 | Q9: 22.65 | R9: =+K9*Q9 -> 22.65
A10: 6 | B10: 1111009 | C10: ชิฟฟ่อนเค้ก รวมรส (6 ชิ้น) | D10: กล่อง | E10: =+สรุป!E10 -> 0 | F10: 50 | G10: =E10+F10 -> 50 | H10: 0 | I10: 0 | J10: =+G10-H10-K10-I10 -> 34 | K10: 16 | L10: 100 | M10: =+L10*K10 -> 1600 | N10: - | P10: =SUM(M10-O10) -> 1600 | Q10: 27.98 | R10: =+K10*Q10 -> 447.68
A11: 7 | B11: 1111056 | C11: ชิฟฟ่อนรวมรส ยอดฮิต (8 ชิ้น) | D11: กล่อง | E11: =+สรุป!E11 -> 0 | F11: 50 | G11: =E11+F11 -> 50 | H11: 0 | I11: 0 | J11: =+G11-H11-K11-I11 -> 36 | K11: 14 | L11: 100 | M11: =+L11*K11 -> 1400 | N11: - | P11: =SUM(M11-O11) -> 1400 | Q11: 34.64 | R11: =+K11*Q11 -> 484.96
A12: 8 | B12: 1111006 | C12: ชิฟฟ่อนเค้ก วรรณวนัช (สอดไส้รวมรส 8 ชิ้น) | D12: กล่อง | E12: =+สรุป!E12 -> 0 | F12: 5 | G12: =E12+F12 -> 5 | H12: 0 | I12: 0 | J12: =+G12-H12-K12-I12 -> 2 | K12: 3 | L12: 130 | M12: =+L12*K12 -> 390 | N12: - | P12: =SUM(M12-O12) -> 390 | Q12: 46.37 | R12: =+K12*Q12 -> 139.11
A13: 9 | B13: 1111035 | C13: ชิฟฟ่อนเค้กมะพร้าวสอดไส้ครีมมะพร้าวล้วน (8 ชิ้น) | D13: กล่อง | E13: =+สรุป!E13 -> 0 | F13: 5 | G13: =E13+F13 -> 5 | H13: 0 | I13: 0 | J13: =+G13-H13-K13-I13 -> 2 | K13: 3 | L13: 130 | M13: =+L13*K13 -> 390 | N13: - | P13: =SUM(M13-O13) -> 390 | Q13: 38.9 | R13: =+K13*Q13 -> 116.7
A14: 10 | B14: 1004080 | C14: ครีมฮอร์น วนิลา | D14: กล่อง | E14: =+สรุป!E14 -> 0 | F14: 20 | G14: =E14+F14 -> 20 | H14: 0 | I14: 0 | J14: =+G14-H14-K14-I14 -> 12 | K14: 8 | L14: 50 | M14: =+L14*K14 -> 400 | N14: - | P14: =SUM(M14-O14) -> 400 | Q14: 27.84 | R14: =+K14*Q14 -> 222.72
A15: 11 | B15: 1004081 | C15: ครีมฮอร์น ใบเตย | D15: กล่อง | E15: =+สรุป!E15 -> 0 | F15: 15 | G15: =E15+F15 -> 15 | H15: 0 | I15: 0 | J15: =+G15-H15-K15-I15 -> 14 | K15: 1 | L15: 50 | M15: =+L15*K15 -> 50 | N15: - | P15: =SUM(M15-O15) -> 50 | Q15: 27.12 | R15: =+K15*Q15 -> 27.12
A16: 12 | B16: 3001200 | C16: ครีมฮอร์น ช็อคโกแลต | D16: กล่อง | E16: =+สรุป!E16 -> 0 | F16: 20 | G16: =E16+F16 -> 20 | H16: 0 | I16: 0 | J16: =+G16-H16-K16-I16 -> 19 | K16: 1 | L16: 50 | M16: =+L16*K16 -> 50 | N16: - | P16: =SUM(M16-O16) -> 50 | Q16: 15.42 | R16: =+K16*Q16 -> 15.42
A17: 13 | B17: 1112015 | C17: เค้กเบาหวิว รสกล้วยหอมหน้ามะพร้าวเผา 110 กรัม | D17: กล่อง | E17: =+สรุป!E17 -> 0 | F17: 15 | G17: =E17+F17 -> 15 | H17: 0 | I17: 0 | J17: =+G17-H17-K17-I17 -> 12 | K17: 3 | L17: 50 | M17: =+L17*K17 -> 150 | N17: - | P17: =SUM(M17-O17) -> 150 | Q17: 17.78 | R17: =+K17*Q17 -> 53.34
A18: 14 | B18: 1112013 | C18: เค้กเบาหวิว เผือกมะพร้าวอ่อน110 กรัม | D18: กล่อง | E18: =+สรุป!E18 -> 0 | F18: 15 | G18: =E18+F18 -> 15 | H18: 0 | I18: 0 | J18: =+G18-H18-K18-I18 -> 14 | K18: 1 | L18: 50 | M18: =+L18*K18 -> 50 | N18: - | P18: =SUM(M18-O18) -> 50 | Q18: 17.99 | R18: =+K18*Q18 -> 17.99
A19: 15 | B19: 1112003 | C19: เค้กเบาหวิว รสกาแฟ 110 กรัม | D19: กล่อง | E19: =+สรุป!E19 -> 0 | F19: 15 | G19: =E19+F19 -> 15 | H19: 0 | I19: 0 | J19: =+G19-H19-K19-I19 -> 14 | K19: 1 | L19: 50 | M19: =+L19*K19 -> 50 | N19: - | P19: =SUM(M19-O19) -> 50 | Q19: 20.06 | R19: =+K19*Q19 -> 20.06
A20: 16 | B20: 1112003 | C20: เค้กเบาหวิว รสเนยนม 110 กรัม | D20: กล่อง | E20: =+สรุป!E20 -> 0 | F20: 15 | G20: =E20+F20 -> 15 | H20: 0 | I20: 0 | J20: =+G20-H20-K20-I20 -> 15 | L20: 50 | M20: =+L20*K20 -> 0 | N20: - | P20: =SUM(M20-O20) -> 0 | Q20: 20.32 | R20: =+K20*Q20 -> 0
A21: 17 | B21: 1112011 | C21: เค้กเบาหวิว หน้าฝอยทอง 110 กรัม | D21: กล่อง | E21: =+สรุป!E21 -> 0 | F21: 15 | G21: =E21+F21 -> 15 | H21: 0 | I21: 0 | J21: =+G21-H21-K21-I21 -> 11 | K21: 4 | L21: 50 | M21: =+L21*K21 -> 200 | N21: - | P21: =SUM(M21-O21) -> 200 | Q21: 16.37 | R21: =+K21*Q21 -> 65.48
A22: 18 | B22: 1112015 | C22: เค้กเบาหวิว รสกล้วยหอมหน้ามะพร้าวเผา 300 กรัม | D22: กล่อง | E22: =+สรุป!E22 -> 0 | F22: 9 | G22: =E22+F22 -> 9 | H22: 0 | I22: 0 | J22: =+G22-H22-K22-I22 -> 9 | L22: 120 | M22: =+L22*K22 -> 0 | N22: - | P22: =SUM(M22-O22) -> 0 | Q22: 25.99 | R22: =+K22*Q22 -> 0
A23: 19 | B23: 1112012 | C23: เค้กเบาหวิว รสเผือกหน้ามะพร้าวเผา 300 กรัม | D23: กล่อง | E23: =+สรุป!E23 -> 0 | F23: 10 | G23: =E23+F23 -> 10 | H23: 0 | I23: 0 | J23: =+G23-H23-K23-I23 -> 10 | L23: 120 | M23: =+L23*K23 -> 0 | N23: - | P23: =SUM(M23-O23) -> 0 | Q23: 28.31 | R23: =+K23*Q23 -> 0
A24: 20 | B24: 1112002 | C24: เค้กเบาหวิว รสกาแฟ 300 กรัม | D24: กล่อง | E24: =+สรุป!E24 -> 0 | F24: 10 | G24: =E24+F24 -> 10 | H24: 0 | I24: 0 | J24: =+G24-H24-K24-I24 -> 10 | L24: 120 | M24: =+L24*K24 -> 0 | N24: - | P24: =SUM(M24-O24) -> 0 | Q24: 31.07 | R24: =+K24*Q24 -> 0
A25: 21 | B25: 1112004 | C25: เค้กเบาหวิว รสเนยนม 300 กรัม | D25: กล่อง | E25: =+สรุป!E25 -> 0 | F25: 10 | G25: =E25+F25 -> 10 | H25: 0 | I25: 0 | J25: =+G25-H25-K25-I25 -> 9 | K25: 1 | L25: 120 | M25: =+L25*K25 -> 120 | N25: - | P25: =SUM(M25-O25) -> 120 | Q25: 29.83 | R25: =+K25*Q25 -> 29.83
A26: 22 | B26: 1112010 | C26: เค้กเบาหวิว หน้าฝอยทอง 300 กรัม | D26: กล่อง | E26: =+สรุป!E26 -> 0 | F26: 10 | G26: =E26+F26 -> 10 | H26: 0 | I26: 0 | J26: =+G26-H26-K26-I26 -> 8 | K26: 2 | L26: 120 | M26: =+L26*K26 -> 240 | N26: - | P26: =SUM(M26-O26) -> 240 | Q26: 26.39 | R26: =+K26*Q26 -> 52.78
A27: 23 | B27: 1113008 | C27: เค้กโบราณรวมรส 4 ชิ้น | D27: กล่อง | E27: =+สรุป!E27 -> 0 | F27: 5 | G27: =E27+F27 -> 5 | H27: 0 | I27: 0 | J27: =+G27-H27-K27-I27 -> 5 | L27: 50 | M27: =+L27*K27 -> 0 | N27: - | P27: =SUM(M27-O27) -> 0 | Q27: 23.69 | R27: =+K27*Q27 -> 0
A28: 24 | B28: 1113006 | C28: เค้กโบราณครีม 4 ชิ้น | D28: กล่อง | E28: =+สรุป!E28 -> 0 | F28: 5 | G28: =E28+F28 -> 5 | H28: 0 | I28: 0 | J28: =+G28-H28-K28-I28 -> 3 | K28: 2 | L28: 50 | M28: =+L28*K28 -> 100 | N28: - | P28: =SUM(M28-O28) -> 100 | Q28: 22.49 | R28: =+K28*Q28 -> 44.98
A29: 25 | B29: 1004062 | C29: เค้กลาวา ฝอยทองทูโทน เล็ก | D29: กล่อง | E29: =+สรุป!E29 -> 0 | F29: 5 | G29: =E29+F29 -> 5 | H29: 0 | I29: 0 | J29: =+G29-H29-K29-I29 -> 4 | K29: 1 | L29: 50 | M29: =+L29*K29 -> 50 | N29: - | P29: =SUM(M29-O29) -> 50 | Q29: 17.09 | R29: =+K29*Q29 -> 17.09
A30: 26 | B30: 1004076 | C30: เอแคลร์นมสด 8 ชิ้น | D30: กล่อง | E30: =+สรุป!E30 -> 0 | F30: 20 | G30: =E30+F30 -> 20 | H30: 0 | I30: 0 | J30: =+G30-H30-K30-I30 -> 5 | K30: 15 | L30: 50 | M30: =+L30*K30 -> 750 | N30: - | P30: =SUM(M30-O30) -> 750 | Q30: 25.15 | R30: =+K30*Q30 -> 377.25
A31: 27 | B31: 1004063 | C31: ซอฟ์ทเค้กช็อคโกแลตหน้านิ่ม | D31: กล่อง | E31: =+สรุป!E31 -> 0 | F31: 5 | G31: =E31+F31 -> 5 | H31: 0 | I31: 0 | J31: =+G31-H31-K31-I31 -> 1 | K31: 4 | L31: 55 | M31: =+L31*K31 -> 220 | N31: - | P31: =SUM(M31-O31) -> 220 | Q31: 14.35 | R31: =+K31*Q31 -> 57.4
A32: 28 | B32: 1004065 | C32: ซอฟ์ทเค้กมะพร้าวนมสดหน้านิ่ม | D32: กล่อง | E32: =+สรุป!E32 -> 0 | F32: 5 | G32: =E32+F32 -> 5 | H32: 0 | I32: 0 | J32: =+G32-H32-K32-I32 -> 4 | K32: 1 | L32: 55 | M32: =+L32*K32 -> 55 | N32: - | P32: =SUM(M32-O32) -> 55 | Q32: 19.58 | R32: =+K32*Q32 -> 19.58
A33: 29 | B33: 1200003 | C33: ท๊อฟฟี่ถั่ว (กระเช้า) | D33: กระเช้า | E33: =+สรุป!E33 -> 0 | F33: 20 | G33: =E33+F33 -> 20 | H33: 0 | I33: 0 | J33: =+G33-H33-K33-I33 -> 17 | K33: 3 | L33: 100 | M33: =+L33*K33 -> 300 | N33: - | P33: =SUM(M33-O33) -> 300 | Q33: 23.61 | R33: =+K33*Q33 -> 70.83
