Workbook

Sheet เช้า 
B1: ยอดจริง ออนไลน์ วันที่ 20/6/68เช้า
L2: ยอดรวมผลิต
L3: จำนวน
B4: รหัสสินค้า | C4: สินค้า | D4: ปณ | E4: ชอปปี้ | F4: ลาซาด้า | G4: ติ๊กตอก | H4: ติ๊กตอก 2 | I4: ติ๊กตอก3 | J4: ชอยส์ | K4: ยอดเส้น | L4: (กล่อง)
B6: ชิฟฟอนรวมรส
B7: 1111002 | C7: ชิฟฟอนรวมรส 8 ชิ้น | D7: 2 | E7: 2 | F7: 12 | G7: 10 | L7: =SUM(D7:K7) -> 26
C8: ชิฟฟอนแบบกล่องสุ่มอะไรก็ได้ที่มี | L8: =SUM(D8:K8) -> 0
B9: 1111084 | C9: ชิฟฟอน 8 ชิ้น กาแฟล้วน | L9: =SUM(D9:K9) -> 0
B10: 1111085 | C10: ชิฟฟอน 8 ชิ้น บลูเบอรี่ล้วน | L10: =SUM(D10:K10) -> 0
B11: 1111086 | C11: ชิฟฟอน 8 ชิ้น มะพร้าวล้วน | L11: =SUM(D11:K11) -> 0
B12: 1111087 | C12: ชิฟฟอน 8 ชิ้น สตอเบอรี่ล้วน | L12: =SUM(D12:K12) -> 0
B13: 1111088 | C13: ชิฟฟอน 8 ชิ้น ส้มล้วน | L13: =SUM(D13:K13) -> 0
B14: 1111089 | C14: ชิฟฟอน 8 ชิ้น เนยล้วน | L14: =SUM(D14:K14) -> 0
B15: 1111090 | C15: ชิฟฟอน 8 ชิ้น เผือกล้วน | L15: =SUM(D15:K15) -> 0
B16: 1111091 | C16: ชิฟฟอน 8 ชิ้น ใบเตยล้วน | L16: =SUM(D16:K16) -> 0
B17: 1111092 | C17: ชิฟฟอน 8 ชิ้น กล้วยหอม | L17: =SUM(D17:K17) -> 0
B18: 1111093 | C18: ชิฟฟอน 8 ชิ้น โกโก้ล้วน | L18: =SUM(D18:K18) -> 0
B19: 1111094 | C19: ชิฟฟอน 8 ชิ้น ชาไทยล้วน | L19: =SUM(D19:K19) -> 0
B20: 1111095 | C20: ชิฟฟอน 8 ชิ้น ชาเขียวล้วน | L20: =SUM(D20:K20) -> 0
... B24: 1111043 | C24: ชิฟฟอน 8 ชิ้น มะลิ | L24: =SUM(D24:K24) -> 0
B25: 1111056 | C25: ชิฟฟอน 8 ชิ้น รวมรสยอดฮิต | D25: 1 | F25: 3 | G25: 1 | L25: =SUM(D25:K25) -> 5
B26: 1004055 | C26: ชิฟฟอนรวมรส 4 ชิ้น | G26: 33 | K26: 30 | L26: =SUM(D26:K26) -> 63
B27: 1004055 | C27: ชิฟฟอน 4 ชิ้น โกโก้ล้วน | L27: =SUM(D27:K27) -> 0
B28: 1004055 | C28: ชิฟฟอน 4 ชิ้น มะพร้าวล้วน | L28: =SUM(D28:K28) -> 0
B29: 1004055 | C29: ชิฟฟอน 4 ชิ้น เนยล้วน | L29: =SUM(D29:K29) -> 0
B30: 1004055 | C30: ชิฟฟอน 4 ชิ้น กาแฟล้วน | L30: =SUM(D30:K30) -> 0
B31: 1004055 | C31: ชิฟฟอน 4 ชิ้น ใบเตยล้วน | L31: =SUM(D31:K31) -> 0
B32: 1004055 | C32: ชิฟฟอน 4 ชิ้น บลูเบอร์รี่ล้วน | L32: =SUM(D32:K32) -> 0
B33: 1004055 | C33: ชิฟฟอน 4 ชิ้น ส้มล้วน | L33: =SUM(D33:K33) -> 0
B34: 1004055 | C34: ชิฟฟอน 4 ชิ้น เผือกล้วน | L34: =SUM(D34:K34) -> 0
B35: 1004055 | C35: ชิฟฟอน 4 ชิ้น สตอเบอรี่ล้วน | L35: =SUM(D35:K35) -> 0
B36: 1004055 | C36: ชิฟฟอน 4 ชิ้น กล้วยหอมล้วน | L36: =SUM(D36:K36) -> 0
B37: 1004055 | C37: ชิฟฟอน 4 ชิ้น ชาเขียวล้วน | L37: =SUM(D37:K37) -> 0
B38: 1004055 | C38: ชิฟฟอน 4 ชิ้น ชาไทยล้วน | L38: =SUM(D38:K38) -> 0
B39: 1004055 | C39: ชิฟฟอน 4 ชิ้น สับปะรดล้วน | L39: =SUM(D39:K39) -> 0
B40: 1111057 | C40: ชิฟฟอนแยกชิ้น กาแฟ | E40: 27 | L40: =SUM(D40:K40) -> 27
B41: 1111058 | C41: ชิฟฟอนแยกชิ้น ชาเขียว | E41: 27 | L41: =SUM(D41:K41) -> 27
B42: 1111059 | C42: ชิฟฟอนแยกชิ้น ใบเตย | E42: 27 | L42: =SUM(D42:K42) -> 27
B43: 1111060 | C43: ชิฟฟอนแยกชิ้น กล้วยหอม | E43: 27 | L43: =SUM(D43:K43) -> 27
B44: 1111061 | C44: ชิฟฟอนแยกชิ้น ชาไทย | E44: 27 | L44: =SUM(D44:K44) -> 27
...

Sheet เย็น 
B1: ยอดจริง ออนไลน์ วันที่ - เย็น
L2: ยอดรวมผลิต
L3: จำนวน
B4: รหัสสินค้า | C4: สินค้า | D4: ปณ | E4: ชอปปี้ | F4: ลาซาด้า | G4: ติ๊กตอก | H4: ติ๊กตอก 2 | I4: ติ๊กตอก3 | J4: ชอยส์ | K4: ยอดเส้น | L4: (กล่อง)
B6: ชิฟฟอนรวมรส
B7: 1111002 | C7: ชิฟฟอนรวมรส 8 ชิ้น | L7: =SUM(D7:K7) -> 0
C8: ชิฟฟอนแบบกล่องสุ่มอะไรก็ได้ที่มี | L8: =SUM(D8:K8) -> 0
B9: 1111084 | C9: ชิฟฟอน 8 ชิ้น กาแฟล้วน | L9: =SUM(D9:K9) -> 0
B10: 1111085 | C10: ชิฟฟอน 8 ชิ้น บลูเบอรี่ล้วน | L10: =SUM(D10:K10) -> 0
B11: 1111086 | C11: ชิฟฟอน 8 ชิ้น มะพร้าวล้วน | L11: =SUM(D11:K11) -> 0
B12: 1111087 | C12: ชิฟฟอน 8 ชิ้น สตอเบอรี่ล้วน | L12: =SUM(D12:K12) -> 0
B13: 1111088 | C13: ชิฟฟอน 8 ชิ้น ส้มล้วน | L13: =SUM(D13:K13) -> 0
B14: 1111089 | C14: ชิฟฟอน 8 ชิ้น เนยล้วน | L14: =SUM(D14:K14) -> 0
B15: 1111090 | C15: ชิฟฟอน 8 ชิ้น เผือกล้วน | L15: =SUM(D15:K15) -> 0
B16: 1111091 | C16: ชิฟฟอน 8 ชิ้น ใบเตยล้วน | L16: =SUM(D16:K16) -> 0
B17: 1111092 | C17: ชิฟฟอน 8 ชิ้น กล้วยหอม | L17: =SUM(D17:K17) -> 0
B18: 1111093 | C18: ชิฟฟอน 8 ชิ้น โกโก้ล้วน | L18: =SUM(D18:K18) -> 0
B19: 1111094 | C19: ชิฟฟอน 8 ชิ้น ชาไทยล้วน | L19: =SUM(D19:K19) -> 0
B20: 1111095 | C20: ชิฟฟอน 8 ชิ้น ชาเขียวล้วน | L20: =SUM(D20:K20) -> 0
... B66: 1111010 | C66: ชิฟฟอนไส้แยมแยกชิ้น คละรส | L66: =SUM(D66:K66) -> 0
C67: รวม | L67: =SUM(L7:L66) -> 0
B68: ชิฟฟอนไส้แยม 6 ชิ้น
B69: 1111009 | C69: ชิฟฟอนไส้แยมรวมรส 6 ชิ้น | L69: =SUM(D69:K69) -> 0
B70: 1111023 | C70: ชิฟฟอนไส้แยมรสสตอเบอร์รี่ล้วน 6 ชิ้น | L70: =SUM(D70:K70) -> 0
B71: 1111016 | C71: ชิฟฟอนไส้แยมรสมะพร้าวล้วน 6 ชิ้น | L71: =SUM(D71:K71) -> 0
B72: 1111014 | C72: ชิฟฟอนไส้แยมรสช็อกโกแลตนูเทลล่าล้วน 6 ชิ้น | L72: =SUM(D72:K72) -> 0
B73: 1111025 | C73: ชิฟฟอนไส้แยมรสส้มล้วน 6 ชิ้น | L73: =SUM(D73:K73) -> 0
B74: 1111018 | C74: ชิฟฟอนไส้แยมรสบลูเบอร์รี่ล้วน 6 ชิ้น | L74: =SUM(D74:K74) -> 0
B75: 1111012 | C75: ชิฟฟอนไส้แยมรสนมชมพูฮอกไกโดล้วน 6 ชิ้น | L75: =SUM(D75:K75) -> 0
B76: 1111020 | C76: ชิฟฟอนไส้แยมฝอยทองไส้ทะลัก 6 ชิ้น | L76: =SUM(D76:K76) -> 0
C77: รวม | L77: =SUM(L69:L76) -> 0
B78: ชิฟฟอนไส้แยม 3 ชิ้น
B79: 1111022 | C79: ชิฟฟอนไส้แยมรสสตอเบอร์รี่ล้วน 3 ชิ้น | L79: =SUM(D79:K79) -> 0
B80: 1111015 | C80: ชิฟฟอนไส้แยมรสมะพร้าวล้วน 3 ชิ้น | L80: =SUM(D80:K80) -> 0
B81: 1111013 | C81: ชิฟฟอนไส้แยมรสช็อกโกแลตนูเทลล่าล้วน 3 ชิ้น | L81: =SUM(D81:K81) -> 0
B82: 1111024 | C82: ชิฟฟอนไส้แยมรสส้มล้วน 3 ชิ้น | L82: =SUM(D82:K82) -> 0
B83: 1111017 | C83: ชิฟฟอนไส้แยมรสบลูเบอร์รี่ล้วน 3 ชิ้น | L83: =SUM(D83:K83) -> 0
B84: 1111011 | C84: ชิฟฟอนไส้แยมรสนมชมพูฮอกไกโดล้วน 3 ชิ้น | L84: =SUM(D84:K84) -> 0
B85: 1111019 | C85: ชิฟฟอนไส้แยมฝอยทองไส้ทะลัก 3 ชิ้น | L85: =SUM(D85:K85) -> 0
B86: 1113081 | C86: ชิฟฟอนไส้แยม วนิลา/ใบเตย/เมล่อน | L86: =SUM(D86:K86) -> 0
...

Sheet บ่าย
B1: ยอดจริง ออนไลน์ วันที่ 20/6/68 บ่าย
M2: ยอดรวมผลิต
M3: จำนวน
B4: รหัสสินค้า | C4: สินค้า | D4: ปณ | E4: ชอปปี้ | F4: ลาซาด้า | G4: ติ๊กตอก | H4: ติ๊กตอก 2 | I4: ติ๊กตอก3 | J4: รวม TT | K4: ชอยส์ | L4: ยอดเส้น | M4: (กล่อง)
B6: ชิฟฟอนรวมรส
B7: 1111002 | C7: ชิฟฟอนรวมรส 8 ชิ้น | E7: 6 | F7: 9 | G7: 3 | J7: =+G7+H7+I7 -> 3 | M7: =+D7+E7+F7+J7+K7+L7 -> 18
C8: ชิฟฟอนแบบกล่องสุ่มอะไรก็ได้ที่มี | J8: =+G8+H8+I8 -> 0 | M8: =+D8+E8+F8+J8+K8+L8 -> 0
B9: 1111084 | C9: ชิฟฟอน 8 ชิ้น กาแฟล้วน | J9: =+G9+H9+I9 -> 0 | M9: =+D9+E9+F9+J9+K9+L9 -> 0
B10: 1111085 | C10: ชิฟฟอน 8 ชิ้น บลูเบอรี่ล้วน | J10: =+G10+H10+I10 -> 0 | M10: =+D10+E10+F10+J10+K10+L10 -> 0
B11: 1111086 | C11: ชิฟฟอน 8 ชิ้น มะพร้าวล้วน | J11: =+G11+H11+I11 -> 0 | M11: =+D11+E11+F11+J11+K11+L11 -> 0
B12: 1111087 | C12: ชิฟฟอน 8 ชิ้น สตอเบอรี่ล้วน | J12: =+G12+H12+I12 -> 0 | M12: =+D12+E12+F12+J12+K12+L12 -> 0
B13: 1111088 | C13: ชิฟฟอน 8 ชิ้น ส้มล้วน | J13: =+G13+H13+I13 -> 0 | M13: =+D13+E13+F13+J13+K13+L13 -> 0
B14: 1111089 | C14: ชิฟฟอน 8 ชิ้น เนยล้วน | J14: =+G14+H14+I14 -> 0 | M14: =+D14+E14+F14+J14+K14+L14 -> 0
B15: 1111090 | C15: ชิฟฟอน 8 ชิ้น เผือกล้วน | J15: =+G15+H15+I15 -> 0 | M15: =+D15+E15+F15+J15+K15+L15 -> 0
B16: 1111091 | C16: ชิฟฟอน 8 ชิ้น ใบเตยล้วน | J16: =+G16+H16+I16 -> 0 | M16: =+D16+E16+F16+J16+K16+L16 -> 0
B17: 1111092 | C17: ชิฟฟอน 8 ชิ้น กล้วยหอม | J17: =+G17+H17+I17 -> 0 | M17: =+D17+E17+F17+J17+K17+L17 -> 0
B18: 1111093 | C18: ชิฟฟอน 8 ชิ้น โกโก้ล้วน | J18: =+G18+H18+I18 -> 0 | M18: =+D18+E18+F18+J18+K18+L18 -> 0
B19: 1111094 | C19: ชิฟฟอน 8 ชิ้น ชาไทยล้วน | J19: =+G19+H19+I19 -> 0 | M19: =+D19+E19+F19+J19+K19+L19 -> 0
B20: 1111095 | C20: ชิฟฟอน 8 ชิ้น ชาเขียวล้วน | J20: =+G20+H20+I20 -> 0 | M20: =+D20+E20+F20+J20+K20+L20 -> 0
... B24: 1111043 | C24: ชิฟฟอน 8 ชิ้น มะลิ | J24: =+G24+H24+I24 -> 0 | M24: =+D24+E24+F24+J24+K24+L24 -> 0
B25: 1111056 | C25: ชิฟฟอน 8 ชิ้น รวมรสยอดฮิต | G25: 1 | J25: =+G25+H25+I25 -> 1 | M25: =+D25+E25+F25+J25+K25+L25 -> 1
B26: 1004055 | C26: ชิฟฟอนรวมรส 4 ชิ้น | G26: 12 | J26: =+G26+H26+I26 -> 12 | M26: =+D26+E26+F26+J26+K26+L26 -> 12
B27: 1004055 | C27: ชิฟฟอน 4 ชิ้น โกโก้ล้วน | J27: =+G27+H27+I27 -> 0 | M27: =+D27+E27+F27+J27+K27+L27 -> 0
B28: 1004055 | C28: ชิฟฟอน 4 ชิ้น มะพร้าวล้วน | J28: =+G28+H28+I28 -> 0 | M28: =+D28+E28+F28+J28+K28+L28 -> 0
B29: 1004055 | C29: ชิฟฟอน 4 ชิ้น เนยล้วน | J29: =+G29+H29+I29 -> 0 | M29: =+D29+E29+F29+J29+K29+L29 -> 0
B30: 1004055 | C30: ชิฟฟอน 4 ชิ้น กาแฟล้วน | J30: =+G30+H30+I30 -> 0 | M30: =+D30+E30+F30+J30+K30+L30 -> 0
B31: 1004055 | C31: ชิฟฟอน 4 ชิ้น ใบเตยล้วน | J31: =+G31+H31+I31 -> 0 | M31: =+D31+E31+F31+J31+K31+L31 -> 0
B32: 1004055 | C32: ชิฟฟอน 4 ชิ้น บลูเบอร์รี่ล้วน | J32: =+G32+H32+I32 -> 0 | M32: =+D32+E32+F32+J32+K32+L32 -> 0
B33: 1004055 | C33: ชิฟฟอน 4 ชิ้น ส้มล้วน | J33: =+G33+H33+I33 -> 0 | M33: =+D33+E33+F33+J33+K33+L33 -> 0
B34: 1004055 | C34: ชิฟฟอน 4 ชิ้น เผือกล้วน | J34: =+G34+H34+I34 -> 0 | M34: =+D34+E34+F34+J34+K34+L34 -> 0
B35: 1004055 | C35: ชิฟฟอน 4 ชิ้น สตอเบอรี่ล้วน | J35: =+G35+H35+I35 -> 0 | M35: =+D35+E35+F35+J35+K35+L35 -> 0
B36: 1004055 | C36: ชิฟฟอน 4 ชิ้น กล้วยหอมล้วน | J36: =+G36+H36+I36 -> 0 | M36: =+D36+E36+F36+J36+K36+L36 -> 0
B37: 1004055 | C37: ชิฟฟอน 4 ชิ้น ชาเขียวล้วน | J37: =+G37+H37+I37 -> 0 | M37: =+D37+E37+F37+J37+K37+L37 -> 0
B38: 1004055 | C38: ชิฟฟอน 4 ชิ้น ชาไทยล้วน | J38: =+G38+H38+I38 -> 0 | M38: =+D38+E38+F38+J38+K38+L38 -> 0
... B66: 1111010 | C66: ชิฟฟอนไส้แยมแยกชิ้น คละรส | J66: =+G66+H66+I66 -> 0 | M66: =+D66+E66+F66+J66+K66+L66 -> 0
C67: รวม | J67: =+G67+H67+I67 -> 0 | M67: =+D67+E67+F67+J67+K67+L67 -> 0
B68: ชิฟฟอนไส้แยม 6 ชิ้น | J68: =+G68+H68+I68 -> 0 | M68: =+D68+E68+F68+J68+K68+L68 -> 0
B69: 1111009 | C69: ชิฟฟอนไส้แยมรวมรส 6 ชิ้น | J69: =+G69+H69+I69 -> 0 | M69: =+D69+E69+F69+J69+K69+L69 -> 0
B70: 1111023 | C70: ชิฟฟอนไส้แยมรสสตอเบอร์รี่ล้วน 6 ชิ้น | J70: =+G70+H70+I70 -> 0 | M70: =+D70+E70+F70+J70+K70+L70 -> 0
B71: 1111016 | C71: ชิฟฟอนไส้แยมรสมะพร้าวล้วน 6 ชิ้น | J71: =+G71+H71+I71 -> 0 | M71: =+D71+E71+F71+J71+K71+L71 -> 0
...

Sheet รวม
B1: ยอดจริง ออนไลน์ วันที่ 20/6/68 รวม
M2: ยอดรวมผลิต | N2: ยอดฟอแคส | O2: ยอดสตอค | P2: ยอดเมโม่ | Q2: ยอดฟอแคสวันพรุ่งนี้ | R2: รวม
M3: จำนวน
B4: รหัสสินค้า | C4: สินค้า | D4: ปณ | E4: ชอปปี้ | F4: ลาซาด้า | G4: ติ๊กตอก | H4: ติ๊กตอก2 | I4: ติ๊กตอก3 | J4: รวม TT | K4: ชอยส์ | L4: ยอดเส้น | M4: (กล่อง)
B6: ชิฟฟอนรวมรส
B7: 1111002 | C7: ชิฟฟอนรวมรส 8 ชิ้น | D7: ='เย็น '!D7+'เช้า '!D7+บ่าย!D7 -> 2 | E7: 4 | F7: ='เย็น '!F7+'เช้า '!F7+บ่าย!F7 -> 21 | G7: ='เย็น '!G7+'เช้า '!G7+บ่าย!G7 -> 13 | H7: ='เย็น '!H7+'เช้า '!H7+บ่าย!H7 -> 0 | I7: ='เย็น '!I7+'เช้า '!I7+บ่าย!I7 -> 0 | J7: =+G7+H7+I7 -> 13 | K7: ='เย็น '!J7+'เช้า '!J7+บ่าย!K7 -> 0 | L7: ='เย็น '!K7+'เช้า '!K7+บ่าย!L7 -> 0 | M7: =+D7+E7+F7+J7+K7+L7 -> 40 | O7: 82 | R7: =(N7+O7+P7+Q7)-M7 -> 42
C8: ชิฟฟอนแบบกล่องสุ่มอะไรก็ได้ที่มี | D8: ='เย็น '!D8+'เช้า '!D8+บ่าย!D8 -> 0 | E8: ='เย็น '!E8+'เช้า '!E8+บ่าย!E8 -> 0 | F8: ='เย็น '!F8+'เช้า '!F8+บ่าย!F8 -> 0 | G8: ='เย็น '!G8+'เช้า '!G8+บ่าย!G8 -> 0 | H8: ='เย็น '!H8+'เช้า '!H8+บ่าย!H8 -> 0 | I8: ='เย็น '!I8+'เช้า '!I8+บ่าย!I8 -> 0 | J8: =+G8+H8+I8 -> 0 | K8: ='เย็น '!J8+'เช้า '!J8+บ่าย!K8 -> 0 | L8: ='เย็น '!K8+'เช้า '!K8+บ่าย!L8 -> 0 | M8: =+D8+E8+F8+J8+K8+L8 -> 0 | R8: =(N8+O8+P8+Q8)-M8 -> 0
B9: 1111084 | C9: ชิฟฟอน 8 ชิ้น กาแฟล้วน | D9: ='เย็น '!D9+'เช้า '!D9+บ่าย!D9 -> 0 | E9: ='เย็น '!E9+'เช้า '!E9+บ่าย!E9 -> 0 | F9: ='เย็น '!F9+'เช้า '!F9+บ่าย!F9 -> 0 | G9: ='เย็น '!G9+'เช้า '!G9+บ่าย!G9 -> 0 | H9: ='เย็น '!H9+'เช้า '!H9+บ่าย!H9 -> 0 | I9: ='เย็น '!I9+'เช้า '!I9+บ่าย!I9 -> 0 | J9: =+G9+H9+I9 -> 0 | K9: ='เย็น '!J9+'เช้า '!J9+บ่าย!K9 -> 0 | L9: ='เย็น '!K9+'เช้า '!K9+บ่าย!L9 -> 0 | M9: =+D9+E9+F9+J9+K9+L9 -> 0 | R9: =(N9+O9+P9+Q9)-M9 -> 0
B10: 1111085 | C10: ชิฟฟอน 8 ชิ้น บลูเบอรี่ล้วน | D10: ='เย็น '!D10+'เช้า '!D10+บ่าย!D10 -> 0 | E10: ='เย็น '!E10+'เช้า '!E10+บ่าย!E10 -> 0 | F10: ='เย็น '!F10+'เช้า '!F10+บ่าย!F10 -> 0 | G10: ='เย็น '!G10+'เช้า '!G10+บ่าย!G10 -> 0 | H10: ='เย็น '!H10+'เช้า '!H10+บ่าย!H10 -> 0 | I10: ='เย็น '!I10+'เช้า '!I10+บ่าย!I10 -> 0 | J10: =+G10+H10+I10 -> 0 | K10: ='เย็น '!J10+'เช้า '!J10+บ่าย!K10 -> 0 | L10: ='เย็น '!K10+'เช้า '!K10+บ่าย!L10 -> 0 | M10: =+D10+E10+F10+J10+K10+L10 -> 0 | R10: =(N10+O10+P10+Q10)-M10 -> 0
B11: 1111086 | C11: ชิฟฟอน 8 ชิ้น มะพร้าวล้วน | D11: ='เย็น '!D11+'เช้า '!D11+บ่าย!D11 -> 0 | E11: ='เย็น '!E11+'เช้า '!E11+บ่าย!E11 -> 0 | F11: ='เย็น '!F11+'เช้า '!F11+บ่าย!F11 -> 0 | G11: ='เย็น '!G11+'เช้า '!G11+บ่าย!G11 -> 0 | H11: ='เย็น '!H11+'เช้า '!H11+บ่าย!H11 -> 0 | I11: ='เย็น '!I11+'เช้า '!I11+บ่าย!I11 -> 0 | J11: =+G11+H11+I11 -> 0 | K11: ='เย็น '!J11+'เช้า '!J11+บ่าย!K11 -> 0 | L11: ='เย็น '!K11+'เช้า '!K11+บ่าย!L11 -> 0 | M11: =+D11+E11+F11+J11+K11+L11 -> 0 | R11: =(N11+O11+P11+Q11)-M11 -> 0
B12: 1111087 | C12: ชิฟฟอน 8 ชิ้น สตอเบอรี่ล้วน | D12: ='เย็น '!D12+'เช้า '!D12+บ่าย!D12 -> 0 | E12: ='เย็น '!E12+'เช้า '!E12+บ่าย!E12 -> 0 | F12: ='เย็น '!F12+'เช้า '!F12+บ่าย!F12 -> 0 | G12: ='เย็น '!G12+'เช้า '!G12+บ่าย!G12 -> 0 | H12: ='เย็น '!H12+'เช้า '!H12+บ่าย!H12 -> 0 | I12: ='เย็น '!I12+'เช้า '!I12+บ่าย!I12 -> 0 | J12: =+G12+H12+I12 -> 0 | K12: ='เย็น '!J12+'เช้า '!J12+บ่าย!K12 -> 0 | L12: ='เย็น '!K12+'เช้า '!K12+บ่าย!L12 -> 0 | M12: =+D12+E12+F12+J12+K12+L12 -> 0 | R12: =(N12+O12+P12+Q12)-M12 -> 0
B13: 1111088 | C13: ชิฟฟอน 8 ชิ้น ส้มล้วน | D13: ='เย็น '!D13+'เช้า '!D13+บ่าย!D13 -> 0 | E13: ='เย็น '!E13+'เช้า '!E13+บ่าย!E13 -> 0 | F13: ='เย็น '!F13+'เช้า '!F13+บ่าย!F13 -> 0 | G13: ='เย็น '!G13+'เช้า '!G13+บ่าย!G13 -> 0 | H13: ='เย็น '!H13+'เช้า '!H13+บ่าย!H13 -> 0 | I13: ='เย็น '!I13+'เช้า '!I13+บ่าย!I13 -> 0 | J13: =+G13+H13+I13 -> 0 | K13: ='เย็น '!J13+'เช้า '!J13+บ่าย!K13 -> 0 | L13: ='เย็น '!K13+'เช้า '!K13+บ่าย!L13 -> 0 | M13: =+D13+E13+F13+J13+K13+L13 -> 0 | R13: =(N13+O13+P13+Q13)-M13 -> 0
B14: 1111089 | C14: ชิฟฟอน 8 ชิ้น เนยล้วน | D14: ='เย็น '!D14+'เช้า '!D14+บ่าย!D14 -> 0 | E14: ='เย็น '!E14+'เช้า '!E14+บ่าย!E14 -> 0 | F14: ='เย็น '!F14+'เช้า '!F14+บ่าย!F14 -> 0 | G14: ='เย็น '!G14+'เช้า '!G14+บ่าย!G14 -> 0 | H14: ='เย็น '!H14+'เช้า '!H14+บ่าย!H14 -> 0 | I14: ='เย็น '!I14+'เช้า '!I14+บ่าย!I14 -> 0 | J14: =+G14+H14+I14 -> 0 | K14: ='เย็น '!J14+'เช้า '!J14+บ่าย!K14 -> 0 | L14: ='เย็น '!K14+'เช้า '!K14+บ่าย!L14 -> 0 | M14: =+D14+E14+F14+J14+K14+L14 -> 0 | R14: =(N14+O14+P14+Q14)-M14 -> 0
B15: 1111090 | C15: ชิฟฟอน 8 ชิ้น เผือกล้วน | D15: ='เย็น '!D15+'เช้า '!D15+บ่าย!D15 -> 0 | E15: ='เย็น '!E15+'เช้า '!E15+บ่าย!E15 -> 0 | F15: ='เย็น '!F15+'เช้า '!F15+บ่าย!F15 -> 0 | G15: ='เย็น '!G15+'เช้า '!G15+บ่าย!G15 -> 0 | H15: ='เย็น '!H15+'เช้า '!H15+บ่าย!H15 -> 0 | I15: ='เย็น '!I15+'เช้า '!I15+บ่าย!I15 -> 0 | J15: =+G15+H15+I15 -> 0 | K15: ='เย็น '!J15+'เช้า '!J15+บ่าย!K15 -> 0 | L15: ='เย็น '!K15+'เช้า '!K15+บ่าย!L15 -> 0 | M15: =+D15+E15+F15+J15+K15+L15 -> 0 | R15: =(N15+O15+P15+Q15)-M15 -> 0
B16: 1111091 | C16: ชิฟฟอน 8 ชิ้น ใบเตยล้วน | D16: ='เย็น '!D16+'เช้า '!D16+บ่าย!D16 -> 0 | E16: ='เย็น '!E16+'เช้า '!E16+บ่าย!E16 -> 0 | F16: ='เย็น '!F16+'เช้า '!F16+บ่าย!F16 -> 0 | G16: ='เย็น '!G16+'เช้า '!G16+บ่าย!G16 -> 0 | H16: ='เย็น '!H16+'เช้า '!H16+บ่าย!H16 -> 0 | I16: ='เย็น '!I16+'เช้า '!I16+บ่าย!I16 -> 0 | J16: =+G16+H16+I16 -> 0 | K16: ='เย็น '!J16+'เช้า '!J16+บ่าย!K16 -> 0 | L16: ='เย็น '!K16+'เช้า '!K16+บ่าย!L16 -> 0 | M16: =+D16+E16+F16+J16+K16+L16 -> 0 | R16: =(N16+O16+P16+Q16)-M16 -> 0
B17: 1111092 | C17: ชิฟฟอน 8 ชิ้น กล้วยหอม | D17: ='เย็น '!D17+'เช้า '!D17+บ่าย!D17 -> 0 | E17: ='เย็น '!E17+'เช้า '!E17+บ่าย!E17 -> 0 | F17: ='เย็น '!F17+'เช้า '!F17+บ่าย!F17 -> 0 | G17: ='เย็น '!G17+'เช้า '!G17+บ่าย!G17 -> 0 | H17: ='เย็น '!H17+'เช้า '!H17+บ่าย!H17 -> 0 | I17: ='เย็น '!I17+'เช้า '!I17+บ่าย!I17 -> 0 | J17: =+G17+H17+I17 -> 0 | K17: ='เย็น '!J17+'เช้า '!J17+บ่าย!K17 -> 0 | L17: ='เย็น '!K17+'เช้า '!K17+บ่าย!L17 -> 0 | M17: =+D17+E17+F17+J17+K17+L17 -> 0 | R17: =(N17+O17+P17+Q17)-M17 -> 0
B18: 1111093 | C18: ชิฟฟอน 8 ชิ้น โกโก้ล้วน | D18: ='เย็น '!D18+'เช้า '!D18+บ่าย!D18 -> 0 | E18: ='เย็น '!E18+'เช้า '!E18+บ่าย!E18 -> 0 | F18: ='เย็น '!F18+'เช้า '!F18+บ่าย!F18 -> 0 | G18: ='เย็น '!G18+'เช้า '!G18+บ่าย!G18 -> 0 | H18: ='เย็น '!H18+'เช้า '!H18+บ่าย!H18 -> 0 | I18: ='เย็น '!I18+'เช้า '!I18+บ่าย!I18 -> 0 | J18: =+G18+H18+I18 -> 0 | K18: ='เย็น '!J18+'เช้า '!J18+บ่าย!K18 -> 0 | L18: ='เย็น '!K18+'เช้า '!K18+บ่าย!L18 -> 0 | M18: =+D18+E18+F18+J18+K18+L18 -> 0 | R18: =(N18+O18+P18+Q18)-M18 -> 0
B19: 1111094 | C19: ชิฟฟอน 8 ชิ้น ชาไทยล้วน | D19: ='เย็น '!D19+'เช้า '!D19+บ่าย!D19 -> 0 | E19: ='เย็น '!E19+'เช้า '!E19+บ่าย!E19 -> 0 | F19: ='เย็น '!F19+'เช้า '!F19+บ่าย!F19 -> 0 | G19: ='เย็น '!G19+'เช้า '!G19+บ่าย!G19 -> 0 | H19: ='เย็น '!H19+'เช้า '!H19+บ่าย!H19 -> 0 | I19: ='เย็น '!I19+'เช้า '!I19+บ่าย!I19 -> 0 | J19: =+G19+H19+I19 -> 0 | K19: ='เย็น '!J19+'เช้า '!J19+บ่าย!K19 -> 0 | L19: ='เย็น '!K19+'เช้า '!K19+บ่าย!L19 -> 0 | M19: =+D19+E19+F19+J19+K19+L19 -> 0 | R19: =(N19+O19+P19+Q19)-M19 -> 0
B20: 1111095 | C20: ชิฟฟอน 8 ชิ้น ชาเขียวล้วน | D20: ='เย็น '!D20+'เช้า '!D20+บ่าย!D20 -> 0 | E20: ='เย็น '!E20+'เช้า '!E20+บ่าย!E20 -> 0 | F20: ='เย็น '!F20+'เช้า '!F20+บ่าย!F20 -> 0 | G20: ='เย็น '!G20+'เช้า '!G20+บ่าย!G20 -> 0 | H20: ='เย็น '!H20+'เช้า '!H20+บ่าย!H20 -> 0 | I20: ='เย็น '!I20+'เช้า '!I20+บ่าย!I20 -> 0 | J20: =+G20+H20+I20 -> 0 | K20: ='เย็น '!J20+'เช้า '!J20+บ่าย!K20 -> 0 | L20: ='เย็น '!K20+'เช้า '!K20+บ่าย!L20 -> 0 | M20: =+D20+E20+F20+J20+K20+L20 -> 0 | R20: =(N20+O20+P20+Q20)-M20 -> 0
... B24: 1111043 | C24: ชิฟฟอน 8 ชิ้น มะลิ | D24: ='เย็น '!D24+'เช้า '!D24+บ่าย!D24 -> 0 | E24: ='เย็น '!E24+'เช้า '!E24+บ่าย!E24 -> 0 | F24: ='เย็น '!F24+'เช้า '!F24+บ่าย!F24 -> 0 | G24: ='เย็น '!G24+'เช้า '!G24+บ่าย!G24 -> 0 | H24: ='เย็น '!H24+'เช้า '!H24+บ่าย!H24 -> 0 | I24: ='เย็น '!I24+'เช้า '!I24+บ่าย!I24 -> 0 | J24: =+G24+H24+I24 -> 0 | K24: ='เย็น '!J24+'เช้า '!J24+บ่าย!K24 -> 0 | L24: ='เย็น '!K24+'เช้า '!K24+บ่าย!L24 -> 0 | M24: =+D24+E24+F24+J24+K24+L24 -> 0 | R24: =(N24+O24+P24+Q24)-M24 -> 0
B25: 1111056 | C25: ชิฟฟอน 8 ชิ้น รวมรสยอดฮิต | D25: ='เย็น '!D25+'เช้า '!D25+บ่าย!D25 -> 1 | E25: ='เย็น '!E25+'เช้า '!E25+บ่าย!E25 -> 0 | F25: ='เย็น '!F25+'เช้า '!F25+บ่าย!F25 -> 3 | G25: ='เย็น '!G25+'เช้า '!G25+บ่าย!G25 -> 2 | H25: ='เย็น '!H25+'เช้า '!H25+บ่าย!H25 -> 0 | I25: ='เย็น '!I25+'เช้า '!I25+บ่าย!I25 -> 0 | J25: =+G25+H25+I25 -> 2 | K25: ='เย็น '!J25+'เช้า '!J25+บ่าย!K25 -> 0 | L25: ='เย็น '!K25+'เช้า '!K25+บ่าย!L25 -> 0 | M25: =+D25+E25+F25+J25+K25+L25 -> 6 | N25: 5 | O25: 4 | Q25: 5 | R25: =(N25+O25+P25+Q25)-M25 -> 8
B26: 1004055 | C26: ชิฟฟอนรวมรส 4 ชิ้น | D26: ='เย็น '!D26+'เช้า '!D26+บ่าย!D26 -> 0 | E26: ='เย็น '!E26+'เช้า '!E26+บ่าย!E26 -> 0 | F26: ='เย็น '!F26+'เช้า '!F26+บ่าย!F26 -> 0 | G26: ='เย็น '!G26+'เช้า '!G26+บ่าย!G26 -> 45 | H26: ='เย็น '!H26+'เช้า '!H26+บ่าย!H26 -> 0 | I26: ='เย็น '!I26+'เช้า '!I26+บ่าย!I26 -> 0 | J26: =+G26+H26+I26 -> 45 | K26: ='เย็น '!J26+'เช้า '!J26+บ่าย!K26 -> 0 | L26: ='เย็น '!K26+'เช้า '!K26+บ่าย!L26 -> 30 | M26: =+D26+E26+F26+J26+K26+L26 -> 75 | N26: 30 | O26: 14 | R26: =(N26+O26+P26+Q26)-M26 -> -31
B27: 1004055 | C27: ชิฟฟอน 4 ชิ้น โกโก้ล้วน | D27: ='เย็น '!D27+'เช้า '!D27+บ่าย!D27 -> 0 | E27: ='เย็น '!E27+'เช้า '!E27+บ่าย!E27 -> 0 | F27: ='เย็น '!F27+'เช้า '!F27+บ่าย!F27 -> 0 | G27: ='เย็น '!G27+'เช้า '!G27+บ่าย!G27 -> 0 | H27: ='เย็น '!H27+'เช้า '!H27+บ่าย!H27 -> 0 | I27: ='เย็น '!I27+'เช้า '!I27+บ่าย!I27 -> 0 | J27: =+G27+H27+I27 -> 0 | K27: ='เย็น '!J27+'เช้า '!J27+บ่าย!K27 -> 0 | L27: ='เย็น '!K27+'เช้า '!K27+บ่าย!L27 -> 0 | M27: =+D27+E27+F27+J27+K27+L27 -> 0 | R27: =(N27+O27+P27+Q27)-M27 -> 0
B28: 1004055 | C28: ชิฟฟอน 4 ชิ้น มะพร้าวล้วน | D28: ='เย็น '!D28+'เช้า '!D28+บ่าย!D28 -> 0 | E28: ='เย็น '!E28+'เช้า '!E28+บ่าย!E28 -> 0 | F28: ='เย็น '!F28+'เช้า '!F28+บ่าย!F28 -> 0 | G28: ='เย็น '!G28+'เช้า '!G28+บ่าย!G28 -> 0 | H28: ='เย็น '!H28+'เช้า '!H28+บ่าย!H28 -> 0 | I28: ='เย็น '!I28+'เช้า '!I28+บ่าย!I28 -> 0 | J28: =+G28+H28+I28 -> 0 | K28: ='เย็น '!J28+'เช้า '!J28+บ่าย!K28 -> 0 | L28: ='เย็น '!K28+'เช้า '!K28+บ่าย!L28 -> 0 | M28: =+D28+E28+F28+J28+K28+L28 -> 0 | R28: =(N28+O28+P28+Q28)-M28 -> 0
B29: 1004055 | C29: ชิฟฟอน 4 ชิ้น เนยล้วน | D29: ='เย็น '!D29+'เช้า '!D29+บ่าย!D29 -> 0 | E29: ='เย็น '!E29+'เช้า '!E29+บ่าย!E29 -> 0 | F29: ='เย็น '!F29+'เช้า '!F29+บ่าย!F29 -> 0 | G29: ='เย็น '!G29+'เช้า '!G29+บ่าย!G29 -> 0 | H29: ='เย็น '!H29+'เช้า '!H29+บ่าย!H29 -> 0 | I29: ='เย็น '!I29+'เช้า '!I29+บ่าย!I29 -> 0 | J29: =+G29+H29+I29 -> 0 | K29: ='เย็น '!J29+'เช้า '!J29+บ่าย!K29 -> 0 | L29: ='เย็น '!K29+'เช้า '!K29+บ่าย!L29 -> 0 | M29: =+D29+E29+F29+J29+K29+L29 -> 0 | R29: =(N29+O29+P29+Q29)-M29 -> 0
B30: 1004055 | C30: ชิฟฟอน 4 ชิ้น กาแฟล้วน | D30: ='เย็น '!D30+'เช้า '!D30+บ่าย!D30 -> 0 | E30: ='เย็น '!E30+'เช้า '!E30+บ่าย!E30 -> 0 | F30: ='เย็น '!F30+'เช้า '!F30+บ่าย!F30 -> 0 | G30: ='เย็น '!G30+'เช้า '!G30+บ่าย!G30 -> 0 | H30: ='เย็น '!H30+'เช้า '!H30+บ่าย!H30 -> 0 | I30: ='เย็น '!I30+'เช้า '!I30+บ่าย!I30 -> 0 | J30: =+G30+H30+I30 -> 0 | K30: ='เย็น '!J30+'เช้า '!J30+บ่าย!K30 -> 0 | L30: ='เย็น '!K30+'เช้า '!K30+บ่าย!L30 -> 0 | M30: =+D30+E30+F30+J30+K30+L30 -> 0 | R30: =(N30+O30+P30+Q30)-M30 -> 0
B31: 1004055 | C31: ชิฟฟอน 4 ชิ้น ใบเตยล้วน | D31: ='เย็น '!D31+'เช้า '!D31+บ่าย!D31 -> 0 | E31: ='เย็น '!E31+'เช้า '!E31+บ่าย!E31 -> 0 | F31: ='เย็น '!F31+'เช้า '!F31+บ่าย!F31 -> 0 | G31: ='เย็น '!G31+'เช้า '!G31+บ่าย!G31 -> 0 | H31: ='เย็น '!H31+'เช้า '!H31+บ่าย!H31 -> 0 | I31: ='เย็น '!I31+'เช้า '!I31+บ่าย!I31 -> 0 | J31: =+G31+H31+I31 -> 0 | K31: ='เย็น '!J31+'เช้า '!J31+บ่าย!K31 -> 0 | L31: ='เย็น '!K31+'เช้า '!K31+บ่าย!L31 -> 0 | M31: =+D31+E31+F31+J31+K31+L31 -> 0 | R31: =(N31+O31+P31+Q31)-M31 -> 0
B32: 1004055 | C32: ชิฟฟอน 4 ชิ้น บลูเบอร์รี่ล้วน | D32: ='เย็น '!D32+'เช้า '!D32+บ่าย!D32 -> 0 | E32: ='เย็น '!E32+'เช้า '!E32+บ่าย!E32 -> 0 | F32: ='เย็น '!F32+'เช้า '!F32+บ่าย!F32 -> 0 | G32: ='เย็น '!G32+'เช้า '!G32+บ่าย!G32 -> 0 | H32: ='เย็น '!H32+'เช้า '!H32+บ่าย!H32 -> 0 | I32: ='เย็น '!I32+'เช้า '!I32+บ่าย!I32 -> 0 | J32: =+G32+H32+I32 -> 0 | K32: ='เย็น '!J32+'เช้า '!J32+บ่าย!K32 -> 0 | L32: ='เย็น '!K32+'เช้า '!K32+บ่าย!L32 -> 0 | M32: =+D32+E32+F32+J32+K32+L32 -> 0 | R32: =(N32+O32+P32+Q32)-M32 -> 0
B33: 1004055 | C33: ชิฟฟอน 4 ชิ้น ส้มล้วน | D33: ='เย็น '!D33+'เช้า '!D33+บ่าย!D33 -> 0 | E33: ='เย็น '!E33+'เช้า '!E33+บ่าย!E33 -> 0 | F33: ='เย็น '!F33+'เช้า '!F33+บ่าย!F33 -> 0 | G33: ='เย็น '!G33+'เช้า '!G33+บ่าย!G33 -> 0 | H33: ='เย็น '!H33+'เช้า '!H33+บ่าย!H33 -> 0 | I33: ='เย็น '!I33+'เช้า '!I33+บ่าย!I33 -> 0 | J33: =+G33+H33+I33 -> 0 | K33: ='เย็น '!J33+'เช้า '!J33+บ่าย!K33 -> 0 | L33: ='เย็น '!K33+'เช้า '!K33+บ่าย!L33 -> 0 | M33: =+D33+E33+F33+J33+K33+L33 -> 0 | R33: =(N33+O33+P33+Q33)-M33 -> 0
B34: 1004055 | C34: ชิฟฟอน 4 ชิ้น เผือกล้วน | D34: ='เย็น '!D34+'เช้า '!D34+บ่าย!D34 -> 0 | E34: ='เย็น '!E34+'เช้า '!E34+บ่าย!E34 -> 0 | F34: ='เย็น '!F34+'เช้า '!F34+บ่าย!F34 -> 0 | G34: ='เย็น '!G34+'เช้า '!G34+บ่าย!G34 -> 0 | H34: ='เย็น '!H34+'เช้า '!H34+บ่าย!H34 -> 0 | I34: ='เย็น '!I34+'เช้า '!I34+บ่าย!I34 -> 0 | J34: =+G34+H34+I34 -> 0 | K34: ='เย็น '!J34+'เช้า '!J34+บ่าย!K34 -> 0 | L34: ='เย็น '!K34+'เช้า '!K34+บ่าย!L34 -> 0 | M34: =+D34+E34+F34+J34+K34+L34 -> 0 | R34: =(N34+O34+P34+Q34)-M34 -> 0
B35: 1004055 | C35: ชิฟฟอน 4 ชิ้น สตอเบอรี่ล้วน | D35: ='เย็น '!D35+'เช้า '!D35+บ่าย!D35 -> 0 | E35: ='เย็น '!E35+'เช้า '!E35+บ่าย!E35 -> 0 | F35: ='เย็น '!F35+'เช้า '!F35+บ่าย!F35 -> 0 | G35: ='เย็น '!G35+'เช้า '!G35+บ่าย!G35 -> 0 | H35: ='เย็น '!H35+'เช้า '!H35+บ่าย!H35 -> 0 | I35: ='เย็น '!I35+'เช้า '!I35+บ่าย!I35 -> 0 | J35: =+G35+H35+I35 -> 0 | K35: ='เย็น '!J35+'เช้า '!J35+บ่าย!K35 -> 0 | L35: ='เย็น '!K35+'เช้า '!K35+บ่าย!L35 -> 0 | M35: =+D35+E35+F35+J35+K35+L35 -> 0 | R35: =(N35+O35+P35+Q35)-M35 -> 0
B36: 1004055 | C36: ชิฟฟอน 4 ชิ้น กล้วยหอมล้วน | D36: ='เย็น '!D36+'เช้า '!D36+บ่าย!D36 -> 0 | E36: ='เย็น '!E36+'เช้า '!E36+บ่าย!E36 -> 0 | F36: ='เย็น '!F36+'เช้า '!F36+บ่าย!F36 -> 0 | G36: ='เย็น '!G36+'เช้า '!G36+บ่าย!G36 -> 0 | H36: ='เย็น '!H36+'เช้า '!H36+บ่าย!H36 -> 0 | I36: ='เย็น '!I36+'เช้า '!I36+บ่าย!I36 -> 0 | J36: =+G36+H36+I36 -> 0 | K36: ='เย็น '!J36+'เช้า '!J36+บ่าย!K36 -> 0 | L36: ='เย็น '!K36+'เช้า '!K36+บ่าย!L36 -> 0 | M36: =+D36+E36+F36+J36+K36+L36 -> 0 | R36: =(N36+O36+P36+Q36)-M36 -> 0
B37: 1004055 | C37: ชิฟฟอน 4 ชิ้น ชาเขียวล้วน | D37: ='เย็น '!D37+'เช้า '!D37+บ่าย!D37 -> 0 | E37: ='เย็น '!E37+'เช้า '!E37+บ่าย!E37 -> 0 | F37: ='เย็น '!F37+'เช้า '!F37+บ่าย!F37 -> 0 | G37: ='เย็น '!G37+'เช้า '!G37+บ่าย!G37 -> 0 | H37: ='เย็น '!H37+'เช้า '!H37+บ่าย!H37 -> 0 | I37: ='เย็น '!I37+'เช้า '!I37+บ่าย!I37 -> 0 | J37: =+G37+H37+I37 -> 0 | K37: ='เย็น '!J37+'เช้า '!J37+บ่าย!K37 -> 0 | L37: ='เย็น '!K37+'เช้า '!K37+บ่าย!L37 -> 0 | M37: =+D37+E37+F37+J37+K37+L37 -> 0 | R37: =(N37+O37+P37+Q37)-M37 -> 0
B38: 1004055 | C38: ชิฟฟอน 4 ชิ้น ชาไทยล้วน | D38: ='เย็น '!D38+'เช้า '!D38+บ่าย!D38 -> 0 | E38: ='เย็น '!E38+'เช้า '!E38+บ่าย!E38 -> 0 | F38: ='เย็น '!F38+'เช้า '!F38+บ่าย!F38 -> 0 | G38: ='เย็น '!G38+'เช้า '!G38+บ่าย!G38 -> 0 | H38: ='เย็น '!H38+'เช้า '!H38+บ่าย!H38 -> 0 | I38: ='เย็น '!I38+'เช้า '!I38+บ่าย!I38 -> 0 | J38: =+G38+H38+I38 -> 0 | K38: ='เย็น '!J38+'เช้า '!J38+บ่าย!K38 -> 0 | L38: ='เย็น '!K38+'เช้า '!K38+บ่าย!L38 -> 0 | M38: =+D38+E38+F38+J38+K38+L38 -> 0 | R38: =(N38+O38+P38+Q38)-M38 -> 0
... B65: 1111083 | C65: ชิฟฟอนไส้แยมแยกชิ้น เมล่อน | D65: ='เย็น '!D65+'เช้า '!D65+บ่าย!D65 -> 0 | E65: ='เย็น '!E65+'เช้า '!E65+บ่าย!E65 -> 0 | F65: ='เย็น '!F65+'เช้า '!F65+บ่าย!F65 -> 0 | G65: ='เย็น '!G65+'เช้า '!G65+บ่าย!G65 -> 0 | H65: ='เย็น '!H65+'เช้า '!H65+บ่าย!H65 -> 0 | I65: ='เย็น '!I65+'เช้า '!I65+บ่าย!I65 -> 0 | J65: =+G65+H65+I65 -> 0 | K65: ='เย็น '!J65+'เช้า '!J65+บ่าย!K65 -> 0 | L65: ='เย็น '!K65+'เช้า '!K65+บ่าย!L65 -> 0 | M65: =+D65+E65+F65+J65+K65+L65 -> 0 | R65: =(N65+O65+P65+Q65)-M65 -> 0
B66: 1111010 | C66: ชิฟฟอนไส้แยมแยกชิ้น คละรส | D66: =บ่าย!D66+'เช้า '!D66+'เย็น '!D66 -> 0 | E66: =บ่าย!E66+'เช้า '!E66+'เย็น '!E66 -> 0 | F66: =บ่าย!F66+'เช้า '!F66+'เย็น '!F66 -> 0 | G66: =บ่าย!G66+'เช้า '!G66+'เย็น '!G66 -> 0 | H66: =บ่าย!H66+'เช้า '!H66+'เย็น '!H66 -> 0 | I66: =บ่าย!I66+'เช้า '!I66+'เย็น '!I66 -> 0 | J66: =+G66+H66+I66 -> 0 | K66: =บ่าย!K66+'เช้า '!J66+'เย็น '!J66 -> 0 | M66: =+D66+E66+F66+J66+K66+L66 -> 0 | R66: =(N66+O66+P66+Q66)-M66 -> 0
C67: รวม | J67: =+G67+H67+I67 -> 0 | M67: =+D67+E67+F67+J67+K67+L67 -> 0 | R67: =(N67+O67+P67+Q67)-M67 -> 0
B68: ชิฟฟอนไส้แยม 6 ชิ้น | J68: =+G68+H68+I68 -> 0 | M68: =+D68+E68+F68+J68+K68+L68 -> 0
B69: 1111009 | C69: ชิฟฟอนไส้แยมรวมรส 6 ชิ้น | D69: ='เย็น '!D69+'เช้า '!D69+บ่าย!D69 -> 2 | E69: ='เย็น '!E69+'เช้า '!E69+บ่าย!E69 -> 0 | F69: ='เย็น '!F69+'เช้า '!F69+บ่าย!F69 -> 1 | G69: ='เย็น '!G69+'เช้า '!G69+บ่าย!G69 -> 0 | H69: ='เย็น '!H69+'เช้า '!H69+บ่าย!H69 -> 0 | I69: ='เย็น '!I69+'เช้า '!I69+บ่าย!I69 -> 0 | J69: =+G69+H69+I69 -> 0 | K69: ='เย็น '!J69+'เช้า '!J69+บ่าย!K69 -> 0 | L69: ='เย็น '!K69+'เช้า '!K69+บ่าย!L69 -> 0 | M69: =+D69+E69+F69+J69+K69+L69 -> 3 | Q69: 10 | R69: =(N69+O69+P69+Q69)-M69 -> 7
B70: 1111023 | C70: ชิฟฟอนไส้แยมรสสตอเบอร์รี่ล้วน 6 ชิ้น | D70: ='เย็น '!D70+'เช้า '!D70+บ่าย!D70 -> 0 | E70: ='เย็น '!E70+'เช้า '!E70+บ่าย!E70 -> 0 | F70: ='เย็น '!F70+'เช้า '!F70+บ่าย!F70 -> 0 | G70: ='เย็น '!G70+'เช้า '!G70+บ่าย!G70 -> 0 | H70: ='เย็น '!H70+'เช้า '!H70+บ่าย!H70 -> 0 | I70: ='เย็น '!I70+'เช้า '!I70+บ่าย!I70 -> 0 | J70: =+G70+H70+I70 -> 0 | K70: ='เย็น '!J70+'เช้า '!J70+บ่าย!K70 -> 0 | L70: ='เย็น '!K70+'เช้า '!K70+บ่าย!L70 -> 0 | M70: =+D70+E70+F70+J70+K70+L70 -> 0 | R70: =(N70+O70+P70+Q70)-M70 -> 0
...
