Workbook

Sheet รวม
B1: ยอดจริง ออนไลน์ วันที่ รวม
L2: ยอดรวมผลิต | M2: ยอดฟอแคส | N2: ยอดสตอค | O2: ยอดเมโม่ | P2: ยอดฟอแคสวันพรุ่งนี้ | Q2: รวม
L3: จำนวน
B4: รหัสสินค้า | C4: สินค้า | D4: ปณ | E4: ชอปปี้ | F4: ลาซาด้า | G4: ติ๊กตอก | H4: ติ๊กตอก2 | I4: ติ๊กตอก3 | J4: ชอยส์ | K4: ยอดเส้น | L4: (กล่อง)
B6: ชิฟฟอนรวมรส
B7: 1111002 | C7: ชิฟฟอนรวมรส 8 ชิ้น | D7: ='1'!D7+'2'!D7+'3'!D7+'4'!D7+'5'!D7+'6'!D7+'7'!D7+'8'!D7+'9'!D7+'10'!D7+'11'!D7+'12'!C7+'13'!D7+'14'!D7+'15'!D7+'16'!D7+'17'!D7+'18'!D7+'19'!C7+'20'!D7+'21'!D7+'22'!C7+'23'!D7+'24'!D7+'25'!D7+'26'!C7+'27'!D7+'28'!D7+'29'!D7 -> 378 | E7: ='1'!E7+'2'!E7+'3'!E7+'4'!E7+'5'!E7+'6'!E7+'7'!E7+'8'!E7+'9'!E7+'10'!E7+'11'!E7+'12'!D7+'13'!E7+'14'!E7+'15'!E7+'16'!E7+'17'!E7+'18'!E7+'19'!D7+'20'!E7+'21'!E7+'22'!D7+'23'!E7+'24'!E7+'25'!E7+'26'!D7+'27'!E7+'28'!E7+'29'!E7 -> 1857 | F7: ='1'!F7+'2'!F7+'3'!F7+'4'!F7+'5'!F7+'6'!F7+'7'!F7+'8'!F7+'9'!F7+'10'!F7+'11'!F7+'12'!E7+'13'!F7+'14'!F7+'15'!F7+'16'!F7+'17'!F7+'18'!F7+'19'!E7+'20'!F7+'21'!F7+'22'!E7+'23'!F7+'24'!F7+'25'!F7+'26'!E7+'27'!F7+'28'!F7+'29'!F7 -> 2441 | G7: ='1'!G7+'2'!G7+'3'!G7+'4'!G7+'5'!G7+'6'!G7+'7'!G7+'8'!G7+'9'!G7+'10'!G7+'11'!G7+'12'!F7+'13'!G7+'14'!G7+'15'!G7+'16'!G7+'17'!G7+'18'!G7+'19'!F7+'20'!G7+'21'!G7+'22'!F7+'23'!G7+'24'!G7+'25'!G7+'26'!F7+'27'!G7+'28'!G7+'29'!G7 -> 238 | H7: ='1'!H7+'2'!H7+'3'!H7+'4'!H7+'5'!H7+'6'!H7+'7'!H7+'8'!H7+'9'!H7+'10'!H7+'11'!H7+'12'!G7+'13'!H7+'14'!H7+'15'!H7+'16'!H7+'17'!H7+'18'!H7+'19'!G7+'20'!H7+'21'!H7+'22'!G7+'23'!H7+'24'!H7+'25'!H7+'26'!G7+'27'!H7+'28'!H7+'29'!H7 -> 47 | I7: ='1'!I7+'2'!I7+'3'!I7+'4'!I7+'5'!I7+'6'!I7+'7'!I7+'8'!I7+'9'!I7+'10'!I7+'11'!I7+'12'!H7+'13'!I7+'14'!I7+'15'!I7+'16'!I7+'17'!I7+'18'!I7+'19'!H7+'20'!I7+'21'!I7+'22'!H7+'23'!I7+'24'!I7+'25'!I7+'26'!H7+'27'!I7+'28'!I7+'29'!I7 -> 0 | J7: ='1'!J7+'2'!J7+'3'!J7+'4'!J7+'5'!J7+'6'!J7+'7'!J7+'8'!J7+'9'!J7+'10'!J7+'11'!J7+'12'!I7+'13'!J7+'14'!J7+'15'!J7+'16'!J7+'17'!J7+'18'!J7+'19'!I7+'20'!J7+'21'!J7+'22'!I7+'23'!J7+'24'!J7+'25'!J7+'26'!I7+'27'!J7+'28'!J7+'29'!J7 -> 0 | K7: ='1'!K7+'2'!K7+'3'!K7+'4'!K7+'5'!K7+'6'!K7+'7'!K7+'8'!K7+'9'!K7+'10'!K7+'11'!K7+'12'!J7+'13'!K7+'14'!K7+'15'!K7+'16'!K7+'17'!K7+'18'!K7+'19'!J7+'20'!K7+'21'!K7+'22'!J7+'23'!K7+'24'!K7+'25'!K7+'26'!J7+'27'!K7+'28'!K7+'29'!K7 -> 1301 | L7: =SUM(D7:K7) -> 6262 | Q7: 0
C8: ชิฟฟอนแบบกล่องสุ่มอะไรก็ได้ที่มี | D8: ='1'!D8+'2'!D8+'3'!D8+'4'!D8+'5'!D8+'6'!D8+'7'!D8+'8'!D8+'9'!D8+'10'!D8+'11'!D8+'12'!C8+'13'!D8+'14'!D8+'15'!D8+'16'!D8+'17'!D8+'18'!D8+'19'!C8+'20'!D8+'21'!D8+'22'!C8+'23'!D8+'24'!D8+'25'!D8+'26'!C8+'27'!D8+'28'!D8+'29'!D8 -> 0 | E8: ='1'!E8+'2'!E8+'3'!E8+'4'!E8+'5'!E8+'6'!E8+'7'!E8+'8'!E8+'9'!E8+'10'!E8+'11'!E8+'12'!D8+'13'!E8+'14'!E8+'15'!E8+'16'!E8+'17'!E8+'18'!E8+'19'!D8+'20'!E8+'21'!E8+'22'!D8+'23'!E8+'24'!E8+'25'!E8+'26'!D8+'27'!E8+'28'!E8+'29'!E8 -> 0 | F8: ='1'!F8+'2'!F8+'3'!F8+'4'!F8+'5'!F8+'6'!F8+'7'!F8+'8'!F8+'9'!F8+'10'!F8+'11'!F8+'12'!E8+'13'!F8+'14'!F8+'15'!F8+'16'!F8+'17'!F8+'18'!F8+'19'!E8+'20'!F8+'21'!F8+'22'!E8+'23'!F8+'24'!F8+'25'!F8+'26'!E8+'27'!F8+'28'!F8+'29'!F8 -> 0 | G8: ='1'!G8+'2'!G8+'3'!G8+'4'!G8+'5'!G8+'6'!G8+'7'!G8+'8'!G8+'9'!G8+'10'!G8+'11'!G8+'12'!F8+'13'!G8+'14'!G8+'15'!G8+'16'!G8+'17'!G8+'18'!G8+'19'!F8+'20'!G8+'21'!G8+'22'!F8+'23'!G8+'24'!G8+'25'!G8+'26'!F8+'27'!G8+'28'!G8+'29'!G8 -> 0 | H8: ='1'!H8+'2'!H8+'3'!H8+'4'!H8+'5'!H8+'6'!H8+'7'!H8+'8'!H8+'9'!H8+'10'!H8+'11'!H8+'12'!G8+'13'!H8+'14'!H8+'15'!H8+'16'!H8+'17'!H8+'18'!H8+'19'!G8+'20'!H8+'21'!H8+'22'!G8+'23'!H8+'24'!H8+'25'!H8+'26'!G8+'27'!H8+'28'!H8+'29'!H8 -> 0 | I8: ='1'!I8+'2'!I8+'3'!I8+'4'!I8+'5'!I8+'6'!I8+'7'!I8+'8'!I8+'9'!I8+'10'!I8+'11'!I8+'12'!H8+'13'!I8+'14'!I8+'15'!I8+'16'!I8+'17'!I8+'18'!I8+'19'!H8+'20'!I8+'21'!I8+'22'!H8+'23'!I8+'24'!I8+'25'!I8+'26'!H8+'27'!I8+'28'!I8+'29'!I8 -> 0 | J8: ='1'!J8+'2'!J8+'3'!J8+'4'!J8+'5'!J8+'6'!J8+'7'!J8+'8'!J8+'9'!J8+'10'!J8+'11'!J8+'12'!I8+'13'!J8+'14'!J8+'15'!J8+'16'!J8+'17'!J8+'18'!J8+'19'!I8+'20'!J8+'21'!J8+'22'!I8+'23'!J8+'24'!J8+'25'!J8+'26'!I8+'27'!J8+'28'!J8+'29'!J8 -> 0 | K8: ='1'!K8+'2'!K8+'3'!K8+'4'!K8+'5'!K8+'6'!K8+'7'!K8+'8'!K8+'9'!K8+'10'!K8+'11'!K8+'12'!J8+'13'!K8+'14'!K8+'15'!K8+'16'!K8+'17'!K8+'18'!K8+'19'!J8+'20'!K8+'21'!K8+'22'!J8+'23'!K8+'24'!K8+'25'!K8+'26'!J8+'27'!K8+'28'!K8+'29'!K8 -> 0 | L8: =SUM(D8:K8) -> 0 | Q8: 0
B9: 1111084 | C9: ชิฟฟอน 8 ชิ้น กาแฟล้วน | D9: ='1'!D9+'2'!D9+'3'!D9+'4'!D9+'5'!D9+'6'!D9+'7'!D9+'8'!D9+'9'!D9+'10'!D9+'11'!D9+'12'!C9+'13'!D9+'14'!D9+'15'!D9+'16'!D9+'17'!D9+'18'!D9+'19'!C9+'20'!D9+'21'!D9+'22'!C9+'23'!D9+'24'!D9+'25'!D9+'26'!C9+'27'!D9+'28'!D9+'29'!D9 -> 0 | E9: ='1'!E9+'2'!E9+'3'!E9+'4'!E9+'5'!E9+'6'!E9+'7'!E9+'8'!E9+'9'!E9+'10'!E9+'11'!E9+'12'!D9+'13'!E9+'14'!E9+'15'!E9+'16'!E9+'17'!E9+'18'!E9+'19'!D9+'20'!E9+'21'!E9+'22'!D9+'23'!E9+'24'!E9+'25'!E9+'26'!D9+'27'!E9+'28'!E9+'29'!E9 -> 0 | F9: ='1'!F9+'2'!F9+'3'!F9+'4'!F9+'5'!F9+'6'!F9+'7'!F9+'8'!F9+'9'!F9+'10'!F9+'11'!F9+'12'!E9+'13'!F9+'14'!F9+'15'!F9+'16'!F9+'17'!F9+'18'!F9+'19'!E9+'20'!F9+'21'!F9+'22'!E9+'23'!F9+'24'!F9+'25'!F9+'26'!E9+'27'!F9+'28'!F9+'29'!F9 -> 0 | G9: ='1'!G9+'2'!G9+'3'!G9+'4'!G9+'5'!G9+'6'!G9+'7'!G9+'8'!G9+'9'!G9+'10'!G9+'11'!G9+'12'!F9+'13'!G9+'14'!G9+'15'!G9+'16'!G9+'17'!G9+'18'!G9+'19'!F9+'20'!G9+'21'!G9+'22'!F9+'23'!G9+'24'!G9+'25'!G9+'26'!F9+'27'!G9+'28'!G9+'29'!G9 -> 0 | H9: ='1'!H9+'2'!H9+'3'!H9+'4'!H9+'5'!H9+'6'!H9+'7'!H9+'8'!H9+'9'!H9+'10'!H9+'11'!H9+'12'!G9+'13'!H9+'14'!H9+'15'!H9+'16'!H9+'17'!H9+'18'!H9+'19'!G9+'20'!H9+'21'!H9+'22'!G9+'23'!H9+'24'!H9+'25'!H9+'26'!G9+'27'!H9+'28'!H9+'29'!H9 -> 0 | I9: ='1'!I9+'2'!I9+'3'!I9+'4'!I9+'5'!I9+'6'!I9+'7'!I9+'8'!I9+'9'!I9+'10'!I9+'11'!I9+'12'!H9+'13'!I9+'14'!I9+'15'!I9+'16'!I9+'17'!I9+'18'!I9+'19'!H9+'20'!I9+'21'!I9+'22'!H9+'23'!I9+'24'!I9+'25'!I9+'26'!H9+'27'!I9+'28'!I9+'29'!I9 -> 0 | J9: ='1'!J9+'2'!J9+'3'!J9+'4'!J9+'5'!J9+'6'!J9+'7'!J9+'8'!J9+'9'!J9+'10'!J9+'11'!J9+'12'!I9+'13'!J9+'14'!J9+'15'!J9+'16'!J9+'17'!J9+'18'!J9+'19'!I9+'20'!J9+'21'!J9+'22'!I9+'23'!J9+'24'!J9+'25'!J9+'26'!I9+'27'!J9+'28'!J9+'29'!J9 -> 0 | K9: ='1'!K9+'2'!K9+'3'!K9+'4'!K9+'5'!K9+'6'!K9+'7'!K9+'8'!K9+'9'!K9+'10'!K9+'11'!K9+'12'!J9+'13'!K9+'14'!K9+'15'!K9+'16'!K9+'17'!K9+'18'!K9+'19'!J9+'20'!K9+'21'!K9+'22'!J9+'23'!K9+'24'!K9+'25'!K9+'26'!J9+'27'!K9+'28'!K9+'29'!K9 -> 0 | L9: =SUM(D9:K9) -> 0 | Q9: 0
B10: 1111085 | C10: ชิฟฟอน 8 ชิ้น บลูเบอรี่ล้วน | D10: ='1'!D10+'2'!D10+'3'!D10+'4'!D10+'5'!D10+'6'!D10+'7'!D10+'8'!D10+'9'!D10+'10'!D10+'11'!D10+'12'!C10+'13'!D10+'14'!D10+'15'!D10+'16'!D10+'17'!D10+'18'!D10+'19'!C10+'20'!D10+'21'!D10+'22'!C10+'23'!D10+'24'!D10+'25'!D10+'26'!C10+'27'!D10+'28'!D10+'29'!D10 -> 0 | E10: ='1'!E10+'2'!E10+'3'!E10+'4'!E10+'5'!E10+'6'!E10+'7'!E10+'8'!E10+'9'!E10+'10'!E10+'11'!E10+'12'!D10+'13'!E10+'14'!E10+'15'!E10+'16'!E10+'17'!E10+'18'!E10+'19'!D10+'20'!E10+'21'!E10+'22'!D10+'23'!E10+'24'!E10+'25'!E10+'26'!D10+'27'!E10+'28'!E10+'29'!E10 -> 0 | F10: ='1'!F10+'2'!F10+'3'!F10+'4'!F10+'5'!F10+'6'!F10+'7'!F10+'8'!F10+'9'!F10+'10'!F10+'11'!F10+'12'!E10+'13'!F10+'14'!F10+'15'!F10+'16'!F10+'17'!F10+'18'!F10+'19'!E10+'20'!F10+'21'!F10+'22'!E10+'23'!F10+'24'!F10+'25'!F10+'26'!E10+'27'!F10+'28'!F10+'29'!F10 -> 0 | G10: ='1'!G10+'2'!G10+'3'!G10+'4'!G10+'5'!G10+'6'!G10+'7'!G10+'8'!G10+'9'!G10+'10'!G10+'11'!G10+'12'!F10+'13'!G10+'14'!G10+'15'!G10+'16'!G10+'17'!G10+'18'!G10+'19'!F10+'20'!G10+'21'!G10+'22'!F10+'23'!G10+'24'!G10+'25'!G10+'26'!F10+'27'!G10+'28'!G10+'29'!G10 -> 0 | H10: ='1'!H10+'2'!H10+'3'!H10+'4'!H10+'5'!H10+'6'!H10+'7'!H10+'8'!H10+'9'!H10+'10'!H10+'11'!H10+'12'!G10+'13'!H10+'14'!H10+'15'!H10+'16'!H10+'17'!H10+'18'!H10+'19'!G10+'20'!H10+'21'!H10+'22'!G10+'23'!H10+'24'!H10+'25'!H10+'26'!G10+'27'!H10+'28'!H10+'29'!H10 -> 0 | I10: ='1'!I10+'2'!I10+'3'!I10+'4'!I10+'5'!I10+'6'!I10+'7'!I10+'8'!I10+'9'!I10+'10'!I10+'11'!I10+'12'!H10+'13'!I10+'14'!I10+'15'!I10+'16'!I10+'17'!I10+'18'!I10+'19'!H10+'20'!I10+'21'!I10+'22'!H10+'23'!I10+'24'!I10+'25'!I10+'26'!H10+'27'!I10+'28'!I10+'29'!I10 -> 0 | J10: ='1'!J10+'2'!J10+'3'!J10+'4'!J10+'5'!J10+'6'!J10+'7'!J10+'8'!J10+'9'!J10+'10'!J10+'11'!J10+'12'!I10+'13'!J10+'14'!J10+'15'!J10+'16'!J10+'17'!J10+'18'!J10+'19'!I10+'20'!J10+'21'!J10+'22'!I10+'23'!J10+'24'!J10+'25'!J10+'26'!I10+'27'!J10+'28'!J10+'29'!J10 -> 0 | K10: ='1'!K10+'2'!K10+'3'!K10+'4'!K10+'5'!K10+'6'!K10+'7'!K10+'8'!K10+'9'!K10+'10'!K10+'11'!K10+'12'!J10+'13'!K10+'14'!K10+'15'!K10+'16'!K10+'17'!K10+'18'!K10+'19'!J10+'20'!K10+'21'!K10+'22'!J10+'23'!K10+'24'!K10+'25'!K10+'26'!J10+'27'!K10+'28'!K10+'29'!K10 -> 0 | L10: =SUM(D10:K10) -> 0 | Q10: 0
B11: 1111086 | C11: ชิฟฟอน 8 ชิ้น มะพร้าวล้วน | D11: ='1'!D11+'2'!D11+'3'!D11+'4'!D11+'5'!D11+'6'!D11+'7'!D11+'8'!D11+'9'!D11+'10'!D11+'11'!D11+'12'!C11+'13'!D11+'14'!D11+'15'!D11+'16'!D11+'17'!D11+'18'!D11+'19'!C11+'20'!D11+'21'!D11+'22'!C11+'23'!D11+'24'!D11+'25'!D11+'26'!C11+'27'!D11+'28'!D11+'29'!D11 -> 20 | E11: ='1'!E11+'2'!E11+'3'!E11+'4'!E11+'5'!E11+'6'!E11+'7'!E11+'8'!E11+'9'!E11+'10'!E11+'11'!E11+'12'!D11+'13'!E11+'14'!E11+'15'!E11+'16'!E11+'17'!E11+'18'!E11+'19'!D11+'20'!E11+'21'!E11+'22'!D11+'23'!E11+'24'!E11+'25'!E11+'26'!D11+'27'!E11+'28'!E11+'29'!E11 -> 0 | F11: ='1'!F11+'2'!F11+'3'!F11+'4'!F11+'5'!F11+'6'!F11+'7'!F11+'8'!F11+'9'!F11+'10'!F11+'11'!F11+'12'!E11+'13'!F11+'14'!F11+'15'!F11+'16'!F11+'17'!F11+'18'!F11+'19'!E11+'20'!F11+'21'!F11+'22'!E11+'23'!F11+'24'!F11+'25'!F11+'26'!E11+'27'!F11+'28'!F11+'29'!F11 -> 0 | G11: ='1'!G11+'2'!G11+'3'!G11+'4'!G11+'5'!G11+'6'!G11+'7'!G11+'8'!G11+'9'!G11+'10'!G11+'11'!G11+'12'!F11+'13'!G11+'14'!G11+'15'!G11+'16'!G11+'17'!G11+'18'!G11+'19'!F11+'20'!G11+'21'!G11+'22'!F11+'23'!G11+'24'!G11+'25'!G11+'26'!F11+'27'!G11+'28'!G11+'29'!G11 -> 0 | H11: ='1'!H11+'2'!H11+'3'!H11+'4'!H11+'5'!H11+'6'!H11+'7'!H11+'8'!H11+'9'!H11+'10'!H11+'11'!H11+'12'!G11+'13'!H11+'14'!H11+'15'!H11+'16'!H11+'17'!H11+'18'!H11+'19'!G11+'20'!H11+'21'!H11+'22'!G11+'23'!H11+'24'!H11+'25'!H11+'26'!G11+'27'!H11+'28'!H11+'29'!H11 -> 0 | I11: ='1'!I11+'2'!I11+'3'!I11+'4'!I11+'5'!I11+'6'!I11+'7'!I11+'8'!I11+'9'!I11+'10'!I11+'11'!I11+'12'!H11+'13'!I11+'14'!I11+'15'!I11+'16'!I11+'17'!I11+'18'!I11+'19'!H11+'20'!I11+'21'!I11+'22'!H11+'23'!I11+'24'!I11+'25'!I11+'26'!H11+'27'!I11+'28'!I11+'29'!I11 -> 0 | J11: ='1'!J11+'2'!J11+'3'!J11+'4'!J11+'5'!J11+'6'!J11+'7'!J11+'8'!J11+'9'!J11+'10'!J11+'11'!J11+'12'!I11+'13'!J11+'14'!J11+'15'!J11+'16'!J11+'17'!J11+'18'!J11+'19'!I11+'20'!J11+'21'!J11+'22'!I11+'23'!J11+'24'!J11+'25'!J11+'26'!I11+'27'!J11+'28'!J11+'29'!J11 -> 0 | K11: ='1'!K11+'2'!K11+'3'!K11+'4'!K11+'5'!K11+'6'!K11+'7'!K11+'8'!K11+'9'!K11+'10'!K11+'11'!K11+'12'!J11+'13'!K11+'14'!K11+'15'!K11+'16'!K11+'17'!K11+'18'!K11+'19'!J11+'20'!K11+'21'!K11+'22'!J11+'23'!K11+'24'!K11+'25'!K11+'26'!J11+'27'!K11+'28'!K11+'29'!K11 -> 0 | L11: =SUM(D11:K11) -> 20 | Q11: 0
B12: 1111087 | C12: ชิฟฟอน 8 ชิ้น สตอเบอรี่ล้วน | D12: ='1'!D12+'2'!D12+'3'!D12+'4'!D12+'5'!D12+'6'!D12+'7'!D12+'8'!D12+'9'!D12+'10'!D12+'11'!D12+'12'!C12+'13'!D12+'14'!D12+'15'!D12+'16'!D12+'17'!D12+'18'!D12+'19'!C12+'20'!D12+'21'!D12+'22'!C12+'23'!D12+'24'!D12+'25'!D12+'26'!C12+'27'!D12+'28'!D12+'29'!D12 -> 0 | E12: ='1'!E12+'2'!E12+'3'!E12+'4'!E12+'5'!E12+'6'!E12+'7'!E12+'8'!E12+'9'!E12+'10'!E12+'11'!E12+'12'!D12+'13'!E12+'14'!E12+'15'!E12+'16'!E12+'17'!E12+'18'!E12+'19'!D12+'20'!E12+'21'!E12+'22'!D12+'23'!E12+'24'!E12+'25'!E12+'26'!D12+'27'!E12+'28'!E12+'29'!E12 -> 0 | F12: ='1'!F12+'2'!F12+'3'!F12+'4'!F12+'5'!F12+'6'!F12+'7'!F12+'8'!F12+'9'!F12+'10'!F12+'11'!F12+'12'!E12+'13'!F12+'14'!F12+'15'!F12+'16'!F12+'17'!F12+'18'!F12+'19'!E12+'20'!F12+'21'!F12+'22'!E12+'23'!F12+'24'!F12+'25'!F12+'26'!E12+'27'!F12+'28'!F12+'29'!F12 -> 0 | G12: ='1'!G12+'2'!G12+'3'!G12+'4'!G12+'5'!G12+'6'!G12+'7'!G12+'8'!G12+'9'!G12+'10'!G12+'11'!G12+'12'!F12+'13'!G12+'14'!G12+'15'!G12+'16'!G12+'17'!G12+'18'!G12+'19'!F12+'20'!G12+'21'!G12+'22'!F12+'23'!G12+'24'!G12+'25'!G12+'26'!F12+'27'!G12+'28'!G12+'29'!G12 -> 0 | H12: ='1'!H12+'2'!H12+'3'!H12+'4'!H12+'5'!H12+'6'!H12+'7'!H12+'8'!H12+'9'!H12+'10'!H12+'11'!H12+'12'!G12+'13'!H12+'14'!H12+'15'!H12+'16'!H12+'17'!H12+'18'!H12+'19'!G12+'20'!H12+'21'!H12+'22'!G12+'23'!H12+'24'!H12+'25'!H12+'26'!G12+'27'!H12+'28'!H12+'29'!H12 -> 0 | I12: ='1'!I12+'2'!I12+'3'!I12+'4'!I12+'5'!I12+'6'!I12+'7'!I12+'8'!I12+'9'!I12+'10'!I12+'11'!I12+'12'!H12+'13'!I12+'14'!I12+'15'!I12+'16'!I12+'17'!I12+'18'!I12+'19'!H12+'20'!I12+'21'!I12+'22'!H12+'23'!I12+'24'!I12+'25'!I12+'26'!H12+'27'!I12+'28'!I12+'29'!I12 -> 0 | J12: ='1'!J12+'2'!J12+'3'!J12+'4'!J12+'5'!J12+'6'!J12+'7'!J12+'8'!J12+'9'!J12+'10'!J12+'11'!J12+'12'!I12+'13'!J12+'14'!J12+'15'!J12+'16'!J12+'17'!J12+'18'!J12+'19'!I12+'20'!J12+'21'!J12+'22'!I12+'23'!J12+'24'!J12+'25'!J12+'26'!I12+'27'!J12+'28'!J12+'29'!J12 -> 0 | K12: ='1'!K12+'2'!K12+'3'!K12+'4'!K12+'5'!K12+'6'!K12+'7'!K12+'8'!K12+'9'!K12+'10'!K12+'11'!K12+'12'!J12+'13'!K12+'14'!K12+'15'!K12+'16'!K12+'17'!K12+'18'!K12+'19'!J12+'20'!K12+'21'!K12+'22'!J12+'23'!K12+'24'!K12+'25'!K12+'26'!J12+'27'!K12+'28'!K12+'29'!K12 -> 0 | L12: =SUM(D12:K12) -> 0 | Q12: 0
B13: 1111088 | C13: ชิฟฟอน 8 ชิ้น ส้มล้วน | D13: ='1'!D13+'2'!D13+'3'!D13+'4'!D13+'5'!D13+'6'!D13+'7'!D13+'8'!D13+'9'!D13+'10'!D13+'11'!D13+'12'!C13+'13'!D13+'14'!D13+'15'!D13+'16'!D13+'17'!D13+'18'!D13+'19'!C13+'20'!D13+'21'!D13+'22'!C13+'23'!D13+'24'!D13+'25'!D13+'26'!C13+'27'!D13+'28'!D13+'29'!D13 -> 0 | E13: ='1'!E13+'2'!E13+'3'!E13+'4'!E13+'5'!E13+'6'!E13+'7'!E13+'8'!E13+'9'!E13+'10'!E13+'11'!E13+'12'!D13+'13'!E13+'14'!E13+'15'!E13+'16'!E13+'17'!E13+'18'!E13+'19'!D13+'20'!E13+'21'!E13+'22'!D13+'23'!E13+'24'!E13+'25'!E13+'26'!D13+'27'!E13+'28'!E13+'29'!E13 -> 0 | F13: ='1'!F13+'2'!F13+'3'!F13+'4'!F13+'5'!F13+'6'!F13+'7'!F13+'8'!F13+'9'!F13+'10'!F13+'11'!F13+'12'!E13+'13'!F13+'14'!F13+'15'!F13+'16'!F13+'17'!F13+'18'!F13+'19'!E13+'20'!F13+'21'!F13+'22'!E13+'23'!F13+'24'!F13+'25'!F13+'26'!E13+'27'!F13+'28'!F13+'29'!F13 -> 0 | G13: ='1'!G13+'2'!G13+'3'!G13+'4'!G13+'5'!G13+'6'!G13+'7'!G13+'8'!G13+'9'!G13+'10'!G13+'11'!G13+'12'!F13+'13'!G13+'14'!G13+'15'!G13+'16'!G13+'17'!G13+'18'!G13+'19'!F13+'20'!G13+'21'!G13+'22'!F13+'23'!G13+'24'!G13+'25'!G13+'26'!F13+'27'!G13+'28'!G13+'29'!G13 -> 0 | H13: ='1'!H13+'2'!H13+'3'!H13+'4'!H13+'5'!H13+'6'!H13+'7'!H13+'8'!H13+'9'!H13+'10'!H13+'11'!H13+'12'!G13+'13'!H13+'14'!H13+'15'!H13+'16'!H13+'17'!H13+'18'!H13+'19'!G13+'20'!H13+'21'!H13+'22'!G13+'23'!H13+'24'!H13+'25'!H13+'26'!G13+'27'!H13+'28'!H13+'29'!H13 -> 0 | I13: ='1'!I13+'2'!I13+'3'!I13+'4'!I13+'5'!I13+'6'!I13+'7'!I13+'8'!I13+'9'!I13+'10'!I13+'11'!I13+'12'!H13+'13'!I13+'14'!I13+'15'!I13+'16'!I13+'17'!I13+'18'!I13+'19'!H13+'20'!I13+'21'!I13+'22'!H13+'23'!I13+'24'!I13+'25'!I13+'26'!H13+'27'!I13+'28'!I13+'29'!I13 -> 0 | J13: ='1'!J13+'2'!J13+'3'!J13+'4'!J13+'5'!J13+'6'!J13+'7'!J13+'8'!J13+'9'!J13+'10'!J13+'11'!J13+'12'!I13+'13'!J13+'14'!J13+'15'!J13+'16'!J13+'17'!J13+'18'!J13+'19'!I13+'20'!J13+'21'!J13+'22'!I13+'23'!J13+'24'!J13+'25'!J13+'26'!I13+'27'!J13+'28'!J13+'29'!J13 -> 0 | K13: ='1'!K13+'2'!K13+'3'!K13+'4'!K13+'5'!K13+'6'!K13+'7'!K13+'8'!K13+'9'!K13+'10'!K13+'11'!K13+'12'!J13+'13'!K13+'14'!K13+'15'!K13+'16'!K13+'17'!K13+'18'!K13+'19'!J13+'20'!K13+'21'!K13+'22'!J13+'23'!K13+'24'!K13+'25'!K13+'26'!J13+'27'!K13+'28'!K13+'29'!K13 -> 0 | L13: =SUM(D13:K13) -> 0 | Q13: 0
B14: 1111089 | C14: ชิฟฟอน 8 ชิ้น เนยล้วน | D14: ='1'!D14+'2'!D14+'3'!D14+'4'!D14+'5'!D14+'6'!D14+'7'!D14+'8'!D14+'9'!D14+'10'!D14+'11'!D14+'12'!C14+'13'!D14+'14'!D14+'15'!D14+'16'!D14+'17'!D14+'18'!D14+'19'!C14+'20'!D14+'21'!D14+'22'!C14+'23'!D14+'24'!D14+'25'!D14+'26'!C14+'27'!D14+'28'!D14+'29'!D14 -> 0 | E14: ='1'!E14+'2'!E14+'3'!E14+'4'!E14+'5'!E14+'6'!E14+'7'!E14+'8'!E14+'9'!E14+'10'!E14+'11'!E14+'12'!D14+'13'!E14+'14'!E14+'15'!E14+'16'!E14+'17'!E14+'18'!E14+'19'!D14+'20'!E14+'21'!E14+'22'!D14+'23'!E14+'24'!E14+'25'!E14+'26'!D14+'27'!E14+'28'!E14+'29'!E14 -> 0 | F14: ='1'!F14+'2'!F14+'3'!F14+'4'!F14+'5'!F14+'6'!F14+'7'!F14+'8'!F14+'9'!F14+'10'!F14+'11'!F14+'12'!E14+'13'!F14+'14'!F14+'15'!F14+'16'!F14+'17'!F14+'18'!F14+'19'!E14+'20'!F14+'21'!F14+'22'!E14+'23'!F14+'24'!F14+'25'!F14+'26'!E14+'27'!F14+'28'!F14+'29'!F14 -> 0 | G14: ='1'!G14+'2'!G14+'3'!G14+'4'!G14+'5'!G14+'6'!G14+'7'!G14+'8'!G14+'9'!G14+'10'!G14+'11'!G14+'12'!F14+'13'!G14+'14'!G14+'15'!G14+'16'!G14+'17'!G14+'18'!G14+'19'!F14+'20'!G14+'21'!G14+'22'!F14+'23'!G14+'24'!G14+'25'!G14+'26'!F14+'27'!G14+'28'!G14+'29'!G14 -> 0 | H14: ='1'!H14+'2'!H14+'3'!H14+'4'!H14+'5'!H14+'6'!H14+'7'!H14+'8'!H14+'9'!H14+'10'!H14+'11'!H14+'12'!G14+'13'!H14+'14'!H14+'15'!H14+'16'!H14+'17'!H14+'18'!H14+'19'!G14+'20'!H14+'21'!H14+'22'!G14+'23'!H14+'24'!H14+'25'!H14+'26'!G14+'27'!H14+'28'!H14+'29'!H14 -> 0 | I14: ='1'!I14+'2'!I14+'3'!I14+'4'!I14+'5'!I14+'6'!I14+'7'!I14+'8'!I14+'9'!I14+'10'!I14+'11'!I14+'12'!H14+'13'!I14+'14'!I14+'15'!I14+'16'!I14+'17'!I14+'18'!I14+'19'!H14+'20'!I14+'21'!I14+'22'!H14+'23'!I14+'24'!I14+'25'!I14+'26'!H14+'27'!I14+'28'!I14+'29'!I14 -> 0 | J14: ='1'!J14+'2'!J14+'3'!J14+'4'!J14+'5'!J14+'6'!J14+'7'!J14+'8'!J14+'9'!J14+'10'!J14+'11'!J14+'12'!I14+'13'!J14+'14'!J14+'15'!J14+'16'!J14+'17'!J14+'18'!J14+'19'!I14+'20'!J14+'21'!J14+'22'!I14+'23'!J14+'24'!J14+'25'!J14+'26'!I14+'27'!J14+'28'!J14+'29'!J14 -> 0 | K14: ='1'!K14+'2'!K14+'3'!K14+'4'!K14+'5'!K14+'6'!K14+'7'!K14+'8'!K14+'9'!K14+'10'!K14+'11'!K14+'12'!J14+'13'!K14+'14'!K14+'15'!K14+'16'!K14+'17'!K14+'18'!K14+'19'!J14+'20'!K14+'21'!K14+'22'!J14+'23'!K14+'24'!K14+'25'!K14+'26'!J14+'27'!K14+'28'!K14+'29'!K14 -> 0 | L14: =SUM(D14:K14) -> 0 | Q14: 0
B15: 1111090 | C15: ชิฟฟอน 8 ชิ้น เผือกล้วน | D15: ='1'!D15+'2'!D15+'3'!D15+'4'!D15+'5'!D15+'6'!D15+'7'!D15+'8'!D15+'9'!D15+'10'!D15+'11'!D15+'12'!C15+'13'!D15+'14'!D15+'15'!D15+'16'!D15+'17'!D15+'18'!D15+'19'!C15+'20'!D15+'21'!D15+'22'!C15+'23'!D15+'24'!D15+'25'!D15+'26'!C15+'27'!D15+'28'!D15+'29'!D15 -> 0 | E15: ='1'!E15+'2'!E15+'3'!E15+'4'!E15+'5'!E15+'6'!E15+'7'!E15+'8'!E15+'9'!E15+'10'!E15+'11'!E15+'12'!D15+'13'!E15+'14'!E15+'15'!E15+'16'!E15+'17'!E15+'18'!E15+'19'!D15+'20'!E15+'21'!E15+'22'!D15+'23'!E15+'24'!E15+'25'!E15+'26'!D15+'27'!E15+'28'!E15+'29'!E15 -> 0 | F15: ='1'!F15+'2'!F15+'3'!F15+'4'!F15+'5'!F15+'6'!F15+'7'!F15+'8'!F15+'9'!F15+'10'!F15+'11'!F15+'12'!E15+'13'!F15+'14'!F15+'15'!F15+'16'!F15+'17'!F15+'18'!F15+'19'!E15+'20'!F15+'21'!F15+'22'!E15+'23'!F15+'24'!F15+'25'!F15+'26'!E15+'27'!F15+'28'!F15+'29'!F15 -> 0 | G15: ='1'!G15+'2'!G15+'3'!G15+'4'!G15+'5'!G15+'6'!G15+'7'!G15+'8'!G15+'9'!G15+'10'!G15+'11'!G15+'12'!F15+'13'!G15+'14'!G15+'15'!G15+'16'!G15+'17'!G15+'18'!G15+'19'!F15+'20'!G15+'21'!G15+'22'!F15+'23'!G15+'24'!G15+'25'!G15+'26'!F15+'27'!G15+'28'!G15+'29'!G15 -> 0 | H15: ='1'!H15+'2'!H15+'3'!H15+'4'!H15+'5'!H15+'6'!H15+'7'!H15+'8'!H15+'9'!H15+'10'!H15+'11'!H15+'12'!G15+'13'!H15+'14'!H15+'15'!H15+'16'!H15+'17'!H15+'18'!H15+'19'!G15+'20'!H15+'21'!H15+'22'!G15+'23'!H15+'24'!H15+'25'!H15+'26'!G15+'27'!H15+'28'!H15+'29'!H15 -> 0 | I15: ='1'!I15+'2'!I15+'3'!I15+'4'!I15+'5'!I15+'6'!I15+'7'!I15+'8'!I15+'9'!I15+'10'!I15+'11'!I15+'12'!H15+'13'!I15+'14'!I15+'15'!I15+'16'!I15+'17'!I15+'18'!I15+'19'!H15+'20'!I15+'21'!I15+'22'!H15+'23'!I15+'24'!I15+'25'!I15+'26'!H15+'27'!I15+'28'!I15+'29'!I15 -> 0 | J15: ='1'!J15+'2'!J15+'3'!J15+'4'!J15+'5'!J15+'6'!J15+'7'!J15+'8'!J15+'9'!J15+'10'!J15+'11'!J15+'12'!I15+'13'!J15+'14'!J15+'15'!J15+'16'!J15+'17'!J15+'18'!J15+'19'!I15+'20'!J15+'21'!J15+'22'!I15+'23'!J15+'24'!J15+'25'!J15+'26'!I15+'27'!J15+'28'!J15+'29'!J15 -> 0 | K15: ='1'!K15+'2'!K15+'3'!K15+'4'!K15+'5'!K15+'6'!K15+'7'!K15+'8'!K15+'9'!K15+'10'!K15+'11'!K15+'12'!J15+'13'!K15+'14'!K15+'15'!K15+'16'!K15+'17'!K15+'18'!K15+'19'!J15+'20'!K15+'21'!K15+'22'!J15+'23'!K15+'24'!K15+'25'!K15+'26'!J15+'27'!K15+'28'!K15+'29'!K15 -> 0 | L15: =SUM(D15:K15) -> 0 | Q15: 0
B16: 1111091 | C16: ชิฟฟอน 8 ชิ้น ใบเตยล้วน | D16: ='1'!D16+'2'!D16+'3'!D16+'4'!D16+'5'!D16+'6'!D16+'7'!D16+'8'!D16+'9'!D16+'10'!D16+'11'!D16+'12'!C16+'13'!D16+'14'!D16+'15'!D16+'16'!D16+'17'!D16+'18'!D16+'19'!C16+'20'!D16+'21'!D16+'22'!C16+'23'!D16+'24'!D16+'25'!D16+'26'!C16+'27'!D16+'28'!D16+'29'!D16 -> 0 | E16: ='1'!E16+'2'!E16+'3'!E16+'4'!E16+'5'!E16+'6'!E16+'7'!E16+'8'!E16+'9'!E16+'10'!E16+'11'!E16+'12'!D16+'13'!E16+'14'!E16+'15'!E16+'16'!E16+'17'!E16+'18'!E16+'19'!D16+'20'!E16+'21'!E16+'22'!D16+'23'!E16+'24'!E16+'25'!E16+'26'!D16+'27'!E16+'28'!E16+'29'!E16 -> 0 | F16: ='1'!F16+'2'!F16+'3'!F16+'4'!F16+'5'!F16+'6'!F16+'7'!F16+'8'!F16+'9'!F16+'10'!F16+'11'!F16+'12'!E16+'13'!F16+'14'!F16+'15'!F16+'16'!F16+'17'!F16+'18'!F16+'19'!E16+'20'!F16+'21'!F16+'22'!E16+'23'!F16+'24'!F16+'25'!F16+'26'!E16+'27'!F16+'28'!F16+'29'!F16 -> 0 | G16: ='1'!G16+'2'!G16+'3'!G16+'4'!G16+'5'!G16+'6'!G16+'7'!G16+'8'!G16+'9'!G16+'10'!G16+'11'!G16+'12'!F16+'13'!G16+'14'!G16+'15'!G16+'16'!G16+'17'!G16+'18'!G16+'19'!F16+'20'!G16+'21'!G16+'22'!F16+'23'!G16+'24'!G16+'25'!G16+'26'!F16+'27'!G16+'28'!G16+'29'!G16 -> 0 | H16: ='1'!H16+'2'!H16+'3'!H16+'4'!H16+'5'!H16+'6'!H16+'7'!H16+'8'!H16+'9'!H16+'10'!H16+'11'!H16+'12'!G16+'13'!H16+'14'!H16+'15'!H16+'16'!H16+'17'!H16+'18'!H16+'19'!G16+'20'!H16+'21'!H16+'22'!G16+'23'!H16+'24'!H16+'25'!H16+'26'!G16+'27'!H16+'28'!H16+'29'!H16 -> 0 | I16: ='1'!I16+'2'!I16+'3'!I16+'4'!I16+'5'!I16+'6'!I16+'7'!I16+'8'!I16+'9'!I16+'10'!I16+'11'!I16+'12'!H16+'13'!I16+'14'!I16+'15'!I16+'16'!I16+'17'!I16+'18'!I16+'19'!H16+'20'!I16+'21'!I16+'22'!H16+'23'!I16+'24'!I16+'25'!I16+'26'!H16+'27'!I16+'28'!I16+'29'!I16 -> 0 | J16: ='1'!J16+'2'!J16+'3'!J16+'4'!J16+'5'!J16+'6'!J16+'7'!J16+'8'!J16+'9'!J16+'10'!J16+'11'!J16+'12'!I16+'13'!J16+'14'!J16+'15'!J16+'16'!J16+'17'!J16+'18'!J16+'19'!I16+'20'!J16+'21'!J16+'22'!I16+'23'!J16+'24'!J16+'25'!J16+'26'!I16+'27'!J16+'28'!J16+'29'!J16 -> 0 | K16: ='1'!K16+'2'!K16+'3'!K16+'4'!K16+'5'!K16+'6'!K16+'7'!K16+'8'!K16+'9'!K16+'10'!K16+'11'!K16+'12'!J16+'13'!K16+'14'!K16+'15'!K16+'16'!K16+'17'!K16+'18'!K16+'19'!J16+'20'!K16+'21'!K16+'22'!J16+'23'!K16+'24'!K16+'25'!K16+'26'!J16+'27'!K16+'28'!K16+'29'!K16 -> 185 | L16: =SUM(D16:K16) -> 185 | Q16: 0
B17: 1111092 | C17: ชิฟฟอน 8 ชิ้น กล้วยหอม | D17: ='1'!D17+'2'!D17+'3'!D17+'4'!D17+'5'!D17+'6'!D17+'7'!D17+'8'!D17+'9'!D17+'10'!D17+'11'!D17+'12'!C17+'13'!D17+'14'!D17+'15'!D17+'16'!D17+'17'!D17+'18'!D17+'19'!C17+'20'!D17+'21'!D17+'22'!C17+'23'!D17+'24'!D17+'25'!D17+'26'!C17+'27'!D17+'28'!D17+'29'!D17 -> 0 | E17: ='1'!E17+'2'!E17+'3'!E17+'4'!E17+'5'!E17+'6'!E17+'7'!E17+'8'!E17+'9'!E17+'10'!E17+'11'!E17+'12'!D17+'13'!E17+'14'!E17+'15'!E17+'16'!E17+'17'!E17+'18'!E17+'19'!D17+'20'!E17+'21'!E17+'22'!D17+'23'!E17+'24'!E17+'25'!E17+'26'!D17+'27'!E17+'28'!E17+'29'!E17 -> 0 | F17: ='1'!F17+'2'!F17+'3'!F17+'4'!F17+'5'!F17+'6'!F17+'7'!F17+'8'!F17+'9'!F17+'10'!F17+'11'!F17+'12'!E17+'13'!F17+'14'!F17+'15'!F17+'16'!F17+'17'!F17+'18'!F17+'19'!E17+'20'!F17+'21'!F17+'22'!E17+'23'!F17+'24'!F17+'25'!F17+'26'!E17+'27'!F17+'28'!F17+'29'!F17 -> 0 | G17: ='1'!G17+'2'!G17+'3'!G17+'4'!G17+'5'!G17+'6'!G17+'7'!G17+'8'!G17+'9'!G17+'10'!G17+'11'!G17+'12'!F17+'13'!G17+'14'!G17+'15'!G17+'16'!G17+'17'!G17+'18'!G17+'19'!F17+'20'!G17+'21'!G17+'22'!F17+'23'!G17+'24'!G17+'25'!G17+'26'!F17+'27'!G17+'28'!G17+'29'!G17 -> 0 | H17: ='1'!H17+'2'!H17+'3'!H17+'4'!H17+'5'!H17+'6'!H17+'7'!H17+'8'!H17+'9'!H17+'10'!H17+'11'!H17+'12'!G17+'13'!H17+'14'!H17+'15'!H17+'16'!H17+'17'!H17+'18'!H17+'19'!G17+'20'!H17+'21'!H17+'22'!G17+'23'!H17+'24'!H17+'25'!H17+'26'!G17+'27'!H17+'28'!H17+'29'!H17 -> 0 | I17: ='1'!I17+'2'!I17+'3'!I17+'4'!I17+'5'!I17+'6'!I17+'7'!I17+'8'!I17+'9'!I17+'10'!I17+'11'!I17+'12'!H17+'13'!I17+'14'!I17+'15'!I17+'16'!I17+'17'!I17+'18'!I17+'19'!H17+'20'!I17+'21'!I17+'22'!H17+'23'!I17+'24'!I17+'25'!I17+'26'!H17+'27'!I17+'28'!I17+'29'!I17 -> 0 | J17: ='1'!J17+'2'!J17+'3'!J17+'4'!J17+'5'!J17+'6'!J17+'7'!J17+'8'!J17+'9'!J17+'10'!J17+'11'!J17+'12'!I17+'13'!J17+'14'!J17+'15'!J17+'16'!J17+'17'!J17+'18'!J17+'19'!I17+'20'!J17+'21'!J17+'22'!I17+'23'!J17+'24'!J17+'25'!J17+'26'!I17+'27'!J17+'28'!J17+'29'!J17 -> 0 | K17: ='1'!K17+'2'!K17+'3'!K17+'4'!K17+'5'!K17+'6'!K17+'7'!K17+'8'!K17+'9'!K17+'10'!K17+'11'!K17+'12'!J17+'13'!K17+'14'!K17+'15'!K17+'16'!K17+'17'!K17+'18'!K17+'19'!J17+'20'!K17+'21'!K17+'22'!J17+'23'!K17+'24'!K17+'25'!K17+'26'!J17+'27'!K17+'28'!K17+'29'!K17 -> 0 | L17: =SUM(D17:K17) -> 0 | Q17: 0
B18: 1111093 | C18: ชิฟฟอน 8 ชิ้น โกโก้ล้วน | D18: ='1'!D18+'2'!D18+'3'!D18+'4'!D18+'5'!D18+'6'!D18+'7'!D18+'8'!D18+'9'!D18+'10'!D18+'11'!D18+'12'!C18+'13'!D18+'14'!D18+'15'!D18+'16'!D18+'17'!D18+'18'!D18+'19'!C18+'20'!D18+'21'!D18+'22'!C18+'23'!D18+'24'!D18+'25'!D18+'26'!C18+'27'!D18+'28'!D18+'29'!D18 -> 0 | E18: ='1'!E18+'2'!E18+'3'!E18+'4'!E18+'5'!E18+'6'!E18+'7'!E18+'8'!E18+'9'!E18+'10'!E18+'11'!E18+'12'!D18+'13'!E18+'14'!E18+'15'!E18+'16'!E18+'17'!E18+'18'!E18+'19'!D18+'20'!E18+'21'!E18+'22'!D18+'23'!E18+'24'!E18+'25'!E18+'26'!D18+'27'!E18+'28'!E18+'29'!E18 -> 0 | F18: ='1'!F18+'2'!F18+'3'!F18+'4'!F18+'5'!F18+'6'!F18+'7'!F18+'8'!F18+'9'!F18+'10'!F18+'11'!F18+'12'!E18+'13'!F18+'14'!F18+'15'!F18+'16'!F18+'17'!F18+'18'!F18+'19'!E18+'20'!F18+'21'!F18+'22'!E18+'23'!F18+'24'!F18+'25'!F18+'26'!E18+'27'!F18+'28'!F18+'29'!F18 -> 0 | G18: ='1'!G18+'2'!G18+'3'!G18+'4'!G18+'5'!G18+'6'!G18+'7'!G18+'8'!G18+'9'!G18+'10'!G18+'11'!G18+'12'!F18+'13'!G18+'14'!G18+'15'!G18+'16'!G18+'17'!G18+'18'!G18+'19'!F18+'20'!G18+'21'!G18+'22'!F18+'23'!G18+'24'!G18+'25'!G18+'26'!F18+'27'!G18+'28'!G18+'29'!G18 -> 0 | H18: ='1'!H18+'2'!H18+'3'!H18+'4'!H18+'5'!H18+'6'!H18+'7'!H18+'8'!H18+'9'!H18+'10'!H18+'11'!H18+'12'!G18+'13'!H18+'14'!H18+'15'!H18+'16'!H18+'17'!H18+'18'!H18+'19'!G18+'20'!H18+'21'!H18+'22'!G18+'23'!H18+'24'!H18+'25'!H18+'26'!G18+'27'!H18+'28'!H18+'29'!H18 -> 0 | I18: ='1'!I18+'2'!I18+'3'!I18+'4'!I18+'5'!I18+'6'!I18+'7'!I18+'8'!I18+'9'!I18+'10'!I18+'11'!I18+'12'!H18+'13'!I18+'14'!I18+'15'!I18+'16'!I18+'17'!I18+'18'!I18+'19'!H18+'20'!I18+'21'!I18+'22'!H18+'23'!I18+'24'!I18+'25'!I18+'26'!H18+'27'!I18+'28'!I18+'29'!I18 -> 0 | J18: ='1'!J18+'2'!J18+'3'!J18+'4'!J18+'5'!J18+'6'!J18+'7'!J18+'8'!J18+'9'!J18+'10'!J18+'11'!J18+'12'!I18+'13'!J18+'14'!J18+'15'!J18+'16'!J18+'17'!J18+'18'!J18+'19'!I18+'20'!J18+'21'!J18+'22'!I18+'23'!J18+'24'!J18+'25'!J18+'26'!I18+'27'!J18+'28'!J18+'29'!J18 -> 0 | K18: ='1'!K18+'2'!K18+'3'!K18+'4'!K18+'5'!K18+'6'!K18+'7'!K18+'8'!K18+'9'!K18+'10'!K18+'11'!K18+'12'!J18+'13'!K18+'14'!K18+'15'!K18+'16'!K18+'17'!K18+'18'!K18+'19'!J18+'20'!K18+'21'!K18+'22'!J18+'23'!K18+'24'!K18+'25'!K18+'26'!J18+'27'!K18+'28'!K18+'29'!K18 -> 0 | L18: =SUM(D18:K18) -> 0 | Q18: 0
B19: 1111094 | C19: ชิฟฟอน 8 ชิ้น ชาไทยล้วน | D19: ='1'!D19+'2'!D19+'3'!D19+'4'!D19+'5'!D19+'6'!D19+'7'!D19+'8'!D19+'9'!D19+'10'!D19+'11'!D19+'12'!C19+'13'!D19+'14'!D19+'15'!D19+'16'!D19+'17'!D19+'18'!D19+'19'!C19+'20'!D19+'21'!D19+'22'!C19+'23'!D19+'24'!D19+'25'!D19+'26'!C19+'27'!D19+'28'!D19+'29'!D19 -> 0 | E19: ='1'!E19+'2'!E19+'3'!E19+'4'!E19+'5'!E19+'6'!E19+'7'!E19+'8'!E19+'9'!E19+'10'!E19+'11'!E19+'12'!D19+'13'!E19+'14'!E19+'15'!E19+'16'!E19+'17'!E19+'18'!E19+'19'!D19+'20'!E19+'21'!E19+'22'!D19+'23'!E19+'24'!E19+'25'!E19+'26'!D19+'27'!E19+'28'!E19+'29'!E19 -> 0 | F19: ='1'!F19+'2'!F19+'3'!F19+'4'!F19+'5'!F19+'6'!F19+'7'!F19+'8'!F19+'9'!F19+'10'!F19+'11'!F19+'12'!E19+'13'!F19+'14'!F19+'15'!F19+'16'!F19+'17'!F19+'18'!F19+'19'!E19+'20'!F19+'21'!F19+'22'!E19+'23'!F19+'24'!F19+'25'!F19+'26'!E19+'27'!F19+'28'!F19+'29'!F19 -> 0 | G19: ='1'!G19+'2'!G19+'3'!G19+'4'!G19+'5'!G19+'6'!G19+'7'!G19+'8'!G19+'9'!G19+'10'!G19+'11'!G19+'12'!F19+'13'!G19+'14'!G19+'15'!G19+'16'!G19+'17'!G19+'18'!G19+'19'!F19+'20'!G19+'21'!G19+'22'!F19+'23'!G19+'24'!G19+'25'!G19+'26'!F19+'27'!G19+'28'!G19+'29'!G19 -> 0 | H19: ='1'!H19+'2'!H19+'3'!H19+'4'!H19+'5'!H19+'6'!H19+'7'!H19+'8'!H19+'9'!H19+'10'!H19+'11'!H19+'12'!G19+'13'!H19+'14'!H19+'15'!H19+'16'!H19+'17'!H19+'18'!H19+'19'!G19+'20'!H19+'21'!H19+'22'!G19+'23'!H19+'24'!H19+'25'!H19+'26'!G19+'27'!H19+'28'!H19+'29'!H19 -> 0 | I19: ='1'!I19+'2'!I19+'3'!I19+'4'!I19+'5'!I19+'6'!I19+'7'!I19+'8'!I19+'9'!I19+'10'!I19+'11'!I19+'12'!H19+'13'!I19+'14'!I19+'15'!I19+'16'!I19+'17'!I19+'18'!I19+'19'!H19+'20'!I19+'21'!I19+'22'!H19+'23'!I19+'24'!I19+'25'!I19+'26'!H19+'27'!I19+'28'!I19+'29'!I19 -> 0 | J19: ='1'!J19+'2'!J19+'3'!J19+'4'!J19+'5'!J19+'6'!J19+'7'!J19+'8'!J19+'9'!J19+'10'!J19+'11'!J19+'12'!I19+'13'!J19+'14'!J19+'15'!J19+'16'!J19+'17'!J19+'18'!J19+'19'!I19+'20'!J19+'21'!J19+'22'!I19+'23'!J19+'24'!J19+'25'!J19+'26'!I19+'27'!J19+'28'!J19+'29'!J19 -> 0 | K19: ='1'!K19+'2'!K19+'3'!K19+'4'!K19+'5'!K19+'6'!K19+'7'!K19+'8'!K19+'9'!K19+'10'!K19+'11'!K19+'12'!J19+'13'!K19+'14'!K19+'15'!K19+'16'!K19+'17'!K19+'18'!K19+'19'!J19+'20'!K19+'21'!K19+'22'!J19+'23'!K19+'24'!K19+'25'!K19+'26'!J19+'27'!K19+'28'!K19+'29'!K19 -> 0 | L19: =SUM(D19:K19) -> 0 | Q19: 0
B20: 1111095 | C20: ชิฟฟอน 8 ชิ้น ชาเขียวล้วน | D20: ='1'!D20+'2'!D20+'3'!D20+'4'!D20+'5'!D20+'6'!D20+'7'!D20+'8'!D20+'9'!D20+'10'!D20+'11'!D20+'12'!C20+'13'!D20+'14'!D20+'15'!D20+'16'!D20+'17'!D20+'18'!D20+'19'!C20+'20'!D20+'21'!D20+'22'!C20+'23'!D20+'24'!D20+'25'!D20+'26'!C20+'27'!D20+'28'!D20+'29'!D20 -> 0 | E20: ='1'!E20+'2'!E20+'3'!E20+'4'!E20+'5'!E20+'6'!E20+'7'!E20+'8'!E20+'9'!E20+'10'!E20+'11'!E20+'12'!D20+'13'!E20+'14'!E20+'15'!E20+'16'!E20+'17'!E20+'18'!E20+'19'!D20+'20'!E20+'21'!E20+'22'!D20+'23'!E20+'24'!E20+'25'!E20+'26'!D20+'27'!E20+'28'!E20+'29'!E20 -> 0 | F20: ='1'!F20+'2'!F20+'3'!F20+'4'!F20+'5'!F20+'6'!F20+'7'!F20+'8'!F20+'9'!F20+'10'!F20+'11'!F20+'12'!E20+'13'!F20+'14'!F20+'15'!F20+'16'!F20+'17'!F20+'18'!F20+'19'!E20+'20'!F20+'21'!F20+'22'!E20+'23'!F20+'24'!F20+'25'!F20+'26'!E20+'27'!F20+'28'!F20+'29'!F20 -> 0 | G20: ='1'!G20+'2'!G20+'3'!G20+'4'!G20+'5'!G20+'6'!G20+'7'!G20+'8'!G20+'9'!G20+'10'!G20+'11'!G20+'12'!F20+'13'!G20+'14'!G20+'15'!G20+'16'!G20+'17'!G20+'18'!G20+'19'!F20+'20'!G20+'21'!G20+'22'!F20+'23'!G20+'24'!G20+'25'!G20+'26'!F20+'27'!G20+'28'!G20+'29'!G20 -> 0 | H20: ='1'!H20+'2'!H20+'3'!H20+'4'!H20+'5'!H20+'6'!H20+'7'!H20+'8'!H20+'9'!H20+'10'!H20+'11'!H20+'12'!G20+'13'!H20+'14'!H20+'15'!H20+'16'!H20+'17'!H20+'18'!H20+'19'!G20+'20'!H20+'21'!H20+'22'!G20+'23'!H20+'24'!H20+'25'!H20+'26'!G20+'27'!H20+'28'!H20+'29'!H20 -> 0 | I20: ='1'!I20+'2'!I20+'3'!I20+'4'!I20+'5'!I20+'6'!I20+'7'!I20+'8'!I20+'9'!I20+'10'!I20+'11'!I20+'12'!H20+'13'!I20+'14'!I20+'15'!I20+'16'!I20+'17'!I20+'18'!I20+'19'!H20+'20'!I20+'21'!I20+'22'!H20+'23'!I20+'24'!I20+'25'!I20+'26'!H20+'27'!I20+'28'!I20+'29'!I20 -> 0 | J20: ='1'!J20+'2'!J20+'3'!J20+'4'!J20+'5'!J20+'6'!J20+'7'!J20+'8'!J20+'9'!J20+'10'!J20+'11'!J20+'12'!I20+'13'!J20+'14'!J20+'15'!J20+'16'!J20+'17'!J20+'18'!J20+'19'!I20+'20'!J20+'21'!J20+'22'!I20+'23'!J20+'24'!J20+'25'!J20+'26'!I20+'27'!J20+'28'!J20+'29'!J20 -> 0 | K20: ='1'!K20+'2'!K20+'3'!K20+'4'!K20+'5'!K20+'6'!K20+'7'!K20+'8'!K20+'9'!K20+'10'!K20+'11'!K20+'12'!J20+'13'!K20+'14'!K20+'15'!K20+'16'!K20+'17'!K20+'18'!K20+'19'!J20+'20'!K20+'21'!K20+'22'!J20+'23'!K20+'24'!K20+'25'!K20+'26'!J20+'27'!K20+'28'!K20+'29'!K20 -> 0 | L20: =SUM(D20:K20) -> 0 | Q20: 0
... B56: 1111074 | C56: ชิฟฟอนไส้แยมแยกชิ้น มะพร้าว | D56: ='1'!D56+'2'!D56+'3'!D56+'4'!D56+'5'!D56+'6'!D56+'7'!D56+'8'!D56+'9'!D56+'10'!D56+'11'!D56+'12'!C56+'13'!D56+'14'!D56+'15'!D56+'16'!D56+'17'!D56+'18'!D56+'19'!C56+'20'!D56+'21'!D56+'22'!C56+'23'!D56+'24'!D56+'25'!D56+'26'!C56+'27'!D56+'28'!D56+'29'!D56 -> 125 | E56: ='1'!E56+'2'!E56+'3'!E56+'4'!E56+'5'!E56+'6'!E56+'7'!E56+'8'!E56+'9'!E56+'10'!E56+'11'!E56+'12'!D56+'13'!E56+'14'!E56+'15'!E56+'16'!E56+'17'!E56+'18'!E56+'19'!D56+'20'!E56+'21'!E56+'22'!D56+'23'!E56+'24'!E56+'25'!E56+'26'!D56+'27'!E56+'28'!E56+'29'!E56 -> 80 | F56: ='1'!F56+'2'!F56+'3'!F56+'4'!F56+'5'!F56+'6'!F56+'7'!F56+'8'!F56+'9'!F56+'10'!F56+'11'!F56+'12'!E56+'13'!F56+'14'!F56+'15'!F56+'16'!F56+'17'!F56+'18'!F56+'19'!E56+'20'!F56+'21'!F56+'22'!E56+'23'!F56+'24'!F56+'25'!F56+'26'!E56+'27'!F56+'28'!F56+'29'!F56 -> 116 | G56: ='1'!G56+'2'!G56+'3'!G56+'4'!G56+'5'!G56+'6'!G56+'7'!G56+'8'!G56+'9'!G56+'10'!G56+'11'!G56+'12'!F56+'13'!G56+'14'!G56+'15'!G56+'16'!G56+'17'!G56+'18'!G56+'19'!F56+'20'!G56+'21'!G56+'22'!F56+'23'!G56+'24'!G56+'25'!G56+'26'!F56+'27'!G56+'28'!G56+'29'!G56 -> 135 | H56: ='1'!H56+'2'!H56+'3'!H56+'4'!H56+'5'!H56+'6'!H56+'7'!H56+'8'!H56+'9'!H56+'10'!H56+'11'!H56+'12'!G56+'13'!H56+'14'!H56+'15'!H56+'16'!H56+'17'!H56+'18'!H56+'19'!G56+'20'!H56+'21'!H56+'22'!G56+'23'!H56+'24'!H56+'25'!H56+'26'!G56+'27'!H56+'28'!H56+'29'!H56 -> 9 | I56: ='1'!I56+'2'!I56+'3'!I56+'4'!I56+'5'!I56+'6'!I56+'7'!I56+'8'!I56+'9'!I56+'10'!I56+'11'!I56+'12'!H56+'13'!I56+'14'!I56+'15'!I56+'16'!I56+'17'!I56+'18'!I56+'19'!H56+'20'!I56+'21'!I56+'22'!H56+'23'!I56+'24'!I56+'25'!I56+'26'!H56+'27'!I56+'28'!I56+'29'!I56 -> 0 | J56: ='1'!J56+'2'!J56+'3'!J56+'4'!J56+'5'!J56+'6'!J56+'7'!J56+'8'!J56+'9'!J56+'10'!J56+'11'!J56+'12'!I56+'13'!J56+'14'!J56+'15'!J56+'16'!J56+'17'!J56+'18'!J56+'19'!I56+'20'!J56+'21'!J56+'22'!I56+'23'!J56+'24'!J56+'25'!J56+'26'!I56+'27'!J56+'28'!J56+'29'!J56 -> 0 | K56: ='1'!K56+'2'!K56+'3'!K56+'4'!K56+'5'!K56+'6'!K56+'7'!K56+'8'!K56+'9'!K56+'10'!K56+'11'!K56+'12'!J56+'13'!K56+'14'!K56+'15'!K56+'16'!K56+'17'!K56+'18'!K56+'19'!J56+'20'!K56+'21'!K56+'22'!J56+'23'!K56+'24'!K56+'25'!K56+'26'!J56+'27'!K56+'28'!K56+'29'!K56 -> 0 | L56: =SUM(D56:K56) -> 465 | Q56: 0
B57: 1111075 | C57: ชิฟฟอนไส้แยมแยกชิ้น สตอเบอรี่ | D57: ='1'!D57+'2'!D57+'3'!D57+'4'!D57+'5'!D57+'6'!D57+'7'!D57+'8'!D57+'9'!D57+'10'!D57+'11'!D57+'12'!C57+'13'!D57+'14'!D57+'15'!D57+'16'!D57+'17'!D57+'18'!D57+'19'!C57+'20'!D57+'21'!D57+'22'!C57+'23'!D57+'24'!D57+'25'!D57+'26'!C57+'27'!D57+'28'!D57+'29'!D57 -> 125 | E57: ='1'!E57+'2'!E57+'3'!E57+'4'!E57+'5'!E57+'6'!E57+'7'!E57+'8'!E57+'9'!E57+'10'!E57+'11'!E57+'12'!D57+'13'!E57+'14'!E57+'15'!E57+'16'!E57+'17'!E57+'18'!E57+'19'!D57+'20'!E57+'21'!E57+'22'!D57+'23'!E57+'24'!E57+'25'!E57+'26'!D57+'27'!E57+'28'!E57+'29'!E57 -> 80 | F57: ='1'!F57+'2'!F57+'3'!F57+'4'!F57+'5'!F57+'6'!F57+'7'!F57+'8'!F57+'9'!F57+'10'!F57+'11'!F57+'12'!E57+'13'!F57+'14'!F57+'15'!F57+'16'!F57+'17'!F57+'18'!F57+'19'!E57+'20'!F57+'21'!F57+'22'!E57+'23'!F57+'24'!F57+'25'!F57+'26'!E57+'27'!F57+'28'!F57+'29'!F57 -> 115 | G57: ='1'!G57+'2'!G57+'3'!G57+'4'!G57+'5'!G57+'6'!G57+'7'!G57+'8'!G57+'9'!G57+'10'!G57+'11'!G57+'12'!F57+'13'!G57+'14'!G57+'15'!G57+'16'!G57+'17'!G57+'18'!G57+'19'!F57+'20'!G57+'21'!G57+'22'!F57+'23'!G57+'24'!G57+'25'!G57+'26'!F57+'27'!G57+'28'!G57+'29'!G57 -> 129 | H57: ='1'!H57+'2'!H57+'3'!H57+'4'!H57+'5'!H57+'6'!H57+'7'!H57+'8'!H57+'9'!H57+'10'!H57+'11'!H57+'12'!G57+'13'!H57+'14'!H57+'15'!H57+'16'!H57+'17'!H57+'18'!H57+'19'!G57+'20'!H57+'21'!H57+'22'!G57+'23'!H57+'24'!H57+'25'!H57+'26'!G57+'27'!H57+'28'!H57+'29'!H57 -> 9 | I57: ='1'!I57+'2'!I57+'3'!I57+'4'!I57+'5'!I57+'6'!I57+'7'!I57+'8'!I57+'9'!I57+'10'!I57+'11'!I57+'12'!H57+'13'!I57+'14'!I57+'15'!I57+'16'!I57+'17'!I57+'18'!I57+'19'!H57+'20'!I57+'21'!I57+'22'!H57+'23'!I57+'24'!I57+'25'!I57+'26'!H57+'27'!I57+'28'!I57+'29'!I57 -> 0 | J57: ='1'!J57+'2'!J57+'3'!J57+'4'!J57+'5'!J57+'6'!J57+'7'!J57+'8'!J57+'9'!J57+'10'!J57+'11'!J57+'12'!I57+'13'!J57+'14'!J57+'15'!J57+'16'!J57+'17'!J57+'18'!J57+'19'!I57+'20'!J57+'21'!J57+'22'!I57+'23'!J57+'24'!J57+'25'!J57+'26'!I57+'27'!J57+'28'!J57+'29'!J57 -> 0 | K57: ='1'!K57+'2'!K57+'3'!K57+'4'!K57+'5'!K57+'6'!K57+'7'!K57+'8'!K57+'9'!K57+'10'!K57+'11'!K57+'12'!J57+'13'!K57+'14'!K57+'15'!K57+'16'!K57+'17'!K57+'18'!K57+'19'!J57+'20'!K57+'21'!K57+'22'!J57+'23'!K57+'24'!K57+'25'!K57+'26'!J57+'27'!K57+'28'!K57+'29'!K57 -> 0 | L57: =SUM(D57:K57) -> 458 | N57: 1 | Q57: 1
B58: 1111076 | C58: ชิฟฟอนไส้แยมแยกชิ้น ส้ม | D58: ='1'!D58+'2'!D58+'3'!D58+'4'!D58+'5'!D58+'6'!D58+'7'!D58+'8'!D58+'9'!D58+'10'!D58+'11'!D58+'12'!C58+'13'!D58+'14'!D58+'15'!D58+'16'!D58+'17'!D58+'18'!D58+'19'!C58+'20'!D58+'21'!D58+'22'!C58+'23'!D58+'24'!D58+'25'!D58+'26'!C58+'27'!D58+'28'!D58+'29'!D58 -> 120 | E58: ='1'!E58+'2'!E58+'3'!E58+'4'!E58+'5'!E58+'6'!E58+'7'!E58+'8'!E58+'9'!E58+'10'!E58+'11'!E58+'12'!D58+'13'!E58+'14'!E58+'15'!E58+'16'!E58+'17'!E58+'18'!E58+'19'!D58+'20'!E58+'21'!E58+'22'!D58+'23'!E58+'24'!E58+'25'!E58+'26'!D58+'27'!E58+'28'!E58+'29'!E58 -> 80 | F58: ='1'!F58+'2'!F58+'3'!F58+'4'!F58+'5'!F58+'6'!F58+'7'!F58+'8'!F58+'9'!F58+'10'!F58+'11'!F58+'12'!E58+'13'!F58+'14'!F58+'15'!F58+'16'!F58+'17'!F58+'18'!F58+'19'!E58+'20'!F58+'21'!F58+'22'!E58+'23'!F58+'24'!F58+'25'!F58+'26'!E58+'27'!F58+'28'!F58+'29'!F58 -> 113 | G58: ='1'!G58+'2'!G58+'3'!G58+'4'!G58+'5'!G58+'6'!G58+'7'!G58+'8'!G58+'9'!G58+'10'!G58+'11'!G58+'12'!F58+'13'!G58+'14'!G58+'15'!G58+'16'!G58+'17'!G58+'18'!G58+'19'!F58+'20'!G58+'21'!G58+'22'!F58+'23'!G58+'24'!G58+'25'!G58+'26'!F58+'27'!G58+'28'!G58+'29'!G58 -> 124 | H58: ='1'!H58+'2'!H58+'3'!H58+'4'!H58+'5'!H58+'6'!H58+'7'!H58+'8'!H58+'9'!H58+'10'!H58+'11'!H58+'12'!G58+'13'!H58+'14'!H58+'15'!H58+'16'!H58+'17'!H58+'18'!H58+'19'!G58+'20'!H58+'21'!H58+'22'!G58+'23'!H58+'24'!H58+'25'!H58+'26'!G58+'27'!H58+'28'!H58+'29'!H58 -> 8 | I58: ='1'!I58+'2'!I58+'3'!I58+'4'!I58+'5'!I58+'6'!I58+'7'!I58+'8'!I58+'9'!I58+'10'!I58+'11'!I58+'12'!H58+'13'!I58+'14'!I58+'15'!I58+'16'!I58+'17'!I58+'18'!I58+'19'!H58+'20'!I58+'21'!I58+'22'!H58+'23'!I58+'24'!I58+'25'!I58+'26'!H58+'27'!I58+'28'!I58+'29'!I58 -> 0 | J58: ='1'!J58+'2'!J58+'3'!J58+'4'!J58+'5'!J58+'6'!J58+'7'!J58+'8'!J58+'9'!J58+'10'!J58+'11'!J58+'12'!I58+'13'!J58+'14'!J58+'15'!J58+'16'!J58+'17'!J58+'18'!J58+'19'!I58+'20'!J58+'21'!J58+'22'!I58+'23'!J58+'24'!J58+'25'!J58+'26'!I58+'27'!J58+'28'!J58+'29'!J58 -> 0 | K58: ='1'!K58+'2'!K58+'3'!K58+'4'!K58+'5'!K58+'6'!K58+'7'!K58+'8'!K58+'9'!K58+'10'!K58+'11'!K58+'12'!J58+'13'!K58+'14'!K58+'15'!K58+'16'!K58+'17'!K58+'18'!K58+'19'!J58+'20'!K58+'21'!K58+'22'!J58+'23'!K58+'24'!K58+'25'!K58+'26'!J58+'27'!K58+'28'!K58+'29'!K58 -> 0 | L58: =SUM(D58:K58) -> 445 | N58: 1 | Q58: 1
B59: 1111077 | C59: ชิฟฟอนไส้แยมแยกชิ้น บลูเบอรี่ | D59: ='1'!D59+'2'!D59+'3'!D59+'4'!D59+'5'!D59+'6'!D59+'7'!D59+'8'!D59+'9'!D59+'10'!D59+'11'!D59+'12'!C59+'13'!D59+'14'!D59+'15'!D59+'16'!D59+'17'!D59+'18'!D59+'19'!C59+'20'!D59+'21'!D59+'22'!C59+'23'!D59+'24'!D59+'25'!D59+'26'!C59+'27'!D59+'28'!D59+'29'!D59 -> 125 | E59: ='1'!E59+'2'!E59+'3'!E59+'4'!E59+'5'!E59+'6'!E59+'7'!E59+'8'!E59+'9'!E59+'10'!E59+'11'!E59+'12'!D59+'13'!E59+'14'!E59+'15'!E59+'16'!E59+'17'!E59+'18'!E59+'19'!D59+'20'!E59+'21'!E59+'22'!D59+'23'!E59+'24'!E59+'25'!E59+'26'!D59+'27'!E59+'28'!E59+'29'!E59 -> 80 | F59: ='1'!F59+'2'!F59+'3'!F59+'4'!F59+'5'!F59+'6'!F59+'7'!F59+'8'!F59+'9'!F59+'10'!F59+'11'!F59+'12'!E59+'13'!F59+'14'!F59+'15'!F59+'16'!F59+'17'!F59+'18'!F59+'19'!E59+'20'!F59+'21'!F59+'22'!E59+'23'!F59+'24'!F59+'25'!F59+'26'!E59+'27'!F59+'28'!F59+'29'!F59 -> 121 | G59: ='1'!G59+'2'!G59+'3'!G59+'4'!G59+'5'!G59+'6'!G59+'7'!G59+'8'!G59+'9'!G59+'10'!G59+'11'!G59+'12'!F59+'13'!G59+'14'!G59+'15'!G59+'16'!G59+'17'!G59+'18'!G59+'19'!F59+'20'!G59+'21'!G59+'22'!F59+'23'!G59+'24'!G59+'25'!G59+'26'!F59+'27'!G59+'28'!G59+'29'!G59 -> 123 | H59: ='1'!H59+'2'!H59+'3'!H59+'4'!H59+'5'!H59+'6'!H59+'7'!H59+'8'!H59+'9'!H59+'10'!H59+'11'!H59+'12'!G59+'13'!H59+'14'!H59+'15'!H59+'16'!H59+'17'!H59+'18'!H59+'19'!G59+'20'!H59+'21'!H59+'22'!G59+'23'!H59+'24'!H59+'25'!H59+'26'!G59+'27'!H59+'28'!H59+'29'!H59 -> 8 | I59: ='1'!I59+'2'!I59+'3'!I59+'4'!I59+'5'!I59+'6'!I59+'7'!I59+'8'!I59+'9'!I59+'10'!I59+'11'!I59+'12'!H59+'13'!I59+'14'!I59+'15'!I59+'16'!I59+'17'!I59+'18'!I59+'19'!H59+'20'!I59+'21'!I59+'22'!H59+'23'!I59+'24'!I59+'25'!I59+'26'!H59+'27'!I59+'28'!I59+'29'!I59 -> 0 | J59: ='1'!J59+'2'!J59+'3'!J59+'4'!J59+'5'!J59+'6'!J59+'7'!J59+'8'!J59+'9'!J59+'10'!J59+'11'!J59+'12'!I59+'13'!J59+'14'!J59+'15'!J59+'16'!J59+'17'!J59+'18'!J59+'19'!I59+'20'!J59+'21'!J59+'22'!I59+'23'!J59+'24'!J59+'25'!J59+'26'!I59+'27'!J59+'28'!J59+'29'!J59 -> 0 | K59: ='1'!K59+'2'!K59+'3'!K59+'4'!K59+'5'!K59+'6'!K59+'7'!K59+'8'!K59+'9'!K59+'10'!K59+'11'!K59+'12'!J59+'13'!K59+'14'!K59+'15'!K59+'16'!K59+'17'!K59+'18'!K59+'19'!J59+'20'!K59+'21'!K59+'22'!J59+'23'!K59+'24'!K59+'25'!K59+'26'!J59+'27'!K59+'28'!K59+'29'!K59 -> 0 | L59: =SUM(D59:K59) -> 457 | N59: 1 | Q59: 1
B60: 1111078 | C60: ชิฟฟอนไส้แยมแยกชิ้น นมชมพู | D60: ='1'!D60+'2'!D60+'3'!D60+'4'!D60+'5'!D60+'6'!D60+'7'!D60+'8'!D60+'9'!D60+'10'!D60+'11'!D60+'12'!C60+'13'!D60+'14'!D60+'15'!D60+'16'!D60+'17'!D60+'18'!D60+'19'!C60+'20'!D60+'21'!D60+'22'!C60+'23'!D60+'24'!D60+'25'!D60+'26'!C60+'27'!D60+'28'!D60+'29'!D60 -> 125 | E60: ='1'!E60+'2'!E60+'3'!E60+'4'!E60+'5'!E60+'6'!E60+'7'!E60+'8'!E60+'9'!E60+'10'!E60+'11'!E60+'12'!D60+'13'!E60+'14'!E60+'15'!E60+'16'!E60+'17'!E60+'18'!E60+'19'!D60+'20'!E60+'21'!E60+'22'!D60+'23'!E60+'24'!E60+'25'!E60+'26'!D60+'27'!E60+'28'!E60+'29'!E60 -> 80 | F60: ='1'!F60+'2'!F60+'3'!F60+'4'!F60+'5'!F60+'6'!F60+'7'!F60+'8'!F60+'9'!F60+'10'!F60+'11'!F60+'12'!E60+'13'!F60+'14'!F60+'15'!F60+'16'!F60+'17'!F60+'18'!F60+'19'!E60+'20'!F60+'21'!F60+'22'!E60+'23'!F60+'24'!F60+'25'!F60+'26'!E60+'27'!F60+'28'!F60+'29'!F60 -> 111 | G60: ='1'!G60+'2'!G60+'3'!G60+'4'!G60+'5'!G60+'6'!G60+'7'!G60+'8'!G60+'9'!G60+'10'!G60+'11'!G60+'12'!F60+'13'!G60+'14'!G60+'15'!G60+'16'!G60+'17'!G60+'18'!G60+'19'!F60+'20'!G60+'21'!G60+'22'!F60+'23'!G60+'24'!G60+'25'!G60+'26'!F60+'27'!G60+'28'!G60+'29'!G60 -> 123 | H60: ='1'!H60+'2'!H60+'3'!H60+'4'!H60+'5'!H60+'6'!H60+'7'!H60+'8'!H60+'9'!H60+'10'!H60+'11'!H60+'12'!G60+'13'!H60+'14'!H60+'15'!H60+'16'!H60+'17'!H60+'18'!H60+'19'!G60+'20'!H60+'21'!H60+'22'!G60+'23'!H60+'24'!H60+'25'!H60+'26'!G60+'27'!H60+'28'!H60+'29'!H60 -> 7 | I60: ='1'!I60+'2'!I60+'3'!I60+'4'!I60+'5'!I60+'6'!I60+'7'!I60+'8'!I60+'9'!I60+'10'!I60+'11'!I60+'12'!H60+'13'!I60+'14'!I60+'15'!I60+'16'!I60+'17'!I60+'18'!I60+'19'!H60+'20'!I60+'21'!I60+'22'!H60+'23'!I60+'24'!I60+'25'!I60+'26'!H60+'27'!I60+'28'!I60+'29'!I60 -> 0 | J60: ='1'!J60+'2'!J60+'3'!J60+'4'!J60+'5'!J60+'6'!J60+'7'!J60+'8'!J60+'9'!J60+'10'!J60+'11'!J60+'12'!I60+'13'!J60+'14'!J60+'15'!J60+'16'!J60+'17'!J60+'18'!J60+'19'!I60+'20'!J60+'21'!J60+'22'!I60+'23'!J60+'24'!J60+'25'!J60+'26'!I60+'27'!J60+'28'!J60+'29'!J60 -> 0 | K60: ='1'!K60+'2'!K60+'3'!K60+'4'!K60+'5'!K60+'6'!K60+'7'!K60+'8'!K60+'9'!K60+'10'!K60+'11'!K60+'12'!J60+'13'!K60+'14'!K60+'15'!K60+'16'!K60+'17'!K60+'18'!K60+'19'!J60+'20'!K60+'21'!K60+'22'!J60+'23'!K60+'24'!K60+'25'!K60+'26'!J60+'27'!K60+'28'!K60+'29'!K60 -> 0 | L60: =SUM(D60:K60) -> 446 | Q60: 0
B61: 1111079 | C61: ชิฟฟอนไส้แยมแยกชิ้น ชอคโกแลต | D61: ='1'!D61+'2'!D61+'3'!D61+'4'!D61+'5'!D61+'6'!D61+'7'!D61+'8'!D61+'9'!D61+'10'!D61+'11'!D61+'12'!C61+'13'!D61+'14'!D61+'15'!D61+'16'!D61+'17'!D61+'18'!D61+'19'!C61+'20'!D61+'21'!D61+'22'!C61+'23'!D61+'24'!D61+'25'!D61+'26'!C61+'27'!D61+'28'!D61+'29'!D61 -> 124 | E61: ='1'!E61+'2'!E61+'3'!E61+'4'!E61+'5'!E61+'6'!E61+'7'!E61+'8'!E61+'9'!E61+'10'!E61+'11'!E61+'12'!D61+'13'!E61+'14'!E61+'15'!E61+'16'!E61+'17'!E61+'18'!E61+'19'!D61+'20'!E61+'21'!E61+'22'!D61+'23'!E61+'24'!E61+'25'!E61+'26'!D61+'27'!E61+'28'!E61+'29'!E61 -> 80 | F61: ='1'!F61+'2'!F61+'3'!F61+'4'!F61+'5'!F61+'6'!F61+'7'!F61+'8'!F61+'9'!F61+'10'!F61+'11'!F61+'12'!E61+'13'!F61+'14'!F61+'15'!F61+'16'!F61+'17'!F61+'18'!F61+'19'!E61+'20'!F61+'21'!F61+'22'!E61+'23'!F61+'24'!F61+'25'!F61+'26'!E61+'27'!F61+'28'!F61+'29'!F61 -> 119 | G61: ='1'!G61+'2'!G61+'3'!G61+'4'!G61+'5'!G61+'6'!G61+'7'!G61+'8'!G61+'9'!G61+'10'!G61+'11'!G61+'12'!F61+'13'!G61+'14'!G61+'15'!G61+'16'!G61+'17'!G61+'18'!G61+'19'!F61+'20'!G61+'21'!G61+'22'!F61+'23'!G61+'24'!G61+'25'!G61+'26'!F61+'27'!G61+'28'!G61+'29'!G61 -> 119 | H61: ='1'!H61+'2'!H61+'3'!H61+'4'!H61+'5'!H61+'6'!H61+'7'!H61+'8'!H61+'9'!H61+'10'!H61+'11'!H61+'12'!G61+'13'!H61+'14'!H61+'15'!H61+'16'!H61+'17'!H61+'18'!H61+'19'!G61+'20'!H61+'21'!H61+'22'!G61+'23'!H61+'24'!H61+'25'!H61+'26'!G61+'27'!H61+'28'!H61+'29'!H61 -> 7 | I61: ='1'!I61+'2'!I61+'3'!I61+'4'!I61+'5'!I61+'6'!I61+'7'!I61+'8'!I61+'9'!I61+'10'!I61+'11'!I61+'12'!H61+'13'!I61+'14'!I61+'15'!I61+'16'!I61+'17'!I61+'18'!I61+'19'!H61+'20'!I61+'21'!I61+'22'!H61+'23'!I61+'24'!I61+'25'!I61+'26'!H61+'27'!I61+'28'!I61+'29'!I61 -> 0 | J61: ='1'!J61+'2'!J61+'3'!J61+'4'!J61+'5'!J61+'6'!J61+'7'!J61+'8'!J61+'9'!J61+'10'!J61+'11'!J61+'12'!I61+'13'!J61+'14'!J61+'15'!J61+'16'!J61+'17'!J61+'18'!J61+'19'!I61+'20'!J61+'21'!J61+'22'!I61+'23'!J61+'24'!J61+'25'!J61+'26'!I61+'27'!J61+'28'!J61+'29'!J61 -> 0 | K61: ='1'!K61+'2'!K61+'3'!K61+'4'!K61+'5'!K61+'6'!K61+'7'!K61+'8'!K61+'9'!K61+'10'!K61+'11'!K61+'12'!J61+'13'!K61+'14'!K61+'15'!K61+'16'!K61+'17'!K61+'18'!K61+'19'!J61+'20'!K61+'21'!K61+'22'!J61+'23'!K61+'24'!K61+'25'!K61+'26'!J61+'27'!K61+'28'!K61+'29'!K61 -> 0 | L61: =SUM(D61:K61) -> 449 | Q61: 0
B62: 1111080 | C62: ชิฟฟอนไส้แยมแยกชิ้น ฝอยทอง | D62: ='1'!D62+'2'!D62+'3'!D62+'4'!D62+'5'!D62+'6'!D62+'7'!D62+'8'!D62+'9'!D62+'10'!D62+'11'!D62+'12'!C62+'13'!D62+'14'!D62+'15'!D62+'16'!D62+'17'!D62+'18'!D62+'19'!C62+'20'!D62+'21'!D62+'22'!C62+'23'!D62+'24'!D62+'25'!D62+'26'!C62+'27'!D62+'28'!D62+'29'!D62 -> 118 | E62: ='1'!E62+'2'!E62+'3'!E62+'4'!E62+'5'!E62+'6'!E62+'7'!E62+'8'!E62+'9'!E62+'10'!E62+'11'!E62+'12'!D62+'13'!E62+'14'!E62+'15'!E62+'16'!E62+'17'!E62+'18'!E62+'19'!D62+'20'!E62+'21'!E62+'22'!D62+'23'!E62+'24'!E62+'25'!E62+'26'!D62+'27'!E62+'28'!E62+'29'!E62 -> 80 | F62: ='1'!F62+'2'!F62+'3'!F62+'4'!F62+'5'!F62+'6'!F62+'7'!F62+'8'!F62+'9'!F62+'10'!F62+'11'!F62+'12'!E62+'13'!F62+'14'!F62+'15'!F62+'16'!F62+'17'!F62+'18'!F62+'19'!E62+'20'!F62+'21'!F62+'22'!E62+'23'!F62+'24'!F62+'25'!F62+'26'!E62+'27'!F62+'28'!F62+'29'!F62 -> 119 | G62: ='1'!G62+'2'!G62+'3'!G62+'4'!G62+'5'!G62+'6'!G62+'7'!G62+'8'!G62+'9'!G62+'10'!G62+'11'!G62+'12'!F62+'13'!G62+'14'!G62+'15'!G62+'16'!G62+'17'!G62+'18'!G62+'19'!F62+'20'!G62+'21'!G62+'22'!F62+'23'!G62+'24'!G62+'25'!G62+'26'!F62+'27'!G62+'28'!G62+'29'!G62 -> 118 | H62: ='1'!H62+'2'!H62+'3'!H62+'4'!H62+'5'!H62+'6'!H62+'7'!H62+'8'!H62+'9'!H62+'10'!H62+'11'!H62+'12'!G62+'13'!H62+'14'!H62+'15'!H62+'16'!H62+'17'!H62+'18'!H62+'19'!G62+'20'!H62+'21'!H62+'22'!G62+'23'!H62+'24'!H62+'25'!H62+'26'!G62+'27'!H62+'28'!H62+'29'!H62 -> 7 | I62: ='1'!I62+'2'!I62+'3'!I62+'4'!I62+'5'!I62+'6'!I62+'7'!I62+'8'!I62+'9'!I62+'10'!I62+'11'!I62+'12'!H62+'13'!I62+'14'!I62+'15'!I62+'16'!I62+'17'!I62+'18'!I62+'19'!H62+'20'!I62+'21'!I62+'22'!H62+'23'!I62+'24'!I62+'25'!I62+'26'!H62+'27'!I62+'28'!I62+'29'!I62 -> 0 | J62: ='1'!J62+'2'!J62+'3'!J62+'4'!J62+'5'!J62+'6'!J62+'7'!J62+'8'!J62+'9'!J62+'10'!J62+'11'!J62+'12'!I62+'13'!J62+'14'!J62+'15'!J62+'16'!J62+'17'!J62+'18'!J62+'19'!I62+'20'!J62+'21'!J62+'22'!I62+'23'!J62+'24'!J62+'25'!J62+'26'!I62+'27'!J62+'28'!J62+'29'!J62 -> 0 | K62: ='1'!K62+'2'!K62+'3'!K62+'4'!K62+'5'!K62+'6'!K62+'7'!K62+'8'!K62+'9'!K62+'10'!K62+'11'!K62+'12'!J62+'13'!K62+'14'!K62+'15'!K62+'16'!K62+'17'!K62+'18'!K62+'19'!J62+'20'!K62+'21'!K62+'22'!J62+'23'!K62+'24'!K62+'25'!K62+'26'!J62+'27'!K62+'28'!K62+'29'!K62 -> 0 | L62: =SUM(D62:K62) -> 442 | Q62: 0
B63: 1111081 | C63: ชิฟฟอนไส้แยมแยกชิ้น วนิลา | D63: ='1'!D63+'2'!D63+'3'!D63+'4'!D63+'5'!D63+'6'!D63+'7'!D63+'8'!D63+'9'!D63+'10'!D63+'11'!D63+'12'!C63+'13'!D63+'14'!D63+'15'!D63+'16'!D63+'17'!D63+'18'!D63+'19'!C63+'20'!D63+'21'!D63+'22'!C63+'23'!D63+'24'!D63+'25'!D63+'26'!C63+'27'!D63+'28'!D63+'29'!D63 -> 118 | E63: ='1'!E63+'2'!E63+'3'!E63+'4'!E63+'5'!E63+'6'!E63+'7'!E63+'8'!E63+'9'!E63+'10'!E63+'11'!E63+'12'!D63+'13'!E63+'14'!E63+'15'!E63+'16'!E63+'17'!E63+'18'!E63+'19'!D63+'20'!E63+'21'!E63+'22'!D63+'23'!E63+'24'!E63+'25'!E63+'26'!D63+'27'!E63+'28'!E63+'29'!E63 -> 60 | F63: ='1'!F63+'2'!F63+'3'!F63+'4'!F63+'5'!F63+'6'!F63+'7'!F63+'8'!F63+'9'!F63+'10'!F63+'11'!F63+'12'!E63+'13'!F63+'14'!F63+'15'!F63+'16'!F63+'17'!F63+'18'!F63+'19'!E63+'20'!F63+'21'!F63+'22'!E63+'23'!F63+'24'!F63+'25'!F63+'26'!E63+'27'!F63+'28'!F63+'29'!F63 -> 111 | G63: ='1'!G63+'2'!G63+'3'!G63+'4'!G63+'5'!G63+'6'!G63+'7'!G63+'8'!G63+'9'!G63+'10'!G63+'11'!G63+'12'!F63+'13'!G63+'14'!G63+'15'!G63+'16'!G63+'17'!G63+'18'!G63+'19'!F63+'20'!G63+'21'!G63+'22'!F63+'23'!G63+'24'!G63+'25'!G63+'26'!F63+'27'!G63+'28'!G63+'29'!G63 -> 117 | H63: ='1'!H63+'2'!H63+'3'!H63+'4'!H63+'5'!H63+'6'!H63+'7'!H63+'8'!H63+'9'!H63+'10'!H63+'11'!H63+'12'!G63+'13'!H63+'14'!H63+'15'!H63+'16'!H63+'17'!H63+'18'!H63+'19'!G63+'20'!H63+'21'!H63+'22'!G63+'23'!H63+'24'!H63+'25'!H63+'26'!G63+'27'!H63+'28'!H63+'29'!H63 -> 7 | I63: ='1'!I63+'2'!I63+'3'!I63+'4'!I63+'5'!I63+'6'!I63+'7'!I63+'8'!I63+'9'!I63+'10'!I63+'11'!I63+'12'!H63+'13'!I63+'14'!I63+'15'!I63+'16'!I63+'17'!I63+'18'!I63+'19'!H63+'20'!I63+'21'!I63+'22'!H63+'23'!I63+'24'!I63+'25'!I63+'26'!H63+'27'!I63+'28'!I63+'29'!I63 -> 0 | J63: ='1'!J63+'2'!J63+'3'!J63+'4'!J63+'5'!J63+'6'!J63+'7'!J63+'8'!J63+'9'!J63+'10'!J63+'11'!J63+'12'!I63+'13'!J63+'14'!J63+'15'!J63+'16'!J63+'17'!J63+'18'!J63+'19'!I63+'20'!J63+'21'!J63+'22'!I63+'23'!J63+'24'!J63+'25'!J63+'26'!I63+'27'!J63+'28'!J63+'29'!J63 -> 0 | K63: ='1'!K63+'2'!K63+'3'!K63+'4'!K63+'5'!K63+'6'!K63+'7'!K63+'8'!K63+'9'!K63+'10'!K63+'11'!K63+'12'!J63+'13'!K63+'14'!K63+'15'!K63+'16'!K63+'17'!K63+'18'!K63+'19'!J63+'20'!K63+'21'!K63+'22'!J63+'23'!K63+'24'!K63+'25'!K63+'26'!J63+'27'!K63+'28'!K63+'29'!K63 -> 0 | L63: =SUM(D63:K63) -> 413 | Q63: 0
B64: 1111082 | C64: ชิฟฟอนไส้แยมแยกชิ้น ใบเตย | D64: ='1'!D64+'2'!D64+'3'!D64+'4'!D64+'5'!D64+'6'!D64+'7'!D64+'8'!D64+'9'!D64+'10'!D64+'11'!D64+'12'!C64+'13'!D64+'14'!D64+'15'!D64+'16'!D64+'17'!D64+'18'!D64+'19'!C64+'20'!D64+'21'!D64+'22'!C64+'23'!D64+'24'!D64+'25'!D64+'26'!C64+'27'!D64+'28'!D64+'29'!D64 -> 118 | E64: ='1'!E64+'2'!E64+'3'!E64+'4'!E64+'5'!E64+'6'!E64+'7'!E64+'8'!E64+'9'!E64+'10'!E64+'11'!E64+'12'!D64+'13'!E64+'14'!E64+'15'!E64+'16'!E64+'17'!E64+'18'!E64+'19'!D64+'20'!E64+'21'!E64+'22'!D64+'23'!E64+'24'!E64+'25'!E64+'26'!D64+'27'!E64+'28'!E64+'29'!E64 -> 80 | F64: ='1'!F64+'2'!F64+'3'!F64+'4'!F64+'5'!F64+'6'!F64+'7'!F64+'8'!F64+'9'!F64+'10'!F64+'11'!F64+'12'!E64+'13'!F64+'14'!F64+'15'!F64+'16'!F64+'17'!F64+'18'!F64+'19'!E64+'20'!F64+'21'!F64+'22'!E64+'23'!F64+'24'!F64+'25'!F64+'26'!E64+'27'!F64+'28'!F64+'29'!F64 -> 111 | G64: ='1'!G64+'2'!G64+'3'!G64+'4'!G64+'5'!G64+'6'!G64+'7'!G64+'8'!G64+'9'!G64+'10'!G64+'11'!G64+'12'!F64+'13'!G64+'14'!G64+'15'!G64+'16'!G64+'17'!G64+'18'!G64+'19'!F64+'20'!G64+'21'!G64+'22'!F64+'23'!G64+'24'!G64+'25'!G64+'26'!F64+'27'!G64+'28'!G64+'29'!G64 -> 116 | H64: ='1'!H64+'2'!H64+'3'!H64+'4'!H64+'5'!H64+'6'!H64+'7'!H64+'8'!H64+'9'!H64+'10'!H64+'11'!H64+'12'!G64+'13'!H64+'14'!H64+'15'!H64+'16'!H64+'17'!H64+'18'!H64+'19'!G64+'20'!H64+'21'!H64+'22'!G64+'23'!H64+'24'!H64+'25'!H64+'26'!G64+'27'!H64+'28'!H64+'29'!H64 -> 7 | I64: ='1'!I64+'2'!I64+'3'!I64+'4'!I64+'5'!I64+'6'!I64+'7'!I64+'8'!I64+'9'!I64+'10'!I64+'11'!I64+'12'!H64+'13'!I64+'14'!I64+'15'!I64+'16'!I64+'17'!I64+'18'!I64+'19'!H64+'20'!I64+'21'!I64+'22'!H64+'23'!I64+'24'!I64+'25'!I64+'26'!H64+'27'!I64+'28'!I64+'29'!I64 -> 0 | J64: ='1'!J64+'2'!J64+'3'!J64+'4'!J64+'5'!J64+'6'!J64+'7'!J64+'8'!J64+'9'!J64+'10'!J64+'11'!J64+'12'!I64+'13'!J64+'14'!J64+'15'!J64+'16'!J64+'17'!J64+'18'!J64+'19'!I64+'20'!J64+'21'!J64+'22'!I64+'23'!J64+'24'!J64+'25'!J64+'26'!I64+'27'!J64+'28'!J64+'29'!J64 -> 0 | K64: ='1'!K64+'2'!K64+'3'!K64+'4'!K64+'5'!K64+'6'!K64+'7'!K64+'8'!K64+'9'!K64+'10'!K64+'11'!K64+'12'!J64+'13'!K64+'14'!K64+'15'!K64+'16'!K64+'17'!K64+'18'!K64+'19'!J64+'20'!K64+'21'!K64+'22'!J64+'23'!K64+'24'!K64+'25'!K64+'26'!J64+'27'!K64+'28'!K64+'29'!K64 -> 0 | L64: =SUM(D64:K64) -> 432 | Q64: 0
B65: 1111083 | C65: ชิฟฟอนไส้แยมแยกชิ้น เมล่อน | D65: ='1'!D65+'2'!D65+'3'!D65+'4'!D65+'5'!D65+'6'!D65+'7'!D65+'8'!D65+'9'!D65+'10'!D65+'11'!D65+'12'!C65+'13'!D65+'14'!D65+'15'!D65+'16'!D65+'17'!D65+'18'!D65+'19'!C65+'20'!D65+'21'!D65+'22'!C65+'23'!D65+'24'!D65+'25'!D65+'26'!C65+'27'!D65+'28'!D65+'29'!D65 -> 117 | E65: ='1'!E65+'2'!E65+'3'!E65+'4'!E65+'5'!E65+'6'!E65+'7'!E65+'8'!E65+'9'!E65+'10'!E65+'11'!E65+'12'!D65+'13'!E65+'14'!E65+'15'!E65+'16'!E65+'17'!E65+'18'!E65+'19'!D65+'20'!E65+'21'!E65+'22'!D65+'23'!E65+'24'!E65+'25'!E65+'26'!D65+'27'!E65+'28'!E65+'29'!E65 -> 57 | F65: ='1'!F65+'2'!F65+'3'!F65+'4'!F65+'5'!F65+'6'!F65+'7'!F65+'8'!F65+'9'!F65+'10'!F65+'11'!F65+'12'!E65+'13'!F65+'14'!F65+'15'!F65+'16'!F65+'17'!F65+'18'!F65+'19'!E65+'20'!F65+'21'!F65+'22'!E65+'23'!F65+'24'!F65+'25'!F65+'26'!E65+'27'!F65+'28'!F65+'29'!F65 -> 86 | G65: ='1'!G65+'2'!G65+'3'!G65+'4'!G65+'5'!G65+'6'!G65+'7'!G65+'8'!G65+'9'!G65+'10'!G65+'11'!G65+'12'!F65+'13'!G65+'14'!G65+'15'!G65+'16'!G65+'17'!G65+'18'!G65+'19'!F65+'20'!G65+'21'!G65+'22'!F65+'23'!G65+'24'!G65+'25'!G65+'26'!F65+'27'!G65+'28'!G65+'29'!G65 -> 116 | H65: ='1'!H65+'2'!H65+'3'!H65+'4'!H65+'5'!H65+'6'!H65+'7'!H65+'8'!H65+'9'!H65+'10'!H65+'11'!H65+'12'!G65+'13'!H65+'14'!H65+'15'!H65+'16'!H65+'17'!H65+'18'!H65+'19'!G65+'20'!H65+'21'!H65+'22'!G65+'23'!H65+'24'!H65+'25'!H65+'26'!G65+'27'!H65+'28'!H65+'29'!H65 -> 7 | I65: ='1'!I65+'2'!I65+'3'!I65+'4'!I65+'5'!I65+'6'!I65+'7'!I65+'8'!I65+'9'!I65+'10'!I65+'11'!I65+'12'!H65+'13'!I65+'14'!I65+'15'!I65+'16'!I65+'17'!I65+'18'!I65+'19'!H65+'20'!I65+'21'!I65+'22'!H65+'23'!I65+'24'!I65+'25'!I65+'26'!H65+'27'!I65+'28'!I65+'29'!I65 -> 0 | J65: ='1'!J65+'2'!J65+'3'!J65+'4'!J65+'5'!J65+'6'!J65+'7'!J65+'8'!J65+'9'!J65+'10'!J65+'11'!J65+'12'!I65+'13'!J65+'14'!J65+'15'!J65+'16'!J65+'17'!J65+'18'!J65+'19'!I65+'20'!J65+'21'!J65+'22'!I65+'23'!J65+'24'!J65+'25'!J65+'26'!I65+'27'!J65+'28'!J65+'29'!J65 -> 0 | K65: ='1'!K65+'2'!K65+'3'!K65+'4'!K65+'5'!K65+'6'!K65+'7'!K65+'8'!K65+'9'!K65+'10'!K65+'11'!K65+'12'!J65+'13'!K65+'14'!K65+'15'!K65+'16'!K65+'17'!K65+'18'!K65+'19'!J65+'20'!K65+'21'!K65+'22'!J65+'23'!K65+'24'!K65+'25'!K65+'26'!J65+'27'!K65+'28'!K65+'29'!K65 -> 0 | L65: =SUM(D65:K65) -> 383 | Q65: 0
B66: 1111010 | C66: ชิฟฟอนไส้แยมแยกชิ้น คละรส | D66: ='1'!D66+'2'!D66+'3'!D66+'4'!D66+'5'!D66+'6'!D66+'7'!D66+'8'!D66+'9'!D66+'10'!D66+'11'!D66+'12'!C66+'13'!D66+'14'!D66+'15'!D66+'16'!D66+'17'!D66+'18'!D66+'19'!C66+'20'!D66+'21'!D66+'22'!C66+'23'!D66+'24'!D66+'25'!D66+'26'!C66+'27'!D66+'28'!D66+'29'!D66 -> 0 | E66: ='1'!E66+'2'!E66+'3'!E66+'4'!E66+'5'!E66+'6'!E66+'7'!E66+'8'!E66+'9'!E66+'10'!E66+'11'!E66+'12'!D66+'13'!E66+'14'!E66+'15'!E66+'16'!E66+'17'!E66+'18'!E66+'19'!D66+'20'!E66+'21'!E66+'22'!D66+'23'!E66+'24'!E66+'25'!E66+'26'!D66+'27'!E66+'28'!E66+'29'!E66 -> 0 | F66: ='1'!F66+'2'!F66+'3'!F66+'4'!F66+'5'!F66+'6'!F66+'7'!F66+'8'!F66+'9'!F66+'10'!F66+'11'!F66+'12'!E66+'13'!F66+'14'!F66+'15'!F66+'16'!F66+'17'!F66+'18'!F66+'19'!E66+'20'!F66+'21'!F66+'22'!E66+'23'!F66+'24'!F66+'25'!F66+'26'!E66+'27'!F66+'28'!F66+'29'!F66 -> 0 | G66: ='1'!G66+'2'!G66+'3'!G66+'4'!G66+'5'!G66+'6'!G66+'7'!G66+'8'!G66+'9'!G66+'10'!G66+'11'!G66+'12'!F66+'13'!G66+'14'!G66+'15'!G66+'16'!G66+'17'!G66+'18'!G66+'19'!F66+'20'!G66+'21'!G66+'22'!F66+'23'!G66+'24'!G66+'25'!G66+'26'!F66+'27'!G66+'28'!G66+'29'!G66 -> 0 | H66: ='1'!H66+'2'!H66+'3'!H66+'4'!H66+'5'!H66+'6'!H66+'7'!H66+'8'!H66+'9'!H66+'10'!H66+'11'!H66+'12'!G66+'13'!H66+'14'!H66+'15'!H66+'16'!H66+'17'!H66+'18'!H66+'19'!G66+'20'!H66+'21'!H66+'22'!G66+'23'!H66+'24'!H66+'25'!H66+'26'!G66+'27'!H66+'28'!H66+'29'!H66 -> 0 | I66: ='1'!I66+'2'!I66+'3'!I66+'4'!I66+'5'!I66+'6'!I66+'7'!I66+'8'!I66+'9'!I66+'10'!I66+'11'!I66+'12'!H66+'13'!I66+'14'!I66+'15'!I66+'16'!I66+'17'!I66+'18'!I66+'19'!H66+'20'!I66+'21'!I66+'22'!H66+'23'!I66+'24'!I66+'25'!I66+'26'!H66+'27'!I66+'28'!I66+'29'!I66 -> 0 | J66: ='1'!J66+'2'!J66+'3'!J66+'4'!J66+'5'!J66+'6'!J66+'7'!J66+'8'!J66+'9'!J66+'10'!J66+'11'!J66+'12'!I66+'13'!J66+'14'!J66+'15'!J66+'16'!J66+'17'!J66+'18'!J66+'19'!I66+'20'!J66+'21'!J66+'22'!I66+'23'!J66+'24'!J66+'25'!J66+'26'!I66+'27'!J66+'28'!J66+'29'!J66 -> 0 | K66: ='1'!K66+'2'!K66+'3'!K66+'4'!K66+'5'!K66+'6'!K66+'7'!K66+'8'!K66+'9'!K66+'10'!K66+'11'!K66+'12'!J66+'13'!K66+'14'!K66+'15'!K66+'16'!K66+'17'!K66+'18'!K66+'19'!J66+'20'!K66+'21'!K66+'22'!J66+'23'!K66+'24'!K66+'25'!K66+'26'!J66+'27'!K66+'28'!K66+'29'!K66 -> 0 | L66: =SUM(D66:K66) -> 0 | Q66: 0
C67: รวม | L67: =SUM(L7:L66) -> 25628 | Q67: 0 | T67: =+L67+L77+L88+L100+L139 -> 70460
B68: ชิฟฟอนไส้แยม 6 ชิ้น
B69: 1111009 | C69: ชิฟฟอนไส้แยมรวมรส 6 ชิ้น | D69: ='1'!D69+'2'!D69+'3'!D69+'4'!D69+'5'!D69+'6'!D69+'7'!D69+'8'!D69+'9'!D69+'10'!D69+'11'!D69+'12'!C69+'13'!D69+'14'!D69+'15'!D69+'16'!D69+'17'!D69+'18'!D69+'19'!C69+'20'!D69+'21'!D69+'22'!C69+'23'!D69+'24'!D69+'25'!D69+'26'!C69+'27'!D69+'28'!D69+'29'!D69 -> 234 | E69: ='1'!E69+'2'!E69+'3'!E69+'4'!E69+'5'!E69+'6'!E69+'7'!E69+'8'!E69+'9'!E69+'10'!E69+'11'!E69+'12'!D69+'13'!E69+'14'!E69+'15'!E69+'16'!E69+'17'!E69+'18'!E69+'19'!D69+'20'!E69+'21'!E69+'22'!D69+'23'!E69+'24'!E69+'25'!E69+'26'!D69+'27'!E69+'28'!E69+'29'!E69 -> 125 | F69: ='1'!F69+'2'!F69+'3'!F69+'4'!F69+'5'!F69+'6'!F69+'7'!F69+'8'!F69+'9'!F69+'10'!F69+'11'!F69+'12'!E69+'13'!F69+'14'!F69+'15'!F69+'16'!F69+'17'!F69+'18'!F69+'19'!E69+'20'!F69+'21'!F69+'22'!E69+'23'!F69+'24'!F69+'25'!F69+'26'!E69+'27'!F69+'28'!F69+'29'!F69 -> 392 | G69: ='1'!G69+'2'!G69+'3'!G69+'4'!G69+'5'!G69+'6'!G69+'7'!G69+'8'!G69+'9'!G69+'10'!G69+'11'!G69+'12'!F69+'13'!G69+'14'!G69+'15'!G69+'16'!G69+'17'!G69+'18'!G69+'19'!F69+'20'!G69+'21'!G69+'22'!F69+'23'!G69+'24'!G69+'25'!G69+'26'!F69+'27'!G69+'28'!G69+'29'!G69 -> 146 | H69: ='1'!H69+'2'!H69+'3'!H69+'4'!H69+'5'!H69+'6'!H69+'7'!H69+'8'!H69+'9'!H69+'10'!H69+'11'!H69+'12'!G69+'13'!H69+'14'!H69+'15'!H69+'16'!H69+'17'!H69+'18'!H69+'19'!G69+'20'!H69+'21'!H69+'22'!G69+'23'!H69+'24'!H69+'25'!H69+'26'!G69+'27'!H69+'28'!H69+'29'!H69 -> 18 | I69: ='1'!I69+'2'!I69+'3'!I69+'4'!I69+'5'!I69+'6'!I69+'7'!I69+'8'!I69+'9'!I69+'10'!I69+'11'!I69+'12'!H69+'13'!I69+'14'!I69+'15'!I69+'16'!I69+'17'!I69+'18'!I69+'19'!H69+'20'!I69+'21'!I69+'22'!H69+'23'!I69+'24'!I69+'25'!I69+'26'!H69+'27'!I69+'28'!I69+'29'!I69 -> 0 | J69: ='1'!J69+'2'!J69+'3'!J69+'4'!J69+'5'!J69+'6'!J69+'7'!J69+'8'!J69+'9'!J69+'10'!J69+'11'!J69+'12'!I69+'13'!J69+'14'!J69+'15'!J69+'16'!J69+'17'!J69+'18'!J69+'19'!I69+'20'!J69+'21'!J69+'22'!I69+'23'!J69+'24'!J69+'25'!J69+'26'!I69+'27'!J69+'28'!J69+'29'!J69 -> 0 | K69: ='1'!K69+'2'!K69+'3'!K69+'4'!K69+'5'!K69+'6'!K69+'7'!K69+'8'!K69+'9'!K69+'10'!K69+'11'!K69+'12'!J69+'13'!K69+'14'!K69+'15'!K69+'16'!K69+'17'!K69+'18'!K69+'19'!J69+'20'!K69+'21'!K69+'22'!J69+'23'!K69+'24'!K69+'25'!K69+'26'!J69+'27'!K69+'28'!K69+'29'!K69 -> 26 | L69: =SUM(D69:K69) -> 941 | Q69: 0
B70: 1111023 | C70: ชิฟฟอนไส้แยมรสสตอเบอร์รี่ล้วน 6 ชิ้น | D70: ='1'!D70+'2'!D70+'3'!D70+'4'!D70+'5'!D70+'6'!D70+'7'!D70+'8'!D70+'9'!D70+'10'!D70+'11'!D70+'12'!C70+'13'!D70+'14'!D70+'15'!D70+'16'!D70+'17'!D70+'18'!D70+'19'!C70+'20'!D70+'21'!D70+'22'!C70+'23'!D70+'24'!D70+'25'!D70+'26'!C70+'27'!D70+'28'!D70+'29'!D70 -> 5 | E70: ='1'!E70+'2'!E70+'3'!E70+'4'!E70+'5'!E70+'6'!E70+'7'!E70+'8'!E70+'9'!E70+'10'!E70+'11'!E70+'12'!D70+'13'!E70+'14'!E70+'15'!E70+'16'!E70+'17'!E70+'18'!E70+'19'!D70+'20'!E70+'21'!E70+'22'!D70+'23'!E70+'24'!E70+'25'!E70+'26'!D70+'27'!E70+'28'!E70+'29'!E70 -> 0 | F70: ='1'!F70+'2'!F70+'3'!F70+'4'!F70+'5'!F70+'6'!F70+'7'!F70+'8'!F70+'9'!F70+'10'!F70+'11'!F70+'12'!E70+'13'!F70+'14'!F70+'15'!F70+'16'!F70+'17'!F70+'18'!F70+'19'!E70+'20'!F70+'21'!F70+'22'!E70+'23'!F70+'24'!F70+'25'!F70+'26'!E70+'27'!F70+'28'!F70+'29'!F70 -> 0 | G70: ='1'!G70+'2'!G70+'3'!G70+'4'!G70+'5'!G70+'6'!G70+'7'!G70+'8'!G70+'9'!G70+'10'!G70+'11'!G70+'12'!F70+'13'!G70+'14'!G70+'15'!G70+'16'!G70+'17'!G70+'18'!G70+'19'!F70+'20'!G70+'21'!G70+'22'!F70+'23'!G70+'24'!G70+'25'!G70+'26'!F70+'27'!G70+'28'!G70+'29'!G70 -> 0 | H70: ='1'!H70+'2'!H70+'3'!H70+'4'!H70+'5'!H70+'6'!H70+'7'!H70+'8'!H70+'9'!H70+'10'!H70+'11'!H70+'12'!G70+'13'!H70+'14'!H70+'15'!H70+'16'!H70+'17'!H70+'18'!H70+'19'!G70+'20'!H70+'21'!H70+'22'!G70+'23'!H70+'24'!H70+'25'!H70+'26'!G70+'27'!H70+'28'!H70+'29'!H70 -> 0 | I70: ='1'!I70+'2'!I70+'3'!I70+'4'!I70+'5'!I70+'6'!I70+'7'!I70+'8'!I70+'9'!I70+'10'!I70+'11'!I70+'12'!H70+'13'!I70+'14'!I70+'15'!I70+'16'!I70+'17'!I70+'18'!I70+'19'!H70+'20'!I70+'21'!I70+'22'!H70+'23'!I70+'24'!I70+'25'!I70+'26'!H70+'27'!I70+'28'!I70+'29'!I70 -> 0 | J70: ='1'!J70+'2'!J70+'3'!J70+'4'!J70+'5'!J70+'6'!J70+'7'!J70+'8'!J70+'9'!J70+'10'!J70+'11'!J70+'12'!I70+'13'!J70+'14'!J70+'15'!J70+'16'!J70+'17'!J70+'18'!J70+'19'!I70+'20'!J70+'21'!J70+'22'!I70+'23'!J70+'24'!J70+'25'!J70+'26'!I70+'27'!J70+'28'!J70+'29'!J70 -> 0 | K70: ='1'!K70+'2'!K70+'3'!K70+'4'!K70+'5'!K70+'6'!K70+'7'!K70+'8'!K70+'9'!K70+'10'!K70+'11'!K70+'12'!J70+'13'!K70+'14'!K70+'15'!K70+'16'!K70+'17'!K70+'18'!K70+'19'!J70+'20'!K70+'21'!K70+'22'!J70+'23'!K70+'24'!K70+'25'!K70+'26'!J70+'27'!K70+'28'!K70+'29'!K70 -> 0 | L70: =SUM(D70:K70) -> 5 | Q70: 0
