Workbook

Sheet เย็น
B1: ยอดจริง ออนไลน์ วันที่ - เช้า
L2: ยอดรวมผลิต
L3: จำนวน
B4: รหัสสินค้า | C4: สินค้า | D4: ปณ | E4: ชอปปี้ | F4: ลาซาด้า | G4: ติ๊กตอก | H4: ติ๊กตอก 2 | I4: ติ๊กตอก3 | J4: ชอยส์ | K4: ยอดเส้น | L4: (กล่อง)
B6: ชิฟฟอนรวมรส
B7: 1111002 | C7: ชิฟฟอนรวมรส 8 ชิ้น | L7: =SUM(D7:K7) -> 0
C8: ชิฟฟอนแบบกล่องสุ่มอะไรก็ได้ที่มี | L8: =SUM(D8:K8) -> 0
B9: 1111084 | C9: ชิฟฟอน 8 ชิ้น กาแฟล้วน | L9: =SUM(D9:K9) -> 0
B10: 1111085 | C10: ชิฟฟอน 8 ชิ้น บลูเบอรี่ล้วน | L10: =SUM(D10:K10) -> 0
B11: 1111086 | C11: ชิฟฟอน 8 ชิ้น มะพร้าวล้วน | L11: =SUM(D11:K11) -> 0
B12: 1111087 | C12: ชิฟฟอน 8 ชิ้น สตอเบอรี่ล้วน | L12: =SUM(D12:K12) -> 0
B13: 1111088 | C13: ชิฟฟอน 8 ชิ้น ส้มล้วน | L13: =SUM(D13:K13) -> 0
B14: 1111089 | C14: ชิฟฟอน 8 ชิ้น เนยล้วน | L14: =SUM(D14:K14) -> 0
B15: 1111090 | C15: ชิฟฟอน 8 ชิ้น เผือกล้วน | L15: =SUM(D15:K15) -> 0
B16: 1111091 | C16: ชิฟฟอน 8 ชิ้น ใบเตยล้วน | L16: =SUM(D16:K16) -> 0
B17: 1111092 | C17: ชิฟฟอน 8 ชิ้น กล้วยหอม | L17: =SUM(D17:K17) -> 0
B18: 1111093 | C18: ชิฟฟอน 8 ชิ้น โกโก้ล้วน | L18: =SUM(D18:K18) -> 0
B19: 1111094 | C19: ชิฟฟอน 8 ชิ้น ชาไทยล้วน | L19: =SUM(D19:K19) -> 0
B20: 1111095 | C20: ชิฟฟอน 8 ชิ้น ชาเขียวล้วน | L20: =SUM(D20:K20) -> 0
... B66: 1111010 | C66: ชิฟฟอนไส้แยมแยกชิ้น คละรส | L66: =SUM(D66:K66) -> 0
C67: รวม
B68: ชิฟฟอนไส้แยม 6 ชิ้น
B69: 1111009 | C69: ชิฟฟอนไส้แยมรวมรส 6 ชิ้น | L69: =SUM(D69:K69) -> 0
B70: 1111023 | C70: ชิฟฟอนไส้แยมรสสตอเบอร์รี่ล้วน 6 ชิ้น | L70: =SUM(D70:K70) -> 0
B71: 1111016 | C71: ชิฟฟอนไส้แยมรสมะพร้าวล้วน 6 ชิ้น | L71: =SUM(D71:K71) -> 0
B72: 1111014 | C72: ชิฟฟอนไส้แยมรสช็อกโกแลตนูเทลล่าล้วน 6 ชิ้น | L72: =SUM(D72:K72) -> 0
B73: 1111025 | C73: ชิฟฟอนไส้แยมรสส้มล้วน 6 ชิ้น | L73: =SUM(D73:K73) -> 0
B74: 1111018 | C74: ชิฟฟอนไส้แยมรสบลูเบอร์รี่ล้วน 6 ชิ้น | L74: =SUM(D74:K74) -> 0
B75: 1111012 | C75: ชิฟฟอนไส้แยมรสนมชมพูฮอกไกโดล้วน 6 ชิ้น | L75: =SUM(D75:K75) -> 0
B76: 1111020 | C76: ชิฟฟอนไส้แยมฝอยทองไส้ทะลัก 6 ชิ้น | L76: =SUM(D76:K76) -> 0
C77: รวม
B78: ชิฟฟอนไส้แยม 3 ชิ้น
B79: 1111022 | C79: ชิฟฟอนไส้แยมรสสตอเบอร์รี่ล้วน 3 ชิ้น | L79: =SUM(D79:K79) -> 0
B80: 1111015 | C80: ชิฟฟอนไส้แยมรสมะพร้าวล้วน 3 ชิ้น | L80: =SUM(D80:K80) -> 0
B81: 1111013 | C81: ชิฟฟอนไส้แยมรสช็อกโกแลตนูเทลล่าล้วน 3 ชิ้น | L81: =SUM(D81:K81) -> 0
B82: 1111024 | C82: ชิฟฟอนไส้แยมรสส้มล้วน 3 ชิ้น | L82: =SUM(D82:K82) -> 0
B83: 1111017 | C83: ชิฟฟอนไส้แยมรสบลูเบอร์รี่ล้วน 3 ชิ้น | L83: =SUM(D83:K83) -> 0
B84: 1111011 | C84: ชิฟฟอนไส้แยมรสนมชมพูฮอกไกโดล้วน 3 ชิ้น | L84: =SUM(D84:K84) -> 0
B85: 1111019 | C85: ชิฟฟอนไส้แยมฝอยทองไส้ทะลัก 3 ชิ้น | L85: =SUM(D85:K85) -> 0
B86: 1113081 | C86: ชิฟฟอนไส้แยม วนิลา/ใบเตย/เมล่อน | L86: =SUM(D86:K86) -> 0
...

Sheet เช้า
B1: ยอดจริง ออนไลน์ วันที่ 26/1/2568 - เช้า
L2: ยอดรวมผลิต
L3: จำนวน
B4: รหัสสินค้า | C4: สินค้า | D4: ปณ | E4: ชอปปี้ | F4: ลาซาด้า | G4: ติ๊กตอก | H4: ติ๊กตอก 2 | I4: ติ๊กตอก3 | J4: ชอยส์ | K4: ยอดเส้น | L4: (กล่อง)
B6: ชิฟฟอนรวมรส
B7: 1111002 | C7: ชิฟฟอนรวมรส 8 ชิ้น | E7: 8 | L7: =SUM(D7:K7) -> 8
C8: ชิฟฟอนแบบกล่องสุ่มอะไรก็ได้ที่มี | L8: =SUM(D8:K8) -> 0
B9: 1111084 | C9: ชิฟฟอน 8 ชิ้น กาแฟล้วน | L9: =SUM(D9:K9) -> 0
B10: 1111085 | C10: ชิฟฟอน 8 ชิ้น บลูเบอรี่ล้วน | L10: =SUM(D10:K10) -> 0
B11: 1111086 | C11: ชิฟฟอน 8 ชิ้น มะพร้าวล้วน | L11: =SUM(D11:K11) -> 0
B12: 1111087 | C12: ชิฟฟอน 8 ชิ้น สตอเบอรี่ล้วน | L12: =SUM(D12:K12) -> 0
B13: 1111088 | C13: ชิฟฟอน 8 ชิ้น ส้มล้วน | L13: =SUM(D13:K13) -> 0
B14: 1111089 | C14: ชิฟฟอน 8 ชิ้น เนยล้วน | L14: =SUM(D14:K14) -> 0
B15: 1111090 | C15: ชิฟฟอน 8 ชิ้น เผือกล้วน | L15: =SUM(D15:K15) -> 0
B16: 1111091 | C16: ชิฟฟอน 8 ชิ้น ใบเตยล้วน | L16: =SUM(D16:K16) -> 0
B17: 1111092 | C17: ชิฟฟอน 8 ชิ้น กล้วยหอม | L17: =SUM(D17:K17) -> 0
B18: 1111093 | C18: ชิฟฟอน 8 ชิ้น โกโก้ล้วน | L18: =SUM(D18:K18) -> 0
B19: 1111094 | C19: ชิฟฟอน 8 ชิ้น ชาไทยล้วน | L19: =SUM(D19:K19) -> 0
B20: 1111095 | C20: ชิฟฟอน 8 ชิ้น ชาเขียวล้วน | L20: =SUM(D20:K20) -> 0
... B24: 1111043 | C24: ชิฟฟอน 8 ชิ้น มะลิ | L24: =SUM(D24:K24) -> 0
B25: 1111056 | C25: ชิฟฟอน 8 ชิ้น รวมรสยอดฮิต | E25: 3 | F25: 12 | L25: =SUM(D25:K25) -> 15
B26: 1004055 | C26: ชิฟฟอนรวมรส 4 ชิ้น | G26: 3 | L26: =SUM(D26:K26) -> 3
B27: 1004055 | C27: ชิฟฟอน 4 ชิ้น โกโก้ล้วน | L27: =SUM(D27:K27) -> 0
B28: 1004055 | C28: ชิฟฟอน 4 ชิ้น มะพร้าวล้วน | L28: =SUM(D28:K28) -> 0
B29: 1004055 | C29: ชิฟฟอน 4 ชิ้น เนยล้วน | L29: =SUM(D29:K29) -> 0
B30: 1004055 | C30: ชิฟฟอน 4 ชิ้น กาแฟล้วน | L30: =SUM(D30:K30) -> 0
B31: 1004055 | C31: ชิฟฟอน 4 ชิ้น ใบเตยล้วน | L31: =SUM(D31:K31) -> 0
B32: 1004055 | C32: ชิฟฟอน 4 ชิ้น บลูเบอร์รี่ล้วน | L32: =SUM(D32:K32) -> 0
B33: 1004055 | C33: ชิฟฟอน 4 ชิ้น ส้มล้วน | L33: =SUM(D33:K33) -> 0
B34: 1004055 | C34: ชิฟฟอน 4 ชิ้น เผือกล้วน | L34: =SUM(D34:K34) -> 0
B35: 1004055 | C35: ชิฟฟอน 4 ชิ้น สตอเบอรี่ล้วน | L35: =SUM(D35:K35) -> 0
B36: 1004055 | C36: ชิฟฟอน 4 ชิ้น กล้วยหอมล้วน | L36: =SUM(D36:K36) -> 0
B37: 1004055 | C37: ชิฟฟอน 4 ชิ้น ชาเขียวล้วน | L37: =SUM(D37:K37) -> 0
B38: 1004055 | C38: ชิฟฟอน 4 ชิ้น ชาไทยล้วน | L38: =SUM(D38:K38) -> 0
B39: 1004055 | C39: ชิฟฟอน 4 ชิ้น สับปะรดล้วน | L39: =SUM(D39:K39) -> 0
B40: 1111057 | C40: ชิฟฟอนแยกชิ้น กาแฟ | F40: 3 | L40: =SUM(D40:K40) -> 3
B41: 1111058 | C41: ชิฟฟอนแยกชิ้น ชาเขียว | F41: 3 | L41: =SUM(D41:K41) -> 3
B42: 1111059 | C42: ชิฟฟอนแยกชิ้น ใบเตย | F42: 3 | L42: =SUM(D42:K42) -> 3
B43: 1111060 | C43: ชิฟฟอนแยกชิ้น กล้วยหอม | F43: 3 | L43: =SUM(D43:K43) -> 3
B44: 1111061 | C44: ชิฟฟอนแยกชิ้น ชาไทย | F44: 3 | L44: =SUM(D44:K44) -> 3
...

Sheet บ่าย
B1: ยอดจริง ออนไลน์ วันที่ 26/1/2568 - บ่าย
L2: ยอดรวมผลิต
L3: จำนวน
B4: รหัสสินค้า | C4: สินค้า | D4: ปณ | E4: ชอปปี้ | F4: ลาซาด้า | G4: ติ๊กตอก | H4: ติ๊กตอก 2 | I4: ติ๊กตอก3 | J4: ชอยส์ | K4: ยอดเส้น | L4: (กล่อง)
B6: ชิฟฟอนรวมรส
B7: 1111002 | C7: ชิฟฟอนรวมรส 8 ชิ้น | L7: =SUM(D7:K7) -> 0
C8: ชิฟฟอนแบบกล่องสุ่มอะไรก็ได้ที่มี | L8: =SUM(D8:K8) -> 0
B9: 1111084 | C9: ชิฟฟอน 8 ชิ้น กาแฟล้วน | L9: =SUM(D9:K9) -> 0
B10: 1111085 | C10: ชิฟฟอน 8 ชิ้น บลูเบอรี่ล้วน | L10: =SUM(D10:K10) -> 0
B11: 1111086 | C11: ชิฟฟอน 8 ชิ้น มะพร้าวล้วน | L11: =SUM(D11:K11) -> 0
B12: 1111087 | C12: ชิฟฟอน 8 ชิ้น สตอเบอรี่ล้วน | L12: =SUM(D12:K12) -> 0
B13: 1111088 | C13: ชิฟฟอน 8 ชิ้น ส้มล้วน | L13: =SUM(D13:K13) -> 0
B14: 1111089 | C14: ชิฟฟอน 8 ชิ้น เนยล้วน | L14: =SUM(D14:K14) -> 0
B15: 1111090 | C15: ชิฟฟอน 8 ชิ้น เผือกล้วน | L15: =SUM(D15:K15) -> 0
B16: 1111091 | C16: ชิฟฟอน 8 ชิ้น ใบเตยล้วน | L16: =SUM(D16:K16) -> 0
B17: 1111092 | C17: ชิฟฟอน 8 ชิ้น กล้วยหอม | L17: =SUM(D17:K17) -> 0
B18: 1111093 | C18: ชิฟฟอน 8 ชิ้น โกโก้ล้วน | L18: =SUM(D18:K18) -> 0
B19: 1111094 | C19: ชิฟฟอน 8 ชิ้น ชาไทยล้วน | L19: =SUM(D19:K19) -> 0
B20: 1111095 | C20: ชิฟฟอน 8 ชิ้น ชาเขียวล้วน | L20: =SUM(D20:K20) -> 0
... B24: 1111043 | C24: ชิฟฟอน 8 ชิ้น มะลิ | L24: =SUM(D24:K24) -> 0
B25: 1111056 | C25: ชิฟฟอน 8 ชิ้น รวมรสยอดฮิต | D25: 1 | L25: =SUM(D25:K25) -> 1
B26: 1004055 | C26: ชิฟฟอนรวมรส 4 ชิ้น | L26: =SUM(D26:K26) -> 0
B27: 1004055 | C27: ชิฟฟอน 4 ชิ้น โกโก้ล้วน | L27: =SUM(D27:K27) -> 0
B28: 1004055 | C28: ชิฟฟอน 4 ชิ้น มะพร้าวล้วน | L28: =SUM(D28:K28) -> 0
B29: 1004055 | C29: ชิฟฟอน 4 ชิ้น เนยล้วน | L29: =SUM(D29:K29) -> 0
B30: 1004055 | C30: ชิฟฟอน 4 ชิ้น กาแฟล้วน | L30: =SUM(D30:K30) -> 0
B31: 1004055 | C31: ชิฟฟอน 4 ชิ้น ใบเตยล้วน | L31: =SUM(D31:K31) -> 0
B32: 1004055 | C32: ชิฟฟอน 4 ชิ้น บลูเบอร์รี่ล้วน | L32: =SUM(D32:K32) -> 0
B33: 1004055 | C33: ชิฟฟอน 4 ชิ้น ส้มล้วน | L33: =SUM(D33:K33) -> 0
B34: 1004055 | C34: ชิฟฟอน 4 ชิ้น เผือกล้วน | L34: =SUM(D34:K34) -> 0
B35: 1004055 | C35: ชิฟฟอน 4 ชิ้น สตอเบอรี่ล้วน | L35: =SUM(D35:K35) -> 0
B36: 1004055 | C36: ชิฟฟอน 4 ชิ้น กล้วยหอมล้วน | L36: =SUM(D36:K36) -> 0
B37: 1004055 | C37: ชิฟฟอน 4 ชิ้น ชาเขียวล้วน | L37: =SUM(D37:K37) -> 0
... B55: 1111001 | C55: ชิฟฟอนแยกชิ้น คละรส | L55: =SUM(D55:K55) -> 0
B56: 1111074 | C56: ชิฟฟอนไส้แยมแยกชิ้น มะพร้าว | D56: 1 | L56: =SUM(D56:K56) -> 1
B57: 1111075 | C57: ชิฟฟอนไส้แยมแยกชิ้น สตอเบอรี่ | D57: 1 | L57: =SUM(D57:K57) -> 1
B58: 1111076 | C58: ชิฟฟอนไส้แยมแยกชิ้น ส้ม | D58: 1 | L58: =SUM(D58:K58) -> 1
B59: 1111077 | C59: ชิฟฟอนไส้แยมแยกชิ้น บลูเบอรี่ | D59: 1 | L59: =SUM(D59:K59) -> 1
B60: 1111078 | C60: ชิฟฟอนไส้แยมแยกชิ้น นมชมพู | D60: 1 | L60: =SUM(D60:K60) -> 1
B61: 1111079 | C61: ชิฟฟอนไส้แยมแยกชิ้น ชอคโกแลต | D61: 1 | L61: =SUM(D61:K61) -> 1
...

Sheet รวม
B1: ยอดจริง ออนไลน์ วันที่ 26/1/2568 รวม
L2: ยอดรวมผลิต | M2: ยอดฟอแคส | N2: ยอดสตอค | O2: ยอดเมโม่ | P2: ยอดฟอแคสวันพรุ่งนี้ | Q2: รวม
L3: จำนวน
B4: รหัสสินค้า | C4: สินค้า | D4: ปณ | E4: ชอปปี้ | F4: ลาซาด้า | G4: ติ๊กตอก | H4: ติ๊กตอก2 | I4: ติ๊กตอก3 | J4: ชอยส์ | K4: ยอดเส้น | L4: (กล่อง)
B6: ชิฟฟอนรวมรส
B7: 1111002 | C7: ชิฟฟอนรวมรส 8 ชิ้น | D7: =เช้า!D7+เย็น!D7+บ่าย!D7 -> 0 | E7: =เช้า!E7+เย็น!E7+บ่าย!E7 -> 8 | F7: =เช้า!F7+เย็น!F7+บ่าย!F7 -> 0 | G7: =เช้า!G7+เย็น!G7+บ่าย!G7 -> 0 | H7: =เช้า!H7+เย็น!H7+บ่าย!H7 -> 0 | I7: =เช้า!I7+เย็น!I7+บ่าย!I7 -> 0 | J7: =เช้า!J7+เย็น!J7+บ่าย!J7 -> 0 | K7: =เช้า!K7+เย็น!K7+บ่าย!K7 -> 0 | L7: =SUM(D7:K7) -> 8 | Q7: =(M7+N7+O7+P7)-L7 -> -8
C8: ชิฟฟอนแบบกล่องสุ่มอะไรก็ได้ที่มี | D8: =เช้า!D8+เย็น!D8+บ่าย!D8 -> 0 | E8: =เช้า!E8+เย็น!E8+บ่าย!E8 -> 0 | F8: =เช้า!F8+เย็น!F8+บ่าย!F8 -> 0 | G8: =เช้า!G8+เย็น!G8+บ่าย!G8 -> 0 | H8: =เช้า!H8+เย็น!H8+บ่าย!H8 -> 0 | I8: =เช้า!I8+เย็น!I8+บ่าย!I8 -> 0 | J8: =เช้า!J8+เย็น!J8+บ่าย!J8 -> 0 | K8: =เช้า!K8+เย็น!K8+บ่าย!K8 -> 0 | L8: =SUM(D8:K8) -> 0 | Q8: =(M8+N8+O8+P8)-L8 -> 0
B9: 1111084 | C9: ชิฟฟอน 8 ชิ้น กาแฟล้วน | D9: =เช้า!D9+เย็น!D9+บ่าย!D9 -> 0 | E9: =เช้า!E9+เย็น!E9+บ่าย!E9 -> 0 | F9: =เช้า!F9+เย็น!F9+บ่าย!F9 -> 0 | G9: =เช้า!G9+เย็น!G9+บ่าย!G9 -> 0 | H9: =เช้า!H9+เย็น!H9+บ่าย!H9 -> 0 | I9: =เช้า!I9+เย็น!I9+บ่าย!I9 -> 0 | J9: =เช้า!J9+เย็น!J9+บ่าย!J9 -> 0 | K9: =เช้า!K9+เย็น!K9+บ่าย!K9 -> 0 | L9: =SUM(D9:K9) -> 0 | Q9: =(M9+N9+O9+P9)-L9 -> 0
B10: 1111085 | C10: ชิฟฟอน 8 ชิ้น บลูเบอรี่ล้วน | D10: =เช้า!D10+เย็น!D10+บ่าย!D10 -> 0 | E10: =เช้า!E10+เย็น!E10+บ่าย!E10 -> 0 | F10: =เช้า!F10+เย็น!F10+บ่าย!F10 -> 0 | G10: =เช้า!G10+เย็น!G10+บ่าย!G10 -> 0 | H10: =เช้า!H10+เย็น!H10+บ่าย!H10 -> 0 | I10: =เช้า!I10+เย็น!I10+บ่าย!I10 -> 0 | J10: =เช้า!J10+เย็น!J10+บ่าย!J10 -> 0 | K10: =เช้า!K10+เย็น!K10+บ่าย!K10 -> 0 | L10: =SUM(D10:K10) -> 0 | Q10: =(M10+N10+O10+P10)-L10 -> 0
B11: 1111086 | C11: ชิฟฟอน 8 ชิ้น มะพร้าวล้วน | D11: =เช้า!D11+เย็น!D11+บ่าย!D11 -> 0 | E11: =เช้า!E11+เย็น!E11+บ่าย!E11 -> 0 | F11: =เช้า!F11+เย็น!F11+บ่าย!F11 -> 0 | G11: =เช้า!G11+เย็น!G11+บ่าย!G11 -> 0 | H11: =เช้า!H11+เย็น!H11+บ่าย!H11 -> 0 | I11: =เช้า!I11+เย็น!I11+บ่าย!I11 -> 0 | J11: =เช้า!J11+เย็น!J11+บ่าย!J11 -> 0 | K11: =เช้า!K11+เย็น!K11+บ่าย!K11 -> 0 | L11: =SUM(D11:K11) -> 0 | Q11: =(M11+N11+O11+P11)-L11 -> 0
B12: 1111087 | C12: ชิฟฟอน 8 ชิ้น สตอเบอรี่ล้วน | D12: =เช้า!D12+เย็น!D12+บ่าย!D12 -> 0 | E12: =เช้า!E12+เย็น!E12+บ่าย!E12 -> 0 | F12: =เช้า!F12+เย็น!F12+บ่าย!F12 -> 0 | G12: =เช้า!G12+เย็น!G12+บ่าย!G12 -> 0 | H12: =เช้า!H12+เย็น!H12+บ่าย!H12 -> 0 | I12: =เช้า!I12+เย็น!I12+บ่าย!I12 -> 0 | J12: =เช้า!J12+เย็น!J12+บ่าย!J12 -> 0 | K12: =เช้า!K12+เย็น!K12+บ่าย!K12 -> 0 | L12: =SUM(D12:K12) -> 0 | Q12: =(M12+N12+O12+P12)-L12 -> 0
B13: 1111088 | C13: ชิฟฟอน 8 ชิ้น ส้มล้วน | D13: =เช้า!D13+เย็น!D13+บ่าย!D13 -> 0 | E13: =เช้า!E13+เย็น!E13+บ่าย!E13 -> 0 | F13: =เช้า!F13+เย็น!F13+บ่าย!F13 -> 0 | G13: =เช้า!G13+เย็น!G13+บ่าย!G13 -> 0 | H13: =เช้า!H13+เย็น!H13+บ่าย!H13 -> 0 | I13: =เช้า!I13+เย็น!I13+บ่าย!I13 -> 0 | J13: =เช้า!J13+เย็น!J13+บ่าย!J13 -> 0 | K13: =เช้า!K13+เย็น!K13+บ่าย!K13 -> 0 | L13: =SUM(D13:K13) -> 0 | Q13: =(M13+N13+O13+P13)-L13 -> 0
B14: 1111089 | C14: ชิฟฟอน 8 ชิ้น เนยล้วน | D14: =เช้า!D14+เย็น!D14+บ่าย!D14 -> 0 | E14: =เช้า!E14+เย็น!E14+บ่าย!E14 -> 0 | F14: =เช้า!F14+เย็น!F14+บ่าย!F14 -> 0 | G14: =เช้า!G14+เย็น!G14+บ่าย!G14 -> 0 | H14: =เช้า!H14+เย็น!H14+บ่าย!H14 -> 0 | I14: =เช้า!I14+เย็น!I14+บ่าย!I14 -> 0 | J14: =เช้า!J14+เย็น!J14+บ่าย!J14 -> 0 | K14: =เช้า!K14+เย็น!K14+บ่าย!K14 -> 0 | L14: =SUM(D14:K14) -> 0 | Q14: =(M14+N14+O14+P14)-L14 -> 0
B15: 1111090 | C15: ชิฟฟอน 8 ชิ้น เผือกล้วน | D15: =เช้า!D15+เย็น!D15+บ่าย!D15 -> 0 | E15: =เช้า!E15+เย็น!E15+บ่าย!E15 -> 0 | F15: =เช้า!F15+เย็น!F15+บ่าย!F15 -> 0 | G15: =เช้า!G15+เย็น!G15+บ่าย!G15 -> 0 | H15: =เช้า!H15+เย็น!H15+บ่าย!H15 -> 0 | I15: =เช้า!I15+เย็น!I15+บ่าย!I15 -> 0 | J15: =เช้า!J15+เย็น!J15+บ่าย!J15 -> 0 | K15: =เช้า!K15+เย็น!K15+บ่าย!K15 -> 0 | L15: =SUM(D15:K15) -> 0 | Q15: =(M15+N15+O15+P15)-L15 -> 0
B16: 1111091 | C16: ชิฟฟอน 8 ชิ้น ใบเตยล้วน | D16: =เช้า!D16+เย็น!D16+บ่าย!D16 -> 0 | E16: =เช้า!E16+เย็น!E16+บ่าย!E16 -> 0 | F16: =เช้า!F16+เย็น!F16+บ่าย!F16 -> 0 | G16: =เช้า!G16+เย็น!G16+บ่าย!G16 -> 0 | H16: =เช้า!H16+เย็น!H16+บ่าย!H16 -> 0 | I16: =เช้า!I16+เย็น!I16+บ่าย!I16 -> 0 | J16: =เช้า!J16+เย็น!J16+บ่าย!J16 -> 0 | K16: =เช้า!K16+เย็น!K16+บ่าย!K16 -> 0 | L16: =SUM(D16:K16) -> 0 | Q16: =(M16+N16+O16+P16)-L16 -> 0
B17: 1111092 | C17: ชิฟฟอน 8 ชิ้น กล้วยหอม | D17: =เช้า!D17+เย็น!D17+บ่าย!D17 -> 0 | E17: =เช้า!E17+เย็น!E17+บ่าย!E17 -> 0 | F17: =เช้า!F17+เย็น!F17+บ่าย!F17 -> 0 | G17: =เช้า!G17+เย็น!G17+บ่าย!G17 -> 0 | H17: =เช้า!H17+เย็น!H17+บ่าย!H17 -> 0 | I17: =เช้า!I17+เย็น!I17+บ่าย!I17 -> 0 | J17: =เช้า!J17+เย็น!J17+บ่าย!J17 -> 0 | K17: =เช้า!K17+เย็น!K17+บ่าย!K17 -> 0 | L17: =SUM(D17:K17) -> 0 | Q17: =(M17+N17+O17+P17)-L17 -> 0
B18: 1111093 | C18: ชิฟฟอน 8 ชิ้น โกโก้ล้วน | D18: =เช้า!D18+เย็น!D18+บ่าย!D18 -> 0 | E18: =เช้า!E18+เย็น!E18+บ่าย!E18 -> 0 | F18: =เช้า!F18+เย็น!F18+บ่าย!F18 -> 0 | G18: =เช้า!G18+เย็น!G18+บ่าย!G18 -> 0 | H18: =เช้า!H18+เย็น!H18+บ่าย!H18 -> 0 | I18: =เช้า!I18+เย็น!I18+บ่าย!I18 -> 0 | J18: =เช้า!J18+เย็น!J18+บ่าย!J18 -> 0 | K18: =เช้า!K18+เย็น!K18+บ่าย!K18 -> 0 | L18: =SUM(D18:K18) -> 0 | Q18: =(M18+N18+O18+P18)-L18 -> 0
B19: 1111094 | C19: ชิฟฟอน 8 ชิ้น ชาไทยล้วน | D19: =เช้า!D19+เย็น!D19+บ่าย!D19 -> 0 | E19: =เช้า!E19+เย็น!E19+บ่าย!E19 -> 0 | F19: =เช้า!F19+เย็น!F19+บ่าย!F19 -> 0 | G19: =เช้า!G19+เย็น!G19+บ่าย!G19 -> 0 | H19: =เช้า!H19+เย็น!H19+บ่าย!H19 -> 0 | I19: =เช้า!I19+เย็น!I19+บ่าย!I19 -> 0 | J19: =เช้า!J19+เย็น!J19+บ่าย!J19 -> 0 | K19: =เช้า!K19+เย็น!K19+บ่าย!K19 -> 0 | L19: =SUM(D19:K19) -> 0 | Q19: =(M19+N19+O19+P19)-L19 -> 0
B20: 1111095 | C20: ชิฟฟอน 8 ชิ้น ชาเขียวล้วน | D20: =เช้า!D20+เย็น!D20+บ่าย!D20 -> 0 | E20: =เช้า!E20+เย็น!E20+บ่าย!E20 -> 0 | F20: =เช้า!F20+เย็น!F20+บ่าย!F20 -> 0 | G20: =เช้า!G20+เย็น!G20+บ่าย!G20 -> 0 | H20: =เช้า!H20+เย็น!H20+บ่าย!H20 -> 0 | I20: =เช้า!I20+เย็น!I20+บ่าย!I20 -> 0 | J20: =เช้า!J20+เย็น!J20+บ่าย!J20 -> 0 | K20: =เช้า!K20+เย็น!K20+บ่าย!K20 -> 0 | L20: =SUM(D20:K20) -> 0 | Q20: =(M20+N20+O20+P20)-L20 -> 0
... B58: 1111076 | C58: ชิฟฟอนไส้แยมแยกชิ้น ส้ม | D58: =เช้า!D58+เย็น!D58+บ่าย!D58 -> 1 | E58: =เช้า!E58+เย็น!E58+บ่าย!E58 -> 0 | F58: =เช้า!F58+เย็น!F58+บ่าย!F58 -> 3 | G58: =เช้า!G58+เย็น!G58+บ่าย!G58 -> 0 | H58: =เช้า!H58+เย็น!H58+บ่าย!H58 -> 0 | I58: =เช้า!I58+เย็น!I58+บ่าย!I58 -> 0 | J58: =เช้า!J58+เย็น!J58+บ่าย!J58 -> 0 | K58: =เช้า!K58+เย็น!K58+บ่าย!K58 -> 0 | L58: =SUM(D58:K58) -> 4 | Q58: =(M58+N58+O58+P58)-L58 -> -4
B59: 1111077 | C59: ชิฟฟอนไส้แยมแยกชิ้น บลูเบอรี่ | D59: =เช้า!D59+เย็น!D59+บ่าย!D59 -> 1 | E59: =เช้า!E59+เย็น!E59+บ่าย!E59 -> 0 | F59: =เช้า!F59+เย็น!F59+บ่าย!F59 -> 3 | G59: =เช้า!G59+เย็น!G59+บ่าย!G59 -> 0 | H59: =เช้า!H59+เย็น!H59+บ่าย!H59 -> 0 | I59: =เช้า!I59+เย็น!I59+บ่าย!I59 -> 0 | J59: =เช้า!J59+เย็น!J59+บ่าย!J59 -> 0 | K59: =เช้า!K59+เย็น!K59+บ่าย!K59 -> 0 | L59: =SUM(D59:K59) -> 4 | N59: 10 | Q59: =(M59+N59+O59+P59)-L59 -> 6
B60: 1111078 | C60: ชิฟฟอนไส้แยมแยกชิ้น นมชมพู | D60: =เช้า!D60+เย็น!D60+บ่าย!D60 -> 1 | E60: =เช้า!E60+เย็น!E60+บ่าย!E60 -> 0 | F60: =เช้า!F60+เย็น!F60+บ่าย!F60 -> 3 | G60: =เช้า!G60+เย็น!G60+บ่าย!G60 -> 0 | H60: =เช้า!H60+เย็น!H60+บ่าย!H60 -> 0 | I60: =เช้า!I60+เย็น!I60+บ่าย!I60 -> 0 | J60: =เช้า!J60+เย็น!J60+บ่าย!J60 -> 0 | K60: =เช้า!K60+เย็น!K60+บ่าย!K60 -> 0 | L60: =SUM(D60:K60) -> 4 | Q60: =(M60+N60+O60+P60)-L60 -> -4
B61: 1111079 | C61: ชิฟฟอนไส้แยมแยกชิ้น ชอคโกแลต | D61: =เช้า!D61+เย็น!D61+บ่าย!D61 -> 1 | E61: =เช้า!E61+เย็น!E61+บ่าย!E61 -> 0 | F61: =เช้า!F61+เย็น!F61+บ่าย!F61 -> 3 | G61: =เช้า!G61+เย็น!G61+บ่าย!G61 -> 0 | H61: =เช้า!H61+เย็น!H61+บ่าย!H61 -> 0 | I61: =เช้า!I61+เย็น!I61+บ่าย!I61 -> 0 | J61: =เช้า!J61+เย็น!J61+บ่าย!J61 -> 0 | K61: =เช้า!K61+เย็น!K61+บ่าย!K61 -> 0 | L61: =SUM(D61:K61) -> 4 | Q61: =(M61+N61+O61+P61)-L61 -> -4
B62: 1111080 | C62: ชิฟฟอนไส้แยมแยกชิ้น ฝอยทอง | D62: =เช้า!D62+เย็น!D62+บ่าย!D62 -> 1 | E62: =เช้า!E62+เย็น!E62+บ่าย!E62 -> 0 | F62: =เช้า!F62+เย็น!F62+บ่าย!F62 -> 3 | G62: =เช้า!G62+เย็น!G62+บ่าย!G62 -> 0 | H62: =เช้า!H62+เย็น!H62+บ่าย!H62 -> 0 | I62: =เช้า!I62+เย็น!I62+บ่าย!I62 -> 0 | J62: =เช้า!J62+เย็น!J62+บ่าย!J62 -> 0 | K62: =เช้า!K62+เย็น!K62+บ่าย!K62 -> 0 | L62: =SUM(D62:K62) -> 4 | Q62: =(M62+N62+O62+P62)-L62 -> -4
B63: 1111081 | C63: ชิฟฟอนไส้แยมแยกชิ้น วนิลา | D63: =เช้า!D63+เย็น!D63+บ่าย!D63 -> 1 | E63: =เช้า!E63+เย็น!E63+บ่าย!E63 -> 0 | F63: =เช้า!F63+เย็น!F63+บ่าย!F63 -> 3 | G63: =เช้า!G63+เย็น!G63+บ่าย!G63 -> 0 | H63: =เช้า!H63+เย็น!H63+บ่าย!H63 -> 0 | I63: =เช้า!I63+เย็น!I63+บ่าย!I63 -> 0 | J63: =เช้า!J63+เย็น!J63+บ่าย!J63 -> 0 | K63: =เช้า!K63+เย็น!K63+บ่าย!K63 -> 0 | L63: =SUM(D63:K63) -> 4 | N63: 1 | Q63: =(M63+N63+O63+P63)-L63 -> -3
B64: 1111082 | C64: ชิฟฟอนไส้แยมแยกชิ้น ใบเตย | D64: =เช้า!D64+เย็น!D64+บ่าย!D64 -> 1 | E64: =เช้า!E64+เย็น!E64+บ่าย!E64 -> 0 | F64: =เช้า!F64+เย็น!F64+บ่าย!F64 -> 3 | G64: =เช้า!G64+เย็น!G64+บ่าย!G64 -> 0 | H64: =เช้า!H64+เย็น!H64+บ่าย!H64 -> 0 | I64: =เช้า!I64+เย็น!I64+บ่าย!I64 -> 0 | J64: =เช้า!J64+เย็น!J64+บ่าย!J64 -> 0 | K64: =เช้า!K64+เย็น!K64+บ่าย!K64 -> 0 | L64: =SUM(D64:K64) -> 4 | Q64: =(M64+N64+O64+P64)-L64 -> -4
B65: 1111083 | C65: ชิฟฟอนไส้แยมแยกชิ้น เมล่อน | D65: =เช้า!D65+เย็น!D65+บ่าย!D65 -> 1 | E65: =เช้า!E65+เย็น!E65+บ่าย!E65 -> 0 | F65: =เช้า!F65+เย็น!F65+บ่าย!F65 -> 3 | G65: =เช้า!G65+เย็น!G65+บ่าย!G65 -> 0 | H65: =เช้า!H65+เย็น!H65+บ่าย!H65 -> 0 | I65: =เช้า!I65+เย็น!I65+บ่าย!I65 -> 0 | J65: =เช้า!J65+เย็น!J65+บ่าย!J65 -> 0 | K65: =เช้า!K65+เย็น!K65+บ่าย!K65 -> 0 | L65: =SUM(D65:K65) -> 4 | Q65: =(M65+N65+O65+P65)-L65 -> -4
B66: 1111010 | C66: ชิฟฟอนไส้แยมแยกชิ้น คละรส | D66: =บ่าย!D66+เย็น!D66+เช้า!D66 -> 0 | E66: =บ่าย!E66+เย็น!E66+เช้า!E66 -> 0 | F66: =บ่าย!F66+เย็น!F66+เช้า!F66 -> 0 | G66: =บ่าย!G66+เย็น!G66+เช้า!G66 -> 0 | H66: =บ่าย!H66+เย็น!H66+เช้า!H66 -> 0 | I66: =บ่าย!I66+เย็น!I66+เช้า!I66 -> 0 | J66: =บ่าย!J66+เย็น!J66+เช้า!J66 -> 0 | L66: =SUM(D66:K66) -> 0 | Q66: =(M66+N66+O66+P66)-L66 -> 0
C67: รวม | L67: =SUM(D67:J67) -> 0 | Q67: =(M67+N67+O67+P67)-L67 -> 0
B68: ชิฟฟอนไส้แยม 6 ชิ้น
B69: 1111009 | C69: ชิฟฟอนไส้แยมรวมรส 6 ชิ้น | D69: =เช้า!D69+เย็น!D69+บ่าย!D69 -> 1 | E69: =เช้า!E69+เย็น!E69+บ่าย!E69 -> 2 | F69: =เช้า!F69+เย็น!F69+บ่าย!F69 -> 0 | G69: =เช้า!G69+เย็น!G69+บ่าย!G69 -> 0 | H69: =เช้า!H69+เย็น!H69+บ่าย!H69 -> 0 | I69: =เช้า!I69+เย็น!I69+บ่าย!I69 -> 0 | J69: =เช้า!J69+เย็น!J69+บ่าย!J69 -> 0 | K69: =เช้า!K69+เย็น!K69+บ่าย!K69 -> 0 | L69: =SUM(D69:K69) -> 3 | N69: 3 | Q69: =(M69+N69+O69+P69)-L69 -> 0
B70: 1111023 | C70: ชิฟฟอนไส้แยมรสสตอเบอร์รี่ล้วน 6 ชิ้น | D70: =เช้า!D70+เย็น!D70+บ่าย!D70 -> 0 | E70: =เช้า!E70+เย็น!E70+บ่าย!E70 -> 0 | F70: =เช้า!F70+เย็น!F70+บ่าย!F70 -> 0 | G70: =เช้า!G70+เย็น!G70+บ่าย!G70 -> 0 | H70: =เช้า!H70+เย็น!H70+บ่าย!H70 -> 0 | I70: =เช้า!I70+เย็น!I70+บ่าย!I70 -> 0 | J70: =เช้า!J70+เย็น!J70+บ่าย!J70 -> 0 | K70: =เช้า!K70+เย็น!K70+บ่าย!K70 -> 0 | L70: =SUM(D70:K70) -> 0 | Q70: =(M70+N70+O70+P70)-L70 -> 0
B71: 1111016 | C71: ชิฟฟอนไส้แยมรสมะพร้าวล้วน 6 ชิ้น | D71: =เช้า!D71+เย็น!D71+บ่าย!D71 -> 0 | E71: =เช้า!E71+เย็น!E71+บ่าย!E71 -> 0 | F71: =เช้า!F71+เย็น!F71+บ่าย!F71 -> 0 | G71: =เช้า!G71+เย็น!G71+บ่าย!G71 -> 0 | H71: =เช้า!H71+เย็น!H71+บ่าย!H71 -> 0 | I71: =เช้า!I71+เย็น!I71+บ่าย!I71 -> 0 | J71: =เช้า!J71+เย็น!J71+บ่าย!J71 -> 0 | K71: =เช้า!K71+เย็น!K71+บ่าย!K71 -> 0 | L71: =SUM(D71:K71) -> 0 | Q71: =(M71+N71+O71+P71)-L71 -> 0
B72: 1111014 | C72: ชิฟฟอนไส้แยมรสช็อกโกแลตนูเทลล่าล้วน 6 ชิ้น | D72: =เช้า!D72+เย็น!D72+บ่าย!D72 -> 0 | E72: =เช้า!E72+เย็น!E72+บ่าย!E72 -> 0 | F72: =เช้า!F72+เย็น!F72+บ่าย!F72 -> 0 | G72: =เช้า!G72+เย็น!G72+บ่าย!G72 -> 0 | H72: =เช้า!H72+เย็น!H72+บ่าย!H72 -> 0 | I72: =เช้า!I72+เย็น!I72+บ่าย!I72 -> 0 | J72: =เช้า!J72+เย็น!J72+บ่าย!J72 -> 0 | K72: =เช้า!K72+เย็น!K72+บ่าย!K72 -> 0 | L72: =SUM(D72:K72) -> 0 | Q72: =(M72+N72+O72+P72)-L72 -> 0
B73: 1111025 | C73: ชิฟฟอนไส้แยมรสส้มล้วน 6 ชิ้น | D73: =เช้า!D73+เย็น!D73+บ่าย!D73 -> 0 | E73: =เช้า!E73+เย็น!E73+บ่าย!E73 -> 0 | F73: =เช้า!F73+เย็น!F73+บ่าย!F73 -> 0 | G73: =เช้า!G73+เย็น!G73+บ่าย!G73 -> 0 | H73: =เช้า!H73+เย็น!H73+บ่าย!H73 -> 0 | I73: =เช้า!I73+เย็น!I73+บ่าย!I73 -> 0 | J73: =เช้า!J73+เย็น!J73+บ่าย!J73 -> 0 | K73: =เช้า!K73+เย็น!K73+บ่าย!K73 -> 0 | L73: =SUM(D73:K73) -> 0 | Q73: =(M73+N73+O73+P73)-L73 -> 0
B74: 1111018 | C74: ชิฟฟอนไส้แยมรสบลูเบอร์รี่ล้วน 6 ชิ้น | D74: =เช้า!D74+เย็น!D74+บ่าย!D74 -> 0 | E74: =เช้า!E74+เย็น!E74+บ่าย!E74 -> 0 | F74: =เช้า!F74+เย็น!F74+บ่าย!F74 -> 0 | G74: =เช้า!G74+เย็น!G74+บ่าย!G74 -> 0 | H74: =เช้า!H74+เย็น!H74+บ่าย!H74 -> 0 | I74: =เช้า!I74+เย็น!I74+บ่าย!I74 -> 0 | J74: =เช้า!J74+เย็น!J74+บ่าย!J74 -> 0 | K74: =เช้า!K74+เย็น!K74+บ่าย!K74 -> 0 | L74: =SUM(D74:K74) -> 0 | Q74: =(M74+N74+O74+P74)-L74 -> 0
B75: 1111012 | C75: ชิฟฟอนไส้แยมรสนมชมพูฮอกไกโดล้วน 6 ชิ้น | D75: =เช้า!D75+เย็น!D75+บ่าย!D75 -> 0 | E75: =เช้า!E75+เย็น!E75+บ่าย!E75 -> 0 | F75: =เช้า!F75+เย็น!F75+บ่าย!F75 -> 0 | G75: =เช้า!G75+เย็น!G75+บ่าย!G75 -> 0 | H75: =เช้า!H75+เย็น!H75+บ่าย!H75 -> 0 | I75: =เช้า!I75+เย็น!I75+บ่าย!I75 -> 0 | J75: =เช้า!J75+เย็น!J75+บ่าย!J75 -> 0 | K75: =เช้า!K75+เย็น!K75+บ่าย!K75 -> 0 | L75: =SUM(D75:K75) -> 0 | Q75: =(M75+N75+O75+P75)-L75 -> 0
B76: 1111020 | C76: ชิฟฟอนไส้แยมฝอยทองไส้ทะลัก 6 ชิ้น | D76: =เช้า!D76+เย็น!D76+บ่าย!D76 -> 0 | E76: =เช้า!E76+เย็น!E76+บ่าย!E76 -> 0 | F76: =เช้า!F76+เย็น!F76+บ่าย!F76 -> 0 | G76: =เช้า!G76+เย็น!G76+บ่าย!G76 -> 0 | H76: =เช้า!H76+เย็น!H76+บ่าย!H76 -> 0 | I76: =เช้า!I76+เย็น!I76+บ่าย!I76 -> 0 | J76: =เช้า!J76+เย็น!J76+บ่าย!J76 -> 0 | K76: =เช้า!K76+เย็น!K76+บ่าย!K76 -> 0 | L76: =SUM(D76:K76) -> 0 | Q76: =(M76+N76+O76+P76)-L76 -> 0
C77: รวม | Q77: =(M77+N77+O77+P77)-L77 -> 0
B78: ชิฟฟอนไส้แยม 3 ชิ้น
...
