Workbook

Sheet เช้า 
B1: ยอดจริง ออนไลน์ วันที่ - เช้า
L2: ยอดรวมผลิต
L3: จำนวน
B4: รหัสสินค้า | C4: สินค้า | D4: ปณ | E4: ชอปปี้ | F4: ลาซาด้า | G4: ติ๊กตอก | H4: ติ๊กตอก 2 | I4: ติ๊กตอก3 | J4: ชอยส์ | K4: ยอดเส้น | L4: (กล่อง)
B6: ชิฟฟอนรวมรส
B7: 1111002 | C7: ชิฟฟอนรวมรส 8 ชิ้น | D7: 5 | E7: 28 | F7: 7 | G7: 41 | H7: 16 | L7: =SUM(D7:K7) -> 97
C8: ชิฟฟอนแบบกล่องสุ่มอะไรก็ได้ที่มี | L8: =SUM(D8:K8) -> 0
B9: 1111084 | C9: ชิฟฟอน 8 ชิ้น กาแฟล้วน | L9: =SUM(D9:K9) -> 0
B10: 1111085 | C10: ชิฟฟอน 8 ชิ้น บลูเบอรี่ล้วน | L10: =SUM(D10:K10) -> 0
B11: 1111086 | C11: ชิฟฟอน 8 ชิ้น มะพร้าวล้วน | L11: =SUM(D11:K11) -> 0
B12: 1111087 | C12: ชิฟฟอน 8 ชิ้น สตอเบอรี่ล้วน | L12: =SUM(D12:K12) -> 0
B13: 1111088 | C13: ชิฟฟอน 8 ชิ้น ส้มล้วน | L13: =SUM(D13:K13) -> 0
B14: 1111089 | C14: ชิฟฟอน 8 ชิ้น เนยล้วน | L14: =SUM(D14:K14) -> 0
B15: 1111090 | C15: ชิฟฟอน 8 ชิ้น เผือกล้วน | L15: =SUM(D15:K15) -> 0
B16: 1111091 | C16: ชิฟฟอน 8 ชิ้น ใบเตยล้วน | L16: =SUM(D16:K16) -> 0
B17: 1111092 | C17: ชิฟฟอน 8 ชิ้น กล้วยหอม | L17: =SUM(D17:K17) -> 0
B18: 1111093 | C18: ชิฟฟอน 8 ชิ้น โกโก้ล้วน | L18: =SUM(D18:K18) -> 0
B19: 1111094 | C19: ชิฟฟอน 8 ชิ้น ชาไทยล้วน | L19: =SUM(D19:K19) -> 0
B20: 1111095 | C20: ชิฟฟอน 8 ชิ้น ชาเขียวล้วน | L20: =SUM(D20:K20) -> 0
... B24: 1111043 | C24: ชิฟฟอน 8 ชิ้น มะลิ | L24: =SUM(D24:K24) -> 0
B25: 1111056 | C25: ชิฟฟอน 8 ชิ้น รวมรสยอดฮิต | D25: 5 | E25: 9 | F25: 4 | G25: 2 | H25: 1 | L25: =SUM(D25:K25) -> 21
B26: 1004055 | C26: ชิฟฟอนรวมรส 4 ชิ้น | E26: 21 | G26: 24 | H26: 48 | L26: =SUM(D26:K26) -> 93
B27: 1004055 | C27: ชิฟฟอน 4 ชิ้น โกโก้ล้วน | L27: =SUM(D27:K27) -> 0
B28: 1004055 | C28: ชิฟฟอน 4 ชิ้น มะพร้าวล้วน | L28: =SUM(D28:K28) -> 0
B29: 1004055 | C29: ชิฟฟอน 4 ชิ้น เนยล้วน | L29: =SUM(D29:K29) -> 0
B30: 1004055 | C30: ชิฟฟอน 4 ชิ้น กาแฟล้วน | L30: =SUM(D30:K30) -> 0
B31: 1004055 | C31: ชิฟฟอน 4 ชิ้น ใบเตยล้วน | L31: =SUM(D31:K31) -> 0
B32: 1004055 | C32: ชิฟฟอน 4 ชิ้น บลูเบอร์รี่ล้วน | L32: =SUM(D32:K32) -> 0
B33: 1004055 | C33: ชิฟฟอน 4 ชิ้น ส้มล้วน | L33: =SUM(D33:K33) -> 0
B34: 1004055 | C34: ชิฟฟอน 4 ชิ้น เผือกล้วน | L34: =SUM(D34:K34) -> 0
B35: 1004055 | C35: ชิฟฟอน 4 ชิ้น สตอเบอรี่ล้วน | L35: =SUM(D35:K35) -> 0
B36: 1004055 | C36: ชิฟฟอน 4 ชิ้น กล้วยหอมล้วน | L36: =SUM(D36:K36) -> 0
B37: 1004055 | C37: ชิฟฟอน 4 ชิ้น ชาเขียวล้วน | L37: =SUM(D37:K37) -> 0
B38: 1004055 | C38: ชิฟฟอน 4 ชิ้น ชาไทยล้วน | L38: =SUM(D38:K38) -> 0
B39: 1004055 | C39: ชิฟฟอน 4 ชิ้น สับปะรดล้วน | L39: =SUM(D39:K39) -> 0
B40: 1111057 | C40: ชิฟฟอนแยกชิ้น กาแฟ | H40: 6 | L40: =SUM(D40:K40) -> 6
B41: 1111058 | C41: ชิฟฟอนแยกชิ้น ชาเขียว | H41: 6 | L41: =SUM(D41:K41) -> 6
B42: 1111059 | C42: ชิฟฟอนแยกชิ้น ใบเตย | H42: 15 | L42: =SUM(D42:K42) -> 15
B43: 1111060 | C43: ชิฟฟอนแยกชิ้น กล้วยหอม | H43: 1 | L43: =SUM(D43:K43) -> 1
B44: 1111061 | C44: ชิฟฟอนแยกชิ้น ชาไทย | H44: 4 | L44: =SUM(D44:K44) -> 4
...

Sheet บ่าย
B1: ยอดจริง ออนไลน์ วันที่ - บ่าย
L2: ยอดรวมผลิต
L3: จำนวน
B4: รหัสสินค้า | C4: สินค้า | D4: ปณ | E4: ชอปปี้ | F4: ลาซาด้า | G4: ติ๊กตอก | H4: ติ๊กตอก 2 | I4: ติ๊กตอก3 | J4: ชอยส์ | K4: ยอดเส้น | L4: (กล่อง)
B6: ชิฟฟอนรวมรส
B7: 1111002 | C7: ชิฟฟอนรวมรส 8 ชิ้น | D7: 2 | E7: 13 | F7: 13 | L7: =SUM(D7:K7) -> 28
C8: ชิฟฟอนแบบกล่องสุ่มอะไรก็ได้ที่มี | L8: =SUM(D8:K8) -> 0
B9: 1111084 | C9: ชิฟฟอน 8 ชิ้น กาแฟล้วน | L9: =SUM(D9:K9) -> 0
B10: 1111085 | C10: ชิฟฟอน 8 ชิ้น บลูเบอรี่ล้วน | L10: =SUM(D10:K10) -> 0
B11: 1111086 | C11: ชิฟฟอน 8 ชิ้น มะพร้าวล้วน | L11: =SUM(D11:K11) -> 0
B12: 1111087 | C12: ชิฟฟอน 8 ชิ้น สตอเบอรี่ล้วน | L12: =SUM(D12:K12) -> 0
B13: 1111088 | C13: ชิฟฟอน 8 ชิ้น ส้มล้วน | L13: =SUM(D13:K13) -> 0
B14: 1111089 | C14: ชิฟฟอน 8 ชิ้น เนยล้วน | L14: =SUM(D14:K14) -> 0
B15: 1111090 | C15: ชิฟฟอน 8 ชิ้น เผือกล้วน | L15: =SUM(D15:K15) -> 0
B16: 1111091 | C16: ชิฟฟอน 8 ชิ้น ใบเตยล้วน | L16: =SUM(D16:K16) -> 0
B17: 1111092 | C17: ชิฟฟอน 8 ชิ้น กล้วยหอม | L17: =SUM(D17:K17) -> 0
B18: 1111093 | C18: ชิฟฟอน 8 ชิ้น โกโก้ล้วน | L18: =SUM(D18:K18) -> 0
B19: 1111094 | C19: ชิฟฟอน 8 ชิ้น ชาไทยล้วน | L19: =SUM(D19:K19) -> 0
B20: 1111095 | C20: ชิฟฟอน 8 ชิ้น ชาเขียวล้วน | L20: =SUM(D20:K20) -> 0
... B24: 1111043 | C24: ชิฟฟอน 8 ชิ้น มะลิ | L24: =SUM(D24:K24) -> 0
B25: 1111056 | C25: ชิฟฟอน 8 ชิ้น รวมรสยอดฮิต | D25: 2 | E25: 12 | L25: =SUM(D25:K25) -> 14
B26: 1004055 | C26: ชิฟฟอนรวมรส 4 ชิ้น | D26: 15 | E26: 10 | F26: 6 | G26: 79 | L26: =SUM(D26:K26) -> 110
B27: 1004055 | C27: ชิฟฟอน 4 ชิ้น โกโก้ล้วน | L27: =SUM(D27:K27) -> 0
B28: 1004055 | C28: ชิฟฟอน 4 ชิ้น มะพร้าวล้วน | L28: =SUM(D28:K28) -> 0
B29: 1004055 | C29: ชิฟฟอน 4 ชิ้น เนยล้วน | L29: =SUM(D29:K29) -> 0
B30: 1004055 | C30: ชิฟฟอน 4 ชิ้น กาแฟล้วน | L30: =SUM(D30:K30) -> 0
B31: 1004055 | C31: ชิฟฟอน 4 ชิ้น ใบเตยล้วน | L31: =SUM(D31:K31) -> 0
B32: 1004055 | C32: ชิฟฟอน 4 ชิ้น บลูเบอร์รี่ล้วน | L32: =SUM(D32:K32) -> 0
B33: 1004055 | C33: ชิฟฟอน 4 ชิ้น ส้มล้วน | L33: =SUM(D33:K33) -> 0
B34: 1004055 | C34: ชิฟฟอน 4 ชิ้น เผือกล้วน | L34: =SUM(D34:K34) -> 0
B35: 1004055 | C35: ชิฟฟอน 4 ชิ้น สตอเบอรี่ล้วน | L35: =SUM(D35:K35) -> 0
B36: 1004055 | C36: ชิฟฟอน 4 ชิ้น กล้วยหอมล้วน | L36: =SUM(D36:K36) -> 0
B37: 1004055 | C37: ชิฟฟอน 4 ชิ้น ชาเขียวล้วน | L37: =SUM(D37:K37) -> 0
B38: 1004055 | C38: ชิฟฟอน 4 ชิ้น ชาไทยล้วน | L38: =SUM(D38:K38) -> 0
B39: 1004055 | C39: ชิฟฟอน 4 ชิ้น สับปะรดล้วน | L39: =SUM(D39:K39) -> 0
B40: 1111057 | C40: ชิฟฟอนแยกชิ้น กาแฟ | G40: 1 | L40: =SUM(D40:K40) -> 1
B41: 1111058 | C41: ชิฟฟอนแยกชิ้น ชาเขียว | G41: 1 | L41: =SUM(D41:K41) -> 1
B42: 1111059 | C42: ชิฟฟอนแยกชิ้น ใบเตย | G42: 1 | L42: =SUM(D42:K42) -> 1
B43: 1111060 | C43: ชิฟฟอนแยกชิ้น กล้วยหอม | G43: 1 | L43: =SUM(D43:K43) -> 1
B44: 1111061 | C44: ชิฟฟอนแยกชิ้น ชาไทย | G44: 1 | L44: =SUM(D44:K44) -> 1
...

Sheet เย็น 
B1: ยอดจริง ออนไลน์ วันที่ 20/1/2568- บ่าย 2
L2: ยอดรวมผลิต
L3: จำนวน
B4: รหัสสินค้า | C4: สินค้า | D4: ปณ | E4: ชอปปี้ | F4: ลาซาด้า | G4: ติ๊กตอก | H4: ติ๊กตอก 2 | I4: ติ๊กตอก3 | J4: ชอยส์ | K4: ยอดเส้น | L4: (กล่อง)
B6: ชิฟฟอนรวมรส
B7: 1111002 | C7: ชิฟฟอนรวมรส 8 ชิ้น | G7: 1 | L7: =SUM(D7:K7) -> 1
C8: ชิฟฟอนแบบกล่องสุ่มอะไรก็ได้ที่มี | L8: =SUM(D8:K8) -> 0
B9: 1111084 | C9: ชิฟฟอน 8 ชิ้น กาแฟล้วน | L9: =SUM(D9:K9) -> 0
B10: 1111085 | C10: ชิฟฟอน 8 ชิ้น บลูเบอรี่ล้วน | L10: =SUM(D10:K10) -> 0
B11: 1111086 | C11: ชิฟฟอน 8 ชิ้น มะพร้าวล้วน | L11: =SUM(D11:K11) -> 0
B12: 1111087 | C12: ชิฟฟอน 8 ชิ้น สตอเบอรี่ล้วน | L12: =SUM(D12:K12) -> 0
B13: 1111088 | C13: ชิฟฟอน 8 ชิ้น ส้มล้วน | L13: =SUM(D13:K13) -> 0
B14: 1111089 | C14: ชิฟฟอน 8 ชิ้น เนยล้วน | L14: =SUM(D14:K14) -> 0
B15: 1111090 | C15: ชิฟฟอน 8 ชิ้น เผือกล้วน | L15: =SUM(D15:K15) -> 0
B16: 1111091 | C16: ชิฟฟอน 8 ชิ้น ใบเตยล้วน | L16: =SUM(D16:K16) -> 0
B17: 1111092 | C17: ชิฟฟอน 8 ชิ้น กล้วยหอม | L17: =SUM(D17:K17) -> 0
B18: 1111093 | C18: ชิฟฟอน 8 ชิ้น โกโก้ล้วน | L18: =SUM(D18:K18) -> 0
B19: 1111094 | C19: ชิฟฟอน 8 ชิ้น ชาไทยล้วน | L19: =SUM(D19:K19) -> 0
B20: 1111095 | C20: ชิฟฟอน 8 ชิ้น ชาเขียวล้วน | L20: =SUM(D20:K20) -> 0
... B24: 1111043 | C24: ชิฟฟอน 8 ชิ้น มะลิ | L24: =SUM(D24:K24) -> 0
B25: 1111056 | C25: ชิฟฟอน 8 ชิ้น รวมรสยอดฮิต | G25: 1 | L25: =SUM(D25:K25) -> 1
B26: 1004055 | C26: ชิฟฟอนรวมรส 4 ชิ้น | G26: 6 | L26: =SUM(D26:K26) -> 6
B27: 1004055 | C27: ชิฟฟอน 4 ชิ้น โกโก้ล้วน | L27: =SUM(D27:K27) -> 0
B28: 1004055 | C28: ชิฟฟอน 4 ชิ้น มะพร้าวล้วน | L28: =SUM(D28:K28) -> 0
B29: 1004055 | C29: ชิฟฟอน 4 ชิ้น เนยล้วน | L29: =SUM(D29:K29) -> 0
B30: 1004055 | C30: ชิฟฟอน 4 ชิ้น กาแฟล้วน | L30: =SUM(D30:K30) -> 0
B31: 1004055 | C31: ชิฟฟอน 4 ชิ้น ใบเตยล้วน | L31: =SUM(D31:K31) -> 0
B32: 1004055 | C32: ชิฟฟอน 4 ชิ้น บลูเบอร์รี่ล้วน | L32: =SUM(D32:K32) -> 0
B33: 1004055 | C33: ชิฟฟอน 4 ชิ้น ส้มล้วน | L33: =SUM(D33:K33) -> 0
B34: 1004055 | C34: ชิฟฟอน 4 ชิ้น เผือกล้วน | L34: =SUM(D34:K34) -> 0
B35: 1004055 | C35: ชิฟฟอน 4 ชิ้น สตอเบอรี่ล้วน | L35: =SUM(D35:K35) -> 0
B36: 1004055 | C36: ชิฟฟอน 4 ชิ้น กล้วยหอมล้วน | L36: =SUM(D36:K36) -> 0
B37: 1004055 | C37: ชิฟฟอน 4 ชิ้น ชาเขียวล้วน | L37: =SUM(D37:K37) -> 0
B38: 1004055 | C38: ชิฟฟอน 4 ชิ้น ชาไทยล้วน | L38: =SUM(D38:K38) -> 0
... B66: 1111010 | C66: ชิฟฟอนไส้แยมแยกชิ้น คละรส | L66: =SUM(D66:K66) -> 0
C67: รวม
B68: ชิฟฟอนไส้แยม 6 ชิ้น
B69: 1111009 | C69: ชิฟฟอนไส้แยมรวมรส 6 ชิ้น | G69: 4 | L69: =SUM(D69:K69) -> 4
B70: 1111023 | C70: ชิฟฟอนไส้แยมรสสตอเบอร์รี่ล้วน 6 ชิ้น | L70: =SUM(D70:K70) -> 0
B71: 1111016 | C71: ชิฟฟอนไส้แยมรสมะพร้าวล้วน 6 ชิ้น | L71: =SUM(D71:K71) -> 0
...

Sheet รวม
B1: ยอดจริง ออนไลน์ วันที่ 20/1/68 รวม
L2: ยอดรวมผลิต | M2: ยอดฟอแคส | N2: ยอดสตอค | O2: ยอดเมโม่ | P2: ยอดฟอแคสวันพรุ่งนี้ | Q2: รวม
L3: จำนวน
B4: รหัสสินค้า | C4: สินค้า | D4: ปณ | E4: ชอปปี้ | F4: ลาซาด้า | G4: ติ๊กตอก | H4: ติ๊กตอก2 | I4: ติ๊กตอก3 | J4: ชอยส์ | K4: ยอดเส้น | L4: (กล่อง)
B6: ชิฟฟอนรวมรส
B7: 1111002 | C7: ชิฟฟอนรวมรส 8 ชิ้น | D7: ='เย็น '!D7+'เช้า '!D7+บ่าย!D7 -> 7 | E7: ='เย็น '!E7+'เช้า '!E7+บ่าย!E7 -> 41 | F7: ='เย็น '!F7+'เช้า '!F7+บ่าย!F7 -> 20 | G7: ='เย็น '!G7+'เช้า '!G7+บ่าย!G7 -> 42 | H7: ='เย็น '!H7+'เช้า '!H7+บ่าย!H7 -> 16 | I7: ='เย็น '!I7+'เช้า '!I7+บ่าย!I7 -> 0 | J7: ='เย็น '!J7+'เช้า '!J7+บ่าย!J7 -> 0 | K7: ='เย็น '!K7+'เช้า '!K7+บ่าย!K7 -> 0 | L7: =SUM(D7:K7) -> 126 | N7: 1460 | Q7: =(M7+N7+O7+P7)-L7 -> 1334
C8: ชิฟฟอนแบบกล่องสุ่มอะไรก็ได้ที่มี | D8: ='เย็น '!D8+'เช้า '!D8+บ่าย!D8 -> 0 | E8: ='เย็น '!E8+'เช้า '!E8+บ่าย!E8 -> 0 | F8: ='เย็น '!F8+'เช้า '!F8+บ่าย!F8 -> 0 | G8: ='เย็น '!G8+'เช้า '!G8+บ่าย!G8 -> 0 | H8: ='เย็น '!H8+'เช้า '!H8+บ่าย!H8 -> 0 | I8: ='เย็น '!I8+'เช้า '!I8+บ่าย!I8 -> 0 | J8: ='เย็น '!J8+'เช้า '!J8+บ่าย!J8 -> 0 | K8: ='เย็น '!K8+'เช้า '!K8+บ่าย!K8 -> 0 | L8: =SUM(D8:K8) -> 0 | Q8: =(M8+N8+O8+P8)-L8 -> 0
B9: 1111084 | C9: ชิฟฟอน 8 ชิ้น กาแฟล้วน | D9: ='เย็น '!D9+'เช้า '!D9+บ่าย!D9 -> 0 | E9: ='เย็น '!E9+'เช้า '!E9+บ่าย!E9 -> 0 | F9: ='เย็น '!F9+'เช้า '!F9+บ่าย!F9 -> 0 | G9: ='เย็น '!G9+'เช้า '!G9+บ่าย!G9 -> 0 | H9: ='เย็น '!H9+'เช้า '!H9+บ่าย!H9 -> 0 | I9: ='เย็น '!I9+'เช้า '!I9+บ่าย!I9 -> 0 | J9: ='เย็น '!J9+'เช้า '!J9+บ่าย!J9 -> 0 | K9: ='เย็น '!K9+'เช้า '!K9+บ่าย!K9 -> 0 | L9: =SUM(D9:K9) -> 0 | Q9: =(M9+N9+O9+P9)-L9 -> 0
B10: 1111085 | C10: ชิฟฟอน 8 ชิ้น บลูเบอรี่ล้วน | D10: ='เย็น '!D10+'เช้า '!D10+บ่าย!D10 -> 0 | E10: ='เย็น '!E10+'เช้า '!E10+บ่าย!E10 -> 0 | F10: ='เย็น '!F10+'เช้า '!F10+บ่าย!F10 -> 0 | G10: ='เย็น '!G10+'เช้า '!G10+บ่าย!G10 -> 0 | H10: ='เย็น '!H10+'เช้า '!H10+บ่าย!H10 -> 0 | I10: ='เย็น '!I10+'เช้า '!I10+บ่าย!I10 -> 0 | J10: ='เย็น '!J10+'เช้า '!J10+บ่าย!J10 -> 0 | K10: ='เย็น '!K10+'เช้า '!K10+บ่าย!K10 -> 0 | L10: =SUM(D10:K10) -> 0 | Q10: =(M10+N10+O10+P10)-L10 -> 0
B11: 1111086 | C11: ชิฟฟอน 8 ชิ้น มะพร้าวล้วน | D11: ='เย็น '!D11+'เช้า '!D11+บ่าย!D11 -> 0 | E11: ='เย็น '!E11+'เช้า '!E11+บ่าย!E11 -> 0 | F11: ='เย็น '!F11+'เช้า '!F11+บ่าย!F11 -> 0 | G11: ='เย็น '!G11+'เช้า '!G11+บ่าย!G11 -> 0 | H11: ='เย็น '!H11+'เช้า '!H11+บ่าย!H11 -> 0 | I11: ='เย็น '!I11+'เช้า '!I11+บ่าย!I11 -> 0 | J11: ='เย็น '!J11+'เช้า '!J11+บ่าย!J11 -> 0 | K11: ='เย็น '!K11+'เช้า '!K11+บ่าย!K11 -> 0 | L11: =SUM(D11:K11) -> 0 | Q11: =(M11+N11+O11+P11)-L11 -> 0
B12: 1111087 | C12: ชิฟฟอน 8 ชิ้น สตอเบอรี่ล้วน | D12: ='เย็น '!D12+'เช้า '!D12+บ่าย!D12 -> 0 | E12: ='เย็น '!E12+'เช้า '!E12+บ่าย!E12 -> 0 | F12: ='เย็น '!F12+'เช้า '!F12+บ่าย!F12 -> 0 | G12: ='เย็น '!G12+'เช้า '!G12+บ่าย!G12 -> 0 | H12: ='เย็น '!H12+'เช้า '!H12+บ่าย!H12 -> 0 | I12: ='เย็น '!I12+'เช้า '!I12+บ่าย!I12 -> 0 | J12: ='เย็น '!J12+'เช้า '!J12+บ่าย!J12 -> 0 | K12: ='เย็น '!K12+'เช้า '!K12+บ่าย!K12 -> 0 | L12: =SUM(D12:K12) -> 0 | Q12: =(M12+N12+O12+P12)-L12 -> 0
B13: 1111088 | C13: ชิฟฟอน 8 ชิ้น ส้มล้วน | D13: ='เย็น '!D13+'เช้า '!D13+บ่าย!D13 -> 0 | E13: ='เย็น '!E13+'เช้า '!E13+บ่าย!E13 -> 0 | F13: ='เย็น '!F13+'เช้า '!F13+บ่าย!F13 -> 0 | G13: ='เย็น '!G13+'เช้า '!G13+บ่าย!G13 -> 0 | H13: ='เย็น '!H13+'เช้า '!H13+บ่าย!H13 -> 0 | I13: ='เย็น '!I13+'เช้า '!I13+บ่าย!I13 -> 0 | J13: ='เย็น '!J13+'เช้า '!J13+บ่าย!J13 -> 0 | K13: ='เย็น '!K13+'เช้า '!K13+บ่าย!K13 -> 0 | L13: =SUM(D13:K13) -> 0 | Q13: =(M13+N13+O13+P13)-L13 -> 0
B14: 1111089 | C14: ชิฟฟอน 8 ชิ้น เนยล้วน | D14: ='เย็น '!D14+'เช้า '!D14+บ่าย!D14 -> 0 | E14: ='เย็น '!E14+'เช้า '!E14+บ่าย!E14 -> 0 | F14: ='เย็น '!F14+'เช้า '!F14+บ่าย!F14 -> 0 | G14: ='เย็น '!G14+'เช้า '!G14+บ่าย!G14 -> 0 | H14: ='เย็น '!H14+'เช้า '!H14+บ่าย!H14 -> 0 | I14: ='เย็น '!I14+'เช้า '!I14+บ่าย!I14 -> 0 | J14: ='เย็น '!J14+'เช้า '!J14+บ่าย!J14 -> 0 | K14: ='เย็น '!K14+'เช้า '!K14+บ่าย!K14 -> 0 | L14: =SUM(D14:K14) -> 0 | Q14: =(M14+N14+O14+P14)-L14 -> 0
B15: 1111090 | C15: ชิฟฟอน 8 ชิ้น เผือกล้วน | D15: ='เย็น '!D15+'เช้า '!D15+บ่าย!D15 -> 0 | E15: ='เย็น '!E15+'เช้า '!E15+บ่าย!E15 -> 0 | F15: ='เย็น '!F15+'เช้า '!F15+บ่าย!F15 -> 0 | G15: ='เย็น '!G15+'เช้า '!G15+บ่าย!G15 -> 0 | H15: ='เย็น '!H15+'เช้า '!H15+บ่าย!H15 -> 0 | I15: ='เย็น '!I15+'เช้า '!I15+บ่าย!I15 -> 0 | J15: ='เย็น '!J15+'เช้า '!J15+บ่าย!J15 -> 0 | K15: ='เย็น '!K15+'เช้า '!K15+บ่าย!K15 -> 0 | L15: =SUM(D15:K15) -> 0 | Q15: =(M15+N15+O15+P15)-L15 -> 0
B16: 1111091 | C16: ชิฟฟอน 8 ชิ้น ใบเตยล้วน | D16: ='เย็น '!D16+'เช้า '!D16+บ่าย!D16 -> 0 | E16: ='เย็น '!E16+'เช้า '!E16+บ่าย!E16 -> 0 | F16: ='เย็น '!F16+'เช้า '!F16+บ่าย!F16 -> 0 | G16: ='เย็น '!G16+'เช้า '!G16+บ่าย!G16 -> 0 | H16: ='เย็น '!H16+'เช้า '!H16+บ่าย!H16 -> 0 | I16: ='เย็น '!I16+'เช้า '!I16+บ่าย!I16 -> 0 | J16: ='เย็น '!J16+'เช้า '!J16+บ่าย!J16 -> 0 | K16: ='เย็น '!K16+'เช้า '!K16+บ่าย!K16 -> 0 | L16: =SUM(D16:K16) -> 0 | Q16: =(M16+N16+O16+P16)-L16 -> 0
B17: 1111092 | C17: ชิฟฟอน 8 ชิ้น กล้วยหอม | D17: ='เย็น '!D17+'เช้า '!D17+บ่าย!D17 -> 0 | E17: ='เย็น '!E17+'เช้า '!E17+บ่าย!E17 -> 0 | F17: ='เย็น '!F17+'เช้า '!F17+บ่าย!F17 -> 0 | G17: ='เย็น '!G17+'เช้า '!G17+บ่าย!G17 -> 0 | H17: ='เย็น '!H17+'เช้า '!H17+บ่าย!H17 -> 0 | I17: ='เย็น '!I17+'เช้า '!I17+บ่าย!I17 -> 0 | J17: ='เย็น '!J17+'เช้า '!J17+บ่าย!J17 -> 0 | K17: ='เย็น '!K17+'เช้า '!K17+บ่าย!K17 -> 0 | L17: =SUM(D17:K17) -> 0 | Q17: =(M17+N17+O17+P17)-L17 -> 0
B18: 1111093 | C18: ชิฟฟอน 8 ชิ้น โกโก้ล้วน | D18: ='เย็น '!D18+'เช้า '!D18+บ่าย!D18 -> 0 | E18: ='เย็น '!E18+'เช้า '!E18+บ่าย!E18 -> 0 | F18: ='เย็น '!F18+'เช้า '!F18+บ่าย!F18 -> 0 | G18: ='เย็น '!G18+'เช้า '!G18+บ่าย!G18 -> 0 | H18: ='เย็น '!H18+'เช้า '!H18+บ่าย!H18 -> 0 | I18: ='เย็น '!I18+'เช้า '!I18+บ่าย!I18 -> 0 | J18: ='เย็น '!J18+'เช้า '!J18+บ่าย!J18 -> 0 | K18: ='เย็น '!K18+'เช้า '!K18+บ่าย!K18 -> 0 | L18: =SUM(D18:K18) -> 0 | Q18: =(M18+N18+O18+P18)-L18 -> 0
B19: 1111094 | C19: ชิฟฟอน 8 ชิ้น ชาไทยล้วน | D19: ='เย็น '!D19+'เช้า '!D19+บ่าย!D19 -> 0 | E19: ='เย็น '!E19+'เช้า '!E19+บ่าย!E19 -> 0 | F19: ='เย็น '!F19+'เช้า '!F19+บ่าย!F19 -> 0 | G19: ='เย็น '!G19+'เช้า '!G19+บ่าย!G19 -> 0 | H19: ='เย็น '!H19+'เช้า '!H19+บ่าย!H19 -> 0 | I19: ='เย็น '!I19+'เช้า '!I19+บ่าย!I19 -> 0 | J19: ='เย็น '!J19+'เช้า '!J19+บ่าย!J19 -> 0 | K19: ='เย็น '!K19+'เช้า '!K19+บ่าย!K19 -> 0 | L19: =SUM(D19:K19) -> 0 | Q19: =(M19+N19+O19+P19)-L19 -> 0
B20: 1111095 | C20: ชิฟฟอน 8 ชิ้น ชาเขียวล้วน | D20: ='เย็น '!D20+'เช้า '!D20+บ่าย!D20 -> 0 | E20: ='เย็น '!E20+'เช้า '!E20+บ่าย!E20 -> 0 | F20: ='เย็น '!F20+'เช้า '!F20+บ่าย!F20 -> 0 | G20: ='เย็น '!G20+'เช้า '!G20+บ่าย!G20 -> 0 | H20: ='เย็น '!H20+'เช้า '!H20+บ่าย!H20 -> 0 | I20: ='เย็น '!I20+'เช้า '!I20+บ่าย!I20 -> 0 | J20: ='เย็น '!J20+'เช้า '!J20+บ่าย!J20 -> 0 | K20: ='เย็น '!K20+'เช้า '!K20+บ่าย!K20 -> 0 | L20: =SUM(D20:K20) -> 0 | Q20: =(M20+N20+O20+P20)-L20 -> 0
... B24: 1111043 | C24: ชิฟฟอน 8 ชิ้น มะลิ | D24: ='เย็น '!D24+'เช้า '!D24+บ่าย!D24 -> 0 | E24: ='เย็น '!E24+'เช้า '!E24+บ่าย!E24 -> 0 | F24: ='เย็น '!F24+'เช้า '!F24+บ่าย!F24 -> 0 | G24: ='เย็น '!G24+'เช้า '!G24+บ่าย!G24 -> 0 | H24: ='เย็น '!H24+'เช้า '!H24+บ่าย!H24 -> 0 | I24: ='เย็น '!I24+'เช้า '!I24+บ่าย!I24 -> 0 | J24: ='เย็น '!J24+'เช้า '!J24+บ่าย!J24 -> 0 | K24: ='เย็น '!K24+'เช้า '!K24+บ่าย!K24 -> 0 | L24: =SUM(D24:K24) -> 0 | Q24: =(M24+N24+O24+P24)-L24 -> 0
B25: 1111056 | C25: ชิฟฟอน 8 ชิ้น รวมรสยอดฮิต | D25: ='เย็น '!D25+'เช้า '!D25+บ่าย!D25 -> 7 | E25: ='เย็น '!E25+'เช้า '!E25+บ่าย!E25 -> 21 | F25: ='เย็น '!F25+'เช้า '!F25+บ่าย!F25 -> 4 | G25: ='เย็น '!G25+'เช้า '!G25+บ่าย!G25 -> 3 | H25: ='เย็น '!H25+'เช้า '!H25+บ่าย!H25 -> 1 | I25: ='เย็น '!I25+'เช้า '!I25+บ่าย!I25 -> 0 | J25: ='เย็น '!J25+'เช้า '!J25+บ่าย!J25 -> 0 | K25: ='เย็น '!K25+'เช้า '!K25+บ่าย!K25 -> 0 | L25: =SUM(D25:K25) -> 36 | N25: 67 | Q25: =(M25+N25+O25+P25)-L25 -> 31
B26: 1004055 | C26: ชิฟฟอนรวมรส 4 ชิ้น | D26: ='เย็น '!D26+'เช้า '!D26+บ่าย!D26 -> 15 | E26: ='เย็น '!E26+'เช้า '!E26+บ่าย!E26 -> 31 | F26: ='เย็น '!F26+'เช้า '!F26+บ่าย!F26 -> 6 | G26: ='เย็น '!G26+'เช้า '!G26+บ่าย!G26 -> 109 | H26: ='เย็น '!H26+'เช้า '!H26+บ่าย!H26 -> 48 | I26: ='เย็น '!I26+'เช้า '!I26+บ่าย!I26 -> 0 | J26: ='เย็น '!J26+'เช้า '!J26+บ่าย!J26 -> 0 | K26: ='เย็น '!K26+'เช้า '!K26+บ่าย!K26 -> 0 | L26: =SUM(D26:K26) -> 209 | N26: 117 | Q26: =(M26+N26+O26+P26)-L26 -> -92
B27: 1004055 | C27: ชิฟฟอน 4 ชิ้น โกโก้ล้วน | D27: ='เย็น '!D27+'เช้า '!D27+บ่าย!D27 -> 0 | E27: ='เย็น '!E27+'เช้า '!E27+บ่าย!E27 -> 0 | F27: ='เย็น '!F27+'เช้า '!F27+บ่าย!F27 -> 0 | G27: ='เย็น '!G27+'เช้า '!G27+บ่าย!G27 -> 0 | H27: ='เย็น '!H27+'เช้า '!H27+บ่าย!H27 -> 0 | I27: ='เย็น '!I27+'เช้า '!I27+บ่าย!I27 -> 0 | J27: ='เย็น '!J27+'เช้า '!J27+บ่าย!J27 -> 0 | K27: ='เย็น '!K27+'เช้า '!K27+บ่าย!K27 -> 0 | L27: =SUM(D27:K27) -> 0 | Q27: =(M27+N27+O27+P27)-L27 -> 0
B28: 1004055 | C28: ชิฟฟอน 4 ชิ้น มะพร้าวล้วน | D28: ='เย็น '!D28+'เช้า '!D28+บ่าย!D28 -> 0 | E28: ='เย็น '!E28+'เช้า '!E28+บ่าย!E28 -> 0 | F28: ='เย็น '!F28+'เช้า '!F28+บ่าย!F28 -> 0 | G28: ='เย็น '!G28+'เช้า '!G28+บ่าย!G28 -> 0 | H28: ='เย็น '!H28+'เช้า '!H28+บ่าย!H28 -> 0 | I28: ='เย็น '!I28+'เช้า '!I28+บ่าย!I28 -> 0 | J28: ='เย็น '!J28+'เช้า '!J28+บ่าย!J28 -> 0 | K28: ='เย็น '!K28+'เช้า '!K28+บ่าย!K28 -> 0 | L28: =SUM(D28:K28) -> 0 | Q28: =(M28+N28+O28+P28)-L28 -> 0
B29: 1004055 | C29: ชิฟฟอน 4 ชิ้น เนยล้วน | D29: ='เย็น '!D29+'เช้า '!D29+บ่าย!D29 -> 0 | E29: ='เย็น '!E29+'เช้า '!E29+บ่าย!E29 -> 0 | F29: ='เย็น '!F29+'เช้า '!F29+บ่าย!F29 -> 0 | G29: ='เย็น '!G29+'เช้า '!G29+บ่าย!G29 -> 0 | H29: ='เย็น '!H29+'เช้า '!H29+บ่าย!H29 -> 0 | I29: ='เย็น '!I29+'เช้า '!I29+บ่าย!I29 -> 0 | J29: ='เย็น '!J29+'เช้า '!J29+บ่าย!J29 -> 0 | K29: ='เย็น '!K29+'เช้า '!K29+บ่าย!K29 -> 0 | L29: =SUM(D29:K29) -> 0 | Q29: =(M29+N29+O29+P29)-L29 -> 0
B30: 1004055 | C30: ชิฟฟอน 4 ชิ้น กาแฟล้วน | D30: ='เย็น '!D30+'เช้า '!D30+บ่าย!D30 -> 0 | E30: ='เย็น '!E30+'เช้า '!E30+บ่าย!E30 -> 0 | F30: ='เย็น '!F30+'เช้า '!F30+บ่าย!F30 -> 0 | G30: ='เย็น '!G30+'เช้า '!G30+บ่าย!G30 -> 0 | H30: ='เย็น '!H30+'เช้า '!H30+บ่าย!H30 -> 0 | I30: ='เย็น '!I30+'เช้า '!I30+บ่าย!I30 -> 0 | J30: ='เย็น '!J30+'เช้า '!J30+บ่าย!J30 -> 0 | K30: ='เย็น '!K30+'เช้า '!K30+บ่าย!K30 -> 0 | L30: =SUM(D30:K30) -> 0 | Q30: =(M30+N30+O30+P30)-L30 -> 0
B31: 1004055 | C31: ชิฟฟอน 4 ชิ้น ใบเตยล้วน | D31: ='เย็น '!D31+'เช้า '!D31+บ่าย!D31 -> 0 | E31: ='เย็น '!E31+'เช้า '!E31+บ่าย!E31 -> 0 | F31: ='เย็น '!F31+'เช้า '!F31+บ่าย!F31 -> 0 | G31: ='เย็น '!G31+'เช้า '!G31+บ่าย!G31 -> 0 | H31: ='เย็น '!H31+'เช้า '!H31+บ่าย!H31 -> 0 | I31: ='เย็น '!I31+'เช้า '!I31+บ่าย!I31 -> 0 | J31: ='เย็น '!J31+'เช้า '!J31+บ่าย!J31 -> 0 | K31: ='เย็น '!K31+'เช้า '!K31+บ่าย!K31 -> 0 | L31: =SUM(D31:K31) -> 0 | Q31: =(M31+N31+O31+P31)-L31 -> 0
B32: 1004055 | C32: ชิฟฟอน 4 ชิ้น บลูเบอร์รี่ล้วน | D32: ='เย็น '!D32+'เช้า '!D32+บ่าย!D32 -> 0 | E32: ='เย็น '!E32+'เช้า '!E32+บ่าย!E32 -> 0 | F32: ='เย็น '!F32+'เช้า '!F32+บ่าย!F32 -> 0 | G32: ='เย็น '!G32+'เช้า '!G32+บ่าย!G32 -> 0 | H32: ='เย็น '!H32+'เช้า '!H32+บ่าย!H32 -> 0 | I32: ='เย็น '!I32+'เช้า '!I32+บ่าย!I32 -> 0 | J32: ='เย็น '!J32+'เช้า '!J32+บ่าย!J32 -> 0 | K32: ='เย็น '!K32+'เช้า '!K32+บ่าย!K32 -> 0 | L32: =SUM(D32:K32) -> 0 | Q32: =(M32+N32+O32+P32)-L32 -> 0
B33: 1004055 | C33: ชิฟฟอน 4 ชิ้น ส้มล้วน | D33: ='เย็น '!D33+'เช้า '!D33+บ่าย!D33 -> 0 | E33: ='เย็น '!E33+'เช้า '!E33+บ่าย!E33 -> 0 | F33: ='เย็น '!F33+'เช้า '!F33+บ่าย!F33 -> 0 | G33: ='เย็น '!G33+'เช้า '!G33+บ่าย!G33 -> 0 | H33: ='เย็น '!H33+'เช้า '!H33+บ่าย!H33 -> 0 | I33: ='เย็น '!I33+'เช้า '!I33+บ่าย!I33 -> 0 | J33: ='เย็น '!J33+'เช้า '!J33+บ่าย!J33 -> 0 | K33: ='เย็น '!K33+'เช้า '!K33+บ่าย!K33 -> 0 | L33: =SUM(D33:K33) -> 0 | Q33: =(M33+N33+O33+P33)-L33 -> 0
B34: 1004055 | C34: ชิฟฟอน 4 ชิ้น เผือกล้วน | D34: ='เย็น '!D34+'เช้า '!D34+บ่าย!D34 -> 0 | E34: ='เย็น '!E34+'เช้า '!E34+บ่าย!E34 -> 0 | F34: ='เย็น '!F34+'เช้า '!F34+บ่าย!F34 -> 0 | G34: ='เย็น '!G34+'เช้า '!G34+บ่าย!G34 -> 0 | H34: ='เย็น '!H34+'เช้า '!H34+บ่าย!H34 -> 0 | I34: ='เย็น '!I34+'เช้า '!I34+บ่าย!I34 -> 0 | J34: ='เย็น '!J34+'เช้า '!J34+บ่าย!J34 -> 0 | K34: ='เย็น '!K34+'เช้า '!K34+บ่าย!K34 -> 0 | L34: =SUM(D34:K34) -> 0 | Q34: =(M34+N34+O34+P34)-L34 -> 0
B35: 1004055 | C35: ชิฟฟอน 4 ชิ้น สตอเบอรี่ล้วน | D35: ='เย็น '!D35+'เช้า '!D35+บ่าย!D35 -> 0 | E35: ='เย็น '!E35+'เช้า '!E35+บ่าย!E35 -> 0 | F35: ='เย็น '!F35+'เช้า '!F35+บ่าย!F35 -> 0 | G35: ='เย็น '!G35+'เช้า '!G35+บ่าย!G35 -> 0 | H35: ='เย็น '!H35+'เช้า '!H35+บ่าย!H35 -> 0 | I35: ='เย็น '!I35+'เช้า '!I35+บ่าย!I35 -> 0 | J35: ='เย็น '!J35+'เช้า '!J35+บ่าย!J35 -> 0 | K35: ='เย็น '!K35+'เช้า '!K35+บ่าย!K35 -> 0 | L35: =SUM(D35:K35) -> 0 | Q35: =(M35+N35+O35+P35)-L35 -> 0
B36: 1004055 | C36: ชิฟฟอน 4 ชิ้น กล้วยหอมล้วน | D36: ='เย็น '!D36+'เช้า '!D36+บ่าย!D36 -> 0 | E36: ='เย็น '!E36+'เช้า '!E36+บ่าย!E36 -> 0 | F36: ='เย็น '!F36+'เช้า '!F36+บ่าย!F36 -> 0 | G36: ='เย็น '!G36+'เช้า '!G36+บ่าย!G36 -> 0 | H36: ='เย็น '!H36+'เช้า '!H36+บ่าย!H36 -> 0 | I36: ='เย็น '!I36+'เช้า '!I36+บ่าย!I36 -> 0 | J36: ='เย็น '!J36+'เช้า '!J36+บ่าย!J36 -> 0 | K36: ='เย็น '!K36+'เช้า '!K36+บ่าย!K36 -> 0 | L36: =SUM(D36:K36) -> 0 | Q36: =(M36+N36+O36+P36)-L36 -> 0
B37: 1004055 | C37: ชิฟฟอน 4 ชิ้น ชาเขียวล้วน | D37: ='เย็น '!D37+'เช้า '!D37+บ่าย!D37 -> 0 | E37: ='เย็น '!E37+'เช้า '!E37+บ่าย!E37 -> 0 | F37: ='เย็น '!F37+'เช้า '!F37+บ่าย!F37 -> 0 | G37: ='เย็น '!G37+'เช้า '!G37+บ่าย!G37 -> 0 | H37: ='เย็น '!H37+'เช้า '!H37+บ่าย!H37 -> 0 | I37: ='เย็น '!I37+'เช้า '!I37+บ่าย!I37 -> 0 | J37: ='เย็น '!J37+'เช้า '!J37+บ่าย!J37 -> 0 | K37: ='เย็น '!K37+'เช้า '!K37+บ่าย!K37 -> 0 | L37: =SUM(D37:K37) -> 0 | Q37: =(M37+N37+O37+P37)-L37 -> 0
B38: 1004055 | C38: ชิฟฟอน 4 ชิ้น ชาไทยล้วน | D38: ='เย็น '!D38+'เช้า '!D38+บ่าย!D38 -> 0 | E38: ='เย็น '!E38+'เช้า '!E38+บ่าย!E38 -> 0 | F38: ='เย็น '!F38+'เช้า '!F38+บ่าย!F38 -> 0 | G38: ='เย็น '!G38+'เช้า '!G38+บ่าย!G38 -> 0 | H38: ='เย็น '!H38+'เช้า '!H38+บ่าย!H38 -> 0 | I38: ='เย็น '!I38+'เช้า '!I38+บ่าย!I38 -> 0 | J38: ='เย็น '!J38+'เช้า '!J38+บ่าย!J38 -> 0 | K38: ='เย็น '!K38+'เช้า '!K38+บ่าย!K38 -> 0 | L38: =SUM(D38:K38) -> 0 | Q38: =(M38+N38+O38+P38)-L38 -> 0
B39: 1004055 | C39: ชิฟฟอน 4 ชิ้น สับปะรดล้วน | D39: ='เย็น '!D39+'เช้า '!D39+บ่าย!D39 -> 0 | E39: ='เย็น '!E39+'เช้า '!E39+บ่าย!E39 -> 0 | F39: ='เย็น '!F39+'เช้า '!F39+บ่าย!F39 -> 0 | G39: ='เย็น '!G39+'เช้า '!G39+บ่าย!G39 -> 0 | H39: ='เย็น '!H39+'เช้า '!H39+บ่าย!H39 -> 0 | I39: ='เย็น '!I39+'เช้า '!I39+บ่าย!I39 -> 0 | J39: ='เย็น '!J39+'เช้า '!J39+บ่าย!J39 -> 0 | K39: ='เย็น '!K39+'เช้า '!K39+บ่าย!K39 -> 0 | L39: =SUM(D39:K39) -> 0 | Q39: =(M39+N39+O39+P39)-L39 -> 0
B40: 1111057 | C40: ชิฟฟอนแยกชิ้น กาแฟ | D40: ='เย็น '!D40+'เช้า '!D40+บ่าย!D40 -> 0 | E40: ='เย็น '!E40+'เช้า '!E40+บ่าย!E40 -> 0 | F40: ='เย็น '!F40+'เช้า '!F40+บ่าย!F40 -> 0 | G40: ='เย็น '!G40+'เช้า '!G40+บ่าย!G40 -> 1 | H40: ='เย็น '!H40+'เช้า '!H40+บ่าย!H40 -> 6 | I40: ='เย็น '!I40+'เช้า '!I40+บ่าย!I40 -> 0 | J40: ='เย็น '!J40+'เช้า '!J40+บ่าย!J40 -> 0 | K40: ='เย็น '!K40+'เช้า '!K40+บ่าย!K40 -> 0 | L40: =SUM(D40:K40) -> 7 | N40: 229 | Q40: =(M40+N40+O40+P40)-L40 -> 222
B41: 1111058 | C41: ชิฟฟอนแยกชิ้น ชาเขียว | D41: ='เย็น '!D41+'เช้า '!D41+บ่าย!D41 -> 0 | E41: ='เย็น '!E41+'เช้า '!E41+บ่าย!E41 -> 0 | F41: ='เย็น '!F41+'เช้า '!F41+บ่าย!F41 -> 0 | G41: ='เย็น '!G41+'เช้า '!G41+บ่าย!G41 -> 1 | H41: ='เย็น '!H41+'เช้า '!H41+บ่าย!H41 -> 6 | I41: ='เย็น '!I41+'เช้า '!I41+บ่าย!I41 -> 0 | J41: ='เย็น '!J41+'เช้า '!J41+บ่าย!J41 -> 0 | K41: ='เย็น '!K41+'เช้า '!K41+บ่าย!K41 -> 0 | L41: =SUM(D41:K41) -> 7 | Q41: =(M41+N41+O41+P41)-L41 -> -7
B42: 1111059 | C42: ชิฟฟอนแยกชิ้น ใบเตย | D42: ='เย็น '!D42+'เช้า '!D42+บ่าย!D42 -> 0 | E42: ='เย็น '!E42+'เช้า '!E42+บ่าย!E42 -> 0 | F42: ='เย็น '!F42+'เช้า '!F42+บ่าย!F42 -> 0 | G42: ='เย็น '!G42+'เช้า '!G42+บ่าย!G42 -> 1 | H42: ='เย็น '!H42+'เช้า '!H42+บ่าย!H42 -> 15 | I42: ='เย็น '!I42+'เช้า '!I42+บ่าย!I42 -> 0 | J42: ='เย็น '!J42+'เช้า '!J42+บ่าย!J42 -> 0 | K42: ='เย็น '!K42+'เช้า '!K42+บ่าย!K42 -> 0 | L42: =SUM(D42:K42) -> 16 | Q42: =(M42+N42+O42+P42)-L42 -> -16
B43: 1111060 | C43: ชิฟฟอนแยกชิ้น กล้วยหอม | D43: ='เย็น '!D43+'เช้า '!D43+บ่าย!D43 -> 0 | E43: ='เย็น '!E43+'เช้า '!E43+บ่าย!E43 -> 0 | F43: ='เย็น '!F43+'เช้า '!F43+บ่าย!F43 -> 0 | G43: ='เย็น '!G43+'เช้า '!G43+บ่าย!G43 -> 1 | H43: ='เย็น '!H43+'เช้า '!H43+บ่าย!H43 -> 1 | I43: ='เย็น '!I43+'เช้า '!I43+บ่าย!I43 -> 0 | J43: ='เย็น '!J43+'เช้า '!J43+บ่าย!J43 -> 0 | K43: ='เย็น '!K43+'เช้า '!K43+บ่าย!K43 -> 0 | L43: =SUM(D43:K43) -> 2 | Q43: =(M43+N43+O43+P43)-L43 -> -2
B44: 1111061 | C44: ชิฟฟอนแยกชิ้น ชาไทย | D44: ='เย็น '!D44+'เช้า '!D44+บ่าย!D44 -> 0 | E44: ='เย็น '!E44+'เช้า '!E44+บ่าย!E44 -> 0 | F44: ='เย็น '!F44+'เช้า '!F44+บ่าย!F44 -> 0 | G44: ='เย็น '!G44+'เช้า '!G44+บ่าย!G44 -> 1 | H44: ='เย็น '!H44+'เช้า '!H44+บ่าย!H44 -> 4 | I44: ='เย็น '!I44+'เช้า '!I44+บ่าย!I44 -> 0 | J44: ='เย็น '!J44+'เช้า '!J44+บ่าย!J44 -> 0 | K44: ='เย็น '!K44+'เช้า '!K44+บ่าย!K44 -> 0 | L44: =SUM(D44:K44) -> 5 | N44: 40 | Q44: =(M44+N44+O44+P44)-L44 -> 35
...
