Workbook

Sheet สรุป
A2: สรุป บูธ ปตท.ราชบุรี วันที่ 1-30/06/2567
A3: ลำดับ | B3: รายการ | C3: ยกมา | D3: รับ | E3: รวม | F3: เปลี่ยน/ | G3: คงเหลือ | H3: รายการขาย | K3: หมายเหตุ | L3: วันที่ | M3: ยอดเงิน | N3: ส่วนลด | O3: สแกนใช้สิทธิ์ | P3: ค่าโอนเงิน | Q3: ค่าใช้จ่ายอื่นๆ | R3: โอนหน้าร้าน | S3: รับสุทธิ | T3: ยอดโอนเงิน | U3: โอนเกิน/โอนขาด
F4: คืน/เสีย | H4: จำนวน | I4: @ | J4: เป็นเงิน
A5: 1 | B5: ชิฟฟ่อน (ล) | C5: =+'1'!C5 -> 31 | D5: =+'1'!D5+'2'!D5+'3'!D5+'4'!D5+'5'!D5+'6'!D5+'7'!D5+'8'!D5+'9'!D29+'10'!D5+'11'!D5+'12'!D5+'13'!D5+'14'!D5+'15'!D5+'16'!D5+'17'!D5+'18'!D5+'19'!D5+'20'!D5+'21'!D5+'22'!D5+'23'!D5+'24'!D5+'25'!D5+'26'!D5+'27'!D5+'28'!D5+'29'!D5+'30'!D5+'31'!D5 -> 145 | E5: =+C5+D5 -> 176 | F5: =+'1'!F5+'2'!F5+'3'!F5+'4'!F5+'5'!F5+'6'!F5+'7'!F5+'8'!F5+'9'!F5+'10'!F5+'11'!F5+'12'!F5+'13'!F5+'14'!F5+'15'!F5+'16'!F5+'17'!F5+'18'!F5+'19'!F5+'20'!F5+'21'!F5+'22'!F5+'23'!F5+'24'!F5+'25'!F5+'26'!F5+'27'!F5+'28'!F5+'29'!F5+'30'!F5+'31'!F5 -> 0 | G5: =E5-F5-H5 -> 19 | H5: =+'1'!H5+'2'!H5+'3'!H5+'4'!H5+'5'!H5+'6'!H5+'7'!H5+'8'!H5+'9'!H5+'10'!H5+'11'!H5+'12'!H5+'13'!H5+'14'!H5+'15'!H5+'16'!H5+'17'!H5+'18'!H5+'19'!H5+'20'!H5+'21'!H5+'22'!H5+'23'!H5+'24'!H5+'25'!H5+'26'!H5+'27'!H5+'28'!H5+'29'!H5+'30'!H5+'31'!H5 -> 157 | I5: 50 | J5: =+'1'!J5+'2'!J5+'3'!J5+'4'!J5+'5'!J5+'6'!J5+'7'!J5+'8'!J5+'9'!J5+'10'!J5+'11'!J5+'12'!J5+'13'!J5+'14'!J5+'15'!J5+'16'!J5+'17'!J5+'18'!J5+'19'!J5+'20'!J5+'21'!J5+'22'!J5+'23'!J5+'24'!J5+'25'!J5+'26'!J5+'27'!J5+'28'!J5+'29'!J5+'30'!J5+'31'!J5 -> 7850 | L5: 1 | M5: =+'1'!K219 -> 5275 | N5: =+'1'!K224 -> 165 | O5: =+'1'!K222 -> 0 | P5: =+'1'!K220 -> 15 | Q5: =+'1'!K223 -> 0 | R5: =+'1'!K221 -> 1770 | S5: =+M5-N5-P5-R5-Q5 -> 3325 | T5: =+'1'!K226 -> 3325 | U5: =+T5-S5 -> 0
A6: 2 | B6: ชิฟฟ่อน (ญ) | C6: =+'1'!C6 -> 61 | D6: =+'1'!D6+'2'!D6+'3'!D6+'4'!D6+'5'!D6+'6'!D6+'7'!D6+'8'!D6+'9'!D30+'10'!D6+'11'!D6+'12'!D6+'13'!D6+'14'!D6+'15'!D6+'16'!D6+'17'!D6+'18'!D6+'19'!D6+'20'!D6+'21'!D6+'22'!D6+'23'!D6+'24'!D6+'25'!D6+'26'!D6+'27'!D6+'28'!D6+'29'!D6+'30'!D6+'31'!D6 -> 190 | E6: =+C6+D6 -> 251 | F6: =+'1'!F6+'2'!F6+'3'!F6+'4'!F6+'5'!F6+'6'!F6+'7'!F6+'8'!F6+'9'!F6+'10'!F6+'11'!F6+'12'!F6+'13'!F6+'14'!F6+'15'!F6+'16'!F6+'17'!F6+'18'!F6+'19'!F6+'20'!F6+'21'!F6+'22'!F6+'23'!F6+'24'!F6+'25'!F6+'26'!F6+'27'!F6+'28'!F6+'29'!F6+'30'!F6+'31'!F6 -> 0 | G6: =E6-F6-H6 -> 37 | H6: =+'1'!H6+'2'!H6+'3'!H6+'4'!H6+'5'!H6+'6'!H6+'7'!H6+'8'!H6+'9'!H6+'10'!H6+'11'!H6+'12'!H6+'13'!H6+'14'!H6+'15'!H6+'16'!H6+'17'!H6+'18'!H6+'19'!H6+'20'!H6+'21'!H6+'22'!H6+'23'!H6+'24'!H6+'25'!H6+'26'!H6+'27'!H6+'28'!H6+'29'!H6+'30'!H6+'31'!H6 -> 214 | I6: 100 | J6: =+'1'!J6+'2'!J6+'3'!J6+'4'!J6+'5'!J6+'6'!J6+'7'!J6+'8'!J6+'9'!J6+'10'!J6+'11'!J6+'12'!J6+'13'!J6+'14'!J6+'15'!J6+'16'!J6+'17'!J6+'18'!J6+'19'!J6+'20'!J6+'21'!J6+'22'!J6+'23'!J6+'24'!J6+'25'!J6+'26'!J6+'27'!J6+'28'!J6+'29'!J6+'30'!J6+'31'!J6 -> 21400 | L6: 2 | M6: =+'2'!K219 -> 6065 | N6: =+'2'!K224 -> 650 | O6: =+'2'!K222 -> 0 | P6: =+'2'!K220 -> 15 | Q6: =+'2'!K223 -> 0 | R6: =+'2'!K221 -> 2080 | S6: =+M6-N6-P6-R6-Q6 -> 3320 | T6: =+'2'!K226 -> 3320 | U6: =+T6-S6 -> 0
A7: 3 | B7: ชิฟฟ่อน (ล) กาแฟ | C7: =+'1'!C7 -> 0 | D7: =+'1'!D7+'2'!D7+'3'!D7+'4'!D7+'5'!D7+'6'!D7+'7'!D7+'8'!D7+'9'!D31+'10'!D7+'11'!D7+'12'!D7+'13'!D7+'14'!D7+'15'!D7+'16'!D7+'17'!D7+'18'!D7+'19'!D7+'20'!D7+'21'!D7+'22'!D7+'23'!D7+'24'!D7+'25'!D7+'26'!D7+'27'!D7+'28'!D7+'29'!D7+'30'!D7+'31'!D7 -> 0 | E7: =+C7+D7 -> 0 | F7: =+'1'!F7+'2'!F7+'3'!F7+'4'!F7+'5'!F7+'6'!F7+'7'!F7+'8'!F7+'9'!F7+'10'!F7+'11'!F7+'12'!F7+'13'!F7+'14'!F7+'15'!F7+'16'!F7+'17'!F7+'18'!F7+'19'!F7+'20'!F7+'21'!F7+'22'!F7+'23'!F7+'24'!F7+'25'!F7+'26'!F7+'27'!F7+'28'!F7+'29'!F7+'30'!F7+'31'!F7 -> 0 | G7: =E7-F7-H7 -> 0 | H7: =+'1'!H7+'2'!H7+'3'!H7+'4'!H7+'5'!H7+'6'!H7+'7'!H7+'8'!H7+'9'!H7+'10'!H7+'11'!H7+'12'!H7+'13'!H7+'14'!H7+'15'!H7+'16'!H7+'17'!H7+'18'!H7+'19'!H7+'20'!H7+'21'!H7+'22'!H7+'23'!H7+'24'!H7+'25'!H7+'26'!H7+'27'!H7+'28'!H7+'29'!H7+'30'!H7+'31'!H7 -> 0 | I7: 50 | J7: =+'1'!J7+'2'!J7+'3'!J7+'4'!J7+'5'!J7+'6'!J7+'7'!J7+'8'!J7+'9'!J7+'10'!J7+'11'!J7+'12'!J7+'13'!J7+'14'!J7+'15'!J7+'16'!J7+'17'!J7+'18'!J7+'19'!J7+'20'!J7+'21'!J7+'22'!J7+'23'!J7+'24'!J7+'25'!J7+'26'!J7+'27'!J7+'28'!J7+'29'!J7+'30'!J7+'31'!J7 -> 0 | L7: 3 | M7: =+'3'!K219 -> 5620 | N7: =+'3'!K224 -> 440 | O7: =+'3'!K222 -> 0 | P7: =+'3'!K220 -> 15 | Q7: =+'3'!K223 -> 0 | R7: =+'3'!K221 -> 505 | S7: =+M7-N7-P7-R7-Q7 -> 4660 | T7: =+'3'!K226 -> 4660 | U7: =+T7-S7 -> 0
A8: 4 | B8: ชิฟฟ่อน (ญ) กาแฟ | C8: =+'1'!C8 -> 0 | D8: =+'1'!D8+'2'!D8+'3'!D8+'4'!D8+'5'!D8+'6'!D8+'7'!D8+'8'!D8+'9'!D32+'10'!D8+'11'!D8+'12'!D8+'13'!D8+'14'!D8+'15'!D8+'16'!D8+'17'!D8+'18'!D8+'19'!D8+'20'!D8+'21'!D8+'22'!D8+'23'!D8+'24'!D8+'25'!D8+'26'!D8+'27'!D8+'28'!D8+'29'!D8+'30'!D8+'31'!D8 -> 4 | E8: =+C8+D8 -> 4 | F8: =+'1'!F8+'2'!F8+'3'!F8+'4'!F8+'5'!F8+'6'!F8+'7'!F8+'8'!F8+'9'!F8+'10'!F8+'11'!F8+'12'!F8+'13'!F8+'14'!F8+'15'!F8+'16'!F8+'17'!F8+'18'!F8+'19'!F8+'20'!F8+'21'!F8+'22'!F8+'23'!F8+'24'!F8+'25'!F8+'26'!F8+'27'!F8+'28'!F8+'29'!F8+'30'!F8+'31'!F8 -> 0 | G8: =E8-F8-H8 -> 2 | H8: =+'1'!H8+'2'!H8+'3'!H8+'4'!H8+'5'!H8+'6'!H8+'7'!H8+'8'!H8+'9'!H8+'10'!H8+'11'!H8+'12'!H8+'13'!H8+'14'!H8+'15'!H8+'16'!H8+'17'!H8+'18'!H8+'19'!H8+'20'!H8+'21'!H8+'22'!H8+'23'!H8+'24'!H8+'25'!H8+'26'!H8+'27'!H8+'28'!H8+'29'!H8+'30'!H8+'31'!H8 -> 2 | I8: 100 | J8: =+'1'!J8+'2'!J8+'3'!J8+'4'!J8+'5'!J8+'6'!J8+'7'!J8+'8'!J8+'9'!J8+'10'!J8+'11'!J8+'12'!J8+'13'!J8+'14'!J8+'15'!J8+'16'!J8+'17'!J8+'18'!J8+'19'!J8+'20'!J8+'21'!J8+'22'!J8+'23'!J8+'24'!J8+'25'!J8+'26'!J8+'27'!J8+'28'!J8+'29'!J8+'30'!J8+'31'!J8 -> 200 | L8: 4 | M8: =+'4'!K219 -> 4705 | N8: =+'4'!K224 -> 250 | O8: =+'4'!K222 -> 0 | P8: =+'4'!K220 -> 15 | Q8: =+'4'!K223 -> 0 | R8: =+'4'!K221 -> 660 | S8: =+M8-N8-P8-R8-Q8 -> 3780 | T8: =+'4'!K226 -> 3780 | U8: =+T8-S8 -> 0
A9: 5 | B9: ชิฟฟ่อนเค้ก 1 ชิ้น | C9: =+'1'!C9 -> 0 | D9: =+'1'!D9+'2'!D9+'3'!D9+'4'!D9+'5'!D9+'6'!D9+'7'!D9+'8'!D9+'9'!D33+'10'!D9+'11'!D9+'12'!D9+'13'!D9+'14'!D9+'15'!D9+'16'!D9+'17'!D9+'18'!D9+'19'!D9+'20'!D9+'21'!D9+'22'!D9+'23'!D9+'24'!D9+'25'!D9+'26'!D9+'27'!D9+'28'!D9+'29'!D9+'30'!D9+'31'!D9 -> 0 | E9: =+C9+D9 -> 0 | F9: =+'1'!F9+'2'!F9+'3'!F9+'4'!F9+'5'!F9+'6'!F9+'7'!F9+'8'!F9+'9'!F9+'10'!F9+'11'!F9+'12'!F9+'13'!F9+'14'!F9+'15'!F9+'16'!F9+'17'!F9+'18'!F9+'19'!F9+'20'!F9+'21'!F9+'22'!F9+'23'!F9+'24'!F9+'25'!F9+'26'!F9+'27'!F9+'28'!F9+'29'!F9+'30'!F9+'31'!F9 -> 0 | G9: =E9-F9-H9 -> 0 | H9: =+'1'!H9+'2'!H9+'3'!H9+'4'!H9+'5'!H9+'6'!H9+'7'!H9+'8'!H9+'9'!H9+'10'!H9+'11'!H9+'12'!H9+'13'!H9+'14'!H9+'15'!H9+'16'!H9+'17'!H9+'18'!H9+'19'!H9+'20'!H9+'21'!H9+'22'!H9+'23'!H9+'24'!H9+'25'!H9+'26'!H9+'27'!H9+'28'!H9+'29'!H9+'30'!H9+'31'!H9 -> 0 | I9: 10 | J9: =+'1'!J9+'2'!J9+'3'!J9+'4'!J9+'5'!J9+'6'!J9+'7'!J9+'8'!J9+'9'!J9+'10'!J9+'11'!J9+'12'!J9+'13'!J9+'14'!J9+'15'!J9+'16'!J9+'17'!J9+'18'!J9+'19'!J9+'20'!J9+'21'!J9+'22'!J9+'23'!J9+'24'!J9+'25'!J9+'26'!J9+'27'!J9+'28'!J9+'29'!J9+'30'!J9+'31'!J9 -> 0 | L9: 5 | M9: =+'5'!K219 -> 4210 | N9: =+'5'!K224 -> 175 | O9: =+'5'!K222 -> 0 | P9: =+'5'!K220 -> 15 | Q9: =+'5'!K223 -> 0 | R9: =+'5'!K221 -> 1455 | S9: =+M9-N9-P9-R9-Q9 -> 2565 | T9: =+'5'!K226 -> 2565 | U9: =+T9-S9 -> 0
A10: 6 | B10: ชิฟฟ่อนเค้กสอดไส้แยม 1 ชิ้น | C10: =+'1'!C10 -> 0 | D10: =+'1'!D10+'2'!D10+'3'!D10+'4'!D10+'5'!D10+'6'!D10+'7'!D10+'8'!D10+'9'!D34+'10'!D10+'11'!D10+'12'!D10+'13'!D10+'14'!D10+'15'!D10+'16'!D10+'17'!D10+'18'!D10+'19'!D10+'20'!D10+'21'!D10+'22'!D10+'23'!D10+'24'!D10+'25'!D10+'26'!D10+'27'!D10+'28'!D10+'29'!D10+'30'!D10+'31'!D10 -> 0 | E10: =+C10+D10 -> 0 | F10: =+'1'!F10+'2'!F10+'3'!F10+'4'!F10+'5'!F10+'6'!F10+'7'!F10+'8'!F10+'9'!F10+'10'!F10+'11'!F10+'12'!F10+'13'!F10+'14'!F10+'15'!F10+'16'!F10+'17'!F10+'18'!F10+'19'!F10+'20'!F10+'21'!F10+'22'!F10+'23'!F10+'24'!F10+'25'!F10+'26'!F10+'27'!F10+'28'!F10+'29'!F10+'30'!F10+'31'!F10 -> 0 | G10: =E10-F10-H10 -> 0 | H10: =+'1'!H10+'2'!H10+'3'!H10+'4'!H10+'5'!H10+'6'!H10+'7'!H10+'8'!H10+'9'!H10+'10'!H10+'11'!H10+'12'!H10+'13'!H10+'14'!H10+'15'!H10+'16'!H10+'17'!H10+'18'!H10+'19'!H10+'20'!H10+'21'!H10+'22'!H10+'23'!H10+'24'!H10+'25'!H10+'26'!H10+'27'!H10+'28'!H10+'29'!H10+'30'!H10+'31'!H10 -> 0 | I10: 12 | J10: =+'1'!J10+'2'!J10+'3'!J10+'4'!J10+'5'!J10+'6'!J10+'7'!J10+'8'!J10+'9'!J10+'10'!J10+'11'!J10+'12'!J10+'13'!J10+'14'!J10+'15'!J10+'16'!J10+'17'!J10+'18'!J10+'19'!J10+'20'!J10+'21'!J10+'22'!J10+'23'!J10+'24'!J10+'25'!J10+'26'!J10+'27'!J10+'28'!J10+'29'!J10+'30'!J10+'31'!J10 -> 0 | L10: 6 | M10: =+'6'!K219 -> 2055 | N10: =+'6'!K224 -> 40 | O10: =+'6'!K222 -> 0 | P10: =+'6'!K220 -> 15 | Q10: =+'6'!K223 -> 0 | R10: =+'6'!K221 -> 480 | S10: =+M10-N10-P10-R10-Q10 -> 1520 | T10: =+'6'!K226 -> 1520 | U10: =+T10-S10 -> 0
A11: 7 | B11: ชิฟฟ่อน สอดไส้ (ล) 2 ชิ้น ครีมมะพร้าว | C11: =+'1'!C11 -> 0 | D11: =+'1'!D11+'2'!D11+'3'!D11+'4'!D11+'5'!D11+'6'!D11+'7'!D11+'8'!D11+'9'!D35+'10'!D11+'11'!D11+'12'!D11+'13'!D11+'14'!D11+'15'!D11+'16'!D11+'17'!D11+'18'!D11+'19'!D11+'20'!D11+'21'!D11+'22'!D11+'23'!D11+'24'!D11+'25'!D11+'26'!D11+'27'!D11+'28'!D11+'29'!D11+'30'!D11+'31'!D11 -> 0 | E11: =+C11+D11 -> 0 | F11: =+'1'!F11+'2'!F11+'3'!F11+'4'!F11+'5'!F11+'6'!F11+'7'!F11+'8'!F11+'9'!F11+'10'!F11+'11'!F11+'12'!F11+'13'!F11+'14'!F11+'15'!F11+'16'!F11+'17'!F11+'18'!F11+'19'!F11+'20'!F11+'21'!F11+'22'!F11+'23'!F11+'24'!F11+'25'!F11+'26'!F11+'27'!F11+'28'!F11+'29'!F11+'30'!F11+'31'!F11 -> 0 | G11: =E11-F11-H11 -> 0 | H11: =+'1'!H11+'2'!H11+'3'!H11+'4'!H11+'5'!H11+'6'!H11+'7'!H11+'8'!H11+'9'!H11+'10'!H11+'11'!H11+'12'!H11+'13'!H11+'14'!H11+'15'!H11+'16'!H11+'17'!H11+'18'!H11+'19'!H11+'20'!H11+'21'!H11+'22'!H11+'23'!H11+'24'!H11+'25'!H11+'26'!H11+'27'!H11+'28'!H11+'29'!H11+'30'!H11+'31'!H11 -> 0 | I11: 40 | J11: =+'1'!J11+'2'!J11+'3'!J11+'4'!J11+'5'!J11+'6'!J11+'7'!J11+'8'!J11+'9'!J11+'10'!J11+'11'!J11+'12'!J11+'13'!J11+'14'!J11+'15'!J11+'16'!J11+'17'!J11+'18'!J11+'19'!J11+'20'!J11+'21'!J11+'22'!J11+'23'!J11+'24'!J11+'25'!J11+'26'!J11+'27'!J11+'28'!J11+'29'!J11+'30'!J11+'31'!J11 -> 0 | L11: 7 | M11: =+'7'!K219 -> 3770 | N11: =+'7'!K224 -> 175 | O11: =+'7'!K222 -> 0 | P11: =+'7'!K220 -> 15 | Q11: =+'7'!K223 -> 0 | R11: =+'7'!K221 -> 1450 | S11: =+M11-N11-P11-R11-Q11 -> 2130 | T11: =+'7'!K226 -> 2130 | U11: =+T11-S11 -> 0
A12: 8 | B12: ชิฟฟ่อน สอดไส้ (ล) 3 ชิ้น รวมรส | C12: =+'1'!C12 -> 7 | D12: =+'1'!D12+'2'!D12+'3'!D12+'4'!D12+'5'!D12+'6'!D12+'7'!D12+'8'!D12+'9'!D36+'10'!D12+'11'!D12+'12'!D12+'13'!D12+'14'!D12+'15'!D12+'16'!D12+'17'!D12+'18'!D12+'19'!D12+'20'!D12+'21'!D12+'22'!D12+'23'!D12+'24'!D12+'25'!D12+'26'!D12+'27'!D12+'28'!D12+'29'!D12+'30'!D12+'31'!D12 -> 35 | E12: =+C12+D12 -> 42 | F12: =+'1'!F12+'2'!F12+'3'!F12+'4'!F12+'5'!F12+'6'!F12+'7'!F12+'8'!F12+'9'!F12+'10'!F12+'11'!F12+'12'!F12+'13'!F12+'14'!F12+'15'!F12+'16'!F12+'17'!F12+'18'!F12+'19'!F12+'20'!F12+'21'!F12+'22'!F12+'23'!F12+'24'!F12+'25'!F12+'26'!F12+'27'!F12+'28'!F12+'29'!F12+'30'!F12+'31'!F12 -> 2 | G12: =E12-F12-H12 -> 0 | H12: =+'1'!H12+'2'!H12+'3'!H12+'4'!H12+'5'!H12+'6'!H12+'7'!H12+'8'!H12+'9'!H12+'10'!H12+'11'!H12+'12'!H12+'13'!H12+'14'!H12+'15'!H12+'16'!H12+'17'!H12+'18'!H12+'19'!H12+'20'!H12+'21'!H12+'22'!H12+'23'!H12+'24'!H12+'25'!H12+'26'!H12+'27'!H12+'28'!H12+'29'!H12+'30'!H12+'31'!H12 -> 40 | I12: 50 | J12: =+'1'!J12+'2'!J12+'3'!J12+'4'!J12+'5'!J12+'6'!J12+'7'!J12+'8'!J12+'9'!J12+'10'!J12+'11'!J12+'12'!J12+'13'!J12+'14'!J12+'15'!J12+'16'!J12+'17'!J12+'18'!J12+'19'!J12+'20'!J12+'21'!J12+'22'!J12+'23'!J12+'24'!J12+'25'!J12+'26'!J12+'27'!J12+'28'!J12+'29'!J12+'30'!J12+'31'!J12 -> 2000 | L12: 8 | M12: =+'8'!K219 -> 5045 | N12: =+'8'!K224 -> 130 | O12: =+'8'!K222 -> 0 | P12: =+'8'!K220 -> 15 | Q12: =+'8'!K223 -> 0 | R12: =+'8'!K221 -> 2195 | S12: =+M12-N12-P12-R12-Q12 -> 2705 | T12: =+'8'!K226 -> 2705 | U12: =+T12-S12 -> 0
A13: 9 | B13: ชิฟฟ่อน สอดไส้ (ล) 3 ชิ้น เมล่อน | C13: =+'1'!C13 -> 0 | D13: =+'1'!D13+'2'!D13+'3'!D13+'4'!D13+'5'!D13+'6'!D13+'7'!D13+'8'!D13+'9'!D37+'10'!D13+'11'!D13+'12'!D13+'13'!D13+'14'!D13+'15'!D13+'16'!D13+'17'!D13+'18'!D13+'19'!D13+'20'!D13+'21'!D13+'22'!D13+'23'!D13+'24'!D13+'25'!D13+'26'!D13+'27'!D13+'28'!D13+'29'!D13+'30'!D13+'31'!D13 -> 0 | E13: =+C13+D13 -> 0 | F13: =+'1'!F13+'2'!F13+'3'!F13+'4'!F13+'5'!F13+'6'!F13+'7'!F13+'8'!F13+'9'!F13+'10'!F13+'11'!F13+'12'!F13+'13'!F13+'14'!F13+'15'!F13+'16'!F13+'17'!F13+'18'!F13+'19'!F13+'20'!F13+'21'!F13+'22'!F13+'23'!F13+'24'!F13+'25'!F13+'26'!F13+'27'!F13+'28'!F13+'29'!F13+'30'!F13+'31'!F13 -> 0 | G13: =E13-F13-H13 -> 0 | H13: =+'1'!H13+'2'!H13+'3'!H13+'4'!H13+'5'!H13+'6'!H13+'7'!H13+'8'!H13+'9'!H13+'10'!H13+'11'!H13+'12'!H13+'13'!H13+'14'!H13+'15'!H13+'16'!H13+'17'!H13+'18'!H13+'19'!H13+'20'!H13+'21'!H13+'22'!H13+'23'!H13+'24'!H13+'25'!H13+'26'!H13+'27'!H13+'28'!H13+'29'!H13+'30'!H13+'31'!H13 -> 0 | I13: 55 | J13: =+'1'!J13+'2'!J13+'3'!J13+'4'!J13+'5'!J13+'6'!J13+'7'!J13+'8'!J13+'9'!J13+'10'!J13+'11'!J13+'12'!J13+'13'!J13+'14'!J13+'15'!J13+'16'!J13+'17'!J13+'18'!J13+'19'!J13+'20'!J13+'21'!J13+'22'!J13+'23'!J13+'24'!J13+'25'!J13+'26'!J13+'27'!J13+'28'!J13+'29'!J13+'30'!J13+'31'!J13 -> 0 | L13: 9 | M13: =+'9'!K219 -> 3740 | N13: =+'9'!K224 -> 240 | O13: =+'9'!K222 -> 0 | P13: =+'9'!K220 -> 15 | Q13: =+'9'!K223 -> 0 | R13: =+'9'!K221 -> 960 | S13: =+M13-N13-P13-R13-Q13 -> 2525 | T13: =+'9'!K226 -> 2345 | U13: =+T13-S13 -> -180
A14: 10 | B14: ชิฟฟ่อน สอดไส้ (ล) 4 ชิ้น ครีมมะพร้าว | C14: =+'1'!C14 -> 0 | D14: =+'1'!D14+'2'!D14+'3'!D14+'4'!D14+'5'!D14+'6'!D14+'7'!D14+'8'!D14+'9'!D38+'10'!D14+'11'!D14+'12'!D14+'13'!D14+'14'!D14+'15'!D14+'16'!D14+'17'!D14+'18'!D14+'19'!D14+'20'!D14+'21'!D14+'22'!D14+'23'!D14+'24'!D14+'25'!D14+'26'!D14+'27'!D14+'28'!D14+'29'!D14+'30'!D14+'31'!D14 -> 26 | E14: =+C14+D14 -> 26 | F14: =+'1'!F14+'2'!F14+'3'!F14+'4'!F14+'5'!F14+'6'!F14+'7'!F14+'8'!F14+'9'!F14+'10'!F14+'11'!F14+'12'!F14+'13'!F14+'14'!F14+'15'!F14+'16'!F14+'17'!F14+'18'!F14+'19'!F14+'20'!F14+'21'!F14+'22'!F14+'23'!F14+'24'!F14+'25'!F14+'26'!F14+'27'!F14+'28'!F14+'29'!F14+'30'!F14+'31'!F14 -> 0 | G14: =E14-F14-H14 -> 0 | H14: =+'1'!H14+'2'!H14+'3'!H14+'4'!H14+'5'!H14+'6'!H14+'7'!H14+'8'!H14+'9'!H14+'10'!H14+'11'!H14+'12'!H14+'13'!H14+'14'!H14+'15'!H14+'16'!H14+'17'!H14+'18'!H14+'19'!H14+'20'!H14+'21'!H14+'22'!H14+'23'!H14+'24'!H14+'25'!H14+'26'!H14+'27'!H14+'28'!H14+'29'!H14+'30'!H14+'31'!H14 -> 26 | I14: 65 | J14: =+'1'!J14+'2'!J14+'3'!J14+'4'!J14+'5'!J14+'6'!J14+'7'!J14+'8'!J14+'9'!J14+'10'!J14+'11'!J14+'12'!J14+'13'!J14+'14'!J14+'15'!J14+'16'!J14+'17'!J14+'18'!J14+'19'!J14+'20'!J14+'21'!J14+'22'!J14+'23'!J14+'24'!J14+'25'!J14+'26'!J14+'27'!J14+'28'!J14+'29'!J14+'30'!J14+'31'!J14 -> 1690 | L14: 10 | M14: =+'10'!K219 -> 4305 | N14: =+'10'!K224 -> 230 | O14: =+'10'!K222 -> 0 | P14: =+'10'!K220 -> 15 | Q14: =+'10'!K223 -> 0 | R14: =+'10'!K221 -> 1555 | S14: =+M14-N14-P14-R14-Q14 -> 2505 | T14: =+'10'!K226 -> 2685 | U14: =+T14-S14 -> 180
A15: 11 | B15: ชิฟฟ่อน สอดไส้ (ล) 3 ชิ้น แยมส้ม | C15: =+'1'!C15 -> 0 | D15: =+'1'!D15+'2'!D15+'3'!D15+'4'!D15+'5'!D15+'6'!D15+'7'!D15+'8'!D15+'9'!D39+'10'!D15+'11'!D15+'12'!D15+'13'!D15+'14'!D15+'15'!D15+'16'!D15+'17'!D15+'18'!D15+'19'!D15+'20'!D15+'21'!D15+'22'!D15+'23'!D15+'24'!D15+'25'!D15+'26'!D15+'27'!D15+'28'!D15+'29'!D15+'30'!D15+'31'!D15 -> 10 | E15: =+C15+D15 -> 10 | F15: =+'1'!F15+'2'!F15+'3'!F15+'4'!F15+'5'!F15+'6'!F15+'7'!F15+'8'!F15+'9'!F15+'10'!F15+'11'!F15+'12'!F15+'13'!F15+'14'!F15+'15'!F15+'16'!F15+'17'!F15+'18'!F15+'19'!F15+'20'!F15+'21'!F15+'22'!F15+'23'!F15+'24'!F15+'25'!F15+'26'!F15+'27'!F15+'28'!F15+'29'!F15+'30'!F15+'31'!F15 -> 0 | G15: =E15-F15-H15 -> 2 | H15: =+'1'!H15+'2'!H15+'3'!H15+'4'!H15+'5'!H15+'6'!H15+'7'!H15+'8'!H15+'9'!H15+'10'!H15+'11'!H15+'12'!H15+'13'!H15+'14'!H15+'15'!H15+'16'!H15+'17'!H15+'18'!H15+'19'!H15+'20'!H15+'21'!H15+'22'!H15+'23'!H15+'24'!H15+'25'!H15+'26'!H15+'27'!H15+'28'!H15+'29'!H15+'30'!H15+'31'!H15 -> 8 | I15: 50 | J15: =+'1'!J15+'2'!J15+'3'!J15+'4'!J15+'5'!J15+'6'!J15+'7'!J15+'8'!J15+'9'!J15+'10'!J15+'11'!J15+'12'!J15+'13'!J15+'14'!J15+'15'!J15+'16'!J15+'17'!J15+'18'!J15+'19'!J15+'20'!J15+'21'!J15+'22'!J15+'23'!J15+'24'!J15+'25'!J15+'26'!J15+'27'!J15+'28'!J15+'29'!J15+'30'!J15+'31'!J15 -> 400 | L15: 11 | M15: =+'11'!K219 -> 3510 | N15: =+'11'!K224 -> 240 | O15: =+'11'!K222 -> 0 | P15: =+'11'!K220 -> 15 | Q15: =+'11'!K223 -> 0 | R15: =+'11'!K221 -> 1250 | S15: =+M15-N15-P15-R15-Q15 -> 2005 | T15: =+'11'!K226 -> 2015 | U15: =+T15-S15 -> 10
A16: 12 | B16: ชิฟฟ่อน สอดไส้ (ล) 3 ชิ้น บลูเบอรี่ | C16: =+'1'!C16 -> 0 | D16: =+'1'!D16+'2'!D16+'3'!D16+'4'!D16+'5'!D16+'6'!D16+'7'!D16+'8'!D16+'9'!D40+'10'!D16+'11'!D16+'12'!D16+'13'!D16+'14'!D16+'15'!D16+'16'!D16+'17'!D16+'18'!D16+'19'!D16+'20'!D16+'21'!D16+'22'!D16+'23'!D16+'24'!D16+'25'!D16+'26'!D16+'27'!D16+'28'!D16+'29'!D16+'30'!D16+'31'!D16 -> 0 | E16: =+C16+D16 -> 0 | F16: =+'1'!F16+'2'!F16+'3'!F16+'4'!F16+'5'!F16+'6'!F16+'7'!F16+'8'!F16+'9'!F16+'10'!F16+'11'!F16+'12'!F16+'13'!F16+'14'!F16+'15'!F16+'16'!F16+'17'!F16+'18'!F16+'19'!F16+'20'!F16+'21'!F16+'22'!F16+'23'!F16+'24'!F16+'25'!F16+'26'!F16+'27'!F16+'28'!F16+'29'!F16+'30'!F16+'31'!F16 -> 0 | G16: =E16-F16-H16 -> 0 | H16: =+'1'!H16+'2'!H16+'3'!H16+'4'!H16+'5'!H16+'6'!H16+'7'!H16+'8'!H16+'9'!H16+'10'!H16+'11'!H16+'12'!H16+'13'!H16+'14'!H16+'15'!H16+'16'!H16+'17'!H16+'18'!H16+'19'!H16+'20'!H16+'21'!H16+'22'!H16+'23'!H16+'24'!H16+'25'!H16+'26'!H16+'27'!H16+'28'!H16+'29'!H16+'30'!H16+'31'!H16 -> 0 | I16: 50 | J16: =+'1'!J16+'2'!J16+'3'!J16+'4'!J16+'5'!J16+'6'!J16+'7'!J16+'8'!J16+'9'!J16+'10'!J16+'11'!J16+'12'!J16+'13'!J16+'14'!J16+'15'!J16+'16'!J16+'17'!J16+'18'!J16+'19'!J16+'20'!J16+'21'!J16+'22'!J16+'23'!J16+'24'!J16+'25'!J16+'26'!J16+'27'!J16+'28'!J16+'29'!J16+'30'!J16+'31'!J16 -> 0 | L16: 12 | M16: =+'12'!K219 -> 3350 | N16: =+'12'!K224 -> 670 | O16: =+'12'!K222 -> 0 | P16: =+'12'!K220 -> 15 | Q16: =+'12'!K223 -> 0 | R16: =+'12'!K221 -> 415 | S16: =+M16-N16-P16-R16-Q16 -> 2250 | T16: =+'12'!K226 -> 2255 | U16: =+T16-S16 -> 5
A17: 13 | B17: ชิฟฟ่อน สอดไส้ (ล) 3 ชิ้น ฝอยทอง | C17: =+'1'!C17 -> 4 | D17: =+'1'!D17+'2'!D17+'3'!D17+'4'!D17+'5'!D17+'6'!D17+'7'!D17+'8'!D17+'9'!D41+'10'!D17+'11'!D17+'12'!D17+'13'!D17+'14'!D17+'15'!D17+'16'!D17+'17'!D17+'18'!D17+'19'!D17+'20'!D17+'21'!D17+'22'!D17+'23'!D17+'24'!D17+'25'!D17+'26'!D17+'27'!D17+'28'!D17+'29'!D17+'30'!D17+'31'!D17 -> 25 | E17: =+C17+D17 -> 29 | F17: =+'1'!F17+'2'!F17+'3'!F17+'4'!F17+'5'!F17+'6'!F17+'7'!F17+'8'!F17+'9'!F17+'10'!F17+'11'!F17+'12'!F17+'13'!F17+'14'!F17+'15'!F17+'16'!F17+'17'!F17+'18'!F17+'19'!F17+'20'!F17+'21'!F17+'22'!F17+'23'!F17+'24'!F17+'25'!F17+'26'!F17+'27'!F17+'28'!F17+'29'!F17+'30'!F17+'31'!F17 -> 0 | G17: =E17-F17-H17 -> 0 | H17: =+'1'!H17+'2'!H17+'3'!H17+'4'!H17+'5'!H17+'6'!H17+'7'!H17+'8'!H17+'9'!H17+'10'!H17+'11'!H17+'12'!H17+'13'!H17+'14'!H17+'15'!H17+'16'!H17+'17'!H17+'18'!H17+'19'!H17+'20'!H17+'21'!H17+'22'!H17+'23'!H17+'24'!H17+'25'!H17+'26'!H17+'27'!H17+'28'!H17+'29'!H17+'30'!H17+'31'!H17 -> 29 | I17: 50 | J17: =+'1'!J17+'2'!J17+'3'!J17+'4'!J17+'5'!J17+'6'!J17+'7'!J17+'8'!J17+'9'!J17+'10'!J17+'11'!J17+'12'!J17+'13'!J17+'14'!J17+'15'!J17+'16'!J17+'17'!J17+'18'!J17+'19'!J17+'20'!J17+'21'!J17+'22'!J17+'23'!J17+'24'!J17+'25'!J17+'26'!J17+'27'!J17+'28'!J17+'29'!J17+'30'!J17+'31'!J17 -> 1450 | L17: 13 | M17: =+'13'!K219 -> 4475 | N17: =+'13'!K224 -> 440 | O17: =+'13'!K222 -> 0 | P17: =+'13'!K220 -> 15 | Q17: =+'13'!K223 -> 0 | R17: =+'13'!K221 -> 700 | S17: =+M17-N17-P17-R17-Q17 -> 3320 | T17: =+'13'!K226 -> 3320 | U17: =+T17-S17 -> 0
A18: 14 | B18: ชิฟฟ่อน สอดไส้ (ล) 3 ชิ้น แยมสตรอเบอรี่ | C18: =+'1'!C18 -> 0 | D18: =+'1'!D18+'2'!D18+'3'!D18+'4'!D18+'5'!D18+'6'!D18+'7'!D18+'8'!D18+'9'!D42+'10'!D18+'11'!D18+'12'!D18+'13'!D18+'14'!D18+'15'!D18+'16'!D18+'17'!D18+'18'!D18+'19'!D18+'20'!D18+'21'!D18+'22'!D18+'23'!D18+'24'!D18+'25'!D18+'26'!D18+'27'!D18+'28'!D18+'29'!D18+'30'!D18+'31'!D18 -> 0 | E18: =+C18+D18 -> 0 | F18: =+'1'!F18+'2'!F18+'3'!F18+'4'!F18+'5'!F18+'6'!F18+'7'!F18+'8'!F18+'9'!F18+'10'!F18+'11'!F18+'12'!F18+'13'!F18+'14'!F18+'15'!F18+'16'!F18+'17'!F18+'18'!F18+'19'!F18+'20'!F18+'21'!F18+'22'!F18+'23'!F18+'24'!F18+'25'!F18+'26'!F18+'27'!F18+'28'!F18+'29'!F18+'30'!F18+'31'!F18 -> 0 | G18: =E18-F18-H18 -> 0 | H18: =+'1'!H18+'2'!H18+'3'!H18+'4'!H18+'5'!H18+'6'!H18+'7'!H18+'8'!H18+'9'!H18+'10'!H18+'11'!H18+'12'!H18+'13'!H18+'14'!H18+'15'!H18+'16'!H18+'17'!H18+'18'!H18+'19'!H18+'20'!H18+'21'!H18+'22'!H18+'23'!H18+'24'!H18+'25'!H18+'26'!H18+'27'!H18+'28'!H18+'29'!H18+'30'!H18+'31'!H18 -> 0 | I18: 50 | J18: =+'1'!J18+'2'!J18+'3'!J18+'4'!J18+'5'!J18+'6'!J18+'7'!J18+'8'!J18+'9'!J18+'10'!J18+'11'!J18+'12'!J18+'13'!J18+'14'!J18+'15'!J18+'16'!J18+'17'!J18+'18'!J18+'19'!J18+'20'!J18+'21'!J18+'22'!J18+'23'!J18+'24'!J18+'25'!J18+'26'!J18+'27'!J18+'28'!J18+'29'!J18+'30'!J18+'31'!J18 -> 0 | L18: 14 | M18: =+'14'!K219 -> 3695 | N18: =+'14'!K224 -> 180 | O18: =+'14'!K222 -> 0 | P18: =+'14'!K220 -> 15 | Q18: =+'14'!K223 -> 0 | R18: =+'14'!K221 -> 1615 | S18: =+M18-N18-P18-R18-Q18 -> 1885 | T18: =+'14'!K226 -> 1885 | U18: =+T18-S18 -> 0
A19: 15 | B19: ชิฟฟ่อน สอดไส้ (ล) 3 ชิ้น เนยมพะร้าว | C19: =+'1'!C19 -> 8 | D19: =+'1'!D19+'2'!D19+'3'!D19+'4'!D19+'5'!D19+'6'!D19+'7'!D19+'8'!D19+'9'!D43+'10'!D19+'11'!D19+'12'!D19+'13'!D19+'14'!D19+'15'!D19+'16'!D19+'17'!D19+'18'!D19+'19'!D19+'20'!D19+'21'!D19+'22'!D19+'23'!D19+'24'!D19+'25'!D19+'26'!D19+'27'!D19+'28'!D19+'29'!D19+'30'!D19+'31'!D19 -> 10 | E19: =+C19+D19 -> 18 | F19: =+'1'!F19+'2'!F19+'3'!F19+'4'!F19+'5'!F19+'6'!F19+'7'!F19+'8'!F19+'9'!F19+'10'!F19+'11'!F19+'12'!F19+'13'!F19+'14'!F19+'15'!F19+'16'!F19+'17'!F19+'18'!F19+'19'!F19+'20'!F19+'21'!F19+'22'!F19+'23'!F19+'24'!F19+'25'!F19+'26'!F19+'27'!F19+'28'!F19+'29'!F19+'30'!F19+'31'!F19 -> 0 | G19: =E19-F19-H19 -> 6 | H19: =+'1'!H19+'2'!H19+'3'!H19+'4'!H19+'5'!H19+'6'!H19+'7'!H19+'8'!H19+'9'!H19+'10'!H19+'11'!H19+'12'!H19+'13'!H19+'14'!H19+'15'!H19+'16'!H19+'17'!H19+'18'!H19+'19'!H19+'20'!H19+'21'!H19+'22'!H19+'23'!H19+'24'!H19+'25'!H19+'26'!H19+'27'!H19+'28'!H19+'29'!H19+'30'!H19+'31'!H19 -> 12 | I19: 50 | J19: =+'1'!J19+'2'!J19+'3'!J19+'4'!J19+'5'!J19+'6'!J19+'7'!J19+'8'!J19+'9'!J19+'10'!J19+'11'!J19+'12'!J19+'13'!J19+'14'!J19+'15'!J19+'16'!J19+'17'!J19+'18'!J19+'19'!J19+'20'!J19+'21'!J19+'22'!J19+'23'!J19+'24'!J19+'25'!J19+'26'!J19+'27'!J19+'28'!J19+'29'!J19+'30'!J19+'31'!J19 -> 600 | L19: 15 | M19: =+'15'!K219 -> 4265 | N19: =+'15'!K224 -> 90 | O19: =+'15'!K222 -> 0 | P19: =+'15'!K220 -> 15 | Q19: =+'15'!K223 -> 0 | R19: =+'15'!K221 -> 1370 | S19: =+M19-N19-P19-R19-Q19 -> 2790 | T19: =+'15'!K226 -> 2790 | U19: =+T19-S19 -> 0
A20: 16 | B20: ชิฟฟ่อน สอดไส้ (ล) 3 ชิ้น นมชมพู | C20: =+'1'!C20 -> 0 | D20: =+'1'!D20+'2'!D20+'3'!D20+'4'!D20+'5'!D20+'6'!D20+'7'!D20+'8'!D20+'9'!D44+'10'!D20+'11'!D20+'12'!D20+'13'!D20+'14'!D20+'15'!D20+'16'!D20+'17'!D20+'18'!D20+'19'!D20+'20'!D20+'21'!D20+'22'!D20+'23'!D20+'24'!D20+'25'!D20+'26'!D20+'27'!D20+'28'!D20+'29'!D20+'30'!D20+'31'!D20 -> 0 | E20: =+C20+D20 -> 0 | F20: =+'1'!F20+'2'!F20+'3'!F20+'4'!F20+'5'!F20+'6'!F20+'7'!F20+'8'!F20+'9'!F20+'10'!F20+'11'!F20+'12'!F20+'13'!F20+'14'!F20+'15'!F20+'16'!F20+'17'!F20+'18'!F20+'19'!F20+'20'!F20+'21'!F20+'22'!F20+'23'!F20+'24'!F20+'25'!F20+'26'!F20+'27'!F20+'28'!F20+'29'!F20+'30'!F20+'31'!F20 -> 0 | G20: =E20-F20-H20 -> 0 | H20: =+'1'!H20+'2'!H20+'3'!H20+'4'!H20+'5'!H20+'6'!H20+'7'!H20+'8'!H20+'9'!H20+'10'!H20+'11'!H20+'12'!H20+'13'!H20+'14'!H20+'15'!H20+'16'!H20+'17'!H20+'18'!H20+'19'!H20+'20'!H20+'21'!H20+'22'!H20+'23'!H20+'24'!H20+'25'!H20+'26'!H20+'27'!H20+'28'!H20+'29'!H20+'30'!H20+'31'!H20 -> 0 | I20: 50 | J20: =+'1'!J20+'2'!J20+'3'!J20+'4'!J20+'5'!J20+'6'!J20+'7'!J20+'8'!J20+'9'!J20+'10'!J20+'11'!J20+'12'!J20+'13'!J20+'14'!J20+'15'!J20+'16'!J20+'17'!J20+'18'!J20+'19'!J20+'20'!J20+'21'!J20+'22'!J20+'23'!J20+'24'!J20+'25'!J20+'26'!J20+'27'!J20+'28'!J20+'29'!J20+'30'!J20+'31'!J20 -> 0 | L20: 16 | M20: =+'16'!K219 -> 3040 | N20: =+'16'!K224 -> 350 | O20: =+'16'!K222 -> 0 | P20: =+'16'!K220 -> 15 | Q20: =+'16'!K223 -> 0 | R20: =+'16'!K221 -> 730 | S20: =+M20-N20-P20-R20-Q20 -> 1945 | T20: =+'16'!K226 -> 1945 | U20: =+T20-S20 -> 0
A21: 17 | B21: ชิฟฟ่อน สอดไส้ (ล) 3 ชิ้น ช็อคโกแลต | C21: =+'1'!C21 -> 0 | D21: =+'1'!D21+'2'!D21+'3'!D21+'4'!D21+'5'!D21+'6'!D21+'7'!D21+'8'!D21+'9'!D45+'10'!D21+'11'!D21+'12'!D21+'13'!D21+'14'!D21+'15'!D21+'16'!D21+'17'!D21+'18'!D21+'19'!D21+'20'!D21+'21'!D21+'22'!D21+'23'!D21+'24'!D21+'25'!D21+'26'!D21+'27'!D21+'28'!D21+'29'!D21+'30'!D21+'31'!D21 -> 0 | E21: =+C21+D21 -> 0 | F21: =+'1'!F21+'2'!F21+'3'!F21+'4'!F21+'5'!F21+'6'!F21+'7'!F21+'8'!F21+'9'!F21+'10'!F21+'11'!F21+'12'!F21+'13'!F21+'14'!F21+'15'!F21+'16'!F21+'17'!F21+'18'!F21+'19'!F21+'20'!F21+'21'!F21+'22'!F21+'23'!F21+'24'!F21+'25'!F21+'26'!F21+'27'!F21+'28'!F21+'29'!F21+'30'!F21+'31'!F21 -> 0 | G21: =E21-F21-H21 -> 0 | H21: =+'1'!H21+'2'!H21+'3'!H21+'4'!H21+'5'!H21+'6'!H21+'7'!H21+'8'!H21+'9'!H21+'10'!H21+'11'!H21+'12'!H21+'13'!H21+'14'!H21+'15'!H21+'16'!H21+'17'!H21+'18'!H21+'19'!H21+'20'!H21+'21'!H21+'22'!H21+'23'!H21+'24'!H21+'25'!H21+'26'!H21+'27'!H21+'28'!H21+'29'!H21+'30'!H21+'31'!H21 -> 0 | I21: 50 | J21: =+'1'!J21+'2'!J21+'3'!J21+'4'!J21+'5'!J21+'6'!J21+'7'!J21+'8'!J21+'9'!J21+'10'!J21+'11'!J21+'12'!J21+'13'!J21+'14'!J21+'15'!J21+'16'!J21+'17'!J21+'18'!J21+'19'!J21+'20'!J21+'21'!J21+'22'!J21+'23'!J21+'24'!J21+'25'!J21+'26'!J21+'27'!J21+'28'!J21+'29'!J21+'30'!J21+'31'!J21 -> 0 | L21: 17 | M21: =+'17'!K219 -> 2435 | N21: =+'17'!K224 -> 275 | O21: =+'17'!K222 -> 0 | P21: =+'17'!K220 -> 15 | Q21: =+'17'!K223 -> 0 | R21: =+'17'!K221 -> 480 | S21: =+M21-N21-P21-R21-Q21 -> 1665 | T21: =+'17'!K226 -> 1665 | U21: =+T21-S21 -> 0
A22: 18 | B22: ชิฟฟ่อน สอดไส้ (ก) 5 ชิ้น | C22: =+'1'!C22 -> 0 | D22: =+'1'!D22+'2'!D22+'3'!D22+'4'!D22+'5'!D22+'6'!D22+'7'!D22+'8'!D22+'9'!D46+'10'!D22+'11'!D22+'12'!D22+'13'!D22+'14'!D22+'15'!D22+'16'!D22+'17'!D22+'18'!D22+'19'!D22+'20'!D22+'21'!D22+'22'!D22+'23'!D22+'24'!D22+'25'!D22+'26'!D22+'27'!D22+'28'!D22+'29'!D22+'30'!D22+'31'!D22 -> 4 | E22: =+C22+D22 -> 4 | F22: =+'1'!F22+'2'!F22+'3'!F22+'4'!F22+'5'!F22+'6'!F22+'7'!F22+'8'!F22+'9'!F22+'10'!F22+'11'!F22+'12'!F22+'13'!F22+'14'!F22+'15'!F22+'16'!F22+'17'!F22+'18'!F22+'19'!F22+'20'!F22+'21'!F22+'22'!F22+'23'!F22+'24'!F22+'25'!F22+'26'!F22+'27'!F22+'28'!F22+'29'!F22+'30'!F22+'31'!F22 -> 0 | G22: =E22-F22-H22 -> 0 | H22: =+'1'!H22+'2'!H22+'3'!H22+'4'!H22+'5'!H22+'6'!H22+'7'!H22+'8'!H22+'9'!H22+'10'!H22+'11'!H22+'12'!H22+'13'!H22+'14'!H22+'15'!H22+'16'!H22+'17'!H22+'18'!H22+'19'!H22+'20'!H22+'21'!H22+'22'!H22+'23'!H22+'24'!H22+'25'!H22+'26'!H22+'27'!H22+'28'!H22+'29'!H22+'30'!H22+'31'!H22 -> 4 | I22: 85 | J22: =+'1'!J22+'2'!J22+'3'!J22+'4'!J22+'5'!J22+'6'!J22+'7'!J22+'8'!J22+'9'!J22+'10'!J22+'11'!J22+'12'!J22+'13'!J22+'14'!J22+'15'!J22+'16'!J22+'17'!J22+'18'!J22+'19'!J22+'20'!J22+'21'!J22+'22'!J22+'23'!J22+'24'!J22+'25'!J22+'26'!J22+'27'!J22+'28'!J22+'29'!J22+'30'!J22+'31'!J22 -> 340 | L22: 18 | M22: =+'18'!K219 -> 1760 | N22: =+'18'!K224 -> 130 | O22: =+'18'!K222 -> 0 | P22: =+'18'!K220 -> 15 | Q22: =+'18'!K223 -> 0 | R22: =+'18'!K221 -> 500 | S22: =+M22-N22-P22-R22-Q22 -> 1115 | T22: =+'18'!K226 -> 1115 | U22: =+T22-S22 -> 0
A23: 19 | B23: ชิฟฟ่อน สอดไส้ 6 ชิ้น รวมรส | C23: =+'1'!C23 -> 15 | D23: =+'1'!D23+'2'!D23+'3'!D23+'4'!D23+'5'!D23+'6'!D23+'7'!D23+'8'!D23+'9'!D47+'10'!D23+'11'!D23+'12'!D23+'13'!D23+'14'!D23+'15'!D23+'16'!D23+'17'!D23+'18'!D23+'19'!D23+'20'!D23+'21'!D23+'22'!D23+'23'!D23+'24'!D23+'25'!D23+'26'!D23+'27'!D23+'28'!D23+'29'!D23+'30'!D23+'31'!D23 -> 70 | E23: =+C23+D23 -> 85 | F23: =+'1'!F23+'2'!F23+'3'!F23+'4'!F23+'5'!F23+'6'!F23+'7'!F23+'8'!F23+'9'!F23+'10'!F23+'11'!F23+'12'!F23+'13'!F23+'14'!F23+'15'!F23+'16'!F23+'17'!F23+'18'!F23+'19'!F23+'20'!F23+'21'!F23+'22'!F23+'23'!F23+'24'!F23+'25'!F23+'26'!F23+'27'!F23+'28'!F23+'29'!F23+'30'!F23+'31'!F23 -> 1 | G23: =E23-F23-H23 -> 0 | H23: =+'1'!H23+'2'!H23+'3'!H23+'4'!H23+'5'!H23+'6'!H23+'7'!H23+'8'!H23+'9'!H23+'10'!H23+'11'!H23+'12'!H23+'13'!H23+'14'!H23+'15'!H23+'16'!H23+'17'!H23+'18'!H23+'19'!H23+'20'!H23+'21'!H23+'22'!H23+'23'!H23+'24'!H23+'25'!H23+'26'!H23+'27'!H23+'28'!H23+'29'!H23+'30'!H23+'31'!H23 -> 84 | I23: 100 | J23: =+'1'!J23+'2'!J23+'3'!J23+'4'!J23+'5'!J23+'6'!J23+'7'!J23+'8'!J23+'9'!J23+'10'!J23+'11'!J23+'12'!J23+'13'!J23+'14'!J23+'15'!J23+'16'!J23+'17'!J23+'18'!J23+'19'!J23+'20'!J23+'21'!J23+'22'!J23+'23'!J23+'24'!J23+'25'!J23+'26'!J23+'27'!J23+'28'!J23+'29'!J23+'30'!J23+'31'!J23 -> 8400 | L23: 19 | M23: =+'19'!K219 -> 3380 | N23: =+'19'!K224 -> 175 | O23: =+'19'!K222 -> 0 | P23: =+'19'!K220 -> 15 | Q23: =+'19'!K223 -> 0 | R23: =+'19'!K221 -> 860 | S23: =+M23-N23-P23-R23-Q23 -> 2330 | T23: =+'19'!K226 -> 2230 | U23: =+T23-S23 -> -100
A24: 20 | B24: ชิฟฟ่อน สอดไส้ 6 ชิ้น ฝอยทอง | C24: =+'1'!C24 -> 1 | D24: =+'1'!D24+'2'!D24+'3'!D24+'4'!D24+'5'!D24+'6'!D24+'7'!D24+'8'!D24+'9'!D48+'10'!D24+'11'!D24+'12'!D24+'13'!D24+'14'!D24+'15'!D24+'16'!D24+'17'!D24+'18'!D24+'19'!D24+'20'!D24+'21'!D24+'22'!D24+'23'!D24+'24'!D24+'25'!D24+'26'!D24+'27'!D24+'28'!D24+'29'!D24+'30'!D24+'31'!D24 -> 9 | E24: =+C24+D24 -> 10 | F24: =+'1'!F24+'2'!F24+'3'!F24+'4'!F24+'5'!F24+'6'!F24+'7'!F24+'8'!F24+'9'!F24+'10'!F24+'11'!F24+'12'!F24+'13'!F24+'14'!F24+'15'!F24+'16'!F24+'17'!F24+'18'!F24+'19'!F24+'20'!F24+'21'!F24+'22'!F24+'23'!F24+'24'!F24+'25'!F24+'26'!F24+'27'!F24+'28'!F24+'29'!F24+'30'!F24+'31'!F24 -> 0 | G24: =E24-F24-H24 -> 0 | H24: =+'1'!H24+'2'!H24+'3'!H24+'4'!H24+'5'!H24+'6'!H24+'7'!H24+'8'!H24+'9'!H24+'10'!H24+'11'!H24+'12'!H24+'13'!H24+'14'!H24+'15'!H24+'16'!H24+'17'!H24+'18'!H24+'19'!H24+'20'!H24+'21'!H24+'22'!H24+'23'!H24+'24'!H24+'25'!H24+'26'!H24+'27'!H24+'28'!H24+'29'!H24+'30'!H24+'31'!H24 -> 10 | I24: 100 | J24: =+'1'!J24+'2'!J24+'3'!J24+'4'!J24+'5'!J24+'6'!J24+'7'!J24+'8'!J24+'9'!J24+'10'!J24+'11'!J24+'12'!J24+'13'!J24+'14'!J24+'15'!J24+'16'!J24+'17'!J24+'18'!J24+'19'!J24+'20'!J24+'21'!J24+'22'!J24+'23'!J24+'24'!J24+'25'!J24+'26'!J24+'27'!J24+'28'!J24+'29'!J24+'30'!J24+'31'!J24 -> 1000 | L24: 20 | M24: =+'20'!K219 -> 5595 | N24: =+'20'!K224 -> 567 | O24: =+'20'!K222 -> 0 | P24: =+'20'!K220 -> 15 | Q24: =+'20'!K223 -> 0 | R24: =+'20'!K221 -> 1620 | S24: =+M24-N24-P24-R24-Q24 -> 3393 | T24: =+'20'!K226 -> 3543 | U24: =+T24-S24 -> 150
A25: 21 | B25: ชิฟฟ่อน สอดไส้ 6 ชิ้น ทูโทน | C25: =+'1'!C25 -> 5 | D25: =+'1'!D25+'2'!D25+'3'!D25+'4'!D25+'5'!D25+'6'!D25+'7'!D25+'8'!D25+'9'!D49+'10'!D25+'11'!D25+'12'!D25+'13'!D25+'14'!D25+'15'!D25+'16'!D25+'17'!D25+'18'!D25+'19'!D25+'20'!D25+'21'!D25+'22'!D25+'23'!D25+'24'!D25+'25'!D25+'26'!D25+'27'!D25+'28'!D25+'29'!D25+'30'!D25+'31'!D25 -> 7 | E25: =+C25+D25 -> 12 | F25: =+'1'!F25+'2'!F25+'3'!F25+'4'!F25+'5'!F25+'6'!F25+'7'!F25+'8'!F25+'9'!F25+'10'!F25+'11'!F25+'12'!F25+'13'!F25+'14'!F25+'15'!F25+'16'!F25+'17'!F25+'18'!F25+'19'!F25+'20'!F25+'21'!F25+'22'!F25+'23'!F25+'24'!F25+'25'!F25+'26'!F25+'27'!F25+'28'!F25+'29'!F25+'30'!F25+'31'!F25 -> 0 | G25: =E25-F25-H25 -> 0 | H25: =+'1'!H25+'2'!H25+'3'!H25+'4'!H25+'5'!H25+'6'!H25+'7'!H25+'8'!H25+'9'!H25+'10'!H25+'11'!H25+'12'!H25+'13'!H25+'14'!H25+'15'!H25+'16'!H25+'17'!H25+'18'!H25+'19'!H25+'20'!H25+'21'!H25+'22'!H25+'23'!H25+'24'!H25+'25'!H25+'26'!H25+'27'!H25+'28'!H25+'29'!H25+'30'!H25+'31'!H25 -> 12 | I25: 100 | J25: =+'1'!J25+'2'!J25+'3'!J25+'4'!J25+'5'!J25+'6'!J25+'7'!J25+'8'!J25+'9'!J25+'10'!J25+'11'!J25+'12'!J25+'13'!J25+'14'!J25+'15'!J25+'16'!J25+'17'!J25+'18'!J25+'19'!J25+'20'!J25+'21'!J25+'22'!J25+'23'!J25+'24'!J25+'25'!J25+'26'!J25+'27'!J25+'28'!J25+'29'!J25+'30'!J25+'31'!J25 -> 1200 | L25: 21 | M25: =+'21'!K219 -> 4500 | N25: =+'21'!K224 -> 295 | O25: =+'21'!K222 -> 0 | P25: =+'21'!K220 -> 15 | Q25: =+'21'!K223 -> 0 | R25: =+'21'!K221 -> 820 | S25: =+M25-N25-P25-R25-Q25 -> 3370 | T25: =+'21'!K226 -> 3320 | U25: =+T25-S25 -> -50
A26: 22 | B26: ชิฟฟ่อน สอดไส้ 6 ชิ้น นมชมพู | C26: =+'1'!C26 -> 0 | D26: =+'1'!D26+'2'!D26+'3'!D26+'4'!D26+'5'!D26+'6'!D26+'7'!D26+'8'!D26+'9'!D50+'10'!D26+'11'!D26+'12'!D26+'13'!D26+'14'!D26+'15'!D26+'16'!D26+'17'!D26+'18'!D26+'19'!D26+'20'!D26+'21'!D26+'22'!D26+'23'!D26+'24'!D26+'25'!D26+'26'!D26+'27'!D26+'28'!D26+'29'!D26+'30'!D26+'31'!D26 -> 0 | E26: =+C26+D26 -> 0 | F26: =+'1'!F26+'2'!F26+'3'!F26+'4'!F26+'5'!F26+'6'!F26+'7'!F26+'8'!F26+'9'!F26+'10'!F26+'11'!F26+'12'!F26+'13'!F26+'14'!F26+'15'!F26+'16'!F26+'17'!F26+'18'!F26+'19'!F26+'20'!F26+'21'!F26+'22'!F26+'23'!F26+'24'!F26+'25'!F26+'26'!F26+'27'!F26+'28'!F26+'29'!F26+'30'!F26+'31'!F26 -> 0 | G26: =E26-F26-H26 -> 0 | H26: =+'1'!H26+'2'!H26+'3'!H26+'4'!H26+'5'!H26+'6'!H26+'7'!H26+'8'!H26+'9'!H26+'10'!H26+'11'!H26+'12'!H26+'13'!H26+'14'!H26+'15'!H26+'16'!H26+'17'!H26+'18'!H26+'19'!H26+'20'!H26+'21'!H26+'22'!H26+'23'!H26+'24'!H26+'25'!H26+'26'!H26+'27'!H26+'28'!H26+'29'!H26+'30'!H26+'31'!H26 -> 0 | I26: 100 | J26: =+'1'!J26+'2'!J26+'3'!J26+'4'!J26+'5'!J26+'6'!J26+'7'!J26+'8'!J26+'9'!J26+'10'!J26+'11'!J26+'12'!J26+'13'!J26+'14'!J26+'15'!J26+'16'!J26+'17'!J26+'18'!J26+'19'!J26+'20'!J26+'21'!J26+'22'!J26+'23'!J26+'24'!J26+'25'!J26+'26'!J26+'27'!J26+'28'!J26+'29'!J26+'30'!J26+'31'!J26 -> 0 | L26: 22 | M26: =+'22'!K219 -> 3755 | N26: =+'22'!K224 -> 225 | O26: =+'22'!K222 -> 0 | P26: =+'22'!K220 -> 15 | Q26: =+'22'!K223 -> 0 | R26: =+'22'!K221 -> 1530 | S26: =+M26-N26-P26-R26-Q26 -> 1985 | T26: =+'22'!K226 -> 1985 | U26: =+T26-S26 -> 0
A27: 23 | B27: ชิฟฟ่อน สอดไส้ 6 ชิ้น บลูเบอรี่ | C27: =+'1'!C27 -> 0 | D27: =+'1'!D27+'2'!D27+'3'!D27+'4'!D27+'5'!D27+'6'!D27+'7'!D27+'8'!D27+'9'!D51+'10'!D27+'11'!D27+'12'!D27+'13'!D27+'14'!D27+'15'!D27+'16'!D27+'17'!D27+'18'!D27+'19'!D27+'20'!D27+'21'!D27+'22'!D27+'23'!D27+'24'!D27+'25'!D27+'26'!D27+'27'!D27+'28'!D27+'29'!D27+'30'!D27+'31'!D27 -> 0 | E27: =+C27+D27 -> 0 | F27: =+'1'!F27+'2'!F27+'3'!F27+'4'!F27+'5'!F27+'6'!F27+'7'!F27+'8'!F27+'9'!F27+'10'!F27+'11'!F27+'12'!F27+'13'!F27+'14'!F27+'15'!F27+'16'!F27+'17'!F27+'18'!F27+'19'!F27+'20'!F27+'21'!F27+'22'!F27+'23'!F27+'24'!F27+'25'!F27+'26'!F27+'27'!F27+'28'!F27+'29'!F27+'30'!F27+'31'!F27 -> 0 | G27: =E27-F27-H27 -> 0 | H27: =+'1'!H27+'2'!H27+'3'!H27+'4'!H27+'5'!H27+'6'!H27+'7'!H27+'8'!H27+'9'!H27+'10'!H27+'11'!H27+'12'!H27+'13'!H27+'14'!H27+'15'!H27+'16'!H27+'17'!H27+'18'!H27+'19'!H27+'20'!H27+'21'!H27+'22'!H27+'23'!H27+'24'!H27+'25'!H27+'26'!H27+'27'!H27+'28'!H27+'29'!H27+'30'!H27+'31'!H27 -> 0 | I27: 100 | J27: =+'1'!J27+'2'!J27+'3'!J27+'4'!J27+'5'!J27+'6'!J27+'7'!J27+'8'!J27+'9'!J27+'10'!J27+'11'!J27+'12'!J27+'13'!J27+'14'!J27+'15'!J27+'16'!J27+'17'!J27+'18'!J27+'19'!J27+'20'!J27+'21'!J27+'22'!J27+'23'!J27+'24'!J27+'25'!J27+'26'!J27+'27'!J27+'28'!J27+'29'!J27+'30'!J27+'31'!J27 -> 0 | L27: 23 | M27: =+'23'!K219 -> 7125 | N27: =+'23'!K224 -> 652 | O27: =+'23'!K222 -> 0 | P27: =+'23'!K220 -> 15 | Q27: =+'23'!K223 -> 0 | R27: =+'23'!K221 -> 1685 | S27: =+M27-N27-P27-R27-Q27 -> 4773 | T27: =+'23'!K226 -> 4773 | U27: =+T27-S27 -> 0
A28: 24 | B28: ชิฟฟ่อน สอดไส้ 6 ชิ้น ช็อคโกแลต | C28: =+'1'!C28 -> 0 | D28: =+'1'!D28+'2'!D28+'3'!D28+'4'!D28+'5'!D28+'6'!D28+'7'!D28+'8'!D28+'9'!D52+'10'!D28+'11'!D28+'12'!D28+'13'!D28+'14'!D28+'15'!D28+'16'!D28+'17'!D28+'18'!D28+'19'!D28+'20'!D28+'21'!D28+'22'!D28+'23'!D28+'24'!D28+'25'!D28+'26'!D28+'27'!D28+'28'!D28+'29'!D28+'30'!D28+'31'!D28 -> 0 | E28: =+C28+D28 -> 0 | F28: =+'1'!F28+'2'!F28+'3'!F28+'4'!F28+'5'!F28+'6'!F28+'7'!F28+'8'!F28+'9'!F28+'10'!F28+'11'!F28+'12'!F28+'13'!F28+'14'!F28+'15'!F28+'16'!F28+'17'!F28+'18'!F28+'19'!F28+'20'!F28+'21'!F28+'22'!F28+'23'!F28+'24'!F28+'25'!F28+'26'!F28+'27'!F28+'28'!F28+'29'!F28+'30'!F28+'31'!F28 -> 0 | G28: =E28-F28-H28 -> 0 | H28: =+'1'!H28+'2'!H28+'3'!H28+'4'!H28+'5'!H28+'6'!H28+'7'!H28+'8'!H28+'9'!H28+'10'!H28+'11'!H28+'12'!H28+'13'!H28+'14'!H28+'15'!H28+'16'!H28+'17'!H28+'18'!H28+'19'!H28+'20'!H28+'21'!H28+'22'!H28+'23'!H28+'24'!H28+'25'!H28+'26'!H28+'27'!H28+'28'!H28+'29'!H28+'30'!H28+'31'!H28 -> 0 | I28: 100 | J28: =+'1'!J28+'2'!J28+'3'!J28+'4'!J28+'5'!J28+'6'!J28+'7'!J28+'8'!J28+'9'!J28+'10'!J28+'11'!J28+'12'!J28+'13'!J28+'14'!J28+'15'!J28+'16'!J28+'17'!J28+'18'!J28+'19'!J28+'20'!J28+'21'!J28+'22'!J28+'23'!J28+'24'!J28+'25'!J28+'26'!J28+'27'!J28+'28'!J28+'29'!J28+'30'!J28+'31'!J28 -> 0 | L28: 24 | M28: =+'24'!K222 -> 1465 | N28: =+'24'!K227 -> 25 | O28: =+'24'!K225 -> 0 | P28: =+'24'!K223 -> 15 | Q28: =+'24'!K226 -> 0 | R28: =+'24'!K224 -> 150 | S28: =+M28-N28-P28-R28-Q28 -> 1275 | T28: =+'24'!K229 -> 1275 | U28: =+T28-S28 -> 0
A29: 25 | B29: ชิฟฟ่อน สอดไส้ 6 ชิ้น มะพร้าว | C29: =+'1'!C29 -> 0 | D29: =+'1'!D29+'2'!D29+'3'!D29+'4'!D29+'5'!D29+'6'!D29+'7'!D29+'8'!D29+'9'!D53+'10'!D29+'11'!D29+'12'!D29+'13'!D29+'14'!D29+'15'!D29+'16'!D29+'17'!D29+'18'!D29+'19'!D29+'20'!D29+'21'!D29+'22'!D29+'23'!D29+'24'!D29+'25'!D29+'26'!D29+'27'!D29+'28'!D29+'29'!D29+'30'!D29+'31'!D29 -> 0 | E29: =+C29+D29 -> 0 | F29: =+'1'!F29+'2'!F29+'3'!F29+'4'!F29+'5'!F29+'6'!F29+'7'!F29+'8'!F29+'9'!F29+'10'!F29+'11'!F29+'12'!F29+'13'!F29+'14'!F29+'15'!F29+'16'!F29+'17'!F29+'18'!F29+'19'!F29+'20'!F29+'21'!F29+'22'!F29+'23'!F29+'24'!F29+'25'!F29+'26'!F29+'27'!F29+'28'!F29+'29'!F29+'30'!F29+'31'!F29 -> 0 | G29: =E29-F29-H29 -> 0 | H29: =+'1'!H29+'2'!H29+'3'!H29+'4'!H29+'5'!H29+'6'!H29+'7'!H29+'8'!H29+'9'!H29+'10'!H29+'11'!H29+'12'!H29+'13'!H29+'14'!H29+'15'!H29+'16'!H29+'17'!H29+'18'!H29+'19'!H29+'20'!H29+'21'!H29+'22'!H29+'23'!H29+'24'!H29+'25'!H29+'26'!H29+'27'!H29+'28'!H29+'29'!H29+'30'!H29+'31'!H29 -> 0 | I29: 100 | J29: =+'1'!J29+'2'!J29+'3'!J29+'4'!J29+'5'!J29+'6'!J29+'7'!J29+'8'!J29+'9'!J29+'10'!J29+'11'!J29+'12'!J29+'13'!J29+'14'!J29+'15'!J29+'16'!J29+'17'!J29+'18'!J29+'19'!J29+'20'!J29+'21'!J29+'22'!J29+'23'!J29+'24'!J29+'25'!J29+'26'!J29+'27'!J29+'28'!J29+'29'!J29+'30'!J29+'31'!J29 -> 0 | L29: 25 | M29: =+'25'!K222 -> 4330 | N29: =+'25'!K227 -> 155 | O29: =+'25'!K225 -> 0 | P29: =+'25'!K223 -> 15 | Q29: =+'25'!K226 -> 0 | R29: =+'25'!K224 -> 1195 | S29: =+M29-N29-P29-R29-Q29 -> 2965 | T29: =+'25'!K229 -> 2970 | U29: =+T29-S29 -> 5
A30: 26 | B30: ชิฟฟ่อน สอดไส้ 6 ชิ้น ส้ม | C30: =+'1'!C30 -> 0 | D30: =+'1'!D30+'2'!D30+'3'!D30+'4'!D30+'5'!D30+'6'!D30+'7'!D30+'8'!D30+'9'!D54+'10'!D30+'11'!D30+'12'!D30+'13'!D30+'14'!D30+'15'!D30+'16'!D30+'17'!D30+'18'!D30+'19'!D30+'20'!D30+'21'!D30+'22'!D30+'23'!D30+'24'!D30+'25'!D30+'26'!D30+'27'!D30+'28'!D30+'29'!D30+'30'!D30+'31'!D30 -> 0 | E30: =+C30+D30 -> 0 | F30: =+'1'!F30+'2'!F30+'3'!F30+'4'!F30+'5'!F30+'6'!F30+'7'!F30+'8'!F30+'9'!F30+'10'!F30+'11'!F30+'12'!F30+'13'!F30+'14'!F30+'15'!F30+'16'!F30+'17'!F30+'18'!F30+'19'!F30+'20'!F30+'21'!F30+'22'!F30+'23'!F30+'24'!F30+'25'!F30+'26'!F30+'27'!F30+'28'!F30+'29'!F30+'30'!F30+'31'!F30 -> 0 | G30: =E30-F30-H30 -> 0 | H30: =+'1'!H30+'2'!H30+'3'!H30+'4'!H30+'5'!H30+'6'!H30+'7'!H30+'8'!H30+'9'!H30+'10'!H30+'11'!H30+'12'!H30+'13'!H30+'14'!H30+'15'!H30+'16'!H30+'17'!H30+'18'!H30+'19'!H30+'20'!H30+'21'!H30+'22'!H30+'23'!H30+'24'!H30+'25'!H30+'26'!H30+'27'!H30+'28'!H30+'29'!H30+'30'!H30+'31'!H30 -> 0 | I30: 100 | J30: =+'1'!J30+'2'!J30+'3'!J30+'4'!J30+'5'!J30+'6'!J30+'7'!J30+'8'!J30+'9'!J30+'10'!J30+'11'!J30+'12'!J30+'13'!J30+'14'!J30+'15'!J30+'16'!J30+'17'!J30+'18'!J30+'19'!J30+'20'!J30+'21'!J30+'22'!J30+'23'!J30+'24'!J30+'25'!J30+'26'!J30+'27'!J30+'28'!J30+'29'!J30+'30'!J30+'31'!J30 -> 0 | L30: 26 | M30: =+'26'!K222 -> 2950 | N30: =+'26'!K227 -> 0 | O30: =+'26'!K225 -> 0 | P30: =+'26'!K223 -> 15 | Q30: =+'26'!K226 -> 0 | R30: =+'26'!K224 -> 690 | S30: =+M30-N30-P30-R30-Q30 -> 2245 | T30: =+'26'!K229 -> 2245 | U30: =+T30-S30 -> 0
A31: 27 | B31: ชิฟฟ่อน สอดไส้ 6 ชิ้น สตรอเบอรี่ | C31: =+'1'!C31 -> 0 | D31: =+'1'!D31+'2'!D31+'3'!D31+'4'!D31+'5'!D31+'6'!D31+'7'!D31+'8'!D31+'9'!D55+'10'!D31+'11'!D31+'12'!D31+'13'!D31+'14'!D31+'15'!D31+'16'!D31+'17'!D31+'18'!D31+'19'!D31+'20'!D31+'21'!D31+'22'!D31+'23'!D31+'24'!D31+'25'!D31+'26'!D31+'27'!D31+'28'!D31+'29'!D31+'30'!D31+'31'!D31 -> 0 | E31: =+C31+D31 -> 0 | F31: =+'1'!F31+'2'!F31+'3'!F31+'4'!F31+'5'!F31+'6'!F31+'7'!F31+'8'!F31+'9'!F31+'10'!F31+'11'!F31+'12'!F31+'13'!F31+'14'!F31+'15'!F31+'16'!F31+'17'!F31+'18'!F31+'19'!F31+'20'!F31+'21'!F31+'22'!F31+'23'!F31+'24'!F31+'25'!F31+'26'!F31+'27'!F31+'28'!F31+'29'!F31+'30'!F31+'31'!F31 -> 0 | G31: =E31-F31-H31 -> 0 | H31: =+'1'!H31+'2'!H31+'3'!H31+'4'!H31+'5'!H31+'6'!H31+'7'!H31+'8'!H31+'9'!H31+'10'!H31+'11'!H31+'12'!H31+'13'!H31+'14'!H31+'15'!H31+'16'!H31+'17'!H31+'18'!H31+'19'!H31+'20'!H31+'21'!H31+'22'!H31+'23'!H31+'24'!H31+'25'!H31+'26'!H31+'27'!H31+'28'!H31+'29'!H31+'30'!H31+'31'!H31 -> 0 | I31: 100 | J31: =+'1'!J31+'2'!J31+'3'!J31+'4'!J31+'5'!J31+'6'!J31+'7'!J31+'8'!J31+'9'!J31+'10'!J31+'11'!J31+'12'!J31+'13'!J31+'14'!J31+'15'!J31+'16'!J31+'17'!J31+'18'!J31+'19'!J31+'20'!J31+'21'!J31+'22'!J31+'23'!J31+'24'!J31+'25'!J31+'26'!J31+'27'!J31+'28'!J31+'29'!J31+'30'!J31+'31'!J31 -> 0 | L31: 27 | M31: =+'27'!K222 -> 4845 | N31: =+'27'!K227 -> 450 | O31: =+'27'!K225 -> 0 | P31: =+'27'!K223 -> 15 | Q31: =+'27'!K226 -> 0 | R31: =+'27'!K224 -> 2050 | S31: =+M31-N31-P31-R31-Q31 -> 2330 | T31: =+'27'!K229 -> 2330 | U31: =+T31-S31 -> 0
A32: 28 | B32: ชิฟฟ่อน สอดไส้ (ญ) 8 ชิ้น ใบเตย | C32: =+'1'!C32 -> 0 | D32: =+'1'!D32+'2'!D32+'3'!D32+'4'!D32+'5'!D32+'6'!D32+'7'!D32+'8'!D32+'9'!D56+'10'!D32+'11'!D32+'12'!D32+'13'!D32+'14'!D32+'15'!D32+'16'!D32+'17'!D32+'18'!D32+'19'!D32+'20'!D32+'21'!D32+'22'!D32+'23'!D32+'24'!D32+'25'!D32+'26'!D32+'27'!D32+'28'!D32+'29'!D32+'30'!D32+'31'!D32 -> 0 | E32: =+C32+D32 -> 0 | F32: =+'1'!F32+'2'!F32+'3'!F32+'4'!F32+'5'!F32+'6'!F32+'7'!F32+'8'!F32+'9'!F32+'10'!F32+'11'!F32+'12'!F32+'13'!F32+'14'!F32+'15'!F32+'16'!F32+'17'!F32+'18'!F32+'19'!F32+'20'!F32+'21'!F32+'22'!F32+'23'!F32+'24'!F32+'25'!F32+'26'!F32+'27'!F32+'28'!F32+'29'!F32+'30'!F32+'31'!F32 -> 0 | G32: =E32-F32-H32 -> 0 | H32: =+'1'!H32+'2'!H32+'3'!H32+'4'!H32+'5'!H32+'6'!H32+'7'!H32+'8'!H32+'9'!H32+'10'!H32+'11'!H32+'12'!H32+'13'!H32+'14'!H32+'15'!H32+'16'!H32+'17'!H32+'18'!H32+'19'!H32+'20'!H32+'21'!H32+'22'!H32+'23'!H32+'24'!H32+'25'!H32+'26'!H32+'27'!H32+'28'!H32+'29'!H32+'30'!H32+'31'!H32 -> 0 | I32: 130 | J32: =+'1'!J32+'2'!J32+'3'!J32+'4'!J32+'5'!J32+'6'!J32+'7'!J32+'8'!J32+'9'!J32+'10'!J32+'11'!J32+'12'!J32+'13'!J32+'14'!J32+'15'!J32+'16'!J32+'17'!J32+'18'!J32+'19'!J32+'20'!J32+'21'!J32+'22'!J32+'23'!J32+'24'!J32+'25'!J32+'26'!J32+'27'!J32+'28'!J32+'29'!J32+'30'!J32+'31'!J32 -> 0 | L32: 28 | M32: =+'28'!K222 -> 4735 | N32: =+'28'!K227 -> 305 | O32: =+'28'!K225 -> 0 | P32: =+'28'!K223 -> 15 | Q32: =+'28'!K226 -> 0 | R32: =+'28'!K224 -> 1980 | S32: =+M32-N32-P32-R32-Q32 -> 2435 | T32: =+'28'!K229 -> 2435 | U32: =+T32-S32 -> 0
A33: 29 | B33: ชิฟฟ่อน สอดไส้ (ญ) 8 ชิ้น ทูโทนใบเตย | C33: =+'1'!C33 -> 0 | D33: =+'1'!D33+'2'!D33+'3'!D33+'4'!D33+'5'!D33+'6'!D33+'7'!D33+'8'!D33+'9'!D57+'10'!D33+'11'!D33+'12'!D33+'13'!D33+'14'!D33+'15'!D33+'16'!D33+'17'!D33+'18'!D33+'19'!D33+'20'!D33+'21'!D33+'22'!D33+'23'!D33+'24'!D33+'25'!D33+'26'!D33+'27'!D33+'28'!D33+'29'!D33+'30'!D33+'31'!D33 -> 18 | E33: =+C33+D33 -> 18 | F33: =+'1'!F33+'2'!F33+'3'!F33+'4'!F33+'5'!F33+'6'!F33+'7'!F33+'8'!F33+'9'!F33+'10'!F33+'11'!F33+'12'!F33+'13'!F33+'14'!F33+'15'!F33+'16'!F33+'17'!F33+'18'!F33+'19'!F33+'20'!F33+'21'!F33+'22'!F33+'23'!F33+'24'!F33+'25'!F33+'26'!F33+'27'!F33+'28'!F33+'29'!F33+'30'!F33+'31'!F33 -> 0 | G33: =E33-F33-H33 -> 0 | H33: =+'1'!H33+'2'!H33+'3'!H33+'4'!H33+'5'!H33+'6'!H33+'7'!H33+'8'!H33+'9'!H33+'10'!H33+'11'!H33+'12'!H33+'13'!H33+'14'!H33+'15'!H33+'16'!H33+'17'!H33+'18'!H33+'19'!H33+'20'!H33+'21'!H33+'22'!H33+'23'!H33+'24'!H33+'25'!H33+'26'!H33+'27'!H33+'28'!H33+'29'!H33+'30'!H33+'31'!H33 -> 18 | I33: 130 | J33: =+'1'!J33+'2'!J33+'3'!J33+'4'!J33+'5'!J33+'6'!J33+'7'!J33+'8'!J33+'9'!J33+'10'!J33+'11'!J33+'12'!J33+'13'!J33+'14'!J33+'15'!J33+'16'!J33+'17'!J33+'18'!J33+'19'!J33+'20'!J33+'21'!J33+'22'!J33+'23'!J33+'24'!J33+'25'!J33+'26'!J33+'27'!J33+'28'!J33+'29'!J33+'30'!J33+'31'!J33 -> 2340 | L33: 29 | M33: =+'29'!K227 -> 7575 | N33: =+'29'!K232 -> 395 | O33: =+'29'!K230 -> 0 | P33: =+'29'!K228 -> 15 | Q33: =+'29'!K231 -> 0 | R33: =+'29'!K229 -> 2700 | S33: =+M33-N33-P33-R33-Q33 -> 4465 | T33: =+'29'!K234 -> 4465 | U33: =+T33-S33 -> 0
A34: 30 | B34: ชิฟฟ่อน สอดไส้ (ญ) 8 ชิ้น รวมรส | C34: =+'1'!C34 -> 0 | D34: =+'1'!D34+'2'!D34+'3'!D34+'4'!D34+'5'!D34+'6'!D34+'7'!D34+'8'!D34+'9'!D58+'10'!D34+'11'!D34+'12'!D34+'13'!D34+'14'!D34+'15'!D34+'16'!D34+'17'!D34+'18'!D34+'19'!D34+'20'!D34+'21'!D34+'22'!D34+'23'!D34+'24'!D34+'25'!D34+'26'!D34+'27'!D34+'28'!D34+'29'!D34+'30'!D34+'31'!D34 -> 0 | E34: =+C34+D34 -> 0 | F34: =+'1'!F34+'2'!F34+'3'!F34+'4'!F34+'5'!F34+'6'!F34+'7'!F34+'8'!F34+'9'!F34+'10'!F34+'11'!F34+'12'!F34+'13'!F34+'14'!F34+'15'!F34+'16'!F34+'17'!F34+'18'!F34+'19'!F34+'20'!F34+'21'!F34+'22'!F34+'23'!F34+'24'!F34+'25'!F34+'26'!F34+'27'!F34+'28'!F34+'29'!F34+'30'!F34+'31'!F34 -> 0 | G34: =E34-F34-H34 -> 0 | H34: =+'1'!H34+'2'!H34+'3'!H34+'4'!H34+'5'!H34+'6'!H34+'7'!H34+'8'!H34+'9'!H34+'10'!H34+'11'!H34+'12'!H34+'13'!H34+'14'!H34+'15'!H34+'16'!H34+'17'!H34+'18'!H34+'19'!H34+'20'!H34+'21'!H34+'22'!H34+'23'!H34+'24'!H34+'25'!H34+'26'!H34+'27'!H34+'28'!H34+'29'!H34+'30'!H34+'31'!H34 -> 0 | I34: 130 | J34: =+'1'!J34+'2'!J34+'3'!J34+'4'!J34+'5'!J34+'6'!J34+'7'!J34+'8'!J34+'9'!J34+'10'!J34+'11'!J34+'12'!J34+'13'!J34+'14'!J34+'15'!J34+'16'!J34+'17'!J34+'18'!J34+'19'!J34+'20'!J34+'21'!J34+'22'!J34+'23'!J34+'24'!J34+'25'!J34+'26'!J34+'27'!J34+'28'!J34+'29'!J34+'30'!J34+'31'!J34 -> 0 | L34: 30 | M34: =+'30'!K222 -> 5920 | N34: =+'30'!K227 -> 677 | O34: =+'30'!K225 -> 0 | P34: =+'30'!K223 -> 15 | Q34: =+'30'!K226 -> 0 | R34: =+'30'!K224 -> 2635 | S34: =+M34-N34-P34-R34-Q34 -> 2593 | T34: =+'30'!K229 -> 2643 | U34: =+T34-S34 -> 50
A35: 31 | B35: ชิฟฟ่อน สอดไส้ (ญ) 8 ชิ้น มะพร้าว | C35: =+'1'!C35 -> 0 | D35: =+'1'!D35+'2'!D35+'3'!D35+'4'!D35+'5'!D35+'6'!D35+'7'!D35+'8'!D35+'9'!D59+'10'!D35+'11'!D35+'12'!D35+'13'!D35+'14'!D35+'15'!D35+'16'!D35+'17'!D35+'18'!D35+'19'!D35+'20'!D35+'21'!D35+'22'!D35+'23'!D35+'24'!D35+'25'!D35+'26'!D35+'27'!D35+'28'!D35+'29'!D35+'30'!D35+'31'!D35 -> 18 | E35: =+C35+D35 -> 18 | F35: =+'1'!F35+'2'!F35+'3'!F35+'4'!F35+'5'!F35+'6'!F35+'7'!F35+'8'!F35+'9'!F35+'10'!F35+'11'!F35+'12'!F35+'13'!F35+'14'!F35+'15'!F35+'16'!F35+'17'!F35+'18'!F35+'19'!F35+'20'!F35+'21'!F35+'22'!F35+'23'!F35+'24'!F35+'25'!F35+'26'!F35+'27'!F35+'28'!F35+'29'!F35+'30'!F35+'31'!F35 -> 0 | G35: =E35-F35-H35 -> 0 | H35: =+'1'!H35+'2'!H35+'3'!H35+'4'!H35+'5'!H35+'6'!H35+'7'!H35+'8'!H35+'9'!H35+'10'!H35+'11'!H35+'12'!H35+'13'!H35+'14'!H35+'15'!H35+'16'!H35+'17'!H35+'18'!H35+'19'!H35+'20'!H35+'21'!H35+'22'!H35+'23'!H35+'24'!H35+'25'!H35+'26'!H35+'27'!H35+'28'!H35+'29'!H35+'30'!H35+'31'!H35 -> 18 | I35: 130 | J35: =+'1'!J35+'2'!J35+'3'!J35+'4'!J35+'5'!J35+'6'!J35+'7'!J35+'8'!J35+'9'!J35+'10'!J35+'11'!J35+'12'!J35+'13'!J35+'14'!J35+'15'!J35+'16'!J35+'17'!J35+'18'!J35+'19'!J35+'20'!J35+'21'!J35+'22'!J35+'23'!J35+'24'!J35+'25'!J35+'26'!J35+'27'!J35+'28'!J35+'29'!J35+'30'!J35+'31'!J35 -> 2340 | L35: 31 | M35: =+'31'!K219 -> 0 | N35: =+'31'!K224 -> 0 | O35: =+'31'!K222 -> 0 | P35: =+'31'!K220 -> 0 | Q35: =+'31'!K223 -> 0 | R35: =+'31'!K221 -> 0 | S35: =+M35-N35-P35-R35-Q35 -> 0 | T35: =+'31'!K226 -> 0 | U35: =+T35-S35 -> 0
A36: 32 | B36: ชิฟฟ่อน 8 ชิ้น มะลิ | C36: =+'1'!C36 -> 0 | D36: =+'1'!D36+'2'!D36+'3'!D36+'4'!D36+'5'!D36+'6'!D36+'7'!D36+'8'!D36+'9'!D60+'10'!D36+'11'!D36+'12'!D36+'13'!D36+'14'!D36+'15'!D36+'16'!D36+'17'!D36+'18'!D36+'19'!D36+'20'!D36+'21'!D36+'22'!D36+'23'!D36+'24'!D36+'25'!D36+'26'!D36+'27'!D36+'28'!D36+'29'!D36+'30'!D36+'31'!D36 -> 0 | E36: =+C36+D36 -> 0 | F36: =+'1'!F36+'2'!F36+'3'!F36+'4'!F36+'5'!F36+'6'!F36+'7'!F36+'8'!F36+'9'!F36+'10'!F36+'11'!F36+'12'!F36+'13'!F36+'14'!F36+'15'!F36+'16'!F36+'17'!F36+'18'!F36+'19'!F36+'20'!F36+'21'!F36+'22'!F36+'23'!F36+'24'!F36+'25'!F36+'26'!F36+'27'!F36+'28'!F36+'29'!F36+'30'!F36+'31'!F36 -> 0 | G36: =E36-F36-H36 -> 0 | H36: =+'1'!H36+'2'!H36+'3'!H36+'4'!H36+'5'!H36+'6'!H36+'7'!H36+'8'!H36+'9'!H36+'10'!H36+'11'!H36+'12'!H36+'13'!H36+'14'!H36+'15'!H36+'16'!H36+'17'!H36+'18'!H36+'19'!H36+'20'!H36+'21'!H36+'22'!H36+'23'!H36+'24'!H36+'25'!H36+'26'!H36+'27'!H36+'28'!H36+'29'!H36+'30'!H36+'31'!H36 -> 0 | I36: 100 | J36: =+'1'!J36+'2'!J36+'3'!J36+'4'!J36+'5'!J36+'6'!J36+'7'!J36+'8'!J36+'9'!J36+'10'!J36+'11'!J36+'12'!J36+'13'!J36+'14'!J36+'15'!J36+'16'!J36+'17'!J36+'18'!J36+'19'!J36+'20'!J36+'21'!J36+'22'!J36+'23'!J36+'24'!J36+'25'!J36+'26'!J36+'27'!J36+'28'!J36+'29'!J36+'30'!J36+'31'!J36 -> 0 | L36: รวม | M36: =SUM(M5:M35) -> 127495 | N36: =SUM(N5:N35) -> 8791 | O36: =SUM(O5:O35) -> 0 | P36: =SUM(P5:P35) -> 450 | Q36: =SUM(Q5:Q35) -> 0 | R36: =SUM(R5:R35) -> 38085 | S36: =SUM(S5:S35) -> 80169 | T36: =SUM(T5:T35) -> 80239 | U36: =SUM(U5:U35) -> 70
A37: 33 | B37: ชิฟฟ่อนรวมรส ยอดฮิต 8 ชิ้น | C37: =+'1'!C37 -> 15 | D37: =+'1'!D37+'2'!D37+'3'!D37+'4'!D37+'5'!D37+'6'!D37+'7'!D37+'8'!D37+'9'!D61+'10'!D37+'11'!D37+'12'!D37+'13'!D37+'14'!D37+'15'!D37+'16'!D37+'17'!D37+'18'!D37+'19'!D37+'20'!D37+'21'!D37+'22'!D37+'23'!D37+'24'!D37+'25'!D37+'26'!D37+'27'!D37+'28'!D37+'29'!D37+'30'!D37+'31'!D37 -> 165 | E37: =+C37+D37 -> 180 | F37: =+'1'!F37+'2'!F37+'3'!F37+'4'!F37+'5'!F37+'6'!F37+'7'!F37+'8'!F37+'9'!F37+'10'!F37+'11'!F37+'12'!F37+'13'!F37+'14'!F37+'15'!F37+'16'!F37+'17'!F37+'18'!F37+'19'!F37+'20'!F37+'21'!F37+'22'!F37+'23'!F37+'24'!F37+'25'!F37+'26'!F37+'27'!F37+'28'!F37+'29'!F37+'30'!F37+'31'!F37 -> 9 | G37: =E37-F37-H37 -> 1 | H37: =+'1'!H37+'2'!H37+'3'!H37+'4'!H37+'5'!H37+'6'!H37+'7'!H37+'8'!H37+'9'!H37+'10'!H37+'11'!H37+'12'!H37+'13'!H37+'14'!H37+'15'!H37+'16'!H37+'17'!H37+'18'!H37+'19'!H37+'20'!H37+'21'!H37+'22'!H37+'23'!H37+'24'!H37+'25'!H37+'26'!H37+'27'!H37+'28'!H37+'29'!H37+'30'!H37+'31'!H37 -> 170 | I37: 100 | J37: =+'1'!J37+'2'!J37+'3'!J37+'4'!J37+'5'!J37+'6'!J37+'7'!J37+'8'!J37+'9'!J37+'10'!J37+'11'!J37+'12'!J37+'13'!J37+'14'!J37+'15'!J37+'16'!J37+'17'!J37+'18'!J37+'19'!J37+'20'!J37+'21'!J37+'22'!J37+'23'!J37+'24'!J37+'25'!J37+'26'!J37+'27'!J37+'28'!J37+'29'!J37+'30'!J37+'31'!J37 -> 17000
A38: 34 | B38: ครีมฮอร์น วนิลา | C38: =+'1'!C38 -> 10 | D38: =+'1'!D38+'2'!D38+'3'!D38+'4'!D38+'5'!D38+'6'!D38+'7'!D38+'8'!D38+'9'!D62+'10'!D38+'11'!D38+'12'!D38+'13'!D38+'14'!D38+'15'!D38+'16'!D38+'17'!D38+'18'!D38+'19'!D38+'20'!D38+'21'!D38+'22'!D38+'23'!D38+'24'!D38+'25'!D38+'26'!D38+'27'!D38+'28'!D38+'29'!D38+'30'!D38+'31'!D38 -> 60 | E38: =+C38+D38 -> 70 | F38: =+'1'!F38+'2'!F38+'3'!F38+'4'!F38+'5'!F38+'6'!F38+'7'!F38+'8'!F38+'9'!F38+'10'!F38+'11'!F38+'12'!F38+'13'!F38+'14'!F38+'15'!F38+'16'!F38+'17'!F38+'18'!F38+'19'!F38+'20'!F38+'21'!F38+'22'!F38+'23'!F38+'24'!F38+'25'!F38+'26'!F38+'27'!F38+'28'!F38+'29'!F38+'30'!F38+'31'!F38 -> 0 | G38: =E38-F38-H38 -> 3 | H38: =+'1'!H38+'2'!H38+'3'!H38+'4'!H38+'5'!H38+'6'!H38+'7'!H38+'8'!H38+'9'!H38+'10'!H38+'11'!H38+'12'!H38+'13'!H38+'14'!H38+'15'!H38+'16'!H38+'17'!H38+'18'!H38+'19'!H38+'20'!H38+'21'!H38+'22'!H38+'23'!H38+'24'!H38+'25'!H38+'26'!H38+'27'!H38+'28'!H38+'29'!H38+'30'!H38+'31'!H38 -> 67 | I38: 50 | J38: =+'1'!J38+'2'!J38+'3'!J38+'4'!J38+'5'!J38+'6'!J38+'7'!J38+'8'!J38+'9'!J38+'10'!J38+'11'!J38+'12'!J38+'13'!J38+'14'!J38+'15'!J38+'16'!J38+'17'!J38+'18'!J38+'19'!J38+'20'!J38+'21'!J38+'22'!J38+'23'!J38+'24'!J38+'25'!J38+'26'!J38+'27'!J38+'28'!J38+'29'!J38+'30'!J38+'31'!J38 -> 3350
A39: 35 | B39: ครีมฮอร์น ใบเตย | C39: =+'1'!C39 -> 9 | D39: =+'1'!D39+'2'!D39+'3'!D39+'4'!D39+'5'!D39+'6'!D39+'7'!D39+'8'!D39+'9'!D63+'10'!D39+'11'!D39+'12'!D39+'13'!D39+'14'!D39+'15'!D39+'16'!D39+'17'!D39+'18'!D39+'19'!D39+'20'!D39+'21'!D39+'22'!D39+'23'!D39+'24'!D39+'25'!D39+'26'!D39+'27'!D39+'28'!D39+'29'!D39+'30'!D39+'31'!D39 -> 35 | E39: =+C39+D39 -> 44 | F39: =+'1'!F39+'2'!F39+'3'!F39+'4'!F39+'5'!F39+'6'!F39+'7'!F39+'8'!F39+'9'!F39+'10'!F39+'11'!F39+'12'!F39+'13'!F39+'14'!F39+'15'!F39+'16'!F39+'17'!F39+'18'!F39+'19'!F39+'20'!F39+'21'!F39+'22'!F39+'23'!F39+'24'!F39+'25'!F39+'26'!F39+'27'!F39+'28'!F39+'29'!F39+'30'!F39+'31'!F39 -> 1 | G39: =E39-F39-H39 -> 9 | H39: =+'1'!H39+'2'!H39+'3'!H39+'4'!H39+'5'!H39+'6'!H39+'7'!H39+'8'!H39+'9'!H39+'10'!H39+'11'!H39+'12'!H39+'13'!H39+'14'!H39+'15'!H39+'16'!H39+'17'!H39+'18'!H39+'19'!H39+'20'!H39+'21'!H39+'22'!H39+'23'!H39+'24'!H39+'25'!H39+'26'!H39+'27'!H39+'28'!H39+'29'!H39+'30'!H39+'31'!H39 -> 34 | I39: 50 | J39: =+'1'!J39+'2'!J39+'3'!J39+'4'!J39+'5'!J39+'6'!J39+'7'!J39+'8'!J39+'9'!J39+'10'!J39+'11'!J39+'12'!J39+'13'!J39+'14'!J39+'15'!J39+'16'!J39+'17'!J39+'18'!J39+'19'!J39+'20'!J39+'21'!J39+'22'!J39+'23'!J39+'24'!J39+'25'!J39+'26'!J39+'27'!J39+'28'!J39+'29'!J39+'30'!J39+'31'!J39 -> 1700
A40: 36 | B40: ครีมฮอร์น ช็อคโกแลต | C40: =+'1'!C40 -> 8 | D40: =+'1'!D40+'2'!D40+'3'!D40+'4'!D40+'5'!D40+'6'!D40+'7'!D40+'8'!D40+'9'!D64+'10'!D40+'11'!D40+'12'!D40+'13'!D40+'14'!D40+'15'!D40+'16'!D40+'17'!D40+'18'!D40+'19'!D40+'20'!D40+'21'!D40+'22'!D40+'23'!D40+'24'!D40+'25'!D40+'26'!D40+'27'!D40+'28'!D40+'29'!D40+'30'!D40+'31'!D40 -> 50 | E40: =+C40+D40 -> 58 | F40: =+'1'!F40+'2'!F40+'3'!F40+'4'!F40+'5'!F40+'6'!F40+'7'!F40+'8'!F40+'9'!F40+'10'!F40+'11'!F40+'12'!F40+'13'!F40+'14'!F40+'15'!F40+'16'!F40+'17'!F40+'18'!F40+'19'!F40+'20'!F40+'21'!F40+'22'!F40+'23'!F40+'24'!F40+'25'!F40+'26'!F40+'27'!F40+'28'!F40+'29'!F40+'30'!F40+'31'!F40 -> 0 | G40: =E40-F40-H40 -> 18 | H40: =+'1'!H40+'2'!H40+'3'!H40+'4'!H40+'5'!H40+'6'!H40+'7'!H40+'8'!H40+'9'!H40+'10'!H40+'11'!H40+'12'!H40+'13'!H40+'14'!H40+'15'!H40+'16'!H40+'17'!H40+'18'!H40+'19'!H40+'20'!H40+'21'!H40+'22'!H40+'23'!H40+'24'!H40+'25'!H40+'26'!H40+'27'!H40+'28'!H40+'29'!H40+'30'!H40+'31'!H40 -> 40 | I40: 50 | J40: =+'1'!J40+'2'!J40+'3'!J40+'4'!J40+'5'!J40+'6'!J40+'7'!J40+'8'!J40+'9'!J40+'10'!J40+'11'!J40+'12'!J40+'13'!J40+'14'!J40+'15'!J40+'16'!J40+'17'!J40+'18'!J40+'19'!J40+'20'!J40+'21'!J40+'22'!J40+'23'!J40+'24'!J40+'25'!J40+'26'!J40+'27'!J40+'28'!J40+'29'!J40+'30'!J40+'31'!J40 -> 2000
A41: 37 | B41: เบาหวิว (ล) ใหม่ รสกล้วยหอมมะพร้าวเผา | C41: =+'1'!C41 -> 0 | D41: =+'1'!D41+'2'!D41+'3'!D41+'4'!D41+'5'!D41+'6'!D41+'7'!D41+'8'!D41+'9'!D65+'10'!D41+'11'!D41+'12'!D41+'13'!D41+'14'!D41+'15'!D41+'16'!D41+'17'!D41+'18'!D41+'19'!D41+'20'!D41+'21'!D41+'22'!D41+'23'!D41+'24'!D41+'25'!D41+'26'!D41+'27'!D41+'28'!D41+'29'!D41+'30'!D41+'31'!D41 -> 25 | E41: =+C41+D41 -> 25 | F41: =+'1'!F41+'2'!F41+'3'!F41+'4'!F41+'5'!F41+'6'!F41+'7'!F41+'8'!F41+'9'!F41+'10'!F41+'11'!F41+'12'!F41+'13'!F41+'14'!F41+'15'!F41+'16'!F41+'17'!F41+'18'!F41+'19'!F41+'20'!F41+'21'!F41+'22'!F41+'23'!F41+'24'!F41+'25'!F41+'26'!F41+'27'!F41+'28'!F41+'29'!F41+'30'!F41+'31'!F41 -> 0 | G41: =E41-F41-H41 -> 5 | H41: =+'1'!H41+'2'!H41+'3'!H41+'4'!H41+'5'!H41+'6'!H41+'7'!H41+'8'!H41+'9'!H41+'10'!H41+'11'!H41+'12'!H41+'13'!H41+'14'!H41+'15'!H41+'16'!H41+'17'!H41+'18'!H41+'19'!H41+'20'!H41+'21'!H41+'22'!H41+'23'!H41+'24'!H41+'25'!H41+'26'!H41+'27'!H41+'28'!H41+'29'!H41+'30'!H41+'31'!H41 -> 20 | I41: 50 | J41: =+'1'!J41+'2'!J41+'3'!J41+'4'!J41+'5'!J41+'6'!J41+'7'!J41+'8'!J41+'9'!J41+'10'!J41+'11'!J41+'12'!J41+'13'!J41+'14'!J41+'15'!J41+'16'!J41+'17'!J41+'18'!J41+'19'!J41+'20'!J41+'21'!J41+'22'!J41+'23'!J41+'24'!J41+'25'!J41+'26'!J41+'27'!J41+'28'!J41+'29'!J41+'30'!J41+'31'!J41 -> 1000
...

Sheet ยกมา
A2: บูธ ปตท.ราชบุรี วันที่ 1-31/05/2567 | O2: สินค้า SALE
A3: ลำดับ | B3: รายการ | C3: ยกมา | D3: รับ | E3: รวม | F3: เปลี่ยน/ | G3: คงเหลือ | H3: รายการขาย | K3: หมายเหตุ | L3: ส่วนลด | O3: ลำดับ | P3: รายการ | Q3: ยกมา | R3: รับ | S3: รวม | T3: เปลี่ยน/ | U3: คงเหลือ | V3: รายการขาย | Y3: หมายเหตุ | Z3: ส่วนลด
F4: คืน/เสีย | H4: จำนวน | I4: @ | J4: เป็นเงิน | T4: คืน/เสีย | V4: จำนวน | W4: @ | X4: เป็นเงิน
A5: 1 | B5: ชิฟฟ่อน (ล) | C5: =+'[1]30'!G5 -> 32 | D5: 0 | E5: =C5+D5 -> 32 | F5: 0 | G5: =E5-F5-H5 -> 31 | H5: 1 | I5: 50 | J5: =+I5*H5 -> 50 | K5: - | L5: 0 | M5: =+J5-L5 -> 50 | O5: 1 | Q5: 0 | R5: 0 | S5: =Q5+R5 -> 0 | T5: 0 | U5: =S5-T5-V5 -> 0 | V5: 0 | X5: =+W5*V5 -> 0 | Y5: - | Z5: 0
A6: 2 | B6: ชิฟฟ่อน (ญ) | C6: =+'[1]30'!G6 -> 76 | D6: 0 | E6: =C6+D6 -> 76 | F6: 0 | G6: =E6-F6-H6 -> 61 | H6: 15 | I6: 100 | J6: =+I6*H6 -> 1500 | K6: 3กล่อง250=4 | L6: 200 | M6: =+J6-L6 -> 1300 | O6: 2 | Q6: 0 | R6: 0 | S6: =Q6+R6 -> 0 | T6: 0 | U6: =S6-T6-V6 -> 0 | V6: 0 | X6: =+W6*V6 -> 0 | Y6: - | Z6: 0
A7: 3 | B7: ชิฟฟ่อน (ล) กาแฟ | C7: =+'[1]30'!G7 -> 0 | D7: 0 | E7: =C7+D7 -> 0 | F7: 0 | G7: =E7-F7-H7 -> 0 | H7: 0 | I7: 50 | J7: =+I7*H7 -> 0 | K7: - | L7: 0 | M7: =+J7-L7 -> 0 | O7: 3 | Q7: 0 | R7: 0 | S7: =Q7+R7 -> 0 | T7: 0 | U7: =S7-T7-V7 -> 0 | V7: 0 | X7: =+W7*V7 -> 0 | Y7: - | Z7: 0
A8: 4 | B8: ชิฟฟ่อน (ญ) กาแฟ | C8: =+'[1]30'!G8 -> 0 | D8: 0 | E8: =C8+D8 -> 0 | F8: 0 | G8: =E8-F8-H8 -> 0 | H8: 0 | I8: 100 | J8: =+I8*H8 -> 0 | K8: - | L8: 0 | M8: =+J8-L8 -> 0 | O8: 4 | Q8: 0 | R8: 0 | S8: =Q8+R8 -> 0 | T8: 0 | U8: =S8-T8-V8 -> 0 | V8: 0 | X8: =+W8*V8 -> 0 | Y8: - | Z8: 0
A9: 5 | B9: ชิฟฟ่อนเค้ก 1 ชิ้น | C9: =+'[1]30'!G9 -> 0 | D9: 0 | E9: =C9+D9 -> 0 | F9: 0 | G9: =E9-F9-H9 -> 0 | H9: 0 | I9: 10 | J9: =+I9*H9 -> 0 | K9: - | L9: 0 | M9: =+J9-L9 -> 0 | O9: 5 | Q9: 0 | R9: 0 | S9: =Q9+R9 -> 0 | T9: 0 | U9: =S9-T9-V9 -> 0 | V9: 0 | X9: =+W9*V9 -> 0 | Y9: - | Z9: 0
A10: 6 | B10: ชิฟฟ่อนเค้กสอดไส้แยม 1 ชิ้น | C10: =+'[1]30'!G10 -> 0 | D10: 0 | E10: =C10+D10 -> 0 | F10: 0 | G10: =E10-F10-H10 -> 0 | H10: 0 | I10: 12 | J10: =+I10*H10 -> 0 | K10: - | L10: 0 | M10: =+J10-L10 -> 0 | O10: 6 | Q10: 0 | R10: 0 | S10: =Q10+R10 -> 0 | T10: 0 | U10: =S10-T10-V10 -> 0 | V10: 0 | X10: =+W10*V10 -> 0 | Y10: - | Z10: 0
A11: 7 | B11: ชิฟฟ่อน สอดไส้ (ล) 2 ชิ้น ครีมมะพร้าว | C11: =+'[1]30'!G11 -> 0 | D11: 0 | E11: =C11+D11 -> 0 | F11: 0 | G11: =E11-F11-H11 -> 0 | H11: 0 | I11: 40 | J11: =+I11*H11 -> 0 | K11: - | L11: 0 | M11: =+J11-L11 -> 0 | O11: 7 | Q11: 0 | R11: 0 | S11: =Q11+R11 -> 0 | T11: 0 | U11: =S11-T11-V11 -> 0 | V11: 0 | X11: =+W11*V11 -> 0 | Y11: - | Z11: 0
A12: 8 | B12: ชิฟฟ่อน สอดไส้ (ล) 3 ชิ้น รวมรส | C12: =+'[1]30'!G12 -> 7 | D12: 0 | E12: =C12+D12 -> 7 | F12: 0 | G12: =E12-F12-H12 -> 7 | H12: 0 | I12: 50 | J12: =+I12*H12 -> 0 | K12: - | L12: 0 | M12: =+J12-L12 -> 0 | O12: 8 | Q12: 0 | R12: 0 | S12: =Q12+R12 -> 0 | T12: 0 | U12: =S12-T12-V12 -> 0 | V12: 0 | X12: =+W12*V12 -> 0 | Y12: - | Z12: 0
A13: 9 | B13: ชิฟฟ่อน สอดไส้ (ล) 3 ชิ้น เมล่อน | C13: =+'[1]30'!G13 -> 0 | D13: 0 | E13: =C13+D13 -> 0 | F13: 0 | G13: =E13-F13-H13 -> 0 | H13: 0 | I13: 55 | J13: =+I13*H13 -> 0 | K13: - | L13: 0 | M13: =+J13-L13 -> 0 | O13: 9 | Q13: 0 | R13: 0 | S13: =Q13+R13 -> 0 | T13: 0 | U13: =S13-T13-V13 -> 0 | V13: 0 | X13: =+W13*V13 -> 0 | Y13: - | Z13: 0
A14: 10 | B14: ชิฟฟ่อน สอดไส้ (ล) 4 ชิ้น ครีมมะพร้าว | C14: =+'[1]30'!G14 -> 0 | D14: 0 | E14: =C14+D14 -> 0 | F14: 0 | G14: =E14-F14-H14 -> 0 | H14: 0 | I14: 65 | J14: =+I14*H14 -> 0 | K14: - | L14: 0 | M14: =+J14-L14 -> 0 | O14: 10 | Q14: 0 | R14: 0 | S14: =Q14+R14 -> 0 | T14: 0 | U14: =S14-T14-V14 -> 0 | V14: 0 | X14: =+W14*V14 -> 0 | Y14: - | Z14: 0
A15: 11 | B15: ชิฟฟ่อน สอดไส้ (ล) 3 ชิ้น แยมส้ม | C15: =+'[1]30'!G15 -> 0 | D15: 0 | E15: =C15+D15 -> 0 | F15: 0 | G15: =E15-F15-H15 -> 0 | H15: 0 | I15: 50 | J15: =+I15*H15 -> 0 | K15: - | L15: 0 | M15: =+J15-L15 -> 0 | O15: 11 | Q15: 0 | R15: 0 | S15: =Q15+R15 -> 0 | T15: 0 | U15: =S15-T15-V15 -> 0 | V15: 0 | X15: =+W15*V15 -> 0 | Y15: - | Z15: 0
A16: 12 | B16: ชิฟฟ่อน สอดไส้ (ล) 3 ชิ้น บลูเบอรี่ | C16: =+'[1]30'!G16 -> 0 | D16: 0 | E16: =C16+D16 -> 0 | F16: 0 | G16: =E16-F16-H16 -> 0 | H16: 0 | I16: 50 | J16: =+I16*H16 -> 0 | K16: - | L16: 0 | M16: =+J16-L16 -> 0 | O16: 12 | Q16: 0 | R16: 0 | S16: =Q16+R16 -> 0 | T16: 0 | U16: =S16-T16-V16 -> 0 | V16: 0 | X16: =+W16*V16 -> 0 | Y16: - | Z16: 0
... A103: 99 | B103: ไดฟุกุ 8 ชิ้น | C103: =+'[1]30'!G103 -> 0 | D103: 0 | E103: =C103+D103 -> 0 | F103: 0 | G103: =E103-F103-H103 -> 0 | H103: 0 | I103: 100 | J103: =+I103*H103 -> 0 | K103: - | L103: 0 | M103: =+J103-L103 -> 0 | O103: 99 | Q103: 0 | R103: 0 | S103: =Q103+R103 -> 0 | T103: 0 | U103: =S103-T103-V103 -> 0 | V103: 0 | X103: =+W103*V103 -> 0 | Y103: - | Z103: 0
A104: 100 | B104: หมูทุบ | C104: =+'[1]30'!G104 -> 0 | D104: 0 | E104: =C104+D104 -> 0 | F104: 0 | G104: =E104-F104-H104 -> 0 | H104: 0 | I104: 100 | J104: =+I104*H104 -> 0 | K104: - | L104: 0 | M104: =+J104-L104 -> 0 | O104: 100 | Q104: 0 | R104: 0 | S104: =Q104+R104 -> 0 | T104: 0 | U104: =S104-T104-V104 -> 0 | V104: 0 | X104: =+W104*V104 -> 0 | Z104: 0
A105: 101 | B105: ดอกจอก | C105: =+'[1]30'!G105 -> 0 | D105: 0 | E105: =C105+D105 -> 0 | F105: 0 | G105: =E105-F105-H105 -> 0 | H105: 0 | I105: 30 | J105: =+I105*H105 -> 0 | K105: - | L105: 0 | M105: =+J105-L105 -> 0 | Z105: =SUM(Z5:Z104) -> 0
A106: 102 | B106: เทียน | C106: =+'[1]30'!G106 -> 0 | D106: 0 | E106: =C106+D106 -> 0 | F106: 0 | G106: =E106-F106-H106 -> 0 | H106: 0 | I106: 20 | J106: =+I106*H106 -> 0 | K106: - | L106: 0 | M106: =+J106-L106 -> 0
