Workbook

Sheet ก.พ.
A1: ยอดขายออนไลน์ ตามจำนวนชิ้น | F1: =SUM(F4:F109) -> 350398.32 | G1: =SUM(G4:G115) -> 3168 | H1: =SUM(H4:H115) -> 1948 | I1: =SUM(I4:I115) -> 2587 | J1: =SUM(J4:J115) -> 4306 | K1: =SUM(K4:K115) -> 0 | L1: =SUM(L4:L115) -> 1433 | M1: =SUM(M4:M115) -> 13442 | N1: =SUM(N4:N115) -> 12009 | ... HW1: =SUM(HW4:HW115) -> 0
A2: NO. | B2: รหัสสินค้า | C2: ชื่อสินค้า | D2: หน่วย | E2: ราคาต้นทุน / หน่วย | F2: รวมต้นทุน | G2: ยอดรวม กุมภาพันธ์ 2568 | O2: 243984 | V2: 243985 | AC2: 243986 | AJ2: 243987 | AQ2: 243988 | AX2: 243989 | BE2: 243990 | BL2: 243991 | BS2: 243992 | BZ2: 243993 | CG2: 243994 | CN2: 243995 | CU2: 243996 | DB2: 243997 | DI2: 243998 | DP2: 243999 | DW2: 244000 | ED2: 244001 | EK2: 244002 | ER2: 244003 | EY2: 244004 | FF2: 244005 | FM2: 244006 | FT2: 244007 | GA2: 244008 | GH2: 244009 | GO2: 244010 | GV2: 244011 | HC2: 244012 | HJ2: 244013 | HQ2: 244014
G3: ปณ | H3: Shopee | I3: Lazada | J3: Tiktok | K3: Lazchoice | L3: ยอดเส้น | M3: Total | N3: Total แพลตฟอร์ม | O3: ปณ | P3: Shopee | Q3: Lazada | R3: Tiktok | S3: Lazchoice | T3: ยอดเส้น | U3: Total | V3: ปณ | W3: Shopee | X3: Lazada | Y3: Tiktok | Z3: Lazchoice | AA3: ยอดเส้น | AB3: Total | AC3: ปณ | AD3: Shopee | AE3: Lazada | AF3: Tiktok | AG3: Lazchoice | AH3: ยอดเส้น | AI3: Total | AJ3: ปณ | AK3: Shopee | AL3: Lazada | AM3: Tiktok | AN3: Lazchoice | AO3: ยอดเส้น | AP3: Total | AQ3: ปณ | AR3: Shopee | AS3: Lazada | AT3: Tiktok | AU3: Lazchoice | AV3: ยอดเส้น | AW3: Total | AX3: ปณ | AY3: Shopee | AZ3: Lazada | BA3: Tiktok | BB3: Lazchoice | BC3: ยอดเส้น | BD3: Total | BE3: ปณ | BF3: Shopee | BG3: Lazada | BH3: Tiktok | BI3: Lazchoice | BJ3: ยอดเส้น | BK3: Total | BL3: ปณ | BM3: Shopee | BN3: Lazada | BO3: Tiktok | BP3: Lazchoice | BQ3: ยอดเส้น | BR3: Total | BS3: ปณ | BT3: Shopee | BU3: Lazada | BV3: Tiktok | BW3: Lazchoice | BX3: ยอดเส้น | BY3: Total | BZ3: ปณ | CA3: Shopee | CB3: Lazada | CC3: Tiktok | CD3: Lazchoice | CE3: ยอดเส้น | CF3: Total | CG3: ปณ | CH3: Shopee | CI3: Lazada | CJ3: Tiktok | CK3: Lazchoice | CL3: ยอดเส้น | CM3: Total | CN3: ปณ | CO3: Shopee | CP3: Lazada | CQ3: Tiktok | CR3: Lazchoice | CS3: ยอดเส้น | CT3: Total | CU3: ปณ | CV3: Shopee | CW3: Lazada | CX3: Tiktok | CY3: Lazchoice | CZ3: ยอดเส้น | DA3: Total | DB3: ปณ | DC3: Shopee | DD3: Lazada | DE3: Tiktok | DF3: Lazchoice | DG3: ยอดเส้น | DH3: Total | DI3: ปณ | DJ3: Shopee | DK3: Lazada | DL3: Tiktok | DM3: Lazchoice | DN3: ยอดเส้น | DO3: Total | DP3: ปณ | DQ3: Shopee | DR3: Lazada | DS3: Tiktok | DT3: Lazchoice | DU3: ยอดเส้น | DV3: Total | DW3: ปณ | DX3: Shopee | DY3: Lazada | DZ3: Tiktok | EA3: Lazchoice | EB3: ยอดเส้น | EC3: Total | ED3: ปณ | EE3: Shopee | EF3: Lazada | EG3: Tiktok | EH3: Lazchoice | EI3: ยอดเส้น | EJ3: Total | EK3: ปณ | EL3: Shopee | EM3: Lazada | EN3: Tiktok | EO3: Lazchoice | EP3: ยอดเส้น | EQ3: Total | ER3: ปณ | ES3: Shopee | ET3: Lazada | EU3: Tiktok | EV3: Lazchoice | EW3: ยอดเส้น | EX3: Total | EY3: ปณ | EZ3: Shopee | FA3: Lazada | FB3: Tiktok | FC3: Lazchoice | FD3: ยอดเส้น | FE3: Total | FF3: ปณ | FG3: Shopee | FH3: Lazada | FI3: Tiktok | FJ3: Lazchoice | FK3: ยอดเส้น | FL3: Total | FM3: ปณ | FN3: Shopee | FO3: Lazada | FP3: Tiktok | FQ3: Lazchoice | FR3: ยอดเส้น | FS3: Total | FT3: ปณ | FU3: Shopee | FV3: Lazada | FW3: Tiktok | FX3: Lazchoice | FY3: ยอดเส้น | FZ3: Total | GA3: ปณ | GB3: Shopee | GC3: Lazada | GD3: Tiktok | GE3: Lazchoice | GF3: ยอดเส้น | GG3: Total | GH3: ปณ | GI3: Shopee | GJ3: Lazada | GK3: Tiktok | GL3: Lazchoice | GM3: ยอดเส้น | GN3: Total | GO3: ปณ | GP3: Shopee | GQ3: Lazada | GR3: Tiktok | GS3: Lazchoice | GT3: ยอดเส้น | GU3: Total | GV3: ปณ | GW3: Shopee | GX3: Lazada | GY3: Tiktok | GZ3: Lazchoice | HA3: ยอดเส้น | HB3: Total | HC3: ปณ | HD3: Shopee | HE3: Lazada | HF3: Tiktok | HG3: Lazchoice | HH3: ยอดเส้น | HI3: Total | HJ3: ปณ | HK3: Shopee | HL3: Lazada | HM3: Tiktok | HN3: Lazchoice | HO3: ยอดเส้น | HP3: Total | HQ3: ปณ | HR3: Shopee | HS3: Lazada | HT3: Tiktok | HU3: Lazchoice | HV3: ยอดเส้น | HW3: Total
A4: 1 | B4: 1111002 | C4: ชิฟฟอนรวมรส 8 ชิ้น | D4: กล่อง | E4: 37.17 | F4: =+M4*E4 -> 133626.15 | G4: =+O4+V4+AC4+AJ4+AQ4+AX4+BE4+BL4+BS4+BZ4+CG4+CN4+CU4+DB4+DI4+DP4+DW4+ED4+EK4+ER4+EY4+FF4+FM4+FT4+GA4+GH4+GO4+GV4+HC4+HJ4+HQ4 -> 849 | H4: =+P4+W4+AD4+AK4+AR4+AY4+BF4+BM4+BT4+CA4+CH4+CO4+CV4+DC4+DJ4+DQ4+DX4+EE4+EL4+ES4+EZ4+FG4+FN4+FU4+GB4+GI4+GP4+GW4+HD4+HK4+HR4 -> 725 | I4: =+Q4+X4+AE4+AL4+AS4+AZ4+BG4+BN4+BU4+CB4+CI4+CP4+CW4+DD4+DK4+DR4+DY4+EF4+EM4+ET4+FA4+FH4+FO4+FV4+GC4+GJ4+GQ4+GX4+HE4+HL4+HS4 -> 1150 | J4: =+R4+Y4+AF4+AM4+AT4+BA4+BH4+BO4+BV4+CC4+CJ4+CQ4+CX4+DE4+DL4+DS4+DZ4+EG4+EN4+EU4+FB4+FI4+FP4+FW4+GD4+GK4+GR4+GY4+HF4+HM4+HT4 -> 578 | K4: =+S4+Z4+AG4+AN4+AU4+BB4+BI4+BP4+BW4+CD4+CK4+CR4+CY4+DF4+DM4+DT4+EA4+EH4+EO4+EV4+FC4+FJ4+FQ4+FX4+GE4+GL4+GS4+GZ4+HG4+HN4+HU4 -> 0 | L4: =+T4+AA4+AH4+AO4+AV4+BC4+BJ4+BQ4+BX4+CE4+CL4+CS4+CZ4+DG4+DN4+DU4+EB4+EI4+EP4+EW4+FD4+FK4+FR4+FY4+GF4+GM4+GT4+HA4+HH4+HO4+HV4 -> 293 | M4: =SUM(G4:L4) -> 3595 | N4: =+G4+H4+I4+J4+K4 -> 3302 | O4: =IFERROR(VLOOKUP(B4,'1ไม่มียอด'!B:D,3,0),"0") -> 0 | P4: =IFERROR(VLOOKUP(B4,'1ไม่มียอด'!B:E,4,0),"0") -> 0 | Q4: =IFERROR(VLOOKUP(B4,'1ไม่มียอด'!B:F,5,0),"0") -> 0 | R4: =IFERROR(VLOOKUP(B4,'1ไม่มียอด'!B:G,6,0),"0") -> 0 | S4: =IFERROR(VLOOKUP(B4,'1ไม่มียอด'!B:J,9,0),"0") -> 0 | T4: =IFERROR(VLOOKUP(B4,'1ไม่มียอด'!B:K,10,0),"0") -> 0 | U4: =SUM(O4:T4) -> 0 | V4: =IFERROR(VLOOKUP(B4,#REF!,3,0),"0") -> 0 | W4: =IFERROR(VLOOKUP(B4,#REF!,4,0),"0") -> 0 | X4: =IFERROR(VLOOKUP(B4,#REF!,5,0),"0") -> 0 | Y4: =IFERROR(VLOOKUP(B4,#REF!,9,0),"0") -> 0 | Z4: =IFERROR(VLOOKUP(B4,#REF!,10,0),"0") -> 0 | AA4: =IFERROR(VLOOKUP(B4,#REF!,11,0),"0") -> 0 | AB4: =SUM(V4:AA4) -> 0 | AC4: =IFERROR(VLOOKUP(B4,'3'!B:D,3,0),"0") -> 16 | AD4: =IFERROR(VLOOKUP(B4,'3'!B:E,4,0),"0") -> 50 | AE4: =IFERROR(VLOOKUP(B4,'3'!B:F,5,0),"0") -> 1 | AF4: =IFERROR(VLOOKUP(B4,'3'!B:J,9,0),"0") -> 32 | AG4: =IFERROR(VLOOKUP(B4,'3'!B:K,10,0),"0") -> 0 | AH4: =IFERROR(VLOOKUP(B4,'3'!B:L,11,0),"0") -> 0 | AI4: =SUM(AC4:AH4) -> 99 | AJ4: =IFERROR(VLOOKUP(B4,'4'!B:D,3,0),"0") -> 8 | AK4: =IFERROR(VLOOKUP(B4,'4'!B:E,4,0),"0") -> 20 | AL4: =IFERROR(VLOOKUP(B4,'4'!B:F,5,0),"0") -> 20 | AM4: =IFERROR(VLOOKUP(B4,'4'!B:J,9,0),"0") -> 28 | AN4: =IFERROR(VLOOKUP(B4,'4'!B:K,10,0),"0") -> 0 | AO4: =IFERROR(VLOOKUP(B4,'4'!B:L,11,0),"0") -> 0 | AP4: =SUM(AJ4:AO4) -> 76 | AQ4: =IFERROR(VLOOKUP(B4,'5'!B:D,3,0),"0") -> 86 | AR4: =IFERROR(VLOOKUP(B4,'5'!B:E,4,0),"0") -> 30 | AS4: =IFERROR(VLOOKUP(B4,'5'!B:F,5,0),"0") -> 14 | AT4: =IFERROR(VLOOKUP(B4,'5'!B:J,9,0),"0") -> 10 | AU4: =IFERROR(VLOOKUP(B4,'5'!B:K,10,0),"0") -> 0 | AV4: =IFERROR(VLOOKUP(B4,'5'!B:L,11,0),"0") -> 15 | AW4: =SUM(AQ4:AV4) -> 155 | AX4: =IFERROR(VLOOKUP(B4,'6'!B:D,3,0),"0") -> 11 | AY4: =IFERROR(VLOOKUP(B4,'6'!B:E,4,0),"0") -> 54 | AZ4: =IFERROR(VLOOKUP(B4,'6'!B:F,5,0),"0") -> 1 | BA4: =IFERROR(VLOOKUP(B4,'6'!B:J,9,0),"0") -> 29 | BB4: =IFERROR(VLOOKUP(B4,'6'!B:K,10,0),"0") -> 0 | BC4: =IFERROR(VLOOKUP(B4,'6'!B:L,11,0),"0") -> 10 | BD4: =SUM(AX4:BC4) -> 105 | BE4: =IFERROR(VLOOKUP(B4,'7'!B:D,3,0),"0") -> 103 | BF4: =IFERROR(VLOOKUP(B4,'7'!B:E,4,0),"0") -> 31 | BG4: =IFERROR(VLOOKUP(B4,'7'!B:F,5,0),"0") -> 7 | BH4: =IFERROR(VLOOKUP(B4,'7'!B:J,9,0),"0") -> 11 | BI4: =IFERROR(VLOOKUP(B4,'7'!B:K,10,0),"0") -> 0 | BJ4: =IFERROR(VLOOKUP(B4,'7'!B:L,11,0),"0") -> 12 | BK4: =SUM(BE4:BJ4) -> 164 | BL4: =IFERROR(VLOOKUP(B4,'8'!B:D,3,0),"0") -> 93 | BM4: =IFERROR(VLOOKUP(B4,'8'!B:E,4,0),"0") -> 13 | BN4: =IFERROR(VLOOKUP(B4,'8'!B:F,5,0),"0") -> 36 | BO4: =IFERROR(VLOOKUP(B4,'8'!B:J,9,0),"0") -> 35 | BP4: =IFERROR(VLOOKUP(B4,'8'!B:K,10,0),"0") -> 0 | BQ4: =IFERROR(VLOOKUP(B4,'8'!B:L,11,0),"0") -> 0 | BR4: =SUM(BL4:BQ4) -> 177 | BS4: =IFERROR(VLOOKUP(B4,'9'!B:D,3,0),"0") -> 16 | BT4: =IFERROR(VLOOKUP(B4,'9'!B:E,4,0),"0") -> 29 | BU4: =IFERROR(VLOOKUP(B4,'9'!B:F,5,0),"0") -> 23 | BV4: =IFERROR(VLOOKUP(B4,'9'!B:J,9,0),"0") -> 18 | BW4: =IFERROR(VLOOKUP(B4,'9'!B:K,10,0),"0") -> 0 | BX4: =IFERROR(VLOOKUP(B4,'9'!B:L,11,0),"0") -> 30 | BY4: =SUM(BS4:BX4) -> 116 | BZ4: =IFERROR(VLOOKUP(B4,'10'!B:D,3,0),"0") -> 10 | CA4: =IFERROR(VLOOKUP(B4,'10'!B:E,4,0),"0") -> 11 | CB4: =VLOOKUP(B4,'10'!B:F,5,0) -> 5 | CC4: =IFERROR(VLOOKUP(B4,'10'!B:J,9,0),"0") -> 28 | CD4: =IFERROR(VLOOKUP(B4,'10'!B:K,10,0),"0") -> 0 | CE4: =IFERROR(VLOOKUP(B4,'10'!B:L,11,0),"0") -> 11 | CF4: =SUM(BZ4:CE4) -> 65 | CG4: =IFERROR(VLOOKUP(B4,'11'!B:D,3,0),"0") -> 14 | CH4: =IFERROR(VLOOKUP(B4,'11'!B:E,4,0),"0") -> 15 | CI4: =IFERROR(VLOOKUP(B4,'11'!B:F,5,0),"0") -> 33 | CJ4: =IFERROR(VLOOKUP(B4,'11'!B:J,9,0),"0") -> 2 | CK4: =IFERROR(VLOOKUP(B4,'11'!B:K,10,0),"0") -> 0 | CL4: =IFERROR(VLOOKUP(B4,'11'!B:L,11,0),"0") -> 0 | CM4: =SUM(CG4:CL4) -> 64 | CN4: =IFERROR(VLOOKUP(B4,'12'!B:D,3,0),"0") -> 18 | CO4: =IFERROR(VLOOKUP(B4,'12'!B:E,4,0),"0") -> 24 | CP4: =IFERROR(VLOOKUP(B4,'12'!B:F,5,0),"0") -> 23 | CQ4: =IFERROR(VLOOKUP(B4,'12'!B:J,9,0),"0") -> 22 | CR4: =IFERROR(VLOOKUP(B4,'12'!B:K,10,0),"0") -> 0 | CS4: =IFERROR(VLOOKUP(B4,'12'!B:L,11,0),"0") -> 16 | CT4: =SUM(CN4:CS4) -> 103 | CU4: =IFERROR(VLOOKUP(B4,'13'!B:D,3,0),"0") -> 10 | CV4: =IFERROR(VLOOKUP(B4,'13'!B:E,4,0),"0") -> 11 | CW4: =IFERROR(VLOOKUP(B4,'13'!B:F,5,0),"0") -> 5 | CX4: =IFERROR(VLOOKUP(B4,'13'!B:J,9,0),"0") -> 28 | CY4: =IFERROR(VLOOKUP(B4,'13'!B:K,10,0),"0") -> 0 | CZ4: =IFERROR(VLOOKUP(B4,'13'!B:L,11,0),"0") -> 11 | DA4: =SUM(CU4:CZ4) -> 65 | DB4: =IFERROR(VLOOKUP(B4,'14'!B:D,3,0),"0") -> 19 | DC4: =IFERROR(VLOOKUP(B4,'14'!B:E,4,0),"0") -> 14 | DD4: =IFERROR(VLOOKUP(B4,'14'!B:F,5,0),"0") -> 6 | DE4: =IFERROR(VLOOKUP(B4,'14'!B:J,9,0),"0") -> 24 | DF4: =IFERROR(VLOOKUP(B4,'14'!B:K,10,0),"0") -> 0 | DG4: =IFERROR(VLOOKUP(B4,'14'!B:L,11,0),"0") -> 0 | DH4: =SUM(DB4:DG4) -> 63 | DI4: =IFERROR(VLOOKUP(B4,'15'!B:D,3,0),"0") -> 27 | DJ4: =IFERROR(VLOOKUP(B4,'15'!B:E,4,0),"0") -> 22 | DK4: =IFERROR(VLOOKUP(B4,'15'!B:F,5,0),"0") -> 43 | DL4: =IFERROR(VLOOKUP(B4,'15'!B:J,9,0),"0") -> 43 | DM4: =IFERROR(VLOOKUP(B4,'15'!B:K,10,0),"0") -> 0 | DN4: =IFERROR(VLOOKUP(B4,'15'!B:L,11,0),"0") -> 0 | DO4: =SUM(DI4:DN4) -> 135 | DP4: =IFERROR(VLOOKUP(B4,'16'!B:D,3,0),"0") -> 22 | DQ4: =IFERROR(VLOOKUP(B4,'16'!B:E,4,0),"0") -> 55 | DR4: =IFERROR(VLOOKUP(B4,'16'!B:F,5,0),"0") -> 154 | DS4: =IFERROR(VLOOKUP(B4,'16'!B:J,9,0),"0") -> 18 | DT4: =IFERROR(VLOOKUP(B4,'16'!B:K,10,0),"0") -> 0 | DU4: =IFERROR(VLOOKUP(B4,'16'!B:L,11,0),"0") -> 12 | DV4: =SUM(DP4:DU4) -> 261 | DW4: =IFERROR(VLOOKUP(B4,'17'!B:D,3,0),"0") -> 13 | DX4: =IFERROR(VLOOKUP(B4,'17'!B:E,4,0),"0") -> 47 | DY4: =IFERROR(VLOOKUP(B4,'17'!B:F,5,0),"0") -> 62 | DZ4: =IFERROR(VLOOKUP(B4,'17'!B:J,9,0),"0") -> 71 | EA4: =IFERROR(VLOOKUP(B4,'17'!B:K,10,0),"0") -> 0 | EB4: =IFERROR(VLOOKUP(B4,'17'!B:L,11,0),"0") -> 0 | EC4: =SUM(DW4:EB4) -> 193 | ED4: =IFERROR(VLOOKUP(B4,'18'!B:D,3,0),"0") -> 8 | EE4: =IFERROR(VLOOKUP(B4,'18'!B:E,4,0),"0") -> 14 | EF4: =IFERROR(VLOOKUP(B4,'18'!B:F,5,0),"0") -> 45 | EG4: =IFERROR(VLOOKUP(B4,'18'!B:J,9,0),"0") -> 30 | EH4: =IFERROR(VLOOKUP(B4,'18'!B:K,10,0),"0") -> 0 | EI4: =IFERROR(VLOOKUP(B4,'18'!B:L,11,0),"0") -> 0 | EJ4: =SUM(ED4:EI4) -> 97 | EK4: =IFERROR(VLOOKUP(B4,'19'!B:D,3,0),"0") -> 26 | EL4: =IFERROR(VLOOKUP(B4,'19'!B:E,4,0),"0") -> 36 | EM4: =IFERROR(VLOOKUP(B4,'19'!B:F,5,0),"0") -> 21 | EN4: =IFERROR(VLOOKUP(B4,'19'!B:J,9,0),"0") -> 25 | EO4: =IFERROR(VLOOKUP(B4,'19'!B:K,10,0),"0") -> 0 | EP4: =IFERROR(VLOOKUP(B4,'19'!B:L,11,0),"0") -> 83 | EQ4: =SUM(EK4:EP4) -> 191 | ER4: =IFERROR(VLOOKUP(B4,'20'!B:D,3,0),"0") -> 52 | ES4: =IFERROR(VLOOKUP(B4,'20'!B:E,4,0),"0") -> 14 | ET4: =IFERROR(VLOOKUP(B4,'20'!B:F,5,0),"0") -> 74 | EU4: =IFERROR(VLOOKUP(B4,'20'!B:J,9,0),"0") -> 15 | EV4: =IFERROR(VLOOKUP(B4,'20'!B:K,10,0),"0") -> 0 | EW4: =IFERROR(VLOOKUP(B4,'20'!B:L,11,0),"0") -> 10 | EX4: =SUM(ER4:EW4) -> 165 | EY4: =IFERROR(VLOOKUP(B4,'21'!B:D,3,0),"0") -> 8 | EZ4: =IFERROR(VLOOKUP(B4,'21'!B:E,4,0),"0") -> 15 | FA4: =IFERROR(VLOOKUP(B4,'21'!B:F,5,0),"0") -> 159 | FB4: =IFERROR(VLOOKUP(B4,'21'!B:J,9,0),"0") -> 17 | FC4: =IFERROR(VLOOKUP(B4,'21'!B:K,10,0),"0") -> 0 | FD4: =IFERROR(VLOOKUP(B4,'21'!B:L,11,0),"0") -> 0 | FE4: =SUM(EY4:FD4) -> 199 | FF4: =IFERROR(VLOOKUP(B4,'22'!B:D,3,0),"0") -> 81 | FG4: =IFERROR(VLOOKUP(B4,'22'!B:E,4,0),"0") -> 13 | FH4: =IFERROR(VLOOKUP(B4,'22'!B:F,5,0),"0") -> 102 | FI4: =IFERROR(VLOOKUP(B4,'22'!B:J,9,0),"0") -> 7 | FJ4: =IFERROR(VLOOKUP(B4,'22'!B:K,10,0),"0") -> 0 | FK4: =IFERROR(VLOOKUP(B4,'22'!B:L,11,0),"0") -> 0 | FL4: =SUM(FF4:FK4) -> 203 | FM4: =IFERROR(VLOOKUP(B4,'23'!B:D,3,0),"0") -> 17 | FN4: =IFERROR(VLOOKUP(B4,'23'!B:E,4,0),"0") -> 15 | FO4: =IFERROR(VLOOKUP(B4,'23'!B:F,5,0),"0") -> 82 | FP4: =IFERROR(VLOOKUP(B4,'23'!B:J,9,0),"0") -> 17 | FQ4: =IFERROR(VLOOKUP(B4,'23'!B:K,10,0),"0") -> 0 | FR4: =IFERROR(VLOOKUP(B4,'23'!B:L,11,0),"0") -> 48 | FS4: =SUM(FM4:FR4) -> 179 | FT4: =IFERROR(VLOOKUP(B4,'24'!B:D,3,0),"0") -> 14 | FU4: =IFERROR(VLOOKUP(B4,'24'!B:E,4,0),"0") -> 18 | FV4: =IFERROR(VLOOKUP(B4,'24'!B:F,5,0),"0") -> 32 | FW4: =IFERROR(VLOOKUP(B4,'24'!B:J,9,0),"0") -> 15 | FX4: =IFERROR(VLOOKUP(B4,'24'!B:K,10,0),"0") -> 0 | FY4: =IFERROR(VLOOKUP(B4,'24'!B:L,11,0),"0") -> 0 | FZ4: =SUM(FT4:FY4) -> 79 | GA4: =IFERROR(VLOOKUP(B4,'25'!B:D,3,0),"0") -> 13 | GB4: =IFERROR(VLOOKUP(B4,'25'!B:E,4,0),"0") -> 13 | GC4: =IFERROR(VLOOKUP(B4,'25'!B:F,5,0),"0") -> 30 | GD4: =IFERROR(VLOOKUP(B4,'25'!B:J,9,0),"0") -> 13 | GE4: =IFERROR(VLOOKUP(B4,'25'!B:K,10,0),"0") -> 0 | GF4: =IFERROR(VLOOKUP(B4,'25'!B:L,11,0),"0") -> 0 | GG4: =SUM(GA4:GF4) -> 69 | GH4: =IFERROR(VLOOKUP(B4,'26'!B:D,3,0),"0") -> 21 | GI4: =IFERROR(VLOOKUP(B4,'26'!B:E,4,0),"0") -> 88 | GJ4: =IFERROR(VLOOKUP(B4,'26'!B:F,5,0),"0") -> 127 | GK4: =IFERROR(VLOOKUP(B4,'26'!B:J,9,0),"0") -> 10 | GL4: =IFERROR(VLOOKUP(B4,'26'!B:K,10,0),"0") -> 0 | GM4: =IFERROR(VLOOKUP(B4,'26'!B:L,11,0),"0") -> 15 | GN4: =SUM(GH4:GM4) -> 261 | GO4: =IFERROR(VLOOKUP(B4,'27'!B:D,3,0),"0") -> 138 | GP4: =IFERROR(VLOOKUP(B4,'27'!B:E,4,0),"0") -> 47 | GQ4: =IFERROR(VLOOKUP(B4,'27'!B:F,5,0),"0") -> 35 | GR4: =IFERROR(VLOOKUP(B4,'27'!B:J,9,0),"0") -> 23 | GS4: =IFERROR(VLOOKUP(B4,'27'!B:K,10,0),"0") -> 0 | GT4: =IFERROR(VLOOKUP(B4,'27'!B:L,11,0),"0") -> 20 | GU4: =SUM(GO4:GT4) -> 263 | GV4: =IFERROR(VLOOKUP(B4,'28'!B:D,3,0),"0") -> 5 | GW4: =IFERROR(VLOOKUP(B4,'28'!B:E,4,0),"0") -> 26 | GX4: =IFERROR(VLOOKUP(B4,'28'!B:F,5,0),"0") -> 10 | GY4: =IFERROR(VLOOKUP(B4,'28'!B:J,9,0),"0") -> 7 | GZ4: =IFERROR(VLOOKUP(B4,'28'!B:K,10,0),"0") -> 0 | HA4: =IFERROR(VLOOKUP(B4,'28'!B:L,11,0),"0") -> 0 | HB4: =SUM(GV4:HA4) -> 48 | HC4: =IFERROR(VLOOKUP(B4,#REF!,3),"0") -> 0 | HD4: =IFERROR(VLOOKUP(B4,#REF!,4,0),"0") -> 0 | HE4: =IFERROR(VLOOKUP(B4,#REF!,5,0),"0") -> 0 | HF4: =IFERROR(VLOOKUP(B4,#REF!,9,0),"0") -> 0 | HG4: =IFERROR(VLOOKUP(B4,#REF!,10,0),"0") -> 0 | HH4: =IFERROR(VLOOKUP(B4,#REF!,11,0),"0") -> 0 | HI4: =SUM(HC4:HH4) -> 0 | HP4: =SUM(HJ4:HO4) -> 0 | HW4: =SUM(HQ4:HV4) -> 0
A5: 2 | B5: 1111084 | C5: ชิฟฟอน 8 ชิ้น กาแฟล้วน | D5: กล่อง | E5: 39.4 | F5: =+M5*E5 -> 0 | G5: =+O5+V5+AC5+AJ5+AQ5+AX5+BE5+BL5+BS5+BZ5+CG5+CN5+CU5+DB5+DI5+DP5+DW5+ED5+EK5+ER5+EY5+FF5+FM5+FT5+GA5+GH5+GO5+GV5+HC5+HJ5+HQ5 -> 0 | H5: =+P5+W5+AD5+AK5+AR5+AY5+BF5+BM5+BT5+CA5+CH5+CO5+CV5+DC5+DJ5+DQ5+DX5+EE5+EL5+ES5+EZ5+FG5+FN5+FU5+GB5+GI5+GP5+GW5+HD5+HK5+HR5 -> 0 | I5: =+Q5+X5+AE5+AL5+AS5+AZ5+BG5+BN5+BU5+CB5+CI5+CP5+CW5+DD5+DK5+DR5+DY5+EF5+EM5+ET5+FA5+FH5+FO5+FV5+GC5+GJ5+GQ5+GX5+HE5+HL5+HS5 -> 0 | J5: =+R5+Y5+AF5+AM5+AT5+BA5+BH5+BO5+BV5+CC5+CJ5+CQ5+CX5+DE5+DL5+DS5+DZ5+EG5+EN5+EU5+FB5+FI5+FP5+FW5+GD5+GK5+GR5+GY5+HF5+HM5+HT5 -> 0 | K5: =+S5+Z5+AG5+AN5+AU5+BB5+BI5+BP5+BW5+CD5+CK5+CR5+CY5+DF5+DM5+DT5+EA5+EH5+EO5+EV5+FC5+FJ5+FQ5+FX5+GE5+GL5+GS5+GZ5+HG5+HN5+HU5 -> 0 | L5: =+T5+AA5+AH5+AO5+AV5+BC5+BJ5+BQ5+BX5+CE5+CL5+CS5+CZ5+DG5+DN5+DU5+EB5+EI5+EP5+EW5+FD5+FK5+FR5+FY5+GF5+GM5+GT5+HA5+HH5+HO5+HV5 -> 0 | M5: =SUM(G5:L5) -> 0 | N5: =+G5+H5+I5+J5+K5 -> 0 | O5: =IFERROR(VLOOKUP(B5,'1ไม่มียอด'!B:D,3,0),"0") -> 0 | P5: =IFERROR(VLOOKUP(B5,'1ไม่มียอด'!B:E,4,0),"0") -> 0 | Q5: =IFERROR(VLOOKUP(B5,'1ไม่มียอด'!B:F,5,0),"0") -> 0 | R5: =IFERROR(VLOOKUP(B5,'1ไม่มียอด'!B:G,6,0),"0") -> 0 | S5: =IFERROR(VLOOKUP(B5,'1ไม่มียอด'!B:J,9,0),"0") -> 0 | T5: =IFERROR(VLOOKUP(B5,'1ไม่มียอด'!B:K,10,0),"0") -> 0 | U5: =SUM(O5:R5) -> 0 | V5: =IFERROR(VLOOKUP(B5,#REF!,3,0),"0") -> 0 | W5: =IFERROR(VLOOKUP(B5,#REF!,4,0),"0") -> 0 | X5: =IFERROR(VLOOKUP(B5,#REF!,5,0),"0") -> 0 | Y5: =IFERROR(VLOOKUP(B5,#REF!,9,0),"0") -> 0 | Z5: =IFERROR(VLOOKUP(B5,#REF!,10,0),"0") -> 0 | AA5: =IFERROR(VLOOKUP(B5,#REF!,11,0),"0") -> 0 | AB5: =SUM(V5:Y5) -> 0 | AC5: =IFERROR(VLOOKUP(B5,'3'!B:D,3,0),"0") -> 0 | AD5: =IFERROR(VLOOKUP(B5,'3'!B:E,4,0),"0") -> 0 | AE5: =IFERROR(VLOOKUP(B5,'3'!B:F,5,0),"0") -> 0 | AF5: =IFERROR(VLOOKUP(B5,'3'!B:J,9,0),"0") -> 0 | AG5: =IFERROR(VLOOKUP(B5,'3'!B:K,10,0),"0") -> 0 | AH5: =IFERROR(VLOOKUP(B5,'3'!B:L,11,0),"0") -> 0 | AI5: =SUM(AC5:AH5) -> 0 | AJ5: =IFERROR(VLOOKUP(B5,'4'!B:D,3,0),"0") -> 0 | AK5: =IFERROR(VLOOKUP(B5,'4'!B:E,4,0),"0") -> 0 | AL5: =IFERROR(VLOOKUP(B5,'4'!B:F,5,0),"0") -> 0 | AM5: =IFERROR(VLOOKUP(B5,'4'!B:J,9,0),"0") -> 0 | AN5: =IFERROR(VLOOKUP(B5,'4'!B:K,10,0),"0") -> 0 | AO5: =IFERROR(VLOOKUP(B5,'4'!B:L,11,0),"0") -> 0 | AP5: =SUM(AJ5:AO5) -> 0 | AQ5: =IFERROR(VLOOKUP(B5,'5'!B:D,3,0),"0") -> 0 | AR5: =IFERROR(VLOOKUP(B5,'5'!B:E,4,0),"0") -> 0 | AS5: =IFERROR(VLOOKUP(B5,'5'!B:F,5,0),"0") -> 0 | AT5: =IFERROR(VLOOKUP(B5,'5'!B:J,9,0),"0") -> 0 | AU5: =IFERROR(VLOOKUP(B5,'5'!B:K,10,0),"0") -> 0 | AV5: =IFERROR(VLOOKUP(B5,'5'!B:L,11,0),"0") -> 0 | AW5: =SUM(AQ5:AT5) -> 0 | AX5: =IFERROR(VLOOKUP(B5,'6'!B:D,3,0),"0") -> 0 | AY5: =IFERROR(VLOOKUP(B5,'6'!B:E,4,0),"0") -> 0 | AZ5: =IFERROR(VLOOKUP(B5,'6'!B:F,5,0),"0") -> 0 | BA5: =IFERROR(VLOOKUP(B5,'6'!B:J,9,0),"0") -> 0 | BB5: =IFERROR(VLOOKUP(B5,'6'!B:K,10,0),"0") -> 0 | BC5: =IFERROR(VLOOKUP(B5,'6'!B:L,11,0),"0") -> 0 | BD5: =SUM(AX5:BC5) -> 0 | BE5: =IFERROR(VLOOKUP(B5,'7'!B:D,3,0),"0") -> 0 | BF5: =IFERROR(VLOOKUP(B5,'7'!B:E,4,0),"0") -> 0 | BG5: =IFERROR(VLOOKUP(B5,'7'!B:F,5,0),"0") -> 0 | BH5: =IFERROR(VLOOKUP(B5,'7'!B:J,9,0),"0") -> 0 | BI5: =IFERROR(VLOOKUP(B5,'7'!B:K,10,0),"0") -> 0 | BJ5: =IFERROR(VLOOKUP(B5,'7'!B:L,11,0),"0") -> 0 | BK5: =SUM(BE5:BH5) -> 0 | BL5: =IFERROR(VLOOKUP(B5,'8'!B:D,3,0),"0") -> 0 | BM5: =IFERROR(VLOOKUP(B5,'8'!B:E,4,0),"0") -> 0 | BN5: =IFERROR(VLOOKUP(B5,'8'!B:F,5,0),"0") -> 0 | BO5: =IFERROR(VLOOKUP(B5,'8'!B:J,9,0),"0") -> 0 | BP5: =IFERROR(VLOOKUP(B5,'8'!B:K,10,0),"0") -> 0 | BQ5: =IFERROR(VLOOKUP(B5,'8'!B:L,11,0),"0") -> 0 | BR5: =SUM(BL5:BQ5) -> 0 | BS5: =IFERROR(VLOOKUP(B5,'9'!B:D,3,0),"0") -> 0 | BT5: =IFERROR(VLOOKUP(B5,'9'!B:E,4,0),"0") -> 0 | BU5: =IFERROR(VLOOKUP(B5,'9'!B:F,5,0),"0") -> 0 | BV5: =IFERROR(VLOOKUP(B5,'9'!B:J,9,0),"0") -> 0 | BW5: =IFERROR(VLOOKUP(B5,'9'!B:K,10,0),"0") -> 0 | BX5: =IFERROR(VLOOKUP(B5,'9'!B:L,11,0),"0") -> 0 | BY5: =SUM(BS5:BX5) -> 0 | BZ5: =IFERROR(VLOOKUP(B5,'10'!B:D,3,0),"0") -> 0 | CA5: =IFERROR(VLOOKUP(B5,'10'!B:E,4,0),"0") -> 0 | CB5: =VLOOKUP(B5,'10'!B:F,5,0) -> 0 | CC5: =IFERROR(VLOOKUP(B5,'10'!B:J,9,0),"0") -> 0 | CD5: =IFERROR(VLOOKUP(B5,'10'!B:K,10,0),"0") -> 0 | CE5: =IFERROR(VLOOKUP(B5,'10'!B:L,11,0),"0") -> 0 | CF5: =SUM(BZ5:CC5) -> 0 | CG5: =IFERROR(VLOOKUP(B5,'11'!B:D,3,0),"0") -> 0 | CH5: =IFERROR(VLOOKUP(B5,'11'!B:E,4,0),"0") -> 0 | CI5: =IFERROR(VLOOKUP(B5,'11'!B:F,5,0),"0") -> 0 | CJ5: =IFERROR(VLOOKUP(B5,'11'!B:J,9,0),"0") -> 0 | CK5: =IFERROR(VLOOKUP(B5,'11'!B:K,10,0),"0") -> 0 | CL5: =IFERROR(VLOOKUP(B5,'11'!B:L,11,0),"0") -> 0 | CM5: =SUM(CG5:CJ5) -> 0 | CN5: =IFERROR(VLOOKUP(B5,'12'!B:D,3,0),"0") -> 0 | CO5: =IFERROR(VLOOKUP(B5,'12'!B:E,4,0),"0") -> 0 | CP5: =IFERROR(VLOOKUP(B5,'12'!B:F,5,0),"0") -> 0 | CQ5: =IFERROR(VLOOKUP(B5,'12'!B:J,9,0),"0") -> 0 | CR5: =IFERROR(VLOOKUP(B5,'12'!B:K,10,0),"0") -> 0 | CS5: =IFERROR(VLOOKUP(B5,'12'!B:L,11,0),"0") -> 0 | CT5: =SUM(CN5:CQ5) -> 0 | CU5: =IFERROR(VLOOKUP(B5,'13'!B:D,3,0),"0") -> 0 | CV5: =IFERROR(VLOOKUP(B5,'13'!B:E,4,0),"0") -> 0 | CW5: =IFERROR(VLOOKUP(B5,'13'!B:F,5,0),"0") -> 0 | CX5: =IFERROR(VLOOKUP(B5,'13'!B:J,9,0),"0") -> 0 | CY5: =IFERROR(VLOOKUP(B5,'13'!B:K,10,0),"0") -> 0 | CZ5: =IFERROR(VLOOKUP(B5,'13'!B:L,11,0),"0") -> 0 | DA5: =SUM(CU5:CX5) -> 0 | DB5: =IFERROR(VLOOKUP(B5,'14'!B:D,3,0),"0") -> 0 | DC5: =IFERROR(VLOOKUP(B5,'14'!B:E,4,0),"0") -> 0 | DD5: =IFERROR(VLOOKUP(B5,'14'!B:F,5,0),"0") -> 0 | DE5: =IFERROR(VLOOKUP(B5,'14'!B:J,9,0),"0") -> 0 | DF5: =IFERROR(VLOOKUP(B5,'14'!B:K,10,0),"0") -> 0 | DG5: =IFERROR(VLOOKUP(B5,'14'!B:L,11,0),"0") -> 0 | DH5: =SUM(DB5:DE5) -> 0 | DI5: =IFERROR(VLOOKUP(B5,'15'!B:D,3,0),"0") -> 0 | DJ5: =IFERROR(VLOOKUP(B5,'15'!B:E,4,0),"0") -> 0 | DK5: =IFERROR(VLOOKUP(B5,'15'!B:F,5,0),"0") -> 0 | DL5: =IFERROR(VLOOKUP(B5,'15'!B:J,9,0),"0") -> 0 | DM5: =IFERROR(VLOOKUP(B5,'15'!B:K,10,0),"0") -> 0 | DN5: =IFERROR(VLOOKUP(B5,'15'!B:L,11,0),"0") -> 0 | DO5: =SUM(DI5:DL5) -> 0 | DP5: =IFERROR(VLOOKUP(B5,'16'!B:D,3,0),"0") -> 0 | DQ5: =IFERROR(VLOOKUP(B5,'16'!B:E,4,0),"0") -> 0 | DR5: =IFERROR(VLOOKUP(B5,'16'!B:F,5,0),"0") -> 0 | DS5: =IFERROR(VLOOKUP(B5,'16'!B:J,9,0),"0") -> 0 | DT5: =IFERROR(VLOOKUP(B5,'16'!B:K,10,0),"0") -> 0 | DU5: =IFERROR(VLOOKUP(B5,'16'!B:L,11,0),"0") -> 0 | DV5: =SUM(DP5:DS5) -> 0 | DW5: =IFERROR(VLOOKUP(B5,'17'!B:D,3,0),"0") -> 0 | DX5: =IFERROR(VLOOKUP(B5,'17'!B:E,4,0),"0") -> 0 | DY5: =IFERROR(VLOOKUP(B5,'17'!B:F,5,0),"0") -> 0 | DZ5: =IFERROR(VLOOKUP(B5,'17'!B:J,9,0),"0") -> 0 | EA5: =IFERROR(VLOOKUP(B5,'17'!B:K,10,0),"0") -> 0 | EB5: =IFERROR(VLOOKUP(B5,'17'!B:L,11,0),"0") -> 0 | EC5: =SUM(DW5:DZ5) -> 0 | ED5: =IFERROR(VLOOKUP(B5,'18'!B:D,3,0),"0") -> 0 | EE5: =IFERROR(VLOOKUP(B5,'18'!B:E,4,0),"0") -> 0 | EF5: =IFERROR(VLOOKUP(B5,'18'!B:F,5,0),"0") -> 0 | EG5: =IFERROR(VLOOKUP(B5,'18'!B:J,9,0),"0") -> 0 | EH5: =IFERROR(VLOOKUP(B5,'18'!B:K,10,0),"0") -> 0 | EI5: =IFERROR(VLOOKUP(B5,'18'!B:L,11,0),"0") -> 0 | EJ5: =SUM(ED5:EI5) -> 0 | EK5: =IFERROR(VLOOKUP(B5,'19'!B:D,3,0),"0") -> 0 | EL5: =IFERROR(VLOOKUP(B5,'19'!B:E,4,0),"0") -> 0 | EM5: =IFERROR(VLOOKUP(B5,'19'!B:F,5,0),"0") -> 0 | EN5: =IFERROR(VLOOKUP(B5,'19'!B:J,9,0),"0") -> 0 | EO5: =IFERROR(VLOOKUP(B5,'19'!B:K,10,0),"0") -> 0 | EP5: =IFERROR(VLOOKUP(B5,'19'!B:L,11,0),"0") -> 0 | EQ5: =SUM(EK5:EP5) -> 0 | ER5: =IFERROR(VLOOKUP(B5,'20'!B:D,3,0),"0") -> 0 | ES5: =IFERROR(VLOOKUP(B5,'20'!B:E,4,0),"0") -> 0 | ET5: =IFERROR(VLOOKUP(B5,'20'!B:F,5,0),"0") -> 0 | EU5: =IFERROR(VLOOKUP(B5,'20'!B:J,9,0),"0") -> 0 | EV5: =IFERROR(VLOOKUP(B5,'20'!B:K,10,0),"0") -> 0 | EW5: =IFERROR(VLOOKUP(B5,'20'!B:L,11,0),"0") -> 0 | EX5: =SUM(ER5:EW5) -> 0 | EY5: =IFERROR(VLOOKUP(B5,'21'!B:D,3,0),"0") -> 0 | EZ5: =IFERROR(VLOOKUP(B5,'21'!B:E,4,0),"0") -> 0 | FA5: =IFERROR(VLOOKUP(B5,'21'!B:F,5,0),"0") -> 0 | FB5: =IFERROR(VLOOKUP(B5,'21'!B:J,9,0),"0") -> 0 | FC5: =IFERROR(VLOOKUP(B5,'21'!B:K,10,0),"0") -> 0 | FD5: =IFERROR(VLOOKUP(B5,'21'!B:L,11,0),"0") -> 0 | FE5: =SUM(EY5:FD5) -> 0 | FF5: =IFERROR(VLOOKUP(B5,'22'!B:D,3,0),"0") -> 0 | FG5: =IFERROR(VLOOKUP(B5,'22'!B:E,4,0),"0") -> 0 | FH5: =IFERROR(VLOOKUP(B5,'22'!B:F,5,0),"0") -> 0 | FI5: =IFERROR(VLOOKUP(B5,'22'!B:J,9,0),"0") -> 0 | FJ5: =IFERROR(VLOOKUP(B5,'22'!B:K,10,0),"0") -> 0 | FK5: =IFERROR(VLOOKUP(B5,'22'!B:L,11,0),"0") -> 0 | FL5: =SUM(FF5:FK5) -> 0 | FM5: =IFERROR(VLOOKUP(B5,'23'!B:D,3,0),"0") -> 0 | FN5: =IFERROR(VLOOKUP(B5,'23'!B:E,4,0),"0") -> 0 | FO5: =IFERROR(VLOOKUP(B5,'23'!B:F,5,0),"0") -> 0 | FP5: =IFERROR(VLOOKUP(B5,'23'!B:J,9,0),"0") -> 0 | FQ5: =IFERROR(VLOOKUP(B5,'23'!B:K,10,0),"0") -> 0 | FR5: =IFERROR(VLOOKUP(B5,'23'!B:L,11,0),"0") -> 0 | FS5: =SUM(FM5:FR5) -> 0 | FT5: =IFERROR(VLOOKUP(B5,'24'!B:D,3,0),"0") -> 0 | FU5: =IFERROR(VLOOKUP(B5,'24'!B:E,4,0),"0") -> 0 | FV5: =IFERROR(VLOOKUP(B5,'24'!B:F,5,0),"0") -> 0 | FW5: =IFERROR(VLOOKUP(B5,'24'!B:J,9,0),"0") -> 0 | FX5: =IFERROR(VLOOKUP(B5,'24'!B:K,10,0),"0") -> 0 | FY5: =IFERROR(VLOOKUP(B5,'24'!B:L,11,0),"0") -> 0 | FZ5: =SUM(FT5:FY5) -> 0 | GA5: =IFERROR(VLOOKUP(B5,'25'!B:D,3,0),"0") -> 0 | GB5: =IFERROR(VLOOKUP(B5,'25'!B:E,4,0),"0") -> 0 | GC5: =IFERROR(VLOOKUP(B5,'25'!B:F,5,0),"0") -> 0 | GD5: =IFERROR(VLOOKUP(B5,'25'!B:J,9,0),"0") -> 0 | GE5: =IFERROR(VLOOKUP(B5,'25'!B:K,10,0),"0") -> 0 | GF5: =IFERROR(VLOOKUP(B5,'25'!B:L,11,0),"0") -> 0 | GG5: =SUM(GA5:GD5) -> 0 | GH5: =IFERROR(VLOOKUP(B5,'26'!B:D,3,0),"0") -> 0 | GI5: =IFERROR(VLOOKUP(B5,'26'!B:E,4,0),"0") -> 0 | GJ5: =IFERROR(VLOOKUP(B5,'26'!B:F,5,0),"0") -> 0 | GK5: =IFERROR(VLOOKUP(B5,'26'!B:J,9,0),"0") -> 0 | GL5: =IFERROR(VLOOKUP(B5,'26'!B:K,10,0),"0") -> 0 | GM5: =IFERROR(VLOOKUP(B5,'26'!B:L,11,0),"0") -> 0 | GN5: =SUM(GH5:GK5) -> 0 | GO5: =IFERROR(VLOOKUP(B5,'27'!B:D,3,0),"0") -> 0 | GP5: =IFERROR(VLOOKUP(B5,'27'!B:E,4,0),"0") -> 0 | GQ5: =IFERROR(VLOOKUP(B5,'27'!B:F,5,0),"0") -> 0 | GR5: =IFERROR(VLOOKUP(B5,'27'!B:J,9,0),"0") -> 0 | GS5: =IFERROR(VLOOKUP(B5,'27'!B:K,10,0),"0") -> 0 | GT5: =IFERROR(VLOOKUP(B5,'27'!B:L,11,0),"0") -> 0 | GU5: =SUM(GO5:GT5) -> 0 | GV5: =IFERROR(VLOOKUP(B5,'28'!B:D,3,0),"0") -> 0 | GW5: =IFERROR(VLOOKUP(B5,'28'!B:E,4,0),"0") -> 0 | GX5: =IFERROR(VLOOKUP(B5,'28'!B:F,5,0),"0") -> 0 | GY5: =IFERROR(VLOOKUP(B5,'28'!B:J,9,0),"0") -> 0 | GZ5: =IFERROR(VLOOKUP(B5,'28'!B:K,10,0),"0") -> 0 | HA5: =IFERROR(VLOOKUP(B5,'28'!B:L,11,0),"0") -> 0 | HB5: =SUM(GV5:HA5) -> 0 | HC5: =IFERROR(VLOOKUP(B5,#REF!,3),"0") -> 0 | HD5: =IFERROR(VLOOKUP(B5,#REF!,4,0),"0") -> 0 | HE5: =IFERROR(VLOOKUP(B5,#REF!,5,0),"0") -> 0 | HF5: =IFERROR(VLOOKUP(B5,#REF!,9,0),"0") -> 0 | HG5: =IFERROR(VLOOKUP(B5,#REF!,10,0),"0") -> 0 | HH5: =IFERROR(VLOOKUP(B5,#REF!,11,0),"0") -> 0 | HI5: =SUM(HC5:HF5) -> 0 | HP5: =SUM(HJ5:HM5) -> 0 | HW5: =SUM(HQ5:HT5) -> 0
A6: 3 | B6: 1111085 | C6: ชิฟฟอน 8 ชิ้น บลูเบอรี่ล้วน | D6: กล่อง | E6: 37.04 | F6: =+M6*E6 -> 0 | G6: =+O6+V6+AC6+AJ6+AQ6+AX6+BE6+BL6+BS6+BZ6+CG6+CN6+CU6+DB6+DI6+DP6+DW6+ED6+EK6+ER6+EY6+FF6+FM6+FT6+GA6+GH6+GO6+GV6+HC6+HJ6+HQ6 -> 0 | H6: =+P6+W6+AD6+AK6+AR6+AY6+BF6+BM6+BT6+CA6+CH6+CO6+CV6+DC6+DJ6+DQ6+DX6+EE6+EL6+ES6+EZ6+FG6+FN6+FU6+GB6+GI6+GP6+GW6+HD6+HK6+HR6 -> 0 | I6: =+Q6+X6+AE6+AL6+AS6+AZ6+BG6+BN6+BU6+CB6+CI6+CP6+CW6+DD6+DK6+DR6+DY6+EF6+EM6+ET6+FA6+FH6+FO6+FV6+GC6+GJ6+GQ6+GX6+HE6+HL6+HS6 -> 0 | J6: =+R6+Y6+AF6+AM6+AT6+BA6+BH6+BO6+BV6+CC6+CJ6+CQ6+CX6+DE6+DL6+DS6+DZ6+EG6+EN6+EU6+FB6+FI6+FP6+FW6+GD6+GK6+GR6+GY6+HF6+HM6+HT6 -> 0 | K6: =+S6+Z6+AG6+AN6+AU6+BB6+BI6+BP6+BW6+CD6+CK6+CR6+CY6+DF6+DM6+DT6+EA6+EH6+EO6+EV6+FC6+FJ6+FQ6+FX6+GE6+GL6+GS6+GZ6+HG6+HN6+HU6 -> 0 | L6: =+T6+AA6+AH6+AO6+AV6+BC6+BJ6+BQ6+BX6+CE6+CL6+CS6+CZ6+DG6+DN6+DU6+EB6+EI6+EP6+EW6+FD6+FK6+FR6+FY6+GF6+GM6+GT6+HA6+HH6+HO6+HV6 -> 0 | M6: =SUM(G6:L6) -> 0 | N6: =+G6+H6+I6+J6+K6 -> 0 | O6: =IFERROR(VLOOKUP(B6,'1ไม่มียอด'!B:D,3,0),"0") -> 0 | P6: =IFERROR(VLOOKUP(B6,'1ไม่มียอด'!B:E,4,0),"0") -> 0 | Q6: =IFERROR(VLOOKUP(B6,'1ไม่มียอด'!B:F,5,0),"0") -> 0 | R6: =IFERROR(VLOOKUP(B6,'1ไม่มียอด'!B:G,6,0),"0") -> 0 | S6: =IFERROR(VLOOKUP(B6,'1ไม่มียอด'!B:J,9,0),"0") -> 0 | T6: =IFERROR(VLOOKUP(B6,'1ไม่มียอด'!B:K,10,0),"0") -> 0 | U6: =SUM(O6:R6) -> 0 | V6: =IFERROR(VLOOKUP(B6,#REF!,3,0),"0") -> 0 | W6: =IFERROR(VLOOKUP(B6,#REF!,4,0),"0") -> 0 | X6: =IFERROR(VLOOKUP(B6,#REF!,5,0),"0") -> 0 | Y6: =IFERROR(VLOOKUP(B6,#REF!,9,0),"0") -> 0 | Z6: =IFERROR(VLOOKUP(B6,#REF!,10,0),"0") -> 0 | AA6: =IFERROR(VLOOKUP(B6,#REF!,11,0),"0") -> 0 | AB6: =SUM(V6:Y6) -> 0 | AC6: =IFERROR(VLOOKUP(B6,'3'!B:D,3,0),"0") -> 0 | AD6: =IFERROR(VLOOKUP(B6,'3'!B:E,4,0),"0") -> 0 | AE6: =IFERROR(VLOOKUP(B6,'3'!B:F,5,0),"0") -> 0 | AF6: =IFERROR(VLOOKUP(B6,'3'!B:J,9,0),"0") -> 0 | AG6: =IFERROR(VLOOKUP(B6,'3'!B:K,10,0),"0") -> 0 | AH6: =IFERROR(VLOOKUP(B6,'3'!B:L,11,0),"0") -> 0 | AI6: =SUM(AC6:AH6) -> 0 | AJ6: =IFERROR(VLOOKUP(B6,'4'!B:D,3,0),"0") -> 0 | AK6: =IFERROR(VLOOKUP(B6,'4'!B:E,4,0),"0") -> 0 | AL6: =IFERROR(VLOOKUP(B6,'4'!B:F,5,0),"0") -> 0 | AM6: =IFERROR(VLOOKUP(B6,'4'!B:J,9,0),"0") -> 0 | AN6: =IFERROR(VLOOKUP(B6,'4'!B:K,10,0),"0") -> 0 | AO6: =IFERROR(VLOOKUP(B6,'4'!B:L,11,0),"0") -> 0 | AP6: =SUM(AJ6:AO6) -> 0 | AQ6: =IFERROR(VLOOKUP(B6,'5'!B:D,3,0),"0") -> 0 | AR6: =IFERROR(VLOOKUP(B6,'5'!B:E,4,0),"0") -> 0 | AS6: =IFERROR(VLOOKUP(B6,'5'!B:F,5,0),"0") -> 0 | AT6: =IFERROR(VLOOKUP(B6,'5'!B:J,9,0),"0") -> 0 | AU6: =IFERROR(VLOOKUP(B6,'5'!B:K,10,0),"0") -> 0 | AV6: =IFERROR(VLOOKUP(B6,'5'!B:L,11,0),"0") -> 0 | AW6: =SUM(AQ6:AT6) -> 0 | AX6: =IFERROR(VLOOKUP(B6,'6'!B:D,3,0),"0") -> 0 | AY6: =IFERROR(VLOOKUP(B6,'6'!B:E,4,0),"0") -> 0 | AZ6: =IFERROR(VLOOKUP(B6,'6'!B:F,5,0),"0") -> 0 | BA6: =IFERROR(VLOOKUP(B6,'6'!B:J,9,0),"0") -> 0 | BB6: =IFERROR(VLOOKUP(B6,'6'!B:K,10,0),"0") -> 0 | BC6: =IFERROR(VLOOKUP(B6,'6'!B:L,11,0),"0") -> 0 | BD6: =SUM(AX6:BC6) -> 0 | BE6: =IFERROR(VLOOKUP(B6,'7'!B:D,3,0),"0") -> 0 | BF6: =IFERROR(VLOOKUP(B6,'7'!B:E,4,0),"0") -> 0 | BG6: =IFERROR(VLOOKUP(B6,'7'!B:F,5,0),"0") -> 0 | BH6: =IFERROR(VLOOKUP(B6,'7'!B:J,9,0),"0") -> 0 | BI6: =IFERROR(VLOOKUP(B6,'7'!B:K,10,0),"0") -> 0 | BJ6: =IFERROR(VLOOKUP(B6,'7'!B:L,11,0),"0") -> 0 | BK6: =SUM(BE6:BH6) -> 0 | BL6: =IFERROR(VLOOKUP(B6,'8'!B:D,3,0),"0") -> 0 | BM6: =IFERROR(VLOOKUP(B6,'8'!B:E,4,0),"0") -> 0 | BN6: =IFERROR(VLOOKUP(B6,'8'!B:F,5,0),"0") -> 0 | BO6: =IFERROR(VLOOKUP(B6,'8'!B:J,9,0),"0") -> 0 | BP6: =IFERROR(VLOOKUP(B6,'8'!B:K,10,0),"0") -> 0 | BQ6: =IFERROR(VLOOKUP(B6,'8'!B:L,11,0),"0") -> 0 | BR6: =SUM(BL6:BQ6) -> 0 | BS6: =IFERROR(VLOOKUP(B6,'9'!B:D,3,0),"0") -> 0 | BT6: =IFERROR(VLOOKUP(B6,'9'!B:E,4,0),"0") -> 0 | BU6: =IFERROR(VLOOKUP(B6,'9'!B:F,5,0),"0") -> 0 | BV6: =IFERROR(VLOOKUP(B6,'9'!B:J,9,0),"0") -> 0 | BW6: =IFERROR(VLOOKUP(B6,'9'!B:K,10,0),"0") -> 0 | BX6: =IFERROR(VLOOKUP(B6,'9'!B:L,11,0),"0") -> 0 | BY6: =SUM(BS6:BX6) -> 0 | BZ6: =IFERROR(VLOOKUP(B6,'10'!B:D,3,0),"0") -> 0 | CA6: =IFERROR(VLOOKUP(B6,'10'!B:E,4,0),"0") -> 0 | CB6: =VLOOKUP(B6,'10'!B:F,5,0) -> 0 | CC6: =IFERROR(VLOOKUP(B6,'10'!B:J,9,0),"0") -> 0 | CD6: =IFERROR(VLOOKUP(B6,'10'!B:K,10,0),"0") -> 0 | CE6: =IFERROR(VLOOKUP(B6,'10'!B:L,11,0),"0") -> 0 | CF6: =SUM(BZ6:CC6) -> 0 | CG6: =IFERROR(VLOOKUP(B6,'11'!B:D,3,0),"0") -> 0 | CH6: =IFERROR(VLOOKUP(B6,'11'!B:E,4,0),"0") -> 0 | CI6: =IFERROR(VLOOKUP(B6,'11'!B:F,5,0),"0") -> 0 | CJ6: =IFERROR(VLOOKUP(B6,'11'!B:J,9,0),"0") -> 0 | CK6: =IFERROR(VLOOKUP(B6,'11'!B:K,10,0),"0") -> 0 | CL6: =IFERROR(VLOOKUP(B6,'11'!B:L,11,0),"0") -> 0 | CM6: =SUM(CG6:CJ6) -> 0 | CN6: =IFERROR(VLOOKUP(B6,'12'!B:D,3,0),"0") -> 0 | CO6: =IFERROR(VLOOKUP(B6,'12'!B:E,4,0),"0") -> 0 | CP6: =IFERROR(VLOOKUP(B6,'12'!B:F,5,0),"0") -> 0 | CQ6: =IFERROR(VLOOKUP(B6,'12'!B:J,9,0),"0") -> 0 | CR6: =IFERROR(VLOOKUP(B6,'12'!B:K,10,0),"0") -> 0 | CS6: =IFERROR(VLOOKUP(B6,'12'!B:L,11,0),"0") -> 0 | CT6: =SUM(CN6:CQ6) -> 0 | CU6: =IFERROR(VLOOKUP(B6,'13'!B:D,3,0),"0") -> 0 | CV6: =IFERROR(VLOOKUP(B6,'13'!B:E,4,0),"0") -> 0 | CW6: =IFERROR(VLOOKUP(B6,'13'!B:F,5,0),"0") -> 0 | CX6: =IFERROR(VLOOKUP(B6,'13'!B:J,9,0),"0") -> 0 | CY6: =IFERROR(VLOOKUP(B6,'13'!B:K,10,0),"0") -> 0 | CZ6: =IFERROR(VLOOKUP(B6,'13'!B:L,11,0),"0") -> 0 | DA6: =SUM(CU6:CX6) -> 0 | DB6: =IFERROR(VLOOKUP(B6,'14'!B:D,3,0),"0") -> 0 | DC6: =IFERROR(VLOOKUP(B6,'14'!B:E,4,0),"0") -> 0 | DD6: =IFERROR(VLOOKUP(B6,'14'!B:F,5,0),"0") -> 0 | DE6: =IFERROR(VLOOKUP(B6,'14'!B:J,9,0),"0") -> 0 | DF6: =IFERROR(VLOOKUP(B6,'14'!B:K,10,0),"0") -> 0 | DG6: =IFERROR(VLOOKUP(B6,'14'!B:L,11,0),"0") -> 0 | DH6: =SUM(DB6:DE6) -> 0 | DI6: =IFERROR(VLOOKUP(B6,'15'!B:D,3,0),"0") -> 0 | DJ6: =IFERROR(VLOOKUP(B6,'15'!B:E,4,0),"0") -> 0 | DK6: =IFERROR(VLOOKUP(B6,'15'!B:F,5,0),"0") -> 0 | DL6: =IFERROR(VLOOKUP(B6,'15'!B:J,9,0),"0") -> 0 | DM6: =IFERROR(VLOOKUP(B6,'15'!B:K,10,0),"0") -> 0 | DN6: =IFERROR(VLOOKUP(B6,'15'!B:L,11,0),"0") -> 0 | DO6: =SUM(DI6:DL6) -> 0 | DP6: =IFERROR(VLOOKUP(B6,'16'!B:D,3,0),"0") -> 0 | DQ6: =IFERROR(VLOOKUP(B6,'16'!B:E,4,0),"0") -> 0 | DR6: =IFERROR(VLOOKUP(B6,'16'!B:F,5,0),"0") -> 0 | DS6: =IFERROR(VLOOKUP(B6,'16'!B:J,9,0),"0") -> 0 | DT6: =IFERROR(VLOOKUP(B6,'16'!B:K,10,0),"0") -> 0 | DU6: =IFERROR(VLOOKUP(B6,'16'!B:L,11,0),"0") -> 0 | DV6: =SUM(DP6:DS6) -> 0 | DW6: =IFERROR(VLOOKUP(B6,'17'!B:D,3,0),"0") -> 0 | DX6: =IFERROR(VLOOKUP(B6,'17'!B:E,4,0),"0") -> 0 | DY6: =IFERROR(VLOOKUP(B6,'17'!B:F,5,0),"0") -> 0 | DZ6: =IFERROR(VLOOKUP(B6,'17'!B:J,9,0),"0") -> 0 | EA6: =IFERROR(VLOOKUP(B6,'17'!B:K,10,0),"0") -> 0 | EB6: =IFERROR(VLOOKUP(B6,'17'!B:L,11,0),"0") -> 0 | EC6: =SUM(DW6:DZ6) -> 0 | ED6: =IFERROR(VLOOKUP(B6,'18'!B:D,3,0),"0") -> 0 | EE6: =IFERROR(VLOOKUP(B6,'18'!B:E,4,0),"0") -> 0 | EF6: =IFERROR(VLOOKUP(B6,'18'!B:F,5,0),"0") -> 0 | EG6: =IFERROR(VLOOKUP(B6,'18'!B:J,9,0),"0") -> 0 | EH6: =IFERROR(VLOOKUP(B6,'18'!B:K,10,0),"0") -> 0 | EI6: =IFERROR(VLOOKUP(B6,'18'!B:L,11,0),"0") -> 0 | EJ6: =SUM(ED6:EI6) -> 0 | EK6: =IFERROR(VLOOKUP(B6,'19'!B:D,3,0),"0") -> 0 | EL6: =IFERROR(VLOOKUP(B6,'19'!B:E,4,0),"0") -> 0 | EM6: =IFERROR(VLOOKUP(B6,'19'!B:F,5,0),"0") -> 0 | EN6: =IFERROR(VLOOKUP(B6,'19'!B:J,9,0),"0") -> 0 | EO6: =IFERROR(VLOOKUP(B6,'19'!B:K,10,0),"0") -> 0 | EP6: =IFERROR(VLOOKUP(B6,'19'!B:L,11,0),"0") -> 0 | EQ6: =SUM(EK6:EP6) -> 0 | ER6: =IFERROR(VLOOKUP(B6,'20'!B:D,3,0),"0") -> 0 | ES6: =IFERROR(VLOOKUP(B6,'20'!B:E,4,0),"0") -> 0 | ET6: =IFERROR(VLOOKUP(B6,'20'!B:F,5,0),"0") -> 0 | EU6: =IFERROR(VLOOKUP(B6,'20'!B:J,9,0),"0") -> 0 | EV6: =IFERROR(VLOOKUP(B6,'20'!B:K,10,0),"0") -> 0 | EW6: =IFERROR(VLOOKUP(B6,'20'!B:L,11,0),"0") -> 0 | EX6: =SUM(ER6:EW6) -> 0 | EY6: =IFERROR(VLOOKUP(B6,'21'!B:D,3,0),"0") -> 0 | EZ6: =IFERROR(VLOOKUP(B6,'21'!B:E,4,0),"0") -> 0 | FA6: =IFERROR(VLOOKUP(B6,'21'!B:F,5,0),"0") -> 0 | FB6: =IFERROR(VLOOKUP(B6,'21'!B:J,9,0),"0") -> 0 | FC6: =IFERROR(VLOOKUP(B6,'21'!B:K,10,0),"0") -> 0 | FD6: =IFERROR(VLOOKUP(B6,'21'!B:L,11,0),"0") -> 0 | FE6: =SUM(EY6:FD6) -> 0 | FF6: =IFERROR(VLOOKUP(B6,'22'!B:D,3,0),"0") -> 0 | FG6: =IFERROR(VLOOKUP(B6,'22'!B:E,4,0),"0") -> 0 | FH6: =IFERROR(VLOOKUP(B6,'22'!B:F,5,0),"0") -> 0 | FI6: =IFERROR(VLOOKUP(B6,'22'!B:J,9,0),"0") -> 0 | FJ6: =IFERROR(VLOOKUP(B6,'22'!B:K,10,0),"0") -> 0 | FK6: =IFERROR(VLOOKUP(B6,'22'!B:L,11,0),"0") -> 0 | FL6: =SUM(FF6:FK6) -> 0 | FM6: =IFERROR(VLOOKUP(B6,'23'!B:D,3,0),"0") -> 0 | FN6: =IFERROR(VLOOKUP(B6,'23'!B:E,4,0),"0") -> 0 | FO6: =IFERROR(VLOOKUP(B6,'23'!B:F,5,0),"0") -> 0 | FP6: =IFERROR(VLOOKUP(B6,'23'!B:J,9,0),"0") -> 0 | FQ6: =IFERROR(VLOOKUP(B6,'23'!B:K,10,0),"0") -> 0 | FR6: =IFERROR(VLOOKUP(B6,'23'!B:L,11,0),"0") -> 0 | FS6: =SUM(FM6:FR6) -> 0 | FT6: =IFERROR(VLOOKUP(B6,'24'!B:D,3,0),"0") -> 0 | FU6: =IFERROR(VLOOKUP(B6,'24'!B:E,4,0),"0") -> 0 | FV6: =IFERROR(VLOOKUP(B6,'24'!B:F,5,0),"0") -> 0 | FW6: =IFERROR(VLOOKUP(B6,'24'!B:J,9,0),"0") -> 0 | FX6: =IFERROR(VLOOKUP(B6,'24'!B:K,10,0),"0") -> 0 | FY6: =IFERROR(VLOOKUP(B6,'24'!B:L,11,0),"0") -> 0 | FZ6: =SUM(FT6:FY6) -> 0 | GA6: =IFERROR(VLOOKUP(B6,'25'!B:D,3,0),"0") -> 0 | GB6: =IFERROR(VLOOKUP(B6,'25'!B:E,4,0),"0") -> 0 | GC6: =IFERROR(VLOOKUP(B6,'25'!B:F,5,0),"0") -> 0 | GD6: =IFERROR(VLOOKUP(B6,'25'!B:J,9,0),"0") -> 0 | GE6: =IFERROR(VLOOKUP(B6,'25'!B:K,10,0),"0") -> 0 | GF6: =IFERROR(VLOOKUP(B6,'25'!B:L,11,0),"0") -> 0 | GG6: =SUM(GA6:GD6) -> 0 | GH6: =IFERROR(VLOOKUP(B6,'26'!B:D,3,0),"0") -> 0 | GI6: =IFERROR(VLOOKUP(B6,'26'!B:E,4,0),"0") -> 0 | GJ6: =IFERROR(VLOOKUP(B6,'26'!B:F,5,0),"0") -> 0 | GK6: =IFERROR(VLOOKUP(B6,'26'!B:J,9,0),"0") -> 0 | GL6: =IFERROR(VLOOKUP(B6,'26'!B:K,10,0),"0") -> 0 | GM6: =IFERROR(VLOOKUP(B6,'26'!B:L,11,0),"0") -> 0 | GN6: =SUM(GH6:GK6) -> 0 | GO6: =IFERROR(VLOOKUP(B6,'27'!B:D,3,0),"0") -> 0 | GP6: =IFERROR(VLOOKUP(B6,'27'!B:E,4,0),"0") -> 0 | GQ6: =IFERROR(VLOOKUP(B6,'27'!B:F,5,0),"0") -> 0 | GR6: =IFERROR(VLOOKUP(B6,'27'!B:J,9,0),"0") -> 0 | GS6: =IFERROR(VLOOKUP(B6,'27'!B:K,10,0),"0") -> 0 | GT6: =IFERROR(VLOOKUP(B6,'27'!B:L,11,0),"0") -> 0 | GU6: =SUM(GO6:GT6) -> 0 | GV6: =IFERROR(VLOOKUP(B6,'28'!B:D,3,0),"0") -> 0 | GW6: =IFERROR(VLOOKUP(B6,'28'!B:E,4,0),"0") -> 0 | GX6: =IFERROR(VLOOKUP(B6,'28'!B:F,5,0),"0") -> 0 | GY6: =IFERROR(VLOOKUP(B6,'28'!B:J,9,0),"0") -> 0 | GZ6: =IFERROR(VLOOKUP(B6,'28'!B:K,10,0),"0") -> 0 | HA6: =IFERROR(VLOOKUP(B6,'28'!B:L,11,0),"0") -> 0 | HB6: =SUM(GV6:HA6) -> 0 | HC6: =IFERROR(VLOOKUP(B6,#REF!,3),"0") -> 0 | HD6: =IFERROR(VLOOKUP(B6,#REF!,4,0),"0") -> 0 | HE6: =IFERROR(VLOOKUP(B6,#REF!,5,0),"0") -> 0 | HF6: =IFERROR(VLOOKUP(B6,#REF!,9,0),"0") -> 0 | HG6: =IFERROR(VLOOKUP(B6,#REF!,10,0),"0") -> 0 | HH6: =IFERROR(VLOOKUP(B6,#REF!,11,0),"0") -> 0 | HI6: =SUM(HC6:HF6) -> 0 | HP6: =SUM(HJ6:HM6) -> 0 | HW6: =SUM(HQ6:HT6) -> 0
A7: 4 | B7: 1111086 | C7: ชิฟฟอน 8 ชิ้น มะพร้าวล้วน | D7: กล่อง | E7: 38.11 | F7: =+M7*E7 -> 0 | G7: =+O7+V7+AC7+AJ7+AQ7+AX7+BE7+BL7+BS7+BZ7+CG7+CN7+CU7+DB7+DI7+DP7+DW7+ED7+EK7+ER7+EY7+FF7+FM7+FT7+GA7+GH7+GO7+GV7+HC7+HJ7+HQ7 -> 0 | H7: =+P7+W7+AD7+AK7+AR7+AY7+BF7+BM7+BT7+CA7+CH7+CO7+CV7+DC7+DJ7+DQ7+DX7+EE7+EL7+ES7+EZ7+FG7+FN7+FU7+GB7+GI7+GP7+GW7+HD7+HK7+HR7 -> 0 | I7: =+Q7+X7+AE7+AL7+AS7+AZ7+BG7+BN7+BU7+CB7+CI7+CP7+CW7+DD7+DK7+DR7+DY7+EF7+EM7+ET7+FA7+FH7+FO7+FV7+GC7+GJ7+GQ7+GX7+HE7+HL7+HS7 -> 0 | J7: =+R7+Y7+AF7+AM7+AT7+BA7+BH7+BO7+BV7+CC7+CJ7+CQ7+CX7+DE7+DL7+DS7+DZ7+EG7+EN7+EU7+FB7+FI7+FP7+FW7+GD7+GK7+GR7+GY7+HF7+HM7+HT7 -> 0 | K7: =+S7+Z7+AG7+AN7+AU7+BB7+BI7+BP7+BW7+CD7+CK7+CR7+CY7+DF7+DM7+DT7+EA7+EH7+EO7+EV7+FC7+FJ7+FQ7+FX7+GE7+GL7+GS7+GZ7+HG7+HN7+HU7 -> 0 | L7: =+T7+AA7+AH7+AO7+AV7+BC7+BJ7+BQ7+BX7+CE7+CL7+CS7+CZ7+DG7+DN7+DU7+EB7+EI7+EP7+EW7+FD7+FK7+FR7+FY7+GF7+GM7+GT7+HA7+HH7+HO7+HV7 -> 0 | M7: =SUM(G7:L7) -> 0 | N7: =+G7+H7+I7+J7+K7 -> 0 | O7: =IFERROR(VLOOKUP(B7,'1ไม่มียอด'!B:D,3,0),"0") -> 0 | P7: =IFERROR(VLOOKUP(B7,'1ไม่มียอด'!B:E,4,0),"0") -> 0 | Q7: =IFERROR(VLOOKUP(B7,'1ไม่มียอด'!B:F,5,0),"0") -> 0 | R7: =IFERROR(VLOOKUP(B7,'1ไม่มียอด'!B:G,6,0),"0") -> 0 | S7: =IFERROR(VLOOKUP(B7,'1ไม่มียอด'!B:J,9,0),"0") -> 0 | T7: =IFERROR(VLOOKUP(B7,'1ไม่มียอด'!B:K,10,0),"0") -> 0 | U7: =SUM(O7:R7) -> 0 | V7: =IFERROR(VLOOKUP(B7,#REF!,3,0),"0") -> 0 | W7: =IFERROR(VLOOKUP(B7,#REF!,4,0),"0") -> 0 | X7: =IFERROR(VLOOKUP(B7,#REF!,5,0),"0") -> 0 | Y7: =IFERROR(VLOOKUP(B7,#REF!,9,0),"0") -> 0 | Z7: =IFERROR(VLOOKUP(B7,#REF!,10,0),"0") -> 0 | AA7: =IFERROR(VLOOKUP(B7,#REF!,11,0),"0") -> 0 | AB7: =SUM(V7:Y7) -> 0 | AC7: =IFERROR(VLOOKUP(B7,'3'!B:D,3,0),"0") -> 0 | AD7: =IFERROR(VLOOKUP(B7,'3'!B:E,4,0),"0") -> 0 | AE7: =IFERROR(VLOOKUP(B7,'3'!B:F,5,0),"0") -> 0 | AF7: =IFERROR(VLOOKUP(B7,'3'!B:J,9,0),"0") -> 0 | AG7: =IFERROR(VLOOKUP(B7,'3'!B:K,10,0),"0") -> 0 | AH7: =IFERROR(VLOOKUP(B7,'3'!B:L,11,0),"0") -> 0 | AI7: =SUM(AC7:AH7) -> 0 | AJ7: =IFERROR(VLOOKUP(B7,'4'!B:D,3,0),"0") -> 0 | AK7: =IFERROR(VLOOKUP(B7,'4'!B:E,4,0),"0") -> 0 | AL7: =IFERROR(VLOOKUP(B7,'4'!B:F,5,0),"0") -> 0 | AM7: =IFERROR(VLOOKUP(B7,'4'!B:J,9,0),"0") -> 0 | AN7: =IFERROR(VLOOKUP(B7,'4'!B:K,10,0),"0") -> 0 | AO7: =IFERROR(VLOOKUP(B7,'4'!B:L,11,0),"0") -> 0 | AP7: =SUM(AJ7:AO7) -> 0 | AQ7: =IFERROR(VLOOKUP(B7,'5'!B:D,3,0),"0") -> 0 | AR7: =IFERROR(VLOOKUP(B7,'5'!B:E,4,0),"0") -> 0 | AS7: =IFERROR(VLOOKUP(B7,'5'!B:F,5,0),"0") -> 0 | AT7: =IFERROR(VLOOKUP(B7,'5'!B:J,9,0),"0") -> 0 | AU7: =IFERROR(VLOOKUP(B7,'5'!B:K,10,0),"0") -> 0 | AV7: =IFERROR(VLOOKUP(B7,'5'!B:L,11,0),"0") -> 0 | AW7: =SUM(AQ7:AT7) -> 0 | AX7: =IFERROR(VLOOKUP(B7,'6'!B:D,3,0),"0") -> 0 | AY7: =IFERROR(VLOOKUP(B7,'6'!B:E,4,0),"0") -> 0 | AZ7: =IFERROR(VLOOKUP(B7,'6'!B:F,5,0),"0") -> 0 | BA7: =IFERROR(VLOOKUP(B7,'6'!B:J,9,0),"0") -> 0 | BB7: =IFERROR(VLOOKUP(B7,'6'!B:K,10,0),"0") -> 0 | BC7: =IFERROR(VLOOKUP(B7,'6'!B:L,11,0),"0") -> 0 | BD7: =SUM(AX7:BC7) -> 0 | BE7: =IFERROR(VLOOKUP(B7,'7'!B:D,3,0),"0") -> 0 | BF7: =IFERROR(VLOOKUP(B7,'7'!B:E,4,0),"0") -> 0 | BG7: =IFERROR(VLOOKUP(B7,'7'!B:F,5,0),"0") -> 0 | BH7: =IFERROR(VLOOKUP(B7,'7'!B:J,9,0),"0") -> 0 | BI7: =IFERROR(VLOOKUP(B7,'7'!B:K,10,0),"0") -> 0 | BJ7: =IFERROR(VLOOKUP(B7,'7'!B:L,11,0),"0") -> 0 | BK7: =SUM(BE7:BH7) -> 0 | BL7: =IFERROR(VLOOKUP(B7,'8'!B:D,3,0),"0") -> 0 | BM7: =IFERROR(VLOOKUP(B7,'8'!B:E,4,0),"0") -> 0 | BN7: =IFERROR(VLOOKUP(B7,'8'!B:F,5,0),"0") -> 0 | BO7: =IFERROR(VLOOKUP(B7,'8'!B:J,9,0),"0") -> 0 | BP7: =IFERROR(VLOOKUP(B7,'8'!B:K,10,0),"0") -> 0 | BQ7: =IFERROR(VLOOKUP(B7,'8'!B:L,11,0),"0") -> 0 | BR7: =SUM(BL7:BQ7) -> 0 | BS7: =IFERROR(VLOOKUP(B7,'9'!B:D,3,0),"0") -> 0 | BT7: =IFERROR(VLOOKUP(B7,'9'!B:E,4,0),"0") -> 0 | BU7: =IFERROR(VLOOKUP(B7,'9'!B:F,5,0),"0") -> 0 | BV7: =IFERROR(VLOOKUP(B7,'9'!B:J,9,0),"0") -> 0 | BW7: =IFERROR(VLOOKUP(B7,'9'!B:K,10,0),"0") -> 0 | BX7: =IFERROR(VLOOKUP(B7,'9'!B:L,11,0),"0") -> 0 | BY7: =SUM(BS7:BX7) -> 0 | BZ7: =IFERROR(VLOOKUP(B7,'10'!B:D,3,0),"0") -> 0 | CA7: =IFERROR(VLOOKUP(B7,'10'!B:E,4,0),"0") -> 0 | CB7: =VLOOKUP(B7,'10'!B:F,5,0) -> 0 | CC7: =IFERROR(VLOOKUP(B7,'10'!B:J,9,0),"0") -> 0 | CD7: =IFERROR(VLOOKUP(B7,'10'!B:K,10,0),"0") -> 0 | CE7: =IFERROR(VLOOKUP(B7,'10'!B:L,11,0),"0") -> 0 | CF7: =SUM(BZ7:CC7) -> 0 | CG7: =IFERROR(VLOOKUP(B7,'11'!B:D,3,0),"0") -> 0 | CH7: =IFERROR(VLOOKUP(B7,'11'!B:E,4,0),"0") -> 0 | CI7: =IFERROR(VLOOKUP(B7,'11'!B:F,5,0),"0") -> 0 | CJ7: =IFERROR(VLOOKUP(B7,'11'!B:J,9,0),"0") -> 0 | CK7: =IFERROR(VLOOKUP(B7,'11'!B:K,10,0),"0") -> 0 | CL7: =IFERROR(VLOOKUP(B7,'11'!B:L,11,0),"0") -> 0 | CM7: =SUM(CG7:CJ7) -> 0 | CN7: =IFERROR(VLOOKUP(B7,'12'!B:D,3,0),"0") -> 0 | CO7: =IFERROR(VLOOKUP(B7,'12'!B:E,4,0),"0") -> 0 | CP7: =IFERROR(VLOOKUP(B7,'12'!B:F,5,0),"0") -> 0 | CQ7: =IFERROR(VLOOKUP(B7,'12'!B:J,9,0),"0") -> 0 | CR7: =IFERROR(VLOOKUP(B7,'12'!B:K,10,0),"0") -> 0 | CS7: =IFERROR(VLOOKUP(B7,'12'!B:L,11,0),"0") -> 0 | CT7: =SUM(CN7:CQ7) -> 0 | CU7: =IFERROR(VLOOKUP(B7,'13'!B:D,3,0),"0") -> 0 | CV7: =IFERROR(VLOOKUP(B7,'13'!B:E,4,0),"0") -> 0 | CW7: =IFERROR(VLOOKUP(B7,'13'!B:F,5,0),"0") -> 0 | CX7: =IFERROR(VLOOKUP(B7,'13'!B:J,9,0),"0") -> 0 | CY7: =IFERROR(VLOOKUP(B7,'13'!B:K,10,0),"0") -> 0 | CZ7: =IFERROR(VLOOKUP(B7,'13'!B:L,11,0),"0") -> 0 | DA7: =SUM(CU7:CX7) -> 0 | DB7: =IFERROR(VLOOKUP(B7,'14'!B:D,3,0),"0") -> 0 | DC7: =IFERROR(VLOOKUP(B7,'14'!B:E,4,0),"0") -> 0 | DD7: =IFERROR(VLOOKUP(B7,'14'!B:F,5,0),"0") -> 0 | DE7: =IFERROR(VLOOKUP(B7,'14'!B:J,9,0),"0") -> 0 | DF7: =IFERROR(VLOOKUP(B7,'14'!B:K,10,0),"0") -> 0 | DG7: =IFERROR(VLOOKUP(B7,'14'!B:L,11,0),"0") -> 0 | DH7: =SUM(DB7:DE7) -> 0 | DI7: =IFERROR(VLOOKUP(B7,'15'!B:D,3,0),"0") -> 0 | DJ7: =IFERROR(VLOOKUP(B7,'15'!B:E,4,0),"0") -> 0 | DK7: =IFERROR(VLOOKUP(B7,'15'!B:F,5,0),"0") -> 0 | DL7: =IFERROR(VLOOKUP(B7,'15'!B:J,9,0),"0") -> 0 | DM7: =IFERROR(VLOOKUP(B7,'15'!B:K,10,0),"0") -> 0 | DN7: =IFERROR(VLOOKUP(B7,'15'!B:L,11,0),"0") -> 0 | DO7: =SUM(DI7:DL7) -> 0 | DP7: =IFERROR(VLOOKUP(B7,'16'!B:D,3,0),"0") -> 0 | DQ7: =IFERROR(VLOOKUP(B7,'16'!B:E,4,0),"0") -> 0 | DR7: =IFERROR(VLOOKUP(B7,'16'!B:F,5,0),"0") -> 0 | DS7: =IFERROR(VLOOKUP(B7,'16'!B:J,9,0),"0") -> 0 | DT7: =IFERROR(VLOOKUP(B7,'16'!B:K,10,0),"0") -> 0 | DU7: =IFERROR(VLOOKUP(B7,'16'!B:L,11,0),"0") -> 0 | DV7: =SUM(DP7:DS7) -> 0 | DW7: =IFERROR(VLOOKUP(B7,'17'!B:D,3,0),"0") -> 0 | DX7: =IFERROR(VLOOKUP(B7,'17'!B:E,4,0),"0") -> 0 | DY7: =IFERROR(VLOOKUP(B7,'17'!B:F,5,0),"0") -> 0 | DZ7: =IFERROR(VLOOKUP(B7,'17'!B:J,9,0),"0") -> 0 | EA7: =IFERROR(VLOOKUP(B7,'17'!B:K,10,0),"0") -> 0 | EB7: =IFERROR(VLOOKUP(B7,'17'!B:L,11,0),"0") -> 0 | EC7: =SUM(DW7:DZ7) -> 0 | ED7: =IFERROR(VLOOKUP(B7,'18'!B:D,3,0),"0") -> 0 | EE7: =IFERROR(VLOOKUP(B7,'18'!B:E,4,0),"0") -> 0 | EF7: =IFERROR(VLOOKUP(B7,'18'!B:F,5,0),"0") -> 0 | EG7: =IFERROR(VLOOKUP(B7,'18'!B:J,9,0),"0") -> 0 | EH7: =IFERROR(VLOOKUP(B7,'18'!B:K,10,0),"0") -> 0 | EI7: =IFERROR(VLOOKUP(B7,'18'!B:L,11,0),"0") -> 0 | EJ7: =SUM(ED7:EI7) -> 0 | EK7: =IFERROR(VLOOKUP(B7,'19'!B:D,3,0),"0") -> 0 | EL7: =IFERROR(VLOOKUP(B7,'19'!B:E,4,0),"0") -> 0 | EM7: =IFERROR(VLOOKUP(B7,'19'!B:F,5,0),"0") -> 0 | EN7: =IFERROR(VLOOKUP(B7,'19'!B:J,9,0),"0") -> 0 | EO7: =IFERROR(VLOOKUP(B7,'19'!B:K,10,0),"0") -> 0 | EP7: =IFERROR(VLOOKUP(B7,'19'!B:L,11,0),"0") -> 0 | EQ7: =SUM(EK7:EP7) -> 0 | ER7: =IFERROR(VLOOKUP(B7,'20'!B:D,3,0),"0") -> 0 | ES7: =IFERROR(VLOOKUP(B7,'20'!B:E,4,0),"0") -> 0 | ET7: =IFERROR(VLOOKUP(B7,'20'!B:F,5,0),"0") -> 0 | EU7: =IFERROR(VLOOKUP(B7,'20'!B:J,9,0),"0") -> 0 | EV7: =IFERROR(VLOOKUP(B7,'20'!B:K,10,0),"0") -> 0 | EW7: =IFERROR(VLOOKUP(B7,'20'!B:L,11,0),"0") -> 0 | EX7: =SUM(ER7:EW7) -> 0 | EY7: =IFERROR(VLOOKUP(B7,'21'!B:D,3,0),"0") -> 0 | EZ7: =IFERROR(VLOOKUP(B7,'21'!B:E,4,0),"0") -> 0 | FA7: =IFERROR(VLOOKUP(B7,'21'!B:F,5,0),"0") -> 0 | FB7: =IFERROR(VLOOKUP(B7,'21'!B:J,9,0),"0") -> 0 | FC7: =IFERROR(VLOOKUP(B7,'21'!B:K,10,0),"0") -> 0 | FD7: =IFERROR(VLOOKUP(B7,'21'!B:L,11,0),"0") -> 0 | FE7: =SUM(EY7:FD7) -> 0 | FF7: =IFERROR(VLOOKUP(B7,'22'!B:D,3,0),"0") -> 0 | FG7: =IFERROR(VLOOKUP(B7,'22'!B:E,4,0),"0") -> 0 | FH7: =IFERROR(VLOOKUP(B7,'22'!B:F,5,0),"0") -> 0 | FI7: =IFERROR(VLOOKUP(B7,'22'!B:J,9,0),"0") -> 0 | FJ7: =IFERROR(VLOOKUP(B7,'22'!B:K,10,0),"0") -> 0 | FK7: =IFERROR(VLOOKUP(B7,'22'!B:L,11,0),"0") -> 0 | FL7: =SUM(FF7:FK7) -> 0 | FM7: =IFERROR(VLOOKUP(B7,'23'!B:D,3,0),"0") -> 0 | FN7: =IFERROR(VLOOKUP(B7,'23'!B:E,4,0),"0") -> 0 | FO7: =IFERROR(VLOOKUP(B7,'23'!B:F,5,0),"0") -> 0 | FP7: =IFERROR(VLOOKUP(B7,'23'!B:J,9,0),"0") -> 0 | FQ7: =IFERROR(VLOOKUP(B7,'23'!B:K,10,0),"0") -> 0 | FR7: =IFERROR(VLOOKUP(B7,'23'!B:L,11,0),"0") -> 0 | FS7: =SUM(FM7:FR7) -> 0 | FT7: =IFERROR(VLOOKUP(B7,'24'!B:D,3,0),"0") -> 0 | FU7: =IFERROR(VLOOKUP(B7,'24'!B:E,4,0),"0") -> 0 | FV7: =IFERROR(VLOOKUP(B7,'24'!B:F,5,0),"0") -> 0 | FW7: =IFERROR(VLOOKUP(B7,'24'!B:J,9,0),"0") -> 0 | FX7: =IFERROR(VLOOKUP(B7,'24'!B:K,10,0),"0") -> 0 | FY7: =IFERROR(VLOOKUP(B7,'24'!B:L,11,0),"0") -> 0 | FZ7: =SUM(FT7:FY7) -> 0 | GA7: =IFERROR(VLOOKUP(B7,'25'!B:D,3,0),"0") -> 0 | GB7: =IFERROR(VLOOKUP(B7,'25'!B:E,4,0),"0") -> 0 | GC7: =IFERROR(VLOOKUP(B7,'25'!B:F,5,0),"0") -> 0 | GD7: =IFERROR(VLOOKUP(B7,'25'!B:J,9,0),"0") -> 0 | GE7: =IFERROR(VLOOKUP(B7,'25'!B:K,10,0),"0") -> 0 | GF7: =IFERROR(VLOOKUP(B7,'25'!B:L,11,0),"0") -> 0 | GG7: =SUM(GA7:GD7) -> 0 | GH7: =IFERROR(VLOOKUP(B7,'26'!B:D,3,0),"0") -> 0 | GI7: =IFERROR(VLOOKUP(B7,'26'!B:E,4,0),"0") -> 0 | GJ7: =IFERROR(VLOOKUP(B7,'26'!B:F,5,0),"0") -> 0 | GK7: =IFERROR(VLOOKUP(B7,'26'!B:J,9,0),"0") -> 0 | GL7: =IFERROR(VLOOKUP(B7,'26'!B:K,10,0),"0") -> 0 | GM7: =IFERROR(VLOOKUP(B7,'26'!B:L,11,0),"0") -> 0 | GN7: =SUM(GH7:GK7) -> 0 | GO7: =IFERROR(VLOOKUP(B7,'27'!B:D,3,0),"0") -> 0 | GP7: =IFERROR(VLOOKUP(B7,'27'!B:E,4,0),"0") -> 0 | GQ7: =IFERROR(VLOOKUP(B7,'27'!B:F,5,0),"0") -> 0 | GR7: =IFERROR(VLOOKUP(B7,'27'!B:J,9,0),"0") -> 0 | GS7: =IFERROR(VLOOKUP(B7,'27'!B:K,10,0),"0") -> 0 | GT7: =IFERROR(VLOOKUP(B7,'27'!B:L,11,0),"0") -> 0 | GU7: =SUM(GO7:GT7) -> 0 | GV7: =IFERROR(VLOOKUP(B7,'28'!B:D,3,0),"0") -> 0 | GW7: =IFERROR(VLOOKUP(B7,'28'!B:E,4,0),"0") -> 0 | GX7: =IFERROR(VLOOKUP(B7,'28'!B:F,5,0),"0") -> 0 | GY7: =IFERROR(VLOOKUP(B7,'28'!B:J,9,0),"0") -> 0 | GZ7: =IFERROR(VLOOKUP(B7,'28'!B:K,10,0),"0") -> 0 | HA7: =IFERROR(VLOOKUP(B7,'28'!B:L,11,0),"0") -> 0 | HB7: =SUM(GV7:HA7) -> 0 | HC7: =IFERROR(VLOOKUP(B7,#REF!,3),"0") -> 0 | HD7: =IFERROR(VLOOKUP(B7,#REF!,4,0),"0") -> 0 | HE7: =IFERROR(VLOOKUP(B7,#REF!,5,0),"0") -> 0 | HF7: =IFERROR(VLOOKUP(B7,#REF!,9,0),"0") -> 0 | HG7: =IFERROR(VLOOKUP(B7,#REF!,10,0),"0") -> 0 | HH7: =IFERROR(VLOOKUP(B7,#REF!,11,0),"0") -> 0 | HI7: =SUM(HC7:HF7) -> 0 | HP7: =SUM(HJ7:HM7) -> 0 | HW7: =SUM(HQ7:HT7) -> 0
A8: 5 | B8: 1111087 | C8: ชิฟฟอน 8 ชิ้น สตอเบอรี่ล้วน | D8: กล่อง | E8: 37 | F8: =+M8*E8 -> 0 | G8: =+O8+V8+AC8+AJ8+AQ8+AX8+BE8+BL8+BS8+BZ8+CG8+CN8+CU8+DB8+DI8+DP8+DW8+ED8+EK8+ER8+EY8+FF8+FM8+FT8+GA8+GH8+GO8+GV8+HC8+HJ8+HQ8 -> 0 | H8: =+P8+W8+AD8+AK8+AR8+AY8+BF8+BM8+BT8+CA8+CH8+CO8+CV8+DC8+DJ8+DQ8+DX8+EE8+EL8+ES8+EZ8+FG8+FN8+FU8+GB8+GI8+GP8+GW8+HD8+HK8+HR8 -> 0 | I8: =+Q8+X8+AE8+AL8+AS8+AZ8+BG8+BN8+BU8+CB8+CI8+CP8+CW8+DD8+DK8+DR8+DY8+EF8+EM8+ET8+FA8+FH8+FO8+FV8+GC8+GJ8+GQ8+GX8+HE8+HL8+HS8 -> 0 | J8: =+R8+Y8+AF8+AM8+AT8+BA8+BH8+BO8+BV8+CC8+CJ8+CQ8+CX8+DE8+DL8+DS8+DZ8+EG8+EN8+EU8+FB8+FI8+FP8+FW8+GD8+GK8+GR8+GY8+HF8+HM8+HT8 -> 0 | K8: =+S8+Z8+AG8+AN8+AU8+BB8+BI8+BP8+BW8+CD8+CK8+CR8+CY8+DF8+DM8+DT8+EA8+EH8+EO8+EV8+FC8+FJ8+FQ8+FX8+GE8+GL8+GS8+GZ8+HG8+HN8+HU8 -> 0 | L8: =+T8+AA8+AH8+AO8+AV8+BC8+BJ8+BQ8+BX8+CE8+CL8+CS8+CZ8+DG8+DN8+DU8+EB8+EI8+EP8+EW8+FD8+FK8+FR8+FY8+GF8+GM8+GT8+HA8+HH8+HO8+HV8 -> 0 | M8: =SUM(G8:L8) -> 0 | N8: =+G8+H8+I8+J8+K8 -> 0 | O8: =IFERROR(VLOOKUP(B8,'1ไม่มียอด'!B:D,3,0),"0") -> 0 | P8: =IFERROR(VLOOKUP(B8,'1ไม่มียอด'!B:E,4,0),"0") -> 0 | Q8: =IFERROR(VLOOKUP(B8,'1ไม่มียอด'!B:F,5,0),"0") -> 0 | R8: =IFERROR(VLOOKUP(B8,'1ไม่มียอด'!B:G,6,0),"0") -> 0 | S8: =IFERROR(VLOOKUP(B8,'1ไม่มียอด'!B:J,9,0),"0") -> 0 | T8: =IFERROR(VLOOKUP(B8,'1ไม่มียอด'!B:K,10,0),"0") -> 0 | U8: =SUM(O8:R8) -> 0 | V8: =IFERROR(VLOOKUP(B8,#REF!,3,0),"0") -> 0 | W8: =IFERROR(VLOOKUP(B8,#REF!,4,0),"0") -> 0 | X8: =IFERROR(VLOOKUP(B8,#REF!,5,0),"0") -> 0 | Y8: =IFERROR(VLOOKUP(B8,#REF!,9,0),"0") -> 0 | Z8: =IFERROR(VLOOKUP(B8,#REF!,10,0),"0") -> 0 | AA8: =IFERROR(VLOOKUP(B8,#REF!,11,0),"0") -> 0 | AB8: =SUM(V8:Y8) -> 0 | AC8: =IFERROR(VLOOKUP(B8,'3'!B:D,3,0),"0") -> 0 | AD8: =IFERROR(VLOOKUP(B8,'3'!B:E,4,0),"0") -> 0 | AE8: =IFERROR(VLOOKUP(B8,'3'!B:F,5,0),"0") -> 0 | AF8: =IFERROR(VLOOKUP(B8,'3'!B:J,9,0),"0") -> 0 | AG8: =IFERROR(VLOOKUP(B8,'3'!B:K,10,0),"0") -> 0 | AH8: =IFERROR(VLOOKUP(B8,'3'!B:L,11,0),"0") -> 0 | AI8: =SUM(AC8:AH8) -> 0 | AJ8: =IFERROR(VLOOKUP(B8,'4'!B:D,3,0),"0") -> 0 | AK8: =IFERROR(VLOOKUP(B8,'4'!B:E,4,0),"0") -> 0 | AL8: =IFERROR(VLOOKUP(B8,'4'!B:F,5,0),"0") -> 0 | AM8: =IFERROR(VLOOKUP(B8,'4'!B:J,9,0),"0") -> 0 | AN8: =IFERROR(VLOOKUP(B8,'4'!B:K,10,0),"0") -> 0 | AO8: =IFERROR(VLOOKUP(B8,'4'!B:L,11,0),"0") -> 0 | AP8: =SUM(AJ8:AO8) -> 0 | AQ8: =IFERROR(VLOOKUP(B8,'5'!B:D,3,0),"0") -> 0 | AR8: =IFERROR(VLOOKUP(B8,'5'!B:E,4,0),"0") -> 0 | AS8: =IFERROR(VLOOKUP(B8,'5'!B:F,5,0),"0") -> 0 | AT8: =IFERROR(VLOOKUP(B8,'5'!B:J,9,0),"0") -> 0 | AU8: =IFERROR(VLOOKUP(B8,'5'!B:K,10,0),"0") -> 0 | AV8: =IFERROR(VLOOKUP(B8,'5'!B:L,11,0),"0") -> 0 | AW8: =SUM(AQ8:AT8) -> 0 | AX8: =IFERROR(VLOOKUP(B8,'6'!B:D,3,0),"0") -> 0 | AY8: =IFERROR(VLOOKUP(B8,'6'!B:E,4,0),"0") -> 0 | AZ8: =IFERROR(VLOOKUP(B8,'6'!B:F,5,0),"0") -> 0 | BA8: =IFERROR(VLOOKUP(B8,'6'!B:J,9,0),"0") -> 0 | BB8: =IFERROR(VLOOKUP(B8,'6'!B:K,10,0),"0") -> 0 | BC8: =IFERROR(VLOOKUP(B8,'6'!B:L,11,0),"0") -> 0 | BD8: =SUM(AX8:BC8) -> 0 | BE8: =IFERROR(VLOOKUP(B8,'7'!B:D,3,0),"0") -> 0 | BF8: =IFERROR(VLOOKUP(B8,'7'!B:E,4,0),"0") -> 0 | BG8: =IFERROR(VLOOKUP(B8,'7'!B:F,5,0),"0") -> 0 | BH8: =IFERROR(VLOOKUP(B8,'7'!B:J,9,0),"0") -> 0 | BI8: =IFERROR(VLOOKUP(B8,'7'!B:K,10,0),"0") -> 0 | BJ8: =IFERROR(VLOOKUP(B8,'7'!B:L,11,0),"0") -> 0 | BK8: =SUM(BE8:BH8) -> 0 | BL8: =IFERROR(VLOOKUP(B8,'8'!B:D,3,0),"0") -> 0 | BM8: =IFERROR(VLOOKUP(B8,'8'!B:E,4,0),"0") -> 0 | BN8: =IFERROR(VLOOKUP(B8,'8'!B:F,5,0),"0") -> 0 | BO8: =IFERROR(VLOOKUP(B8,'8'!B:J,9,0),"0") -> 0 | BP8: =IFERROR(VLOOKUP(B8,'8'!B:K,10,0),"0") -> 0 | BQ8: =IFERROR(VLOOKUP(B8,'8'!B:L,11,0),"0") -> 0 | BR8: =SUM(BL8:BQ8) -> 0 | BS8: =IFERROR(VLOOKUP(B8,'9'!B:D,3,0),"0") -> 0 | BT8: =IFERROR(VLOOKUP(B8,'9'!B:E,4,0),"0") -> 0 | BU8: =IFERROR(VLOOKUP(B8,'9'!B:F,5,0),"0") -> 0 | BV8: =IFERROR(VLOOKUP(B8,'9'!B:J,9,0),"0") -> 0 | BW8: =IFERROR(VLOOKUP(B8,'9'!B:K,10,0),"0") -> 0 | BX8: =IFERROR(VLOOKUP(B8,'9'!B:L,11,0),"0") -> 0 | BY8: =SUM(BS8:BX8) -> 0 | BZ8: =IFERROR(VLOOKUP(B8,'10'!B:D,3,0),"0") -> 0 | CA8: =IFERROR(VLOOKUP(B8,'10'!B:E,4,0),"0") -> 0 | CB8: =VLOOKUP(B8,'10'!B:F,5,0) -> 0 | CC8: =IFERROR(VLOOKUP(B8,'10'!B:J,9,0),"0") -> 0 | CD8: =IFERROR(VLOOKUP(B8,'10'!B:K,10,0),"0") -> 0 | CE8: =IFERROR(VLOOKUP(B8,'10'!B:L,11,0),"0") -> 0 | CF8: =SUM(BZ8:CC8) -> 0 | CG8: =IFERROR(VLOOKUP(B8,'11'!B:D,3,0),"0") -> 0 | CH8: =IFERROR(VLOOKUP(B8,'11'!B:E,4,0),"0") -> 0 | CI8: =IFERROR(VLOOKUP(B8,'11'!B:F,5,0),"0") -> 0 | CJ8: =IFERROR(VLOOKUP(B8,'11'!B:J,9,0),"0") -> 0 | CK8: =IFERROR(VLOOKUP(B8,'11'!B:K,10,0),"0") -> 0 | CL8: =IFERROR(VLOOKUP(B8,'11'!B:L,11,0),"0") -> 0 | CM8: =SUM(CG8:CJ8) -> 0 | CN8: =IFERROR(VLOOKUP(B8,'12'!B:D,3,0),"0") -> 0 | CO8: =IFERROR(VLOOKUP(B8,'12'!B:E,4,0),"0") -> 0 | CP8: =IFERROR(VLOOKUP(B8,'12'!B:F,5,0),"0") -> 0 | CQ8: =IFERROR(VLOOKUP(B8,'12'!B:J,9,0),"0") -> 0 | CR8: =IFERROR(VLOOKUP(B8,'12'!B:K,10,0),"0") -> 0 | CS8: =IFERROR(VLOOKUP(B8,'12'!B:L,11,0),"0") -> 0 | CT8: =SUM(CN8:CQ8) -> 0 | CU8: =IFERROR(VLOOKUP(B8,'13'!B:D,3,0),"0") -> 0 | CV8: =IFERROR(VLOOKUP(B8,'13'!B:E,4,0),"0") -> 0 | CW8: =IFERROR(VLOOKUP(B8,'13'!B:F,5,0),"0") -> 0 | CX8: =IFERROR(VLOOKUP(B8,'13'!B:J,9,0),"0") -> 0 | CY8: =IFERROR(VLOOKUP(B8,'13'!B:K,10,0),"0") -> 0 | CZ8: =IFERROR(VLOOKUP(B8,'13'!B:L,11,0),"0") -> 0 | DA8: =SUM(CU8:CX8) -> 0 | DB8: =IFERROR(VLOOKUP(B8,'14'!B:D,3,0),"0") -> 0 | DC8: =IFERROR(VLOOKUP(B8,'14'!B:E,4,0),"0") -> 0 | DD8: =IFERROR(VLOOKUP(B8,'14'!B:F,5,0),"0") -> 0 | DE8: =IFERROR(VLOOKUP(B8,'14'!B:J,9,0),"0") -> 0 | DF8: =IFERROR(VLOOKUP(B8,'14'!B:K,10,0),"0") -> 0 | DG8: =IFERROR(VLOOKUP(B8,'14'!B:L,11,0),"0") -> 0 | DH8: =SUM(DB8:DE8) -> 0 | DI8: =IFERROR(VLOOKUP(B8,'15'!B:D,3,0),"0") -> 0 | DJ8: =IFERROR(VLOOKUP(B8,'15'!B:E,4,0),"0") -> 0 | DK8: =IFERROR(VLOOKUP(B8,'15'!B:F,5,0),"0") -> 0 | DL8: =IFERROR(VLOOKUP(B8,'15'!B:J,9,0),"0") -> 0 | DM8: =IFERROR(VLOOKUP(B8,'15'!B:K,10,0),"0") -> 0 | DN8: =IFERROR(VLOOKUP(B8,'15'!B:L,11,0),"0") -> 0 | DO8: =SUM(DI8:DL8) -> 0 | DP8: =IFERROR(VLOOKUP(B8,'16'!B:D,3,0),"0") -> 0 | DQ8: =IFERROR(VLOOKUP(B8,'16'!B:E,4,0),"0") -> 0 | DR8: =IFERROR(VLOOKUP(B8,'16'!B:F,5,0),"0") -> 0 | DS8: =IFERROR(VLOOKUP(B8,'16'!B:J,9,0),"0") -> 0 | DT8: =IFERROR(VLOOKUP(B8,'16'!B:K,10,0),"0") -> 0 | DU8: =IFERROR(VLOOKUP(B8,'16'!B:L,11,0),"0") -> 0 | DV8: =SUM(DP8:DS8) -> 0 | DW8: =IFERROR(VLOOKUP(B8,'17'!B:D,3,0),"0") -> 0 | DX8: =IFERROR(VLOOKUP(B8,'17'!B:E,4,0),"0") -> 0 | DY8: =IFERROR(VLOOKUP(B8,'17'!B:F,5,0),"0") -> 0 | DZ8: =IFERROR(VLOOKUP(B8,'17'!B:J,9,0),"0") -> 0 | EA8: =IFERROR(VLOOKUP(B8,'17'!B:K,10,0),"0") -> 0 | EB8: =IFERROR(VLOOKUP(B8,'17'!B:L,11,0),"0") -> 0 | EC8: =SUM(DW8:DZ8) -> 0 | ED8: =IFERROR(VLOOKUP(B8,'18'!B:D,3,0),"0") -> 0 | EE8: =IFERROR(VLOOKUP(B8,'18'!B:E,4,0),"0") -> 0 | EF8: =IFERROR(VLOOKUP(B8,'18'!B:F,5,0),"0") -> 0 | EG8: =IFERROR(VLOOKUP(B8,'18'!B:J,9,0),"0") -> 0 | EH8: =IFERROR(VLOOKUP(B8,'18'!B:K,10,0),"0") -> 0 | EI8: =IFERROR(VLOOKUP(B8,'18'!B:L,11,0),"0") -> 0 | EJ8: =SUM(ED8:EI8) -> 0 | EK8: =IFERROR(VLOOKUP(B8,'19'!B:D,3,0),"0") -> 0 | EL8: =IFERROR(VLOOKUP(B8,'19'!B:E,4,0),"0") -> 0 | EM8: =IFERROR(VLOOKUP(B8,'19'!B:F,5,0),"0") -> 0 | EN8: =IFERROR(VLOOKUP(B8,'19'!B:J,9,0),"0") -> 0 | EO8: =IFERROR(VLOOKUP(B8,'19'!B:K,10,0),"0") -> 0 | EP8: =IFERROR(VLOOKUP(B8,'19'!B:L,11,0),"0") -> 0 | EQ8: =SUM(EK8:EP8) -> 0 | ER8: =IFERROR(VLOOKUP(B8,'20'!B:D,3,0),"0") -> 0 | ES8: =IFERROR(VLOOKUP(B8,'20'!B:E,4,0),"0") -> 0 | ET8: =IFERROR(VLOOKUP(B8,'20'!B:F,5,0),"0") -> 0 | EU8: =IFERROR(VLOOKUP(B8,'20'!B:J,9,0),"0") -> 0 | EV8: =IFERROR(VLOOKUP(B8,'20'!B:K,10,0),"0") -> 0 | EW8: =IFERROR(VLOOKUP(B8,'20'!B:L,11,0),"0") -> 0 | EX8: =SUM(ER8:EW8) -> 0 | EY8: =IFERROR(VLOOKUP(B8,'21'!B:D,3,0),"0") -> 0 | EZ8: =IFERROR(VLOOKUP(B8,'21'!B:E,4,0),"0") -> 0 | FA8: =IFERROR(VLOOKUP(B8,'21'!B:F,5,0),"0") -> 0 | FB8: =IFERROR(VLOOKUP(B8,'21'!B:J,9,0),"0") -> 0 | FC8: =IFERROR(VLOOKUP(B8,'21'!B:K,10,0),"0") -> 0 | FD8: =IFERROR(VLOOKUP(B8,'21'!B:L,11,0),"0") -> 0 | FE8: =SUM(EY8:FD8) -> 0 | FF8: =IFERROR(VLOOKUP(B8,'22'!B:D,3,0),"0") -> 0 | FG8: =IFERROR(VLOOKUP(B8,'22'!B:E,4,0),"0") -> 0 | FH8: =IFERROR(VLOOKUP(B8,'22'!B:F,5,0),"0") -> 0 | FI8: =IFERROR(VLOOKUP(B8,'22'!B:J,9,0),"0") -> 0 | FJ8: =IFERROR(VLOOKUP(B8,'22'!B:K,10,0),"0") -> 0 | FK8: =IFERROR(VLOOKUP(B8,'22'!B:L,11,0),"0") -> 0 | FL8: =SUM(FF8:FK8) -> 0 | FM8: =IFERROR(VLOOKUP(B8,'23'!B:D,3,0),"0") -> 0 | FN8: =IFERROR(VLOOKUP(B8,'23'!B:E,4,0),"0") -> 0 | FO8: =IFERROR(VLOOKUP(B8,'23'!B:F,5,0),"0") -> 0 | FP8: =IFERROR(VLOOKUP(B8,'23'!B:J,9,0),"0") -> 0 | FQ8: =IFERROR(VLOOKUP(B8,'23'!B:K,10,0),"0") -> 0 | FR8: =IFERROR(VLOOKUP(B8,'23'!B:L,11,0),"0") -> 0 | FS8: =SUM(FM8:FR8) -> 0 | FT8: =IFERROR(VLOOKUP(B8,'24'!B:D,3,0),"0") -> 0 | FU8: =IFERROR(VLOOKUP(B8,'24'!B:E,4,0),"0") -> 0 | FV8: =IFERROR(VLOOKUP(B8,'24'!B:F,5,0),"0") -> 0 | FW8: =IFERROR(VLOOKUP(B8,'24'!B:J,9,0),"0") -> 0 | FX8: =IFERROR(VLOOKUP(B8,'24'!B:K,10,0),"0") -> 0 | FY8: =IFERROR(VLOOKUP(B8,'24'!B:L,11,0),"0") -> 0 | FZ8: =SUM(FT8:FY8) -> 0 | GA8: =IFERROR(VLOOKUP(B8,'25'!B:D,3,0),"0") -> 0 | GB8: =IFERROR(VLOOKUP(B8,'25'!B:E,4,0),"0") -> 0 | GC8: =IFERROR(VLOOKUP(B8,'25'!B:F,5,0),"0") -> 0 | GD8: =IFERROR(VLOOKUP(B8,'25'!B:J,9,0),"0") -> 0 | GE8: =IFERROR(VLOOKUP(B8,'25'!B:K,10,0),"0") -> 0 | GF8: =IFERROR(VLOOKUP(B8,'25'!B:L,11,0),"0") -> 0 | GG8: =SUM(GA8:GD8) -> 0 | GH8: =IFERROR(VLOOKUP(B8,'26'!B:D,3,0),"0") -> 0 | GI8: =IFERROR(VLOOKUP(B8,'26'!B:E,4,0),"0") -> 0 | GJ8: =IFERROR(VLOOKUP(B8,'26'!B:F,5,0),"0") -> 0 | GK8: =IFERROR(VLOOKUP(B8,'26'!B:J,9,0),"0") -> 0 | GL8: =IFERROR(VLOOKUP(B8,'26'!B:K,10,0),"0") -> 0 | GM8: =IFERROR(VLOOKUP(B8,'26'!B:L,11,0),"0") -> 0 | GN8: =SUM(GH8:GK8) -> 0 | GO8: =IFERROR(VLOOKUP(B8,'27'!B:D,3,0),"0") -> 0 | GP8: =IFERROR(VLOOKUP(B8,'27'!B:E,4,0),"0") -> 0 | GQ8: =IFERROR(VLOOKUP(B8,'27'!B:F,5,0),"0") -> 0 | GR8: =IFERROR(VLOOKUP(B8,'27'!B:J,9,0),"0") -> 0 | GS8: =IFERROR(VLOOKUP(B8,'27'!B:K,10,0),"0") -> 0 | GT8: =IFERROR(VLOOKUP(B8,'27'!B:L,11,0),"0") -> 0 | GU8: =SUM(GO8:GT8) -> 0 | GV8: =IFERROR(VLOOKUP(B8,'28'!B:D,3,0),"0") -> 0 | GW8: =IFERROR(VLOOKUP(B8,'28'!B:E,4,0),"0") -> 0 | GX8: =IFERROR(VLOOKUP(B8,'28'!B:F,5,0),"0") -> 0 | GY8: =IFERROR(VLOOKUP(B8,'28'!B:J,9,0),"0") -> 0 | GZ8: =IFERROR(VLOOKUP(B8,'28'!B:K,10,0),"0") -> 0 | HA8: =IFERROR(VLOOKUP(B8,'28'!B:L,11,0),"0") -> 0 | HB8: =SUM(GV8:HA8) -> 0 | HC8: =IFERROR(VLOOKUP(B8,#REF!,3),"0") -> 0 | HD8: =IFERROR(VLOOKUP(B8,#REF!,4,0),"0") -> 0 | HE8: =IFERROR(VLOOKUP(B8,#REF!,5,0),"0") -> 0 | HF8: =IFERROR(VLOOKUP(B8,#REF!,9,0),"0") -> 0 | HG8: =IFERROR(VLOOKUP(B8,#REF!,10,0),"0") -> 0 | HH8: =IFERROR(VLOOKUP(B8,#REF!,11,0),"0") -> 0 | HI8: =SUM(HC8:HF8) -> 0 | HP8: =SUM(HJ8:HM8) -> 0 | HW8: =SUM(HQ8:HT8) -> 0
