Workbook

Sheet ตัวอย่าง
A1: ยอดจริง ออนไลน์ วันที่ ............................
A2: NO | B2: รหัสสินค้า | C2: สินค้า | D2: ปณ | E2: Shopee | F2: Lazada | G2: Tiktok 1 | H2: Tiktok 2 | I2: Tiktok 3 | J2: Total Tiktok | K2: Choice | L2: ยอดเส้น | M2: ยอดรวมผลิต จำนวน (กล่อง) | N2: ยอดฟอแคส | O2: ยอดสต็อก | P2: รวม
A3: 1 | B3: 1111002 | C3: ชิฟฟอนรวมรส 8 ชิ้น | D3: ='[1]เย็น '!D7+'[1]เช้า '!D7+[1]บ่าย!D7 -> 38 | E3: ='[1]เย็น '!E7+'[1]เช้า '!E7+[1]บ่าย!E7 -> 251 | F3: ='[1]เย็น '!F7+'[1]เช้า '!F7+[1]บ่าย!F7 -> 57 | G3: ='[1]เย็น '!G7+'[1]เช้า '!G7+[1]บ่าย!G7 -> 5 | H3: ='[1]เย็น '!H7+'[1]เช้า '!H7+[1]บ่าย!H7 -> 17 | I3: ='[1]เย็น '!I7+'[1]เช้า '!I7+[1]บ่าย!I7 -> 0 | J3: =+G3+H3+I3 -> 22 | K3: ='[1]เย็น '!J7+'[1]เช้า '!J7+[1]บ่าย!J7 -> 0 | L3: ='[1]เย็น '!K7+'[1]เช้า '!K7+[1]บ่าย!K7 -> 0 | M3: =+D3+E3+F3+J3+K3+L3 -> 368 | P3: =(N3+O3)-M3 -> -368
A4: 2 | C4: ชิฟฟอนแบบกล่องสุ่มอะไรก็ได้ที่มี | D4: ='[1]เย็น '!D8+'[1]เช้า '!D8+[1]บ่าย!D8 -> 0 | E4: ='[1]เย็น '!E8+'[1]เช้า '!E8+[1]บ่าย!E8 -> 0 | F4: ='[1]เย็น '!F8+'[1]เช้า '!F8+[1]บ่าย!F8 -> 0 | G4: ='[1]เย็น '!G8+'[1]เช้า '!G8+[1]บ่าย!G8 -> 0 | H4: ='[1]เย็น '!H8+'[1]เช้า '!H8+[1]บ่าย!H8 -> 0 | I4: ='[1]เย็น '!I8+'[1]เช้า '!I8+[1]บ่าย!I8 -> 0 | J4: =+G4+H4+I4 -> 0 | K4: ='[1]เย็น '!J8+'[1]เช้า '!J8+[1]บ่าย!J8 -> 0 | L4: ='[1]เย็น '!K8+'[1]เช้า '!K8+[1]บ่าย!K8 -> 0 | M4: =+D4+E4+F4+J4+K4+L4 -> 0 | P4: =(N4+O4)-M4 -> 0
A5: 3 | B5: 1111084 | C5: ชิฟฟอน 8 ชิ้น กาแฟล้วน | D5: ='[1]เย็น '!D9+'[1]เช้า '!D9+[1]บ่าย!D9 -> 0 | E5: ='[1]เย็น '!E9+'[1]เช้า '!E9+[1]บ่าย!E9 -> 0 | F5: ='[1]เย็น '!F9+'[1]เช้า '!F9+[1]บ่าย!F9 -> 0 | G5: ='[1]เย็น '!G9+'[1]เช้า '!G9+[1]บ่าย!G9 -> 0 | H5: ='[1]เย็น '!H9+'[1]เช้า '!H9+[1]บ่าย!H9 -> 0 | I5: ='[1]เย็น '!I9+'[1]เช้า '!I9+[1]บ่าย!I9 -> 0 | J5: =+G5+H5+I5 -> 0 | K5: ='[1]เย็น '!J9+'[1]เช้า '!J9+[1]บ่าย!J9 -> 0 | L5: ='[1]เย็น '!K9+'[1]เช้า '!K9+[1]บ่าย!K9 -> 0 | M5: =+D5+E5+F5+J5+K5+L5 -> 0 | P5: =(N5+O5)-M5 -> 0
A6: 4 | B6: 1111085 | C6: ชิฟฟอน 8 ชิ้น บลูเบอรี่ล้วน | D6: ='[1]เย็น '!D10+'[1]เช้า '!D10+[1]บ่าย!D10 -> 0 | E6: ='[1]เย็น '!E10+'[1]เช้า '!E10+[1]บ่าย!E10 -> 0 | F6: ='[1]เย็น '!F10+'[1]เช้า '!F10+[1]บ่าย!F10 -> 0 | G6: ='[1]เย็น '!G10+'[1]เช้า '!G10+[1]บ่าย!G10 -> 0 | H6: ='[1]เย็น '!H10+'[1]เช้า '!H10+[1]บ่าย!H10 -> 0 | I6: ='[1]เย็น '!I10+'[1]เช้า '!I10+[1]บ่าย!I10 -> 0 | J6: =+G6+H6+I6 -> 0 | K6: ='[1]เย็น '!J10+'[1]เช้า '!J10+[1]บ่าย!J10 -> 0 | L6: ='[1]เย็น '!K10+'[1]เช้า '!K10+[1]บ่าย!K10 -> 0 | M6: =+D6+E6+F6+J6+K6+L6 -> 0 | P6: =(N6+O6)-M6 -> 0
A7: 5 | B7: 1111086 | C7: ชิฟฟอน 8 ชิ้น มะพร้าวล้วน | D7: ='[1]เย็น '!D11+'[1]เช้า '!D11+[1]บ่าย!D11 -> 20 | E7: ='[1]เย็น '!E11+'[1]เช้า '!E11+[1]บ่าย!E11 -> 0 | F7: ='[1]เย็น '!F11+'[1]เช้า '!F11+[1]บ่าย!F11 -> 0 | G7: ='[1]เย็น '!G11+'[1]เช้า '!G11+[1]บ่าย!G11 -> 0 | H7: ='[1]เย็น '!H11+'[1]เช้า '!H11+[1]บ่าย!H11 -> 0 | I7: ='[1]เย็น '!I11+'[1]เช้า '!I11+[1]บ่าย!I11 -> 0 | J7: =+G7+H7+I7 -> 0 | K7: ='[1]เย็น '!J11+'[1]เช้า '!J11+[1]บ่าย!J11 -> 0 | L7: ='[1]เย็น '!K11+'[1]เช้า '!K11+[1]บ่าย!K11 -> 0 | M7: =+D7+E7+F7+J7+K7+L7 -> 20 | P7: =(N7+O7)-M7 -> -20
A8: 6 | B8: 1111087 | C8: ชิฟฟอน 8 ชิ้น สตอเบอรี่ล้วน | D8: ='[1]เย็น '!D12+'[1]เช้า '!D12+[1]บ่าย!D12 -> 0 | E8: ='[1]เย็น '!E12+'[1]เช้า '!E12+[1]บ่าย!E12 -> 0 | F8: ='[1]เย็น '!F12+'[1]เช้า '!F12+[1]บ่าย!F12 -> 0 | G8: ='[1]เย็น '!G12+'[1]เช้า '!G12+[1]บ่าย!G12 -> 0 | H8: ='[1]เย็น '!H12+'[1]เช้า '!H12+[1]บ่าย!H12 -> 0 | I8: ='[1]เย็น '!I12+'[1]เช้า '!I12+[1]บ่าย!I12 -> 0 | J8: =+G8+H8+I8 -> 0 | K8: ='[1]เย็น '!J12+'[1]เช้า '!J12+[1]บ่าย!J12 -> 0 | L8: ='[1]เย็น '!K12+'[1]เช้า '!K12+[1]บ่าย!K12 -> 0 | M8: =+D8+E8+F8+J8+K8+L8 -> 0 | P8: =(N8+O8)-M8 -> 0
A9: 7 | B9: 1111088 | C9: ชิฟฟอน 8 ชิ้น ส้มล้วน | D9: ='[1]เย็น '!D13+'[1]เช้า '!D13+[1]บ่าย!D13 -> 0 | E9: ='[1]เย็น '!E13+'[1]เช้า '!E13+[1]บ่าย!E13 -> 0 | F9: ='[1]เย็น '!F13+'[1]เช้า '!F13+[1]บ่าย!F13 -> 0 | G9: ='[1]เย็น '!G13+'[1]เช้า '!G13+[1]บ่าย!G13 -> 0 | H9: ='[1]เย็น '!H13+'[1]เช้า '!H13+[1]บ่าย!H13 -> 0 | I9: ='[1]เย็น '!I13+'[1]เช้า '!I13+[1]บ่าย!I13 -> 0 | J9: =+G9+H9+I9 -> 0 | K9: ='[1]เย็น '!J13+'[1]เช้า '!J13+[1]บ่าย!J13 -> 0 | L9: ='[1]เย็น '!K13+'[1]เช้า '!K13+[1]บ่าย!K13 -> 0 | M9: =+D9+E9+F9+J9+K9+L9 -> 0 | P9: =(N9+O9)-M9 -> 0
A10: 8 | B10: 1111089 | C10: ชิฟฟอน 8 ชิ้น เนยล้วน | D10: ='[1]เย็น '!D14+'[1]เช้า '!D14+[1]บ่าย!D14 -> 0 | E10: ='[1]เย็น '!E14+'[1]เช้า '!E14+[1]บ่าย!E14 -> 0 | F10: ='[1]เย็น '!F14+'[1]เช้า '!F14+[1]บ่าย!F14 -> 0 | G10: ='[1]เย็น '!G14+'[1]เช้า '!G14+[1]บ่าย!G14 -> 0 | H10: ='[1]เย็น '!H14+'[1]เช้า '!H14+[1]บ่าย!H14 -> 0 | I10: ='[1]เย็น '!I14+'[1]เช้า '!I14+[1]บ่าย!I14 -> 0 | J10: =+G10+H10+I10 -> 0 | K10: ='[1]เย็น '!J14+'[1]เช้า '!J14+[1]บ่าย!J14 -> 0 | L10: ='[1]เย็น '!K14+'[1]เช้า '!K14+[1]บ่าย!K14 -> 0 | M10: =+D10+E10+F10+J10+K10+L10 -> 0 | P10: =(N10+O10)-M10 -> 0
A11: 9 | B11: 1111090 | C11: ชิฟฟอน 8 ชิ้น เผือกล้วน | D11: ='[1]เย็น '!D15+'[1]เช้า '!D15+[1]บ่าย!D15 -> 0 | E11: ='[1]เย็น '!E15+'[1]เช้า '!E15+[1]บ่าย!E15 -> 0 | F11: ='[1]เย็น '!F15+'[1]เช้า '!F15+[1]บ่าย!F15 -> 0 | G11: ='[1]เย็น '!G15+'[1]เช้า '!G15+[1]บ่าย!G15 -> 0 | H11: ='[1]เย็น '!H15+'[1]เช้า '!H15+[1]บ่าย!H15 -> 0 | I11: ='[1]เย็น '!I15+'[1]เช้า '!I15+[1]บ่าย!I15 -> 0 | J11: =+G11+H11+I11 -> 0 | K11: ='[1]เย็น '!J15+'[1]เช้า '!J15+[1]บ่าย!J15 -> 0 | L11: ='[1]เย็น '!K15+'[1]เช้า '!K15+[1]บ่าย!K15 -> 0 | M11: =+D11+E11+F11+J11+K11+L11 -> 0 | P11: =(N11+O11)-M11 -> 0
A12: 10 | B12: 1111091 | C12: ชิฟฟอน 8 ชิ้น ใบเตยล้วน | D12: ='[1]เย็น '!D16+'[1]เช้า '!D16+[1]บ่าย!D16 -> 0 | E12: ='[1]เย็น '!E16+'[1]เช้า '!E16+[1]บ่าย!E16 -> 0 | F12: ='[1]เย็น '!F16+'[1]เช้า '!F16+[1]บ่าย!F16 -> 0 | G12: ='[1]เย็น '!G16+'[1]เช้า '!G16+[1]บ่าย!G16 -> 0 | H12: ='[1]เย็น '!H16+'[1]เช้า '!H16+[1]บ่าย!H16 -> 0 | I12: ='[1]เย็น '!I16+'[1]เช้า '!I16+[1]บ่าย!I16 -> 0 | J12: =+G12+H12+I12 -> 0 | K12: ='[1]เย็น '!J16+'[1]เช้า '!J16+[1]บ่าย!J16 -> 0 | L12: ='[1]เย็น '!K16+'[1]เช้า '!K16+[1]บ่าย!K16 -> 0 | M12: =+D12+E12+F12+J12+K12+L12 -> 0 | P12: =(N12+O12)-M12 -> 0
A13: 11 | B13: 1111092 | C13: ชิฟฟอน 8 ชิ้น กล้วยหอม | D13: ='[1]เย็น '!D17+'[1]เช้า '!D17+[1]บ่าย!D17 -> 0 | E13: ='[1]เย็น '!E17+'[1]เช้า '!E17+[1]บ่าย!E17 -> 0 | F13: ='[1]เย็น '!F17+'[1]เช้า '!F17+[1]บ่าย!F17 -> 0 | G13: ='[1]เย็น '!G17+'[1]เช้า '!G17+[1]บ่าย!G17 -> 0 | H13: ='[1]เย็น '!H17+'[1]เช้า '!H17+[1]บ่าย!H17 -> 0 | I13: ='[1]เย็น '!I17+'[1]เช้า '!I17+[1]บ่าย!I17 -> 0 | J13: =+G13+H13+I13 -> 0 | K13: ='[1]เย็น '!J17+'[1]เช้า '!J17+[1]บ่าย!J17 -> 0 | L13: ='[1]เย็น '!K17+'[1]เช้า '!K17+[1]บ่าย!K17 -> 0 | M13: =+D13+E13+F13+J13+K13+L13 -> 0 | P13: =(N13+O13)-M13 -> 0
A14: 12 | B14: 1111093 | C14: ชิฟฟอน 8 ชิ้น โกโก้ล้วน | D14: ='[1]เย็น '!D18+'[1]เช้า '!D18+[1]บ่าย!D18 -> 0 | E14: ='[1]เย็น '!E18+'[1]เช้า '!E18+[1]บ่าย!E18 -> 0 | F14: ='[1]เย็น '!F18+'[1]เช้า '!F18+[1]บ่าย!F18 -> 0 | G14: ='[1]เย็น '!G18+'[1]เช้า '!G18+[1]บ่าย!G18 -> 0 | H14: ='[1]เย็น '!H18+'[1]เช้า '!H18+[1]บ่าย!H18 -> 0 | I14: ='[1]เย็น '!I18+'[1]เช้า '!I18+[1]บ่าย!I18 -> 0 | J14: =+G14+H14+I14 -> 0 | K14: ='[1]เย็น '!J18+'[1]เช้า '!J18+[1]บ่าย!J18 -> 0 | L14: ='[1]เย็น '!K18+'[1]เช้า '!K18+[1]บ่าย!K18 -> 0 | M14: =+D14+E14+F14+J14+K14+L14 -> 0 | P14: =(N14+O14)-M14 -> 0
A15: 13 | B15: 1111094 | C15: ชิฟฟอน 8 ชิ้น ชาไทยล้วน | D15: ='[1]เย็น '!D19+'[1]เช้า '!D19+[1]บ่าย!D19 -> 0 | E15: ='[1]เย็น '!E19+'[1]เช้า '!E19+[1]บ่าย!E19 -> 0 | F15: ='[1]เย็น '!F19+'[1]เช้า '!F19+[1]บ่าย!F19 -> 0 | G15: ='[1]เย็น '!G19+'[1]เช้า '!G19+[1]บ่าย!G19 -> 0 | H15: ='[1]เย็น '!H19+'[1]เช้า '!H19+[1]บ่าย!H19 -> 0 | I15: ='[1]เย็น '!I19+'[1]เช้า '!I19+[1]บ่าย!I19 -> 0 | J15: =+G15+H15+I15 -> 0 | K15: ='[1]เย็น '!J19+'[1]เช้า '!J19+[1]บ่าย!J19 -> 0 | L15: ='[1]เย็น '!K19+'[1]เช้า '!K19+[1]บ่าย!K19 -> 0 | M15: =+D15+E15+F15+J15+K15+L15 -> 0 | P15: =(N15+O15)-M15 -> 0
A16: 14 | B16: 1111095 | C16: ชิฟฟอน 8 ชิ้น ชาเขียวล้วน | D16: ='[1]เย็น '!D20+'[1]เช้า '!D20+[1]บ่าย!D20 -> 0 | E16: ='[1]เย็น '!E20+'[1]เช้า '!E20+[1]บ่าย!E20 -> 0 | F16: ='[1]เย็น '!F20+'[1]เช้า '!F20+[1]บ่าย!F20 -> 0 | G16: ='[1]เย็น '!G20+'[1]เช้า '!G20+[1]บ่าย!G20 -> 0 | H16: ='[1]เย็น '!H20+'[1]เช้า '!H20+[1]บ่าย!H20 -> 0 | I16: ='[1]เย็น '!I20+'[1]เช้า '!I20+[1]บ่าย!I20 -> 0 | J16: =+G16+H16+I16 -> 0 | K16: ='[1]เย็น '!J20+'[1]เช้า '!J20+[1]บ่าย!J20 -> 0 | L16: ='[1]เย็น '!K20+'[1]เช้า '!K20+[1]บ่าย!K20 -> 0 | M16: =+D16+E16+F16+J16+K16+L16 -> 0 | P16: =(N16+O16)-M16 -> 0
... A61: 59 | B61: 1111083 | C61: ชิฟฟอนไส้แยมแยกชิ้น เมล่อน | D61: ='[1]เย็น '!D65+'[1]เช้า '!D65+[1]บ่าย!D65 -> 0 | E61: ='[1]เย็น '!E65+'[1]เช้า '!E65+[1]บ่าย!E65 -> 10 | F61: ='[1]เย็น '!F65+'[1]เช้า '!F65+[1]บ่าย!F65 -> 2 | G61: ='[1]เย็น '!G65+'[1]เช้า '!G65+[1]บ่าย!G65 -> 0 | H61: ='[1]เย็น '!H65+'[1]เช้า '!H65+[1]บ่าย!H65 -> 0 | I61: ='[1]เย็น '!I65+'[1]เช้า '!I65+[1]บ่าย!I65 -> 0 | J61: =+G61+H61+I61 -> 0 | K61: ='[1]เย็น '!J65+'[1]เช้า '!J65+[1]บ่าย!J65 -> 0 | L61: ='[1]เย็น '!K65+'[1]เช้า '!K65+[1]บ่าย!K65 -> 0 | M61: =+D61+E61+F61+J61+K61+L61 -> 12 | P61: =(N61+O61)-M61 -> -12
A62: 60 | B62: 1111010 | C62: ชิฟฟอนไส้แยมแยกชิ้น คละรส | D62: =[1]บ่าย!D66+'[1]เช้า '!D66+'[1]เย็น '!D66 -> 0 | E62: =[1]บ่าย!E66+'[1]เช้า '!E66+'[1]เย็น '!E66 -> 0 | F62: =[1]บ่าย!F66+'[1]เช้า '!F66+'[1]เย็น '!F66 -> 0 | G62: =[1]บ่าย!G66+'[1]เช้า '!G66+'[1]เย็น '!G66 -> 0 | H62: =[1]บ่าย!H66+'[1]เช้า '!H66+'[1]เย็น '!H66 -> 0 | I62: =[1]บ่าย!I66+'[1]เช้า '!I66+'[1]เย็น '!I66 -> 0 | J62: =+G62+H62+I62 -> 0 | K62: =[1]บ่าย!J66+'[1]เช้า '!J66+'[1]เย็น '!J66 -> 0 | M62: =+D62+E62+F62+J62+K62+L62 -> 0 | P62: =(N62+O62)-M62 -> 0
A63: 61 | B63: 1111009 | C63: ชิฟฟอนไส้แยมรวมรส 6 ชิ้น | D63: ='[1]เย็น '!D69+'[1]เช้า '!D69+[1]บ่าย!D69 -> 14 | E63: ='[1]เย็น '!E69+'[1]เช้า '!E69+[1]บ่าย!E69 -> 4 | F63: ='[1]เย็น '!F69+'[1]เช้า '!F69+[1]บ่าย!F69 -> 21 | G63: ='[1]เย็น '!G69+'[1]เช้า '!G69+[1]บ่าย!G69 -> 7 | H63: ='[1]เย็น '!H69+'[1]เช้า '!H69+[1]บ่าย!H69 -> 1 | I63: ='[1]เย็น '!I69+'[1]เช้า '!I69+[1]บ่าย!I69 -> 0 | J63: =+G63+H63+I63 -> 8 | K63: ='[1]เย็น '!J69+'[1]เช้า '!J69+[1]บ่าย!J69 -> 0 | L63: ='[1]เย็น '!K69+'[1]เช้า '!K69+[1]บ่าย!K69 -> 0 | M63: =+D63+E63+F63+J63+K63+L63 -> 47 | P63: =(N63+O63)-M63 -> -47
A64: 62 | B64: 1111023 | C64: ชิฟฟอนไส้แยมรสสตอเบอร์รี่ล้วน 6 ชิ้น | D64: ='[1]เย็น '!D70+'[1]เช้า '!D70+[1]บ่าย!D70 -> 0 | E64: ='[1]เย็น '!E70+'[1]เช้า '!E70+[1]บ่าย!E70 -> 0 | F64: ='[1]เย็น '!F70+'[1]เช้า '!F70+[1]บ่าย!F70 -> 0 | G64: ='[1]เย็น '!G70+'[1]เช้า '!G70+[1]บ่าย!G70 -> 0 | H64: ='[1]เย็น '!H70+'[1]เช้า '!H70+[1]บ่าย!H70 -> 0 | I64: ='[1]เย็น '!I70+'[1]เช้า '!I70+[1]บ่าย!I70 -> 0 | J64: =+G64+H64+I64 -> 0 | K64: ='[1]เย็น '!J70+'[1]เช้า '!J70+[1]บ่าย!J70 -> 0 | L64: ='[1]เย็น '!K70+'[1]เช้า '!K70+[1]บ่าย!K70 -> 0 | M64: =+D64+E64+F64+J64+K64+L64 -> 0 | P64: =(N64+O64)-M64 -> 0
A65: 63 | B65: 1111016 | C65: ชิฟฟอนไส้แยมรสมะพร้าวล้วน 6 ชิ้น | D65: ='[1]เย็น '!D71+'[1]เช้า '!D71+[1]บ่าย!D71 -> 0 | E65: ='[1]เย็น '!E71+'[1]เช้า '!E71+[1]บ่าย!E71 -> 0 | F65: ='[1]เย็น '!F71+'[1]เช้า '!F71+[1]บ่าย!F71 -> 0 | G65: ='[1]เย็น '!G71+'[1]เช้า '!G71+[1]บ่าย!G71 -> 0 | H65: ='[1]เย็น '!H71+'[1]เช้า '!H71+[1]บ่าย!H71 -> 0 | I65: ='[1]เย็น '!I71+'[1]เช้า '!I71+[1]บ่าย!I71 -> 0 | J65: =+G65+H65+I65 -> 0 | K65: ='[1]เย็น '!J71+'[1]เช้า '!J71+[1]บ่าย!J71 -> 0 | L65: ='[1]เย็น '!K71+'[1]เช้า '!K71+[1]บ่าย!K71 -> 0 | M65: =+D65+E65+F65+J65+K65+L65 -> 0 | P65: =(N65+O65)-M65 -> 0
A66: 64 | B66: 1111014 | C66: ชิฟฟอนไส้แยมรสช็อกโกแลตนูเทลล่าล้วน 6 ชิ้น | D66: ='[1]เย็น '!D72+'[1]เช้า '!D72+[1]บ่าย!D72 -> 0 | E66: ='[1]เย็น '!E72+'[1]เช้า '!E72+[1]บ่าย!E72 -> 0 | F66: ='[1]เย็น '!F72+'[1]เช้า '!F72+[1]บ่าย!F72 -> 0 | G66: ='[1]เย็น '!G72+'[1]เช้า '!G72+[1]บ่าย!G72 -> 0 | H66: ='[1]เย็น '!H72+'[1]เช้า '!H72+[1]บ่าย!H72 -> 0 | I66: ='[1]เย็น '!I72+'[1]เช้า '!I72+[1]บ่าย!I72 -> 0 | J66: =+G66+H66+I66 -> 0 | K66: ='[1]เย็น '!J72+'[1]เช้า '!J72+[1]บ่าย!J72 -> 0 | L66: ='[1]เย็น '!K72+'[1]เช้า '!K72+[1]บ่าย!K72 -> 0 | M66: =+D66+E66+F66+J66+K66+L66 -> 0 | P66: =(N66+O66)-M66 -> 0
A67: 65 | B67: 1111025 | C67: ชิฟฟอนไส้แยมรสส้มล้วน 6 ชิ้น | D67: ='[1]เย็น '!D73+'[1]เช้า '!D73+[1]บ่าย!D73 -> 0 | E67: ='[1]เย็น '!E73+'[1]เช้า '!E73+[1]บ่าย!E73 -> 0 | F67: ='[1]เย็น '!F73+'[1]เช้า '!F73+[1]บ่าย!F73 -> 0 | G67: ='[1]เย็น '!G73+'[1]เช้า '!G73+[1]บ่าย!G73 -> 0 | H67: ='[1]เย็น '!H73+'[1]เช้า '!H73+[1]บ่าย!H73 -> 0 | I67: ='[1]เย็น '!I73+'[1]เช้า '!I73+[1]บ่าย!I73 -> 0 | J67: =+G67+H67+I67 -> 0 | K67: ='[1]เย็น '!J73+'[1]เช้า '!J73+[1]บ่าย!J73 -> 0 | L67: ='[1]เย็น '!K73+'[1]เช้า '!K73+[1]บ่าย!K73 -> 0 | M67: =+D67+E67+F67+J67+K67+L67 -> 0 | P67: =(N67+O67)-M67 -> 0
A68: 66 | B68: 1111018 | C68: ชิฟฟอนไส้แยมรสบลูเบอร์รี่ล้วน 6 ชิ้น | D68: ='[1]เย็น '!D74+'[1]เช้า '!D74+[1]บ่าย!D74 -> 0 | E68: ='[1]เย็น '!E74+'[1]เช้า '!E74+[1]บ่าย!E74 -> 0 | F68: ='[1]เย็น '!F74+'[1]เช้า '!F74+[1]บ่าย!F74 -> 0 | G68: ='[1]เย็น '!G74+'[1]เช้า '!G74+[1]บ่าย!G74 -> 0 | H68: ='[1]เย็น '!H74+'[1]เช้า '!H74+[1]บ่าย!H74 -> 0 | I68: ='[1]เย็น '!I74+'[1]เช้า '!I74+[1]บ่าย!I74 -> 0 | J68: =+G68+H68+I68 -> 0 | K68: ='[1]เย็น '!J74+'[1]เช้า '!J74+[1]บ่าย!J74 -> 0 | L68: ='[1]เย็น '!K74+'[1]เช้า '!K74+[1]บ่าย!K74 -> 0 | M68: =+D68+E68+F68+J68+K68+L68 -> 0 | P68: =(N68+O68)-M68 -> 0
A69: 67 | B69: 1111012 | C69: ชิฟฟอนไส้แยมรสนมชมพูฮอกไกโดล้วน 6 ชิ้น | D69: ='[1]เย็น '!D75+'[1]เช้า '!D75+[1]บ่าย!D75 -> 0 | E69: ='[1]เย็น '!E75+'[1]เช้า '!E75+[1]บ่าย!E75 -> 0 | F69: ='[1]เย็น '!F75+'[1]เช้า '!F75+[1]บ่าย!F75 -> 0 | G69: ='[1]เย็น '!G75+'[1]เช้า '!G75+[1]บ่าย!G75 -> 0 | H69: ='[1]เย็น '!H75+'[1]เช้า '!H75+[1]บ่าย!H75 -> 0 | I69: ='[1]เย็น '!I75+'[1]เช้า '!I75+[1]บ่าย!I75 -> 0 | J69: =+G69+H69+I69 -> 0 | K69: ='[1]เย็น '!J75+'[1]เช้า '!J75+[1]บ่าย!J75 -> 0 | L69: ='[1]เย็น '!K75+'[1]เช้า '!K75+[1]บ่าย!K75 -> 0 | M69: =+D69+E69+F69+J69+K69+L69 -> 0 | P69: =(N69+O69)-M69 -> 0
A70: 68 | B70: 1111020 | C70: ชิฟฟอนไส้แยมฝอยทองไส้ทะลัก 6 ชิ้น | D70: ='[1]เย็น '!D76+'[1]เช้า '!D76+[1]บ่าย!D76 -> 0 | E70: ='[1]เย็น '!E76+'[1]เช้า '!E76+[1]บ่าย!E76 -> 0 | F70: ='[1]เย็น '!F76+'[1]เช้า '!F76+[1]บ่าย!F76 -> 0 | G70: ='[1]เย็น '!G76+'[1]เช้า '!G76+[1]บ่าย!G76 -> 0 | H70: ='[1]เย็น '!H76+'[1]เช้า '!H76+[1]บ่าย!H76 -> 0 | I70: ='[1]เย็น '!I76+'[1]เช้า '!I76+[1]บ่าย!I76 -> 0 | J70: =+G70+H70+I70 -> 0 | K70: ='[1]เย็น '!J76+'[1]เช้า '!J76+[1]บ่าย!J76 -> 0 | L70: ='[1]เย็น '!K76+'[1]เช้า '!K76+[1]บ่าย!K76 -> 0 | M70: =+D70+E70+F70+J70+K70+L70 -> 0 | P70: =(N70+O70)-M70 -> 0
A71: 69 | B71: 1111022 | C71: ชิฟฟอนไส้แยมรสสตอเบอร์รี่ล้วน 3 ชิ้น | D71: ='[1]เย็น '!D79+'[1]เช้า '!D79+[1]บ่าย!D79 -> 0 | E71: ='[1]เย็น '!E79+'[1]เช้า '!E79+[1]บ่าย!E79 -> 0 | F71: ='[1]เย็น '!F79+'[1]เช้า '!F79+[1]บ่าย!F79 -> 0 | G71: ='[1]เย็น '!G79+'[1]เช้า '!G79+[1]บ่าย!G79 -> 0 | H71: ='[1]เย็น '!H79+'[1]เช้า '!H79+[1]บ่าย!H79 -> 0 | I71: ='[1]เย็น '!I79+'[1]เช้า '!I79+[1]บ่าย!I79 -> 0 | J71: =+G71+H71+I71 -> 0 | K71: ='[1]เย็น '!J79+'[1]เช้า '!J79+[1]บ่าย!J79 -> 0 | L71: ='[1]เย็น '!K79+'[1]เช้า '!K79+[1]บ่าย!K79 -> 0 | M71: =+D71+E71+F71+J71+K71+L71 -> 0 | P71: =(N71+O71)-M71 -> 0
A72: 70 | B72: 1111015 | C72: ชิฟฟอนไส้แยมรสมะพร้าวล้วน 3 ชิ้น | D72: ='[1]เย็น '!D80+'[1]เช้า '!D80+[1]บ่าย!D80 -> 0 | E72: ='[1]เย็น '!E80+'[1]เช้า '!E80+[1]บ่าย!E80 -> 0 | F72: ='[1]เย็น '!F80+'[1]เช้า '!F80+[1]บ่าย!F80 -> 0 | G72: ='[1]เย็น '!G80+'[1]เช้า '!G80+[1]บ่าย!G80 -> 0 | H72: ='[1]เย็น '!H80+'[1]เช้า '!H80+[1]บ่าย!H80 -> 0 | I72: ='[1]เย็น '!I80+'[1]เช้า '!I80+[1]บ่าย!I80 -> 0 | J72: =+G72+H72+I72 -> 0 | K72: ='[1]เย็น '!J80+'[1]เช้า '!J80+[1]บ่าย!J80 -> 0 | L72: ='[1]เย็น '!K80+'[1]เช้า '!K80+[1]บ่าย!K80 -> 0 | M72: =+D72+E72+F72+J72+K72+L72 -> 0 | P72: =(N72+O72)-M72 -> 0
A73: 71 | B73: 1111013 | C73: ชิฟฟอนไส้แยมรสช็อกโกแลตนูเทลล่าล้วน 3 ชิ้น | D73: ='[1]เย็น '!D81+'[1]เช้า '!D81+[1]บ่าย!D81 -> 0 | E73: ='[1]เย็น '!E81+'[1]เช้า '!E81+[1]บ่าย!E81 -> 0 | F73: ='[1]เย็น '!F81+'[1]เช้า '!F81+[1]บ่าย!F81 -> 0 | G73: ='[1]เย็น '!G81+'[1]เช้า '!G81+[1]บ่าย!G81 -> 0 | H73: ='[1]เย็น '!H81+'[1]เช้า '!H81+[1]บ่าย!H81 -> 0 | I73: ='[1]เย็น '!I81+'[1]เช้า '!I81+[1]บ่าย!I81 -> 0 | J73: =+G73+H73+I73 -> 0 | K73: ='[1]เย็น '!J81+'[1]เช้า '!J81+[1]บ่าย!J81 -> 0 | L73: ='[1]เย็น '!K81+'[1]เช้า '!K81+[1]บ่าย!K81 -> 0 | M73: =+D73+E73+F73+J73+K73+L73 -> 0 | P73: =(N73+O73)-M73 -> 0
A74: 72 | B74: 1111024 | C74: ชิฟฟอนไส้แยมรสส้มล้วน 3 ชิ้น | D74: ='[1]เย็น '!D82+'[1]เช้า '!D82+[1]บ่าย!D82 -> 0 | E74: ='[1]เย็น '!E82+'[1]เช้า '!E82+[1]บ่าย!E82 -> 0 | F74: ='[1]เย็น '!F82+'[1]เช้า '!F82+[1]บ่าย!F82 -> 0 | G74: ='[1]เย็น '!G82+'[1]เช้า '!G82+[1]บ่าย!G82 -> 0 | H74: ='[1]เย็น '!H82+'[1]เช้า '!H82+[1]บ่าย!H82 -> 0 | I74: ='[1]เย็น '!I82+'[1]เช้า '!I82+[1]บ่าย!I82 -> 0 | J74: =+G74+H74+I74 -> 0 | K74: ='[1]เย็น '!J82+'[1]เช้า '!J82+[1]บ่าย!J82 -> 0 | L74: ='[1]เย็น '!K82+'[1]เช้า '!K82+[1]บ่าย!K82 -> 0 | M74: =+D74+E74+F74+J74+K74+L74 -> 0 | P74: =(N74+O74)-M74 -> 0
A75: 73 | B75: 1111017 | C75: ชิฟฟอนไส้แยมรสบลูเบอร์รี่ล้วน 3 ชิ้น | D75: ='[1]เย็น '!D83+'[1]เช้า '!D83+[1]บ่าย!D83 -> 0 | E75: ='[1]เย็น '!E83+'[1]เช้า '!E83+[1]บ่าย!E83 -> 0 | F75: ='[1]เย็น '!F83+'[1]เช้า '!F83+[1]บ่าย!F83 -> 0 | G75: ='[1]เย็น '!G83+'[1]เช้า '!G83+[1]บ่าย!G83 -> 0 | H75: ='[1]เย็น '!H83+'[1]เช้า '!H83+[1]บ่าย!H83 -> 0 | I75: ='[1]เย็น '!I83+'[1]เช้า '!I83+[1]บ่าย!I83 -> 0 | J75: =+G75+H75+I75 -> 0 | K75: ='[1]เย็น '!J83+'[1]เช้า '!J83+[1]บ่าย!J83 -> 0 | L75: ='[1]เย็น '!K83+'[1]เช้า '!K83+[1]บ่าย!K83 -> 0 | M75: =+D75+E75+F75+J75+K75+L75 -> 0 | P75: =(N75+O75)-M75 -> 0
A76: 74 | B76: 1111011 | C76: ชิฟฟอนไส้แยมรสนมชมพูฮอกไกโดล้วน 3 ชิ้น | D76: ='[1]เย็น '!D84+'[1]เช้า '!D84+[1]บ่าย!D84 -> 0 | E76: ='[1]เย็น '!E84+'[1]เช้า '!E84+[1]บ่าย!E84 -> 0 | F76: ='[1]เย็น '!F84+'[1]เช้า '!F84+[1]บ่าย!F84 -> 0 | G76: ='[1]เย็น '!G84+'[1]เช้า '!G84+[1]บ่าย!G84 -> 0 | H76: ='[1]เย็น '!H84+'[1]เช้า '!H84+[1]บ่าย!H84 -> 0 | I76: ='[1]เย็น '!I84+'[1]เช้า '!I84+[1]บ่าย!I84 -> 0 | J76: =+G76+H76+I76 -> 0 | K76: ='[1]เย็น '!J84+'[1]เช้า '!J84+[1]บ่าย!J84 -> 0 | L76: ='[1]เย็น '!K84+'[1]เช้า '!K84+[1]บ่าย!K84 -> 0 | M76: =+D76+E76+F76+J76+K76+L76 -> 0 | P76: =(N76+O76)-M76 -> 0
A77: 75 | B77: 1111019 | C77: ชิฟฟอนไส้แยมฝอยทองไส้ทะลัก 3 ชิ้น | D77: ='[1]เย็น '!D85+'[1]เช้า '!D85+[1]บ่าย!D85 -> 0 | E77: ='[1]เย็น '!E85+'[1]เช้า '!E85+[1]บ่าย!E85 -> 0 | F77: ='[1]เย็น '!F85+'[1]เช้า '!F85+[1]บ่าย!F85 -> 0 | G77: ='[1]เย็น '!G85+'[1]เช้า '!G85+[1]บ่าย!G85 -> 0 | H77: ='[1]เย็น '!H85+'[1]เช้า '!H85+[1]บ่าย!H85 -> 0 | I77: ='[1]เย็น '!I85+'[1]เช้า '!I85+[1]บ่าย!I85 -> 0 | J77: =+G77+H77+I77 -> 0 | K77: ='[1]เย็น '!J85+'[1]เช้า '!J85+[1]บ่าย!J85 -> 0 | L77: ='[1]เย็น '!K85+'[1]เช้า '!K85+[1]บ่าย!K85 -> 0 | M77: =+D77+E77+F77+J77+K77+L77 -> 0 | P77: =(N77+O77)-M77 -> 0
A78: 76 | B78: 1113081 | C78: ชิฟฟอนไส้แยม วนิลา/ใบเตย/เมล่อน | D78: ='[1]เย็น '!D86+'[1]เช้า '!D86+[1]บ่าย!D86 -> 0 | E78: ='[1]เย็น '!E86+'[1]เช้า '!E86+[1]บ่าย!E86 -> 0 | F78: ='[1]เย็น '!F86+'[1]เช้า '!F86+[1]บ่าย!F86 -> 0 | G78: ='[1]เย็น '!G86+'[1]เช้า '!G86+[1]บ่าย!G86 -> 0 | H78: ='[1]เย็น '!H86+'[1]เช้า '!H86+[1]บ่าย!H86 -> 0 | I78: ='[1]เย็น '!I86+'[1]เช้า '!I86+[1]บ่าย!I86 -> 0 | J78: =+G78+H78+I78 -> 0 | K78: ='[1]เย็น '!J86+'[1]เช้า '!J86+[1]บ่าย!J86 -> 0 | L78: ='[1]เย็น '!K86+'[1]เช้า '!K86+[1]บ่าย!K86 -> 0 | M78: =+D78+E78+F78+J78+K78+L78 -> 0 | P78: =(N78+O78)-M78 -> 0
A79: 77 | B79: 1111008 | C79: ชิฟฟอนไส้แยมรวมรส 3 ชิ้น | D79: ='[1]เย็น '!D87+'[1]เช้า '!D87+[1]บ่าย!D87 -> 20 | E79: ='[1]เย็น '!E87+'[1]เช้า '!E87+[1]บ่าย!E87 -> 9 | F79: ='[1]เย็น '!F87+'[1]เช้า '!F87+[1]บ่าย!F87 -> 0 | G79: ='[1]เย็น '!G87+'[1]เช้า '!G87+[1]บ่าย!G87 -> 366 | H79: ='[1]เย็น '!H87+'[1]เช้า '!H87+[1]บ่าย!H87 -> 211 | I79: ='[1]เย็น '!I87+'[1]เช้า '!I87+[1]บ่าย!I87 -> 0 | J79: =+G79+H79+I79 -> 577 | K79: ='[1]เย็น '!J87+'[1]เช้า '!J87+[1]บ่าย!J87 -> 0 | L79: ='[1]เย็น '!K87+'[1]เช้า '!K87+[1]บ่าย!K87 -> 0 | M79: =+D79+E79+F79+J79+K79+L79 -> 606 | P79: =(N79+O79)-M79 -> -606
A80: 78 | B80: 1112009 | C80: เค้กเบาหวิว รสมะพร้าว 110 กรัม | D80: ='[1]เย็น '!D90+'[1]เช้า '!D90+[1]บ่าย!D90 -> 19 | E80: ='[1]เย็น '!E90+'[1]เช้า '!E90+[1]บ่าย!E90 -> 29 | F80: ='[1]เย็น '!F90+'[1]เช้า '!F90+[1]บ่าย!F90 -> 32 | G80: ='[1]เย็น '!G90+'[1]เช้า '!G90+[1]บ่าย!G90 -> 123 | H80: ='[1]เย็น '!H90+'[1]เช้า '!H90+[1]บ่าย!H90 -> 60 | I80: ='[1]เย็น '!I90+'[1]เช้า '!I90+[1]บ่าย!I90 -> 0 | J80: =+G80+H80+I80 -> 183 | K80: ='[1]เย็น '!J90+'[1]เช้า '!J90+[1]บ่าย!J90 -> 0 | L80: ='[1]เย็น '!K90+'[1]เช้า '!K90+[1]บ่าย!K90 -> 0 | M80: =+D80+E80+F80+J80+K80+L80 -> 263 | P80: =(N80+O80)-M80 -> -263
A81: 79 | B81: 1112011 | C81: เค้กเบาหวิว รสฝอยทอง 110 กรัม | D81: ='[1]เย็น '!D91+'[1]เช้า '!D91+[1]บ่าย!D91 -> 21 | E81: ='[1]เย็น '!E91+'[1]เช้า '!E91+[1]บ่าย!E91 -> 31 | F81: ='[1]เย็น '!F91+'[1]เช้า '!F91+[1]บ่าย!F91 -> 34 | G81: ='[1]เย็น '!G91+'[1]เช้า '!G91+[1]บ่าย!G91 -> 123 | H81: ='[1]เย็น '!H91+'[1]เช้า '!H91+[1]บ่าย!H91 -> 60 | I81: ='[1]เย็น '!I91+'[1]เช้า '!I91+[1]บ่าย!I91 -> 0 | J81: =+G81+H81+I81 -> 183 | K81: ='[1]เย็น '!J91+'[1]เช้า '!J91+[1]บ่าย!J91 -> 0 | L81: ='[1]เย็น '!K91+'[1]เช้า '!K91+[1]บ่าย!K91 -> 0 | M81: =+D81+E81+F81+J81+K81+L81 -> 269 | P81: =(N81+O81)-M81 -> -269
A82: 80 | B82: 1112003 | C82: เค้กเบาหวิว รสกาแฟ 110 กรัม | D82: ='[1]เย็น '!D92+'[1]เช้า '!D92+[1]บ่าย!D92 -> 14 | E82: ='[1]เย็น '!E92+'[1]เช้า '!E92+[1]บ่าย!E92 -> 0 | F82: ='[1]เย็น '!F92+'[1]เช้า '!F92+[1]บ่าย!F92 -> 2 | G82: ='[1]เย็น '!G92+'[1]เช้า '!G92+[1]บ่าย!G92 -> 87 | H82: ='[1]เย็น '!H92+'[1]เช้า '!H92+[1]บ่าย!H92 -> 50 | I82: ='[1]เย็น '!I92+'[1]เช้า '!I92+[1]บ่าย!I92 -> 0 | J82: =+G82+H82+I82 -> 137 | K82: ='[1]เย็น '!J92+'[1]เช้า '!J92+[1]บ่าย!J92 -> 0 | L82: ='[1]เย็น '!K92+'[1]เช้า '!K92+[1]บ่าย!K92 -> 0 | M82: =+D82+E82+F82+J82+K82+L82 -> 153 | P82: =(N82+O82)-M82 -> -153
A83: 81 | B83: 1112005 | C83: เค้กเบาหวิว รสเนยนม 110 กรัม | D83: ='[1]เย็น '!D93+'[1]เช้า '!D93+[1]บ่าย!D93 -> 15 | E83: ='[1]เย็น '!E93+'[1]เช้า '!E93+[1]บ่าย!E93 -> 0 | F83: ='[1]เย็น '!F93+'[1]เช้า '!F93+[1]บ่าย!F93 -> 0 | G83: ='[1]เย็น '!G93+'[1]เช้า '!G93+[1]บ่าย!G93 -> 35 | H83: ='[1]เย็น '!H93+'[1]เช้า '!H93+[1]บ่าย!H93 -> 13 | I83: ='[1]เย็น '!I93+'[1]เช้า '!I93+[1]บ่าย!I93 -> 0 | J83: =+G83+H83+I83 -> 48 | K83: ='[1]เย็น '!J93+'[1]เช้า '!J93+[1]บ่าย!J93 -> 0 | L83: ='[1]เย็น '!K93+'[1]เช้า '!K93+[1]บ่าย!K93 -> 0 | M83: =+D83+E83+F83+J83+K83+L83 -> 63 | P83: =(N83+O83)-M83 -> -63
A84: 82 | B84: 1112007 | C84: เค้กเบาหวิว รสใบเตย 110 กรัม | D84: ='[1]เย็น '!D94+'[1]เช้า '!D94+[1]บ่าย!D94 -> 0 | E84: ='[1]เย็น '!E94+'[1]เช้า '!E94+[1]บ่าย!E94 -> 0 | F84: ='[1]เย็น '!F94+'[1]เช้า '!F94+[1]บ่าย!F94 -> 0 | G84: ='[1]เย็น '!G94+'[1]เช้า '!G94+[1]บ่าย!G94 -> 0 | H84: ='[1]เย็น '!H94+'[1]เช้า '!H94+[1]บ่าย!H94 -> 0 | I84: ='[1]เย็น '!I94+'[1]เช้า '!I94+[1]บ่าย!I94 -> 0 | J84: =+G84+H84+I84 -> 0 | K84: ='[1]เย็น '!J94+'[1]เช้า '!J94+[1]บ่าย!J94 -> 0 | L84: ='[1]เย็น '!K94+'[1]เช้า '!K94+[1]บ่าย!K94 -> 0 | M84: =+D84+E84+F84+J84+K84+L84 -> 0 | P84: =(N84+O84)-M84 -> 0
...
