Workbook

Sheet Month
A1: ลำดับ | B1: ทีมโทร | C1: บูธ | D1: online | E1: Modern Trade | F1: รหัส | G1: ชื่อสินค้า | H1: ลูกค้า | I1: ขนาดบรรจุ | N1: week 1 (วันที่ 22-28 ก.พ. 2569) | AI1: week 2 (วันที่ 1 - 7 มี.ค. 2569) | BD1: week 3 (วันที่ 8 - 14 มี.ค. 2569) | BY1: week 4 (วันที่ 15-21 มี.ค. 2569) | CT1: week 5 ()
I2: จำนวน(ชิ้น) | J2: หน่วย(กล่อง) | K2: วัน | N2: วันอาทิตย์ | Q2: วันจันทร์ | T2: วันอังคาร | W2: วันพุธ | Z2: วันพฤหัสบดี | AC2: วันศุกร์ | AF2: เสาร์ | AI2: วันอาทิตย์ | AL2: วันจันทร์ | AO2: วันอังคาร | AR2: วันพุธ | AU2: วันพฤหัสบดี | AX2: วันศุกร์ | BA2: เสาร์ | BD2: วันอาทิตย์ | BG2: วันจันทร์ | BJ2: วันอังคาร | BM2: วันพุธ | BP2: วันพฤหัสบดี | BS2: วันศุกร์ | BV2: เสาร์ | BY2: วันอาทิตย์ | CB2: วันจันทร์ | CE2: วันอังคาร | CH2: วันพุธ | CK2: วันพฤหัสบดี | CN2: วันศุกร์ | CQ2: เสาร์ | CT2: วันอาทิตย์ | CW2: วันจันทร์ | CZ2: วันอังคาร | DC2: วันพุธ | DF2: วันพฤหัสบดี | DI2: วันศุกร์ | DL2: เสาร์
N3: 22 | Q3: 23 | T3: 24 | W3: 25 | Z3: 26 | AC3: 27 | AF3: 28 | AI3: 1 | AL3: 2 | AO3: 3 | AR3: 4 | AU3: 5 | AX3: 6 | BA3: 7 | BD3: 8 | BG3: 9 | BJ3: 10 | BM3: 11 | BP3: 12 | BS3: 13 | BV3: 14 | BY3: 15 | CB3: 16 | CE3: 17 | CH3: 18 | CK3: 19 | CN3: 20 | CQ3: 21
K4: ติดป้าย Amezon | L4: ไม่ติดป้าย Amezon | M4: Non Logo | N4: ติดป้าย Amezon | O4: ไม่ติดป้าย Amezon | P4: Non Logo | Q4: ติดป้าย Amezon | R4: ไม่ติดป้าย Amezon | S4: Non Logo | T4: ติดป้าย Amezon | U4: ไม่ติดป้าย Amezon | V4: Non Logo | W4: ติดป้าย Amezon | X4: ไม่ติดป้าย Amezon | Y4: Non Logo | Z4: ติดป้าย Amezon | AA4: ไม่ติดป้าย Amezon | AB4: Non Logo | AC4: ติดป้าย Amezon | AD4: ไม่ติดป้าย Amezon | AE4: Non Logo | AF4: ติดป้าย Amezon | AG4: ไม่ติดป้าย Amezon | AH4: Non Logo | AI4: ติดป้าย Amezon | AJ4: ไม่ติดป้าย Amezon | AK4: Non Logo | AL4: ติดป้าย Amezon | AM4: ไม่ติดป้าย Amezon | AN4: Non Logo | AO4: ติดป้าย Amezon | AP4: ไม่ติดป้าย Amezon | AQ4: Non Logo | AR4: ติดป้าย Amezon | AS4: ไม่ติดป้าย Amezon | AT4: Non Logo | AU4: ติดป้าย Amezon | AV4: ไม่ติดป้าย Amezon | AW4: Non Logo | AX4: ติดป้าย Amezon | AY4: ไม่ติดป้าย Amezon | AZ4: Non Logo | BA4: ติดป้าย Amezon | BB4: ไม่ติดป้าย Amezon | BC4: Non Logo | BD4: ติดป้าย Amezon | BE4: ไม่ติดป้าย Amezon | BF4: Non Logo | BG4: ติดป้าย Amezon | BH4: ไม่ติดป้าย Amezon | BI4: Non Logo | BJ4: ติดป้าย Amezon | BK4: ไม่ติดป้าย Amezon | BL4: Non Logo | BM4: ติดป้าย Amezon | BN4: ไม่ติดป้าย Amezon | BO4: Non Logo | BP4: ติดป้าย Amezon | BQ4: ไม่ติดป้าย Amezon | BR4: Non Logo | BS4: ติดป้าย Amezon | BT4: ไม่ติดป้าย Amezon | BU4: Non Logo | BV4: ติดป้าย Amezon | BW4: ไม่ติดป้าย Amezon | BX4: Non Logo | BY4: ติดป้าย Amezon | BZ4: ไม่ติดป้าย Amezon | CA4: Non Logo | CB4: ติดป้าย Amezon | CC4: ไม่ติดป้าย Amezon | CD4: Non Logo | CE4: ติดป้าย Amezon | CF4: ไม่ติดป้าย Amezon | CG4: Non Logo | CH4: ติดป้าย Amezon | CI4: ไม่ติดป้าย Amezon | CJ4: Non Logo | CK4: ติดป้าย Amezon | CL4: ไม่ติดป้าย Amezon | CM4: Non Logo | CN4: ติดป้าย Amezon | CO4: ไม่ติดป้าย Amezon | CP4: Non Logo | CQ4: ติดป้าย Amezon | CR4: ไม่ติดป้าย Amezon | CS4: Non Logo | CT4: ติดป้าย Amezon | CU4: ไม่ติดป้าย Amezon | CV4: Non Logo | CW4: ติดป้าย Amezon | CX4: ไม่ติดป้าย Amezon | CY4: Non Logo | CZ4: ติดป้าย Amezon | DA4: ไม่ติดป้าย Amezon | DB4: Non Logo | DC4: ติดป้าย Amezon | DD4: ไม่ติดป้าย Amezon | DE4: Non Logo | DF4: ติดป้าย Amezon | DG4: ไม่ติดป้าย Amezon | DH4: Non Logo | DI4: ติดป้าย Amezon | DJ4: ไม่ติดป้าย Amezon | DK4: Non Logo | DL4: ติดป้าย Amezon | DM4: ไม่ติดป้าย Amezon | DN4: Non Logo
A5: 1 | F5: 1113036 | G5: ช็อกบอล | K5: =SUM(N5,Q5,T5,W5,Z5,AC5,AF5,AI5,AL5,AO5,AR5,AU5,AX5,BA5,BD5,BG5,BJ5,BM5,BP5,BS5,BV5,BY5,CB5,CE5,CH5,CK5,CN5,CQ5,CT5,CW5,CZ5,DC5,DF5,DI5,DL5) -> 0 | L5: =SUM(O5,R5,U5,X5,AA5,AD5,AG5,AJ5,AM5,AP5,AS5,AV5,AY5,BB5,BE5,BH5,BK5,BN5,BQ5,BT5,BW5,BZ5,CC5,CF5,CI5,CL5,CO5,CR5,CU5,CX5,DA5,DD5,DG5,DJ5,DM5) -> 0 | M5: =SUM(P5,S5,V5,Y5,AB5,AE5,AH5,AK5,AN5,AQ5,AT5,AW5,AZ5,BC5,BF5,BI5,BL5,BO5,BR5,BU5,BX5,CA5,CD5,CG5,CJ5,CM5,CP5,CS5,CV5,CY5,DB5,DE5,DH5,DK5,DN5) -> 0
A6: =A5+1 -> 2 | F6: 1111001 | G6: ชิฟฟ่อนเค้ก (1 ชิ้น) | K6: =SUM(N6,Q6,T6,W6,Z6,AC6,AF6,AI6,AL6,AO6,AR6,AU6,AX6,BA6,BD6,BG6,BJ6,BM6,BP6,BS6,BV6,BY6,CB6,CE6,CH6,CK6,CN6,CQ6,CT6,CW6,CZ6,DC6,DF6,DI6,DL6) -> 0 | L6: =SUM(O6,R6,U6,X6,AA6,AD6,AG6,AJ6,AM6,AP6,AS6,AV6,AY6,BB6,BE6,BH6,BK6,BN6,BQ6,BT6,BW6,BZ6,CC6,CF6,CI6,CL6,CO6,CR6,CU6,CX6,DA6,DD6,DG6,DJ6,DM6) -> 0 | M6: =SUM(P6,S6,V6,Y6,AB6,AE6,AH6,AK6,AN6,AQ6,AT6,AW6,AZ6,BC6,BF6,BI6,BL6,BO6,BR6,BU6,BX6,CA6,CD6,CG6,CJ6,CM6,CP6,CS6,CV6,CY6,DB6,DE6,DH6,DK6,DN6) -> 0
A7: =A6+1 -> 3 | F7: 1004055 | G7: ชิฟฟ่อนเค้ก วรรณวนัช (รวมรส 4 ชิ้น) | K7: =SUM(N7,Q7,T7,W7,Z7,AC7,AF7,AI7,AL7,AO7,AR7,AU7,AX7,BA7,BD7,BG7,BJ7,BM7,BP7,BS7,BV7,BY7,CB7,CE7,CH7,CK7,CN7,CQ7,CT7,CW7,CZ7,DC7,DF7,DI7,DL7) -> 0 | L7: =SUM(O7,R7,U7,X7,AA7,AD7,AG7,AJ7,AM7,AP7,AS7,AV7,AY7,BB7,BE7,BH7,BK7,BN7,BQ7,BT7,BW7,BZ7,CC7,CF7,CI7,CL7,CO7,CR7,CU7,CX7,DA7,DD7,DG7,DJ7,DM7) -> 0 | M7: =SUM(P7,S7,V7,Y7,AB7,AE7,AH7,AK7,AN7,AQ7,AT7,AW7,AZ7,BC7,BF7,BI7,BL7,BO7,BR7,BU7,BX7,CA7,CD7,CG7,CJ7,CM7,CP7,CS7,CV7,CY7,DB7,DE7,DH7,DK7,DN7) -> 0
A8: =A7+1 -> 4 | F8: 1111002 | G8: ชิฟฟ่อนเค้ก วรรณวนัช (รวมรส 8 ชิ้น) | K8: =SUM(N8,Q8,T8,W8,Z8,AC8,AF8,AI8,AL8,AO8,AR8,AU8,AX8,BA8,BD8,BG8,BJ8,BM8,BP8,BS8,BV8,BY8,CB8,CE8,CH8,CK8,CN8,CQ8,CT8,CW8,CZ8,DC8,DF8,DI8,DL8) -> 0 | L8: =SUM(O8,R8,U8,X8,AA8,AD8,AG8,AJ8,AM8,AP8,AS8,AV8,AY8,BB8,BE8,BH8,BK8,BN8,BQ8,BT8,BW8,BZ8,CC8,CF8,CI8,CL8,CO8,CR8,CU8,CX8,DA8,DD8,DG8,DJ8,DM8) -> 0 | M8: =SUM(P8,S8,V8,Y8,AB8,AE8,AH8,AK8,AN8,AQ8,AT8,AW8,AZ8,BC8,BF8,BI8,BL8,BO8,BR8,BU8,BX8,CA8,CD8,CG8,CJ8,CM8,CP8,CS8,CV8,CY8,DB8,DE8,DH8,DK8,DN8) -> 0
A9: =A8+1 -> 5 | F9: 1111055 | G9: วรรณวนัช ชิฟฟ่อนรวมรส 8 ชิ้น | K9: =SUM(N9,Q9,T9,W9,Z9,AC9,AF9,AI9,AL9,AO9,AR9,AU9,AX9,BA9,BD9,BG9,BJ9,BM9,BP9,BS9,BV9,BY9,CB9,CE9,CH9,CK9,CN9,CQ9,CT9,CW9,CZ9,DC9,DF9,DI9,DL9) -> 0 | L9: =SUM(O9,R9,U9,X9,AA9,AD9,AG9,AJ9,AM9,AP9,AS9,AV9,AY9,BB9,BE9,BH9,BK9,BN9,BQ9,BT9,BW9,BZ9,CC9,CF9,CI9,CL9,CO9,CR9,CU9,CX9,DA9,DD9,DG9,DJ9,DM9) -> 0 | M9: =SUM(P9,S9,V9,Y9,AB9,AE9,AH9,AK9,AN9,AQ9,AT9,AW9,AZ9,BC9,BF9,BI9,BL9,BO9,BR9,BU9,BX9,CA9,CD9,CG9,CJ9,CM9,CP9,CS9,CV9,CY9,DB9,DE9,DH9,DK9,DN9) -> 0
A10: =A9+1 -> 6 | F10: 1111030 | G10: ชิฟฟ่อนเค้ก รสกาแฟ (8 ชิ้น) | K10: =SUM(N10,Q10,T10,W10,Z10,AC10,AF10,AI10,AL10,AO10,AR10,AU10,AX10,BA10,BD10,BG10,BJ10,BM10,BP10,BS10,BV10,BY10,CB10,CE10,CH10,CK10,CN10,CQ10,CT10,CW10,CZ10,DC10,DF10,DI10,DL10) -> 0 | L10: =SUM(O10,R10,U10,X10,AA10,AD10,AG10,AJ10,AM10,AP10,AS10,AV10,AY10,BB10,BE10,BH10,BK10,BN10,BQ10,BT10,BW10,BZ10,CC10,CF10,CI10,CL10,CO10,CR10,CU10,CX10,DA10,DD10,DG10,DJ10,DM10) -> 0 | M10: =SUM(P10,S10,V10,Y10,AB10,AE10,AH10,AK10,AN10,AQ10,AT10,AW10,AZ10,BC10,BF10,BI10,BL10,BO10,BR10,BU10,BX10,CA10,CD10,CG10,CJ10,CM10,CP10,CS10,CV10,CY10,DB10,DE10,DH10,DK10,DN10) -> 0
A11: =A10+1 -> 7 | F11: 1111036 | G11: ชิฟฟอนเค้ก วรรณวนัช ห่อกระดาษ (รวมรส 4 ชิ้น) | K11: =SUM(N11,Q11,T11,W11,Z11,AC11,AF11,AI11,AL11,AO11,AR11,AU11,AX11,BA11,BD11,BG11,BJ11,BM11,BP11,BS11,BV11,BY11,CB11,CE11,CH11,CK11,CN11,CQ11,CT11,CW11,CZ11,DC11,DF11,DI11,DL11) -> 0 | L11: =SUM(O11,R11,U11,X11,AA11,AD11,AG11,AJ11,AM11,AP11,AS11,AV11,AY11,BB11,BE11,BH11,BK11,BN11,BQ11,BT11,BW11,BZ11,CC11,CF11,CI11,CL11,CO11,CR11,CU11,CX11,DA11,DD11,DG11,DJ11,DM11) -> 0 | M11: =SUM(P11,S11,V11,Y11,AB11,AE11,AH11,AK11,AN11,AQ11,AT11,AW11,AZ11,BC11,BF11,BI11,BL11,BO11,BR11,BU11,BX11,CA11,CD11,CG11,CJ11,CM11,CP11,CS11,CV11,CY11,DB11,DE11,DH11,DK11,DN11) -> 0
A12: =A11+1 -> 8 | F12: 1111037 | G12: ชิฟฟอนเค้ก วรรณวนัช ห่อกระดาษ (รวมรส 8 ชิ้น) | K12: =SUM(N12,Q12,T12,W12,Z12,AC12,AF12,AI12,AL12,AO12,AR12,AU12,AX12,BA12,BD12,BG12,BJ12,BM12,BP12,BS12,BV12,BY12,CB12,CE12,CH12,CK12,CN12,CQ12,CT12,CW12,CZ12,DC12,DF12,DI12,DL12) -> 0 | L12: =SUM(O12,R12,U12,X12,AA12,AD12,AG12,AJ12,AM12,AP12,AS12,AV12,AY12,BB12,BE12,BH12,BK12,BN12,BQ12,BT12,BW12,BZ12,CC12,CF12,CI12,CL12,CO12,CR12,CU12,CX12,DA12,DD12,DG12,DJ12,DM12) -> 0 | M12: =SUM(P12,S12,V12,Y12,AB12,AE12,AH12,AK12,AN12,AQ12,AT12,AW12,AZ12,BC12,BF12,BI12,BL12,BO12,BR12,BU12,BX12,CA12,CD12,CG12,CJ12,CM12,CP12,CS12,CV12,CY12,DB12,DE12,DH12,DK12,DN12) -> 0
A13: =A12+1 -> 9 | F13: 1111040 | G13: ชิฟฟอนเค้กวรรณวนัช ห่อซีน (รวมรส 4 ชิ้น) | K13: =SUM(N13,Q13,T13,W13,Z13,AC13,AF13,AI13,AL13,AO13,AR13,AU13,AX13,BA13,BD13,BG13,BJ13,BM13,BP13,BS13,BV13,BY13,CB13,CE13,CH13,CK13,CN13,CQ13,CT13,CW13,CZ13,DC13,DF13,DI13,DL13) -> 0 | L13: =SUM(O13,R13,U13,X13,AA13,AD13,AG13,AJ13,AM13,AP13,AS13,AV13,AY13,BB13,BE13,BH13,BK13,BN13,BQ13,BT13,BW13,BZ13,CC13,CF13,CI13,CL13,CO13,CR13,CU13,CX13,DA13,DD13,DG13,DJ13,DM13) -> 0 | M13: =SUM(P13,S13,V13,Y13,AB13,AE13,AH13,AK13,AN13,AQ13,AT13,AW13,AZ13,BC13,BF13,BI13,BL13,BO13,BR13,BU13,BX13,CA13,CD13,CG13,CJ13,CM13,CP13,CS13,CV13,CY13,DB13,DE13,DH13,DK13,DN13) -> 0
A14: =A13+1 -> 10 | F14: 1111039 | G14: ชิฟฟอนเค้ก วรรรณวนัช ห่อซีน (รวมรส 8 ชิ้น) | K14: =SUM(N14,Q14,T14,W14,Z14,AC14,AF14,AI14,AL14,AO14,AR14,AU14,AX14,BA14,BD14,BG14,BJ14,BM14,BP14,BS14,BV14,BY14,CB14,CE14,CH14,CK14,CN14,CQ14,CT14,CW14,CZ14,DC14,DF14,DI14,DL14) -> 0 | L14: =SUM(O14,R14,U14,X14,AA14,AD14,AG14,AJ14,AM14,AP14,AS14,AV14,AY14,BB14,BE14,BH14,BK14,BN14,BQ14,BT14,BW14,BZ14,CC14,CF14,CI14,CL14,CO14,CR14,CU14,CX14,DA14,DD14,DG14,DJ14,DM14) -> 0 | M14: =SUM(P14,S14,V14,Y14,AB14,AE14,AH14,AK14,AN14,AQ14,AT14,AW14,AZ14,BC14,BF14,BI14,BL14,BO14,BR14,BU14,BX14,CA14,CD14,CG14,CJ14,CM14,CP14,CS14,CV14,CY14,DB14,DE14,DH14,DK14,DN14) -> 0
A15: =A14+1 -> 11 | F15: 1111041 | G15: ชิฟฟอนเค้ก วรรณวนัช กาแฟล้วน(รวมรส 4 ชิ้น) | K15: =SUM(N15,Q15,T15,W15,Z15,AC15,AF15,AI15,AL15,AO15,AR15,AU15,AX15,BA15,BD15,BG15,BJ15,BM15,BP15,BS15,BV15,BY15,CB15,CE15,CH15,CK15,CN15,CQ15,CT15,CW15,CZ15,DC15,DF15,DI15,DL15) -> 0 | L15: =SUM(O15,R15,U15,X15,AA15,AD15,AG15,AJ15,AM15,AP15,AS15,AV15,AY15,BB15,BE15,BH15,BK15,BN15,BQ15,BT15,BW15,BZ15,CC15,CF15,CI15,CL15,CO15,CR15,CU15,CX15,DA15,DD15,DG15,DJ15,DM15) -> 0 | M15: =SUM(P15,S15,V15,Y15,AB15,AE15,AH15,AK15,AN15,AQ15,AT15,AW15,AZ15,BC15,BF15,BI15,BL15,BO15,BR15,BU15,BX15,CA15,CD15,CG15,CJ15,CM15,CP15,CS15,CV15,CY15,DB15,DE15,DH15,DK15,DN15) -> 0
A16: =A15+1 -> 12 | F16: 1111043 | G16: ชิฟฟอนรสมะลิ 8 ชิ้น ห่อ ซีน | K16: =SUM(N16,Q16,T16,W16,Z16,AC16,AF16,AI16,AL16,AO16,AR16,AU16,AX16,BA16,BD16,BG16,BJ16,BM16,BP16,BS16,BV16,BY16,CB16,CE16,CH16,CK16,CN16,CQ16,CT16,CW16,CZ16,DC16,DF16,DI16,DL16) -> 0 | L16: =SUM(O16,R16,U16,X16,AA16,AD16,AG16,AJ16,AM16,AP16,AS16,AV16,AY16,BB16,BE16,BH16,BK16,BN16,BQ16,BT16,BW16,BZ16,CC16,CF16,CI16,CL16,CO16,CR16,CU16,CX16,DA16,DD16,DG16,DJ16,DM16) -> 0 | M16: =SUM(P16,S16,V16,Y16,AB16,AE16,AH16,AK16,AN16,AQ16,AT16,AW16,AZ16,BC16,BF16,BI16,BL16,BO16,BR16,BU16,BX16,CA16,CD16,CG16,CJ16,CM16,CP16,CS16,CV16,CY16,DB16,DE16,DH16,DK16,DN16) -> 0
A17: =A16+1 -> 13 | F17: 1113091 | G17: (BC) ชิฟฟ่อนรวมรส 4 ชิ้น | K17: =SUM(N17,Q17,T17,W17,Z17,AC17,AF17,AI17,AL17,AO17,AR17,AU17,AX17,BA17,BD17,BG17,BJ17,BM17,BP17,BS17,BV17,BY17,CB17,CE17,CH17,CK17,CN17,CQ17,CT17,CW17,CZ17,DC17,DF17,DI17,DL17) -> 0 | L17: =SUM(O17,R17,U17,X17,AA17,AD17,AG17,AJ17,AM17,AP17,AS17,AV17,AY17,BB17,BE17,BH17,BK17,BN17,BQ17,BT17,BW17,BZ17,CC17,CF17,CI17,CL17,CO17,CR17,CU17,CX17,DA17,DD17,DG17,DJ17,DM17) -> 0 | M17: =SUM(P17,S17,V17,Y17,AB17,AE17,AH17,AK17,AN17,AQ17,AT17,AW17,AZ17,BC17,BF17,BI17,BL17,BO17,BR17,BU17,BX17,CA17,CD17,CG17,CJ17,CM17,CP17,CS17,CV17,CY17,DB17,DE17,DH17,DK17,DN17) -> 0
... A100: =A99+1 -> 96 | F100: 1113062 | G100: (MK) ชิฟฟ่อนหม้อแกง | K100: =SUM(N100,Q100,T100,W100,Z100,AC100,AF100,AI100,AL100,AO100,AR100,AU100,AX100,BA100,BD100,BG100,BJ100,BM100,BP100,BS100,BV100,BY100,CB100,CE100,CH100,CK100,CN100,CQ100,CT100,CW100,CZ100,DC100,DF100,DI100,DL100) -> 0 | L100: =SUM(O100,R100,U100,X100,AA100,AD100,AG100,AJ100,AM100,AP100,AS100,AV100,AY100,BB100,BE100,BH100,BK100,BN100,BQ100,BT100,BW100,BZ100,CC100,CF100,CI100,CL100,CO100,CR100,CU100,CX100,DA100,DD100,DG100,DJ100,DM100) -> 0 | M100: =SUM(P100,S100,V100,Y100,AB100,AE100,AH100,AK100,AN100,AQ100,AT100,AW100,AZ100,BC100,BF100,BI100,BL100,BO100,BR100,BU100,BX100,CA100,CD100,CG100,CJ100,CM100,CP100,CS100,CV100,CY100,DB100,DE100,DH100,DK100,DN100) -> 0
A101: =A100+1 -> 97 | F101: 1113085 | K101: =SUM(N101,Q101,T101,W101,Z101,AC101,AF101,AI101,AL101,AO101,AR101,AU101,AX101,BA101,BD101,BG101,BJ101,BM101,BP101,BS101,BV101,BY101,CB101,CE101,CH101,CK101,CN101,CQ101,CT101,CW101,CZ101,DC101,DF101,DI101,DL101) -> 0 | L101: =SUM(O101,R101,U101,X101,AA101,AD101,AG101,AJ101,AM101,AP101,AS101,AV101,AY101,BB101,BE101,BH101,BK101,BN101,BQ101,BT101,BW101,BZ101,CC101,CF101,CI101,CL101,CO101,CR101,CU101,CX101,DA101,DD101,DG101,DJ101,DM101) -> 0 | M101: =SUM(P101,S101,V101,Y101,AB101,AE101,AH101,AK101,AN101,AQ101,AT101,AW101,AZ101,BC101,BF101,BI101,BL101,BO101,BR101,BU101,BX101,CA101,CD101,CG101,CJ101,CM101,CP101,CS101,CV101,CY101,DB101,DE101,DH101,DK101,DN101) -> 0
A102: =A101+1 -> 98 | F102: 1004074 | K102: =SUM(N102,Q102,T102,W102,Z102,AC102,AF102,AI102,AL102,AO102,AR102,AU102,AX102,BA102,BD102,BG102,BJ102,BM102,BP102,BS102,BV102,BY102,CB102,CE102,CH102,CK102,CN102,CQ102,CT102,CW102,CZ102,DC102,DF102,DI102,DL102) -> 0 | L102: =SUM(O102,R102,U102,X102,AA102,AD102,AG102,AJ102,AM102,AP102,AS102,AV102,AY102,BB102,BE102,BH102,BK102,BN102,BQ102,BT102,BW102,BZ102,CC102,CF102,CI102,CL102,CO102,CR102,CU102,CX102,DA102,DD102,DG102,DJ102,DM102) -> 0 | M102: =SUM(P102,S102,V102,Y102,AB102,AE102,AH102,AK102,AN102,AQ102,AT102,AW102,AZ102,BC102,BF102,BI102,BL102,BO102,BR102,BU102,BX102,CA102,CD102,CG102,CJ102,CM102,CP102,CS102,CV102,CY102,DB102,DE102,DH102,DK102,DN102) -> 0
A103: =A102+1 -> 99 | F103: 20053053 | K103: =SUM(N103,Q103,T103,W103,Z103,AC103,AF103,AI103,AL103,AO103,AR103,AU103,AX103,BA103,BD103,BG103,BJ103,BM103,BP103,BS103,BV103,BY103,CB103,CE103,CH103,CK103,CN103,CQ103,CT103,CW103,CZ103,DC103,DF103,DI103,DL103) -> 0 | L103: =SUM(O103,R103,U103,X103,AA103,AD103,AG103,AJ103,AM103,AP103,AS103,AV103,AY103,BB103,BE103,BH103,BK103,BN103,BQ103,BT103,BW103,BZ103,CC103,CF103,CI103,CL103,CO103,CR103,CU103,CX103,DA103,DD103,DG103,DJ103,DM103) -> 0 | M103: =SUM(P103,S103,V103,Y103,AB103,AE103,AH103,AK103,AN103,AQ103,AT103,AW103,AZ103,BC103,BF103,BI103,BL103,BO103,BR103,BU103,BX103,CA103,CD103,CG103,CJ103,CM103,CP103,CS103,CV103,CY103,DB103,DE103,DH103,DK103,DN103) -> 0
A104: =A103+1 -> 100 | F104: 1113157 | G104: (BC) เค้กลอดช่อง 85 g. | K104: =SUM(N104,Q104,T104,W104,Z104,AC104,AF104,AI104,AL104,AO104,AR104,AU104,AX104,BA104,BD104,BG104,BJ104,BM104,BP104,BS104,BV104,BY104,CB104,CE104,CH104,CK104,CN104,CQ104,CT104,CW104,CZ104,DC104,DF104,DI104,DL104) -> 0 | L104: =SUM(O104,R104,U104,X104,AA104,AD104,AG104,AJ104,AM104,AP104,AS104,AV104,AY104,BB104,BE104,BH104,BK104,BN104,BQ104,BT104,BW104,BZ104,CC104,CF104,CI104,CL104,CO104,CR104,CU104,CX104,DA104,DD104,DG104,DJ104,DM104) -> 0 | M104: =SUM(P104,S104,V104,Y104,AB104,AE104,AH104,AK104,AN104,AQ104,AT104,AW104,AZ104,BC104,BF104,BI104,BL104,BO104,BR104,BU104,BX104,CA104,CD104,CG104,CJ104,CM104,CP104,CS104,CV104,CY104,DB104,DE104,DH104,DK104,DN104) -> 0
A105: =A104+1 -> 101 | F105: 1004064 | K105: =SUM(N105,Q105,T105,W105,Z105,AC105,AF105,AI105,AL105,AO105,AR105,AU105,AX105,BA105,BD105,BG105,BJ105,BM105,BP105,BS105,BV105,BY105,CB105,CE105,CH105,CK105,CN105,CQ105,CT105,CW105,CZ105,DC105,DF105,DI105,DL105) -> 0 | L105: =SUM(O105,R105,U105,X105,AA105,AD105,AG105,AJ105,AM105,AP105,AS105,AV105,AY105,BB105,BE105,BH105,BK105,BN105,BQ105,BT105,BW105,BZ105,CC105,CF105,CI105,CL105,CO105,CR105,CU105,CX105,DA105,DD105,DG105,DJ105,DM105) -> 0 | M105: =SUM(P105,S105,V105,Y105,AB105,AE105,AH105,AK105,AN105,AQ105,AT105,AW105,AZ105,BC105,BF105,BI105,BL105,BO105,BR105,BU105,BX105,CA105,CD105,CG105,CJ105,CM105,CP105,CS105,CV105,CY105,DB105,DE105,DH105,DK105,DN105) -> 0
A106: =A105+1 -> 102 | F106: 20052724 | K106: =SUM(N106,Q106,T106,W106,Z106,AC106,AF106,AI106,AL106,AO106,AR106,AU106,AX106,BA106,BD106,BG106,BJ106,BM106,BP106,BS106,BV106,BY106,CB106,CE106,CH106,CK106,CN106,CQ106,CT106,CW106,CZ106,DC106,DF106,DI106,DL106) -> 0 | L106: =SUM(O106,R106,U106,X106,AA106,AD106,AG106,AJ106,AM106,AP106,AS106,AV106,AY106,BB106,BE106,BH106,BK106,BN106,BQ106,BT106,BW106,BZ106,CC106,CF106,CI106,CL106,CO106,CR106,CU106,CX106,DA106,DD106,DG106,DJ106,DM106) -> 0 | M106: =SUM(P106,S106,V106,Y106,AB106,AE106,AH106,AK106,AN106,AQ106,AT106,AW106,AZ106,BC106,BF106,BI106,BL106,BO106,BR106,BU106,BX106,CA106,CD106,CG106,CJ106,CM106,CP106,CS106,CV106,CY106,DB106,DE106,DH106,DK106,DN106) -> 0
A107: =A106+1 -> 103 | F107: 1004072 | G107: เค้กโบราณ ครีม (2ชิ้น) | K107: =SUM(N107,Q107,T107,W107,Z107,AC107,AF107,AI107,AL107,AO107,AR107,AU107,AX107,BA107,BD107,BG107,BJ107,BM107,BP107,BS107,BV107,BY107,CB107,CE107,CH107,CK107,CN107,CQ107,CT107,CW107,CZ107,DC107,DF107,DI107,DL107) -> 0 | L107: =SUM(O107,R107,U107,X107,AA107,AD107,AG107,AJ107,AM107,AP107,AS107,AV107,AY107,BB107,BE107,BH107,BK107,BN107,BQ107,BT107,BW107,BZ107,CC107,CF107,CI107,CL107,CO107,CR107,CU107,CX107,DA107,DD107,DG107,DJ107,DM107) -> 0 | M107: =SUM(P107,S107,V107,Y107,AB107,AE107,AH107,AK107,AN107,AQ107,AT107,AW107,AZ107,BC107,BF107,BI107,BL107,BO107,BR107,BU107,BX107,CA107,CD107,CG107,CJ107,CM107,CP107,CS107,CV107,CY107,DB107,DE107,DH107,DK107,DN107) -> 0
A108: =A107+1 -> 104 | F108: 1004073 | G108: เค้กโบราณ ผลไม้ (2 ชิ้น) | K108: =SUM(N108,Q108,T108,W108,Z108,AC108,AF108,AI108,AL108,AO108,AR108,AU108,AX108,BA108,BD108,BG108,BJ108,BM108,BP108,BS108,BV108,BY108,CB108,CE108,CH108,CK108,CN108,CQ108,CT108,CW108,CZ108,DC108,DF108,DI108,DL108) -> 0 | L108: =SUM(O108,R108,U108,X108,AA108,AD108,AG108,AJ108,AM108,AP108,AS108,AV108,AY108,BB108,BE108,BH108,BK108,BN108,BQ108,BT108,BW108,BZ108,CC108,CF108,CI108,CL108,CO108,CR108,CU108,CX108,DA108,DD108,DG108,DJ108,DM108) -> 0 | M108: =SUM(P108,S108,V108,Y108,AB108,AE108,AH108,AK108,AN108,AQ108,AT108,AW108,AZ108,BC108,BF108,BI108,BL108,BO108,BR108,BU108,BX108,CA108,CD108,CG108,CJ108,CM108,CP108,CS108,CV108,CY108,DB108,DE108,DH108,DK108,DN108) -> 0
A109: =A108+1 -> 105 | F109: 1113006 | G109: เค้กโบราณ ครีม (4 ชิ้น) | K109: =SUM(N109,Q109,T109,W109,Z109,AC109,AF109,AI109,AL109,AO109,AR109,AU109,AX109,BA109,BD109,BG109,BJ109,BM109,BP109,BS109,BV109,BY109,CB109,CE109,CH109,CK109,CN109,CQ109,CT109,CW109,CZ109,DC109,DF109,DI109,DL109) -> 0 | L109: =SUM(O109,R109,U109,X109,AA109,AD109,AG109,AJ109,AM109,AP109,AS109,AV109,AY109,BB109,BE109,BH109,BK109,BN109,BQ109,BT109,BW109,BZ109,CC109,CF109,CI109,CL109,CO109,CR109,CU109,CX109,DA109,DD109,DG109,DJ109,DM109) -> 0 | M109: =SUM(P109,S109,V109,Y109,AB109,AE109,AH109,AK109,AN109,AQ109,AT109,AW109,AZ109,BC109,BF109,BI109,BL109,BO109,BR109,BU109,BX109,CA109,CD109,CG109,CJ109,CM109,CP109,CS109,CV109,CY109,DB109,DE109,DH109,DK109,DN109) -> 0
A110: =A109+1 -> 106 | F110: 1113007 | G110: เค้กโบราณ ผลไม้ (4 ชิ้น) | K110: =SUM(N110,Q110,T110,W110,Z110,AC110,AF110,AI110,AL110,AO110,AR110,AU110,AX110,BA110,BD110,BG110,BJ110,BM110,BP110,BS110,BV110,BY110,CB110,CE110,CH110,CK110,CN110,CQ110,CT110,CW110,CZ110,DC110,DF110,DI110,DL110) -> 0 | L110: =SUM(O110,R110,U110,X110,AA110,AD110,AG110,AJ110,AM110,AP110,AS110,AV110,AY110,BB110,BE110,BH110,BK110,BN110,BQ110,BT110,BW110,BZ110,CC110,CF110,CI110,CL110,CO110,CR110,CU110,CX110,DA110,DD110,DG110,DJ110,DM110) -> 0 | M110: =SUM(P110,S110,V110,Y110,AB110,AE110,AH110,AK110,AN110,AQ110,AT110,AW110,AZ110,BC110,BF110,BI110,BL110,BO110,BR110,BU110,BX110,CA110,CD110,CG110,CJ110,CM110,CP110,CS110,CV110,CY110,DB110,DE110,DH110,DK110,DN110) -> 0
A111: =A110+1 -> 107 | F111: 1113008 | G111: เค้กโบราณ รวมรส (4 ชิ้น) | K111: =SUM(N111,Q111,T111,W111,Z111,AC111,AF111,AI111,AL111,AO111,AR111,AU111,AX111,BA111,BD111,BG111,BJ111,BM111,BP111,BS111,BV111,BY111,CB111,CE111,CH111,CK111,CN111,CQ111,CT111,CW111,CZ111,DC111,DF111,DI111,DL111) -> 0 | L111: =SUM(O111,R111,U111,X111,AA111,AD111,AG111,AJ111,AM111,AP111,AS111,AV111,AY111,BB111,BE111,BH111,BK111,BN111,BQ111,BT111,BW111,BZ111,CC111,CF111,CI111,CL111,CO111,CR111,CU111,CX111,DA111,DD111,DG111,DJ111,DM111) -> 0 | M111: =SUM(P111,S111,V111,Y111,AB111,AE111,AH111,AK111,AN111,AQ111,AT111,AW111,AZ111,BC111,BF111,BI111,BL111,BO111,BR111,BU111,BX111,CA111,CD111,CG111,CJ111,CM111,CP111,CS111,CV111,CY111,DB111,DE111,DH111,DK111,DN111) -> 0
A112: =A111+1 -> 108 | F112: 1113107 | G112: โบราณใหญ่ 12 ชิ้น | K112: =SUM(N112,Q112,T112,W112,Z112,AC112,AF112,AI112,AL112,AO112,AR112,AU112,AX112,BA112,BD112,BG112,BJ112,BM112,BP112,BS112,BV112,BY112,CB112,CE112,CH112,CK112,CN112,CQ112,CT112,CW112,CZ112,DC112,DF112,DI112,DL112) -> 0 | L112: =SUM(O112,R112,U112,X112,AA112,AD112,AG112,AJ112,AM112,AP112,AS112,AV112,AY112,BB112,BE112,BH112,BK112,BN112,BQ112,BT112,BW112,BZ112,CC112,CF112,CI112,CL112,CO112,CR112,CU112,CX112,DA112,DD112,DG112,DJ112,DM112) -> 0 | M112: =SUM(P112,S112,V112,Y112,AB112,AE112,AH112,AK112,AN112,AQ112,AT112,AW112,AZ112,BC112,BF112,BI112,BL112,BO112,BR112,BU112,BX112,CA112,CD112,CG112,CJ112,CM112,CP112,CS112,CV112,CY112,DB112,DE112,DH112,DK112,DN112) -> 0
A113: =A112+1 -> 109 | F113: 1113120 | G113: โบราณใหญ่หน้าครีม (แผ่น) | K113: =SUM(N113,Q113,T113,W113,Z113,AC113,AF113,AI113,AL113,AO113,AR113,AU113,AX113,BA113,BD113,BG113,BJ113,BM113,BP113,BS113,BV113,BY113,CB113,CE113,CH113,CK113,CN113,CQ113,CT113,CW113,CZ113,DC113,DF113,DI113,DL113) -> 0 | L113: =SUM(O113,R113,U113,X113,AA113,AD113,AG113,AJ113,AM113,AP113,AS113,AV113,AY113,BB113,BE113,BH113,BK113,BN113,BQ113,BT113,BW113,BZ113,CC113,CF113,CI113,CL113,CO113,CR113,CU113,CX113,DA113,DD113,DG113,DJ113,DM113) -> 0 | M113: =SUM(P113,S113,V113,Y113,AB113,AE113,AH113,AK113,AN113,AQ113,AT113,AW113,AZ113,BC113,BF113,BI113,BL113,BO113,BR113,BU113,BX113,CA113,CD113,CG113,CJ113,CM113,CP113,CS113,CV113,CY113,DB113,DE113,DH113,DK113,DN113) -> 0
A114: =A113+1 -> 110 | F114: 1113092 | G114: (BC) เค้กโบราณ 4 ชิ้น | K114: =SUM(N114,Q114,T114,W114,Z114,AC114,AF114,AI114,AL114,AO114,AR114,AU114,AX114,BA114,BD114,BG114,BJ114,BM114,BP114,BS114,BV114,BY114,CB114,CE114,CH114,CK114,CN114,CQ114,CT114,CW114,CZ114,DC114,DF114,DI114,DL114) -> 0 | L114: =SUM(O114,R114,U114,X114,AA114,AD114,AG114,AJ114,AM114,AP114,AS114,AV114,AY114,BB114,BE114,BH114,BK114,BN114,BQ114,BT114,BW114,BZ114,CC114,CF114,CI114,CL114,CO114,CR114,CU114,CX114,DA114,DD114,DG114,DJ114,DM114) -> 0 | M114: =SUM(P114,S114,V114,Y114,AB114,AE114,AH114,AK114,AN114,AQ114,AT114,AW114,AZ114,BC114,BF114,BI114,BL114,BO114,BR114,BU114,BX114,CA114,CD114,CG114,CJ114,CM114,CP114,CS114,CV114,CY114,DB114,DE114,DH114,DK114,DN114) -> 0
A115: =A114+1 -> 111 | F115: 1113146 | G115: โบราณ 4 ชิ้น (กล่องแดง) | K115: =SUM(N115,Q115,T115,W115,Z115,AC115,AF115,AI115,AL115,AO115,AR115,AU115,AX115,BA115,BD115,BG115,BJ115,BM115,BP115,BS115,BV115,BY115,CB115,CE115,CH115,CK115,CN115,CQ115,CT115,CW115,CZ115,DC115,DF115,DI115,DL115) -> 0 | L115: =SUM(O115,R115,U115,X115,AA115,AD115,AG115,AJ115,AM115,AP115,AS115,AV115,AY115,BB115,BE115,BH115,BK115,BN115,BQ115,BT115,BW115,BZ115,CC115,CF115,CI115,CL115,CO115,CR115,CU115,CX115,DA115,DD115,DG115,DJ115,DM115) -> 0 | M115: =SUM(P115,S115,V115,Y115,AB115,AE115,AH115,AK115,AN115,AQ115,AT115,AW115,AZ115,BC115,BF115,BI115,BL115,BO115,BR115,BU115,BX115,CA115,CD115,CG115,CJ115,CM115,CP115,CS115,CV115,CY115,DB115,DE115,DH115,DK115,DN115) -> 0
A116: =A115+1 -> 112 | F116: 1113147 | G116: โบราณ 4 ชิ้น (กล่องแดง) แบบแผ่น | K116: =SUM(N116,Q116,T116,W116,Z116,AC116,AF116,AI116,AL116,AO116,AR116,AU116,AX116,BA116,BD116,BG116,BJ116,BM116,BP116,BS116,BV116,BY116,CB116,CE116,CH116,CK116,CN116,CQ116,CT116,CW116,CZ116,DC116,DF116,DI116,DL116) -> 0 | L116: =SUM(O116,R116,U116,X116,AA116,AD116,AG116,AJ116,AM116,AP116,AS116,AV116,AY116,BB116,BE116,BH116,BK116,BN116,BQ116,BT116,BW116,BZ116,CC116,CF116,CI116,CL116,CO116,CR116,CU116,CX116,DA116,DD116,DG116,DJ116,DM116) -> 0 | M116: =SUM(P116,S116,V116,Y116,AB116,AE116,AH116,AK116,AN116,AQ116,AT116,AW116,AZ116,BC116,BF116,BI116,BL116,BO116,BR116,BU116,BX116,CA116,CD116,CG116,CJ116,CM116,CP116,CS116,CV116,CY116,DB116,DE116,DH116,DK116,DN116) -> 0
A117: =A116+1 -> 113 | F117: 20036350 | G117: Wanwanach_เค้กโบราณ 200 g | K117: =SUM(N117,Q117,T117,W117,Z117,AC117,AF117,AI117,AL117,AO117,AR117,AU117,AX117,BA117,BD117,BG117,BJ117,BM117,BP117,BS117,BV117,BY117,CB117,CE117,CH117,CK117,CN117,CQ117,CT117,CW117,CZ117,DC117,DF117,DI117,DL117) -> 0 | L117: =SUM(O117,R117,U117,X117,AA117,AD117,AG117,AJ117,AM117,AP117,AS117,AV117,AY117,BB117,BE117,BH117,BK117,BN117,BQ117,BT117,BW117,BZ117,CC117,CF117,CI117,CL117,CO117,CR117,CU117,CX117,DA117,DD117,DG117,DJ117,DM117) -> 0 | M117: =SUM(P117,S117,V117,Y117,AB117,AE117,AH117,AK117,AN117,AQ117,AT117,AW117,AZ117,BC117,BF117,BI117,BL117,BO117,BR117,BU117,BX117,CA117,CD117,CG117,CJ117,CM117,CP117,CS117,CV117,CY117,DB117,DE117,DH117,DK117,DN117) -> 0
A118: =A117+1 -> 114 | F118: 1113162 | G118: เค้กโบราณครีม 12 ชิ้น | K118: =SUM(N118,Q118,T118,W118,Z118,AC118,AF118,AI118,AL118,AO118,AR118,AU118,AX118,BA118,BD118,BG118,BJ118,BM118,BP118,BS118,BV118,BY118,CB118,CE118,CH118,CK118,CN118,CQ118,CT118,CW118,CZ118,DC118,DF118,DI118,DL118) -> 0 | L118: =SUM(O118,R118,U118,X118,AA118,AD118,AG118,AJ118,AM118,AP118,AS118,AV118,AY118,BB118,BE118,BH118,BK118,BN118,BQ118,BT118,BW118,BZ118,CC118,CF118,CI118,CL118,CO118,CR118,CU118,CX118,DA118,DD118,DG118,DJ118,DM118) -> 0 | M118: =SUM(P118,S118,V118,Y118,AB118,AE118,AH118,AK118,AN118,AQ118,AT118,AW118,AZ118,BC118,BF118,BI118,BL118,BO118,BR118,BU118,BX118,CA118,CD118,CG118,CJ118,CM118,CP118,CS118,CV118,CY118,DB118,DE118,DH118,DK118,DN118) -> 0
... A135: =A134+1 -> 131 | F135: 1111408 | G135: เค้กวันเกิดสตอเบอรี่ 1 ปอนด์ | K135: =SUM(N135,Q135,T135,W135,Z135,AC135,AF135,AI135,AL135,AO135,AR135,AU135,AX135,BA135,BD135,BG135,BJ135,BM135,BP135,BS135,BV135,BY135,CB135,CE135,CH135,CK135,CN135,CQ135,CT135,CW135,CZ135,DC135,DF135,DI135,DL135) -> 0 | L135: =SUM(O135,R135,U135,X135,AA135,AD135,AG135,AJ135,AM135,AP135,AS135,AV135,AY135,BB135,BE135,BH135,BK135,BN135,BQ135,BT135,BW135,BZ135,CC135,CF135,CI135,CL135,CO135,CR135,CU135,CX135,DA135,DD135,DG135,DJ135,DM135) -> 0 | M135: =SUM(P135,S135,V135,Y135,AB135,AE135,AH135,AK135,AN135,AQ135,AT135,AW135,AZ135,BC135,BF135,BI135,BL135,BO135,BR135,BU135,BX135,CA135,CD135,CG135,CJ135,CM135,CP135,CS135,CV135,CY135,DB135,DE135,DH135,DK135,DN135) -> 0
A136: =A135+1 -> 132 | F136: 1111409 | G136: เค้กวันเกิดช็อกโกแลต 1/2 ปอนด์ | L136: =SUM(O136,R136,U136,X136,AA136,AD136,AG136,AJ136,AM136,AP136,AS136,AV136,AY136,BB136,BE136,BH136,BK136,BN136,BQ136,BT136,BW136,BZ136,CC136,CF136,CI136,CL136,CO136,CR136,CU136,CX136,DA136,DD136,DG136,DJ136,DM136) -> 0
A137: =A136+1 -> 133 | F137: 1111410 | G137: เค้กวันเกิดมะพร้าว 1/2 ปอนด์ | K137: =SUM(N137,Q137,T137,W137,Z137,AC137,AF137,AI137,AL137,AO137,AR137,AU137,AX137,BA137,BD137,BG137,BJ137,BM137,BP137,BS137,BV137,BY137,CB137,CE137,CH137,CK137,CN137,CQ137,CT137,CW137,CZ137,DC137,DF137,DI137,DL137) -> 0 | L137: =SUM(O137,R137,U137,X137,AA137,AD137,AG137,AJ137,AM137,AP137,AS137,AV137,AY137,BB137,BE137,BH137,BK137,BN137,BQ137,BT137,BW137,BZ137,CC137,CF137,CI137,CL137,CO137,CR137,CU137,CX137,DA137,DD137,DG137,DJ137,DM137) -> 0 | M137: =SUM(P137,S137,V137,Y137,AB137,AE137,AH137,AK137,AN137,AQ137,AT137,AW137,AZ137,BC137,BF137,BI137,BL137,BO137,BR137,BU137,BX137,CA137,CD137,CG137,CJ137,CM137,CP137,CS137,CV137,CY137,DB137,DE137,DH137,DK137,DN137) -> 0
A138: =A137+1 -> 134 | F138: 1111411 | G138: เค้กวันเกิดส้ม 1/2 ปอนด์ | K138: =SUM(N138,Q138,T138,W138,Z138,AC138,AF138,AI138,AL138,AO138,AR138,AU138,AX138,BA138,BD138,BG138,BJ138,BM138,BP138,BS138,BV138,BY138,CB138,CE138,CH138,CK138,CN138,CQ138,CT138,CW138,CZ138,DC138,DF138,DI138,DL138) -> 0 | L138: =SUM(O138,R138,U138,X138,AA138,AD138,AG138,AJ138,AM138,AP138,AS138,AV138,AY138,BB138,BE138,BH138,BK138,BN138,BQ138,BT138,BW138,BZ138,CC138,CF138,CI138,CL138,CO138,CR138,CU138,CX138,DA138,DD138,DG138,DJ138,DM138) -> 0 | M138: =SUM(P138,S138,V138,Y138,AB138,AE138,AH138,AK138,AN138,AQ138,AT138,AW138,AZ138,BC138,BF138,BI138,BL138,BO138,BR138,BU138,BX138,CA138,CD138,CG138,CJ138,CM138,CP138,CS138,CV138,CY138,DB138,DE138,DH138,DK138,DN138) -> 0
...

Sheet Week 1
A1: ลำดับ | B1: ทีมโทร | C1: บูธ | D1: online | E1: Modern Trade | F1: รหัส | G1: ชื่อสินค้า | H1: ลูกค้า | I1: ขนาดบรรจุ | N1: week 1 (วันที่ 1-7 มี.ค. 2569)
I2: จำนวน(ชิ้น) | J2: หน่วย(กล่อง) | K2: วัน | N2: วันอาทิตย์ | R2: ยอดจริง | X2: วันจันทร์ | AB2: ยอดจริง | AH2: วันอังคาร | AL2: ยอดจริง | AR2: วันพุธ | AV2: ยอดจริง | BB2: วันพฤหัสบดี | BF2: ยอดจริง | BL2: วันศุกร์ | BP2: ยอดจริง | BV2: เสาร์ | BZ2: ยอดจริง
K3: วันที่ | N3: 4 | X3: 5 | AH3: 6 | AR3: 7 | BB3: 8 | BL3: 9 | BV3: 10
K4: ติดป้าย Amezon | L4: ไม่ติดป้าย Amezon | M4: Non Logo | N4: ติดป้าย Amezon | O4: ไม่ติดป้าย Amezon | P4: Non Logo | Q4: รวม | R4: ติดป้าย Amezon | S4: ไม่ติดป้าย Amezon | T4: Non Logo | U4: ติดป้าย Amezon | V4: ไม่ติดป้าย Amezon | W4: Non Logo | X4: ติดป้าย Amezon | Y4: ไม่ติดป้าย Amezon | Z4: Non Logo | AA4: รวม | AB4: ติดป้าย Amezon | AC4: ไม่ติดป้าย Amezon | AD4: Non Logo | AE4: ติดป้าย Amezon | AF4: ไม่ติดป้าย Amezon | AG4: Non Logo | AH4: ติดป้าย Amezon | AI4: ไม่ติดป้าย Amezon | AJ4: Non Logo | AK4: รวม | AL4: ติดป้าย Amezon | AM4: ไม่ติดป้าย Amezon | AN4: Non Logo | AO4: ติดป้าย Amezon | AP4: ไม่ติดป้าย Amezon | AQ4: Non Logo | AR4: ติดป้าย Amezon | AS4: ไม่ติดป้าย Amezon | AT4: Non Logo | AU4: รวม | AV4: ติดป้าย Amezon | AW4: ไม่ติดป้าย Amezon | AX4: Non Logo | AY4: ติดป้าย Amezon | AZ4: ไม่ติดป้าย Amezon | BA4: Non Logo | BB4: ติดป้าย Amezon | BC4: ไม่ติดป้าย Amezon | BD4: Non Logo | BE4: รวม | BF4: ติดป้าย Amezon | BG4: ไม่ติดป้าย Amezon | BH4: Non Logo | BI4: ติดป้าย Amezon | BJ4: ไม่ติดป้าย Amezon | BK4: Non Logo | BL4: ติดป้าย Amezon | BM4: ไม่ติดป้าย Amezon | BN4: Non Logo | BO4: รวม | BP4: ติดป้าย Amezon | BQ4: ไม่ติดป้าย Amezon | BR4: Non Logo | BS4: ติดป้าย Amezon | BT4: ไม่ติดป้าย Amezon | BU4: Non Logo | BV4: ติดป้าย Amezon | BW4: ไม่ติดป้าย Amezon | BX4: Non Logo | BY4: รวม | BZ4: ติดป้าย Amezon | CA4: ไม่ติดป้าย Amezon | CB4: Non Logo | CC4: ติดป้าย Amezon | CD4: ไม่ติดป้าย Amezon | CE4: Non Logo
A5: 1 | F5: 1113036 | G5: ช็อกบอล | H5: Aeon | K5: =SUM(N5,X5,AH5,AR5,BB5,BL5,BV5) -> 0 | L5: =SUM(O5,Y5,AI5,AS5,BC5,BM5,BW5) -> 0 | O5: 0 | Q5: =SUM(N5:P5) -> 0 | R5: =SUMIF('ยอดจริง Week 1'!A:A,'Week 1'!F5,'ยอดจริง Week 1'!C:C) -> 0 | S5: =SUMIF('ยอดจริง Week 1'!A:A,'Week 1'!F5,'ยอดจริง Week 1'!D:D) -> 0 | T5: =SUMIF('ยอดจริง Week 1'!A:A,'Week 1'!F5,'ยอดจริง Week 1'!E:E) -> 0 | U5: =N5-R5 -> 0 | V5: =O5-S5 -> 0 | W5: =P5-T5 -> 0 | Y5: 0 | AA5: =SUM(X5:Z5) -> 0 | AB5: =SUMIF('ยอดจริง Week 1'!H:H,'Week 1'!F5,'ยอดจริง Week 1'!J:J) -> 0 | AC5: =SUMIF('ยอดจริง Week 1'!H:H,'Week 1'!F5,'ยอดจริง Week 1'!K:K) -> 0 | AD5: =SUMIF('ยอดจริง Week 1'!H:H,'Week 1'!F5,'ยอดจริง Week 1'!L:L) -> 0 | AE5: =X5-AB5 -> 0 | AF5: =Y5-AC5 -> 0 | AG5: =Z5-AD5 -> 0 | AI5: 0 | AK5: =SUM(AH5:AJ5) -> 0 | AL5: =SUMIF('ยอดจริง Week 1'!O:O,'Week 1'!F5,'ยอดจริง Week 1'!Q:Q) -> 0 | AM5: =SUMIF('ยอดจริง Week 1'!O:O,'Week 1'!F5,'ยอดจริง Week 1'!R:R) -> 0 | AN5: =SUMIF('ยอดจริง Week 1'!O:O,'Week 1'!F5,'ยอดจริง Week 1'!S:S) -> 0 | AO5: =AH5-AL5 -> 0 | AP5: =AI5-AM5 -> 0 | AQ5: =AJ5-AN5 -> 0 | AS5: 0 | AU5: =SUM(AR5:AT5) -> 0 | AV5: =SUMIF('ยอดจริง Week 1'!V:V,'Week 1'!F5,'ยอดจริง Week 1'!X:X) -> 0 | AW5: =SUMIF('ยอดจริง Week 1'!V:V,'Week 1'!F5,'ยอดจริง Week 1'!Y:Y) -> 0 | AX5: =SUMIF('ยอดจริง Week 1'!V:V,'Week 1'!F5,'ยอดจริง Week 1'!Z:Z) -> 0 | AY5: =AR5-AV5 -> 0 | AZ5: =AS5-AW5 -> 0 | BA5: =AT5-AX5 -> 0 | BC5: 0 | BE5: =SUM(BB5:BD5) -> 0 | BF5: =SUMIF('ยอดจริง Week 1'!AC:AC,'Week 1'!F5,'ยอดจริง Week 1'!AE:AE) -> 0 | BG5: =SUMIF('ยอดจริง Week 1'!AC:AC,'Week 1'!F5,'ยอดจริง Week 1'!AF:AF) -> 0 | BH5: =SUMIF('ยอดจริง Week 1'!AC:AC,'Week 1'!F5,'ยอดจริง Week 1'!AG:AG) -> 0 | BI5: =BB5-BF5 -> 0 | BJ5: =BC5-BG5 -> 0 | BK5: =BD5-BH5 -> 0 | BM5: 0 | BO5: =SUM(BL5:BN5) -> 0 | BP5: =SUMIF('ยอดจริง Week 1'!AJ:AJ,'Week 1'!F5,'ยอดจริง Week 1'!AL:AL) -> 0 | BQ5: =SUMIF('ยอดจริง Week 1'!AJ:AJ,'Week 1'!F5,'ยอดจริง Week 1'!AM:AM) -> 0 | BR5: =SUMIF('ยอดจริง Week 1'!AJ:AJ,'Week 1'!F5,'ยอดจริง Week 1'!AN:AN) -> 0 | BS5: =BL5-BP5 -> 0 | BT5: =BM5-BQ5 -> 0 | BU5: =BN5-BR5 -> 0 | BW5: 0 | BY5: =SUM(BV5:BX5) -> 0 | BZ5: =SUMIF('ยอดจริง Week 1'!AQ:AQ,'Week 1'!F5,'ยอดจริง Week 1'!AS:AS) -> 0 | CA5: =SUMIF('ยอดจริง Week 1'!AQ:AQ,'Week 1'!F5,'ยอดจริง Week 1'!AT:AT) -> 0 | CB5: =SUMIF('ยอดจริง Week 1'!AQ:AQ,'Week 1'!F5,'ยอดจริง Week 1'!AU:AU) -> 0 | CC5: =BV5-BZ5 -> 0 | CD5: =BW5-CA5 -> 0 | CE5: =BX5-CB5 -> 0
A6: =A5+1 -> 2 | F6: 1111001 | G6: ชิฟฟ่อนเค้ก (1 ชิ้น) | H6: Aeon | K6: =SUM(N6,X6,AH6,AR6,BB6,BL6,BV6) -> 0 | L6: =SUM(O6,Y6,AI6,AS6,BC6,BM6,BW6) -> 0 | O6: 0 | Q6: =SUM(N6:P6) -> 0 | R6: =SUMIF('ยอดจริง Week 1'!A:A,'Week 1'!F6,'ยอดจริง Week 1'!C:C) -> 0 | S6: =SUMIF('ยอดจริง Week 1'!A:A,'Week 1'!F6,'ยอดจริง Week 1'!D:D) -> 0 | T6: =SUMIF('ยอดจริง Week 1'!A:A,'Week 1'!F6,'ยอดจริง Week 1'!E:E) -> 0 | U6: =N6-R6 -> 0 | V6: =O6-S6 -> 0 | W6: =P6-T6 -> 0 | Y6: 0 | AA6: =SUM(X6:Z6) -> 0 | AB6: =SUMIF('ยอดจริง Week 1'!H:H,'Week 1'!F6,'ยอดจริง Week 1'!J:J) -> 0 | AC6: =SUMIF('ยอดจริง Week 1'!H:H,'Week 1'!F6,'ยอดจริง Week 1'!K:K) -> 0 | AD6: =SUMIF('ยอดจริง Week 1'!H:H,'Week 1'!F6,'ยอดจริง Week 1'!L:L) -> 0 | AE6: =X6-AB6 -> 0 | AF6: =Y6-AC6 -> 0 | AG6: =Z6-AD6 -> 0 | AI6: 0 | AK6: =SUM(AH6:AJ6) -> 0 | AL6: =SUMIF('ยอดจริง Week 1'!O:O,'Week 1'!F6,'ยอดจริง Week 1'!Q:Q) -> 0 | AM6: =SUMIF('ยอดจริง Week 1'!O:O,'Week 1'!F6,'ยอดจริง Week 1'!R:R) -> 0 | AN6: =SUMIF('ยอดจริง Week 1'!O:O,'Week 1'!F6,'ยอดจริง Week 1'!S:S) -> 0 | AO6: =AH6-AL6 -> 0 | AP6: =AI6-AM6 -> 0 | AQ6: =AJ6-AN6 -> 0 | AS6: 0 | AU6: =SUM(AR6:AT6) -> 0 | AV6: =SUMIF('ยอดจริง Week 1'!V:V,'Week 1'!F6,'ยอดจริง Week 1'!X:X) -> 0 | AW6: =SUMIF('ยอดจริง Week 1'!V:V,'Week 1'!F6,'ยอดจริง Week 1'!Y:Y) -> 0 | AX6: =SUMIF('ยอดจริง Week 1'!V:V,'Week 1'!F6,'ยอดจริง Week 1'!Z:Z) -> 0 | AY6: =AR6-AV6 -> 0 | AZ6: =AS6-AW6 -> 0 | BA6: =AT6-AX6 -> 0 | BC6: 0 | BE6: =SUM(BB6:BD6) -> 0 | BF6: =SUMIF('ยอดจริง Week 1'!AC:AC,'Week 1'!F6,'ยอดจริง Week 1'!AE:AE) -> 0 | BG6: =SUMIF('ยอดจริง Week 1'!AC:AC,'Week 1'!F6,'ยอดจริง Week 1'!AF:AF) -> 0 | BH6: =SUMIF('ยอดจริง Week 1'!AC:AC,'Week 1'!F6,'ยอดจริง Week 1'!AG:AG) -> 0 | BI6: =BB6-BF6 -> 0 | BJ6: =BC6-BG6 -> 0 | BK6: =BD6-BH6 -> 0 | BM6: 0 | BO6: =SUM(BL6:BN6) -> 0 | BP6: =SUMIF('ยอดจริง Week 1'!AJ:AJ,'Week 1'!F6,'ยอดจริง Week 1'!AL:AL) -> 0 | BQ6: =SUMIF('ยอดจริง Week 1'!AJ:AJ,'Week 1'!F6,'ยอดจริง Week 1'!AM:AM) -> 0 | BR6: =SUMIF('ยอดจริง Week 1'!AJ:AJ,'Week 1'!F6,'ยอดจริง Week 1'!AN:AN) -> 0 | BS6: =BL6-BP6 -> 0 | BT6: =BM6-BQ6 -> 0 | BU6: =BN6-BR6 -> 0 | BW6: 0 | BY6: =SUM(BV6:BX6) -> 0 | BZ6: =SUMIF('ยอดจริง Week 1'!AQ:AQ,'Week 1'!F6,'ยอดจริง Week 1'!AS:AS) -> 0 | CA6: =SUMIF('ยอดจริง Week 1'!AQ:AQ,'Week 1'!F6,'ยอดจริง Week 1'!AT:AT) -> 0 | CB6: =SUMIF('ยอดจริง Week 1'!AQ:AQ,'Week 1'!F6,'ยอดจริง Week 1'!AU:AU) -> 0 | CC6: =BV6-BZ6 -> 0 | CD6: =BW6-CA6 -> 0 | CE6: =BX6-CB6 -> 0
A7: =A6+1 -> 3 | F7: 1004055 | G7: ชิฟฟ่อนเค้ก วรรณวนัช (รวมรส 4 ชิ้น) | K7: =SUM(N7,X7,AH7,AR7,BB7,BL7,BV7) -> 0 | L7: =SUM(O7,Y7,AI7,AS7,BC7,BM7,BW7) -> 40 | O7: 20 | Q7: =SUM(N7:P7) -> 20 | R7: =SUMIF('ยอดจริง Week 1'!A:A,'Week 1'!F7,'ยอดจริง Week 1'!C:C) -> 0 | S7: =SUMIF('ยอดจริง Week 1'!A:A,'Week 1'!F7,'ยอดจริง Week 1'!D:D) -> 0 | T7: =SUMIF('ยอดจริง Week 1'!A:A,'Week 1'!F7,'ยอดจริง Week 1'!E:E) -> 0 | U7: =N7-R7 -> 0 | V7: =O7-S7 -> 20 | W7: =P7-T7 -> 0 | Y7: 0 | AA7: =SUM(X7:Z7) -> 0 | AB7: =SUMIF('ยอดจริง Week 1'!H:H,'Week 1'!F7,'ยอดจริง Week 1'!J:J) -> 0 | AC7: =SUMIF('ยอดจริง Week 1'!H:H,'Week 1'!F7,'ยอดจริง Week 1'!K:K) -> 0 | AD7: =SUMIF('ยอดจริง Week 1'!H:H,'Week 1'!F7,'ยอดจริง Week 1'!L:L) -> 0 | AE7: =X7-AB7 -> 0 | AF7: =Y7-AC7 -> 0 | AG7: =Z7-AD7 -> 0 | AI7: 0 | AK7: =SUM(AH7:AJ7) -> 0 | AL7: =SUMIF('ยอดจริง Week 1'!O:O,'Week 1'!F7,'ยอดจริง Week 1'!Q:Q) -> 0 | AM7: =SUMIF('ยอดจริง Week 1'!O:O,'Week 1'!F7,'ยอดจริง Week 1'!R:R) -> 0 | AN7: =SUMIF('ยอดจริง Week 1'!O:O,'Week 1'!F7,'ยอดจริง Week 1'!S:S) -> 0 | AO7: =AH7-AL7 -> 0 | AP7: =AI7-AM7 -> 0 | AQ7: =AJ7-AN7 -> 0 | AS7: 0 | AU7: =SUM(AR7:AT7) -> 0 | AV7: =SUMIF('ยอดจริง Week 1'!V:V,'Week 1'!F7,'ยอดจริง Week 1'!X:X) -> 0 | AW7: =SUMIF('ยอดจริง Week 1'!V:V,'Week 1'!F7,'ยอดจริง Week 1'!Y:Y) -> 0 | AX7: =SUMIF('ยอดจริง Week 1'!V:V,'Week 1'!F7,'ยอดจริง Week 1'!Z:Z) -> 0 | AY7: =AR7-AV7 -> 0 | AZ7: =AS7-AW7 -> 0 | BA7: =AT7-AX7 -> 0 | BC7: 20 | BE7: =SUM(BB7:BD7) -> 20 | BF7: =SUMIF('ยอดจริง Week 1'!AC:AC,'Week 1'!F7,'ยอดจริง Week 1'!AE:AE) -> 0 | BG7: =SUMIF('ยอดจริง Week 1'!AC:AC,'Week 1'!F7,'ยอดจริง Week 1'!AF:AF) -> 0 | BH7: =SUMIF('ยอดจริง Week 1'!AC:AC,'Week 1'!F7,'ยอดจริง Week 1'!AG:AG) -> 0 | BI7: =BB7-BF7 -> 0 | BJ7: =BC7-BG7 -> 20 | BK7: =BD7-BH7 -> 0 | BM7: 0 | BO7: =SUM(BL7:BN7) -> 0 | BP7: =SUMIF('ยอดจริง Week 1'!AJ:AJ,'Week 1'!F7,'ยอดจริง Week 1'!AL:AL) -> 0 | BQ7: =SUMIF('ยอดจริง Week 1'!AJ:AJ,'Week 1'!F7,'ยอดจริง Week 1'!AM:AM) -> 0 | BR7: =SUMIF('ยอดจริง Week 1'!AJ:AJ,'Week 1'!F7,'ยอดจริง Week 1'!AN:AN) -> 0 | BS7: =BL7-BP7 -> 0 | BT7: =BM7-BQ7 -> 0 | BU7: =BN7-BR7 -> 0 | BW7: 0 | BY7: =SUM(BV7:BX7) -> 0 | BZ7: =SUMIF('ยอดจริง Week 1'!AQ:AQ,'Week 1'!F7,'ยอดจริง Week 1'!AS:AS) -> 0 | CA7: =SUMIF('ยอดจริง Week 1'!AQ:AQ,'Week 1'!F7,'ยอดจริง Week 1'!AT:AT) -> 0 | CB7: =SUMIF('ยอดจริง Week 1'!AQ:AQ,'Week 1'!F7,'ยอดจริง Week 1'!AU:AU) -> 0 | CC7: =BV7-BZ7 -> 0 | CD7: =BW7-CA7 -> 0 | CE7: =BX7-CB7 -> 0
A8: =A7+1 -> 4 | F8: 1111002 | G8: ชิฟฟ่อนเค้ก วรรณวนัช (รวมรส 8 ชิ้น) | H8: Lotus | K8: =SUM(N8,X8,AH8,AR8,BB8,BL8,BV8) -> 0 | L8: =SUM(O8,Y8,AI8,AS8,BC8,BM8,BW8) -> 70 | O8: 30 | Q8: =SUM(N8:P8) -> 30 | R8: =SUMIF('ยอดจริง Week 1'!A:A,'Week 1'!F8,'ยอดจริง Week 1'!C:C) -> 0 | S8: =SUMIF('ยอดจริง Week 1'!A:A,'Week 1'!F8,'ยอดจริง Week 1'!D:D) -> 0 | T8: =SUMIF('ยอดจริง Week 1'!A:A,'Week 1'!F8,'ยอดจริง Week 1'!E:E) -> 0 | U8: =N8-R8 -> 0 | V8: =O8-S8 -> 30 | W8: =P8-T8 -> 0 | Y8: 0 | AA8: =SUM(X8:Z8) -> 0 | AB8: =SUMIF('ยอดจริง Week 1'!H:H,'Week 1'!F8,'ยอดจริง Week 1'!J:J) -> 0 | AC8: =SUMIF('ยอดจริง Week 1'!H:H,'Week 1'!F8,'ยอดจริง Week 1'!K:K) -> 0 | AD8: =SUMIF('ยอดจริง Week 1'!H:H,'Week 1'!F8,'ยอดจริง Week 1'!L:L) -> 0 | AE8: =X8-AB8 -> 0 | AF8: =Y8-AC8 -> 0 | AG8: =Z8-AD8 -> 0 | AI8: 0 | AK8: =SUM(AH8:AJ8) -> 0 | AL8: =SUMIF('ยอดจริง Week 1'!O:O,'Week 1'!F8,'ยอดจริง Week 1'!Q:Q) -> 0 | AM8: =SUMIF('ยอดจริง Week 1'!O:O,'Week 1'!F8,'ยอดจริง Week 1'!R:R) -> 0 | AN8: =SUMIF('ยอดจริง Week 1'!O:O,'Week 1'!F8,'ยอดจริง Week 1'!S:S) -> 0 | AO8: =AH8-AL8 -> 0 | AP8: =AI8-AM8 -> 0 | AQ8: =AJ8-AN8 -> 0 | AS8: 0 | AU8: =SUM(AR8:AT8) -> 0 | AV8: =SUMIF('ยอดจริง Week 1'!V:V,'Week 1'!F8,'ยอดจริง Week 1'!X:X) -> 0 | AW8: =SUMIF('ยอดจริง Week 1'!V:V,'Week 1'!F8,'ยอดจริง Week 1'!Y:Y) -> 0 | AX8: =SUMIF('ยอดจริง Week 1'!V:V,'Week 1'!F8,'ยอดจริง Week 1'!Z:Z) -> 0 | AY8: =AR8-AV8 -> 0 | AZ8: =AS8-AW8 -> 0 | BA8: =AT8-AX8 -> 0 | BC8: 40 | BE8: =SUM(BB8:BD8) -> 40 | BF8: =SUMIF('ยอดจริง Week 1'!AC:AC,'Week 1'!F8,'ยอดจริง Week 1'!AE:AE) -> 0 | BG8: =SUMIF('ยอดจริง Week 1'!AC:AC,'Week 1'!F8,'ยอดจริง Week 1'!AF:AF) -> 0 | BH8: =SUMIF('ยอดจริง Week 1'!AC:AC,'Week 1'!F8,'ยอดจริง Week 1'!AG:AG) -> 0 | BI8: =BB8-BF8 -> 0 | BJ8: =BC8-BG8 -> 40 | BK8: =BD8-BH8 -> 0 | BM8: 0 | BO8: =SUM(BL8:BN8) -> 0 | BP8: =SUMIF('ยอดจริง Week 1'!AJ:AJ,'Week 1'!F8,'ยอดจริง Week 1'!AL:AL) -> 0 | BQ8: =SUMIF('ยอดจริง Week 1'!AJ:AJ,'Week 1'!F8,'ยอดจริง Week 1'!AM:AM) -> 0 | BR8: =SUMIF('ยอดจริง Week 1'!AJ:AJ,'Week 1'!F8,'ยอดจริง Week 1'!AN:AN) -> 0 | BS8: =BL8-BP8 -> 0 | BT8: =BM8-BQ8 -> 0 | BU8: =BN8-BR8 -> 0 | BW8: 0 | BY8: =SUM(BV8:BX8) -> 0 | BZ8: =SUMIF('ยอดจริง Week 1'!AQ:AQ,'Week 1'!F8,'ยอดจริง Week 1'!AS:AS) -> 0 | CA8: =SUMIF('ยอดจริง Week 1'!AQ:AQ,'Week 1'!F8,'ยอดจริง Week 1'!AT:AT) -> 0 | CB8: =SUMIF('ยอดจริง Week 1'!AQ:AQ,'Week 1'!F8,'ยอดจริง Week 1'!AU:AU) -> 0 | CC8: =BV8-BZ8 -> 0 | CD8: =BW8-CA8 -> 0 | CE8: =BX8-CB8 -> 0
A9: =A8+1 -> 5 | F9: 1111055 | G9: วรรณวนัช ชิฟฟ่อนรวมรส 8 ชิ้น | H9: Makro | K9: =SUM(N9,X9,AH9,AR9,BB9,BL9,BV9) -> 0 | L9: =SUM(O9,Y9,AI9,AS9,BC9,BM9,BW9) -> 0 | O9: 0 | Q9: =SUM(N9:P9) -> 0 | R9: =SUMIF('ยอดจริง Week 1'!A:A,'Week 1'!F9,'ยอดจริง Week 1'!C:C) -> 0 | S9: =SUMIF('ยอดจริง Week 1'!A:A,'Week 1'!F9,'ยอดจริง Week 1'!D:D) -> 0 | T9: =SUMIF('ยอดจริง Week 1'!A:A,'Week 1'!F9,'ยอดจริง Week 1'!E:E) -> 0 | U9: =N9-R9 -> 0 | V9: =O9-S9 -> 0 | W9: =P9-T9 -> 0 | Y9: 0 | AA9: =SUM(X9:Z9) -> 0 | AB9: =SUMIF('ยอดจริง Week 1'!H:H,'Week 1'!F9,'ยอดจริง Week 1'!J:J) -> 0 | AC9: =SUMIF('ยอดจริง Week 1'!H:H,'Week 1'!F9,'ยอดจริง Week 1'!K:K) -> 0 | AD9: =SUMIF('ยอดจริง Week 1'!H:H,'Week 1'!F9,'ยอดจริง Week 1'!L:L) -> 0 | AE9: =X9-AB9 -> 0 | AF9: =Y9-AC9 -> 0 | AG9: =Z9-AD9 -> 0 | AI9: 0 | AK9: =SUM(AH9:AJ9) -> 0 | AL9: =SUMIF('ยอดจริง Week 1'!O:O,'Week 1'!F9,'ยอดจริง Week 1'!Q:Q) -> 0 | AM9: =SUMIF('ยอดจริง Week 1'!O:O,'Week 1'!F9,'ยอดจริง Week 1'!R:R) -> 0 | AN9: =SUMIF('ยอดจริง Week 1'!O:O,'Week 1'!F9,'ยอดจริง Week 1'!S:S) -> 0 | AO9: =AH9-AL9 -> 0 | AP9: =AI9-AM9 -> 0 | AQ9: =AJ9-AN9 -> 0 | AS9: 0 | AU9: =SUM(AR9:AT9) -> 0 | AV9: =SUMIF('ยอดจริง Week 1'!V:V,'Week 1'!F9,'ยอดจริง Week 1'!X:X) -> 0 | AW9: =SUMIF('ยอดจริง Week 1'!V:V,'Week 1'!F9,'ยอดจริง Week 1'!Y:Y) -> 0 | AX9: =SUMIF('ยอดจริง Week 1'!V:V,'Week 1'!F9,'ยอดจริง Week 1'!Z:Z) -> 0 | AY9: =AR9-AV9 -> 0 | AZ9: =AS9-AW9 -> 0 | BA9: =AT9-AX9 -> 0 | BC9: 0 | BE9: =SUM(BB9:BD9) -> 0 | BF9: =SUMIF('ยอดจริง Week 1'!AC:AC,'Week 1'!F9,'ยอดจริง Week 1'!AE:AE) -> 0 | BG9: =SUMIF('ยอดจริง Week 1'!AC:AC,'Week 1'!F9,'ยอดจริง Week 1'!AF:AF) -> 0 | BH9: =SUMIF('ยอดจริง Week 1'!AC:AC,'Week 1'!F9,'ยอดจริง Week 1'!AG:AG) -> 0 | BI9: =BB9-BF9 -> 0 | BJ9: =BC9-BG9 -> 0 | BK9: =BD9-BH9 -> 0 | BM9: 0 | BO9: =SUM(BL9:BN9) -> 0 | BP9: =SUMIF('ยอดจริง Week 1'!AJ:AJ,'Week 1'!F9,'ยอดจริง Week 1'!AL:AL) -> 0 | BQ9: =SUMIF('ยอดจริง Week 1'!AJ:AJ,'Week 1'!F9,'ยอดจริง Week 1'!AM:AM) -> 0 | BR9: =SUMIF('ยอดจริง Week 1'!AJ:AJ,'Week 1'!F9,'ยอดจริง Week 1'!AN:AN) -> 0 | BS9: =BL9-BP9 -> 0 | BT9: =BM9-BQ9 -> 0 | BU9: =BN9-BR9 -> 0 | BW9: 0 | BY9: =SUM(BV9:BX9) -> 0 | BZ9: =SUMIF('ยอดจริง Week 1'!AQ:AQ,'Week 1'!F9,'ยอดจริง Week 1'!AS:AS) -> 0 | CA9: =SUMIF('ยอดจริง Week 1'!AQ:AQ,'Week 1'!F9,'ยอดจริง Week 1'!AT:AT) -> 0 | CB9: =SUMIF('ยอดจริง Week 1'!AQ:AQ,'Week 1'!F9,'ยอดจริง Week 1'!AU:AU) -> 0 | CC9: =BV9-BZ9 -> 0 | CD9: =BW9-CA9 -> 0 | CE9: =BX9-CB9 -> 0
A10: =A9+1 -> 6 | F10: 1111030 | G10: ชิฟฟ่อนเค้ก รสกาแฟ (8 ชิ้น) | K10: =SUM(N10,X10,AH10,AR10,BB10,BL10,BV10) -> 0 | L10: =SUM(O10,Y10,AI10,AS10,BC10,BM10,BW10) -> 0 | O10: 0 | Q10: =SUM(N10:P10) -> 0 | R10: =SUMIF('ยอดจริง Week 1'!A:A,'Week 1'!F10,'ยอดจริง Week 1'!C:C) -> 0 | S10: =SUMIF('ยอดจริง Week 1'!A:A,'Week 1'!F10,'ยอดจริง Week 1'!D:D) -> 0 | T10: =SUMIF('ยอดจริง Week 1'!A:A,'Week 1'!F10,'ยอดจริง Week 1'!E:E) -> 0 | U10: =N10-R10 -> 0 | V10: =O10-S10 -> 0 | W10: =P10-T10 -> 0 | Y10: 0 | AA10: =SUM(X10:Z10) -> 0 | AB10: =SUMIF('ยอดจริง Week 1'!H:H,'Week 1'!F10,'ยอดจริง Week 1'!J:J) -> 0 | AC10: =SUMIF('ยอดจริง Week 1'!H:H,'Week 1'!F10,'ยอดจริง Week 1'!K:K) -> 0 | AD10: =SUMIF('ยอดจริง Week 1'!H:H,'Week 1'!F10,'ยอดจริง Week 1'!L:L) -> 0 | AE10: =X10-AB10 -> 0 | AF10: =Y10-AC10 -> 0 | AG10: =Z10-AD10 -> 0 | AI10: 0 | AK10: =SUM(AH10:AJ10) -> 0 | AL10: =SUMIF('ยอดจริง Week 1'!O:O,'Week 1'!F10,'ยอดจริง Week 1'!Q:Q) -> 0 | AM10: =SUMIF('ยอดจริง Week 1'!O:O,'Week 1'!F10,'ยอดจริง Week 1'!R:R) -> 0 | AN10: =SUMIF('ยอดจริง Week 1'!O:O,'Week 1'!F10,'ยอดจริง Week 1'!S:S) -> 0 | AO10: =AH10-AL10 -> 0 | AP10: =AI10-AM10 -> 0 | AQ10: =AJ10-AN10 -> 0 | AS10: 0 | AU10: =SUM(AR10:AT10) -> 0 | AV10: =SUMIF('ยอดจริง Week 1'!V:V,'Week 1'!F10,'ยอดจริง Week 1'!X:X) -> 0 | AW10: =SUMIF('ยอดจริง Week 1'!V:V,'Week 1'!F10,'ยอดจริง Week 1'!Y:Y) -> 0 | AX10: =SUMIF('ยอดจริง Week 1'!V:V,'Week 1'!F10,'ยอดจริง Week 1'!Z:Z) -> 0 | AY10: =AR10-AV10 -> 0 | AZ10: =AS10-AW10 -> 0 | BA10: =AT10-AX10 -> 0 | BC10: 0 | BE10: =SUM(BB10:BD10) -> 0 | BF10: =SUMIF('ยอดจริง Week 1'!AC:AC,'Week 1'!F10,'ยอดจริง Week 1'!AE:AE) -> 0 | BG10: =SUMIF('ยอดจริง Week 1'!AC:AC,'Week 1'!F10,'ยอดจริง Week 1'!AF:AF) -> 0 | BH10: =SUMIF('ยอดจริง Week 1'!AC:AC,'Week 1'!F10,'ยอดจริง Week 1'!AG:AG) -> 0 | BI10: =BB10-BF10 -> 0 | BJ10: =BC10-BG10 -> 0 | BK10: =BD10-BH10 -> 0 | BM10: 0 | BO10: =SUM(BL10:BN10) -> 0 | BP10: =SUMIF('ยอดจริง Week 1'!AJ:AJ,'Week 1'!F10,'ยอดจริง Week 1'!AL:AL) -> 0 | BQ10: =SUMIF('ยอดจริง Week 1'!AJ:AJ,'Week 1'!F10,'ยอดจริง Week 1'!AM:AM) -> 0 | BR10: =SUMIF('ยอดจริง Week 1'!AJ:AJ,'Week 1'!F10,'ยอดจริง Week 1'!AN:AN) -> 0 | BS10: =BL10-BP10 -> 0 | BT10: =BM10-BQ10 -> 0 | BU10: =BN10-BR10 -> 0 | BW10: 0 | BY10: =SUM(BV10:BX10) -> 0 | BZ10: =SUMIF('ยอดจริง Week 1'!AQ:AQ,'Week 1'!F10,'ยอดจริง Week 1'!AS:AS) -> 0 | CA10: =SUMIF('ยอดจริง Week 1'!AQ:AQ,'Week 1'!F10,'ยอดจริง Week 1'!AT:AT) -> 0 | CB10: =SUMIF('ยอดจริง Week 1'!AQ:AQ,'Week 1'!F10,'ยอดจริง Week 1'!AU:AU) -> 0 | CC10: =BV10-BZ10 -> 0 | CD10: =BW10-CA10 -> 0 | CE10: =BX10-CB10 -> 0
A11: =A10+1 -> 7 | F11: 1111036 | G11: ชิฟฟอนเค้ก วรรณวนัช ห่อกระดาษ (รวมรส 4 ชิ้น) | K11: =SUM(N11,X11,AH11,AR11,BB11,BL11,BV11) -> 0 | L11: =SUM(O11,Y11,AI11,AS11,BC11,BM11,BW11) -> 0 | O11: 0 | Q11: =SUM(N11:P11) -> 0 | R11: =SUMIF('ยอดจริง Week 1'!A:A,'Week 1'!F11,'ยอดจริง Week 1'!C:C) -> 0 | S11: =SUMIF('ยอดจริง Week 1'!A:A,'Week 1'!F11,'ยอดจริง Week 1'!D:D) -> 0 | T11: =SUMIF('ยอดจริง Week 1'!A:A,'Week 1'!F11,'ยอดจริง Week 1'!E:E) -> 0 | U11: =N11-R11 -> 0 | V11: =O11-S11 -> 0 | W11: =P11-T11 -> 0 | Y11: 0 | AA11: =SUM(X11:Z11) -> 0 | AB11: =SUMIF('ยอดจริง Week 1'!H:H,'Week 1'!F11,'ยอดจริง Week 1'!J:J) -> 0 | AC11: =SUMIF('ยอดจริง Week 1'!H:H,'Week 1'!F11,'ยอดจริง Week 1'!K:K) -> 0 | AD11: =SUMIF('ยอดจริง Week 1'!H:H,'Week 1'!F11,'ยอดจริง Week 1'!L:L) -> 0 | AE11: =X11-AB11 -> 0 | AF11: =Y11-AC11 -> 0 | AG11: =Z11-AD11 -> 0 | AI11: 0 | AK11: =SUM(AH11:AJ11) -> 0 | AL11: =SUMIF('ยอดจริง Week 1'!O:O,'Week 1'!F11,'ยอดจริง Week 1'!Q:Q) -> 0 | AM11: =SUMIF('ยอดจริง Week 1'!O:O,'Week 1'!F11,'ยอดจริง Week 1'!R:R) -> 0 | AN11: =SUMIF('ยอดจริง Week 1'!O:O,'Week 1'!F11,'ยอดจริง Week 1'!S:S) -> 0 | AO11: =AH11-AL11 -> 0 | AP11: =AI11-AM11 -> 0 | AQ11: =AJ11-AN11 -> 0 | AS11: 0 | AU11: =SUM(AR11:AT11) -> 0 | AV11: =SUMIF('ยอดจริง Week 1'!V:V,'Week 1'!F11,'ยอดจริง Week 1'!X:X) -> 0 | AW11: =SUMIF('ยอดจริง Week 1'!V:V,'Week 1'!F11,'ยอดจริง Week 1'!Y:Y) -> 0 | AX11: =SUMIF('ยอดจริง Week 1'!V:V,'Week 1'!F11,'ยอดจริง Week 1'!Z:Z) -> 0 | AY11: =AR11-AV11 -> 0 | AZ11: =AS11-AW11 -> 0 | BA11: =AT11-AX11 -> 0 | BC11: 0 | BE11: =SUM(BB11:BD11) -> 0 | BF11: =SUMIF('ยอดจริง Week 1'!AC:AC,'Week 1'!F11,'ยอดจริง Week 1'!AE:AE) -> 0 | BG11: =SUMIF('ยอดจริง Week 1'!AC:AC,'Week 1'!F11,'ยอดจริง Week 1'!AF:AF) -> 0 | BH11: =SUMIF('ยอดจริง Week 1'!AC:AC,'Week 1'!F11,'ยอดจริง Week 1'!AG:AG) -> 0 | BI11: =BB11-BF11 -> 0 | BJ11: =BC11-BG11 -> 0 | BK11: =BD11-BH11 -> 0 | BM11: 0 | BO11: =SUM(BL11:BN11) -> 0 | BP11: =SUMIF('ยอดจริง Week 1'!AJ:AJ,'Week 1'!F11,'ยอดจริง Week 1'!AL:AL) -> 0 | BQ11: =SUMIF('ยอดจริง Week 1'!AJ:AJ,'Week 1'!F11,'ยอดจริง Week 1'!AM:AM) -> 0 | BR11: =SUMIF('ยอดจริง Week 1'!AJ:AJ,'Week 1'!F11,'ยอดจริง Week 1'!AN:AN) -> 0 | BS11: =BL11-BP11 -> 0 | BT11: =BM11-BQ11 -> 0 | BU11: =BN11-BR11 -> 0 | BW11: 0 | BY11: =SUM(BV11:BX11) -> 0 | BZ11: =SUMIF('ยอดจริง Week 1'!AQ:AQ,'Week 1'!F11,'ยอดจริง Week 1'!AS:AS) -> 0 | CA11: =SUMIF('ยอดจริง Week 1'!AQ:AQ,'Week 1'!F11,'ยอดจริง Week 1'!AT:AT) -> 0 | CB11: =SUMIF('ยอดจริง Week 1'!AQ:AQ,'Week 1'!F11,'ยอดจริง Week 1'!AU:AU) -> 0 | CC11: =BV11-BZ11 -> 0 | CD11: =BW11-CA11 -> 0 | CE11: =BX11-CB11 -> 0
A12: =A11+1 -> 8 | F12: 1111037 | G12: ชิฟฟอนเค้ก วรรณวนัช ห่อกระดาษ (รวมรส 8 ชิ้น) | K12: =SUM(N12,X12,AH12,AR12,BB12,BL12,BV12) -> 0 | L12: =SUM(O12,Y12,AI12,AS12,BC12,BM12,BW12) -> 0 | O12: 0 | Q12: =SUM(N12:P12) -> 0 | R12: =SUMIF('ยอดจริง Week 1'!A:A,'Week 1'!F12,'ยอดจริง Week 1'!C:C) -> 0 | S12: =SUMIF('ยอดจริง Week 1'!A:A,'Week 1'!F12,'ยอดจริง Week 1'!D:D) -> 0 | T12: =SUMIF('ยอดจริง Week 1'!A:A,'Week 1'!F12,'ยอดจริง Week 1'!E:E) -> 0 | U12: =N12-R12 -> 0 | V12: =O12-S12 -> 0 | W12: =P12-T12 -> 0 | Y12: 0 | AA12: =SUM(X12:Z12) -> 0 | AB12: =SUMIF('ยอดจริง Week 1'!H:H,'Week 1'!F12,'ยอดจริง Week 1'!J:J) -> 0 | AC12: =SUMIF('ยอดจริง Week 1'!H:H,'Week 1'!F12,'ยอดจริง Week 1'!K:K) -> 0 | AD12: =SUMIF('ยอดจริง Week 1'!H:H,'Week 1'!F12,'ยอดจริง Week 1'!L:L) -> 0 | AE12: =X12-AB12 -> 0 | AF12: =Y12-AC12 -> 0 | AG12: =Z12-AD12 -> 0 | AI12: 0 | AK12: =SUM(AH12:AJ12) -> 0 | AL12: =SUMIF('ยอดจริง Week 1'!O:O,'Week 1'!F12,'ยอดจริง Week 1'!Q:Q) -> 0 | AM12: =SUMIF('ยอดจริง Week 1'!O:O,'Week 1'!F12,'ยอดจริง Week 1'!R:R) -> 0 | AN12: =SUMIF('ยอดจริง Week 1'!O:O,'Week 1'!F12,'ยอดจริง Week 1'!S:S) -> 0 | AO12: =AH12-AL12 -> 0 | AP12: =AI12-AM12 -> 0 | AQ12: =AJ12-AN12 -> 0 | AS12: 0 | AU12: =SUM(AR12:AT12) -> 0 | AV12: =SUMIF('ยอดจริง Week 1'!V:V,'Week 1'!F12,'ยอดจริง Week 1'!X:X) -> 0 | AW12: =SUMIF('ยอดจริง Week 1'!V:V,'Week 1'!F12,'ยอดจริง Week 1'!Y:Y) -> 0 | AX12: =SUMIF('ยอดจริง Week 1'!V:V,'Week 1'!F12,'ยอดจริง Week 1'!Z:Z) -> 0 | AY12: =AR12-AV12 -> 0 | AZ12: =AS12-AW12 -> 0 | BA12: =AT12-AX12 -> 0 | BC12: 0 | BE12: =SUM(BB12:BD12) -> 0 | BF12: =SUMIF('ยอดจริง Week 1'!AC:AC,'Week 1'!F12,'ยอดจริง Week 1'!AE:AE) -> 0 | BG12: =SUMIF('ยอดจริง Week 1'!AC:AC,'Week 1'!F12,'ยอดจริง Week 1'!AF:AF) -> 0 | BH12: =SUMIF('ยอดจริง Week 1'!AC:AC,'Week 1'!F12,'ยอดจริง Week 1'!AG:AG) -> 0 | BI12: =BB12-BF12 -> 0 | BJ12: =BC12-BG12 -> 0 | BK12: =BD12-BH12 -> 0 | BM12: 0 | BO12: =SUM(BL12:BN12) -> 0 | BP12: =SUMIF('ยอดจริง Week 1'!AJ:AJ,'Week 1'!F12,'ยอดจริง Week 1'!AL:AL) -> 0 | BQ12: =SUMIF('ยอดจริง Week 1'!AJ:AJ,'Week 1'!F12,'ยอดจริง Week 1'!AM:AM) -> 0 | BR12: =SUMIF('ยอดจริง Week 1'!AJ:AJ,'Week 1'!F12,'ยอดจริง Week 1'!AN:AN) -> 0 | BS12: =BL12-BP12 -> 0 | BT12: =BM12-BQ12 -> 0 | BU12: =BN12-BR12 -> 0 | BW12: 0 | BY12: =SUM(BV12:BX12) -> 0 | BZ12: =SUMIF('ยอดจริง Week 1'!AQ:AQ,'Week 1'!F12,'ยอดจริง Week 1'!AS:AS) -> 0 | CA12: =SUMIF('ยอดจริง Week 1'!AQ:AQ,'Week 1'!F12,'ยอดจริง Week 1'!AT:AT) -> 0 | CB12: =SUMIF('ยอดจริง Week 1'!AQ:AQ,'Week 1'!F12,'ยอดจริง Week 1'!AU:AU) -> 0 | CC12: =BV12-BZ12 -> 0 | CD12: =BW12-CA12 -> 0 | CE12: =BX12-CB12 -> 0
A13: =A12+1 -> 9 | F13: 1111040 | G13: ชิฟฟอนเค้กวรรณวนัช ห่อซีน (รวมรส 4 ชิ้น) | K13: =SUM(N13,X13,AH13,AR13,BB13,BL13,BV13) -> 0 | L13: =SUM(O13,Y13,AI13,AS13,BC13,BM13,BW13) -> 0 | O13: 0 | Q13: =SUM(N13:P13) -> 0 | R13: =SUMIF('ยอดจริง Week 1'!A:A,'Week 1'!F13,'ยอดจริง Week 1'!C:C) -> 0 | S13: =SUMIF('ยอดจริง Week 1'!A:A,'Week 1'!F13,'ยอดจริง Week 1'!D:D) -> 0 | T13: =SUMIF('ยอดจริง Week 1'!A:A,'Week 1'!F13,'ยอดจริง Week 1'!E:E) -> 0 | U13: =N13-R13 -> 0 | V13: =O13-S13 -> 0 | W13: =P13-T13 -> 0 | Y13: 0 | AA13: =SUM(X13:Z13) -> 0 | AB13: =SUMIF('ยอดจริง Week 1'!H:H,'Week 1'!F13,'ยอดจริง Week 1'!J:J) -> 0 | AC13: =SUMIF('ยอดจริง Week 1'!H:H,'Week 1'!F13,'ยอดจริง Week 1'!K:K) -> 0 | AD13: =SUMIF('ยอดจริง Week 1'!H:H,'Week 1'!F13,'ยอดจริง Week 1'!L:L) -> 0 | AE13: =X13-AB13 -> 0 | AF13: =Y13-AC13 -> 0 | AG13: =Z13-AD13 -> 0 | AI13: 0 | AK13: =SUM(AH13:AJ13) -> 0 | AL13: =SUMIF('ยอดจริง Week 1'!O:O,'Week 1'!F13,'ยอดจริง Week 1'!Q:Q) -> 0 | AM13: =SUMIF('ยอดจริง Week 1'!O:O,'Week 1'!F13,'ยอดจริง Week 1'!R:R) -> 0 | AN13: =SUMIF('ยอดจริง Week 1'!O:O,'Week 1'!F13,'ยอดจริง Week 1'!S:S) -> 0 | AO13: =AH13-AL13 -> 0 | AP13: =AI13-AM13 -> 0 | AQ13: =AJ13-AN13 -> 0 | AS13: 0 | AU13: =SUM(AR13:AT13) -> 0 | AV13: =SUMIF('ยอดจริง Week 1'!V:V,'Week 1'!F13,'ยอดจริง Week 1'!X:X) -> 0 | AW13: =SUMIF('ยอดจริง Week 1'!V:V,'Week 1'!F13,'ยอดจริง Week 1'!Y:Y) -> 0 | AX13: =SUMIF('ยอดจริง Week 1'!V:V,'Week 1'!F13,'ยอดจริง Week 1'!Z:Z) -> 0 | AY13: =AR13-AV13 -> 0 | AZ13: =AS13-AW13 -> 0 | BA13: =AT13-AX13 -> 0 | BC13: 0 | BE13: =SUM(BB13:BD13) -> 0 | BF13: =SUMIF('ยอดจริง Week 1'!AC:AC,'Week 1'!F13,'ยอดจริง Week 1'!AE:AE) -> 0 | BG13: =SUMIF('ยอดจริง Week 1'!AC:AC,'Week 1'!F13,'ยอดจริง Week 1'!AF:AF) -> 0 | BH13: =SUMIF('ยอดจริง Week 1'!AC:AC,'Week 1'!F13,'ยอดจริง Week 1'!AG:AG) -> 0 | BI13: =BB13-BF13 -> 0 | BJ13: =BC13-BG13 -> 0 | BK13: =BD13-BH13 -> 0 | BM13: 0 | BO13: =SUM(BL13:BN13) -> 0 | BP13: =SUMIF('ยอดจริง Week 1'!AJ:AJ,'Week 1'!F13,'ยอดจริง Week 1'!AL:AL) -> 0 | BQ13: =SUMIF('ยอดจริง Week 1'!AJ:AJ,'Week 1'!F13,'ยอดจริง Week 1'!AM:AM) -> 0 | BR13: =SUMIF('ยอดจริง Week 1'!AJ:AJ,'Week 1'!F13,'ยอดจริง Week 1'!AN:AN) -> 0 | BS13: =BL13-BP13 -> 0 | BT13: =BM13-BQ13 -> 0 | BU13: =BN13-BR13 -> 0 | BW13: 0 | BY13: =SUM(BV13:BX13) -> 0 | BZ13: =SUMIF('ยอดจริง Week 1'!AQ:AQ,'Week 1'!F13,'ยอดจริง Week 1'!AS:AS) -> 0 | CA13: =SUMIF('ยอดจริง Week 1'!AQ:AQ,'Week 1'!F13,'ยอดจริง Week 1'!AT:AT) -> 0 | CB13: =SUMIF('ยอดจริง Week 1'!AQ:AQ,'Week 1'!F13,'ยอดจริง Week 1'!AU:AU) -> 0 | CC13: =BV13-BZ13 -> 0 | CD13: =BW13-CA13 -> 0 | CE13: =BX13-CB13 -> 0
A14: =A13+1 -> 10 | F14: 1111039 | G14: ชิฟฟอนเค้ก วรรรณวนัช ห่อซีน (รวมรส 8 ชิ้น) | K14: =SUM(N14,X14,AH14,AR14,BB14,BL14,BV14) -> 0 | L14: =SUM(O14,Y14,AI14,AS14,BC14,BM14,BW14) -> 0 | O14: 0 | Q14: =SUM(N14:P14) -> 0 | R14: =SUMIF('ยอดจริง Week 1'!A:A,'Week 1'!F14,'ยอดจริง Week 1'!C:C) -> 0 | S14: =SUMIF('ยอดจริง Week 1'!A:A,'Week 1'!F14,'ยอดจริง Week 1'!D:D) -> 0 | T14: =SUMIF('ยอดจริง Week 1'!A:A,'Week 1'!F14,'ยอดจริง Week 1'!E:E) -> 0 | U14: =N14-R14 -> 0 | V14: =O14-S14 -> 0 | W14: =P14-T14 -> 0 | Y14: 0 | AA14: =SUM(X14:Z14) -> 0 | AB14: =SUMIF('ยอดจริง Week 1'!H:H,'Week 1'!F14,'ยอดจริง Week 1'!J:J) -> 0 | AC14: =SUMIF('ยอดจริง Week 1'!H:H,'Week 1'!F14,'ยอดจริง Week 1'!K:K) -> 0 | AD14: =SUMIF('ยอดจริง Week 1'!H:H,'Week 1'!F14,'ยอดจริง Week 1'!L:L) -> 0 | AE14: =X14-AB14 -> 0 | AF14: =Y14-AC14 -> 0 | AG14: =Z14-AD14 -> 0 | AI14: 0 | AK14: =SUM(AH14:AJ14) -> 0 | AL14: =SUMIF('ยอดจริง Week 1'!O:O,'Week 1'!F14,'ยอดจริง Week 1'!Q:Q) -> 0 | AM14: =SUMIF('ยอดจริง Week 1'!O:O,'Week 1'!F14,'ยอดจริง Week 1'!R:R) -> 0 | AN14: =SUMIF('ยอดจริง Week 1'!O:O,'Week 1'!F14,'ยอดจริง Week 1'!S:S) -> 0 | AO14: =AH14-AL14 -> 0 | AP14: =AI14-AM14 -> 0 | AQ14: =AJ14-AN14 -> 0 | AS14: 0 | AU14: =SUM(AR14:AT14) -> 0 | AV14: =SUMIF('ยอดจริง Week 1'!V:V,'Week 1'!F14,'ยอดจริง Week 1'!X:X) -> 0 | AW14: =SUMIF('ยอดจริง Week 1'!V:V,'Week 1'!F14,'ยอดจริง Week 1'!Y:Y) -> 0 | AX14: =SUMIF('ยอดจริง Week 1'!V:V,'Week 1'!F14,'ยอดจริง Week 1'!Z:Z) -> 0 | AY14: =AR14-AV14 -> 0 | AZ14: =AS14-AW14 -> 0 | BA14: =AT14-AX14 -> 0 | BC14: 0 | BE14: =SUM(BB14:BD14) -> 0 | BF14: =SUMIF('ยอดจริง Week 1'!AC:AC,'Week 1'!F14,'ยอดจริง Week 1'!AE:AE) -> 0 | BG14: =SUMIF('ยอดจริง Week 1'!AC:AC,'Week 1'!F14,'ยอดจริง Week 1'!AF:AF) -> 0 | BH14: =SUMIF('ยอดจริง Week 1'!AC:AC,'Week 1'!F14,'ยอดจริง Week 1'!AG:AG) -> 0 | BI14: =BB14-BF14 -> 0 | BJ14: =BC14-BG14 -> 0 | BK14: =BD14-BH14 -> 0 | BM14: 0 | BO14: =SUM(BL14:BN14) -> 0 | BP14: =SUMIF('ยอดจริง Week 1'!AJ:AJ,'Week 1'!F14,'ยอดจริง Week 1'!AL:AL) -> 0 | BQ14: =SUMIF('ยอดจริง Week 1'!AJ:AJ,'Week 1'!F14,'ยอดจริง Week 1'!AM:AM) -> 0 | BR14: =SUMIF('ยอดจริง Week 1'!AJ:AJ,'Week 1'!F14,'ยอดจริง Week 1'!AN:AN) -> 0 | BS14: =BL14-BP14 -> 0 | BT14: =BM14-BQ14 -> 0 | BU14: =BN14-BR14 -> 0 | BW14: 0 | BY14: =SUM(BV14:BX14) -> 0 | BZ14: =SUMIF('ยอดจริง Week 1'!AQ:AQ,'Week 1'!F14,'ยอดจริง Week 1'!AS:AS) -> 0 | CA14: =SUMIF('ยอดจริง Week 1'!AQ:AQ,'Week 1'!F14,'ยอดจริง Week 1'!AT:AT) -> 0 | CB14: =SUMIF('ยอดจริง Week 1'!AQ:AQ,'Week 1'!F14,'ยอดจริง Week 1'!AU:AU) -> 0 | CC14: =BV14-BZ14 -> 0 | CD14: =BW14-CA14 -> 0 | CE14: =BX14-CB14 -> 0
A15: =A14+1 -> 11 | F15: 1111041 | G15: ชิฟฟอนเค้ก วรรณวนัช กาแฟล้วน(รวมรส 4 ชิ้น) | K15: =SUM(N15,X15,AH15,AR15,BB15,BL15,BV15) -> 0 | L15: =SUM(O15,Y15,AI15,AS15,BC15,BM15,BW15) -> 0 | O15: 0 | Q15: =SUM(N15:P15) -> 0 | R15: =SUMIF('ยอดจริง Week 1'!A:A,'Week 1'!F15,'ยอดจริง Week 1'!C:C) -> 0 | S15: =SUMIF('ยอดจริง Week 1'!A:A,'Week 1'!F15,'ยอดจริง Week 1'!D:D) -> 0 | T15: =SUMIF('ยอดจริง Week 1'!A:A,'Week 1'!F15,'ยอดจริง Week 1'!E:E) -> 0 | U15: =N15-R15 -> 0 | V15: =O15-S15 -> 0 | W15: =P15-T15 -> 0 | Y15: 0 | AA15: =SUM(X15:Z15) -> 0 | AB15: =SUMIF('ยอดจริง Week 1'!H:H,'Week 1'!F15,'ยอดจริง Week 1'!J:J) -> 0 | AC15: =SUMIF('ยอดจริง Week 1'!H:H,'Week 1'!F15,'ยอดจริง Week 1'!K:K) -> 0 | AD15: =SUMIF('ยอดจริง Week 1'!H:H,'Week 1'!F15,'ยอดจริง Week 1'!L:L) -> 0 | AE15: =X15-AB15 -> 0 | AF15: =Y15-AC15 -> 0 | AG15: =Z15-AD15 -> 0 | AI15: 0 | AK15: =SUM(AH15:AJ15) -> 0 | AL15: =SUMIF('ยอดจริง Week 1'!O:O,'Week 1'!F15,'ยอดจริง Week 1'!Q:Q) -> 0 | AM15: =SUMIF('ยอดจริง Week 1'!O:O,'Week 1'!F15,'ยอดจริง Week 1'!R:R) -> 0 | AN15: =SUMIF('ยอดจริง Week 1'!O:O,'Week 1'!F15,'ยอดจริง Week 1'!S:S) -> 0 | AO15: =AH15-AL15 -> 0 | AP15: =AI15-AM15 -> 0 | AQ15: =AJ15-AN15 -> 0 | AS15: 0 | AU15: =SUM(AR15:AT15) -> 0 | AV15: =SUMIF('ยอดจริง Week 1'!V:V,'Week 1'!F15,'ยอดจริง Week 1'!X:X) -> 0 | AW15: =SUMIF('ยอดจริง Week 1'!V:V,'Week 1'!F15,'ยอดจริง Week 1'!Y:Y) -> 0 | AX15: =SUMIF('ยอดจริง Week 1'!V:V,'Week 1'!F15,'ยอดจริง Week 1'!Z:Z) -> 0 | AY15: =AR15-AV15 -> 0 | AZ15: =AS15-AW15 -> 0 | BA15: =AT15-AX15 -> 0 | BC15: 0 | BE15: =SUM(BB15:BD15) -> 0 | BF15: =SUMIF('ยอดจริง Week 1'!AC:AC,'Week 1'!F15,'ยอดจริง Week 1'!AE:AE) -> 0 | BG15: =SUMIF('ยอดจริง Week 1'!AC:AC,'Week 1'!F15,'ยอดจริง Week 1'!AF:AF) -> 0 | BH15: =SUMIF('ยอดจริง Week 1'!AC:AC,'Week 1'!F15,'ยอดจริง Week 1'!AG:AG) -> 0 | BI15: =BB15-BF15 -> 0 | BJ15: =BC15-BG15 -> 0 | BK15: =BD15-BH15 -> 0 | BM15: 0 | BO15: =SUM(BL15:BN15) -> 0 | BP15: =SUMIF('ยอดจริง Week 1'!AJ:AJ,'Week 1'!F15,'ยอดจริง Week 1'!AL:AL) -> 0 | BQ15: =SUMIF('ยอดจริง Week 1'!AJ:AJ,'Week 1'!F15,'ยอดจริง Week 1'!AM:AM) -> 0 | BR15: =SUMIF('ยอดจริง Week 1'!AJ:AJ,'Week 1'!F15,'ยอดจริง Week 1'!AN:AN) -> 0 | BS15: =BL15-BP15 -> 0 | BT15: =BM15-BQ15 -> 0 | BU15: =BN15-BR15 -> 0 | BW15: 0 | BY15: =SUM(BV15:BX15) -> 0 | BZ15: =SUMIF('ยอดจริง Week 1'!AQ:AQ,'Week 1'!F15,'ยอดจริง Week 1'!AS:AS) -> 0 | CA15: =SUMIF('ยอดจริง Week 1'!AQ:AQ,'Week 1'!F15,'ยอดจริง Week 1'!AT:AT) -> 0 | CB15: =SUMIF('ยอดจริง Week 1'!AQ:AQ,'Week 1'!F15,'ยอดจริง Week 1'!AU:AU) -> 0 | CC15: =BV15-BZ15 -> 0 | CD15: =BW15-CA15 -> 0 | CE15: =BX15-CB15 -> 0
A16: =A15+1 -> 12 | F16: 1111043 | G16: ชิฟฟอนรสมะลิ 8 ชิ้น ห่อ ซีน | K16: =SUM(N16,X16,AH16,AR16,BB16,BL16,BV16) -> 0 | L16: =SUM(O16,Y16,AI16,AS16,BC16,BM16,BW16) -> 0 | O16: 0 | Q16: =SUM(N16:P16) -> 0 | R16: =SUMIF('ยอดจริง Week 1'!A:A,'Week 1'!F16,'ยอดจริง Week 1'!C:C) -> 0 | S16: =SUMIF('ยอดจริง Week 1'!A:A,'Week 1'!F16,'ยอดจริง Week 1'!D:D) -> 0 | T16: =SUMIF('ยอดจริง Week 1'!A:A,'Week 1'!F16,'ยอดจริง Week 1'!E:E) -> 0 | U16: =N16-R16 -> 0 | V16: =O16-S16 -> 0 | W16: =P16-T16 -> 0 | Y16: 0 | AA16: =SUM(X16:Z16) -> 0 | AB16: =SUMIF('ยอดจริง Week 1'!H:H,'Week 1'!F16,'ยอดจริง Week 1'!J:J) -> 0 | AC16: =SUMIF('ยอดจริง Week 1'!H:H,'Week 1'!F16,'ยอดจริง Week 1'!K:K) -> 0 | AD16: =SUMIF('ยอดจริง Week 1'!H:H,'Week 1'!F16,'ยอดจริง Week 1'!L:L) -> 0 | AE16: =X16-AB16 -> 0 | AF16: =Y16-AC16 -> 0 | AG16: =Z16-AD16 -> 0 | AI16: 0 | AK16: =SUM(AH16:AJ16) -> 0 | AL16: =SUMIF('ยอดจริง Week 1'!O:O,'Week 1'!F16,'ยอดจริง Week 1'!Q:Q) -> 0 | AM16: =SUMIF('ยอดจริง Week 1'!O:O,'Week 1'!F16,'ยอดจริง Week 1'!R:R) -> 0 | AN16: =SUMIF('ยอดจริง Week 1'!O:O,'Week 1'!F16,'ยอดจริง Week 1'!S:S) -> 0 | AO16: =AH16-AL16 -> 0 | AP16: =AI16-AM16 -> 0 | AQ16: =AJ16-AN16 -> 0 | AS16: 0 | AU16: =SUM(AR16:AT16) -> 0 | AV16: =SUMIF('ยอดจริง Week 1'!V:V,'Week 1'!F16,'ยอดจริง Week 1'!X:X) -> 0 | AW16: =SUMIF('ยอดจริง Week 1'!V:V,'Week 1'!F16,'ยอดจริง Week 1'!Y:Y) -> 0 | AX16: =SUMIF('ยอดจริง Week 1'!V:V,'Week 1'!F16,'ยอดจริง Week 1'!Z:Z) -> 0 | AY16: =AR16-AV16 -> 0 | AZ16: =AS16-AW16 -> 0 | BA16: =AT16-AX16 -> 0 | BC16: 0 | BE16: =SUM(BB16:BD16) -> 0 | BF16: =SUMIF('ยอดจริง Week 1'!AC:AC,'Week 1'!F16,'ยอดจริง Week 1'!AE:AE) -> 0 | BG16: =SUMIF('ยอดจริง Week 1'!AC:AC,'Week 1'!F16,'ยอดจริง Week 1'!AF:AF) -> 0 | BH16: =SUMIF('ยอดจริง Week 1'!AC:AC,'Week 1'!F16,'ยอดจริง Week 1'!AG:AG) -> 0 | BI16: =BB16-BF16 -> 0 | BJ16: =BC16-BG16 -> 0 | BK16: =BD16-BH16 -> 0 | BM16: 0 | BO16: =SUM(BL16:BN16) -> 0 | BP16: =SUMIF('ยอดจริง Week 1'!AJ:AJ,'Week 1'!F16,'ยอดจริง Week 1'!AL:AL) -> 0 | BQ16: =SUMIF('ยอดจริง Week 1'!AJ:AJ,'Week 1'!F16,'ยอดจริง Week 1'!AM:AM) -> 0 | BR16: =SUMIF('ยอดจริง Week 1'!AJ:AJ,'Week 1'!F16,'ยอดจริง Week 1'!AN:AN) -> 0 | BS16: =BL16-BP16 -> 0 | BT16: =BM16-BQ16 -> 0 | BU16: =BN16-BR16 -> 0 | BW16: 0 | BY16: =SUM(BV16:BX16) -> 0 | BZ16: =SUMIF('ยอดจริง Week 1'!AQ:AQ,'Week 1'!F16,'ยอดจริง Week 1'!AS:AS) -> 0 | CA16: =SUMIF('ยอดจริง Week 1'!AQ:AQ,'Week 1'!F16,'ยอดจริง Week 1'!AT:AT) -> 0 | CB16: =SUMIF('ยอดจริง Week 1'!AQ:AQ,'Week 1'!F16,'ยอดจริง Week 1'!AU:AU) -> 0 | CC16: =BV16-BZ16 -> 0 | CD16: =BW16-CA16 -> 0 | CE16: =BX16-CB16 -> 0
