Workbook

Sheet ALL
A1: ข้อมูลการยิง ADS ของแผนกออนไลน์ทุกแพลตฟอร์ม Y2026
A2: Month | B2: Total 2569 | C2: ค่าแอด | E2: Tiktok | H2: Facebook | K2: Lazada | N2: Shopee
B3: ยอดขาย | D3: คิดเป็น% | E3: ยอดขาย | F3: ค่าแอด | G3: คิดเป็น% | H3: ยอดขาย | I3: ค่าแอด | J3: คิดเป็น% | K3: ยอดขาย | L3: ค่าแอด | M3: คิดเป็น% | N3: ยอดขาย | O3: ค่าแอด | P3: คิดเป็น%
A4: มกราคม | B4: =+E4+H4+K4+N4 -> 2060742 | C4: =+F4+I4+L4+O4 -> 265582.82 | D4: =+C4/B4 -> 0.12887728 | E4: 1592536.9 | F4: 219910.05 | G4: =+F4/E4 -> 0.13808789 | H4: 74677 | I4: 23083.88 | J4: =+I4/H4 -> 0.30911633 | K4: 135333.12 | L4: 12874.91 | M4: =+L4/K4 -> 0.095134953 | N4: 258195 | O4: 9713.98 | P4: =+O4/N4 -> 0.03762265
A5: กุมภาพันธ์ | B5: =+E5+H5+K5+N5 -> 2166787.4 | C5: =+F5+I5+L5+O5 -> 230962.49 | D5: =+C5/B5 -> 0.10659213 | E5: 674363.2 | F5: 121862.2 | G5: =+F5/E5 -> 0.18070707 | H5: 1122704.1 | I5: 60539.42 | J5: =+I5/H5 -> 0.053922864 | K5: 139746.1 | L5: 7122.3 | M5: =+L5/K5 -> 0.050966002 | N5: 229974 | O5: 41438.57 | P5: =+O5/N5 -> 0.18018806
A6: มีนาคม | B6: =+E6+H6+K6+N6 -> 1456036.2 | C6: =+F6+I6+L6+O6 -> 252228.2 | D6: =+C6/B6 -> 0.17322935 | E6: 575377.1 | F6: 143713.3 | G6: =+F6/E6 -> 0.24977237 | H6: 417617.6 | I6: 53391.9 | J6: =+I6/H6 -> 0.12784878 | K6: 169465.5 | L6: 14270.4 | M6: =+L6/K6 -> 0.08420829 | N6: 293576 | O6: 40852.6 | P6: =+O6/N6 -> 0.13915511
A7: เมษายน | B7: =+E7+H7+K7+N7 -> 1717225.4 | C7: =+F7+I7+L7+O7 -> 297186.9 | D7: =+C7/B7 -> 0.17306225 | E7: =+'เม.ย.'!B35 -> 716790.9 | F7: =+'เม.ย.'!C35 -> 138044.7 | G7: =+F7/E7 -> 0.19258713 | H7: =+'เม.ย.'!F35 -> 355371 | I7: =+'เม.ย.'!G35 -> 59360.1 | J7: =+I7/H7 -> 0.16703698 | K7: =+'เม.ย.'!J35 -> 169730.5 | L7: =+'เม.ย.'!K35 -> 15728.4 | M7: =+L7/K7 -> 0.092666904 | N7: =+'เม.ย.'!N35 -> 475333 | O7: =+'เม.ย.'!O35 -> 84053.7 | P7: =+O7/N7 -> 0.17683119
A8: พฤษภาคม | B8: =+E8+H8+K8+N8 -> 1781163 | C8: =+F8+I8+L8+O8 -> 271674.8 | D8: =+C8/B8 -> 0.15252664 | E8: =+'พ.ค.'!B35 -> 862076.8 | F8: =+'พ.ค.'!C35 -> 137768.5 | G8: =+F8/E8 -> 0.15981001 | H8: =+'พ.ค.'!F35 -> 319999.6 | I8: =+'พ.ค.'!G35 -> 54928.5 | J8: =+I8/H8 -> 0.17165178 | K8: =+'พ.ค.'!J35 -> 147721.6 | L8: =+'พ.ค.'!K35 -> 12886.9 | M8: =+L8/K8 -> 0.08723775 | N8: =+'พ.ค.'!N35 -> 451365 | O8: =+'พ.ค.'!O35 -> 66090.9 | P8: =+O8/N8 -> 0.14642451
A9: มิถุนายน | B9: =+E9+H9+K9+N9 -> 1483621.1 | C9: =+F9+I9+L9+O9 -> 196718.7 | D9: =+C9/B9 -> 0.13259363 | E9: =+'มิ.ย.'!B35 -> 723452.4 | F9: =+'มิ.ย.'!C35 -> 113143.7 | G9: =+F9/E9 -> 0.15639412 | H9: =+'มิ.ย.'!F35 -> 265994.2 | I9: =+'มิ.ย.'!G35 -> 32634.2 | J9: =+I9/H9 -> 0.12268764 | K9: =+'มิ.ย.'!J35 -> 82802.5 | L9: =+'มิ.ย.'!K35 -> 3802.7 | M9: =+L9/K9 -> 0.045924942 | N9: =+'มิ.ย.'!N35 -> 411372 | O9: =+'มิ.ย.'!O35 -> 47138.1 | P9: =+O9/N9 -> 0.11458753
A10: กรกฎาคม | B10: =+E10+H10+K10+N10 -> 0 | C10: =+F10+I10+L10+O10 -> 0 | D10: =+C10/B10 -> #DIV/0! | G10: =+F10/E10 -> #DIV/0! | J10: =+I10/H10 -> #DIV/0! | M10: =+L10/K10 -> #DIV/0! | P10: =+O10/N10 -> #DIV/0!
A11: สิงหาคม | B11: =+E11+H11+K11+N11 -> 0 | C11: =+F11+I11+L11+O11 -> 0 | D11: =+C11/B11 -> #DIV/0! | G11: =+F11/E11 -> #DIV/0! | J11: =+I11/H11 -> #DIV/0! | M11: =+L11/K11 -> #DIV/0! | P11: =+O11/N11 -> #DIV/0!
A12: กันยายน | B12: =+E12+H12+K12+N12 -> 0 | C12: =+F12+I12+L12+O12 -> 0 | D12: =+C12/B12 -> #DIV/0! | G12: =+F12/E12 -> #DIV/0! | J12: =+I12/H12 -> #DIV/0! | M12: =+L12/K12 -> #DIV/0! | P12: =+O12/N12 -> #DIV/0!
A13: ตุลาคม | B13: =+E13+H13+K13+N13 -> 0 | C13: =+F13+I13+L13+O13 -> 0 | D13: =+C13/B13 -> #DIV/0! | G13: =+F13/E13 -> #DIV/0! | J13: =+I13/H13 -> #DIV/0! | M13: =+L13/K13 -> #DIV/0! | P13: =+O13/N13 -> #DIV/0!
A14: พฤศจิกายน | B14: =+E14+H14+K14+N14 -> 0 | C14: =+F14+I14+L14+O14 -> 0 | D14: =+C14/B14 -> #DIV/0! | G14: =+F14/E14 -> #DIV/0! | J14: =+I14/H14 -> #DIV/0! | M14: =+L14/K14 -> #DIV/0! | P14: =+O14/N14 -> #DIV/0!
A15: ธันวาคม | B15: =+E15+H15+K15+N15 -> 0 | C15: =+F15+I15+L15+O15 -> 0 | D15: =+C15/B15 -> #DIV/0! | G15: =+F15/E15 -> #DIV/0! | J15: =+I15/H15 -> #DIV/0! | M15: =+L15/K15 -> #DIV/0! | P15: =+O15/N15 -> #DIV/0!
A16: Total | B16: =SUM(B4:B15) -> 10665575 | C16: =SUM(C4:C15) -> 1514353.9 | D16: MB | E16: =SUM(E4:E15) -> 5144597.3 | F16: =SUM(F4:F15) -> 874442.45 | G16: MB | H16: =SUM(H4:H15) -> 2556363.5 | I16: =SUM(I4:I15) -> 283938 | J16: MB | K16: =SUM(K4:K15) -> 844799.32 | L16: =SUM(L4:L15) -> 66685.61 | M16: MB | N16: =SUM(N4:N15) -> 2119815 | O16: =SUM(O4:O15) -> 289287.85 | P16: MB
B18: ข้อมูลการยิง ADS ของแผนกออนไลน์ทุกแพลตฟอร์ม Y2026
I30: แพลตฟอร์ม | J30: ยอดขาย | L30: ค่าแอด | N30: คิดเป็น%
I31: Tiktok | J31: =+E16 -> 5144597.3 | L31: =+F16 -> 874442.45 | N31: =+L31/J31 -> 0.16997297
I32: Facebook | J32: =+H16 -> 2556363.5 | L32: =+I16 -> 283938 | N32: =+L32/J32 -> 0.11107106
I33: Lazada | J33: =+K16 -> 844799.32 | L33: =+L16 -> 66685.61 | N33: =+L33/J33 -> 0.078936628
I34: Shopee | J34: =+N16 -> 2119815 | L34: =+O16 -> 289287.85 | N34: =+L34/J34 -> 0.13646844
I35: Total | J35: =SUM(J31:J34) -> 10665575 | L35: =SUM(L31:L34) -> 1514353.9 | N35: =+L35/J35 -> 0.14198521
M38: =NOW() -> 46207.72

Sheet ม.ค.
A1: ข้อมูลการยิง ADS ของแผนกออนไลน์ทุกแพลตฟอร์ม January 2026
A2: Tiktok | E2: Facebook | I2: Lazada | M2: Shopee
A3: ว/ด/ป | B3: ยอดขาย | C3: ค่าแอด | D3: คิดเป็น% | E3: ว/ด/ป | F3: ยอดขาย | G3: ค่าแอด | H3: คิดเป็น% | I3: ว/ด/ป | J3: ยอดขาย | K3: ค่าแอด | L3: คิดเป็น% | M3: ว/ด/ป | N3: ยอดขาย | O3: ค่าแอด | P3: คิดเป็น%
A4: 46023 | B4: 218211.13 | C4: 24106.91 | D4: =+C4/B4 -> 0.11047516 | E4: 46023 | F4: 1426 | G4: 300 | H4: =+G4/F4 -> 0.21037868 | I4: 46023 | J4: 7475.35 | K4: 637 | L4: =+K4/J4 -> 0.085213401 | M4: 46023 | N4: 21588 | O4: 0 | P4: =+O4/N4 -> 0
A5: 46024 | B5: 126979.91 | C5: 13804.19 | D5: =+C5/B5 -> 0.10871161 | E5: 46024 | F5: 4100 | G5: 344 | H5: =+G5/F5 -> 0.083902439 | I5: 46024 | J5: 12322.2 | K5: 571.95 | L5: =+K5/J5 -> 0.046416224 | M5: 46024 | N5: 14959 | O5: 0 | P5: =+O5/N5 -> 0
A6: 46025 | B6: 152360.05 | C6: 16364.55 | D6: =+C6/B6 -> 0.10740709 | E6: 46025 | F6: 2687 | G6: 271 | H6: =+G6/F6 -> 0.10085597 | I6: 46025 | J6: 8064.45 | K6: 531.56 | L6: =+K6/J6 -> 0.06591398 | M6: 46025 | N6: 15279 | O6: 0 | P6: =+O6/N6 -> 0
A7: 46026 | B7: 111733.03 | C7: 11994.86 | D7: =+C7/B7 -> 0.10735286 | E7: 46026 | F7: 2619 | G7: 337 | H7: =+G7/F7 -> 0.12867507 | I7: 46026 | J7: 5531.85 | K7: 600.29 | L7: =+K7/J7 -> 0.10851523 | M7: 46026 | N7: 14348 | O7: 0 | P7: =+O7/N7 -> 0
A8: 46027 | B8: 116531.41 | C8: 13451.56 | D8: =+C8/B8 -> 0.11543291 | E8: 46027 | F8: - | G8: 330 | H8: =+G8/F8 -> #VALUE! | I8: 46027 | J8: 7116.3 | K8: 598.43 | L8: =+K8/J8 -> 0.084092857 | M8: 46027 | N8: 12891 | O8: 0 | P8: =+O8/N8 -> 0
A9: 46028 | B9: 87620.22 | C9: 10396.11 | D9: =+C9/B9 -> 0.11864967 | E9: 46028 | F9: 2621 | G9: 312 | H9: =+G9/F9 -> 0.11903853 | I9: 46028 | J9: 4142.84 | K9: 519.56 | L9: =+K9/J9 -> 0.12541155 | M9: 46028 | N9: 14449 | O9: 0 | P9: =+O9/N9 -> 0
A10: 46029 | B10: 89970.48 | C10: 10888.29 | D10: =+C10/B10 -> 0.12102069 | E10: 46029 | F10: 3466 | G10: 267 | H10: =+G10/F10 -> 0.077034045 | I10: 46029 | J10: 10280.81 | K10: 473.24 | L10: =+K10/J10 -> 0.046031392 | M10: 46029 | N10: 8502 | O10: 0 | P10: =+O10/N10 -> 0
A11: 46030 | B11: 62988.06 | C11: 6933.14 | D11: =+C11/B11 -> 0.1100707 | E11: 46030 | F11: 2135 | G11: 263 | H11: =+G11/F11 -> 0.12318501 | I11: 46030 | J11: 5112.8 | K11: 411.17 | L11: =+K11/J11 -> 0.080419731 | M11: 46030 | N11: 3744 | O11: 0 | P11: =+O11/N11 -> 0
A12: 46031 | B12: 30292.56 | C12: 4226.56 | D12: =+C12/B12 -> 0.13952469 | E12: 46031 | F12: - | G12: 293 | H12: =+G12/F12 -> #VALUE! | I12: 46031 | J12: 5880.5 | K12: 276.19 | L12: =+K12/J12 -> 0.046967095 | M12: 46031 | N12: 7634 | O12: 0 | P12: =+O12/N12 -> 0
A13: 46032 | B13: 38206.02 | C13: 7204.6 | D13: =+C13/B13 -> 0.18857238 | E13: 46032 | F13: - | G13: 295 | H13: =+G13/F13 -> #VALUE! | I13: 46032 | J13: 2633.3 | K13: 289.8 | L13: =+K13/J13 -> 0.11005203 | M13: 46032 | N13: 7171 | O13: 197 | P13: =+O13/N13 -> 0.027471761
A14: 46033 | B14: 44813.98 | C14: 5202.35 | D14: =+C14/B14 -> 0.11608766 | E14: 46033 | F14: 9285 | G14: 330 | H14: =+G14/F14 -> 0.035541195 | I14: 46033 | J14: 6244.25 | K14: 384.96 | L14: =+K14/J14 -> 0.061650318 | M14: 46033 | N14: 6862 | O14: 1486.03 | P14: =+O14/N14 -> 0.21655931
A15: 46034 | B15: 47256.12 | C15: 7401.14 | D15: =+C15/B15 -> 0.1566176 | E15: 46034 | F15: 2575 | G15: 361 | H15: =+G15/F15 -> 0.14019417 | I15: 46034 | J15: 3325.1 | K15: 344.6 | L15: =+K15/J15 -> 0.10363598 | M15: 46034 | N15: 4775 | O15: 355.33 | P15: =+O15/N15 -> 0.07441466
A16: 46035 | B16: 32075.69 | C16: 5342.58 | D16: =+C16/B16 -> 0.16656165 | E16: 46035 | F16: 1115 | G16: 262 | H16: =+G16/F16 -> 0.23497758 | I16: 46035 | J16: 3772.5 | K16: 154.46 | L16: =+K16/J16 -> 0.040943671 | M16: 46035 | N16: 7754 | O16: 0 | P16: =+O16/N16 -> 0
A17: 46036 | B17: 23965.8 | C17: 3949.59 | D17: =+C17/B17 -> 0.16480109 | E17: 46036 | F17: 1474 | G17: 835 | H17: =+G17/F17 -> 0.56648575 | I17: 46036 | J17: 2222.85 | K17: 238 | L17: =+K17/J17 -> 0.10706975 | M17: 46036 | N17: 3432 | O17: 0 | P17: =+O17/N17 -> 0
A18: 46037 | B18: 26965.38 | C18: 3319.29 | D18: =+C18/B18 -> 0.1230945 | E18: 46037 | F18: 4598 | G18: 1831 | H18: =+G18/F18 -> 0.39821662 | I18: 46037 | J18: 1975.46 | K18: 238.52 | L18: =+K18/J18 -> 0.1207415 | M18: 46037 | N18: 5101 | O18: 0 | P18: =+O18/N18 -> 0
A19: 46038 | B19: 22176.19 | C19: 3924.97 | D19: =+C19/B19 -> 0.17699028 | E19: 46038 | F19: 3438 | G19: 1311 | H19: =+G19/F19 -> 0.38132635 | I19: 46038 | J19: 336.1 | K19: 279.64 | L19: =+K19/J19 -> 0.83201428 | M19: 46038 | N19: 4243 | O19: 0 | P19: =+O19/N19 -> 0
A20: 46039 | B20: 23257.32 | C20: 3330.13 | D20: =+C20/B20 -> 0.14318632 | E20: 46039 | F20: 2652 | G20: 1331 | H20: =+G20/F20 -> 0.50188537 | I20: 46039 | J20: 3599.85 | K20: 223.71 | L20: =+K20/J20 -> 0.062144256 | M20: 46039 | N20: 3728 | O20: 0 | P20: =+O20/N20 -> 0
A21: 46040 | B21: 37366.7 | C21: 3759.12 | D21: =+C21/B21 -> 0.1006008 | E21: 46040 | F21: 1028 | G21: 1561 | H21: =+G21/F21 -> 1.5184825 | I21: 46040 | J21: 2014.53 | K21: 135.2 | L21: =+K21/J21 -> 0.067112428 | M21: 46040 | N21: 2754 | O21: 0 | P21: =+O21/N21 -> 0
A22: 46041 | B22: 28086.01 | C22: 2914.5 | D22: =+C22/B22 -> 0.10377052 | E22: 46041 | F22: 2557 | G22: 1274 | H22: =+G22/F22 -> 0.49824013 | I22: 46041 | J22: 3941.8 | K22: 299.93 | L22: =+K22/J22 -> 0.076089604 | M22: 46041 | N22: 7729 | O22: 0 | P22: =+O22/N22 -> 0
A23: 46042 | B23: 28288.04 | C23: 3639.83 | D23: =+C23/B23 -> 0.12867028 | E23: 46042 | F23: 1595 | G23: 1380 | H23: 0 | I23: 46042 | J23: 3122.45 | K23: 344.41 | L23: =+K23/J23 -> 0.11030121 | M23: 46042 | N23: 5219 | O23: 0 | P23: =+O23/N23 -> 0
A24: 46043 | B24: 25263.27 | C24: 3033.58 | D24: =+C24/B24 -> 0.12007868 | E24: 46043 | F24: 3231 | G24: 1261 | H24: =+G24/F24 -> 0.39028165 | I24: 46043 | J24: 4248.9 | K24: 107.04 | L24: =+K24/J24 -> 0.025192403 | M24: 46043 | N24: 5108 | O24: 0 | P24: =+O24/N24 -> 0
A25: 46044 | B25: 22664.48 | C25: 3468.36 | D25: =+C25/B25 -> 0.15303065 | E25: 46044 | F25: 2057 | G25: 1165 | H25: =+G25/F25 -> 0.56635877 | I25: 46044 | J25: 1659.25 | K25: 281.44 | L25: =+K25/J25 -> 0.1696188 | M25: 46044 | N25: 4838 | O25: 0 | P25: =+O25/N25 -> 0
A26: 46045 | B26: 20289.75 | C26: 3187.12 | D26: =+C26/B26 -> 0.1570803 | E26: 46045 | F26: 2356 | G26: 976 | H26: =+G26/F26 -> 0.41426146 | I26: 46045 | J26: 3233.35 | K26: 175.75 | L26: =+K26/J26 -> 0.05435539 | M26: 46045 | N26: 10472 | O26: 0 | P26: =+O26/N26 -> 0
A27: 46046 | B27: 25197.1 | C27: 3880.02 | D27: =+C27/B27 -> 0.15398677 | E27: 46046 | F27: 3483 | G27: 905 | H27: =+G27/F27 -> 0.25983348 | I27: 46046 | J27: 3334.43 | K27: 281.17 | L27: =+K27/J27 -> 0.084323258 | M27: 46046 | N27: 2531 | O27: 0 | P27: =+O27/N27 -> 0
A28: 46047 | B28: 18795.25 | C28: 3758.36 | D28: =+C28/B28 -> 0.19996329 | E28: 46047 | F28: 1402 | G28: 1133 | H28: =+G28/F28 -> 0.80813124 | I28: 46047 | J28: 3447.25 | K28: 403.32 | L28: =+K28/J28 -> 0.11699761 | M28: 46047 | N28: 4826 | O28: 309.74 | P28: =+O28/N28 -> 0.064181517
A29: 46048 | B29: 25600.31 | C29: 3331.16 | D29: =+C29/B29 -> 0.13012186 | E29: 46048 | F29: 2699 | G29: 1141 | H29: 0 | I29: 46048 | J29: 5775.6 | K29: 406.98 | L29: 0 | M29: 46048 | N29: 12451 | O29: 976 | P29: =+O29/N29 -> 0.078387278
A30: 46049 | B30: 20512.12 | C30: 3725.45 | D30: =+C30/B30 -> 0.18162189 | E30: 46049 | F30: 3551 | G30: 929 | H30: 0 | I30: 46049 | J30: 2934.7 | K30: 309.84 | L30: =+K30/J30 -> 0.10557808 | M30: 46049 | N30: 14132 | O30: 628.19 | P30: =+O30/N30 -> 0.044451599
A31: 46050 | B31: 3518.19 | C31: 21698.23 | D31: =+C31/B31 -> 6.1674412 | E31: 46050 | F31: 2586 | G31: 440.28 | H31: =+G31/F31 -> 0.17025522 | I31: 46050 | J31: 2872.95 | K31: 2872 | L31: 0 | M31: 46050 | N31: 6980 | O31: 1207.97 | P31: =+O31/N31 -> 0.1730616
A32: 46051 | B32: 26107.98 | C32: 3240.2 | D32: =+C32/B32 -> 0.12410765 | E32: 46051 | F32: 1212 | G32: 219 | H32: 0 | I32: 46051 | J32: 1323 | K32: 384.59 | L32: =+K32/J32 -> 0.29069539 | M32: 46051 | N32: 6023 | O32: 1137.6 | P32: =+O32/N32 -> 0.18887598
A33: 46052 | B33: 31309.96 | C33: 5000 | D33: 0 | E33: 46052 | F33: 1144 | G33: 371 | H33: 0 | I33: 46052 | J33: 4245 | K33: 100.16 | L33: 0 | M33: 46052 | N33: 6832 | O33: 1434.86 | P33: =+O33/N33 -> 0.21002049
A34: 46053 | B34: 24134.34 | C34: 3433.3 | D34: 0 | E34: 46053 | F34: 1585 | G34: 1055.6 | H34: 0 | I34: 46053 | J34: 3143.4 | K34: 0 | L34: 0 | M34: 46053 | N34: 11840 | O34: 1981.26 | P34: =+O34/N34 -> 0.16733615
A35: Total | B35: =SUM(B4:B34) -> 1592536.9 | C35: =SUM(C4:C34) -> 219910.05 | D35: MB | E35: Total | F35: =SUM(F4:F34) -> 74677 | G35: =SUM(G4:G34) -> 23083.88 | H35: MB | I35: Total | J35: =SUM(J4:J34) -> 135333.12 | K35: =SUM(K4:K34) -> 12874.91 | L35: MB | M35: Total | N35: =SUM(N4:N34) -> 258195 | O35: =SUM(O4:O34) -> 9713.98 | P35: MB | XFD35: =SUM(A35:XFC35) -> 2326324.8
B38: ตารางสรุป 1- 31 January 2026
B39: แพลตฟอร์ม | C39: ยอดขาย | D39: ค่าแอด | E39: คิดเป็น%
B40: Tiktok | C40: =+B35 -> 1592536.9 | D40: =+C35 -> 219910.05 | E40: =+D40/C40 -> 0.13808789
B41: Facebook | C41: =+F35 -> 74677 | D41: =+G35 -> 23083.88 | E41: =+D41/C41 -> 0.30911633
B42: Lazada | C42: =+J35 -> 135333.12 | D42: =+K35 -> 12874.91 | E42: =+D42/C42 -> 0.095134953
...

Sheet ก.พ.
A1: ข้อมูลการยิง ADS ของแผนกออนไลน์ทุกแพลตฟอร์ม February 2026
A2: Tiktok | E2: Facebook | I2: Lazada | M2: Shopee
A3: ว/ด/ป | B3: ยอดขาย | C3: ค่าแอด | D3: คิดเป็น% | E3: ว/ด/ป | F3: ยอดขาย | G3: ค่าแอด | H3: คิดเป็น% | I3: ว/ด/ป | J3: ยอดขาย | K3: ค่าแอด | L3: คิดเป็น% | M3: ว/ด/ป | N3: ยอดขาย | O3: ค่าแอด | P3: คิดเป็น%
A4: 46054 | B4: 20565.4 | C4: 3347.4 | D4: =+C4/B4 -> 0.16276853 | E4: 46054 | F4: 21098 | G4: 1733.63 | H4: =+G4/F4 -> 0.082170348 | I4: 46054 | J4: 6421.3 | L4: =+K4/J4 -> 0 | M4: 46054 | N4: 2514 | O4: 1553.48 | P4: =+O4/N4 -> 0.61793158
A5: 46055 | B5: 26418.4 | C5: 4827.9 | D5: =+C5/B5 -> 0.18274763 | E5: 46055 | F5: 42958.8 | G5: 1362.5 | H5: =+G5/F5 -> 0.031716435 | I5: 46055 | J5: 3540.1 | L5: =+K5/J5 -> 0 | M5: 46055 | N5: 9021 | O5: 2382.51 | P5: =+O5/N5 -> 0.26410708
A6: 46056 | B6: 25808.9 | C6: 4379 | D6: =+C6/B6 -> 0.16967015 | E6: 46056 | F6: 14753 | G6: 1381.57 | H6: =+G6/F6 -> 0.093646716 | I6: 46056 | J6: 11429 | L6: =+K6/J6 -> 0 | M6: 46056 | N6: 5608 | O6: 1813.97 | P6: =+O6/N6 -> 0.32346113
A7: 46057 | B7: 14678.9 | C7: 3977.4 | D7: =+C7/B7 -> 0.27096036 | E7: 46057 | F7: 18347.6 | G7: 1256.1 | H7: =+G7/F7 -> 0.06846127 | I7: 46057 | J7: 4952.5 | L7: =+K7/J7 -> 0 | M7: 46057 | N7: 8337 | O7: 1443.39 | P7: =+O7/N7 -> 0.17313062
A8: 46058 | B8: 17390.2 | C8: 3550 | D8: =+C8/B8 -> 0.20413796 | E8: 46058 | F8: 14497.3 | G8: 1136.31 | H8: =+G8/F8 -> 0.078380802 | I8: 46058 | J8: 2320.2 | L8: =+K8/J8 -> 0 | M8: 46058 | N8: 6590 | O8: 2117.47 | P8: =+O8/N8 -> 0.32131563
A9: 46059 | B9: 15811.3 | C9: 3228.5 | D9: =+C9/B9 -> 0.20418941 | E9: 46059 | F9: 6032 | G9: 1193.98 | H9: =+G9/F9 -> 0.19794098 | I9: 46059 | J9: 5370.8 | L9: =+K9/J9 -> 0 | M9: 46059 | N9: 9808 | O9: 1848.67 | P9: =+O9/N9 -> 0.18848593
A10: 46060 | B10: 25740 | C10: 3746.3 | D10: =+C10/B10 -> 0.1455439 | E10: 46060 | G10: 1151.11 | H10: =+G10/F10 -> #DIV/0! | I10: 46060 | J10: 7464.6 | L10: =+K10/J10 -> 0 | M10: 46060 | N10: 10471 | O10: 1865.07 | P10: =+O10/N10 -> 0.17811766
A11: 46061 | B11: 34808.6 | C11: 4227.3 | D11: =+C11/B11 -> 0.12144413 | E11: 46061 | F11: 12302.3 | G11: 1193.14 | H11: =+G11/F11 -> 0.096985117 | I11: 46061 | J11: 8364.3 | L11: =+K11/J11 -> 0 | M11: 46061 | N11: 9091 | O11: 1539.92 | P11: =+O11/N11 -> 0.16938951
A12: 46062 | B12: 34800.9 | C12: 4648.7 | D12: =+C12/B12 -> 0.13357988 | E12: 46062 | F12: 52642.2 | G12: 4168.25 | H12: =+G12/F12 -> 0.079180771 | I12: 46062 | J12: 5057.5 | L12: =+K12/J12 -> 0 | M12: 46062 | N12: 14717 | O12: 2037.18 | P12: =+O12/N12 -> 0.13842359
A13: 46063 | B13: 19158.3 | C13: 2286.1 | D13: =+C13/B13 -> 0.11932687 | E13: 46063 | F13: 20967 | G13: 1223.31 | H13: =+G13/F13 -> 0.058344541 | I13: 46063 | J13: 7216.6 | L13: =+K13/J13 -> 0 | M13: 46063 | N13: 3945 | O13: 1074.88 | P13: =+O13/N13 -> 0.27246641
A14: 46064 | B14: 34064.3 | C14: 4985.6 | D14: =+C14/B14 -> 0.1463585 | E14: 46064 | F14: 215614 | G14: 2004.06 | H14: =+G14/F14 -> 0.0092946655 | I14: 46064 | J14: 5998.6 | K14: 188 | L14: =+K14/J14 -> 0.031340646 | M14: 46064 | N14: 11734 | O14: 1243.85 | P14: =+O14/N14 -> 0.10600392
A15: 46065 | B15: 27438.6 | C15: 5120.7 | D15: =+C15/B15 -> 0.18662395 | E15: 46065 | F15: 13862 | G15: 2332.3 | H15: =+G15/F15 -> 0.16825133 | I15: 46065 | J15: 10156.7 | K15: 1214.4 | L15: =+K15/J15 -> 0.11956639 | M15: 46065 | N15: 12039 | O15: 1312.79 | P15: =+O15/N15 -> 0.10904477
A16: 46066 | B16: 24839.9 | C16: 5694.4 | D16: =+C16/B16 -> 0.22924408 | E16: 46066 | F16: 6352.6 | G16: 3095.97 | H16: =+G16/F16 -> 0.48735478 | I16: 46066 | J16: 9889.3 | K16: 1186 | L16: =+K16/J16 -> 0.1199276 | M16: 46066 | N16: 7567 | O16: 1358.78 | P16: =+O16/N16 -> 0.17956654
A17: 46067 | B17: 19343.3 | C17: 4460.6 | D17: =+C17/B17 -> 0.23060181 | E17: 46067 | F17: 8511 | G17: 4481.89 | H17: =+G17/F17 -> 0.52659969 | I17: 46067 | J17: 5230.5 | K17: 585.8 | L17: =+K17/J17 -> 0.11199694 | M17: 46067 | N17: 5210 | O17: 1358.78 | P17: =+O17/N17 -> 0.2608023
A18: 46068 | B18: 27896.5 | C18: 7215.8 | D18: =+C18/B18 -> 0.25866327 | E18: 46068 | F18: 33066 | G18: 1387.96 | H18: =+G18/F18 -> 0.041975443 | I18: 46068 | J18: 4716.6 | K18: 532.7 | L18: =+K18/J18 -> 0.11294153 | M18: 46068 | N18: 11412 | O18: 1507.89 | P18: =+O18/N18 -> 0.13213197
A19: 46069 | B19: 24880.2 | C19: 7374.3 | D19: =+C19/B19 -> 0.29639231 | E19: 46069 | F19: 32295.5 | G19: 3654.44 | H19: =+G19/F19 -> 0.11315632 | I19: 46069 | J19: 2983.3 | K19: 362.1 | L19: =+K19/J19 -> 0.12137566 | M19: 46069 | N19: 8042 | O19: 1649.65 | P19: =+O19/N19 -> 0.20512932
A20: 46070 | B20: 36192.5 | C20: 7418.3 | D20: =+C20/B20 -> 0.20496788 | E20: 46070 | F20: 9478.6 | G20: 3879.74 | H20: =+G20/F20 -> 0.40931572 | I20: 46070 | J20: 3173.1 | K20: 268.9 | L20: =+K20/J20 -> 0.084743626 | M20: 46070 | N20: 8602 | O20: 1356.02 | P20: =+O20/N20 -> 0.15764008
A21: 46071 | B21: 23749.3 | C21: 4128.9 | D21: =+C21/B21 -> 0.17385355 | E21: 46071 | F21: 6397 | G21: 2470.23 | H21: =+G21/F21 -> 0.38615445 | I21: 46071 | J21: 2953.9 | K21: 379.6 | L21: =+K21/J21 -> 0.12850807 | M21: 46071 | N21: 9702 | O21: 1128.5 | P21: =+O21/N21 -> 0.11631622
A22: 46072 | B22: 28160 | C22: 5926.4 | D22: =+C22/B22 -> 0.21045455 | E22: 46072 | F22: 476003 | G22: 2044.75 | H22: =+G22/F22 -> 0.0042956662 | I22: 46072 | J22: 2896.4 | K22: 184 | L22: =+K22/J22 -> 0.063527137 | M22: 46072 | N22: 8544 | O22: 1725.6 | P22: =+O22/N22 -> 0.20196629
A23: 46073 | B23: 22002.4 | C23: 3955.5 | D23: =+C23/B23 -> 0.17977584 | E23: 46073 | F23: 11903.8 | G23: 1912.69 | H23: 0 | I23: 46073 | J23: 2560.1 | K23: 124.9 | L23: =+K23/J23 -> 0.048787157 | M23: 46073 | N23: 10735 | O23: 1180.1 | P23: =+O23/N23 -> 0.10993014
A24: 46074 | B24: 17924.6 | C24: 3196.9 | D24: =+C24/B24 -> 0.17835266 | E24: 46074 | F24: 3911 | G24: 2207.02 | H24: =+G24/F24 -> 0.56431092 | I24: 46074 | J24: 2017.6 | K24: 248.6 | L24: =+K24/J24 -> 0.1232157 | M24: 46074 | N24: 7022 | O24: 1468.4 | P24: =+O24/N24 -> 0.20911421
A25: 46075 | B25: 13083.6 | C25: 2680.2 | D25: =+C25/B25 -> 0.20485188 | E25: 46075 | F25: 42070.5 | G25: 2426.51 | H25: =+G25/F25 -> 0.057677232 | I25: 46075 | J25: 2699.3 | K25: 295.7 | L25: =+K25/J25 -> 0.10954692 | M25: 46075 | N25: 6044 | O25: 1435.9 | P25: =+O25/N25 -> 0.23757445
A26: 46076 | B26: 17887.3 | C26: 2833.2 | D26: =+C26/B26 -> 0.15839171 | E26: 46076 | F26: 29780 | G26: 96.21 | H26: =+G26/F26 -> 0.0032306917 | I26: 46076 | J26: 3315.2 | K26: 179.6 | L26: =+K26/J26 -> 0.05417471 | M26: 46076 | N26: 8399 | O26: 1258.4 | P26: =+O26/N26 -> 0.14982736
A27: 46077 | B27: 26765.9 | C27: 3740.9 | D27: =+C27/B27 -> 0.13976365 | E27: 46077 | F27: 8548 | H27: =+G27/F27 -> 0 | I27: 46077 | J27: 3765 | K27: 215.5 | L27: =+K27/J27 -> 0.057237716 | M27: 46077 | N27: 5599 | O27: 1111 | P27: =+O27/N27 -> 0.19842829
A28: 46078 | B28: 25231.8 | C28: 3322.6 | D28: =+C28/B28 -> 0.13168303 | E28: 46078 | F28: 2528 | H28: =+G28/F28 -> 0 | I28: 46078 | J28: 2944.2 | K28: 321.8 | L28: =+K28/J28 -> 0.10929964 | M28: 46078 | N28: 7991 | O28: 966.37 | P28: =+O28/N28 -> 0.1209323
A29: 46079 | B29: 20800.6 | C29: 3502.6 | D29: =+C29/B29 -> 0.16838937 | E29: 46079 | F29: 6155 | G29: 3787.65 | H29: 0 | I29: 46079 | J29: 5993 | K29: 395.1 | L29: 0 | M29: 46079 | N29: 4946 | O29: 1100 | P29: =+O29/N29 -> 0.22240194
A30: 46080 | B30: 25382.2 | C30: 4176.5 | D30: =+C30/B30 -> 0.16454444 | E30: 46080 | F30: 4814.3 | G30: 4466.49 | H30: 0 | I30: 46080 | J30: 1084.3 | K30: 148.8 | L30: =+K30/J30 -> 0.13723139 | M30: 46080 | N30: 8906 | O30: 1300 | P30: =+O30/N30 -> 0.14596901
A31: 46081 | B31: 23539.3 | C31: 3910.2 | D31: =+C31/B31 -> 0.16611369 | E31: 46081 | F31: 7815.6 | G31: 4491.61 | H31: =+G31/F31 -> 0.57469804 | I31: 46081 | J31: 5232.1 | K31: 290.8 | L31: 0 | M31: 46081 | N31: 7378 | O31: 1300 | P31: =+O31/N31 -> 0.17619951
A32: 46082 | D32: =+C32/B32 -> #DIV/0! | E32: 46082 | H32: 0 | I32: 46082 | L32: =+K32/J32 -> #DIV/0! | M32: 46082 | P32: =+O32/N32 -> #DIV/0!
A33: 46083 | D33: 0 | E33: 46083 | H33: 0 | I33: 46083 | L33: 0 | M33: 46083 | P33: 0
A34: 46084 | D34: 0 | E34: 46084 | H34: 0 | I34: 46084 | L34: 0 | M34: 46084 | P34: =+O34/N34 -> #DIV/0!
A35: Total | B35: =SUM(B4:B34) -> 674363.2 | C35: =SUM(C4:C34) -> 121862.2 | D35: MB | E35: Total | F35: =SUM(F4:F34) -> 1122704.1 | G35: =SUM(G4:G34) -> 60539.42 | H35: MB | I35: Total | J35: =SUM(J4:J34) -> 139746.1 | K35: =SUM(K4:K34) -> 7122.3 | L35: MB | M35: Total | N35: =SUM(N4:N34) -> 229974 | O35: =SUM(O4:O34) -> 41438.57 | P35: MB | XFD35: =SUM(A35:XFC35) -> 2397749.9
B38: ตารางสรุป 1- 28 February 2026
B39: แพลตฟอร์ม | C39: ยอดขาย | D39: ค่าแอด | E39: คิดเป็น%
B40: Tiktok | C40: =+B35 -> 674363.2 | D40: =+C35 -> 121862.2 | E40: =+D40/C40 -> 0.18070707
B41: Facebook | C41: =+F35 -> 1122704.1 | D41: =+G35 -> 60539.42 | E41: =+D41/C41 -> 0.053922864
B42: Lazada | C42: =+J35 -> 139746.1 | D42: =+K35 -> 7122.3 | E42: =+D42/C42 -> 0.050966002
...

Sheet มี.ค.
A1: ข้อมูลการยิง ADS ของแผนกออนไลน์ทุกแพลตฟอร์ม March 2026
A2: Tiktok | E2: Facebook | I2: Lazada | M2: Shopee
A3: ว/ด/ป | B3: ยอดขาย | C3: ค่าแอด | D3: คิดเป็น% | E3: ว/ด/ป | F3: ยอดขาย | G3: ค่าแอด | H3: คิดเป็น% | I3: ว/ด/ป | J3: ยอดขาย | K3: ค่าแอด | L3: คิดเป็น% | M3: ว/ด/ป | N3: ยอดขาย | O3: ค่าแอด | P3: คิดเป็น%
A4: 46082 | B4: 16584.1 | C4: 4361.8 | D4: =+C4/B4 -> 0.26301096 | E4: 46082 | F4: 22585.5 | G4: 3062.9 | H4: =+G4/F4 -> 0.13561356 | I4: 46082 | J4: 4426.2 | K4: 443.5 | L4: =+K4/J4 -> 0.10019882 | M4: 46082 | N4: 11054 | O4: 1262 | P4: =+O4/N4 -> 0.11416682
A5: 46083 | B5: 16849.1 | C5: 4990.2 | D5: =+C5/B5 -> 0.29617012 | E5: 46083 | F5: 31645.1 | G5: 2677.7 | H5: =+G5/F5 -> 0.084616576 | I5: 46083 | J5: 6507.2 | K5: 587.7 | L5: =+K5/J5 -> 0.090315343 | M5: 46083 | N5: 10289 | O5: 1620.2 | P5: =+O5/N5 -> 0.15746914
A6: 46084 | B6: 19446.2 | C6: 7970 | D6: =+C6/B6 -> 0.40984871 | E6: 46084 | F6: 1472 | G6: 199.7 | H6: =+G6/F6 -> 0.13566576 | I6: 46084 | J6: 8373.2 | K6: 584.3 | L6: =+K6/J6 -> 0.069782162 | M6: 46084 | N6: 12690 | O6: 1649.8 | P6: =+O6/N6 -> 0.13000788
A7: 46085 | B7: 9178.2 | C7: 2755 | D7: =+C7/B7 -> 0.30016779 | E7: 46085 | F7: 637.7 | H7: =+G7/F7 -> 0 | I7: 46085 | J7: 4277.5 | K7: 676.1 | L7: =+K7/J7 -> 0.15805961 | M7: 46085 | N7: 7022 | O7: 1125.1 | P7: =+O7/N7 -> 0.16022501
A8: 46086 | B8: 23507.3 | C8: 7998.1 | D8: =+C8/B8 -> 0.34023899 | E8: 46086 | F8: 3680 | G8: 3506.4 | H8: =+G8/F8 -> 0.95282609 | I8: 46086 | J8: 7475.3 | K8: 871.4 | L8: =+K8/J8 -> 0.11657057 | M8: 46086 | N8: 11249 | O8: 1658.4 | P8: =+O8/N8 -> 0.14742644
A9: 46087 | B9: 11812.1 | C9: 7527.4 | D9: =+C9/B9 -> 0.63726179 | E9: 46087 | F9: 12727 | G9: 4332.7 | H9: =+G9/F9 -> 0.34043372 | I9: 46087 | J9: 2347 | K9: 560 | L9: =+K9/J9 -> 0.23860247 | M9: 46087 | N9: 7723 | O9: 1143 | P9: =+O9/N9 -> 0.14799948
A10: 46088 | B10: 11463.7 | C10: 4854.5 | D10: =+C10/B10 -> 0.42346712 | E10: 46088 | F10: 12727 | G10: 4256 | H10: =+G10/F10 -> 0.33440717 | I10: 46088 | J10: 3190.3 | K10: 573.9 | L10: =+K10/J10 -> 0.17988904 | M10: 46088 | N10: 5907 | O10: 1148 | P10: =+O10/N10 -> 0.19434569
A11: 46089 | B11: 14620.2 | C11: 5591.5 | D11: =+C11/B11 -> 0.38245031 | E11: 46089 | F11: 34005 | G11: 3058.6 | H11: =+G11/F11 -> 0.089945596 | I11: 46089 | J11: 3473.2 | K11: 508.6 | L11: =+K11/J11 -> 0.14643556 | M11: 46089 | N11: 7173 | O11: 1022.1 | P11: =+O11/N11 -> 0.14249268
A12: 46090 | B12: 7201.9 | C12: 4697.7 | D12: =+C12/B12 -> 0.6522862 | E12: 46090 | F12: 19495.9 | G12: 134.4 | H12: =+G12/F12 -> 0.0068937571 | I12: 46090 | J12: 8169.9 | K12: 347.9 | L12: =+K12/J12 -> 0.042583141 | M12: 46090 | N12: 16335 | O12: 1628.8 | P12: =+O12/N12 -> 0.099712274
A13: 46091 | B13: 15679.8 | C13: 5916.7 | D13: =+C13/B13 -> 0.37734537 | E13: 46091 | F13: 5003 | G13: 819.6 | H13: =+G13/F13 -> 0.16382171 | I13: 46091 | J13: 4094 | K13: 571.7 | L13: =+K13/J13 -> 0.13964338 | M13: 46091 | N13: 8857 | O13: 1657.3 | P13: =+O13/N13 -> 0.18711753
A14: 46092 | B14: 14750.8 | C14: 4945.9 | D14: =+C14/B14 -> 0.33529707 | E14: 46092 | F14: 215 | G14: 1341.4 | H14: =+G14/F14 -> 6.2390698 | I14: 46092 | J14: 6045.2 | K14: 618.7 | L14: =+K14/J14 -> 0.10234566 | M14: 46092 | N14: 7306 | O14: 1203.8 | P14: =+O14/N14 -> 0.16476868
A15: 46093 | B15: 13347 | C15: 5552.2 | D15: =+C15/B15 -> 0.41598861 | E15: 46093 | F15: 3173 | G15: 1117.9 | H15: =+G15/F15 -> 0.35231642 | I15: 46093 | J15: 5642 | K15: 500.8 | L15: =+K15/J15 -> 0.08876285 | M15: 46093 | N15: 10039 | O15: 1143 | P15: =+O15/N15 -> 0.11385596
A16: 46094 | B16: 18101.6 | C16: 7612.4 | D16: =+C16/B16 -> 0.42053741 | E16: 46094 | F16: 1653 | G16: 1144.1 | H16: =+G16/F16 -> 0.69213551 | I16: 46094 | J16: 3617 | K16: 414.1 | L16: =+K16/J16 -> 0.11448714 | M16: 46094 | N16: 10952 | O16: 1379.5 | P16: =+O16/N16 -> 0.12595873
A17: 46095 | B17: 6024.3 | C17: 91.8 | D17: =+C17/B17 -> 0.015238285 | E17: 46095 | F17: 14354 | G17: 843 | H17: =+G17/F17 -> 0.058729274 | I17: 46095 | J17: 7940.6 | K17: 669.9 | L17: =+K17/J17 -> 0.084363902 | M17: 46095 | N17: 18523 | O17: 1532.1 | P17: =+O17/N17 -> 0.082713383
A18: 46096 | B18: 27046.1 | C18: 4968.9 | D18: =+C18/B18 -> 0.18371965 | E18: 46096 | F18: 30120.7 | G18: 1357.9 | H18: =+G18/F18 -> 0.045081954 | I18: 46096 | J18: 4586.4 | K18: 641.3 | L18: =+K18/J18 -> 0.13982644 | M18: 46096 | N18: 9122 | O18: 1809.2 | P18: =+O18/N18 -> 0.1983337
A19: 46097 | B19: 22520.4 | C19: 3188.5 | D19: =+C19/B19 -> 0.14158274 | E19: 46097 | F19: 23577.9 | G19: 1262.4 | H19: =+G19/F19 -> 0.053541664 | I19: 46097 | J19: 8847.2 | K19: 737.1 | L19: =+K19/J19 -> 0.083314495 | M19: 46097 | N19: 6287 | O19: 1057.2 | P19: =+O19/N19 -> 0.16815651
... A21: 46099 | B21: 16504.9 | C21: 3496.3 | D21: =+C21/B21 -> 0.21183406 | E21: 46099 | F21: 6828.5 | G21: 1056.1 | H21: =+G21/F21 -> 0.15466061 | I21: 46099 | J21: 6879.1 | K21: 726.5 | L21: =+K21/J21 -> 0.10560975 | M21: 46099 | N21: 12283 | O21: 586.8 | P21: =+O21/N21 -> 0.047773345
A22: 46100 | B22: 12195.1 | C22: 3264.4 | D22: =+C22/B22 -> 0.26768128 | E22: 46100 | F22: 3899.5 | G22: 1017.5 | H22: =+G22/F22 -> 0.26093089 | I22: 46100 | J22: 5064 | K22: 567.1 | L22: =+K22/J22 -> 0.11198657 | M22: 46100 | N22: 8460 | P22: =+O22/N22 -> 0
A23: 46101 | B23: 18230.2 | C23: 1264.9 | D23: =+C23/B23 -> 0.069384867 | E23: 46101 | F23: 6536 | G23: 939.9 | H23: 0 | I23: 46101 | J23: 4935.9 | K23: 326.5 | L23: =+K23/J23 -> 0.066148018 | M23: 46101 | N23: 8610 | O23: 1322.7 | P23: =+O23/N23 -> 0.15362369
A24: 46102 | B24: 33582.8 | C24: 4962.1 | D24: =+C24/B24 -> 0.14775719 | E24: 46102 | F24: 1108 | G24: 1379 | H24: =+G24/F24 -> 1.2445848 | I24: 46102 | J24: 3191 | K24: 231 | L24: =+K24/J24 -> 0.0723911 | M24: 46102 | N24: 8597 | O24: 1353.7 | P24: =+O24/N24 -> 0.15746191
A25: 46103 | B25: 27001.2 | C25: 4408.8 | D25: =+C25/B25 -> 0.16328163 | E25: 46103 | F25: 18344 | G25: 3058.3 | H25: =+G25/F25 -> 0.16671936 | I25: 46103 | J25: 5854.5 | K25: 236.8 | L25: =+K25/J25 -> 0.040447519 | M25: 46103 | N25: 5023 | O25: 1054.4 | P25: =+O25/N25 -> 0.20991439
A26: 46104 | B26: 23048.3 | C26: 3084.5 | D26: =+C26/B26 -> 0.13382766 | E26: 46104 | F26: 32129.5 | G26: 2715.1 | H26: =+G26/F26 -> 0.084504894 | I26: 46104 | J26: 4930 | K26: 237.3 | L26: =+K26/J26 -> 0.048133874 | M26: 46104 | N26: 7883 | O26: 1147 | P26: =+O26/N26 -> 0.14550298
A27: 46105 | B27: 22288.2 | C27: 3503.9 | D27: =+C27/B27 -> 0.15720875 | E27: 46105 | F27: 9159 | G27: 401.9 | H27: =+G27/F27 -> 0.043880336 | I27: 46105 | J27: 7195.2 | K27: 244.8 | L27: =+K27/J27 -> 0.034022682 | M27: 46105 | N27: 9822 | O27: 1588 | P27: =+O27/N27 -> 0.16167787
A28: 46106 | B28: 27320.6 | C28: 4811 | D28: =+C28/B28 -> 0.17609423 | E28: 46106 | F28: 11926.1 | H28: =+G28/F28 -> 0 | I28: 46106 | J28: 6633.8 | K28: 240.1 | L28: =+K28/J28 -> 0.036193434 | M28: 46106 | N28: 11274 | O28: 2202.9 | P28: =+O28/N28 -> 0.19539649
A29: 46107 | B29: 14289.1 | C29: 3667 | D29: =+C29/B29 -> 0.25662918 | E29: 46107 | F29: 2283.5 | G29: 2606.7 | H29: 0 | I29: 46107 | J29: 7076.8 | K29: 271.5 | L29: 0 | M29: 46107 | N29: 5329 | O29: 1271.1 | P29: =+O29/N29 -> 0.23852505
A30: 46108 | B30: 13272.6 | C30: 0 | D30: =+C30/B30 -> 0 | E30: 46108 | F30: 1349.2 | G30: 2996.7 | H30: 0 | I30: 46108 | J30: 6576.4 | K30: 223.6 | L30: =+K30/J30 -> 0.034000365 | M30: 46108 | N30: 8903 | O30: 1479.7 | P30: =+O30/N30 -> 0.1662024
A31: 46109 | B31: 25658.9 | C31: 6665.7 | D31: =+C31/B31 -> 0.25978121 | E31: 46109 | F31: 6765.5 | G31: 2017 | H31: =+G31/F31 -> 0.29813022 | I31: 46109 | J31: 3051.9 | K31: 231.7 | L31: 0 | M31: 46109 | N31: 6447 | O31: 1231.1 | P31: =+O31/N31 -> 0.19095703
A32: 46110 | B32: 24731.8 | C32: 7425.3 | D32: =+C32/B32 -> 0.3002329 | E32: 46110 | F32: 15655 | G32: 1678.5 | H32: 0 | I32: 46110 | J32: 3910.1 | K32: 221.5 | L32: =+K32/J32 -> 0.056648168 | M32: 46110 | N32: 8978 | O32: 1618.1 | P32: =+O32/N32 -> 0.18022945
A33: 46111 | B33: 22532.8 | C33: 4696.7 | D33: 0 | E33: 46111 | F33: 73083 | G33: 1385.8 | H33: 0 | I33: 46111 | J33: 5103.3 | K33: 224.7 | L33: 0 | M33: 46111 | N33: 9920 | O33: 1385.6 | P33: 0
A34: 46112 | B34: 25391.6 | C34: 5773.6 | D34: 0 | E34: 46112 | F34: 6554 | G34: 1960 | H34: 0 | I34: 46112 | J34: 4052 | K34: 261.6 | L34: 0 | M34: 46112 | N34: 9735 | O34: 1567.1 | P34: =+O34/N34 -> 0.16097586
A35: Total | B35: =SUM(B4:B34) -> 575377.1 | C35: =SUM(C4:C34) -> 143713.3 | D35: MB | E35: Total | F35: =SUM(F4:F34) -> 417617.6 | G35: =SUM(G4:G34) -> 53391.9 | H35: MB | I35: Total | J35: =SUM(J4:J34) -> 169465.5 | K35: =SUM(K4:K34) -> 14270.4 | L35: MB | M35: Total | N35: =SUM(N4:N34) -> 293576 | O35: =SUM(O4:O34) -> 40852.6 | P35: MB | XFD35: =SUM(A35:XFC35) -> 1708264.4
B38: ตารางสรุป 1- 31 March 2026
B39: แพลตฟอร์ม | C39: ยอดขาย | D39: ค่าแอด | E39: คิดเป็น%
B40: Tiktok | C40: =+B35 -> 575377.1 | D40: =+C35 -> 143713.3 | E40: =+D40/C40 -> 0.24977237
B41: Facebook | C41: =+F35 -> 417617.6 | D41: =+G35 -> 53391.9 | E41: =+D41/C41 -> 0.12784878
B42: Lazada | C42: =+J35 -> 169465.5 | D42: =+K35 -> 14270.4 | E42: =+D42/C42 -> 0.08420829
B43: Shopee | C43: =+N35 -> 293576 | D43: =+O35 -> 40852.6 | E43: =+D43/C43 -> 0.13915511
...

Sheet เม.ย.
A1: ข้อมูลการยิง ADS ของแผนกออนไลน์ทุกแพลตฟอร์ม April 2026
A2: Tiktok | E2: Facebook | I2: Lazada | M2: Shopee
A3: ว/ด/ป | B3: ยอดขาย | C3: ค่าแอด | D3: คิดเป็น% | E3: ว/ด/ป | F3: ยอดขาย | G3: ค่าแอด | H3: คิดเป็น% | I3: ว/ด/ป | J3: ยอดขาย | K3: ค่าแอด | L3: คิดเป็น% | M3: ว/ด/ป | N3: ยอดขาย | O3: ค่าแอด | P3: คิดเป็น%
A4: 46113 | B4: 31252.9 | C4: 5911.6 | D4: =+C4/B4 -> 0.18915365 | E4: 46113 | F4: 8016 | G4: 1691.8 | H4: =+G4/F4 -> 0.21105289 | I4: 46113 | J4: 3341.1 | K4: 242.1 | L4: =+K4/J4 -> 0.072461165 | M4: 46113 | N4: 14413 | O4: 2263.9 | P4: =+O4/N4 -> 0.15707348
A5: 46114 | B5: 41355.6 | C5: 6477.5 | D5: =+C5/B5 -> 0.15662933 | E5: 46114 | F5: 8849 | G5: 1438.3 | H5: =+G5/F5 -> 0.16253814 | I5: 46114 | J5: 4282.1 | K5: 204.6 | L5: =+K5/J5 -> 0.047780295 | M5: 46114 | N5: 10975 | O5: 1514.8 | P5: =+O5/N5 -> 0.13802278
A6: 46115 | B6: 49064.4 | C6: 7068 | D6: =+C6/B6 -> 0.14405557 | E6: 46115 | F6: 7426 | G6: 2180.3 | H6: =+G6/F6 -> 0.29360356 | I6: 46115 | J6: 5973.9 | K6: 279.5 | L6: =+K6/J6 -> 0.046786856 | M6: 46115 | N6: 14008 | O6: 2241.5 | P6: =+O6/N6 -> 0.16001571
A7: 46116 | B7: 42096 | C7: 7440.7 | D7: =+C7/B7 -> 0.17675551 | E7: 46116 | F7: 3065 | G7: 1466.6 | H7: =+G7/F7 -> 0.47849918 | I7: 46116 | J7: 8549.1 | K7: 332.4 | L7: =+K7/J7 -> 0.038881286 | M7: 46116 | N7: 17796 | O7: 2886.8 | P7: =+O7/N7 -> 0.16221623
A8: 46117 | B8: 30392.5 | C8: 4683 | D8: =+C8/B8 -> 0.15408407 | E8: 46117 | F8: 2620 | G8: 1839.9 | H8: =+G8/F8 -> 0.70225191 | I8: 46117 | J8: 7342.5 | K8: 781.8 | L8: =+K8/J8 -> 0.106476 | M8: 46117 | N8: 17687 | O8: 3335.8 | P8: =+O8/N8 -> 0.1886018
A9: 46118 | B9: 30892.4 | C9: 8347.5 | D9: =+C9/B9 -> 0.27021209 | E9: 46118 | F9: 60640 | G9: 3378.2 | H9: =+G9/F9 -> 0.055709103 | I9: 46118 | J9: 10014.2 | K9: 772.5 | L9: =+K9/J9 -> 0.077140461 | M9: 46118 | N9: 21857 | O9: 3297.9 | P9: =+O9/N9 -> 0.1508853
A10: 46119 | B10: 39961 | C10: 5442.6 | D10: =+C10/B10 -> 0.13619779 | E10: 46119 | F10: 23642 | G10: 3334.3 | H10: =+G10/F10 -> 0.14103291 | I10: 46119 | J10: 7281 | K10: 711.3 | L10: =+K10/J10 -> 0.097692625 | M10: 46119 | N10: 28960 | O10: 3970.8 | P10: =+O10/N10 -> 0.13711326
A11: 46120 | B11: 29413.6 | C11: 5721.1 | D11: =+C11/B11 -> 0.19450526 | E11: 46120 | F11: 3434 | G11: 2331.1 | H11: =+G11/F11 -> 0.67882935 | I11: 46120 | J11: 3936 | K11: 482.3 | L11: =+K11/J11 -> 0.12253557 | M11: 46120 | N11: 26738 | O11: 4484.3 | P11: =+O11/N11 -> 0.16771262
A12: 46121 | B12: 27043.2 | C12: 4956.8 | D12: =+C12/B12 -> 0.18329192 | E12: 46121 | F12: 9580 | G12: 2350.1 | H12: =+G12/F12 -> 0.24531315 | I12: 46121 | J12: 4089.2 | K12: 606.1 | L12: =+K12/J12 -> 0.1482197 | M12: 46121 | N12: 25597 | O12: 4623.4 | P12: =+O12/N12 -> 0.18062273
A13: 46122 | B13: 28426.8 | C13: 4122.8 | D13: =+C13/B13 -> 0.14503215 | E13: 46122 | F13: 9620 | G13: 2588.8 | H13: =+G13/F13 -> 0.26910603 | I13: 46122 | J13: 4955.1 | K13: 551.9 | L13: =+K13/J13 -> 0.11138019 | M13: 46122 | N13: 19767 | O13: 2796.3 | P13: =+O13/N13 -> 0.14146304
A14: 46123 | B14: 13906.6 | C14: 3847.6 | D14: =+C14/B14 -> 0.27667438 | E14: 46123 | F14: 5540 | G14: 2544.5 | H14: =+G14/F14 -> 0.45929603 | I14: 46123 | J14: 8114.4 | K14: 708.5 | L14: =+K14/J14 -> 0.087313911 | M14: 46123 | N14: 17091 | O14: 2808 | P14: =+O14/N14 -> 0.164297
A15: 46124 | B15: 24056.8 | C15: 6663.4 | D15: =+C15/B15 -> 0.27698613 | E15: 46124 | F15: 26089 | G15: 1387.3 | H15: =+G15/F15 -> 0.053175668 | I15: 46124 | J15: 6144.7 | K15: 671.2 | L15: =+K15/J15 -> 0.10923235 | M15: 46124 | N15: 11633 | O15: 1806.2 | P15: =+O15/N15 -> 0.15526519
... A33: 46142 | B33: 6492 | C33: 5393.6 | D33: =+C33/B33 -> 0.83080715 | E33: 46142 | F33: 3230 | G33: 1944.4 | H33: =+G33/F33 -> 0.60198142 | I33: 46142 | J33: 5428.6 | K33: 201.1 | L33: =+K33/J33 -> 0.037044542 | M33: 46142 | N33: 14731 | O33: 3010.8 | P33: =+O33/N33 -> 0.20438531
A34: 46143 | D34: =+C34/B34 -> #DIV/0! | E34: 46143 | H34: =+G34/F34 -> #DIV/0! | I34: 46143 | L34: =+K34/J34 -> #DIV/0! | M34: 46143 | P34: =+O34/N34 -> #DIV/0!
A35: Total | B35: =SUM(B4:B34) -> 716790.9 | C35: =SUM(C4:C34) -> 138044.7 | D35: MB | E35: Total | F35: =SUM(F4:F34) -> 355371 | G35: =SUM(G4:G34) -> 59360.1 | H35: MB | I35: Total | J35: =SUM(J4:J34) -> 169730.5 | K35: =SUM(K4:K34) -> 15728.4 | L35: MB | M35: Total | N35: =SUM(N4:N34) -> 475333 | O35: =SUM(O4:O34) -> 84053.7 | P35: MB | XFD35: =SUM(A35:XFC35) -> 2014412.3
B38: ตารางสรุป 1- 30 April 2026
B39: แพลตฟอร์ม | C39: ยอดขาย | D39: ค่าแอด | E39: คิดเป็น%
B40: Tiktok | C40: =+B35 -> 716790.9 | D40: =+C35 -> 138044.7 | E40: =+D40/C40 -> 0.19258713
B41: Facebook | C41: =+F35 -> 355371 | D41: =+G35 -> 59360.1 | E41: =+D41/C41 -> 0.16703698
B42: Lazada | C42: =+J35 -> 169730.5 | D42: =+K35 -> 15728.4 | E42: =+D42/C42 -> 0.092666904
B43: Shopee | C43: =+N35 -> 475333 | D43: =+O35 -> 84053.7 | E43: =+D43/C43 -> 0.17683119
B44: Total | C44: =SUM(C40:C43) -> 1717225.4 | D44: =SUM(D40:D43) -> 297186.9 | E44: =+D44/C44 -> 0.17306225

Sheet พ.ค.
A1: ข้อมูลการยิง ADS ของแผนกออนไลน์ทุกแพลตฟอร์ม May 2026
A2: Tiktok | E2: Facebook | I2: Lazada | M2: Shopee
A3: ว/ด/ป | B3: ยอดขาย | C3: ค่าแอด | D3: คิดเป็น% | E3: ว/ด/ป | F3: ยอดขาย | G3: ค่าแอด | H3: คิดเป็น% | I3: ว/ด/ป | J3: ยอดขาย | K3: ค่าแอด | L3: คิดเป็น% | M3: ว/ด/ป | N3: ยอดขาย | O3: ค่าแอด | P3: คิดเป็น%
A4: 38838 | B4: 20824.2 | C4: 4956.4 | D4: =+C4/B4 -> 0.23801154 | E4: 38838 | F4: 4030 | G4: 2463.6 | H4: =+G4/F4 -> 0.61131514 | I4: 38838 | J4: 3853.5 | K4: 160 | L4: =+K4/J4 -> 0.041520695 | M4: 38838 | N4: 19424 | O4: 2712.5 | P4: =+O4/N4 -> 0.13964683
A5: 38839 | B5: 24667.8 | C5: 5744.9 | D5: =+C5/B5 -> 0.23289065 | E5: 38839 | F5: 1 | G5: 2932.1 | H5: =+G5/F5 -> 2932.1 | I5: 38839 | J5: 4130.5 | K5: 211.5 | L5: =+K5/J5 -> 0.051204455 | M5: 38839 | N5: 21981 | O5: 2852.8 | P5: =+O5/N5 -> 0.12978481
A6: 38840 | B6: 21834.6 | C6: 5050.8 | D6: =+C6/B6 -> 0.23132093 | E6: 38840 | F6: 12955 | G6: 3136.3 | H6: =+G6/F6 -> 0.24209186 | I6: 38840 | J6: 2851 | K6: 101.2 | L6: =+K6/J6 -> 0.035496317 | M6: 38840 | N6: 10624 | O6: 1668.2 | P6: =+O6/N6 -> 0.15702184
A7: 38841 | B7: 30402.8 | C7: 6867.8 | D7: =+C7/B7 -> 0.22589367 | E7: 38841 | F7: 42783 | G7: 2250.4 | H7: =+G7/F7 -> 0.052600332 | I7: 38841 | J7: 6066.5 | K7: 217.4 | L7: =+K7/J7 -> 0.035836149 | M7: 38841 | N7: 21937 | O7: 3661.5 | P7: =+O7/N7 -> 0.16690979
A8: 38842 | B8: 33558 | C8: 7253.6 | D8: =+C8/B8 -> 0.21615114 | E8: 38842 | F8: 5098 | G8: 3089.1 | H8: =+G8/F8 -> 0.60594351 | I8: 38842 | J8: 4067.3 | K8: 280.3 | L8: =+K8/J8 -> 0.068915497 | M8: 38842 | N8: 12078 | O8: 1965.1 | P8: =+O8/N8 -> 0.16270078
A9: 38843 | B9: 35225.8 | C9: 6138.9 | D9: =+C9/B9 -> 0.17427283 | E9: 38843 | F9: 8643.6 | G9: 2639.5 | H9: =+G9/F9 -> 0.30537045 | I9: 38843 | J9: 4405.1 | K9: 185.6 | L9: =+K9/J9 -> 0.042132982 | M9: 38843 | N9: 8892 | O9: 1991.4 | P9: =+O9/N9 -> 0.22395412
A10: 38844 | B10: 18761.3 | C10: 2698 | D10: =+C10/B10 -> 0.14380667 | E10: 38844 | F10: 15753 | G10: 2572 | H10: =+G10/F10 -> 0.16327049 | I10: 38844 | J10: 2560.1 | K10: 228.8 | L10: =+K10/J10 -> 0.089371509 | M10: 38844 | N10: 8992 | O10: 1853.6 | P10: =+O10/N10 -> 0.20613879
A11: 38845 | B11: 35459.7 | C11: 6285.5 | D11: =+C11/B11 -> 0.17725756 | E11: 38845 | F11: 5026 | G11: 2590.8 | H11: =+G11/F11 -> 0.51547951 | I11: 38845 | J11: 5721.7 | K11: 245.9 | L11: =+K11/J11 -> 0.042976738 | M11: 38845 | N11: 14186 | O11: 2068.9 | P11: =+O11/N11 -> 0.14584097
A12: 38846 | B12: 28890.5 | C12: 5524.9 | D12: =+C12/B12 -> 0.19123587 | E12: 38846 | F12: 199 | G12: 2238.8 | H12: =+G12/F12 -> 11.250251 | I12: 38846 | J12: 3714.2 | K12: 326.7 | L12: =+K12/J12 -> 0.087959722 | M12: 38846 | N12: 14053 | O12: 2076.7 | P12: =+O12/N12 -> 0.14777628
A13: 38847 | B13: 22764 | C13: 3987.2 | D13: =+C13/B13 -> 0.17515375 | E13: 38847 | F13: 23988 | G13: 2516.6 | H13: =+G13/F13 -> 0.10491079 | I13: 38847 | J13: 2601.1 | K13: 226.6 | L13: =+K13/J13 -> 0.087116989 | M13: 38847 | N13: 10632 | O13: 1807.2 | P13: =+O13/N13 -> 0.16997743
A14: 38848 | B14: 20760.3 | C14: 3751.9 | D14: =+C14/B14 -> 0.18072475 | E14: 38848 | F14: 42558 | G14: 2549.7 | H14: =+G14/F14 -> 0.05991118 | I14: 38848 | J14: 6545.9 | K14: 258.4 | L14: =+K14/J14 -> 0.039475091 | M14: 38848 | N14: 13760 | O14: 2243.2 | P14: =+O14/N14 -> 0.16302326
A15: 38849 | B15: 17775.3 | C15: 3240 | D15: =+C15/B15 -> 0.1822754 | E15: 38849 | F15: 8755 | G15: 1792.6 | H15: =+G15/F15 -> 0.20475157 | I15: 38849 | J15: 3993.2 | K15: 445.8 | L15: =+K15/J15 -> 0.11163979 | M15: 38849 | N15: 50797 | O15: 3951.5 | P15: =+O15/N15 -> 0.077790027
... A22: 38856 | B22: 35521.3 | C22: 5592.6 | D22: =+C22/B22 -> 0.15744356 | E22: 38856 | F22: 13696 | G22: 2146 | H22: =+G22/F22 -> 0.15668808 | I22: 38856 | J22: 5490.5 | K22: 560.5 | L22: =+K22/J22 -> 0.10208542 | M22: 38856 | N22: 9356 | O22: 1533.6 | P22: =+O22/N22 -> 0.1639162
A23: 38857 | B23: 22322.3 | C23: 3094.1 | D23: =+C23/B23 -> 0.13861027 | E23: 38857 | F23: 3525 | G23: 1700.9 | H23: 0 | I23: 38857 | J23: 11524.7 | K23: 686.8 | L23: =+K23/J23 -> 0.059593742 | M23: 38857 | N23: 14931 | O23: 2098.8 | P23: =+O23/N23 -> 0.14056661
A24: 38858 | B24: 18281.1 | C24: 2931 | D24: =+C24/B24 -> 0.16032952 | E24: 38858 | F24: 2962 | G24: 1464.3 | H24: =+G24/F24 -> 0.49436192 | I24: 38858 | J24: 6459.8 | K24: 674.8 | L24: =+K24/J24 -> 0.10446144 | M24: 38858 | N24: 7827 | O24: 1409.3 | P24: =+O24/N24 -> 0.18005622
A25: 38859 | B25: 24249.5 | C25: 3802.6 | D25: =+C25/B25 -> 0.15681148 | E25: 38859 | F25: 8803 | G25: 1592.6 | H25: =+G25/F25 -> 0.1809156 | I25: 38859 | J25: 4463.9 | K25: 651.1 | L25: =+K25/J25 -> 0.145859 | M25: 38859 | N25: 17587 | O25: 2697.3 | P25: =+O25/N25 -> 0.15336897
A26: 38860 | B26: 20837.5 | C26: 3252 | D26: =+C26/B26 -> 0.15606479 | E26: 38860 | F26: 1 | G26: 1575.7 | H26: =+G26/F26 -> 1575.7 | I26: 38860 | J26: 5167 | K26: 602 | L26: =+K26/J26 -> 0.11650861 | M26: 38860 | N26: 7734 | O26: 1587.2 | P26: =+O26/N26 -> 0.20522369
A27: 38861 | B27: 31886.7 | C27: 4968.1 | D27: =+C27/B27 -> 0.15580477 | E27: 38861 | F27: 2324 | G27: 1946.2 | H27: =+G27/F27 -> 0.83743546 | I27: 38861 | J27: 5463.3 | K27: 680.4 | L27: =+K27/J27 -> 0.12454011 | M27: 38861 | N27: 11227 | O27: 1516.9 | P27: =+O27/N27 -> 0.13511178
A28: 38862 | B28: 27811.8 | C28: 2979.1 | D28: =+C28/B28 -> 0.1071164 | E28: 38862 | F28: 20347 | G28: 0 | H28: =+G28/F28 -> 0 | I28: 38862 | J28: 5354.4 | K28: 564.6 | L28: =+K28/J28 -> 0.10544599 | M28: 38862 | N28: 22343 | O28: 4349.5 | P28: =+O28/N28 -> 0.19466947
A29: 38863 | B29: 34695.6 | C29: 4202.6 | D29: =+C29/B29 -> 0.12112775 | E29: 38863 | F29: 6547 | G29: 0 | H29: 0 | I29: 38863 | J29: 4652.2 | K29: 443 | L29: 0 | M29: 38863 | N29: 18508 | O29: 3267.4 | P29: =+O29/N29 -> 0.17653987
A30: 38864 | B30: 25360 | C30: 4474.2 | D30: =+C30/B30 -> 0.17642744 | E30: 38864 | F30: 1808 | G30: 0 | H30: 0 | I30: 38864 | J30: 5598 | K30: 631 | L30: =+K30/J30 -> 0.11271883 | M30: 38864 | N30: 11014 | O30: 1604.9 | P30: =+O30/N30 -> 0.14571455
A31: 38865 | B31: 27154 | C31: 3684.8 | D31: =+C31/B31 -> 0.13570008 | E31: 38865 | F31: 9916 | G31: 0 | H31: =+G31/F31 -> 0 | I31: 38865 | J31: 5366.6 | K31: 606.6 | L31: 0 | M31: 38865 | N31: 5830 | O31: 235.9 | P31: =+O31/N31 -> 0.040463122
A32: 38866 | B32: 27772.9 | C32: 3996.3 | D32: =+C32/B32 -> 0.14389207 | E32: 38866 | F32: 4704 | G32: 3290.3 | H32: 0 | I32: 38866 | J32: 2675.5 | K32: 352.1 | L32: =+K32/J32 -> 0.13160157 | M32: 38866 | N32: 7973 | O32: 0 | P32: =+O32/N32 -> 0
A33: 38867 | B33: 25046.3 | C33: 3325.3 | D33: 0 | E33: 38867 | F33: 3620 | G33: 0 | H33: 0 | I33: 38867 | J33: 5465.6 | K33: 343.5 | L33: 0 | M33: 38867 | N33: 10742 | O33: 1387.5 | P33: 0
A34: 38868 | B34: 28088.4 | C34: 3563.3 | D34: 0 | E34: 38868 | F34: 3556 | G34: 0 | H34: 0 | I34: 38868 | J34: 4733.2 | K34: 236.9 | L34: 0 | M34: 38868 | N34: 8986 | O34: 1329.8 | P34: =+O34/N34 -> 0.14798576
A35: Total | B35: =SUM(B4:B34) -> 862076.8 | C35: =SUM(C4:C34) -> 137768.5 | D35: MB | E35: Total | F35: =SUM(F4:F34) -> 319999.6 | G35: =SUM(G4:G34) -> 54928.5 | H35: MB | I35: Total | J35: =SUM(J4:J34) -> 147721.6 | K35: =SUM(K4:K34) -> 12886.9 | L35: MB | M35: Total | N35: =SUM(N4:N34) -> 451365 | O35: =SUM(O4:O34) -> 66090.9 | P35: MB | XFD35: =SUM(A35:XFC35) -> 2052837.8
B38: ตารางสรุป 1- 31 May 2569
B39: แพลตฟอร์ม | C39: ยอดขาย | D39: ค่าแอด | E39: คิดเป็น%
B40: Tiktok | C40: =+B35 -> 862076.8 | D40: =+C35 -> 137768.5 | E40: =+D40/C40 -> 0.15981001
B41: Facebook | C41: =+F35 -> 319999.6 | D41: =+G35 -> 54928.5 | E41: =+D41/C41 -> 0.17165178
B42: Lazada | C42: =+J35 -> 147721.6 | D42: =+K35 -> 12886.9 | E42: =+D42/C42 -> 0.08723775
B43: Shopee | C43: =+N35 -> 451365 | D43: =+O35 -> 66090.9 | E43: =+D43/C43 -> 0.14642451
B44: Total | C44: =SUM(C40:C43) -> 1781163 | D44: =SUM(D40:D43) -> 271674.8 | E44: =+D44/C44 -> 0.15252664

Sheet มิ.ย.
A1: ข้อมูลการยิง ADS ของแผนกออนไลน์ทุกแพลตฟอร์ม เดือนมิถุนายน 2569
A2: Tiktok | E2: Facebook | I2: Lazada | M2: Shopee | Q2: รวมค่าแอดรายวัน | R2: รวมค่าแอดรายวัน | S2: คิดเป็น%
A3: ว/ด/ป | B3: ยอดขาย | C3: ค่าแอด | D3: คิดเป็น% | E3: ว/ด/ป | F3: ยอดขาย | G3: ค่าแอด | H3: คิดเป็น% | I3: ว/ด/ป | J3: ยอดขาย | K3: ค่าแอด | L3: คิดเป็น% | M3: ว/ด/ป | N3: ยอดขาย | O3: ค่าแอด | P3: คิดเป็น%
A4: 46174 | B4: 27936.6 | C4: 3053.8 | D4: =+C4/B4 -> 0.1093118 | E4: 46174 | F4: 24609 | H4: =+G4/F4 -> 0 | I4: 46174 | J4: 4259.3 | K4: 98.9 | L4: =+K4/J4 -> 0.023219778 | M4: 46174 | N4: 15790 | O4: 2000 | P4: =+O4/N4 -> 0.12666244 | Q4: =+B4+F4+J4+N4 -> 72594.9 | R4: =+C4+G4+K4+O4 -> 5152.7 | S4: =+R4/Q4 -> 0.070978815
A5: 46175 | B5: 36011.1 | C5: 4915.3 | D5: =+C5/B5 -> 0.13649403 | E5: 46175 | F5: 3218 | G5: 2452.1 | H5: =+G5/F5 -> 0.76199503 | I5: 46175 | J5: 1403.1 | K5: 94.9 | L5: =+K5/J5 -> 0.067635949 | M5: 46175 | N5: 15118 | O5: 2000 | P5: =+O5/N5 -> 0.13229263 | Q5: =+B5+F5+J5+N5 -> 55750.2 | R5: =+C5+G5+K5+O5 -> 9462.3 | S5: =+R5/Q5 -> 0.16972675
A6: 46176 | B6: 32496.7 | C6: 3273.2 | D6: =+C6/B6 -> 0.10072407 | E6: 46176 | F6: 4126 | G6: 4296.7 | H6: =+G6/F6 -> 1.0413718 | I6: 46176 | J6: 1863.4 | K6: 120.4 | L6: =+K6/J6 -> 0.064613073 | M6: 46176 | N6: 13614 | O6: 2000 | P6: =+O6/N6 -> 0.1469076 | Q6: =+B6+F6+J6+N6 -> 52100.1 | R6: =+C6+G6+K6+O6 -> 9690.3 | S6: =+R6/Q6 -> 0.18599388
A7: 46177 | B7: 37279.8 | C7: 5385.7 | D7: =+C7/B7 -> 0.14446698 | E7: 46177 | F7: 11786 | G7: 2574.8 | H7: =+G7/F7 -> 0.21846258 | I7: 46177 | J7: 5855.8 | K7: 48.8 | L7: =+K7/J7 -> 0.008333618 | M7: 46177 | N7: 6408 | O7: 1033.6 | P7: =+O7/N7 -> 0.16129838 | Q7: =+B7+F7+J7+N7 -> 61329.6 | R7: =+C7+G7+K7+O7 -> 9042.9 | S7: =+R7/Q7 -> 0.14744756
A8: 46178 | B8: 28299.6 | C8: 5228.3 | D8: =+C8/B8 -> 0.18474819 | E8: 46178 | F8: 1467 | H8: =+G8/F8 -> 0 | I8: 46178 | J8: 1944.4 | K8: 93.7 | L8: =+K8/J8 -> 0.048189673 | M8: 46178 | N8: 11020 | O8: 1669.9 | P8: =+O8/N8 -> 0.15153358 | Q8: =+B8+F8+J8+N8 -> 42731 | R8: =+C8+G8+K8+O8 -> 6991.9 | S8: =+R8/Q8 -> 0.16362594
A9: 46179 | B9: 35082.8 | C9: 5837.3 | D9: =+C9/B9 -> 0.16638638 | E9: 46179 | F9: 199 | H9: =+G9/F9 -> 0 | I9: 46179 | J9: 8112.7 | K9: 227.8 | L9: =+K9/J9 -> 0.028079431 | M9: 46179 | N9: 20932 | O9: 2000 | P9: =+O9/N9 -> 0.095547487 | Q9: =+B9+F9+J9+N9 -> 64326.5 | R9: =+C9+G9+K9+O9 -> 8065.1 | S9: =+R9/Q9 -> 0.12537757
A10: 46180 | B10: 43368.2 | C10: 6184.8 | D10: =+C10/B10 -> 0.14261141 | E10: 46180 | F10: 13524 | G10: 1890.3 | H10: =+G10/F10 -> 0.13977374 | I10: 46180 | J10: 6087.8 | K10: 189.9 | L10: =+K10/J10 -> 0.031193535 | M10: 46180 | N10: 14432 | O10: 2000 | P10: =+O10/N10 -> 0.13858093 | Q10: =+B10+F10+J10+N10 -> 77412 | R10: =+C10+G10+K10+O10 -> 10265 | S10: =+R10/Q10 -> 0.13260218
A11: 46181 | B11: 23839.1 | C11: 4637.4 | D11: =+C11/B11 -> 0.19452916 | E11: 46181 | F11: 31585 | G11: 2616 | H11: =+G11/F11 -> 0.082824125 | I11: 46181 | J11: 3516.6 | K11: 104.1 | L11: =+K11/J11 -> 0.029602457 | M11: 46181 | N11: 16028 | O11: 2000 | P11: =+O11/N11 -> 0.12478163 | Q11: =+B11+F11+J11+N11 -> 74968.7 | R11: =+C11+G11+K11+O11 -> 9357.5 | S11: =+R11/Q11 -> 0.12481876
A12: 46182 | B12: 30567.8 | C12: 5634.7 | D12: =+C12/B12 -> 0.1843345 | E12: 46182 | F12: 9680 | G12: 2517.7 | H12: =+G12/F12 -> 0.26009298 | I12: 46182 | J12: 1620.2 | K12: 204.9 | L12: =+K12/J12 -> 0.12646587 | M12: 46182 | N12: 15498 | O12: 2000 | P12: =+O12/N12 -> 0.12904891 | Q12: =+B12+F12+J12+N12 -> 57366 | R12: =+C12+G12+K12+O12 -> 10357.3 | S12: =+R12/Q12 -> 0.18054771
A13: 46183 | B13: 23903.8 | C13: 4741.6 | D13: =+C13/B13 -> 0.19836177 | E13: 46183 | F13: 8833 | G13: 2248.3 | H13: =+G13/F13 -> 0.25453413 | I13: 46183 | J13: 1627.7 | K13: 167.8 | L13: =+K13/J13 -> 0.10309025 | M13: 46183 | N13: 23321 | O13: 2000 | P13: =+O13/N13 -> 0.085759616 | Q13: =+B13+F13+J13+N13 -> 57685.5 | R13: =+C13+G13+K13+O13 -> 9157.7 | S13: =+R13/Q13 -> 0.1587522
A14: 46184 | B14: 24537.5 | C14: 4919.2 | D14: =+C14/B14 -> 0.20047682 | E14: 46184 | F14: 7897 | G14: 42.2 | H14: =+G14/F14 -> 0.0053438014 | I14: 46184 | J14: 2624.9 | K14: 89.8 | L14: =+K14/J14 -> 0.034210827 | M14: 46184 | N14: 18776 | O14: 2000 | P14: =+O14/N14 -> 0.10651896 | Q14: =+B14+F14+J14+N14 -> 53835.4 | R14: =+C14+G14+K14+O14 -> 7051.2 | S14: =+R14/Q14 -> 0.13097702
A15: 46185 | B15: 21059 | C15: 4900.2 | D15: =+C15/B15 -> 0.23268911 | E15: 46185 | F15: 7065 | G15: 7.5 | H15: =+G15/F15 -> 0.0010615711 | I15: 46185 | J15: 2235.1 | K15: 152.5 | L15: =+K15/J15 -> 0.068229609 | M15: 46185 | N15: 14485 | O15: 2000 | P15: =+O15/N15 -> 0.13807387 | Q15: =+B15+F15+J15+N15 -> 44844.1 | R15: =+C15+G15+K15+O15 -> 7060.2 | S15: =+R15/Q15 -> 0.15743877
A16: 46186 | B16: 38200.1 | C16: 7065.2 | D16: =+C16/B16 -> 0.1849524 | E16: 46186 | F16: 215 | G16: 3834 | H16: =+G16/F16 -> 17.832558 | I16: 46186 | J16: 3232.9 | K16: 257.1 | L16: =+K16/J16 -> 0.079526122 | M16: 46186 | N16: 14850 | O16: 2000 | P16: =+O16/N16 -> 0.13468013 | Q16: =+B16+F16+J16+N16 -> 56498 | R16: =+C16+G16+K16+O16 -> 13156.3 | S16: =+R16/Q16 -> 0.23286311
A17: 46187 | B17: 16732.9 | C17: 1659.3 | D17: =+C17/B17 -> 0.099163923 | E17: 46187 | F17: 16284 | G17: 2933.2 | H17: =+G17/F17 -> 0.18012773 | I17: 46187 | J17: 1592.6 | K17: 133.2 | L17: =+K17/J17 -> 0.08363682 | M17: 46187 | N17: 9376 | O17: 1204.9 | P17: =+O17/N17 -> 0.12850896 | Q17: =+B17+F17+J17+N17 -> 43985.5 | R17: =+C17+G17+K17+O17 -> 5930.6 | S17: =+R17/Q17 -> 0.1348308
A18: 46188 | B18: 23632.7 | C18: 2039.2 | D18: =+C18/B18 -> 0.086287221 | E18: 46188 | F18: 26146 | G18: 1923.6 | H18: =+G18/F18 -> 0.073571483 | I18: 46188 | J18: 1481.6 | K18: 120.6 | L18: =+K18/J18 -> 0.081398488 | M18: 46188 | N18: 19441 | O18: 2000 | P18: =+O18/N18 -> 0.10287537 | Q18: =+B18+F18+J18+N18 -> 70701.3 | R18: =+C18+G18+K18+O18 -> 6083.4 | S18: =+R18/Q18 -> 0.08604368
A19: 46189 | B19: 16194.4 | C19: 1378 | D19: =+C19/B19 -> 0.085091143 | E19: 46189 | F19: 5050 | G19: 632.4 | H19: =+G19/F19 -> 0.12522772 | I19: 46189 | J19: 4115.8 | K19: 524.3 | L19: =+K19/J19 -> 0.12738714 | M19: 46189 | N19: 11459 | O19: 1792.4 | P19: =+O19/N19 -> 0.15641854 | Q19: =+B19+F19+J19+N19 -> 36819.2 | R19: =+C19+G19+K19+O19 -> 4327.1 | S19: =+R19/Q19 -> 0.11752292
A20: 46190 | B20: 20850.1 | C20: 2531.3 | D20: =+C20/B20 -> 0.12140469 | E20: 46190 | F20: 839 | G20: 0.1 | H20: =+G20/F20 -> 0.00011918951 | I20: 46190 | J20: 2941.4 | K20: 201.2 | L20: =+K20/J20 -> 0.068402801 | M20: 46190 | N20: 14800 | O20: 2000 | P20: =+O20/N20 -> 0.13513514 | Q20: =+B20+F20+J20+N20 -> 39430.5 | R20: =+C20+G20+K20+O20 -> 4732.6 | S20: =+R20/Q20 -> 0.12002384
A21: 46191 | B21: 19644 | C21: 5379.2 | D21: =+C21/B21 -> 0.27383425 | E21: 46191 | F21: 2078 | H21: =+G21/F21 -> 0 | I21: 46191 | J21: 5277.8 | K21: 160.2 | L21: =+K21/J21 -> 0.030353556 | M21: 46191 | N21: 11725 | O21: 1699.3 | P21: =+O21/N21 -> 0.14492964 | Q21: =+B21+F21+J21+N21 -> 38724.8 | R21: =+C21+G21+K21+O21 -> 7238.7 | S21: =+R21/Q21 -> 0.18692672
A22: 46192 | B22: 20887.7 | C22: 3681.1 | D22: =+C22/B22 -> 0.1762329 | E22: 46192 | F22: 3588 | H22: =+G22/F22 -> 0 | I22: 46192 | J22: 3972 | K22: 457 | L22: =+K22/J22 -> 0.11505539 | M22: 46192 | N22: 18739 | O22: 2000 | P22: =+O22/N22 -> 0.10672928 | Q22: =+B22+F22+J22+N22 -> 47186.7 | R22: =+C22+G22+K22+O22 -> 6138.1 | S22: =+R22/Q22 -> 0.13008115
A23: 46193 | B23: 17212.1 | C23: 3928.5 | D23: =+C23/B23 -> 0.2282406 | E23: 46193 | H23: 0 | I23: 46193 | J23: 2426.4 | K23: 43.1 | L23: =+K23/J23 -> 0.017762941 | M23: 46193 | N23: 5565 | O23: 800 | P23: =+O23/N23 -> 0.14375562 | Q23: =+B23+F23+J23+N23 -> 25203.5 | R23: =+C23+G23+K23+O23 -> 4771.6 | S23: =+R23/Q23 -> 0.18932291
A24: 46194 | B24: 22521.5 | C24: 4171.2 | D24: =+C24/B24 -> 0.18520969 | E24: 46194 | F24: 13723 | H24: =+G24/F24 -> 0 | I24: 46194 | J24: 2228 | K24: 137 | L24: =+K24/J24 -> 0.061490126 | M24: 46194 | N24: 17052 | O24: 2000 | P24: =+O24/N24 -> 0.11728829 | Q24: =+B24+F24+J24+N24 -> 55524.5 | R24: =+C24+G24+K24+O24 -> 6308.2 | S24: =+R24/Q24 -> 0.11361111
A25: 46195 | B25: 21882.8 | C25: 3555.2 | D25: =+C25/B25 -> 0.1624655 | E25: 46195 | G25: 1849.8 | H25: =+G25/F25 -> #DIV/0! | I25: 46195 | J25: 1220.6 | K25: 17.3 | L25: =+K25/J25 -> 0.014173357 | M25: 46195 | N25: 12362 | O25: 2000 | P25: =+O25/N25 -> 0.16178612 | Q25: =+B25+F25+J25+N25 -> 35465.4 | R25: =+C25+G25+K25+O25 -> 7422.3 | S25: =+R25/Q25 -> 0.20928285
A26: 46196 | B26: 25264.4 | C26: 4462.8 | D26: =+C26/B26 -> 0.17664382 | E26: 46196 | F26: 3162 | G26: 2348.9 | H26: =+G26/F26 -> 0.74285262 | I26: 46196 | J26: 1688.4 | K26: 29.8 | L26: =+K26/J26 -> 0.017649846 | M26: 46196 | N26: 29600 | O26: 2000 | P26: =+O26/N26 -> 0.067567568 | Q26: =+B26+F26+J26+N26 -> 59714.8 | R26: =+C26+G26+K26+O26 -> 8841.5 | S26: =+R26/Q26 -> 0.14806212
A27: 46197 | B27: 18583.5 | C27: 3942.7 | D27: =+C27/B27 -> 0.21216133 | E27: 46197 | F27: 1446 | G27: 466.6 | H27: =+G27/F27 -> 0.32268326 | I27: 46197 | J27: 1597.3 | K27: 14.5 | L27: =+K27/J27 -> 0.0090778188 | M27: 46197 | N27: 13615 | O27: 2000 | P27: =+O27/N27 -> 0.1468968 | Q27: =+B27+F27+J27+N27 -> 35241.8 | R27: =+C27+G27+K27+O27 -> 6423.8 | S27: =+R27/Q27 -> 0.18227786
A28: 46198 | B28: 26610.9 | C28: 4555.2 | D28: =+C28/B28 -> 0.17117798 | E28: 46198 | F28: 17511 | H28: =+G28/F28 -> 0 | I28: 46198 | J28: 2286.9 | K28: 24 | L28: =+K28/J28 -> 0.010494556 | M28: 46198 | N28: 18476 | O28: 2000 | P28: =+O28/N28 -> 0.10824854 | Q28: =+B28+F28+J28+N28 -> 64884.8 | R28: =+C28+G28+K28+O28 -> 6579.2 | S28: =+R28/Q28 -> 0.10139817
A29: 46199 | B29: 11340.6 | C29: 653.7 | D29: =+C29/B29 -> 0.057642453 | E29: 46199 | F29: 3243 | H29: 0 | I29: 46199 | J29: 1379.1 | K29: 16.3 | L29: 0 | M29: 46199 | N29: 10998 | O29: 938 | P29: =+O29/N29 -> 0.085288234 | Q29: =+B29+F29+J29+N29 -> 26960.7 | R29: =+C29+G29+K29+O29 -> 1608 | S29: =+R29/Q29 -> 0.059642368
A30: 46200 | B30: 12611.7 | C30: 4.8 | D30: =+C30/B30 -> 0.00038059897 | E30: 46200 | F30: 8945.2 | H30: 0 | I30: 46200 | J30: 556.1 | K30: 28.9 | L30: =+K30/J30 -> 0.05196907 | M30: 46200 | N30: 4434 | P30: =+O30/N30 -> 0 | Q30: =+B30+F30+J30+N30 -> 26547 | R30: =+C30+G30+K30+O30 -> 33.7 | S30: =+R30/Q30 -> 0.0012694466
A31: 46201 | B31: 8368.2 | C31: 1.5 | D31: =+C31/B31 -> 0.00017925002 | E31: 46201 | F31: 7385 | H31: =+G31/F31 -> 0 | I31: 46201 | J31: 1139.9 | K31: 17.5 | L31: 0 | M31: 46201 | N31: 6326 | P31: =+O31/N31 -> 0 | Q31: =+B31+F31+J31+N31 -> 23219.1 | R31: =+C31+G31+K31+O31 -> 19 | S31: =+R31/Q31 -> 0.00081829184
A32: 46202 | B32: 10750.4 | C32: 0.7 | D32: =+C32/B32 -> 6.5113856e-05 | E32: 46202 | F32: 27540 | H32: 0 | I32: 46202 | J32: 2291.3 | K32: 7 | L32: =+K32/J32 -> 0.0030550343 | M32: 46202 | N32: 2870 | P32: =+O32/N32 -> 0 | Q32: =+B32+F32+J32+N32 -> 43451.7 | R32: =+C32+G32+K32+O32 -> 7.7 | S32: =+R32/Q32 -> 0.00017720826
A33: 46203 | B33: 27782.4 | C33: 5422.6 | D33: 0 | E33: 46203 | F33: 4850 | H33: 0 | I33: 46203 | J33: 2223.4 | K33: 20.2 | L33: 0 | M33: 46203 | N33: 4262 | P33: 0 | Q33: =+B33+F33+J33+N33 -> 39117.8 | R33: =+C33+G33+K33+O33 -> 5442.8 | S33: =+R33/Q33 -> 0.1391387
A34: 46204 | D34: 0 | E34: 46204 | H34: 0 | I34: 46204 | L34: 0 | M34: 46204 | P34: =+O34/N34 -> #DIV/0! | Q34: =+B34+F34+J34+N34 -> 0 | R34: =+C34+G34+K34+O34 -> 0
A35: Total | B35: =SUM(B4:B34) -> 723452.4 | C35: =SUM(C4:C34) -> 113143.7 | D35: บาท | E35: Total | F35: =SUM(F4:F34) -> 265994.2 | G35: =SUM(G4:G34) -> 32634.2 | H35: บาท | I35: Total | J35: =SUM(J4:J34) -> 82802.5 | K35: =SUM(K4:K34) -> 3802.7 | L35: บาท | M35: Total | N35: =SUM(N4:N34) -> 411372 | O35: =SUM(O4:O34) -> 47138.1 | P35: บาท | Q35: =SUM(Q4:Q34) -> 1483621.1 | R35: =SUM(R4:R34) -> 196718.7 | S35: บาท | XFD35: =SUM(A35:XFC35) -> 3360679.6
B38: ตารางสรุป 1- 30 มิถุนายน 2569
B39: แพลตฟอร์ม | C39: ยอดขาย | D39: ค่าแอด | E39: คิดเป็น%
B40: Tiktok | C40: =+B35 -> 723452.4 | D40: =+C35 -> 113143.7 | E40: =+D40/C40 -> 0.15639412
B41: Facebook | C41: =+F35 -> 265994.2 | D41: =+G35 -> 32634.2 | E41: =+D41/C41 -> 0.12268764
B42: Lazada | C42: =+J35 -> 82802.5 | D42: =+K35 -> 3802.7 | E42: =+D42/C42 -> 0.045924942
...

Sheet ก.ค.
A1: ข้อมูลการยิง ADS ของแผนกออนไลน์ทุกแพลตฟอร์ม เดือนกรกฏาคม 2569
A2: Tiktok | E2: Facebook | I2: Lazada | M2: Shopee
A3: ว/ด/ป | B3: ยอดขาย | C3: ค่าแอด | D3: คิดเป็น% | E3: ว/ด/ป | F3: ยอดขาย | G3: ค่าแอด | H3: คิดเป็น% | I3: ว/ด/ป | J3: ยอดขาย | K3: ค่าแอด | L3: คิดเป็น% | M3: ว/ด/ป | N3: ยอดขาย | O3: ค่าแอด | P3: คิดเป็น%
A4: 46204 | D4: =+C4/B4 -> #DIV/0! | E4: 46204 | H4: =+G4/F4 -> #DIV/0! | I4: 46204 | L4: =+K4/J4 -> #DIV/0! | M4: 46204 | P4: =+O4/N4 -> #DIV/0!
A5: 46205 | D5: =+C5/B5 -> #DIV/0! | E5: 46205 | H5: =+G5/F5 -> #DIV/0! | I5: 46205 | L5: =+K5/J5 -> #DIV/0! | M5: 46205 | P5: =+O5/N5 -> #DIV/0!
A6: 46206 | D6: =+C6/B6 -> #DIV/0! | E6: 46206 | H6: =+G6/F6 -> #DIV/0! | I6: 46206 | L6: =+K6/J6 -> #DIV/0! | M6: 46206 | P6: =+O6/N6 -> #DIV/0!
A7: 46207 | D7: =+C7/B7 -> #DIV/0! | E7: 46207 | H7: =+G7/F7 -> #DIV/0! | I7: 46207 | L7: =+K7/J7 -> #DIV/0! | M7: 46207 | P7: =+O7/N7 -> #DIV/0!
A8: 46208 | D8: =+C8/B8 -> #DIV/0! | E8: 46208 | H8: =+G8/F8 -> #DIV/0! | I8: 46208 | L8: =+K8/J8 -> #DIV/0! | M8: 46208 | P8: =+O8/N8 -> #DIV/0!
A9: 46209 | D9: =+C9/B9 -> #DIV/0! | E9: 46209 | H9: =+G9/F9 -> #DIV/0! | I9: 46209 | L9: =+K9/J9 -> #DIV/0! | M9: 46209 | P9: =+O9/N9 -> #DIV/0!
A10: 46210 | D10: =+C10/B10 -> #DIV/0! | E10: 46210 | H10: =+G10/F10 -> #DIV/0! | I10: 46210 | L10: =+K10/J10 -> #DIV/0! | M10: 46210 | P10: =+O10/N10 -> #DIV/0!
A11: 46211 | D11: =+C11/B11 -> #DIV/0! | E11: 46211 | H11: =+G11/F11 -> #DIV/0! | I11: 46211 | L11: =+K11/J11 -> #DIV/0! | M11: 46211 | P11: =+O11/N11 -> #DIV/0!
A12: 46212 | D12: =+C12/B12 -> #DIV/0! | E12: 46212 | H12: =+G12/F12 -> #DIV/0! | I12: 46212 | L12: =+K12/J12 -> #DIV/0! | M12: 46212 | P12: =+O12/N12 -> #DIV/0!
A13: 46213 | D13: =+C13/B13 -> #DIV/0! | E13: 46213 | H13: =+G13/F13 -> #DIV/0! | I13: 46213 | L13: =+K13/J13 -> #DIV/0! | M13: 46213 | P13: =+O13/N13 -> #DIV/0!
A14: 46214 | D14: =+C14/B14 -> #DIV/0! | E14: 46214 | H14: =+G14/F14 -> #DIV/0! | I14: 46214 | L14: =+K14/J14 -> #DIV/0! | M14: 46214 | P14: =+O14/N14 -> #DIV/0!
A15: 46215 | D15: =+C15/B15 -> #DIV/0! | E15: 46215 | H15: =+G15/F15 -> #DIV/0! | I15: 46215 | L15: =+K15/J15 -> #DIV/0! | M15: 46215 | P15: =+O15/N15 -> #DIV/0!
... A22: 46222 | D22: =+C22/B22 -> #DIV/0! | E22: 46222 | H22: =+G22/F22 -> #DIV/0! | I22: 46222 | L22: =+K22/J22 -> #DIV/0! | M22: 46222 | P22: =+O22/N22 -> #DIV/0!
A23: 46223 | D23: =+C23/B23 -> #DIV/0! | E23: 46223 | H23: 0 | I23: 46223 | L23: =+K23/J23 -> #DIV/0! | M23: 46223 | P23: =+O23/N23 -> #DIV/0!
A24: 46224 | D24: =+C24/B24 -> #DIV/0! | E24: 46224 | H24: =+G24/F24 -> #DIV/0! | I24: 46224 | L24: =+K24/J24 -> #DIV/0! | M24: 46224 | P24: =+O24/N24 -> #DIV/0!
A25: 46225 | D25: =+C25/B25 -> #DIV/0! | E25: 46225 | H25: =+G25/F25 -> #DIV/0! | I25: 46225 | L25: =+K25/J25 -> #DIV/0! | M25: 46225 | P25: =+O25/N25 -> #DIV/0!
