Workbook

Sheet ALL
A1: รายการขายสินค้าออนไลน์แยกจำนวนชิ้นรายวัน เดือนกุมภาพันธ์ 2569
D2: =SUBTOTAL(9,D5:D10195) -> 40782 | E2: =SUBTOTAL(9,E5:E10195) -> 0 | F2: =SUBTOTAL(9,F5:F10195) -> 1018152.5 | G2: =SUBTOTAL(9,G5:G10195) -> 880 | H2: =SUBTOTAL(9,H5:H10195) -> 0 | I2: =SUBTOTAL(9,I5:I10195) -> 17152.89 | J2: =SUBTOTAL(9,J5:J10195) -> 1097 | K2: =SUBTOTAL(9,K5:K10195) -> 0 | ... CX2: =SUBTOTAL(9,CX5:CX10195) -> 1018152.5
A3: รหัสสินค้า | B3: ชื่อสินค้า | C3: ราคาต้นทุน | D3: เดือนกุมภาพันธ์ | G3: 244381 | J3: 244382 | M3: 244383 | P3: 244384 | S3: 244385 | V3: 244386 | Y3: 244387 | AB3: 244388 | AE3: 244389 | AH3: 244390 | AK3: 244391 | AN3: 244392 | AQ3: 244393 | AT3: 244394 | AW3: 244395 | AZ3: 244396 | BC3: 244397 | BF3: 244398 | BI3: 244399 | BL3: 244400 | BO3: 244401 | BR3: 244402 | BU3: 244403 | BX3: 244404 | CA3: 244405 | CD3: 244406 | CG3: 244407 | CJ3: 244408 | CM3: 244409 | CP3: 244410 | CS3: 244411 | CV3: สรุป
D4: จำนวน | E4: หน่วย | F4: ยอดต้นทุน/วัน | G4: จำนวน | H4: หน่วย | I4: ยอดต้นทุน/วัน | J4: จำนวน | K4: หน่วย | L4: ยอดต้นทุน/วัน | M4: จำนวน | N4: หน่วย | O4: ยอดต้นทุน/วัน | P4: จำนวน | Q4: หน่วย | R4: ยอดต้นทุน/วัน | S4: จำนวน | T4: หน่วย | U4: ยอดต้นทุน/วัน | V4: จำนวน | W4: หน่วย | X4: ยอดต้นทุน/วัน | Y4: จำนวน | Z4: หน่วย | AA4: ยอดต้นทุน/วัน | AB4: จำนวน | AC4: หน่วย | AD4: ยอดต้นทุน/วัน | AE4: จำนวน | AF4: หน่วย | AG4: ยอดต้นทุน/วัน | AH4: จำนวน | AI4: หน่วย | AJ4: ยอดต้นทุน/วัน | AK4: จำนวน | AL4: หน่วย | AM4: ยอดต้นทุน/วัน | AN4: จำนวน | AO4: หน่วย | AP4: ยอดต้นทุน/วัน | AQ4: จำนวน | AR4: หน่วย | AS4: ยอดต้นทุน/วัน | AT4: จำนวน | AU4: หน่วย | AV4: ยอดต้นทุน/วัน | AW4: จำนวน | AX4: หน่วย | AY4: ยอดต้นทุน/วัน | AZ4: จำนวน | BA4: หน่วย | BB4: ยอดต้นทุน/วัน | BC4: จำนวน | BD4: หน่วย | BE4: ยอดต้นทุน/วัน | BF4: จำนวน | BG4: หน่วย | BH4: ยอดต้นทุน/วัน | BI4: จำนวน | BJ4: หน่วย | BK4: ยอดต้นทุน/วัน | BL4: จำนวน | BM4: หน่วย | BN4: ยอดต้นทุน/วัน | BO4: จำนวน | BP4: หน่วย | BQ4: ยอดต้นทุน/วัน | BR4: จำนวน | BS4: หน่วย | BT4: ยอดต้นทุน/วัน | BU4: จำนวน | BV4: หน่วย | BW4: ยอดต้นทุน/วัน | BX4: จำนวน | BY4: หน่วย | BZ4: ยอดต้นทุน/วัน | CA4: จำนวน | CB4: หน่วย | CC4: ยอดต้นทุน/วัน | CD4: จำนวน | CE4: หน่วย | CF4: ยอดต้นทุน/วัน | CG4: จำนวน | CH4: หน่วย | CI4: ยอดต้นทุน/วัน | CJ4: จำนวน | CK4: หน่วย | CL4: ยอดต้นทุน/วัน | CM4: จำนวน | CN4: หน่วย | CO4: ยอดต้นทุน/วัน | CP4: จำนวน | CQ4: หน่วย | CR4: ยอดต้นทุน/วัน | CS4: จำนวน | CT4: หน่วย | CU4: ยอดต้นทุน/วัน | CV4: จำนวน | CW4: หน่วย | CX4: ยอดต้นทุน/วัน
A5: 1004055 | B5: ชิฟฟ่อน รวมรส 1กล่อง4ชิ้น | C5: 18.2 | D5: =+CV5 -> 5936 | E5: กล่อง | F5: =+D5*C5 -> 108035.2 | G5: =VLOOKUP(A5,'1'!B:BA,52,0) -> 0 | H5: กล่อง | I5: =+G5*C5 -> 0 | J5: =VLOOKUP(A5,'2'!B:BA,52,0) -> 0 | K5: กล่อง | L5: =+J5*C5 -> 0 | M5: =VLOOKUP(A5,'3'!B:BA,52,0) -> 0 | N5: กล่อง | O5: =+M5*C5 -> 0 | P5: =VLOOKUP(A5,'4'!B:BA,52,0) -> 20 | Q5: กล่อง | R5: =+P5*C5 -> 364 | S5: =VLOOKUP(A5,'5'!B:BA,52,0) -> 0 | T5: กล่อง | U5: =+S5*C5 -> 0 | V5: =VLOOKUP(A5,'6'!B:BA,52,0) -> 30 | W5: กล่อง | X5: =+V5*C5 -> 546 | Y5: =VLOOKUP(A5,'7'!B:BA,52,0) -> 0 | Z5: กล่อง | AA5: =+Y5*C5 -> 0 | AB5: =VLOOKUP(A5,'8'!B:BA,52,0) -> 0 | AC5: กล่อง | AD5: =+AB5*C5 -> 0 | AE5: =VLOOKUP(A5,'9'!B:BA,52,0) -> 0 | AF5: กล่อง | AG5: =+AE5*C5 -> 0 | AH5: =VLOOKUP(A5,'10'!B:BA,52,0) -> 0 | AI5: กล่อง | AJ5: =+AH5*C5 -> 0 | AK5: =VLOOKUP(A5,'11'!B:BA,52,0) -> 0 | AL5: กล่อง | AM5: =+AK5*C5 -> 0 | AN5: =VLOOKUP(A5,'12'!B:BA,52,0) -> 0 | AO5: กล่อง | AP5: =+AN5*C5 -> 0 | AQ5: =VLOOKUP(A5,'13'!B:BA,52,0) -> 5 | AR5: กล่อง | AS5: =+AQ5*C5 -> 91 | AT5: =VLOOKUP(A5,'14'!B:BA,52,0) -> 0 | AU5: กล่อง | AV5: =+AT5*C5 -> 0 | AW5: =VLOOKUP(A5,'15'!B:BA,52,0) -> 0 | AX5: กล่อง | AY5: =+AW5*C5 -> 0 | AZ5: =VLOOKUP(A5,'16'!B:BA,52,0) -> 10 | BA5: กล่อง | BB5: =+AZ5*C5 -> 182 | BC5: =VLOOKUP(A5,'17'!B:BA,52,0) -> 0 | BD5: กล่อง | BE5: =+BC5*C5 -> 0 | BF5: =VLOOKUP(A5,'18'!B:BA,52,0) -> 20 | BG5: กล่อง | BH5: =+BF5*C5 -> 364 | BI5: =VLOOKUP(A5,'19'!B:BA,52,0) -> 0 | BJ5: กล่อง | BK5: =+BI5*C5 -> 0 | BL5: =VLOOKUP(A5,'20'!B:BA,52,0) -> 35 | BM5: กล่อง | BN5: =+BL5*C5 -> 637 | BO5: =VLOOKUP(A5,'21'!B:BA,52,0) -> 0 | BP5: กล่อง | BQ5: =+BO5*C5 -> 0 | BR5: =VLOOKUP(A5,'22'!B:BA,52,0) -> 0 | BS5: กล่อง | BT5: =+BR5*C5 -> 0 | BU5: =VLOOKUP(A5,'23'!B:BA,52,0) -> 0 | BV5: กล่อง | BW5: =+BU5*C5 -> 0 | BX5: =VLOOKUP(A5,'24'!B:BA,52,0) -> 5810 | BY5: กล่อง | BZ5: =+BX5*C5 -> 105742 | CA5: =VLOOKUP(A5,'25'!B:BA,52,0) -> 0 | CB5: กล่อง | CC5: =+CA5*C5 -> 0 | CD5: =VLOOKUP(A5,'26'!B:BA,52,0) -> 0 | CE5: กล่อง | CF5: =+CD5*C5 -> 0 | CG5: =VLOOKUP(A5,'27'!B:BA,52,0) -> 6 | CH5: กล่อง | CI5: =+CG5*C5 -> 109.2 | CJ5: =VLOOKUP(A5,'28'!B:BA,52,0) -> 0 | CK5: กล่อง | CL5: =+CJ5*C5 -> 0 | CM5: =VLOOKUP(A5,'29'!B:BA,52,0) -> 0 | CN5: กล่อง | CO5: =+CM5*C5 -> 0 | CP5: =VLOOKUP(A5,'30'!B:BA,52,0) -> 0 | CQ5: กล่อง | CR5: =+CP5*C5 -> 0 | CS5: =VLOOKUP(A5,'31'!B:BA,52,0) -> 0 | CT5: กล่อง | CU5: =+CS5*C5 -> 0 | CV5: =VLOOKUP(A5,สรุป!B:BA,52,0) -> 5936 | CW5: กล่อง | CX5: =+CV5*C5 -> 108035.2
A6: 1100001 | B6: ทาร์ตสับปะรดแบบชิ้น อร่อยนุ่ม (1 ชิ้น) | C6: 0 | D6: =+CV6 -> 0 | E6: ชิ้น | F6: =+D6*C6 -> 0 | G6: =VLOOKUP(A6,'1'!B:BA,52,0) -> 0 | H6: ชิ้น | I6: =+G6*C6 -> 0 | J6: =VLOOKUP(A6,'2'!B:BA,52,0) -> 0 | K6: ชิ้น | L6: =+J6*C6 -> 0 | M6: =VLOOKUP(A6,'3'!B:BA,52,0) -> 0 | N6: ชิ้น | O6: =+M6*C6 -> 0 | P6: =VLOOKUP(A6,'4'!B:BA,52,0) -> 0 | Q6: ชิ้น | R6: =+P6*C6 -> 0 | S6: =VLOOKUP(A6,'5'!B:BA,52,0) -> 0 | T6: ชิ้น | U6: =+S6*C6 -> 0 | V6: =VLOOKUP(A6,'6'!B:BA,52,0) -> 0 | W6: ชิ้น | X6: =+V6*C6 -> 0 | Y6: =VLOOKUP(A6,'7'!B:BA,52,0) -> 0 | Z6: ชิ้น | AA6: =+Y6*C6 -> 0 | AB6: =VLOOKUP(A6,'8'!B:BA,52,0) -> 0 | AC6: ชิ้น | AD6: =+AB6*C6 -> 0 | AE6: =VLOOKUP(A6,'9'!B:BA,52,0) -> 0 | AF6: ชิ้น | AG6: =+AE6*C6 -> 0 | AH6: =VLOOKUP(A6,'10'!B:BA,52,0) -> 0 | AI6: ชิ้น | AJ6: =+AH6*C6 -> 0 | AK6: =VLOOKUP(A6,'11'!B:BA,52,0) -> 0 | AL6: ชิ้น | AM6: =+AK6*C6 -> 0 | AN6: =VLOOKUP(A6,'12'!B:BA,52,0) -> 0 | AO6: ชิ้น | AP6: =+AN6*C6 -> 0 | AQ6: =VLOOKUP(A6,'13'!B:BA,52,0) -> 0 | AR6: ชิ้น | AS6: =+AQ6*C6 -> 0 | AT6: =VLOOKUP(A6,'14'!B:BA,52,0) -> 0 | AU6: ชิ้น | AV6: =+AT6*C6 -> 0 | AW6: =VLOOKUP(A6,'15'!B:BA,52,0) -> 0 | AX6: ชิ้น | AY6: =+AW6*C6 -> 0 | AZ6: =VLOOKUP(A6,'16'!B:BA,52,0) -> 0 | BA6: ชิ้น | BB6: =+AZ6*C6 -> 0 | BC6: =VLOOKUP(A6,'17'!B:BA,52,0) -> 0 | BD6: ชิ้น | BE6: =+BC6*C6 -> 0 | BF6: =VLOOKUP(A6,'18'!B:BA,52,0) -> 0 | BG6: ชิ้น | BH6: =+BF6*C6 -> 0 | BI6: =VLOOKUP(A6,'19'!B:BA,52,0) -> 0 | BJ6: ชิ้น | BK6: =+BI6*C6 -> 0 | BL6: =VLOOKUP(A6,'20'!B:BA,52,0) -> 0 | BM6: ชิ้น | BN6: =+BL6*C6 -> 0 | BO6: =VLOOKUP(A6,'21'!B:BA,52,0) -> 0 | BP6: ชิ้น | BQ6: =+BO6*C6 -> 0 | BR6: =VLOOKUP(A6,'22'!B:BA,52,0) -> 0 | BS6: ชิ้น | BT6: =+BR6*C6 -> 0 | BU6: =VLOOKUP(A6,'23'!B:BA,52,0) -> 0 | BV6: ชิ้น | BW6: =+BU6*C6 -> 0 | BX6: =VLOOKUP(A6,'24'!B:BA,52,0) -> 0 | BY6: ชิ้น | BZ6: =+BX6*C6 -> 0 | CA6: =VLOOKUP(A6,'25'!B:BA,52,0) -> 0 | CB6: ชิ้น | CC6: =+CA6*C6 -> 0 | CD6: =VLOOKUP(A6,'26'!B:BA,52,0) -> 0 | CE6: ชิ้น | CF6: =+CD6*C6 -> 0 | CG6: =VLOOKUP(A6,'27'!B:BA,52,0) -> 0 | CH6: ชิ้น | CI6: =+CG6*C6 -> 0 | CJ6: =VLOOKUP(A6,'28'!B:BA,52,0) -> 0 | CK6: ชิ้น | CL6: =+CJ6*C6 -> 0 | CM6: =VLOOKUP(A6,'29'!B:BA,52,0) -> 0 | CN6: ชิ้น | CO6: =+CM6*C6 -> 0 | CP6: =VLOOKUP(A6,'30'!B:BA,52,0) -> 0 | CQ6: ชิ้น | CR6: =+CP6*C6 -> 0 | CS6: =VLOOKUP(A6,'31'!B:BA,52,0) -> 0 | CT6: ชิ้น | CU6: =+CS6*C6 -> 0 | CV6: =VLOOKUP(A6,สรุป!B:BA,52,0) -> 0 | CW6: ชิ้น | CX6: =+CV6*C6 -> 0
A7: 1100002 | B7: ทาร์ตสับปะรด (ทาร์ตสับปะรดกล่อง 4 ชิ้น) | C7: 0 | D7: =+CV7 -> 18 | E7: กล่อง | F7: =+D7*C7 -> 0 | G7: =VLOOKUP(A7,'1'!B:BA,52,0) -> 0 | H7: กล่อง | I7: =+G7*C7 -> 0 | J7: =VLOOKUP(A7,'2'!B:BA,52,0) -> 0 | K7: กล่อง | L7: =+J7*C7 -> 0 | M7: =VLOOKUP(A7,'3'!B:BA,52,0) -> 0 | N7: กล่อง | O7: =+M7*C7 -> 0 | P7: =VLOOKUP(A7,'4'!B:BA,52,0) -> 5 | Q7: กล่อง | R7: =+P7*C7 -> 0 | S7: =VLOOKUP(A7,'5'!B:BA,52,0) -> 3 | T7: กล่อง | U7: =+S7*C7 -> 0 | V7: =VLOOKUP(A7,'6'!B:BA,52,0) -> 0 | W7: กล่อง | X7: =+V7*C7 -> 0 | Y7: =VLOOKUP(A7,'7'!B:BA,52,0) -> 0 | Z7: กล่อง | AA7: =+Y7*C7 -> 0 | AB7: =VLOOKUP(A7,'8'!B:BA,52,0) -> 0 | AC7: กล่อง | AD7: =+AB7*C7 -> 0 | AE7: =VLOOKUP(A7,'9'!B:BA,52,0) -> 0 | AF7: กล่อง | AG7: =+AE7*C7 -> 0 | AH7: =VLOOKUP(A7,'10'!B:BA,52,0) -> 0 | AI7: กล่อง | AJ7: =+AH7*C7 -> 0 | AK7: =VLOOKUP(A7,'11'!B:BA,52,0) -> 0 | AL7: กล่อง | AM7: =+AK7*C7 -> 0 | AN7: =VLOOKUP(A7,'12'!B:BA,52,0) -> 0 | AO7: กล่อง | AP7: =+AN7*C7 -> 0 | AQ7: =VLOOKUP(A7,'13'!B:BA,52,0) -> 0 | AR7: กล่อง | AS7: =+AQ7*C7 -> 0 | AT7: =VLOOKUP(A7,'14'!B:BA,52,0) -> 0 | AU7: กล่อง | AV7: =+AT7*C7 -> 0 | AW7: =VLOOKUP(A7,'15'!B:BA,52,0) -> 0 | AX7: กล่อง | AY7: =+AW7*C7 -> 0 | AZ7: =VLOOKUP(A7,'16'!B:BA,52,0) -> 10 | BA7: กล่อง | BB7: =+AZ7*C7 -> 0 | BC7: =VLOOKUP(A7,'17'!B:BA,52,0) -> 0 | BD7: กล่อง | BE7: =+BC7*C7 -> 0 | BF7: =VLOOKUP(A7,'18'!B:BA,52,0) -> 0 | BG7: กล่อง | BH7: =+BF7*C7 -> 0 | BI7: =VLOOKUP(A7,'19'!B:BA,52,0) -> 0 | BJ7: กล่อง | BK7: =+BI7*C7 -> 0 | BL7: =VLOOKUP(A7,'20'!B:BA,52,0) -> 0 | BM7: กล่อง | BN7: =+BL7*C7 -> 0 | BO7: =VLOOKUP(A7,'21'!B:BA,52,0) -> 0 | BP7: กล่อง | BQ7: =+BO7*C7 -> 0 | BR7: =VLOOKUP(A7,'22'!B:BA,52,0) -> 0 | BS7: กล่อง | BT7: =+BR7*C7 -> 0 | BU7: =VLOOKUP(A7,'23'!B:BA,52,0) -> 0 | BV7: กล่อง | BW7: =+BU7*C7 -> 0 | BX7: =VLOOKUP(A7,'24'!B:BA,52,0) -> 0 | BY7: กล่อง | BZ7: =+BX7*C7 -> 0 | CA7: =VLOOKUP(A7,'25'!B:BA,52,0) -> 0 | CB7: กล่อง | CC7: =+CA7*C7 -> 0 | CD7: =VLOOKUP(A7,'26'!B:BA,52,0) -> 0 | CE7: กล่อง | CF7: =+CD7*C7 -> 0 | CG7: =VLOOKUP(A7,'27'!B:BA,52,0) -> 0 | CH7: กล่อง | CI7: =+CG7*C7 -> 0 | CJ7: =VLOOKUP(A7,'28'!B:BA,52,0) -> 0 | CK7: กล่อง | CL7: =+CJ7*C7 -> 0 | CM7: =VLOOKUP(A7,'29'!B:BA,52,0) -> 0 | CN7: กล่อง | CO7: =+CM7*C7 -> 0 | CP7: =VLOOKUP(A7,'30'!B:BA,52,0) -> 0 | CQ7: กล่อง | CR7: =+CP7*C7 -> 0 | CS7: =VLOOKUP(A7,'31'!B:BA,52,0) -> 0 | CT7: กล่อง | CU7: =+CS7*C7 -> 0 | CV7: =VLOOKUP(A7,สรุป!B:BA,52,0) -> 18 | CW7: กล่อง | CX7: =+CV7*C7 -> 0
A8: 1111001 | B8: ชิฟฟอนไม่มีไส้เเบบเเยกชิ้น เลือกรสชาติได้ (คละรส) | C8: 0 | D8: =+CV8 -> 1212 | E8: ชิ้น | F8: =+D8*C8 -> 0 | G8: =VLOOKUP(A8,'1'!B:BA,52,0) -> 0 | H8: ชิ้น | I8: =+G8*C8 -> 0 | J8: =VLOOKUP(A8,'2'!B:BA,52,0) -> 100 | K8: ชิ้น | L8: =+J8*C8 -> 0 | M8: =VLOOKUP(A8,'3'!B:BA,52,0) -> 10 | N8: ชิ้น | O8: =+M8*C8 -> 0 | P8: =VLOOKUP(A8,'4'!B:BA,52,0) -> 130 | Q8: ชิ้น | R8: =+P8*C8 -> 0 | S8: =VLOOKUP(A8,'5'!B:BA,52,0) -> 90 | T8: ชิ้น | U8: =+S8*C8 -> 0 | V8: =VLOOKUP(A8,'6'!B:BA,52,0) -> 20 | W8: ชิ้น | X8: =+V8*C8 -> 0 | Y8: =VLOOKUP(A8,'7'!B:BA,52,0) -> 140 | Z8: ชิ้น | AA8: =+Y8*C8 -> 0 | AB8: =VLOOKUP(A8,'8'!B:BA,52,0) -> 0 | AC8: ชิ้น | AD8: =+AB8*C8 -> 0 | AE8: =VLOOKUP(A8,'9'!B:BA,52,0) -> 190 | AF8: ชิ้น | AG8: =+AE8*C8 -> 0 | AH8: =VLOOKUP(A8,'10'!B:BA,52,0) -> 30 | AI8: ชิ้น | AJ8: =+AH8*C8 -> 0 | AK8: =VLOOKUP(A8,'11'!B:BA,52,0) -> 0 | AL8: ชิ้น | AM8: =+AK8*C8 -> 0 | AN8: =VLOOKUP(A8,'12'!B:BA,52,0) -> 10 | AO8: ชิ้น | AP8: =+AN8*C8 -> 0 | AQ8: =VLOOKUP(A8,'13'!B:BA,52,0) -> 40 | AR8: ชิ้น | AS8: =+AQ8*C8 -> 0 | AT8: =VLOOKUP(A8,'14'!B:BA,52,0) -> 0 | AU8: ชิ้น | AV8: =+AT8*C8 -> 0 | AW8: =VLOOKUP(A8,'15'!B:BA,52,0) -> 0 | AX8: ชิ้น | AY8: =+AW8*C8 -> 0 | AZ8: =VLOOKUP(A8,'16'!B:BA,52,0) -> 0 | BA8: ชิ้น | BB8: =+AZ8*C8 -> 0 | BC8: =VLOOKUP(A8,'17'!B:BA,52,0) -> 30 | BD8: ชิ้น | BE8: =+BC8*C8 -> 0 | BF8: =VLOOKUP(A8,'18'!B:BA,52,0) -> 30 | BG8: ชิ้น | BH8: =+BF8*C8 -> 0 | BI8: =VLOOKUP(A8,'19'!B:BA,52,0) -> 30 | BJ8: ชิ้น | BK8: =+BI8*C8 -> 0 | BL8: =VLOOKUP(A8,'20'!B:BA,52,0) -> 90 | BM8: ชิ้น | BN8: =+BL8*C8 -> 0 | BO8: =VLOOKUP(A8,'21'!B:BA,52,0) -> 80 | BP8: ชิ้น | BQ8: =+BO8*C8 -> 0 | BR8: =VLOOKUP(A8,'22'!B:BA,52,0) -> 150 | BS8: ชิ้น | BT8: =+BR8*C8 -> 0 | BU8: =VLOOKUP(A8,'23'!B:BA,52,0) -> 42 | BV8: ชิ้น | BW8: =+BU8*C8 -> 0 | BX8: =VLOOKUP(A8,'24'!B:BA,52,0) -> 0 | BY8: ชิ้น | BZ8: =+BX8*C8 -> 0 | CA8: =VLOOKUP(A8,'25'!B:BA,52,0) -> 0 | CB8: ชิ้น | CC8: =+CA8*C8 -> 0 | CD8: =VLOOKUP(A8,'26'!B:BA,52,0) -> 0 | CE8: ชิ้น | CF8: =+CD8*C8 -> 0 | CG8: =VLOOKUP(A8,'27'!B:BA,52,0) -> 0 | CH8: ชิ้น | CI8: =+CG8*C8 -> 0 | CJ8: =VLOOKUP(A8,'28'!B:BA,52,0) -> 0 | CK8: ชิ้น | CL8: =+CJ8*C8 -> 0 | CM8: =VLOOKUP(A8,'29'!B:BA,52,0) -> 0 | CN8: ชิ้น | CO8: =+CM8*C8 -> 0 | CP8: =VLOOKUP(A8,'30'!B:BA,52,0) -> 0 | CQ8: ชิ้น | CR8: =+CP8*C8 -> 0 | CS8: =VLOOKUP(A8,'31'!B:BA,52,0) -> 0 | CT8: ชิ้น | CU8: =+CS8*C8 -> 0 | CV8: =VLOOKUP(A8,สรุป!B:BA,52,0) -> 1212 | CW8: ชิ้น | CX8: =+CV8*C8 -> 0
A9: 1111002 | B9: ชิฟฟ่อนไม่มีไส้ แบบกล่อง8ชิ้น รวมรส | C9: 30.04 | D9: =+CV9 -> 5539 | E9: กล่อง | F9: =+D9*C9 -> 166391.56 | G9: =VLOOKUP(A9,'1'!B:BA,52,0) -> 43 | H9: กล่อง | I9: =+G9*C9 -> 1291.72 | J9: =VLOOKUP(A9,'2'!B:BA,52,0) -> 129 | K9: กล่อง | L9: =+J9*C9 -> 3875.16 | M9: =VLOOKUP(A9,'3'!B:BA,52,0) -> 85 | N9: กล่อง | O9: =+M9*C9 -> 2553.4 | P9: =VLOOKUP(A9,'4'!B:BA,52,0) -> 130 | Q9: กล่อง | R9: =+P9*C9 -> 3905.2 | S9: =VLOOKUP(A9,'5'!B:BA,52,0) -> 124 | T9: กล่อง | U9: =+S9*C9 -> 3724.96 | V9: =VLOOKUP(A9,'6'!B:BA,52,0) -> 70 | W9: กล่อง | X9: =+V9*C9 -> 2102.8 | Y9: =VLOOKUP(A9,'7'!B:BA,52,0) -> 64 | Z9: กล่อง | AA9: =+Y9*C9 -> 1922.56 | AB9: =VLOOKUP(A9,'8'!B:BA,52,0) -> 39 | AC9: กล่อง | AD9: =+AB9*C9 -> 1171.56 | AE9: =VLOOKUP(A9,'9'!B:BA,52,0) -> 106 | AF9: กล่อง | AG9: =+AE9*C9 -> 3184.24 | AH9: =VLOOKUP(A9,'10'!B:BA,52,0) -> 111 | AI9: กล่อง | AJ9: =+AH9*C9 -> 3334.44 | AK9: =VLOOKUP(A9,'11'!B:BA,52,0) -> 86 | AL9: กล่อง | AM9: =+AK9*C9 -> 2583.44 | AN9: =VLOOKUP(A9,'12'!B:BA,52,0) -> 59 | AO9: กล่อง | AP9: =+AN9*C9 -> 1772.36 | AQ9: =VLOOKUP(A9,'13'!B:BA,52,0) -> 150 | AR9: กล่อง | AS9: =+AQ9*C9 -> 4506 | AT9: =VLOOKUP(A9,'14'!B:BA,52,0) -> 104 | AU9: กล่อง | AV9: =+AT9*C9 -> 3124.16 | AW9: =VLOOKUP(A9,'15'!B:BA,52,0) -> 138 | AX9: กล่อง | AY9: =+AW9*C9 -> 4145.52 | AZ9: =VLOOKUP(A9,'16'!B:BA,52,0) -> 103 | BA9: กล่อง | BB9: =+AZ9*C9 -> 3094.12 | BC9: =VLOOKUP(A9,'17'!B:BA,52,0) -> 69 | BD9: กล่อง | BE9: =+BC9*C9 -> 2072.76 | BF9: =VLOOKUP(A9,'18'!B:BA,52,0) -> 132 | BG9: กล่อง | BH9: =+BF9*C9 -> 3965.28 | BI9: =VLOOKUP(A9,'19'!B:BA,52,0) -> 110 | BJ9: กล่อง | BK9: =+BI9*C9 -> 3304.4 | BL9: =VLOOKUP(A9,'20'!B:BA,52,0) -> 1461 | BM9: กล่อง | BN9: =+BL9*C9 -> 43888.44 | BO9: =VLOOKUP(A9,'21'!B:BA,52,0) -> 95 | BP9: กล่อง | BQ9: =+BO9*C9 -> 2853.8 | BR9: =VLOOKUP(A9,'22'!B:BA,52,0) -> 68 | BS9: กล่อง | BT9: =+BR9*C9 -> 2042.72 | BU9: =VLOOKUP(A9,'23'!B:BA,52,0) -> 66 | BV9: กล่อง | BW9: =+BU9*C9 -> 1982.64 | BX9: =VLOOKUP(A9,'24'!B:BA,52,0) -> 1519 | BY9: กล่อง | BZ9: =+BX9*C9 -> 45630.76 | CA9: =VLOOKUP(A9,'25'!B:BA,52,0) -> 85 | CB9: กล่อง | CC9: =+CA9*C9 -> 2553.4 | CD9: =VLOOKUP(A9,'26'!B:BA,52,0) -> 91 | CE9: กล่อง | CF9: =+CD9*C9 -> 2733.64 | CG9: =VLOOKUP(A9,'27'!B:BA,52,0) -> 129 | CH9: กล่อง | CI9: =+CG9*C9 -> 3875.16 | CJ9: =VLOOKUP(A9,'28'!B:BA,52,0) -> 173 | CK9: กล่อง | CL9: =+CJ9*C9 -> 5196.92 | CM9: =VLOOKUP(A9,'29'!B:BA,52,0) -> 0 | CN9: กล่อง | CO9: =+CM9*C9 -> 0 | CP9: =VLOOKUP(A9,'30'!B:BA,52,0) -> 0 | CQ9: กล่อง | CR9: =+CP9*C9 -> 0 | CS9: =VLOOKUP(A9,'31'!B:BA,52,0) -> 0 | CT9: กล่อง | CU9: =+CS9*C9 -> 0 | CV9: =VLOOKUP(A9,สรุป!B:BA,52,0) -> 5539 | CW9: กล่อง | CX9: =+CV9*C9 -> 166391.56
A10: 1111008 | B10: ชิฟฟ่อน สอดไส้แยม ขนาด3 ชิ้น มีรสให้เลือก 7 รส (รวมรส) | C10: 17.27 | D10: =+CV10 -> 2236 | E10: กล่อง | F10: =+D10*C10 -> 38615.72 | G10: =VLOOKUP(A10,'1'!B:BA,52,0) -> 55 | H10: กล่อง | I10: =+G10*C10 -> 949.85 | J10: =VLOOKUP(A10,'2'!B:BA,52,0) -> 85 | K10: กล่อง | L10: =+J10*C10 -> 1467.95 | M10: =VLOOKUP(A10,'3'!B:BA,52,0) -> 193 | N10: กล่อง | O10: =+M10*C10 -> 3333.11 | P10: =VLOOKUP(A10,'4'!B:BA,52,0) -> 128 | Q10: กล่อง | R10: =+P10*C10 -> 2210.56 | S10: =VLOOKUP(A10,'5'!B:BA,52,0) -> 72 | T10: กล่อง | U10: =+S10*C10 -> 1243.44 | V10: =VLOOKUP(A10,'6'!B:BA,52,0) -> 31 | W10: กล่อง | X10: =+V10*C10 -> 535.37 | Y10: =VLOOKUP(A10,'7'!B:BA,52,0) -> 91 | Z10: กล่อง | AA10: =+Y10*C10 -> 1571.57 | AB10: =VLOOKUP(A10,'8'!B:BA,52,0) -> 57 | AC10: กล่อง | AD10: =+AB10*C10 -> 984.39 | AE10: =VLOOKUP(A10,'9'!B:BA,52,0) -> 136 | AF10: กล่อง | AG10: =+AE10*C10 -> 2348.72 | AH10: =VLOOKUP(A10,'10'!B:BA,52,0) -> 76 | AI10: กล่อง | AJ10: =+AH10*C10 -> 1312.52 | AK10: =VLOOKUP(A10,'11'!B:BA,52,0) -> 39 | AL10: กล่อง | AM10: =+AK10*C10 -> 673.53 | AN10: =VLOOKUP(A10,'12'!B:BA,52,0) -> 124 | AO10: กล่อง | AP10: =+AN10*C10 -> 2141.48 | AQ10: =VLOOKUP(A10,'13'!B:BA,52,0) -> 120 | AR10: กล่อง | AS10: =+AQ10*C10 -> 2072.4 | AT10: =VLOOKUP(A10,'14'!B:BA,52,0) -> 92 | AU10: กล่อง | AV10: =+AT10*C10 -> 1588.84 | AW10: =VLOOKUP(A10,'15'!B:BA,52,0) -> 46 | AX10: กล่อง | AY10: =+AW10*C10 -> 794.42 | AZ10: =VLOOKUP(A10,'16'!B:BA,52,0) -> 109 | BA10: กล่อง | BB10: =+AZ10*C10 -> 1882.43 | BC10: =VLOOKUP(A10,'17'!B:BA,52,0) -> 67 | BD10: กล่อง | BE10: =+BC10*C10 -> 1157.09 | BF10: =VLOOKUP(A10,'18'!B:BA,52,0) -> 37 | BG10: กล่อง | BH10: =+BF10*C10 -> 638.99 | BI10: =VLOOKUP(A10,'19'!B:BA,52,0) -> 80 | BJ10: กล่อง | BK10: =+BI10*C10 -> 1381.6 | BL10: =VLOOKUP(A10,'20'!B:BA,52,0) -> 63 | BM10: กล่อง | BN10: =+BL10*C10 -> 1088.01 | BO10: =VLOOKUP(A10,'21'!B:BA,52,0) -> 68 | BP10: กล่อง | BQ10: =+BO10*C10 -> 1174.36 | BR10: =VLOOKUP(A10,'22'!B:BA,52,0) -> 40 | BS10: กล่อง | BT10: =+BR10*C10 -> 690.8 | BU10: =VLOOKUP(A10,'23'!B:BA,52,0) -> 60 | BV10: กล่อง | BW10: =+BU10*C10 -> 1036.2 | BX10: =VLOOKUP(A10,'24'!B:BA,52,0) -> 87 | BY10: กล่อง | BZ10: =+BX10*C10 -> 1502.49 | CA10: =VLOOKUP(A10,'25'!B:BA,52,0) -> 72 | CB10: กล่อง | CC10: =+CA10*C10 -> 1243.44 | CD10: =VLOOKUP(A10,'26'!B:BA,52,0) -> 72 | CE10: กล่อง | CF10: =+CD10*C10 -> 1243.44 | CG10: =VLOOKUP(A10,'27'!B:BA,52,0) -> 63 | CH10: กล่อง | CI10: =+CG10*C10 -> 1088.01 | CJ10: =VLOOKUP(A10,'28'!B:BA,52,0) -> 73 | CK10: กล่อง | CL10: =+CJ10*C10 -> 1260.71 | CM10: =VLOOKUP(A10,'29'!B:BA,52,0) -> 0 | CN10: กล่อง | CO10: =+CM10*C10 -> 0 | CP10: =VLOOKUP(A10,'30'!B:BA,52,0) -> 0 | CQ10: กล่อง | CR10: =+CP10*C10 -> 0 | CS10: =VLOOKUP(A10,'31'!B:BA,52,0) -> 0 | CT10: กล่อง | CU10: =+CS10*C10 -> 0 | CV10: =VLOOKUP(A10,สรุป!B:BA,52,0) -> 2236 | CW10: กล่อง | CX10: =+CV10*C10 -> 38615.72
A11: 1111009 | B11: ชิฟฟ่อนสอดไส้ แยม 1กล่อง มี6ชิ้น (รวมรส) | C11: 25.66 | D11: =+CV11 -> 336 | E11: กล่อง | F11: =+D11*C11 -> 8621.76 | G11: =VLOOKUP(A11,'1'!B:BA,52,0) -> 10 | H11: กล่อง | I11: =+G11*C11 -> 256.6 | J11: =VLOOKUP(A11,'2'!B:BA,52,0) -> 10 | K11: กล่อง | L11: =+J11*C11 -> 256.6 | M11: =VLOOKUP(A11,'3'!B:BA,52,0) -> 27 | N11: กล่อง | O11: =+M11*C11 -> 692.82 | P11: =VLOOKUP(A11,'4'!B:BA,52,0) -> 14 | Q11: กล่อง | R11: =+P11*C11 -> 359.24 | S11: =VLOOKUP(A11,'5'!B:BA,52,0) -> 4 | T11: กล่อง | U11: =+S11*C11 -> 102.64 | V11: =VLOOKUP(A11,'6'!B:BA,52,0) -> 17 | W11: กล่อง | X11: =+V11*C11 -> 436.22 | Y11: =VLOOKUP(A11,'7'!B:BA,52,0) -> 6 | Z11: กล่อง | AA11: =+Y11*C11 -> 153.96 | AB11: =VLOOKUP(A11,'8'!B:BA,52,0) -> 6 | AC11: กล่อง | AD11: =+AB11*C11 -> 153.96 | AE11: =VLOOKUP(A11,'9'!B:BA,52,0) -> 17 | AF11: กล่อง | AG11: =+AE11*C11 -> 436.22 | AH11: =VLOOKUP(A11,'10'!B:BA,52,0) -> 5 | AI11: กล่อง | AJ11: =+AH11*C11 -> 128.3 | AK11: =VLOOKUP(A11,'11'!B:BA,52,0) -> 34 | AL11: กล่อง | AM11: =+AK11*C11 -> 872.44 | AN11: =VLOOKUP(A11,'12'!B:BA,52,0) -> 9 | AO11: กล่อง | AP11: =+AN11*C11 -> 230.94 | AQ11: =VLOOKUP(A11,'13'!B:BA,52,0) -> 21 | AR11: กล่อง | AS11: =+AQ11*C11 -> 538.86 | AT11: =VLOOKUP(A11,'14'!B:BA,52,0) -> 19 | AU11: กล่อง | AV11: =+AT11*C11 -> 487.54 | AW11: =VLOOKUP(A11,'15'!B:BA,52,0) -> 4 | AX11: กล่อง | AY11: =+AW11*C11 -> 102.64 | AZ11: =VLOOKUP(A11,'16'!B:BA,52,0) -> 16 | BA11: กล่อง | BB11: =+AZ11*C11 -> 410.56 | BC11: =VLOOKUP(A11,'17'!B:BA,52,0) -> 20 | BD11: กล่อง | BE11: =+BC11*C11 -> 513.2 | BF11: =VLOOKUP(A11,'18'!B:BA,52,0) -> 9 | BG11: กล่อง | BH11: =+BF11*C11 -> 230.94 | BI11: =VLOOKUP(A11,'19'!B:BA,52,0) -> 14 | BJ11: กล่อง | BK11: =+BI11*C11 -> 359.24 | BL11: =VLOOKUP(A11,'20'!B:BA,52,0) -> 7 | BM11: กล่อง | BN11: =+BL11*C11 -> 179.62 | BO11: =VLOOKUP(A11,'21'!B:BA,52,0) -> 4 | BP11: กล่อง | BQ11: =+BO11*C11 -> 102.64 | BR11: =VLOOKUP(A11,'22'!B:BA,52,0) -> 2 | BS11: กล่อง | BT11: =+BR11*C11 -> 51.32 | BU11: =VLOOKUP(A11,'23'!B:BA,52,0) -> 16 | BV11: กล่อง | BW11: =+BU11*C11 -> 410.56 | BX11: =VLOOKUP(A11,'24'!B:BA,52,0) -> 9 | BY11: กล่อง | BZ11: =+BX11*C11 -> 230.94 | CA11: =VLOOKUP(A11,'25'!B:BA,52,0) -> 7 | CB11: กล่อง | CC11: =+CA11*C11 -> 179.62 | CD11: =VLOOKUP(A11,'26'!B:BA,52,0) -> 12 | CE11: กล่อง | CF11: =+CD11*C11 -> 307.92 | CG11: =VLOOKUP(A11,'27'!B:BA,52,0) -> 11 | CH11: กล่อง | CI11: =+CG11*C11 -> 282.26 | CJ11: =VLOOKUP(A11,'28'!B:BA,52,0) -> 6 | CK11: กล่อง | CL11: =+CJ11*C11 -> 153.96 | CM11: =VLOOKUP(A11,'29'!B:BA,52,0) -> 0 | CN11: กล่อง | CO11: =+CM11*C11 -> 0 | CP11: =VLOOKUP(A11,'30'!B:BA,52,0) -> 0 | CQ11: กล่อง | CR11: =+CP11*C11 -> 0 | CS11: =VLOOKUP(A11,'31'!B:BA,52,0) -> 0 | CT11: กล่อง | CU11: =+CS11*C11 -> 0 | CV11: =VLOOKUP(A11,สรุป!B:BA,52,0) -> 336 | CW11: กล่อง | CX11: =+CV11*C11 -> 8621.76
A12: 1111020 | B12: ชิฟฟ่อนสอดไส้ แยม 1กล่อง มี6ชิ้น (ฝอยทอง) | C12: 35.96 | D12: =+CV12 -> 10 | E12: กล่อง | F12: =+D12*C12 -> 359.6 | G12: =VLOOKUP(A12,'1'!B:BA,52,0) -> 0 | H12: กล่อง | I12: =+G12*C12 -> 0 | J12: =VLOOKUP(A12,'2'!B:BA,52,0) -> 0 | K12: กล่อง | L12: =+J12*C12 -> 0 | M12: =VLOOKUP(A12,'3'!B:BA,52,0) -> 0 | N12: กล่อง | O12: =+M12*C12 -> 0 | P12: =VLOOKUP(A12,'4'!B:BA,52,0) -> 0 | Q12: กล่อง | R12: =+P12*C12 -> 0 | S12: =VLOOKUP(A12,'5'!B:BA,52,0) -> 0 | T12: กล่อง | U12: =+S12*C12 -> 0 | V12: =VLOOKUP(A12,'6'!B:BA,52,0) -> 0 | W12: กล่อง | X12: =+V12*C12 -> 0 | Y12: =VLOOKUP(A12,'7'!B:BA,52,0) -> 0 | Z12: กล่อง | AA12: =+Y12*C12 -> 0 | AB12: =VLOOKUP(A12,'8'!B:BA,52,0) -> 0 | AC12: กล่อง | AD12: =+AB12*C12 -> 0 | AE12: =VLOOKUP(A12,'9'!B:BA,52,0) -> 0 | AF12: กล่อง | AG12: =+AE12*C12 -> 0 | AH12: =VLOOKUP(A12,'10'!B:BA,52,0) -> 0 | AI12: กล่อง | AJ12: =+AH12*C12 -> 0 | AK12: =VLOOKUP(A12,'11'!B:BA,52,0) -> 10 | AL12: กล่อง | AM12: =+AK12*C12 -> 359.6 | AN12: =VLOOKUP(A12,'12'!B:BA,52,0) -> 0 | AO12: กล่อง | AP12: =+AN12*C12 -> 0 | AQ12: =VLOOKUP(A12,'13'!B:BA,52,0) -> 0 | AR12: กล่อง | AS12: =+AQ12*C12 -> 0 | AT12: =VLOOKUP(A12,'14'!B:BA,52,0) -> 0 | AU12: กล่อง | AV12: =+AT12*C12 -> 0 | AW12: =VLOOKUP(A12,'15'!B:BA,52,0) -> 0 | AX12: กล่อง | AY12: =+AW12*C12 -> 0 | AZ12: =VLOOKUP(A12,'16'!B:BA,52,0) -> 0 | BA12: กล่อง | BB12: =+AZ12*C12 -> 0 | BC12: =VLOOKUP(A12,'17'!B:BA,52,0) -> 0 | BD12: กล่อง | BE12: =+BC12*C12 -> 0 | BF12: =VLOOKUP(A12,'18'!B:BA,52,0) -> 0 | BG12: กล่อง | BH12: =+BF12*C12 -> 0 | BI12: =VLOOKUP(A12,'19'!B:BA,52,0) -> 0 | BJ12: กล่อง | BK12: =+BI12*C12 -> 0 | BL12: =VLOOKUP(A12,'20'!B:BA,52,0) -> 0 | BM12: กล่อง | BN12: =+BL12*C12 -> 0 | BO12: =VLOOKUP(A12,'21'!B:BA,52,0) -> 0 | BP12: กล่อง | BQ12: =+BO12*C12 -> 0 | BR12: =VLOOKUP(A12,'22'!B:BA,52,0) -> 0 | BS12: กล่อง | BT12: =+BR12*C12 -> 0 | BU12: =VLOOKUP(A12,'23'!B:BA,52,0) -> 0 | BV12: กล่อง | BW12: =+BU12*C12 -> 0 | BX12: =VLOOKUP(A12,'24'!B:BA,52,0) -> 0 | BY12: กล่อง | BZ12: =+BX12*C12 -> 0 | CA12: =VLOOKUP(A12,'25'!B:BA,52,0) -> 0 | CB12: กล่อง | CC12: =+CA12*C12 -> 0 | CD12: =VLOOKUP(A12,'26'!B:BA,52,0) -> 0 | CE12: กล่อง | CF12: =+CD12*C12 -> 0 | CG12: =VLOOKUP(A12,'27'!B:BA,52,0) -> 0 | CH12: กล่อง | CI12: =+CG12*C12 -> 0 | CJ12: =VLOOKUP(A12,'28'!B:BA,52,0) -> 0 | CK12: กล่อง | CL12: =+CJ12*C12 -> 0 | CM12: =VLOOKUP(A12,'29'!B:BA,52,0) -> 0 | CN12: กล่อง | CO12: =+CM12*C12 -> 0 | CP12: =VLOOKUP(A12,'30'!B:BA,52,0) -> 0 | CQ12: กล่อง | CR12: =+CP12*C12 -> 0 | CS12: =VLOOKUP(A12,'31'!B:BA,52,0) -> 0 | CT12: กล่อง | CU12: =+CS12*C12 -> 0 | CV12: =VLOOKUP(A12,สรุป!B:BA,52,0) -> 10 | CW12: กล่อง | CX12: =+CV12*C12 -> 359.6
A13: 1111056 | B13: ชิฟฟ่อนไม่มีไส้ แบบกล่อง8ชิ้น รวมรส (รวมรสยอดฮิต) | C13: 29.56 | D13: =+CV13 -> 2970 | E13: กล่อง | F13: =+D13*C13 -> 87793.2 | G13: =VLOOKUP(A13,'1'!B:BA,52,0) -> 6 | H13: กล่อง | I13: =+G13*C13 -> 177.36 | J13: =VLOOKUP(A13,'2'!B:BA,52,0) -> 3 | K13: กล่อง | L13: =+J13*C13 -> 88.68 | M13: =VLOOKUP(A13,'3'!B:BA,52,0) -> 5 | N13: กล่อง | O13: =+M13*C13 -> 147.8 | P13: =VLOOKUP(A13,'4'!B:BA,52,0) -> 4 | Q13: กล่อง | R13: =+P13*C13 -> 118.24 | S13: =VLOOKUP(A13,'5'!B:BA,52,0) -> 5 | T13: กล่อง | U13: =+S13*C13 -> 147.8 | V13: =VLOOKUP(A13,'6'!B:BA,52,0) -> 3 | W13: กล่อง | X13: =+V13*C13 -> 88.68 | Y13: =VLOOKUP(A13,'7'!B:BA,52,0) -> 5 | Z13: กล่อง | AA13: =+Y13*C13 -> 147.8 | AB13: =VLOOKUP(A13,'8'!B:BA,52,0) -> 6 | AC13: กล่อง | AD13: =+AB13*C13 -> 177.36 | AE13: =VLOOKUP(A13,'9'!B:BA,52,0) -> 11 | AF13: กล่อง | AG13: =+AE13*C13 -> 325.16 | AH13: =VLOOKUP(A13,'10'!B:BA,52,0) -> 4 | AI13: กล่อง | AJ13: =+AH13*C13 -> 118.24 | AK13: =VLOOKUP(A13,'11'!B:BA,52,0) -> 16 | AL13: กล่อง | AM13: =+AK13*C13 -> 472.96 | AN13: =VLOOKUP(A13,'12'!B:BA,52,0) -> 7 | AO13: กล่อง | AP13: =+AN13*C13 -> 206.92 | AQ13: =VLOOKUP(A13,'13'!B:BA,52,0) -> 12 | AR13: กล่อง | AS13: =+AQ13*C13 -> 354.72 | AT13: =VLOOKUP(A13,'14'!B:BA,52,0) -> 1 | AU13: กล่อง | AV13: =+AT13*C13 -> 29.56 | AW13: =VLOOKUP(A13,'15'!B:BA,52,0) -> 1 | AX13: กล่อง | AY13: =+AW13*C13 -> 29.56 | AZ13: =VLOOKUP(A13,'16'!B:BA,52,0) -> 21 | BA13: กล่อง | BB13: =+AZ13*C13 -> 620.76 | BC13: =VLOOKUP(A13,'17'!B:BA,52,0) -> 6 | BD13: กล่อง | BE13: =+BC13*C13 -> 177.36 | BF13: =VLOOKUP(A13,'18'!B:BA,52,0) -> 5 | BG13: กล่อง | BH13: =+BF13*C13 -> 147.8 | BI13: =VLOOKUP(A13,'19'!B:BA,52,0) -> 18 | BJ13: กล่อง | BK13: =+BI13*C13 -> 532.08 | BL13: =VLOOKUP(A13,'20'!B:BA,52,0) -> 1387 | BM13: กล่อง | BN13: =+BL13*C13 -> 40999.72 | BO13: =VLOOKUP(A13,'21'!B:BA,52,0) -> 4 | BP13: กล่อง | BQ13: =+BO13*C13 -> 118.24 | BR13: =VLOOKUP(A13,'22'!B:BA,52,0) -> 6 | BS13: กล่อง | BT13: =+BR13*C13 -> 177.36 | BU13: =VLOOKUP(A13,'23'!B:BA,52,0) -> 3 | BV13: กล่อง | BW13: =+BU13*C13 -> 88.68 | BX13: =VLOOKUP(A13,'24'!B:BA,52,0) -> 1386 | BY13: กล่อง | BZ13: =+BX13*C13 -> 40970.16 | CA13: =VLOOKUP(A13,'25'!B:BA,52,0) -> 26 | CB13: กล่อง | CC13: =+CA13*C13 -> 768.56 | CD13: =VLOOKUP(A13,'26'!B:BA,52,0) -> 6 | CE13: กล่อง | CF13: =+CD13*C13 -> 177.36 | CG13: =VLOOKUP(A13,'27'!B:BA,52,0) -> 4 | CH13: กล่อง | CI13: =+CG13*C13 -> 118.24 | CJ13: =VLOOKUP(A13,'28'!B:BA,52,0) -> 9 | CK13: กล่อง | CL13: =+CJ13*C13 -> 266.04 | CM13: =VLOOKUP(A13,'29'!B:BA,52,0) -> 0 | CN13: กล่อง | CO13: =+CM13*C13 -> 0 | CP13: =VLOOKUP(A13,'30'!B:BA,52,0) -> 0 | CQ13: กล่อง | CR13: =+CP13*C13 -> 0 | CS13: =VLOOKUP(A13,'31'!B:BA,52,0) -> 0 | CT13: กล่อง | CU13: =+CS13*C13 -> 0 | CV13: =VLOOKUP(A13,สรุป!B:BA,52,0) -> 2970 | CW13: กล่อง | CX13: =+CV13*C13 -> 87793.2
A14: 1111068 | B14: ชิฟฟอนไม่มีไส้เเบบเเยกชิ้น เลือกรสชาติได้ (เนย) | C14: 0 | D14: =+CV14 -> 0 | E14: ชิ้น | F14: =+D14*C14 -> 0 | G14: =VLOOKUP(A14,'1'!B:BA,52,0) -> 0 | H14: ชิ้น | I14: =+G14*C14 -> 0 | J14: =VLOOKUP(A14,'2'!B:BA,52,0) -> 0 | K14: ชิ้น | L14: =+J14*C14 -> 0 | M14: =VLOOKUP(A14,'3'!B:BA,52,0) -> 0 | N14: ชิ้น | O14: =+M14*C14 -> 0 | P14: =VLOOKUP(A14,'4'!B:BA,52,0) -> 0 | Q14: ชิ้น | R14: =+P14*C14 -> 0 | S14: =VLOOKUP(A14,'5'!B:BA,52,0) -> 0 | T14: ชิ้น | U14: =+S14*C14 -> 0 | V14: =VLOOKUP(A14,'6'!B:BA,52,0) -> 0 | W14: ชิ้น | X14: =+V14*C14 -> 0 | Y14: =VLOOKUP(A14,'7'!B:BA,52,0) -> 0 | Z14: ชิ้น | AA14: =+Y14*C14 -> 0 | AB14: =VLOOKUP(A14,'8'!B:BA,52,0) -> 0 | AC14: ชิ้น | AD14: =+AB14*C14 -> 0 | AE14: =VLOOKUP(A14,'9'!B:BA,52,0) -> 0 | AF14: ชิ้น | AG14: =+AE14*C14 -> 0 | AH14: =VLOOKUP(A14,'10'!B:BA,52,0) -> 0 | AI14: ชิ้น | AJ14: =+AH14*C14 -> 0 | AK14: =VLOOKUP(A14,'11'!B:BA,52,0) -> 0 | AL14: ชิ้น | AM14: =+AK14*C14 -> 0 | AN14: =VLOOKUP(A14,'12'!B:BA,52,0) -> 0 | AO14: ชิ้น | AP14: =+AN14*C14 -> 0 | AQ14: =VLOOKUP(A14,'13'!B:BA,52,0) -> 0 | AR14: ชิ้น | AS14: =+AQ14*C14 -> 0 | AT14: =VLOOKUP(A14,'14'!B:BA,52,0) -> 0 | AU14: ชิ้น | AV14: =+AT14*C14 -> 0 | AW14: =VLOOKUP(A14,'15'!B:BA,52,0) -> 0 | AX14: ชิ้น | AY14: =+AW14*C14 -> 0 | AZ14: =VLOOKUP(A14,'16'!B:BA,52,0) -> 0 | BA14: ชิ้น | BB14: =+AZ14*C14 -> 0 | BC14: =VLOOKUP(A14,'17'!B:BA,52,0) -> 0 | BD14: ชิ้น | BE14: =+BC14*C14 -> 0 | BF14: =VLOOKUP(A14,'18'!B:BA,52,0) -> 0 | BG14: ชิ้น | BH14: =+BF14*C14 -> 0 | BI14: =VLOOKUP(A14,'19'!B:BA,52,0) -> 0 | BJ14: ชิ้น | BK14: =+BI14*C14 -> 0 | BL14: =VLOOKUP(A14,'20'!B:BA,52,0) -> 0 | BM14: ชิ้น | BN14: =+BL14*C14 -> 0 | BO14: =VLOOKUP(A14,'21'!B:BA,52,0) -> 0 | BP14: ชิ้น | BQ14: =+BO14*C14 -> 0 | BR14: =VLOOKUP(A14,'22'!B:BA,52,0) -> 0 | BS14: ชิ้น | BT14: =+BR14*C14 -> 0 | BU14: =VLOOKUP(A14,'23'!B:BA,52,0) -> 0 | BV14: ชิ้น | BW14: =+BU14*C14 -> 0 | BX14: =VLOOKUP(A14,'24'!B:BA,52,0) -> 0 | BY14: ชิ้น | BZ14: =+BX14*C14 -> 0 | CA14: =VLOOKUP(A14,'25'!B:BA,52,0) -> 0 | CB14: ชิ้น | CC14: =+CA14*C14 -> 0 | CD14: =VLOOKUP(A14,'26'!B:BA,52,0) -> 0 | CE14: ชิ้น | CF14: =+CD14*C14 -> 0 | CG14: =VLOOKUP(A14,'27'!B:BA,52,0) -> 0 | CH14: ชิ้น | CI14: =+CG14*C14 -> 0 | CJ14: =VLOOKUP(A14,'28'!B:BA,52,0) -> 0 | CK14: ชิ้น | CL14: =+CJ14*C14 -> 0 | CM14: =VLOOKUP(A14,'29'!B:BA,52,0) -> 0 | CN14: ชิ้น | CO14: =+CM14*C14 -> 0 | CP14: =VLOOKUP(A14,'30'!B:BA,52,0) -> 0 | CQ14: ชิ้น | CR14: =+CP14*C14 -> 0 | CS14: =VLOOKUP(A14,'31'!B:BA,52,0) -> 0 | CT14: ชิ้น | CU14: =+CS14*C14 -> 0 | CV14: =VLOOKUP(A14,สรุป!B:BA,52,0) -> 0 | CW14: ชิ้น | CX14: =+CV14*C14 -> 0
A15: 1111074 | B15: ชิฟฟ่อนสอดไส้ 1 ชิ้น ชิฟฟ่อนเค้ก เลือกรสชาติได้ (มะพร้าว) | C15: 0 | D15: =+CV15 -> 0 | E15: ชิ้น | F15: =+D15*C15 -> 0 | G15: =VLOOKUP(A15,'1'!B:BA,52,0) -> 0 | H15: ชิ้น | I15: =+G15*C15 -> 0 | J15: =VLOOKUP(A15,'2'!B:BA,52,0) -> 0 | K15: ชิ้น | L15: =+J15*C15 -> 0 | M15: =VLOOKUP(A15,'3'!B:BA,52,0) -> 0 | N15: ชิ้น | O15: =+M15*C15 -> 0 | P15: =VLOOKUP(A15,'4'!B:BA,52,0) -> 0 | Q15: ชิ้น | R15: =+P15*C15 -> 0 | S15: =VLOOKUP(A15,'5'!B:BA,52,0) -> 0 | T15: ชิ้น | U15: =+S15*C15 -> 0 | V15: =VLOOKUP(A15,'6'!B:BA,52,0) -> 0 | W15: ชิ้น | X15: =+V15*C15 -> 0 | Y15: =VLOOKUP(A15,'7'!B:BA,52,0) -> 0 | Z15: ชิ้น | AA15: =+Y15*C15 -> 0 | AB15: =VLOOKUP(A15,'8'!B:BA,52,0) -> 0 | AC15: ชิ้น | AD15: =+AB15*C15 -> 0 | AE15: =VLOOKUP(A15,'9'!B:BA,52,0) -> 0 | AF15: ชิ้น | AG15: =+AE15*C15 -> 0 | AH15: =VLOOKUP(A15,'10'!B:BA,52,0) -> 0 | AI15: ชิ้น | AJ15: =+AH15*C15 -> 0 | AK15: =VLOOKUP(A15,'11'!B:BA,52,0) -> 0 | AL15: ชิ้น | AM15: =+AK15*C15 -> 0 | AN15: =VLOOKUP(A15,'12'!B:BA,52,0) -> 0 | AO15: ชิ้น | AP15: =+AN15*C15 -> 0 | AQ15: =VLOOKUP(A15,'13'!B:BA,52,0) -> 0 | AR15: ชิ้น | AS15: =+AQ15*C15 -> 0 | AT15: =VLOOKUP(A15,'14'!B:BA,52,0) -> 0 | AU15: ชิ้น | AV15: =+AT15*C15 -> 0 | AW15: =VLOOKUP(A15,'15'!B:BA,52,0) -> 0 | AX15: ชิ้น | AY15: =+AW15*C15 -> 0 | AZ15: =VLOOKUP(A15,'16'!B:BA,52,0) -> 0 | BA15: ชิ้น | BB15: =+AZ15*C15 -> 0 | BC15: =VLOOKUP(A15,'17'!B:BA,52,0) -> 0 | BD15: ชิ้น | BE15: =+BC15*C15 -> 0 | BF15: =VLOOKUP(A15,'18'!B:BA,52,0) -> 0 | BG15: ชิ้น | BH15: =+BF15*C15 -> 0 | BI15: =VLOOKUP(A15,'19'!B:BA,52,0) -> 0 | BJ15: ชิ้น | BK15: =+BI15*C15 -> 0 | BL15: =VLOOKUP(A15,'20'!B:BA,52,0) -> 0 | BM15: ชิ้น | BN15: =+BL15*C15 -> 0 | BO15: =VLOOKUP(A15,'21'!B:BA,52,0) -> 0 | BP15: ชิ้น | BQ15: =+BO15*C15 -> 0 | BR15: =VLOOKUP(A15,'22'!B:BA,52,0) -> 0 | BS15: ชิ้น | BT15: =+BR15*C15 -> 0 | BU15: =VLOOKUP(A15,'23'!B:BA,52,0) -> 0 | BV15: ชิ้น | BW15: =+BU15*C15 -> 0 | BX15: =VLOOKUP(A15,'24'!B:BA,52,0) -> 0 | BY15: ชิ้น | BZ15: =+BX15*C15 -> 0 | CA15: =VLOOKUP(A15,'25'!B:BA,52,0) -> 0 | CB15: ชิ้น | CC15: =+CA15*C15 -> 0 | CD15: =VLOOKUP(A15,'26'!B:BA,52,0) -> 0 | CE15: ชิ้น | CF15: =+CD15*C15 -> 0 | CG15: =VLOOKUP(A15,'27'!B:BA,52,0) -> 0 | CH15: ชิ้น | CI15: =+CG15*C15 -> 0 | CJ15: =VLOOKUP(A15,'28'!B:BA,52,0) -> 0 | CK15: ชิ้น | CL15: =+CJ15*C15 -> 0 | CM15: =VLOOKUP(A15,'29'!B:BA,52,0) -> 0 | CN15: ชิ้น | CO15: =+CM15*C15 -> 0 | CP15: =VLOOKUP(A15,'30'!B:BA,52,0) -> 0 | CQ15: ชิ้น | CR15: =+CP15*C15 -> 0 | CS15: =VLOOKUP(A15,'31'!B:BA,52,0) -> 0 | CT15: ชิ้น | CU15: =+CS15*C15 -> 0 | CV15: =VLOOKUP(A15,สรุป!B:BA,52,0) -> 0 | CW15: ชิ้น | CX15: =+CV15*C15 -> 0
A16: 1111075 | B16: ชิฟฟ่อนสอดไส้ 1 ชิ้น ชิฟฟ่อนเค้ก เลือกรสชาติได้ (สตอเบอรี่) | C16: 0 | D16: =+CV16 -> 0 | E16: ชิ้น | F16: =+D16*C16 -> 0 | G16: =VLOOKUP(A16,'1'!B:BA,52,0) -> 0 | H16: ชิ้น | I16: =+G16*C16 -> 0 | J16: =VLOOKUP(A16,'2'!B:BA,52,0) -> 0 | K16: ชิ้น | L16: =+J16*C16 -> 0 | M16: =VLOOKUP(A16,'3'!B:BA,52,0) -> 0 | N16: ชิ้น | O16: =+M16*C16 -> 0 | P16: =VLOOKUP(A16,'4'!B:BA,52,0) -> 0 | Q16: ชิ้น | R16: =+P16*C16 -> 0 | S16: =VLOOKUP(A16,'5'!B:BA,52,0) -> 0 | T16: ชิ้น | U16: =+S16*C16 -> 0 | V16: =VLOOKUP(A16,'6'!B:BA,52,0) -> 0 | W16: ชิ้น | X16: =+V16*C16 -> 0 | Y16: =VLOOKUP(A16,'7'!B:BA,52,0) -> 0 | Z16: ชิ้น | AA16: =+Y16*C16 -> 0 | AB16: =VLOOKUP(A16,'8'!B:BA,52,0) -> 0 | AC16: ชิ้น | AD16: =+AB16*C16 -> 0 | AE16: =VLOOKUP(A16,'9'!B:BA,52,0) -> 0 | AF16: ชิ้น | AG16: =+AE16*C16 -> 0 | AH16: =VLOOKUP(A16,'10'!B:BA,52,0) -> 0 | AI16: ชิ้น | AJ16: =+AH16*C16 -> 0 | AK16: =VLOOKUP(A16,'11'!B:BA,52,0) -> 0 | AL16: ชิ้น | AM16: =+AK16*C16 -> 0 | AN16: =VLOOKUP(A16,'12'!B:BA,52,0) -> 0 | AO16: ชิ้น | AP16: =+AN16*C16 -> 0 | AQ16: =VLOOKUP(A16,'13'!B:BA,52,0) -> 0 | AR16: ชิ้น | AS16: =+AQ16*C16 -> 0 | AT16: =VLOOKUP(A16,'14'!B:BA,52,0) -> 0 | AU16: ชิ้น | AV16: =+AT16*C16 -> 0 | AW16: =VLOOKUP(A16,'15'!B:BA,52,0) -> 0 | AX16: ชิ้น | AY16: =+AW16*C16 -> 0 | AZ16: =VLOOKUP(A16,'16'!B:BA,52,0) -> 0 | BA16: ชิ้น | BB16: =+AZ16*C16 -> 0 | BC16: =VLOOKUP(A16,'17'!B:BA,52,0) -> 0 | BD16: ชิ้น | BE16: =+BC16*C16 -> 0 | BF16: =VLOOKUP(A16,'18'!B:BA,52,0) -> 0 | BG16: ชิ้น | BH16: =+BF16*C16 -> 0 | BI16: =VLOOKUP(A16,'19'!B:BA,52,0) -> 0 | BJ16: ชิ้น | BK16: =+BI16*C16 -> 0 | BL16: =VLOOKUP(A16,'20'!B:BA,52,0) -> 0 | BM16: ชิ้น | BN16: =+BL16*C16 -> 0 | BO16: =VLOOKUP(A16,'21'!B:BA,52,0) -> 0 | BP16: ชิ้น | BQ16: =+BO16*C16 -> 0 | BR16: =VLOOKUP(A16,'22'!B:BA,52,0) -> 0 | BS16: ชิ้น | BT16: =+BR16*C16 -> 0 | BU16: =VLOOKUP(A16,'23'!B:BA,52,0) -> 0 | BV16: ชิ้น | BW16: =+BU16*C16 -> 0 | BX16: =VLOOKUP(A16,'24'!B:BA,52,0) -> 0 | BY16: ชิ้น | BZ16: =+BX16*C16 -> 0 | CA16: =VLOOKUP(A16,'25'!B:BA,52,0) -> 0 | CB16: ชิ้น | CC16: =+CA16*C16 -> 0 | CD16: =VLOOKUP(A16,'26'!B:BA,52,0) -> 0 | CE16: ชิ้น | CF16: =+CD16*C16 -> 0 | CG16: =VLOOKUP(A16,'27'!B:BA,52,0) -> 0 | CH16: ชิ้น | CI16: =+CG16*C16 -> 0 | CJ16: =VLOOKUP(A16,'28'!B:BA,52,0) -> 0 | CK16: ชิ้น | CL16: =+CJ16*C16 -> 0 | CM16: =VLOOKUP(A16,'29'!B:BA,52,0) -> 0 | CN16: ชิ้น | CO16: =+CM16*C16 -> 0 | CP16: =VLOOKUP(A16,'30'!B:BA,52,0) -> 0 | CQ16: ชิ้น | CR16: =+CP16*C16 -> 0 | CS16: =VLOOKUP(A16,'31'!B:BA,52,0) -> 0 | CT16: ชิ้น | CU16: =+CS16*C16 -> 0 | CV16: =VLOOKUP(A16,สรุป!B:BA,52,0) -> 0 | CW16: ชิ้น | CX16: =+CV16*C16 -> 0
A17: 1111076 | B17: ชิฟฟ่อนสอดไส้ 1 ชิ้น ชิฟฟ่อนเค้ก เลือกรสชาติได้ (ส้ม) | C17: 0 | D17: =+CV17 -> 0 | E17: ชิ้น | F17: =+D17*C17 -> 0 | G17: =VLOOKUP(A17,'1'!B:BA,52,0) -> 0 | H17: ชิ้น | I17: =+G17*C17 -> 0 | J17: =VLOOKUP(A17,'2'!B:BA,52,0) -> 0 | K17: ชิ้น | L17: =+J17*C17 -> 0 | M17: =VLOOKUP(A17,'3'!B:BA,52,0) -> 0 | N17: ชิ้น | O17: =+M17*C17 -> 0 | P17: =VLOOKUP(A17,'4'!B:BA,52,0) -> 0 | Q17: ชิ้น | R17: =+P17*C17 -> 0 | S17: =VLOOKUP(A17,'5'!B:BA,52,0) -> 0 | T17: ชิ้น | U17: =+S17*C17 -> 0 | V17: =VLOOKUP(A17,'6'!B:BA,52,0) -> 0 | W17: ชิ้น | X17: =+V17*C17 -> 0 | Y17: =VLOOKUP(A17,'7'!B:BA,52,0) -> 0 | Z17: ชิ้น | AA17: =+Y17*C17 -> 0 | AB17: =VLOOKUP(A17,'8'!B:BA,52,0) -> 0 | AC17: ชิ้น | AD17: =+AB17*C17 -> 0 | AE17: =VLOOKUP(A17,'9'!B:BA,52,0) -> 0 | AF17: ชิ้น | AG17: =+AE17*C17 -> 0 | AH17: =VLOOKUP(A17,'10'!B:BA,52,0) -> 0 | AI17: ชิ้น | AJ17: =+AH17*C17 -> 0 | AK17: =VLOOKUP(A17,'11'!B:BA,52,0) -> 0 | AL17: ชิ้น | AM17: =+AK17*C17 -> 0 | AN17: =VLOOKUP(A17,'12'!B:BA,52,0) -> 0 | AO17: ชิ้น | AP17: =+AN17*C17 -> 0 | AQ17: =VLOOKUP(A17,'13'!B:BA,52,0) -> 0 | AR17: ชิ้น | AS17: =+AQ17*C17 -> 0 | AT17: =VLOOKUP(A17,'14'!B:BA,52,0) -> 0 | AU17: ชิ้น | AV17: =+AT17*C17 -> 0 | AW17: =VLOOKUP(A17,'15'!B:BA,52,0) -> 0 | AX17: ชิ้น | AY17: =+AW17*C17 -> 0 | AZ17: =VLOOKUP(A17,'16'!B:BA,52,0) -> 0 | BA17: ชิ้น | BB17: =+AZ17*C17 -> 0 | BC17: =VLOOKUP(A17,'17'!B:BA,52,0) -> 0 | BD17: ชิ้น | BE17: =+BC17*C17 -> 0 | BF17: =VLOOKUP(A17,'18'!B:BA,52,0) -> 0 | BG17: ชิ้น | BH17: =+BF17*C17 -> 0 | BI17: =VLOOKUP(A17,'19'!B:BA,52,0) -> 0 | BJ17: ชิ้น | BK17: =+BI17*C17 -> 0 | BL17: =VLOOKUP(A17,'20'!B:BA,52,0) -> 0 | BM17: ชิ้น | BN17: =+BL17*C17 -> 0 | BO17: =VLOOKUP(A17,'21'!B:BA,52,0) -> 0 | BP17: ชิ้น | BQ17: =+BO17*C17 -> 0 | BR17: =VLOOKUP(A17,'22'!B:BA,52,0) -> 0 | BS17: ชิ้น | BT17: =+BR17*C17 -> 0 | BU17: =VLOOKUP(A17,'23'!B:BA,52,0) -> 0 | BV17: ชิ้น | BW17: =+BU17*C17 -> 0 | BX17: =VLOOKUP(A17,'24'!B:BA,52,0) -> 0 | BY17: ชิ้น | BZ17: =+BX17*C17 -> 0 | CA17: =VLOOKUP(A17,'25'!B:BA,52,0) -> 0 | CB17: ชิ้น | CC17: =+CA17*C17 -> 0 | CD17: =VLOOKUP(A17,'26'!B:BA,52,0) -> 0 | CE17: ชิ้น | CF17: =+CD17*C17 -> 0 | CG17: =VLOOKUP(A17,'27'!B:BA,52,0) -> 0 | CH17: ชิ้น | CI17: =+CG17*C17 -> 0 | CJ17: =VLOOKUP(A17,'28'!B:BA,52,0) -> 0 | CK17: ชิ้น | CL17: =+CJ17*C17 -> 0 | CM17: =VLOOKUP(A17,'29'!B:BA,52,0) -> 0 | CN17: ชิ้น | CO17: =+CM17*C17 -> 0 | CP17: =VLOOKUP(A17,'30'!B:BA,52,0) -> 0 | CQ17: ชิ้น | CR17: =+CP17*C17 -> 0 | CS17: =VLOOKUP(A17,'31'!B:BA,52,0) -> 0 | CT17: ชิ้น | CU17: =+CS17*C17 -> 0 | CV17: =VLOOKUP(A17,สรุป!B:BA,52,0) -> 0 | CW17: ชิ้น | CX17: =+CV17*C17 -> 0
A18: 1111077 | B18: ชิฟฟ่อนสอดไส้ 1 ชิ้น ชิฟฟ่อนเค้ก เลือกรสชาติได้ (บลูเบอรี่) | C18: 0 | D18: =+CV18 -> 0 | E18: ชิ้น | F18: =+D18*C18 -> 0 | G18: =VLOOKUP(A18,'1'!B:BA,52,0) -> 0 | H18: ชิ้น | I18: =+G18*C18 -> 0 | J18: =VLOOKUP(A18,'2'!B:BA,52,0) -> 0 | K18: ชิ้น | L18: =+J18*C18 -> 0 | M18: =VLOOKUP(A18,'3'!B:BA,52,0) -> 0 | N18: ชิ้น | O18: =+M18*C18 -> 0 | P18: =VLOOKUP(A18,'4'!B:BA,52,0) -> 0 | Q18: ชิ้น | R18: =+P18*C18 -> 0 | S18: =VLOOKUP(A18,'5'!B:BA,52,0) -> 0 | T18: ชิ้น | U18: =+S18*C18 -> 0 | V18: =VLOOKUP(A18,'6'!B:BA,52,0) -> 0 | W18: ชิ้น | X18: =+V18*C18 -> 0 | Y18: =VLOOKUP(A18,'7'!B:BA,52,0) -> 0 | Z18: ชิ้น | AA18: =+Y18*C18 -> 0 | AB18: =VLOOKUP(A18,'8'!B:BA,52,0) -> 0 | AC18: ชิ้น | AD18: =+AB18*C18 -> 0 | AE18: =VLOOKUP(A18,'9'!B:BA,52,0) -> 0 | AF18: ชิ้น | AG18: =+AE18*C18 -> 0 | AH18: =VLOOKUP(A18,'10'!B:BA,52,0) -> 0 | AI18: ชิ้น | AJ18: =+AH18*C18 -> 0 | AK18: =VLOOKUP(A18,'11'!B:BA,52,0) -> 0 | AL18: ชิ้น | AM18: =+AK18*C18 -> 0 | AN18: =VLOOKUP(A18,'12'!B:BA,52,0) -> 0 | AO18: ชิ้น | AP18: =+AN18*C18 -> 0 | AQ18: =VLOOKUP(A18,'13'!B:BA,52,0) -> 0 | AR18: ชิ้น | AS18: =+AQ18*C18 -> 0 | AT18: =VLOOKUP(A18,'14'!B:BA,52,0) -> 0 | AU18: ชิ้น | AV18: =+AT18*C18 -> 0 | AW18: =VLOOKUP(A18,'15'!B:BA,52,0) -> 0 | AX18: ชิ้น | AY18: =+AW18*C18 -> 0 | AZ18: =VLOOKUP(A18,'16'!B:BA,52,0) -> 0 | BA18: ชิ้น | BB18: =+AZ18*C18 -> 0 | BC18: =VLOOKUP(A18,'17'!B:BA,52,0) -> 0 | BD18: ชิ้น | BE18: =+BC18*C18 -> 0 | BF18: =VLOOKUP(A18,'18'!B:BA,52,0) -> 0 | BG18: ชิ้น | BH18: =+BF18*C18 -> 0 | BI18: =VLOOKUP(A18,'19'!B:BA,52,0) -> 0 | BJ18: ชิ้น | BK18: =+BI18*C18 -> 0 | BL18: =VLOOKUP(A18,'20'!B:BA,52,0) -> 0 | BM18: ชิ้น | BN18: =+BL18*C18 -> 0 | BO18: =VLOOKUP(A18,'21'!B:BA,52,0) -> 0 | BP18: ชิ้น | BQ18: =+BO18*C18 -> 0 | BR18: =VLOOKUP(A18,'22'!B:BA,52,0) -> 0 | BS18: ชิ้น | BT18: =+BR18*C18 -> 0 | BU18: =VLOOKUP(A18,'23'!B:BA,52,0) -> 0 | BV18: ชิ้น | BW18: =+BU18*C18 -> 0 | BX18: =VLOOKUP(A18,'24'!B:BA,52,0) -> 0 | BY18: ชิ้น | BZ18: =+BX18*C18 -> 0 | CA18: =VLOOKUP(A18,'25'!B:BA,52,0) -> 0 | CB18: ชิ้น | CC18: =+CA18*C18 -> 0 | CD18: =VLOOKUP(A18,'26'!B:BA,52,0) -> 0 | CE18: ชิ้น | CF18: =+CD18*C18 -> 0 | CG18: =VLOOKUP(A18,'27'!B:BA,52,0) -> 0 | CH18: ชิ้น | CI18: =+CG18*C18 -> 0 | CJ18: =VLOOKUP(A18,'28'!B:BA,52,0) -> 0 | CK18: ชิ้น | CL18: =+CJ18*C18 -> 0 | CM18: =VLOOKUP(A18,'29'!B:BA,52,0) -> 0 | CN18: ชิ้น | CO18: =+CM18*C18 -> 0 | CP18: =VLOOKUP(A18,'30'!B:BA,52,0) -> 0 | CQ18: ชิ้น | CR18: =+CP18*C18 -> 0 | CS18: =VLOOKUP(A18,'31'!B:BA,52,0) -> 0 | CT18: ชิ้น | CU18: =+CS18*C18 -> 0 | CV18: =VLOOKUP(A18,สรุป!B:BA,52,0) -> 0 | CW18: ชิ้น | CX18: =+CV18*C18 -> 0
A19: 1111078 | B19: ชิฟฟ่อนสอดไส้ 1 ชิ้น ชิฟฟ่อนเค้ก เลือกรสชาติได้ (นมชมพู) | C19: 0 | D19: =+CV19 -> 0 | E19: ชิ้น | F19: =+D19*C19 -> 0 | G19: =VLOOKUP(A19,'1'!B:BA,52,0) -> 0 | H19: ชิ้น | I19: =+G19*C19 -> 0 | J19: =VLOOKUP(A19,'2'!B:BA,52,0) -> 0 | K19: ชิ้น | L19: =+J19*C19 -> 0 | M19: =VLOOKUP(A19,'3'!B:BA,52,0) -> 0 | N19: ชิ้น | O19: =+M19*C19 -> 0 | P19: =VLOOKUP(A19,'4'!B:BA,52,0) -> 0 | Q19: ชิ้น | R19: =+P19*C19 -> 0 | S19: =VLOOKUP(A19,'5'!B:BA,52,0) -> 0 | T19: ชิ้น | U19: =+S19*C19 -> 0 | V19: =VLOOKUP(A19,'6'!B:BA,52,0) -> 0 | W19: ชิ้น | X19: =+V19*C19 -> 0 | Y19: =VLOOKUP(A19,'7'!B:BA,52,0) -> 0 | Z19: ชิ้น | AA19: =+Y19*C19 -> 0 | AB19: =VLOOKUP(A19,'8'!B:BA,52,0) -> 0 | AC19: ชิ้น | AD19: =+AB19*C19 -> 0 | AE19: =VLOOKUP(A19,'9'!B:BA,52,0) -> 0 | AF19: ชิ้น | AG19: =+AE19*C19 -> 0 | AH19: =VLOOKUP(A19,'10'!B:BA,52,0) -> 0 | AI19: ชิ้น | AJ19: =+AH19*C19 -> 0 | AK19: =VLOOKUP(A19,'11'!B:BA,52,0) -> 0 | AL19: ชิ้น | AM19: =+AK19*C19 -> 0 | AN19: =VLOOKUP(A19,'12'!B:BA,52,0) -> 0 | AO19: ชิ้น | AP19: =+AN19*C19 -> 0 | AQ19: =VLOOKUP(A19,'13'!B:BA,52,0) -> 0 | AR19: ชิ้น | AS19: =+AQ19*C19 -> 0 | AT19: =VLOOKUP(A19,'14'!B:BA,52,0) -> 0 | AU19: ชิ้น | AV19: =+AT19*C19 -> 0 | AW19: =VLOOKUP(A19,'15'!B:BA,52,0) -> 0 | AX19: ชิ้น | AY19: =+AW19*C19 -> 0 | AZ19: =VLOOKUP(A19,'16'!B:BA,52,0) -> 0 | BA19: ชิ้น | BB19: =+AZ19*C19 -> 0 | BC19: =VLOOKUP(A19,'17'!B:BA,52,0) -> 0 | BD19: ชิ้น | BE19: =+BC19*C19 -> 0 | BF19: =VLOOKUP(A19,'18'!B:BA,52,0) -> 0 | BG19: ชิ้น | BH19: =+BF19*C19 -> 0 | BI19: =VLOOKUP(A19,'19'!B:BA,52,0) -> 0 | BJ19: ชิ้น | BK19: =+BI19*C19 -> 0 | BL19: =VLOOKUP(A19,'20'!B:BA,52,0) -> 0 | BM19: ชิ้น | BN19: =+BL19*C19 -> 0 | BO19: =VLOOKUP(A19,'21'!B:BA,52,0) -> 0 | BP19: ชิ้น | BQ19: =+BO19*C19 -> 0 | BR19: =VLOOKUP(A19,'22'!B:BA,52,0) -> 0 | BS19: ชิ้น | BT19: =+BR19*C19 -> 0 | BU19: =VLOOKUP(A19,'23'!B:BA,52,0) -> 0 | BV19: ชิ้น | BW19: =+BU19*C19 -> 0 | BX19: =VLOOKUP(A19,'24'!B:BA,52,0) -> 0 | BY19: ชิ้น | BZ19: =+BX19*C19 -> 0 | CA19: =VLOOKUP(A19,'25'!B:BA,52,0) -> 0 | CB19: ชิ้น | CC19: =+CA19*C19 -> 0 | CD19: =VLOOKUP(A19,'26'!B:BA,52,0) -> 0 | CE19: ชิ้น | CF19: =+CD19*C19 -> 0 | CG19: =VLOOKUP(A19,'27'!B:BA,52,0) -> 0 | CH19: ชิ้น | CI19: =+CG19*C19 -> 0 | CJ19: =VLOOKUP(A19,'28'!B:BA,52,0) -> 0 | CK19: ชิ้น | CL19: =+CJ19*C19 -> 0 | CM19: =VLOOKUP(A19,'29'!B:BA,52,0) -> 0 | CN19: ชิ้น | CO19: =+CM19*C19 -> 0 | CP19: =VLOOKUP(A19,'30'!B:BA,52,0) -> 0 | CQ19: ชิ้น | CR19: =+CP19*C19 -> 0 | CS19: =VLOOKUP(A19,'31'!B:BA,52,0) -> 0 | CT19: ชิ้น | CU19: =+CS19*C19 -> 0 | CV19: =VLOOKUP(A19,สรุป!B:BA,52,0) -> 0 | CW19: ชิ้น | CX19: =+CV19*C19 -> 0
A20: 1111079 | B20: ชิฟฟ่อนสอดไส้ 1 ชิ้น ชิฟฟ่อนเค้ก เลือกรสชาติได้ (ช็อกโกแลต) | C20: 0 | D20: =+CV20 -> 0 | E20: ชิ้น | F20: =+D20*C20 -> 0 | G20: =VLOOKUP(A20,'1'!B:BA,52,0) -> 0 | H20: ชิ้น | I20: =+G20*C20 -> 0 | J20: =VLOOKUP(A20,'2'!B:BA,52,0) -> 0 | K20: ชิ้น | L20: =+J20*C20 -> 0 | M20: =VLOOKUP(A20,'3'!B:BA,52,0) -> 0 | N20: ชิ้น | O20: =+M20*C20 -> 0 | P20: =VLOOKUP(A20,'4'!B:BA,52,0) -> 0 | Q20: ชิ้น | R20: =+P20*C20 -> 0 | S20: =VLOOKUP(A20,'5'!B:BA,52,0) -> 0 | T20: ชิ้น | U20: =+S20*C20 -> 0 | V20: =VLOOKUP(A20,'6'!B:BA,52,0) -> 0 | W20: ชิ้น | X20: =+V20*C20 -> 0 | Y20: =VLOOKUP(A20,'7'!B:BA,52,0) -> 0 | Z20: ชิ้น | AA20: =+Y20*C20 -> 0 | AB20: =VLOOKUP(A20,'8'!B:BA,52,0) -> 0 | AC20: ชิ้น | AD20: =+AB20*C20 -> 0 | AE20: =VLOOKUP(A20,'9'!B:BA,52,0) -> 0 | AF20: ชิ้น | AG20: =+AE20*C20 -> 0 | AH20: =VLOOKUP(A20,'10'!B:BA,52,0) -> 0 | AI20: ชิ้น | AJ20: =+AH20*C20 -> 0 | AK20: =VLOOKUP(A20,'11'!B:BA,52,0) -> 0 | AL20: ชิ้น | AM20: =+AK20*C20 -> 0 | AN20: =VLOOKUP(A20,'12'!B:BA,52,0) -> 0 | AO20: ชิ้น | AP20: =+AN20*C20 -> 0 | AQ20: =VLOOKUP(A20,'13'!B:BA,52,0) -> 0 | AR20: ชิ้น | AS20: =+AQ20*C20 -> 0 | AT20: =VLOOKUP(A20,'14'!B:BA,52,0) -> 0 | AU20: ชิ้น | AV20: =+AT20*C20 -> 0 | AW20: =VLOOKUP(A20,'15'!B:BA,52,0) -> 0 | AX20: ชิ้น | AY20: =+AW20*C20 -> 0 | AZ20: =VLOOKUP(A20,'16'!B:BA,52,0) -> 0 | BA20: ชิ้น | BB20: =+AZ20*C20 -> 0 | BC20: =VLOOKUP(A20,'17'!B:BA,52,0) -> 0 | BD20: ชิ้น | BE20: =+BC20*C20 -> 0 | BF20: =VLOOKUP(A20,'18'!B:BA,52,0) -> 0 | BG20: ชิ้น | BH20: =+BF20*C20 -> 0 | BI20: =VLOOKUP(A20,'19'!B:BA,52,0) -> 0 | BJ20: ชิ้น | BK20: =+BI20*C20 -> 0 | BL20: =VLOOKUP(A20,'20'!B:BA,52,0) -> 0 | BM20: ชิ้น | BN20: =+BL20*C20 -> 0 | BO20: =VLOOKUP(A20,'21'!B:BA,52,0) -> 0 | BP20: ชิ้น | BQ20: =+BO20*C20 -> 0 | BR20: =VLOOKUP(A20,'22'!B:BA,52,0) -> 0 | BS20: ชิ้น | BT20: =+BR20*C20 -> 0 | BU20: =VLOOKUP(A20,'23'!B:BA,52,0) -> 0 | BV20: ชิ้น | BW20: =+BU20*C20 -> 0 | BX20: =VLOOKUP(A20,'24'!B:BA,52,0) -> 0 | BY20: ชิ้น | BZ20: =+BX20*C20 -> 0 | CA20: =VLOOKUP(A20,'25'!B:BA,52,0) -> 0 | CB20: ชิ้น | CC20: =+CA20*C20 -> 0 | CD20: =VLOOKUP(A20,'26'!B:BA,52,0) -> 0 | CE20: ชิ้น | CF20: =+CD20*C20 -> 0 | CG20: =VLOOKUP(A20,'27'!B:BA,52,0) -> 0 | CH20: ชิ้น | CI20: =+CG20*C20 -> 0 | CJ20: =VLOOKUP(A20,'28'!B:BA,52,0) -> 0 | CK20: ชิ้น | CL20: =+CJ20*C20 -> 0 | CM20: =VLOOKUP(A20,'29'!B:BA,52,0) -> 0 | CN20: ชิ้น | CO20: =+CM20*C20 -> 0 | CP20: =VLOOKUP(A20,'30'!B:BA,52,0) -> 0 | CQ20: ชิ้น | CR20: =+CP20*C20 -> 0 | CS20: =VLOOKUP(A20,'31'!B:BA,52,0) -> 0 | CT20: ชิ้น | CU20: =+CS20*C20 -> 0 | CV20: =VLOOKUP(A20,สรุป!B:BA,52,0) -> 0 | CW20: ชิ้น | CX20: =+CV20*C20 -> 0
A21: 1111080 | B21: ชิฟฟ่อนสอดไส้ 1 ชิ้น ชิฟฟ่อนเค้ก เลือกรสชาติได้ (ฝอยทอง) | C21: 0 | D21: =+CV21 -> 0 | E21: ชิ้น | F21: =+D21*C21 -> 0 | G21: =VLOOKUP(A21,'1'!B:BA,52,0) -> 0 | H21: ชิ้น | I21: =+G21*C21 -> 0 | J21: =VLOOKUP(A21,'2'!B:BA,52,0) -> 0 | K21: ชิ้น | L21: =+J21*C21 -> 0 | M21: =VLOOKUP(A21,'3'!B:BA,52,0) -> 0 | N21: ชิ้น | O21: =+M21*C21 -> 0 | P21: =VLOOKUP(A21,'4'!B:BA,52,0) -> 0 | Q21: ชิ้น | R21: =+P21*C21 -> 0 | S21: =VLOOKUP(A21,'5'!B:BA,52,0) -> 0 | T21: ชิ้น | U21: =+S21*C21 -> 0 | V21: =VLOOKUP(A21,'6'!B:BA,52,0) -> 0 | W21: ชิ้น | X21: =+V21*C21 -> 0 | Y21: =VLOOKUP(A21,'7'!B:BA,52,0) -> 0 | Z21: ชิ้น | AA21: =+Y21*C21 -> 0 | AB21: =VLOOKUP(A21,'8'!B:BA,52,0) -> 0 | AC21: ชิ้น | AD21: =+AB21*C21 -> 0 | AE21: =VLOOKUP(A21,'9'!B:BA,52,0) -> 0 | AF21: ชิ้น | AG21: =+AE21*C21 -> 0 | AH21: =VLOOKUP(A21,'10'!B:BA,52,0) -> 0 | AI21: ชิ้น | AJ21: =+AH21*C21 -> 0 | AK21: =VLOOKUP(A21,'11'!B:BA,52,0) -> 0 | AL21: ชิ้น | AM21: =+AK21*C21 -> 0 | AN21: =VLOOKUP(A21,'12'!B:BA,52,0) -> 0 | AO21: ชิ้น | AP21: =+AN21*C21 -> 0 | AQ21: =VLOOKUP(A21,'13'!B:BA,52,0) -> 0 | AR21: ชิ้น | AS21: =+AQ21*C21 -> 0 | AT21: =VLOOKUP(A21,'14'!B:BA,52,0) -> 0 | AU21: ชิ้น | AV21: =+AT21*C21 -> 0 | AW21: =VLOOKUP(A21,'15'!B:BA,52,0) -> 0 | AX21: ชิ้น | AY21: =+AW21*C21 -> 0 | AZ21: =VLOOKUP(A21,'16'!B:BA,52,0) -> 0 | BA21: ชิ้น | BB21: =+AZ21*C21 -> 0 | BC21: =VLOOKUP(A21,'17'!B:BA,52,0) -> 0 | BD21: ชิ้น | BE21: =+BC21*C21 -> 0 | BF21: =VLOOKUP(A21,'18'!B:BA,52,0) -> 0 | BG21: ชิ้น | BH21: =+BF21*C21 -> 0 | BI21: =VLOOKUP(A21,'19'!B:BA,52,0) -> 0 | BJ21: ชิ้น | BK21: =+BI21*C21 -> 0 | BL21: =VLOOKUP(A21,'20'!B:BA,52,0) -> 0 | BM21: ชิ้น | BN21: =+BL21*C21 -> 0 | BO21: =VLOOKUP(A21,'21'!B:BA,52,0) -> 0 | BP21: ชิ้น | BQ21: =+BO21*C21 -> 0 | BR21: =VLOOKUP(A21,'22'!B:BA,52,0) -> 0 | BS21: ชิ้น | BT21: =+BR21*C21 -> 0 | BU21: =VLOOKUP(A21,'23'!B:BA,52,0) -> 0 | BV21: ชิ้น | BW21: =+BU21*C21 -> 0 | BX21: =VLOOKUP(A21,'24'!B:BA,52,0) -> 0 | BY21: ชิ้น | BZ21: =+BX21*C21 -> 0 | CA21: =VLOOKUP(A21,'25'!B:BA,52,0) -> 0 | CB21: ชิ้น | CC21: =+CA21*C21 -> 0 | CD21: =VLOOKUP(A21,'26'!B:BA,52,0) -> 0 | CE21: ชิ้น | CF21: =+CD21*C21 -> 0 | CG21: =VLOOKUP(A21,'27'!B:BA,52,0) -> 0 | CH21: ชิ้น | CI21: =+CG21*C21 -> 0 | CJ21: =VLOOKUP(A21,'28'!B:BA,52,0) -> 0 | CK21: ชิ้น | CL21: =+CJ21*C21 -> 0 | CM21: =VLOOKUP(A21,'29'!B:BA,52,0) -> 0 | CN21: ชิ้น | CO21: =+CM21*C21 -> 0 | CP21: =VLOOKUP(A21,'30'!B:BA,52,0) -> 0 | CQ21: ชิ้น | CR21: =+CP21*C21 -> 0 | CS21: =VLOOKUP(A21,'31'!B:BA,52,0) -> 0 | CT21: ชิ้น | CU21: =+CS21*C21 -> 0 | CV21: =VLOOKUP(A21,สรุป!B:BA,52,0) -> 0 | CW21: ชิ้น | CX21: =+CV21*C21 -> 0
A22: 1111081 | B22: ชิฟฟ่อนสอดไส้ 1 ชิ้น ชิฟฟ่อนเค้ก เลือกรสชาติได้ (วนิลา) | C22: 0 | D22: =+CV22 -> 0 | E22: ชิ้น | F22: =+D22*C22 -> 0 | G22: =VLOOKUP(A22,'1'!B:BA,52,0) -> 0 | H22: ชิ้น | I22: =+G22*C22 -> 0 | J22: =VLOOKUP(A22,'2'!B:BA,52,0) -> 0 | K22: ชิ้น | L22: =+J22*C22 -> 0 | M22: =VLOOKUP(A22,'3'!B:BA,52,0) -> 0 | N22: ชิ้น | O22: =+M22*C22 -> 0 | P22: =VLOOKUP(A22,'4'!B:BA,52,0) -> 0 | Q22: ชิ้น | R22: =+P22*C22 -> 0 | S22: =VLOOKUP(A22,'5'!B:BA,52,0) -> 0 | T22: ชิ้น | U22: =+S22*C22 -> 0 | V22: =VLOOKUP(A22,'6'!B:BA,52,0) -> 0 | W22: ชิ้น | X22: =+V22*C22 -> 0 | Y22: =VLOOKUP(A22,'7'!B:BA,52,0) -> 0 | Z22: ชิ้น | AA22: =+Y22*C22 -> 0 | AB22: =VLOOKUP(A22,'8'!B:BA,52,0) -> 0 | AC22: ชิ้น | AD22: =+AB22*C22 -> 0 | AE22: =VLOOKUP(A22,'9'!B:BA,52,0) -> 0 | AF22: ชิ้น | AG22: =+AE22*C22 -> 0 | AH22: =VLOOKUP(A22,'10'!B:BA,52,0) -> 0 | AI22: ชิ้น | AJ22: =+AH22*C22 -> 0 | AK22: =VLOOKUP(A22,'11'!B:BA,52,0) -> 0 | AL22: ชิ้น | AM22: =+AK22*C22 -> 0 | AN22: =VLOOKUP(A22,'12'!B:BA,52,0) -> 0 | AO22: ชิ้น | AP22: =+AN22*C22 -> 0 | AQ22: =VLOOKUP(A22,'13'!B:BA,52,0) -> 0 | AR22: ชิ้น | AS22: =+AQ22*C22 -> 0 | AT22: =VLOOKUP(A22,'14'!B:BA,52,0) -> 0 | AU22: ชิ้น | AV22: =+AT22*C22 -> 0 | AW22: =VLOOKUP(A22,'15'!B:BA,52,0) -> 0 | AX22: ชิ้น | AY22: =+AW22*C22 -> 0 | AZ22: =VLOOKUP(A22,'16'!B:BA,52,0) -> 0 | BA22: ชิ้น | BB22: =+AZ22*C22 -> 0 | BC22: =VLOOKUP(A22,'17'!B:BA,52,0) -> 0 | BD22: ชิ้น | BE22: =+BC22*C22 -> 0 | BF22: =VLOOKUP(A22,'18'!B:BA,52,0) -> 0 | BG22: ชิ้น | BH22: =+BF22*C22 -> 0 | BI22: =VLOOKUP(A22,'19'!B:BA,52,0) -> 0 | BJ22: ชิ้น | BK22: =+BI22*C22 -> 0 | BL22: =VLOOKUP(A22,'20'!B:BA,52,0) -> 0 | BM22: ชิ้น | BN22: =+BL22*C22 -> 0 | BO22: =VLOOKUP(A22,'21'!B:BA,52,0) -> 0 | BP22: ชิ้น | BQ22: =+BO22*C22 -> 0 | BR22: =VLOOKUP(A22,'22'!B:BA,52,0) -> 0 | BS22: ชิ้น | BT22: =+BR22*C22 -> 0 | BU22: =VLOOKUP(A22,'23'!B:BA,52,0) -> 0 | BV22: ชิ้น | BW22: =+BU22*C22 -> 0 | BX22: =VLOOKUP(A22,'24'!B:BA,52,0) -> 0 | BY22: ชิ้น | BZ22: =+BX22*C22 -> 0 | CA22: =VLOOKUP(A22,'25'!B:BA,52,0) -> 0 | CB22: ชิ้น | CC22: =+CA22*C22 -> 0 | CD22: =VLOOKUP(A22,'26'!B:BA,52,0) -> 0 | CE22: ชิ้น | CF22: =+CD22*C22 -> 0 | CG22: =VLOOKUP(A22,'27'!B:BA,52,0) -> 0 | CH22: ชิ้น | CI22: =+CG22*C22 -> 0 | CJ22: =VLOOKUP(A22,'28'!B:BA,52,0) -> 0 | CK22: ชิ้น | CL22: =+CJ22*C22 -> 0 | CM22: =VLOOKUP(A22,'29'!B:BA,52,0) -> 0 | CN22: ชิ้น | CO22: =+CM22*C22 -> 0 | CP22: =VLOOKUP(A22,'30'!B:BA,52,0) -> 0 | CQ22: ชิ้น | CR22: =+CP22*C22 -> 0 | CS22: =VLOOKUP(A22,'31'!B:BA,52,0) -> 0 | CT22: ชิ้น | CU22: =+CS22*C22 -> 0 | CV22: =VLOOKUP(A22,สรุป!B:BA,52,0) -> 0 | CW22: ชิ้น | CX22: =+CV22*C22 -> 0
A23: 1111082 | B23: ชิฟฟ่อนสอดไส้ 1 ชิ้น ชิฟฟ่อนเค้ก เลือกรสชาติได้ (ใบเตย) | C23: 0 | D23: =+CV23 -> 0 | E23: ชิ้น | F23: =+D23*C23 -> 0 | G23: =VLOOKUP(A23,'1'!B:BA,52,0) -> 0 | H23: ชิ้น | I23: =+G23*C23 -> 0 | J23: =VLOOKUP(A23,'2'!B:BA,52,0) -> 0 | K23: ชิ้น | L23: =+J23*C23 -> 0 | M23: =VLOOKUP(A23,'3'!B:BA,52,0) -> 0 | N23: ชิ้น | O23: =+M23*C23 -> 0 | P23: =VLOOKUP(A23,'4'!B:BA,52,0) -> 0 | Q23: ชิ้น | R23: =+P23*C23 -> 0 | S23: =VLOOKUP(A23,'5'!B:BA,52,0) -> 0 | T23: ชิ้น | U23: =+S23*C23 -> 0 | V23: =VLOOKUP(A23,'6'!B:BA,52,0) -> 0 | W23: ชิ้น | X23: =+V23*C23 -> 0 | Y23: =VLOOKUP(A23,'7'!B:BA,52,0) -> 0 | Z23: ชิ้น | AA23: =+Y23*C23 -> 0 | AB23: =VLOOKUP(A23,'8'!B:BA,52,0) -> 0 | AC23: ชิ้น | AD23: =+AB23*C23 -> 0 | AE23: =VLOOKUP(A23,'9'!B:BA,52,0) -> 0 | AF23: ชิ้น | AG23: =+AE23*C23 -> 0 | AH23: =VLOOKUP(A23,'10'!B:BA,52,0) -> 0 | AI23: ชิ้น | AJ23: =+AH23*C23 -> 0 | AK23: =VLOOKUP(A23,'11'!B:BA,52,0) -> 0 | AL23: ชิ้น | AM23: =+AK23*C23 -> 0 | AN23: =VLOOKUP(A23,'12'!B:BA,52,0) -> 0 | AO23: ชิ้น | AP23: =+AN23*C23 -> 0 | AQ23: =VLOOKUP(A23,'13'!B:BA,52,0) -> 0 | AR23: ชิ้น | AS23: =+AQ23*C23 -> 0 | AT23: =VLOOKUP(A23,'14'!B:BA,52,0) -> 0 | AU23: ชิ้น | AV23: =+AT23*C23 -> 0 | AW23: =VLOOKUP(A23,'15'!B:BA,52,0) -> 0 | AX23: ชิ้น | AY23: =+AW23*C23 -> 0 | AZ23: =VLOOKUP(A23,'16'!B:BA,52,0) -> 0 | BA23: ชิ้น | BB23: =+AZ23*C23 -> 0 | BC23: =VLOOKUP(A23,'17'!B:BA,52,0) -> 0 | BD23: ชิ้น | BE23: =+BC23*C23 -> 0 | BF23: =VLOOKUP(A23,'18'!B:BA,52,0) -> 0 | BG23: ชิ้น | BH23: =+BF23*C23 -> 0 | BI23: =VLOOKUP(A23,'19'!B:BA,52,0) -> 0 | BJ23: ชิ้น | BK23: =+BI23*C23 -> 0 | BL23: =VLOOKUP(A23,'20'!B:BA,52,0) -> 0 | BM23: ชิ้น | BN23: =+BL23*C23 -> 0 | BO23: =VLOOKUP(A23,'21'!B:BA,52,0) -> 0 | BP23: ชิ้น | BQ23: =+BO23*C23 -> 0 | BR23: =VLOOKUP(A23,'22'!B:BA,52,0) -> 0 | BS23: ชิ้น | BT23: =+BR23*C23 -> 0 | BU23: =VLOOKUP(A23,'23'!B:BA,52,0) -> 0 | BV23: ชิ้น | BW23: =+BU23*C23 -> 0 | BX23: =VLOOKUP(A23,'24'!B:BA,52,0) -> 0 | BY23: ชิ้น | BZ23: =+BX23*C23 -> 0 | CA23: =VLOOKUP(A23,'25'!B:BA,52,0) -> 0 | CB23: ชิ้น | CC23: =+CA23*C23 -> 0 | CD23: =VLOOKUP(A23,'26'!B:BA,52,0) -> 0 | CE23: ชิ้น | CF23: =+CD23*C23 -> 0 | CG23: =VLOOKUP(A23,'27'!B:BA,52,0) -> 0 | CH23: ชิ้น | CI23: =+CG23*C23 -> 0 | CJ23: =VLOOKUP(A23,'28'!B:BA,52,0) -> 0 | CK23: ชิ้น | CL23: =+CJ23*C23 -> 0 | CM23: =VLOOKUP(A23,'29'!B:BA,52,0) -> 0 | CN23: ชิ้น | CO23: =+CM23*C23 -> 0 | CP23: =VLOOKUP(A23,'30'!B:BA,52,0) -> 0 | CQ23: ชิ้น | CR23: =+CP23*C23 -> 0 | CS23: =VLOOKUP(A23,'31'!B:BA,52,0) -> 0 | CT23: ชิ้น | CU23: =+CS23*C23 -> 0 | CV23: =VLOOKUP(A23,สรุป!B:BA,52,0) -> 0 | CW23: ชิ้น | CX23: =+CV23*C23 -> 0
A24: 1111083 | B24: ชิฟฟ่อนสอดไส้ 1 ชิ้น ชิฟฟ่อนเค้ก เลือกรสชาติได้ (เมล่อน) | C24: 0 | D24: =+CV24 -> 0 | E24: ชิ้น | F24: =+D24*C24 -> 0 | G24: =VLOOKUP(A24,'1'!B:BA,52,0) -> 0 | H24: ชิ้น | I24: =+G24*C24 -> 0 | J24: =VLOOKUP(A24,'2'!B:BA,52,0) -> 0 | K24: ชิ้น | L24: =+J24*C24 -> 0 | M24: =VLOOKUP(A24,'3'!B:BA,52,0) -> 0 | N24: ชิ้น | O24: =+M24*C24 -> 0 | P24: =VLOOKUP(A24,'4'!B:BA,52,0) -> 0 | Q24: ชิ้น | R24: =+P24*C24 -> 0 | S24: =VLOOKUP(A24,'5'!B:BA,52,0) -> 0 | T24: ชิ้น | U24: =+S24*C24 -> 0 | V24: =VLOOKUP(A24,'6'!B:BA,52,0) -> 0 | W24: ชิ้น | X24: =+V24*C24 -> 0 | Y24: =VLOOKUP(A24,'7'!B:BA,52,0) -> 0 | Z24: ชิ้น | AA24: =+Y24*C24 -> 0 | AB24: =VLOOKUP(A24,'8'!B:BA,52,0) -> 0 | AC24: ชิ้น | AD24: =+AB24*C24 -> 0 | AE24: =VLOOKUP(A24,'9'!B:BA,52,0) -> 0 | AF24: ชิ้น | AG24: =+AE24*C24 -> 0 | AH24: =VLOOKUP(A24,'10'!B:BA,52,0) -> 0 | AI24: ชิ้น | AJ24: =+AH24*C24 -> 0 | AK24: =VLOOKUP(A24,'11'!B:BA,52,0) -> 0 | AL24: ชิ้น | AM24: =+AK24*C24 -> 0 | AN24: =VLOOKUP(A24,'12'!B:BA,52,0) -> 0 | AO24: ชิ้น | AP24: =+AN24*C24 -> 0 | AQ24: =VLOOKUP(A24,'13'!B:BA,52,0) -> 0 | AR24: ชิ้น | AS24: =+AQ24*C24 -> 0 | AT24: =VLOOKUP(A24,'14'!B:BA,52,0) -> 0 | AU24: ชิ้น | AV24: =+AT24*C24 -> 0 | AW24: =VLOOKUP(A24,'15'!B:BA,52,0) -> 0 | AX24: ชิ้น | AY24: =+AW24*C24 -> 0 | AZ24: =VLOOKUP(A24,'16'!B:BA,52,0) -> 0 | BA24: ชิ้น | BB24: =+AZ24*C24 -> 0 | BC24: =VLOOKUP(A24,'17'!B:BA,52,0) -> 0 | BD24: ชิ้น | BE24: =+BC24*C24 -> 0 | BF24: =VLOOKUP(A24,'18'!B:BA,52,0) -> 0 | BG24: ชิ้น | BH24: =+BF24*C24 -> 0 | BI24: =VLOOKUP(A24,'19'!B:BA,52,0) -> 0 | BJ24: ชิ้น | BK24: =+BI24*C24 -> 0 | BL24: =VLOOKUP(A24,'20'!B:BA,52,0) -> 0 | BM24: ชิ้น | BN24: =+BL24*C24 -> 0 | BO24: =VLOOKUP(A24,'21'!B:BA,52,0) -> 0 | BP24: ชิ้น | BQ24: =+BO24*C24 -> 0 | BR24: =VLOOKUP(A24,'22'!B:BA,52,0) -> 0 | BS24: ชิ้น | BT24: =+BR24*C24 -> 0 | BU24: =VLOOKUP(A24,'23'!B:BA,52,0) -> 0 | BV24: ชิ้น | BW24: =+BU24*C24 -> 0 | BX24: =VLOOKUP(A24,'24'!B:BA,52,0) -> 0 | BY24: ชิ้น | BZ24: =+BX24*C24 -> 0 | CA24: =VLOOKUP(A24,'25'!B:BA,52,0) -> 0 | CB24: ชิ้น | CC24: =+CA24*C24 -> 0 | CD24: =VLOOKUP(A24,'26'!B:BA,52,0) -> 0 | CE24: ชิ้น | CF24: =+CD24*C24 -> 0 | CG24: =VLOOKUP(A24,'27'!B:BA,52,0) -> 0 | CH24: ชิ้น | CI24: =+CG24*C24 -> 0 | CJ24: =VLOOKUP(A24,'28'!B:BA,52,0) -> 0 | CK24: ชิ้น | CL24: =+CJ24*C24 -> 0 | CM24: =VLOOKUP(A24,'29'!B:BA,52,0) -> 0 | CN24: ชิ้น | CO24: =+CM24*C24 -> 0 | CP24: =VLOOKUP(A24,'30'!B:BA,52,0) -> 0 | CQ24: ชิ้น | CR24: =+CP24*C24 -> 0 | CS24: =VLOOKUP(A24,'31'!B:BA,52,0) -> 0 | CT24: ชิ้น | CU24: =+CS24*C24 -> 0 | CV24: =VLOOKUP(A24,สรุป!B:BA,52,0) -> 0 | CW24: ชิ้น | CX24: =+CV24*C24 -> 0
A25: 1112003 | B25: เค้กเบาหวิวเล็ก 1กล่องขนาด 100 กรัม (กาแฟ) | C25: 19.08 | D25: =+CV25 -> 2114 | E25: กล่อง | F25: =+D25*C25 -> 40335.12 | G25: =VLOOKUP(A25,'1'!B:BA,52,0) -> 91 | H25: กล่อง | I25: =+G25*C25 -> 1736.28 | J25: =VLOOKUP(A25,'2'!B:BA,52,0) -> 105 | K25: กล่อง | L25: =+J25*C25 -> 2003.4 | M25: =VLOOKUP(A25,'3'!B:BA,52,0) -> 124 | N25: กล่อง | O25: =+M25*C25 -> 2365.92 | P25: =VLOOKUP(A25,'4'!B:BA,52,0) -> 94 | Q25: กล่อง | R25: =+P25*C25 -> 1793.52 | S25: =VLOOKUP(A25,'5'!B:BA,52,0) -> 58 | T25: กล่อง | U25: =+S25*C25 -> 1106.64 | V25: =VLOOKUP(A25,'6'!B:BA,52,0) -> 65 | W25: กล่อง | X25: =+V25*C25 -> 1240.2 | Y25: =VLOOKUP(A25,'7'!B:BA,52,0) -> 45 | Z25: กล่อง | AA25: =+Y25*C25 -> 858.6 | AB25: =VLOOKUP(A25,'8'!B:BA,52,0) -> 128 | AC25: กล่อง | AD25: =+AB25*C25 -> 2442.24 | AE25: =VLOOKUP(A25,'9'!B:BA,52,0) -> 103 | AF25: กล่อง | AG25: =+AE25*C25 -> 1965.24 | AH25: =VLOOKUP(A25,'10'!B:BA,52,0) -> 158 | AI25: กล่อง | AJ25: =+AH25*C25 -> 3014.64 | AK25: =VLOOKUP(A25,'11'!B:BA,52,0) -> 34 | AL25: กล่อง | AM25: =+AK25*C25 -> 648.72 | AN25: =VLOOKUP(A25,'12'!B:BA,52,0) -> 108 | AO25: กล่อง | AP25: =+AN25*C25 -> 2060.64 | AQ25: =VLOOKUP(A25,'13'!B:BA,52,0) -> 75 | AR25: กล่อง | AS25: =+AQ25*C25 -> 1431 | AT25: =VLOOKUP(A25,'14'!B:BA,52,0) -> 98 | AU25: กล่อง | AV25: =+AT25*C25 -> 1869.84 | AW25: =VLOOKUP(A25,'15'!B:BA,52,0) -> 52 | AX25: กล่อง | AY25: =+AW25*C25 -> 992.16 | AZ25: =VLOOKUP(A25,'16'!B:BA,52,0) -> 78 | BA25: กล่อง | BB25: =+AZ25*C25 -> 1488.24 | BC25: =VLOOKUP(A25,'17'!B:BA,52,0) -> 83 | BD25: กล่อง | BE25: =+BC25*C25 -> 1583.64 | BF25: =VLOOKUP(A25,'18'!B:BA,52,0) -> 67 | BG25: กล่อง | BH25: =+BF25*C25 -> 1278.36 | BI25: =VLOOKUP(A25,'19'!B:BA,52,0) -> 53 | BJ25: กล่อง | BK25: =+BI25*C25 -> 1011.24 | BL25: =VLOOKUP(A25,'20'!B:BA,52,0) -> 53 | BM25: กล่อง | BN25: =+BL25*C25 -> 1011.24 | BO25: =VLOOKUP(A25,'21'!B:BA,52,0) -> 65 | BP25: กล่อง | BQ25: =+BO25*C25 -> 1240.2 | BR25: =VLOOKUP(A25,'22'!B:BA,52,0) -> 60 | BS25: กล่อง | BT25: =+BR25*C25 -> 1144.8 | BU25: =VLOOKUP(A25,'23'!B:BA,52,0) -> 42 | BV25: กล่อง | BW25: =+BU25*C25 -> 801.36 | BX25: =VLOOKUP(A25,'24'!B:BA,52,0) -> 44 | BY25: กล่อง | BZ25: =+BX25*C25 -> 839.52 | CA25: =VLOOKUP(A25,'25'!B:BA,52,0) -> 63 | CB25: กล่อง | CC25: =+CA25*C25 -> 1202.04 | CD25: =VLOOKUP(A25,'26'!B:BA,52,0) -> 58 | CE25: กล่อง | CF25: =+CD25*C25 -> 1106.64 | CG25: =VLOOKUP(A25,'27'!B:BA,52,0) -> 45 | CH25: กล่อง | CI25: =+CG25*C25 -> 858.6 | CJ25: =VLOOKUP(A25,'28'!B:BA,52,0) -> 65 | CK25: กล่อง | CL25: =+CJ25*C25 -> 1240.2 | CM25: =VLOOKUP(A25,'29'!B:BA,52,0) -> 0 | CN25: กล่อง | CO25: =+CM25*C25 -> 0 | CP25: =VLOOKUP(A25,'30'!B:BA,52,0) -> 0 | CQ25: กล่อง | CR25: =+CP25*C25 -> 0 | CS25: =VLOOKUP(A25,'31'!B:BA,52,0) -> 0 | CT25: กล่อง | CU25: =+CS25*C25 -> 0 | CV25: =VLOOKUP(A25,สรุป!B:BA,52,0) -> 2114 | CW25: กล่อง | CX25: =+CV25*C25 -> 40335.12
