Workbook

Sheet ALL
A1: รายการขายสินค้าออนไลน์แยกจำนวนชิ้นรายวัน เดือนกุมภาพันธ์ 2569
E2: =SUBTOTAL(9,E5:E10473) -> 24212 | F2: =SUBTOTAL(9,F5:F10473) -> 24212 | G2: =SUBTOTAL(9,G5:G10473) -> 0 | H2: =SUBTOTAL(9,H5:H10473) -> 620244.71 | I2: =SUBTOTAL(9,I5:I10473) -> 0 | J2: =SUBTOTAL(9,J5:J10473) -> 0 | K2: =SUBTOTAL(9,K5:K10473) -> 0 | L2: =SUBTOTAL(9,L5:L10473) -> 1263 | ... CZ2: =SUBTOTAL(9,CZ5:CZ10473) -> 0
A3: รหัสสินค้า | B3: ชื่อสินค้า | C3: ราคาต้นทุน | D3: จำนวน | E3: สุทธิ | F3: เดือนกุมภาพันธ์ | I3: 244381 | L3: 244382 | O3: 244383 | R3: 244384 | U3: 244385 | X3: 244386 | AA3: 244387 | AD3: 244388 | AG3: 244389 | AJ3: 244390 | AM3: 244391 | AP3: 244392 | AS3: 244393 | AV3: 244394 | AY3: 244395 | BB3: 244396 | BE3: 244397 | BH3: 244398 | BK3: 244399 | BN3: 244400 | BQ3: 244401 | BT3: 244402 | BW3: 244403 | BZ3: 244404 | CC3: 244405 | CF3: 244406 | CI3: 244407 | CL3: 244408 | CO3: 244409 | CR3: 244410 | CU3: 244411 | CX3: เซตวันที่ 1-28/02/2569
F4: จำนวน | G4: หน่วย | H4: ยอดต้นทุน/วัน | I4: จำนวน | J4: หน่วย | K4: ยอดต้นทุน/วัน | L4: จำนวน | M4: หน่วย | N4: ยอดต้นทุน/วัน | O4: จำนวน | P4: หน่วย | Q4: ยอดต้นทุน/วัน | R4: จำนวน | S4: หน่วย | T4: ยอดต้นทุน/วัน | U4: จำนวน | V4: หน่วย | W4: ยอดต้นทุน/วัน | X4: จำนวน | Y4: หน่วย | Z4: ยอดต้นทุน/วัน | AA4: จำนวน | AB4: หน่วย | AC4: ยอดต้นทุน/วัน | AD4: จำนวน | AE4: หน่วย | AF4: ยอดต้นทุน/วัน | AG4: จำนวน | AH4: หน่วย | AI4: ยอดต้นทุน/วัน | AJ4: จำนวน | AK4: หน่วย | AL4: ยอดต้นทุน/วัน | AM4: จำนวน | AN4: หน่วย | AO4: ยอดต้นทุน/วัน | AP4: จำนวน | AQ4: หน่วย | AR4: ยอดต้นทุน/วัน | AS4: จำนวน | AT4: หน่วย | AU4: ยอดต้นทุน/วัน | AV4: จำนวน | AW4: หน่วย | AX4: ยอดต้นทุน/วัน | AY4: จำนวน | AZ4: หน่วย | BA4: ยอดต้นทุน/วัน | BB4: จำนวน | BC4: หน่วย | BD4: ยอดต้นทุน/วัน | BE4: จำนวน | BF4: หน่วย | BG4: ยอดต้นทุน/วัน | BH4: จำนวน | BI4: หน่วย | BJ4: ยอดต้นทุน/วัน | BK4: จำนวน | BL4: หน่วย | BM4: ยอดต้นทุน/วัน | BN4: จำนวน | BO4: หน่วย | BP4: ยอดต้นทุน/วัน | BQ4: จำนวน | BR4: หน่วย | BS4: ยอดต้นทุน/วัน | BT4: จำนวน | BU4: หน่วย | BV4: ยอดต้นทุน/วัน | BW4: จำนวน | BX4: หน่วย | BY4: ยอดต้นทุน/วัน | BZ4: จำนวน | CA4: หน่วย | CB4: ยอดต้นทุน/วัน | CC4: จำนวน | CD4: หน่วย | CE4: ยอดต้นทุน/วัน | CF4: จำนวน | CG4: หน่วย | CH4: ยอดต้นทุน/วัน | CI4: จำนวน | CJ4: หน่วย | CK4: ยอดต้นทุน/วัน | CL4: จำนวน | CM4: หน่วย | CN4: ยอดต้นทุน/วัน | CO4: จำนวน | CP4: หน่วย | CQ4: ยอดต้นทุน/วัน | CR4: จำนวน | CS4: หน่วย | CT4: ยอดต้นทุน/วัน | CU4: จำนวน | CV4: หน่วย | CW4: ยอดต้นทุน/วัน | CX4: จำนวน | CY4: หน่วย | CZ4: ยอดต้นทุน/วัน
A5: 0006 | B5: เค้กเบาหวิวเล็ก 1กล่องขนาด 100 กรัม (คละรส) | C5: 14.05 | D5: 1 | E5: =+D5*F5 -> 11337 | F5: =+I5+L5+O5+R5+U5+X5+AA5+AD5+AG5+AJ5+AM5+AP5+AS5+AV5+AY5+BB5+BE5+BH5+BK5+BN5+BQ5+BT5+BW5+BZ5+CC5+CF5+CI5+CL5+CO5+CR5+CU5+CX5 -> 11337 | G5: กล่อง | H5: =+F5*C5 -> 159284.85 | I5: =IFERROR(VLOOKUP(A5,'1'!U:V,2,0),"0") -> 0 | J5: กล่อง | K5: =+I5*C5 -> 0 | L5: =IFERROR(VLOOKUP(A5,'2'!U:V,2,0),"0") -> 704 | M5: กล่อง | N5: =+L5*C5 -> 9891.2 | O5: =IFERROR(VLOOKUP(A5,'3'!U:V,2,0),"0") -> 576 | P5: กล่อง | Q5: =+O5*C5 -> 8092.8 | R5: =IFERROR(VLOOKUP(A5,'4'!U:V,2,0),"0") -> 362 | S5: กล่อง | T5: =+R5*C5 -> 5086.1 | U5: =IFERROR(VLOOKUP(A5,'5'!U:V,2,0),"0") -> 366 | V5: กล่อง | W5: =+U5*C5 -> 5142.3 | X5: =IFERROR(VLOOKUP(A5,'6'!U:V,2,0),"0") -> 311 | Y5: กล่อง | Z5: =+X5*C5 -> 4369.55 | AA5: =IFERROR(VLOOKUP(A5,'7'!U:V,2,0),"0") -> 531 | AB5: กล่อง | AC5: =+AA5*C5 -> 7460.55 | AD5: =IFERROR(VLOOKUP(A5,'8'!U:V,2,0),"0") -> 703 | AE5: กล่อง | AF5: =+AD5*C5 -> 9877.15 | AG5: =IFERROR(VLOOKUP(A5,'9'!U:V,2,0),"0") -> 770 | AH5: กล่อง | AI5: =+AG5*C5 -> 10818.5 | AJ5: =IFERROR(VLOOKUP(A5,'10'!U:V,2,0),"0") -> 293 | AK5: กล่อง | AL5: =+AJ5*C5 -> 4116.65 | AM5: =IFERROR(VLOOKUP(A5,'11'!U:V,2,0),"0") -> 557 | AN5: กล่อง | AO5: =+AM5*C5 -> 7825.85 | AP5: =IFERROR(VLOOKUP(A5,'12'!U:V,2,0),"0") -> 440 | AQ5: กล่อง | AR5: =+AP5*C5 -> 6182 | AS5: =IFERROR(VLOOKUP(A5,'13'!U:V,2,0),"0") -> 511 | AT5: กล่อง | AU5: =+AS5*C5 -> 7179.55 | AV5: =IFERROR(VLOOKUP(A5,'14'!U:V,2,0),"0") -> 397 | AW5: กล่อง | AX5: =+AV5*C5 -> 5577.85 | AY5: =IFERROR(VLOOKUP(A5,'15'!U:V,2,0),"0") -> 441 | AZ5: กล่อง | BA5: =+AY5*C5 -> 6196.05 | BB5: =IFERROR(VLOOKUP(A5,'16'!U:V,2,0),"0") -> 440 | BC5: กล่อง | BD5: =+BB5*C5 -> 6182 | BE5: =IFERROR(VLOOKUP(A5,'17'!U:V,2,0),"0") -> 479 | BF5: กล่อง | BG5: =+BE5*C5 -> 6729.95 | BH5: =IFERROR(VLOOKUP(A5,'18'!U:V,2,0),"0") -> 315 | BI5: กล่อง | BJ5: =+BH5*C5 -> 4425.75 | BK5: =IFERROR(VLOOKUP(A5,'19'!U:V,2,0),"0") -> 254 | BL5: กล่อง | BM5: =+BK5*C5 -> 3568.7 | BN5: =IFERROR(VLOOKUP(A5,'20'!U:V,2,0),"0") -> 341 | BO5: กล่อง | BP5: =+BN5*C5 -> 4791.05 | BQ5: =IFERROR(VLOOKUP(A5,'21'!U:V,2,0),"0") -> 328 | BR5: กล่อง | BS5: =+BQ5*C5 -> 4608.4 | BT5: =IFERROR(VLOOKUP(A5,'22'!U:V,2,0),"0") -> 310 | BU5: กล่อง | BV5: =+BT5*C5 -> 4355.5 | BW5: =IFERROR(VLOOKUP(A5,'23'!U:V,2,0),"0") -> 194 | BX5: กล่อง | BY5: =+BW5*C5 -> 2725.7 | BZ5: =IFERROR(VLOOKUP(A5,'24'!U:V,2,0),"0") -> 348 | CA5: กล่อง | CB5: =+BZ5*C5 -> 4889.4 | CC5: =IFERROR(VLOOKUP(A5,'25'!U:V,2,0),"0") -> 387 | CD5: กล่อง | CE5: =+CC5*C5 -> 5437.35 | CF5: =IFERROR(VLOOKUP(A5,'26'!U:V,2,0),"0") -> 233 | CG5: กล่อง | CH5: =+CF5*C5 -> 3273.65 | CI5: =IFERROR(VLOOKUP(A5,'27'!U:V,2,0),"0") -> 377 | CJ5: กล่อง | CK5: =+CI5*C5 -> 5296.85 | CL5: =IFERROR(VLOOKUP(A5,'28'!U:V,2,0),"0") -> 369 | CM5: กล่อง | CN5: =+CL5*C5 -> 5184.45 | CO5: =IFERROR(VLOOKUP(A5,'29'!U:V,2,0),"0") -> 0 | CP5: กล่อง | CQ5: =+CO5*C5 -> 0 | CR5: =IFERROR(VLOOKUP(A5,'30'!U:V,2,0),"0") -> 0 | CS5: กล่อง | CT5: =+CR5*C5 -> 0 | CU5: =IFERROR(VLOOKUP(A5,'31'!U:V,2,0),"0") -> 0 | CV5: กล่อง | CW5: =+CU5*C5 -> 0 | CX5: =IFERROR(VLOOKUP(A5,'เซต1-31'!V:W,2,0),"0") -> 0 | CY5: กล่อง | CZ5: =+CX5*CQ5 -> 0
A6: 1004055 | B6: ชิฟฟ่อน รวมรส 1กล่อง4ชิ้น | C6: 19.58 | D6: 1 | E6: =+D6*F6 -> 10 | F6: =+I6+L6+O6+R6+U6+X6+AA6+AD6+AG6+AJ6+AM6+AP6+AS6+AV6+AY6+BB6+BE6+BH6+BK6+BN6+BQ6+BT6+BW6+BZ6+CC6+CF6+CI6+CL6+CO6+CR6+CU6+CX6 -> 10 | G6: กล่อง | H6: =+F6*C6 -> 195.8 | I6: =IFERROR(VLOOKUP(A6,'1'!U:V,2,0),"0") -> 0 | J6: กล่อง | K6: =+I6*C6 -> 0 | L6: =IFERROR(VLOOKUP(A6,'2'!U:V,2,0),"0") -> 0 | M6: กล่อง | N6: =+L6*C6 -> 0 | O6: =IFERROR(VLOOKUP(A6,'3'!U:V,2,0),"0") -> 0 | P6: กล่อง | Q6: =+O6*C6 -> 0 | R6: =IFERROR(VLOOKUP(A6,'4'!U:V,2,0),"0") -> 0 | S6: กล่อง | T6: =+R6*C6 -> 0 | U6: =IFERROR(VLOOKUP(A6,'5'!U:V,2,0),"0") -> 0 | V6: กล่อง | W6: =+U6*C6 -> 0 | X6: =IFERROR(VLOOKUP(A6,'6'!U:V,2,0),"0") -> 0 | Y6: กล่อง | Z6: =+X6*C6 -> 0 | AA6: =IFERROR(VLOOKUP(A6,'7'!U:V,2,0),"0") -> 0 | AB6: กล่อง | AC6: =+AA6*C6 -> 0 | AD6: =IFERROR(VLOOKUP(A6,'8'!U:V,2,0),"0") -> 0 | AE6: กล่อง | AF6: =+AD6*C6 -> 0 | AG6: =IFERROR(VLOOKUP(A6,'9'!U:V,2,0),"0") -> 0 | AH6: กล่อง | AI6: =+AG6*C6 -> 0 | AJ6: =IFERROR(VLOOKUP(A6,'10'!U:V,2,0),"0") -> 0 | AK6: กล่อง | AL6: =+AJ6*C6 -> 0 | AM6: =IFERROR(VLOOKUP(A6,'11'!U:V,2,0),"0") -> 0 | AN6: กล่อง | AO6: =+AM6*C6 -> 0 | AP6: =IFERROR(VLOOKUP(A6,'12'!U:V,2,0),"0") -> 0 | AQ6: กล่อง | AR6: =+AP6*C6 -> 0 | AS6: =IFERROR(VLOOKUP(A6,'13'!U:V,2,0),"0") -> 0 | AT6: กล่อง | AU6: =+AS6*C6 -> 0 | AV6: =IFERROR(VLOOKUP(A6,'14'!U:V,2,0),"0") -> 0 | AW6: กล่อง | AX6: =+AV6*C6 -> 0 | AY6: =IFERROR(VLOOKUP(A6,'15'!U:V,2,0),"0") -> 10 | AZ6: กล่อง | BA6: =+AY6*C6 -> 195.8 | BB6: =IFERROR(VLOOKUP(A6,'16'!U:V,2,0),"0") -> 0 | BC6: กล่อง | BD6: =+BB6*C6 -> 0 | BE6: =IFERROR(VLOOKUP(A6,'17'!U:V,2,0),"0") -> 0 | BF6: กล่อง | BG6: =+BE6*C6 -> 0 | BH6: =IFERROR(VLOOKUP(A6,'18'!U:V,2,0),"0") -> 0 | BI6: กล่อง | BJ6: =+BH6*C6 -> 0 | BK6: =IFERROR(VLOOKUP(A6,'19'!U:V,2,0),"0") -> 0 | BL6: กล่อง | BM6: =+BK6*C6 -> 0 | BN6: =IFERROR(VLOOKUP(A6,'20'!U:V,2,0),"0") -> 0 | BO6: กล่อง | BP6: =+BN6*C6 -> 0 | BQ6: =IFERROR(VLOOKUP(A6,'21'!U:V,2,0),"0") -> 0 | BR6: กล่อง | BS6: =+BQ6*C6 -> 0 | BT6: =IFERROR(VLOOKUP(A6,'22'!U:V,2,0),"0") -> 0 | BU6: กล่อง | BV6: =+BT6*C6 -> 0 | BW6: =IFERROR(VLOOKUP(A6,'23'!U:V,2,0),"0") -> 0 | BX6: กล่อง | BY6: =+BW6*C6 -> 0 | BZ6: =IFERROR(VLOOKUP(A6,'24'!U:V,2,0),"0") -> 0 | CA6: กล่อง | CB6: =+BZ6*C6 -> 0 | CC6: =IFERROR(VLOOKUP(A6,'25'!U:V,2,0),"0") -> 0 | CD6: กล่อง | CE6: =+CC6*C6 -> 0 | CF6: =IFERROR(VLOOKUP(A6,'26'!U:V,2,0),"0") -> 0 | CG6: กล่อง | CH6: =+CF6*C6 -> 0 | CI6: =IFERROR(VLOOKUP(A6,'27'!U:V,2,0),"0") -> 0 | CJ6: กล่อง | CK6: =+CI6*C6 -> 0 | CL6: =IFERROR(VLOOKUP(A6,'28'!U:V,2,0),"0") -> 0 | CM6: กล่อง | CN6: =+CL6*C6 -> 0 | CO6: =IFERROR(VLOOKUP(A6,'29'!U:V,2,0),"0") -> 0 | CP6: กล่อง | CQ6: =+CO6*C6 -> 0 | CR6: =IFERROR(VLOOKUP(A6,'30'!U:V,2,0),"0") -> 0 | CS6: กล่อง | CT6: =+CR6*C6 -> 0 | CU6: =IFERROR(VLOOKUP(A6,'31'!U:V,2,0),"0") -> 0 | CV6: กล่อง | CW6: =+CU6*C6 -> 0 | CX6: =IFERROR(VLOOKUP(A6,'เซต1-31'!V:W,2,0),"0") -> 0 | CY6: กล่อง | CZ6: =+CX6*CQ6 -> 0
A7: 1005761 | B7: ขนมปังกรอบคาราเมล(ถุง) | C7: 17.5 | D7: 1 | E7: =+D7*F7 -> 0 | F7: =+I7+L7+O7+R7+U7+X7+AA7+AD7+AG7+AJ7+AM7+AP7+AS7+AV7+AY7+BB7+BE7+BH7+BK7+BN7+BQ7+BT7+BW7+BZ7+CC7+CF7+CI7+CL7+CO7+CR7+CU7+CX7 -> 0 | G7: ถุง | H7: =+F7*C7 -> 0 | I7: =IFERROR(VLOOKUP(A7,'1'!U:V,2,0),"0") -> 0 | J7: ถุง | K7: =+I7*C7 -> 0 | L7: =IFERROR(VLOOKUP(A7,'2'!U:V,2,0),"0") -> 0 | M7: ถุง | N7: =+L7*C7 -> 0 | O7: =IFERROR(VLOOKUP(A7,'3'!U:V,2,0),"0") -> 0 | P7: ถุง | Q7: =+O7*C7 -> 0 | R7: =IFERROR(VLOOKUP(A7,'4'!U:V,2,0),"0") -> 0 | S7: ถุง | T7: =+R7*C7 -> 0 | U7: =IFERROR(VLOOKUP(A7,'5'!U:V,2,0),"0") -> 0 | V7: ถุง | W7: =+U7*C7 -> 0 | X7: =IFERROR(VLOOKUP(A7,'6'!U:V,2,0),"0") -> 0 | Y7: ถุง | Z7: =+X7*C7 -> 0 | AA7: =IFERROR(VLOOKUP(A7,'7'!U:V,2,0),"0") -> 0 | AB7: ถุง | AC7: =+AA7*C7 -> 0 | AD7: =IFERROR(VLOOKUP(A7,'8'!U:V,2,0),"0") -> 0 | AE7: ถุง | AF7: =+AD7*C7 -> 0 | AG7: =IFERROR(VLOOKUP(A7,'9'!U:V,2,0),"0") -> 0 | AH7: ถุง | AI7: =+AG7*C7 -> 0 | AJ7: =IFERROR(VLOOKUP(A7,'10'!U:V,2,0),"0") -> 0 | AK7: ถุง | AL7: =+AJ7*C7 -> 0 | AM7: =IFERROR(VLOOKUP(A7,'11'!U:V,2,0),"0") -> 0 | AN7: ถุง | AO7: =+AM7*C7 -> 0 | AP7: =IFERROR(VLOOKUP(A7,'12'!U:V,2,0),"0") -> 0 | AQ7: ถุง | AR7: =+AP7*C7 -> 0 | AS7: =IFERROR(VLOOKUP(A7,'13'!U:V,2,0),"0") -> 0 | AT7: ถุง | AU7: =+AS7*C7 -> 0 | AV7: =IFERROR(VLOOKUP(A7,'14'!U:V,2,0),"0") -> 0 | AW7: ถุง | AX7: =+AV7*C7 -> 0 | AY7: =IFERROR(VLOOKUP(A7,'15'!U:V,2,0),"0") -> 0 | AZ7: ถุง | BA7: =+AY7*C7 -> 0 | BB7: =IFERROR(VLOOKUP(A7,'16'!U:V,2,0),"0") -> 0 | BC7: ถุง | BD7: =+BB7*C7 -> 0 | BE7: =IFERROR(VLOOKUP(A7,'17'!U:V,2,0),"0") -> 0 | BF7: ถุง | BG7: =+BE7*C7 -> 0 | BH7: =IFERROR(VLOOKUP(A7,'18'!U:V,2,0),"0") -> 0 | BI7: ถุง | BJ7: =+BH7*C7 -> 0 | BK7: =IFERROR(VLOOKUP(A7,'19'!U:V,2,0),"0") -> 0 | BL7: ถุง | BM7: =+BK7*C7 -> 0 | BN7: =IFERROR(VLOOKUP(A7,'20'!U:V,2,0),"0") -> 0 | BO7: ถุง | BP7: =+BN7*C7 -> 0 | BQ7: =IFERROR(VLOOKUP(A7,'21'!U:V,2,0),"0") -> 0 | BR7: ถุง | BS7: =+BQ7*C7 -> 0 | BT7: =IFERROR(VLOOKUP(A7,'22'!U:V,2,0),"0") -> 0 | BU7: ถุง | BV7: =+BT7*C7 -> 0 | BW7: =IFERROR(VLOOKUP(A7,'23'!U:V,2,0),"0") -> 0 | BX7: ถุง | BY7: =+BW7*C7 -> 0 | BZ7: =IFERROR(VLOOKUP(A7,'24'!U:V,2,0),"0") -> 0 | CA7: ถุง | CB7: =+BZ7*C7 -> 0 | CC7: =IFERROR(VLOOKUP(A7,'25'!U:V,2,0),"0") -> 0 | CD7: ถุง | CE7: =+CC7*C7 -> 0 | CF7: =IFERROR(VLOOKUP(A7,'26'!U:V,2,0),"0") -> 0 | CG7: ถุง | CH7: =+CF7*C7 -> 0 | CI7: =IFERROR(VLOOKUP(A7,'27'!U:V,2,0),"0") -> 0 | CJ7: ถุง | CK7: =+CI7*C7 -> 0 | CL7: =IFERROR(VLOOKUP(A7,'28'!U:V,2,0),"0") -> 0 | CM7: ถุง | CN7: =+CL7*C7 -> 0 | CO7: =IFERROR(VLOOKUP(A7,'29'!U:V,2,0),"0") -> 0 | CP7: ถุง | CQ7: =+CO7*C7 -> 0 | CR7: =IFERROR(VLOOKUP(A7,'30'!U:V,2,0),"0") -> 0 | CS7: ถุง | CT7: =+CR7*C7 -> 0 | CU7: =IFERROR(VLOOKUP(A7,'31'!U:V,2,0),"0") -> 0 | CV7: ถุง | CW7: =+CU7*C7 -> 0 | CX7: =IFERROR(VLOOKUP(A7,'เซต1-31'!V:W,2,0),"0") -> 0 | CY7: ถุง | CZ7: =+CX7*CQ7 -> 0
A8: 1100001 | B8: ทาร์ตสับปะรดแบบชิ้น อร่อยนุ่ม (1 ชิ้น) | C8: 4.43 | D8: 1 | E8: =+D8*F8 -> 0 | F8: =+I8+L8+O8+R8+U8+X8+AA8+AD8+AG8+AJ8+AM8+AP8+AS8+AV8+AY8+BB8+BE8+BH8+BK8+BN8+BQ8+BT8+BW8+BZ8+CC8+CF8+CI8+CL8+CO8+CR8+CU8+CX8 -> 0 | G8: ชิ้น | H8: =+F8*C8 -> 0 | I8: =IFERROR(VLOOKUP(A8,'1'!U:V,2,0),"0") -> 0 | J8: ชิ้น | K8: =+I8*C8 -> 0 | L8: =IFERROR(VLOOKUP(A8,'2'!U:V,2,0),"0") -> 0 | M8: ชิ้น | N8: =+L8*C8 -> 0 | O8: =IFERROR(VLOOKUP(A8,'3'!U:V,2,0),"0") -> 0 | P8: ชิ้น | Q8: =+O8*C8 -> 0 | R8: =IFERROR(VLOOKUP(A8,'4'!U:V,2,0),"0") -> 0 | S8: ชิ้น | T8: =+R8*C8 -> 0 | U8: =IFERROR(VLOOKUP(A8,'5'!U:V,2,0),"0") -> 0 | V8: ชิ้น | W8: =+U8*C8 -> 0 | X8: =IFERROR(VLOOKUP(A8,'6'!U:V,2,0),"0") -> 0 | Y8: ชิ้น | Z8: =+X8*C8 -> 0 | AA8: =IFERROR(VLOOKUP(A8,'7'!U:V,2,0),"0") -> 0 | AB8: ชิ้น | AC8: =+AA8*C8 -> 0 | AD8: =IFERROR(VLOOKUP(A8,'8'!U:V,2,0),"0") -> 0 | AE8: ชิ้น | AF8: =+AD8*C8 -> 0 | AG8: =IFERROR(VLOOKUP(A8,'9'!U:V,2,0),"0") -> 0 | AH8: ชิ้น | AI8: =+AG8*C8 -> 0 | AJ8: =IFERROR(VLOOKUP(A8,'10'!U:V,2,0),"0") -> 0 | AK8: ชิ้น | AL8: =+AJ8*C8 -> 0 | AM8: =IFERROR(VLOOKUP(A8,'11'!U:V,2,0),"0") -> 0 | AN8: ชิ้น | AO8: =+AM8*C8 -> 0 | AP8: =IFERROR(VLOOKUP(A8,'12'!U:V,2,0),"0") -> 0 | AQ8: ชิ้น | AR8: =+AP8*C8 -> 0 | AS8: =IFERROR(VLOOKUP(A8,'13'!U:V,2,0),"0") -> 0 | AT8: ชิ้น | AU8: =+AS8*C8 -> 0 | AV8: =IFERROR(VLOOKUP(A8,'14'!U:V,2,0),"0") -> 0 | AW8: ชิ้น | AX8: =+AV8*C8 -> 0 | AY8: =IFERROR(VLOOKUP(A8,'15'!U:V,2,0),"0") -> 0 | AZ8: ชิ้น | BA8: =+AY8*C8 -> 0 | BB8: =IFERROR(VLOOKUP(A8,'16'!U:V,2,0),"0") -> 0 | BC8: ชิ้น | BD8: =+BB8*C8 -> 0 | BE8: =IFERROR(VLOOKUP(A8,'17'!U:V,2,0),"0") -> 0 | BF8: ชิ้น | BG8: =+BE8*C8 -> 0 | BH8: =IFERROR(VLOOKUP(A8,'18'!U:V,2,0),"0") -> 0 | BI8: ชิ้น | BJ8: =+BH8*C8 -> 0 | BK8: =IFERROR(VLOOKUP(A8,'19'!U:V,2,0),"0") -> 0 | BL8: ชิ้น | BM8: =+BK8*C8 -> 0 | BN8: =IFERROR(VLOOKUP(A8,'20'!U:V,2,0),"0") -> 0 | BO8: ชิ้น | BP8: =+BN8*C8 -> 0 | BQ8: =IFERROR(VLOOKUP(A8,'21'!U:V,2,0),"0") -> 0 | BR8: ชิ้น | BS8: =+BQ8*C8 -> 0 | BT8: =IFERROR(VLOOKUP(A8,'22'!U:V,2,0),"0") -> 0 | BU8: ชิ้น | BV8: =+BT8*C8 -> 0 | BW8: =IFERROR(VLOOKUP(A8,'23'!U:V,2,0),"0") -> 0 | BX8: ชิ้น | BY8: =+BW8*C8 -> 0 | BZ8: =IFERROR(VLOOKUP(A8,'24'!U:V,2,0),"0") -> 0 | CA8: ชิ้น | CB8: =+BZ8*C8 -> 0 | CC8: =IFERROR(VLOOKUP(A8,'25'!U:V,2,0),"0") -> 0 | CD8: ชิ้น | CE8: =+CC8*C8 -> 0 | CF8: =IFERROR(VLOOKUP(A8,'26'!U:V,2,0),"0") -> 0 | CG8: ชิ้น | CH8: =+CF8*C8 -> 0 | CI8: =IFERROR(VLOOKUP(A8,'27'!U:V,2,0),"0") -> 0 | CJ8: ชิ้น | CK8: =+CI8*C8 -> 0 | CL8: =IFERROR(VLOOKUP(A8,'28'!U:V,2,0),"0") -> 0 | CM8: ชิ้น | CN8: =+CL8*C8 -> 0 | CO8: =IFERROR(VLOOKUP(A8,'29'!U:V,2,0),"0") -> 0 | CP8: ชิ้น | CQ8: =+CO8*C8 -> 0 | CR8: =IFERROR(VLOOKUP(A8,'30'!U:V,2,0),"0") -> 0 | CS8: ชิ้น | CT8: =+CR8*C8 -> 0 | CU8: =IFERROR(VLOOKUP(A8,'31'!U:V,2,0),"0") -> 0 | CV8: ชิ้น | CW8: =+CU8*C8 -> 0 | CX8: =IFERROR(VLOOKUP(A8,'เซต1-31'!V:W,2,0),"0") -> 0 | CY8: ชิ้น | CZ8: =+CX8*CQ8 -> 0
A9: 1100002 | B9: ทาร์ตสับปะรด (ทาร์ตสับปะรดกล่อง 4 ชิ้น) | C9: 22.02 | D9: 1 | E9: =+D9*F9 -> 10 | F9: =+I9+L9+O9+R9+U9+X9+AA9+AD9+AG9+AJ9+AM9+AP9+AS9+AV9+AY9+BB9+BE9+BH9+BK9+BN9+BQ9+BT9+BW9+BZ9+CC9+CF9+CI9+CL9+CO9+CR9+CU9+CX9 -> 10 | G9: กล่อง | H9: =+F9*C9 -> 220.2 | I9: =IFERROR(VLOOKUP(A9,'1'!U:V,2,0),"0") -> 0 | J9: กล่อง | K9: =+I9*C9 -> 0 | L9: =IFERROR(VLOOKUP(A9,'2'!U:V,2,0),"0") -> 0 | M9: กล่อง | N9: =+L9*C9 -> 0 | O9: =IFERROR(VLOOKUP(A9,'3'!U:V,2,0),"0") -> 0 | P9: กล่อง | Q9: =+O9*C9 -> 0 | R9: =IFERROR(VLOOKUP(A9,'4'!U:V,2,0),"0") -> 0 | S9: กล่อง | T9: =+R9*C9 -> 0 | U9: =IFERROR(VLOOKUP(A9,'5'!U:V,2,0),"0") -> 0 | V9: กล่อง | W9: =+U9*C9 -> 0 | X9: =IFERROR(VLOOKUP(A9,'6'!U:V,2,0),"0") -> 0 | Y9: กล่อง | Z9: =+X9*C9 -> 0 | AA9: =IFERROR(VLOOKUP(A9,'7'!U:V,2,0),"0") -> 0 | AB9: กล่อง | AC9: =+AA9*C9 -> 0 | AD9: =IFERROR(VLOOKUP(A9,'8'!U:V,2,0),"0") -> 0 | AE9: กล่อง | AF9: =+AD9*C9 -> 0 | AG9: =IFERROR(VLOOKUP(A9,'9'!U:V,2,0),"0") -> 0 | AH9: กล่อง | AI9: =+AG9*C9 -> 0 | AJ9: =IFERROR(VLOOKUP(A9,'10'!U:V,2,0),"0") -> 0 | AK9: กล่อง | AL9: =+AJ9*C9 -> 0 | AM9: =IFERROR(VLOOKUP(A9,'11'!U:V,2,0),"0") -> 0 | AN9: กล่อง | AO9: =+AM9*C9 -> 0 | AP9: =IFERROR(VLOOKUP(A9,'12'!U:V,2,0),"0") -> 0 | AQ9: กล่อง | AR9: =+AP9*C9 -> 0 | AS9: =IFERROR(VLOOKUP(A9,'13'!U:V,2,0),"0") -> 0 | AT9: กล่อง | AU9: =+AS9*C9 -> 0 | AV9: =IFERROR(VLOOKUP(A9,'14'!U:V,2,0),"0") -> 0 | AW9: กล่อง | AX9: =+AV9*C9 -> 0 | AY9: =IFERROR(VLOOKUP(A9,'15'!U:V,2,0),"0") -> 10 | AZ9: กล่อง | BA9: =+AY9*C9 -> 220.2 | BB9: =IFERROR(VLOOKUP(A9,'16'!U:V,2,0),"0") -> 0 | BC9: กล่อง | BD9: =+BB9*C9 -> 0 | BE9: =IFERROR(VLOOKUP(A9,'17'!U:V,2,0),"0") -> 0 | BF9: กล่อง | BG9: =+BE9*C9 -> 0 | BH9: =IFERROR(VLOOKUP(A9,'18'!U:V,2,0),"0") -> 0 | BI9: กล่อง | BJ9: =+BH9*C9 -> 0 | BK9: =IFERROR(VLOOKUP(A9,'19'!U:V,2,0),"0") -> 0 | BL9: กล่อง | BM9: =+BK9*C9 -> 0 | BN9: =IFERROR(VLOOKUP(A9,'20'!U:V,2,0),"0") -> 0 | BO9: กล่อง | BP9: =+BN9*C9 -> 0 | BQ9: =IFERROR(VLOOKUP(A9,'21'!U:V,2,0),"0") -> 0 | BR9: กล่อง | BS9: =+BQ9*C9 -> 0 | BT9: =IFERROR(VLOOKUP(A9,'22'!U:V,2,0),"0") -> 0 | BU9: กล่อง | BV9: =+BT9*C9 -> 0 | BW9: =IFERROR(VLOOKUP(A9,'23'!U:V,2,0),"0") -> 0 | BX9: กล่อง | BY9: =+BW9*C9 -> 0 | BZ9: =IFERROR(VLOOKUP(A9,'24'!U:V,2,0),"0") -> 0 | CA9: กล่อง | CB9: =+BZ9*C9 -> 0 | CC9: =IFERROR(VLOOKUP(A9,'25'!U:V,2,0),"0") -> 0 | CD9: กล่อง | CE9: =+CC9*C9 -> 0 | CF9: =IFERROR(VLOOKUP(A9,'26'!U:V,2,0),"0") -> 0 | CG9: กล่อง | CH9: =+CF9*C9 -> 0 | CI9: =IFERROR(VLOOKUP(A9,'27'!U:V,2,0),"0") -> 0 | CJ9: กล่อง | CK9: =+CI9*C9 -> 0 | CL9: =IFERROR(VLOOKUP(A9,'28'!U:V,2,0),"0") -> 0 | CM9: กล่อง | CN9: =+CL9*C9 -> 0 | CO9: =IFERROR(VLOOKUP(A9,'29'!U:V,2,0),"0") -> 0 | CP9: กล่อง | CQ9: =+CO9*C9 -> 0 | CR9: =IFERROR(VLOOKUP(A9,'30'!U:V,2,0),"0") -> 0 | CS9: กล่อง | CT9: =+CR9*C9 -> 0 | CU9: =IFERROR(VLOOKUP(A9,'31'!U:V,2,0),"0") -> 0 | CV9: กล่อง | CW9: =+CU9*C9 -> 0 | CX9: =IFERROR(VLOOKUP(A9,'เซต1-31'!V:W,2,0),"0") -> 0 | CY9: กล่อง | CZ9: =+CX9*CQ9 -> 0
A10: 1100003 | B10: เมอแรงก์กระปุก (เก็บไว้ได้ 60 วัน) | C10: 11.91 | D10: 1 | E10: =+D10*F10 -> 0 | F10: =+I10+L10+O10+R10+U10+X10+AA10+AD10+AG10+AJ10+AM10+AP10+AS10+AV10+AY10+BB10+BE10+BH10+BK10+BN10+BQ10+BT10+BW10+BZ10+CC10+CF10+CI10+CL10+CO10+CR10+CU10+CX10 -> 0 | G10: กระปุก | H10: =+F10*C10 -> 0 | I10: =IFERROR(VLOOKUP(A10,'1'!U:V,2,0),"0") -> 0 | J10: กระปุก | K10: =+I10*C10 -> 0 | L10: =IFERROR(VLOOKUP(A10,'2'!U:V,2,0),"0") -> 0 | M10: กระปุก | N10: =+L10*C10 -> 0 | O10: =IFERROR(VLOOKUP(A10,'3'!U:V,2,0),"0") -> 0 | P10: กระปุก | Q10: =+O10*C10 -> 0 | R10: =IFERROR(VLOOKUP(A10,'4'!U:V,2,0),"0") -> 0 | S10: กระปุก | T10: =+R10*C10 -> 0 | U10: =IFERROR(VLOOKUP(A10,'5'!U:V,2,0),"0") -> 0 | V10: กระปุก | W10: =+U10*C10 -> 0 | X10: =IFERROR(VLOOKUP(A10,'6'!U:V,2,0),"0") -> 0 | Y10: กระปุก | Z10: =+X10*C10 -> 0 | AA10: =IFERROR(VLOOKUP(A10,'7'!U:V,2,0),"0") -> 0 | AB10: กระปุก | AC10: =+AA10*C10 -> 0 | AD10: =IFERROR(VLOOKUP(A10,'8'!U:V,2,0),"0") -> 0 | AE10: กระปุก | AF10: =+AD10*C10 -> 0 | AG10: =IFERROR(VLOOKUP(A10,'9'!U:V,2,0),"0") -> 0 | AH10: กระปุก | AI10: =+AG10*C10 -> 0 | AJ10: =IFERROR(VLOOKUP(A10,'10'!U:V,2,0),"0") -> 0 | AK10: กระปุก | AL10: =+AJ10*C10 -> 0 | AM10: =IFERROR(VLOOKUP(A10,'11'!U:V,2,0),"0") -> 0 | AN10: กระปุก | AO10: =+AM10*C10 -> 0 | AP10: =IFERROR(VLOOKUP(A10,'12'!U:V,2,0),"0") -> 0 | AQ10: กระปุก | AR10: =+AP10*C10 -> 0 | AS10: =IFERROR(VLOOKUP(A10,'13'!U:V,2,0),"0") -> 0 | AT10: กระปุก | AU10: =+AS10*C10 -> 0 | AV10: =IFERROR(VLOOKUP(A10,'14'!U:V,2,0),"0") -> 0 | AW10: กระปุก | AX10: =+AV10*C10 -> 0 | AY10: =IFERROR(VLOOKUP(A10,'15'!U:V,2,0),"0") -> 0 | AZ10: กระปุก | BA10: =+AY10*C10 -> 0 | BB10: =IFERROR(VLOOKUP(A10,'16'!U:V,2,0),"0") -> 0 | BC10: กระปุก | BD10: =+BB10*C10 -> 0 | BE10: =IFERROR(VLOOKUP(A10,'17'!U:V,2,0),"0") -> 0 | BF10: กระปุก | BG10: =+BE10*C10 -> 0 | BH10: =IFERROR(VLOOKUP(A10,'18'!U:V,2,0),"0") -> 0 | BI10: กระปุก | BJ10: =+BH10*C10 -> 0 | BK10: =IFERROR(VLOOKUP(A10,'19'!U:V,2,0),"0") -> 0 | BL10: กระปุก | BM10: =+BK10*C10 -> 0 | BN10: =IFERROR(VLOOKUP(A10,'20'!U:V,2,0),"0") -> 0 | BO10: กระปุก | BP10: =+BN10*C10 -> 0 | BQ10: =IFERROR(VLOOKUP(A10,'21'!U:V,2,0),"0") -> 0 | BR10: กระปุก | BS10: =+BQ10*C10 -> 0 | BT10: =IFERROR(VLOOKUP(A10,'22'!U:V,2,0),"0") -> 0 | BU10: กระปุก | BV10: =+BT10*C10 -> 0 | BW10: =IFERROR(VLOOKUP(A10,'23'!U:V,2,0),"0") -> 0 | BX10: กระปุก | BY10: =+BW10*C10 -> 0 | BZ10: =IFERROR(VLOOKUP(A10,'24'!U:V,2,0),"0") -> 0 | CA10: กระปุก | CB10: =+BZ10*C10 -> 0 | CC10: =IFERROR(VLOOKUP(A10,'25'!U:V,2,0),"0") -> 0 | CD10: กระปุก | CE10: =+CC10*C10 -> 0 | CF10: =IFERROR(VLOOKUP(A10,'26'!U:V,2,0),"0") -> 0 | CG10: กระปุก | CH10: =+CF10*C10 -> 0 | CI10: =IFERROR(VLOOKUP(A10,'27'!U:V,2,0),"0") -> 0 | CJ10: กระปุก | CK10: =+CI10*C10 -> 0 | CL10: =IFERROR(VLOOKUP(A10,'28'!U:V,2,0),"0") -> 0 | CM10: กระปุก | CN10: =+CL10*C10 -> 0 | CO10: =IFERROR(VLOOKUP(A10,'29'!U:V,2,0),"0") -> 0 | CP10: กระปุก | CQ10: =+CO10*C10 -> 0 | CR10: =IFERROR(VLOOKUP(A10,'30'!U:V,2,0),"0") -> 0 | CS10: กระปุก | CT10: =+CR10*C10 -> 0 | CU10: =IFERROR(VLOOKUP(A10,'31'!U:V,2,0),"0") -> 0 | CV10: กระปุก | CW10: =+CU10*C10 -> 0 | CX10: =IFERROR(VLOOKUP(A10,'เซต1-31'!V:W,2,0),"0") -> 0 | CY10: กระปุก | CZ10: =+CX10*CQ10 -> 0
A11: 1100004 | B11: เมอแรงค์ อัลม่อนเม็ดมะม่วงหิมพานต์ (ถุง) | C11: 13.03 | D11: 1 | E11: =+D11*F11 -> 0 | F11: =+I11+L11+O11+R11+U11+X11+AA11+AD11+AG11+AJ11+AM11+AP11+AS11+AV11+AY11+BB11+BE11+BH11+BK11+BN11+BQ11+BT11+BW11+BZ11+CC11+CF11+CI11+CL11+CO11+CR11+CU11+CX11 -> 0 | G11: ถุง | H11: =+F11*C11 -> 0 | I11: =IFERROR(VLOOKUP(A11,'1'!U:V,2,0),"0") -> 0 | J11: ถุง | K11: =+I11*C11 -> 0 | L11: =IFERROR(VLOOKUP(A11,'2'!U:V,2,0),"0") -> 0 | M11: ถุง | N11: =+L11*C11 -> 0 | O11: =IFERROR(VLOOKUP(A11,'3'!U:V,2,0),"0") -> 0 | P11: ถุง | Q11: =+O11*C11 -> 0 | R11: =IFERROR(VLOOKUP(A11,'4'!U:V,2,0),"0") -> 0 | S11: ถุง | T11: =+R11*C11 -> 0 | U11: =IFERROR(VLOOKUP(A11,'5'!U:V,2,0),"0") -> 0 | V11: ถุง | W11: =+U11*C11 -> 0 | X11: =IFERROR(VLOOKUP(A11,'6'!U:V,2,0),"0") -> 0 | Y11: ถุง | Z11: =+X11*C11 -> 0 | AA11: =IFERROR(VLOOKUP(A11,'7'!U:V,2,0),"0") -> 0 | AB11: ถุง | AC11: =+AA11*C11 -> 0 | AD11: =IFERROR(VLOOKUP(A11,'8'!U:V,2,0),"0") -> 0 | AE11: ถุง | AF11: =+AD11*C11 -> 0 | AG11: =IFERROR(VLOOKUP(A11,'9'!U:V,2,0),"0") -> 0 | AH11: ถุง | AI11: =+AG11*C11 -> 0 | AJ11: =IFERROR(VLOOKUP(A11,'10'!U:V,2,0),"0") -> 0 | AK11: ถุง | AL11: =+AJ11*C11 -> 0 | AM11: =IFERROR(VLOOKUP(A11,'11'!U:V,2,0),"0") -> 0 | AN11: ถุง | AO11: =+AM11*C11 -> 0 | AP11: =IFERROR(VLOOKUP(A11,'12'!U:V,2,0),"0") -> 0 | AQ11: ถุง | AR11: =+AP11*C11 -> 0 | AS11: =IFERROR(VLOOKUP(A11,'13'!U:V,2,0),"0") -> 0 | AT11: ถุง | AU11: =+AS11*C11 -> 0 | AV11: =IFERROR(VLOOKUP(A11,'14'!U:V,2,0),"0") -> 0 | AW11: ถุง | AX11: =+AV11*C11 -> 0 | AY11: =IFERROR(VLOOKUP(A11,'15'!U:V,2,0),"0") -> 0 | AZ11: ถุง | BA11: =+AY11*C11 -> 0 | BB11: =IFERROR(VLOOKUP(A11,'16'!U:V,2,0),"0") -> 0 | BC11: ถุง | BD11: =+BB11*C11 -> 0 | BE11: =IFERROR(VLOOKUP(A11,'17'!U:V,2,0),"0") -> 0 | BF11: ถุง | BG11: =+BE11*C11 -> 0 | BH11: =IFERROR(VLOOKUP(A11,'18'!U:V,2,0),"0") -> 0 | BI11: ถุง | BJ11: =+BH11*C11 -> 0 | BK11: =IFERROR(VLOOKUP(A11,'19'!U:V,2,0),"0") -> 0 | BL11: ถุง | BM11: =+BK11*C11 -> 0 | BN11: =IFERROR(VLOOKUP(A11,'20'!U:V,2,0),"0") -> 0 | BO11: ถุง | BP11: =+BN11*C11 -> 0 | BQ11: =IFERROR(VLOOKUP(A11,'21'!U:V,2,0),"0") -> 0 | BR11: ถุง | BS11: =+BQ11*C11 -> 0 | BT11: =IFERROR(VLOOKUP(A11,'22'!U:V,2,0),"0") -> 0 | BU11: ถุง | BV11: =+BT11*C11 -> 0 | BW11: =IFERROR(VLOOKUP(A11,'23'!U:V,2,0),"0") -> 0 | BX11: ถุง | BY11: =+BW11*C11 -> 0 | BZ11: =IFERROR(VLOOKUP(A11,'24'!U:V,2,0),"0") -> 0 | CA11: ถุง | CB11: =+BZ11*C11 -> 0 | CC11: =IFERROR(VLOOKUP(A11,'25'!U:V,2,0),"0") -> 0 | CD11: ถุง | CE11: =+CC11*C11 -> 0 | CF11: =IFERROR(VLOOKUP(A11,'26'!U:V,2,0),"0") -> 0 | CG11: ถุง | CH11: =+CF11*C11 -> 0 | CI11: =IFERROR(VLOOKUP(A11,'27'!U:V,2,0),"0") -> 0 | CJ11: ถุง | CK11: =+CI11*C11 -> 0 | CL11: =IFERROR(VLOOKUP(A11,'28'!U:V,2,0),"0") -> 0 | CM11: ถุง | CN11: =+CL11*C11 -> 0 | CO11: =IFERROR(VLOOKUP(A11,'29'!U:V,2,0),"0") -> 0 | CP11: ถุง | CQ11: =+CO11*C11 -> 0 | CR11: =IFERROR(VLOOKUP(A11,'30'!U:V,2,0),"0") -> 0 | CS11: ถุง | CT11: =+CR11*C11 -> 0 | CU11: =IFERROR(VLOOKUP(A11,'31'!U:V,2,0),"0") -> 0 | CV11: ถุง | CW11: =+CU11*C11 -> 0 | CX11: =IFERROR(VLOOKUP(A11,'เซต1-31'!V:W,2,0),"0") -> 0 | CY11: ถุง | CZ11: =+CX11*CQ11 -> 0
A12: 1111001 | B12: ชิฟฟอนไม่มีไส้เเบบเเยกชิ้น เลือกรสชาติได้ (คละรส) | C12: 4.33 | D12: 1 | E12: =+D12*F12 -> 1212 | F12: =+I12+L12+O12+R12+U12+X12+AA12+AD12+AG12+AJ12+AM12+AP12+AS12+AV12+AY12+BB12+BE12+BH12+BK12+BN12+BQ12+BT12+BW12+BZ12+CC12+CF12+CI12+CL12+CO12+CR12+CU12+CX12 -> 1212 | G12: ชิ้น | H12: =+F12*C12 -> 5247.96 | I12: =IFERROR(VLOOKUP(A12,'1'!U:V,2,0),"0") -> 0 | J12: ชิ้น | K12: =+I12*C12 -> 0 | L12: =IFERROR(VLOOKUP(A12,'2'!U:V,2,0),"0") -> 50 | M12: ชิ้น | N12: =+L12*C12 -> 216.5 | O12: =IFERROR(VLOOKUP(A12,'3'!U:V,2,0),"0") -> 90 | P12: ชิ้น | Q12: =+O12*C12 -> 389.7 | R12: =IFERROR(VLOOKUP(A12,'4'!U:V,2,0),"0") -> 160 | S12: ชิ้น | T12: =+R12*C12 -> 692.8 | U12: =IFERROR(VLOOKUP(A12,'5'!U:V,2,0),"0") -> 50 | V12: ชิ้น | W12: =+U12*C12 -> 216.5 | X12: =IFERROR(VLOOKUP(A12,'6'!U:V,2,0),"0") -> 140 | Y12: ชิ้น | Z12: =+X12*C12 -> 606.2 | AA12: =IFERROR(VLOOKUP(A12,'7'!U:V,2,0),"0") -> 0 | AB12: ชิ้น | AC12: =+AA12*C12 -> 0 | AD12: =IFERROR(VLOOKUP(A12,'8'!U:V,2,0),"0") -> 120 | AE12: ชิ้น | AF12: =+AD12*C12 -> 519.6 | AG12: =IFERROR(VLOOKUP(A12,'9'!U:V,2,0),"0") -> 80 | AH12: ชิ้น | AI12: =+AG12*C12 -> 346.4 | AJ12: =IFERROR(VLOOKUP(A12,'10'!U:V,2,0),"0") -> 20 | AK12: ชิ้น | AL12: =+AJ12*C12 -> 86.6 | AM12: =IFERROR(VLOOKUP(A12,'11'!U:V,2,0),"0") -> 0 | AN12: ชิ้น | AO12: =+AM12*C12 -> 0 | AP12: =IFERROR(VLOOKUP(A12,'12'!U:V,2,0),"0") -> 50 | AQ12: ชิ้น | AR12: =+AP12*C12 -> 216.5 | AS12: =IFERROR(VLOOKUP(A12,'13'!U:V,2,0),"0") -> 0 | AT12: ชิ้น | AU12: =+AS12*C12 -> 0 | AV12: =IFERROR(VLOOKUP(A12,'14'!U:V,2,0),"0") -> 0 | AW12: ชิ้น | AX12: =+AV12*C12 -> 0 | AY12: =IFERROR(VLOOKUP(A12,'15'!U:V,2,0),"0") -> 0 | AZ12: ชิ้น | BA12: =+AY12*C12 -> 0 | BB12: =IFERROR(VLOOKUP(A12,'16'!U:V,2,0),"0") -> 0 | BC12: ชิ้น | BD12: =+BB12*C12 -> 0 | BE12: =IFERROR(VLOOKUP(A12,'17'!U:V,2,0),"0") -> 60 | BF12: ชิ้น | BG12: =+BE12*C12 -> 259.8 | BH12: =IFERROR(VLOOKUP(A12,'18'!U:V,2,0),"0") -> 30 | BI12: ชิ้น | BJ12: =+BH12*C12 -> 129.9 | BK12: =IFERROR(VLOOKUP(A12,'19'!U:V,2,0),"0") -> 70 | BL12: ชิ้น | BM12: =+BK12*C12 -> 303.1 | BN12: =IFERROR(VLOOKUP(A12,'20'!U:V,2,0),"0") -> 90 | BO12: ชิ้น | BP12: =+BN12*C12 -> 389.7 | BQ12: =IFERROR(VLOOKUP(A12,'21'!U:V,2,0),"0") -> 160 | BR12: ชิ้น | BS12: =+BQ12*C12 -> 692.8 | BT12: =IFERROR(VLOOKUP(A12,'22'!U:V,2,0),"0") -> 42 | BU12: ชิ้น | BV12: =+BT12*C12 -> 181.86 | BW12: =IFERROR(VLOOKUP(A12,'23'!U:V,2,0),"0") -> 0 | BX12: ชิ้น | BY12: =+BW12*C12 -> 0 | BZ12: =IFERROR(VLOOKUP(A12,'24'!U:V,2,0),"0") -> 0 | CA12: ชิ้น | CB12: =+BZ12*C12 -> 0 | CC12: =IFERROR(VLOOKUP(A12,'25'!U:V,2,0),"0") -> 0 | CD12: ชิ้น | CE12: =+CC12*C12 -> 0 | CF12: =IFERROR(VLOOKUP(A12,'26'!U:V,2,0),"0") -> 0 | CG12: ชิ้น | CH12: =+CF12*C12 -> 0 | CI12: =IFERROR(VLOOKUP(A12,'27'!U:V,2,0),"0") -> 0 | CJ12: ชิ้น | CK12: =+CI12*C12 -> 0 | CL12: =IFERROR(VLOOKUP(A12,'28'!U:V,2,0),"0") -> 0 | CM12: ชิ้น | CN12: =+CL12*C12 -> 0 | CO12: =IFERROR(VLOOKUP(A12,'29'!U:V,2,0),"0") -> 0 | CP12: ชิ้น | CQ12: =+CO12*C12 -> 0 | CR12: =IFERROR(VLOOKUP(A12,'30'!U:V,2,0),"0") -> 0 | CS12: ชิ้น | CT12: =+CR12*C12 -> 0 | CU12: =IFERROR(VLOOKUP(A12,'31'!U:V,2,0),"0") -> 0 | CV12: ชิ้น | CW12: =+CU12*C12 -> 0 | CX12: =IFERROR(VLOOKUP(A12,'เซต1-31'!V:W,2,0),"0") -> 0 | CY12: ชิ้น | CZ12: =+CX12*CQ12 -> 0
A13: 1111002 | B13: ชิฟฟ่อนไม่มีไส้ แบบกล่อง8ชิ้น รวมรส | C13: 37.17 | D13: 1 | E13: =+D13*F13 -> 2633 | F13: =+I13+L13+O13+R13+U13+X13+AA13+AD13+AG13+AJ13+AM13+AP13+AS13+AV13+AY13+BB13+BE13+BH13+BK13+BN13+BQ13+BT13+BW13+BZ13+CC13+CF13+CI13+CL13+CO13+CR13+CU13+CX13 -> 2633 | G13: กล่อง | H13: =+F13*C13 -> 97868.61 | I13: =IFERROR(VLOOKUP(A13,'1'!U:V,2,0),"0") -> 0 | J13: กล่อง | K13: =+I13*C13 -> 0 | L13: =IFERROR(VLOOKUP(A13,'2'!U:V,2,0),"0") -> 110 | M13: กล่อง | N13: =+L13*C13 -> 4088.7 | O13: =IFERROR(VLOOKUP(A13,'3'!U:V,2,0),"0") -> 123 | P13: กล่อง | Q13: =+O13*C13 -> 4571.91 | R13: =IFERROR(VLOOKUP(A13,'4'!U:V,2,0),"0") -> 79 | S13: กล่อง | T13: =+R13*C13 -> 2936.43 | U13: =IFERROR(VLOOKUP(A13,'5'!U:V,2,0),"0") -> 107 | V13: กล่อง | W13: =+U13*C13 -> 3977.19 | X13: =IFERROR(VLOOKUP(A13,'6'!U:V,2,0),"0") -> 56 | Y13: กล่อง | Z13: =+X13*C13 -> 2081.52 | AA13: =IFERROR(VLOOKUP(A13,'7'!U:V,2,0),"0") -> 31 | AB13: กล่อง | AC13: =+AA13*C13 -> 1152.27 | AD13: =IFERROR(VLOOKUP(A13,'8'!U:V,2,0),"0") -> 81 | AE13: กล่อง | AF13: =+AD13*C13 -> 3010.77 | AG13: =IFERROR(VLOOKUP(A13,'9'!U:V,2,0),"0") -> 110 | AH13: กล่อง | AI13: =+AG13*C13 -> 4088.7 | AJ13: =IFERROR(VLOOKUP(A13,'10'!U:V,2,0),"0") -> 109 | AK13: กล่อง | AL13: =+AJ13*C13 -> 4051.53 | AM13: =IFERROR(VLOOKUP(A13,'11'!U:V,2,0),"0") -> 53 | AN13: กล่อง | AO13: =+AM13*C13 -> 1970.01 | AP13: =IFERROR(VLOOKUP(A13,'12'!U:V,2,0),"0") -> 148 | AQ13: กล่อง | AR13: =+AP13*C13 -> 5501.16 | AS13: =IFERROR(VLOOKUP(A13,'13'!U:V,2,0),"0") -> 77 | AT13: กล่อง | AU13: =+AS13*C13 -> 2862.09 | AV13: =IFERROR(VLOOKUP(A13,'14'!U:V,2,0),"0") -> 114 | AW13: กล่อง | AX13: =+AV13*C13 -> 4237.38 | AY13: =IFERROR(VLOOKUP(A13,'15'!U:V,2,0),"0") -> 119 | AZ13: กล่อง | BA13: =+AY13*C13 -> 4423.23 | BB13: =IFERROR(VLOOKUP(A13,'16'!U:V,2,0),"0") -> 77 | BC13: กล่อง | BD13: =+BB13*C13 -> 2862.09 | BE13: =IFERROR(VLOOKUP(A13,'17'!U:V,2,0),"0") -> 130 | BF13: กล่อง | BG13: =+BE13*C13 -> 4832.1 | BH13: =IFERROR(VLOOKUP(A13,'18'!U:V,2,0),"0") -> 69 | BI13: กล่อง | BJ13: =+BH13*C13 -> 2564.73 | BK13: =IFERROR(VLOOKUP(A13,'19'!U:V,2,0),"0") -> 55 | BL13: กล่อง | BM13: =+BK13*C13 -> 2044.35 | BN13: =IFERROR(VLOOKUP(A13,'20'!U:V,2,0),"0") -> 113 | BO13: กล่อง | BP13: =+BN13*C13 -> 4200.21 | BQ13: =IFERROR(VLOOKUP(A13,'21'!U:V,2,0),"0") -> 66 | BR13: กล่อง | BS13: =+BQ13*C13 -> 2453.22 | BT13: =IFERROR(VLOOKUP(A13,'22'!U:V,2,0),"0") -> 82 | BU13: กล่อง | BV13: =+BT13*C13 -> 3047.94 | BW13: =IFERROR(VLOOKUP(A13,'23'!U:V,2,0),"0") -> 104 | BX13: กล่อง | BY13: =+BW13*C13 -> 3865.68 | BZ13: =IFERROR(VLOOKUP(A13,'24'!U:V,2,0),"0") -> 89 | CA13: กล่อง | CB13: =+BZ13*C13 -> 3308.13 | CC13: =IFERROR(VLOOKUP(A13,'25'!U:V,2,0),"0") -> 69 | CD13: กล่อง | CE13: =+CC13*C13 -> 2564.73 | CF13: =IFERROR(VLOOKUP(A13,'26'!U:V,2,0),"0") -> 150 | CG13: กล่อง | CH13: =+CF13*C13 -> 5575.5 | CI13: =IFERROR(VLOOKUP(A13,'27'!U:V,2,0),"0") -> 142 | CJ13: กล่อง | CK13: =+CI13*C13 -> 5278.14 | CL13: =IFERROR(VLOOKUP(A13,'28'!U:V,2,0),"0") -> 170 | CM13: กล่อง | CN13: =+CL13*C13 -> 6318.9 | CO13: =IFERROR(VLOOKUP(A13,'29'!U:V,2,0),"0") -> 0 | CP13: กล่อง | CQ13: =+CO13*C13 -> 0 | CR13: =IFERROR(VLOOKUP(A13,'30'!U:V,2,0),"0") -> 0 | CS13: กล่อง | CT13: =+CR13*C13 -> 0 | CU13: =IFERROR(VLOOKUP(A13,'31'!U:V,2,0),"0") -> 0 | CV13: กล่อง | CW13: =+CU13*C13 -> 0 | CX13: =IFERROR(VLOOKUP(A13,'เซต1-31'!V:W,2,0),"0") -> 0 | CY13: กล่อง | CZ13: =+CX13*CQ13 -> 0
A14: 1111002-A | B14: ชิฟฟ่อนไม่มีไส้ แบบกล่อง8ชิ้น รวมรส (รวมรส) | C14: 37.17 | D14: 1 | E14: =+D14*F14 -> 0 | F14: =+I14+L14+O14+R14+U14+X14+AA14+AD14+AG14+AJ14+AM14+AP14+AS14+AV14+AY14+BB14+BE14+BH14+BK14+BN14+BQ14+BT14+BW14+BZ14+CC14+CF14+CI14+CL14+CO14+CR14+CU14+CX14 -> 0 | G14: กล่อง | H14: =+F14*C14 -> 0 | I14: =IFERROR(VLOOKUP(A14,'1'!U:V,2,0),"0") -> 0 | J14: กล่อง | K14: =+I14*C14 -> 0 | L14: =IFERROR(VLOOKUP(A14,'2'!U:V,2,0),"0") -> 0 | M14: กล่อง | N14: =+L14*C14 -> 0 | O14: =IFERROR(VLOOKUP(A14,'3'!U:V,2,0),"0") -> 0 | P14: กล่อง | Q14: =+O14*C14 -> 0 | R14: =IFERROR(VLOOKUP(A14,'4'!U:V,2,0),"0") -> 0 | S14: กล่อง | T14: =+R14*C14 -> 0 | U14: =IFERROR(VLOOKUP(A14,'5'!U:V,2,0),"0") -> 0 | V14: กล่อง | W14: =+U14*C14 -> 0 | X14: =IFERROR(VLOOKUP(A14,'6'!U:V,2,0),"0") -> 0 | Y14: กล่อง | Z14: =+X14*C14 -> 0 | AA14: =IFERROR(VLOOKUP(A14,'7'!U:V,2,0),"0") -> 0 | AB14: กล่อง | AC14: =+AA14*C14 -> 0 | AD14: =IFERROR(VLOOKUP(A14,'8'!U:V,2,0),"0") -> 0 | AE14: กล่อง | AF14: =+AD14*C14 -> 0 | AG14: =IFERROR(VLOOKUP(A14,'9'!U:V,2,0),"0") -> 0 | AH14: กล่อง | AI14: =+AG14*C14 -> 0 | AJ14: =IFERROR(VLOOKUP(A14,'10'!U:V,2,0),"0") -> 0 | AK14: กล่อง | AL14: =+AJ14*C14 -> 0 | AM14: =IFERROR(VLOOKUP(A14,'11'!U:V,2,0),"0") -> 0 | AN14: กล่อง | AO14: =+AM14*C14 -> 0 | AP14: =IFERROR(VLOOKUP(A14,'12'!U:V,2,0),"0") -> 0 | AQ14: กล่อง | AR14: =+AP14*C14 -> 0 | AS14: =IFERROR(VLOOKUP(A14,'13'!U:V,2,0),"0") -> 0 | AT14: กล่อง | AU14: =+AS14*C14 -> 0 | AV14: =IFERROR(VLOOKUP(A14,'14'!U:V,2,0),"0") -> 0 | AW14: กล่อง | AX14: =+AV14*C14 -> 0 | AY14: =IFERROR(VLOOKUP(A14,'15'!U:V,2,0),"0") -> 0 | AZ14: กล่อง | BA14: =+AY14*C14 -> 0 | BB14: =IFERROR(VLOOKUP(A14,'16'!U:V,2,0),"0") -> 0 | BC14: กล่อง | BD14: =+BB14*C14 -> 0 | BE14: =IFERROR(VLOOKUP(A14,'17'!U:V,2,0),"0") -> 0 | BF14: กล่อง | BG14: =+BE14*C14 -> 0 | BH14: =IFERROR(VLOOKUP(A14,'18'!U:V,2,0),"0") -> 0 | BI14: กล่อง | BJ14: =+BH14*C14 -> 0 | BK14: =IFERROR(VLOOKUP(A14,'19'!U:V,2,0),"0") -> 0 | BL14: กล่อง | BM14: =+BK14*C14 -> 0 | BN14: =IFERROR(VLOOKUP(A14,'20'!U:V,2,0),"0") -> 0 | BO14: กล่อง | BP14: =+BN14*C14 -> 0 | BQ14: =IFERROR(VLOOKUP(A14,'21'!U:V,2,0),"0") -> 0 | BR14: กล่อง | BS14: =+BQ14*C14 -> 0 | BT14: =IFERROR(VLOOKUP(A14,'22'!U:V,2,0),"0") -> 0 | BU14: กล่อง | BV14: =+BT14*C14 -> 0 | BW14: =IFERROR(VLOOKUP(A14,'23'!U:V,2,0),"0") -> 0 | BX14: กล่อง | BY14: =+BW14*C14 -> 0 | BZ14: =IFERROR(VLOOKUP(A14,'24'!U:V,2,0),"0") -> 0 | CA14: กล่อง | CB14: =+BZ14*C14 -> 0 | CC14: =IFERROR(VLOOKUP(A14,'25'!U:V,2,0),"0") -> 0 | CD14: กล่อง | CE14: =+CC14*C14 -> 0 | CF14: =IFERROR(VLOOKUP(A14,'26'!U:V,2,0),"0") -> 0 | CG14: กล่อง | CH14: =+CF14*C14 -> 0 | CI14: =IFERROR(VLOOKUP(A14,'27'!U:V,2,0),"0") -> 0 | CJ14: กล่อง | CK14: =+CI14*C14 -> 0 | CL14: =IFERROR(VLOOKUP(A14,'28'!U:V,2,0),"0") -> 0 | CM14: กล่อง | CN14: =+CL14*C14 -> 0 | CO14: =IFERROR(VLOOKUP(A14,'29'!U:V,2,0),"0") -> 0 | CP14: กล่อง | CQ14: =+CO14*C14 -> 0 | CR14: =IFERROR(VLOOKUP(A14,'30'!U:V,2,0),"0") -> 0 | CS14: กล่อง | CT14: =+CR14*C14 -> 0 | CU14: =IFERROR(VLOOKUP(A14,'31'!U:V,2,0),"0") -> 0 | CV14: กล่อง | CW14: =+CU14*C14 -> 0 | CX14: =IFERROR(VLOOKUP(A14,'เซต1-31'!V:W,2,0),"0") -> 0 | CY14: กล่อง | CZ14: =+CX14*CQ14 -> 0
A15: 1111002-M | B15: ชิฟฟ่อนรวมรส แบบไม่มีไส้ 1 กล่องมี 8 ชิ้น เก็บได้ 20 วัน คละรสชาติให้ นุ่ม หอม อร่อย วรรณวนัช | C15: 37.17 | D15: 1 | E15: =+D15*F15 -> 0 | F15: =+I15+L15+O15+R15+U15+X15+AA15+AD15+AG15+AJ15+AM15+AP15+AS15+AV15+AY15+BB15+BE15+BH15+BK15+BN15+BQ15+BT15+BW15+BZ15+CC15+CF15+CI15+CL15+CO15+CR15+CU15+CX15 -> 0 | G15: กล่อง | H15: =+F15*C15 -> 0 | I15: =IFERROR(VLOOKUP(A15,'1'!U:V,2,0),"0") -> 0 | J15: กล่อง | K15: =+I15*C15 -> 0 | L15: =IFERROR(VLOOKUP(A15,'2'!U:V,2,0),"0") -> 0 | M15: กล่อง | N15: =+L15*C15 -> 0 | O15: =IFERROR(VLOOKUP(A15,'3'!U:V,2,0),"0") -> 0 | P15: กล่อง | Q15: =+O15*C15 -> 0 | R15: =IFERROR(VLOOKUP(A15,'4'!U:V,2,0),"0") -> 0 | S15: กล่อง | T15: =+R15*C15 -> 0 | U15: =IFERROR(VLOOKUP(A15,'5'!U:V,2,0),"0") -> 0 | V15: กล่อง | W15: =+U15*C15 -> 0 | X15: =IFERROR(VLOOKUP(A15,'6'!U:V,2,0),"0") -> 0 | Y15: กล่อง | Z15: =+X15*C15 -> 0 | AA15: =IFERROR(VLOOKUP(A15,'7'!U:V,2,0),"0") -> 0 | AB15: กล่อง | AC15: =+AA15*C15 -> 0 | AD15: =IFERROR(VLOOKUP(A15,'8'!U:V,2,0),"0") -> 0 | AE15: กล่อง | AF15: =+AD15*C15 -> 0 | AG15: =IFERROR(VLOOKUP(A15,'9'!U:V,2,0),"0") -> 0 | AH15: กล่อง | AI15: =+AG15*C15 -> 0 | AJ15: =IFERROR(VLOOKUP(A15,'10'!U:V,2,0),"0") -> 0 | AK15: กล่อง | AL15: =+AJ15*C15 -> 0 | AM15: =IFERROR(VLOOKUP(A15,'11'!U:V,2,0),"0") -> 0 | AN15: กล่อง | AO15: =+AM15*C15 -> 0 | AP15: =IFERROR(VLOOKUP(A15,'12'!U:V,2,0),"0") -> 0 | AQ15: กล่อง | AR15: =+AP15*C15 -> 0 | AS15: =IFERROR(VLOOKUP(A15,'13'!U:V,2,0),"0") -> 0 | AT15: กล่อง | AU15: =+AS15*C15 -> 0 | AV15: =IFERROR(VLOOKUP(A15,'14'!U:V,2,0),"0") -> 0 | AW15: กล่อง | AX15: =+AV15*C15 -> 0 | AY15: =IFERROR(VLOOKUP(A15,'15'!U:V,2,0),"0") -> 0 | AZ15: กล่อง | BA15: =+AY15*C15 -> 0 | BB15: =IFERROR(VLOOKUP(A15,'16'!U:V,2,0),"0") -> 0 | BC15: กล่อง | BD15: =+BB15*C15 -> 0 | BE15: =IFERROR(VLOOKUP(A15,'17'!U:V,2,0),"0") -> 0 | BF15: กล่อง | BG15: =+BE15*C15 -> 0 | BH15: =IFERROR(VLOOKUP(A15,'18'!U:V,2,0),"0") -> 0 | BI15: กล่อง | BJ15: =+BH15*C15 -> 0 | BK15: =IFERROR(VLOOKUP(A15,'19'!U:V,2,0),"0") -> 0 | BL15: กล่อง | BM15: =+BK15*C15 -> 0 | BN15: =IFERROR(VLOOKUP(A15,'20'!U:V,2,0),"0") -> 0 | BO15: กล่อง | BP15: =+BN15*C15 -> 0 | BQ15: =IFERROR(VLOOKUP(A15,'21'!U:V,2,0),"0") -> 0 | BR15: กล่อง | BS15: =+BQ15*C15 -> 0 | BT15: =IFERROR(VLOOKUP(A15,'22'!U:V,2,0),"0") -> 0 | BU15: กล่อง | BV15: =+BT15*C15 -> 0 | BW15: =IFERROR(VLOOKUP(A15,'23'!U:V,2,0),"0") -> 0 | BX15: กล่อง | BY15: =+BW15*C15 -> 0 | BZ15: =IFERROR(VLOOKUP(A15,'24'!U:V,2,0),"0") -> 0 | CA15: กล่อง | CB15: =+BZ15*C15 -> 0 | CC15: =IFERROR(VLOOKUP(A15,'25'!U:V,2,0),"0") -> 0 | CD15: กล่อง | CE15: =+CC15*C15 -> 0 | CF15: =IFERROR(VLOOKUP(A15,'26'!U:V,2,0),"0") -> 0 | CG15: กล่อง | CH15: =+CF15*C15 -> 0 | CI15: =IFERROR(VLOOKUP(A15,'27'!U:V,2,0),"0") -> 0 | CJ15: กล่อง | CK15: =+CI15*C15 -> 0 | CL15: =IFERROR(VLOOKUP(A15,'28'!U:V,2,0),"0") -> 0 | CM15: กล่อง | CN15: =+CL15*C15 -> 0 | CO15: =IFERROR(VLOOKUP(A15,'29'!U:V,2,0),"0") -> 0 | CP15: กล่อง | CQ15: =+CO15*C15 -> 0 | CR15: =IFERROR(VLOOKUP(A15,'30'!U:V,2,0),"0") -> 0 | CS15: กล่อง | CT15: =+CR15*C15 -> 0 | CU15: =IFERROR(VLOOKUP(A15,'31'!U:V,2,0),"0") -> 0 | CV15: กล่อง | CW15: =+CU15*C15 -> 0 | CX15: =IFERROR(VLOOKUP(A15,'เซต1-31'!V:W,2,0),"0") -> 0 | CY15: กล่อง | CZ15: =+CX15*CQ15 -> 0
A16: 1111008 | B16: ชิฟฟ่อน สอดไส้แยม ขนาด3 ชิ้น มีรสให้เลือก 7 รส (รวมรส) | C16: 11.38 | D16: 1 | E16: =+D16*F16 -> 2208 | F16: =+I16+L16+O16+R16+U16+X16+AA16+AD16+AG16+AJ16+AM16+AP16+AS16+AV16+AY16+BB16+BE16+BH16+BK16+BN16+BQ16+BT16+BW16+BZ16+CC16+CF16+CI16+CL16+CO16+CR16+CU16+CX16 -> 2208 | G16: กล่อง | H16: =+F16*C16 -> 25127.04 | I16: =IFERROR(VLOOKUP(A16,'1'!U:V,2,0),"0") -> 0 | J16: กล่อง | K16: =+I16*C16 -> 0 | L16: =IFERROR(VLOOKUP(A16,'2'!U:V,2,0),"0") -> 167 | M16: กล่อง | N16: =+L16*C16 -> 1900.46 | O16: =IFERROR(VLOOKUP(A16,'3'!U:V,2,0),"0") -> 162 | P16: กล่อง | Q16: =+O16*C16 -> 1843.56 | R16: =IFERROR(VLOOKUP(A16,'4'!U:V,2,0),"0") -> 79 | S16: กล่อง | T16: =+R16*C16 -> 899.02 | U16: =IFERROR(VLOOKUP(A16,'5'!U:V,2,0),"0") -> 38 | V16: กล่อง | W16: =+U16*C16 -> 432.44 | X16: =IFERROR(VLOOKUP(A16,'6'!U:V,2,0),"0") -> 91 | Y16: กล่อง | Z16: =+X16*C16 -> 1035.58 | AA16: =IFERROR(VLOOKUP(A16,'7'!U:V,2,0),"0") -> 62 | AB16: กล่อง | AC16: =+AA16*C16 -> 705.56 | AD16: =IFERROR(VLOOKUP(A16,'8'!U:V,2,0),"0") -> 103 | AE16: กล่อง | AF16: =+AD16*C16 -> 1172.14 | AG16: =IFERROR(VLOOKUP(A16,'9'!U:V,2,0),"0") -> 110 | AH16: กล่อง | AI16: =+AG16*C16 -> 1251.8 | AJ16: =IFERROR(VLOOKUP(A16,'10'!U:V,2,0),"0") -> 45 | AK16: กล่อง | AL16: =+AJ16*C16 -> 512.1 | AM16: =IFERROR(VLOOKUP(A16,'11'!U:V,2,0),"0") -> 162 | AN16: กล่อง | AO16: =+AM16*C16 -> 1843.56 | AP16: =IFERROR(VLOOKUP(A16,'12'!U:V,2,0),"0") -> 64 | AQ16: กล่อง | AR16: =+AP16*C16 -> 728.32 | AS16: =IFERROR(VLOOKUP(A16,'13'!U:V,2,0),"0") -> 121 | AT16: กล่อง | AU16: =+AS16*C16 -> 1376.98 | AV16: =IFERROR(VLOOKUP(A16,'14'!U:V,2,0),"0") -> 44 | AW16: กล่อง | AX16: =+AV16*C16 -> 500.72 | AY16: =IFERROR(VLOOKUP(A16,'15'!U:V,2,0),"0") -> 110 | AZ16: กล่อง | BA16: =+AY16*C16 -> 1251.8 | BB16: =IFERROR(VLOOKUP(A16,'16'!U:V,2,0),"0") -> 72 | BC16: กล่อง | BD16: =+BB16*C16 -> 819.36 | BE16: =IFERROR(VLOOKUP(A16,'17'!U:V,2,0),"0") -> 37 | BF16: กล่อง | BG16: =+BE16*C16 -> 421.06 | BH16: =IFERROR(VLOOKUP(A16,'18'!U:V,2,0),"0") -> 78 | BI16: กล่อง | BJ16: =+BH16*C16 -> 887.64 | BK16: =IFERROR(VLOOKUP(A16,'19'!U:V,2,0),"0") -> 57 | BL16: กล่อง | BM16: =+BK16*C16 -> 648.66 | BN16: =IFERROR(VLOOKUP(A16,'20'!U:V,2,0),"0") -> 71 | BO16: กล่อง | BP16: =+BN16*C16 -> 807.98 | BQ16: =IFERROR(VLOOKUP(A16,'21'!U:V,2,0),"0") -> 52 | BR16: กล่อง | BS16: =+BQ16*C16 -> 591.76 | BT16: =IFERROR(VLOOKUP(A16,'22'!U:V,2,0),"0") -> 51 | BU16: กล่อง | BV16: =+BT16*C16 -> 580.38 | BW16: =IFERROR(VLOOKUP(A16,'23'!U:V,2,0),"0") -> 83 | BX16: กล่อง | BY16: =+BW16*C16 -> 944.54 | BZ16: =IFERROR(VLOOKUP(A16,'24'!U:V,2,0),"0") -> 78 | CA16: กล่อง | CB16: =+BZ16*C16 -> 887.64 | CC16: =IFERROR(VLOOKUP(A16,'25'!U:V,2,0),"0") -> 75 | CD16: กล่อง | CE16: =+CC16*C16 -> 853.5 | CF16: =IFERROR(VLOOKUP(A16,'26'!U:V,2,0),"0") -> 63 | CG16: กล่อง | CH16: =+CF16*C16 -> 716.94 | CI16: =IFERROR(VLOOKUP(A16,'27'!U:V,2,0),"0") -> 58 | CJ16: กล่อง | CK16: =+CI16*C16 -> 660.04 | CL16: =IFERROR(VLOOKUP(A16,'28'!U:V,2,0),"0") -> 75 | CM16: กล่อง | CN16: =+CL16*C16 -> 853.5 | CO16: =IFERROR(VLOOKUP(A16,'29'!U:V,2,0),"0") -> 0 | CP16: กล่อง | CQ16: =+CO16*C16 -> 0 | CR16: =IFERROR(VLOOKUP(A16,'30'!U:V,2,0),"0") -> 0 | CS16: กล่อง | CT16: =+CR16*C16 -> 0 | CU16: =IFERROR(VLOOKUP(A16,'31'!U:V,2,0),"0") -> 0 | CV16: กล่อง | CW16: =+CU16*C16 -> 0 | CX16: =IFERROR(VLOOKUP(A16,'เซต1-31'!V:W,2,0),"0") -> 0 | CY16: กล่อง | CZ16: =+CX16*CQ16 -> 0
... A110: ปกค1 | B110: ปังกรอบคาราเมล | C110: 17.5 | D110: 1 | E110: =+D110*F110 -> 0 | F110: =+I110+L110+O110+R110+U110+X110+AA110+AD110+AG110+AJ110+AM110+AP110+AS110+AV110+AY110+BB110+BE110+BH110+BK110+BN110+BQ110+BT110+BW110+BZ110+CC110+CF110+CI110+CL110+CO110+CR110+CU110+CX110 -> 0 | G110: ถุง | H110: =+F110*C110 -> 0 | I110: =IFERROR(VLOOKUP(A110,'1'!U:V,2,0),"0") -> 0 | J110: ถุง | K110: =+I110*C110 -> 0 | L110: =IFERROR(VLOOKUP(A110,'2'!U:V,2,0),"0") -> 0 | M110: ถุง | N110: =+L110*C110 -> 0 | O110: =IFERROR(VLOOKUP(A110,'3'!U:V,2,0),"0") -> 0 | P110: ถุง | Q110: =+O110*C110 -> 0 | R110: =IFERROR(VLOOKUP(A110,'4'!U:V,2,0),"0") -> 0 | S110: ถุง | T110: =+R110*C110 -> 0 | U110: =IFERROR(VLOOKUP(A110,'5'!U:V,2,0),"0") -> 0 | V110: ถุง | W110: =+U110*C110 -> 0 | X110: =IFERROR(VLOOKUP(A110,'6'!U:V,2,0),"0") -> 0 | Y110: ถุง | Z110: =+X110*C110 -> 0 | AA110: =IFERROR(VLOOKUP(A110,'7'!U:V,2,0),"0") -> 0 | AB110: ถุง | AC110: =+AA110*C110 -> 0 | AD110: =IFERROR(VLOOKUP(A110,'8'!U:V,2,0),"0") -> 0 | AE110: ถุง | AF110: =+AD110*C110 -> 0 | AG110: =IFERROR(VLOOKUP(A110,'9'!U:V,2,0),"0") -> 0 | AH110: ถุง | AI110: =+AG110*C110 -> 0 | AJ110: =IFERROR(VLOOKUP(A110,'10'!U:V,2,0),"0") -> 0 | AK110: ถุง | AL110: =+AJ110*C110 -> 0 | AM110: =IFERROR(VLOOKUP(A110,'11'!U:V,2,0),"0") -> 0 | AN110: ถุง | AO110: =+AM110*C110 -> 0 | AP110: =IFERROR(VLOOKUP(A110,'12'!U:V,2,0),"0") -> 0 | AQ110: ถุง | AR110: =+AP110*C110 -> 0 | AS110: =IFERROR(VLOOKUP(A110,'13'!U:V,2,0),"0") -> 0 | AT110: ถุง | AU110: =+AS110*C110 -> 0 | AV110: =IFERROR(VLOOKUP(A110,'14'!U:V,2,0),"0") -> 0 | AW110: ถุง | AX110: =+AV110*C110 -> 0 | AY110: =IFERROR(VLOOKUP(A110,'15'!U:V,2,0),"0") -> 0 | AZ110: ถุง | BA110: =+AY110*C110 -> 0 | BB110: =IFERROR(VLOOKUP(A110,'16'!U:V,2,0),"0") -> 0 | BC110: ถุง | BD110: =+BB110*C110 -> 0 | BE110: =IFERROR(VLOOKUP(A110,'17'!U:V,2,0),"0") -> 0 | BF110: ถุง | BG110: =+BE110*C110 -> 0 | BH110: =IFERROR(VLOOKUP(A110,'18'!U:V,2,0),"0") -> 0 | BI110: ถุง | BJ110: =+BH110*C110 -> 0 | BK110: =IFERROR(VLOOKUP(A110,'19'!U:V,2,0),"0") -> 0 | BL110: ถุง | BM110: =+BK110*C110 -> 0 | BN110: =IFERROR(VLOOKUP(A110,'20'!U:V,2,0),"0") -> 0 | BO110: ถุง | BP110: =+BN110*C110 -> 0 | BQ110: =IFERROR(VLOOKUP(A110,'21'!U:V,2,0),"0") -> 0 | BR110: ถุง | BS110: =+BQ110*C110 -> 0 | BT110: =IFERROR(VLOOKUP(A110,'22'!U:V,2,0),"0") -> 0 | BU110: ถุง | BV110: =+BT110*C110 -> 0 | BW110: =IFERROR(VLOOKUP(A110,'23'!U:V,2,0),"0") -> 0 | BX110: ถุง | BY110: =+BW110*C110 -> 0 | BZ110: =IFERROR(VLOOKUP(A110,'24'!U:V,2,0),"0") -> 0 | CA110: ถุง | CB110: =+BZ110*C110 -> 0 | CC110: =IFERROR(VLOOKUP(A110,'25'!U:V,2,0),"0") -> 0 | CD110: ถุง | CE110: =+CC110*C110 -> 0 | CF110: =IFERROR(VLOOKUP(A110,'26'!U:V,2,0),"0") -> 0 | CG110: ถุง | CH110: =+CF110*C110 -> 0 | CI110: =IFERROR(VLOOKUP(A110,'27'!U:V,2,0),"0") -> 0 | CJ110: ถุง | CK110: =+CI110*C110 -> 0 | CL110: =IFERROR(VLOOKUP(A110,'28'!U:V,2,0),"0") -> 0 | CM110: ถุง | CN110: =+CL110*C110 -> 0 | CO110: =IFERROR(VLOOKUP(A110,'29'!U:V,2,0),"0") -> 0 | CP110: ถุง | CQ110: =+CO110*C110 -> 0 | CR110: =IFERROR(VLOOKUP(A110,'30'!U:V,2,0),"0") -> 0 | CS110: ถุง | CT110: =+CR110*C110 -> 0 | CU110: =IFERROR(VLOOKUP(A110,'31'!U:V,2,0),"0") -> 0 | CV110: ถุง | CW110: =+CU110*C110 -> 0 | CX110: =IFERROR(VLOOKUP(A110,'เซต1-31'!V:W,2,0),"0") -> 0 | CY110: ถุง | CZ110: =+CX110*CQ110 -> 0
A111: เศษปัง | B111: เศษขนมปังปลา1กก. | C111: =7.5*1 -> 7.5 | D111: 1 | E111: =+D111*F111 -> 0 | F111: =+I111+L111+O111+R111+U111+X111+AA111+AD111+AG111+AJ111+AM111+AP111+AS111+AV111+AY111+BB111+BE111+BH111+BK111+BN111+BQ111+BT111+BW111+BZ111+CC111+CF111+CI111+CL111+CO111+CR111+CU111+CX111 -> 0 | G111: กิโลกรัม | H111: =+F111*C111 -> 0 | I111: =IFERROR(VLOOKUP(A111,'1'!U:V,2,0),"0") -> 0 | J111: กิโลกรัม | K111: =+I111*C111 -> 0 | L111: =IFERROR(VLOOKUP(A111,'2'!U:V,2,0),"0") -> 0 | M111: กิโลกรัม | N111: =+L111*C111 -> 0 | O111: =IFERROR(VLOOKUP(A111,'3'!U:V,2,0),"0") -> 0 | P111: กิโลกรัม | Q111: =+O111*C111 -> 0 | R111: =IFERROR(VLOOKUP(A111,'4'!U:V,2,0),"0") -> 0 | S111: กิโลกรัม | T111: =+R111*C111 -> 0 | U111: =IFERROR(VLOOKUP(A111,'5'!U:V,2,0),"0") -> 0 | V111: กิโลกรัม | W111: =+U111*C111 -> 0 | X111: =IFERROR(VLOOKUP(A111,'6'!U:V,2,0),"0") -> 0 | Y111: กิโลกรัม | Z111: =+X111*C111 -> 0 | AA111: =IFERROR(VLOOKUP(A111,'7'!U:V,2,0),"0") -> 0 | AB111: กิโลกรัม | AC111: =+AA111*C111 -> 0 | AD111: =IFERROR(VLOOKUP(A111,'8'!U:V,2,0),"0") -> 0 | AE111: กิโลกรัม | AF111: =+AD111*C111 -> 0 | AG111: =IFERROR(VLOOKUP(A111,'9'!U:V,2,0),"0") -> 0 | AH111: กิโลกรัม | AI111: =+AG111*C111 -> 0 | AJ111: =IFERROR(VLOOKUP(A111,'10'!U:V,2,0),"0") -> 0 | AK111: กิโลกรัม | AL111: =+AJ111*C111 -> 0 | AM111: =IFERROR(VLOOKUP(A111,'11'!U:V,2,0),"0") -> 0 | AN111: กิโลกรัม | AO111: =+AM111*C111 -> 0 | AP111: =IFERROR(VLOOKUP(A111,'12'!U:V,2,0),"0") -> 0 | AQ111: กิโลกรัม | AR111: =+AP111*C111 -> 0 | AS111: =IFERROR(VLOOKUP(A111,'13'!U:V,2,0),"0") -> 0 | AT111: กิโลกรัม | AU111: =+AS111*C111 -> 0 | AV111: =IFERROR(VLOOKUP(A111,'14'!U:V,2,0),"0") -> 0 | AW111: กิโลกรัม | AX111: =+AV111*C111 -> 0 | AY111: =IFERROR(VLOOKUP(A111,'15'!U:V,2,0),"0") -> 0 | AZ111: กิโลกรัม | BA111: =+AY111*C111 -> 0 | BB111: =IFERROR(VLOOKUP(A111,'16'!U:V,2,0),"0") -> 0 | BC111: กิโลกรัม | BD111: =+BB111*C111 -> 0 | BE111: =IFERROR(VLOOKUP(A111,'17'!U:V,2,0),"0") -> 0 | BF111: กิโลกรัม | BG111: =+BE111*C111 -> 0 | BH111: =IFERROR(VLOOKUP(A111,'18'!U:V,2,0),"0") -> 0 | BI111: กิโลกรัม | BJ111: =+BH111*C111 -> 0 | BK111: =IFERROR(VLOOKUP(A111,'19'!U:V,2,0),"0") -> 0 | BL111: กิโลกรัม | BM111: =+BK111*C111 -> 0 | BN111: =IFERROR(VLOOKUP(A111,'20'!U:V,2,0),"0") -> 0 | BO111: กิโลกรัม | BP111: =+BN111*C111 -> 0 | BQ111: =IFERROR(VLOOKUP(A111,'21'!U:V,2,0),"0") -> 0 | BR111: กิโลกรัม | BS111: =+BQ111*C111 -> 0 | BT111: =IFERROR(VLOOKUP(A111,'22'!U:V,2,0),"0") -> 0 | BU111: กิโลกรัม | BV111: =+BT111*C111 -> 0 | BW111: =IFERROR(VLOOKUP(A111,'23'!U:V,2,0),"0") -> 0 | BX111: กิโลกรัม | BY111: =+BW111*C111 -> 0 | BZ111: =IFERROR(VLOOKUP(A111,'24'!U:V,2,0),"0") -> 0 | CA111: กิโลกรัม | CB111: =+BZ111*C111 -> 0 | CC111: =IFERROR(VLOOKUP(A111,'25'!U:V,2,0),"0") -> 0 | CD111: กิโลกรัม | CE111: =+CC111*C111 -> 0 | CF111: =IFERROR(VLOOKUP(A111,'26'!U:V,2,0),"0") -> 0 | CG111: กิโลกรัม | CH111: =+CF111*C111 -> 0 | CI111: =IFERROR(VLOOKUP(A111,'27'!U:V,2,0),"0") -> 0 | CJ111: กิโลกรัม | CK111: =+CI111*C111 -> 0 | CL111: =IFERROR(VLOOKUP(A111,'28'!U:V,2,0),"0") -> 0 | CM111: กิโลกรัม | CN111: =+CL111*C111 -> 0 | CO111: =IFERROR(VLOOKUP(A111,'29'!U:V,2,0),"0") -> 0 | CP111: กิโลกรัม | CQ111: =+CO111*C111 -> 0 | CR111: =IFERROR(VLOOKUP(A111,'30'!U:V,2,0),"0") -> 0 | CS111: กิโลกรัม | CT111: =+CR111*C111 -> 0 | CU111: =IFERROR(VLOOKUP(A111,'31'!U:V,2,0),"0") -> 0 | CV111: กิโลกรัม | CW111: =+CU111*C111 -> 0 | CX111: =IFERROR(VLOOKUP(A111,'เซต1-31'!V:W,2,0),"0") -> 0 | CY111: กิโลกรัม | CZ111: =+CX111*CQ111 -> 0
A112: เศษปัง-1 | B112: เศษขนมปังปลา5กก. | C112: =7.5*5 -> 37.5 | D112: 1 | E112: =+D112*F112 -> 0 | F112: =+I112+L112+O112+R112+U112+X112+AA112+AD112+AG112+AJ112+AM112+AP112+AS112+AV112+AY112+BB112+BE112+BH112+BK112+BN112+BQ112+BT112+BW112+BZ112+CC112+CF112+CI112+CL112+CO112+CR112+CU112+CX112 -> 0 | G112: กิโลกรัม | H112: =+F112*C112 -> 0 | I112: =IFERROR(VLOOKUP(A112,'1'!U:V,2,0),"0") -> 0 | J112: กิโลกรัม | K112: =+I112*C112 -> 0 | L112: =IFERROR(VLOOKUP(A112,'2'!U:V,2,0),"0") -> 0 | M112: กิโลกรัม | N112: =+L112*C112 -> 0 | O112: =IFERROR(VLOOKUP(A112,'3'!U:V,2,0),"0") -> 0 | P112: กิโลกรัม | Q112: =+O112*C112 -> 0 | R112: =IFERROR(VLOOKUP(A112,'4'!U:V,2,0),"0") -> 0 | S112: กิโลกรัม | T112: =+R112*C112 -> 0 | U112: =IFERROR(VLOOKUP(A112,'5'!U:V,2,0),"0") -> 0 | V112: กิโลกรัม | W112: =+U112*C112 -> 0 | X112: =IFERROR(VLOOKUP(A112,'6'!U:V,2,0),"0") -> 0 | Y112: กิโลกรัม | Z112: =+X112*C112 -> 0 | AA112: =IFERROR(VLOOKUP(A112,'7'!U:V,2,0),"0") -> 0 | AB112: กิโลกรัม | AC112: =+AA112*C112 -> 0 | AD112: =IFERROR(VLOOKUP(A112,'8'!U:V,2,0),"0") -> 0 | AE112: กิโลกรัม | AF112: =+AD112*C112 -> 0 | AG112: =IFERROR(VLOOKUP(A112,'9'!U:V,2,0),"0") -> 0 | AH112: กิโลกรัม | AI112: =+AG112*C112 -> 0 | AJ112: =IFERROR(VLOOKUP(A112,'10'!U:V,2,0),"0") -> 0 | AK112: กิโลกรัม | AL112: =+AJ112*C112 -> 0 | AM112: =IFERROR(VLOOKUP(A112,'11'!U:V,2,0),"0") -> 0 | AN112: กิโลกรัม | AO112: =+AM112*C112 -> 0 | AP112: =IFERROR(VLOOKUP(A112,'12'!U:V,2,0),"0") -> 0 | AQ112: กิโลกรัม | AR112: =+AP112*C112 -> 0 | AS112: =IFERROR(VLOOKUP(A112,'13'!U:V,2,0),"0") -> 0 | AT112: กิโลกรัม | AU112: =+AS112*C112 -> 0 | AV112: =IFERROR(VLOOKUP(A112,'14'!U:V,2,0),"0") -> 0 | AW112: กิโลกรัม | AX112: =+AV112*C112 -> 0 | AY112: =IFERROR(VLOOKUP(A112,'15'!U:V,2,0),"0") -> 0 | AZ112: กิโลกรัม | BA112: =+AY112*C112 -> 0 | BB112: =IFERROR(VLOOKUP(A112,'16'!U:V,2,0),"0") -> 0 | BC112: กิโลกรัม | BD112: =+BB112*C112 -> 0 | BE112: =IFERROR(VLOOKUP(A112,'17'!U:V,2,0),"0") -> 0 | BF112: กิโลกรัม | BG112: =+BE112*C112 -> 0 | BH112: =IFERROR(VLOOKUP(A112,'18'!U:V,2,0),"0") -> 0 | BI112: กิโลกรัม | BJ112: =+BH112*C112 -> 0 | BK112: =IFERROR(VLOOKUP(A112,'19'!U:V,2,0),"0") -> 0 | BL112: กิโลกรัม | BM112: =+BK112*C112 -> 0 | BN112: =IFERROR(VLOOKUP(A112,'20'!U:V,2,0),"0") -> 0 | BO112: กิโลกรัม | BP112: =+BN112*C112 -> 0 | BQ112: =IFERROR(VLOOKUP(A112,'21'!U:V,2,0),"0") -> 0 | BR112: กิโลกรัม | BS112: =+BQ112*C112 -> 0 | BT112: =IFERROR(VLOOKUP(A112,'22'!U:V,2,0),"0") -> 0 | BU112: กิโลกรัม | BV112: =+BT112*C112 -> 0 | BW112: =IFERROR(VLOOKUP(A112,'23'!U:V,2,0),"0") -> 0 | BX112: กิโลกรัม | BY112: =+BW112*C112 -> 0 | BZ112: =IFERROR(VLOOKUP(A112,'24'!U:V,2,0),"0") -> 0 | CA112: กิโลกรัม | CB112: =+BZ112*C112 -> 0 | CC112: =IFERROR(VLOOKUP(A112,'25'!U:V,2,0),"0") -> 0 | CD112: กิโลกรัม | CE112: =+CC112*C112 -> 0 | CF112: =IFERROR(VLOOKUP(A112,'26'!U:V,2,0),"0") -> 0 | CG112: กิโลกรัม | CH112: =+CF112*C112 -> 0 | CI112: =IFERROR(VLOOKUP(A112,'27'!U:V,2,0),"0") -> 0 | CJ112: กิโลกรัม | CK112: =+CI112*C112 -> 0 | CL112: =IFERROR(VLOOKUP(A112,'28'!U:V,2,0),"0") -> 0 | CM112: กิโลกรัม | CN112: =+CL112*C112 -> 0 | CO112: =IFERROR(VLOOKUP(A112,'29'!U:V,2,0),"0") -> 0 | CP112: กิโลกรัม | CQ112: =+CO112*C112 -> 0 | CR112: =IFERROR(VLOOKUP(A112,'30'!U:V,2,0),"0") -> 0 | CS112: กิโลกรัม | CT112: =+CR112*C112 -> 0 | CU112: =IFERROR(VLOOKUP(A112,'31'!U:V,2,0),"0") -> 0 | CV112: กิโลกรัม | CW112: =+CU112*C112 -> 0 | CX112: =IFERROR(VLOOKUP(A112,'เซต1-31'!V:W,2,0),"0") -> 0 | CY112: กิโลกรัม | CZ112: =+CX112*CQ112 -> 0
A113: สอดไส้คละ 1ชิ้น | B113: ชิฟฟอนสอดไส้ เเบบเเยกชิ้น ชิฟฟ่อนเค้ก ชิฟฟ่อนคละรสชาติ (Default) | C113: 4.5 | D113: 1 | E113: =+D113*F113 -> 2 | F113: =+I113+L113+O113+R113+U113+X113+AA113+AD113+AG113+AJ113+AM113+AP113+AS113+AV113+AY113+BB113+BE113+BH113+BK113+BN113+BQ113+BT113+BW113+BZ113+CC113+CF113+CI113+CL113+CO113+CR113+CU113+CX113 -> 2 | G113: ชิ้น | H113: =+F113*C113 -> 9 | I113: =IFERROR(VLOOKUP(A113,'1'!U:V,2,0),"0") -> 0 | J113: ชิ้น | K113: =+I113*C113 -> 0 | L113: =IFERROR(VLOOKUP(A113,'2'!U:V,2,0),"0") -> 0 | M113: ชิ้น | N113: =+L113*C113 -> 0 | O113: =IFERROR(VLOOKUP(A113,'3'!U:V,2,0),"0") -> 0 | P113: ชิ้น | Q113: =+O113*C113 -> 0 | R113: =IFERROR(VLOOKUP(A113,'4'!U:V,2,0),"0") -> 0 | S113: ชิ้น | T113: =+R113*C113 -> 0 | U113: =IFERROR(VLOOKUP(A113,'5'!U:V,2,0),"0") -> 0 | V113: ชิ้น | W113: =+U113*C113 -> 0 | X113: =IFERROR(VLOOKUP(A113,'6'!U:V,2,0),"0") -> 0 | Y113: ชิ้น | Z113: =+X113*C113 -> 0 | AA113: =IFERROR(VLOOKUP(A113,'7'!U:V,2,0),"0") -> 0 | AB113: ชิ้น | AC113: =+AA113*C113 -> 0 | AD113: =IFERROR(VLOOKUP(A113,'8'!U:V,2,0),"0") -> 0 | AE113: ชิ้น | AF113: =+AD113*C113 -> 0 | AG113: =IFERROR(VLOOKUP(A113,'9'!U:V,2,0),"0") -> 0 | AH113: ชิ้น | AI113: =+AG113*C113 -> 0 | AJ113: =IFERROR(VLOOKUP(A113,'10'!U:V,2,0),"0") -> 0 | AK113: ชิ้น | AL113: =+AJ113*C113 -> 0 | AM113: =IFERROR(VLOOKUP(A113,'11'!U:V,2,0),"0") -> 0 | AN113: ชิ้น | AO113: =+AM113*C113 -> 0 | AP113: =IFERROR(VLOOKUP(A113,'12'!U:V,2,0),"0") -> 0 | AQ113: ชิ้น | AR113: =+AP113*C113 -> 0 | AS113: =IFERROR(VLOOKUP(A113,'13'!U:V,2,0),"0") -> 1 | AT113: ชิ้น | AU113: =+AS113*C113 -> 4.5 | AV113: =IFERROR(VLOOKUP(A113,'14'!U:V,2,0),"0") -> 0 | AW113: ชิ้น | AX113: =+AV113*C113 -> 0 | AY113: =IFERROR(VLOOKUP(A113,'15'!U:V,2,0),"0") -> 0 | AZ113: ชิ้น | BA113: =+AY113*C113 -> 0 | BB113: =IFERROR(VLOOKUP(A113,'16'!U:V,2,0),"0") -> 0 | BC113: ชิ้น | BD113: =+BB113*C113 -> 0 | BE113: =IFERROR(VLOOKUP(A113,'17'!U:V,2,0),"0") -> 0 | BF113: ชิ้น | BG113: =+BE113*C113 -> 0 | BH113: =IFERROR(VLOOKUP(A113,'18'!U:V,2,0),"0") -> 0 | BI113: ชิ้น | BJ113: =+BH113*C113 -> 0 | BK113: =IFERROR(VLOOKUP(A113,'19'!U:V,2,0),"0") -> 0 | BL113: ชิ้น | BM113: =+BK113*C113 -> 0 | BN113: =IFERROR(VLOOKUP(A113,'20'!U:V,2,0),"0") -> 0 | BO113: ชิ้น | BP113: =+BN113*C113 -> 0 | BQ113: =IFERROR(VLOOKUP(A113,'21'!U:V,2,0),"0") -> 0 | BR113: ชิ้น | BS113: =+BQ113*C113 -> 0 | BT113: =IFERROR(VLOOKUP(A113,'22'!U:V,2,0),"0") -> 0 | BU113: ชิ้น | BV113: =+BT113*C113 -> 0 | BW113: =IFERROR(VLOOKUP(A113,'23'!U:V,2,0),"0") -> 0 | BX113: ชิ้น | BY113: =+BW113*C113 -> 0 | BZ113: =IFERROR(VLOOKUP(A113,'24'!U:V,2,0),"0") -> 0 | CA113: ชิ้น | CB113: =+BZ113*C113 -> 0 | CC113: =IFERROR(VLOOKUP(A113,'25'!U:V,2,0),"0") -> 0 | CD113: ชิ้น | CE113: =+CC113*C113 -> 0 | CF113: =IFERROR(VLOOKUP(A113,'26'!U:V,2,0),"0") -> 1 | CG113: ชิ้น | CH113: =+CF113*C113 -> 4.5 | CI113: =IFERROR(VLOOKUP(A113,'27'!U:V,2,0),"0") -> 0 | CJ113: ชิ้น | CK113: =+CI113*C113 -> 0 | CL113: =IFERROR(VLOOKUP(A113,'28'!U:V,2,0),"0") -> 0 | CM113: ชิ้น | CN113: =+CL113*C113 -> 0 | CO113: =IFERROR(VLOOKUP(A113,'29'!U:V,2,0),"0") -> 0 | CP113: ชิ้น | CQ113: =+CO113*C113 -> 0 | CR113: =IFERROR(VLOOKUP(A113,'30'!U:V,2,0),"0") -> 0 | CS113: ชิ้น | CT113: =+CR113*C113 -> 0 | CU113: =IFERROR(VLOOKUP(A113,'31'!U:V,2,0),"0") -> 0 | CV113: ชิ้น | CW113: =+CU113*C113 -> 0 | CX113: =IFERROR(VLOOKUP(A113,'เซต1-31'!V:W,2,0),"0") -> 0 | CY113: ชิ้น | CZ113: =+CX113*CQ113 -> 0
A114: 1112010 | B114: เค้กเบาหวิว ใหญ่ 1 กล่องขนาด 300 กรัม (ฝอยทอง) | C114: 26.81 | D114: 1 | E114: =+D114*F114 -> 0 | F114: =+I114+L114+O114+R114+U114+X114+AA114+AD114+AG114+AJ114+AM114+AP114+AS114+AV114+AY114+BB114+BE114+BH114+BK114+BN114+BQ114+BT114+BW114+BZ114+CC114+CF114+CI114+CL114+CO114+CR114+CU114+CX114 -> 0 | G114: กล่อง | H114: =+F114*C114 -> 0 | I114: =IFERROR(VLOOKUP(A114,'1'!U:V,2,0),"0") -> 0 | J114: กล่อง | K114: =+I114*C114 -> 0 | L114: =IFERROR(VLOOKUP(A114,'2'!U:V,2,0),"0") -> 0 | M114: กล่อง | N114: =+L114*C114 -> 0 | O114: =IFERROR(VLOOKUP(A114,'3'!U:V,2,0),"0") -> 0 | P114: กล่อง | Q114: =+O114*C114 -> 0 | R114: =IFERROR(VLOOKUP(A114,'4'!U:V,2,0),"0") -> 0 | S114: กล่อง | T114: =+R114*C114 -> 0 | U114: =IFERROR(VLOOKUP(A114,'5'!U:V,2,0),"0") -> 0 | V114: กล่อง | W114: =+U114*C114 -> 0 | X114: =IFERROR(VLOOKUP(A114,'6'!U:V,2,0),"0") -> 0 | Y114: กล่อง | Z114: =+X114*C114 -> 0 | AA114: =IFERROR(VLOOKUP(A114,'7'!U:V,2,0),"0") -> 0 | AB114: กล่อง | AC114: =+AA114*C114 -> 0 | AD114: =IFERROR(VLOOKUP(A114,'8'!U:V,2,0),"0") -> 0 | AE114: กล่อง | AF114: =+AD114*C114 -> 0 | AG114: =IFERROR(VLOOKUP(A114,'9'!U:V,2,0),"0") -> 0 | AH114: กล่อง | AI114: =+AG114*C114 -> 0 | AJ114: =IFERROR(VLOOKUP(A114,'10'!U:V,2,0),"0") -> 0 | AK114: กล่อง | AL114: =+AJ114*C114 -> 0 | AM114: =IFERROR(VLOOKUP(A114,'11'!U:V,2,0),"0") -> 0 | AN114: กล่อง | AO114: =+AM114*C114 -> 0 | AP114: =IFERROR(VLOOKUP(A114,'12'!U:V,2,0),"0") -> 0 | AQ114: กล่อง | AR114: =+AP114*C114 -> 0 | AS114: =IFERROR(VLOOKUP(A114,'13'!U:V,2,0),"0") -> 0 | AT114: กล่อง | AU114: =+AS114*C114 -> 0 | AV114: =IFERROR(VLOOKUP(A114,'14'!U:V,2,0),"0") -> 0 | AW114: กล่อง | AX114: =+AV114*C114 -> 0 | AY114: =IFERROR(VLOOKUP(A114,'15'!U:V,2,0),"0") -> 0 | AZ114: กล่อง | BA114: =+AY114*C114 -> 0 | BB114: =IFERROR(VLOOKUP(A114,'16'!U:V,2,0),"0") -> 0 | BC114: กล่อง | BD114: =+BB114*C114 -> 0 | BE114: =IFERROR(VLOOKUP(A114,'17'!U:V,2,0),"0") -> 0 | BF114: กล่อง | BG114: =+BE114*C114 -> 0 | BH114: =IFERROR(VLOOKUP(A114,'18'!U:V,2,0),"0") -> 0 | BI114: กล่อง | BJ114: =+BH114*C114 -> 0 | BK114: =IFERROR(VLOOKUP(A114,'19'!U:V,2,0),"0") -> 0 | BL114: กล่อง | BM114: =+BK114*C114 -> 0 | BN114: =IFERROR(VLOOKUP(A114,'20'!U:V,2,0),"0") -> 0 | BO114: กล่อง | BP114: =+BN114*C114 -> 0 | BQ114: =IFERROR(VLOOKUP(A114,'21'!U:V,2,0),"0") -> 0 | BR114: กล่อง | BS114: =+BQ114*C114 -> 0 | BT114: =IFERROR(VLOOKUP(A114,'22'!U:V,2,0),"0") -> 0 | BU114: กล่อง | BV114: =+BT114*C114 -> 0 | BW114: =IFERROR(VLOOKUP(A114,'23'!U:V,2,0),"0") -> 0 | BX114: กล่อง | BY114: =+BW114*C114 -> 0 | BZ114: =IFERROR(VLOOKUP(A114,'24'!U:V,2,0),"0") -> 0 | CA114: กล่อง | CB114: =+BZ114*C114 -> 0 | CC114: =IFERROR(VLOOKUP(A114,'25'!U:V,2,0),"0") -> 0 | CD114: กล่อง | CE114: =+CC114*C114 -> 0 | CF114: =IFERROR(VLOOKUP(A114,'26'!U:V,2,0),"0") -> 0 | CG114: กล่อง | CH114: =+CF114*C114 -> 0 | CI114: =IFERROR(VLOOKUP(A114,'27'!U:V,2,0),"0") -> 0 | CJ114: กล่อง | CK114: =+CI114*C114 -> 0 | CL114: =IFERROR(VLOOKUP(A114,'28'!U:V,2,0),"0") -> 0 | CM114: กล่อง | CN114: =+CL114*C114 -> 0 | CO114: =IFERROR(VLOOKUP(A114,'29'!U:V,2,0),"0") -> 0 | CP114: กล่อง | CQ114: =+CO114*C114 -> 0 | CR114: =IFERROR(VLOOKUP(A114,'30'!U:V,2,0),"0") -> 0 | CS114: กล่อง | CT114: =+CR114*C114 -> 0 | CU114: =IFERROR(VLOOKUP(A114,'31'!U:V,2,0),"0") -> 0 | CV114: กล่อง | CW114: =+CU114*C114 -> 0 | CX114: =IFERROR(VLOOKUP(A114,'เซต1-31'!V:W,2,0),"0") -> 0 | CY114: กล่อง | CZ114: =+CX114*CQ114 -> 0
