Workbook

Sheet ALL
A1: รายการขายสินค้าออนไลน์แยกจำนวนชิ้นรายวัน เดือนมีนาคม 2569
E2: =SUBTOTAL(9,E5:E10472) -> 28862 | F2: =SUBTOTAL(9,F5:F10472) -> 0 | G2: =SUBTOTAL(9,G5:G10472) -> 737683.75 | H2: =SUBTOTAL(9,H5:H10472) -> 697 | I2: =SUBTOTAL(9,I5:I10472) -> 0 | J2: =SUBTOTAL(9,J5:J10472) -> 19605.75 | K2: =SUBTOTAL(9,K5:K10472) -> 807 | L2: =SUBTOTAL(9,L5:L10472) -> 0 | ... CY2: =SUBTOTAL(9,CY5:CY10472) -> 171383.11
A3: รหัสสินค้า | B3: รหัสสินค้า | C3: ชื่อสินค้า | D3: ราคาต้นทุน | E3: เดือนมีนาคม | H3: 244409 | K3: 244410 | N3: 244411 | Q3: 244412 | T3: 244413 | W3: 244414 | Z3: 244415 | AC3: 244416 | AF3: 244417 | AI3: 244418 | AL3: 244419 | AO3: 244420 | AR3: 244421 | AU3: 244422 | AX3: 244423 | BA3: 244424 | BD3: 244425 | BG3: 244426 | BJ3: 244427 | BM3: 244428 | BP3: 244429 | BS3: 244430 | BV3: 244431 | BY3: 244432 | CB3: 244433 | CE3: 244434 | CH3: 244435 | CK3: 244436 | CN3: 244437 | CQ3: 244438 | CT3: 244439 | CW3: ระบบ Bplus
E4: จำนวน | F4: หน่วย | G4: ยอดต้นทุน/วัน | H4: จำนวน | I4: หน่วย | J4: ยอดต้นทุน/วัน | K4: จำนวน | L4: หน่วย | M4: ยอดต้นทุน/วัน | N4: จำนวน | O4: หน่วย | P4: ยอดต้นทุน/วัน | Q4: จำนวน | R4: หน่วย | S4: ยอดต้นทุน/วัน | T4: จำนวน | U4: หน่วย | V4: ยอดต้นทุน/วัน | W4: จำนวน | X4: หน่วย | Y4: ยอดต้นทุน/วัน | Z4: จำนวน | AA4: หน่วย | AB4: ยอดต้นทุน/วัน | AC4: จำนวน | AD4: หน่วย | AE4: ยอดต้นทุน/วัน | AF4: จำนวน | AG4: หน่วย | AH4: ยอดต้นทุน/วัน | AI4: จำนวน | AJ4: หน่วย | AK4: ยอดต้นทุน/วัน | AL4: จำนวน | AM4: หน่วย | AN4: ยอดต้นทุน/วัน | AO4: จำนวน | AP4: หน่วย | AQ4: ยอดต้นทุน/วัน | AR4: จำนวน | AS4: หน่วย | AT4: ยอดต้นทุน/วัน | AU4: จำนวน | AV4: หน่วย | AW4: ยอดต้นทุน/วัน | AX4: จำนวน | AY4: หน่วย | AZ4: ยอดต้นทุน/วัน | BA4: จำนวน | BB4: หน่วย | BC4: ยอดต้นทุน/วัน | BD4: จำนวน | BE4: หน่วย | BF4: ยอดต้นทุน/วัน | BG4: จำนวน | BH4: หน่วย | BI4: ยอดต้นทุน/วัน | BJ4: จำนวน | BK4: หน่วย | BL4: ยอดต้นทุน/วัน | BM4: จำนวน | BN4: หน่วย | BO4: ยอดต้นทุน/วัน | BP4: จำนวน | BQ4: หน่วย | BR4: ยอดต้นทุน/วัน | BS4: จำนวน | BT4: หน่วย | BU4: ยอดต้นทุน/วัน | BV4: จำนวน | BW4: หน่วย | BX4: ยอดต้นทุน/วัน | BY4: จำนวน | BZ4: หน่วย | CA4: ยอดต้นทุน/วัน | CB4: จำนวน | CC4: หน่วย | CD4: ยอดต้นทุน/วัน | CE4: จำนวน | CF4: หน่วย | CG4: ยอดต้นทุน/วัน | CH4: จำนวน | CI4: หน่วย | CJ4: ยอดต้นทุน/วัน | CK4: จำนวน | CL4: หน่วย | CM4: ยอดต้นทุน/วัน | CN4: จำนวน | CO4: หน่วย | CP4: ยอดต้นทุน/วัน | CQ4: จำนวน | CR4: หน่วย | CS4: ยอดต้นทุน/วัน | CT4: จำนวน | CU4: หน่วย | CV4: ยอดต้นทุน/วัน | CW4: จำนวน | CX4: หน่วย | CY4: ยอดต้นทุน/วัน
A5: 0006 | B5: 6 | C5: เค้กเบาหวิวเล็ก 1กล่องขนาด 100 กรัม (คละรส) | D5: 24.41 | E5: =+H5+K5+N5+Q5+T5+W5+Z5+AC5+AF5+AI5+AL5+AO5+AR5+AU5+AX5+BA5+BD5+BG5+BJ5+BM5+BP5+BS5+BV5+BY5+CB5+CE5+CH5+CK5+CN5+CQ5+CT5 -> 15725 | F5: กล่อง | G5: =+E5*D5 -> 383847.25 | H5: =IFERROR(VLOOKUP(A5,'1'!U:V,2,0),"0") -> 274 | I5: กล่อง | J5: =+H5*D5 -> 6688.34 | K5: =IFERROR(VLOOKUP(A5,'2'!U:V,2,0),"0") -> 390 | L5: กล่อง | M5: =+K5*D5 -> 9519.9 | N5: =IFERROR(VLOOKUP(A5,'3'!U:V,2,0),"0") -> 487 | O5: กล่อง | P5: =+N5*D5 -> 11887.67 | Q5: =IFERROR(VLOOKUP(A5,'4'!U:V,2,0),"0") -> 176 | R5: กล่อง | S5: =+Q5*D5 -> 4296.16 | T5: =IFERROR(VLOOKUP(A5,'5'!U:V,2,0),"0") -> 742 | U5: กล่อง | V5: =+T5*D5 -> 18112.22 | W5: =IFERROR(VLOOKUP(A5,'6'!U:V,2,0),"0") -> 615 | X5: กล่อง | Y5: =+W5*D5 -> 15012.15 | Z5: =IFERROR(VLOOKUP(A5,'7'!U:V,2,0),"0") -> 364 | AA5: กล่อง | AB5: =+Z5*D5 -> 8885.24 | AC5: =IFERROR(VLOOKUP(A5,'8'!U:V,2,0),"0") -> 573 | AD5: กล่อง | AE5: =+AC5*D5 -> 13986.93 | AF5: =IFERROR(VLOOKUP(A5,'9'!U:V,2,0),"0") -> 295 | AG5: กล่อง | AH5: =+AF5*D5 -> 7200.95 | AI5: =IFERROR(VLOOKUP(A5,'10'!U:V,2,0),"0") -> 529 | AJ5: กล่อง | AK5: =+AI5*D5 -> 12912.89 | AL5: =IFERROR(VLOOKUP(A5,'11'!U:V,2,0),"0") -> 434 | AM5: กล่อง | AN5: =+AL5*D5 -> 10593.94 | AO5: =IFERROR(VLOOKUP(A5,'12'!U:V,2,0),"0") -> 400 | AP5: กล่อง | AQ5: =+AO5*D5 -> 9764 | AR5: =IFERROR(VLOOKUP(A5,'13'!U:V,2,0),"0") -> 439 | AS5: กล่อง | AT5: =+AR5*D5 -> 10715.99 | AU5: =IFERROR(VLOOKUP(A5,'14'!U:V,2,0),"0") -> 181 | AV5: กล่อง | AW5: =+AU5*D5 -> 4418.21 | AX5: =IFERROR(VLOOKUP(A5,'15'!U:V,2,0),"0") -> 755 | AY5: กล่อง | AZ5: =+AX5*D5 -> 18429.55 | BA5: =IFERROR(VLOOKUP(A5,'16'!U:V,2,0),"0") -> 520 | BB5: กล่อง | BC5: =+BA5*D5 -> 12693.2 | BD5: =IFERROR(VLOOKUP(A5,'17'!U:V,2,0),"0") -> 445 | BE5: กล่อง | BF5: =+BD5*D5 -> 10862.45 | BG5: =IFERROR(VLOOKUP(A5,'18'!U:V,2,0),"0") -> 440 | BH5: กล่อง | BI5: =+BG5*D5 -> 10740.4 | BJ5: =IFERROR(VLOOKUP(A5,'19'!U:V,2,0),"0") -> 320 | BK5: กล่อง | BL5: =+BJ5*D5 -> 7811.2 | BM5: =IFERROR(VLOOKUP(A5,'20'!U:V,2,0),"0") -> 507 | BN5: กล่อง | BO5: =+BM5*D5 -> 12375.87 | BP5: =IFERROR(VLOOKUP(A5,'21'!U:V,2,0),"0") -> 868 | BQ5: กล่อง | BR5: =+BP5*D5 -> 21187.88 | BS5: =IFERROR(VLOOKUP(A5,'22'!U:V,2,0),"0") -> 655 | BT5: กล่อง | BU5: =+BS5*D5 -> 15988.55 | BV5: =IFERROR(VLOOKUP(A5,'23'!U:V,2,0),"0") -> 657 | BW5: กล่อง | BX5: =+BV5*D5 -> 16037.37 | BY5: =IFERROR(VLOOKUP(A5,'24'!U:V,2,0),"0") -> 441 | BZ5: กล่อง | CA5: =+BY5*D5 -> 10764.81 | CB5: =IFERROR(VLOOKUP(A5,'25'!U:V,2,0),"0") -> 642 | CC5: กล่อง | CD5: =+CB5*D5 -> 15671.22 | CE5: =IFERROR(VLOOKUP(A5,'26'!U:V,2,0),"0") -> 312 | CF5: กล่อง | CG5: =+CE5*D5 -> 7615.92 | CH5: =IFERROR(VLOOKUP(A5,'27'!U:V,2,0),"0") -> 262 | CI5: กล่อง | CJ5: =+CH5*D5 -> 6395.42 | CK5: =IFERROR(VLOOKUP(A5,'28'!U:V,2,0),"0") -> 535 | CL5: กล่อง | CM5: =+CK5*D5 -> 13059.35 | CN5: =IFERROR(VLOOKUP(A5,'29'!U:V,2,0),"0") -> 695 | CO5: กล่อง | CP5: =+CN5*D5 -> 16964.95 | CQ5: =IFERROR(VLOOKUP(A5,'30'!U:V,2,0),"0") -> 984 | CR5: กล่อง | CS5: =+CQ5*D5 -> 24019.44 | CT5: =IFERROR(VLOOKUP(A5,'31'!U:V,2,0),"0") -> 788 | CU5: กล่อง | CV5: =+CT5*D5 -> 19235.08 | CW5: =IFERROR(VLOOKUP(B5,'B-plus'!A:D,4,0),"0") -> 0 | CX5: กล่อง | CY5: =+CW5*D5 -> 0
A6: 1004055 | B6: 1004055 | C6: ชิฟฟ่อน รวมรส 1กล่อง4ชิ้น | D6: 16.41 | E6: =+H6+K6+N6+Q6+T6+W6+Z6+AC6+AF6+AI6+AL6+AO6+AR6+AU6+AX6+BA6+BD6+BG6+BJ6+BM6+BP6+BS6+BV6+BY6+CB6+CE6+CH6+CK6+CN6+CQ6+CT6 -> 12 | F6: กล่อง | G6: =+E6*D6 -> 196.92 | H6: =IFERROR(VLOOKUP(A6,'1'!U:V,2,0),"0") -> 0 | I6: กล่อง | J6: =+H6*D6 -> 0 | K6: =IFERROR(VLOOKUP(A6,'2'!U:V,2,0),"0") -> 0 | L6: กล่อง | M6: =+K6*D6 -> 0 | N6: =IFERROR(VLOOKUP(A6,'3'!U:V,2,0),"0") -> 0 | O6: กล่อง | P6: =+N6*D6 -> 0 | Q6: =IFERROR(VLOOKUP(A6,'4'!U:V,2,0),"0") -> 0 | R6: กล่อง | S6: =+Q6*D6 -> 0 | T6: =IFERROR(VLOOKUP(A6,'5'!U:V,2,0),"0") -> 0 | U6: กล่อง | V6: =+T6*D6 -> 0 | W6: =IFERROR(VLOOKUP(A6,'6'!U:V,2,0),"0") -> 0 | X6: กล่อง | Y6: =+W6*D6 -> 0 | Z6: =IFERROR(VLOOKUP(A6,'7'!U:V,2,0),"0") -> 0 | AA6: กล่อง | AB6: =+Z6*D6 -> 0 | AC6: =IFERROR(VLOOKUP(A6,'8'!U:V,2,0),"0") -> 0 | AD6: กล่อง | AE6: =+AC6*D6 -> 0 | AF6: =IFERROR(VLOOKUP(A6,'9'!U:V,2,0),"0") -> 0 | AG6: กล่อง | AH6: =+AF6*D6 -> 0 | AI6: =IFERROR(VLOOKUP(A6,'10'!U:V,2,0),"0") -> 12 | AJ6: กล่อง | AK6: =+AI6*D6 -> 196.92 | AL6: =IFERROR(VLOOKUP(A6,'11'!U:V,2,0),"0") -> 0 | AM6: กล่อง | AN6: =+AL6*D6 -> 0 | AO6: =IFERROR(VLOOKUP(A6,'12'!U:V,2,0),"0") -> 0 | AP6: กล่อง | AQ6: =+AO6*D6 -> 0 | AR6: =IFERROR(VLOOKUP(A6,'13'!U:V,2,0),"0") -> 0 | AS6: กล่อง | AT6: =+AR6*D6 -> 0 | AU6: =IFERROR(VLOOKUP(A6,'14'!U:V,2,0),"0") -> 0 | AV6: กล่อง | AW6: =+AU6*D6 -> 0 | AX6: =IFERROR(VLOOKUP(A6,'15'!U:V,2,0),"0") -> 0 | AY6: กล่อง | AZ6: =+AX6*D6 -> 0 | BA6: =IFERROR(VLOOKUP(A6,'16'!U:V,2,0),"0") -> 0 | BB6: กล่อง | BC6: =+BA6*D6 -> 0 | BD6: =IFERROR(VLOOKUP(A6,'17'!U:V,2,0),"0") -> 0 | BE6: กล่อง | BF6: =+BD6*D6 -> 0 | BG6: =IFERROR(VLOOKUP(A6,'18'!U:V,2,0),"0") -> 0 | BH6: กล่อง | BI6: =+BG6*D6 -> 0 | BJ6: =IFERROR(VLOOKUP(A6,'19'!U:V,2,0),"0") -> 0 | BK6: กล่อง | BL6: =+BJ6*D6 -> 0 | BM6: =IFERROR(VLOOKUP(A6,'20'!U:V,2,0),"0") -> 0 | BN6: กล่อง | BO6: =+BM6*D6 -> 0 | BP6: =IFERROR(VLOOKUP(A6,'21'!U:V,2,0),"0") -> 0 | BQ6: กล่อง | BR6: =+BP6*D6 -> 0 | BS6: =IFERROR(VLOOKUP(A6,'22'!U:V,2,0),"0") -> 0 | BT6: กล่อง | BU6: =+BS6*D6 -> 0 | BV6: =IFERROR(VLOOKUP(A6,'23'!U:V,2,0),"0") -> 0 | BW6: กล่อง | BX6: =+BV6*D6 -> 0 | BY6: =IFERROR(VLOOKUP(A6,'24'!U:V,2,0),"0") -> 0 | BZ6: กล่อง | CA6: =+BY6*D6 -> 0 | CB6: =IFERROR(VLOOKUP(A6,'25'!U:V,2,0),"0") -> 0 | CC6: กล่อง | CD6: =+CB6*D6 -> 0 | CE6: =IFERROR(VLOOKUP(A6,'26'!U:V,2,0),"0") -> 0 | CF6: กล่อง | CG6: =+CE6*D6 -> 0 | CH6: =IFERROR(VLOOKUP(A6,'27'!U:V,2,0),"0") -> 0 | CI6: กล่อง | CJ6: =+CH6*D6 -> 0 | CK6: =IFERROR(VLOOKUP(A6,'28'!U:V,2,0),"0") -> 0 | CL6: กล่อง | CM6: =+CK6*D6 -> 0 | CN6: =IFERROR(VLOOKUP(A6,'29'!U:V,2,0),"0") -> 0 | CO6: กล่อง | CP6: =+CN6*D6 -> 0 | CQ6: =IFERROR(VLOOKUP(A6,'30'!U:V,2,0),"0") -> 0 | CR6: กล่อง | CS6: =+CQ6*D6 -> 0 | CT6: =IFERROR(VLOOKUP(A6,'31'!U:V,2,0),"0") -> 0 | CU6: กล่อง | CV6: =+CT6*D6 -> 0 | CW6: =IFERROR(VLOOKUP(B6,'B-plus'!A:D,4,0),"0") -> 321 | CX6: กล่อง | CY6: =+CW6*D6 -> 5267.61
A7: 1005761 | B7: 1005761 | C7: ขนมปังกรอบคาราเมล(ถุง) | D7: 17.5 | E7: =+H7+K7+N7+Q7+T7+W7+Z7+AC7+AF7+AI7+AL7+AO7+AR7+AU7+AX7+BA7+BD7+BG7+BJ7+BM7+BP7+BS7+BV7+BY7+CB7+CE7+CH7+CK7+CN7+CQ7+CT7 -> 0 | F7: ถุง | G7: =+E7*D7 -> 0 | H7: =IFERROR(VLOOKUP(A7,'1'!U:V,2,0),"0") -> 0 | I7: ถุง | J7: =+H7*D7 -> 0 | K7: =IFERROR(VLOOKUP(A7,'2'!U:V,2,0),"0") -> 0 | L7: ถุง | M7: =+K7*D7 -> 0 | N7: =IFERROR(VLOOKUP(A7,'3'!U:V,2,0),"0") -> 0 | O7: ถุง | P7: =+N7*D7 -> 0 | Q7: =IFERROR(VLOOKUP(A7,'4'!U:V,2,0),"0") -> 0 | R7: ถุง | S7: =+Q7*D7 -> 0 | T7: =IFERROR(VLOOKUP(A7,'5'!U:V,2,0),"0") -> 0 | U7: ถุง | V7: =+T7*D7 -> 0 | W7: =IFERROR(VLOOKUP(A7,'6'!U:V,2,0),"0") -> 0 | X7: ถุง | Y7: =+W7*D7 -> 0 | Z7: =IFERROR(VLOOKUP(A7,'7'!U:V,2,0),"0") -> 0 | AA7: ถุง | AB7: =+Z7*D7 -> 0 | AC7: =IFERROR(VLOOKUP(A7,'8'!U:V,2,0),"0") -> 0 | AD7: ถุง | AE7: =+AC7*D7 -> 0 | AF7: =IFERROR(VLOOKUP(A7,'9'!U:V,2,0),"0") -> 0 | AG7: ถุง | AH7: =+AF7*D7 -> 0 | AI7: =IFERROR(VLOOKUP(A7,'10'!U:V,2,0),"0") -> 0 | AJ7: ถุง | AK7: =+AI7*D7 -> 0 | AL7: =IFERROR(VLOOKUP(A7,'11'!U:V,2,0),"0") -> 0 | AM7: ถุง | AN7: =+AL7*D7 -> 0 | AO7: =IFERROR(VLOOKUP(A7,'12'!U:V,2,0),"0") -> 0 | AP7: ถุง | AQ7: =+AO7*D7 -> 0 | AR7: =IFERROR(VLOOKUP(A7,'13'!U:V,2,0),"0") -> 0 | AS7: ถุง | AT7: =+AR7*D7 -> 0 | AU7: =IFERROR(VLOOKUP(A7,'14'!U:V,2,0),"0") -> 0 | AV7: ถุง | AW7: =+AU7*D7 -> 0 | AX7: =IFERROR(VLOOKUP(A7,'15'!U:V,2,0),"0") -> 0 | AY7: ถุง | AZ7: =+AX7*D7 -> 0 | BA7: =IFERROR(VLOOKUP(A7,'16'!U:V,2,0),"0") -> 0 | BB7: ถุง | BC7: =+BA7*D7 -> 0 | BD7: =IFERROR(VLOOKUP(A7,'17'!U:V,2,0),"0") -> 0 | BE7: ถุง | BF7: =+BD7*D7 -> 0 | BG7: =IFERROR(VLOOKUP(A7,'18'!U:V,2,0),"0") -> 0 | BH7: ถุง | BI7: =+BG7*D7 -> 0 | BJ7: =IFERROR(VLOOKUP(A7,'19'!U:V,2,0),"0") -> 0 | BK7: ถุง | BL7: =+BJ7*D7 -> 0 | BM7: =IFERROR(VLOOKUP(A7,'20'!U:V,2,0),"0") -> 0 | BN7: ถุง | BO7: =+BM7*D7 -> 0 | BP7: =IFERROR(VLOOKUP(A7,'21'!U:V,2,0),"0") -> 0 | BQ7: ถุง | BR7: =+BP7*D7 -> 0 | BS7: =IFERROR(VLOOKUP(A7,'22'!U:V,2,0),"0") -> 0 | BT7: ถุง | BU7: =+BS7*D7 -> 0 | BV7: =IFERROR(VLOOKUP(A7,'23'!U:V,2,0),"0") -> 0 | BW7: ถุง | BX7: =+BV7*D7 -> 0 | BY7: =IFERROR(VLOOKUP(A7,'24'!U:V,2,0),"0") -> 0 | BZ7: ถุง | CA7: =+BY7*D7 -> 0 | CB7: =IFERROR(VLOOKUP(A7,'25'!U:V,2,0),"0") -> 0 | CC7: ถุง | CD7: =+CB7*D7 -> 0 | CE7: =IFERROR(VLOOKUP(A7,'26'!U:V,2,0),"0") -> 0 | CF7: ถุง | CG7: =+CE7*D7 -> 0 | CH7: =IFERROR(VLOOKUP(A7,'27'!U:V,2,0),"0") -> 0 | CI7: ถุง | CJ7: =+CH7*D7 -> 0 | CK7: =IFERROR(VLOOKUP(A7,'28'!U:V,2,0),"0") -> 0 | CL7: ถุง | CM7: =+CK7*D7 -> 0 | CN7: =IFERROR(VLOOKUP(A7,'29'!U:V,2,0),"0") -> 0 | CO7: ถุง | CP7: =+CN7*D7 -> 0 | CQ7: =IFERROR(VLOOKUP(A7,'30'!U:V,2,0),"0") -> 0 | CR7: ถุง | CS7: =+CQ7*D7 -> 0 | CT7: =IFERROR(VLOOKUP(A7,'31'!U:V,2,0),"0") -> 0 | CU7: ถุง | CV7: =+CT7*D7 -> 0 | CW7: =IFERROR(VLOOKUP(B7,'B-plus'!A:D,4,0),"0") -> 0 | CX7: ถุง | CY7: =+CW7*D7 -> 0
A8: 1100001 | B8: 1100001 | C8: ทาร์ตสับปะรดแบบชิ้น อร่อยนุ่ม (1 ชิ้น) | D8: 3.24 | E8: =+H8+K8+N8+Q8+T8+W8+Z8+AC8+AF8+AI8+AL8+AO8+AR8+AU8+AX8+BA8+BD8+BG8+BJ8+BM8+BP8+BS8+BV8+BY8+CB8+CE8+CH8+CK8+CN8+CQ8+CT8 -> 0 | F8: ชิ้น | G8: =+E8*D8 -> 0 | H8: =IFERROR(VLOOKUP(A8,'1'!U:V,2,0),"0") -> 0 | I8: ชิ้น | J8: =+H8*D8 -> 0 | K8: =IFERROR(VLOOKUP(A8,'2'!U:V,2,0),"0") -> 0 | L8: ชิ้น | M8: =+K8*D8 -> 0 | N8: =IFERROR(VLOOKUP(A8,'3'!U:V,2,0),"0") -> 0 | O8: ชิ้น | P8: =+N8*D8 -> 0 | Q8: =IFERROR(VLOOKUP(A8,'4'!U:V,2,0),"0") -> 0 | R8: ชิ้น | S8: =+Q8*D8 -> 0 | T8: =IFERROR(VLOOKUP(A8,'5'!U:V,2,0),"0") -> 0 | U8: ชิ้น | V8: =+T8*D8 -> 0 | W8: =IFERROR(VLOOKUP(A8,'6'!U:V,2,0),"0") -> 0 | X8: ชิ้น | Y8: =+W8*D8 -> 0 | Z8: =IFERROR(VLOOKUP(A8,'7'!U:V,2,0),"0") -> 0 | AA8: ชิ้น | AB8: =+Z8*D8 -> 0 | AC8: =IFERROR(VLOOKUP(A8,'8'!U:V,2,0),"0") -> 0 | AD8: ชิ้น | AE8: =+AC8*D8 -> 0 | AF8: =IFERROR(VLOOKUP(A8,'9'!U:V,2,0),"0") -> 0 | AG8: ชิ้น | AH8: =+AF8*D8 -> 0 | AI8: =IFERROR(VLOOKUP(A8,'10'!U:V,2,0),"0") -> 0 | AJ8: ชิ้น | AK8: =+AI8*D8 -> 0 | AL8: =IFERROR(VLOOKUP(A8,'11'!U:V,2,0),"0") -> 0 | AM8: ชิ้น | AN8: =+AL8*D8 -> 0 | AO8: =IFERROR(VLOOKUP(A8,'12'!U:V,2,0),"0") -> 0 | AP8: ชิ้น | AQ8: =+AO8*D8 -> 0 | AR8: =IFERROR(VLOOKUP(A8,'13'!U:V,2,0),"0") -> 0 | AS8: ชิ้น | AT8: =+AR8*D8 -> 0 | AU8: =IFERROR(VLOOKUP(A8,'14'!U:V,2,0),"0") -> 0 | AV8: ชิ้น | AW8: =+AU8*D8 -> 0 | AX8: =IFERROR(VLOOKUP(A8,'15'!U:V,2,0),"0") -> 0 | AY8: ชิ้น | AZ8: =+AX8*D8 -> 0 | BA8: =IFERROR(VLOOKUP(A8,'16'!U:V,2,0),"0") -> 0 | BB8: ชิ้น | BC8: =+BA8*D8 -> 0 | BD8: =IFERROR(VLOOKUP(A8,'17'!U:V,2,0),"0") -> 0 | BE8: ชิ้น | BF8: =+BD8*D8 -> 0 | BG8: =IFERROR(VLOOKUP(A8,'18'!U:V,2,0),"0") -> 0 | BH8: ชิ้น | BI8: =+BG8*D8 -> 0 | BJ8: =IFERROR(VLOOKUP(A8,'19'!U:V,2,0),"0") -> 0 | BK8: ชิ้น | BL8: =+BJ8*D8 -> 0 | BM8: =IFERROR(VLOOKUP(A8,'20'!U:V,2,0),"0") -> 0 | BN8: ชิ้น | BO8: =+BM8*D8 -> 0 | BP8: =IFERROR(VLOOKUP(A8,'21'!U:V,2,0),"0") -> 0 | BQ8: ชิ้น | BR8: =+BP8*D8 -> 0 | BS8: =IFERROR(VLOOKUP(A8,'22'!U:V,2,0),"0") -> 0 | BT8: ชิ้น | BU8: =+BS8*D8 -> 0 | BV8: =IFERROR(VLOOKUP(A8,'23'!U:V,2,0),"0") -> 0 | BW8: ชิ้น | BX8: =+BV8*D8 -> 0 | BY8: =IFERROR(VLOOKUP(A8,'24'!U:V,2,0),"0") -> 0 | BZ8: ชิ้น | CA8: =+BY8*D8 -> 0 | CB8: =IFERROR(VLOOKUP(A8,'25'!U:V,2,0),"0") -> 0 | CC8: ชิ้น | CD8: =+CB8*D8 -> 0 | CE8: =IFERROR(VLOOKUP(A8,'26'!U:V,2,0),"0") -> 0 | CF8: ชิ้น | CG8: =+CE8*D8 -> 0 | CH8: =IFERROR(VLOOKUP(A8,'27'!U:V,2,0),"0") -> 0 | CI8: ชิ้น | CJ8: =+CH8*D8 -> 0 | CK8: =IFERROR(VLOOKUP(A8,'28'!U:V,2,0),"0") -> 0 | CL8: ชิ้น | CM8: =+CK8*D8 -> 0 | CN8: =IFERROR(VLOOKUP(A8,'29'!U:V,2,0),"0") -> 0 | CO8: ชิ้น | CP8: =+CN8*D8 -> 0 | CQ8: =IFERROR(VLOOKUP(A8,'30'!U:V,2,0),"0") -> 0 | CR8: ชิ้น | CS8: =+CQ8*D8 -> 0 | CT8: =IFERROR(VLOOKUP(A8,'31'!U:V,2,0),"0") -> 0 | CU8: ชิ้น | CV8: =+CT8*D8 -> 0 | CW8: =IFERROR(VLOOKUP(B8,'B-plus'!A:D,4,0),"0") -> 0 | CX8: ชิ้น | CY8: =+CW8*D8 -> 0
A9: 1100002 | B9: 1100002 | C9: ทาร์ตสับปะรด (ทาร์ตสับปะรดกล่อง 4 ชิ้น) | D9: 19.39 | E9: =+H9+K9+N9+Q9+T9+W9+Z9+AC9+AF9+AI9+AL9+AO9+AR9+AU9+AX9+BA9+BD9+BG9+BJ9+BM9+BP9+BS9+BV9+BY9+CB9+CE9+CH9+CK9+CN9+CQ9+CT9 -> 12 | F9: กล่อง | G9: =+E9*D9 -> 232.68 | H9: =IFERROR(VLOOKUP(A9,'1'!U:V,2,0),"0") -> 0 | I9: กล่อง | J9: =+H9*D9 -> 0 | K9: =IFERROR(VLOOKUP(A9,'2'!U:V,2,0),"0") -> 0 | L9: กล่อง | M9: =+K9*D9 -> 0 | N9: =IFERROR(VLOOKUP(A9,'3'!U:V,2,0),"0") -> 0 | O9: กล่อง | P9: =+N9*D9 -> 0 | Q9: =IFERROR(VLOOKUP(A9,'4'!U:V,2,0),"0") -> 0 | R9: กล่อง | S9: =+Q9*D9 -> 0 | T9: =IFERROR(VLOOKUP(A9,'5'!U:V,2,0),"0") -> 0 | U9: กล่อง | V9: =+T9*D9 -> 0 | W9: =IFERROR(VLOOKUP(A9,'6'!U:V,2,0),"0") -> 0 | X9: กล่อง | Y9: =+W9*D9 -> 0 | Z9: =IFERROR(VLOOKUP(A9,'7'!U:V,2,0),"0") -> 0 | AA9: กล่อง | AB9: =+Z9*D9 -> 0 | AC9: =IFERROR(VLOOKUP(A9,'8'!U:V,2,0),"0") -> 0 | AD9: กล่อง | AE9: =+AC9*D9 -> 0 | AF9: =IFERROR(VLOOKUP(A9,'9'!U:V,2,0),"0") -> 0 | AG9: กล่อง | AH9: =+AF9*D9 -> 0 | AI9: =IFERROR(VLOOKUP(A9,'10'!U:V,2,0),"0") -> 12 | AJ9: กล่อง | AK9: =+AI9*D9 -> 232.68 | AL9: =IFERROR(VLOOKUP(A9,'11'!U:V,2,0),"0") -> 0 | AM9: กล่อง | AN9: =+AL9*D9 -> 0 | AO9: =IFERROR(VLOOKUP(A9,'12'!U:V,2,0),"0") -> 0 | AP9: กล่อง | AQ9: =+AO9*D9 -> 0 | AR9: =IFERROR(VLOOKUP(A9,'13'!U:V,2,0),"0") -> 0 | AS9: กล่อง | AT9: =+AR9*D9 -> 0 | AU9: =IFERROR(VLOOKUP(A9,'14'!U:V,2,0),"0") -> 0 | AV9: กล่อง | AW9: =+AU9*D9 -> 0 | AX9: =IFERROR(VLOOKUP(A9,'15'!U:V,2,0),"0") -> 0 | AY9: กล่อง | AZ9: =+AX9*D9 -> 0 | BA9: =IFERROR(VLOOKUP(A9,'16'!U:V,2,0),"0") -> 0 | BB9: กล่อง | BC9: =+BA9*D9 -> 0 | BD9: =IFERROR(VLOOKUP(A9,'17'!U:V,2,0),"0") -> 0 | BE9: กล่อง | BF9: =+BD9*D9 -> 0 | BG9: =IFERROR(VLOOKUP(A9,'18'!U:V,2,0),"0") -> 0 | BH9: กล่อง | BI9: =+BG9*D9 -> 0 | BJ9: =IFERROR(VLOOKUP(A9,'19'!U:V,2,0),"0") -> 0 | BK9: กล่อง | BL9: =+BJ9*D9 -> 0 | BM9: =IFERROR(VLOOKUP(A9,'20'!U:V,2,0),"0") -> 0 | BN9: กล่อง | BO9: =+BM9*D9 -> 0 | BP9: =IFERROR(VLOOKUP(A9,'21'!U:V,2,0),"0") -> 0 | BQ9: กล่อง | BR9: =+BP9*D9 -> 0 | BS9: =IFERROR(VLOOKUP(A9,'22'!U:V,2,0),"0") -> 0 | BT9: กล่อง | BU9: =+BS9*D9 -> 0 | BV9: =IFERROR(VLOOKUP(A9,'23'!U:V,2,0),"0") -> 0 | BW9: กล่อง | BX9: =+BV9*D9 -> 0 | BY9: =IFERROR(VLOOKUP(A9,'24'!U:V,2,0),"0") -> 0 | BZ9: กล่อง | CA9: =+BY9*D9 -> 0 | CB9: =IFERROR(VLOOKUP(A9,'25'!U:V,2,0),"0") -> 0 | CC9: กล่อง | CD9: =+CB9*D9 -> 0 | CE9: =IFERROR(VLOOKUP(A9,'26'!U:V,2,0),"0") -> 0 | CF9: กล่อง | CG9: =+CE9*D9 -> 0 | CH9: =IFERROR(VLOOKUP(A9,'27'!U:V,2,0),"0") -> 0 | CI9: กล่อง | CJ9: =+CH9*D9 -> 0 | CK9: =IFERROR(VLOOKUP(A9,'28'!U:V,2,0),"0") -> 0 | CL9: กล่อง | CM9: =+CK9*D9 -> 0 | CN9: =IFERROR(VLOOKUP(A9,'29'!U:V,2,0),"0") -> 0 | CO9: กล่อง | CP9: =+CN9*D9 -> 0 | CQ9: =IFERROR(VLOOKUP(A9,'30'!U:V,2,0),"0") -> 0 | CR9: กล่อง | CS9: =+CQ9*D9 -> 0 | CT9: =IFERROR(VLOOKUP(A9,'31'!U:V,2,0),"0") -> 0 | CU9: กล่อง | CV9: =+CT9*D9 -> 0 | CW9: =IFERROR(VLOOKUP(B9,'B-plus'!A:D,4,0),"0") -> 0 | CX9: กล่อง | CY9: =+CW9*D9 -> 0
A10: 1100003 | B10: 1100003 | C10: เมอแรงก์กระปุก (เก็บไว้ได้ 60 วัน) | D10: 11.17 | E10: =+H10+K10+N10+Q10+T10+W10+Z10+AC10+AF10+AI10+AL10+AO10+AR10+AU10+AX10+BA10+BD10+BG10+BJ10+BM10+BP10+BS10+BV10+BY10+CB10+CE10+CH10+CK10+CN10+CQ10+CT10 -> 0 | F10: กระปุก | G10: =+E10*D10 -> 0 | H10: =IFERROR(VLOOKUP(A10,'1'!U:V,2,0),"0") -> 0 | I10: กระปุก | J10: =+H10*D10 -> 0 | K10: =IFERROR(VLOOKUP(A10,'2'!U:V,2,0),"0") -> 0 | L10: กระปุก | M10: =+K10*D10 -> 0 | N10: =IFERROR(VLOOKUP(A10,'3'!U:V,2,0),"0") -> 0 | O10: กระปุก | P10: =+N10*D10 -> 0 | Q10: =IFERROR(VLOOKUP(A10,'4'!U:V,2,0),"0") -> 0 | R10: กระปุก | S10: =+Q10*D10 -> 0 | T10: =IFERROR(VLOOKUP(A10,'5'!U:V,2,0),"0") -> 0 | U10: กระปุก | V10: =+T10*D10 -> 0 | W10: =IFERROR(VLOOKUP(A10,'6'!U:V,2,0),"0") -> 0 | X10: กระปุก | Y10: =+W10*D10 -> 0 | Z10: =IFERROR(VLOOKUP(A10,'7'!U:V,2,0),"0") -> 0 | AA10: กระปุก | AB10: =+Z10*D10 -> 0 | AC10: =IFERROR(VLOOKUP(A10,'8'!U:V,2,0),"0") -> 0 | AD10: กระปุก | AE10: =+AC10*D10 -> 0 | AF10: =IFERROR(VLOOKUP(A10,'9'!U:V,2,0),"0") -> 0 | AG10: กระปุก | AH10: =+AF10*D10 -> 0 | AI10: =IFERROR(VLOOKUP(A10,'10'!U:V,2,0),"0") -> 0 | AJ10: กระปุก | AK10: =+AI10*D10 -> 0 | AL10: =IFERROR(VLOOKUP(A10,'11'!U:V,2,0),"0") -> 0 | AM10: กระปุก | AN10: =+AL10*D10 -> 0 | AO10: =IFERROR(VLOOKUP(A10,'12'!U:V,2,0),"0") -> 0 | AP10: กระปุก | AQ10: =+AO10*D10 -> 0 | AR10: =IFERROR(VLOOKUP(A10,'13'!U:V,2,0),"0") -> 0 | AS10: กระปุก | AT10: =+AR10*D10 -> 0 | AU10: =IFERROR(VLOOKUP(A10,'14'!U:V,2,0),"0") -> 0 | AV10: กระปุก | AW10: =+AU10*D10 -> 0 | AX10: =IFERROR(VLOOKUP(A10,'15'!U:V,2,0),"0") -> 0 | AY10: กระปุก | AZ10: =+AX10*D10 -> 0 | BA10: =IFERROR(VLOOKUP(A10,'16'!U:V,2,0),"0") -> 0 | BB10: กระปุก | BC10: =+BA10*D10 -> 0 | BD10: =IFERROR(VLOOKUP(A10,'17'!U:V,2,0),"0") -> 0 | BE10: กระปุก | BF10: =+BD10*D10 -> 0 | BG10: =IFERROR(VLOOKUP(A10,'18'!U:V,2,0),"0") -> 0 | BH10: กระปุก | BI10: =+BG10*D10 -> 0 | BJ10: =IFERROR(VLOOKUP(A10,'19'!U:V,2,0),"0") -> 0 | BK10: กระปุก | BL10: =+BJ10*D10 -> 0 | BM10: =IFERROR(VLOOKUP(A10,'20'!U:V,2,0),"0") -> 0 | BN10: กระปุก | BO10: =+BM10*D10 -> 0 | BP10: =IFERROR(VLOOKUP(A10,'21'!U:V,2,0),"0") -> 0 | BQ10: กระปุก | BR10: =+BP10*D10 -> 0 | BS10: =IFERROR(VLOOKUP(A10,'22'!U:V,2,0),"0") -> 0 | BT10: กระปุก | BU10: =+BS10*D10 -> 0 | BV10: =IFERROR(VLOOKUP(A10,'23'!U:V,2,0),"0") -> 0 | BW10: กระปุก | BX10: =+BV10*D10 -> 0 | BY10: =IFERROR(VLOOKUP(A10,'24'!U:V,2,0),"0") -> 0 | BZ10: กระปุก | CA10: =+BY10*D10 -> 0 | CB10: =IFERROR(VLOOKUP(A10,'25'!U:V,2,0),"0") -> 0 | CC10: กระปุก | CD10: =+CB10*D10 -> 0 | CE10: =IFERROR(VLOOKUP(A10,'26'!U:V,2,0),"0") -> 0 | CF10: กระปุก | CG10: =+CE10*D10 -> 0 | CH10: =IFERROR(VLOOKUP(A10,'27'!U:V,2,0),"0") -> 0 | CI10: กระปุก | CJ10: =+CH10*D10 -> 0 | CK10: =IFERROR(VLOOKUP(A10,'28'!U:V,2,0),"0") -> 0 | CL10: กระปุก | CM10: =+CK10*D10 -> 0 | CN10: =IFERROR(VLOOKUP(A10,'29'!U:V,2,0),"0") -> 0 | CO10: กระปุก | CP10: =+CN10*D10 -> 0 | CQ10: =IFERROR(VLOOKUP(A10,'30'!U:V,2,0),"0") -> 0 | CR10: กระปุก | CS10: =+CQ10*D10 -> 0 | CT10: =IFERROR(VLOOKUP(A10,'31'!U:V,2,0),"0") -> 0 | CU10: กระปุก | CV10: =+CT10*D10 -> 0 | CW10: =IFERROR(VLOOKUP(B10,'B-plus'!A:D,4,0),"0") -> 0 | CX10: กระปุก | CY10: =+CW10*D10 -> 0
A11: 1100004 | B11: 1100004 | C11: เมอแรงค์ อัลม่อนเม็ดมะม่วงหิมพานต์ (ถุง) | D11: 13.03 | E11: =+H11+K11+N11+Q11+T11+W11+Z11+AC11+AF11+AI11+AL11+AO11+AR11+AU11+AX11+BA11+BD11+BG11+BJ11+BM11+BP11+BS11+BV11+BY11+CB11+CE11+CH11+CK11+CN11+CQ11+CT11 -> 0 | F11: ถุง | G11: =+E11*D11 -> 0 | H11: =IFERROR(VLOOKUP(A11,'1'!U:V,2,0),"0") -> 0 | I11: ถุง | J11: =+H11*D11 -> 0 | K11: =IFERROR(VLOOKUP(A11,'2'!U:V,2,0),"0") -> 0 | L11: ถุง | M11: =+K11*D11 -> 0 | N11: =IFERROR(VLOOKUP(A11,'3'!U:V,2,0),"0") -> 0 | O11: ถุง | P11: =+N11*D11 -> 0 | Q11: =IFERROR(VLOOKUP(A11,'4'!U:V,2,0),"0") -> 0 | R11: ถุง | S11: =+Q11*D11 -> 0 | T11: =IFERROR(VLOOKUP(A11,'5'!U:V,2,0),"0") -> 0 | U11: ถุง | V11: =+T11*D11 -> 0 | W11: =IFERROR(VLOOKUP(A11,'6'!U:V,2,0),"0") -> 0 | X11: ถุง | Y11: =+W11*D11 -> 0 | Z11: =IFERROR(VLOOKUP(A11,'7'!U:V,2,0),"0") -> 0 | AA11: ถุง | AB11: =+Z11*D11 -> 0 | AC11: =IFERROR(VLOOKUP(A11,'8'!U:V,2,0),"0") -> 0 | AD11: ถุง | AE11: =+AC11*D11 -> 0 | AF11: =IFERROR(VLOOKUP(A11,'9'!U:V,2,0),"0") -> 0 | AG11: ถุง | AH11: =+AF11*D11 -> 0 | AI11: =IFERROR(VLOOKUP(A11,'10'!U:V,2,0),"0") -> 0 | AJ11: ถุง | AK11: =+AI11*D11 -> 0 | AL11: =IFERROR(VLOOKUP(A11,'11'!U:V,2,0),"0") -> 0 | AM11: ถุง | AN11: =+AL11*D11 -> 0 | AO11: =IFERROR(VLOOKUP(A11,'12'!U:V,2,0),"0") -> 0 | AP11: ถุง | AQ11: =+AO11*D11 -> 0 | AR11: =IFERROR(VLOOKUP(A11,'13'!U:V,2,0),"0") -> 0 | AS11: ถุง | AT11: =+AR11*D11 -> 0 | AU11: =IFERROR(VLOOKUP(A11,'14'!U:V,2,0),"0") -> 0 | AV11: ถุง | AW11: =+AU11*D11 -> 0 | AX11: =IFERROR(VLOOKUP(A11,'15'!U:V,2,0),"0") -> 0 | AY11: ถุง | AZ11: =+AX11*D11 -> 0 | BA11: =IFERROR(VLOOKUP(A11,'16'!U:V,2,0),"0") -> 0 | BB11: ถุง | BC11: =+BA11*D11 -> 0 | BD11: =IFERROR(VLOOKUP(A11,'17'!U:V,2,0),"0") -> 0 | BE11: ถุง | BF11: =+BD11*D11 -> 0 | BG11: =IFERROR(VLOOKUP(A11,'18'!U:V,2,0),"0") -> 0 | BH11: ถุง | BI11: =+BG11*D11 -> 0 | BJ11: =IFERROR(VLOOKUP(A11,'19'!U:V,2,0),"0") -> 0 | BK11: ถุง | BL11: =+BJ11*D11 -> 0 | BM11: =IFERROR(VLOOKUP(A11,'20'!U:V,2,0),"0") -> 0 | BN11: ถุง | BO11: =+BM11*D11 -> 0 | BP11: =IFERROR(VLOOKUP(A11,'21'!U:V,2,0),"0") -> 0 | BQ11: ถุง | BR11: =+BP11*D11 -> 0 | BS11: =IFERROR(VLOOKUP(A11,'22'!U:V,2,0),"0") -> 0 | BT11: ถุง | BU11: =+BS11*D11 -> 0 | BV11: =IFERROR(VLOOKUP(A11,'23'!U:V,2,0),"0") -> 0 | BW11: ถุง | BX11: =+BV11*D11 -> 0 | BY11: =IFERROR(VLOOKUP(A11,'24'!U:V,2,0),"0") -> 0 | BZ11: ถุง | CA11: =+BY11*D11 -> 0 | CB11: =IFERROR(VLOOKUP(A11,'25'!U:V,2,0),"0") -> 0 | CC11: ถุง | CD11: =+CB11*D11 -> 0 | CE11: =IFERROR(VLOOKUP(A11,'26'!U:V,2,0),"0") -> 0 | CF11: ถุง | CG11: =+CE11*D11 -> 0 | CH11: =IFERROR(VLOOKUP(A11,'27'!U:V,2,0),"0") -> 0 | CI11: ถุง | CJ11: =+CH11*D11 -> 0 | CK11: =IFERROR(VLOOKUP(A11,'28'!U:V,2,0),"0") -> 0 | CL11: ถุง | CM11: =+CK11*D11 -> 0 | CN11: =IFERROR(VLOOKUP(A11,'29'!U:V,2,0),"0") -> 0 | CO11: ถุง | CP11: =+CN11*D11 -> 0 | CQ11: =IFERROR(VLOOKUP(A11,'30'!U:V,2,0),"0") -> 0 | CR11: ถุง | CS11: =+CQ11*D11 -> 0 | CT11: =IFERROR(VLOOKUP(A11,'31'!U:V,2,0),"0") -> 0 | CU11: ถุง | CV11: =+CT11*D11 -> 0 | CW11: =IFERROR(VLOOKUP(B11,'B-plus'!A:D,4,0),"0") -> 0 | CX11: ถุง | CY11: =+CW11*D11 -> 0
A12: 1111001 | B12: 1111001 | C12: ชิฟฟอนไม่มีไส้เเบบเเยกชิ้น เลือกรสชาติได้ (คละรส) | D12: 4.1 | E12: =+H12+K12+N12+Q12+T12+W12+Z12+AC12+AF12+AI12+AL12+AO12+AR12+AU12+AX12+BA12+BD12+BG12+BJ12+BM12+BP12+BS12+BV12+BY12+CB12+CE12+CH12+CK12+CN12+CQ12+CT12 -> 1051 | F12: ชิ้น | G12: =+E12*D12 -> 4309.1 | H12: =IFERROR(VLOOKUP(A12,'1'!U:V,2,0),"0") -> 40 | I12: ชิ้น | J12: =+H12*D12 -> 164 | K12: =IFERROR(VLOOKUP(A12,'2'!U:V,2,0),"0") -> 30 | L12: ชิ้น | M12: =+K12*D12 -> 123 | N12: =IFERROR(VLOOKUP(A12,'3'!U:V,2,0),"0") -> 0 | O12: ชิ้น | P12: =+N12*D12 -> 0 | Q12: =IFERROR(VLOOKUP(A12,'4'!U:V,2,0),"0") -> 0 | R12: ชิ้น | S12: =+Q12*D12 -> 0 | T12: =IFERROR(VLOOKUP(A12,'5'!U:V,2,0),"0") -> 70 | U12: ชิ้น | V12: =+T12*D12 -> 287 | W12: =IFERROR(VLOOKUP(A12,'6'!U:V,2,0),"0") -> 0 | X12: ชิ้น | Y12: =+W12*D12 -> 0 | Z12: =IFERROR(VLOOKUP(A12,'7'!U:V,2,0),"0") -> 0 | AA12: ชิ้น | AB12: =+Z12*D12 -> 0 | AC12: =IFERROR(VLOOKUP(A12,'8'!U:V,2,0),"0") -> 60 | AD12: ชิ้น | AE12: =+AC12*D12 -> 246 | AF12: =IFERROR(VLOOKUP(A12,'9'!U:V,2,0),"0") -> 130 | AG12: ชิ้น | AH12: =+AF12*D12 -> 533 | AI12: =IFERROR(VLOOKUP(A12,'10'!U:V,2,0),"0") -> 80 | AJ12: ชิ้น | AK12: =+AI12*D12 -> 328 | AL12: =IFERROR(VLOOKUP(A12,'11'!U:V,2,0),"0") -> 30 | AM12: ชิ้น | AN12: =+AL12*D12 -> 123 | AO12: =IFERROR(VLOOKUP(A12,'12'!U:V,2,0),"0") -> 0 | AP12: ชิ้น | AQ12: =+AO12*D12 -> 0 | AR12: =IFERROR(VLOOKUP(A12,'13'!U:V,2,0),"0") -> 140 | AS12: ชิ้น | AT12: =+AR12*D12 -> 574 | AU12: =IFERROR(VLOOKUP(A12,'14'!U:V,2,0),"0") -> 0 | AV12: ชิ้น | AW12: =+AU12*D12 -> 0 | AX12: =IFERROR(VLOOKUP(A12,'15'!U:V,2,0),"0") -> 0 | AY12: ชิ้น | AZ12: =+AX12*D12 -> 0 | BA12: =IFERROR(VLOOKUP(A12,'16'!U:V,2,0),"0") -> 0 | BB12: ชิ้น | BC12: =+BA12*D12 -> 0 | BD12: =IFERROR(VLOOKUP(A12,'17'!U:V,2,0),"0") -> 0 | BE12: ชิ้น | BF12: =+BD12*D12 -> 0 | BG12: =IFERROR(VLOOKUP(A12,'18'!U:V,2,0),"0") -> 0 | BH12: ชิ้น | BI12: =+BG12*D12 -> 0 | BJ12: =IFERROR(VLOOKUP(A12,'19'!U:V,2,0),"0") -> 0 | BK12: ชิ้น | BL12: =+BJ12*D12 -> 0 | BM12: =IFERROR(VLOOKUP(A12,'20'!U:V,2,0),"0") -> 0 | BN12: ชิ้น | BO12: =+BM12*D12 -> 0 | BP12: =IFERROR(VLOOKUP(A12,'21'!U:V,2,0),"0") -> 0 | BQ12: ชิ้น | BR12: =+BP12*D12 -> 0 | BS12: =IFERROR(VLOOKUP(A12,'22'!U:V,2,0),"0") -> 20 | BT12: ชิ้น | BU12: =+BS12*D12 -> 82 | BV12: =IFERROR(VLOOKUP(A12,'23'!U:V,2,0),"0") -> 10 | BW12: ชิ้น | BX12: =+BV12*D12 -> 41 | BY12: =IFERROR(VLOOKUP(A12,'24'!U:V,2,0),"0") -> 30 | BZ12: ชิ้น | CA12: =+BY12*D12 -> 123 | CB12: =IFERROR(VLOOKUP(A12,'25'!U:V,2,0),"0") -> 160 | CC12: ชิ้น | CD12: =+CB12*D12 -> 656 | CE12: =IFERROR(VLOOKUP(A12,'26'!U:V,2,0),"0") -> 0 | CF12: ชิ้น | CG12: =+CE12*D12 -> 0 | CH12: =IFERROR(VLOOKUP(A12,'27'!U:V,2,0),"0") -> 21 | CI12: ชิ้น | CJ12: =+CH12*D12 -> 86.1 | CK12: =IFERROR(VLOOKUP(A12,'28'!U:V,2,0),"0") -> 140 | CL12: ชิ้น | CM12: =+CK12*D12 -> 574 | CN12: =IFERROR(VLOOKUP(A12,'29'!U:V,2,0),"0") -> 20 | CO12: ชิ้น | CP12: =+CN12*D12 -> 82 | CQ12: =IFERROR(VLOOKUP(A12,'30'!U:V,2,0),"0") -> 50 | CR12: ชิ้น | CS12: =+CQ12*D12 -> 205 | CT12: =IFERROR(VLOOKUP(A12,'31'!U:V,2,0),"0") -> 20 | CU12: ชิ้น | CV12: =+CT12*D12 -> 82 | CW12: =IFERROR(VLOOKUP(B12,'B-plus'!A:D,4,0),"0") -> 0 | CX12: ชิ้น | CY12: =+CW12*D12 -> 0
A13: 1111002 | B13: 1111002 | C13: ชิฟฟ่อนไม่มีไส้ แบบกล่อง8ชิ้น รวมรส | D13: 37.17 | E13: =+H13+K13+N13+Q13+T13+W13+Z13+AC13+AF13+AI13+AL13+AO13+AR13+AU13+AX13+BA13+BD13+BG13+BJ13+BM13+BP13+BS13+BV13+BY13+CB13+CE13+CH13+CK13+CN13+CQ13+CT13 -> 2696 | F13: กล่อง | G13: =+E13*D13 -> 100210.32 | H13: =IFERROR(VLOOKUP(A13,'1'!U:V,2,0),"0") -> 115 | I13: กล่อง | J13: =+H13*D13 -> 4274.55 | K13: =IFERROR(VLOOKUP(A13,'2'!U:V,2,0),"0") -> 125 | L13: กล่อง | M13: =+K13*D13 -> 4646.25 | N13: =IFERROR(VLOOKUP(A13,'3'!U:V,2,0),"0") -> 189 | O13: กล่อง | P13: =+N13*D13 -> 7025.13 | Q13: =IFERROR(VLOOKUP(A13,'4'!U:V,2,0),"0") -> 63 | R13: กล่อง | S13: =+Q13*D13 -> 2341.71 | T13: =IFERROR(VLOOKUP(A13,'5'!U:V,2,0),"0") -> 141 | U13: กล่อง | V13: =+T13*D13 -> 5240.97 | W13: =IFERROR(VLOOKUP(A13,'6'!U:V,2,0),"0") -> 73 | X13: กล่อง | Y13: =+W13*D13 -> 2713.41 | Z13: =IFERROR(VLOOKUP(A13,'7'!U:V,2,0),"0") -> 35 | AA13: กล่อง | AB13: =+Z13*D13 -> 1300.95 | AC13: =IFERROR(VLOOKUP(A13,'8'!U:V,2,0),"0") -> 41 | AD13: กล่อง | AE13: =+AC13*D13 -> 1523.97 | AF13: =IFERROR(VLOOKUP(A13,'9'!U:V,2,0),"0") -> 127 | AG13: กล่อง | AH13: =+AF13*D13 -> 4720.59 | AI13: =IFERROR(VLOOKUP(A13,'10'!U:V,2,0),"0") -> 86 | AJ13: กล่อง | AK13: =+AI13*D13 -> 3196.62 | AL13: =IFERROR(VLOOKUP(A13,'11'!U:V,2,0),"0") -> 73 | AM13: กล่อง | AN13: =+AL13*D13 -> 2713.41 | AO13: =IFERROR(VLOOKUP(A13,'12'!U:V,2,0),"0") -> 103 | AP13: กล่อง | AQ13: =+AO13*D13 -> 3828.51 | AR13: =IFERROR(VLOOKUP(A13,'13'!U:V,2,0),"0") -> 80 | AS13: กล่อง | AT13: =+AR13*D13 -> 2973.6 | AU13: =IFERROR(VLOOKUP(A13,'14'!U:V,2,0),"0") -> 154 | AV13: กล่อง | AW13: =+AU13*D13 -> 5724.18 | AX13: =IFERROR(VLOOKUP(A13,'15'!U:V,2,0),"0") -> 66 | AY13: กล่อง | AZ13: =+AX13*D13 -> 2453.22 | BA13: =IFERROR(VLOOKUP(A13,'16'!U:V,2,0),"0") -> 65 | BB13: กล่อง | BC13: =+BA13*D13 -> 2416.05 | BD13: =IFERROR(VLOOKUP(A13,'17'!U:V,2,0),"0") -> 104 | BE13: กล่อง | BF13: =+BD13*D13 -> 3865.68 | BG13: =IFERROR(VLOOKUP(A13,'18'!U:V,2,0),"0") -> 97 | BH13: กล่อง | BI13: =+BG13*D13 -> 3605.49 | BJ13: =IFERROR(VLOOKUP(A13,'19'!U:V,2,0),"0") -> 61 | BK13: กล่อง | BL13: =+BJ13*D13 -> 2267.37 | BM13: =IFERROR(VLOOKUP(A13,'20'!U:V,2,0),"0") -> 89 | BN13: กล่อง | BO13: =+BM13*D13 -> 3308.13 | BP13: =IFERROR(VLOOKUP(A13,'21'!U:V,2,0),"0") -> 55 | BQ13: กล่อง | BR13: =+BP13*D13 -> 2044.35 | BS13: =IFERROR(VLOOKUP(A13,'22'!U:V,2,0),"0") -> 38 | BT13: กล่อง | BU13: =+BS13*D13 -> 1412.46 | BV13: =IFERROR(VLOOKUP(A13,'23'!U:V,2,0),"0") -> 45 | BW13: กล่อง | BX13: =+BV13*D13 -> 1672.65 | BY13: =IFERROR(VLOOKUP(A13,'24'!U:V,2,0),"0") -> 148 | BZ13: กล่อง | CA13: =+BY13*D13 -> 5501.16 | CB13: =IFERROR(VLOOKUP(A13,'25'!U:V,2,0),"0") -> 134 | CC13: กล่อง | CD13: =+CB13*D13 -> 4980.78 | CE13: =IFERROR(VLOOKUP(A13,'26'!U:V,2,0),"0") -> 99 | CF13: กล่อง | CG13: =+CE13*D13 -> 3679.83 | CH13: =IFERROR(VLOOKUP(A13,'27'!U:V,2,0),"0") -> 103 | CI13: กล่อง | CJ13: =+CH13*D13 -> 3828.51 | CK13: =IFERROR(VLOOKUP(A13,'28'!U:V,2,0),"0") -> 41 | CL13: กล่อง | CM13: =+CK13*D13 -> 1523.97 | CN13: =IFERROR(VLOOKUP(A13,'29'!U:V,2,0),"0") -> 35 | CO13: กล่อง | CP13: =+CN13*D13 -> 1300.95 | CQ13: =IFERROR(VLOOKUP(A13,'30'!U:V,2,0),"0") -> 77 | CR13: กล่อง | CS13: =+CQ13*D13 -> 2862.09 | CT13: =IFERROR(VLOOKUP(A13,'31'!U:V,2,0),"0") -> 34 | CU13: กล่อง | CV13: =+CT13*D13 -> 1263.78 | CW13: =IFERROR(VLOOKUP(B13,'B-plus'!A:D,4,0),"0") -> 110 | CX13: กล่อง | CY13: =+CW13*D13 -> 4088.7
A14: 1111002-A | B14: 1111002-A | C14: ชิฟฟ่อนไม่มีไส้ แบบกล่อง8ชิ้น รวมรส (รวมรส) | D14: 37.17 | E14: =+H14+K14+N14+Q14+T14+W14+Z14+AC14+AF14+AI14+AL14+AO14+AR14+AU14+AX14+BA14+BD14+BG14+BJ14+BM14+BP14+BS14+BV14+BY14+CB14+CE14+CH14+CK14+CN14+CQ14+CT14 -> 0 | F14: กล่อง | G14: =+E14*D14 -> 0 | H14: =IFERROR(VLOOKUP(A14,'1'!U:V,2,0),"0") -> 0 | I14: กล่อง | J14: =+H14*D14 -> 0 | K14: =IFERROR(VLOOKUP(A14,'2'!U:V,2,0),"0") -> 0 | L14: กล่อง | M14: =+K14*D14 -> 0 | N14: =IFERROR(VLOOKUP(A14,'3'!U:V,2,0),"0") -> 0 | O14: กล่อง | P14: =+N14*D14 -> 0 | Q14: =IFERROR(VLOOKUP(A14,'4'!U:V,2,0),"0") -> 0 | R14: กล่อง | S14: =+Q14*D14 -> 0 | T14: =IFERROR(VLOOKUP(A14,'5'!U:V,2,0),"0") -> 0 | U14: กล่อง | V14: =+T14*D14 -> 0 | W14: =IFERROR(VLOOKUP(A14,'6'!U:V,2,0),"0") -> 0 | X14: กล่อง | Y14: =+W14*D14 -> 0 | Z14: =IFERROR(VLOOKUP(A14,'7'!U:V,2,0),"0") -> 0 | AA14: กล่อง | AB14: =+Z14*D14 -> 0 | AC14: =IFERROR(VLOOKUP(A14,'8'!U:V,2,0),"0") -> 0 | AD14: กล่อง | AE14: =+AC14*D14 -> 0 | AF14: =IFERROR(VLOOKUP(A14,'9'!U:V,2,0),"0") -> 0 | AG14: กล่อง | AH14: =+AF14*D14 -> 0 | AI14: =IFERROR(VLOOKUP(A14,'10'!U:V,2,0),"0") -> 0 | AJ14: กล่อง | AK14: =+AI14*D14 -> 0 | AL14: =IFERROR(VLOOKUP(A14,'11'!U:V,2,0),"0") -> 0 | AM14: กล่อง | AN14: =+AL14*D14 -> 0 | AO14: =IFERROR(VLOOKUP(A14,'12'!U:V,2,0),"0") -> 0 | AP14: กล่อง | AQ14: =+AO14*D14 -> 0 | AR14: =IFERROR(VLOOKUP(A14,'13'!U:V,2,0),"0") -> 0 | AS14: กล่อง | AT14: =+AR14*D14 -> 0 | AU14: =IFERROR(VLOOKUP(A14,'14'!U:V,2,0),"0") -> 0 | AV14: กล่อง | AW14: =+AU14*D14 -> 0 | AX14: =IFERROR(VLOOKUP(A14,'15'!U:V,2,0),"0") -> 0 | AY14: กล่อง | AZ14: =+AX14*D14 -> 0 | BA14: =IFERROR(VLOOKUP(A14,'16'!U:V,2,0),"0") -> 0 | BB14: กล่อง | BC14: =+BA14*D14 -> 0 | BD14: =IFERROR(VLOOKUP(A14,'17'!U:V,2,0),"0") -> 0 | BE14: กล่อง | BF14: =+BD14*D14 -> 0 | BG14: =IFERROR(VLOOKUP(A14,'18'!U:V,2,0),"0") -> 0 | BH14: กล่อง | BI14: =+BG14*D14 -> 0 | BJ14: =IFERROR(VLOOKUP(A14,'19'!U:V,2,0),"0") -> 0 | BK14: กล่อง | BL14: =+BJ14*D14 -> 0 | BM14: =IFERROR(VLOOKUP(A14,'20'!U:V,2,0),"0") -> 0 | BN14: กล่อง | BO14: =+BM14*D14 -> 0 | BP14: =IFERROR(VLOOKUP(A14,'21'!U:V,2,0),"0") -> 0 | BQ14: กล่อง | BR14: =+BP14*D14 -> 0 | BS14: =IFERROR(VLOOKUP(A14,'22'!U:V,2,0),"0") -> 0 | BT14: กล่อง | BU14: =+BS14*D14 -> 0 | BV14: =IFERROR(VLOOKUP(A14,'23'!U:V,2,0),"0") -> 0 | BW14: กล่อง | BX14: =+BV14*D14 -> 0 | BY14: =IFERROR(VLOOKUP(A14,'24'!U:V,2,0),"0") -> 0 | BZ14: กล่อง | CA14: =+BY14*D14 -> 0 | CB14: =IFERROR(VLOOKUP(A14,'25'!U:V,2,0),"0") -> 0 | CC14: กล่อง | CD14: =+CB14*D14 -> 0 | CE14: =IFERROR(VLOOKUP(A14,'26'!U:V,2,0),"0") -> 0 | CF14: กล่อง | CG14: =+CE14*D14 -> 0 | CH14: =IFERROR(VLOOKUP(A14,'27'!U:V,2,0),"0") -> 0 | CI14: กล่อง | CJ14: =+CH14*D14 -> 0 | CK14: =IFERROR(VLOOKUP(A14,'28'!U:V,2,0),"0") -> 0 | CL14: กล่อง | CM14: =+CK14*D14 -> 0 | CN14: =IFERROR(VLOOKUP(A14,'29'!U:V,2,0),"0") -> 0 | CO14: กล่อง | CP14: =+CN14*D14 -> 0 | CQ14: =IFERROR(VLOOKUP(A14,'30'!U:V,2,0),"0") -> 0 | CR14: กล่อง | CS14: =+CQ14*D14 -> 0 | CT14: =IFERROR(VLOOKUP(A14,'31'!U:V,2,0),"0") -> 0 | CU14: กล่อง | CV14: =+CT14*D14 -> 0 | CW14: =IFERROR(VLOOKUP(B14,'B-plus'!A:D,4,0),"0") -> 0 | CX14: กล่อง | CY14: =+CW14*D14 -> 0
A15: 1111002-M | B15: 1111002-M | C15: ชิฟฟ่อนรวมรส แบบไม่มีไส้ 1 กล่องมี 8 ชิ้น เก็บได้ 20 วัน คละรสชาติให้ นุ่ม หอม อร่อย วรรณวนัช | D15: 37.17 | E15: =+H15+K15+N15+Q15+T15+W15+Z15+AC15+AF15+AI15+AL15+AO15+AR15+AU15+AX15+BA15+BD15+BG15+BJ15+BM15+BP15+BS15+BV15+BY15+CB15+CE15+CH15+CK15+CN15+CQ15+CT15 -> 0 | F15: กล่อง | G15: =+E15*D15 -> 0 | H15: =IFERROR(VLOOKUP(A15,'1'!U:V,2,0),"0") -> 0 | I15: กล่อง | J15: =+H15*D15 -> 0 | K15: =IFERROR(VLOOKUP(A15,'2'!U:V,2,0),"0") -> 0 | L15: กล่อง | M15: =+K15*D15 -> 0 | N15: =IFERROR(VLOOKUP(A15,'3'!U:V,2,0),"0") -> 0 | O15: กล่อง | P15: =+N15*D15 -> 0 | Q15: =IFERROR(VLOOKUP(A15,'4'!U:V,2,0),"0") -> 0 | R15: กล่อง | S15: =+Q15*D15 -> 0 | T15: =IFERROR(VLOOKUP(A15,'5'!U:V,2,0),"0") -> 0 | U15: กล่อง | V15: =+T15*D15 -> 0 | W15: =IFERROR(VLOOKUP(A15,'6'!U:V,2,0),"0") -> 0 | X15: กล่อง | Y15: =+W15*D15 -> 0 | Z15: =IFERROR(VLOOKUP(A15,'7'!U:V,2,0),"0") -> 0 | AA15: กล่อง | AB15: =+Z15*D15 -> 0 | AC15: =IFERROR(VLOOKUP(A15,'8'!U:V,2,0),"0") -> 0 | AD15: กล่อง | AE15: =+AC15*D15 -> 0 | AF15: =IFERROR(VLOOKUP(A15,'9'!U:V,2,0),"0") -> 0 | AG15: กล่อง | AH15: =+AF15*D15 -> 0 | AI15: =IFERROR(VLOOKUP(A15,'10'!U:V,2,0),"0") -> 0 | AJ15: กล่อง | AK15: =+AI15*D15 -> 0 | AL15: =IFERROR(VLOOKUP(A15,'11'!U:V,2,0),"0") -> 0 | AM15: กล่อง | AN15: =+AL15*D15 -> 0 | AO15: =IFERROR(VLOOKUP(A15,'12'!U:V,2,0),"0") -> 0 | AP15: กล่อง | AQ15: =+AO15*D15 -> 0 | AR15: =IFERROR(VLOOKUP(A15,'13'!U:V,2,0),"0") -> 0 | AS15: กล่อง | AT15: =+AR15*D15 -> 0 | AU15: =IFERROR(VLOOKUP(A15,'14'!U:V,2,0),"0") -> 0 | AV15: กล่อง | AW15: =+AU15*D15 -> 0 | AX15: =IFERROR(VLOOKUP(A15,'15'!U:V,2,0),"0") -> 0 | AY15: กล่อง | AZ15: =+AX15*D15 -> 0 | BA15: =IFERROR(VLOOKUP(A15,'16'!U:V,2,0),"0") -> 0 | BB15: กล่อง | BC15: =+BA15*D15 -> 0 | BD15: =IFERROR(VLOOKUP(A15,'17'!U:V,2,0),"0") -> 0 | BE15: กล่อง | BF15: =+BD15*D15 -> 0 | BG15: =IFERROR(VLOOKUP(A15,'18'!U:V,2,0),"0") -> 0 | BH15: กล่อง | BI15: =+BG15*D15 -> 0 | BJ15: =IFERROR(VLOOKUP(A15,'19'!U:V,2,0),"0") -> 0 | BK15: กล่อง | BL15: =+BJ15*D15 -> 0 | BM15: =IFERROR(VLOOKUP(A15,'20'!U:V,2,0),"0") -> 0 | BN15: กล่อง | BO15: =+BM15*D15 -> 0 | BP15: =IFERROR(VLOOKUP(A15,'21'!U:V,2,0),"0") -> 0 | BQ15: กล่อง | BR15: =+BP15*D15 -> 0 | BS15: =IFERROR(VLOOKUP(A15,'22'!U:V,2,0),"0") -> 0 | BT15: กล่อง | BU15: =+BS15*D15 -> 0 | BV15: =IFERROR(VLOOKUP(A15,'23'!U:V,2,0),"0") -> 0 | BW15: กล่อง | BX15: =+BV15*D15 -> 0 | BY15: =IFERROR(VLOOKUP(A15,'24'!U:V,2,0),"0") -> 0 | BZ15: กล่อง | CA15: =+BY15*D15 -> 0 | CB15: =IFERROR(VLOOKUP(A15,'25'!U:V,2,0),"0") -> 0 | CC15: กล่อง | CD15: =+CB15*D15 -> 0 | CE15: =IFERROR(VLOOKUP(A15,'26'!U:V,2,0),"0") -> 0 | CF15: กล่อง | CG15: =+CE15*D15 -> 0 | CH15: =IFERROR(VLOOKUP(A15,'27'!U:V,2,0),"0") -> 0 | CI15: กล่อง | CJ15: =+CH15*D15 -> 0 | CK15: =IFERROR(VLOOKUP(A15,'28'!U:V,2,0),"0") -> 0 | CL15: กล่อง | CM15: =+CK15*D15 -> 0 | CN15: =IFERROR(VLOOKUP(A15,'29'!U:V,2,0),"0") -> 0 | CO15: กล่อง | CP15: =+CN15*D15 -> 0 | CQ15: =IFERROR(VLOOKUP(A15,'30'!U:V,2,0),"0") -> 0 | CR15: กล่อง | CS15: =+CQ15*D15 -> 0 | CT15: =IFERROR(VLOOKUP(A15,'31'!U:V,2,0),"0") -> 0 | CU15: กล่อง | CV15: =+CT15*D15 -> 0 | CW15: =IFERROR(VLOOKUP(B15,'B-plus'!A:D,4,0),"0") -> 0 | CX15: กล่อง | CY15: =+CW15*D15 -> 0
A16: 1111008 | B16: 1111008 | C16: ชิฟฟ่อน สอดไส้แยม ขนาด3 ชิ้น มีรสให้เลือก 7 รส (รวมรส) | D16: 14.31 | E16: =+H16+K16+N16+Q16+T16+W16+Z16+AC16+AF16+AI16+AL16+AO16+AR16+AU16+AX16+BA16+BD16+BG16+BJ16+BM16+BP16+BS16+BV16+BY16+CB16+CE16+CH16+CK16+CN16+CQ16+CT16 -> 2673 | F16: กล่อง | G16: =+E16*D16 -> 38250.63 | H16: =IFERROR(VLOOKUP(A16,'1'!U:V,2,0),"0") -> 89 | I16: กล่อง | J16: =+H16*D16 -> 1273.59 | K16: =IFERROR(VLOOKUP(A16,'2'!U:V,2,0),"0") -> 81 | L16: กล่อง | M16: =+K16*D16 -> 1159.11 | N16: =IFERROR(VLOOKUP(A16,'3'!U:V,2,0),"0") -> 137 | O16: กล่อง | P16: =+N16*D16 -> 1960.47 | Q16: =IFERROR(VLOOKUP(A16,'4'!U:V,2,0),"0") -> 64 | R16: กล่อง | S16: =+Q16*D16 -> 915.84 | T16: =IFERROR(VLOOKUP(A16,'5'!U:V,2,0),"0") -> 220 | U16: กล่อง | V16: =+T16*D16 -> 3148.2 | W16: =IFERROR(VLOOKUP(A16,'6'!U:V,2,0),"0") -> 105 | X16: กล่อง | Y16: =+W16*D16 -> 1502.55 | Z16: =IFERROR(VLOOKUP(A16,'7'!U:V,2,0),"0") -> 45 | AA16: กล่อง | AB16: =+Z16*D16 -> 643.95 | AC16: =IFERROR(VLOOKUP(A16,'8'!U:V,2,0),"0") -> 146 | AD16: กล่อง | AE16: =+AC16*D16 -> 2089.26 | AF16: =IFERROR(VLOOKUP(A16,'9'!U:V,2,0),"0") -> 97 | AG16: กล่อง | AH16: =+AF16*D16 -> 1388.07 | AI16: =IFERROR(VLOOKUP(A16,'10'!U:V,2,0),"0") -> 149 | AJ16: กล่อง | AK16: =+AI16*D16 -> 2132.19 | AL16: =IFERROR(VLOOKUP(A16,'11'!U:V,2,0),"0") -> 52 | AM16: กล่อง | AN16: =+AL16*D16 -> 744.12 | AO16: =IFERROR(VLOOKUP(A16,'12'!U:V,2,0),"0") -> 63 | AP16: กล่อง | AQ16: =+AO16*D16 -> 901.53 | AR16: =IFERROR(VLOOKUP(A16,'13'!U:V,2,0),"0") -> 87 | AS16: กล่อง | AT16: =+AR16*D16 -> 1244.97 | AU16: =IFERROR(VLOOKUP(A16,'14'!U:V,2,0),"0") -> 61 | AV16: กล่อง | AW16: =+AU16*D16 -> 872.91 | AX16: =IFERROR(VLOOKUP(A16,'15'!U:V,2,0),"0") -> 72 | AY16: กล่อง | AZ16: =+AX16*D16 -> 1030.32 | BA16: =IFERROR(VLOOKUP(A16,'16'!U:V,2,0),"0") -> 77 | BB16: กล่อง | BC16: =+BA16*D16 -> 1101.87 | BD16: =IFERROR(VLOOKUP(A16,'17'!U:V,2,0),"0") -> 85 | BE16: กล่อง | BF16: =+BD16*D16 -> 1216.35 | BG16: =IFERROR(VLOOKUP(A16,'18'!U:V,2,0),"0") -> 46 | BH16: กล่อง | BI16: =+BG16*D16 -> 658.26 | BJ16: =IFERROR(VLOOKUP(A16,'19'!U:V,2,0),"0") -> 45 | BK16: กล่อง | BL16: =+BJ16*D16 -> 643.95 | BM16: =IFERROR(VLOOKUP(A16,'20'!U:V,2,0),"0") -> 48 | BN16: กล่อง | BO16: =+BM16*D16 -> 686.88 | BP16: =IFERROR(VLOOKUP(A16,'21'!U:V,2,0),"0") -> 55 | BQ16: กล่อง | BR16: =+BP16*D16 -> 787.05 | BS16: =IFERROR(VLOOKUP(A16,'22'!U:V,2,0),"0") -> 71 | BT16: กล่อง | BU16: =+BS16*D16 -> 1016.01 | BV16: =IFERROR(VLOOKUP(A16,'23'!U:V,2,0),"0") -> 94 | BW16: กล่อง | BX16: =+BV16*D16 -> 1345.14 | BY16: =IFERROR(VLOOKUP(A16,'24'!U:V,2,0),"0") -> 85 | BZ16: กล่อง | CA16: =+BY16*D16 -> 1216.35 | CB16: =IFERROR(VLOOKUP(A16,'25'!U:V,2,0),"0") -> 88 | CC16: กล่อง | CD16: =+CB16*D16 -> 1259.28 | CE16: =IFERROR(VLOOKUP(A16,'26'!U:V,2,0),"0") -> 47 | CF16: กล่อง | CG16: =+CE16*D16 -> 672.57 | CH16: =IFERROR(VLOOKUP(A16,'27'!U:V,2,0),"0") -> 55 | CI16: กล่อง | CJ16: =+CH16*D16 -> 787.05 | CK16: =IFERROR(VLOOKUP(A16,'28'!U:V,2,0),"0") -> 34 | CL16: กล่อง | CM16: =+CK16*D16 -> 486.54 | CN16: =IFERROR(VLOOKUP(A16,'29'!U:V,2,0),"0") -> 69 | CO16: กล่อง | CP16: =+CN16*D16 -> 987.39 | CQ16: =IFERROR(VLOOKUP(A16,'30'!U:V,2,0),"0") -> 130 | CR16: กล่อง | CS16: =+CQ16*D16 -> 1860.3 | CT16: =IFERROR(VLOOKUP(A16,'31'!U:V,2,0),"0") -> 176 | CU16: กล่อง | CV16: =+CT16*D16 -> 2518.56 | CW16: =IFERROR(VLOOKUP(B16,'B-plus'!A:D,4,0),"0") -> 94 | CX16: กล่อง | CY16: =+CW16*D16 -> 1345.14
A17: 1111009 | B17: 1111009 | C17: ชิฟฟ่อนสอดไส้ แยม 1กล่อง มี6ชิ้น (รวมรส) | D17: 27.35 | E17: =+H17+K17+N17+Q17+T17+W17+Z17+AC17+AF17+AI17+AL17+AO17+AR17+AU17+AX17+BA17+BD17+BG17+BJ17+BM17+BP17+BS17+BV17+BY17+CB17+CE17+CH17+CK17+CN17+CQ17+CT17 -> 273 | F17: กล่อง | G17: =+E17*D17 -> 7466.55 | H17: =IFERROR(VLOOKUP(A17,'1'!U:V,2,0),"0") -> 12 | I17: กล่อง | J17: =+H17*D17 -> 328.2 | K17: =IFERROR(VLOOKUP(A17,'2'!U:V,2,0),"0") -> 21 | L17: กล่อง | M17: =+K17*D17 -> 574.35 | N17: =IFERROR(VLOOKUP(A17,'3'!U:V,2,0),"0") -> 6 | O17: กล่อง | P17: =+N17*D17 -> 164.1 | Q17: =IFERROR(VLOOKUP(A17,'4'!U:V,2,0),"0") -> 7 | R17: กล่อง | S17: =+Q17*D17 -> 191.45 | T17: =IFERROR(VLOOKUP(A17,'5'!U:V,2,0),"0") -> 7 | U17: กล่อง | V17: =+T17*D17 -> 191.45 | W17: =IFERROR(VLOOKUP(A17,'6'!U:V,2,0),"0") -> 12 | X17: กล่อง | Y17: =+W17*D17 -> 328.2 | Z17: =IFERROR(VLOOKUP(A17,'7'!U:V,2,0),"0") -> 4 | AA17: กล่อง | AB17: =+Z17*D17 -> 109.4 | AC17: =IFERROR(VLOOKUP(A17,'8'!U:V,2,0),"0") -> 8 | AD17: กล่อง | AE17: =+AC17*D17 -> 218.8 | AF17: =IFERROR(VLOOKUP(A17,'9'!U:V,2,0),"0") -> 10 | AG17: กล่อง | AH17: =+AF17*D17 -> 273.5 | AI17: =IFERROR(VLOOKUP(A17,'10'!U:V,2,0),"0") -> 20 | AJ17: กล่อง | AK17: =+AI17*D17 -> 547 | AL17: =IFERROR(VLOOKUP(A17,'11'!U:V,2,0),"0") -> 3 | AM17: กล่อง | AN17: =+AL17*D17 -> 82.05 | AO17: =IFERROR(VLOOKUP(A17,'12'!U:V,2,0),"0") -> 6 | AP17: กล่อง | AQ17: =+AO17*D17 -> 164.1 | AR17: =IFERROR(VLOOKUP(A17,'13'!U:V,2,0),"0") -> 9 | AS17: กล่อง | AT17: =+AR17*D17 -> 246.15 | AU17: =IFERROR(VLOOKUP(A17,'14'!U:V,2,0),"0") -> 7 | AV17: กล่อง | AW17: =+AU17*D17 -> 191.45 | AX17: =IFERROR(VLOOKUP(A17,'15'!U:V,2,0),"0") -> 8 | AY17: กล่อง | AZ17: =+AX17*D17 -> 218.8 | BA17: =IFERROR(VLOOKUP(A17,'16'!U:V,2,0),"0") -> 6 | BB17: กล่อง | BC17: =+BA17*D17 -> 164.1 | BD17: =IFERROR(VLOOKUP(A17,'17'!U:V,2,0),"0") -> 15 | BE17: กล่อง | BF17: =+BD17*D17 -> 410.25 | BG17: =IFERROR(VLOOKUP(A17,'18'!U:V,2,0),"0") -> 3 | BH17: กล่อง | BI17: =+BG17*D17 -> 82.05 | BJ17: =IFERROR(VLOOKUP(A17,'19'!U:V,2,0),"0") -> 11 | BK17: กล่อง | BL17: =+BJ17*D17 -> 300.85 | BM17: =IFERROR(VLOOKUP(A17,'20'!U:V,2,0),"0") -> 4 | BN17: กล่อง | BO17: =+BM17*D17 -> 109.4 | BP17: =IFERROR(VLOOKUP(A17,'21'!U:V,2,0),"0") -> 5 | BQ17: กล่อง | BR17: =+BP17*D17 -> 136.75 | BS17: =IFERROR(VLOOKUP(A17,'22'!U:V,2,0),"0") -> 8 | BT17: กล่อง | BU17: =+BS17*D17 -> 218.8 | BV17: =IFERROR(VLOOKUP(A17,'23'!U:V,2,0),"0") -> 9 | BW17: กล่อง | BX17: =+BV17*D17 -> 246.15 | BY17: =IFERROR(VLOOKUP(A17,'24'!U:V,2,0),"0") -> 14 | BZ17: กล่อง | CA17: =+BY17*D17 -> 382.9 | CB17: =IFERROR(VLOOKUP(A17,'25'!U:V,2,0),"0") -> 12 | CC17: กล่อง | CD17: =+CB17*D17 -> 328.2 | CE17: =IFERROR(VLOOKUP(A17,'26'!U:V,2,0),"0") -> 7 | CF17: กล่อง | CG17: =+CE17*D17 -> 191.45 | CH17: =IFERROR(VLOOKUP(A17,'27'!U:V,2,0),"0") -> 14 | CI17: กล่อง | CJ17: =+CH17*D17 -> 382.9 | CK17: =IFERROR(VLOOKUP(A17,'28'!U:V,2,0),"0") -> 2 | CL17: กล่อง | CM17: =+CK17*D17 -> 54.7 | CN17: =IFERROR(VLOOKUP(A17,'29'!U:V,2,0),"0") -> 6 | CO17: กล่อง | CP17: =+CN17*D17 -> 164.1 | CQ17: =IFERROR(VLOOKUP(A17,'30'!U:V,2,0),"0") -> 8 | CR17: กล่อง | CS17: =+CQ17*D17 -> 218.8 | CT17: =IFERROR(VLOOKUP(A17,'31'!U:V,2,0),"0") -> 9 | CU17: กล่อง | CV17: =+CT17*D17 -> 246.15 | CW17: =IFERROR(VLOOKUP(B17,'B-plus'!A:D,4,0),"0") -> 67 | CX17: กล่อง | CY17: =+CW17*D17 -> 1832.45
A18: 1111009-A | B18: 1111009-A | C18: ชิฟฟ่อนสอดไส้ รวมรส 6ชิ้น/กล่อง | D18: 27.35 | E18: =+H18+K18+N18+Q18+T18+W18+Z18+AC18+AF18+AI18+AL18+AO18+AR18+AU18+AX18+BA18+BD18+BG18+BJ18+BM18+BP18+BS18+BV18+BY18+CB18+CE18+CH18+CK18+CN18+CQ18+CT18 -> 0 | F18: กล่อง | G18: =+E18*D18 -> 0 | H18: =IFERROR(VLOOKUP(A18,'1'!U:V,2,0),"0") -> 0 | I18: กล่อง | J18: =+H18*D18 -> 0 | K18: =IFERROR(VLOOKUP(A18,'2'!U:V,2,0),"0") -> 0 | L18: กล่อง | M18: =+K18*D18 -> 0 | N18: =IFERROR(VLOOKUP(A18,'3'!U:V,2,0),"0") -> 0 | O18: กล่อง | P18: =+N18*D18 -> 0 | Q18: =IFERROR(VLOOKUP(A18,'4'!U:V,2,0),"0") -> 0 | R18: กล่อง | S18: =+Q18*D18 -> 0 | T18: =IFERROR(VLOOKUP(A18,'5'!U:V,2,0),"0") -> 0 | U18: กล่อง | V18: =+T18*D18 -> 0 | W18: =IFERROR(VLOOKUP(A18,'6'!U:V,2,0),"0") -> 0 | X18: กล่อง | Y18: =+W18*D18 -> 0 | Z18: =IFERROR(VLOOKUP(A18,'7'!U:V,2,0),"0") -> 0 | AA18: กล่อง | AB18: =+Z18*D18 -> 0 | AC18: =IFERROR(VLOOKUP(A18,'8'!U:V,2,0),"0") -> 0 | AD18: กล่อง | AE18: =+AC18*D18 -> 0 | AF18: =IFERROR(VLOOKUP(A18,'9'!U:V,2,0),"0") -> 0 | AG18: กล่อง | AH18: =+AF18*D18 -> 0 | AI18: =IFERROR(VLOOKUP(A18,'10'!U:V,2,0),"0") -> 0 | AJ18: กล่อง | AK18: =+AI18*D18 -> 0 | AL18: =IFERROR(VLOOKUP(A18,'11'!U:V,2,0),"0") -> 0 | AM18: กล่อง | AN18: =+AL18*D18 -> 0 | AO18: =IFERROR(VLOOKUP(A18,'12'!U:V,2,0),"0") -> 0 | AP18: กล่อง | AQ18: =+AO18*D18 -> 0 | AR18: =IFERROR(VLOOKUP(A18,'13'!U:V,2,0),"0") -> 0 | AS18: กล่อง | AT18: =+AR18*D18 -> 0 | AU18: =IFERROR(VLOOKUP(A18,'14'!U:V,2,0),"0") -> 0 | AV18: กล่อง | AW18: =+AU18*D18 -> 0 | AX18: =IFERROR(VLOOKUP(A18,'15'!U:V,2,0),"0") -> 0 | AY18: กล่อง | AZ18: =+AX18*D18 -> 0 | BA18: =IFERROR(VLOOKUP(A18,'16'!U:V,2,0),"0") -> 0 | BB18: กล่อง | BC18: =+BA18*D18 -> 0 | BD18: =IFERROR(VLOOKUP(A18,'17'!U:V,2,0),"0") -> 0 | BE18: กล่อง | BF18: =+BD18*D18 -> 0 | BG18: =IFERROR(VLOOKUP(A18,'18'!U:V,2,0),"0") -> 0 | BH18: กล่อง | BI18: =+BG18*D18 -> 0 | BJ18: =IFERROR(VLOOKUP(A18,'19'!U:V,2,0),"0") -> 0 | BK18: กล่อง | BL18: =+BJ18*D18 -> 0 | BM18: =IFERROR(VLOOKUP(A18,'20'!U:V,2,0),"0") -> 0 | BN18: กล่อง | BO18: =+BM18*D18 -> 0 | BP18: =IFERROR(VLOOKUP(A18,'21'!U:V,2,0),"0") -> 0 | BQ18: กล่อง | BR18: =+BP18*D18 -> 0 | BS18: =IFERROR(VLOOKUP(A18,'22'!U:V,2,0),"0") -> 0 | BT18: กล่อง | BU18: =+BS18*D18 -> 0 | BV18: =IFERROR(VLOOKUP(A18,'23'!U:V,2,0),"0") -> 0 | BW18: กล่อง | BX18: =+BV18*D18 -> 0 | BY18: =IFERROR(VLOOKUP(A18,'24'!U:V,2,0),"0") -> 0 | BZ18: กล่อง | CA18: =+BY18*D18 -> 0 | CB18: =IFERROR(VLOOKUP(A18,'25'!U:V,2,0),"0") -> 0 | CC18: กล่อง | CD18: =+CB18*D18 -> 0 | CE18: =IFERROR(VLOOKUP(A18,'26'!U:V,2,0),"0") -> 0 | CF18: กล่อง | CG18: =+CE18*D18 -> 0 | CH18: =IFERROR(VLOOKUP(A18,'27'!U:V,2,0),"0") -> 0 | CI18: กล่อง | CJ18: =+CH18*D18 -> 0 | CK18: =IFERROR(VLOOKUP(A18,'28'!U:V,2,0),"0") -> 0 | CL18: กล่อง | CM18: =+CK18*D18 -> 0 | CN18: =IFERROR(VLOOKUP(A18,'29'!U:V,2,0),"0") -> 0 | CO18: กล่อง | CP18: =+CN18*D18 -> 0 | CQ18: =IFERROR(VLOOKUP(A18,'30'!U:V,2,0),"0") -> 0 | CR18: กล่อง | CS18: =+CQ18*D18 -> 0 | CT18: =IFERROR(VLOOKUP(A18,'31'!U:V,2,0),"0") -> 0 | CU18: กล่อง | CV18: =+CT18*D18 -> 0 | CW18: =IFERROR(VLOOKUP(B18,'B-plus'!A:D,4,0),"0") -> 0 | CX18: กล่อง | CY18: =+CW18*D18 -> 0
A19: 1111013 | B19: 1111013 | C19: ชิฟฟ่อน สอดไส้แยม ขนาด3 ชิ้น มีรสให้เลือก 7 รส | D19: 27.35 | E19: =+H19+K19+N19+Q19+T19+W19+Z19+AC19+AF19+AI19+AL19+AO19+AR19+AU19+AX19+BA19+BD19+BG19+BJ19+BM19+BP19+BS19+BV19+BY19+CB19+CE19+CH19+CK19+CN19+CQ19+CT19 -> 0 | F19: กล่อง | G19: =+E19*D19 -> 0 | H19: =IFERROR(VLOOKUP(A19,'1'!U:V,2,0),"0") -> 0 | I19: กล่อง | J19: =+H19*D19 -> 0 | K19: =IFERROR(VLOOKUP(A19,'2'!U:V,2,0),"0") -> 0 | L19: กล่อง | M19: =+K19*D19 -> 0 | N19: =IFERROR(VLOOKUP(A19,'3'!U:V,2,0),"0") -> 0 | O19: กล่อง | P19: =+N19*D19 -> 0 | Q19: =IFERROR(VLOOKUP(A19,'4'!U:V,2,0),"0") -> 0 | R19: กล่อง | S19: =+Q19*D19 -> 0 | T19: =IFERROR(VLOOKUP(A19,'5'!U:V,2,0),"0") -> 0 | U19: กล่อง | V19: =+T19*D19 -> 0 | W19: =IFERROR(VLOOKUP(A19,'6'!U:V,2,0),"0") -> 0 | X19: กล่อง | Y19: =+W19*D19 -> 0 | Z19: =IFERROR(VLOOKUP(A19,'7'!U:V,2,0),"0") -> 0 | AA19: กล่อง | AB19: =+Z19*D19 -> 0 | AC19: =IFERROR(VLOOKUP(A19,'8'!U:V,2,0),"0") -> 0 | AD19: กล่อง | AE19: =+AC19*D19 -> 0 | AF19: =IFERROR(VLOOKUP(A19,'9'!U:V,2,0),"0") -> 0 | AG19: กล่อง | AH19: =+AF19*D19 -> 0 | AI19: =IFERROR(VLOOKUP(A19,'10'!U:V,2,0),"0") -> 0 | AJ19: กล่อง | AK19: =+AI19*D19 -> 0 | AL19: =IFERROR(VLOOKUP(A19,'11'!U:V,2,0),"0") -> 0 | AM19: กล่อง | AN19: =+AL19*D19 -> 0 | AO19: =IFERROR(VLOOKUP(A19,'12'!U:V,2,0),"0") -> 0 | AP19: กล่อง | AQ19: =+AO19*D19 -> 0 | AR19: =IFERROR(VLOOKUP(A19,'13'!U:V,2,0),"0") -> 0 | AS19: กล่อง | AT19: =+AR19*D19 -> 0 | AU19: =IFERROR(VLOOKUP(A19,'14'!U:V,2,0),"0") -> 0 | AV19: กล่อง | AW19: =+AU19*D19 -> 0 | AX19: =IFERROR(VLOOKUP(A19,'15'!U:V,2,0),"0") -> 0 | AY19: กล่อง | AZ19: =+AX19*D19 -> 0 | BA19: =IFERROR(VLOOKUP(A19,'16'!U:V,2,0),"0") -> 0 | BB19: กล่อง | BC19: =+BA19*D19 -> 0 | BD19: =IFERROR(VLOOKUP(A19,'17'!U:V,2,0),"0") -> 0 | BE19: กล่อง | BF19: =+BD19*D19 -> 0 | BG19: =IFERROR(VLOOKUP(A19,'18'!U:V,2,0),"0") -> 0 | BH19: กล่อง | BI19: =+BG19*D19 -> 0 | BJ19: =IFERROR(VLOOKUP(A19,'19'!U:V,2,0),"0") -> 0 | BK19: กล่อง | BL19: =+BJ19*D19 -> 0 | BM19: =IFERROR(VLOOKUP(A19,'20'!U:V,2,0),"0") -> 0 | BN19: กล่อง | BO19: =+BM19*D19 -> 0 | BP19: =IFERROR(VLOOKUP(A19,'21'!U:V,2,0),"0") -> 0 | BQ19: กล่อง | BR19: =+BP19*D19 -> 0 | BS19: =IFERROR(VLOOKUP(A19,'22'!U:V,2,0),"0") -> 0 | BT19: กล่อง | BU19: =+BS19*D19 -> 0 | BV19: =IFERROR(VLOOKUP(A19,'23'!U:V,2,0),"0") -> 0 | BW19: กล่อง | BX19: =+BV19*D19 -> 0 | BY19: =IFERROR(VLOOKUP(A19,'24'!U:V,2,0),"0") -> 0 | BZ19: กล่อง | CA19: =+BY19*D19 -> 0 | CB19: =IFERROR(VLOOKUP(A19,'25'!U:V,2,0),"0") -> 0 | CC19: กล่อง | CD19: =+CB19*D19 -> 0 | CE19: =IFERROR(VLOOKUP(A19,'26'!U:V,2,0),"0") -> 0 | CF19: กล่อง | CG19: =+CE19*D19 -> 0 | CH19: =IFERROR(VLOOKUP(A19,'27'!U:V,2,0),"0") -> 0 | CI19: กล่อง | CJ19: =+CH19*D19 -> 0 | CK19: =IFERROR(VLOOKUP(A19,'28'!U:V,2,0),"0") -> 0 | CL19: กล่อง | CM19: =+CK19*D19 -> 0 | CN19: =IFERROR(VLOOKUP(A19,'29'!U:V,2,0),"0") -> 0 | CO19: กล่อง | CP19: =+CN19*D19 -> 0 | CQ19: =IFERROR(VLOOKUP(A19,'30'!U:V,2,0),"0") -> 0 | CR19: กล่อง | CS19: =+CQ19*D19 -> 0 | CT19: =IFERROR(VLOOKUP(A19,'31'!U:V,2,0),"0") -> 0 | CU19: กล่อง | CV19: =+CT19*D19 -> 0 | CW19: =IFERROR(VLOOKUP(B19,'B-plus'!A:D,4,0),"0") -> 0 | CX19: กล่อง | CY19: =+CW19*D19 -> 0
A20: 1111015 | B20: 1111015 | C20: ชิฟฟ่อน สอดไส้แยม ขนาด3 ชิ้น มีรสให้เลือก 7 รส (มะพร้าว) | D20: 27.35 | E20: =+H20+K20+N20+Q20+T20+W20+Z20+AC20+AF20+AI20+AL20+AO20+AR20+AU20+AX20+BA20+BD20+BG20+BJ20+BM20+BP20+BS20+BV20+BY20+CB20+CE20+CH20+CK20+CN20+CQ20+CT20 -> 0 | F20: กล่อง | G20: =+E20*D20 -> 0 | H20: =IFERROR(VLOOKUP(A20,'1'!U:V,2,0),"0") -> 0 | I20: กล่อง | J20: =+H20*D20 -> 0 | K20: =IFERROR(VLOOKUP(A20,'2'!U:V,2,0),"0") -> 0 | L20: กล่อง | M20: =+K20*D20 -> 0 | N20: =IFERROR(VLOOKUP(A20,'3'!U:V,2,0),"0") -> 0 | O20: กล่อง | P20: =+N20*D20 -> 0 | Q20: =IFERROR(VLOOKUP(A20,'4'!U:V,2,0),"0") -> 0 | R20: กล่อง | S20: =+Q20*D20 -> 0 | T20: =IFERROR(VLOOKUP(A20,'5'!U:V,2,0),"0") -> 0 | U20: กล่อง | V20: =+T20*D20 -> 0 | W20: =IFERROR(VLOOKUP(A20,'6'!U:V,2,0),"0") -> 0 | X20: กล่อง | Y20: =+W20*D20 -> 0 | Z20: =IFERROR(VLOOKUP(A20,'7'!U:V,2,0),"0") -> 0 | AA20: กล่อง | AB20: =+Z20*D20 -> 0 | AC20: =IFERROR(VLOOKUP(A20,'8'!U:V,2,0),"0") -> 0 | AD20: กล่อง | AE20: =+AC20*D20 -> 0 | AF20: =IFERROR(VLOOKUP(A20,'9'!U:V,2,0),"0") -> 0 | AG20: กล่อง | AH20: =+AF20*D20 -> 0 | AI20: =IFERROR(VLOOKUP(A20,'10'!U:V,2,0),"0") -> 0 | AJ20: กล่อง | AK20: =+AI20*D20 -> 0 | AL20: =IFERROR(VLOOKUP(A20,'11'!U:V,2,0),"0") -> 0 | AM20: กล่อง | AN20: =+AL20*D20 -> 0 | AO20: =IFERROR(VLOOKUP(A20,'12'!U:V,2,0),"0") -> 0 | AP20: กล่อง | AQ20: =+AO20*D20 -> 0 | AR20: =IFERROR(VLOOKUP(A20,'13'!U:V,2,0),"0") -> 0 | AS20: กล่อง | AT20: =+AR20*D20 -> 0 | AU20: =IFERROR(VLOOKUP(A20,'14'!U:V,2,0),"0") -> 0 | AV20: กล่อง | AW20: =+AU20*D20 -> 0 | AX20: =IFERROR(VLOOKUP(A20,'15'!U:V,2,0),"0") -> 0 | AY20: กล่อง | AZ20: =+AX20*D20 -> 0 | BA20: =IFERROR(VLOOKUP(A20,'16'!U:V,2,0),"0") -> 0 | BB20: กล่อง | BC20: =+BA20*D20 -> 0 | BD20: =IFERROR(VLOOKUP(A20,'17'!U:V,2,0),"0") -> 0 | BE20: กล่อง | BF20: =+BD20*D20 -> 0 | BG20: =IFERROR(VLOOKUP(A20,'18'!U:V,2,0),"0") -> 0 | BH20: กล่อง | BI20: =+BG20*D20 -> 0 | BJ20: =IFERROR(VLOOKUP(A20,'19'!U:V,2,0),"0") -> 0 | BK20: กล่อง | BL20: =+BJ20*D20 -> 0 | BM20: =IFERROR(VLOOKUP(A20,'20'!U:V,2,0),"0") -> 0 | BN20: กล่อง | BO20: =+BM20*D20 -> 0 | BP20: =IFERROR(VLOOKUP(A20,'21'!U:V,2,0),"0") -> 0 | BQ20: กล่อง | BR20: =+BP20*D20 -> 0 | BS20: =IFERROR(VLOOKUP(A20,'22'!U:V,2,0),"0") -> 0 | BT20: กล่อง | BU20: =+BS20*D20 -> 0 | BV20: =IFERROR(VLOOKUP(A20,'23'!U:V,2,0),"0") -> 0 | BW20: กล่อง | BX20: =+BV20*D20 -> 0 | BY20: =IFERROR(VLOOKUP(A20,'24'!U:V,2,0),"0") -> 0 | BZ20: กล่อง | CA20: =+BY20*D20 -> 0 | CB20: =IFERROR(VLOOKUP(A20,'25'!U:V,2,0),"0") -> 0 | CC20: กล่อง | CD20: =+CB20*D20 -> 0 | CE20: =IFERROR(VLOOKUP(A20,'26'!U:V,2,0),"0") -> 0 | CF20: กล่อง | CG20: =+CE20*D20 -> 0 | CH20: =IFERROR(VLOOKUP(A20,'27'!U:V,2,0),"0") -> 0 | CI20: กล่อง | CJ20: =+CH20*D20 -> 0 | CK20: =IFERROR(VLOOKUP(A20,'28'!U:V,2,0),"0") -> 0 | CL20: กล่อง | CM20: =+CK20*D20 -> 0 | CN20: =IFERROR(VLOOKUP(A20,'29'!U:V,2,0),"0") -> 0 | CO20: กล่อง | CP20: =+CN20*D20 -> 0 | CQ20: =IFERROR(VLOOKUP(A20,'30'!U:V,2,0),"0") -> 0 | CR20: กล่อง | CS20: =+CQ20*D20 -> 0 | CT20: =IFERROR(VLOOKUP(A20,'31'!U:V,2,0),"0") -> 0 | CU20: กล่อง | CV20: =+CT20*D20 -> 0 | CW20: =IFERROR(VLOOKUP(B20,'B-plus'!A:D,4,0),"0") -> 0 | CX20: กล่อง | CY20: =+CW20*D20 -> 0
A21: 1111017 | B21: 1111017 | C21: ชิฟฟ่อน สอดไส้แยม ขนาด3 ชิ้น มีรสให้เลือก 7 รส (บลูเบอรี่) | D21: 27.35 | E21: =+H21+K21+N21+Q21+T21+W21+Z21+AC21+AF21+AI21+AL21+AO21+AR21+AU21+AX21+BA21+BD21+BG21+BJ21+BM21+BP21+BS21+BV21+BY21+CB21+CE21+CH21+CK21+CN21+CQ21+CT21 -> 0 | F21: กล่อง | G21: =+E21*D21 -> 0 | H21: =IFERROR(VLOOKUP(A21,'1'!U:V,2,0),"0") -> 0 | I21: กล่อง | J21: =+H21*D21 -> 0 | K21: =IFERROR(VLOOKUP(A21,'2'!U:V,2,0),"0") -> 0 | L21: กล่อง | M21: =+K21*D21 -> 0 | N21: =IFERROR(VLOOKUP(A21,'3'!U:V,2,0),"0") -> 0 | O21: กล่อง | P21: =+N21*D21 -> 0 | Q21: =IFERROR(VLOOKUP(A21,'4'!U:V,2,0),"0") -> 0 | R21: กล่อง | S21: =+Q21*D21 -> 0 | T21: =IFERROR(VLOOKUP(A21,'5'!U:V,2,0),"0") -> 0 | U21: กล่อง | V21: =+T21*D21 -> 0 | W21: =IFERROR(VLOOKUP(A21,'6'!U:V,2,0),"0") -> 0 | X21: กล่อง | Y21: =+W21*D21 -> 0 | Z21: =IFERROR(VLOOKUP(A21,'7'!U:V,2,0),"0") -> 0 | AA21: กล่อง | AB21: =+Z21*D21 -> 0 | AC21: =IFERROR(VLOOKUP(A21,'8'!U:V,2,0),"0") -> 0 | AD21: กล่อง | AE21: =+AC21*D21 -> 0 | AF21: =IFERROR(VLOOKUP(A21,'9'!U:V,2,0),"0") -> 0 | AG21: กล่อง | AH21: =+AF21*D21 -> 0 | AI21: =IFERROR(VLOOKUP(A21,'10'!U:V,2,0),"0") -> 0 | AJ21: กล่อง | AK21: =+AI21*D21 -> 0 | AL21: =IFERROR(VLOOKUP(A21,'11'!U:V,2,0),"0") -> 0 | AM21: กล่อง | AN21: =+AL21*D21 -> 0 | AO21: =IFERROR(VLOOKUP(A21,'12'!U:V,2,0),"0") -> 0 | AP21: กล่อง | AQ21: =+AO21*D21 -> 0 | AR21: =IFERROR(VLOOKUP(A21,'13'!U:V,2,0),"0") -> 0 | AS21: กล่อง | AT21: =+AR21*D21 -> 0 | AU21: =IFERROR(VLOOKUP(A21,'14'!U:V,2,0),"0") -> 0 | AV21: กล่อง | AW21: =+AU21*D21 -> 0 | AX21: =IFERROR(VLOOKUP(A21,'15'!U:V,2,0),"0") -> 0 | AY21: กล่อง | AZ21: =+AX21*D21 -> 0 | BA21: =IFERROR(VLOOKUP(A21,'16'!U:V,2,0),"0") -> 0 | BB21: กล่อง | BC21: =+BA21*D21 -> 0 | BD21: =IFERROR(VLOOKUP(A21,'17'!U:V,2,0),"0") -> 0 | BE21: กล่อง | BF21: =+BD21*D21 -> 0 | BG21: =IFERROR(VLOOKUP(A21,'18'!U:V,2,0),"0") -> 0 | BH21: กล่อง | BI21: =+BG21*D21 -> 0 | BJ21: =IFERROR(VLOOKUP(A21,'19'!U:V,2,0),"0") -> 0 | BK21: กล่อง | BL21: =+BJ21*D21 -> 0 | BM21: =IFERROR(VLOOKUP(A21,'20'!U:V,2,0),"0") -> 0 | BN21: กล่อง | BO21: =+BM21*D21 -> 0 | BP21: =IFERROR(VLOOKUP(A21,'21'!U:V,2,0),"0") -> 0 | BQ21: กล่อง | BR21: =+BP21*D21 -> 0 | BS21: =IFERROR(VLOOKUP(A21,'22'!U:V,2,0),"0") -> 0 | BT21: กล่อง | BU21: =+BS21*D21 -> 0 | BV21: =IFERROR(VLOOKUP(A21,'23'!U:V,2,0),"0") -> 0 | BW21: กล่อง | BX21: =+BV21*D21 -> 0 | BY21: =IFERROR(VLOOKUP(A21,'24'!U:V,2,0),"0") -> 0 | BZ21: กล่อง | CA21: =+BY21*D21 -> 0 | CB21: =IFERROR(VLOOKUP(A21,'25'!U:V,2,0),"0") -> 0 | CC21: กล่อง | CD21: =+CB21*D21 -> 0 | CE21: =IFERROR(VLOOKUP(A21,'26'!U:V,2,0),"0") -> 0 | CF21: กล่อง | CG21: =+CE21*D21 -> 0 | CH21: =IFERROR(VLOOKUP(A21,'27'!U:V,2,0),"0") -> 0 | CI21: กล่อง | CJ21: =+CH21*D21 -> 0 | CK21: =IFERROR(VLOOKUP(A21,'28'!U:V,2,0),"0") -> 0 | CL21: กล่อง | CM21: =+CK21*D21 -> 0 | CN21: =IFERROR(VLOOKUP(A21,'29'!U:V,2,0),"0") -> 0 | CO21: กล่อง | CP21: =+CN21*D21 -> 0 | CQ21: =IFERROR(VLOOKUP(A21,'30'!U:V,2,0),"0") -> 0 | CR21: กล่อง | CS21: =+CQ21*D21 -> 0 | CT21: =IFERROR(VLOOKUP(A21,'31'!U:V,2,0),"0") -> 0 | CU21: กล่อง | CV21: =+CT21*D21 -> 0 | CW21: =IFERROR(VLOOKUP(B21,'B-plus'!A:D,4,0),"0") -> 0 | CX21: กล่อง | CY21: =+CW21*D21 -> 0
A22: 1111019 | B22: 1111019 | C22: ชิฟฟ่อน สอดไส้แยม ขนาด3 ชิ้น มีรสให้เลือก 7 รส (ฝอยทอง) | D22: 27.35 | E22: =+H22+K22+N22+Q22+T22+W22+Z22+AC22+AF22+AI22+AL22+AO22+AR22+AU22+AX22+BA22+BD22+BG22+BJ22+BM22+BP22+BS22+BV22+BY22+CB22+CE22+CH22+CK22+CN22+CQ22+CT22 -> 0 | F22: กล่อง | G22: =+E22*D22 -> 0 | H22: =IFERROR(VLOOKUP(A22,'1'!U:V,2,0),"0") -> 0 | I22: กล่อง | J22: =+H22*D22 -> 0 | K22: =IFERROR(VLOOKUP(A22,'2'!U:V,2,0),"0") -> 0 | L22: กล่อง | M22: =+K22*D22 -> 0 | N22: =IFERROR(VLOOKUP(A22,'3'!U:V,2,0),"0") -> 0 | O22: กล่อง | P22: =+N22*D22 -> 0 | Q22: =IFERROR(VLOOKUP(A22,'4'!U:V,2,0),"0") -> 0 | R22: กล่อง | S22: =+Q22*D22 -> 0 | T22: =IFERROR(VLOOKUP(A22,'5'!U:V,2,0),"0") -> 0 | U22: กล่อง | V22: =+T22*D22 -> 0 | W22: =IFERROR(VLOOKUP(A22,'6'!U:V,2,0),"0") -> 0 | X22: กล่อง | Y22: =+W22*D22 -> 0 | Z22: =IFERROR(VLOOKUP(A22,'7'!U:V,2,0),"0") -> 0 | AA22: กล่อง | AB22: =+Z22*D22 -> 0 | AC22: =IFERROR(VLOOKUP(A22,'8'!U:V,2,0),"0") -> 0 | AD22: กล่อง | AE22: =+AC22*D22 -> 0 | AF22: =IFERROR(VLOOKUP(A22,'9'!U:V,2,0),"0") -> 0 | AG22: กล่อง | AH22: =+AF22*D22 -> 0 | AI22: =IFERROR(VLOOKUP(A22,'10'!U:V,2,0),"0") -> 0 | AJ22: กล่อง | AK22: =+AI22*D22 -> 0 | AL22: =IFERROR(VLOOKUP(A22,'11'!U:V,2,0),"0") -> 0 | AM22: กล่อง | AN22: =+AL22*D22 -> 0 | AO22: =IFERROR(VLOOKUP(A22,'12'!U:V,2,0),"0") -> 0 | AP22: กล่อง | AQ22: =+AO22*D22 -> 0 | AR22: =IFERROR(VLOOKUP(A22,'13'!U:V,2,0),"0") -> 0 | AS22: กล่อง | AT22: =+AR22*D22 -> 0 | AU22: =IFERROR(VLOOKUP(A22,'14'!U:V,2,0),"0") -> 0 | AV22: กล่อง | AW22: =+AU22*D22 -> 0 | AX22: =IFERROR(VLOOKUP(A22,'15'!U:V,2,0),"0") -> 0 | AY22: กล่อง | AZ22: =+AX22*D22 -> 0 | BA22: =IFERROR(VLOOKUP(A22,'16'!U:V,2,0),"0") -> 0 | BB22: กล่อง | BC22: =+BA22*D22 -> 0 | BD22: =IFERROR(VLOOKUP(A22,'17'!U:V,2,0),"0") -> 0 | BE22: กล่อง | BF22: =+BD22*D22 -> 0 | BG22: =IFERROR(VLOOKUP(A22,'18'!U:V,2,0),"0") -> 0 | BH22: กล่อง | BI22: =+BG22*D22 -> 0 | BJ22: =IFERROR(VLOOKUP(A22,'19'!U:V,2,0),"0") -> 0 | BK22: กล่อง | BL22: =+BJ22*D22 -> 0 | BM22: =IFERROR(VLOOKUP(A22,'20'!U:V,2,0),"0") -> 0 | BN22: กล่อง | BO22: =+BM22*D22 -> 0 | BP22: =IFERROR(VLOOKUP(A22,'21'!U:V,2,0),"0") -> 0 | BQ22: กล่อง | BR22: =+BP22*D22 -> 0 | BS22: =IFERROR(VLOOKUP(A22,'22'!U:V,2,0),"0") -> 0 | BT22: กล่อง | BU22: =+BS22*D22 -> 0 | BV22: =IFERROR(VLOOKUP(A22,'23'!U:V,2,0),"0") -> 0 | BW22: กล่อง | BX22: =+BV22*D22 -> 0 | BY22: =IFERROR(VLOOKUP(A22,'24'!U:V,2,0),"0") -> 0 | BZ22: กล่อง | CA22: =+BY22*D22 -> 0 | CB22: =IFERROR(VLOOKUP(A22,'25'!U:V,2,0),"0") -> 0 | CC22: กล่อง | CD22: =+CB22*D22 -> 0 | CE22: =IFERROR(VLOOKUP(A22,'26'!U:V,2,0),"0") -> 0 | CF22: กล่อง | CG22: =+CE22*D22 -> 0 | CH22: =IFERROR(VLOOKUP(A22,'27'!U:V,2,0),"0") -> 0 | CI22: กล่อง | CJ22: =+CH22*D22 -> 0 | CK22: =IFERROR(VLOOKUP(A22,'28'!U:V,2,0),"0") -> 0 | CL22: กล่อง | CM22: =+CK22*D22 -> 0 | CN22: =IFERROR(VLOOKUP(A22,'29'!U:V,2,0),"0") -> 0 | CO22: กล่อง | CP22: =+CN22*D22 -> 0 | CQ22: =IFERROR(VLOOKUP(A22,'30'!U:V,2,0),"0") -> 0 | CR22: กล่อง | CS22: =+CQ22*D22 -> 0 | CT22: =IFERROR(VLOOKUP(A22,'31'!U:V,2,0),"0") -> 0 | CU22: กล่อง | CV22: =+CT22*D22 -> 0 | CW22: =IFERROR(VLOOKUP(B22,'B-plus'!A:D,4,0),"0") -> 0 | CX22: กล่อง | CY22: =+CW22*D22 -> 0
