Workbook

Sheet ALL
A1: รายการขายสินค้าออนไลน์แยกจำนวนชิ้นรายวัน เดือนมิถุนายน 2569
E2: =SUBTOTAL(9,E5:E10305) -> 25020 | F2: =SUBTOTAL(9,F5:F10305) -> 0 | G2: =SUBTOTAL(9,G5:G10305) -> 409566.13 | H2: =SUBTOTAL(9,H5:H10305) -> 668 | I2: =SUBTOTAL(9,I5:I10305) -> 0 | J2: =SUBTOTAL(9,J5:J10305) -> 10338.35 | K2: =SUBTOTAL(9,K5:K10305) -> 993 | L2: =SUBTOTAL(9,L5:L10305) -> 0 | ... CY2: =SUBTOTAL(9,CY5:CY10305) -> 0
A3: รหัสสินค้า | B3: รหัสสินค้า | C3: ชื่อสินค้า | D3: ราคาต้นทุน | E3: เดือนมิถุนายน | H3: 244501 | K3: 244502 | N3: 244503 | Q3: 244504 | T3: 244505 | W3: 244506 | Z3: 244507 | AC3: 244508 | AF3: 244509 | AI3: 244510 | AL3: 244511 | AO3: 244512 | AR3: 244513 | AU3: 244514 | AX3: 244515 | BA3: 244516 | BD3: 244517 | BG3: 244518 | BJ3: 244519 | BM3: 244520 | BP3: 244521 | BS3: 244522 | BV3: 244523 | BY3: 244524 | CB3: 244525 | CE3: 244526 | CH3: 244527 | CK3: 244528 | CN3: 244529 | CQ3: 244530 | CT3: 244531 | CW3: ระบบ Bplus
E4: จำนวน | F4: หน่วย | G4: ยอดต้นทุน/วัน | H4: จำนวน | I4: หน่วย | J4: ยอดต้นทุน/วัน | K4: จำนวน | L4: หน่วย | M4: ยอดต้นทุน/วัน | N4: จำนวน | O4: หน่วย | P4: ยอดต้นทุน/วัน | Q4: จำนวน | R4: หน่วย | S4: ยอดต้นทุน/วัน | T4: จำนวน | U4: หน่วย | V4: ยอดต้นทุน/วัน | W4: จำนวน | X4: หน่วย | Y4: ยอดต้นทุน/วัน | Z4: จำนวน | AA4: หน่วย | AB4: ยอดต้นทุน/วัน | AC4: จำนวน | AD4: หน่วย | AE4: ยอดต้นทุน/วัน | AF4: จำนวน | AG4: หน่วย | AH4: ยอดต้นทุน/วัน | AI4: จำนวน | AJ4: หน่วย | AK4: ยอดต้นทุน/วัน | AL4: จำนวน | AM4: หน่วย | AN4: ยอดต้นทุน/วัน | AO4: จำนวน | AP4: หน่วย | AQ4: ยอดต้นทุน/วัน | AR4: จำนวน | AS4: หน่วย | AT4: ยอดต้นทุน/วัน | AU4: จำนวน | AV4: หน่วย | AW4: ยอดต้นทุน/วัน | AX4: จำนวน | AY4: หน่วย | AZ4: ยอดต้นทุน/วัน | BA4: จำนวน | BB4: หน่วย | BC4: ยอดต้นทุน/วัน | BD4: จำนวน | BE4: หน่วย | BF4: ยอดต้นทุน/วัน | BG4: จำนวน | BH4: หน่วย | BI4: ยอดต้นทุน/วัน | BJ4: จำนวน | BK4: หน่วย | BL4: ยอดต้นทุน/วัน | BM4: จำนวน | BN4: หน่วย | BO4: ยอดต้นทุน/วัน | BP4: จำนวน | BQ4: หน่วย | BR4: ยอดต้นทุน/วัน | BS4: จำนวน | BT4: หน่วย | BU4: ยอดต้นทุน/วัน | BV4: จำนวน | BW4: หน่วย | BX4: ยอดต้นทุน/วัน | BY4: จำนวน | BZ4: หน่วย | CA4: ยอดต้นทุน/วัน | CB4: จำนวน | CC4: หน่วย | CD4: ยอดต้นทุน/วัน | CE4: จำนวน | CF4: หน่วย | CG4: ยอดต้นทุน/วัน | CH4: จำนวน | CI4: หน่วย | CJ4: ยอดต้นทุน/วัน | CK4: จำนวน | CL4: หน่วย | CM4: ยอดต้นทุน/วัน | CN4: จำนวน | CO4: หน่วย | CP4: ยอดต้นทุน/วัน | CQ4: จำนวน | CR4: หน่วย | CS4: ยอดต้นทุน/วัน | CT4: จำนวน | CU4: หน่วย | CV4: ยอดต้นทุน/วัน | CW4: จำนวน | CX4: หน่วย | CY4: ยอดต้นทุน/วัน
A5: 1004055 | B5: 1004055 | C5: ชิฟฟ่อน รวมรส 1กล่อง4ชิ้น | D5: 19.77 | E5: =+H5+K5+N5+Q5+T5+W5+Z5+AC5+AF5+AI5+AL5+AO5+AR5+AU5+AX5+BA5+BD5+BG5+BJ5+BM5+BP5+BS5+BV5+BY5+CB5+CE5+CH5+CK5+CN5+CQ5+CT5 -> 57 | F5: กล่อง | G5: =+E5*D5 -> 1126.89 | H5: =IFERROR(VLOOKUP(B5,'1'!B:BC,54,0),"0") -> 4 | I5: กล่อง | J5: =+H5*D5 -> 79.08 | K5: =IFERROR(VLOOKUP(B5,'2'!B:BC,54,0),"0") -> 0 | L5: กล่อง | M5: =+K5*D5 -> 0 | N5: =IFERROR(VLOOKUP(B5,'3'!B:BC,54,0),"0") -> 0 | O5: กล่อง | P5: =+N5*D5 -> 0 | Q5: =IFERROR(VLOOKUP(B5,'4'!B:BC,54,0),"0") -> 0 | R5: กล่อง | S5: =+Q5*D5 -> 0 | T5: =IFERROR(VLOOKUP(B5,'5'!B:BC,54,0),"0") -> 10 | U5: กล่อง | V5: =+T5*D5 -> 197.7 | W5: =IFERROR(VLOOKUP(B5,'6'!B:BC,54,0),"0") -> 0 | X5: กล่อง | Y5: =+W5*D5 -> 0 | Z5: =IFERROR(VLOOKUP(B5,'7'!B:BC,54,0),"0") -> 0 | AA5: กล่อง | AB5: =+Z5*D5 -> 0 | AC5: =IFERROR(VLOOKUP(B5,'8'!B:BC,54,0),"0") -> 0 | AD5: กล่อง | AE5: =+AC5*D5 -> 0 | AF5: =IFERROR(VLOOKUP(B5,'9'!B:BC,54,0),"0") -> 0 | AG5: กล่อง | AH5: =+AF5*D5 -> 0 | AI5: =IFERROR(VLOOKUP(B5,'10'!B:BC,54,0),"0") -> 15 | AJ5: กล่อง | AK5: =+AI5*D5 -> 296.55 | AL5: =IFERROR(VLOOKUP(B5,'11'!B:BC,54,0),"0") -> 0 | AM5: กล่อง | AN5: =+AL5*D5 -> 0 | AO5: =IFERROR(VLOOKUP(B5,'12'!B:BC,54,0),"0") -> 0 | AP5: กล่อง | AQ5: =+AO5*D5 -> 0 | AR5: =IFERROR(VLOOKUP(B5,'13'!B:BC,54,0),"0") -> 0 | AS5: กล่อง | AT5: =+AR5*D5 -> 0 | AU5: =IFERROR(VLOOKUP(B5,'14'!B:BC,54,0),"0") -> 0 | AV5: กล่อง | AW5: =+AU5*D5 -> 0 | AX5: =IFERROR(VLOOKUP(B5,'15'!B:BC,54,0),"0") -> 2 | AY5: กล่อง | AZ5: =+AX5*D5 -> 39.54 | BA5: =IFERROR(VLOOKUP(B5,'16'!B:BC,54,0),"0") -> 3 | BB5: กล่อง | BC5: =+BA5*D5 -> 59.31 | BD5: =IFERROR(VLOOKUP(B5,'17'!B:BC,54,0),"0") -> 0 | BE5: กล่อง | BF5: =+BD5*D5 -> 0 | BG5: =IFERROR(VLOOKUP(B5,'18'!B:BC,54,0),"0") -> 0 | BH5: กล่อง | BI5: =+BG5*D5 -> 0 | BJ5: =IFERROR(VLOOKUP(B5,'19'!B:BC,54,0),"0") -> 10 | BK5: กล่อง | BL5: =+BJ5*D5 -> 197.7 | BM5: =IFERROR(VLOOKUP(B5,'20'!B:BC,54,0),"0") -> 0 | BN5: กล่อง | BO5: =+BM5*D5 -> 0 | BP5: =IFERROR(VLOOKUP(B5,'21'!B:BC,54,0),"0") -> 0 | BQ5: กล่อง | BR5: =+BP5*D5 -> 0 | BS5: =IFERROR(VLOOKUP(B5,'22'!B:BC,54,0),"0") -> 0 | BT5: กล่อง | BU5: =+BS5*D5 -> 0 | BV5: =IFERROR(VLOOKUP(B5,'23'!B:BC,54,0),"0") -> 0 | BW5: กล่อง | BX5: =+BV5*D5 -> 0 | BY5: =IFERROR(VLOOKUP(B5,'24'!B:BC,54,0),"0") -> 5 | BZ5: กล่อง | CA5: =+BY5*D5 -> 98.85 | CB5: =IFERROR(VLOOKUP(B5,'25'!B:BC,54,0),"0") -> 0 | CC5: กล่อง | CD5: =+CB5*D5 -> 0 | CE5: =IFERROR(VLOOKUP(B5,'26'!B:BC,54,0),"0") -> 5 | CF5: กล่อง | CG5: =+CE5*D5 -> 98.85 | CH5: =IFERROR(VLOOKUP(B5,'27'!B:BC,54,0),"0") -> 0 | CI5: กล่อง | CJ5: =+CH5*D5 -> 0 | CK5: =IFERROR(VLOOKUP(B5,'28'!B:BC,54,0),"0") -> 0 | CL5: กล่อง | CM5: =+CK5*D5 -> 0 | CN5: =IFERROR(VLOOKUP(B5,'29'!B:BC,54,0),"0") -> 3 | CO5: กล่อง | CP5: =+CN5*D5 -> 59.31 | CQ5: =IFERROR(VLOOKUP(B5,'30'!B:BC,54,0),"0") -> 0 | CR5: กล่อง | CS5: =+CQ5*D5 -> 0 | CT5: =IFERROR(VLOOKUP(A5,#REF!,2,0),"0") -> 0 | CU5: กล่อง | CV5: =+CT5*D5 -> 0 | CW5: =IFERROR(VLOOKUP(B5,'B-plus'!A:D,4,0),"0") -> 0 | CX5: กล่อง | CY5: =+CW5*D5 -> 0
A6: 1100001 | B6: 1100001 | C6: ทาร์ตสับปะรดแบบชิ้น อร่อยนุ่ม (1 ชิ้น) | D6: 6.74 | E6: =+H6+K6+N6+Q6+T6+W6+Z6+AC6+AF6+AI6+AL6+AO6+AR6+AU6+AX6+BA6+BD6+BG6+BJ6+BM6+BP6+BS6+BV6+BY6+CB6+CE6+CH6+CK6+CN6+CQ6+CT6 -> 0 | F6: กล่อง | G6: =+E6*D6 -> 0 | H6: =IFERROR(VLOOKUP(B6,'1'!B:BC,54,0),"0") -> 0 | I6: กล่อง | J6: =+H6*D6 -> 0 | K6: =IFERROR(VLOOKUP(B6,'2'!B:BC,54,0),"0") -> 0 | L6: กล่อง | M6: =+K6*D6 -> 0 | N6: =IFERROR(VLOOKUP(B6,'3'!B:BC,54,0),"0") -> 0 | O6: กล่อง | P6: =+N6*D6 -> 0 | Q6: =IFERROR(VLOOKUP(B6,'4'!B:BC,54,0),"0") -> 0 | R6: กล่อง | S6: =+Q6*D6 -> 0 | T6: =IFERROR(VLOOKUP(B6,'5'!B:BC,54,0),"0") -> 0 | U6: กล่อง | V6: =+T6*D6 -> 0 | W6: =IFERROR(VLOOKUP(B6,'6'!B:BC,54,0),"0") -> 0 | X6: กล่อง | Y6: =+W6*D6 -> 0 | Z6: =IFERROR(VLOOKUP(B6,'7'!B:BC,54,0),"0") -> 0 | AA6: กล่อง | AB6: =+Z6*D6 -> 0 | AC6: =IFERROR(VLOOKUP(B6,'8'!B:BC,54,0),"0") -> 0 | AD6: กล่อง | AE6: =+AC6*D6 -> 0 | AF6: =IFERROR(VLOOKUP(B6,'9'!B:BC,54,0),"0") -> 0 | AG6: กล่อง | AH6: =+AF6*D6 -> 0 | AI6: =IFERROR(VLOOKUP(B6,'10'!B:BC,54,0),"0") -> 0 | AJ6: กล่อง | AK6: =+AI6*D6 -> 0 | AL6: =IFERROR(VLOOKUP(B6,'11'!B:BC,54,0),"0") -> 0 | AM6: กล่อง | AN6: =+AL6*D6 -> 0 | AO6: =IFERROR(VLOOKUP(B6,'12'!B:BC,54,0),"0") -> 0 | AP6: กล่อง | AQ6: =+AO6*D6 -> 0 | AR6: =IFERROR(VLOOKUP(B6,'13'!B:BC,54,0),"0") -> 0 | AS6: กล่อง | AT6: =+AR6*D6 -> 0 | AU6: =IFERROR(VLOOKUP(B6,'14'!B:BC,54,0),"0") -> 0 | AV6: กล่อง | AW6: =+AU6*D6 -> 0 | AX6: =IFERROR(VLOOKUP(B6,'15'!B:BC,54,0),"0") -> 0 | AY6: กล่อง | AZ6: =+AX6*D6 -> 0 | BA6: =IFERROR(VLOOKUP(B6,'16'!B:BC,54,0),"0") -> 0 | BB6: กล่อง | BC6: =+BA6*D6 -> 0 | BD6: =IFERROR(VLOOKUP(B6,'17'!B:BC,54,0),"0") -> 0 | BE6: กล่อง | BF6: =+BD6*D6 -> 0 | BG6: =IFERROR(VLOOKUP(B6,'18'!B:BC,54,0),"0") -> 0 | BH6: กล่อง | BI6: =+BG6*D6 -> 0 | BJ6: =IFERROR(VLOOKUP(B6,'19'!B:BC,54,0),"0") -> 0 | BK6: กล่อง | BL6: =+BJ6*D6 -> 0 | BM6: =IFERROR(VLOOKUP(B6,'20'!B:BC,54,0),"0") -> 0 | BN6: กล่อง | BO6: =+BM6*D6 -> 0 | BP6: =IFERROR(VLOOKUP(B6,'21'!B:BC,54,0),"0") -> 0 | BQ6: กล่อง | BR6: =+BP6*D6 -> 0 | BS6: =IFERROR(VLOOKUP(B6,'22'!B:BC,54,0),"0") -> 0 | BT6: กล่อง | BU6: =+BS6*D6 -> 0 | BV6: =IFERROR(VLOOKUP(B6,'23'!B:BC,54,0),"0") -> 0 | BW6: กล่อง | BX6: =+BV6*D6 -> 0 | BY6: =IFERROR(VLOOKUP(B6,'24'!B:BC,54,0),"0") -> 0 | BZ6: กล่อง | CA6: =+BY6*D6 -> 0 | CB6: =IFERROR(VLOOKUP(B6,'25'!B:BC,54,0),"0") -> 0 | CC6: กล่อง | CD6: =+CB6*D6 -> 0 | CE6: =IFERROR(VLOOKUP(B6,'26'!B:BC,54,0),"0") -> 0 | CF6: กล่อง | CG6: =+CE6*D6 -> 0 | CH6: =IFERROR(VLOOKUP(B6,'27'!B:BC,54,0),"0") -> 0 | CI6: กล่อง | CJ6: =+CH6*D6 -> 0 | CK6: =IFERROR(VLOOKUP(B6,'28'!B:BC,54,0),"0") -> 0 | CL6: กล่อง | CM6: =+CK6*D6 -> 0 | CN6: =IFERROR(VLOOKUP(B6,'29'!B:BC,54,0),"0") -> 0 | CO6: กล่อง | CP6: =+CN6*D6 -> 0 | CQ6: =IFERROR(VLOOKUP(B6,'30'!B:BC,54,0),"0") -> 0 | CR6: กล่อง | CS6: =+CQ6*D6 -> 0 | CT6: =IFERROR(VLOOKUP(A6,#REF!,2,0),"0") -> 0 | CU6: กล่อง | CV6: =+CT6*D6 -> 0 | CW6: =IFERROR(VLOOKUP(B6,'B-plus'!A:D,4,0),"0") -> 0 | CX6: กล่อง | CY6: =+CW6*D6 -> 0
A7: 1100002 | B7: 1100002 | C7: ทาร์ตสับปะรด (ทาร์ตสับปะรดกล่อง 4 ชิ้น) | D7: 18.48 | E7: =+H7+K7+N7+Q7+T7+W7+Z7+AC7+AF7+AI7+AL7+AO7+AR7+AU7+AX7+BA7+BD7+BG7+BJ7+BM7+BP7+BS7+BV7+BY7+CB7+CE7+CH7+CK7+CN7+CQ7+CT7 -> 6 | F7: ถุง | G7: =+E7*D7 -> 110.88 | H7: =IFERROR(VLOOKUP(B7,'1'!B:BC,54,0),"0") -> 0 | I7: ถุง | J7: =+H7*D7 -> 0 | K7: =IFERROR(VLOOKUP(B7,'2'!B:BC,54,0),"0") -> 0 | L7: ถุง | M7: =+K7*D7 -> 0 | N7: =IFERROR(VLOOKUP(B7,'3'!B:BC,54,0),"0") -> 0 | O7: ถุง | P7: =+N7*D7 -> 0 | Q7: =IFERROR(VLOOKUP(B7,'4'!B:BC,54,0),"0") -> 0 | R7: ถุง | S7: =+Q7*D7 -> 0 | T7: =IFERROR(VLOOKUP(B7,'5'!B:BC,54,0),"0") -> 0 | U7: ถุง | V7: =+T7*D7 -> 0 | W7: =IFERROR(VLOOKUP(B7,'6'!B:BC,54,0),"0") -> 0 | X7: ถุง | Y7: =+W7*D7 -> 0 | Z7: =IFERROR(VLOOKUP(B7,'7'!B:BC,54,0),"0") -> 0 | AA7: ถุง | AB7: =+Z7*D7 -> 0 | AC7: =IFERROR(VLOOKUP(B7,'8'!B:BC,54,0),"0") -> 0 | AD7: ถุง | AE7: =+AC7*D7 -> 0 | AF7: =IFERROR(VLOOKUP(B7,'9'!B:BC,54,0),"0") -> 0 | AG7: ถุง | AH7: =+AF7*D7 -> 0 | AI7: =IFERROR(VLOOKUP(B7,'10'!B:BC,54,0),"0") -> 0 | AJ7: ถุง | AK7: =+AI7*D7 -> 0 | AL7: =IFERROR(VLOOKUP(B7,'11'!B:BC,54,0),"0") -> 0 | AM7: ถุง | AN7: =+AL7*D7 -> 0 | AO7: =IFERROR(VLOOKUP(B7,'12'!B:BC,54,0),"0") -> 0 | AP7: ถุง | AQ7: =+AO7*D7 -> 0 | AR7: =IFERROR(VLOOKUP(B7,'13'!B:BC,54,0),"0") -> 0 | AS7: ถุง | AT7: =+AR7*D7 -> 0 | AU7: =IFERROR(VLOOKUP(B7,'14'!B:BC,54,0),"0") -> 0 | AV7: ถุง | AW7: =+AU7*D7 -> 0 | AX7: =IFERROR(VLOOKUP(B7,'15'!B:BC,54,0),"0") -> 0 | AY7: ถุง | AZ7: =+AX7*D7 -> 0 | BA7: =IFERROR(VLOOKUP(B7,'16'!B:BC,54,0),"0") -> 3 | BB7: ถุง | BC7: =+BA7*D7 -> 55.44 | BD7: =IFERROR(VLOOKUP(B7,'17'!B:BC,54,0),"0") -> 0 | BE7: ถุง | BF7: =+BD7*D7 -> 0 | BG7: =IFERROR(VLOOKUP(B7,'18'!B:BC,54,0),"0") -> 0 | BH7: ถุง | BI7: =+BG7*D7 -> 0 | BJ7: =IFERROR(VLOOKUP(B7,'19'!B:BC,54,0),"0") -> 0 | BK7: ถุง | BL7: =+BJ7*D7 -> 0 | BM7: =IFERROR(VLOOKUP(B7,'20'!B:BC,54,0),"0") -> 0 | BN7: ถุง | BO7: =+BM7*D7 -> 0 | BP7: =IFERROR(VLOOKUP(B7,'21'!B:BC,54,0),"0") -> 0 | BQ7: ถุง | BR7: =+BP7*D7 -> 0 | BS7: =IFERROR(VLOOKUP(B7,'22'!B:BC,54,0),"0") -> 0 | BT7: ถุง | BU7: =+BS7*D7 -> 0 | BV7: =IFERROR(VLOOKUP(B7,'23'!B:BC,54,0),"0") -> 0 | BW7: ถุง | BX7: =+BV7*D7 -> 0 | BY7: =IFERROR(VLOOKUP(B7,'24'!B:BC,54,0),"0") -> 0 | BZ7: ถุง | CA7: =+BY7*D7 -> 0 | CB7: =IFERROR(VLOOKUP(B7,'25'!B:BC,54,0),"0") -> 0 | CC7: ถุง | CD7: =+CB7*D7 -> 0 | CE7: =IFERROR(VLOOKUP(B7,'26'!B:BC,54,0),"0") -> 0 | CF7: ถุง | CG7: =+CE7*D7 -> 0 | CH7: =IFERROR(VLOOKUP(B7,'27'!B:BC,54,0),"0") -> 0 | CI7: ถุง | CJ7: =+CH7*D7 -> 0 | CK7: =IFERROR(VLOOKUP(B7,'28'!B:BC,54,0),"0") -> 0 | CL7: ถุง | CM7: =+CK7*D7 -> 0 | CN7: =IFERROR(VLOOKUP(B7,'29'!B:BC,54,0),"0") -> 0 | CO7: ถุง | CP7: =+CN7*D7 -> 0 | CQ7: =IFERROR(VLOOKUP(B7,'30'!B:BC,54,0),"0") -> 3 | CR7: ถุง | CS7: =+CQ7*D7 -> 55.44 | CT7: =IFERROR(VLOOKUP(A7,#REF!,2,0),"0") -> 0 | CU7: ถุง | CV7: =+CT7*D7 -> 0 | CW7: =IFERROR(VLOOKUP(B7,'B-plus'!A:D,4,0),"0") -> 0 | CX7: ถุง | CY7: =+CW7*D7 -> 0
A8: 1111001 | B8: 1111001 | C8: ชิฟฟอนไม่มีไส้เเบบเเยกชิ้น เลือกรสชาติได้ (คละรส) | D8: 0 | E8: =+H8+K8+N8+Q8+T8+W8+Z8+AC8+AF8+AI8+AL8+AO8+AR8+AU8+AX8+BA8+BD8+BG8+BJ8+BM8+BP8+BS8+BV8+BY8+CB8+CE8+CH8+CK8+CN8+CQ8+CT8 -> 740 | F8: ชิ้น | G8: =+E8*D8 -> 0 | H8: =IFERROR(VLOOKUP(B8,'1'!B:BC,54,0),"0") -> 30 | I8: ชิ้น | J8: =+H8*D8 -> 0 | K8: =IFERROR(VLOOKUP(B8,'2'!B:BC,54,0),"0") -> 30 | L8: ชิ้น | M8: =+K8*D8 -> 0 | N8: =IFERROR(VLOOKUP(B8,'3'!B:BC,54,0),"0") -> 20 | O8: ชิ้น | P8: =+N8*D8 -> 0 | Q8: =IFERROR(VLOOKUP(B8,'4'!B:BC,54,0),"0") -> 0 | R8: ชิ้น | S8: =+Q8*D8 -> 0 | T8: =IFERROR(VLOOKUP(B8,'5'!B:BC,54,0),"0") -> 0 | U8: ชิ้น | V8: =+T8*D8 -> 0 | W8: =IFERROR(VLOOKUP(B8,'6'!B:BC,54,0),"0") -> 0 | X8: ชิ้น | Y8: =+W8*D8 -> 0 | Z8: =IFERROR(VLOOKUP(B8,'7'!B:BC,54,0),"0") -> 0 | AA8: ชิ้น | AB8: =+Z8*D8 -> 0 | AC8: =IFERROR(VLOOKUP(B8,'8'!B:BC,54,0),"0") -> 0 | AD8: ชิ้น | AE8: =+AC8*D8 -> 0 | AF8: =IFERROR(VLOOKUP(B8,'9'!B:BC,54,0),"0") -> 0 | AG8: ชิ้น | AH8: =+AF8*D8 -> 0 | AI8: =IFERROR(VLOOKUP(B8,'10'!B:BC,54,0),"0") -> 0 | AJ8: ชิ้น | AK8: =+AI8*D8 -> 0 | AL8: =IFERROR(VLOOKUP(B8,'11'!B:BC,54,0),"0") -> 30 | AM8: ชิ้น | AN8: =+AL8*D8 -> 0 | AO8: =IFERROR(VLOOKUP(B8,'12'!B:BC,54,0),"0") -> 0 | AP8: ชิ้น | AQ8: =+AO8*D8 -> 0 | AR8: =IFERROR(VLOOKUP(B8,'13'!B:BC,54,0),"0") -> 30 | AS8: ชิ้น | AT8: =+AR8*D8 -> 0 | AU8: =IFERROR(VLOOKUP(B8,'14'!B:BC,54,0),"0") -> 50 | AV8: ชิ้น | AW8: =+AU8*D8 -> 0 | AX8: =IFERROR(VLOOKUP(B8,'15'!B:BC,54,0),"0") -> 50 | AY8: ชิ้น | AZ8: =+AX8*D8 -> 0 | BA8: =IFERROR(VLOOKUP(B8,'16'!B:BC,54,0),"0") -> 150 | BB8: ชิ้น | BC8: =+BA8*D8 -> 0 | BD8: =IFERROR(VLOOKUP(B8,'17'!B:BC,54,0),"0") -> 0 | BE8: ชิ้น | BF8: =+BD8*D8 -> 0 | BG8: =IFERROR(VLOOKUP(B8,'18'!B:BC,54,0),"0") -> 30 | BH8: ชิ้น | BI8: =+BG8*D8 -> 0 | BJ8: =IFERROR(VLOOKUP(B8,'19'!B:BC,54,0),"0") -> 70 | BK8: ชิ้น | BL8: =+BJ8*D8 -> 0 | BM8: =IFERROR(VLOOKUP(B8,'20'!B:BC,54,0),"0") -> 30 | BN8: ชิ้น | BO8: =+BM8*D8 -> 0 | BP8: =IFERROR(VLOOKUP(B8,'21'!B:BC,54,0),"0") -> 0 | BQ8: ชิ้น | BR8: =+BP8*D8 -> 0 | BS8: =IFERROR(VLOOKUP(B8,'22'!B:BC,54,0),"0") -> 0 | BT8: ชิ้น | BU8: =+BS8*D8 -> 0 | BV8: =IFERROR(VLOOKUP(B8,'23'!B:BC,54,0),"0") -> 20 | BW8: ชิ้น | BX8: =+BV8*D8 -> 0 | BY8: =IFERROR(VLOOKUP(B8,'24'!B:BC,54,0),"0") -> 150 | BZ8: ชิ้น | CA8: =+BY8*D8 -> 0 | CB8: =IFERROR(VLOOKUP(B8,'25'!B:BC,54,0),"0") -> 20 | CC8: ชิ้น | CD8: =+CB8*D8 -> 0 | CE8: =IFERROR(VLOOKUP(B8,'26'!B:BC,54,0),"0") -> 0 | CF8: ชิ้น | CG8: =+CE8*D8 -> 0 | CH8: =IFERROR(VLOOKUP(B8,'27'!B:BC,54,0),"0") -> 0 | CI8: ชิ้น | CJ8: =+CH8*D8 -> 0 | CK8: =IFERROR(VLOOKUP(B8,'28'!B:BC,54,0),"0") -> 0 | CL8: ชิ้น | CM8: =+CK8*D8 -> 0 | CN8: =IFERROR(VLOOKUP(B8,'29'!B:BC,54,0),"0") -> 30 | CO8: ชิ้น | CP8: =+CN8*D8 -> 0 | CQ8: =IFERROR(VLOOKUP(B8,'30'!B:BC,54,0),"0") -> 0 | CR8: ชิ้น | CS8: =+CQ8*D8 -> 0 | CT8: =IFERROR(VLOOKUP(A8,#REF!,2,0),"0") -> 0 | CU8: ชิ้น | CV8: =+CT8*D8 -> 0 | CW8: =IFERROR(VLOOKUP(B8,'B-plus'!A:D,4,0),"0") -> 0 | CX8: ชิ้น | CY8: =+CW8*D8 -> 0
A9: 1111002 | B9: 1111002 | C9: ชิฟฟ่อนไม่มีไส้ แบบกล่อง8ชิ้น รวมรส | D9: 33.22 | E9: =+H9+K9+N9+Q9+T9+W9+Z9+AC9+AF9+AI9+AL9+AO9+AR9+AU9+AX9+BA9+BD9+BG9+BJ9+BM9+BP9+BS9+BV9+BY9+CB9+CE9+CH9+CK9+CN9+CQ9+CT9 -> 2137 | F9: กล่อง | G9: =+E9*D9 -> 70991.14 | H9: =IFERROR(VLOOKUP(B9,'1'!B:BC,54,0),"0") -> 29 | I9: กล่อง | J9: =+H9*D9 -> 963.38 | K9: =IFERROR(VLOOKUP(B9,'2'!B:BC,54,0),"0") -> 69 | L9: กล่อง | M9: =+K9*D9 -> 2292.18 | N9: =IFERROR(VLOOKUP(B9,'3'!B:BC,54,0),"0") -> 75 | O9: กล่อง | P9: =+N9*D9 -> 2491.5 | Q9: =IFERROR(VLOOKUP(B9,'4'!B:BC,54,0),"0") -> 64 | R9: กล่อง | S9: =+Q9*D9 -> 2126.08 | T9: =IFERROR(VLOOKUP(B9,'5'!B:BC,54,0),"0") -> 83 | U9: กล่อง | V9: =+T9*D9 -> 2757.26 | W9: =IFERROR(VLOOKUP(B9,'6'!B:BC,54,0),"0") -> 115 | X9: กล่อง | Y9: =+W9*D9 -> 3820.3 | Z9: =IFERROR(VLOOKUP(B9,'7'!B:BC,54,0),"0") -> 134 | AA9: กล่อง | AB9: =+Z9*D9 -> 4451.48 | AC9: =IFERROR(VLOOKUP(B9,'8'!B:BC,54,0),"0") -> 92 | AD9: กล่อง | AE9: =+AC9*D9 -> 3056.24 | AF9: =IFERROR(VLOOKUP(B9,'9'!B:BC,54,0),"0") -> 76 | AG9: กล่อง | AH9: =+AF9*D9 -> 2524.72 | AI9: =IFERROR(VLOOKUP(B9,'10'!B:BC,54,0),"0") -> 82 | AJ9: กล่อง | AK9: =+AI9*D9 -> 2724.04 | AL9: =IFERROR(VLOOKUP(B9,'11'!B:BC,54,0),"0") -> 90 | AM9: กล่อง | AN9: =+AL9*D9 -> 2989.8 | AO9: =IFERROR(VLOOKUP(B9,'12'!B:BC,54,0),"0") -> 93 | AP9: กล่อง | AQ9: =+AO9*D9 -> 3089.46 | AR9: =IFERROR(VLOOKUP(B9,'13'!B:BC,54,0),"0") -> 25 | AS9: กล่อง | AT9: =+AR9*D9 -> 830.5 | AU9: =IFERROR(VLOOKUP(B9,'14'!B:BC,54,0),"0") -> 83 | AV9: กล่อง | AW9: =+AU9*D9 -> 2757.26 | AX9: =IFERROR(VLOOKUP(B9,'15'!B:BC,54,0),"0") -> 61 | AY9: กล่อง | AZ9: =+AX9*D9 -> 2026.42 | BA9: =IFERROR(VLOOKUP(B9,'16'!B:BC,54,0),"0") -> 76 | BB9: กล่อง | BC9: =+BA9*D9 -> 2524.72 | BD9: =IFERROR(VLOOKUP(B9,'17'!B:BC,54,0),"0") -> 78 | BE9: กล่อง | BF9: =+BD9*D9 -> 2591.16 | BG9: =IFERROR(VLOOKUP(B9,'18'!B:BC,54,0),"0") -> 88 | BH9: กล่อง | BI9: =+BG9*D9 -> 2923.36 | BJ9: =IFERROR(VLOOKUP(B9,'19'!B:BC,54,0),"0") -> 35 | BK9: กล่อง | BL9: =+BJ9*D9 -> 1162.7 | BM9: =IFERROR(VLOOKUP(B9,'20'!B:BC,54,0),"0") -> 93 | BN9: กล่อง | BO9: =+BM9*D9 -> 3089.46 | BP9: =IFERROR(VLOOKUP(B9,'21'!B:BC,54,0),"0") -> 48 | BQ9: กล่อง | BR9: =+BP9*D9 -> 1594.56 | BS9: =IFERROR(VLOOKUP(B9,'22'!B:BC,54,0),"0") -> 61 | BT9: กล่อง | BU9: =+BS9*D9 -> 2026.42 | BV9: =IFERROR(VLOOKUP(B9,'23'!B:BC,54,0),"0") -> 59 | BW9: กล่อง | BX9: =+BV9*D9 -> 1959.98 | BY9: =IFERROR(VLOOKUP(B9,'24'!B:BC,54,0),"0") -> 146 | BZ9: กล่อง | CA9: =+BY9*D9 -> 4850.12 | CB9: =IFERROR(VLOOKUP(B9,'25'!B:BC,54,0),"0") -> 79 | CC9: กล่อง | CD9: =+CB9*D9 -> 2624.38 | CE9: =IFERROR(VLOOKUP(B9,'26'!B:BC,54,0),"0") -> 101 | CF9: กล่อง | CG9: =+CE9*D9 -> 3355.22 | CH9: =IFERROR(VLOOKUP(B9,'27'!B:BC,54,0),"0") -> 14 | CI9: กล่อง | CJ9: =+CH9*D9 -> 465.08 | CK9: =IFERROR(VLOOKUP(B9,'28'!B:BC,54,0),"0") -> 38 | CL9: กล่อง | CM9: =+CK9*D9 -> 1262.36 | CN9: =IFERROR(VLOOKUP(B9,'29'!B:BC,54,0),"0") -> 32 | CO9: กล่อง | CP9: =+CN9*D9 -> 1063.04 | CQ9: =IFERROR(VLOOKUP(B9,'30'!B:BC,54,0),"0") -> 18 | CR9: กล่อง | CS9: =+CQ9*D9 -> 597.96 | CT9: =IFERROR(VLOOKUP(A9,#REF!,2,0),"0") -> 0 | CU9: กล่อง | CV9: =+CT9*D9 -> 0 | CW9: =IFERROR(VLOOKUP(B9,'B-plus'!A:D,4,0),"0") -> 0 | CX9: กล่อง | CY9: =+CW9*D9 -> 0
A10: 1111008 | B10: 1111008 | C10: ชิฟฟ่อน สอดไส้แยม ขนาด3 ชิ้น มีรสให้เลือก 7 รส (รวมรส) | D10: 18.3 | E10: =+H10+K10+N10+Q10+T10+W10+Z10+AC10+AF10+AI10+AL10+AO10+AR10+AU10+AX10+BA10+BD10+BG10+BJ10+BM10+BP10+BS10+BV10+BY10+CB10+CE10+CH10+CK10+CN10+CQ10+CT10 -> 3904 | F10: กระปุก | G10: =+E10*D10 -> 71443.2 | H10: =IFERROR(VLOOKUP(B10,'1'!B:BC,54,0),"0") -> 126 | I10: กระปุก | J10: =+H10*D10 -> 2305.8 | K10: =IFERROR(VLOOKUP(B10,'2'!B:BC,54,0),"0") -> 126 | L10: กระปุก | M10: =+K10*D10 -> 2305.8 | N10: =IFERROR(VLOOKUP(B10,'3'!B:BC,54,0),"0") -> 145 | O10: กระปุก | P10: =+N10*D10 -> 2653.5 | Q10: =IFERROR(VLOOKUP(B10,'4'!B:BC,54,0),"0") -> 159 | R10: กระปุก | S10: =+Q10*D10 -> 2909.7 | T10: =IFERROR(VLOOKUP(B10,'5'!B:BC,54,0),"0") -> 169 | U10: กระปุก | V10: =+T10*D10 -> 3092.7 | W10: =IFERROR(VLOOKUP(B10,'6'!B:BC,54,0),"0") -> 175 | X10: กระปุก | Y10: =+W10*D10 -> 3202.5 | Z10: =IFERROR(VLOOKUP(B10,'7'!B:BC,54,0),"0") -> 176 | AA10: กระปุก | AB10: =+Z10*D10 -> 3220.8 | AC10: =IFERROR(VLOOKUP(B10,'8'!B:BC,54,0),"0") -> 180 | AD10: กระปุก | AE10: =+AC10*D10 -> 3294 | AF10: =IFERROR(VLOOKUP(B10,'9'!B:BC,54,0),"0") -> 145 | AG10: กระปุก | AH10: =+AF10*D10 -> 2653.5 | AI10: =IFERROR(VLOOKUP(B10,'10'!B:BC,54,0),"0") -> 161 | AJ10: กระปุก | AK10: =+AI10*D10 -> 2946.3 | AL10: =IFERROR(VLOOKUP(B10,'11'!B:BC,54,0),"0") -> 160 | AM10: กระปุก | AN10: =+AL10*D10 -> 2928 | AO10: =IFERROR(VLOOKUP(B10,'12'!B:BC,54,0),"0") -> 158 | AP10: กระปุก | AQ10: =+AO10*D10 -> 2891.4 | AR10: =IFERROR(VLOOKUP(B10,'13'!B:BC,54,0),"0") -> 197 | AS10: กระปุก | AT10: =+AR10*D10 -> 3605.1 | AU10: =IFERROR(VLOOKUP(B10,'14'!B:BC,54,0),"0") -> 179 | AV10: กระปุก | AW10: =+AU10*D10 -> 3275.7 | AX10: =IFERROR(VLOOKUP(B10,'15'!B:BC,54,0),"0") -> 117 | AY10: กระปุก | AZ10: =+AX10*D10 -> 2141.1 | BA10: =IFERROR(VLOOKUP(B10,'16'!B:BC,54,0),"0") -> 91 | BB10: กระปุก | BC10: =+BA10*D10 -> 1665.3 | BD10: =IFERROR(VLOOKUP(B10,'17'!B:BC,54,0),"0") -> 135 | BE10: กระปุก | BF10: =+BD10*D10 -> 2470.5 | BG10: =IFERROR(VLOOKUP(B10,'18'!B:BC,54,0),"0") -> 149 | BH10: กระปุก | BI10: =+BG10*D10 -> 2726.7 | BJ10: =IFERROR(VLOOKUP(B10,'19'!B:BC,54,0),"0") -> 125 | BK10: กระปุก | BL10: =+BJ10*D10 -> 2287.5 | BM10: =IFERROR(VLOOKUP(B10,'20'!B:BC,54,0),"0") -> 43 | BN10: กระปุก | BO10: =+BM10*D10 -> 786.9 | BP10: =IFERROR(VLOOKUP(B10,'21'!B:BC,54,0),"0") -> 121 | BQ10: กระปุก | BR10: =+BP10*D10 -> 2214.3 | BS10: =IFERROR(VLOOKUP(B10,'22'!B:BC,54,0),"0") -> 150 | BT10: กระปุก | BU10: =+BS10*D10 -> 2745 | BV10: =IFERROR(VLOOKUP(B10,'23'!B:BC,54,0),"0") -> 133 | BW10: กระปุก | BX10: =+BV10*D10 -> 2433.9 | BY10: =IFERROR(VLOOKUP(B10,'24'!B:BC,54,0),"0") -> 126 | BZ10: กระปุก | CA10: =+BY10*D10 -> 2305.8 | CB10: =IFERROR(VLOOKUP(B10,'25'!B:BC,54,0),"0") -> 117 | CC10: กระปุก | CD10: =+CB10*D10 -> 2141.1 | CE10: =IFERROR(VLOOKUP(B10,'26'!B:BC,54,0),"0") -> 97 | CF10: กระปุก | CG10: =+CE10*D10 -> 1775.1 | CH10: =IFERROR(VLOOKUP(B10,'27'!B:BC,54,0),"0") -> 53 | CI10: กระปุก | CJ10: =+CH10*D10 -> 969.9 | CK10: =IFERROR(VLOOKUP(B10,'28'!B:BC,54,0),"0") -> 55 | CL10: กระปุก | CM10: =+CK10*D10 -> 1006.5 | CN10: =IFERROR(VLOOKUP(B10,'29'!B:BC,54,0),"0") -> 52 | CO10: กระปุก | CP10: =+CN10*D10 -> 951.6 | CQ10: =IFERROR(VLOOKUP(B10,'30'!B:BC,54,0),"0") -> 84 | CR10: กระปุก | CS10: =+CQ10*D10 -> 1537.2 | CT10: =IFERROR(VLOOKUP(A10,#REF!,2,0),"0") -> 0 | CU10: กระปุก | CV10: =+CT10*D10 -> 0 | CW10: =IFERROR(VLOOKUP(B10,'B-plus'!A:D,4,0),"0") -> 0 | CX10: กระปุก | CY10: =+CW10*D10 -> 0
A11: 1111009 | B11: 1111009 | C11: ชิฟฟ่อนสอดไส้ แยม 1กล่อง มี6ชิ้น (รวมรส) | D11: 28.61 | E11: =+H11+K11+N11+Q11+T11+W11+Z11+AC11+AF11+AI11+AL11+AO11+AR11+AU11+AX11+BA11+BD11+BG11+BJ11+BM11+BP11+BS11+BV11+BY11+CB11+CE11+CH11+CK11+CN11+CQ11+CT11 -> 170 | F11: ถุง | G11: =+E11*D11 -> 4863.7 | H11: =IFERROR(VLOOKUP(B11,'1'!B:BC,54,0),"0") -> 9 | I11: ถุง | J11: =+H11*D11 -> 257.49 | K11: =IFERROR(VLOOKUP(B11,'2'!B:BC,54,0),"0") -> 9 | L11: ถุง | M11: =+K11*D11 -> 257.49 | N11: =IFERROR(VLOOKUP(B11,'3'!B:BC,54,0),"0") -> 9 | O11: ถุง | P11: =+N11*D11 -> 257.49 | Q11: =IFERROR(VLOOKUP(B11,'4'!B:BC,54,0),"0") -> 0 | R11: ถุง | S11: =+Q11*D11 -> 0 | T11: =IFERROR(VLOOKUP(B11,'5'!B:BC,54,0),"0") -> 7 | U11: ถุง | V11: =+T11*D11 -> 200.27 | W11: =IFERROR(VLOOKUP(B11,'6'!B:BC,54,0),"0") -> 13 | X11: ถุง | Y11: =+W11*D11 -> 371.93 | Z11: =IFERROR(VLOOKUP(B11,'7'!B:BC,54,0),"0") -> 6 | AA11: ถุง | AB11: =+Z11*D11 -> 171.66 | AC11: =IFERROR(VLOOKUP(B11,'8'!B:BC,54,0),"0") -> 4 | AD11: ถุง | AE11: =+AC11*D11 -> 114.44 | AF11: =IFERROR(VLOOKUP(B11,'9'!B:BC,54,0),"0") -> 12 | AG11: ถุง | AH11: =+AF11*D11 -> 343.32 | AI11: =IFERROR(VLOOKUP(B11,'10'!B:BC,54,0),"0") -> 3 | AJ11: ถุง | AK11: =+AI11*D11 -> 85.83 | AL11: =IFERROR(VLOOKUP(B11,'11'!B:BC,54,0),"0") -> 4 | AM11: ถุง | AN11: =+AL11*D11 -> 114.44 | AO11: =IFERROR(VLOOKUP(B11,'12'!B:BC,54,0),"0") -> 4 | AP11: ถุง | AQ11: =+AO11*D11 -> 114.44 | AR11: =IFERROR(VLOOKUP(B11,'13'!B:BC,54,0),"0") -> 8 | AS11: ถุง | AT11: =+AR11*D11 -> 228.88 | AU11: =IFERROR(VLOOKUP(B11,'14'!B:BC,54,0),"0") -> 6 | AV11: ถุง | AW11: =+AU11*D11 -> 171.66 | AX11: =IFERROR(VLOOKUP(B11,'15'!B:BC,54,0),"0") -> 10 | AY11: ถุง | AZ11: =+AX11*D11 -> 286.1 | BA11: =IFERROR(VLOOKUP(B11,'16'!B:BC,54,0),"0") -> 0 | BB11: ถุง | BC11: =+BA11*D11 -> 0 | BD11: =IFERROR(VLOOKUP(B11,'17'!B:BC,54,0),"0") -> 4 | BE11: ถุง | BF11: =+BD11*D11 -> 114.44 | BG11: =IFERROR(VLOOKUP(B11,'18'!B:BC,54,0),"0") -> 5 | BH11: ถุง | BI11: =+BG11*D11 -> 143.05 | BJ11: =IFERROR(VLOOKUP(B11,'19'!B:BC,54,0),"0") -> 5 | BK11: ถุง | BL11: =+BJ11*D11 -> 143.05 | BM11: =IFERROR(VLOOKUP(B11,'20'!B:BC,54,0),"0") -> 6 | BN11: ถุง | BO11: =+BM11*D11 -> 171.66 | BP11: =IFERROR(VLOOKUP(B11,'21'!B:BC,54,0),"0") -> 3 | BQ11: ถุง | BR11: =+BP11*D11 -> 85.83 | BS11: =IFERROR(VLOOKUP(B11,'22'!B:BC,54,0),"0") -> 4 | BT11: ถุง | BU11: =+BS11*D11 -> 114.44 | BV11: =IFERROR(VLOOKUP(B11,'23'!B:BC,54,0),"0") -> 8 | BW11: ถุง | BX11: =+BV11*D11 -> 228.88 | BY11: =IFERROR(VLOOKUP(B11,'24'!B:BC,54,0),"0") -> 5 | BZ11: ถุง | CA11: =+BY11*D11 -> 143.05 | CB11: =IFERROR(VLOOKUP(B11,'25'!B:BC,54,0),"0") -> 6 | CC11: ถุง | CD11: =+CB11*D11 -> 171.66 | CE11: =IFERROR(VLOOKUP(B11,'26'!B:BC,54,0),"0") -> 8 | CF11: ถุง | CG11: =+CE11*D11 -> 228.88 | CH11: =IFERROR(VLOOKUP(B11,'27'!B:BC,54,0),"0") -> 5 | CI11: ถุง | CJ11: =+CH11*D11 -> 143.05 | CK11: =IFERROR(VLOOKUP(B11,'28'!B:BC,54,0),"0") -> 2 | CL11: ถุง | CM11: =+CK11*D11 -> 57.22 | CN11: =IFERROR(VLOOKUP(B11,'29'!B:BC,54,0),"0") -> 4 | CO11: ถุง | CP11: =+CN11*D11 -> 114.44 | CQ11: =IFERROR(VLOOKUP(B11,'30'!B:BC,54,0),"0") -> 1 | CR11: ถุง | CS11: =+CQ11*D11 -> 28.61 | CT11: =IFERROR(VLOOKUP(A11,#REF!,2,0),"0") -> 0 | CU11: ถุง | CV11: =+CT11*D11 -> 0 | CW11: =IFERROR(VLOOKUP(B11,'B-plus'!A:D,4,0),"0") -> 0 | CX11: ถุง | CY11: =+CW11*D11 -> 0
A12: 1111020 | B12: 1111020 | C12: ชิฟฟ่อนสอดไส้ แยม 1กล่อง มี6ชิ้น (ฝอยทอง) | D12: 37.59 | E12: =+H12+K12+N12+Q12+T12+W12+Z12+AC12+AF12+AI12+AL12+AO12+AR12+AU12+AX12+BA12+BD12+BG12+BJ12+BM12+BP12+BS12+BV12+BY12+CB12+CE12+CH12+CK12+CN12+CQ12+CT12 -> 0 | F12: ชิ้น | G12: =+E12*D12 -> 0 | H12: =IFERROR(VLOOKUP(B12,'1'!B:BC,54,0),"0") -> 0 | I12: ชิ้น | J12: =+H12*D12 -> 0 | K12: =IFERROR(VLOOKUP(B12,'2'!B:BC,54,0),"0") -> 0 | L12: ชิ้น | M12: =+K12*D12 -> 0 | N12: =IFERROR(VLOOKUP(B12,'3'!B:BC,54,0),"0") -> 0 | O12: ชิ้น | P12: =+N12*D12 -> 0 | Q12: =IFERROR(VLOOKUP(B12,'4'!B:BC,54,0),"0") -> 0 | R12: ชิ้น | S12: =+Q12*D12 -> 0 | T12: =IFERROR(VLOOKUP(B12,'5'!B:BC,54,0),"0") -> 0 | U12: ชิ้น | V12: =+T12*D12 -> 0 | W12: =IFERROR(VLOOKUP(B12,'6'!B:BC,54,0),"0") -> 0 | X12: ชิ้น | Y12: =+W12*D12 -> 0 | Z12: =IFERROR(VLOOKUP(B12,'7'!B:BC,54,0),"0") -> 0 | AA12: ชิ้น | AB12: =+Z12*D12 -> 0 | AC12: =IFERROR(VLOOKUP(B12,'8'!B:BC,54,0),"0") -> 0 | AD12: ชิ้น | AE12: =+AC12*D12 -> 0 | AF12: =IFERROR(VLOOKUP(B12,'9'!B:BC,54,0),"0") -> 0 | AG12: ชิ้น | AH12: =+AF12*D12 -> 0 | AI12: =IFERROR(VLOOKUP(B12,'10'!B:BC,54,0),"0") -> 0 | AJ12: ชิ้น | AK12: =+AI12*D12 -> 0 | AL12: =IFERROR(VLOOKUP(B12,'11'!B:BC,54,0),"0") -> 0 | AM12: ชิ้น | AN12: =+AL12*D12 -> 0 | AO12: =IFERROR(VLOOKUP(B12,'12'!B:BC,54,0),"0") -> 0 | AP12: ชิ้น | AQ12: =+AO12*D12 -> 0 | AR12: =IFERROR(VLOOKUP(B12,'13'!B:BC,54,0),"0") -> 0 | AS12: ชิ้น | AT12: =+AR12*D12 -> 0 | AU12: =IFERROR(VLOOKUP(B12,'14'!B:BC,54,0),"0") -> 0 | AV12: ชิ้น | AW12: =+AU12*D12 -> 0 | AX12: =IFERROR(VLOOKUP(B12,'15'!B:BC,54,0),"0") -> 0 | AY12: ชิ้น | AZ12: =+AX12*D12 -> 0 | BA12: =IFERROR(VLOOKUP(B12,'16'!B:BC,54,0),"0") -> 0 | BB12: ชิ้น | BC12: =+BA12*D12 -> 0 | BD12: =IFERROR(VLOOKUP(B12,'17'!B:BC,54,0),"0") -> 0 | BE12: ชิ้น | BF12: =+BD12*D12 -> 0 | BG12: =IFERROR(VLOOKUP(B12,'18'!B:BC,54,0),"0") -> 0 | BH12: ชิ้น | BI12: =+BG12*D12 -> 0 | BJ12: =IFERROR(VLOOKUP(B12,'19'!B:BC,54,0),"0") -> 0 | BK12: ชิ้น | BL12: =+BJ12*D12 -> 0 | BM12: =IFERROR(VLOOKUP(B12,'20'!B:BC,54,0),"0") -> 0 | BN12: ชิ้น | BO12: =+BM12*D12 -> 0 | BP12: =IFERROR(VLOOKUP(B12,'21'!B:BC,54,0),"0") -> 0 | BQ12: ชิ้น | BR12: =+BP12*D12 -> 0 | BS12: =IFERROR(VLOOKUP(B12,'22'!B:BC,54,0),"0") -> 0 | BT12: ชิ้น | BU12: =+BS12*D12 -> 0 | BV12: =IFERROR(VLOOKUP(B12,'23'!B:BC,54,0),"0") -> 0 | BW12: ชิ้น | BX12: =+BV12*D12 -> 0 | BY12: =IFERROR(VLOOKUP(B12,'24'!B:BC,54,0),"0") -> 0 | BZ12: ชิ้น | CA12: =+BY12*D12 -> 0 | CB12: =IFERROR(VLOOKUP(B12,'25'!B:BC,54,0),"0") -> 0 | CC12: ชิ้น | CD12: =+CB12*D12 -> 0 | CE12: =IFERROR(VLOOKUP(B12,'26'!B:BC,54,0),"0") -> 0 | CF12: ชิ้น | CG12: =+CE12*D12 -> 0 | CH12: =IFERROR(VLOOKUP(B12,'27'!B:BC,54,0),"0") -> 0 | CI12: ชิ้น | CJ12: =+CH12*D12 -> 0 | CK12: =IFERROR(VLOOKUP(B12,'28'!B:BC,54,0),"0") -> 0 | CL12: ชิ้น | CM12: =+CK12*D12 -> 0 | CN12: =IFERROR(VLOOKUP(B12,'29'!B:BC,54,0),"0") -> 0 | CO12: ชิ้น | CP12: =+CN12*D12 -> 0 | CQ12: =IFERROR(VLOOKUP(B12,'30'!B:BC,54,0),"0") -> 0 | CR12: ชิ้น | CS12: =+CQ12*D12 -> 0 | CT12: =IFERROR(VLOOKUP(A12,#REF!,2,0),"0") -> 0 | CU12: ชิ้น | CV12: =+CT12*D12 -> 0 | CW12: =IFERROR(VLOOKUP(B12,'B-plus'!A:D,4,0),"0") -> 0 | CX12: ชิ้น | CY12: =+CW12*D12 -> 0
A13: 1111056 | B13: 1111056 | C13: ชิฟฟ่อนไม่มีไส้ แบบกล่อง8ชิ้น รวมรส (รวมรสยอดฮิต) | D13: 30.75 | E13: =+H13+K13+N13+Q13+T13+W13+Z13+AC13+AF13+AI13+AL13+AO13+AR13+AU13+AX13+BA13+BD13+BG13+BJ13+BM13+BP13+BS13+BV13+BY13+CB13+CE13+CH13+CK13+CN13+CQ13+CT13 -> 211 | F13: กล่อง | G13: =+E13*D13 -> 6488.25 | H13: =IFERROR(VLOOKUP(B13,'1'!B:BC,54,0),"0") -> 4 | I13: กล่อง | J13: =+H13*D13 -> 123 | K13: =IFERROR(VLOOKUP(B13,'2'!B:BC,54,0),"0") -> 3 | L13: กล่อง | M13: =+K13*D13 -> 92.25 | N13: =IFERROR(VLOOKUP(B13,'3'!B:BC,54,0),"0") -> 19 | O13: กล่อง | P13: =+N13*D13 -> 584.25 | Q13: =IFERROR(VLOOKUP(B13,'4'!B:BC,54,0),"0") -> 4 | R13: กล่อง | S13: =+Q13*D13 -> 123 | T13: =IFERROR(VLOOKUP(B13,'5'!B:BC,54,0),"0") -> 0 | U13: กล่อง | V13: =+T13*D13 -> 0 | W13: =IFERROR(VLOOKUP(B13,'6'!B:BC,54,0),"0") -> 13 | X13: กล่อง | Y13: =+W13*D13 -> 399.75 | Z13: =IFERROR(VLOOKUP(B13,'7'!B:BC,54,0),"0") -> 10 | AA13: กล่อง | AB13: =+Z13*D13 -> 307.5 | AC13: =IFERROR(VLOOKUP(B13,'8'!B:BC,54,0),"0") -> 0 | AD13: กล่อง | AE13: =+AC13*D13 -> 0 | AF13: =IFERROR(VLOOKUP(B13,'9'!B:BC,54,0),"0") -> 7 | AG13: กล่อง | AH13: =+AF13*D13 -> 215.25 | AI13: =IFERROR(VLOOKUP(B13,'10'!B:BC,54,0),"0") -> 19 | AJ13: กล่อง | AK13: =+AI13*D13 -> 584.25 | AL13: =IFERROR(VLOOKUP(B13,'11'!B:BC,54,0),"0") -> 11 | AM13: กล่อง | AN13: =+AL13*D13 -> 338.25 | AO13: =IFERROR(VLOOKUP(B13,'12'!B:BC,54,0),"0") -> 7 | AP13: กล่อง | AQ13: =+AO13*D13 -> 215.25 | AR13: =IFERROR(VLOOKUP(B13,'13'!B:BC,54,0),"0") -> 11 | AS13: กล่อง | AT13: =+AR13*D13 -> 338.25 | AU13: =IFERROR(VLOOKUP(B13,'14'!B:BC,54,0),"0") -> 11 | AV13: กล่อง | AW13: =+AU13*D13 -> 338.25 | AX13: =IFERROR(VLOOKUP(B13,'15'!B:BC,54,0),"0") -> 10 | AY13: กล่อง | AZ13: =+AX13*D13 -> 307.5 | BA13: =IFERROR(VLOOKUP(B13,'16'!B:BC,54,0),"0") -> 1 | BB13: กล่อง | BC13: =+BA13*D13 -> 30.75 | BD13: =IFERROR(VLOOKUP(B13,'17'!B:BC,54,0),"0") -> 14 | BE13: กล่อง | BF13: =+BD13*D13 -> 430.5 | BG13: =IFERROR(VLOOKUP(B13,'18'!B:BC,54,0),"0") -> 5 | BH13: กล่อง | BI13: =+BG13*D13 -> 153.75 | BJ13: =IFERROR(VLOOKUP(B13,'19'!B:BC,54,0),"0") -> 7 | BK13: กล่อง | BL13: =+BJ13*D13 -> 215.25 | BM13: =IFERROR(VLOOKUP(B13,'20'!B:BC,54,0),"0") -> 10 | BN13: กล่อง | BO13: =+BM13*D13 -> 307.5 | BP13: =IFERROR(VLOOKUP(B13,'21'!B:BC,54,0),"0") -> 5 | BQ13: กล่อง | BR13: =+BP13*D13 -> 153.75 | BS13: =IFERROR(VLOOKUP(B13,'22'!B:BC,54,0),"0") -> 11 | BT13: กล่อง | BU13: =+BS13*D13 -> 338.25 | BV13: =IFERROR(VLOOKUP(B13,'23'!B:BC,54,0),"0") -> 13 | BW13: กล่อง | BX13: =+BV13*D13 -> 399.75 | BY13: =IFERROR(VLOOKUP(B13,'24'!B:BC,54,0),"0") -> 8 | BZ13: กล่อง | CA13: =+BY13*D13 -> 246 | CB13: =IFERROR(VLOOKUP(B13,'25'!B:BC,54,0),"0") -> 5 | CC13: กล่อง | CD13: =+CB13*D13 -> 153.75 | CE13: =IFERROR(VLOOKUP(B13,'26'!B:BC,54,0),"0") -> 2 | CF13: กล่อง | CG13: =+CE13*D13 -> 61.5 | CH13: =IFERROR(VLOOKUP(B13,'27'!B:BC,54,0),"0") -> 1 | CI13: กล่อง | CJ13: =+CH13*D13 -> 30.75 | CK13: =IFERROR(VLOOKUP(B13,'28'!B:BC,54,0),"0") -> 0 | CL13: กล่อง | CM13: =+CK13*D13 -> 0 | CN13: =IFERROR(VLOOKUP(B13,'29'!B:BC,54,0),"0") -> 0 | CO13: กล่อง | CP13: =+CN13*D13 -> 0 | CQ13: =IFERROR(VLOOKUP(B13,'30'!B:BC,54,0),"0") -> 0 | CR13: กล่อง | CS13: =+CQ13*D13 -> 0 | CT13: =IFERROR(VLOOKUP(A13,#REF!,2,0),"0") -> 0 | CU13: กล่อง | CV13: =+CT13*D13 -> 0 | CW13: =IFERROR(VLOOKUP(B13,'B-plus'!A:D,4,0),"0") -> 0 | CX13: กล่อง | CY13: =+CW13*D13 -> 0
A14: 1111068 | B14: 1111068 | C14: ชิฟฟอนไม่มีไส้เเบบเเยกชิ้น เลือกรสชาติได้ (เนย) | D14: 0 | E14: =+H14+K14+N14+Q14+T14+W14+Z14+AC14+AF14+AI14+AL14+AO14+AR14+AU14+AX14+BA14+BD14+BG14+BJ14+BM14+BP14+BS14+BV14+BY14+CB14+CE14+CH14+CK14+CN14+CQ14+CT14 -> 0 | F14: กล่อง | G14: =+E14*D14 -> 0 | H14: =IFERROR(VLOOKUP(B14,'1'!B:BC,54,0),"0") -> 0 | I14: กล่อง | J14: =+H14*D14 -> 0 | K14: =IFERROR(VLOOKUP(B14,'2'!B:BC,54,0),"0") -> 0 | L14: กล่อง | M14: =+K14*D14 -> 0 | N14: =IFERROR(VLOOKUP(B14,'3'!B:BC,54,0),"0") -> 0 | O14: กล่อง | P14: =+N14*D14 -> 0 | Q14: =IFERROR(VLOOKUP(B14,'4'!B:BC,54,0),"0") -> 0 | R14: กล่อง | S14: =+Q14*D14 -> 0 | T14: =IFERROR(VLOOKUP(B14,'5'!B:BC,54,0),"0") -> 0 | U14: กล่อง | V14: =+T14*D14 -> 0 | W14: =IFERROR(VLOOKUP(B14,'6'!B:BC,54,0),"0") -> 0 | X14: กล่อง | Y14: =+W14*D14 -> 0 | Z14: =IFERROR(VLOOKUP(B14,'7'!B:BC,54,0),"0") -> 0 | AA14: กล่อง | AB14: =+Z14*D14 -> 0 | AC14: =IFERROR(VLOOKUP(B14,'8'!B:BC,54,0),"0") -> 0 | AD14: กล่อง | AE14: =+AC14*D14 -> 0 | AF14: =IFERROR(VLOOKUP(B14,'9'!B:BC,54,0),"0") -> 0 | AG14: กล่อง | AH14: =+AF14*D14 -> 0 | AI14: =IFERROR(VLOOKUP(B14,'10'!B:BC,54,0),"0") -> 0 | AJ14: กล่อง | AK14: =+AI14*D14 -> 0 | AL14: =IFERROR(VLOOKUP(B14,'11'!B:BC,54,0),"0") -> 0 | AM14: กล่อง | AN14: =+AL14*D14 -> 0 | AO14: =IFERROR(VLOOKUP(B14,'12'!B:BC,54,0),"0") -> 0 | AP14: กล่อง | AQ14: =+AO14*D14 -> 0 | AR14: =IFERROR(VLOOKUP(B14,'13'!B:BC,54,0),"0") -> 0 | AS14: กล่อง | AT14: =+AR14*D14 -> 0 | AU14: =IFERROR(VLOOKUP(B14,'14'!B:BC,54,0),"0") -> 0 | AV14: กล่อง | AW14: =+AU14*D14 -> 0 | AX14: =IFERROR(VLOOKUP(B14,'15'!B:BC,54,0),"0") -> 0 | AY14: กล่อง | AZ14: =+AX14*D14 -> 0 | BA14: =IFERROR(VLOOKUP(B14,'16'!B:BC,54,0),"0") -> 0 | BB14: กล่อง | BC14: =+BA14*D14 -> 0 | BD14: =IFERROR(VLOOKUP(B14,'17'!B:BC,54,0),"0") -> 0 | BE14: กล่อง | BF14: =+BD14*D14 -> 0 | BG14: =IFERROR(VLOOKUP(B14,'18'!B:BC,54,0),"0") -> 0 | BH14: กล่อง | BI14: =+BG14*D14 -> 0 | BJ14: =IFERROR(VLOOKUP(B14,'19'!B:BC,54,0),"0") -> 0 | BK14: กล่อง | BL14: =+BJ14*D14 -> 0 | BM14: =IFERROR(VLOOKUP(B14,'20'!B:BC,54,0),"0") -> 0 | BN14: กล่อง | BO14: =+BM14*D14 -> 0 | BP14: =IFERROR(VLOOKUP(B14,'21'!B:BC,54,0),"0") -> 0 | BQ14: กล่อง | BR14: =+BP14*D14 -> 0 | BS14: =IFERROR(VLOOKUP(B14,'22'!B:BC,54,0),"0") -> 0 | BT14: กล่อง | BU14: =+BS14*D14 -> 0 | BV14: =IFERROR(VLOOKUP(B14,'23'!B:BC,54,0),"0") -> 0 | BW14: กล่อง | BX14: =+BV14*D14 -> 0 | BY14: =IFERROR(VLOOKUP(B14,'24'!B:BC,54,0),"0") -> 0 | BZ14: กล่อง | CA14: =+BY14*D14 -> 0 | CB14: =IFERROR(VLOOKUP(B14,'25'!B:BC,54,0),"0") -> 0 | CC14: กล่อง | CD14: =+CB14*D14 -> 0 | CE14: =IFERROR(VLOOKUP(B14,'26'!B:BC,54,0),"0") -> 0 | CF14: กล่อง | CG14: =+CE14*D14 -> 0 | CH14: =IFERROR(VLOOKUP(B14,'27'!B:BC,54,0),"0") -> 0 | CI14: กล่อง | CJ14: =+CH14*D14 -> 0 | CK14: =IFERROR(VLOOKUP(B14,'28'!B:BC,54,0),"0") -> 0 | CL14: กล่อง | CM14: =+CK14*D14 -> 0 | CN14: =IFERROR(VLOOKUP(B14,'29'!B:BC,54,0),"0") -> 0 | CO14: กล่อง | CP14: =+CN14*D14 -> 0 | CQ14: =IFERROR(VLOOKUP(B14,'30'!B:BC,54,0),"0") -> 0 | CR14: กล่อง | CS14: =+CQ14*D14 -> 0 | CT14: =IFERROR(VLOOKUP(A14,#REF!,2,0),"0") -> 0 | CU14: กล่อง | CV14: =+CT14*D14 -> 0 | CW14: =IFERROR(VLOOKUP(B14,'B-plus'!A:D,4,0),"0") -> 0 | CX14: กล่อง | CY14: =+CW14*D14 -> 0
A15: 1111074 | B15: 1111074 | C15: ชิฟฟ่อนสอดไส้ 1 ชิ้น ชิฟฟ่อนเค้ก เลือกรสชาติได้ (มะพร้าว) | D15: 0 | E15: =+H15+K15+N15+Q15+T15+W15+Z15+AC15+AF15+AI15+AL15+AO15+AR15+AU15+AX15+BA15+BD15+BG15+BJ15+BM15+BP15+BS15+BV15+BY15+CB15+CE15+CH15+CK15+CN15+CQ15+CT15 -> 0 | F15: กล่อง | G15: =+E15*D15 -> 0 | H15: =IFERROR(VLOOKUP(B15,'1'!B:BC,54,0),"0") -> 0 | I15: กล่อง | J15: =+H15*D15 -> 0 | K15: =IFERROR(VLOOKUP(B15,'2'!B:BC,54,0),"0") -> 0 | L15: กล่อง | M15: =+K15*D15 -> 0 | N15: =IFERROR(VLOOKUP(B15,'3'!B:BC,54,0),"0") -> 0 | O15: กล่อง | P15: =+N15*D15 -> 0 | Q15: =IFERROR(VLOOKUP(B15,'4'!B:BC,54,0),"0") -> 0 | R15: กล่อง | S15: =+Q15*D15 -> 0 | T15: =IFERROR(VLOOKUP(B15,'5'!B:BC,54,0),"0") -> 0 | U15: กล่อง | V15: =+T15*D15 -> 0 | W15: =IFERROR(VLOOKUP(B15,'6'!B:BC,54,0),"0") -> 0 | X15: กล่อง | Y15: =+W15*D15 -> 0 | Z15: =IFERROR(VLOOKUP(B15,'7'!B:BC,54,0),"0") -> 0 | AA15: กล่อง | AB15: =+Z15*D15 -> 0 | AC15: =IFERROR(VLOOKUP(B15,'8'!B:BC,54,0),"0") -> 0 | AD15: กล่อง | AE15: =+AC15*D15 -> 0 | AF15: =IFERROR(VLOOKUP(B15,'9'!B:BC,54,0),"0") -> 0 | AG15: กล่อง | AH15: =+AF15*D15 -> 0 | AI15: =IFERROR(VLOOKUP(B15,'10'!B:BC,54,0),"0") -> 0 | AJ15: กล่อง | AK15: =+AI15*D15 -> 0 | AL15: =IFERROR(VLOOKUP(B15,'11'!B:BC,54,0),"0") -> 0 | AM15: กล่อง | AN15: =+AL15*D15 -> 0 | AO15: =IFERROR(VLOOKUP(B15,'12'!B:BC,54,0),"0") -> 0 | AP15: กล่อง | AQ15: =+AO15*D15 -> 0 | AR15: =IFERROR(VLOOKUP(B15,'13'!B:BC,54,0),"0") -> 0 | AS15: กล่อง | AT15: =+AR15*D15 -> 0 | AU15: =IFERROR(VLOOKUP(B15,'14'!B:BC,54,0),"0") -> 0 | AV15: กล่อง | AW15: =+AU15*D15 -> 0 | AX15: =IFERROR(VLOOKUP(B15,'15'!B:BC,54,0),"0") -> 0 | AY15: กล่อง | AZ15: =+AX15*D15 -> 0 | BA15: =IFERROR(VLOOKUP(B15,'16'!B:BC,54,0),"0") -> 0 | BB15: กล่อง | BC15: =+BA15*D15 -> 0 | BD15: =IFERROR(VLOOKUP(B15,'17'!B:BC,54,0),"0") -> 0 | BE15: กล่อง | BF15: =+BD15*D15 -> 0 | BG15: =IFERROR(VLOOKUP(B15,'18'!B:BC,54,0),"0") -> 0 | BH15: กล่อง | BI15: =+BG15*D15 -> 0 | BJ15: =IFERROR(VLOOKUP(B15,'19'!B:BC,54,0),"0") -> 0 | BK15: กล่อง | BL15: =+BJ15*D15 -> 0 | BM15: =IFERROR(VLOOKUP(B15,'20'!B:BC,54,0),"0") -> 0 | BN15: กล่อง | BO15: =+BM15*D15 -> 0 | BP15: =IFERROR(VLOOKUP(B15,'21'!B:BC,54,0),"0") -> 0 | BQ15: กล่อง | BR15: =+BP15*D15 -> 0 | BS15: =IFERROR(VLOOKUP(B15,'22'!B:BC,54,0),"0") -> 0 | BT15: กล่อง | BU15: =+BS15*D15 -> 0 | BV15: =IFERROR(VLOOKUP(B15,'23'!B:BC,54,0),"0") -> 0 | BW15: กล่อง | BX15: =+BV15*D15 -> 0 | BY15: =IFERROR(VLOOKUP(B15,'24'!B:BC,54,0),"0") -> 0 | BZ15: กล่อง | CA15: =+BY15*D15 -> 0 | CB15: =IFERROR(VLOOKUP(B15,'25'!B:BC,54,0),"0") -> 0 | CC15: กล่อง | CD15: =+CB15*D15 -> 0 | CE15: =IFERROR(VLOOKUP(B15,'26'!B:BC,54,0),"0") -> 0 | CF15: กล่อง | CG15: =+CE15*D15 -> 0 | CH15: =IFERROR(VLOOKUP(B15,'27'!B:BC,54,0),"0") -> 0 | CI15: กล่อง | CJ15: =+CH15*D15 -> 0 | CK15: =IFERROR(VLOOKUP(B15,'28'!B:BC,54,0),"0") -> 0 | CL15: กล่อง | CM15: =+CK15*D15 -> 0 | CN15: =IFERROR(VLOOKUP(B15,'29'!B:BC,54,0),"0") -> 0 | CO15: กล่อง | CP15: =+CN15*D15 -> 0 | CQ15: =IFERROR(VLOOKUP(B15,'30'!B:BC,54,0),"0") -> 0 | CR15: กล่อง | CS15: =+CQ15*D15 -> 0 | CT15: =IFERROR(VLOOKUP(A15,#REF!,2,0),"0") -> 0 | CU15: กล่อง | CV15: =+CT15*D15 -> 0 | CW15: =IFERROR(VLOOKUP(B15,'B-plus'!A:D,4,0),"0") -> 0 | CX15: กล่อง | CY15: =+CW15*D15 -> 0
A16: 1111075 | B16: 1111075 | C16: ชิฟฟ่อนสอดไส้ 1 ชิ้น ชิฟฟ่อนเค้ก เลือกรสชาติได้ (สตอเบอรี่) | D16: 0 | E16: =+H16+K16+N16+Q16+T16+W16+Z16+AC16+AF16+AI16+AL16+AO16+AR16+AU16+AX16+BA16+BD16+BG16+BJ16+BM16+BP16+BS16+BV16+BY16+CB16+CE16+CH16+CK16+CN16+CQ16+CT16 -> 0 | F16: กล่อง | G16: =+E16*D16 -> 0 | H16: =IFERROR(VLOOKUP(B16,'1'!B:BC,54,0),"0") -> 0 | I16: กล่อง | J16: =+H16*D16 -> 0 | K16: =IFERROR(VLOOKUP(B16,'2'!B:BC,54,0),"0") -> 0 | L16: กล่อง | M16: =+K16*D16 -> 0 | N16: =IFERROR(VLOOKUP(B16,'3'!B:BC,54,0),"0") -> 0 | O16: กล่อง | P16: =+N16*D16 -> 0 | Q16: =IFERROR(VLOOKUP(B16,'4'!B:BC,54,0),"0") -> 0 | R16: กล่อง | S16: =+Q16*D16 -> 0 | T16: =IFERROR(VLOOKUP(B16,'5'!B:BC,54,0),"0") -> 0 | U16: กล่อง | V16: =+T16*D16 -> 0 | W16: =IFERROR(VLOOKUP(B16,'6'!B:BC,54,0),"0") -> 0 | X16: กล่อง | Y16: =+W16*D16 -> 0 | Z16: =IFERROR(VLOOKUP(B16,'7'!B:BC,54,0),"0") -> 0 | AA16: กล่อง | AB16: =+Z16*D16 -> 0 | AC16: =IFERROR(VLOOKUP(B16,'8'!B:BC,54,0),"0") -> 0 | AD16: กล่อง | AE16: =+AC16*D16 -> 0 | AF16: =IFERROR(VLOOKUP(B16,'9'!B:BC,54,0),"0") -> 0 | AG16: กล่อง | AH16: =+AF16*D16 -> 0 | AI16: =IFERROR(VLOOKUP(B16,'10'!B:BC,54,0),"0") -> 0 | AJ16: กล่อง | AK16: =+AI16*D16 -> 0 | AL16: =IFERROR(VLOOKUP(B16,'11'!B:BC,54,0),"0") -> 0 | AM16: กล่อง | AN16: =+AL16*D16 -> 0 | AO16: =IFERROR(VLOOKUP(B16,'12'!B:BC,54,0),"0") -> 0 | AP16: กล่อง | AQ16: =+AO16*D16 -> 0 | AR16: =IFERROR(VLOOKUP(B16,'13'!B:BC,54,0),"0") -> 0 | AS16: กล่อง | AT16: =+AR16*D16 -> 0 | AU16: =IFERROR(VLOOKUP(B16,'14'!B:BC,54,0),"0") -> 0 | AV16: กล่อง | AW16: =+AU16*D16 -> 0 | AX16: =IFERROR(VLOOKUP(B16,'15'!B:BC,54,0),"0") -> 0 | AY16: กล่อง | AZ16: =+AX16*D16 -> 0 | BA16: =IFERROR(VLOOKUP(B16,'16'!B:BC,54,0),"0") -> 0 | BB16: กล่อง | BC16: =+BA16*D16 -> 0 | BD16: =IFERROR(VLOOKUP(B16,'17'!B:BC,54,0),"0") -> 0 | BE16: กล่อง | BF16: =+BD16*D16 -> 0 | BG16: =IFERROR(VLOOKUP(B16,'18'!B:BC,54,0),"0") -> 0 | BH16: กล่อง | BI16: =+BG16*D16 -> 0 | BJ16: =IFERROR(VLOOKUP(B16,'19'!B:BC,54,0),"0") -> 0 | BK16: กล่อง | BL16: =+BJ16*D16 -> 0 | BM16: =IFERROR(VLOOKUP(B16,'20'!B:BC,54,0),"0") -> 0 | BN16: กล่อง | BO16: =+BM16*D16 -> 0 | BP16: =IFERROR(VLOOKUP(B16,'21'!B:BC,54,0),"0") -> 0 | BQ16: กล่อง | BR16: =+BP16*D16 -> 0 | BS16: =IFERROR(VLOOKUP(B16,'22'!B:BC,54,0),"0") -> 0 | BT16: กล่อง | BU16: =+BS16*D16 -> 0 | BV16: =IFERROR(VLOOKUP(B16,'23'!B:BC,54,0),"0") -> 0 | BW16: กล่อง | BX16: =+BV16*D16 -> 0 | BY16: =IFERROR(VLOOKUP(B16,'24'!B:BC,54,0),"0") -> 0 | BZ16: กล่อง | CA16: =+BY16*D16 -> 0 | CB16: =IFERROR(VLOOKUP(B16,'25'!B:BC,54,0),"0") -> 0 | CC16: กล่อง | CD16: =+CB16*D16 -> 0 | CE16: =IFERROR(VLOOKUP(B16,'26'!B:BC,54,0),"0") -> 0 | CF16: กล่อง | CG16: =+CE16*D16 -> 0 | CH16: =IFERROR(VLOOKUP(B16,'27'!B:BC,54,0),"0") -> 0 | CI16: กล่อง | CJ16: =+CH16*D16 -> 0 | CK16: =IFERROR(VLOOKUP(B16,'28'!B:BC,54,0),"0") -> 0 | CL16: กล่อง | CM16: =+CK16*D16 -> 0 | CN16: =IFERROR(VLOOKUP(B16,'29'!B:BC,54,0),"0") -> 0 | CO16: กล่อง | CP16: =+CN16*D16 -> 0 | CQ16: =IFERROR(VLOOKUP(B16,'30'!B:BC,54,0),"0") -> 0 | CR16: กล่อง | CS16: =+CQ16*D16 -> 0 | CT16: =IFERROR(VLOOKUP(A16,#REF!,2,0),"0") -> 0 | CU16: กล่อง | CV16: =+CT16*D16 -> 0 | CW16: =IFERROR(VLOOKUP(B16,'B-plus'!A:D,4,0),"0") -> 0 | CX16: กล่อง | CY16: =+CW16*D16 -> 0
A17: 1111076 | B17: 1111076 | C17: ชิฟฟ่อนสอดไส้ 1 ชิ้น ชิฟฟ่อนเค้ก เลือกรสชาติได้ (ส้ม) | D17: 0 | E17: =+H17+K17+N17+Q17+T17+W17+Z17+AC17+AF17+AI17+AL17+AO17+AR17+AU17+AX17+BA17+BD17+BG17+BJ17+BM17+BP17+BS17+BV17+BY17+CB17+CE17+CH17+CK17+CN17+CQ17+CT17 -> 0 | F17: กล่อง | G17: =+E17*D17 -> 0 | H17: =IFERROR(VLOOKUP(B17,'1'!B:BC,54,0),"0") -> 0 | I17: กล่อง | J17: =+H17*D17 -> 0 | K17: =IFERROR(VLOOKUP(B17,'2'!B:BC,54,0),"0") -> 0 | L17: กล่อง | M17: =+K17*D17 -> 0 | N17: =IFERROR(VLOOKUP(B17,'3'!B:BC,54,0),"0") -> 0 | O17: กล่อง | P17: =+N17*D17 -> 0 | Q17: =IFERROR(VLOOKUP(B17,'4'!B:BC,54,0),"0") -> 0 | R17: กล่อง | S17: =+Q17*D17 -> 0 | T17: =IFERROR(VLOOKUP(B17,'5'!B:BC,54,0),"0") -> 0 | U17: กล่อง | V17: =+T17*D17 -> 0 | W17: =IFERROR(VLOOKUP(B17,'6'!B:BC,54,0),"0") -> 0 | X17: กล่อง | Y17: =+W17*D17 -> 0 | Z17: =IFERROR(VLOOKUP(B17,'7'!B:BC,54,0),"0") -> 0 | AA17: กล่อง | AB17: =+Z17*D17 -> 0 | AC17: =IFERROR(VLOOKUP(B17,'8'!B:BC,54,0),"0") -> 0 | AD17: กล่อง | AE17: =+AC17*D17 -> 0 | AF17: =IFERROR(VLOOKUP(B17,'9'!B:BC,54,0),"0") -> 0 | AG17: กล่อง | AH17: =+AF17*D17 -> 0 | AI17: =IFERROR(VLOOKUP(B17,'10'!B:BC,54,0),"0") -> 0 | AJ17: กล่อง | AK17: =+AI17*D17 -> 0 | AL17: =IFERROR(VLOOKUP(B17,'11'!B:BC,54,0),"0") -> 0 | AM17: กล่อง | AN17: =+AL17*D17 -> 0 | AO17: =IFERROR(VLOOKUP(B17,'12'!B:BC,54,0),"0") -> 0 | AP17: กล่อง | AQ17: =+AO17*D17 -> 0 | AR17: =IFERROR(VLOOKUP(B17,'13'!B:BC,54,0),"0") -> 0 | AS17: กล่อง | AT17: =+AR17*D17 -> 0 | AU17: =IFERROR(VLOOKUP(B17,'14'!B:BC,54,0),"0") -> 0 | AV17: กล่อง | AW17: =+AU17*D17 -> 0 | AX17: =IFERROR(VLOOKUP(B17,'15'!B:BC,54,0),"0") -> 0 | AY17: กล่อง | AZ17: =+AX17*D17 -> 0 | BA17: =IFERROR(VLOOKUP(B17,'16'!B:BC,54,0),"0") -> 0 | BB17: กล่อง | BC17: =+BA17*D17 -> 0 | BD17: =IFERROR(VLOOKUP(B17,'17'!B:BC,54,0),"0") -> 0 | BE17: กล่อง | BF17: =+BD17*D17 -> 0 | BG17: =IFERROR(VLOOKUP(B17,'18'!B:BC,54,0),"0") -> 0 | BH17: กล่อง | BI17: =+BG17*D17 -> 0 | BJ17: =IFERROR(VLOOKUP(B17,'19'!B:BC,54,0),"0") -> 0 | BK17: กล่อง | BL17: =+BJ17*D17 -> 0 | BM17: =IFERROR(VLOOKUP(B17,'20'!B:BC,54,0),"0") -> 0 | BN17: กล่อง | BO17: =+BM17*D17 -> 0 | BP17: =IFERROR(VLOOKUP(B17,'21'!B:BC,54,0),"0") -> 0 | BQ17: กล่อง | BR17: =+BP17*D17 -> 0 | BS17: =IFERROR(VLOOKUP(B17,'22'!B:BC,54,0),"0") -> 0 | BT17: กล่อง | BU17: =+BS17*D17 -> 0 | BV17: =IFERROR(VLOOKUP(B17,'23'!B:BC,54,0),"0") -> 0 | BW17: กล่อง | BX17: =+BV17*D17 -> 0 | BY17: =IFERROR(VLOOKUP(B17,'24'!B:BC,54,0),"0") -> 0 | BZ17: กล่อง | CA17: =+BY17*D17 -> 0 | CB17: =IFERROR(VLOOKUP(B17,'25'!B:BC,54,0),"0") -> 0 | CC17: กล่อง | CD17: =+CB17*D17 -> 0 | CE17: =IFERROR(VLOOKUP(B17,'26'!B:BC,54,0),"0") -> 0 | CF17: กล่อง | CG17: =+CE17*D17 -> 0 | CH17: =IFERROR(VLOOKUP(B17,'27'!B:BC,54,0),"0") -> 0 | CI17: กล่อง | CJ17: =+CH17*D17 -> 0 | CK17: =IFERROR(VLOOKUP(B17,'28'!B:BC,54,0),"0") -> 0 | CL17: กล่อง | CM17: =+CK17*D17 -> 0 | CN17: =IFERROR(VLOOKUP(B17,'29'!B:BC,54,0),"0") -> 0 | CO17: กล่อง | CP17: =+CN17*D17 -> 0 | CQ17: =IFERROR(VLOOKUP(B17,'30'!B:BC,54,0),"0") -> 0 | CR17: กล่อง | CS17: =+CQ17*D17 -> 0 | CT17: =IFERROR(VLOOKUP(A17,#REF!,2,0),"0") -> 0 | CU17: กล่อง | CV17: =+CT17*D17 -> 0 | CW17: =IFERROR(VLOOKUP(B17,'B-plus'!A:D,4,0),"0") -> 0 | CX17: กล่อง | CY17: =+CW17*D17 -> 0
A18: 1111077 | B18: 1111077 | C18: ชิฟฟ่อนสอดไส้ 1 ชิ้น ชิฟฟ่อนเค้ก เลือกรสชาติได้ (บลูเบอรี่) | D18: 0 | E18: =+H18+K18+N18+Q18+T18+W18+Z18+AC18+AF18+AI18+AL18+AO18+AR18+AU18+AX18+BA18+BD18+BG18+BJ18+BM18+BP18+BS18+BV18+BY18+CB18+CE18+CH18+CK18+CN18+CQ18+CT18 -> 0 | F18: กล่อง | G18: =+E18*D18 -> 0 | H18: =IFERROR(VLOOKUP(B18,'1'!B:BC,54,0),"0") -> 0 | I18: กล่อง | J18: =+H18*D18 -> 0 | K18: =IFERROR(VLOOKUP(B18,'2'!B:BC,54,0),"0") -> 0 | L18: กล่อง | M18: =+K18*D18 -> 0 | N18: =IFERROR(VLOOKUP(B18,'3'!B:BC,54,0),"0") -> 0 | O18: กล่อง | P18: =+N18*D18 -> 0 | Q18: =IFERROR(VLOOKUP(B18,'4'!B:BC,54,0),"0") -> 0 | R18: กล่อง | S18: =+Q18*D18 -> 0 | T18: =IFERROR(VLOOKUP(B18,'5'!B:BC,54,0),"0") -> 0 | U18: กล่อง | V18: =+T18*D18 -> 0 | W18: =IFERROR(VLOOKUP(B18,'6'!B:BC,54,0),"0") -> 0 | X18: กล่อง | Y18: =+W18*D18 -> 0 | Z18: =IFERROR(VLOOKUP(B18,'7'!B:BC,54,0),"0") -> 0 | AA18: กล่อง | AB18: =+Z18*D18 -> 0 | AC18: =IFERROR(VLOOKUP(B18,'8'!B:BC,54,0),"0") -> 0 | AD18: กล่อง | AE18: =+AC18*D18 -> 0 | AF18: =IFERROR(VLOOKUP(B18,'9'!B:BC,54,0),"0") -> 0 | AG18: กล่อง | AH18: =+AF18*D18 -> 0 | AI18: =IFERROR(VLOOKUP(B18,'10'!B:BC,54,0),"0") -> 0 | AJ18: กล่อง | AK18: =+AI18*D18 -> 0 | AL18: =IFERROR(VLOOKUP(B18,'11'!B:BC,54,0),"0") -> 0 | AM18: กล่อง | AN18: =+AL18*D18 -> 0 | AO18: =IFERROR(VLOOKUP(B18,'12'!B:BC,54,0),"0") -> 0 | AP18: กล่อง | AQ18: =+AO18*D18 -> 0 | AR18: =IFERROR(VLOOKUP(B18,'13'!B:BC,54,0),"0") -> 0 | AS18: กล่อง | AT18: =+AR18*D18 -> 0 | AU18: =IFERROR(VLOOKUP(B18,'14'!B:BC,54,0),"0") -> 0 | AV18: กล่อง | AW18: =+AU18*D18 -> 0 | AX18: =IFERROR(VLOOKUP(B18,'15'!B:BC,54,0),"0") -> 0 | AY18: กล่อง | AZ18: =+AX18*D18 -> 0 | BA18: =IFERROR(VLOOKUP(B18,'16'!B:BC,54,0),"0") -> 0 | BB18: กล่อง | BC18: =+BA18*D18 -> 0 | BD18: =IFERROR(VLOOKUP(B18,'17'!B:BC,54,0),"0") -> 0 | BE18: กล่อง | BF18: =+BD18*D18 -> 0 | BG18: =IFERROR(VLOOKUP(B18,'18'!B:BC,54,0),"0") -> 0 | BH18: กล่อง | BI18: =+BG18*D18 -> 0 | BJ18: =IFERROR(VLOOKUP(B18,'19'!B:BC,54,0),"0") -> 0 | BK18: กล่อง | BL18: =+BJ18*D18 -> 0 | BM18: =IFERROR(VLOOKUP(B18,'20'!B:BC,54,0),"0") -> 0 | BN18: กล่อง | BO18: =+BM18*D18 -> 0 | BP18: =IFERROR(VLOOKUP(B18,'21'!B:BC,54,0),"0") -> 0 | BQ18: กล่อง | BR18: =+BP18*D18 -> 0 | BS18: =IFERROR(VLOOKUP(B18,'22'!B:BC,54,0),"0") -> 0 | BT18: กล่อง | BU18: =+BS18*D18 -> 0 | BV18: =IFERROR(VLOOKUP(B18,'23'!B:BC,54,0),"0") -> 0 | BW18: กล่อง | BX18: =+BV18*D18 -> 0 | BY18: =IFERROR(VLOOKUP(B18,'24'!B:BC,54,0),"0") -> 0 | BZ18: กล่อง | CA18: =+BY18*D18 -> 0 | CB18: =IFERROR(VLOOKUP(B18,'25'!B:BC,54,0),"0") -> 0 | CC18: กล่อง | CD18: =+CB18*D18 -> 0 | CE18: =IFERROR(VLOOKUP(B18,'26'!B:BC,54,0),"0") -> 0 | CF18: กล่อง | CG18: =+CE18*D18 -> 0 | CH18: =IFERROR(VLOOKUP(B18,'27'!B:BC,54,0),"0") -> 0 | CI18: กล่อง | CJ18: =+CH18*D18 -> 0 | CK18: =IFERROR(VLOOKUP(B18,'28'!B:BC,54,0),"0") -> 0 | CL18: กล่อง | CM18: =+CK18*D18 -> 0 | CN18: =IFERROR(VLOOKUP(B18,'29'!B:BC,54,0),"0") -> 0 | CO18: กล่อง | CP18: =+CN18*D18 -> 0 | CQ18: =IFERROR(VLOOKUP(B18,'30'!B:BC,54,0),"0") -> 0 | CR18: กล่อง | CS18: =+CQ18*D18 -> 0 | CT18: =IFERROR(VLOOKUP(A18,#REF!,2,0),"0") -> 0 | CU18: กล่อง | CV18: =+CT18*D18 -> 0 | CW18: =IFERROR(VLOOKUP(B18,'B-plus'!A:D,4,0),"0") -> 0 | CX18: กล่อง | CY18: =+CW18*D18 -> 0
A19: 1111078 | B19: 1111078 | C19: ชิฟฟ่อนสอดไส้ 1 ชิ้น ชิฟฟ่อนเค้ก เลือกรสชาติได้ (นมชมพู) | D19: 0 | E19: =+H19+K19+N19+Q19+T19+W19+Z19+AC19+AF19+AI19+AL19+AO19+AR19+AU19+AX19+BA19+BD19+BG19+BJ19+BM19+BP19+BS19+BV19+BY19+CB19+CE19+CH19+CK19+CN19+CQ19+CT19 -> 0 | F19: กล่อง | G19: =+E19*D19 -> 0 | H19: =IFERROR(VLOOKUP(B19,'1'!B:BC,54,0),"0") -> 0 | I19: กล่อง | J19: =+H19*D19 -> 0 | K19: =IFERROR(VLOOKUP(B19,'2'!B:BC,54,0),"0") -> 0 | L19: กล่อง | M19: =+K19*D19 -> 0 | N19: =IFERROR(VLOOKUP(B19,'3'!B:BC,54,0),"0") -> 0 | O19: กล่อง | P19: =+N19*D19 -> 0 | Q19: =IFERROR(VLOOKUP(B19,'4'!B:BC,54,0),"0") -> 0 | R19: กล่อง | S19: =+Q19*D19 -> 0 | T19: =IFERROR(VLOOKUP(B19,'5'!B:BC,54,0),"0") -> 0 | U19: กล่อง | V19: =+T19*D19 -> 0 | W19: =IFERROR(VLOOKUP(B19,'6'!B:BC,54,0),"0") -> 0 | X19: กล่อง | Y19: =+W19*D19 -> 0 | Z19: =IFERROR(VLOOKUP(B19,'7'!B:BC,54,0),"0") -> 0 | AA19: กล่อง | AB19: =+Z19*D19 -> 0 | AC19: =IFERROR(VLOOKUP(B19,'8'!B:BC,54,0),"0") -> 0 | AD19: กล่อง | AE19: =+AC19*D19 -> 0 | AF19: =IFERROR(VLOOKUP(B19,'9'!B:BC,54,0),"0") -> 0 | AG19: กล่อง | AH19: =+AF19*D19 -> 0 | AI19: =IFERROR(VLOOKUP(B19,'10'!B:BC,54,0),"0") -> 0 | AJ19: กล่อง | AK19: =+AI19*D19 -> 0 | AL19: =IFERROR(VLOOKUP(B19,'11'!B:BC,54,0),"0") -> 0 | AM19: กล่อง | AN19: =+AL19*D19 -> 0 | AO19: =IFERROR(VLOOKUP(B19,'12'!B:BC,54,0),"0") -> 0 | AP19: กล่อง | AQ19: =+AO19*D19 -> 0 | AR19: =IFERROR(VLOOKUP(B19,'13'!B:BC,54,0),"0") -> 0 | AS19: กล่อง | AT19: =+AR19*D19 -> 0 | AU19: =IFERROR(VLOOKUP(B19,'14'!B:BC,54,0),"0") -> 0 | AV19: กล่อง | AW19: =+AU19*D19 -> 0 | AX19: =IFERROR(VLOOKUP(B19,'15'!B:BC,54,0),"0") -> 0 | AY19: กล่อง | AZ19: =+AX19*D19 -> 0 | BA19: =IFERROR(VLOOKUP(B19,'16'!B:BC,54,0),"0") -> 0 | BB19: กล่อง | BC19: =+BA19*D19 -> 0 | BD19: =IFERROR(VLOOKUP(B19,'17'!B:BC,54,0),"0") -> 0 | BE19: กล่อง | BF19: =+BD19*D19 -> 0 | BG19: =IFERROR(VLOOKUP(B19,'18'!B:BC,54,0),"0") -> 0 | BH19: กล่อง | BI19: =+BG19*D19 -> 0 | BJ19: =IFERROR(VLOOKUP(B19,'19'!B:BC,54,0),"0") -> 0 | BK19: กล่อง | BL19: =+BJ19*D19 -> 0 | BM19: =IFERROR(VLOOKUP(B19,'20'!B:BC,54,0),"0") -> 0 | BN19: กล่อง | BO19: =+BM19*D19 -> 0 | BP19: =IFERROR(VLOOKUP(B19,'21'!B:BC,54,0),"0") -> 0 | BQ19: กล่อง | BR19: =+BP19*D19 -> 0 | BS19: =IFERROR(VLOOKUP(B19,'22'!B:BC,54,0),"0") -> 0 | BT19: กล่อง | BU19: =+BS19*D19 -> 0 | BV19: =IFERROR(VLOOKUP(B19,'23'!B:BC,54,0),"0") -> 0 | BW19: กล่อง | BX19: =+BV19*D19 -> 0 | BY19: =IFERROR(VLOOKUP(B19,'24'!B:BC,54,0),"0") -> 0 | BZ19: กล่อง | CA19: =+BY19*D19 -> 0 | CB19: =IFERROR(VLOOKUP(B19,'25'!B:BC,54,0),"0") -> 0 | CC19: กล่อง | CD19: =+CB19*D19 -> 0 | CE19: =IFERROR(VLOOKUP(B19,'26'!B:BC,54,0),"0") -> 0 | CF19: กล่อง | CG19: =+CE19*D19 -> 0 | CH19: =IFERROR(VLOOKUP(B19,'27'!B:BC,54,0),"0") -> 0 | CI19: กล่อง | CJ19: =+CH19*D19 -> 0 | CK19: =IFERROR(VLOOKUP(B19,'28'!B:BC,54,0),"0") -> 0 | CL19: กล่อง | CM19: =+CK19*D19 -> 0 | CN19: =IFERROR(VLOOKUP(B19,'29'!B:BC,54,0),"0") -> 0 | CO19: กล่อง | CP19: =+CN19*D19 -> 0 | CQ19: =IFERROR(VLOOKUP(B19,'30'!B:BC,54,0),"0") -> 0 | CR19: กล่อง | CS19: =+CQ19*D19 -> 0 | CT19: =IFERROR(VLOOKUP(A19,#REF!,2,0),"0") -> 0 | CU19: กล่อง | CV19: =+CT19*D19 -> 0 | CW19: =IFERROR(VLOOKUP(B19,'B-plus'!A:D,4,0),"0") -> 0 | CX19: กล่อง | CY19: =+CW19*D19 -> 0
A20: 1111079 | B20: 1111079 | C20: ชิฟฟ่อนสอดไส้ 1 ชิ้น ชิฟฟ่อนเค้ก เลือกรสชาติได้ (ช็อกโกแลต) | D20: 0 | E20: =+H20+K20+N20+Q20+T20+W20+Z20+AC20+AF20+AI20+AL20+AO20+AR20+AU20+AX20+BA20+BD20+BG20+BJ20+BM20+BP20+BS20+BV20+BY20+CB20+CE20+CH20+CK20+CN20+CQ20+CT20 -> 0 | F20: กล่อง | G20: =+E20*D20 -> 0 | H20: =IFERROR(VLOOKUP(B20,'1'!B:BC,54,0),"0") -> 0 | I20: กล่อง | J20: =+H20*D20 -> 0 | K20: =IFERROR(VLOOKUP(B20,'2'!B:BC,54,0),"0") -> 0 | L20: กล่อง | M20: =+K20*D20 -> 0 | N20: =IFERROR(VLOOKUP(B20,'3'!B:BC,54,0),"0") -> 0 | O20: กล่อง | P20: =+N20*D20 -> 0 | Q20: =IFERROR(VLOOKUP(B20,'4'!B:BC,54,0),"0") -> 0 | R20: กล่อง | S20: =+Q20*D20 -> 0 | T20: =IFERROR(VLOOKUP(B20,'5'!B:BC,54,0),"0") -> 0 | U20: กล่อง | V20: =+T20*D20 -> 0 | W20: =IFERROR(VLOOKUP(B20,'6'!B:BC,54,0),"0") -> 0 | X20: กล่อง | Y20: =+W20*D20 -> 0 | Z20: =IFERROR(VLOOKUP(B20,'7'!B:BC,54,0),"0") -> 0 | AA20: กล่อง | AB20: =+Z20*D20 -> 0 | AC20: =IFERROR(VLOOKUP(B20,'8'!B:BC,54,0),"0") -> 0 | AD20: กล่อง | AE20: =+AC20*D20 -> 0 | AF20: =IFERROR(VLOOKUP(B20,'9'!B:BC,54,0),"0") -> 0 | AG20: กล่อง | AH20: =+AF20*D20 -> 0 | AI20: =IFERROR(VLOOKUP(B20,'10'!B:BC,54,0),"0") -> 0 | AJ20: กล่อง | AK20: =+AI20*D20 -> 0 | AL20: =IFERROR(VLOOKUP(B20,'11'!B:BC,54,0),"0") -> 0 | AM20: กล่อง | AN20: =+AL20*D20 -> 0 | AO20: =IFERROR(VLOOKUP(B20,'12'!B:BC,54,0),"0") -> 0 | AP20: กล่อง | AQ20: =+AO20*D20 -> 0 | AR20: =IFERROR(VLOOKUP(B20,'13'!B:BC,54,0),"0") -> 0 | AS20: กล่อง | AT20: =+AR20*D20 -> 0 | AU20: =IFERROR(VLOOKUP(B20,'14'!B:BC,54,0),"0") -> 0 | AV20: กล่อง | AW20: =+AU20*D20 -> 0 | AX20: =IFERROR(VLOOKUP(B20,'15'!B:BC,54,0),"0") -> 0 | AY20: กล่อง | AZ20: =+AX20*D20 -> 0 | BA20: =IFERROR(VLOOKUP(B20,'16'!B:BC,54,0),"0") -> 0 | BB20: กล่อง | BC20: =+BA20*D20 -> 0 | BD20: =IFERROR(VLOOKUP(B20,'17'!B:BC,54,0),"0") -> 0 | BE20: กล่อง | BF20: =+BD20*D20 -> 0 | BG20: =IFERROR(VLOOKUP(B20,'18'!B:BC,54,0),"0") -> 0 | BH20: กล่อง | BI20: =+BG20*D20 -> 0 | BJ20: =IFERROR(VLOOKUP(B20,'19'!B:BC,54,0),"0") -> 0 | BK20: กล่อง | BL20: =+BJ20*D20 -> 0 | BM20: =IFERROR(VLOOKUP(B20,'20'!B:BC,54,0),"0") -> 0 | BN20: กล่อง | BO20: =+BM20*D20 -> 0 | BP20: =IFERROR(VLOOKUP(B20,'21'!B:BC,54,0),"0") -> 0 | BQ20: กล่อง | BR20: =+BP20*D20 -> 0 | BS20: =IFERROR(VLOOKUP(B20,'22'!B:BC,54,0),"0") -> 0 | BT20: กล่อง | BU20: =+BS20*D20 -> 0 | BV20: =IFERROR(VLOOKUP(B20,'23'!B:BC,54,0),"0") -> 0 | BW20: กล่อง | BX20: =+BV20*D20 -> 0 | BY20: =IFERROR(VLOOKUP(B20,'24'!B:BC,54,0),"0") -> 0 | BZ20: กล่อง | CA20: =+BY20*D20 -> 0 | CB20: =IFERROR(VLOOKUP(B20,'25'!B:BC,54,0),"0") -> 0 | CC20: กล่อง | CD20: =+CB20*D20 -> 0 | CE20: =IFERROR(VLOOKUP(B20,'26'!B:BC,54,0),"0") -> 0 | CF20: กล่อง | CG20: =+CE20*D20 -> 0 | CH20: =IFERROR(VLOOKUP(B20,'27'!B:BC,54,0),"0") -> 0 | CI20: กล่อง | CJ20: =+CH20*D20 -> 0 | CK20: =IFERROR(VLOOKUP(B20,'28'!B:BC,54,0),"0") -> 0 | CL20: กล่อง | CM20: =+CK20*D20 -> 0 | CN20: =IFERROR(VLOOKUP(B20,'29'!B:BC,54,0),"0") -> 0 | CO20: กล่อง | CP20: =+CN20*D20 -> 0 | CQ20: =IFERROR(VLOOKUP(B20,'30'!B:BC,54,0),"0") -> 0 | CR20: กล่อง | CS20: =+CQ20*D20 -> 0 | CT20: =IFERROR(VLOOKUP(A20,#REF!,2,0),"0") -> 0 | CU20: กล่อง | CV20: =+CT20*D20 -> 0 | CW20: =IFERROR(VLOOKUP(B20,'B-plus'!A:D,4,0),"0") -> 0 | CX20: กล่อง | CY20: =+CW20*D20 -> 0
A21: 1111080 | B21: 1111080 | C21: ชิฟฟ่อนสอดไส้ 1 ชิ้น ชิฟฟ่อนเค้ก เลือกรสชาติได้ (ฝอยทอง) | D21: 0 | E21: =+H21+K21+N21+Q21+T21+W21+Z21+AC21+AF21+AI21+AL21+AO21+AR21+AU21+AX21+BA21+BD21+BG21+BJ21+BM21+BP21+BS21+BV21+BY21+CB21+CE21+CH21+CK21+CN21+CQ21+CT21 -> 0 | F21: กล่อง | G21: =+E21*D21 -> 0 | H21: =IFERROR(VLOOKUP(B21,'1'!B:BC,54,0),"0") -> 0 | I21: กล่อง | J21: =+H21*D21 -> 0 | K21: =IFERROR(VLOOKUP(B21,'2'!B:BC,54,0),"0") -> 0 | L21: กล่อง | M21: =+K21*D21 -> 0 | N21: =IFERROR(VLOOKUP(B21,'3'!B:BC,54,0),"0") -> 0 | O21: กล่อง | P21: =+N21*D21 -> 0 | Q21: =IFERROR(VLOOKUP(B21,'4'!B:BC,54,0),"0") -> 0 | R21: กล่อง | S21: =+Q21*D21 -> 0 | T21: =IFERROR(VLOOKUP(B21,'5'!B:BC,54,0),"0") -> 0 | U21: กล่อง | V21: =+T21*D21 -> 0 | W21: =IFERROR(VLOOKUP(B21,'6'!B:BC,54,0),"0") -> 0 | X21: กล่อง | Y21: =+W21*D21 -> 0 | Z21: =IFERROR(VLOOKUP(B21,'7'!B:BC,54,0),"0") -> 0 | AA21: กล่อง | AB21: =+Z21*D21 -> 0 | AC21: =IFERROR(VLOOKUP(B21,'8'!B:BC,54,0),"0") -> 0 | AD21: กล่อง | AE21: =+AC21*D21 -> 0 | AF21: =IFERROR(VLOOKUP(B21,'9'!B:BC,54,0),"0") -> 0 | AG21: กล่อง | AH21: =+AF21*D21 -> 0 | AI21: =IFERROR(VLOOKUP(B21,'10'!B:BC,54,0),"0") -> 0 | AJ21: กล่อง | AK21: =+AI21*D21 -> 0 | AL21: =IFERROR(VLOOKUP(B21,'11'!B:BC,54,0),"0") -> 0 | AM21: กล่อง | AN21: =+AL21*D21 -> 0 | AO21: =IFERROR(VLOOKUP(B21,'12'!B:BC,54,0),"0") -> 0 | AP21: กล่อง | AQ21: =+AO21*D21 -> 0 | AR21: =IFERROR(VLOOKUP(B21,'13'!B:BC,54,0),"0") -> 0 | AS21: กล่อง | AT21: =+AR21*D21 -> 0 | AU21: =IFERROR(VLOOKUP(B21,'14'!B:BC,54,0),"0") -> 0 | AV21: กล่อง | AW21: =+AU21*D21 -> 0 | AX21: =IFERROR(VLOOKUP(B21,'15'!B:BC,54,0),"0") -> 0 | AY21: กล่อง | AZ21: =+AX21*D21 -> 0 | BA21: =IFERROR(VLOOKUP(B21,'16'!B:BC,54,0),"0") -> 0 | BB21: กล่อง | BC21: =+BA21*D21 -> 0 | BD21: =IFERROR(VLOOKUP(B21,'17'!B:BC,54,0),"0") -> 0 | BE21: กล่อง | BF21: =+BD21*D21 -> 0 | BG21: =IFERROR(VLOOKUP(B21,'18'!B:BC,54,0),"0") -> 0 | BH21: กล่อง | BI21: =+BG21*D21 -> 0 | BJ21: =IFERROR(VLOOKUP(B21,'19'!B:BC,54,0),"0") -> 0 | BK21: กล่อง | BL21: =+BJ21*D21 -> 0 | BM21: =IFERROR(VLOOKUP(B21,'20'!B:BC,54,0),"0") -> 0 | BN21: กล่อง | BO21: =+BM21*D21 -> 0 | BP21: =IFERROR(VLOOKUP(B21,'21'!B:BC,54,0),"0") -> 0 | BQ21: กล่อง | BR21: =+BP21*D21 -> 0 | BS21: =IFERROR(VLOOKUP(B21,'22'!B:BC,54,0),"0") -> 0 | BT21: กล่อง | BU21: =+BS21*D21 -> 0 | BV21: =IFERROR(VLOOKUP(B21,'23'!B:BC,54,0),"0") -> 0 | BW21: กล่อง | BX21: =+BV21*D21 -> 0 | BY21: =IFERROR(VLOOKUP(B21,'24'!B:BC,54,0),"0") -> 0 | BZ21: กล่อง | CA21: =+BY21*D21 -> 0 | CB21: =IFERROR(VLOOKUP(B21,'25'!B:BC,54,0),"0") -> 0 | CC21: กล่อง | CD21: =+CB21*D21 -> 0 | CE21: =IFERROR(VLOOKUP(B21,'26'!B:BC,54,0),"0") -> 0 | CF21: กล่อง | CG21: =+CE21*D21 -> 0 | CH21: =IFERROR(VLOOKUP(B21,'27'!B:BC,54,0),"0") -> 0 | CI21: กล่อง | CJ21: =+CH21*D21 -> 0 | CK21: =IFERROR(VLOOKUP(B21,'28'!B:BC,54,0),"0") -> 0 | CL21: กล่อง | CM21: =+CK21*D21 -> 0 | CN21: =IFERROR(VLOOKUP(B21,'29'!B:BC,54,0),"0") -> 0 | CO21: กล่อง | CP21: =+CN21*D21 -> 0 | CQ21: =IFERROR(VLOOKUP(B21,'30'!B:BC,54,0),"0") -> 0 | CR21: กล่อง | CS21: =+CQ21*D21 -> 0 | CT21: =IFERROR(VLOOKUP(A21,#REF!,2,0),"0") -> 0 | CU21: กล่อง | CV21: =+CT21*D21 -> 0 | CW21: =IFERROR(VLOOKUP(B21,'B-plus'!A:D,4,0),"0") -> 0 | CX21: กล่อง | CY21: =+CW21*D21 -> 0
