Workbook

Sheet บ่าย
B1: ยอดจริง ออนไลน์ วันที่ - บ่าย
L2: ยอดรวมผลิต
L3: จำนวน
B4: รหัสสินค้า | C4: สินค้า | D4: ปณ | E4: ชอปปี้ | F4: ลาซาด้า | G4: ติ๊กตอก | H4: ติ๊กตอก 2 | I4: ติ๊กตอก3 | J4: ชอยส์ | K4: ยอดเส้น | L4: (กล่อง)
B6: ชิฟฟอนรวมรส
B7: 1111002 | C7: ชิฟฟอนรวมรส 8 ชิ้น | L7: =SUM(D7:K7) -> 0
C8: ชิฟฟอนแบบกล่องสุ่มอะไรก็ได้ที่มี | L8: =SUM(D8:K8) -> 0
B9: 1111084 | C9: ชิฟฟอน 8 ชิ้น กาแฟล้วน | L9: =SUM(D9:K9) -> 0
B10: 1111085 | C10: ชิฟฟอน 8 ชิ้น บลูเบอรี่ล้วน | L10: =SUM(D10:K10) -> 0
B11: 1111086 | C11: ชิฟฟอน 8 ชิ้น มะพร้าวล้วน | L11: =SUM(D11:K11) -> 0
B12: 1111087 | C12: ชิฟฟอน 8 ชิ้น สตอเบอรี่ล้วน | L12: =SUM(D12:K12) -> 0
B13: 1111088 | C13: ชิฟฟอน 8 ชิ้น ส้มล้วน | L13: =SUM(D13:K13) -> 0
B14: 1111089 | C14: ชิฟฟอน 8 ชิ้น เนยล้วน | L14: =SUM(D14:K14) -> 0
B15: 1111090 | C15: ชิฟฟอน 8 ชิ้น เผือกล้วน | L15: =SUM(D15:K15) -> 0
B16: 1111091 | C16: ชิฟฟอน 8 ชิ้น ใบเตยล้วน | L16: =SUM(D16:K16) -> 0
B17: 1111092 | C17: ชิฟฟอน 8 ชิ้น กล้วยหอม | L17: =SUM(D17:K17) -> 0
B18: 1111093 | C18: ชิฟฟอน 8 ชิ้น โกโก้ล้วน | L18: =SUM(D18:K18) -> 0
B19: 1111094 | C19: ชิฟฟอน 8 ชิ้น ชาไทยล้วน | L19: =SUM(D19:K19) -> 0
B20: 1111095 | C20: ชิฟฟอน 8 ชิ้น ชาเขียวล้วน | L20: =SUM(D20:K20) -> 0
... B66: 1111010 | C66: ชิฟฟอนไส้แยมแยกชิ้น คละรส | L66: =SUM(D66:K66) -> 0
C67: รวม | L67: =SUM(L7:L66) -> 0
B68: ชิฟฟอนไส้แยม 6 ชิ้น
B69: 1111009 | C69: ชิฟฟอนไส้แยมรวมรส 6 ชิ้น | L69: =SUM(D69:K69) -> 0
B70: 1111023 | C70: ชิฟฟอนไส้แยมรสสตอเบอร์รี่ล้วน 6 ชิ้น | L70: =SUM(D70:K70) -> 0
B71: 1111016 | C71: ชิฟฟอนไส้แยมรสมะพร้าวล้วน 6 ชิ้น | L71: =SUM(D71:K71) -> 0
B72: 1111014 | C72: ชิฟฟอนไส้แยมรสช็อกโกแลตนูเทลล่าล้วน 6 ชิ้น | L72: =SUM(D72:K72) -> 0
B73: 1111025 | C73: ชิฟฟอนไส้แยมรสส้มล้วน 6 ชิ้น | L73: =SUM(D73:K73) -> 0
B74: 1111018 | C74: ชิฟฟอนไส้แยมรสบลูเบอร์รี่ล้วน 6 ชิ้น | L74: =SUM(D74:K74) -> 0
B75: 1111012 | C75: ชิฟฟอนไส้แยมรสนมชมพูฮอกไกโดล้วน 6 ชิ้น | L75: =SUM(D75:K75) -> 0
B76: 1111020 | C76: ชิฟฟอนไส้แยมฝอยทองไส้ทะลัก 6 ชิ้น | L76: =SUM(D76:K76) -> 0
C77: รวม | L77: =SUM(L69:L76) -> 0
B78: ชิฟฟอนไส้แยม 3 ชิ้น
B79: 1111022 | C79: ชิฟฟอนไส้แยมรสสตอเบอร์รี่ล้วน 3 ชิ้น | L79: =SUM(D79:K79) -> 0
B80: 1111015 | C80: ชิฟฟอนไส้แยมรสมะพร้าวล้วน 3 ชิ้น | L80: =SUM(D80:K80) -> 0
B81: 1111013 | C81: ชิฟฟอนไส้แยมรสช็อกโกแลตนูเทลล่าล้วน 3 ชิ้น | L81: =SUM(D81:K81) -> 0
B82: 1111024 | C82: ชิฟฟอนไส้แยมรสส้มล้วน 3 ชิ้น | L82: =SUM(D82:K82) -> 0
B83: 1111017 | C83: ชิฟฟอนไส้แยมรสบลูเบอร์รี่ล้วน 3 ชิ้น | L83: =SUM(D83:K83) -> 0
B84: 1111011 | C84: ชิฟฟอนไส้แยมรสนมชมพูฮอกไกโดล้วน 3 ชิ้น | L84: =SUM(D84:K84) -> 0
B85: 1111019 | C85: ชิฟฟอนไส้แยมฝอยทองไส้ทะลัก 3 ชิ้น | L85: =SUM(D85:K85) -> 0
B86: 1113081 | C86: ชิฟฟอนไส้แยม วนิลา/ใบเตย/เมล่อน | L86: =SUM(D86:K86) -> 0
...

Sheet เย็น 
B1: ยอดจริง ออนไลน์ วันที่ - เย็น
L2: ยอดรวมผลิต
L3: จำนวน
B4: รหัสสินค้า | C4: สินค้า | D4: ปณ | E4: ชอปปี้ | F4: ลาซาด้า | G4: ติ๊กตอก | H4: ติ๊กตอก 2 | I4: ติ๊กตอก3 | J4: ชอยส์ | K4: ยอดเส้น | L4: (กล่อง)
B6: ชิฟฟอนรวมรส
B7: 1111002 | C7: ชิฟฟอนรวมรส 8 ชิ้น | L7: =SUM(D7:K7) -> 0
C8: ชิฟฟอนแบบกล่องสุ่มอะไรก็ได้ที่มี | L8: =SUM(D8:K8) -> 0
B9: 1111084 | C9: ชิฟฟอน 8 ชิ้น กาแฟล้วน | L9: =SUM(D9:K9) -> 0
B10: 1111085 | C10: ชิฟฟอน 8 ชิ้น บลูเบอรี่ล้วน | L10: =SUM(D10:K10) -> 0
B11: 1111086 | C11: ชิฟฟอน 8 ชิ้น มะพร้าวล้วน | L11: =SUM(D11:K11) -> 0
B12: 1111087 | C12: ชิฟฟอน 8 ชิ้น สตอเบอรี่ล้วน | L12: =SUM(D12:K12) -> 0
B13: 1111088 | C13: ชิฟฟอน 8 ชิ้น ส้มล้วน | L13: =SUM(D13:K13) -> 0
B14: 1111089 | C14: ชิฟฟอน 8 ชิ้น เนยล้วน | L14: =SUM(D14:K14) -> 0
B15: 1111090 | C15: ชิฟฟอน 8 ชิ้น เผือกล้วน | L15: =SUM(D15:K15) -> 0
B16: 1111091 | C16: ชิฟฟอน 8 ชิ้น ใบเตยล้วน | L16: =SUM(D16:K16) -> 0
B17: 1111092 | C17: ชิฟฟอน 8 ชิ้น กล้วยหอม | L17: =SUM(D17:K17) -> 0
B18: 1111093 | C18: ชิฟฟอน 8 ชิ้น โกโก้ล้วน | L18: =SUM(D18:K18) -> 0
B19: 1111094 | C19: ชิฟฟอน 8 ชิ้น ชาไทยล้วน | L19: =SUM(D19:K19) -> 0
B20: 1111095 | C20: ชิฟฟอน 8 ชิ้น ชาเขียวล้วน | L20: =SUM(D20:K20) -> 0
... B66: 1111010 | C66: ชิฟฟอนไส้แยมแยกชิ้น คละรส | L66: =SUM(D66:K66) -> 0
C67: รวม | L67: =SUM(L7:L66) -> 0
B68: ชิฟฟอนไส้แยม 6 ชิ้น
B69: 1111009 | C69: ชิฟฟอนไส้แยมรวมรส 6 ชิ้น | L69: =SUM(D69:K69) -> 0
B70: 1111023 | C70: ชิฟฟอนไส้แยมรสสตอเบอร์รี่ล้วน 6 ชิ้น | L70: =SUM(D70:K70) -> 0
B71: 1111016 | C71: ชิฟฟอนไส้แยมรสมะพร้าวล้วน 6 ชิ้น | L71: =SUM(D71:K71) -> 0
B72: 1111014 | C72: ชิฟฟอนไส้แยมรสช็อกโกแลตนูเทลล่าล้วน 6 ชิ้น | L72: =SUM(D72:K72) -> 0
B73: 1111025 | C73: ชิฟฟอนไส้แยมรสส้มล้วน 6 ชิ้น | L73: =SUM(D73:K73) -> 0
B74: 1111018 | C74: ชิฟฟอนไส้แยมรสบลูเบอร์รี่ล้วน 6 ชิ้น | L74: =SUM(D74:K74) -> 0
B75: 1111012 | C75: ชิฟฟอนไส้แยมรสนมชมพูฮอกไกโดล้วน 6 ชิ้น | L75: =SUM(D75:K75) -> 0
B76: 1111020 | C76: ชิฟฟอนไส้แยมฝอยทองไส้ทะลัก 6 ชิ้น | L76: =SUM(D76:K76) -> 0
C77: รวม | L77: =SUM(L69:L76) -> 0
B78: ชิฟฟอนไส้แยม 3 ชิ้น
B79: 1111022 | C79: ชิฟฟอนไส้แยมรสสตอเบอร์รี่ล้วน 3 ชิ้น | L79: =SUM(D79:K79) -> 0
B80: 1111015 | C80: ชิฟฟอนไส้แยมรสมะพร้าวล้วน 3 ชิ้น | L80: =SUM(D80:K80) -> 0
B81: 1111013 | C81: ชิฟฟอนไส้แยมรสช็อกโกแลตนูเทลล่าล้วน 3 ชิ้น | L81: =SUM(D81:K81) -> 0
B82: 1111024 | C82: ชิฟฟอนไส้แยมรสส้มล้วน 3 ชิ้น | L82: =SUM(D82:K82) -> 0
B83: 1111017 | C83: ชิฟฟอนไส้แยมรสบลูเบอร์รี่ล้วน 3 ชิ้น | L83: =SUM(D83:K83) -> 0
B84: 1111011 | C84: ชิฟฟอนไส้แยมรสนมชมพูฮอกไกโดล้วน 3 ชิ้น | L84: =SUM(D84:K84) -> 0
B85: 1111019 | C85: ชิฟฟอนไส้แยมฝอยทองไส้ทะลัก 3 ชิ้น | L85: =SUM(D85:K85) -> 0
B86: 1113081 | C86: ชิฟฟอนไส้แยม วนิลา/ใบเตย/เมล่อน | L86: =SUM(D86:K86) -> 0
...

Sheet 01.7.68
B1: ยอดจริง ออนไลน์ วันที่ 1/7/2569
B2: รหัสสินค้า | C2: สินค้า | D2: ปณ | H2: ชอปปี้ | L2: ลาซาด้า | P2: ติ๊กตอก | T2: ติ๊กตอก2 | X2: ติ๊กตอก3 | AB2: ติ๊กตอก4 | AF2: ติ๊กตอก5 | AJ2: ติ๊กตอก6 | AN2: ติ๊กตอก7 | AR2: ติ๊กตอก8 | AV2: ติ๊กตอก9 | AZ2: ยอดเส้น | BA2: ยอดรวมผลิต(กล่อง) | BB2: ยอดยกเลิก | BC2: สรุปใช้จริง | BD2: ยอดForcast | BE2: ยอดStock | BF2: ยอดMemo | BG2: ยอดForcastวันพรุ่งนี้ | BH2: สินค้าที่ขายได้
D3: เช้า | E3: บ่าย | F3: เย็น | G3: รวม | H3: เช้า | I3: บ่าย | J3: เย็น | K3: รวม | L3: เช้า | M3: บ่าย | N3: เย็น | O3: รวม | P3: เช้า | Q3: บ่าย | R3: เย็น | S3: รวม | T3: เช้า | U3: บ่าย | V3: เย็น | W3: รวม | X3: เช้า | Y3: บ่าย | Z3: เย็น | AA3: รวม | AB3: เช้า | AC3: บ่าย | AD3: เย็น | AE3: รวม | AF3: เช้า | AG3: บ่าย | AH3: เย็น | AI3: รวม | AJ3: เช้า | AK3: บ่าย | AL3: เย็น | AM3: รวม | AN3: เช้า | AO3: บ่าย | AP3: เย็น | AQ3: รวม | AR3: เช้า | AS3: บ่าย | AT3: เย็น | AU3: รวม | AV3: เช้า | AW3: บ่าย | AX3: เย็น | AY3: รวม
B4: 1004055 | C4: ชิฟฟ่อนเค้ก วรรณวนัช (รวมรส 4 ชิ้น) | G4: =SUM(D4:F4) -> 0 | K4: =SUM(H4:J4) -> 0 | O4: =SUM(L4:N4) -> 0 | S4: =SUM(P4:R4) -> 0 | W4: =SUM(T4:V4) -> 0 | AA4: =SUM(X4:Z4) -> 0 | AE4: =SUM(AB4:AD4) -> 0 | AI4: =SUM(AF4:AH4) -> 0 | AM4: =SUM(AJ4:AL4) -> 0 | AQ4: =SUM(AN4:AP4) -> 0 | AU4: =SUM(AR4:AT4) -> 0 | AY4: =SUM(AV4:AX4) -> 0 | AZ4: 5 | BA4: =+G4+K4+O4+S4+W4+AA4+AE4+AZ4+AI4+AM4+AQ4+AU4+AY4 -> 5 | BC4: =+BA4-BB4 -> 5 | BD4: 5 | BF4: =+BD4+BE4-BC4 -> 0 | BH4: =BF4+BG4 -> 0
B5: 1111002 | C5: ชิฟฟ่อนเค้ก วรรณวนัช (รวมรส 8 ชิ้น) | D5: 3 | G5: =SUM(D5:F5) -> 3 | H5: 11 | K5: =SUM(H5:J5) -> 11 | L5: 7 | O5: =SUM(L5:N5) -> 7 | P5: 9 | S5: =SUM(P5:R5) -> 9 | W5: =SUM(T5:V5) -> 0 | AA5: =SUM(X5:Z5) -> 0 | AE5: =SUM(AB5:AD5) -> 0 | AI5: =SUM(AF5:AH5) -> 0 | AM5: =SUM(AJ5:AL5) -> 0 | AQ5: =SUM(AN5:AP5) -> 0 | AU5: =SUM(AR5:AT5) -> 0 | AY5: =SUM(AV5:AX5) -> 0 | AZ5: 5 | BA5: =+G5+K5+O5+S5+W5+AA5+AE5+AZ5+AI5+AM5+AQ5+AU5+AY5 -> 35 | BC5: =+BA5-BB5 -> 35 | BD5: 5 | BE5: 235 | BF5: =+BD5+BE5-BC5 -> 205 | BH5: =BF5+BG5 -> 205
B6: 1111001 | C6: ชิฟฟ่อนแยกชิ้นไม่มีไส้ คละรส | G6: =SUM(D6:F6) -> 0 | K6: =SUM(H6:J6) -> 0 | O6: =SUM(L6:N6) -> 0 | S6: =SUM(P6:R6) -> 0 | W6: =SUM(T6:V6) -> 0 | AA6: =SUM(X6:Z6) -> 0 | AE6: =SUM(AB6:AD6) -> 0 | AI6: =SUM(AF6:AH6) -> 0 | AM6: =SUM(AJ6:AL6) -> 0 | AQ6: =SUM(AN6:AP6) -> 0 | AU6: =SUM(AR6:AT6) -> 0 | AY6: =SUM(AV6:AX6) -> 0 | BA6: =+G6+K6+O6+S6+W6+AA6+AE6+AZ6+AI6+AM6+AQ6+AU6+AY6 -> 0 | BC6: =+BA6-BB6 -> 0 | BF6: =+BD6+BE6-BC6 -> 0 | BH6: =BF6+BG6 -> 0
B7: 1111043 | C7: ชิฟฟอนรสมะลิ 8 ชิ้น ห่อ ซีน | G7: =SUM(D7:F7) -> 0 | K7: =SUM(H7:J7) -> 0 | O7: =SUM(L7:N7) -> 0 | S7: =SUM(P7:R7) -> 0 | W7: =SUM(T7:V7) -> 0 | AA7: =SUM(X7:Z7) -> 0 | AE7: =SUM(AB7:AD7) -> 0 | AI7: =SUM(AF7:AH7) -> 0 | AM7: =SUM(AJ7:AL7) -> 0 | AQ7: =SUM(AN7:AP7) -> 0 | AU7: =SUM(AR7:AT7) -> 0 | AY7: =SUM(AV7:AX7) -> 0 | BA7: =+G7+K7+O7+S7+W7+AA7+AE7+AZ7+AI7+AM7+AQ7+AU7+AY7 -> 0 | BC7: =+BA7-BB7 -> 0 | BF7: =+BD7+BE7-BC7 -> 0 | BH7: =BF7+BG7 -> 0
B8: 1111057 | C8: ชิฟฟอนแยกชิ้น กาแฟ | G8: =SUM(D8:F8) -> 0 | K8: =SUM(H8:J8) -> 0 | O8: =SUM(L8:N8) -> 0 | S8: =SUM(P8:R8) -> 0 | W8: =SUM(T8:V8) -> 0 | AA8: =SUM(X8:Z8) -> 0 | AE8: =SUM(AB8:AD8) -> 0 | AI8: =SUM(AF8:AH8) -> 0 | AM8: =SUM(AJ8:AL8) -> 0 | AQ8: =SUM(AN8:AP8) -> 0 | AU8: =SUM(AR8:AT8) -> 0 | AY8: =SUM(AV8:AX8) -> 0 | BA8: =+G8+K8+O8+S8+W8+AA8+AE8+AZ8+AI8+AM8+AQ8+AU8+AY8 -> 0 | BC8: =+BA8-BB8 -> 0 | BF8: =+BD8+BE8-BC8 -> 0 | BH8: =BF8+BG8 -> 0
B9: 1111058 | C9: ชิฟฟอนแยกชิ้น ชาเขียว | G9: =SUM(D9:F9) -> 0 | K9: =SUM(H9:J9) -> 0 | O9: =SUM(L9:N9) -> 0 | S9: =SUM(P9:R9) -> 0 | W9: =SUM(T9:V9) -> 0 | AA9: =SUM(X9:Z9) -> 0 | AE9: =SUM(AB9:AD9) -> 0 | AI9: =SUM(AF9:AH9) -> 0 | AM9: =SUM(AJ9:AL9) -> 0 | AQ9: =SUM(AN9:AP9) -> 0 | AU9: =SUM(AR9:AT9) -> 0 | AY9: =SUM(AV9:AX9) -> 0 | BA9: =+G9+K9+O9+S9+W9+AA9+AE9+AZ9+AI9+AM9+AQ9+AU9+AY9 -> 0 | BC9: =+BA9-BB9 -> 0 | BF9: =+BD9+BE9-BC9 -> 0 | BH9: =BF9+BG9 -> 0
B10: 1111059 | C10: ชิฟฟอนแยกชิ้น ใบเตย | G10: =SUM(D10:F10) -> 0 | K10: =SUM(H10:J10) -> 0 | O10: =SUM(L10:N10) -> 0 | S10: =SUM(P10:R10) -> 0 | W10: =SUM(T10:V10) -> 0 | AA10: =SUM(X10:Z10) -> 0 | AE10: =SUM(AB10:AD10) -> 0 | AI10: =SUM(AF10:AH10) -> 0 | AM10: =SUM(AJ10:AL10) -> 0 | AQ10: =SUM(AN10:AP10) -> 0 | AU10: =SUM(AR10:AT10) -> 0 | AY10: =SUM(AV10:AX10) -> 0 | BA10: =+G10+K10+O10+S10+W10+AA10+AE10+AZ10+AI10+AM10+AQ10+AU10+AY10 -> 0 | BC10: =+BA10-BB10 -> 0 | BF10: =+BD10+BE10-BC10 -> 0 | BH10: =BF10+BG10 -> 0
B11: 1111060 | C11: ชิฟฟอนแยกชิ้น กล้วยหอม | G11: =SUM(D11:F11) -> 0 | K11: =SUM(H11:J11) -> 0 | O11: =SUM(L11:N11) -> 0 | S11: =SUM(P11:R11) -> 0 | W11: =SUM(T11:V11) -> 0 | AA11: =SUM(X11:Z11) -> 0 | AE11: =SUM(AB11:AD11) -> 0 | AI11: =SUM(AF11:AH11) -> 0 | AM11: =SUM(AJ11:AL11) -> 0 | AQ11: =SUM(AN11:AP11) -> 0 | AU11: =SUM(AR11:AT11) -> 0 | AY11: =SUM(AV11:AX11) -> 0 | BA11: =+G11+K11+O11+S11+W11+AA11+AE11+AZ11+AI11+AM11+AQ11+AU11+AY11 -> 0 | BC11: =+BA11-BB11 -> 0 | BF11: =+BD11+BE11-BC11 -> 0 | BH11: =BF11+BG11 -> 0
B12: 1111061 | C12: ชิฟฟอนแยกชิ้น ชาไทย | G12: =SUM(D12:F12) -> 0 | K12: =SUM(H12:J12) -> 0 | O12: =SUM(L12:N12) -> 0 | S12: =SUM(P12:R12) -> 0 | W12: =SUM(T12:V12) -> 0 | AA12: =SUM(X12:Z12) -> 0 | AE12: =SUM(AB12:AD12) -> 0 | AI12: =SUM(AF12:AH12) -> 0 | AM12: =SUM(AJ12:AL12) -> 0 | AQ12: =SUM(AN12:AP12) -> 0 | AU12: =SUM(AR12:AT12) -> 0 | AY12: =SUM(AV12:AX12) -> 0 | BA12: =+G12+K12+O12+S12+W12+AA12+AE12+AZ12+AI12+AM12+AQ12+AU12+AY12 -> 0 | BC12: =+BA12-BB12 -> 0 | BF12: =+BD12+BE12-BC12 -> 0 | BH12: =BF12+BG12 -> 0
B13: 1111062 | C13: ชิฟฟอนแยกชิ้น โกโก้ | G13: =SUM(D13:F13) -> 0 | K13: =SUM(H13:J13) -> 0 | O13: =SUM(L13:N13) -> 0 | S13: =SUM(P13:R13) -> 0 | W13: =SUM(T13:V13) -> 0 | AA13: =SUM(X13:Z13) -> 0 | AE13: =SUM(AB13:AD13) -> 0 | AI13: =SUM(AF13:AH13) -> 0 | AM13: =SUM(AJ13:AL13) -> 0 | AQ13: =SUM(AN13:AP13) -> 0 | AU13: =SUM(AR13:AT13) -> 0 | AY13: =SUM(AV13:AX13) -> 0 | BA13: =+G13+K13+O13+S13+W13+AA13+AE13+AZ13+AI13+AM13+AQ13+AU13+AY13 -> 0 | BC13: =+BA13-BB13 -> 0 | BF13: =+BD13+BE13-BC13 -> 0 | BH13: =BF13+BG13 -> 0
B14: 1111063 | C14: ชิฟฟอนแยกชิ้น ส้ม | G14: =SUM(D14:F14) -> 0 | K14: =SUM(H14:J14) -> 0 | O14: =SUM(L14:N14) -> 0 | S14: =SUM(P14:R14) -> 0 | W14: =SUM(T14:V14) -> 0 | AA14: =SUM(X14:Z14) -> 0 | AE14: =SUM(AB14:AD14) -> 0 | AI14: =SUM(AF14:AH14) -> 0 | AM14: =SUM(AJ14:AL14) -> 0 | AQ14: =SUM(AN14:AP14) -> 0 | AU14: =SUM(AR14:AT14) -> 0 | AY14: =SUM(AV14:AX14) -> 0 | BA14: =+G14+K14+O14+S14+W14+AA14+AE14+AZ14+AI14+AM14+AQ14+AU14+AY14 -> 0 | BC14: =+BA14-BB14 -> 0 | BF14: =+BD14+BE14-BC14 -> 0 | BH14: =BF14+BG14 -> 0
B15: 1111064 | C15: ชิฟฟอนแยกชิ้น เผือก | G15: =SUM(D15:F15) -> 0 | K15: =SUM(H15:J15) -> 0 | O15: =SUM(L15:N15) -> 0 | S15: =SUM(P15:R15) -> 0 | W15: =SUM(T15:V15) -> 0 | AA15: =SUM(X15:Z15) -> 0 | AE15: =SUM(AB15:AD15) -> 0 | AI15: =SUM(AF15:AH15) -> 0 | AM15: =SUM(AJ15:AL15) -> 0 | AQ15: =SUM(AN15:AP15) -> 0 | AU15: =SUM(AR15:AT15) -> 0 | AY15: =SUM(AV15:AX15) -> 0 | BA15: =+G15+K15+O15+S15+W15+AA15+AE15+AZ15+AI15+AM15+AQ15+AU15+AY15 -> 0 | BC15: =+BA15-BB15 -> 0 | BF15: =+BD15+BE15-BC15 -> 0 | BH15: =BF15+BG15 -> 0
B16: 1111065 | C16: ชิฟฟอนแยกชิ้น สับปะรด | G16: =SUM(D16:F16) -> 0 | K16: =SUM(H16:J16) -> 0 | O16: =SUM(L16:N16) -> 0 | S16: =SUM(P16:R16) -> 0 | W16: =SUM(T16:V16) -> 0 | AA16: =SUM(X16:Z16) -> 0 | AE16: =SUM(AB16:AD16) -> 0 | AI16: =SUM(AF16:AH16) -> 0 | AM16: =SUM(AJ16:AL16) -> 0 | AQ16: =SUM(AN16:AP16) -> 0 | AU16: =SUM(AR16:AT16) -> 0 | AY16: =SUM(AV16:AX16) -> 0 | BA16: =+G16+K16+O16+S16+W16+AA16+AE16+AZ16+AI16+AM16+AQ16+AU16+AY16 -> 0 | BC16: =+BA16-BB16 -> 0 | BF16: =+BD16+BE16-BC16 -> 0 | BH16: =BF16+BG16 -> 0
B17: 1111066 | C17: ชิฟฟอนแยกชิ้น สตอเบอรี่ | G17: =SUM(D17:F17) -> 0 | K17: =SUM(H17:J17) -> 0 | O17: =SUM(L17:N17) -> 0 | S17: =SUM(P17:R17) -> 0 | W17: =SUM(T17:V17) -> 0 | AA17: =SUM(X17:Z17) -> 0 | AE17: =SUM(AB17:AD17) -> 0 | AI17: =SUM(AF17:AH17) -> 0 | AM17: =SUM(AJ17:AL17) -> 0 | AQ17: =SUM(AN17:AP17) -> 0 | AU17: =SUM(AR17:AT17) -> 0 | AY17: =SUM(AV17:AX17) -> 0 | BA17: =+G17+K17+O17+S17+W17+AA17+AE17+AZ17+AI17+AM17+AQ17+AU17+AY17 -> 0 | BC17: =+BA17-BB17 -> 0 | BF17: =+BD17+BE17-BC17 -> 0 | BH17: =BF17+BG17 -> 0
... B22: 1111071 | C22: ชิฟฟอนแยกชิ้น ตาล | G22: =SUM(D22:F22) -> 0 | K22: =SUM(H22:J22) -> 0 | O22: =SUM(L22:N22) -> 0 | S22: =SUM(P22:R22) -> 0 | W22: =SUM(T22:V22) -> 0 | AA22: =SUM(X22:Z22) -> 0 | AE22: =SUM(AB22:AD22) -> 0 | AI22: =SUM(AF22:AH22) -> 0 | AM22: =SUM(AJ22:AL22) -> 0 | AQ22: =SUM(AN22:AP22) -> 0 | AU22: =SUM(AR22:AT22) -> 0 | AY22: =SUM(AV22:AX22) -> 0 | BA22: =+G22+K22+O22+S22+W22+AA22+AE22+AZ22+AI22+AM22+AQ22+AU22+AY22 -> 0 | BC22: =+BA22-BB22 -> 0 | BF22: =+BD22+BE22-BC22 -> 0 | BH22: =BF22+BG22 -> 0
B23: 1111010 | C23: ชิฟฟ่อนเค้กสอดไส้แยม (1 ชิ้น) | G23: =SUM(D23:F23) -> 0 | H23: 20 | K23: =SUM(H23:J23) -> 20 | O23: =SUM(L23:N23) -> 0 | P23: 20 | S23: =SUM(P23:R23) -> 20 | W23: =SUM(T23:V23) -> 0 | AA23: =SUM(X23:Z23) -> 0 | AE23: =SUM(AB23:AD23) -> 0 | AI23: =SUM(AF23:AH23) -> 0 | AM23: =SUM(AJ23:AL23) -> 0 | AQ23: =SUM(AN23:AP23) -> 0 | AU23: =SUM(AR23:AT23) -> 0 | AY23: =SUM(AV23:AX23) -> 0 | BA23: =+G23+K23+O23+S23+W23+AA23+AE23+AZ23+AI23+AM23+AQ23+AU23+AY23 -> 40 | BC23: =+BA23-BB23 -> 40 | BF23: =+BD23+BE23-BC23 -> -40 | BH23: =BF23+BG23 -> -40
B24: 1111008 | C24: ชิฟฟ่อนเค้ก สอดไส้ (รวมรส 3 ชิ้น) | G24: =SUM(D24:F24) -> 0 | H24: 10 | K24: =SUM(H24:J24) -> 10 | L24: 9 | O24: =SUM(L24:N24) -> 9 | P24: 52 | S24: =SUM(P24:R24) -> 52 | W24: =SUM(T24:V24) -> 0 | AA24: =SUM(X24:Z24) -> 0 | AE24: =SUM(AB24:AD24) -> 0 | AI24: =SUM(AF24:AH24) -> 0 | AM24: =SUM(AJ24:AL24) -> 0 | AQ24: =SUM(AN24:AP24) -> 0 | AU24: =SUM(AR24:AT24) -> 0 | AY24: =SUM(AV24:AX24) -> 0 | AZ24: 10 | BA24: =+G24+K24+O24+S24+W24+AA24+AE24+AZ24+AI24+AM24+AQ24+AU24+AY24 -> 81 | BC24: =+BA24-BB24 -> 81 | BD24: 10 | BE24: 223 | BF24: =+BD24+BE24-BC24 -> 152 | BH24: =BF24+BG24 -> 152
B25: 1111009 | C25: ชิฟฟ่อนเค้ก สอดไส้ (รวมรส 6 ชิ้น) | G25: =SUM(D25:F25) -> 0 | H25: 1 | K25: =SUM(H25:J25) -> 1 | O25: =SUM(L25:N25) -> 0 | S25: =SUM(P25:R25) -> 0 | W25: =SUM(T25:V25) -> 0 | AA25: =SUM(X25:Z25) -> 0 | AE25: =SUM(AB25:AD25) -> 0 | AI25: =SUM(AF25:AH25) -> 0 | AM25: =SUM(AJ25:AL25) -> 0 | AQ25: =SUM(AN25:AP25) -> 0 | AU25: =SUM(AR25:AT25) -> 0 | AY25: =SUM(AV25:AX25) -> 0 | BA25: =+G25+K25+O25+S25+W25+AA25+AE25+AZ25+AI25+AM25+AQ25+AU25+AY25 -> 1 | BC25: =+BA25-BB25 -> 1 | BE25: 19 | BF25: =+BD25+BE25-BC25 -> 18 | BH25: =BF25+BG25 -> 18
B26: 1111011 | C26: ชิฟฟ่อนเค้กสอดไส้ นมชมพูฮอกไกโด (3 ชิ้น) | G26: =SUM(D26:F26) -> 0 | K26: =SUM(H26:J26) -> 0 | O26: =SUM(L26:N26) -> 0 | S26: =SUM(P26:R26) -> 0 | W26: =SUM(T26:V26) -> 0 | AA26: =SUM(X26:Z26) -> 0 | AE26: =SUM(AB26:AD26) -> 0 | AI26: =SUM(AF26:AH26) -> 0 | AM26: =SUM(AJ26:AL26) -> 0 | AQ26: =SUM(AN26:AP26) -> 0 | AU26: =SUM(AR26:AT26) -> 0 | AY26: =SUM(AV26:AX26) -> 0 | BA26: =+G26+K26+O26+S26+W26+AA26+AE26+AZ26+AI26+AM26+AQ26+AU26+AY26 -> 0 | BC26: =+BA26-BB26 -> 0 | BF26: =+BD26+BE26-BC26 -> 0 | BH26: =BF26+BG26 -> 0
B27: 1111012 | C27: ชิฟฟ่อนเค้กสอดไส้ นมชมพูฮอกไกโด (6 ชิ้น) | G27: =SUM(D27:F27) -> 0 | K27: =SUM(H27:J27) -> 0 | O27: =SUM(L27:N27) -> 0 | S27: =SUM(P27:R27) -> 0 | W27: =SUM(T27:V27) -> 0 | AA27: =SUM(X27:Z27) -> 0 | AE27: =SUM(AB27:AD27) -> 0 | AI27: =SUM(AF27:AH27) -> 0 | AM27: =SUM(AJ27:AL27) -> 0 | AQ27: =SUM(AN27:AP27) -> 0 | AU27: =SUM(AR27:AT27) -> 0 | AY27: =SUM(AV27:AX27) -> 0 | BA27: =+G27+K27+O27+S27+W27+AA27+AE27+AZ27+AI27+AM27+AQ27+AU27+AY27 -> 0 | BC27: =+BA27-BB27 -> 0 | BF27: =+BD27+BE27-BC27 -> 0 | BH27: =BF27+BG27 -> 0
B28: 1111013 | C28: ชิฟฟ่อนเค้กสอดไส้ ช็อคโกแลตนูเทลล่า (3 ชิ้น) | G28: =SUM(D28:F28) -> 0 | K28: =SUM(H28:J28) -> 0 | O28: =SUM(L28:N28) -> 0 | S28: =SUM(P28:R28) -> 0 | W28: =SUM(T28:V28) -> 0 | AA28: =SUM(X28:Z28) -> 0 | AE28: =SUM(AB28:AD28) -> 0 | AI28: =SUM(AF28:AH28) -> 0 | AM28: =SUM(AJ28:AL28) -> 0 | AQ28: =SUM(AN28:AP28) -> 0 | AU28: =SUM(AR28:AT28) -> 0 | AY28: =SUM(AV28:AX28) -> 0 | BA28: =+G28+K28+O28+S28+W28+AA28+AE28+AZ28+AI28+AM28+AQ28+AU28+AY28 -> 0 | BC28: =+BA28-BB28 -> 0 | BF28: =+BD28+BE28-BC28 -> 0 | BH28: =BF28+BG28 -> 0
B29: 1111014 | C29: ชิฟฟ่อนเค้กสอดไส้ ช็อคโกแลตนูเทลล่า (6 ชิ้น) | G29: =SUM(D29:F29) -> 0 | K29: =SUM(H29:J29) -> 0 | O29: =SUM(L29:N29) -> 0 | S29: =SUM(P29:R29) -> 0 | W29: =SUM(T29:V29) -> 0 | AA29: =SUM(X29:Z29) -> 0 | AE29: =SUM(AB29:AD29) -> 0 | AI29: =SUM(AF29:AH29) -> 0 | AM29: =SUM(AJ29:AL29) -> 0 | AQ29: =SUM(AN29:AP29) -> 0 | AU29: =SUM(AR29:AT29) -> 0 | AY29: =SUM(AV29:AX29) -> 0 | BA29: =+G29+K29+O29+S29+W29+AA29+AE29+AZ29+AI29+AM29+AQ29+AU29+AY29 -> 0 | BC29: =+BA29-BB29 -> 0 | BF29: =+BD29+BE29-BC29 -> 0 | BH29: =BF29+BG29 -> 0
B30: 1111015 | C30: ชิฟฟ่อนเค้กสอดไส้เนย รสมะพร้าว (3 ชิ้น) | G30: =SUM(D30:F30) -> 0 | K30: =SUM(H30:J30) -> 0 | O30: =SUM(L30:N30) -> 0 | S30: =SUM(P30:R30) -> 0 | W30: =SUM(T30:V30) -> 0 | AA30: =SUM(X30:Z30) -> 0 | AE30: =SUM(AB30:AD30) -> 0 | AI30: =SUM(AF30:AH30) -> 0 | AM30: =SUM(AJ30:AL30) -> 0 | AQ30: =SUM(AN30:AP30) -> 0 | AU30: =SUM(AR30:AT30) -> 0 | AY30: =SUM(AV30:AX30) -> 0 | BA30: =+G30+K30+O30+S30+W30+AA30+AE30+AZ30+AI30+AM30+AQ30+AU30+AY30 -> 0 | BC30: =+BA30-BB30 -> 0 | BF30: =+BD30+BE30-BC30 -> 0 | BH30: =BF30+BG30 -> 0
B31: 1111016 | C31: ชิฟฟ่อนเค้กสอดไส้เนย รสมะพร้าว (6 ชิ้น) | G31: =SUM(D31:F31) -> 0 | K31: =SUM(H31:J31) -> 0 | O31: =SUM(L31:N31) -> 0 | S31: =SUM(P31:R31) -> 0 | W31: =SUM(T31:V31) -> 0 | AA31: =SUM(X31:Z31) -> 0 | AE31: =SUM(AB31:AD31) -> 0 | AI31: =SUM(AF31:AH31) -> 0 | AM31: =SUM(AJ31:AL31) -> 0 | AQ31: =SUM(AN31:AP31) -> 0 | AU31: =SUM(AR31:AT31) -> 0 | AY31: =SUM(AV31:AX31) -> 0 | BA31: =+G31+K31+O31+S31+W31+AA31+AE31+AZ31+AI31+AM31+AQ31+AU31+AY31 -> 0 | BC31: =+BA31-BB31 -> 0 | BF31: =+BD31+BE31-BC31 -> 0 | BH31: =BF31+BG31 -> 0
B32: 1111017 | C32: ชิฟฟ่อนเค้กสอดไส้แยม รสบลูเบอร์รี่ (3 ชิ้น) | G32: =SUM(D32:F32) -> 0 | K32: =SUM(H32:J32) -> 0 | O32: =SUM(L32:N32) -> 0 | S32: =SUM(P32:R32) -> 0 | W32: =SUM(T32:V32) -> 0 | AA32: =SUM(X32:Z32) -> 0 | AE32: =SUM(AB32:AD32) -> 0 | AI32: =SUM(AF32:AH32) -> 0 | AM32: =SUM(AJ32:AL32) -> 0 | AQ32: =SUM(AN32:AP32) -> 0 | AU32: =SUM(AR32:AT32) -> 0 | AY32: =SUM(AV32:AX32) -> 0 | BA32: =+G32+K32+O32+S32+W32+AA32+AE32+AZ32+AI32+AM32+AQ32+AU32+AY32 -> 0 | BC32: =+BA32-BB32 -> 0 | BF32: =+BD32+BE32-BC32 -> 0 | BH32: =BF32+BG32 -> 0
B33: 1111018 | C33: ชิฟฟ่อนเค้กสอดไส้แยม รสบลูเบอร์รี่ (6 ชิ้น) | G33: =SUM(D33:F33) -> 0 | K33: =SUM(H33:J33) -> 0 | O33: =SUM(L33:N33) -> 0 | S33: =SUM(P33:R33) -> 0 | W33: =SUM(T33:V33) -> 0 | AA33: =SUM(X33:Z33) -> 0 | AE33: =SUM(AB33:AD33) -> 0 | AI33: =SUM(AF33:AH33) -> 0 | AM33: =SUM(AJ33:AL33) -> 0 | AQ33: =SUM(AN33:AP33) -> 0 | AU33: =SUM(AR33:AT33) -> 0 | AY33: =SUM(AV33:AX33) -> 0 | BA33: =+G33+K33+O33+S33+W33+AA33+AE33+AZ33+AI33+AM33+AQ33+AU33+AY33 -> 0 | BC33: =+BA33-BB33 -> 0 | BF33: =+BD33+BE33-BC33 -> 0 | BH33: =BF33+BG33 -> 0
B34: 1111019 | C34: ชิฟฟ่อนเค้กหน้าฝอยทอง สอดไส้แยมส้ม (3 ชิ้น) | G34: =SUM(D34:F34) -> 0 | K34: =SUM(H34:J34) -> 0 | O34: =SUM(L34:N34) -> 0 | S34: =SUM(P34:R34) -> 0 | W34: =SUM(T34:V34) -> 0 | AA34: =SUM(X34:Z34) -> 0 | AE34: =SUM(AB34:AD34) -> 0 | AI34: =SUM(AF34:AH34) -> 0 | AM34: =SUM(AJ34:AL34) -> 0 | AQ34: =SUM(AN34:AP34) -> 0 | AU34: =SUM(AR34:AT34) -> 0 | AY34: =SUM(AV34:AX34) -> 0 | BA34: =+G34+K34+O34+S34+W34+AA34+AE34+AZ34+AI34+AM34+AQ34+AU34+AY34 -> 0 | BC34: =+BA34-BB34 -> 0 | BF34: =+BD34+BE34-BC34 -> 0 | BH34: =BF34+BG34 -> 0
B35: 1111020 | C35: ชิฟฟ่อนเค้กหน้าฝอยทอง สอดไส้แยมส้ม (6 ชิ้น) | G35: =SUM(D35:F35) -> 0 | K35: =SUM(H35:J35) -> 0 | O35: =SUM(L35:N35) -> 0 | S35: =SUM(P35:R35) -> 0 | W35: =SUM(T35:V35) -> 0 | AA35: =SUM(X35:Z35) -> 0 | AE35: =SUM(AB35:AD35) -> 0 | AI35: =SUM(AF35:AH35) -> 0 | AM35: =SUM(AJ35:AL35) -> 0 | AQ35: =SUM(AN35:AP35) -> 0 | AU35: =SUM(AR35:AT35) -> 0 | AY35: =SUM(AV35:AX35) -> 0 | BA35: =+G35+K35+O35+S35+W35+AA35+AE35+AZ35+AI35+AM35+AQ35+AU35+AY35 -> 0 | BC35: =+BA35-BB35 -> 0 | BF35: =+BD35+BE35-BC35 -> 0 | BH35: =BF35+BG35 -> 0
B36: 1111022 | C36: ชิฟฟ่อนเค้กสอดไส้แยม รสสตรอว์เบอร์รี (3 ชิ้น) | G36: =SUM(D36:F36) -> 0 | K36: =SUM(H36:J36) -> 0 | O36: =SUM(L36:N36) -> 0 | S36: =SUM(P36:R36) -> 0 | W36: =SUM(T36:V36) -> 0 | AA36: =SUM(X36:Z36) -> 0 | AE36: =SUM(AB36:AD36) -> 0 | AI36: =SUM(AF36:AH36) -> 0 | AM36: =SUM(AJ36:AL36) -> 0 | AQ36: =SUM(AN36:AP36) -> 0 | AU36: =SUM(AR36:AT36) -> 0 | AY36: =SUM(AV36:AX36) -> 0 | BA36: =+G36+K36+O36+S36+W36+AA36+AE36+AZ36+AI36+AM36+AQ36+AU36+AY36 -> 0 | BC36: =+BA36-BB36 -> 0 | BF36: =+BD36+BE36-BC36 -> 0 | BH36: =BF36+BG36 -> 0
B37: 1111023 | C37: ชิฟฟ่อนเค้กสอดไส้แยม รสสตรอว์เบอร์รี (6 ชิ้น) | G37: =SUM(D37:F37) -> 0 | K37: =SUM(H37:J37) -> 0 | O37: =SUM(L37:N37) -> 0 | S37: =SUM(P37:R37) -> 0 | W37: =SUM(T37:V37) -> 0 | AA37: =SUM(X37:Z37) -> 0 | AE37: =SUM(AB37:AD37) -> 0 | AI37: =SUM(AF37:AH37) -> 0 | AM37: =SUM(AJ37:AL37) -> 0 | AQ37: =SUM(AN37:AP37) -> 0 | AU37: =SUM(AR37:AT37) -> 0 | AY37: =SUM(AV37:AX37) -> 0 | BA37: =+G37+K37+O37+S37+W37+AA37+AE37+AZ37+AI37+AM37+AQ37+AU37+AY37 -> 0 | BC37: =+BA37-BB37 -> 0 | BF37: =+BD37+BE37-BC37 -> 0 | BH37: =BF37+BG37 -> 0
... B39: 1111025 | C39: ชิฟฟ่อนเค้กสอดไส้แยม รสส้ม (6 ชิ้น) | G39: =SUM(D39:F39) -> 0 | K39: =SUM(H39:J39) -> 0 | O39: =SUM(L39:N39) -> 0 | S39: =SUM(P39:R39) -> 0 | W39: =SUM(T39:V39) -> 0 | AA39: =SUM(X39:Z39) -> 0 | AE39: =SUM(AB39:AD39) -> 0 | AI39: =SUM(AF39:AH39) -> 0 | AM39: =SUM(AJ39:AL39) -> 0 | AQ39: =SUM(AN39:AP39) -> 0 | AU39: =SUM(AR39:AT39) -> 0 | AY39: =SUM(AV39:AX39) -> 0 | BA39: =+G39+K39+O39+S39+W39+AA39+AE39+AZ39+AI39+AM39+AQ39+AU39+AY39 -> 0 | BC39: =+BA39-BB39 -> 0 | BF39: =+BD39+BE39-BC39 -> 0 | BH39: =BF39+BG39 -> 0
B40: 1111056 | C40: ชิฟฟอนรวมรสยอดฮิต 8 ชิ้น | G40: =SUM(D40:F40) -> 0 | H40: 4 | K40: =SUM(H40:J40) -> 4 | L40: 2 | O40: =SUM(L40:N40) -> 2 | S40: =SUM(P40:R40) -> 0 | W40: =SUM(T40:V40) -> 0 | AA40: =SUM(X40:Z40) -> 0 | AE40: =SUM(AB40:AD40) -> 0 | AI40: =SUM(AF40:AH40) -> 0 | AM40: =SUM(AJ40:AL40) -> 0 | AQ40: =SUM(AN40:AP40) -> 0 | AU40: =SUM(AR40:AT40) -> 0 | AY40: =SUM(AV40:AX40) -> 0 | AZ40: 10 | BA40: =+G40+K40+O40+S40+W40+AA40+AE40+AZ40+AI40+AM40+AQ40+AU40+AY40 -> 16 | BC40: =+BA40-BB40 -> 16 | BD40: 10 | BE40: 24 | BF40: =+BD40+BE40-BC40 -> 18 | BH40: =BF40+BG40 -> 18
B41: 1111074 | C41: ชิฟฟอนไส้แยมแยกชิ้น มะพร้าว | G41: =SUM(D41:F41) -> 0 | K41: =SUM(H41:J41) -> 0 | O41: =SUM(L41:N41) -> 0 | S41: =SUM(P41:R41) -> 0 | W41: =SUM(T41:V41) -> 0 | AA41: =SUM(X41:Z41) -> 0 | AE41: =SUM(AB41:AD41) -> 0 | AI41: =SUM(AF41:AH41) -> 0 | AM41: =SUM(AJ41:AL41) -> 0 | AQ41: =SUM(AN41:AP41) -> 0 | AU41: =SUM(AR41:AT41) -> 0 | AY41: =SUM(AV41:AX41) -> 0 | BA41: =+G41+K41+O41+S41+W41+AA41+AE41+AZ41+AI41+AM41+AQ41+AU41+AY41 -> 0 | BC41: =+BA41-BB41 -> 0 | BF41: =+BD41+BE41-BC41 -> 0 | BH41: =BF41+BG41 -> 0
B42: 1111075 | C42: ชิฟฟอนไส้แยมแยกชิ้น สตอเบอรี่ | G42: =SUM(D42:F42) -> 0 | K42: =SUM(H42:J42) -> 0 | O42: =SUM(L42:N42) -> 0 | S42: =SUM(P42:R42) -> 0 | W42: =SUM(T42:V42) -> 0 | AA42: =SUM(X42:Z42) -> 0 | AE42: =SUM(AB42:AD42) -> 0 | AI42: =SUM(AF42:AH42) -> 0 | AM42: =SUM(AJ42:AL42) -> 0 | AQ42: =SUM(AN42:AP42) -> 0 | AU42: =SUM(AR42:AT42) -> 0 | AY42: =SUM(AV42:AX42) -> 0 | BA42: =+G42+K42+O42+S42+W42+AA42+AE42+AZ42+AI42+AM42+AQ42+AU42+AY42 -> 0 | BC42: =+BA42-BB42 -> 0 | BF42: =+BD42+BE42-BC42 -> 0 | BH42: =BF42+BG42 -> 0
B43: 1111076 | C43: ชิฟฟอนไส้แยมแยกชิ้น ส้ม | G43: =SUM(D43:F43) -> 0 | K43: =SUM(H43:J43) -> 0 | O43: =SUM(L43:N43) -> 0 | S43: =SUM(P43:R43) -> 0 | W43: =SUM(T43:V43) -> 0 | AA43: =SUM(X43:Z43) -> 0 | AE43: =SUM(AB43:AD43) -> 0 | AI43: =SUM(AF43:AH43) -> 0 | AM43: =SUM(AJ43:AL43) -> 0 | AQ43: =SUM(AN43:AP43) -> 0 | AU43: =SUM(AR43:AT43) -> 0 | AY43: =SUM(AV43:AX43) -> 0 | BA43: =+G43+K43+O43+S43+W43+AA43+AE43+AZ43+AI43+AM43+AQ43+AU43+AY43 -> 0 | BC43: =+BA43-BB43 -> 0 | BF43: =+BD43+BE43-BC43 -> 0 | BH43: =BF43+BG43 -> 0
B44: 1111077 | C44: ชิฟฟอนไส้แยมแยกชิ้น บลูเบอรี่ | G44: =SUM(D44:F44) -> 0 | K44: =SUM(H44:J44) -> 0 | O44: =SUM(L44:N44) -> 0 | S44: =SUM(P44:R44) -> 0 | W44: =SUM(T44:V44) -> 0 | AA44: =SUM(X44:Z44) -> 0 | AE44: =SUM(AB44:AD44) -> 0 | AI44: =SUM(AF44:AH44) -> 0 | AM44: =SUM(AJ44:AL44) -> 0 | AQ44: =SUM(AN44:AP44) -> 0 | AU44: =SUM(AR44:AT44) -> 0 | AY44: =SUM(AV44:AX44) -> 0 | BA44: =+G44+K44+O44+S44+W44+AA44+AE44+AZ44+AI44+AM44+AQ44+AU44+AY44 -> 0 | BC44: =+BA44-BB44 -> 0 | BF44: =+BD44+BE44-BC44 -> 0 | BH44: =BF44+BG44 -> 0
B45: 1111078 | C45: ชิฟฟอนไส้แยมแยกชิ้น นมชมพู | G45: =SUM(D45:F45) -> 0 | K45: =SUM(H45:J45) -> 0 | O45: =SUM(L45:N45) -> 0 | S45: =SUM(P45:R45) -> 0 | W45: =SUM(T45:V45) -> 0 | AA45: =SUM(X45:Z45) -> 0 | AE45: =SUM(AB45:AD45) -> 0 | AI45: =SUM(AF45:AH45) -> 0 | AM45: =SUM(AJ45:AL45) -> 0 | AQ45: =SUM(AN45:AP45) -> 0 | AU45: =SUM(AR45:AT45) -> 0 | AY45: =SUM(AV45:AX45) -> 0 | BA45: =+G45+K45+O45+S45+W45+AA45+AE45+AZ45+AI45+AM45+AQ45+AU45+AY45 -> 0 | BC45: =+BA45-BB45 -> 0 | BF45: =+BD45+BE45-BC45 -> 0 | BH45: =BF45+BG45 -> 0
...

Sheet 02.7.68
B1: ยอดจริง ออนไลน์ วันที่ 2/7/2569
B2: รหัสสินค้า | C2: สินค้า | D2: ปณ | H2: ชอปปี้ | L2: ลาซาด้า | P2: ติ๊กตอก | T2: ติ๊กตอก2 | X2: ติ๊กตอก3 | AB2: ติ๊กตอก4 | AF2: ติ๊กตอก5 | AJ2: ติ๊กตอก6 | AN2: ติ๊กตอก7 | AR2: ติ๊กตอก8 | AV2: ติ๊กตอก9 | AZ2: ยอดเส้น | BA2: ยอดรวมผลิต(กล่อง) | BB2: ยอดยกเลิก | BC2: สรุปใช้จริง | BD2: ยอดForcast | BE2: ยอดStock | BF2: ยอดMemo | BG2: ยอดForcastวันพรุ่งนี้ | BH2: สินค้าที่ขายได้
D3: เช้า | E3: บ่าย | F3: เย็น | G3: รวม | H3: เช้า | I3: บ่าย | J3: เย็น | K3: รวม | L3: เช้า | M3: บ่าย | N3: เย็น | O3: รวม | P3: เช้า | Q3: บ่าย | R3: เย็น | S3: รวม | T3: เช้า | U3: บ่าย | V3: เย็น | W3: รวม | X3: เช้า | Y3: บ่าย | Z3: เย็น | AA3: รวม | AB3: เช้า | AC3: บ่าย | AD3: เย็น | AE3: รวม | AF3: เช้า | AG3: บ่าย | AH3: เย็น | AI3: รวม | AJ3: เช้า | AK3: บ่าย | AL3: เย็น | AM3: รวม | AN3: เช้า | AO3: บ่าย | AP3: เย็น | AQ3: รวม | AR3: เช้า | AS3: บ่าย | AT3: เย็น | AU3: รวม | AV3: เช้า | AW3: บ่าย | AX3: เย็น | AY3: รวม
B4: 1004055 | C4: ชิฟฟ่อนเค้ก วรรณวนัช (รวมรส 4 ชิ้น) | G4: =SUM(D4:F4) -> 0 | K4: =SUM(H4:J4) -> 0 | O4: =SUM(L4:N4) -> 0 | S4: =SUM(P4:R4) -> 0 | W4: =SUM(T4:V4) -> 0 | AA4: =SUM(X4:Z4) -> 0 | AE4: =SUM(AB4:AD4) -> 0 | AI4: =SUM(AF4:AH4) -> 0 | AM4: =SUM(AJ4:AL4) -> 0 | AQ4: =SUM(AN4:AP4) -> 0 | AU4: =SUM(AR4:AT4) -> 0 | AY4: =SUM(AV4:AX4) -> 0 | BA4: =+G4+K4+O4+S4+W4+AA4+AE4+AZ4+AI4+AM4+AQ4+AU4+AY4 -> 0 | BC4: =+BA4-BB4 -> 0 | BF4: =+BD4+BE4-BC4 -> 0 | BH4: =BF4+BG4 -> 0
B5: 1111002 | C5: ชิฟฟ่อนเค้ก วรรณวนัช (รวมรส 8 ชิ้น) | G5: =SUM(D5:F5) -> 0 | K5: =SUM(H5:J5) -> 0 | O5: =SUM(L5:N5) -> 0 | S5: =SUM(P5:R5) -> 0 | W5: =SUM(T5:V5) -> 0 | AA5: =SUM(X5:Z5) -> 0 | AE5: =SUM(AB5:AD5) -> 0 | AI5: =SUM(AF5:AH5) -> 0 | AM5: =SUM(AJ5:AL5) -> 0 | AQ5: =SUM(AN5:AP5) -> 0 | AU5: =SUM(AR5:AT5) -> 0 | AY5: =SUM(AV5:AX5) -> 0 | BA5: =+G5+K5+O5+S5+W5+AA5+AE5+AZ5+AI5+AM5+AQ5+AU5+AY5 -> 0 | BC5: =+BA5-BB5 -> 0 | BF5: =+BD5+BE5-BC5 -> 0 | BH5: =BF5+BG5 -> 0
B6: 1111001 | C6: ชิฟฟ่อนแยกชิ้นไม่มีไส้ คละรส | G6: =SUM(D6:F6) -> 0 | K6: =SUM(H6:J6) -> 0 | O6: =SUM(L6:N6) -> 0 | S6: =SUM(P6:R6) -> 0 | W6: =SUM(T6:V6) -> 0 | AA6: =SUM(X6:Z6) -> 0 | AE6: =SUM(AB6:AD6) -> 0 | AI6: =SUM(AF6:AH6) -> 0 | AM6: =SUM(AJ6:AL6) -> 0 | AQ6: =SUM(AN6:AP6) -> 0 | AU6: =SUM(AR6:AT6) -> 0 | AY6: =SUM(AV6:AX6) -> 0 | BA6: =+G6+K6+O6+S6+W6+AA6+AE6+AZ6+AI6+AM6+AQ6+AU6+AY6 -> 0 | BC6: =+BA6-BB6 -> 0 | BF6: =+BD6+BE6-BC6 -> 0 | BH6: =BF6+BG6 -> 0
B7: 1111043 | C7: ชิฟฟอนรสมะลิ 8 ชิ้น ห่อ ซีน | G7: =SUM(D7:F7) -> 0 | K7: =SUM(H7:J7) -> 0 | O7: =SUM(L7:N7) -> 0 | S7: =SUM(P7:R7) -> 0 | W7: =SUM(T7:V7) -> 0 | AA7: =SUM(X7:Z7) -> 0 | AE7: =SUM(AB7:AD7) -> 0 | AI7: =SUM(AF7:AH7) -> 0 | AM7: =SUM(AJ7:AL7) -> 0 | AQ7: =SUM(AN7:AP7) -> 0 | AU7: =SUM(AR7:AT7) -> 0 | AY7: =SUM(AV7:AX7) -> 0 | BA7: =+G7+K7+O7+S7+W7+AA7+AE7+AZ7+AI7+AM7+AQ7+AU7+AY7 -> 0 | BC7: =+BA7-BB7 -> 0 | BF7: =+BD7+BE7-BC7 -> 0 | BH7: =BF7+BG7 -> 0
B8: 1111057 | C8: ชิฟฟอนแยกชิ้น กาแฟ | G8: =SUM(D8:F8) -> 0 | K8: =SUM(H8:J8) -> 0 | O8: =SUM(L8:N8) -> 0 | S8: =SUM(P8:R8) -> 0 | W8: =SUM(T8:V8) -> 0 | AA8: =SUM(X8:Z8) -> 0 | AE8: =SUM(AB8:AD8) -> 0 | AI8: =SUM(AF8:AH8) -> 0 | AM8: =SUM(AJ8:AL8) -> 0 | AQ8: =SUM(AN8:AP8) -> 0 | AU8: =SUM(AR8:AT8) -> 0 | AY8: =SUM(AV8:AX8) -> 0 | BA8: =+G8+K8+O8+S8+W8+AA8+AE8+AZ8+AI8+AM8+AQ8+AU8+AY8 -> 0 | BC8: =+BA8-BB8 -> 0 | BF8: =+BD8+BE8-BC8 -> 0 | BH8: =BF8+BG8 -> 0
B9: 1111058 | C9: ชิฟฟอนแยกชิ้น ชาเขียว | G9: =SUM(D9:F9) -> 0 | K9: =SUM(H9:J9) -> 0 | O9: =SUM(L9:N9) -> 0 | S9: =SUM(P9:R9) -> 0 | W9: =SUM(T9:V9) -> 0 | AA9: =SUM(X9:Z9) -> 0 | AE9: =SUM(AB9:AD9) -> 0 | AI9: =SUM(AF9:AH9) -> 0 | AM9: =SUM(AJ9:AL9) -> 0 | AQ9: =SUM(AN9:AP9) -> 0 | AU9: =SUM(AR9:AT9) -> 0 | AY9: =SUM(AV9:AX9) -> 0 | BA9: =+G9+K9+O9+S9+W9+AA9+AE9+AZ9+AI9+AM9+AQ9+AU9+AY9 -> 0 | BC9: =+BA9-BB9 -> 0 | BF9: =+BD9+BE9-BC9 -> 0 | BH9: =BF9+BG9 -> 0
B10: 1111059 | C10: ชิฟฟอนแยกชิ้น ใบเตย | G10: =SUM(D10:F10) -> 0 | K10: =SUM(H10:J10) -> 0 | O10: =SUM(L10:N10) -> 0 | S10: =SUM(P10:R10) -> 0 | W10: =SUM(T10:V10) -> 0 | AA10: =SUM(X10:Z10) -> 0 | AE10: =SUM(AB10:AD10) -> 0 | AI10: =SUM(AF10:AH10) -> 0 | AM10: =SUM(AJ10:AL10) -> 0 | AQ10: =SUM(AN10:AP10) -> 0 | AU10: =SUM(AR10:AT10) -> 0 | AY10: =SUM(AV10:AX10) -> 0 | BA10: =+G10+K10+O10+S10+W10+AA10+AE10+AZ10+AI10+AM10+AQ10+AU10+AY10 -> 0 | BC10: =+BA10-BB10 -> 0 | BF10: =+BD10+BE10-BC10 -> 0 | BH10: =BF10+BG10 -> 0
B11: 1111060 | C11: ชิฟฟอนแยกชิ้น กล้วยหอม | G11: =SUM(D11:F11) -> 0 | K11: =SUM(H11:J11) -> 0 | O11: =SUM(L11:N11) -> 0 | S11: =SUM(P11:R11) -> 0 | W11: =SUM(T11:V11) -> 0 | AA11: =SUM(X11:Z11) -> 0 | AE11: =SUM(AB11:AD11) -> 0 | AI11: =SUM(AF11:AH11) -> 0 | AM11: =SUM(AJ11:AL11) -> 0 | AQ11: =SUM(AN11:AP11) -> 0 | AU11: =SUM(AR11:AT11) -> 0 | AY11: =SUM(AV11:AX11) -> 0 | BA11: =+G11+K11+O11+S11+W11+AA11+AE11+AZ11+AI11+AM11+AQ11+AU11+AY11 -> 0 | BC11: =+BA11-BB11 -> 0 | BF11: =+BD11+BE11-BC11 -> 0 | BH11: =BF11+BG11 -> 0
B12: 1111061 | C12: ชิฟฟอนแยกชิ้น ชาไทย | G12: =SUM(D12:F12) -> 0 | K12: =SUM(H12:J12) -> 0 | O12: =SUM(L12:N12) -> 0 | S12: =SUM(P12:R12) -> 0 | W12: =SUM(T12:V12) -> 0 | AA12: =SUM(X12:Z12) -> 0 | AE12: =SUM(AB12:AD12) -> 0 | AI12: =SUM(AF12:AH12) -> 0 | AM12: =SUM(AJ12:AL12) -> 0 | AQ12: =SUM(AN12:AP12) -> 0 | AU12: =SUM(AR12:AT12) -> 0 | AY12: =SUM(AV12:AX12) -> 0 | BA12: =+G12+K12+O12+S12+W12+AA12+AE12+AZ12+AI12+AM12+AQ12+AU12+AY12 -> 0 | BC12: =+BA12-BB12 -> 0 | BF12: =+BD12+BE12-BC12 -> 0 | BH12: =BF12+BG12 -> 0
B13: 1111062 | C13: ชิฟฟอนแยกชิ้น โกโก้ | G13: =SUM(D13:F13) -> 0 | K13: =SUM(H13:J13) -> 0 | O13: =SUM(L13:N13) -> 0 | S13: =SUM(P13:R13) -> 0 | W13: =SUM(T13:V13) -> 0 | AA13: =SUM(X13:Z13) -> 0 | AE13: =SUM(AB13:AD13) -> 0 | AI13: =SUM(AF13:AH13) -> 0 | AM13: =SUM(AJ13:AL13) -> 0 | AQ13: =SUM(AN13:AP13) -> 0 | AU13: =SUM(AR13:AT13) -> 0 | AY13: =SUM(AV13:AX13) -> 0 | BA13: =+G13+K13+O13+S13+W13+AA13+AE13+AZ13+AI13+AM13+AQ13+AU13+AY13 -> 0 | BC13: =+BA13-BB13 -> 0 | BF13: =+BD13+BE13-BC13 -> 0 | BH13: =BF13+BG13 -> 0
B14: 1111063 | C14: ชิฟฟอนแยกชิ้น ส้ม | G14: =SUM(D14:F14) -> 0 | K14: =SUM(H14:J14) -> 0 | O14: =SUM(L14:N14) -> 0 | S14: =SUM(P14:R14) -> 0 | W14: =SUM(T14:V14) -> 0 | AA14: =SUM(X14:Z14) -> 0 | AE14: =SUM(AB14:AD14) -> 0 | AI14: =SUM(AF14:AH14) -> 0 | AM14: =SUM(AJ14:AL14) -> 0 | AQ14: =SUM(AN14:AP14) -> 0 | AU14: =SUM(AR14:AT14) -> 0 | AY14: =SUM(AV14:AX14) -> 0 | BA14: =+G14+K14+O14+S14+W14+AA14+AE14+AZ14+AI14+AM14+AQ14+AU14+AY14 -> 0 | BC14: =+BA14-BB14 -> 0 | BF14: =+BD14+BE14-BC14 -> 0 | BH14: =BF14+BG14 -> 0
B15: 1111064 | C15: ชิฟฟอนแยกชิ้น เผือก | G15: =SUM(D15:F15) -> 0 | K15: =SUM(H15:J15) -> 0 | O15: =SUM(L15:N15) -> 0 | S15: =SUM(P15:R15) -> 0 | W15: =SUM(T15:V15) -> 0 | AA15: =SUM(X15:Z15) -> 0 | AE15: =SUM(AB15:AD15) -> 0 | AI15: =SUM(AF15:AH15) -> 0 | AM15: =SUM(AJ15:AL15) -> 0 | AQ15: =SUM(AN15:AP15) -> 0 | AU15: =SUM(AR15:AT15) -> 0 | AY15: =SUM(AV15:AX15) -> 0 | BA15: =+G15+K15+O15+S15+W15+AA15+AE15+AZ15+AI15+AM15+AQ15+AU15+AY15 -> 0 | BC15: =+BA15-BB15 -> 0 | BF15: =+BD15+BE15-BC15 -> 0 | BH15: =BF15+BG15 -> 0
... B85: 200 | C85: เศษขนมปังปลา 1 กก. | G85: =SUM(D85:F85) -> 0 | K85: =SUM(H85:J85) -> 0 | O85: =SUM(L85:N85) -> 0 | S85: =SUM(P85:R85) -> 0 | W85: =SUM(T85:V85) -> 0 | AA85: =SUM(X85:Z85) -> 0 | AE85: =SUM(AB85:AD85) -> 0 | AI85: =SUM(AF85:AH85) -> 0 | AM85: =SUM(AJ85:AL85) -> 0 | AQ85: =SUM(AN85:AP85) -> 0 | AU85: =SUM(AR85:AT85) -> 0 | AY85: =SUM(AV85:AX85) -> 0 | BA85: =+G85+K85+O85+S85+W85+AA85+AE85+AZ85+AI85+AM85+AQ85+AU85+AY85 -> 0 | BC85: =+BA85-BB85 -> 0 | BF85: =+BD85+BE85-BC85 -> 0 | BH85: =BF85+BG85 -> 0
C86: ชิฟฟอน 4 ชิ้น มะพร้าวล้วน | G86: =SUM(D86:F86) -> 0 | K86: =SUM(H86:J86) -> 0 | O86: =SUM(L86:N86) -> 0 | S86: =SUM(P86:R86) -> 0 | W86: =SUM(T86:V86) -> 0 | AA86: =SUM(X86:Z86) -> 0 | AE86: =SUM(AB86:AD86) -> 0 | AI86: =SUM(AF86:AH86) -> 0 | AM86: =SUM(AJ86:AL86) -> 0 | AQ86: =SUM(AN86:AP86) -> 0 | AU86: =SUM(AR86:AT86) -> 0 | AY86: =SUM(AV86:AX86) -> 0 | BA86: =+G86+K86+O86+S86+W86+AA86+AE86+AZ86+AI86+AM86+AQ86+AU86+AY86 -> 0 | BB86: =+H86+L86+P86+T86+X86+AB86+AF86+BA86+AJ86+AN86+AR86+AV86+AZ86 -> 0 | BC86: =+BA86-BB86 -> 0 | BF86: =+BD86+BE86-BC86 -> 0 | BH86: =BF86+BG86 -> 0
C87: ชิฟฟอน 4 ชิ้น กาแฟล้วน | G87: =SUM(D87:F87) -> 0 | K87: =SUM(H87:J87) -> 0 | O87: =SUM(L87:N87) -> 0 | S87: =SUM(P87:R87) -> 0 | W87: =SUM(T87:V87) -> 0 | AA87: =SUM(X87:Z87) -> 0 | AE87: =SUM(AB87:AD87) -> 0 | AI87: =SUM(AF87:AH87) -> 0 | AM87: =SUM(AJ87:AL87) -> 0 | AQ87: =SUM(AN87:AP87) -> 0 | AU87: =SUM(AR87:AT87) -> 0 | AY87: =SUM(AV87:AX87) -> 0 | BA87: =+G87+K87+O87+S87+W87+AA87+AE87+AZ87+AI87+AM87+AQ87+AU87+AY87 -> 0 | BB87: =+H87+L87+P87+T87+X87+AB87+AF87+BA87+AJ87+AN87+AR87+AV87+AZ87 -> 0 | BC87: =+BA87-BB87 -> 0 | BF87: =+BD87+BE87-BC87 -> 0 | BH87: =BF87+BG87 -> 0
C88: ชิฟฟอน 4 ชิ้น ชาเขียวล้วน | G88: =SUM(D88:F88) -> 0 | K88: =SUM(H88:J88) -> 0 | O88: =SUM(L88:N88) -> 0 | S88: =SUM(P88:R88) -> 0 | W88: =SUM(T88:V88) -> 0 | AA88: =SUM(X88:Z88) -> 0 | AE88: =SUM(AB88:AD88) -> 0 | AI88: =SUM(AF88:AH88) -> 0 | AM88: =SUM(AJ88:AL88) -> 0 | AQ88: =SUM(AN88:AP88) -> 0 | AU88: =SUM(AR88:AT88) -> 0 | AY88: =SUM(AV88:AX88) -> 0 | BA88: =+G88+K88+O88+S88+W88+AA88+AE88+AZ88+AI88+AM88+AQ88+AU88+AY88 -> 0 | BB88: =+H88+L88+P88+T88+X88+AB88+AF88+BA88+AJ88+AN88+AR88+AV88+AZ88 -> 0 | BC88: =+BA88-BB88 -> 0 | BF88: =+BD88+BE88-BC88 -> 0 | BH88: =BF88+BG88 -> 0
C89: ชิฟฟอน 4 ชิ้น ใบเตยล้วน | G89: =SUM(D89:F89) -> 0 | K89: =SUM(H89:J89) -> 0 | O89: =SUM(L89:N89) -> 0 | S89: =SUM(P89:R89) -> 0 | W89: =SUM(T89:V89) -> 0 | AA89: =SUM(X89:Z89) -> 0 | AE89: =SUM(AB89:AD89) -> 0 | AI89: =SUM(AF89:AH89) -> 0 | AM89: =SUM(AJ89:AL89) -> 0 | AQ89: =SUM(AN89:AP89) -> 0 | AU89: =SUM(AR89:AT89) -> 0 | AY89: =SUM(AV89:AX89) -> 0 | BA89: =+G89+K89+O89+S89+W89+AA89+AE89+AZ89+AI89+AM89+AQ89+AU89+AY89 -> 0 | BB89: =+H89+L89+P89+T89+X89+AB89+AF89+BA89+AJ89+AN89+AR89+AV89+AZ89 -> 0 | BC89: =+BA89-BB89 -> 0 | BF89: =+BD89+BE89-BC89 -> 0 | BH89: =BF89+BG89 -> 0
B90: 1111084 | C90: ชิฟฟอน 8 ชิ้น กาแฟล้วน | G90: =SUM(D90:F90) -> 0 | K90: =SUM(H90:J90) -> 0 | O90: =SUM(L90:N90) -> 0 | S90: =SUM(P90:R90) -> 0 | W90: =SUM(T90:V90) -> 0 | AA90: =SUM(X90:Z90) -> 0 | AE90: =SUM(AB90:AD90) -> 0 | AI90: =SUM(AF90:AH90) -> 0 | AM90: =SUM(AJ90:AL90) -> 0 | AQ90: =SUM(AN90:AP90) -> 0 | AU90: =SUM(AR90:AT90) -> 0 | AY90: =SUM(AV90:AX90) -> 0 | BA90: =+G90+K90+O90+S90+W90+AA90+AE90+AZ90+AI90+AM90+AQ90+AU90+AY90 -> 0 | BB90: =+H90+L90+P90+T90+X90+AB90+AF90+BA90+AJ90+AN90+AR90+AV90+AZ90 -> 0 | BC90: =+BA90-BB90 -> 0 | BF90: =+BD90+BE90-BC90 -> 0 | BH90: =BF90+BG90 -> 0
B91: 1111085 | C91: ชิฟฟอน 8 ชิ้น บลูเบอรี่ล้วน | G91: =SUM(D91:F91) -> 0 | K91: =SUM(H91:J91) -> 0 | O91: =SUM(L91:N91) -> 0 | S91: =SUM(P91:R91) -> 0 | W91: =SUM(T91:V91) -> 0 | AA91: =SUM(X91:Z91) -> 0 | AE91: =SUM(AB91:AD91) -> 0 | AI91: =SUM(AF91:AH91) -> 0 | AM91: =SUM(AJ91:AL91) -> 0 | AQ91: =SUM(AN91:AP91) -> 0 | AU91: =SUM(AR91:AT91) -> 0 | AY91: =SUM(AV91:AX91) -> 0 | BA91: =+G91+K91+O91+S91+W91+AA91+AE91+AZ91+AI91+AM91+AQ91+AU91+AY91 -> 0 | BB91: =+H91+L91+P91+T91+X91+AB91+AF91+BA91+AJ91+AN91+AR91+AV91+AZ91 -> 0 | BC91: =+BA91-BB91 -> 0 | BF91: =+BD91+BE91-BC91 -> 0 | BH91: =BF91+BG91 -> 0
B92: 1111086 | C92: ชิฟฟอน 8 ชิ้น มะพร้าวล้วน | G92: =SUM(D92:F92) -> 0 | K92: =SUM(H92:J92) -> 0 | O92: =SUM(L92:N92) -> 0 | S92: =SUM(P92:R92) -> 0 | W92: =SUM(T92:V92) -> 0 | AA92: =SUM(X92:Z92) -> 0 | AE92: =SUM(AB92:AD92) -> 0 | AI92: =SUM(AF92:AH92) -> 0 | AM92: =SUM(AJ92:AL92) -> 0 | AQ92: =SUM(AN92:AP92) -> 0 | AU92: =SUM(AR92:AT92) -> 0 | AY92: =SUM(AV92:AX92) -> 0 | BA92: =+G92+K92+O92+S92+W92+AA92+AE92+AZ92+AI92+AM92+AQ92+AU92+AY92 -> 0 | BB92: =+H92+L92+P92+T92+X92+AB92+AF92+BA92+AJ92+AN92+AR92+AV92+AZ92 -> 0 | BC92: =+BA92-BB92 -> 0 | BF92: =+BD92+BE92-BC92 -> 0 | BH92: =BF92+BG92 -> 0
B93: 1111087 | C93: ชิฟฟอน 8 ชิ้น สตอเบอรี่ล้วน | G93: =SUM(D93:F93) -> 0 | K93: =SUM(H93:J93) -> 0 | O93: =SUM(L93:N93) -> 0 | S93: =SUM(P93:R93) -> 0 | W93: =SUM(T93:V93) -> 0 | AA93: =SUM(X93:Z93) -> 0 | AE93: =SUM(AB93:AD93) -> 0 | AI93: =SUM(AF93:AH93) -> 0 | AM93: =SUM(AJ93:AL93) -> 0 | AQ93: =SUM(AN93:AP93) -> 0 | AU93: =SUM(AR93:AT93) -> 0 | AY93: =SUM(AV93:AX93) -> 0 | BA93: =+G93+K93+O93+S93+W93+AA93+AE93+AZ93+AI93+AM93+AQ93+AU93+AY93 -> 0 | BB93: =+H93+L93+P93+T93+X93+AB93+AF93+BA93+AJ93+AN93+AR93+AV93+AZ93 -> 0 | BC93: =+BA93-BB93 -> 0 | BF93: =+BD93+BE93-BC93 -> 0 | BH93: =BF93+BG93 -> 0
B94: 1111088 | C94: ชิฟฟอน 8 ชิ้น ส้มล้วน | G94: =SUM(D94:F94) -> 0 | K94: =SUM(H94:J94) -> 0 | O94: =SUM(L94:N94) -> 0 | S94: =SUM(P94:R94) -> 0 | W94: =SUM(T94:V94) -> 0 | AA94: =SUM(X94:Z94) -> 0 | AE94: =SUM(AB94:AD94) -> 0 | AI94: =SUM(AF94:AH94) -> 0 | AM94: =SUM(AJ94:AL94) -> 0 | AQ94: =SUM(AN94:AP94) -> 0 | AU94: =SUM(AR94:AT94) -> 0 | AY94: =SUM(AV94:AX94) -> 0 | BA94: =+G94+K94+O94+S94+W94+AA94+AE94+AZ94+AI94+AM94+AQ94+AU94+AY94 -> 0 | BB94: =+H94+L94+P94+T94+X94+AB94+AF94+BA94+AJ94+AN94+AR94+AV94+AZ94 -> 0 | BC94: =+BA94-BB94 -> 0 | BF94: =+BD94+BE94-BC94 -> 0 | BH94: =BF94+BG94 -> 0
B95: 1111089 | C95: ชิฟฟอน 8 ชิ้น เนยล้วน | G95: =SUM(D95:F95) -> 0 | K95: =SUM(H95:J95) -> 0 | O95: =SUM(L95:N95) -> 0 | S95: =SUM(P95:R95) -> 0 | W95: =SUM(T95:V95) -> 0 | AA95: =SUM(X95:Z95) -> 0 | AE95: =SUM(AB95:AD95) -> 0 | AI95: =SUM(AF95:AH95) -> 0 | AM95: =SUM(AJ95:AL95) -> 0 | AQ95: =SUM(AN95:AP95) -> 0 | AU95: =SUM(AR95:AT95) -> 0 | AY95: =SUM(AV95:AX95) -> 0 | BA95: =+G95+K95+O95+S95+W95+AA95+AE95+AZ95+AI95+AM95+AQ95+AU95+AY95 -> 0 | BB95: =+H95+L95+P95+T95+X95+AB95+AF95+BA95+AJ95+AN95+AR95+AV95+AZ95 -> 0 | BC95: =+BA95-BB95 -> 0 | BF95: =+BD95+BE95-BC95 -> 0 | BH95: =BF95+BG95 -> 0
B96: 1111090 | C96: ชิฟฟอน 8 ชิ้น เผือกล้วน | G96: =SUM(D96:F96) -> 0 | K96: =SUM(H96:J96) -> 0 | O96: =SUM(L96:N96) -> 0 | S96: =SUM(P96:R96) -> 0 | W96: =SUM(T96:V96) -> 0 | AA96: =SUM(X96:Z96) -> 0 | AE96: =SUM(AB96:AD96) -> 0 | AI96: =SUM(AF96:AH96) -> 0 | AM96: =SUM(AJ96:AL96) -> 0 | AQ96: =SUM(AN96:AP96) -> 0 | AU96: =SUM(AR96:AT96) -> 0 | AY96: =SUM(AV96:AX96) -> 0 | BA96: =+G96+K96+O96+S96+W96+AA96+AE96+AZ96+AI96+AM96+AQ96+AU96+AY96 -> 0 | BB96: =+H96+L96+P96+T96+X96+AB96+AF96+BA96+AJ96+AN96+AR96+AV96+AZ96 -> 0 | BC96: =+BA96-BB96 -> 0 | BF96: =+BD96+BE96-BC96 -> 0 | BH96: =BF96+BG96 -> 0
B97: 1111091 | C97: ชิฟฟอน 8 ชิ้น ใบเตยล้วน | G97: =SUM(D97:F97) -> 0 | K97: =SUM(H97:J97) -> 0 | O97: =SUM(L97:N97) -> 0 | S97: =SUM(P97:R97) -> 0 | W97: =SUM(T97:V97) -> 0 | AA97: =SUM(X97:Z97) -> 0 | AE97: =SUM(AB97:AD97) -> 0 | AI97: =SUM(AF97:AH97) -> 0 | AM97: =SUM(AJ97:AL97) -> 0 | AQ97: =SUM(AN97:AP97) -> 0 | AU97: =SUM(AR97:AT97) -> 0 | AY97: =SUM(AV97:AX97) -> 0 | BA97: =+G97+K97+O97+S97+W97+AA97+AE97+AZ97+AI97+AM97+AQ97+AU97+AY97 -> 0 | BB97: =+H97+L97+P97+T97+X97+AB97+AF97+BA97+AJ97+AN97+AR97+AV97+AZ97 -> 0 | BC97: =+BA97-BB97 -> 0 | BF97: =+BD97+BE97-BC97 -> 0 | BH97: =BF97+BG97 -> 0
B98: 1111092 | C98: ชิฟฟอน 8 ชิ้น กล้วยหอม | G98: =SUM(D98:F98) -> 0 | K98: =SUM(H98:J98) -> 0 | O98: =SUM(L98:N98) -> 0 | S98: =SUM(P98:R98) -> 0 | W98: =SUM(T98:V98) -> 0 | AA98: =SUM(X98:Z98) -> 0 | AE98: =SUM(AB98:AD98) -> 0 | AI98: =SUM(AF98:AH98) -> 0 | AM98: =SUM(AJ98:AL98) -> 0 | AQ98: =SUM(AN98:AP98) -> 0 | AU98: =SUM(AR98:AT98) -> 0 | AY98: =SUM(AV98:AX98) -> 0 | BA98: =+G98+K98+O98+S98+W98+AA98+AE98+AZ98+AI98+AM98+AQ98+AU98+AY98 -> 0 | BB98: =+H98+L98+P98+T98+X98+AB98+AF98+BA98+AJ98+AN98+AR98+AV98+AZ98 -> 0 | BC98: =+BA98-BB98 -> 0 | BF98: =+BD98+BE98-BC98 -> 0 | BH98: =BF98+BG98 -> 0
B99: 1111093 | C99: ชิฟฟอน 8 ชิ้น โกโก้ล้วน | G99: =SUM(D99:F99) -> 0 | K99: =SUM(H99:J99) -> 0 | O99: =SUM(L99:N99) -> 0 | S99: =SUM(P99:R99) -> 0 | W99: =SUM(T99:V99) -> 0 | AA99: =SUM(X99:Z99) -> 0 | AE99: =SUM(AB99:AD99) -> 0 | AI99: =SUM(AF99:AH99) -> 0 | AM99: =SUM(AJ99:AL99) -> 0 | AQ99: =SUM(AN99:AP99) -> 0 | AU99: =SUM(AR99:AT99) -> 0 | AY99: =SUM(AV99:AX99) -> 0 | BA99: =+G99+K99+O99+S99+W99+AA99+AE99+AZ99+AI99+AM99+AQ99+AU99+AY99 -> 0 | BB99: =+H99+L99+P99+T99+X99+AB99+AF99+BA99+AJ99+AN99+AR99+AV99+AZ99 -> 0 | BC99: =+BA99-BB99 -> 0 | BF99: =+BD99+BE99-BC99 -> 0 | BH99: =BF99+BG99 -> 0
B100: 1111094 | C100: ชิฟฟอน 8 ชิ้น ชาไทยล้วน | G100: =SUM(D100:F100) -> 0 | K100: =SUM(H100:J100) -> 0 | O100: =SUM(L100:N100) -> 0 | S100: =SUM(P100:R100) -> 0 | W100: =SUM(T100:V100) -> 0 | AA100: =SUM(X100:Z100) -> 0 | AE100: =SUM(AB100:AD100) -> 0 | AI100: =SUM(AF100:AH100) -> 0 | AM100: =SUM(AJ100:AL100) -> 0 | AQ100: =SUM(AN100:AP100) -> 0 | AU100: =SUM(AR100:AT100) -> 0 | AY100: =SUM(AV100:AX100) -> 0 | BA100: =+G100+K100+O100+S100+W100+AA100+AE100+AZ100+AI100+AM100+AQ100+AU100+AY100 -> 0 | BB100: =+H100+L100+P100+T100+X100+AB100+AF100+BA100+AJ100+AN100+AR100+AV100+AZ100 -> 0 | BC100: =+BA100-BB100 -> 0 | BF100: =+BD100+BE100-BC100 -> 0 | BH100: =BF100+BG100 -> 0
B101: 1111095 | C101: ชิฟฟอน 8 ชิ้น ชาเขียวล้วน | G101: =SUM(D101:F101) -> 0 | K101: =SUM(H101:J101) -> 0 | O101: =SUM(L101:N101) -> 0 | S101: =SUM(P101:R101) -> 0 | W101: =SUM(T101:V101) -> 0 | AA101: =SUM(X101:Z101) -> 0 | AE101: =SUM(AB101:AD101) -> 0 | AI101: =SUM(AF101:AH101) -> 0 | AM101: =SUM(AJ101:AL101) -> 0 | AQ101: =SUM(AN101:AP101) -> 0 | AU101: =SUM(AR101:AT101) -> 0 | AY101: =SUM(AV101:AX101) -> 0 | BA101: =+G101+K101+O101+S101+W101+AA101+AE101+AZ101+AI101+AM101+AQ101+AU101+AY101 -> 0 | BB101: =+H101+L101+P101+T101+X101+AB101+AF101+BA101+AJ101+AN101+AR101+AV101+AZ101 -> 0 | BC101: =+BA101-BB101 -> 0 | BF101: =+BD101+BE101-BC101 -> 0 | BH101: =BF101+BG101 -> 0
... B117: 1005984 | C117: แซนด์วิชปูอัดสาหร่าย ไร้ขอบ | G117: =SUM(D117:F117) -> 0 | K117: =SUM(H117:J117) -> 0 | O117: =SUM(L117:N117) -> 0 | S117: =SUM(P117:R117) -> 0 | W117: =SUM(T117:V117) -> 0 | AA117: =SUM(X117:Z117) -> 0 | AE117: =SUM(AB117:AD117) -> 0 | AI117: =SUM(AF117:AH117) -> 0 | AM117: =SUM(AJ117:AL117) -> 0 | AQ117: =SUM(AN117:AP117) -> 0 | AU117: =SUM(AR117:AT117) -> 0 | AY117: =SUM(AV117:AX117) -> 0 | BA117: =+G117+K117+O117+S117+W117+AA117+AE117+AZ117+AI117+AM117+AQ117+AU117+AY117 -> 0 | BB117: =+H117+L117+P117+T117+X117+AB117+AF117+BA117+AJ117+AN117+AR117+AV117+AZ117 -> 0 | BC117: =+BA117-BB117 -> 0 | BF117: =+BD117+BE117-BC117 -> 0 | BH117: =BF117+BG117 -> 0
B118: 1005995 | C118: แซนด์วิชปูอัด ไร้ขอบ | G118: =SUM(D118:F118) -> 0 | K118: =SUM(H118:J118) -> 0 | O118: =SUM(L118:N118) -> 0 | S118: =SUM(P118:R118) -> 0 | W118: =SUM(T118:V118) -> 0 | BA118: =+G118+K118+O118+S118+W118+AA118+AE118+AZ118+AI118+AM118+AQ118+AU118+AY118 -> 0 | BB118: =+H118+L118+P118+T118+X118+AB118+AF118+BA118+AJ118+AN118+AR118+AV118+AZ118 -> 0 | BC118: =+BA118-BB118 -> 0 | BF118: =+BD118+BE118-BC118 -> 0 | BH118: =BF118+BG118 -> 0
B119: 1005996 | C119: แซนด์วิช หมูหยองชีส ไร้ขอบ | G119: =SUM(D119:F119) -> 0 | K119: =SUM(H119:J119) -> 0 | O119: =SUM(L119:N119) -> 0 | S119: =SUM(P119:R119) -> 0 | W119: =SUM(T119:V119) -> 0 | BA119: =+G119+K119+O119+S119+W119+AA119+AE119+AZ119+AI119+AM119+AQ119+AU119+AY119 -> 0 | BB119: =+H119+L119+P119+T119+X119+AB119+AF119+BA119+AJ119+AN119+AR119+AV119+AZ119 -> 0 | BC119: =+BA119-BB119 -> 0 | BF119: =+BD119+BE119-BC119 -> 0 | BH119: =BF119+BG119 -> 0
B120: 1005999 | C120: แซนด์วิชแฮมชีส_WWN ไร้ขอบ | G120: =SUM(D120:F120) -> 0 | K120: =SUM(H120:J120) -> 0 | O120: =SUM(L120:N120) -> 0 | S120: =SUM(P120:R120) -> 0 | W120: =SUM(T120:V120) -> 0 | BA120: =+G120+K120+O120+S120+W120+AA120+AE120+AZ120+AI120+AM120+AQ120+AU120+AY120 -> 0 | BB120: =+H120+L120+P120+T120+X120+AB120+AF120+BA120+AJ120+AN120+AR120+AV120+AZ120 -> 0 | BC120: =+BA120-BB120 -> 0 | BF120: =+BD120+BE120-BC120 -> 0 | BH120: =BF120+BG120 -> 0
B121: 1005998 | C121: แซนด์วิช โฮลวีทแฮมชีส ไร้ขอบ | G121: =SUM(D121:F121) -> 0 | K121: =SUM(H121:J121) -> 0 | O121: =SUM(L121:N121) -> 0 | S121: =SUM(P121:R121) -> 0 | W121: =SUM(T121:V121) -> 0 | BA121: =+G121+K121+O121+S121+W121+AA121+AE121+AZ121+AI121+AM121+AQ121+AU121+AY121 -> 0 | BB121: =+H121+L121+P121+T121+X121+AB121+AF121+BA121+AJ121+AN121+AR121+AV121+AZ121 -> 0 | BC121: =+BA121-BB121 -> 0 | BF121: =+BD121+BE121-BC121 -> 0 | BH121: =BF121+BG121 -> 0
B122: 1006000 | C122: แซนด์วิช โฮลวีททูน่า ไร้ขอบ | G122: =SUM(D122:F122) -> 0 | K122: =SUM(H122:J122) -> 0 | O122: =SUM(L122:N122) -> 0 | S122: =SUM(P122:R122) -> 0 | W122: =SUM(T122:V122) -> 0 | BA122: =+G122+K122+O122+S122+W122+AA122+AE122+AZ122+AI122+AM122+AQ122+AU122+AY122 -> 0 | BB122: =+H122+L122+P122+T122+X122+AB122+AF122+BA122+AJ122+AN122+AR122+AV122+AZ122 -> 0 | BC122: =+BA122-BB122 -> 0 | BF122: =+BD122+BE122-BC122 -> 0 | BH122: =BF122+BG122 -> 0
B123: 20049129 | C123: Wan WN_ แซนวิชทูน่าแฮม 115g | G123: =SUM(D123:F123) -> 0 | K123: =SUM(H123:J123) -> 0 | O123: =SUM(L123:N123) -> 0 | S123: =SUM(P123:R123) -> 0 | W123: =SUM(T123:V123) -> 0 | BA123: =+G123+K123+O123+S123+W123+AA123+AE123+AZ123+AI123+AM123+AQ123+AU123+AY123 -> 0 | BB123: =+H123+L123+P123+T123+X123+AB123+AF123+BA123+AJ123+AN123+AR123+AV123+AZ123 -> 0 | BC123: =+BA123-BB123 -> 0 | BF123: =+BD123+BE123-BC123 -> 0 | BH123: =BF123+BG123 -> 0
B124: 20049130 | C124: WanWN_ แซนวิชแฮมชีส 95g | G124: =SUM(D124:F124) -> 0 | K124: =SUM(H124:J124) -> 0 | O124: =SUM(L124:N124) -> 0 | S124: =SUM(P124:R124) -> 0 | W124: =SUM(T124:V124) -> 0 | BA124: =+G124+K124+O124+S124+W124+AA124+AE124+AZ124+AI124+AM124+AQ124+AU124+AY124 -> 0 | BB124: =+H124+L124+P124+T124+X124+AB124+AF124+BA124+AJ124+AN124+AR124+AV124+AZ124 -> 0 | BC124: =+BA124-BB124 -> 0 | BF124: =+BD124+BE124-BC124 -> 0 | BH124: =BF124+BG124 -> 0
...

Sheet 03.7.68
B1: ยอดจริง ออนไลน์ วันที่ 3/7/2569
B2: รหัสสินค้า | C2: สินค้า | D2: ปณ | H2: ชอปปี้ | L2: ลาซาด้า | P2: ติ๊กตอก | T2: ติ๊กตอก2 | X2: ติ๊กตอก3 | AB2: ติ๊กตอก4 | AF2: ติ๊กตอก5 | AJ2: ติ๊กตอก6 | AN2: ติ๊กตอก7 | AR2: ติ๊กตอก8 | AV2: ติ๊กตอก9 | AZ2: ยอดเส้น | BA2: ยอดรวมผลิต(กล่อง) | BB2: ยอดยกเลิก | BC2: สรุปใช้จริง | BD2: ยอดForcast | BE2: ยอดStock | BF2: ยอดMemo | BG2: ยอดForcastวันพรุ่งนี้ | BH2: สินค้าที่ขายได้
D3: เช้า | E3: บ่าย | F3: เย็น | G3: รวม | H3: เช้า | I3: บ่าย | J3: เย็น | K3: รวม | L3: เช้า | M3: บ่าย | N3: เย็น | O3: รวม | P3: เช้า | Q3: บ่าย | R3: เย็น | S3: รวม | T3: เช้า | U3: บ่าย | V3: เย็น | W3: รวม | X3: เช้า | Y3: บ่าย | Z3: เย็น | AA3: รวม | AB3: เช้า | AC3: บ่าย | AD3: เย็น | AE3: รวม | AF3: เช้า | AG3: บ่าย | AH3: เย็น | AI3: รวม | AJ3: เช้า | AK3: บ่าย | AL3: เย็น | AM3: รวม | AN3: เช้า | AO3: บ่าย | AP3: เย็น | AQ3: รวม | AR3: เช้า | AS3: บ่าย | AT3: เย็น | AU3: รวม | AV3: เช้า | AW3: บ่าย | AX3: เย็น | AY3: รวม
B4: 1004055 | C4: ชิฟฟ่อนเค้ก วรรณวนัช (รวมรส 4 ชิ้น) | G4: =SUM(D4:F4) -> 0 | K4: =SUM(H4:J4) -> 0 | O4: =SUM(L4:N4) -> 0 | S4: =SUM(P4:R4) -> 0 | W4: =SUM(T4:V4) -> 0 | AA4: =SUM(X4:Z4) -> 0 | AE4: =SUM(AB4:AD4) -> 0 | AI4: =SUM(AF4:AH4) -> 0 | AM4: =SUM(AJ4:AL4) -> 0 | AQ4: =SUM(AN4:AP4) -> 0 | AU4: =SUM(AR4:AT4) -> 0 | AY4: =SUM(AV4:AX4) -> 0 | BA4: =+G4+K4+O4+S4+W4+AA4+AE4+AZ4+AI4+AM4+AQ4+AU4+AY4 -> 0 | BC4: =+BA4-BB4 -> 0 | BF4: =+BD4+BE4-BC4 -> 0 | BH4: =BF4+BG4 -> 0
B5: 1111002 | C5: ชิฟฟ่อนเค้ก วรรณวนัช (รวมรส 8 ชิ้น) | G5: =SUM(D5:F5) -> 0 | K5: =SUM(H5:J5) -> 0 | O5: =SUM(L5:N5) -> 0 | S5: =SUM(P5:R5) -> 0 | W5: =SUM(T5:V5) -> 0 | AA5: =SUM(X5:Z5) -> 0 | AE5: =SUM(AB5:AD5) -> 0 | AI5: =SUM(AF5:AH5) -> 0 | AM5: =SUM(AJ5:AL5) -> 0 | AQ5: =SUM(AN5:AP5) -> 0 | AU5: =SUM(AR5:AT5) -> 0 | AY5: =SUM(AV5:AX5) -> 0 | BA5: =+G5+K5+O5+S5+W5+AA5+AE5+AZ5+AI5+AM5+AQ5+AU5+AY5 -> 0 | BC5: =+BA5-BB5 -> 0 | BF5: =+BD5+BE5-BC5 -> 0 | BH5: =BF5+BG5 -> 0
B6: 1111001 | C6: ชิฟฟ่อนแยกชิ้นไม่มีไส้ คละรส | G6: =SUM(D6:F6) -> 0 | K6: =SUM(H6:J6) -> 0 | O6: =SUM(L6:N6) -> 0 | S6: =SUM(P6:R6) -> 0 | W6: =SUM(T6:V6) -> 0 | AA6: =SUM(X6:Z6) -> 0 | AE6: =SUM(AB6:AD6) -> 0 | AI6: =SUM(AF6:AH6) -> 0 | AM6: =SUM(AJ6:AL6) -> 0 | AQ6: =SUM(AN6:AP6) -> 0 | AU6: =SUM(AR6:AT6) -> 0 | AY6: =SUM(AV6:AX6) -> 0 | BA6: =+G6+K6+O6+S6+W6+AA6+AE6+AZ6+AI6+AM6+AQ6+AU6+AY6 -> 0 | BC6: =+BA6-BB6 -> 0 | BF6: =+BD6+BE6-BC6 -> 0 | BH6: =BF6+BG6 -> 0
B7: 1111043 | C7: ชิฟฟอนรสมะลิ 8 ชิ้น ห่อ ซีน | G7: =SUM(D7:F7) -> 0 | K7: =SUM(H7:J7) -> 0 | O7: =SUM(L7:N7) -> 0 | S7: =SUM(P7:R7) -> 0 | W7: =SUM(T7:V7) -> 0 | AA7: =SUM(X7:Z7) -> 0 | AE7: =SUM(AB7:AD7) -> 0 | AI7: =SUM(AF7:AH7) -> 0 | AM7: =SUM(AJ7:AL7) -> 0 | AQ7: =SUM(AN7:AP7) -> 0 | AU7: =SUM(AR7:AT7) -> 0 | AY7: =SUM(AV7:AX7) -> 0 | BA7: =+G7+K7+O7+S7+W7+AA7+AE7+AZ7+AI7+AM7+AQ7+AU7+AY7 -> 0 | BC7: =+BA7-BB7 -> 0 | BF7: =+BD7+BE7-BC7 -> 0 | BH7: =BF7+BG7 -> 0
B8: 1111057 | C8: ชิฟฟอนแยกชิ้น กาแฟ | G8: =SUM(D8:F8) -> 0 | K8: =SUM(H8:J8) -> 0 | O8: =SUM(L8:N8) -> 0 | S8: =SUM(P8:R8) -> 0 | W8: =SUM(T8:V8) -> 0 | AA8: =SUM(X8:Z8) -> 0 | AE8: =SUM(AB8:AD8) -> 0 | AI8: =SUM(AF8:AH8) -> 0 | AM8: =SUM(AJ8:AL8) -> 0 | AQ8: =SUM(AN8:AP8) -> 0 | AU8: =SUM(AR8:AT8) -> 0 | AY8: =SUM(AV8:AX8) -> 0 | BA8: =+G8+K8+O8+S8+W8+AA8+AE8+AZ8+AI8+AM8+AQ8+AU8+AY8 -> 0 | BC8: =+BA8-BB8 -> 0 | BF8: =+BD8+BE8-BC8 -> 0 | BH8: =BF8+BG8 -> 0
B9: 1111058 | C9: ชิฟฟอนแยกชิ้น ชาเขียว | G9: =SUM(D9:F9) -> 0 | K9: =SUM(H9:J9) -> 0 | O9: =SUM(L9:N9) -> 0 | S9: =SUM(P9:R9) -> 0 | W9: =SUM(T9:V9) -> 0 | AA9: =SUM(X9:Z9) -> 0 | AE9: =SUM(AB9:AD9) -> 0 | AI9: =SUM(AF9:AH9) -> 0 | AM9: =SUM(AJ9:AL9) -> 0 | AQ9: =SUM(AN9:AP9) -> 0 | AU9: =SUM(AR9:AT9) -> 0 | AY9: =SUM(AV9:AX9) -> 0 | BA9: =+G9+K9+O9+S9+W9+AA9+AE9+AZ9+AI9+AM9+AQ9+AU9+AY9 -> 0 | BC9: =+BA9-BB9 -> 0 | BF9: =+BD9+BE9-BC9 -> 0 | BH9: =BF9+BG9 -> 0
B10: 1111059 | C10: ชิฟฟอนแยกชิ้น ใบเตย | G10: =SUM(D10:F10) -> 0 | K10: =SUM(H10:J10) -> 0 | O10: =SUM(L10:N10) -> 0 | S10: =SUM(P10:R10) -> 0 | W10: =SUM(T10:V10) -> 0 | AA10: =SUM(X10:Z10) -> 0 | AE10: =SUM(AB10:AD10) -> 0 | AI10: =SUM(AF10:AH10) -> 0 | AM10: =SUM(AJ10:AL10) -> 0 | AQ10: =SUM(AN10:AP10) -> 0 | AU10: =SUM(AR10:AT10) -> 0 | AY10: =SUM(AV10:AX10) -> 0 | BA10: =+G10+K10+O10+S10+W10+AA10+AE10+AZ10+AI10+AM10+AQ10+AU10+AY10 -> 0 | BC10: =+BA10-BB10 -> 0 | BF10: =+BD10+BE10-BC10 -> 0 | BH10: =BF10+BG10 -> 0
B11: 1111060 | C11: ชิฟฟอนแยกชิ้น กล้วยหอม | G11: =SUM(D11:F11) -> 0 | K11: =SUM(H11:J11) -> 0 | O11: =SUM(L11:N11) -> 0 | S11: =SUM(P11:R11) -> 0 | W11: =SUM(T11:V11) -> 0 | AA11: =SUM(X11:Z11) -> 0 | AE11: =SUM(AB11:AD11) -> 0 | AI11: =SUM(AF11:AH11) -> 0 | AM11: =SUM(AJ11:AL11) -> 0 | AQ11: =SUM(AN11:AP11) -> 0 | AU11: =SUM(AR11:AT11) -> 0 | AY11: =SUM(AV11:AX11) -> 0 | BA11: =+G11+K11+O11+S11+W11+AA11+AE11+AZ11+AI11+AM11+AQ11+AU11+AY11 -> 0 | BC11: =+BA11-BB11 -> 0 | BF11: =+BD11+BE11-BC11 -> 0 | BH11: =BF11+BG11 -> 0
B12: 1111061 | C12: ชิฟฟอนแยกชิ้น ชาไทย | G12: =SUM(D12:F12) -> 0 | K12: =SUM(H12:J12) -> 0 | O12: =SUM(L12:N12) -> 0 | S12: =SUM(P12:R12) -> 0 | W12: =SUM(T12:V12) -> 0 | AA12: =SUM(X12:Z12) -> 0 | AE12: =SUM(AB12:AD12) -> 0 | AI12: =SUM(AF12:AH12) -> 0 | AM12: =SUM(AJ12:AL12) -> 0 | AQ12: =SUM(AN12:AP12) -> 0 | AU12: =SUM(AR12:AT12) -> 0 | AY12: =SUM(AV12:AX12) -> 0 | BA12: =+G12+K12+O12+S12+W12+AA12+AE12+AZ12+AI12+AM12+AQ12+AU12+AY12 -> 0 | BC12: =+BA12-BB12 -> 0 | BF12: =+BD12+BE12-BC12 -> 0 | BH12: =BF12+BG12 -> 0
B13: 1111062 | C13: ชิฟฟอนแยกชิ้น โกโก้ | G13: =SUM(D13:F13) -> 0 | K13: =SUM(H13:J13) -> 0 | O13: =SUM(L13:N13) -> 0 | S13: =SUM(P13:R13) -> 0 | W13: =SUM(T13:V13) -> 0 | AA13: =SUM(X13:Z13) -> 0 | AE13: =SUM(AB13:AD13) -> 0 | AI13: =SUM(AF13:AH13) -> 0 | AM13: =SUM(AJ13:AL13) -> 0 | AQ13: =SUM(AN13:AP13) -> 0 | AU13: =SUM(AR13:AT13) -> 0 | AY13: =SUM(AV13:AX13) -> 0 | BA13: =+G13+K13+O13+S13+W13+AA13+AE13+AZ13+AI13+AM13+AQ13+AU13+AY13 -> 0 | BC13: =+BA13-BB13 -> 0 | BF13: =+BD13+BE13-BC13 -> 0 | BH13: =BF13+BG13 -> 0
B14: 1111063 | C14: ชิฟฟอนแยกชิ้น ส้ม | G14: =SUM(D14:F14) -> 0 | K14: =SUM(H14:J14) -> 0 | O14: =SUM(L14:N14) -> 0 | S14: =SUM(P14:R14) -> 0 | W14: =SUM(T14:V14) -> 0 | AA14: =SUM(X14:Z14) -> 0 | AE14: =SUM(AB14:AD14) -> 0 | AI14: =SUM(AF14:AH14) -> 0 | AM14: =SUM(AJ14:AL14) -> 0 | AQ14: =SUM(AN14:AP14) -> 0 | AU14: =SUM(AR14:AT14) -> 0 | AY14: =SUM(AV14:AX14) -> 0 | BA14: =+G14+K14+O14+S14+W14+AA14+AE14+AZ14+AI14+AM14+AQ14+AU14+AY14 -> 0 | BC14: =+BA14-BB14 -> 0 | BF14: =+BD14+BE14-BC14 -> 0 | BH14: =BF14+BG14 -> 0
B15: 1111064 | C15: ชิฟฟอนแยกชิ้น เผือก | G15: =SUM(D15:F15) -> 0 | K15: =SUM(H15:J15) -> 0 | O15: =SUM(L15:N15) -> 0 | S15: =SUM(P15:R15) -> 0 | W15: =SUM(T15:V15) -> 0 | AA15: =SUM(X15:Z15) -> 0 | AE15: =SUM(AB15:AD15) -> 0 | AI15: =SUM(AF15:AH15) -> 0 | AM15: =SUM(AJ15:AL15) -> 0 | AQ15: =SUM(AN15:AP15) -> 0 | AU15: =SUM(AR15:AT15) -> 0 | AY15: =SUM(AV15:AX15) -> 0 | BA15: =+G15+K15+O15+S15+W15+AA15+AE15+AZ15+AI15+AM15+AQ15+AU15+AY15 -> 0 | BC15: =+BA15-BB15 -> 0 | BF15: =+BD15+BE15-BC15 -> 0 | BH15: =BF15+BG15 -> 0
... B85: 200 | C85: เศษขนมปังปลา 1 กก. | G85: =SUM(D85:F85) -> 0 | K85: =SUM(H85:J85) -> 0 | O85: =SUM(L85:N85) -> 0 | S85: =SUM(P85:R85) -> 0 | W85: =SUM(T85:V85) -> 0 | AA85: =SUM(X85:Z85) -> 0 | AE85: =SUM(AB85:AD85) -> 0 | AI85: =SUM(AF85:AH85) -> 0 | AM85: =SUM(AJ85:AL85) -> 0 | AQ85: =SUM(AN85:AP85) -> 0 | AU85: =SUM(AR85:AT85) -> 0 | AY85: =SUM(AV85:AX85) -> 0 | BA85: =+G85+K85+O85+S85+W85+AA85+AE85+AZ85+AI85+AM85+AQ85+AU85+AY85 -> 0 | BC85: =+BA85-BB85 -> 0 | BF85: =+BD85+BE85-BC85 -> 0 | BH85: =BF85+BG85 -> 0
C86: ชิฟฟอน 4 ชิ้น มะพร้าวล้วน | G86: =SUM(D86:F86) -> 0 | K86: =SUM(H86:J86) -> 0 | O86: =SUM(L86:N86) -> 0 | S86: =SUM(P86:R86) -> 0 | W86: =SUM(T86:V86) -> 0 | AA86: =SUM(X86:Z86) -> 0 | AE86: =SUM(AB86:AD86) -> 0 | AI86: =SUM(AF86:AH86) -> 0 | AM86: =SUM(AJ86:AL86) -> 0 | AQ86: =SUM(AN86:AP86) -> 0 | AU86: =SUM(AR86:AT86) -> 0 | AY86: =SUM(AV86:AX86) -> 0 | BA86: =+G86+K86+O86+S86+W86+AA86+AE86+AZ86+AI86+AM86+AQ86+AU86+AY86 -> 0 | BB86: =+H86+L86+P86+T86+X86+AB86+AF86+BA86+AJ86+AN86+AR86+AV86+AZ86 -> 0 | BC86: =+BA86-BB86 -> 0 | BF86: =+BD86+BE86-BC86 -> 0 | BH86: =BF86+BG86 -> 0
C87: ชิฟฟอน 4 ชิ้น กาแฟล้วน | G87: =SUM(D87:F87) -> 0 | K87: =SUM(H87:J87) -> 0 | O87: =SUM(L87:N87) -> 0 | S87: =SUM(P87:R87) -> 0 | W87: =SUM(T87:V87) -> 0 | AA87: =SUM(X87:Z87) -> 0 | AE87: =SUM(AB87:AD87) -> 0 | AI87: =SUM(AF87:AH87) -> 0 | AM87: =SUM(AJ87:AL87) -> 0 | AQ87: =SUM(AN87:AP87) -> 0 | AU87: =SUM(AR87:AT87) -> 0 | AY87: =SUM(AV87:AX87) -> 0 | BA87: =+G87+K87+O87+S87+W87+AA87+AE87+AZ87+AI87+AM87+AQ87+AU87+AY87 -> 0 | BB87: =+H87+L87+P87+T87+X87+AB87+AF87+BA87+AJ87+AN87+AR87+AV87+AZ87 -> 0 | BC87: =+BA87-BB87 -> 0 | BF87: =+BD87+BE87-BC87 -> 0 | BH87: =BF87+BG87 -> 0
C88: ชิฟฟอน 4 ชิ้น ชาเขียวล้วน | G88: =SUM(D88:F88) -> 0 | K88: =SUM(H88:J88) -> 0 | O88: =SUM(L88:N88) -> 0 | S88: =SUM(P88:R88) -> 0 | W88: =SUM(T88:V88) -> 0 | AA88: =SUM(X88:Z88) -> 0 | AE88: =SUM(AB88:AD88) -> 0 | AI88: =SUM(AF88:AH88) -> 0 | AM88: =SUM(AJ88:AL88) -> 0 | AQ88: =SUM(AN88:AP88) -> 0 | AU88: =SUM(AR88:AT88) -> 0 | AY88: =SUM(AV88:AX88) -> 0 | BA88: =+G88+K88+O88+S88+W88+AA88+AE88+AZ88+AI88+AM88+AQ88+AU88+AY88 -> 0 | BB88: =+H88+L88+P88+T88+X88+AB88+AF88+BA88+AJ88+AN88+AR88+AV88+AZ88 -> 0 | BC88: =+BA88-BB88 -> 0 | BF88: =+BD88+BE88-BC88 -> 0 | BH88: =BF88+BG88 -> 0
C89: ชิฟฟอน 4 ชิ้น ใบเตยล้วน | G89: =SUM(D89:F89) -> 0 | K89: =SUM(H89:J89) -> 0 | O89: =SUM(L89:N89) -> 0 | S89: =SUM(P89:R89) -> 0 | W89: =SUM(T89:V89) -> 0 | AA89: =SUM(X89:Z89) -> 0 | AE89: =SUM(AB89:AD89) -> 0 | AI89: =SUM(AF89:AH89) -> 0 | AM89: =SUM(AJ89:AL89) -> 0 | AQ89: =SUM(AN89:AP89) -> 0 | AU89: =SUM(AR89:AT89) -> 0 | AY89: =SUM(AV89:AX89) -> 0 | BA89: =+G89+K89+O89+S89+W89+AA89+AE89+AZ89+AI89+AM89+AQ89+AU89+AY89 -> 0 | BB89: =+H89+L89+P89+T89+X89+AB89+AF89+BA89+AJ89+AN89+AR89+AV89+AZ89 -> 0 | BC89: =+BA89-BB89 -> 0 | BF89: =+BD89+BE89-BC89 -> 0 | BH89: =BF89+BG89 -> 0
B90: 1111084 | C90: ชิฟฟอน 8 ชิ้น กาแฟล้วน | G90: =SUM(D90:F90) -> 0 | K90: =SUM(H90:J90) -> 0 | O90: =SUM(L90:N90) -> 0 | S90: =SUM(P90:R90) -> 0 | W90: =SUM(T90:V90) -> 0 | AA90: =SUM(X90:Z90) -> 0 | AE90: =SUM(AB90:AD90) -> 0 | AI90: =SUM(AF90:AH90) -> 0 | AM90: =SUM(AJ90:AL90) -> 0 | AQ90: =SUM(AN90:AP90) -> 0 | AU90: =SUM(AR90:AT90) -> 0 | AY90: =SUM(AV90:AX90) -> 0 | BA90: =+G90+K90+O90+S90+W90+AA90+AE90+AZ90+AI90+AM90+AQ90+AU90+AY90 -> 0 | BB90: =+H90+L90+P90+T90+X90+AB90+AF90+BA90+AJ90+AN90+AR90+AV90+AZ90 -> 0 | BC90: =+BA90-BB90 -> 0 | BF90: =+BD90+BE90-BC90 -> 0 | BH90: =BF90+BG90 -> 0
B91: 1111085 | C91: ชิฟฟอน 8 ชิ้น บลูเบอรี่ล้วน | G91: =SUM(D91:F91) -> 0 | K91: =SUM(H91:J91) -> 0 | O91: =SUM(L91:N91) -> 0 | S91: =SUM(P91:R91) -> 0 | W91: =SUM(T91:V91) -> 0 | AA91: =SUM(X91:Z91) -> 0 | AE91: =SUM(AB91:AD91) -> 0 | AI91: =SUM(AF91:AH91) -> 0 | AM91: =SUM(AJ91:AL91) -> 0 | AQ91: =SUM(AN91:AP91) -> 0 | AU91: =SUM(AR91:AT91) -> 0 | AY91: =SUM(AV91:AX91) -> 0 | BA91: =+G91+K91+O91+S91+W91+AA91+AE91+AZ91+AI91+AM91+AQ91+AU91+AY91 -> 0 | BB91: =+H91+L91+P91+T91+X91+AB91+AF91+BA91+AJ91+AN91+AR91+AV91+AZ91 -> 0 | BC91: =+BA91-BB91 -> 0 | BF91: =+BD91+BE91-BC91 -> 0 | BH91: =BF91+BG91 -> 0
B92: 1111086 | C92: ชิฟฟอน 8 ชิ้น มะพร้าวล้วน | G92: =SUM(D92:F92) -> 0 | K92: =SUM(H92:J92) -> 0 | O92: =SUM(L92:N92) -> 0 | S92: =SUM(P92:R92) -> 0 | W92: =SUM(T92:V92) -> 0 | AA92: =SUM(X92:Z92) -> 0 | AE92: =SUM(AB92:AD92) -> 0 | AI92: =SUM(AF92:AH92) -> 0 | AM92: =SUM(AJ92:AL92) -> 0 | AQ92: =SUM(AN92:AP92) -> 0 | AU92: =SUM(AR92:AT92) -> 0 | AY92: =SUM(AV92:AX92) -> 0 | BA92: =+G92+K92+O92+S92+W92+AA92+AE92+AZ92+AI92+AM92+AQ92+AU92+AY92 -> 0 | BB92: =+H92+L92+P92+T92+X92+AB92+AF92+BA92+AJ92+AN92+AR92+AV92+AZ92 -> 0 | BC92: =+BA92-BB92 -> 0 | BF92: =+BD92+BE92-BC92 -> 0 | BH92: =BF92+BG92 -> 0
B93: 1111087 | C93: ชิฟฟอน 8 ชิ้น สตอเบอรี่ล้วน | G93: =SUM(D93:F93) -> 0 | K93: =SUM(H93:J93) -> 0 | O93: =SUM(L93:N93) -> 0 | S93: =SUM(P93:R93) -> 0 | W93: =SUM(T93:V93) -> 0 | AA93: =SUM(X93:Z93) -> 0 | AE93: =SUM(AB93:AD93) -> 0 | AI93: =SUM(AF93:AH93) -> 0 | AM93: =SUM(AJ93:AL93) -> 0 | AQ93: =SUM(AN93:AP93) -> 0 | AU93: =SUM(AR93:AT93) -> 0 | AY93: =SUM(AV93:AX93) -> 0 | BA93: =+G93+K93+O93+S93+W93+AA93+AE93+AZ93+AI93+AM93+AQ93+AU93+AY93 -> 0 | BB93: =+H93+L93+P93+T93+X93+AB93+AF93+BA93+AJ93+AN93+AR93+AV93+AZ93 -> 0 | BC93: =+BA93-BB93 -> 0 | BF93: =+BD93+BE93-BC93 -> 0 | BH93: =BF93+BG93 -> 0
