Workbook

Sheet บ่าย
B1: ยอดจริง ออนไลน์ วันที่ - บ่าย
L2: ยอดรวมผลิต
L3: จำนวน
B4: รหัสสินค้า | C4: สินค้า | D4: ปณ | E4: ชอปปี้ | F4: ลาซาด้า | G4: ติ๊กตอก | H4: ติ๊กตอก 2 | I4: ติ๊กตอก3 | J4: ชอยส์ | K4: ยอดเส้น | L4: (กล่อง)
B6: ชิฟฟอนรวมรส
B7: 1111002 | C7: ชิฟฟอนรวมรส 8 ชิ้น | L7: =SUM(D7:K7) -> 0
C8: ชิฟฟอนแบบกล่องสุ่มอะไรก็ได้ที่มี | L8: =SUM(D8:K8) -> 0
B9: 1111084 | C9: ชิฟฟอน 8 ชิ้น กาแฟล้วน | L9: =SUM(D9:K9) -> 0
B10: 1111085 | C10: ชิฟฟอน 8 ชิ้น บลูเบอรี่ล้วน | L10: =SUM(D10:K10) -> 0
B11: 1111086 | C11: ชิฟฟอน 8 ชิ้น มะพร้าวล้วน | L11: =SUM(D11:K11) -> 0
B12: 1111087 | C12: ชิฟฟอน 8 ชิ้น สตอเบอรี่ล้วน | L12: =SUM(D12:K12) -> 0
B13: 1111088 | C13: ชิฟฟอน 8 ชิ้น ส้มล้วน | L13: =SUM(D13:K13) -> 0
B14: 1111089 | C14: ชิฟฟอน 8 ชิ้น เนยล้วน | L14: =SUM(D14:K14) -> 0
B15: 1111090 | C15: ชิฟฟอน 8 ชิ้น เผือกล้วน | L15: =SUM(D15:K15) -> 0
B16: 1111091 | C16: ชิฟฟอน 8 ชิ้น ใบเตยล้วน | L16: =SUM(D16:K16) -> 0
B17: 1111092 | C17: ชิฟฟอน 8 ชิ้น กล้วยหอม | L17: =SUM(D17:K17) -> 0
B18: 1111093 | C18: ชิฟฟอน 8 ชิ้น โกโก้ล้วน | L18: =SUM(D18:K18) -> 0
B19: 1111094 | C19: ชิฟฟอน 8 ชิ้น ชาไทยล้วน | L19: =SUM(D19:K19) -> 0
B20: 1111095 | C20: ชิฟฟอน 8 ชิ้น ชาเขียวล้วน | L20: =SUM(D20:K20) -> 0
... B66: 1111010 | C66: ชิฟฟอนไส้แยมแยกชิ้น คละรส | L66: =SUM(D66:K66) -> 0
C67: รวม | L67: =SUM(L7:L66) -> 0
B68: ชิฟฟอนไส้แยม 6 ชิ้น
B69: 1111009 | C69: ชิฟฟอนไส้แยมรวมรส 6 ชิ้น | L69: =SUM(D69:K69) -> 0
B70: 1111023 | C70: ชิฟฟอนไส้แยมรสสตอเบอร์รี่ล้วน 6 ชิ้น | L70: =SUM(D70:K70) -> 0
B71: 1111016 | C71: ชิฟฟอนไส้แยมรสมะพร้าวล้วน 6 ชิ้น | L71: =SUM(D71:K71) -> 0
B72: 1111014 | C72: ชิฟฟอนไส้แยมรสช็อกโกแลตนูเทลล่าล้วน 6 ชิ้น | L72: =SUM(D72:K72) -> 0
B73: 1111025 | C73: ชิฟฟอนไส้แยมรสส้มล้วน 6 ชิ้น | L73: =SUM(D73:K73) -> 0
B74: 1111018 | C74: ชิฟฟอนไส้แยมรสบลูเบอร์รี่ล้วน 6 ชิ้น | L74: =SUM(D74:K74) -> 0
B75: 1111012 | C75: ชิฟฟอนไส้แยมรสนมชมพูฮอกไกโดล้วน 6 ชิ้น | L75: =SUM(D75:K75) -> 0
B76: 1111020 | C76: ชิฟฟอนไส้แยมฝอยทองไส้ทะลัก 6 ชิ้น | L76: =SUM(D76:K76) -> 0
C77: รวม | L77: =SUM(L69:L76) -> 0
B78: ชิฟฟอนไส้แยม 3 ชิ้น
B79: 1111022 | C79: ชิฟฟอนไส้แยมรสสตอเบอร์รี่ล้วน 3 ชิ้น | L79: =SUM(D79:K79) -> 0
B80: 1111015 | C80: ชิฟฟอนไส้แยมรสมะพร้าวล้วน 3 ชิ้น | L80: =SUM(D80:K80) -> 0
B81: 1111013 | C81: ชิฟฟอนไส้แยมรสช็อกโกแลตนูเทลล่าล้วน 3 ชิ้น | L81: =SUM(D81:K81) -> 0
B82: 1111024 | C82: ชิฟฟอนไส้แยมรสส้มล้วน 3 ชิ้น | L82: =SUM(D82:K82) -> 0
B83: 1111017 | C83: ชิฟฟอนไส้แยมรสบลูเบอร์รี่ล้วน 3 ชิ้น | L83: =SUM(D83:K83) -> 0
B84: 1111011 | C84: ชิฟฟอนไส้แยมรสนมชมพูฮอกไกโดล้วน 3 ชิ้น | L84: =SUM(D84:K84) -> 0
B85: 1111019 | C85: ชิฟฟอนไส้แยมฝอยทองไส้ทะลัก 3 ชิ้น | L85: =SUM(D85:K85) -> 0
B86: 1113081 | C86: ชิฟฟอนไส้แยม วนิลา/ใบเตย/เมล่อน | L86: =SUM(D86:K86) -> 0
...

Sheet เย็น 
B1: ยอดจริง ออนไลน์ วันที่ - เย็น
L2: ยอดรวมผลิต
L3: จำนวน
B4: รหัสสินค้า | C4: สินค้า | D4: ปณ | E4: ชอปปี้ | F4: ลาซาด้า | G4: ติ๊กตอก | H4: ติ๊กตอก 2 | I4: ติ๊กตอก3 | J4: ชอยส์ | K4: ยอดเส้น | L4: (กล่อง)
B6: ชิฟฟอนรวมรส
B7: 1111002 | C7: ชิฟฟอนรวมรส 8 ชิ้น | L7: =SUM(D7:K7) -> 0
C8: ชิฟฟอนแบบกล่องสุ่มอะไรก็ได้ที่มี | L8: =SUM(D8:K8) -> 0
B9: 1111084 | C9: ชิฟฟอน 8 ชิ้น กาแฟล้วน | L9: =SUM(D9:K9) -> 0
B10: 1111085 | C10: ชิฟฟอน 8 ชิ้น บลูเบอรี่ล้วน | L10: =SUM(D10:K10) -> 0
B11: 1111086 | C11: ชิฟฟอน 8 ชิ้น มะพร้าวล้วน | L11: =SUM(D11:K11) -> 0
B12: 1111087 | C12: ชิฟฟอน 8 ชิ้น สตอเบอรี่ล้วน | L12: =SUM(D12:K12) -> 0
B13: 1111088 | C13: ชิฟฟอน 8 ชิ้น ส้มล้วน | L13: =SUM(D13:K13) -> 0
B14: 1111089 | C14: ชิฟฟอน 8 ชิ้น เนยล้วน | L14: =SUM(D14:K14) -> 0
B15: 1111090 | C15: ชิฟฟอน 8 ชิ้น เผือกล้วน | L15: =SUM(D15:K15) -> 0
B16: 1111091 | C16: ชิฟฟอน 8 ชิ้น ใบเตยล้วน | L16: =SUM(D16:K16) -> 0
B17: 1111092 | C17: ชิฟฟอน 8 ชิ้น กล้วยหอม | L17: =SUM(D17:K17) -> 0
B18: 1111093 | C18: ชิฟฟอน 8 ชิ้น โกโก้ล้วน | L18: =SUM(D18:K18) -> 0
B19: 1111094 | C19: ชิฟฟอน 8 ชิ้น ชาไทยล้วน | L19: =SUM(D19:K19) -> 0
B20: 1111095 | C20: ชิฟฟอน 8 ชิ้น ชาเขียวล้วน | L20: =SUM(D20:K20) -> 0
... B66: 1111010 | C66: ชิฟฟอนไส้แยมแยกชิ้น คละรส | L66: =SUM(D66:K66) -> 0
C67: รวม | L67: =SUM(L7:L66) -> 0
B68: ชิฟฟอนไส้แยม 6 ชิ้น
B69: 1111009 | C69: ชิฟฟอนไส้แยมรวมรส 6 ชิ้น | L69: =SUM(D69:K69) -> 0
B70: 1111023 | C70: ชิฟฟอนไส้แยมรสสตอเบอร์รี่ล้วน 6 ชิ้น | L70: =SUM(D70:K70) -> 0
B71: 1111016 | C71: ชิฟฟอนไส้แยมรสมะพร้าวล้วน 6 ชิ้น | L71: =SUM(D71:K71) -> 0
B72: 1111014 | C72: ชิฟฟอนไส้แยมรสช็อกโกแลตนูเทลล่าล้วน 6 ชิ้น | L72: =SUM(D72:K72) -> 0
B73: 1111025 | C73: ชิฟฟอนไส้แยมรสส้มล้วน 6 ชิ้น | L73: =SUM(D73:K73) -> 0
B74: 1111018 | C74: ชิฟฟอนไส้แยมรสบลูเบอร์รี่ล้วน 6 ชิ้น | L74: =SUM(D74:K74) -> 0
B75: 1111012 | C75: ชิฟฟอนไส้แยมรสนมชมพูฮอกไกโดล้วน 6 ชิ้น | L75: =SUM(D75:K75) -> 0
B76: 1111020 | C76: ชิฟฟอนไส้แยมฝอยทองไส้ทะลัก 6 ชิ้น | L76: =SUM(D76:K76) -> 0
C77: รวม | L77: =SUM(L69:L76) -> 0
B78: ชิฟฟอนไส้แยม 3 ชิ้น
B79: 1111022 | C79: ชิฟฟอนไส้แยมรสสตอเบอร์รี่ล้วน 3 ชิ้น | L79: =SUM(D79:K79) -> 0
B80: 1111015 | C80: ชิฟฟอนไส้แยมรสมะพร้าวล้วน 3 ชิ้น | L80: =SUM(D80:K80) -> 0
B81: 1111013 | C81: ชิฟฟอนไส้แยมรสช็อกโกแลตนูเทลล่าล้วน 3 ชิ้น | L81: =SUM(D81:K81) -> 0
B82: 1111024 | C82: ชิฟฟอนไส้แยมรสส้มล้วน 3 ชิ้น | L82: =SUM(D82:K82) -> 0
B83: 1111017 | C83: ชิฟฟอนไส้แยมรสบลูเบอร์รี่ล้วน 3 ชิ้น | L83: =SUM(D83:K83) -> 0
B84: 1111011 | C84: ชิฟฟอนไส้แยมรสนมชมพูฮอกไกโดล้วน 3 ชิ้น | L84: =SUM(D84:K84) -> 0
B85: 1111019 | C85: ชิฟฟอนไส้แยมฝอยทองไส้ทะลัก 3 ชิ้น | L85: =SUM(D85:K85) -> 0
B86: 1113081 | C86: ชิฟฟอนไส้แยม วนิลา/ใบเตย/เมล่อน | L86: =SUM(D86:K86) -> 0
...

Sheet 01.4.68
B1: ยอดจริง ออนไลน์ วันที่ 1/4/2569
B2: รหัสสินค้า | C2: สินค้า | D2: ปณ | H2: ชอปปี้ | L2: ลาซาด้า | P2: ติ๊กตอก | T2: ติ๊กตอก2 | X2: ติ๊กตอก3 | AB2: ติ๊กตอก4 | AF2: ติ๊กตอก5 | AJ2: ติ๊กตอก6 | AN2: ติ๊กตอก7 | AR2: ติ๊กตอก8 | AV2: ติ๊กตอก9 | AZ2: ยอดเส้น | BA2: ยอดรวมผลิต(กล่อง) | BB2: ยอดForcast | BC2: ยอดStock | BD2: ยอดMemo | BE2: ยอดForcastวันพรุ่งนี้ | BF2: สินค้าที่ขายได้
D3: เช้า | E3: บ่าย | F3: เย็น | G3: รวม | H3: เช้า | I3: บ่าย | J3: เย็น | K3: รวม | L3: เช้า | M3: บ่าย | N3: เย็น | O3: รวม | P3: เช้า | Q3: บ่าย | R3: เย็น | S3: รวม | T3: เช้า | U3: บ่าย | V3: เย็น | W3: รวม | X3: เช้า | Y3: บ่าย | Z3: เย็น | AA3: รวม | AB3: เช้า | AC3: บ่าย | AD3: เย็น | AE3: รวม | AF3: เช้า | AG3: บ่าย | AH3: เย็น | AI3: รวม | AJ3: เช้า | AK3: บ่าย | AL3: เย็น | AM3: รวม | AN3: เช้า | AO3: บ่าย | AP3: เย็น | AQ3: รวม | AR3: เช้า | AS3: บ่าย | AT3: เย็น | AU3: รวม | AV3: เช้า | AW3: บ่าย | AX3: เย็น | AY3: รวม
B4: 1004055 | C4: ชิฟฟ่อนเค้ก วรรณวนัช (รวมรส 4 ชิ้น) | G4: =SUM(D4:F4) -> 0 | K4: =SUM(H4:J4) -> 0 | O4: =SUM(L4:N4) -> 0 | S4: =SUM(P4:R4) -> 0 | W4: =SUM(T4:V4) -> 0 | AA4: =SUM(X4:Z4) -> 0 | AE4: =SUM(AB4:AD4) -> 0 | AI4: =SUM(AF4:AH4) -> 0 | AM4: =SUM(AJ4:AL4) -> 0 | AQ4: =SUM(AN4:AP4) -> 0 | AU4: =SUM(AR4:AT4) -> 0 | AY4: =SUM(AV4:AX4) -> 0 | BA4: =+G4+K4+O4+S4+W4+AA4+AE4+AZ4+AI4+AM4+AQ4+AU4+AY4 -> 0 | BD4: =+BB4+BC4-BA4 -> 0 | BF4: =BD4+BE4 -> 0
B5: 1111002 | C5: ชิฟฟ่อนเค้ก วรรณวนัช (รวมรส 8 ชิ้น) | G5: =SUM(D5:F5) -> 0 | H5: 36 | I5: 16 | K5: =SUM(H5:J5) -> 52 | L5: 2 | O5: =SUM(L5:N5) -> 2 | P5: 3 | Q5: 3 | S5: =SUM(P5:R5) -> 6 | W5: =SUM(T5:V5) -> 0 | AA5: =SUM(X5:Z5) -> 0 | AE5: =SUM(AB5:AD5) -> 0 | AI5: =SUM(AF5:AH5) -> 0 | AM5: =SUM(AJ5:AL5) -> 0 | AQ5: =SUM(AN5:AP5) -> 0 | AU5: =SUM(AR5:AT5) -> 0 | AY5: =SUM(AV5:AX5) -> 0 | AZ5: 5 | BA5: =+G5+K5+O5+S5+W5+AA5+AE5+AZ5+AI5+AM5+AQ5+AU5+AY5 -> 65 | BB5: 55 | BC5: 212 | BD5: =+BB5+BC5-BA5 -> 202 | BE5: 50 | BF5: =BD5+BE5 -> 252
B6: 1111001 | C6: ชิฟฟ่อนแยกชิ้นไม่มีไส้ คละรส | G6: =SUM(D6:F6) -> 0 | I6: 50 | K6: =SUM(H6:J6) -> 50 | O6: =SUM(L6:N6) -> 0 | S6: =SUM(P6:R6) -> 0 | W6: =SUM(T6:V6) -> 0 | AA6: =SUM(X6:Z6) -> 0 | AE6: =SUM(AB6:AD6) -> 0 | AI6: =SUM(AF6:AH6) -> 0 | AM6: =SUM(AJ6:AL6) -> 0 | AQ6: =SUM(AN6:AP6) -> 0 | AU6: =SUM(AR6:AT6) -> 0 | AY6: =SUM(AV6:AX6) -> 0 | BA6: =+G6+K6+O6+S6+W6+AA6+AE6+AZ6+AI6+AM6+AQ6+AU6+AY6 -> 50 | BD6: =+BB6+BC6-BA6 -> -50 | BF6: =BD6+BE6 -> -50
B7: 1111043 | C7: ชิฟฟอนรสมะลิ 8 ชิ้น ห่อ ซีน | G7: =SUM(D7:F7) -> 0 | K7: =SUM(H7:J7) -> 0 | O7: =SUM(L7:N7) -> 0 | S7: =SUM(P7:R7) -> 0 | W7: =SUM(T7:V7) -> 0 | AA7: =SUM(X7:Z7) -> 0 | AE7: =SUM(AB7:AD7) -> 0 | AI7: =SUM(AF7:AH7) -> 0 | AM7: =SUM(AJ7:AL7) -> 0 | AQ7: =SUM(AN7:AP7) -> 0 | AU7: =SUM(AR7:AT7) -> 0 | AY7: =SUM(AV7:AX7) -> 0 | BA7: =+G7+K7+O7+S7+W7+AA7+AE7+AZ7+AI7+AM7+AQ7+AU7+AY7 -> 0 | BD7: =+BB7+BC7-BA7 -> 0 | BF7: =BD7+BE7 -> 0
B8: 1111057 | C8: ชิฟฟอนแยกชิ้น กาแฟ | G8: =SUM(D8:F8) -> 0 | K8: =SUM(H8:J8) -> 0 | O8: =SUM(L8:N8) -> 0 | S8: =SUM(P8:R8) -> 0 | W8: =SUM(T8:V8) -> 0 | AA8: =SUM(X8:Z8) -> 0 | AE8: =SUM(AB8:AD8) -> 0 | AI8: =SUM(AF8:AH8) -> 0 | AM8: =SUM(AJ8:AL8) -> 0 | AQ8: =SUM(AN8:AP8) -> 0 | AU8: =SUM(AR8:AT8) -> 0 | AY8: =SUM(AV8:AX8) -> 0 | BA8: =+G8+K8+O8+S8+W8+AA8+AE8+AZ8+AI8+AM8+AQ8+AU8+AY8 -> 0 | BD8: =+BB8+BC8-BA8 -> 0 | BF8: =BD8+BE8 -> 0
B9: 1111058 | C9: ชิฟฟอนแยกชิ้น ชาเขียว | G9: =SUM(D9:F9) -> 0 | K9: =SUM(H9:J9) -> 0 | O9: =SUM(L9:N9) -> 0 | S9: =SUM(P9:R9) -> 0 | W9: =SUM(T9:V9) -> 0 | AA9: =SUM(X9:Z9) -> 0 | AE9: =SUM(AB9:AD9) -> 0 | AI9: =SUM(AF9:AH9) -> 0 | AM9: =SUM(AJ9:AL9) -> 0 | AQ9: =SUM(AN9:AP9) -> 0 | AU9: =SUM(AR9:AT9) -> 0 | AY9: =SUM(AV9:AX9) -> 0 | BA9: =+G9+K9+O9+S9+W9+AA9+AE9+AZ9+AI9+AM9+AQ9+AU9+AY9 -> 0 | BD9: =+BB9+BC9-BA9 -> 0 | BF9: =BD9+BE9 -> 0
B10: 1111059 | C10: ชิฟฟอนแยกชิ้น ใบเตย | G10: =SUM(D10:F10) -> 0 | K10: =SUM(H10:J10) -> 0 | O10: =SUM(L10:N10) -> 0 | S10: =SUM(P10:R10) -> 0 | W10: =SUM(T10:V10) -> 0 | AA10: =SUM(X10:Z10) -> 0 | AE10: =SUM(AB10:AD10) -> 0 | AI10: =SUM(AF10:AH10) -> 0 | AM10: =SUM(AJ10:AL10) -> 0 | AQ10: =SUM(AN10:AP10) -> 0 | AU10: =SUM(AR10:AT10) -> 0 | AY10: =SUM(AV10:AX10) -> 0 | BA10: =+G10+K10+O10+S10+W10+AA10+AE10+AZ10+AI10+AM10+AQ10+AU10+AY10 -> 0 | BD10: =+BB10+BC10-BA10 -> 0 | BF10: =BD10+BE10 -> 0
B11: 1111060 | C11: ชิฟฟอนแยกชิ้น กล้วยหอม | G11: =SUM(D11:F11) -> 0 | K11: =SUM(H11:J11) -> 0 | O11: =SUM(L11:N11) -> 0 | S11: =SUM(P11:R11) -> 0 | W11: =SUM(T11:V11) -> 0 | AA11: =SUM(X11:Z11) -> 0 | AE11: =SUM(AB11:AD11) -> 0 | AI11: =SUM(AF11:AH11) -> 0 | AM11: =SUM(AJ11:AL11) -> 0 | AQ11: =SUM(AN11:AP11) -> 0 | AU11: =SUM(AR11:AT11) -> 0 | AY11: =SUM(AV11:AX11) -> 0 | BA11: =+G11+K11+O11+S11+W11+AA11+AE11+AZ11+AI11+AM11+AQ11+AU11+AY11 -> 0 | BD11: =+BB11+BC11-BA11 -> 0 | BF11: =BD11+BE11 -> 0
B12: 1111061 | C12: ชิฟฟอนแยกชิ้น ชาไทย | G12: =SUM(D12:F12) -> 0 | K12: =SUM(H12:J12) -> 0 | O12: =SUM(L12:N12) -> 0 | S12: =SUM(P12:R12) -> 0 | W12: =SUM(T12:V12) -> 0 | AA12: =SUM(X12:Z12) -> 0 | AE12: =SUM(AB12:AD12) -> 0 | AI12: =SUM(AF12:AH12) -> 0 | AM12: =SUM(AJ12:AL12) -> 0 | AQ12: =SUM(AN12:AP12) -> 0 | AU12: =SUM(AR12:AT12) -> 0 | AY12: =SUM(AV12:AX12) -> 0 | BA12: =+G12+K12+O12+S12+W12+AA12+AE12+AZ12+AI12+AM12+AQ12+AU12+AY12 -> 0 | BD12: =+BB12+BC12-BA12 -> 0 | BF12: =BD12+BE12 -> 0
B13: 1111062 | C13: ชิฟฟอนแยกชิ้น โกโก้ | G13: =SUM(D13:F13) -> 0 | K13: =SUM(H13:J13) -> 0 | O13: =SUM(L13:N13) -> 0 | S13: =SUM(P13:R13) -> 0 | W13: =SUM(T13:V13) -> 0 | AA13: =SUM(X13:Z13) -> 0 | AE13: =SUM(AB13:AD13) -> 0 | AI13: =SUM(AF13:AH13) -> 0 | AM13: =SUM(AJ13:AL13) -> 0 | AQ13: =SUM(AN13:AP13) -> 0 | AU13: =SUM(AR13:AT13) -> 0 | AY13: =SUM(AV13:AX13) -> 0 | BA13: =+G13+K13+O13+S13+W13+AA13+AE13+AZ13+AI13+AM13+AQ13+AU13+AY13 -> 0 | BD13: =+BB13+BC13-BA13 -> 0 | BF13: =BD13+BE13 -> 0
B14: 1111063 | C14: ชิฟฟอนแยกชิ้น ส้ม | G14: =SUM(D14:F14) -> 0 | K14: =SUM(H14:J14) -> 0 | O14: =SUM(L14:N14) -> 0 | S14: =SUM(P14:R14) -> 0 | W14: =SUM(T14:V14) -> 0 | AA14: =SUM(X14:Z14) -> 0 | AE14: =SUM(AB14:AD14) -> 0 | AI14: =SUM(AF14:AH14) -> 0 | AM14: =SUM(AJ14:AL14) -> 0 | AQ14: =SUM(AN14:AP14) -> 0 | AU14: =SUM(AR14:AT14) -> 0 | AY14: =SUM(AV14:AX14) -> 0 | BA14: =+G14+K14+O14+S14+W14+AA14+AE14+AZ14+AI14+AM14+AQ14+AU14+AY14 -> 0 | BD14: =+BB14+BC14-BA14 -> 0 | BF14: =BD14+BE14 -> 0
B15: 1111064 | C15: ชิฟฟอนแยกชิ้น เผือก | G15: =SUM(D15:F15) -> 0 | K15: =SUM(H15:J15) -> 0 | O15: =SUM(L15:N15) -> 0 | S15: =SUM(P15:R15) -> 0 | W15: =SUM(T15:V15) -> 0 | AA15: =SUM(X15:Z15) -> 0 | AE15: =SUM(AB15:AD15) -> 0 | AI15: =SUM(AF15:AH15) -> 0 | AM15: =SUM(AJ15:AL15) -> 0 | AQ15: =SUM(AN15:AP15) -> 0 | AU15: =SUM(AR15:AT15) -> 0 | AY15: =SUM(AV15:AX15) -> 0 | BA15: =+G15+K15+O15+S15+W15+AA15+AE15+AZ15+AI15+AM15+AQ15+AU15+AY15 -> 0 | BD15: =+BB15+BC15-BA15 -> 0 | BF15: =BD15+BE15 -> 0
B16: 1111065 | C16: ชิฟฟอนแยกชิ้น สับปะรด | G16: =SUM(D16:F16) -> 0 | K16: =SUM(H16:J16) -> 0 | O16: =SUM(L16:N16) -> 0 | S16: =SUM(P16:R16) -> 0 | W16: =SUM(T16:V16) -> 0 | AA16: =SUM(X16:Z16) -> 0 | AE16: =SUM(AB16:AD16) -> 0 | AI16: =SUM(AF16:AH16) -> 0 | AM16: =SUM(AJ16:AL16) -> 0 | AQ16: =SUM(AN16:AP16) -> 0 | AU16: =SUM(AR16:AT16) -> 0 | AY16: =SUM(AV16:AX16) -> 0 | BA16: =+G16+K16+O16+S16+W16+AA16+AE16+AZ16+AI16+AM16+AQ16+AU16+AY16 -> 0 | BD16: =+BB16+BC16-BA16 -> 0 | BF16: =BD16+BE16 -> 0
B17: 1111066 | C17: ชิฟฟอนแยกชิ้น สตอเบอรี่ | G17: =SUM(D17:F17) -> 0 | K17: =SUM(H17:J17) -> 0 | O17: =SUM(L17:N17) -> 0 | S17: =SUM(P17:R17) -> 0 | W17: =SUM(T17:V17) -> 0 | AA17: =SUM(X17:Z17) -> 0 | AE17: =SUM(AB17:AD17) -> 0 | AI17: =SUM(AF17:AH17) -> 0 | AM17: =SUM(AJ17:AL17) -> 0 | AQ17: =SUM(AN17:AP17) -> 0 | AU17: =SUM(AR17:AT17) -> 0 | AY17: =SUM(AV17:AX17) -> 0 | BA17: =+G17+K17+O17+S17+W17+AA17+AE17+AZ17+AI17+AM17+AQ17+AU17+AY17 -> 0 | BD17: =+BB17+BC17-BA17 -> 0 | BF17: =BD17+BE17 -> 0
B18: 1111067 | C18: ชิฟฟอนแยกชิ้น มะพร้าว | G18: =SUM(D18:F18) -> 0 | K18: =SUM(H18:J18) -> 0 | O18: =SUM(L18:N18) -> 0 | S18: =SUM(P18:R18) -> 0 | W18: =SUM(T18:V18) -> 0 | AA18: =SUM(X18:Z18) -> 0 | AE18: =SUM(AB18:AD18) -> 0 | AI18: =SUM(AF18:AH18) -> 0 | AM18: =SUM(AJ18:AL18) -> 0 | AQ18: =SUM(AN18:AP18) -> 0 | AU18: =SUM(AR18:AT18) -> 0 | AY18: =SUM(AV18:AX18) -> 0 | BA18: =+G18+K18+O18+S18+W18+AA18+AE18+AZ18+AI18+AM18+AQ18+AU18+AY18 -> 0 | BD18: =+BB18+BC18-BA18 -> 0 | BF18: =BD18+BE18 -> 0
... B23: 1111010 | C23: ชิฟฟ่อนเค้กสอดไส้แยม (1 ชิ้น) | G23: =SUM(D23:F23) -> 0 | K23: =SUM(H23:J23) -> 0 | O23: =SUM(L23:N23) -> 0 | S23: =SUM(P23:R23) -> 0 | W23: =SUM(T23:V23) -> 0 | AA23: =SUM(X23:Z23) -> 0 | AE23: =SUM(AB23:AD23) -> 0 | AI23: =SUM(AF23:AH23) -> 0 | AM23: =SUM(AJ23:AL23) -> 0 | AQ23: =SUM(AN23:AP23) -> 0 | AU23: =SUM(AR23:AT23) -> 0 | AY23: =SUM(AV23:AX23) -> 0 | BA23: =+G23+K23+O23+S23+W23+AA23+AE23+AZ23+AI23+AM23+AQ23+AU23+AY23 -> 0 | BD23: =+BB23+BC23-BA23 -> 0 | BF23: =BD23+BE23 -> 0
B24: 1111008 | C24: ชิฟฟ่อนเค้ก สอดไส้ (รวมรส 3 ชิ้น) | G24: =SUM(D24:F24) -> 0 | H24: 19 | I24: 6 | K24: =SUM(H24:J24) -> 25 | L24: 10 | O24: =SUM(L24:N24) -> 10 | P24: 69 | S24: =SUM(P24:R24) -> 69 | W24: =SUM(T24:V24) -> 0 | AA24: =SUM(X24:Z24) -> 0 | AE24: =SUM(AB24:AD24) -> 0 | AI24: =SUM(AF24:AH24) -> 0 | AM24: =SUM(AJ24:AL24) -> 0 | AQ24: =SUM(AN24:AP24) -> 0 | AU24: =SUM(AR24:AT24) -> 0 | AY24: =SUM(AV24:AX24) -> 0 | AZ24: 5 | BA24: =+G24+K24+O24+S24+W24+AA24+AE24+AZ24+AI24+AM24+AQ24+AU24+AY24 -> 109 | BB24: 75 | BC24: 34 | BD24: =+BB24+BC24-BA24 -> 0 | BE24: 70 | BF24: =BD24+BE24 -> 70
B25: 1111009 | C25: ชิฟฟ่อนเค้ก สอดไส้ (รวมรส 6 ชิ้น) | D25: 1 | G25: =SUM(D25:F25) -> 1 | H25: 2 | I25: 3 | K25: =SUM(H25:J25) -> 5 | L25: 4 | O25: =SUM(L25:N25) -> 4 | P25: 3 | S25: =SUM(P25:R25) -> 3 | W25: =SUM(T25:V25) -> 0 | AA25: =SUM(X25:Z25) -> 0 | AE25: =SUM(AB25:AD25) -> 0 | AI25: =SUM(AF25:AH25) -> 0 | AM25: =SUM(AJ25:AL25) -> 0 | AQ25: =SUM(AN25:AP25) -> 0 | AU25: =SUM(AR25:AT25) -> 0 | AY25: =SUM(AV25:AX25) -> 0 | BA25: =+G25+K25+O25+S25+W25+AA25+AE25+AZ25+AI25+AM25+AQ25+AU25+AY25 -> 13 | BB25: 10 | BC25: 12 | BD25: =+BB25+BC25-BA25 -> 9 | BE25: 10 | BF25: =BD25+BE25 -> 19
B26: 1111011 | C26: ชิฟฟ่อนเค้กสอดไส้ นมชมพูฮอกไกโด (3 ชิ้น) | G26: =SUM(D26:F26) -> 0 | K26: =SUM(H26:J26) -> 0 | O26: =SUM(L26:N26) -> 0 | S26: =SUM(P26:R26) -> 0 | W26: =SUM(T26:V26) -> 0 | AA26: =SUM(X26:Z26) -> 0 | AE26: =SUM(AB26:AD26) -> 0 | AI26: =SUM(AF26:AH26) -> 0 | AM26: =SUM(AJ26:AL26) -> 0 | AQ26: =SUM(AN26:AP26) -> 0 | AU26: =SUM(AR26:AT26) -> 0 | AY26: =SUM(AV26:AX26) -> 0 | BA26: =+G26+K26+O26+S26+W26+AA26+AE26+AZ26+AI26+AM26+AQ26+AU26+AY26 -> 0 | BD26: =+BB26+BC26-BA26 -> 0 | BF26: =BD26+BE26 -> 0
B27: 1111012 | C27: ชิฟฟ่อนเค้กสอดไส้ นมชมพูฮอกไกโด (6 ชิ้น) | G27: =SUM(D27:F27) -> 0 | K27: =SUM(H27:J27) -> 0 | O27: =SUM(L27:N27) -> 0 | S27: =SUM(P27:R27) -> 0 | W27: =SUM(T27:V27) -> 0 | AA27: =SUM(X27:Z27) -> 0 | AE27: =SUM(AB27:AD27) -> 0 | AI27: =SUM(AF27:AH27) -> 0 | AM27: =SUM(AJ27:AL27) -> 0 | AQ27: =SUM(AN27:AP27) -> 0 | AU27: =SUM(AR27:AT27) -> 0 | AY27: =SUM(AV27:AX27) -> 0 | BA27: =+G27+K27+O27+S27+W27+AA27+AE27+AZ27+AI27+AM27+AQ27+AU27+AY27 -> 0 | BD27: =+BB27+BC27-BA27 -> 0 | BF27: =BD27+BE27 -> 0
B28: 1111013 | C28: ชิฟฟ่อนเค้กสอดไส้ ช็อคโกแลตนูเทลล่า (3 ชิ้น) | G28: =SUM(D28:F28) -> 0 | K28: =SUM(H28:J28) -> 0 | O28: =SUM(L28:N28) -> 0 | S28: =SUM(P28:R28) -> 0 | W28: =SUM(T28:V28) -> 0 | AA28: =SUM(X28:Z28) -> 0 | AE28: =SUM(AB28:AD28) -> 0 | AI28: =SUM(AF28:AH28) -> 0 | AM28: =SUM(AJ28:AL28) -> 0 | AQ28: =SUM(AN28:AP28) -> 0 | AU28: =SUM(AR28:AT28) -> 0 | AY28: =SUM(AV28:AX28) -> 0 | BA28: =+G28+K28+O28+S28+W28+AA28+AE28+AZ28+AI28+AM28+AQ28+AU28+AY28 -> 0 | BD28: =+BB28+BC28-BA28 -> 0 | BF28: =BD28+BE28 -> 0
B29: 1111014 | C29: ชิฟฟ่อนเค้กสอดไส้ ช็อคโกแลตนูเทลล่า (6 ชิ้น) | G29: =SUM(D29:F29) -> 0 | K29: =SUM(H29:J29) -> 0 | O29: =SUM(L29:N29) -> 0 | S29: =SUM(P29:R29) -> 0 | W29: =SUM(T29:V29) -> 0 | AA29: =SUM(X29:Z29) -> 0 | AE29: =SUM(AB29:AD29) -> 0 | AI29: =SUM(AF29:AH29) -> 0 | AM29: =SUM(AJ29:AL29) -> 0 | AQ29: =SUM(AN29:AP29) -> 0 | AU29: =SUM(AR29:AT29) -> 0 | AY29: =SUM(AV29:AX29) -> 0 | BA29: =+G29+K29+O29+S29+W29+AA29+AE29+AZ29+AI29+AM29+AQ29+AU29+AY29 -> 0 | BD29: =+BB29+BC29-BA29 -> 0 | BF29: =BD29+BE29 -> 0
B30: 1111015 | C30: ชิฟฟ่อนเค้กสอดไส้เนย รสมะพร้าว (3 ชิ้น) | G30: =SUM(D30:F30) -> 0 | K30: =SUM(H30:J30) -> 0 | O30: =SUM(L30:N30) -> 0 | S30: =SUM(P30:R30) -> 0 | W30: =SUM(T30:V30) -> 0 | AA30: =SUM(X30:Z30) -> 0 | AE30: =SUM(AB30:AD30) -> 0 | AI30: =SUM(AF30:AH30) -> 0 | AM30: =SUM(AJ30:AL30) -> 0 | AQ30: =SUM(AN30:AP30) -> 0 | AU30: =SUM(AR30:AT30) -> 0 | AY30: =SUM(AV30:AX30) -> 0 | BA30: =+G30+K30+O30+S30+W30+AA30+AE30+AZ30+AI30+AM30+AQ30+AU30+AY30 -> 0 | BD30: =+BB30+BC30-BA30 -> 0 | BF30: =BD30+BE30 -> 0
B31: 1111016 | C31: ชิฟฟ่อนเค้กสอดไส้เนย รสมะพร้าว (6 ชิ้น) | G31: =SUM(D31:F31) -> 0 | K31: =SUM(H31:J31) -> 0 | O31: =SUM(L31:N31) -> 0 | S31: =SUM(P31:R31) -> 0 | W31: =SUM(T31:V31) -> 0 | AA31: =SUM(X31:Z31) -> 0 | AE31: =SUM(AB31:AD31) -> 0 | AI31: =SUM(AF31:AH31) -> 0 | AM31: =SUM(AJ31:AL31) -> 0 | AQ31: =SUM(AN31:AP31) -> 0 | AU31: =SUM(AR31:AT31) -> 0 | AY31: =SUM(AV31:AX31) -> 0 | BA31: =+G31+K31+O31+S31+W31+AA31+AE31+AZ31+AI31+AM31+AQ31+AU31+AY31 -> 0 | BD31: =+BB31+BC31-BA31 -> 0 | BF31: =BD31+BE31 -> 0
B32: 1111017 | C32: ชิฟฟ่อนเค้กสอดไส้แยม รสบลูเบอร์รี่ (3 ชิ้น) | G32: =SUM(D32:F32) -> 0 | K32: =SUM(H32:J32) -> 0 | O32: =SUM(L32:N32) -> 0 | S32: =SUM(P32:R32) -> 0 | W32: =SUM(T32:V32) -> 0 | AA32: =SUM(X32:Z32) -> 0 | AE32: =SUM(AB32:AD32) -> 0 | AI32: =SUM(AF32:AH32) -> 0 | AM32: =SUM(AJ32:AL32) -> 0 | AQ32: =SUM(AN32:AP32) -> 0 | AU32: =SUM(AR32:AT32) -> 0 | AY32: =SUM(AV32:AX32) -> 0 | BA32: =+G32+K32+O32+S32+W32+AA32+AE32+AZ32+AI32+AM32+AQ32+AU32+AY32 -> 0 | BD32: =+BB32+BC32-BA32 -> 0 | BF32: =BD32+BE32 -> 0
B33: 1111018 | C33: ชิฟฟ่อนเค้กสอดไส้แยม รสบลูเบอร์รี่ (6 ชิ้น) | G33: =SUM(D33:F33) -> 0 | K33: =SUM(H33:J33) -> 0 | O33: =SUM(L33:N33) -> 0 | S33: =SUM(P33:R33) -> 0 | W33: =SUM(T33:V33) -> 0 | AA33: =SUM(X33:Z33) -> 0 | AE33: =SUM(AB33:AD33) -> 0 | AI33: =SUM(AF33:AH33) -> 0 | AM33: =SUM(AJ33:AL33) -> 0 | AQ33: =SUM(AN33:AP33) -> 0 | AU33: =SUM(AR33:AT33) -> 0 | AY33: =SUM(AV33:AX33) -> 0 | BA33: =+G33+K33+O33+S33+W33+AA33+AE33+AZ33+AI33+AM33+AQ33+AU33+AY33 -> 0 | BD33: =+BB33+BC33-BA33 -> 0 | BF33: =BD33+BE33 -> 0
B34: 1111019 | C34: ชิฟฟ่อนเค้กหน้าฝอยทอง สอดไส้แยมส้ม (3 ชิ้น) | G34: =SUM(D34:F34) -> 0 | K34: =SUM(H34:J34) -> 0 | O34: =SUM(L34:N34) -> 0 | S34: =SUM(P34:R34) -> 0 | W34: =SUM(T34:V34) -> 0 | AA34: =SUM(X34:Z34) -> 0 | AE34: =SUM(AB34:AD34) -> 0 | AI34: =SUM(AF34:AH34) -> 0 | AM34: =SUM(AJ34:AL34) -> 0 | AQ34: =SUM(AN34:AP34) -> 0 | AU34: =SUM(AR34:AT34) -> 0 | AY34: =SUM(AV34:AX34) -> 0 | BA34: =+G34+K34+O34+S34+W34+AA34+AE34+AZ34+AI34+AM34+AQ34+AU34+AY34 -> 0 | BD34: =+BB34+BC34-BA34 -> 0 | BF34: =BD34+BE34 -> 0
B35: 1111020 | C35: ชิฟฟ่อนเค้กหน้าฝอยทอง สอดไส้แยมส้ม (6 ชิ้น) | G35: =SUM(D35:F35) -> 0 | K35: =SUM(H35:J35) -> 0 | O35: =SUM(L35:N35) -> 0 | S35: =SUM(P35:R35) -> 0 | W35: =SUM(T35:V35) -> 0 | AA35: =SUM(X35:Z35) -> 0 | AE35: =SUM(AB35:AD35) -> 0 | AI35: =SUM(AF35:AH35) -> 0 | AM35: =SUM(AJ35:AL35) -> 0 | AQ35: =SUM(AN35:AP35) -> 0 | AU35: =SUM(AR35:AT35) -> 0 | AY35: =SUM(AV35:AX35) -> 0 | BA35: =+G35+K35+O35+S35+W35+AA35+AE35+AZ35+AI35+AM35+AQ35+AU35+AY35 -> 0 | BD35: =+BB35+BC35-BA35 -> 0 | BF35: =BD35+BE35 -> 0
B36: 1111022 | C36: ชิฟฟ่อนเค้กสอดไส้แยม รสสตรอว์เบอร์รี (3 ชิ้น) | G36: =SUM(D36:F36) -> 0 | K36: =SUM(H36:J36) -> 0 | O36: =SUM(L36:N36) -> 0 | S36: =SUM(P36:R36) -> 0 | W36: =SUM(T36:V36) -> 0 | AA36: =SUM(X36:Z36) -> 0 | AE36: =SUM(AB36:AD36) -> 0 | AI36: =SUM(AF36:AH36) -> 0 | AM36: =SUM(AJ36:AL36) -> 0 | AQ36: =SUM(AN36:AP36) -> 0 | AU36: =SUM(AR36:AT36) -> 0 | AY36: =SUM(AV36:AX36) -> 0 | BA36: =+G36+K36+O36+S36+W36+AA36+AE36+AZ36+AI36+AM36+AQ36+AU36+AY36 -> 0 | BD36: =+BB36+BC36-BA36 -> 0 | BF36: =BD36+BE36 -> 0
B37: 1111023 | C37: ชิฟฟ่อนเค้กสอดไส้แยม รสสตรอว์เบอร์รี (6 ชิ้น) | G37: =SUM(D37:F37) -> 0 | K37: =SUM(H37:J37) -> 0 | O37: =SUM(L37:N37) -> 0 | S37: =SUM(P37:R37) -> 0 | W37: =SUM(T37:V37) -> 0 | AA37: =SUM(X37:Z37) -> 0 | AE37: =SUM(AB37:AD37) -> 0 | AI37: =SUM(AF37:AH37) -> 0 | AM37: =SUM(AJ37:AL37) -> 0 | AQ37: =SUM(AN37:AP37) -> 0 | AU37: =SUM(AR37:AT37) -> 0 | AY37: =SUM(AV37:AX37) -> 0 | BA37: =+G37+K37+O37+S37+W37+AA37+AE37+AZ37+AI37+AM37+AQ37+AU37+AY37 -> 0 | BD37: =+BB37+BC37-BA37 -> 0 | BF37: =BD37+BE37 -> 0
... B39: 1111025 | C39: ชิฟฟ่อนเค้กสอดไส้แยม รสส้ม (6 ชิ้น) | G39: =SUM(D39:F39) -> 0 | K39: =SUM(H39:J39) -> 0 | O39: =SUM(L39:N39) -> 0 | S39: =SUM(P39:R39) -> 0 | W39: =SUM(T39:V39) -> 0 | AA39: =SUM(X39:Z39) -> 0 | AE39: =SUM(AB39:AD39) -> 0 | AI39: =SUM(AF39:AH39) -> 0 | AM39: =SUM(AJ39:AL39) -> 0 | AQ39: =SUM(AN39:AP39) -> 0 | AU39: =SUM(AR39:AT39) -> 0 | AY39: =SUM(AV39:AX39) -> 0 | BA39: =+G39+K39+O39+S39+W39+AA39+AE39+AZ39+AI39+AM39+AQ39+AU39+AY39 -> 0 | BD39: =+BB39+BC39-BA39 -> 0 | BF39: =BD39+BE39 -> 0
B40: 1111056 | C40: ชิฟฟอนรวมรสยอดฮิต 8 ชิ้น | G40: =SUM(D40:F40) -> 0 | H40: 6 | I40: 3 | K40: =SUM(H40:J40) -> 9 | L40: 1 | O40: =SUM(L40:N40) -> 1 | P40: 2 | S40: =SUM(P40:R40) -> 2 | W40: =SUM(T40:V40) -> 0 | AA40: =SUM(X40:Z40) -> 0 | AE40: =SUM(AB40:AD40) -> 0 | AI40: =SUM(AF40:AH40) -> 0 | AM40: =SUM(AJ40:AL40) -> 0 | AQ40: =SUM(AN40:AP40) -> 0 | AU40: =SUM(AR40:AT40) -> 0 | AY40: =SUM(AV40:AX40) -> 0 | AZ40: 15 | BA40: =+G40+K40+O40+S40+W40+AA40+AE40+AZ40+AI40+AM40+AQ40+AU40+AY40 -> 27 | BB40: 25 | BC40: 7 | BD40: =+BB40+BC40-BA40 -> 5 | BE40: 10 | BF40: =BD40+BE40 -> 15
B41: 1111074 | C41: ชิฟฟอนไส้แยมแยกชิ้น มะพร้าว | G41: =SUM(D41:F41) -> 0 | K41: =SUM(H41:J41) -> 0 | O41: =SUM(L41:N41) -> 0 | S41: =SUM(P41:R41) -> 0 | W41: =SUM(T41:V41) -> 0 | AA41: =SUM(X41:Z41) -> 0 | AE41: =SUM(AB41:AD41) -> 0 | AI41: =SUM(AF41:AH41) -> 0 | AM41: =SUM(AJ41:AL41) -> 0 | AQ41: =SUM(AN41:AP41) -> 0 | AU41: =SUM(AR41:AT41) -> 0 | AY41: =SUM(AV41:AX41) -> 0 | BA41: =+G41+K41+O41+S41+W41+AA41+AE41+AZ41+AI41+AM41+AQ41+AU41+AY41 -> 0 | BD41: =+BB41+BC41-BA41 -> 0 | BF41: =BD41+BE41 -> 0
B42: 1111075 | C42: ชิฟฟอนไส้แยมแยกชิ้น สตอเบอรี่ | G42: =SUM(D42:F42) -> 0 | K42: =SUM(H42:J42) -> 0 | O42: =SUM(L42:N42) -> 0 | S42: =SUM(P42:R42) -> 0 | W42: =SUM(T42:V42) -> 0 | AA42: =SUM(X42:Z42) -> 0 | AE42: =SUM(AB42:AD42) -> 0 | AI42: =SUM(AF42:AH42) -> 0 | AM42: =SUM(AJ42:AL42) -> 0 | AQ42: =SUM(AN42:AP42) -> 0 | AU42: =SUM(AR42:AT42) -> 0 | AY42: =SUM(AV42:AX42) -> 0 | BA42: =+G42+K42+O42+S42+W42+AA42+AE42+AZ42+AI42+AM42+AQ42+AU42+AY42 -> 0 | BD42: =+BB42+BC42-BA42 -> 0 | BF42: =BD42+BE42 -> 0
B43: 1111076 | C43: ชิฟฟอนไส้แยมแยกชิ้น ส้ม | G43: =SUM(D43:F43) -> 0 | K43: =SUM(H43:J43) -> 0 | O43: =SUM(L43:N43) -> 0 | S43: =SUM(P43:R43) -> 0 | W43: =SUM(T43:V43) -> 0 | AA43: =SUM(X43:Z43) -> 0 | AE43: =SUM(AB43:AD43) -> 0 | AI43: =SUM(AF43:AH43) -> 0 | AM43: =SUM(AJ43:AL43) -> 0 | AQ43: =SUM(AN43:AP43) -> 0 | AU43: =SUM(AR43:AT43) -> 0 | AY43: =SUM(AV43:AX43) -> 0 | BA43: =+G43+K43+O43+S43+W43+AA43+AE43+AZ43+AI43+AM43+AQ43+AU43+AY43 -> 0 | BD43: =+BB43+BC43-BA43 -> 0 | BF43: =BD43+BE43 -> 0
B44: 1111077 | C44: ชิฟฟอนไส้แยมแยกชิ้น บลูเบอรี่ | G44: =SUM(D44:F44) -> 0 | K44: =SUM(H44:J44) -> 0 | O44: =SUM(L44:N44) -> 0 | S44: =SUM(P44:R44) -> 0 | W44: =SUM(T44:V44) -> 0 | AA44: =SUM(X44:Z44) -> 0 | AE44: =SUM(AB44:AD44) -> 0 | AI44: =SUM(AF44:AH44) -> 0 | AM44: =SUM(AJ44:AL44) -> 0 | AQ44: =SUM(AN44:AP44) -> 0 | AU44: =SUM(AR44:AT44) -> 0 | AY44: =SUM(AV44:AX44) -> 0 | BA44: =+G44+K44+O44+S44+W44+AA44+AE44+AZ44+AI44+AM44+AQ44+AU44+AY44 -> 0 | BD44: =+BB44+BC44-BA44 -> 0 | BF44: =BD44+BE44 -> 0
B45: 1111078 | C45: ชิฟฟอนไส้แยมแยกชิ้น นมชมพู | G45: =SUM(D45:F45) -> 0 | K45: =SUM(H45:J45) -> 0 | O45: =SUM(L45:N45) -> 0 | S45: =SUM(P45:R45) -> 0 | W45: =SUM(T45:V45) -> 0 | AA45: =SUM(X45:Z45) -> 0 | AE45: =SUM(AB45:AD45) -> 0 | AI45: =SUM(AF45:AH45) -> 0 | AM45: =SUM(AJ45:AL45) -> 0 | AQ45: =SUM(AN45:AP45) -> 0 | AU45: =SUM(AR45:AT45) -> 0 | AY45: =SUM(AV45:AX45) -> 0 | BA45: =+G45+K45+O45+S45+W45+AA45+AE45+AZ45+AI45+AM45+AQ45+AU45+AY45 -> 0 | BD45: =+BB45+BC45-BA45 -> 0 | BF45: =BD45+BE45 -> 0
...

Sheet 02.4.68
B1: ยอดจริง ออนไลน์ วันที่ 2/4/2569
B2: รหัสสินค้า | C2: สินค้า | D2: ปณ | H2: ชอปปี้ | L2: ลาซาด้า | P2: ติ๊กตอก | T2: ติ๊กตอก2 | X2: ติ๊กตอก3 | AB2: ติ๊กตอก4 | AF2: ติ๊กตอก5 | AJ2: ติ๊กตอก6 | AN2: ติ๊กตอก7 | AR2: ติ๊กตอก8 | AV2: ติ๊กตอก9 | AZ2: ยอดเส้น | BA2: ยอดรวมผลิต(กล่อง) | BB2: ยอดForcast | BC2: ยอดStock | BD2: ยอดMemo | BE2: ยอดForcastวันพรุ่งนี้ | BF2: สินค้าที่ขายได้
D3: เช้า | E3: บ่าย | F3: เย็น | G3: รวม | H3: เช้า | I3: บ่าย | J3: เย็น | K3: รวม | L3: เช้า | M3: บ่าย | N3: เย็น | O3: รวม | P3: เช้า | Q3: บ่าย | R3: เย็น | S3: รวม | T3: เช้า | U3: บ่าย | V3: เย็น | W3: รวม | X3: เช้า | Y3: บ่าย | Z3: เย็น | AA3: รวม | AB3: เช้า | AC3: บ่าย | AD3: เย็น | AE3: รวม | AF3: เช้า | AG3: บ่าย | AH3: เย็น | AI3: รวม | AJ3: เช้า | AK3: บ่าย | AL3: เย็น | AM3: รวม | AN3: เช้า | AO3: บ่าย | AP3: เย็น | AQ3: รวม | AR3: เช้า | AS3: บ่าย | AT3: เย็น | AU3: รวม | AV3: เช้า | AW3: บ่าย | AX3: เย็น | AY3: รวม
B4: 1004055 | C4: ชิฟฟ่อนเค้ก วรรณวนัช (รวมรส 4 ชิ้น) | G4: =SUM(D4:F4) -> 0 | K4: =SUM(H4:J4) -> 0 | O4: =SUM(L4:N4) -> 0 | S4: =SUM(P4:R4) -> 0 | W4: =SUM(T4:V4) -> 0 | AA4: =SUM(X4:Z4) -> 0 | AE4: =SUM(AB4:AD4) -> 0 | AI4: =SUM(AF4:AH4) -> 0 | AM4: =SUM(AJ4:AL4) -> 0 | AQ4: =SUM(AN4:AP4) -> 0 | AU4: =SUM(AR4:AT4) -> 0 | AY4: =SUM(AV4:AX4) -> 0 | BA4: =+G4+K4+O4+S4+W4+AA4+AE4+AZ4+AI4+AM4+AQ4+AU4+AY4 -> 0 | BD4: =+BB4+BC4-BA4 -> 0 | BE4: 30 | BF4: =BD4+BE4 -> 30
B5: 1111002 | C5: ชิฟฟ่อนเค้ก วรรณวนัช (รวมรส 8 ชิ้น) | D5: 5 | G5: =SUM(D5:F5) -> 5 | H5: 45 | I5: 50 | K5: =SUM(H5:J5) -> 95 | L5: 2 | O5: =SUM(L5:N5) -> 2 | P5: 6 | Q5: 3 | S5: =SUM(P5:R5) -> 9 | W5: =SUM(T5:V5) -> 0 | AA5: =SUM(X5:Z5) -> 0 | AE5: =SUM(AB5:AD5) -> 0 | AI5: =SUM(AF5:AH5) -> 0 | AM5: =SUM(AJ5:AL5) -> 0 | AQ5: =SUM(AN5:AP5) -> 0 | AU5: =SUM(AR5:AT5) -> 0 | AY5: =SUM(AV5:AX5) -> 0 | BA5: =+G5+K5+O5+S5+W5+AA5+AE5+AZ5+AI5+AM5+AQ5+AU5+AY5 -> 111 | BB5: 50 | BC5: 190 | BD5: =+BB5+BC5-BA5 -> 129 | BE5: 85 | BF5: =BD5+BE5 -> 214
B6: 1111001 | C6: ชิฟฟ่อนแยกชิ้นไม่มีไส้ คละรส | G6: =SUM(D6:F6) -> 0 | H6: 50 | I6: 20 | K6: =SUM(H6:J6) -> 70 | O6: =SUM(L6:N6) -> 0 | P6: 20 | S6: =SUM(P6:R6) -> 20 | W6: =SUM(T6:V6) -> 0 | AA6: =SUM(X6:Z6) -> 0 | AE6: =SUM(AB6:AD6) -> 0 | AI6: =SUM(AF6:AH6) -> 0 | AM6: =SUM(AJ6:AL6) -> 0 | AQ6: =SUM(AN6:AP6) -> 0 | AU6: =SUM(AR6:AT6) -> 0 | AY6: =SUM(AV6:AX6) -> 0 | BA6: =+G6+K6+O6+S6+W6+AA6+AE6+AZ6+AI6+AM6+AQ6+AU6+AY6 -> 90 | BD6: =+BB6+BC6-BA6 -> -90 | BF6: =BD6+BE6 -> -90
B7: 1111043 | C7: ชิฟฟอนรสมะลิ 8 ชิ้น ห่อ ซีน | G7: =SUM(D7:F7) -> 0 | K7: =SUM(H7:J7) -> 0 | O7: =SUM(L7:N7) -> 0 | S7: =SUM(P7:R7) -> 0 | W7: =SUM(T7:V7) -> 0 | AA7: =SUM(X7:Z7) -> 0 | AE7: =SUM(AB7:AD7) -> 0 | AI7: =SUM(AF7:AH7) -> 0 | AM7: =SUM(AJ7:AL7) -> 0 | AQ7: =SUM(AN7:AP7) -> 0 | AU7: =SUM(AR7:AT7) -> 0 | AY7: =SUM(AV7:AX7) -> 0 | BA7: =+G7+K7+O7+S7+W7+AA7+AE7+AZ7+AI7+AM7+AQ7+AU7+AY7 -> 0 | BD7: =+BB7+BC7-BA7 -> 0 | BF7: =BD7+BE7 -> 0
B8: 1111057 | C8: ชิฟฟอนแยกชิ้น กาแฟ | G8: =SUM(D8:F8) -> 0 | K8: =SUM(H8:J8) -> 0 | O8: =SUM(L8:N8) -> 0 | S8: =SUM(P8:R8) -> 0 | W8: =SUM(T8:V8) -> 0 | AA8: =SUM(X8:Z8) -> 0 | AE8: =SUM(AB8:AD8) -> 0 | AI8: =SUM(AF8:AH8) -> 0 | AM8: =SUM(AJ8:AL8) -> 0 | AQ8: =SUM(AN8:AP8) -> 0 | AU8: =SUM(AR8:AT8) -> 0 | AY8: =SUM(AV8:AX8) -> 0 | BA8: =+G8+K8+O8+S8+W8+AA8+AE8+AZ8+AI8+AM8+AQ8+AU8+AY8 -> 0 | BD8: =+BB8+BC8-BA8 -> 0 | BF8: =BD8+BE8 -> 0
B9: 1111058 | C9: ชิฟฟอนแยกชิ้น ชาเขียว | G9: =SUM(D9:F9) -> 0 | K9: =SUM(H9:J9) -> 0 | O9: =SUM(L9:N9) -> 0 | S9: =SUM(P9:R9) -> 0 | W9: =SUM(T9:V9) -> 0 | AA9: =SUM(X9:Z9) -> 0 | AE9: =SUM(AB9:AD9) -> 0 | AI9: =SUM(AF9:AH9) -> 0 | AM9: =SUM(AJ9:AL9) -> 0 | AQ9: =SUM(AN9:AP9) -> 0 | AU9: =SUM(AR9:AT9) -> 0 | AY9: =SUM(AV9:AX9) -> 0 | BA9: =+G9+K9+O9+S9+W9+AA9+AE9+AZ9+AI9+AM9+AQ9+AU9+AY9 -> 0 | BD9: =+BB9+BC9-BA9 -> 0 | BF9: =BD9+BE9 -> 0
B10: 1111059 | C10: ชิฟฟอนแยกชิ้น ใบเตย | G10: =SUM(D10:F10) -> 0 | K10: =SUM(H10:J10) -> 0 | O10: =SUM(L10:N10) -> 0 | S10: =SUM(P10:R10) -> 0 | W10: =SUM(T10:V10) -> 0 | AA10: =SUM(X10:Z10) -> 0 | AE10: =SUM(AB10:AD10) -> 0 | AI10: =SUM(AF10:AH10) -> 0 | AM10: =SUM(AJ10:AL10) -> 0 | AQ10: =SUM(AN10:AP10) -> 0 | AU10: =SUM(AR10:AT10) -> 0 | AY10: =SUM(AV10:AX10) -> 0 | BA10: =+G10+K10+O10+S10+W10+AA10+AE10+AZ10+AI10+AM10+AQ10+AU10+AY10 -> 0 | BD10: =+BB10+BC10-BA10 -> 0 | BF10: =BD10+BE10 -> 0
B11: 1111060 | C11: ชิฟฟอนแยกชิ้น กล้วยหอม | G11: =SUM(D11:F11) -> 0 | K11: =SUM(H11:J11) -> 0 | O11: =SUM(L11:N11) -> 0 | S11: =SUM(P11:R11) -> 0 | W11: =SUM(T11:V11) -> 0 | AA11: =SUM(X11:Z11) -> 0 | AE11: =SUM(AB11:AD11) -> 0 | AI11: =SUM(AF11:AH11) -> 0 | AM11: =SUM(AJ11:AL11) -> 0 | AQ11: =SUM(AN11:AP11) -> 0 | AU11: =SUM(AR11:AT11) -> 0 | AY11: =SUM(AV11:AX11) -> 0 | BA11: =+G11+K11+O11+S11+W11+AA11+AE11+AZ11+AI11+AM11+AQ11+AU11+AY11 -> 0 | BD11: =+BB11+BC11-BA11 -> 0 | BF11: =BD11+BE11 -> 0
B12: 1111061 | C12: ชิฟฟอนแยกชิ้น ชาไทย | G12: =SUM(D12:F12) -> 0 | K12: =SUM(H12:J12) -> 0 | O12: =SUM(L12:N12) -> 0 | S12: =SUM(P12:R12) -> 0 | W12: =SUM(T12:V12) -> 0 | AA12: =SUM(X12:Z12) -> 0 | AE12: =SUM(AB12:AD12) -> 0 | AI12: =SUM(AF12:AH12) -> 0 | AM12: =SUM(AJ12:AL12) -> 0 | AQ12: =SUM(AN12:AP12) -> 0 | AU12: =SUM(AR12:AT12) -> 0 | AY12: =SUM(AV12:AX12) -> 0 | BA12: =+G12+K12+O12+S12+W12+AA12+AE12+AZ12+AI12+AM12+AQ12+AU12+AY12 -> 0 | BD12: =+BB12+BC12-BA12 -> 0 | BF12: =BD12+BE12 -> 0
B13: 1111062 | C13: ชิฟฟอนแยกชิ้น โกโก้ | G13: =SUM(D13:F13) -> 0 | K13: =SUM(H13:J13) -> 0 | O13: =SUM(L13:N13) -> 0 | S13: =SUM(P13:R13) -> 0 | W13: =SUM(T13:V13) -> 0 | AA13: =SUM(X13:Z13) -> 0 | AE13: =SUM(AB13:AD13) -> 0 | AI13: =SUM(AF13:AH13) -> 0 | AM13: =SUM(AJ13:AL13) -> 0 | AQ13: =SUM(AN13:AP13) -> 0 | AU13: =SUM(AR13:AT13) -> 0 | AY13: =SUM(AV13:AX13) -> 0 | BA13: =+G13+K13+O13+S13+W13+AA13+AE13+AZ13+AI13+AM13+AQ13+AU13+AY13 -> 0 | BD13: =+BB13+BC13-BA13 -> 0 | BF13: =BD13+BE13 -> 0
B14: 1111063 | C14: ชิฟฟอนแยกชิ้น ส้ม | G14: =SUM(D14:F14) -> 0 | K14: =SUM(H14:J14) -> 0 | O14: =SUM(L14:N14) -> 0 | S14: =SUM(P14:R14) -> 0 | W14: =SUM(T14:V14) -> 0 | AA14: =SUM(X14:Z14) -> 0 | AE14: =SUM(AB14:AD14) -> 0 | AI14: =SUM(AF14:AH14) -> 0 | AM14: =SUM(AJ14:AL14) -> 0 | AQ14: =SUM(AN14:AP14) -> 0 | AU14: =SUM(AR14:AT14) -> 0 | AY14: =SUM(AV14:AX14) -> 0 | BA14: =+G14+K14+O14+S14+W14+AA14+AE14+AZ14+AI14+AM14+AQ14+AU14+AY14 -> 0 | BD14: =+BB14+BC14-BA14 -> 0 | BF14: =BD14+BE14 -> 0
B15: 1111064 | C15: ชิฟฟอนแยกชิ้น เผือก | G15: =SUM(D15:F15) -> 0 | K15: =SUM(H15:J15) -> 0 | O15: =SUM(L15:N15) -> 0 | S15: =SUM(P15:R15) -> 0 | W15: =SUM(T15:V15) -> 0 | AA15: =SUM(X15:Z15) -> 0 | AE15: =SUM(AB15:AD15) -> 0 | AI15: =SUM(AF15:AH15) -> 0 | AM15: =SUM(AJ15:AL15) -> 0 | AQ15: =SUM(AN15:AP15) -> 0 | AU15: =SUM(AR15:AT15) -> 0 | AY15: =SUM(AV15:AX15) -> 0 | BA15: =+G15+K15+O15+S15+W15+AA15+AE15+AZ15+AI15+AM15+AQ15+AU15+AY15 -> 0 | BD15: =+BB15+BC15-BA15 -> 0 | BF15: =BD15+BE15 -> 0
B16: 1111065 | C16: ชิฟฟอนแยกชิ้น สับปะรด | G16: =SUM(D16:F16) -> 0 | K16: =SUM(H16:J16) -> 0 | O16: =SUM(L16:N16) -> 0 | S16: =SUM(P16:R16) -> 0 | W16: =SUM(T16:V16) -> 0 | AA16: =SUM(X16:Z16) -> 0 | AE16: =SUM(AB16:AD16) -> 0 | AI16: =SUM(AF16:AH16) -> 0 | AM16: =SUM(AJ16:AL16) -> 0 | AQ16: =SUM(AN16:AP16) -> 0 | AU16: =SUM(AR16:AT16) -> 0 | AY16: =SUM(AV16:AX16) -> 0 | BA16: =+G16+K16+O16+S16+W16+AA16+AE16+AZ16+AI16+AM16+AQ16+AU16+AY16 -> 0 | BD16: =+BB16+BC16-BA16 -> 0 | BF16: =BD16+BE16 -> 0
B17: 1111066 | C17: ชิฟฟอนแยกชิ้น สตอเบอรี่ | G17: =SUM(D17:F17) -> 0 | K17: =SUM(H17:J17) -> 0 | O17: =SUM(L17:N17) -> 0 | S17: =SUM(P17:R17) -> 0 | W17: =SUM(T17:V17) -> 0 | AA17: =SUM(X17:Z17) -> 0 | AE17: =SUM(AB17:AD17) -> 0 | AI17: =SUM(AF17:AH17) -> 0 | AM17: =SUM(AJ17:AL17) -> 0 | AQ17: =SUM(AN17:AP17) -> 0 | AU17: =SUM(AR17:AT17) -> 0 | AY17: =SUM(AV17:AX17) -> 0 | BA17: =+G17+K17+O17+S17+W17+AA17+AE17+AZ17+AI17+AM17+AQ17+AU17+AY17 -> 0 | BD17: =+BB17+BC17-BA17 -> 0 | BF17: =BD17+BE17 -> 0
B18: 1111067 | C18: ชิฟฟอนแยกชิ้น มะพร้าว | G18: =SUM(D18:F18) -> 0 | K18: =SUM(H18:J18) -> 0 | O18: =SUM(L18:N18) -> 0 | S18: =SUM(P18:R18) -> 0 | W18: =SUM(T18:V18) -> 0 | AA18: =SUM(X18:Z18) -> 0 | AE18: =SUM(AB18:AD18) -> 0 | AI18: =SUM(AF18:AH18) -> 0 | AM18: =SUM(AJ18:AL18) -> 0 | AQ18: =SUM(AN18:AP18) -> 0 | AU18: =SUM(AR18:AT18) -> 0 | AY18: =SUM(AV18:AX18) -> 0 | BA18: =+G18+K18+O18+S18+W18+AA18+AE18+AZ18+AI18+AM18+AQ18+AU18+AY18 -> 0 | BD18: =+BB18+BC18-BA18 -> 0 | BF18: =BD18+BE18 -> 0
... B23: 1111010 | C23: ชิฟฟ่อนเค้กสอดไส้แยม (1 ชิ้น) | G23: =SUM(D23:F23) -> 0 | K23: =SUM(H23:J23) -> 0 | O23: =SUM(L23:N23) -> 0 | S23: =SUM(P23:R23) -> 0 | W23: =SUM(T23:V23) -> 0 | AA23: =SUM(X23:Z23) -> 0 | AE23: =SUM(AB23:AD23) -> 0 | AI23: =SUM(AF23:AH23) -> 0 | AM23: =SUM(AJ23:AL23) -> 0 | AQ23: =SUM(AN23:AP23) -> 0 | AU23: =SUM(AR23:AT23) -> 0 | AY23: =SUM(AV23:AX23) -> 0 | BA23: =+G23+K23+O23+S23+W23+AA23+AE23+AZ23+AI23+AM23+AQ23+AU23+AY23 -> 0 | BD23: =+BB23+BC23-BA23 -> 0 | BF23: =BD23+BE23 -> 0
B24: 1111008 | C24: ชิฟฟ่อนเค้ก สอดไส้ (รวมรส 3 ชิ้น) | G24: =SUM(D24:F24) -> 0 | H24: 9 | K24: =SUM(H24:J24) -> 9 | O24: =SUM(L24:N24) -> 0 | P24: 97 | S24: =SUM(P24:R24) -> 97 | W24: =SUM(T24:V24) -> 0 | AA24: =SUM(X24:Z24) -> 0 | AE24: =SUM(AB24:AD24) -> 0 | AI24: =SUM(AF24:AH24) -> 0 | AM24: =SUM(AJ24:AL24) -> 0 | AQ24: =SUM(AN24:AP24) -> 0 | AU24: =SUM(AR24:AT24) -> 0 | AY24: =SUM(AV24:AX24) -> 0 | BA24: =+G24+K24+O24+S24+W24+AA24+AE24+AZ24+AI24+AM24+AQ24+AU24+AY24 -> 106 | BB24: 70 | BD24: =+BB24+BC24-BA24 -> -36 | BE24: 117 | BF24: =BD24+BE24 -> 81
B25: 1111009 | C25: ชิฟฟ่อนเค้ก สอดไส้ (รวมรส 6 ชิ้น) | G25: =SUM(D25:F25) -> 0 | H25: 10 | K25: =SUM(H25:J25) -> 10 | O25: =SUM(L25:N25) -> 0 | P25: 1 | S25: =SUM(P25:R25) -> 1 | W25: =SUM(T25:V25) -> 0 | AA25: =SUM(X25:Z25) -> 0 | AE25: =SUM(AB25:AD25) -> 0 | AI25: =SUM(AF25:AH25) -> 0 | AM25: =SUM(AJ25:AL25) -> 0 | AQ25: =SUM(AN25:AP25) -> 0 | AU25: =SUM(AR25:AT25) -> 0 | AY25: =SUM(AV25:AX25) -> 0 | BA25: =+G25+K25+O25+S25+W25+AA25+AE25+AZ25+AI25+AM25+AQ25+AU25+AY25 -> 11 | BB25: 10 | BC25: 8 | BD25: =+BB25+BC25-BA25 -> 7 | BE25: 22 | BF25: =BD25+BE25 -> 29
B26: 1111011 | C26: ชิฟฟ่อนเค้กสอดไส้ นมชมพูฮอกไกโด (3 ชิ้น) | G26: =SUM(D26:F26) -> 0 | K26: =SUM(H26:J26) -> 0 | O26: =SUM(L26:N26) -> 0 | S26: =SUM(P26:R26) -> 0 | W26: =SUM(T26:V26) -> 0 | AA26: =SUM(X26:Z26) -> 0 | AE26: =SUM(AB26:AD26) -> 0 | AI26: =SUM(AF26:AH26) -> 0 | AM26: =SUM(AJ26:AL26) -> 0 | AQ26: =SUM(AN26:AP26) -> 0 | AU26: =SUM(AR26:AT26) -> 0 | AY26: =SUM(AV26:AX26) -> 0 | BA26: =+G26+K26+O26+S26+W26+AA26+AE26+AZ26+AI26+AM26+AQ26+AU26+AY26 -> 0 | BD26: =+BB26+BC26-BA26 -> 0 | BF26: =BD26+BE26 -> 0
B27: 1111012 | C27: ชิฟฟ่อนเค้กสอดไส้ นมชมพูฮอกไกโด (6 ชิ้น) | G27: =SUM(D27:F27) -> 0 | K27: =SUM(H27:J27) -> 0 | O27: =SUM(L27:N27) -> 0 | S27: =SUM(P27:R27) -> 0 | W27: =SUM(T27:V27) -> 0 | AA27: =SUM(X27:Z27) -> 0 | AE27: =SUM(AB27:AD27) -> 0 | AI27: =SUM(AF27:AH27) -> 0 | AM27: =SUM(AJ27:AL27) -> 0 | AQ27: =SUM(AN27:AP27) -> 0 | AU27: =SUM(AR27:AT27) -> 0 | AY27: =SUM(AV27:AX27) -> 0 | BA27: =+G27+K27+O27+S27+W27+AA27+AE27+AZ27+AI27+AM27+AQ27+AU27+AY27 -> 0 | BD27: =+BB27+BC27-BA27 -> 0 | BF27: =BD27+BE27 -> 0
B28: 1111013 | C28: ชิฟฟ่อนเค้กสอดไส้ ช็อคโกแลตนูเทลล่า (3 ชิ้น) | G28: =SUM(D28:F28) -> 0 | K28: =SUM(H28:J28) -> 0 | O28: =SUM(L28:N28) -> 0 | S28: =SUM(P28:R28) -> 0 | W28: =SUM(T28:V28) -> 0 | AA28: =SUM(X28:Z28) -> 0 | AE28: =SUM(AB28:AD28) -> 0 | AI28: =SUM(AF28:AH28) -> 0 | AM28: =SUM(AJ28:AL28) -> 0 | AQ28: =SUM(AN28:AP28) -> 0 | AU28: =SUM(AR28:AT28) -> 0 | AY28: =SUM(AV28:AX28) -> 0 | BA28: =+G28+K28+O28+S28+W28+AA28+AE28+AZ28+AI28+AM28+AQ28+AU28+AY28 -> 0 | BD28: =+BB28+BC28-BA28 -> 0 | BF28: =BD28+BE28 -> 0
B29: 1111014 | C29: ชิฟฟ่อนเค้กสอดไส้ ช็อคโกแลตนูเทลล่า (6 ชิ้น) | G29: =SUM(D29:F29) -> 0 | K29: =SUM(H29:J29) -> 0 | O29: =SUM(L29:N29) -> 0 | S29: =SUM(P29:R29) -> 0 | W29: =SUM(T29:V29) -> 0 | AA29: =SUM(X29:Z29) -> 0 | AE29: =SUM(AB29:AD29) -> 0 | AI29: =SUM(AF29:AH29) -> 0 | AM29: =SUM(AJ29:AL29) -> 0 | AQ29: =SUM(AN29:AP29) -> 0 | AU29: =SUM(AR29:AT29) -> 0 | AY29: =SUM(AV29:AX29) -> 0 | BA29: =+G29+K29+O29+S29+W29+AA29+AE29+AZ29+AI29+AM29+AQ29+AU29+AY29 -> 0 | BD29: =+BB29+BC29-BA29 -> 0 | BF29: =BD29+BE29 -> 0
B30: 1111015 | C30: ชิฟฟ่อนเค้กสอดไส้เนย รสมะพร้าว (3 ชิ้น) | G30: =SUM(D30:F30) -> 0 | K30: =SUM(H30:J30) -> 0 | O30: =SUM(L30:N30) -> 0 | S30: =SUM(P30:R30) -> 0 | W30: =SUM(T30:V30) -> 0 | AA30: =SUM(X30:Z30) -> 0 | AE30: =SUM(AB30:AD30) -> 0 | AI30: =SUM(AF30:AH30) -> 0 | AM30: =SUM(AJ30:AL30) -> 0 | AQ30: =SUM(AN30:AP30) -> 0 | AU30: =SUM(AR30:AT30) -> 0 | AY30: =SUM(AV30:AX30) -> 0 | BA30: =+G30+K30+O30+S30+W30+AA30+AE30+AZ30+AI30+AM30+AQ30+AU30+AY30 -> 0 | BD30: =+BB30+BC30-BA30 -> 0 | BF30: =BD30+BE30 -> 0
B31: 1111016 | C31: ชิฟฟ่อนเค้กสอดไส้เนย รสมะพร้าว (6 ชิ้น) | G31: =SUM(D31:F31) -> 0 | K31: =SUM(H31:J31) -> 0 | O31: =SUM(L31:N31) -> 0 | S31: =SUM(P31:R31) -> 0 | W31: =SUM(T31:V31) -> 0 | AA31: =SUM(X31:Z31) -> 0 | AE31: =SUM(AB31:AD31) -> 0 | AI31: =SUM(AF31:AH31) -> 0 | AM31: =SUM(AJ31:AL31) -> 0 | AQ31: =SUM(AN31:AP31) -> 0 | AU31: =SUM(AR31:AT31) -> 0 | AY31: =SUM(AV31:AX31) -> 0 | BA31: =+G31+K31+O31+S31+W31+AA31+AE31+AZ31+AI31+AM31+AQ31+AU31+AY31 -> 0 | BD31: =+BB31+BC31-BA31 -> 0 | BF31: =BD31+BE31 -> 0
B32: 1111017 | C32: ชิฟฟ่อนเค้กสอดไส้แยม รสบลูเบอร์รี่ (3 ชิ้น) | G32: =SUM(D32:F32) -> 0 | K32: =SUM(H32:J32) -> 0 | O32: =SUM(L32:N32) -> 0 | S32: =SUM(P32:R32) -> 0 | W32: =SUM(T32:V32) -> 0 | AA32: =SUM(X32:Z32) -> 0 | AE32: =SUM(AB32:AD32) -> 0 | AI32: =SUM(AF32:AH32) -> 0 | AM32: =SUM(AJ32:AL32) -> 0 | AQ32: =SUM(AN32:AP32) -> 0 | AU32: =SUM(AR32:AT32) -> 0 | AY32: =SUM(AV32:AX32) -> 0 | BA32: =+G32+K32+O32+S32+W32+AA32+AE32+AZ32+AI32+AM32+AQ32+AU32+AY32 -> 0 | BD32: =+BB32+BC32-BA32 -> 0 | BF32: =BD32+BE32 -> 0
B33: 1111018 | C33: ชิฟฟ่อนเค้กสอดไส้แยม รสบลูเบอร์รี่ (6 ชิ้น) | G33: =SUM(D33:F33) -> 0 | K33: =SUM(H33:J33) -> 0 | O33: =SUM(L33:N33) -> 0 | S33: =SUM(P33:R33) -> 0 | W33: =SUM(T33:V33) -> 0 | AA33: =SUM(X33:Z33) -> 0 | AE33: =SUM(AB33:AD33) -> 0 | AI33: =SUM(AF33:AH33) -> 0 | AM33: =SUM(AJ33:AL33) -> 0 | AQ33: =SUM(AN33:AP33) -> 0 | AU33: =SUM(AR33:AT33) -> 0 | AY33: =SUM(AV33:AX33) -> 0 | BA33: =+G33+K33+O33+S33+W33+AA33+AE33+AZ33+AI33+AM33+AQ33+AU33+AY33 -> 0 | BD33: =+BB33+BC33-BA33 -> 0 | BF33: =BD33+BE33 -> 0
B34: 1111019 | C34: ชิฟฟ่อนเค้กหน้าฝอยทอง สอดไส้แยมส้ม (3 ชิ้น) | G34: =SUM(D34:F34) -> 0 | K34: =SUM(H34:J34) -> 0 | O34: =SUM(L34:N34) -> 0 | S34: =SUM(P34:R34) -> 0 | W34: =SUM(T34:V34) -> 0 | AA34: =SUM(X34:Z34) -> 0 | AE34: =SUM(AB34:AD34) -> 0 | AI34: =SUM(AF34:AH34) -> 0 | AM34: =SUM(AJ34:AL34) -> 0 | AQ34: =SUM(AN34:AP34) -> 0 | AU34: =SUM(AR34:AT34) -> 0 | AY34: =SUM(AV34:AX34) -> 0 | BA34: =+G34+K34+O34+S34+W34+AA34+AE34+AZ34+AI34+AM34+AQ34+AU34+AY34 -> 0 | BD34: =+BB34+BC34-BA34 -> 0 | BF34: =BD34+BE34 -> 0
B35: 1111020 | C35: ชิฟฟ่อนเค้กหน้าฝอยทอง สอดไส้แยมส้ม (6 ชิ้น) | G35: =SUM(D35:F35) -> 0 | K35: =SUM(H35:J35) -> 0 | O35: =SUM(L35:N35) -> 0 | S35: =SUM(P35:R35) -> 0 | W35: =SUM(T35:V35) -> 0 | AA35: =SUM(X35:Z35) -> 0 | AE35: =SUM(AB35:AD35) -> 0 | AI35: =SUM(AF35:AH35) -> 0 | AM35: =SUM(AJ35:AL35) -> 0 | AQ35: =SUM(AN35:AP35) -> 0 | AU35: =SUM(AR35:AT35) -> 0 | AY35: =SUM(AV35:AX35) -> 0 | BA35: =+G35+K35+O35+S35+W35+AA35+AE35+AZ35+AI35+AM35+AQ35+AU35+AY35 -> 0 | BD35: =+BB35+BC35-BA35 -> 0 | BF35: =BD35+BE35 -> 0
B36: 1111022 | C36: ชิฟฟ่อนเค้กสอดไส้แยม รสสตรอว์เบอร์รี (3 ชิ้น) | G36: =SUM(D36:F36) -> 0 | K36: =SUM(H36:J36) -> 0 | O36: =SUM(L36:N36) -> 0 | S36: =SUM(P36:R36) -> 0 | W36: =SUM(T36:V36) -> 0 | AA36: =SUM(X36:Z36) -> 0 | AE36: =SUM(AB36:AD36) -> 0 | AI36: =SUM(AF36:AH36) -> 0 | AM36: =SUM(AJ36:AL36) -> 0 | AQ36: =SUM(AN36:AP36) -> 0 | AU36: =SUM(AR36:AT36) -> 0 | AY36: =SUM(AV36:AX36) -> 0 | BA36: =+G36+K36+O36+S36+W36+AA36+AE36+AZ36+AI36+AM36+AQ36+AU36+AY36 -> 0 | BD36: =+BB36+BC36-BA36 -> 0 | BF36: =BD36+BE36 -> 0
B37: 1111023 | C37: ชิฟฟ่อนเค้กสอดไส้แยม รสสตรอว์เบอร์รี (6 ชิ้น) | G37: =SUM(D37:F37) -> 0 | K37: =SUM(H37:J37) -> 0 | O37: =SUM(L37:N37) -> 0 | S37: =SUM(P37:R37) -> 0 | W37: =SUM(T37:V37) -> 0 | AA37: =SUM(X37:Z37) -> 0 | AE37: =SUM(AB37:AD37) -> 0 | AI37: =SUM(AF37:AH37) -> 0 | AM37: =SUM(AJ37:AL37) -> 0 | AQ37: =SUM(AN37:AP37) -> 0 | AU37: =SUM(AR37:AT37) -> 0 | AY37: =SUM(AV37:AX37) -> 0 | BA37: =+G37+K37+O37+S37+W37+AA37+AE37+AZ37+AI37+AM37+AQ37+AU37+AY37 -> 0 | BD37: =+BB37+BC37-BA37 -> 0 | BF37: =BD37+BE37 -> 0
... B39: 1111025 | C39: ชิฟฟ่อนเค้กสอดไส้แยม รสส้ม (6 ชิ้น) | G39: =SUM(D39:F39) -> 0 | K39: =SUM(H39:J39) -> 0 | O39: =SUM(L39:N39) -> 0 | S39: =SUM(P39:R39) -> 0 | W39: =SUM(T39:V39) -> 0 | AA39: =SUM(X39:Z39) -> 0 | AE39: =SUM(AB39:AD39) -> 0 | AI39: =SUM(AF39:AH39) -> 0 | AM39: =SUM(AJ39:AL39) -> 0 | AQ39: =SUM(AN39:AP39) -> 0 | AU39: =SUM(AR39:AT39) -> 0 | AY39: =SUM(AV39:AX39) -> 0 | BA39: =+G39+K39+O39+S39+W39+AA39+AE39+AZ39+AI39+AM39+AQ39+AU39+AY39 -> 0 | BD39: =+BB39+BC39-BA39 -> 0 | BF39: =BD39+BE39 -> 0
B40: 1111056 | C40: ชิฟฟอนรวมรสยอดฮิต 8 ชิ้น | G40: =SUM(D40:F40) -> 0 | H40: 7 | K40: =SUM(H40:J40) -> 7 | O40: =SUM(L40:N40) -> 0 | P40: 2 | Q40: 5 | S40: =SUM(P40:R40) -> 7 | W40: =SUM(T40:V40) -> 0 | AA40: =SUM(X40:Z40) -> 0 | AE40: =SUM(AB40:AD40) -> 0 | AI40: =SUM(AF40:AH40) -> 0 | AM40: =SUM(AJ40:AL40) -> 0 | AQ40: =SUM(AN40:AP40) -> 0 | AU40: =SUM(AR40:AT40) -> 0 | AY40: =SUM(AV40:AX40) -> 0 | BA40: =+G40+K40+O40+S40+W40+AA40+AE40+AZ40+AI40+AM40+AQ40+AU40+AY40 -> 14 | BB40: 10 | BC40: 5 | BD40: =+BB40+BC40-BA40 -> 1 | BE40: 22 | BF40: =BD40+BE40 -> 23
B41: 1111074 | C41: ชิฟฟอนไส้แยมแยกชิ้น มะพร้าว | G41: =SUM(D41:F41) -> 0 | K41: =SUM(H41:J41) -> 0 | O41: =SUM(L41:N41) -> 0 | S41: =SUM(P41:R41) -> 0 | W41: =SUM(T41:V41) -> 0 | AA41: =SUM(X41:Z41) -> 0 | AE41: =SUM(AB41:AD41) -> 0 | AI41: =SUM(AF41:AH41) -> 0 | AM41: =SUM(AJ41:AL41) -> 0 | AQ41: =SUM(AN41:AP41) -> 0 | AU41: =SUM(AR41:AT41) -> 0 | AY41: =SUM(AV41:AX41) -> 0 | BA41: =+G41+K41+O41+S41+W41+AA41+AE41+AZ41+AI41+AM41+AQ41+AU41+AY41 -> 0 | BD41: =+BB41+BC41-BA41 -> 0 | BF41: =BD41+BE41 -> 0
B42: 1111075 | C42: ชิฟฟอนไส้แยมแยกชิ้น สตอเบอรี่ | G42: =SUM(D42:F42) -> 0 | K42: =SUM(H42:J42) -> 0 | O42: =SUM(L42:N42) -> 0 | S42: =SUM(P42:R42) -> 0 | W42: =SUM(T42:V42) -> 0 | AA42: =SUM(X42:Z42) -> 0 | AE42: =SUM(AB42:AD42) -> 0 | AI42: =SUM(AF42:AH42) -> 0 | AM42: =SUM(AJ42:AL42) -> 0 | AQ42: =SUM(AN42:AP42) -> 0 | AU42: =SUM(AR42:AT42) -> 0 | AY42: =SUM(AV42:AX42) -> 0 | BA42: =+G42+K42+O42+S42+W42+AA42+AE42+AZ42+AI42+AM42+AQ42+AU42+AY42 -> 0 | BD42: =+BB42+BC42-BA42 -> 0 | BF42: =BD42+BE42 -> 0
B43: 1111076 | C43: ชิฟฟอนไส้แยมแยกชิ้น ส้ม | G43: =SUM(D43:F43) -> 0 | K43: =SUM(H43:J43) -> 0 | O43: =SUM(L43:N43) -> 0 | S43: =SUM(P43:R43) -> 0 | W43: =SUM(T43:V43) -> 0 | AA43: =SUM(X43:Z43) -> 0 | AE43: =SUM(AB43:AD43) -> 0 | AI43: =SUM(AF43:AH43) -> 0 | AM43: =SUM(AJ43:AL43) -> 0 | AQ43: =SUM(AN43:AP43) -> 0 | AU43: =SUM(AR43:AT43) -> 0 | AY43: =SUM(AV43:AX43) -> 0 | BA43: =+G43+K43+O43+S43+W43+AA43+AE43+AZ43+AI43+AM43+AQ43+AU43+AY43 -> 0 | BD43: =+BB43+BC43-BA43 -> 0 | BF43: =BD43+BE43 -> 0
B44: 1111077 | C44: ชิฟฟอนไส้แยมแยกชิ้น บลูเบอรี่ | G44: =SUM(D44:F44) -> 0 | K44: =SUM(H44:J44) -> 0 | O44: =SUM(L44:N44) -> 0 | S44: =SUM(P44:R44) -> 0 | W44: =SUM(T44:V44) -> 0 | AA44: =SUM(X44:Z44) -> 0 | AE44: =SUM(AB44:AD44) -> 0 | AI44: =SUM(AF44:AH44) -> 0 | AM44: =SUM(AJ44:AL44) -> 0 | AQ44: =SUM(AN44:AP44) -> 0 | AU44: =SUM(AR44:AT44) -> 0 | AY44: =SUM(AV44:AX44) -> 0 | BA44: =+G44+K44+O44+S44+W44+AA44+AE44+AZ44+AI44+AM44+AQ44+AU44+AY44 -> 0 | BD44: =+BB44+BC44-BA44 -> 0 | BF44: =BD44+BE44 -> 0
B45: 1111078 | C45: ชิฟฟอนไส้แยมแยกชิ้น นมชมพู | G45: =SUM(D45:F45) -> 0 | K45: =SUM(H45:J45) -> 0 | O45: =SUM(L45:N45) -> 0 | S45: =SUM(P45:R45) -> 0 | W45: =SUM(T45:V45) -> 0 | AA45: =SUM(X45:Z45) -> 0 | AE45: =SUM(AB45:AD45) -> 0 | AI45: =SUM(AF45:AH45) -> 0 | AM45: =SUM(AJ45:AL45) -> 0 | AQ45: =SUM(AN45:AP45) -> 0 | AU45: =SUM(AR45:AT45) -> 0 | AY45: =SUM(AV45:AX45) -> 0 | BA45: =+G45+K45+O45+S45+W45+AA45+AE45+AZ45+AI45+AM45+AQ45+AU45+AY45 -> 0 | BD45: =+BB45+BC45-BA45 -> 0 | BF45: =BD45+BE45 -> 0
...

Sheet 03.4.68
B1: ยอดจริง ออนไลน์ วันที่ 3/4/2569
B2: รหัสสินค้า | C2: สินค้า | D2: ปณ | H2: ชอปปี้ | L2: ลาซาด้า | P2: ติ๊กตอก | T2: ติ๊กตอก2 | X2: ติ๊กตอก3 | AB2: ติ๊กตอก4 | AF2: ติ๊กตอก5 | AJ2: ติ๊กตอก6 | AN2: ติ๊กตอก7 | AR2: ติ๊กตอก8 | AV2: ติ๊กตอก9 | AZ2: ยอดเส้น | BA2: ยอดรวมผลิต(กล่อง) | BB2: ยอดForcast | BC2: ยอดStock | BD2: ยอดMemo | BE2: ยอดForcastวันพรุ่งนี้ | BF2: สินค้าที่ขายได้
D3: เช้า | E3: บ่าย | F3: เย็น | G3: รวม | H3: เช้า | I3: บ่าย | J3: เย็น | K3: รวม | L3: เช้า | M3: บ่าย | N3: เย็น | O3: รวม | P3: เช้า | Q3: บ่าย | R3: เย็น | S3: รวม | T3: เช้า | U3: บ่าย | V3: เย็น | W3: รวม | X3: เช้า | Y3: บ่าย | Z3: เย็น | AA3: รวม | AB3: เช้า | AC3: บ่าย | AD3: เย็น | AE3: รวม | AF3: เช้า | AG3: บ่าย | AH3: เย็น | AI3: รวม | AJ3: เช้า | AK3: บ่าย | AL3: เย็น | AM3: รวม | AN3: เช้า | AO3: บ่าย | AP3: เย็น | AQ3: รวม | AR3: เช้า | AS3: บ่าย | AT3: เย็น | AU3: รวม | AV3: เช้า | AW3: บ่าย | AX3: เย็น | AY3: รวม
B4: 1004055 | C4: ชิฟฟ่อนเค้ก วรรณวนัช (รวมรส 4 ชิ้น) | G4: =SUM(D4:F4) -> 0 | K4: =SUM(H4:J4) -> 0 | O4: =SUM(L4:N4) -> 0 | S4: =SUM(P4:R4) -> 0 | W4: =SUM(T4:V4) -> 0 | AA4: =SUM(X4:Z4) -> 0 | AE4: =SUM(AB4:AD4) -> 0 | AI4: =SUM(AF4:AH4) -> 0 | AM4: =SUM(AJ4:AL4) -> 0 | AQ4: =SUM(AN4:AP4) -> 0 | AU4: =SUM(AR4:AT4) -> 0 | AY4: =SUM(AV4:AX4) -> 0 | AZ4: 30 | BA4: =+G4+K4+O4+S4+W4+AA4+AE4+AZ4+AI4+AM4+AQ4+AU4+AY4 -> 30 | BB4: 30 | BD4: =+BB4+BC4-BA4 -> 0 | BF4: =BD4+BE4 -> 0
B5: 1111002 | C5: ชิฟฟ่อนเค้ก วรรณวนัช (รวมรส 8 ชิ้น) | D5: 12 | G5: =SUM(D5:F5) -> 12 | H5: 27 | I5: 3 | K5: =SUM(H5:J5) -> 30 | L5: 19 | O5: =SUM(L5:N5) -> 19 | P5: 5 | Q5: 12 | S5: =SUM(P5:R5) -> 17 | W5: =SUM(T5:V5) -> 0 | AA5: =SUM(X5:Z5) -> 0 | AE5: =SUM(AB5:AD5) -> 0 | AI5: =SUM(AF5:AH5) -> 0 | AM5: =SUM(AJ5:AL5) -> 0 | AQ5: =SUM(AN5:AP5) -> 0 | AU5: =SUM(AR5:AT5) -> 0 | AY5: =SUM(AV5:AX5) -> 0 | AZ5: 6 | BA5: =+G5+K5+O5+S5+W5+AA5+AE5+AZ5+AI5+AM5+AQ5+AU5+AY5 -> 84 | BB5: 85 | BC5: 63 | BD5: =+BB5+BC5-BA5 -> 64 | BE5: 70 | BF5: =BD5+BE5 -> 134
B6: 1111001 | C6: ชิฟฟ่อนแยกชิ้นไม่มีไส้ คละรส | G6: =SUM(D6:F6) -> 0 | H6: 20 | K6: =SUM(H6:J6) -> 20 | O6: =SUM(L6:N6) -> 0 | S6: =SUM(P6:R6) -> 0 | W6: =SUM(T6:V6) -> 0 | AA6: =SUM(X6:Z6) -> 0 | AE6: =SUM(AB6:AD6) -> 0 | AI6: =SUM(AF6:AH6) -> 0 | AM6: =SUM(AJ6:AL6) -> 0 | AQ6: =SUM(AN6:AP6) -> 0 | AU6: =SUM(AR6:AT6) -> 0 | AY6: =SUM(AV6:AX6) -> 0 | BA6: =+G6+K6+O6+S6+W6+AA6+AE6+AZ6+AI6+AM6+AQ6+AU6+AY6 -> 20 | BD6: =+BB6+BC6-BA6 -> -20 | BF6: =BD6+BE6 -> -20
B7: 1111043 | C7: ชิฟฟอนรสมะลิ 8 ชิ้น ห่อ ซีน | G7: =SUM(D7:F7) -> 0 | K7: =SUM(H7:J7) -> 0 | O7: =SUM(L7:N7) -> 0 | S7: =SUM(P7:R7) -> 0 | W7: =SUM(T7:V7) -> 0 | AA7: =SUM(X7:Z7) -> 0 | AE7: =SUM(AB7:AD7) -> 0 | AI7: =SUM(AF7:AH7) -> 0 | AM7: =SUM(AJ7:AL7) -> 0 | AQ7: =SUM(AN7:AP7) -> 0 | AU7: =SUM(AR7:AT7) -> 0 | AY7: =SUM(AV7:AX7) -> 0 | BA7: =+G7+K7+O7+S7+W7+AA7+AE7+AZ7+AI7+AM7+AQ7+AU7+AY7 -> 0 | BD7: =+BB7+BC7-BA7 -> 0 | BF7: =BD7+BE7 -> 0
B8: 1111057 | C8: ชิฟฟอนแยกชิ้น กาแฟ | G8: =SUM(D8:F8) -> 0 | K8: =SUM(H8:J8) -> 0 | O8: =SUM(L8:N8) -> 0 | S8: =SUM(P8:R8) -> 0 | W8: =SUM(T8:V8) -> 0 | AA8: =SUM(X8:Z8) -> 0 | AE8: =SUM(AB8:AD8) -> 0 | AI8: =SUM(AF8:AH8) -> 0 | AM8: =SUM(AJ8:AL8) -> 0 | AQ8: =SUM(AN8:AP8) -> 0 | AU8: =SUM(AR8:AT8) -> 0 | AY8: =SUM(AV8:AX8) -> 0 | BA8: =+G8+K8+O8+S8+W8+AA8+AE8+AZ8+AI8+AM8+AQ8+AU8+AY8 -> 0 | BD8: =+BB8+BC8-BA8 -> 0 | BF8: =BD8+BE8 -> 0
B9: 1111058 | C9: ชิฟฟอนแยกชิ้น ชาเขียว | G9: =SUM(D9:F9) -> 0 | K9: =SUM(H9:J9) -> 0 | O9: =SUM(L9:N9) -> 0 | S9: =SUM(P9:R9) -> 0 | W9: =SUM(T9:V9) -> 0 | AA9: =SUM(X9:Z9) -> 0 | AE9: =SUM(AB9:AD9) -> 0 | AI9: =SUM(AF9:AH9) -> 0 | AM9: =SUM(AJ9:AL9) -> 0 | AQ9: =SUM(AN9:AP9) -> 0 | AU9: =SUM(AR9:AT9) -> 0 | AY9: =SUM(AV9:AX9) -> 0 | BA9: =+G9+K9+O9+S9+W9+AA9+AE9+AZ9+AI9+AM9+AQ9+AU9+AY9 -> 0 | BD9: =+BB9+BC9-BA9 -> 0 | BF9: =BD9+BE9 -> 0
B10: 1111059 | C10: ชิฟฟอนแยกชิ้น ใบเตย | G10: =SUM(D10:F10) -> 0 | K10: =SUM(H10:J10) -> 0 | O10: =SUM(L10:N10) -> 0 | S10: =SUM(P10:R10) -> 0 | W10: =SUM(T10:V10) -> 0 | AA10: =SUM(X10:Z10) -> 0 | AE10: =SUM(AB10:AD10) -> 0 | AI10: =SUM(AF10:AH10) -> 0 | AM10: =SUM(AJ10:AL10) -> 0 | AQ10: =SUM(AN10:AP10) -> 0 | AU10: =SUM(AR10:AT10) -> 0 | AY10: =SUM(AV10:AX10) -> 0 | BA10: =+G10+K10+O10+S10+W10+AA10+AE10+AZ10+AI10+AM10+AQ10+AU10+AY10 -> 0 | BD10: =+BB10+BC10-BA10 -> 0 | BF10: =BD10+BE10 -> 0
B11: 1111060 | C11: ชิฟฟอนแยกชิ้น กล้วยหอม | G11: =SUM(D11:F11) -> 0 | K11: =SUM(H11:J11) -> 0 | O11: =SUM(L11:N11) -> 0 | S11: =SUM(P11:R11) -> 0 | W11: =SUM(T11:V11) -> 0 | AA11: =SUM(X11:Z11) -> 0 | AE11: =SUM(AB11:AD11) -> 0 | AI11: =SUM(AF11:AH11) -> 0 | AM11: =SUM(AJ11:AL11) -> 0 | AQ11: =SUM(AN11:AP11) -> 0 | AU11: =SUM(AR11:AT11) -> 0 | AY11: =SUM(AV11:AX11) -> 0 | BA11: =+G11+K11+O11+S11+W11+AA11+AE11+AZ11+AI11+AM11+AQ11+AU11+AY11 -> 0 | BD11: =+BB11+BC11-BA11 -> 0 | BF11: =BD11+BE11 -> 0
B12: 1111061 | C12: ชิฟฟอนแยกชิ้น ชาไทย | G12: =SUM(D12:F12) -> 0 | K12: =SUM(H12:J12) -> 0 | O12: =SUM(L12:N12) -> 0 | S12: =SUM(P12:R12) -> 0 | W12: =SUM(T12:V12) -> 0 | AA12: =SUM(X12:Z12) -> 0 | AE12: =SUM(AB12:AD12) -> 0 | AI12: =SUM(AF12:AH12) -> 0 | AM12: =SUM(AJ12:AL12) -> 0 | AQ12: =SUM(AN12:AP12) -> 0 | AU12: =SUM(AR12:AT12) -> 0 | AY12: =SUM(AV12:AX12) -> 0 | BA12: =+G12+K12+O12+S12+W12+AA12+AE12+AZ12+AI12+AM12+AQ12+AU12+AY12 -> 0 | BD12: =+BB12+BC12-BA12 -> 0 | BF12: =BD12+BE12 -> 0
B13: 1111062 | C13: ชิฟฟอนแยกชิ้น โกโก้ | G13: =SUM(D13:F13) -> 0 | K13: =SUM(H13:J13) -> 0 | O13: =SUM(L13:N13) -> 0 | S13: =SUM(P13:R13) -> 0 | W13: =SUM(T13:V13) -> 0 | AA13: =SUM(X13:Z13) -> 0 | AE13: =SUM(AB13:AD13) -> 0 | AI13: =SUM(AF13:AH13) -> 0 | AM13: =SUM(AJ13:AL13) -> 0 | AQ13: =SUM(AN13:AP13) -> 0 | AU13: =SUM(AR13:AT13) -> 0 | AY13: =SUM(AV13:AX13) -> 0 | BA13: =+G13+K13+O13+S13+W13+AA13+AE13+AZ13+AI13+AM13+AQ13+AU13+AY13 -> 0 | BD13: =+BB13+BC13-BA13 -> 0 | BF13: =BD13+BE13 -> 0
B14: 1111063 | C14: ชิฟฟอนแยกชิ้น ส้ม | G14: =SUM(D14:F14) -> 0 | K14: =SUM(H14:J14) -> 0 | O14: =SUM(L14:N14) -> 0 | S14: =SUM(P14:R14) -> 0 | W14: =SUM(T14:V14) -> 0 | AA14: =SUM(X14:Z14) -> 0 | AE14: =SUM(AB14:AD14) -> 0 | AI14: =SUM(AF14:AH14) -> 0 | AM14: =SUM(AJ14:AL14) -> 0 | AQ14: =SUM(AN14:AP14) -> 0 | AU14: =SUM(AR14:AT14) -> 0 | AY14: =SUM(AV14:AX14) -> 0 | BA14: =+G14+K14+O14+S14+W14+AA14+AE14+AZ14+AI14+AM14+AQ14+AU14+AY14 -> 0 | BD14: =+BB14+BC14-BA14 -> 0 | BF14: =BD14+BE14 -> 0
B15: 1111064 | C15: ชิฟฟอนแยกชิ้น เผือก | G15: =SUM(D15:F15) -> 0 | K15: =SUM(H15:J15) -> 0 | O15: =SUM(L15:N15) -> 0 | S15: =SUM(P15:R15) -> 0 | W15: =SUM(T15:V15) -> 0 | AA15: =SUM(X15:Z15) -> 0 | AE15: =SUM(AB15:AD15) -> 0 | AI15: =SUM(AF15:AH15) -> 0 | AM15: =SUM(AJ15:AL15) -> 0 | AQ15: =SUM(AN15:AP15) -> 0 | AU15: =SUM(AR15:AT15) -> 0 | AY15: =SUM(AV15:AX15) -> 0 | BA15: =+G15+K15+O15+S15+W15+AA15+AE15+AZ15+AI15+AM15+AQ15+AU15+AY15 -> 0 | BD15: =+BB15+BC15-BA15 -> 0 | BF15: =BD15+BE15 -> 0
B16: 1111065 | C16: ชิฟฟอนแยกชิ้น สับปะรด | G16: =SUM(D16:F16) -> 0 | K16: =SUM(H16:J16) -> 0 | O16: =SUM(L16:N16) -> 0 | S16: =SUM(P16:R16) -> 0 | W16: =SUM(T16:V16) -> 0 | AA16: =SUM(X16:Z16) -> 0 | AE16: =SUM(AB16:AD16) -> 0 | AI16: =SUM(AF16:AH16) -> 0 | AM16: =SUM(AJ16:AL16) -> 0 | AQ16: =SUM(AN16:AP16) -> 0 | AU16: =SUM(AR16:AT16) -> 0 | AY16: =SUM(AV16:AX16) -> 0 | BA16: =+G16+K16+O16+S16+W16+AA16+AE16+AZ16+AI16+AM16+AQ16+AU16+AY16 -> 0 | BD16: =+BB16+BC16-BA16 -> 0 | BF16: =BD16+BE16 -> 0
B17: 1111066 | C17: ชิฟฟอนแยกชิ้น สตอเบอรี่ | G17: =SUM(D17:F17) -> 0 | K17: =SUM(H17:J17) -> 0 | O17: =SUM(L17:N17) -> 0 | S17: =SUM(P17:R17) -> 0 | W17: =SUM(T17:V17) -> 0 | AA17: =SUM(X17:Z17) -> 0 | AE17: =SUM(AB17:AD17) -> 0 | AI17: =SUM(AF17:AH17) -> 0 | AM17: =SUM(AJ17:AL17) -> 0 | AQ17: =SUM(AN17:AP17) -> 0 | AU17: =SUM(AR17:AT17) -> 0 | AY17: =SUM(AV17:AX17) -> 0 | BA17: =+G17+K17+O17+S17+W17+AA17+AE17+AZ17+AI17+AM17+AQ17+AU17+AY17 -> 0 | BD17: =+BB17+BC17-BA17 -> 0 | BF17: =BD17+BE17 -> 0
B18: 1111067 | C18: ชิฟฟอนแยกชิ้น มะพร้าว | G18: =SUM(D18:F18) -> 0 | K18: =SUM(H18:J18) -> 0 | O18: =SUM(L18:N18) -> 0 | S18: =SUM(P18:R18) -> 0 | W18: =SUM(T18:V18) -> 0 | AA18: =SUM(X18:Z18) -> 0 | AE18: =SUM(AB18:AD18) -> 0 | AI18: =SUM(AF18:AH18) -> 0 | AM18: =SUM(AJ18:AL18) -> 0 | AQ18: =SUM(AN18:AP18) -> 0 | AU18: =SUM(AR18:AT18) -> 0 | AY18: =SUM(AV18:AX18) -> 0 | BA18: =+G18+K18+O18+S18+W18+AA18+AE18+AZ18+AI18+AM18+AQ18+AU18+AY18 -> 0 | BD18: =+BB18+BC18-BA18 -> 0 | BF18: =BD18+BE18 -> 0
... B23: 1111010 | C23: ชิฟฟ่อนเค้กสอดไส้แยม (1 ชิ้น) | G23: =SUM(D23:F23) -> 0 | K23: =SUM(H23:J23) -> 0 | O23: =SUM(L23:N23) -> 0 | S23: =SUM(P23:R23) -> 0 | W23: =SUM(T23:V23) -> 0 | AA23: =SUM(X23:Z23) -> 0 | AE23: =SUM(AB23:AD23) -> 0 | AI23: =SUM(AF23:AH23) -> 0 | AM23: =SUM(AJ23:AL23) -> 0 | AQ23: =SUM(AN23:AP23) -> 0 | AU23: =SUM(AR23:AT23) -> 0 | AY23: =SUM(AV23:AX23) -> 0 | BA23: =+G23+K23+O23+S23+W23+AA23+AE23+AZ23+AI23+AM23+AQ23+AU23+AY23 -> 0 | BD23: =+BB23+BC23-BA23 -> 0 | BF23: =BD23+BE23 -> 0
B24: 1111008 | C24: ชิฟฟ่อนเค้ก สอดไส้ (รวมรส 3 ชิ้น) | D24: 12 | G24: =SUM(D24:F24) -> 12 | K24: =SUM(H24:J24) -> 0 | O24: =SUM(L24:N24) -> 0 | P24: 143 | S24: =SUM(P24:R24) -> 143 | W24: =SUM(T24:V24) -> 0 | AA24: =SUM(X24:Z24) -> 0 | AE24: =SUM(AB24:AD24) -> 0 | AI24: =SUM(AF24:AH24) -> 0 | AM24: =SUM(AJ24:AL24) -> 0 | AQ24: =SUM(AN24:AP24) -> 0 | AU24: =SUM(AR24:AT24) -> 0 | AY24: =SUM(AV24:AX24) -> 0 | AZ24: 5 | BA24: =+G24+K24+O24+S24+W24+AA24+AE24+AZ24+AI24+AM24+AQ24+AU24+AY24 -> 160 | BB24: 117 | BC24: 24 | BD24: =+BB24+BC24-BA24 -> -19 | BE24: 100 | BF24: =BD24+BE24 -> 81
B25: 1111009 | C25: ชิฟฟ่อนเค้ก สอดไส้ (รวมรส 6 ชิ้น) | D25: 12 | G25: =SUM(D25:F25) -> 12 | H25: 1 | K25: =SUM(H25:J25) -> 1 | L25: 2 | O25: =SUM(L25:N25) -> 2 | P25: 8 | Q25: 1 | S25: =SUM(P25:R25) -> 9 | W25: =SUM(T25:V25) -> 0 | AA25: =SUM(X25:Z25) -> 0 | AE25: =SUM(AB25:AD25) -> 0 | AI25: =SUM(AF25:AH25) -> 0 | AM25: =SUM(AJ25:AL25) -> 0 | AQ25: =SUM(AN25:AP25) -> 0 | AU25: =SUM(AR25:AT25) -> 0 | AY25: =SUM(AV25:AX25) -> 0 | BA25: =+G25+K25+O25+S25+W25+AA25+AE25+AZ25+AI25+AM25+AQ25+AU25+AY25 -> 24 | BB25: 22 | BC25: 7 | BD25: =+BB25+BC25-BA25 -> 5 | BE25: 10 | BF25: =BD25+BE25 -> 15
B26: 1111011 | C26: ชิฟฟ่อนเค้กสอดไส้ นมชมพูฮอกไกโด (3 ชิ้น) | G26: =SUM(D26:F26) -> 0 | K26: =SUM(H26:J26) -> 0 | O26: =SUM(L26:N26) -> 0 | S26: =SUM(P26:R26) -> 0 | W26: =SUM(T26:V26) -> 0 | AA26: =SUM(X26:Z26) -> 0 | AE26: =SUM(AB26:AD26) -> 0 | AI26: =SUM(AF26:AH26) -> 0 | AM26: =SUM(AJ26:AL26) -> 0 | AQ26: =SUM(AN26:AP26) -> 0 | AU26: =SUM(AR26:AT26) -> 0 | AY26: =SUM(AV26:AX26) -> 0 | BA26: =+G26+K26+O26+S26+W26+AA26+AE26+AZ26+AI26+AM26+AQ26+AU26+AY26 -> 0 | BD26: =+BB26+BC26-BA26 -> 0 | BF26: =BD26+BE26 -> 0
B27: 1111012 | C27: ชิฟฟ่อนเค้กสอดไส้ นมชมพูฮอกไกโด (6 ชิ้น) | G27: =SUM(D27:F27) -> 0 | K27: =SUM(H27:J27) -> 0 | O27: =SUM(L27:N27) -> 0 | S27: =SUM(P27:R27) -> 0 | W27: =SUM(T27:V27) -> 0 | AA27: =SUM(X27:Z27) -> 0 | AE27: =SUM(AB27:AD27) -> 0 | AI27: =SUM(AF27:AH27) -> 0 | AM27: =SUM(AJ27:AL27) -> 0 | AQ27: =SUM(AN27:AP27) -> 0 | AU27: =SUM(AR27:AT27) -> 0 | AY27: =SUM(AV27:AX27) -> 0 | BA27: =+G27+K27+O27+S27+W27+AA27+AE27+AZ27+AI27+AM27+AQ27+AU27+AY27 -> 0 | BD27: =+BB27+BC27-BA27 -> 0 | BF27: =BD27+BE27 -> 0
B28: 1111013 | C28: ชิฟฟ่อนเค้กสอดไส้ ช็อคโกแลตนูเทลล่า (3 ชิ้น) | G28: =SUM(D28:F28) -> 0 | K28: =SUM(H28:J28) -> 0 | O28: =SUM(L28:N28) -> 0 | S28: =SUM(P28:R28) -> 0 | W28: =SUM(T28:V28) -> 0 | AA28: =SUM(X28:Z28) -> 0 | AE28: =SUM(AB28:AD28) -> 0 | AI28: =SUM(AF28:AH28) -> 0 | AM28: =SUM(AJ28:AL28) -> 0 | AQ28: =SUM(AN28:AP28) -> 0 | AU28: =SUM(AR28:AT28) -> 0 | AY28: =SUM(AV28:AX28) -> 0 | BA28: =+G28+K28+O28+S28+W28+AA28+AE28+AZ28+AI28+AM28+AQ28+AU28+AY28 -> 0 | BD28: =+BB28+BC28-BA28 -> 0 | BF28: =BD28+BE28 -> 0
B29: 1111014 | C29: ชิฟฟ่อนเค้กสอดไส้ ช็อคโกแลตนูเทลล่า (6 ชิ้น) | G29: =SUM(D29:F29) -> 0 | K29: =SUM(H29:J29) -> 0 | O29: =SUM(L29:N29) -> 0 | S29: =SUM(P29:R29) -> 0 | W29: =SUM(T29:V29) -> 0 | AA29: =SUM(X29:Z29) -> 0 | AE29: =SUM(AB29:AD29) -> 0 | AI29: =SUM(AF29:AH29) -> 0 | AM29: =SUM(AJ29:AL29) -> 0 | AQ29: =SUM(AN29:AP29) -> 0 | AU29: =SUM(AR29:AT29) -> 0 | AY29: =SUM(AV29:AX29) -> 0 | BA29: =+G29+K29+O29+S29+W29+AA29+AE29+AZ29+AI29+AM29+AQ29+AU29+AY29 -> 0 | BD29: =+BB29+BC29-BA29 -> 0 | BF29: =BD29+BE29 -> 0
B30: 1111015 | C30: ชิฟฟ่อนเค้กสอดไส้เนย รสมะพร้าว (3 ชิ้น) | G30: =SUM(D30:F30) -> 0 | K30: =SUM(H30:J30) -> 0 | O30: =SUM(L30:N30) -> 0 | S30: =SUM(P30:R30) -> 0 | W30: =SUM(T30:V30) -> 0 | AA30: =SUM(X30:Z30) -> 0 | AE30: =SUM(AB30:AD30) -> 0 | AI30: =SUM(AF30:AH30) -> 0 | AM30: =SUM(AJ30:AL30) -> 0 | AQ30: =SUM(AN30:AP30) -> 0 | AU30: =SUM(AR30:AT30) -> 0 | AY30: =SUM(AV30:AX30) -> 0 | BA30: =+G30+K30+O30+S30+W30+AA30+AE30+AZ30+AI30+AM30+AQ30+AU30+AY30 -> 0 | BD30: =+BB30+BC30-BA30 -> 0 | BF30: =BD30+BE30 -> 0
B31: 1111016 | C31: ชิฟฟ่อนเค้กสอดไส้เนย รสมะพร้าว (6 ชิ้น) | G31: =SUM(D31:F31) -> 0 | K31: =SUM(H31:J31) -> 0 | O31: =SUM(L31:N31) -> 0 | S31: =SUM(P31:R31) -> 0 | W31: =SUM(T31:V31) -> 0 | AA31: =SUM(X31:Z31) -> 0 | AE31: =SUM(AB31:AD31) -> 0 | AI31: =SUM(AF31:AH31) -> 0 | AM31: =SUM(AJ31:AL31) -> 0 | AQ31: =SUM(AN31:AP31) -> 0 | AU31: =SUM(AR31:AT31) -> 0 | AY31: =SUM(AV31:AX31) -> 0 | BA31: =+G31+K31+O31+S31+W31+AA31+AE31+AZ31+AI31+AM31+AQ31+AU31+AY31 -> 0 | BD31: =+BB31+BC31-BA31 -> 0 | BF31: =BD31+BE31 -> 0
B32: 1111017 | C32: ชิฟฟ่อนเค้กสอดไส้แยม รสบลูเบอร์รี่ (3 ชิ้น) | G32: =SUM(D32:F32) -> 0 | K32: =SUM(H32:J32) -> 0 | O32: =SUM(L32:N32) -> 0 | S32: =SUM(P32:R32) -> 0 | W32: =SUM(T32:V32) -> 0 | AA32: =SUM(X32:Z32) -> 0 | AE32: =SUM(AB32:AD32) -> 0 | AI32: =SUM(AF32:AH32) -> 0 | AM32: =SUM(AJ32:AL32) -> 0 | AQ32: =SUM(AN32:AP32) -> 0 | AU32: =SUM(AR32:AT32) -> 0 | AY32: =SUM(AV32:AX32) -> 0 | BA32: =+G32+K32+O32+S32+W32+AA32+AE32+AZ32+AI32+AM32+AQ32+AU32+AY32 -> 0 | BD32: =+BB32+BC32-BA32 -> 0 | BF32: =BD32+BE32 -> 0
B33: 1111018 | C33: ชิฟฟ่อนเค้กสอดไส้แยม รสบลูเบอร์รี่ (6 ชิ้น) | G33: =SUM(D33:F33) -> 0 | K33: =SUM(H33:J33) -> 0 | O33: =SUM(L33:N33) -> 0 | S33: =SUM(P33:R33) -> 0 | W33: =SUM(T33:V33) -> 0 | AA33: =SUM(X33:Z33) -> 0 | AE33: =SUM(AB33:AD33) -> 0 | AI33: =SUM(AF33:AH33) -> 0 | AM33: =SUM(AJ33:AL33) -> 0 | AQ33: =SUM(AN33:AP33) -> 0 | AU33: =SUM(AR33:AT33) -> 0 | AY33: =SUM(AV33:AX33) -> 0 | BA33: =+G33+K33+O33+S33+W33+AA33+AE33+AZ33+AI33+AM33+AQ33+AU33+AY33 -> 0 | BD33: =+BB33+BC33-BA33 -> 0 | BF33: =BD33+BE33 -> 0
B34: 1111019 | C34: ชิฟฟ่อนเค้กหน้าฝอยทอง สอดไส้แยมส้ม (3 ชิ้น) | G34: =SUM(D34:F34) -> 0 | K34: =SUM(H34:J34) -> 0 | O34: =SUM(L34:N34) -> 0 | S34: =SUM(P34:R34) -> 0 | W34: =SUM(T34:V34) -> 0 | AA34: =SUM(X34:Z34) -> 0 | AE34: =SUM(AB34:AD34) -> 0 | AI34: =SUM(AF34:AH34) -> 0 | AM34: =SUM(AJ34:AL34) -> 0 | AQ34: =SUM(AN34:AP34) -> 0 | AU34: =SUM(AR34:AT34) -> 0 | AY34: =SUM(AV34:AX34) -> 0 | BA34: =+G34+K34+O34+S34+W34+AA34+AE34+AZ34+AI34+AM34+AQ34+AU34+AY34 -> 0 | BD34: =+BB34+BC34-BA34 -> 0 | BF34: =BD34+BE34 -> 0
