Workbook

Sheet ค่าใช้จ่าย
A1: สรุปค่าใช้จ่าย บูธ แก้วมณีกาญจน์ วันที่ 1-31 ส.ค.
A2: วันที่ | B2: รายการค่าใช้จ่าย | C2: ยอดค่าใช้จ่าย | D2: หมายเหตุ
A3: 243833 | B3: ค่าซ่อมสวิสต์ไฟตู้แช่ | C3: 350
A4: 243835 | B4: ค่าปากกา + เทปใส | C4: 47
A5: 243837 | B5: ค่าถ่านใส่คีย์บอร์ด | C5: 69
B6: ยอดรวมค่าใช้จ่าย | C6: =SUM(C3:C5) -> 466 | D6: บาท
B194: เครปคิทแคท | I194: 35

Sheet รายการคืนสินค้า
A1: สรุปรายการคืนสินค้า บูธ แก้วมณีกาญจน์ วันที่ 1-31 ส.ค.
A2: วันที่ | B2: รายการสินค้า | C2: จำนวนคืนสินค้า | D2: ราคา/หน่วย | E2: ยอดรวม | F2: หมายเหตุ
A3: 243833 | B3: ชิฟฟ่อนเค้ก วรรณวนัช (สอดไส้รวมรส 8 ชิ้น) | C3: 1 | D3: 130 | E3: 100 | F3: หมดอายุ
A4: 243833 | B4: ชิฟฟ่อนเค้กมะพร้าวสอดไส้ครีมมะพร้าวล้วน (8 ชิ้น) | C4: 1 | D4: 130 | E4: 200 | F4: หมดอายุ
A5: 243833 | B5: ชิฟฟ่อนเค้กทูโทนใบเตยและมะพร้าวสอดไส้ครีม (8 ชิ้น) | C5: 2 | D5: 130 | E5: 100 | F5: หมดอายุ
A6: 243834 | B6: ชิฟฟ่อน สอดไส้ (ก) 5 ชิ้น ครีมมะพร้าว | C6: 2 | D6: 85 | E6: 100 | F6: คืนไส้เปรี๊ยว 2
A7: 243834 | B7: ชิฟฟ่อนเค้ก วรรณวนัช (สอดไส้รวมรส 8 ชิ้น) | C7: 6 | D7: 130 | E7: 100 | F7: คืนไส้เปรี๊ยว 6
A8: 243834 | B8: ชิฟฟ่อนเค้กมะพร้าวสอดไส้ครีมมะพร้าวล้วน (8 ชิ้น) | C8: 1 | D8: 130 | E8: 100 | F8: คืนไส้เปรี๊ยว 1
A9: 243834 | B9: ครีมฮอร์น ใบเตย | C9: 2 | D9: 50 | E9: 100 | F9: คืนไส้เปรี๊ยว 2
A10: 243834 | B10: ครีมฮอร์น ช็อคโกแลต | C10: 4 | D10: 50 | E10: 100 | F10: คืนไส้เปรี๊ยว 4
A11: 243834 | B11: ชิฟฟ่อนเค้กทูโทนใบเตยและมะพร้าวสอดไส้ครีม (8 ชิ้น) | C11: 1 | D11: 130 | E11: =+C11*D11 -> 130 | F11: คืนไส้เปรี๊ยว 1
A12: 243841 | B12: ครีมฮอร์นใบเตยจัมโบ้ | C12: 12 | D12: 25 | E12: =+C12*D12 -> 300 | F12: หมดอายุ 12
A13: 243841 | B13: ครีมฮอร์นชาไทยจัมโบ้ | C13: 14 | D13: 25 | E13: =+C13*D13 -> 350 | F13: หมดอายุ 14
A14: 243844 | B14: ครีมฮอร์น วนิลา | C14: 1 | D14: 50 | E14: =+C14*D14 -> 50 | F14: หมดอายุ
A15: 243844 | B15: เบาหวิว (ญ) ใหม่ รสกาแฟ | C15: 1 | D15: 120 | E15: =+C15*D15 -> 120 | F15: หมดอายุ 1
A16: 243844 | B16: คัพเค้กคัสตาร์ด | C16: 9 | D16: 45 | E16: =+C16*D16 -> 405 | F16: หมดอายุ 9
A17: 243847 | B17: เอแคลร์นมสด 8 ชิ้น | C17: 1 | D17: 50 | E17: =+C17*D17 -> 50 | F17: หมดอายุ 1
A18: 243848 | B18: ครีมฮอร์น ช็อคโกแลต | C18: 2 | D18: 50 | E18: =+C18*D18 -> 100 | F18: หมดอายุ 2
A19: 243850 | B19: ครีมฮอร์น วนิลา | C19: 1 | D19: 50 | E19: =+C19*D19 -> 50 | F19: หมดอายุ 1
A20: 243850 | B20: เอแคลร์นมสด 8 ชิ้น | C20: 2 | D20: 50 | E20: =+C20*D20 -> 100 | F20: หมดอายุ 2
A21: 243854 | B21: เค้กลอดช่อง | C21: 2 | D21: 35 | E21: =+C21*D21 -> 70 | F21: หมดอายุ 2
A22: 243855 | B22: เบาหวิว (ญ) ใหม่ รสมะพร้าว | C22: 1 | D22: 120 | E22: =+C22*D22 -> 120 | F22: หมดอายุ 2
... A39: 243861 | B39: ขนมปังสังขยา 4 ลูก | C39: 2 | D39: 60 | E39: =+C39*D39 -> 120 | F39: หมดอายุ 2
B40: ยอดรวมคืนสินค้า | C40: =SUM(C3:C39) -> 106 | D40: บาท | E40: =SUM(E3:E39) -> 6095 | F40: บาท

Sheet รายการส่วนลด
A1: สรุปส่วนลดสินค้า บูธ แก้วมณีกาญจน์ วันที่ 1-31 ส.ค. 67
A2: วันที่ | B2: รายการสินค้า | C2: จำนวน | D2: ราคาเต็ม/หน่วย | E2: ราคาลด/หน่วย | F2: ยอดรวม | G2: หมายเหตุ
A3: 243831 | B3: ชิฟฟ่อนเค้ก วรรณวนัช (สอดไส้รวมรส 8 ชิ้น) | C3: 3 | D3: 130 | E3: =+D3/2 -> 65 | F3: =+C3*E3 -> 195 | G3: ลด 50 %
A4: 243831 | B4: ครีมฮอร์น ใบเตย | C4: 2 | D4: 50 | E4: =+D4/2 -> 25 | F4: =+C4*E4 -> 50 | G4: ลด 50 %
A5: 243831 | B5: ครีมฮอร์น ช็อคโกแลต | C5: 1 | D5: 50 | E5: =+D5/2 -> 25 | F5: =+C5*E5 -> 25 | G5: ลด 50 %
A6: 243831 | B6: เบาหวิว (ญ) ใหม่ รสกาแฟ | C6: 1 | D6: 120 | E6: 35 | F6: =+C6*E6 -> 35 | G6: โปรจับคู่
A7: 243831 | B7: เบาหวิว (ญ) ใหม่ รสกล้วยหอมมะพร้าวเผา | C7: 1 | D7: 120 | E7: 35 | F7: =+C7*E7 -> 35 | G7: โปรจับคู่
A8: 243831 | B8: เบาหวิว (ญ) ใหม่ รสฝอยทอง | C8: 4 | D8: 120 | E8: 140 | F8: =+C8*E8 -> 560 | G8: โปรจับคู่ 2 คู่
A9: 243832 | B9: เบาหวิว (ล) ใหม่ กาแฟ | C9: 1 | D9: 50 | E9: 50 | F9: =+C9*E9 -> 50 | G9: แถม
A10: 243832 | B10: เบาหวิว (ล) ใหม่ ฝอยทอง | C10: 1 | D10: 50 | E10: 50 | F10: =+C10*E10 -> 50 | G10: แถม
A11: 243832 | B11: เบาหวิว (ญ) ใหม่ รสกาแฟ | C11: 1 | D11: 120 | E11: 35 | F11: =+C11*E11 -> 35 | G11: โปรจับ 1 คู่
A12: 243832 | B12: เบาหวิว (ญ) ใหม่ รสเผือกมะพร้าวเผา | C12: 1 | D12: 120 | E12: 35 | F12: =+C12*E12 -> 35 | G12: โปรจับ 1 คู่
A13: 243833 | B13: ชิฟฟ่อน สอดไส้ (ก) 5 ชิ้น ครีมมะพร้าว | C13: 4 | D13: 85 | E13: =+D13/2 -> 42.5 | F13: =+C13*E13 -> 170 | G13: ลด 50 % 4
A14: 243833 | B14: ชิฟฟ่อนเค้ก วรรณวนัช (สอดไส้รวมรส 8 ชิ้น) | C14: 7 | D14: 130 | E14: =+D14/2 -> 65 | F14: =+C14*E14 -> 455 | G14: ลด 50 % 7
A15: 243833 | B15: ชิฟฟ่อนเค้กมะพร้าวสอดไส้ครีมมะพร้าวล้วน (8 ชิ้น) | C15: 1 | D15: 130 | E15: =+D15/2 -> 65 | F15: =+C15*E15 -> 65 | G15: ลด 50 % 1
A16: 243833 | B16: ครีมฮอร์น วนิลา | C16: 2 | D16: 50 | E16: =+D16/2 -> 25 | F16: =+C16*E16 -> 50 | G16: ลด 50 % 2
A17: 243833 | B17: ครีมฮอร์น ใบเตย | C17: 2 | D17: 50 | E17: =+D17/2 -> 25 | F17: =+C17*E17 -> 50 | G17: ลด 50 % 2
A18: 243833 | B18: ลาวา ทูโทน (ล) (สีเขียว + สีเหลือง) | C18: 2 | D18: 50 | E18: =+D18/2 -> 25 | F18: =+C18*E18 -> 50 | G18: ลด 50 % 2
A19: 243833 | B19: ท๊อฟฟี่ถั่ว (กระเช้า) | C19: 1 | D19: 100 | E19: 100 | F19: =+C19*E19 -> 100 | G19: แถม 1
A20: 243833 | B20: ขนมปังสังขยา 6 ลูก | C20: 4 | D20: 50 | E20: =+D20/2 -> 25 | F20: =+C20*E20 -> 100 | G20: ลด 50 % 4
A21: 243834 | B21: ชิฟฟ่อนเค้กสอดไส้ รวมรส (8 ชิ้น) กล่องชมพู | C21: 9 | D21: 100 | E21: =+D21/2 -> 50 | F21: =+C21*E21 -> 450 | G21: ลด 50 % 9
A22: 243834 | B22: ชิฟฟ่อนเค้กสอดไส้ รวมรส (3 ชิ้น) | C22: 1 | D22: 50 | E22: =+D22/2 -> 25 | F22: =+C22*E22 -> 25 | G22: ลด 50 % 1
A23: 243834 | B23: ชิฟฟ่อนเค้กสอดไส้แยม รสส้ม (3 ชิ้น) | C23: 1 | D23: 50 | E23: =+D23/2 -> 25 | F23: =+C23*E23 -> 25 | G23: ลด 50 % 1
A24: 243834 | B24: ชิฟฟ่อนเค้กหน้าฝอยทอง สอดไส้แยมส้ม (3 ชิ้น) | C24: 4 | D24: 50 | E24: =+D24/2 -> 25 | F24: =+C24*E24 -> 100 | G24: ลด 50 % 4
A25: 243834 | B25: ชิฟฟ่อนเค้กหน้าฝอยทอง สอดไส้แยมส้ม (6 ชิ้น) | C25: 6 | D25: 100 | E25: =+D25/2 -> 50 | F25: =+C25*E25 -> 300 | G25: ลด 50 % 6
A26: 243834 | B26: เบาหวิว (ญ) ใหม่ รสฝอยทอง | C26: 2 | D26: 120 | E26: 35 | F26: =+C26*E26 -> 70 | G26: โปรจับคู่ 1
A27: 243835 | B27: ชิฟฟ่อนเค้กสอดไส้ รวมรส (8 ชิ้น) กล่องชมพู | C27: 2 | D27: 100 | E27: =+D27/2 -> 50 | F27: =+C27*E27 -> 100 | G27: ลด 50 % 2
A28: 243835 | B28: ชิฟฟ่อนเค้กหน้าฝอยทอง สอดไส้แยมส้ม (3 ชิ้น) | C28: 3 | D28: 50 | E28: =+D28/2 -> 25 | F28: =+C28*E28 -> 75 | G28: ลด 50 % 3
A29: 243835 | B29: ชิฟฟ่อนเค้ก วรรณวนัช (สอดไส้รวมรส 8 ชิ้น) | C29: 2 | D29: 130 | E29: =+D29/2 -> 65 | F29: =+C29*E29 -> 130 | G29: ลด 50 % 2
A30: 243835 | B30: ครีมฮอร์นใบเตยจัมโบ้ | C30: 1 | D30: 25 | E30: 25 | F30: =+C30*E30 -> 25 | G30: 1 แถม 1
A31: 243835 | B31: เบาหวิว (ญ) ใหม่ รสมะพร้าว | C31: 3 | D31: 120 | E31: 35 | F31: =+C31*E31 -> 105 | G31: จับคู่โปร 3
A32: 243835 | B32: เบาหวิว (ญ) ใหม่ รสกล้วยหอมมะพร้าวเผา | C32: 2 | D32: 120 | E32: 35 | F32: =+C32*E32 -> 70 | G32: จับคู่โปร 2
A33: 243835 | B33: เบาหวิว (ญ) ใหม่ รสฝอยทอง | C33: 1 | D33: 120 | E33: 35 | F33: =+C33*E33 -> 35 | G33: จับคู่โปร 1
A34: 243835 | B34: ลาวา (ล) (สีเหลืองล้วน) | C34: 1 | D34: 50 | E34: =+D34/2 -> 25 | F34: =+C34*E34 -> 25 | G34: ลด 50 % 1
A35: 243835 | B35: ขนมเปี๊ยะ 450 กรัม เผือก | C35: 1 | D35: 150 | E35: =+D35/2 -> 75 | F35: =+C35*E35 -> 75 | G35: ลด 50 % 1
A36: 243836 | B36: เบาหวิว (ล) ใหม่ มะพร้าว | C36: 1 | D36: 50 | E36: 50 | F36: =+C36*E36 -> 50 | G36: แถม
A37: 243836 | B37: เบาหวิว (ญ) ใหม่ รสมะพร้าว | C37: 1 | D37: 120 | E37: 35 | F37: =+C37*E37 -> 35 | G37: โปรจับคู่ 1
A38: 243836 | B38: เบาหวิว (ญ) ใหม่ รสกล้วยหอมมะพร้าวเผา | C38: 2 | D38: 120 | E38: 35 | F38: =+C38*E38 -> 70 | G38: โปรจับคู่ 2
A39: 243836 | B39: เบาหวิว (ญ) ใหม่ รสเผือกมะพร้าวเผา | C39: 1 | D39: 120 | E39: 35 | F39: =+C39*E39 -> 35 | G39: โปรจับคู่ 1
A40: 243836 | B40: ข้าวเกรียบว่าว (กระปุก) | C40: 1 | D40: 40 | E40: 20 | F40: =+C40*E40 -> 20 | G40: โปร 3 กระปุก 100 บาท
...

Sheet รายการโยกย้ายสินค้า
A1: สรุปรายการโยกย้ายสินค้า บูธ แก้วมณีกาญจน์ วันที่ 1-31 ส.ค.
A2: วันที่ | B2: รายการสินค้า | C2: จำนวนสินค้า | D2: โยกไปสาขา | E2: หมายเหตุ
A3: 243840 | B3: ชิฟฟ่อนเค้กสอดไส้ รวมรส (8 ชิ้น) กล่องชมพู | C3: 10 | D3: ลำพยา 2 ใหม่
A4: 243840 | B4: ชิฟฟ่อนเค้กสอดไส้ รวมรส (8 ชิ้น) กล่องชมพู | C4: 10 | D4: ไทวัสดุ
A5: 243840 | B5: ชิฟฟ่อนเค้กสอดไส้ รวมรส (8 ชิ้น) กล่องชมพู | C5: 10 | D5: ปตท.คุณาวรรณ
A6: 243840 | B6: ชิฟฟ่อนเค้กสอดไส้ รวมรส (8 ชิ้น) กล่องชมพู | C6: 10 | D6: ปตท.ราชบุรี
A7: 243840 | B7: ชิฟฟ่อนเค้กสอดไส้ รวมรส (8 ชิ้น) กล่องชมพู | C7: 10 | D7: ลำพยา 3 ใหม่
B8: ยอดรวม | C8: =SUM(C3:C7) -> 50 | D8: กล่อง

Sheet ออม
A2: สรุปยอดขาย บูธ แก้วมณีกาญจน์ วันที่ 1-31 ส.ค. 67
A3: วันที่ | B3: ยอดเงิน | C3: ส่วนลด | D3: สแกนใช้สิทธิ์ | E3: ค่าโอนเงิน | F3: ค่าใช้จ่ายอื่นๆ | G3: โอนหน้าร้าน | H3: รับสุทธิ | I3: ยอดโอนเงิน | J3: โอนเกิน/โอนขาด
A5: 1 | B5: =+'1'!M287 -> 3230 | C5: =+'1'!M292 -> 350 | D5: =+'1'!M290 -> 0 | E5: =+'1'!M288 -> 0 | F5: =+'1'!M291 -> 0 | G5: =+'1'!M289 -> 785 | H5: =+B5-C5-D5-E5-F5-G5 -> 2095 | I5: =+'1'!M294 -> 2095 | J5: =+I5-H5 -> 0
A6: 2 | B6: =+'2'!M287 -> 4340 | C6: =+'2'!M292 -> 170 | D6: =+'2'!M290 -> 0 | E6: =+'2'!M288 -> 0 | F6: =+'2'!M291 -> 0 | G6: =+'2'!M289 -> 1620 | H6: =+B6-C6-D6-E6-F6-G6 -> 2550 | I6: =+'2'!M294 -> 2550 | J6: =+I6-H6 -> 0
A7: 3 | B7: =+'3'!M287 -> 6790 | C7: =+'3'!M292 -> 1040 | D7: =+'3'!M290 -> 0 | E7: =+'3'!M288 -> 0 | F7: =+'3'!M291 -> 350 | G7: =+'3'!M289 -> 1625 | H7: =+B7-C7-D7-E7-F7-G7 -> 3775 | I7: =+'3'!M294 -> 3775 | J7: =+I7-H7 -> 0
A8: 4 | B8: =+'4'!M287 -> 4600 | C8: =+'4'!M292 -> 970 | D8: =+'4'!M290 -> 0 | E8: =+'4'!M298 -> 0 | F8: =+'4'!M291 -> 0 | G8: =+'4'!M289 -> 1635 | H8: =+B8-C8-D8-E8-F8-G8 -> 1995 | I8: =+'4'!M294 -> 1995 | J8: =+I8-H8 -> 0
A9: 5 | B9: =+'5'!M287 -> 3110 | C9: =+'5'!M292 -> 640 | D9: =+'5'!M290 -> 0 | E9: =+'5'!M288 -> 0 | F9: =+'5'!M291 -> 47 | G9: =+'5'!M289 -> 1210 | H9: =+B9-C9-D9-E9-F9-G9 -> 1213 | I9: =+'5'!M294 -> 1213 | J9: =+I9-H9 -> 0
A10: 6 | B10: =+'6'!M287 -> 3585 | C10: =+'6'!M292 -> 210 | D10: =+'6'!M290 -> 0 | E10: =+'6'!M288 -> 0 | F10: =+'6'!M291 -> 0 | G10: =+'6'!M289 -> 490 | H10: =+B10-C10-D10-E10-F10-G10 -> 2885 | I10: =+'6'!M294 -> 2885 | J10: =+I10-H10 -> 0
A11: 7 | B11: =+'7'!M287 -> 3925 | C11: =+'7'!M292 -> 1570 | D11: =+'7'!M290 -> 0 | E11: =+'7'!M288 -> 0 | F11: =+'7'!M291 -> 69 | G11: =+'7'!M289 -> 640 | H11: =+B11-C11-D11-E11-F11-G11 -> 1646 | I11: =+'7'!M294 -> 1646 | J11: =+I11-H11 -> 0
A12: 8 | B12: =+'8'!M287 -> 4060 | C12: =+'8'!M292 -> 1625 | D12: =+'8'!M290 -> 0 | E12: =+'8'!M288 -> 0 | F12: =+'8'!M291 -> 0 | G12: =+'8'!M289 -> 300 | H12: =+B12-C12-D12-E12-F12-G12 -> 2135 | I12: =+'8'!M294 -> 2135 | J12: =+I12-H12 -> 0
A13: 9 | B13: =+'9'!M287 -> 4850 | C13: =+'9'!M292 -> 1385 | D13: =+'9'!M290 -> 0 | E13: =+'9'!M288 -> 0 | F13: =+'9'!M291 -> 0 | G13: =+'9'!M289 -> 520 | H13: =+B13-C13-D13-E13-F13-G13 -> 2945 | I13: =+'9'!M294 -> 2970 | J13: =+I13-H13 -> 25
A14: 10 | B14: =+'10'!M287 -> 7555 | C14: =+'10'!M292 -> 490 | D14: =+'10'!M290 -> 0 | E14: =+'10'!M288 -> 0 | F14: =+'10'!M291 -> 0 | G14: =+'10'!M289 -> 3030 | H14: =+B14-C14-D14-E14-F14-G14 -> 4035 | I14: =+'10'!M294 -> 4035 | J14: =+I14-H14 -> 0
A15: 11 | B15: =+'11'!M287 -> 9845 | C15: =+'11'!M292 -> 1515 | D15: =+'11'!M290 -> 0 | E15: =+'11'!M288 -> 0 | F15: =+'11'!M291 -> 0 | G15: =+'11'!M289 -> 2045 | H15: =+B15-C15-D15-E15-F15-G15 -> 6285 | I15: =+'11'!M294 -> 6285 | J15: =+I15-H15 -> 0
A16: 12 | B16: =+'12'!M287 -> 5090 | C16: =+'12'!M292 -> 205 | D16: =+'12'!M290 -> 0 | E16: =+'12'!M288 -> 0 | F16: =+'12'!M291 -> 0 | G16: =+'12'!M289 -> 1405 | H16: =+B16-C16-D16-E16-F16-G16 -> 3480 | I16: =+'12'!M294 -> 3480 | J16: =+I16-H16 -> 0
A17: 13 | B17: =+'13'!M287 -> 3525 | C17: =+'13'!M292 -> 530 | D17: =+'13'!M290 -> 0 | E17: =+'13'!M288 -> 0 | F17: =+'13'!M291 -> 0 | G17: =+'13'!M289 -> 480 | H17: =+B17-C17-D17-E17-F17-G17 -> 2515 | I17: =+'13'!M294 -> 2515 | J17: =+I17-H17 -> 0
A18: 14 | B18: =+'14'!M287 -> 3760 | C18: =+'14'!M292 -> 550 | D18: =+'14'!M290 -> 0 | E18: =+'14'!M288 -> 0 | F18: =+'14'!M291 -> 0 | G18: =+'14'!M289 -> 1260 | H18: =+B18-C18-D18-E18-F18-G18 -> 1950 | I18: =+'14'!M294 -> 1950 | J18: =+I18-H18 -> 0
A19: 15 | B19: =+'15'!M287 -> 2680 | C19: =+'15'!M292 -> 840 | D19: =+'15'!M290 -> 0 | E19: =+'15'!M288 -> 0 | F19: =+'15'!M291 -> 0 | G19: =+'15'!M289 -> 420 | H19: =+B19-C19-D19-E19-F19-G19 -> 1420 | I19: =+'15'!M294 -> 1420 | J19: =+I19-H19 -> 0
A20: 16 | B20: =+'16'!M287 -> 3385 | C20: =+'16'!M292 -> 120 | D20: =+'16'!M290 -> 0 | E20: =+'16'!M288 -> 0 | F20: =+'16'!M291 -> 0 | G20: =+'16'!M289 -> 1145 | H20: =+B20-C20-D20-E20-F20-G20 -> 2120 | I20: =+'16'!M294 -> 2120 | J20: =+I20-H20 -> 0
A21: 17 | B21: =+'17'!M287 -> 6205 | C21: =+'17'!M292 -> 1080 | D21: =+'17'!M290 -> 0 | E21: =+'17'!M288 -> 0 | F21: =+'17'!M291 -> 0 | G21: =+'17'!M289 -> 2050 | H21: =+B21-C21-D21-E21-F21-G21 -> 3075 | I21: =+'17'!M294 -> 3075 | J21: =+I21-H21 -> 0
A22: 18 | B22: =+'18'!M287 -> 2660 | C22: =+'18'!M292 -> 230 | D22: =+'18'!M290 -> 0 | E22: =+'18'!M288 -> 0 | F22: =+'17'!M291 -> 0 | G22: =+'18'!M289 -> 735 | H22: =+B22-C22-D22-E22-F22-G22 -> 1695 | I22: =+'18'!M294 -> 1695 | J22: =+I22-H22 -> 0
A23: 19 | B23: =+'19'!M287 -> 3610 | C23: =+'19'!M292 -> 565 | D23: =+'19'!M290 -> 0 | E23: =+'19'!M288 -> 0 | F23: =+'19'!M291 -> 0 | G23: =+'19'!M289 -> 235 | H23: =+B23-C23-D23-E23-F23-G23 -> 2810 | I23: =+'19'!M294 -> 2810 | J23: =+I23-H23 -> 0
A24: 20 | B24: =+'20'!M287 -> 2935 | C24: =+'20'!M292 -> 640 | D24: =+'20'!M290 -> 0 | E24: =+'20'!M288 -> 0 | F24: =+'20'!M291 -> 0 | G24: =+'20'!M289 -> 910 | H24: =+B24-C24-D24-E24-F24-G24 -> 1385 | I24: =+'20'!M294 -> 1385 | J24: =+I24-H24 -> 0
A25: 21 | B25: =+'21'!M287 -> 1745 | C25: =+'21'!M292 -> 240 | D25: =+'21'!M290 -> 0 | E25: =+'21'!M288 -> 0 | F25: =+'21'!M291 -> 0 | G25: =+'21'!M289 -> 550 | H25: =+B25-C25-D25-E25-F25-G25 -> 955 | I25: =+'21'!M294 -> 955 | J25: =+I25-H25 -> 0
A26: 22 | B26: =+'22'!M287 -> 815 | C26: =+'22'!M292 -> 75 | D26: =+'22'!M290 -> 0 | E26: =+'22'!M288 -> 0 | F26: =+'22'!M291 -> 0 | G26: =+'22'!M289 -> 615 | H26: =+B26-C26-D26-E26-F26-G26 -> 125 | I26: =+'22'!M294 -> 125 | J26: =+I26-H26 -> 0
A27: 23 | B27: =+'23'!M287 -> 5750 | C27: =+'23'!M292 -> 2050 | D27: =+'23'!M290 -> 0 | E27: =+'23'!M288 -> 0 | F27: =+'23'!M291 -> 0 | G27: =+'23'!M289 -> 500 | H27: =+B27-C27-D27-E27-F27-G27 -> 3200 | I27: =+'23'!M294 -> 3250 | J27: =+I27-H27 -> 50
A28: 24 | B28: =+'24'!M287 -> 5485 | C28: =+'24'!M292 -> 350 | D28: =+'24'!M290 -> 0 | E28: =+'24'!M288 -> 0 | F28: =+'24'!M291 -> 0 | G28: =+'24'!M289 -> 1745 | H28: =+B28-C28-D28-E28-F28-G28 -> 3390 | I28: =+'24'!M294 -> 3390 | J28: =+I28-H28 -> 0
A29: 25 | B29: =+'25'!M287 -> 5330 | C29: =+'25'!M292 -> 985 | D29: =+'25'!M290 -> 0 | E29: =+'25'!M288 -> 0 | F29: =+'25'!M291 -> 0 | G29: =+'25'!M289 -> 1160 | H29: =+B29-C29-D29-E29-F29-G29 -> 3185 | I29: =+'25'!M294 -> 3185 | J29: =+I29-H29 -> 0
A30: 26 | B30: =+'26'!M287 -> 1350 | C30: =+'26'!M292 -> 0 | D30: =+'26'!M290 -> 0 | E30: =+'26'!M288 -> 0 | F30: =+'26'!M291 -> 0 | G30: =+'26'!M289 -> 0 | H30: =+B30-C30-D30-E30-F30-G30 -> 1350 | I30: =+'26'!M294 -> 1350 | J30: =+I30-H30 -> 0
A31: 27 | B31: =+'27'!M287 -> 3155 | C31: =+'27'!M292 -> 140 | D31: =+'27'!M290 -> 0 | E31: =+'27'!M288 -> 0 | F31: =+'27'!M291 -> 0 | G31: =+'27'!M289 -> 900 | H31: =+B31-C31-D31-E31-F31-G31 -> 2115 | I31: =+'27'!M294 -> 2115 | J31: =+I31-H31 -> 0
A32: 28 | B32: =+'28'!M287 -> 2000 | C32: =+'28'!M292 -> 310 | D32: =+'28'!M290 -> 0 | E32: =+'28'!M288 -> 0 | F32: =+'28'!M291 -> 0 | G32: =+'28'!M289 -> 305 | H32: =+B32-C32-D32-E32-F32-G32 -> 1385 | I32: =+'28'!M294 -> 1385 | J32: =+I32-H32 -> 0
A33: 29 | B33: =+'29'!M287 -> 2775 | C33: =+'29'!M292 -> 670 | D33: =+'29'!M290 -> 0 | E33: =+'29'!M288 -> 0 | F33: =+'29'!M291 -> 0 | G33: =+'29'!M289 -> 505 | H33: =+B33-C33-D33-E33-F33-G33 -> 1600 | I33: =+'29'!M294 -> 1600 | J33: =+I33-H33 -> 0
A34: 30 | B34: =+'30'!M287 -> 4110 | C34: =+'30'!M292 -> 1645 | D34: =+'30'!M290 -> 0 | E34: =+'30'!M288 -> 0 | F34: =+'30'!M291 -> 0 | G34: =+'30'!M289 -> 920 | H34: =+B34-C34-D34-E34-F34-G34 -> 1545 | I34: =+'30'!M294 -> 1545 | J34: =+I34-H34 -> 0
A35: 31 | B35: =+'31.'!M287 -> 6545 | C35: =+'31.'!M292 -> 485 | D35: =+'31.'!M290 -> 0 | E35: =+'31.'!M288 -> 0 | F35: =+'31.'!M291 -> 0 | G35: =+'31.'!M289 -> 2990 | H35: =+B35-C35-D35-E35-F35-G35 -> 3070 | I35: =+'31.'!M294 -> 3070 | J35: =+I35-H35 -> 0
B36: =SUM(B5:B35) -> 128800 | C36: =SUM(C5:C35) -> 21675 | D36: =SUM(D5:D35) -> 0 | E36: =SUM(E5:E35) -> 0 | F36: =SUM(F5:F35) -> 466 | G36: =SUM(G5:G35) -> 32730 | H36: =SUM(H5:H35) -> 73929 | I36: =SUM(I5:I35) -> 74004 | J36: =SUM(J5:J35) -> 75

Sheet สรุป
A2: บูธ แก้วมณีกาญจน์ วันที่ 1-31 ส.ค. 67 | O2: สรุปยอดขาย บูธ แก้วมณีกาญจน์ วันที่ 1-31 ส.ค. 67
A3: ลำดับ | B3: รายการ | C3: ยกมา | D3: รับ | E3: รวม | F3: เปลี่ยน/ | G3: โยก | H3: คงเหลือ | I3: รายการขาย | L3: หมายเหตุ | M3: ราคาต้นทุน | N3: ยอดรวมต้นทุนสินค้า | O3: วันที่ | P3: ยอดเงิน | Q3: ส่วนลด | R3: สแกนใช้สิทธิ์ | S3: ค่าโอนเงิน | T3: ค่าใช้จ่ายอื่นๆ | U3: โอนหน้าร้าน | V3: รับสุทธิ | W3: ยอดโอนเงิน | X3: โอนเกิน/โอนขาด
F4: คืน/เสีย | I4: จำนวน | J4: @ | K4: เป็นเงิน
A5: 1 | B5: ชิฟฟ่อนเค้กสอดไส้ รวมรส (4 ชิ้น) กล่องชมพู | C5: =+ยกมา!D5 -> 10 | D5: =+'1'!E5+'2'!E5+'3'!E5+'4'!E5+'5'!E5+'6'!E5+'7'!E5+'8'!E5+'9'!E5+'10'!E5+'11'!E5+'12'!E5+'13'!E5+'14'!E5+'15'!E5+'16'!E5+'17'!E5+'18'!E5+'19'!E5+'20'!E5+'21'!E5+'22'!E5+'23'!E5+'24'!E5+'25'!E5+'26'!E5+'27'!E5+'28'!E5+'29'!E5+'30'!E5+'31.'!E5 -> 96 | E5: =+C5+D5 -> 106 | F5: =+'1'!G5+'2'!G5+'3'!G5+'4'!G5+'5'!G5+'6'!G5+'7'!G5+'8'!G5+'9'!G5+'10'!G5+'11'!G5+'12'!G5+'13'!G5+'14'!G5+'15'!G5+'16'!G5+'17'!G5+'18'!G5+'19'!G5+'20'!G5+'21'!G5+'22'!G5+'23'!G5+'24'!G5+'25'!G5+'26'!G5+'27'!G5+'28'!G5+'29'!G5+'30'!G5+'31.'!G5 -> 0 | G5: =+'1'!H5+'2'!H5+'3'!H5+'4'!H5+'5'!H5+'6'!H5+'7'!H5+'8'!H5+'9'!H5+'10'!H5+'11'!H5+'12'!H5+'13'!H5+'14'!H5+'15'!H5+'16'!H5+'17'!H5+'18'!H5+'19'!H5+'20'!H5+'21'!H5+'22'!H5+'23'!H5+'24'!H5+'25'!H5+'26'!H5+'27'!H5+'28'!H5+'29'!H5+'30'!H5+'31.'!H5 -> 0 | H5: =+C5+D5-F5-G5-I5 -> 28 | I5: =+'1'!J5+'2'!J5+'3'!J5+'4'!J5+'5'!J5+'6'!J5+'7'!J5+'8'!J5+'9'!J5+'10'!J5+'11'!J5+'12'!J5+'13'!J5+'14'!J5+'15'!J5+'16'!J5+'17'!J5+'18'!J5+'19'!J5+'20'!J5+'21'!J5+'22'!J5+'23'!J5+'24'!J5+'25'!J5+'26'!J5+'27'!J5+'28'!J5+'29'!J5+'30'!J5+'31.'!J5 -> 78 | J5: 50 | K5: =+'1'!L5+'2'!L5+'3'!L5+'4'!L5+'5'!L5+'6'!L5+'7'!L5+'8'!L5+'9'!L5+'10'!L5+'11'!L5+'12'!L5+'13'!L5+'14'!L5+'15'!L5+'16'!L5+'17'!L5+'18'!L5+'19'!L5+'20'!L5+'21'!L5+'22'!L5+'23'!L5+'24'!L5+'25'!L5+'26'!L5+'27'!L5+'28'!L5+'29'!L5+'30'!L5+'31.'!L5 -> 3900 | M5: 19.58 | N5: =+I5*M5 -> 1527.24 | O5: 1 | P5: =+'1'!M287 -> 3230 | Q5: =+'1'!M292 -> 350 | R5: =+'1'!M290 -> 0 | S5: =+'1'!M288 -> 0 | T5: =+'1'!M291 -> 0 | U5: =+'1'!M289 -> 785 | V5: =+P5-Q5-R5-S5-T5-U5 -> 2095 | W5: =+'1'!M294 -> 2095 | X5: =+W5-V5 -> 0 | Y5: =+U5+W5+X5 -> 2880
A6: 2 | B6: ชิฟฟ่อนเค้กสอดไส้ รวมรส (8 ชิ้น) กล่องชมพู | C6: =+ยกมา!D6 -> 191 | D6: =+'1'!E6+'2'!E6+'3'!E6+'4'!E6+'5'!E6+'6'!E6+'7'!E6+'8'!E6+'9'!E6+'10'!E6+'11'!E6+'12'!E6+'13'!E6+'14'!E6+'15'!E6+'16'!E6+'17'!E6+'18'!E6+'19'!E6+'20'!E6+'21'!E6+'22'!E6+'23'!E6+'24'!E6+'25'!E6+'26'!E6+'27'!E6+'28'!E6+'29'!E6+'30'!E6+'31.'!E6 -> 98 | E6: =+C6+D6 -> 289 | F6: =+'1'!G6+'2'!G6+'3'!G6+'4'!G6+'5'!G6+'6'!G6+'7'!G6+'8'!G6+'9'!G6+'10'!G6+'11'!G6+'12'!G6+'13'!G6+'14'!G6+'15'!G6+'16'!G6+'17'!G6+'18'!G6+'19'!G6+'20'!G6+'21'!G6+'22'!G6+'23'!G6+'24'!G6+'25'!G6+'26'!G6+'27'!G6+'28'!G6+'29'!G6+'30'!G6+'31.'!G6 -> 0 | G6: =+'1'!H6+'2'!H6+'3'!H6+'4'!H6+'5'!H6+'6'!H6+'7'!H6+'8'!H6+'9'!H6+'10'!H6+'11'!H6+'12'!H6+'13'!H6+'14'!H6+'15'!H6+'16'!H6+'17'!H6+'18'!H6+'19'!H6+'20'!H6+'21'!H6+'22'!H6+'23'!H6+'24'!H6+'25'!H6+'26'!H6+'27'!H6+'28'!H6+'29'!H6+'30'!H6+'31.'!H6 -> 60 | H6: =+C6+D6-F6-G6-I6 -> 98 | I6: =+'1'!J6+'2'!J6+'3'!J6+'4'!J6+'5'!J6+'6'!J6+'7'!J6+'8'!J6+'9'!J6+'10'!J6+'11'!J6+'12'!J6+'13'!J6+'14'!J6+'15'!J6+'16'!J6+'17'!J6+'18'!J6+'19'!J6+'20'!J6+'21'!J6+'22'!J6+'23'!J6+'24'!J6+'25'!J6+'26'!J6+'27'!J6+'28'!J6+'29'!J6+'30'!J6+'31.'!J6 -> 131 | J6: 100 | K6: =+'1'!L6+'2'!L6+'3'!L6+'4'!L6+'5'!L6+'6'!L6+'7'!L6+'8'!L6+'9'!L6+'10'!L6+'11'!L6+'12'!L6+'13'!L6+'14'!L6+'15'!L6+'16'!L6+'17'!L6+'18'!L6+'19'!L6+'20'!L6+'21'!L6+'22'!L6+'23'!L6+'24'!L6+'25'!L6+'26'!L6+'27'!L6+'28'!L6+'29'!L6+'30'!L6+'31.'!L6 -> 13100 | M6: 37.17 | N6: =+I6*M6 -> 4869.27 | O6: 2 | P6: =+'2'!M287 -> 4340 | Q6: =+'2'!M292 -> 170 | R6: =+'2'!M290 -> 0 | S6: =+'2'!M288 -> 0 | T6: =+'2'!M291 -> 0 | U6: =+'2'!M289 -> 1620 | V6: =+P6-Q6-R6-S6-T6-U6 -> 2550 | W6: =+'2'!M294 -> 2550 | X6: =+W6-V6 -> 0 | Y6: =+U6+W6+X6 -> 4170
A7: 3 | B7: ชิฟฟ่อนเค้ก รสกาแฟ (4 ชิ้น) | C7: =+ยกมา!D7 -> 0 | D7: =+'1'!E7+'2'!E7+'3'!E7+'4'!E7+'5'!E7+'6'!E7+'7'!E7+'8'!E7+'9'!E7+'10'!E7+'11'!E7+'12'!E7+'13'!E7+'14'!E7+'15'!E7+'16'!E7+'17'!E7+'18'!E7+'19'!E7+'20'!E7+'21'!E7+'22'!E7+'23'!E7+'24'!E7+'25'!E7+'26'!E7+'27'!E7+'28'!E7+'29'!E7+'30'!E7+'31.'!E7 -> 0 | E7: =+C7+D7 -> 0 | F7: =+'1'!G7+'2'!G7+'3'!G7+'4'!G7+'5'!G7+'6'!G7+'7'!G7+'8'!G7+'9'!G7+'10'!G7+'11'!G7+'12'!G7+'13'!G7+'14'!G7+'15'!G7+'16'!G7+'17'!G7+'18'!G7+'19'!G7+'20'!G7+'21'!G7+'22'!G7+'23'!G7+'24'!G7+'25'!G7+'26'!G7+'27'!G7+'28'!G7+'29'!G7+'30'!G7+'31.'!G7 -> 0 | G7: =+'1'!H7+'2'!H7+'3'!H7+'4'!H7+'5'!H7+'6'!H7+'7'!H7+'8'!H7+'9'!H7+'10'!H7+'11'!H7+'12'!H7+'13'!H7+'14'!H7+'15'!H7+'16'!H7+'17'!H7+'18'!H7+'19'!H7+'20'!H7+'21'!H7+'22'!H7+'23'!H7+'24'!H7+'25'!H7+'26'!H7+'27'!H7+'28'!H7+'29'!H7+'30'!H7+'31.'!H7 -> 0 | H7: =+C7+D7-F7-G7-I7 -> 0 | I7: =+'1'!J7+'2'!J7+'3'!J7+'4'!J7+'5'!J7+'6'!J7+'7'!J7+'8'!J7+'9'!J7+'10'!J7+'11'!J7+'12'!J7+'13'!J7+'14'!J7+'15'!J7+'16'!J7+'17'!J7+'18'!J7+'19'!J7+'20'!J7+'21'!J7+'22'!J7+'23'!J7+'24'!J7+'25'!J7+'26'!J7+'27'!J7+'28'!J7+'29'!J7+'30'!J7+'31.'!J7 -> 0 | J7: 50 | K7: =+'1'!L7+'2'!L7+'3'!L7+'4'!L7+'5'!L7+'6'!L7+'7'!L7+'8'!L7+'9'!L7+'10'!L7+'11'!L7+'12'!L7+'13'!L7+'14'!L7+'15'!L7+'16'!L7+'17'!L7+'18'!L7+'19'!L7+'20'!L7+'21'!L7+'22'!L7+'23'!L7+'24'!L7+'25'!L7+'26'!L7+'27'!L7+'28'!L7+'29'!L7+'30'!L7+'31.'!L7 -> 0 | M7: 26.11 | N7: =+I7*M7 -> 0 | O7: 3 | P7: =+'3'!M287 -> 6790 | Q7: =+'3'!M292 -> 1040 | R7: =+'3'!M290 -> 0 | S7: =+'3'!M288 -> 0 | T7: =+'3'!M291 -> 350 | U7: =+'3'!M289 -> 1625 | V7: =+P7-Q7-R7-S7-T7-U7 -> 3775 | W7: =+'3'!M294 -> 3775 | X7: =+W7-V7 -> 0 | Y7: =+U7+W7+X7 -> 5400
A8: 4 | B8: ชิฟฟ่อนเค้ก รสกาแฟ (8 ชิ้น) | C8: =+ยกมา!D8 -> 0 | D8: =+'1'!E8+'2'!E8+'3'!E8+'4'!E8+'5'!E8+'6'!E8+'7'!E8+'8'!E8+'9'!E8+'10'!E8+'11'!E8+'12'!E8+'13'!E8+'14'!E8+'15'!E8+'16'!E8+'17'!E8+'18'!E8+'19'!E8+'20'!E8+'21'!E8+'22'!E8+'23'!E8+'24'!E8+'25'!E8+'26'!E8+'27'!E8+'28'!E8+'29'!E8+'30'!E8+'31.'!E8 -> 0 | E8: =+C8+D8 -> 0 | F8: =+'1'!G8+'2'!G8+'3'!G8+'4'!G8+'5'!G8+'6'!G8+'7'!G8+'8'!G8+'9'!G8+'10'!G8+'11'!G8+'12'!G8+'13'!G8+'14'!G8+'15'!G8+'16'!G8+'17'!G8+'18'!G8+'19'!G8+'20'!G8+'21'!G8+'22'!G8+'23'!G8+'24'!G8+'25'!G8+'26'!G8+'27'!G8+'28'!G8+'29'!G8+'30'!G8+'31.'!G8 -> 0 | G8: =+'1'!H8+'2'!H8+'3'!H8+'4'!H8+'5'!H8+'6'!H8+'7'!H8+'8'!H8+'9'!H8+'10'!H8+'11'!H8+'12'!H8+'13'!H8+'14'!H8+'15'!H8+'16'!H8+'17'!H8+'18'!H8+'19'!H8+'20'!H8+'21'!H8+'22'!H8+'23'!H8+'24'!H8+'25'!H8+'26'!H8+'27'!H8+'28'!H8+'29'!H8+'30'!H8+'31.'!H8 -> 0 | H8: =+C8+D8-F8-G8-I8 -> 0 | I8: =+'1'!J8+'2'!J8+'3'!J8+'4'!J8+'5'!J8+'6'!J8+'7'!J8+'8'!J8+'9'!J8+'10'!J8+'11'!J8+'12'!J8+'13'!J8+'14'!J8+'15'!J8+'16'!J8+'17'!J8+'18'!J8+'19'!J8+'20'!J8+'21'!J8+'22'!J8+'23'!J8+'24'!J8+'25'!J8+'26'!J8+'27'!J8+'28'!J8+'29'!J8+'30'!J8+'31.'!J8 -> 0 | J8: 100 | K8: =+'1'!L8+'2'!L8+'3'!L8+'4'!L8+'5'!L8+'6'!L8+'7'!L8+'8'!L8+'9'!L8+'10'!L8+'11'!L8+'12'!L8+'13'!L8+'14'!L8+'15'!L8+'16'!L8+'17'!L8+'18'!L8+'19'!L8+'20'!L8+'21'!L8+'22'!L8+'23'!L8+'24'!L8+'25'!L8+'26'!L8+'27'!L8+'28'!L8+'29'!L8+'30'!L8+'31.'!L8 -> 0 | M8: 33.89 | N8: =+I8*M8 -> 0 | O8: 4 | P8: =+'4'!M287 -> 4600 | Q8: =+'4'!M292 -> 970 | R8: =+'4'!M290 -> 0 | S8: =+'4'!M298 -> 0 | T8: =+'4'!M291 -> 0 | U8: =+'4'!M289 -> 1635 | V8: =+P8-Q8-R8-S8-T8-U8 -> 1995 | W8: =+'4'!M294 -> 1995 | X8: =+W8-V8 -> 0 | Y8: =+U8+W8+X8 -> 3630
A9: 5 | B9: ชิฟฟ่อนเค้ก 1 ชิ้น | C9: =+ยกมา!D9 -> 0 | D9: =+'1'!E9+'2'!E9+'3'!E9+'4'!E9+'5'!E9+'6'!E9+'7'!E9+'8'!E9+'9'!E9+'10'!E9+'11'!E9+'12'!E9+'13'!E9+'14'!E9+'15'!E9+'16'!E9+'17'!E9+'18'!E9+'19'!E9+'20'!E9+'21'!E9+'22'!E9+'23'!E9+'24'!E9+'25'!E9+'26'!E9+'27'!E9+'28'!E9+'29'!E9+'30'!E9+'31.'!E9 -> 0 | E9: =+C9+D9 -> 0 | F9: =+'1'!G9+'2'!G9+'3'!G9+'4'!G9+'5'!G9+'6'!G9+'7'!G9+'8'!G9+'9'!G9+'10'!G9+'11'!G9+'12'!G9+'13'!G9+'14'!G9+'15'!G9+'16'!G9+'17'!G9+'18'!G9+'19'!G9+'20'!G9+'21'!G9+'22'!G9+'23'!G9+'24'!G9+'25'!G9+'26'!G9+'27'!G9+'28'!G9+'29'!G9+'30'!G9+'31.'!G9 -> 0 | G9: =+'1'!H9+'2'!H9+'3'!H9+'4'!H9+'5'!H9+'6'!H9+'7'!H9+'8'!H9+'9'!H9+'10'!H9+'11'!H9+'12'!H9+'13'!H9+'14'!H9+'15'!H9+'16'!H9+'17'!H9+'18'!H9+'19'!H9+'20'!H9+'21'!H9+'22'!H9+'23'!H9+'24'!H9+'25'!H9+'26'!H9+'27'!H9+'28'!H9+'29'!H9+'30'!H9+'31.'!H9 -> 0 | H9: =+C9+D9-F9-G9-I9 -> 0 | I9: =+'1'!J9+'2'!J9+'3'!J9+'4'!J9+'5'!J9+'6'!J9+'7'!J9+'8'!J9+'9'!J9+'10'!J9+'11'!J9+'12'!J9+'13'!J9+'14'!J9+'15'!J9+'16'!J9+'17'!J9+'18'!J9+'19'!J9+'20'!J9+'21'!J9+'22'!J9+'23'!J9+'24'!J9+'25'!J9+'26'!J9+'27'!J9+'28'!J9+'29'!J9+'30'!J9+'31.'!J9 -> 0 | J9: 10 | K9: =+'1'!L9+'2'!L9+'3'!L9+'4'!L9+'5'!L9+'6'!L9+'7'!L9+'8'!L9+'9'!L9+'10'!L9+'11'!L9+'12'!L9+'13'!L9+'14'!L9+'15'!L9+'16'!L9+'17'!L9+'18'!L9+'19'!L9+'20'!L9+'21'!L9+'22'!L9+'23'!L9+'24'!L9+'25'!L9+'26'!L9+'27'!L9+'28'!L9+'29'!L9+'30'!L9+'31.'!L9 -> 0 | N9: =+I9*M9 -> 0 | O9: 5 | P9: =+'5'!M287 -> 3110 | Q9: =+'5'!M292 -> 640 | R9: =+'5'!M290 -> 0 | S9: =+'5'!M288 -> 0 | T9: =+'5'!M291 -> 47 | U9: =+'5'!M289 -> 1210 | V9: =+P9-Q9-R9-S9-T9-U9 -> 1213 | W9: =+'5'!M294 -> 1213 | X9: =+W9-V9 -> 0 | Y9: =+U9+W9+X9 -> 2423
A10: 6 | B10: ชิฟฟ่อนเค้กสอดไส้แยม 1 ชิ้น | C10: =+ยกมา!D10 -> 0 | D10: =+'1'!E10+'2'!E10+'3'!E10+'4'!E10+'5'!E10+'6'!E10+'7'!E10+'8'!E10+'9'!E10+'10'!E10+'11'!E10+'12'!E10+'13'!E10+'14'!E10+'15'!E10+'16'!E10+'17'!E10+'18'!E10+'19'!E10+'20'!E10+'21'!E10+'22'!E10+'23'!E10+'24'!E10+'25'!E10+'26'!E10+'27'!E10+'28'!E10+'29'!E10+'30'!E10+'31.'!E10 -> 0 | E10: =+C10+D10 -> 0 | F10: =+'1'!G10+'2'!G10+'3'!G10+'4'!G10+'5'!G10+'6'!G10+'7'!G10+'8'!G10+'9'!G10+'10'!G10+'11'!G10+'12'!G10+'13'!G10+'14'!G10+'15'!G10+'16'!G10+'17'!G10+'18'!G10+'19'!G10+'20'!G10+'21'!G10+'22'!G10+'23'!G10+'24'!G10+'25'!G10+'26'!G10+'27'!G10+'28'!G10+'29'!G10+'30'!G10+'31.'!G10 -> 0 | G10: =+'1'!H10+'2'!H10+'3'!H10+'4'!H10+'5'!H10+'6'!H10+'7'!H10+'8'!H10+'9'!H10+'10'!H10+'11'!H10+'12'!H10+'13'!H10+'14'!H10+'15'!H10+'16'!H10+'17'!H10+'18'!H10+'19'!H10+'20'!H10+'21'!H10+'22'!H10+'23'!H10+'24'!H10+'25'!H10+'26'!H10+'27'!H10+'28'!H10+'29'!H10+'30'!H10+'31.'!H10 -> 0 | H10: =+C10+D10-F10-G10-I10 -> 0 | I10: =+'1'!J10+'2'!J10+'3'!J10+'4'!J10+'5'!J10+'6'!J10+'7'!J10+'8'!J10+'9'!J10+'10'!J10+'11'!J10+'12'!J10+'13'!J10+'14'!J10+'15'!J10+'16'!J10+'17'!J10+'18'!J10+'19'!J10+'20'!J10+'21'!J10+'22'!J10+'23'!J10+'24'!J10+'25'!J10+'26'!J10+'27'!J10+'28'!J10+'29'!J10+'30'!J10+'31.'!J10 -> 0 | J10: 15 | K10: =+'1'!L10+'2'!L10+'3'!L10+'4'!L10+'5'!L10+'6'!L10+'7'!L10+'8'!L10+'9'!L10+'10'!L10+'11'!L10+'12'!L10+'13'!L10+'14'!L10+'15'!L10+'16'!L10+'17'!L10+'18'!L10+'19'!L10+'20'!L10+'21'!L10+'22'!L10+'23'!L10+'24'!L10+'25'!L10+'26'!L10+'27'!L10+'28'!L10+'29'!L10+'30'!L10+'31.'!L10 -> 0 | N10: =+I10*M10 -> 0 | O10: 6 | P10: =+'6'!M287 -> 3585 | Q10: =+'6'!M292 -> 210 | R10: =+'6'!M290 -> 0 | S10: =+'6'!M288 -> 0 | T10: =+'6'!M291 -> 0 | U10: =+'6'!M289 -> 490 | V10: =+P10-Q10-R10-S10-T10-U10 -> 2885 | W10: =+'6'!M294 -> 2885 | X10: =+W10-V10 -> 0 | Y10: =+U10+W10+X10 -> 3375
A11: 7 | B11: ชิฟฟ่อนเค้กสอดไส้เนย รสมะพร้าว (2 ชิ้น) | C11: =+ยกมา!D11 -> 0 | D11: =+'1'!E11+'2'!E11+'3'!E11+'4'!E11+'5'!E11+'6'!E11+'7'!E11+'8'!E11+'9'!E11+'10'!E11+'11'!E11+'12'!E11+'13'!E11+'14'!E11+'15'!E11+'16'!E11+'17'!E11+'18'!E11+'19'!E11+'20'!E11+'21'!E11+'22'!E11+'23'!E11+'24'!E11+'25'!E11+'26'!E11+'27'!E11+'28'!E11+'29'!E11+'30'!E11+'31.'!E11 -> 0 | E11: =+C11+D11 -> 0 | F11: =+'1'!G11+'2'!G11+'3'!G11+'4'!G11+'5'!G11+'6'!G11+'7'!G11+'8'!G11+'9'!G11+'10'!G11+'11'!G11+'12'!G11+'13'!G11+'14'!G11+'15'!G11+'16'!G11+'17'!G11+'18'!G11+'19'!G11+'20'!G11+'21'!G11+'22'!G11+'23'!G11+'24'!G11+'25'!G11+'26'!G11+'27'!G11+'28'!G11+'29'!G11+'30'!G11+'31.'!G11 -> 0 | G11: =+'1'!H11+'2'!H11+'3'!H11+'4'!H11+'5'!H11+'6'!H11+'7'!H11+'8'!H11+'9'!H11+'10'!H11+'11'!H11+'12'!H11+'13'!H11+'14'!H11+'15'!H11+'16'!H11+'17'!H11+'18'!H11+'19'!H11+'20'!H11+'21'!H11+'22'!H11+'23'!H11+'24'!H11+'25'!H11+'26'!H11+'27'!H11+'28'!H11+'29'!H11+'30'!H11+'31.'!H11 -> 0 | H11: =+C11+D11-F11-G11-I11 -> 0 | I11: =+'1'!J11+'2'!J11+'3'!J11+'4'!J11+'5'!J11+'6'!J11+'7'!J11+'8'!J11+'9'!J11+'10'!J11+'11'!J11+'12'!J11+'13'!J11+'14'!J11+'15'!J11+'16'!J11+'17'!J11+'18'!J11+'19'!J11+'20'!J11+'21'!J11+'22'!J11+'23'!J11+'24'!J11+'25'!J11+'26'!J11+'27'!J11+'28'!J11+'29'!J11+'30'!J11+'31.'!J11 -> 0 | J11: 40 | K11: =+'1'!L11+'2'!L11+'3'!L11+'4'!L11+'5'!L11+'6'!L11+'7'!L11+'8'!L11+'9'!L11+'10'!L11+'11'!L11+'12'!L11+'13'!L11+'14'!L11+'15'!L11+'16'!L11+'17'!L11+'18'!L11+'19'!L11+'20'!L11+'21'!L11+'22'!L11+'23'!L11+'24'!L11+'25'!L11+'26'!L11+'27'!L11+'28'!L11+'29'!L11+'30'!L11+'31.'!L11 -> 0 | M11: 12.74 | N11: =+I11*M11 -> 0 | O11: 7 | P11: =+'7'!M287 -> 3925 | Q11: =+'7'!M292 -> 1570 | R11: =+'7'!M290 -> 0 | S11: =+'7'!M288 -> 0 | T11: =+'7'!M291 -> 69 | U11: =+'7'!M289 -> 640 | V11: =+P11-Q11-R11-S11-T11-U11 -> 1646 | W11: =+'7'!M294 -> 1646 | X11: =+W11-V11 -> 0 | Y11: =+U11+W11+X11 -> 2286
A12: 8 | B12: ชิฟฟ่อน (ญ) ห่อซีน | C12: =+ยกมา!D12 -> 0 | D12: =+'1'!E12+'2'!E12+'3'!E12+'4'!E12+'5'!E12+'6'!E12+'7'!E12+'8'!E12+'9'!E12+'10'!E12+'11'!E12+'12'!E12+'13'!E12+'14'!E12+'15'!E12+'16'!E12+'17'!E12+'18'!E12+'19'!E12+'20'!E12+'21'!E12+'22'!E12+'23'!E12+'24'!E12+'25'!E12+'26'!E12+'27'!E12+'28'!E12+'29'!E12+'30'!E12+'31.'!E12 -> 0 | E12: =+C12+D12 -> 0 | F12: =+'1'!G12+'2'!G12+'3'!G12+'4'!G12+'5'!G12+'6'!G12+'7'!G12+'8'!G12+'9'!G12+'10'!G12+'11'!G12+'12'!G12+'13'!G12+'14'!G12+'15'!G12+'16'!G12+'17'!G12+'18'!G12+'19'!G12+'20'!G12+'21'!G12+'22'!G12+'23'!G12+'24'!G12+'25'!G12+'26'!G12+'27'!G12+'28'!G12+'29'!G12+'30'!G12+'31.'!G12 -> 0 | G12: =+'1'!H12+'2'!H12+'3'!H12+'4'!H12+'5'!H12+'6'!H12+'7'!H12+'8'!H12+'9'!H12+'10'!H12+'11'!H12+'12'!H12+'13'!H12+'14'!H12+'15'!H12+'16'!H12+'17'!H12+'18'!H12+'19'!H12+'20'!H12+'21'!H12+'22'!H12+'23'!H12+'24'!H12+'25'!H12+'26'!H12+'27'!H12+'28'!H12+'29'!H12+'30'!H12+'31.'!H12 -> 0 | H12: =+C12+D12-F12-G12-I12 -> 0 | I12: =+'1'!J12+'2'!J12+'3'!J12+'4'!J12+'5'!J12+'6'!J12+'7'!J12+'8'!J12+'9'!J12+'10'!J12+'11'!J12+'12'!J12+'13'!J12+'14'!J12+'15'!J12+'16'!J12+'17'!J12+'18'!J12+'19'!J12+'20'!J12+'21'!J12+'22'!J12+'23'!J12+'24'!J12+'25'!J12+'26'!J12+'27'!J12+'28'!J12+'29'!J12+'30'!J12+'31.'!J12 -> 0 | J12: 100 | K12: =+'1'!L12+'2'!L12+'3'!L12+'4'!L12+'5'!L12+'6'!L12+'7'!L12+'8'!L12+'9'!L12+'10'!L12+'11'!L12+'12'!L12+'13'!L12+'14'!L12+'15'!L12+'16'!L12+'17'!L12+'18'!L12+'19'!L12+'20'!L12+'21'!L12+'22'!L12+'23'!L12+'24'!L12+'25'!L12+'26'!L12+'27'!L12+'28'!L12+'29'!L12+'30'!L12+'31.'!L12 -> 0 | N12: =+I12*M12 -> 0 | O12: 8 | P12: =+'8'!M287 -> 4060 | Q12: =+'8'!M292 -> 1625 | R12: =+'8'!M290 -> 0 | S12: =+'8'!M288 -> 0 | T12: =+'8'!M291 -> 0 | U12: =+'8'!M289 -> 300 | V12: =+P12-Q12-R12-S12-T12-U12 -> 2135 | W12: =+'8'!M294 -> 2135 | X12: =+W12-V12 -> 0 | Y12: =+U12+W12+X12 -> 2435
A13: 9 | B13: ชิฟฟ่อนเค้กสอดไส้ รวมรส (3 ชิ้น) | C13: =+ยกมา!D13 -> 20 | D13: =+'1'!E13+'2'!E13+'3'!E13+'4'!E13+'5'!E13+'6'!E13+'7'!E13+'8'!E13+'9'!E13+'10'!E13+'11'!E13+'12'!E13+'13'!E13+'14'!E13+'15'!E13+'16'!E13+'17'!E13+'18'!E13+'19'!E13+'20'!E13+'21'!E13+'22'!E13+'23'!E13+'24'!E13+'25'!E13+'26'!E13+'27'!E13+'28'!E13+'29'!E13+'30'!E13+'31.'!E13 -> 80 | E13: =+C13+D13 -> 100 | F13: =+'1'!G13+'2'!G13+'3'!G13+'4'!G13+'5'!G13+'6'!G13+'7'!G13+'8'!G13+'9'!G13+'10'!G13+'11'!G13+'12'!G13+'13'!G13+'14'!G13+'15'!G13+'16'!G13+'17'!G13+'18'!G13+'19'!G13+'20'!G13+'21'!G13+'22'!G13+'23'!G13+'24'!G13+'25'!G13+'26'!G13+'27'!G13+'28'!G13+'29'!G13+'30'!G13+'31.'!G13 -> 0 | G13: =+'1'!H13+'2'!H13+'3'!H13+'4'!H13+'5'!H13+'6'!H13+'7'!H13+'8'!H13+'9'!H13+'10'!H13+'11'!H13+'12'!H13+'13'!H13+'14'!H13+'15'!H13+'16'!H13+'17'!H13+'18'!H13+'19'!H13+'20'!H13+'21'!H13+'22'!H13+'23'!H13+'24'!H13+'25'!H13+'26'!H13+'27'!H13+'28'!H13+'29'!H13+'30'!H13+'31.'!H13 -> 0 | H13: =+C13+D13-F13-G13-I13 -> 23 | I13: =+'1'!J13+'2'!J13+'3'!J13+'4'!J13+'5'!J13+'6'!J13+'7'!J13+'8'!J13+'9'!J13+'10'!J13+'11'!J13+'12'!J13+'13'!J13+'14'!J13+'15'!J13+'16'!J13+'17'!J13+'18'!J13+'19'!J13+'20'!J13+'21'!J13+'22'!J13+'23'!J13+'24'!J13+'25'!J13+'26'!J13+'27'!J13+'28'!J13+'29'!J13+'30'!J13+'31.'!J13 -> 77 | J13: 50 | K13: =+'1'!L13+'2'!L13+'3'!L13+'4'!L13+'5'!L13+'6'!L13+'7'!L13+'8'!L13+'9'!L13+'10'!L13+'11'!L13+'12'!L13+'13'!L13+'14'!L13+'15'!L13+'16'!L13+'17'!L13+'18'!L13+'19'!L13+'20'!L13+'21'!L13+'22'!L13+'23'!L13+'24'!L13+'25'!L13+'26'!L13+'27'!L13+'28'!L13+'29'!L13+'30'!L13+'31.'!L13 -> 3850 | M13: 11.38 | N13: =+I13*M13 -> 876.26 | O13: 9 | P13: =+'9'!M287 -> 4850 | Q13: =+'9'!M292 -> 1385 | R13: =+'9'!M290 -> 0 | S13: =+'9'!M288 -> 0 | T13: =+'9'!M291 -> 0 | U13: =+'9'!M289 -> 520 | V13: =+P13-Q13-R13-S13-T13-U13 -> 2945 | W13: =+'9'!M294 -> 2970 | X13: =+W13-V13 -> 25 | Y13: =+U13+W13+X13 -> 3515
A14: 10 | B14: ชิฟฟ่อนเค้กสอดไส้ เมล่อน (3 ชิ้น) | C14: =+ยกมา!D14 -> 0 | D14: =+'1'!E14+'2'!E14+'3'!E14+'4'!E14+'5'!E14+'6'!E14+'7'!E14+'8'!E14+'9'!E14+'10'!E14+'11'!E14+'12'!E14+'13'!E14+'14'!E14+'15'!E14+'16'!E14+'17'!E14+'18'!E14+'19'!E14+'20'!E14+'21'!E14+'22'!E14+'23'!E14+'24'!E14+'25'!E14+'26'!E14+'27'!E14+'28'!E14+'29'!E14+'30'!E14+'31.'!E14 -> 0 | E14: =+C14+D14 -> 0 | F14: =+'1'!G14+'2'!G14+'3'!G14+'4'!G14+'5'!G14+'6'!G14+'7'!G14+'8'!G14+'9'!G14+'10'!G14+'11'!G14+'12'!G14+'13'!G14+'14'!G14+'15'!G14+'16'!G14+'17'!G14+'18'!G14+'19'!G14+'20'!G14+'21'!G14+'22'!G14+'23'!G14+'24'!G14+'25'!G14+'26'!G14+'27'!G14+'28'!G14+'29'!G14+'30'!G14+'31.'!G14 -> 0 | G14: =+'1'!H14+'2'!H14+'3'!H14+'4'!H14+'5'!H14+'6'!H14+'7'!H14+'8'!H14+'9'!H14+'10'!H14+'11'!H14+'12'!H14+'13'!H14+'14'!H14+'15'!H14+'16'!H14+'17'!H14+'18'!H14+'19'!H14+'20'!H14+'21'!H14+'22'!H14+'23'!H14+'24'!H14+'25'!H14+'26'!H14+'27'!H14+'28'!H14+'29'!H14+'30'!H14+'31.'!H14 -> 0 | H14: =+C14+D14-F14-G14-I14 -> 0 | I14: =+'1'!J14+'2'!J14+'3'!J14+'4'!J14+'5'!J14+'6'!J14+'7'!J14+'8'!J14+'9'!J14+'10'!J14+'11'!J14+'12'!J14+'13'!J14+'14'!J14+'15'!J14+'16'!J14+'17'!J14+'18'!J14+'19'!J14+'20'!J14+'21'!J14+'22'!J14+'23'!J14+'24'!J14+'25'!J14+'26'!J14+'27'!J14+'28'!J14+'29'!J14+'30'!J14+'31.'!J14 -> 0 | J14: 50 | K14: =+'1'!L14+'2'!L14+'3'!L14+'4'!L14+'5'!L14+'6'!L14+'7'!L14+'8'!L14+'9'!L14+'10'!L14+'11'!L14+'12'!L14+'13'!L14+'14'!L14+'15'!L14+'16'!L14+'17'!L14+'18'!L14+'19'!L14+'20'!L14+'21'!L14+'22'!L14+'23'!L14+'24'!L14+'25'!L14+'26'!L14+'27'!L14+'28'!L14+'29'!L14+'30'!L14+'31.'!L14 -> 0 | N14: =+I14*M14 -> 0 | O14: 10 | P14: =+'10'!M287 -> 7555 | Q14: =+'10'!M292 -> 490 | R14: =+'10'!M290 -> 0 | S14: =+'10'!M288 -> 0 | T14: =+'10'!M291 -> 0 | U14: =+'10'!M289 -> 3030 | V14: =+P14-Q14-R14-S14-T14-U14 -> 4035 | W14: =+'10'!M294 -> 4035 | X14: =+W14-V14 -> 0 | Y14: =+U14+W14+X14 -> 7065
A15: 11 | B15: ชิฟฟ่อนเค้กสอดไส้แยม รสบลูเบอร์รี่ (3 ชิ้น) | C15: =+ยกมา!D15 -> 0 | D15: =+'1'!E15+'2'!E15+'3'!E15+'4'!E15+'5'!E15+'6'!E15+'7'!E15+'8'!E15+'9'!E15+'10'!E15+'11'!E15+'12'!E15+'13'!E15+'14'!E15+'15'!E15+'16'!E15+'17'!E15+'18'!E15+'19'!E15+'20'!E15+'21'!E15+'22'!E15+'23'!E15+'24'!E15+'25'!E15+'26'!E15+'27'!E15+'28'!E15+'29'!E15+'30'!E15+'31.'!E15 -> 0 | E15: =+C15+D15 -> 0 | F15: =+'1'!G15+'2'!G15+'3'!G15+'4'!G15+'5'!G15+'6'!G15+'7'!G15+'8'!G15+'9'!G15+'10'!G15+'11'!G15+'12'!G15+'13'!G15+'14'!G15+'15'!G15+'16'!G15+'17'!G15+'18'!G15+'19'!G15+'20'!G15+'21'!G15+'22'!G15+'23'!G15+'24'!G15+'25'!G15+'26'!G15+'27'!G15+'28'!G15+'29'!G15+'30'!G15+'31.'!G15 -> 0 | G15: =+'1'!H15+'2'!H15+'3'!H15+'4'!H15+'5'!H15+'6'!H15+'7'!H15+'8'!H15+'9'!H15+'10'!H15+'11'!H15+'12'!H15+'13'!H15+'14'!H15+'15'!H15+'16'!H15+'17'!H15+'18'!H15+'19'!H15+'20'!H15+'21'!H15+'22'!H15+'23'!H15+'24'!H15+'25'!H15+'26'!H15+'27'!H15+'28'!H15+'29'!H15+'30'!H15+'31.'!H15 -> 0 | H15: =+C15+D15-F15-G15-I15 -> 0 | I15: =+'1'!J15+'2'!J15+'3'!J15+'4'!J15+'5'!J15+'6'!J15+'7'!J15+'8'!J15+'9'!J15+'10'!J15+'11'!J15+'12'!J15+'13'!J15+'14'!J15+'15'!J15+'16'!J15+'17'!J15+'18'!J15+'19'!J15+'20'!J15+'21'!J15+'22'!J15+'23'!J15+'24'!J15+'25'!J15+'26'!J15+'27'!J15+'28'!J15+'29'!J15+'30'!J15+'31.'!J15 -> 0 | J15: 50 | K15: =+'1'!L15+'2'!L15+'3'!L15+'4'!L15+'5'!L15+'6'!L15+'7'!L15+'8'!L15+'9'!L15+'10'!L15+'11'!L15+'12'!L15+'13'!L15+'14'!L15+'15'!L15+'16'!L15+'17'!L15+'18'!L15+'19'!L15+'20'!L15+'21'!L15+'22'!L15+'23'!L15+'24'!L15+'25'!L15+'26'!L15+'27'!L15+'28'!L15+'29'!L15+'30'!L15+'31.'!L15 -> 0 | M15: 17.32 | N15: =+I15*M15 -> 0 | O15: 11 | P15: =+'11'!M287 -> 9845 | Q15: =+'11'!M292 -> 1515 | R15: =+'11'!M290 -> 0 | S15: =+'11'!M288 -> 0 | T15: =+'11'!M291 -> 0 | U15: =+'11'!M289 -> 2045 | V15: =+P15-Q15-R15-S15-T15-U15 -> 6285 | W15: =+'11'!M294 -> 6285 | X15: =+W15-V15 -> 0 | Y15: =+U15+W15+X15 -> 8330
A16: 12 | B16: ชิฟฟ่อนเค้กสอดไส้แยม รสส้ม (3 ชิ้น) | C16: =+ยกมา!D16 -> 5 | D16: =+'1'!E16+'2'!E16+'3'!E16+'4'!E16+'5'!E16+'6'!E16+'7'!E16+'8'!E16+'9'!E16+'10'!E16+'11'!E16+'12'!E16+'13'!E16+'14'!E16+'15'!E16+'16'!E16+'17'!E16+'18'!E16+'19'!E16+'20'!E16+'21'!E16+'22'!E16+'23'!E16+'24'!E16+'25'!E16+'26'!E16+'27'!E16+'28'!E16+'29'!E16+'30'!E16+'31.'!E16 -> 30 | E16: =+C16+D16 -> 35 | F16: =+'1'!G16+'2'!G16+'3'!G16+'4'!G16+'5'!G16+'6'!G16+'7'!G16+'8'!G16+'9'!G16+'10'!G16+'11'!G16+'12'!G16+'13'!G16+'14'!G16+'15'!G16+'16'!G16+'17'!G16+'18'!G16+'19'!G16+'20'!G16+'21'!G16+'22'!G16+'23'!G16+'24'!G16+'25'!G16+'26'!G16+'27'!G16+'28'!G16+'29'!G16+'30'!G16+'31.'!G16 -> 0 | G16: =+'1'!H16+'2'!H16+'3'!H16+'4'!H16+'5'!H16+'6'!H16+'7'!H16+'8'!H16+'9'!H16+'10'!H16+'11'!H16+'12'!H16+'13'!H16+'14'!H16+'15'!H16+'16'!H16+'17'!H16+'18'!H16+'19'!H16+'20'!H16+'21'!H16+'22'!H16+'23'!H16+'24'!H16+'25'!H16+'26'!H16+'27'!H16+'28'!H16+'29'!H16+'30'!H16+'31.'!H16 -> 0 | H16: =+C16+D16-F16-G16-I16 -> 8 | I16: =+'1'!J16+'2'!J16+'3'!J16+'4'!J16+'5'!J16+'6'!J16+'7'!J16+'8'!J16+'9'!J16+'10'!J16+'11'!J16+'12'!J16+'13'!J16+'14'!J16+'15'!J16+'16'!J16+'17'!J16+'18'!J16+'19'!J16+'20'!J16+'21'!J16+'22'!J16+'23'!J16+'24'!J16+'25'!J16+'26'!J16+'27'!J16+'28'!J16+'29'!J16+'30'!J16+'31.'!J16 -> 27 | J16: 50 | K16: =+'1'!L16+'2'!L16+'3'!L16+'4'!L16+'5'!L16+'6'!L16+'7'!L16+'8'!L16+'9'!L16+'10'!L16+'11'!L16+'12'!L16+'13'!L16+'14'!L16+'15'!L16+'16'!L16+'17'!L16+'18'!L16+'19'!L16+'20'!L16+'21'!L16+'22'!L16+'23'!L16+'24'!L16+'25'!L16+'26'!L16+'27'!L16+'28'!L16+'29'!L16+'30'!L16+'31.'!L16 -> 1350 | M16: 16.92 | N16: =+I16*M16 -> 456.84 | O16: 12 | P16: =+'12'!M287 -> 5090 | Q16: =+'12'!M292 -> 205 | R16: =+'12'!M290 -> 0 | S16: =+'12'!M288 -> 0 | T16: =+'12'!M291 -> 0 | U16: =+'12'!M289 -> 1405 | V16: =+P16-Q16-R16-S16-T16-U16 -> 3480 | W16: =+'12'!M294 -> 3480 | X16: =+W16-V16 -> 0 | Y16: =+U16+W16+X16 -> 4885
A17: 13 | B17: ชิฟฟ่อนเค้กหน้าฝอยทอง สอดไส้แยมส้ม (3 ชิ้น) | C17: =+ยกมา!D17 -> 17 | D17: =+'1'!E17+'2'!E17+'3'!E17+'4'!E17+'5'!E17+'6'!E17+'7'!E17+'8'!E17+'9'!E17+'10'!E17+'11'!E17+'12'!E17+'13'!E17+'14'!E17+'15'!E17+'16'!E17+'17'!E17+'18'!E17+'19'!E17+'20'!E17+'21'!E17+'22'!E17+'23'!E17+'24'!E17+'25'!E17+'26'!E17+'27'!E17+'28'!E17+'29'!E17+'30'!E17+'31.'!E17 -> 25 | E17: =+C17+D17 -> 42 | F17: =+'1'!G17+'2'!G17+'3'!G17+'4'!G17+'5'!G17+'6'!G17+'7'!G17+'8'!G17+'9'!G17+'10'!G17+'11'!G17+'12'!G17+'13'!G17+'14'!G17+'15'!G17+'16'!G17+'17'!G17+'18'!G17+'19'!G17+'20'!G17+'21'!G17+'22'!G17+'23'!G17+'24'!G17+'25'!G17+'26'!G17+'27'!G17+'28'!G17+'29'!G17+'30'!G17+'31.'!G17 -> 0 | G17: =+'1'!H17+'2'!H17+'3'!H17+'4'!H17+'5'!H17+'6'!H17+'7'!H17+'8'!H17+'9'!H17+'10'!H17+'11'!H17+'12'!H17+'13'!H17+'14'!H17+'15'!H17+'16'!H17+'17'!H17+'18'!H17+'19'!H17+'20'!H17+'21'!H17+'22'!H17+'23'!H17+'24'!H17+'25'!H17+'26'!H17+'27'!H17+'28'!H17+'29'!H17+'30'!H17+'31.'!H17 -> 0 | H17: =+C17+D17-F17-G17-I17 -> 7 | I17: =+'1'!J17+'2'!J17+'3'!J17+'4'!J17+'5'!J17+'6'!J17+'7'!J17+'8'!J17+'9'!J17+'10'!J17+'11'!J17+'12'!J17+'13'!J17+'14'!J17+'15'!J17+'16'!J17+'17'!J17+'18'!J17+'19'!J17+'20'!J17+'21'!J17+'22'!J17+'23'!J17+'24'!J17+'25'!J17+'26'!J17+'27'!J17+'28'!J17+'29'!J17+'30'!J17+'31.'!J17 -> 35 | J17: 50 | K17: =+'1'!L17+'2'!L17+'3'!L17+'4'!L17+'5'!L17+'6'!L17+'7'!L17+'8'!L17+'9'!L17+'10'!L17+'11'!L17+'12'!L17+'13'!L17+'14'!L17+'15'!L17+'16'!L17+'17'!L17+'18'!L17+'19'!L17+'20'!L17+'21'!L17+'22'!L17+'23'!L17+'24'!L17+'25'!L17+'26'!L17+'27'!L17+'28'!L17+'29'!L17+'30'!L17+'31.'!L17 -> 1750 | M17: 21.22 | N17: =+I17*M17 -> 742.7 | O17: 13 | P17: =+'13'!M287 -> 3525 | Q17: =+'13'!M292 -> 530 | R17: =+'13'!M290 -> 0 | S17: =+'13'!M288 -> 0 | T17: =+'13'!M291 -> 0 | U17: =+'13'!M289 -> 480 | V17: =+P17-Q17-R17-S17-T17-U17 -> 2515 | W17: =+'13'!M294 -> 2515 | X17: =+W17-V17 -> 0 | Y17: =+U17+W17+X17 -> 2995
A18: 14 | B18: ชิฟฟ่อนเค้กหน้าฝอยทองทูโทน สอดไส้แยมส้ม (3 ชิ้น) | C18: =+ยกมา!D18 -> 0 | D18: =+'1'!E18+'2'!E18+'3'!E18+'4'!E18+'5'!E18+'6'!E18+'7'!E18+'8'!E18+'9'!E18+'10'!E18+'11'!E18+'12'!E18+'13'!E18+'14'!E18+'15'!E18+'16'!E18+'17'!E18+'18'!E18+'19'!E18+'20'!E18+'21'!E18+'22'!E18+'23'!E18+'24'!E18+'25'!E18+'26'!E18+'27'!E18+'28'!E18+'29'!E18+'30'!E18+'31.'!E18 -> 0 | E18: =+C18+D18 -> 0 | F18: =+'1'!G18+'2'!G18+'3'!G18+'4'!G18+'5'!G18+'6'!G18+'7'!G18+'8'!G18+'9'!G18+'10'!G18+'11'!G18+'12'!G18+'13'!G18+'14'!G18+'15'!G18+'16'!G18+'17'!G18+'18'!G18+'19'!G18+'20'!G18+'21'!G18+'22'!G18+'23'!G18+'24'!G18+'25'!G18+'26'!G18+'27'!G18+'28'!G18+'29'!G18+'30'!G18+'31.'!G18 -> 0 | G18: =+'1'!H18+'2'!H18+'3'!H18+'4'!H18+'5'!H18+'6'!H18+'7'!H18+'8'!H18+'9'!H18+'10'!H18+'11'!H18+'12'!H18+'13'!H18+'14'!H18+'15'!H18+'16'!H18+'17'!H18+'18'!H18+'19'!H18+'20'!H18+'21'!H18+'22'!H18+'23'!H18+'24'!H18+'25'!H18+'26'!H18+'27'!H18+'28'!H18+'29'!H18+'30'!H18+'31.'!H18 -> 0 | H18: =+C18+D18-F18-G18-I18 -> 0 | I18: =+'1'!J18+'2'!J18+'3'!J18+'4'!J18+'5'!J18+'6'!J18+'7'!J18+'8'!J18+'9'!J18+'10'!J18+'11'!J18+'12'!J18+'13'!J18+'14'!J18+'15'!J18+'16'!J18+'17'!J18+'18'!J18+'19'!J18+'20'!J18+'21'!J18+'22'!J18+'23'!J18+'24'!J18+'25'!J18+'26'!J18+'27'!J18+'28'!J18+'29'!J18+'30'!J18+'31.'!J18 -> 0 | J18: 50 | K18: =+'1'!L18+'2'!L18+'3'!L18+'4'!L18+'5'!L18+'6'!L18+'7'!L18+'8'!L18+'9'!L18+'10'!L18+'11'!L18+'12'!L18+'13'!L18+'14'!L18+'15'!L18+'16'!L18+'17'!L18+'18'!L18+'19'!L18+'20'!L18+'21'!L18+'22'!L18+'23'!L18+'24'!L18+'25'!L18+'26'!L18+'27'!L18+'28'!L18+'29'!L18+'30'!L18+'31.'!L18 -> 0 | N18: =+I18*M18 -> 0 | O18: 14 | P18: =+'14'!M287 -> 3760 | Q18: =+'14'!M292 -> 550 | R18: =+'14'!M290 -> 0 | S18: =+'14'!M288 -> 0 | T18: =+'14'!M291 -> 0 | U18: =+'14'!M289 -> 1260 | V18: =+P18-Q18-R18-S18-T18-U18 -> 1950 | W18: =+'14'!M294 -> 1950 | X18: =+W18-V18 -> 0 | Y18: =+U18+W18+X18 -> 3210
A19: 15 | B19: ชิฟฟ่อนเค้กสอดไส้แยม รสสตรอว์เบอรี่ (3 ชิ้น) | C19: =+ยกมา!D19 -> 0 | D19: =+'1'!E19+'2'!E19+'3'!E19+'4'!E19+'5'!E19+'6'!E19+'7'!E19+'8'!E19+'9'!E19+'10'!E19+'11'!E19+'12'!E19+'13'!E19+'14'!E19+'15'!E19+'16'!E19+'17'!E19+'18'!E19+'19'!E19+'20'!E19+'21'!E19+'22'!E19+'23'!E19+'24'!E19+'25'!E19+'26'!E19+'27'!E19+'28'!E19+'29'!E19+'30'!E19+'31.'!E19 -> 0 | E19: =+C19+D19 -> 0 | F19: =+'1'!G19+'2'!G19+'3'!G19+'4'!G19+'5'!G19+'6'!G19+'7'!G19+'8'!G19+'9'!G19+'10'!G19+'11'!G19+'12'!G19+'13'!G19+'14'!G19+'15'!G19+'16'!G19+'17'!G19+'18'!G19+'19'!G19+'20'!G19+'21'!G19+'22'!G19+'23'!G19+'24'!G19+'25'!G19+'26'!G19+'27'!G19+'28'!G19+'29'!G19+'30'!G19+'31.'!G19 -> 0 | G19: =+'1'!H19+'2'!H19+'3'!H19+'4'!H19+'5'!H19+'6'!H19+'7'!H19+'8'!H19+'9'!H19+'10'!H19+'11'!H19+'12'!H19+'13'!H19+'14'!H19+'15'!H19+'16'!H19+'17'!H19+'18'!H19+'19'!H19+'20'!H19+'21'!H19+'22'!H19+'23'!H19+'24'!H19+'25'!H19+'26'!H19+'27'!H19+'28'!H19+'29'!H19+'30'!H19+'31.'!H19 -> 0 | H19: =+C19+D19-F19-G19-I19 -> 0 | I19: =+'1'!J19+'2'!J19+'3'!J19+'4'!J19+'5'!J19+'6'!J19+'7'!J19+'8'!J19+'9'!J19+'10'!J19+'11'!J19+'12'!J19+'13'!J19+'14'!J19+'15'!J19+'16'!J19+'17'!J19+'18'!J19+'19'!J19+'20'!J19+'21'!J19+'22'!J19+'23'!J19+'24'!J19+'25'!J19+'26'!J19+'27'!J19+'28'!J19+'29'!J19+'30'!J19+'31.'!J19 -> 0 | J19: 50 | K19: =+'1'!L19+'2'!L19+'3'!L19+'4'!L19+'5'!L19+'6'!L19+'7'!L19+'8'!L19+'9'!L19+'10'!L19+'11'!L19+'12'!L19+'13'!L19+'14'!L19+'15'!L19+'16'!L19+'17'!L19+'18'!L19+'19'!L19+'20'!L19+'21'!L19+'22'!L19+'23'!L19+'24'!L19+'25'!L19+'26'!L19+'27'!L19+'28'!L19+'29'!L19+'30'!L19+'31.'!L19 -> 0 | M19: 15.05 | N19: =+I19*M19 -> 0 | O19: 15 | P19: =+'15'!M287 -> 2680 | Q19: =+'15'!M292 -> 840 | R19: =+'15'!M290 -> 0 | S19: =+'15'!M288 -> 0 | T19: =+'15'!M291 -> 0 | U19: =+'15'!M289 -> 420 | V19: =+P19-Q19-R19-S19-T19-U19 -> 1420 | W19: =+'15'!M294 -> 1420 | X19: =+W19-V19 -> 0 | Y19: =+U19+W19+X19 -> 1840
A20: 16 | B20: ชิฟฟ่อนเค้กสอดไส้เนย รสมะพร้าว (3 ชิ้น) | C20: =+ยกมา!D20 -> 1 | D20: =+'1'!E20+'2'!E20+'3'!E20+'4'!E20+'5'!E20+'6'!E20+'7'!E20+'8'!E20+'9'!E20+'10'!E20+'11'!E20+'12'!E20+'13'!E20+'14'!E20+'15'!E20+'16'!E20+'17'!E20+'18'!E20+'19'!E20+'20'!E20+'21'!E20+'22'!E20+'23'!E20+'24'!E20+'25'!E20+'26'!E20+'27'!E20+'28'!E20+'29'!E20+'30'!E20+'31.'!E20 -> 30 | E20: =+C20+D20 -> 31 | F20: =+'1'!G20+'2'!G20+'3'!G20+'4'!G20+'5'!G20+'6'!G20+'7'!G20+'8'!G20+'9'!G20+'10'!G20+'11'!G20+'12'!G20+'13'!G20+'14'!G20+'15'!G20+'16'!G20+'17'!G20+'18'!G20+'19'!G20+'20'!G20+'21'!G20+'22'!G20+'23'!G20+'24'!G20+'25'!G20+'26'!G20+'27'!G20+'28'!G20+'29'!G20+'30'!G20+'31.'!G20 -> 0 | G20: =+'1'!H20+'2'!H20+'3'!H20+'4'!H20+'5'!H20+'6'!H20+'7'!H20+'8'!H20+'9'!H20+'10'!H20+'11'!H20+'12'!H20+'13'!H20+'14'!H20+'15'!H20+'16'!H20+'17'!H20+'18'!H20+'19'!H20+'20'!H20+'21'!H20+'22'!H20+'23'!H20+'24'!H20+'25'!H20+'26'!H20+'27'!H20+'28'!H20+'29'!H20+'30'!H20+'31.'!H20 -> 0 | H20: =+C20+D20-F20-G20-I20 -> 13 | I20: =+'1'!J20+'2'!J20+'3'!J20+'4'!J20+'5'!J20+'6'!J20+'7'!J20+'8'!J20+'9'!J20+'10'!J20+'11'!J20+'12'!J20+'13'!J20+'14'!J20+'15'!J20+'16'!J20+'17'!J20+'18'!J20+'19'!J20+'20'!J20+'21'!J20+'22'!J20+'23'!J20+'24'!J20+'25'!J20+'26'!J20+'27'!J20+'28'!J20+'29'!J20+'30'!J20+'31.'!J20 -> 18 | J20: 50 | K20: =+'1'!L20+'2'!L20+'3'!L20+'4'!L20+'5'!L20+'6'!L20+'7'!L20+'8'!L20+'9'!L20+'10'!L20+'11'!L20+'12'!L20+'13'!L20+'14'!L20+'15'!L20+'16'!L20+'17'!L20+'18'!L20+'19'!L20+'20'!L20+'21'!L20+'22'!L20+'23'!L20+'24'!L20+'25'!L20+'26'!L20+'27'!L20+'28'!L20+'29'!L20+'30'!L20+'31.'!L20 -> 900 | M20: 16.7 | N20: =+I20*M20 -> 300.6 | O20: 16 | P20: =+'16'!M287 -> 3385 | Q20: =+'16'!M292 -> 120 | R20: =+'16'!M290 -> 0 | S20: =+'16'!M288 -> 0 | T20: =+'16'!M291 -> 0 | U20: =+'16'!M289 -> 1145 | V20: =+P20-Q20-R20-S20-T20-U20 -> 2120 | W20: =+'16'!M294 -> 2120 | X20: =+W20-V20 -> 0 | Y20: =+U20+W20+X20 -> 3265
A21: 17 | B21: ชิฟฟ่อนเค้กสอดไส้ นมชมพูฮอกไกโด (3 ชิ้น) | C21: =+ยกมา!D21 -> 0 | D21: =+'1'!E21+'2'!E21+'3'!E21+'4'!E21+'5'!E21+'6'!E21+'7'!E21+'8'!E21+'9'!E21+'10'!E21+'11'!E21+'12'!E21+'13'!E21+'14'!E21+'15'!E21+'16'!E21+'17'!E21+'18'!E21+'19'!E21+'20'!E21+'21'!E21+'22'!E21+'23'!E21+'24'!E21+'25'!E21+'26'!E21+'27'!E21+'28'!E21+'29'!E21+'30'!E21+'31.'!E21 -> 0 | E21: =+C21+D21 -> 0 | F21: =+'1'!G21+'2'!G21+'3'!G21+'4'!G21+'5'!G21+'6'!G21+'7'!G21+'8'!G21+'9'!G21+'10'!G21+'11'!G21+'12'!G21+'13'!G21+'14'!G21+'15'!G21+'16'!G21+'17'!G21+'18'!G21+'19'!G21+'20'!G21+'21'!G21+'22'!G21+'23'!G21+'24'!G21+'25'!G21+'26'!G21+'27'!G21+'28'!G21+'29'!G21+'30'!G21+'31.'!G21 -> 0 | G21: =+'1'!H21+'2'!H21+'3'!H21+'4'!H21+'5'!H21+'6'!H21+'7'!H21+'8'!H21+'9'!H21+'10'!H21+'11'!H21+'12'!H21+'13'!H21+'14'!H21+'15'!H21+'16'!H21+'17'!H21+'18'!H21+'19'!H21+'20'!H21+'21'!H21+'22'!H21+'23'!H21+'24'!H21+'25'!H21+'26'!H21+'27'!H21+'28'!H21+'29'!H21+'30'!H21+'31.'!H21 -> 0 | H21: =+C21+D21-F21-G21-I21 -> 0 | I21: =+'1'!J21+'2'!J21+'3'!J21+'4'!J21+'5'!J21+'6'!J21+'7'!J21+'8'!J21+'9'!J21+'10'!J21+'11'!J21+'12'!J21+'13'!J21+'14'!J21+'15'!J21+'16'!J21+'17'!J21+'18'!J21+'19'!J21+'20'!J21+'21'!J21+'22'!J21+'23'!J21+'24'!J21+'25'!J21+'26'!J21+'27'!J21+'28'!J21+'29'!J21+'30'!J21+'31.'!J21 -> 0 | J21: 50 | K21: =+'1'!L21+'2'!L21+'3'!L21+'4'!L21+'5'!L21+'6'!L21+'7'!L21+'8'!L21+'9'!L21+'10'!L21+'11'!L21+'12'!L21+'13'!L21+'14'!L21+'15'!L21+'16'!L21+'17'!L21+'18'!L21+'19'!L21+'20'!L21+'21'!L21+'22'!L21+'23'!L21+'24'!L21+'25'!L21+'26'!L21+'27'!L21+'28'!L21+'29'!L21+'30'!L21+'31.'!L21 -> 0 | M21: 19.04 | N21: =+I21*M21 -> 0 | O21: 17 | P21: =+'17'!M287 -> 6205 | Q21: =+'17'!M292 -> 1080 | R21: =+'17'!M290 -> 0 | S21: =+'17'!M288 -> 0 | T21: =+'17'!M291 -> 0 | U21: =+'17'!M289 -> 2050 | V21: =+P21-Q21-R21-S21-T21-U21 -> 3075 | W21: =+'17'!M294 -> 3075 | X21: =+W21-V21 -> 0 | Y21: =+U21+W21+X21 -> 5125
A22: 18 | B22: ชิฟฟ่อนเค้กสอดไส้ ช็อคโกแลตนูเทลล่า (3 ชิ้น) | C22: =+ยกมา!D22 -> 0 | D22: =+'1'!E22+'2'!E22+'3'!E22+'4'!E22+'5'!E22+'6'!E22+'7'!E22+'8'!E22+'9'!E22+'10'!E22+'11'!E22+'12'!E22+'13'!E22+'14'!E22+'15'!E22+'16'!E22+'17'!E22+'18'!E22+'19'!E22+'20'!E22+'21'!E22+'22'!E22+'23'!E22+'24'!E22+'25'!E22+'26'!E22+'27'!E22+'28'!E22+'29'!E22+'30'!E22+'31.'!E22 -> 0 | E22: =+C22+D22 -> 0 | F22: =+'1'!G22+'2'!G22+'3'!G22+'4'!G22+'5'!G22+'6'!G22+'7'!G22+'8'!G22+'9'!G22+'10'!G22+'11'!G22+'12'!G22+'13'!G22+'14'!G22+'15'!G22+'16'!G22+'17'!G22+'18'!G22+'19'!G22+'20'!G22+'21'!G22+'22'!G22+'23'!G22+'24'!G22+'25'!G22+'26'!G22+'27'!G22+'28'!G22+'29'!G22+'30'!G22+'31.'!G22 -> 0 | G22: =+'1'!H22+'2'!H22+'3'!H22+'4'!H22+'5'!H22+'6'!H22+'7'!H22+'8'!H22+'9'!H22+'10'!H22+'11'!H22+'12'!H22+'13'!H22+'14'!H22+'15'!H22+'16'!H22+'17'!H22+'18'!H22+'19'!H22+'20'!H22+'21'!H22+'22'!H22+'23'!H22+'24'!H22+'25'!H22+'26'!H22+'27'!H22+'28'!H22+'29'!H22+'30'!H22+'31.'!H22 -> 0 | H22: =+C22+D22-F22-G22-I22 -> 0 | I22: =+'1'!J22+'2'!J22+'3'!J22+'4'!J22+'5'!J22+'6'!J22+'7'!J22+'8'!J22+'9'!J22+'10'!J22+'11'!J22+'12'!J22+'13'!J22+'14'!J22+'15'!J22+'16'!J22+'17'!J22+'18'!J22+'19'!J22+'20'!J22+'21'!J22+'22'!J22+'23'!J22+'24'!J22+'25'!J22+'26'!J22+'27'!J22+'28'!J22+'29'!J22+'30'!J22+'31.'!J22 -> 0 | J22: 50 | K22: =+'1'!L22+'2'!L22+'3'!L22+'4'!L22+'5'!L22+'6'!L22+'7'!L22+'8'!L22+'9'!L22+'10'!L22+'11'!L22+'12'!L22+'13'!L22+'14'!L22+'15'!L22+'16'!L22+'17'!L22+'18'!L22+'19'!L22+'20'!L22+'21'!L22+'22'!L22+'23'!L22+'24'!L22+'25'!L22+'26'!L22+'27'!L22+'28'!L22+'29'!L22+'30'!L22+'31.'!L22 -> 0 | M22: 15.3 | N22: =+I22*M22 -> 0 | O22: 18 | P22: =+'18'!M287 -> 2660 | Q22: =+'18'!M292 -> 230 | R22: =+'18'!M290 -> 0 | S22: =+'18'!M288 -> 0 | T22: =+'17'!M291 -> 0 | U22: =+'18'!M289 -> 735 | V22: =+P22-Q22-R22-S22-T22-U22 -> 1695 | W22: =+'18'!M294 -> 1695 | X22: =+W22-V22 -> 0 | Y22: =+U22+W22+X22 -> 2430
A23: 19 | B23: ชิฟฟ่อน สอดไส้ (ล) 4 ชิ้น ครีมมะพร้าว | C23: =+ยกมา!D23 -> 0 | D23: =+'1'!E23+'2'!E23+'3'!E23+'4'!E23+'5'!E23+'6'!E23+'7'!E23+'8'!E23+'9'!E23+'10'!E23+'11'!E23+'12'!E23+'13'!E23+'14'!E23+'15'!E23+'16'!E23+'17'!E23+'18'!E23+'19'!E23+'20'!E23+'21'!E23+'22'!E23+'23'!E23+'24'!E23+'25'!E23+'26'!E23+'27'!E23+'28'!E23+'29'!E23+'30'!E23+'31.'!E23 -> 0 | E23: =+C23+D23 -> 0 | F23: =+'1'!G23+'2'!G23+'3'!G23+'4'!G23+'5'!G23+'6'!G23+'7'!G23+'8'!G23+'9'!G23+'10'!G23+'11'!G23+'12'!G23+'13'!G23+'14'!G23+'15'!G23+'16'!G23+'17'!G23+'18'!G23+'19'!G23+'20'!G23+'21'!G23+'22'!G23+'23'!G23+'24'!G23+'25'!G23+'26'!G23+'27'!G23+'28'!G23+'29'!G23+'30'!G23+'31.'!G23 -> 0 | G23: =+'1'!H23+'2'!H23+'3'!H23+'4'!H23+'5'!H23+'6'!H23+'7'!H23+'8'!H23+'9'!H23+'10'!H23+'11'!H23+'12'!H23+'13'!H23+'14'!H23+'15'!H23+'16'!H23+'17'!H23+'18'!H23+'19'!H23+'20'!H23+'21'!H23+'22'!H23+'23'!H23+'24'!H23+'25'!H23+'26'!H23+'27'!H23+'28'!H23+'29'!H23+'30'!H23+'31.'!H23 -> 0 | H23: =+C23+D23-F23-G23-I23 -> 0 | I23: =+'1'!J23+'2'!J23+'3'!J23+'4'!J23+'5'!J23+'6'!J23+'7'!J23+'8'!J23+'9'!J23+'10'!J23+'11'!J23+'12'!J23+'13'!J23+'14'!J23+'15'!J23+'16'!J23+'17'!J23+'18'!J23+'19'!J23+'20'!J23+'21'!J23+'22'!J23+'23'!J23+'24'!J23+'25'!J23+'26'!J23+'27'!J23+'28'!J23+'29'!J23+'30'!J23+'31.'!J23 -> 0 | J23: 65 | K23: =+'1'!L23+'2'!L23+'3'!L23+'4'!L23+'5'!L23+'6'!L23+'7'!L23+'8'!L23+'9'!L23+'10'!L23+'11'!L23+'12'!L23+'13'!L23+'14'!L23+'15'!L23+'16'!L23+'17'!L23+'18'!L23+'19'!L23+'20'!L23+'21'!L23+'22'!L23+'23'!L23+'24'!L23+'25'!L23+'26'!L23+'27'!L23+'28'!L23+'29'!L23+'30'!L23+'31.'!L23 -> 0 | M23: 27.86 | N23: =+I23*M23 -> 0 | O23: 19 | P23: =+'19'!M287 -> 3610 | Q23: =+'19'!M292 -> 565 | R23: =+'19'!M290 -> 0 | S23: =+'19'!M288 -> 0 | T23: =+'19'!M291 -> 0 | U23: =+'19'!M289 -> 235 | V23: =+P23-Q23-R23-S23-T23-U23 -> 2810 | W23: =+'19'!M294 -> 2810 | X23: =+W23-V23 -> 0 | Y23: =+U23+W23+X23 -> 3045
A24: 20 | B24: ชิฟฟ่อน สอดไส้ (ก) 5 ชิ้น ครีมมะพร้าว | C24: =+ยกมา!D24 -> 6 | D24: =+'1'!E24+'2'!E24+'3'!E24+'4'!E24+'5'!E24+'6'!E24+'7'!E24+'8'!E24+'9'!E24+'10'!E24+'11'!E24+'12'!E24+'13'!E24+'14'!E24+'15'!E24+'16'!E24+'17'!E24+'18'!E24+'19'!E24+'20'!E24+'21'!E24+'22'!E24+'23'!E24+'24'!E24+'25'!E24+'26'!E24+'27'!E24+'28'!E24+'29'!E24+'30'!E24+'31.'!E24 -> 24 | E24: =+C24+D24 -> 30 | F24: =+'1'!G24+'2'!G24+'3'!G24+'4'!G24+'5'!G24+'6'!G24+'7'!G24+'8'!G24+'9'!G24+'10'!G24+'11'!G24+'12'!G24+'13'!G24+'14'!G24+'15'!G24+'16'!G24+'17'!G24+'18'!G24+'19'!G24+'20'!G24+'21'!G24+'22'!G24+'23'!G24+'24'!G24+'25'!G24+'26'!G24+'27'!G24+'28'!G24+'29'!G24+'30'!G24+'31.'!G24 -> 2 | G24: =+'1'!H24+'2'!H24+'3'!H24+'4'!H24+'5'!H24+'6'!H24+'7'!H24+'8'!H24+'9'!H24+'10'!H24+'11'!H24+'12'!H24+'13'!H24+'14'!H24+'15'!H24+'16'!H24+'17'!H24+'18'!H24+'19'!H24+'20'!H24+'21'!H24+'22'!H24+'23'!H24+'24'!H24+'25'!H24+'26'!H24+'27'!H24+'28'!H24+'29'!H24+'30'!H24+'31.'!H24 -> 0 | H24: =+C24+D24-F24-G24-I24 -> 5 | I24: =+'1'!J24+'2'!J24+'3'!J24+'4'!J24+'5'!J24+'6'!J24+'7'!J24+'8'!J24+'9'!J24+'10'!J24+'11'!J24+'12'!J24+'13'!J24+'14'!J24+'15'!J24+'16'!J24+'17'!J24+'18'!J24+'19'!J24+'20'!J24+'21'!J24+'22'!J24+'23'!J24+'24'!J24+'25'!J24+'26'!J24+'27'!J24+'28'!J24+'29'!J24+'30'!J24+'31.'!J24 -> 23 | J24: 85 | K24: =+'1'!L24+'2'!L24+'3'!L24+'4'!L24+'5'!L24+'6'!L24+'7'!L24+'8'!L24+'9'!L24+'10'!L24+'11'!L24+'12'!L24+'13'!L24+'14'!L24+'15'!L24+'16'!L24+'17'!L24+'18'!L24+'19'!L24+'20'!L24+'21'!L24+'22'!L24+'23'!L24+'24'!L24+'25'!L24+'26'!L24+'27'!L24+'28'!L24+'29'!L24+'30'!L24+'31.'!L24 -> 1955 | M24: 26.91 | N24: =+I24*M24 -> 618.93 | O24: 20 | P24: =+'20'!M287 -> 2935 | Q24: =+'20'!M292 -> 640 | R24: =+'20'!M290 -> 0 | S24: =+'20'!M288 -> 0 | T24: =+'20'!M291 -> 0 | U24: =+'20'!M289 -> 910 | V24: =+P24-Q24-R24-S24-T24-U24 -> 1385 | W24: =+'20'!M294 -> 1385 | X24: =+W24-V24 -> 0 | Y24: =+U24+W24+X24 -> 2295
A25: 21 | B25: ชิฟฟ่อนเค้กสอดไส้ รวมรส (6 ชิ้น) | C25: =+ยกมา!D25 -> 50 | D25: =+'1'!E25+'2'!E25+'3'!E25+'4'!E25+'5'!E25+'6'!E25+'7'!E25+'8'!E25+'9'!E25+'10'!E25+'11'!E25+'12'!E25+'13'!E25+'14'!E25+'15'!E25+'16'!E25+'17'!E25+'18'!E25+'19'!E25+'20'!E25+'21'!E25+'22'!E25+'23'!E25+'24'!E25+'25'!E25+'26'!E25+'27'!E25+'28'!E25+'29'!E25+'30'!E25+'31.'!E25 -> 148 | E25: =+C25+D25 -> 198 | F25: =+'1'!G25+'2'!G25+'3'!G25+'4'!G25+'5'!G25+'6'!G25+'7'!G25+'8'!G25+'9'!G25+'10'!G25+'11'!G25+'12'!G25+'13'!G25+'14'!G25+'15'!G25+'16'!G25+'17'!G25+'18'!G25+'19'!G25+'20'!G25+'21'!G25+'22'!G25+'23'!G25+'24'!G25+'25'!G25+'26'!G25+'27'!G25+'28'!G25+'29'!G25+'30'!G25+'31.'!G25 -> 0 | G25: =+'1'!H25+'2'!H25+'3'!H25+'4'!H25+'5'!H25+'6'!H25+'7'!H25+'8'!H25+'9'!H25+'10'!H25+'11'!H25+'12'!H25+'13'!H25+'14'!H25+'15'!H25+'16'!H25+'17'!H25+'18'!H25+'19'!H25+'20'!H25+'21'!H25+'22'!H25+'23'!H25+'24'!H25+'25'!H25+'26'!H25+'27'!H25+'28'!H25+'29'!H25+'30'!H25+'31.'!H25 -> 10 | H25: =+C25+D25-F25-G25-I25 -> 44 | I25: =+'1'!J25+'2'!J25+'3'!J25+'4'!J25+'5'!J25+'6'!J25+'7'!J25+'8'!J25+'9'!J25+'10'!J25+'11'!J25+'12'!J25+'13'!J25+'14'!J25+'15'!J25+'16'!J25+'17'!J25+'18'!J25+'19'!J25+'20'!J25+'21'!J25+'22'!J25+'23'!J25+'24'!J25+'25'!J25+'26'!J25+'27'!J25+'28'!J25+'29'!J25+'30'!J25+'31.'!J25 -> 144 | J25: 100 | K25: =+'1'!L25+'2'!L25+'3'!L25+'4'!L25+'5'!L25+'6'!L25+'7'!L25+'8'!L25+'9'!L25+'10'!L25+'11'!L25+'12'!L25+'13'!L25+'14'!L25+'15'!L25+'16'!L25+'17'!L25+'18'!L25+'19'!L25+'20'!L25+'21'!L25+'22'!L25+'23'!L25+'24'!L25+'25'!L25+'26'!L25+'27'!L25+'28'!L25+'29'!L25+'30'!L25+'31.'!L25 -> 14400 | M25: 24.8 | N25: =+I25*M25 -> 3571.2 | O25: 21 | P25: =+'21'!M287 -> 1745 | Q25: =+'21'!M292 -> 240 | R25: =+'21'!M290 -> 0 | S25: =+'21'!M288 -> 0 | T25: =+'21'!M291 -> 0 | U25: =+'21'!M289 -> 550 | V25: =+P25-Q25-R25-S25-T25-U25 -> 955 | W25: =+'21'!M294 -> 955 | X25: =+W25-V25 -> 0 | Y25: =+U25+W25+X25 -> 1505
A26: 22 | B26: ชิฟฟ่อนเค้กสอดไส้แยม รสส้ม (6 ชิ้น) | C26: =+ยกมา!D26 -> 0 | D26: =+'1'!E26+'2'!E26+'3'!E26+'4'!E26+'5'!E26+'6'!E26+'7'!E26+'8'!E26+'9'!E26+'10'!E26+'11'!E26+'12'!E26+'13'!E26+'14'!E26+'15'!E26+'16'!E26+'17'!E26+'18'!E26+'19'!E26+'20'!E26+'21'!E26+'22'!E26+'23'!E26+'24'!E26+'25'!E26+'26'!E26+'27'!E26+'28'!E26+'29'!E26+'30'!E26+'31.'!E26 -> 0 | E26: =+C26+D26 -> 0 | F26: =+'1'!G26+'2'!G26+'3'!G26+'4'!G26+'5'!G26+'6'!G26+'7'!G26+'8'!G26+'9'!G26+'10'!G26+'11'!G26+'12'!G26+'13'!G26+'14'!G26+'15'!G26+'16'!G26+'17'!G26+'18'!G26+'19'!G26+'20'!G26+'21'!G26+'22'!G26+'23'!G26+'24'!G26+'25'!G26+'26'!G26+'27'!G26+'28'!G26+'29'!G26+'30'!G26+'31.'!G26 -> 0 | G26: =+'1'!H26+'2'!H26+'3'!H26+'4'!H26+'5'!H26+'6'!H26+'7'!H26+'8'!H26+'9'!H26+'10'!H26+'11'!H26+'12'!H26+'13'!H26+'14'!H26+'15'!H26+'16'!H26+'17'!H26+'18'!H26+'19'!H26+'20'!H26+'21'!H26+'22'!H26+'23'!H26+'24'!H26+'25'!H26+'26'!H26+'27'!H26+'28'!H26+'29'!H26+'30'!H26+'31.'!H26 -> 0 | H26: =+C26+D26-F26-G26-I26 -> 0 | I26: =+'1'!J26+'2'!J26+'3'!J26+'4'!J26+'5'!J26+'6'!J26+'7'!J26+'8'!J26+'9'!J26+'10'!J26+'11'!J26+'12'!J26+'13'!J26+'14'!J26+'15'!J26+'16'!J26+'17'!J26+'18'!J26+'19'!J26+'20'!J26+'21'!J26+'22'!J26+'23'!J26+'24'!J26+'25'!J26+'26'!J26+'27'!J26+'28'!J26+'29'!J26+'30'!J26+'31.'!J26 -> 0 | J26: 100 | K26: =+'1'!L26+'2'!L26+'3'!L26+'4'!L26+'5'!L26+'6'!L26+'7'!L26+'8'!L26+'9'!L26+'10'!L26+'11'!L26+'12'!L26+'13'!L26+'14'!L26+'15'!L26+'16'!L26+'17'!L26+'18'!L26+'19'!L26+'20'!L26+'21'!L26+'22'!L26+'23'!L26+'24'!L26+'25'!L26+'26'!L26+'27'!L26+'28'!L26+'29'!L26+'30'!L26+'31.'!L26 -> 0 | M26: 23.71 | N26: =+I26*M26 -> 0 | O26: 22 | P26: =+'22'!M287 -> 815 | Q26: =+'22'!M292 -> 75 | R26: =+'22'!M290 -> 0 | S26: =+'22'!M288 -> 0 | T26: =+'22'!M291 -> 0 | U26: =+'22'!M289 -> 615 | V26: =+P26-Q26-R26-S26-T26-U26 -> 125 | W26: =+'22'!M294 -> 125 | X26: =+W26-V26 -> 0 | Y26: =+U26+W26+X26 -> 740
A27: 23 | B27: ชิฟฟ่อนเค้กหน้าฝอยทอง สอดไส้แยมส้ม (6 ชิ้น) | C27: =+ยกมา!D27 -> 34 | D27: =+'1'!E27+'2'!E27+'3'!E27+'4'!E27+'5'!E27+'6'!E27+'7'!E27+'8'!E27+'9'!E27+'10'!E27+'11'!E27+'12'!E27+'13'!E27+'14'!E27+'15'!E27+'16'!E27+'17'!E27+'18'!E27+'19'!E27+'20'!E27+'21'!E27+'22'!E27+'23'!E27+'24'!E27+'25'!E27+'26'!E27+'27'!E27+'28'!E27+'29'!E27+'30'!E27+'31.'!E27 -> 62 | E27: =+C27+D27 -> 96 | F27: =+'1'!G27+'2'!G27+'3'!G27+'4'!G27+'5'!G27+'6'!G27+'7'!G27+'8'!G27+'9'!G27+'10'!G27+'11'!G27+'12'!G27+'13'!G27+'14'!G27+'15'!G27+'16'!G27+'17'!G27+'18'!G27+'19'!G27+'20'!G27+'21'!G27+'22'!G27+'23'!G27+'24'!G27+'25'!G27+'26'!G27+'27'!G27+'28'!G27+'29'!G27+'30'!G27+'31.'!G27 -> 0 | G27: =+'1'!H27+'2'!H27+'3'!H27+'4'!H27+'5'!H27+'6'!H27+'7'!H27+'8'!H27+'9'!H27+'10'!H27+'11'!H27+'12'!H27+'13'!H27+'14'!H27+'15'!H27+'16'!H27+'17'!H27+'18'!H27+'19'!H27+'20'!H27+'21'!H27+'22'!H27+'23'!H27+'24'!H27+'25'!H27+'26'!H27+'27'!H27+'28'!H27+'29'!H27+'30'!H27+'31.'!H27 -> 0 | H27: =+C27+D27-F27-G27-I27 -> 25 | I27: =+'1'!J27+'2'!J27+'3'!J27+'4'!J27+'5'!J27+'6'!J27+'7'!J27+'8'!J27+'9'!J27+'10'!J27+'11'!J27+'12'!J27+'13'!J27+'14'!J27+'15'!J27+'16'!J27+'17'!J27+'18'!J27+'19'!J27+'20'!J27+'21'!J27+'22'!J27+'23'!J27+'24'!J27+'25'!J27+'26'!J27+'27'!J27+'28'!J27+'29'!J27+'30'!J27+'31.'!J27 -> 71 | J27: 100 | K27: =+'1'!L27+'2'!L27+'3'!L27+'4'!L27+'5'!L27+'6'!L27+'7'!L27+'8'!L27+'9'!L27+'10'!L27+'11'!L27+'12'!L27+'13'!L27+'14'!L27+'15'!L27+'16'!L27+'17'!L27+'18'!L27+'19'!L27+'20'!L27+'21'!L27+'22'!L27+'23'!L27+'24'!L27+'25'!L27+'26'!L27+'27'!L27+'28'!L27+'29'!L27+'30'!L27+'31.'!L27 -> 7100 | M27: 37.51 | N27: =+I27*M27 -> 2663.21 | O27: 23 | P27: =+'23'!M287 -> 5750 | Q27: =+'23'!M292 -> 2050 | R27: =+'23'!M290 -> 0 | S27: =+'23'!M288 -> 0 | T27: =+'23'!M291 -> 0 | U27: =+'23'!M289 -> 500 | V27: =+P27-Q27-R27-S27-T27-U27 -> 3200 | W27: =+'23'!M294 -> 3250 | X27: =+W27-V27 -> 50 | Y27: =+U27+W27+X27 -> 3800
