Workbook

Sheet ค่าใช้จ่าย
A1: สรุปค่าใช้จ่าย บูธ ตลาดดิโอโซน วันที่ 1-31 ส.ค. 67
A2: วันที่ | B2: รายการค่าใช้จ่าย | C2: ยอดค่าใช้จ่าย | D2: หมายเหตุ
A3: 243832 | B3: ค่าน้ำแข็ง | C3: 50 | D3: ยังไม่ได้ส่งบิล
A4: 243833 | B4: ค่าน้ำแข็ง | C4: 50 | D4: มีบิลแลว
B31: ยอดรวมค่าใช้จ่าย | C31: =SUM(C20:C30) -> 0 | D31: บาท
B219: เครปคิทแคท | I219: 35

Sheet รายการส่วนลด
A1: สรุปส่วนลดสินค้า บูธ ตลาดดิโอโซน วันที่ 1-31 ส.ค. 67
A2: วันที่ | B2: รายการสินค้า | C2: จำนวน | D2: ราคาเต็ม/หน่วย | E2: ราคาลด/หน่วย | F2: ยอดรวม | G2: หมายเหตุ
A3: 243831 | B3: ชิฟฟ่อนเค้กสอดไส้แยม รสส้ม (3 ชิ้น) | C3: 1 | D3: 50 | E3: =+D3/2 -> 25 | F3: =+C3*E3 -> 25 | G3: ลด 50 %
A4: 243831 | B4: ชิฟฟ่อนเค้กหน้าฝอยทอง สอดไส้แยมส้ม (3 ชิ้น) | C4: 1 | D4: 50 | E4: =+D4/2 -> 25 | F4: =+C4*E4 -> 25 | G4: ลด 50 %
A5: 243831 | B5: ชิฟฟ่อนเค้กสอดไส้เนย รสมะพร้าว (3 ชิ้น) | C5: 1 | D5: 50 | E5: =+D5/2 -> 25 | F5: =+C5*E5 -> 25 | G5: ลด 50 %
A6: 243831 | B6: ชิฟฟ่อนเค้กหน้าฝอยทอง สอดไส้แยมส้ม (6 ชิ้น) | C6: 3 | D6: 100 | E6: =+D6/2 -> 50 | F6: =+C6*E6 -> 150 | G6: ลด 50 %
A7: 243831 | B7: ชิฟฟ่อนเค้กสอดไส้ มะพร้าว (6 ชิ้น) | C7: 2 | D7: 100 | E7: =+D7/2 -> 50 | F7: =+C7*E7 -> 100 | G7: ลด 50 %
A8: 243832 | B8: ชิฟฟ่อนเค้กสอดไส้ รวมรส (3 ชิ้น) | C8: 3 | D8: 50 | E8: =+D8/2 -> 25 | F8: =+C8*E8 -> 75 | G8: ลด 50 %
A9: 243832 | B9: ชิฟฟ่อนเค้กสอดไส้แยม รสส้ม (3 ชิ้น) | C9: 3 | D9: 50 | E9: =+D9/2 -> 25 | F9: =+C9*E9 -> 75 | G9: ลด 50 %
A10: 243832 | B10: ชิฟฟ่อนเค้กหน้าฝอยทอง สอดไส้แยมส้ม (3 ชิ้น) | C10: 4 | D10: 50 | E10: =+D10/2 -> 25 | F10: =+C10*E10 -> 100 | G10: ลด 50 %
A11: 243832 | B11: ชิฟฟ่อนเค้กสอดไส้เนย รสมะพร้าว (3 ชิ้น) | C11: 3 | D11: 50 | E11: =+D11/2 -> 25 | F11: =+C11*E11 -> 75 | G11: ลด 50 %
A12: 243832 | B12: ชิฟฟ่อนเค้กสอดไส้ รวมรส (6 ชิ้น) | C12: 5 | D12: 100 | E12: =+D12/2 -> 50 | F12: =+C12*E12 -> 250 | G12: ลด 50 %
A13: 243832 | B13: ชิฟฟ่อนเค้กหน้าฝอยทอง สอดไส้แยมส้ม (6 ชิ้น) | C13: 4 | D13: 100 | E13: =+D13/2 -> 50 | F13: =+C13*E13 -> 200 | G13: ลด 50 %
A14: 243832 | B14: ชิฟฟ่อนเค้กสอดไส้ มะพร้าว (6 ชิ้น) | C14: 3 | D14: 100 | E14: =+D14/2 -> 50 | F14: =+C14*E14 -> 150 | G14: ลด 50 %
... A22: 243833 | B22: เบาหวิว (ญ) ใหม่ รสมะพร้าว | C22: 1 | D22: 120 | E22: =+D22/2 -> 60 | F22: =+C22*E22 -> 60 | G22: ลด 50 %
A23: 243833 | B23: เค้กลอดช่อง | C23: 18 | D23: 35 | E23: 13.61111 | F23: =+C23*E23 -> 244.99998 | G23: โปร 2 แถม 1
A24: 243834 | B24: ชิฟฟ่อนเค้กสอดไส้ รวมรส (3 ชิ้น) | C24: 1 | D24: 50 | E24: =+D24/2 -> 25 | F24: =+C24*E24 -> 25 | G24: ลด 50 % 1
A25: 243834 | B25: ชิฟฟ่อนเค้กหน้าฝอยทอง สอดไส้แยมส้ม (3 ชิ้น) | C25: 1 | D25: 50 | E25: 50 | F25: =+C25*E25 -> 50 | G25: แถม
F36: =+C36*E36 -> 0
B37: ยอดรวมส่วนลด | C37: =SUM(C3:C36) -> 65 | D37: ชิ้น | F37: =SUM(F3:F36) -> 2095 | G37: บาท

Sheet รายการคืนสินค้า
A1: สรุปรายการคืนสินค้า บูธ ตลาดดิโอโซน วันที่ 1-31 ส.ค. 67
A2: วันที่ | B2: รายการสินค้า | C2: จำนวนคืนสินค้า | D2: ราคา/หน่วย | E2: ยอดรวม | F2: หมายเหตุ
A3: 243833 | B3: ชิฟฟ่อนเค้กสอดไส้แยม รสส้ม (3 ชิ้น) | C3: 1 | D3: 50 | E3: =+C3*D3 -> 50 | F3: หมดอายุ 1
A4: 243833 | B4: ชิฟฟ่อนเค้กสอดไส้ รวมรส (6 ชิ้น) | C4: 3 | D4: 100 | E4: =+C4*D4 -> 300 | F4: หมดอายุ 3
A5: 243833 | B5: ชิฟฟ่อนเค้กมะพร้าวสอดไส้ครีมมะพร้าวล้วน (8 ชิ้น) | C5: 2 | D5: 130 | E5: =+C5*D5 -> 260 | F5: หมดอายุ 2
A6: 243833 | B6: ครีมฮอร์น ช็อคโกแลต | C6: 13 | D6: 50 | E6: =+C6*D6 -> 650 | F6: หมดอายุ 13
A7: 243833 | B7: โบราณ 4 ชิ้น รวมรส | C7: 1 | D7: 50 | E7: =+C7*D7 -> 50 | F7: หมดอายุ 1
A8: 243833 | B8: โบราณครีม 4 ชิ้น วรรณวนัช | C8: 1 | D8: 50 | E8: =+C8*D8 -> 50 | F8: หมดอายุ 1
A9: 243833 | B9: ลาวา ทูโทน (ล) (สีเขียว + สีเหลือง) | C9: 2 | D9: 50 | E9: =+C9*D9 -> 100 | F9: หมดอายุ 2
A10: 243833 | B10: เอแคลร์นมสด 8 ชิ้น | C10: 3 | D10: 50 | E10: =+C10*D10 -> 150 | F10: หมดอายุ 1
A11: 243833 | B11: เค้กช็อคโกแลตหน้านิ่ม | C11: 2 | D11: 55 | E11: =+C11*D11 -> 110 | F11: หมดอายุ 2
A12: 243833 | B12: เค้กลอดช่อง | C12: 6 | D12: 35 | E12: =+C12*D12 -> 210 | F12: หมดอายุ 6
A13: 243833 | B13: ขนมปังเนยนิ่ม | C13: 1 | D13: 50 | E13: =+C13*D13 -> 50 | F13: หมดอายุ 1
A14: 243833 | B14: ขนมปังสังขยา 6 ลูก | C14: 4 | D14: 50 | E14: =+C14*D14 -> 200 | F14: หมดอายุ 4
A15: 243833 | B15: นมชมพูเย็น | C15: 6 | D15: 25 | E15: =+C15*D15 -> 150 | F15: หมดอายุ 6
B23: ยอดรวมคืนสินค้า | C23: =SUM(C3:C22) -> 45 | D23: ชิ้น | E23: =SUM(E3:E22) -> 2330 | F23: บาท

Sheet รายการเบิกชิม ไหว้พระ
A1: สรุปรายเบิกชิม ไหว้พระ บูธ ตลาดดิโอโซน วันที่ 1-31 ส.ค. 67
A2: วันที่ | B2: รายการสินค้า | C2: จำนวนคืนสินค้า | D2: ราคา/หน่วย | E2: ยอดรวม | F2: หมายเหตุ
A3: 243833 | B3: ครีมฮอร์น วนิลา | C3: 1 | D3: 50 | E3: =+C3*D3 -> 50 | F3: เบิกชิม 1
A4: 243833 | B4: ครีมฮอร์น ใบเตย | C4: 1 | D4: 50 | E4: =+C4*D4 -> 50 | F4: เบิกชิม 1
B22: ยอดรวมคืนสินค้า | C22: =SUM(C3:C21) -> 2 | D22: ชิ้น | E22: =SUM(E3:E21) -> 100 | F22: บาท

Sheet รายการโยกย้ายสินค้า
A1: สรุปรายการโยกย้ายสินค้า บูธ ตลาดดิโอโซน วันที่ 1-31 ส.ค. 67
A2: วันที่ | B2: รายการสินค้า | C2: จำนวนสินค้า | D2: โยกไปสาขา | E2: หมายเหตุ
B25: ยอดรวมคืนสินค้า | C25: =SUM(C14:C24) -> 0 | D25: =SUM(D14:D24) -> 0 | E25: บาท

Sheet ออม
A2: สรุปยอดขาย บูธ ตลาดดิโอโซน วันที่ 1-31 ส.ค. 67
A3: วันที่ | B3: ยอดเงิน | C3: ส่วนลด | D3: สแกนใช้สิทธิ์ | E3: ค่าโอนเงิน | F3: ค่าใช้จ่ายอื่นๆ | G3: โอนหน้าร้าน | H3: รับสุทธิ | I3: ยอดโอนเงิน | J3: โอนเกิน/โอนขาด
A5: 1 | B5: =+'1'!L287 -> 1620 | C5: =+'1'!L292 -> 325 | D5: =+'1'!L290 -> 0 | E5: =+'1'!L288 -> 0 | F5: =+'1'!L291 -> 0 | G5: =+'1'!L289 -> 670 | H5: =+B5-C5-D5-E5-F5-G5 -> 625 | I5: =+'1'!L294 -> 625 | J5: =+I5-H5 -> 0 | K5: =+G5+I5+J5 -> 1295
A6: 2 | B6: =+'2'!L287 -> 4420 | C6: =+'2'!L292 -> 1190 | D6: =+'2'!L290 -> 0 | E6: =+'2'!L288 -> 0 | F6: =+'2'!L291 -> 50 | G6: =+'2'!L289 -> 1180 | H6: =+B6-C6-D6-E6-F6-G6 -> 2000 | I6: =+'2'!L294 -> 2000 | J6: =+I6-H6 -> 0 | K6: =+G6+I6+J6 -> 3180
A7: 3 | B7: =+'3'!L287 -> 2470 | C7: =+'3'!L292 -> 505 | D7: =+'3'!L290 -> 0 | E7: =+'3'!L288 -> 0 | F7: =+'3'!L291 -> 50 | G7: =+'3'!L289 -> 980 | H7: =+B7-C7-D7-E7-F7-G7 -> 935 | I7: =+'3'!L294 -> 935 | J7: =+I7-H7 -> 0 | K7: =+G7+I7+J7 -> 1915
A8: 4 | B8: =+'4'!L287 -> 2600 | C8: =+'4'!L292 -> 75 | D8: =+'4'!L290 -> 0 | E8: =+'4'!L298 -> 0 | F8: =+'4'!L291 -> 0 | G8: =+'4'!L289 -> 345 | H8: =+B8-C8-D8-E8-F8-G8 -> 2180 | I8: =+'4'!L294 -> 2290 | J8: =+I8-H8 -> 110 | K8: =+G8+I8+J8 -> 2745
A9: 5 | B9: =+'5'!L287 -> 1985 | C9: =+'5'!L292 -> 265 | D9: =+'5'!L290 -> 0 | E9: =+'5'!L288 -> 0 | F9: =+'5'!L291 -> 0 | G9: =+'5'!L289 -> 655 | H9: =+B9-C9-D9-E9-F9-G9 -> 1065 | I9: =+'5'!L294 -> 1065 | J9: =+I9-H9 -> 0 | K9: =+G9+I9+J9 -> 1720
A10: 6 | B10: =+'6'!L287 -> 4675 | C10: =+'6'!L292 -> 1320 | D10: =+'6'!L290 -> 0 | E10: =+'6'!L288 -> 0 | F10: =+'6'!L291 -> 50 | G10: =+'6'!L289 -> 360 | H10: =+B10-C10-D10-E10-F10-G10 -> 2945 | I10: =+'6'!L294 -> 2945 | J10: =+I10-H10 -> 0 | K10: =+G10+I10+J10 -> 3305
A11: 7 | B11: =+'7'!L287 -> 2060 | C11: =+'7'!L292 -> 395 | D11: =+'7'!L290 -> 0 | E11: =+'7'!L288 -> 0 | F11: =+'7'!L291 -> 0 | G11: =+'7'!L289 -> 665 | H11: =+B11-C11-D11-E11-F11-G11 -> 1000 | I11: =+'7'!L294 -> 1000 | J11: =+I11-H11 -> 0 | K11: =+G11+I11+J11 -> 1665
A12: 8 | B12: =+'8'!L287 -> 5435 | C12: =+'8'!L292 -> 1175 | D12: =+'8'!L290 -> 0 | E12: =+'8'!L288 -> 0 | F12: =+'8'!L291 -> 50 | G12: =+'8'!L289 -> 1850 | H12: =+B12-C12-D12-E12-F12-G12 -> 2360 | I12: =+'8'!L294 -> 2360 | J12: =+I12-H12 -> 0 | K12: =+G12+I12+J12 -> 4210
A13: 9 | B13: =+'9'!L287 -> 1580 | C13: =+'9'!L292 -> 310 | D13: =+'9'!L290 -> 0 | E13: =+'9'!L288 -> 0 | F13: =+'9'!L291 -> 0 | G13: =+'9'!L289 -> 300 | H13: =+B13-C13-D13-E13-F13-G13 -> 970 | I13: =+'9'!L294 -> 970 | J13: =+I13-H13 -> 0 | K13: =+G13+I13+J13 -> 1270
A14: 10 | B14: =+'10'!L287 -> 5805 | C14: =+'10'!L292 -> 720 | D14: =+'10'!L290 -> 0 | E14: =+'10'!L288 -> 0 | F14: =+'10'!L291 -> 50 | G14: =+'10'!L289 -> 670 | H14: =+B14-C14-D14-E14-F14-G14 -> 4365 | I14: =+'10'!L294 -> 4365 | J14: =+I14-H14 -> 0 | K14: =+G14+I14+J14 -> 5035
A15: 11 | B15: =+'11'!L287 -> 4750 | C15: =+'11'!L292 -> 895 | D15: =+'11'!L290 -> 0 | E15: =+'11'!L288 -> 0 | F15: =+'11'!L291 -> 0 | G15: =+'11'!L289 -> 1430 | H15: =+B15-C15-D15-E15-F15-G15 -> 2425 | I15: =+'11'!L294 -> 2425 | J15: =+I15-H15 -> 0 | K15: =+G15+I15+J15 -> 3855
A16: 12 | B16: =+'12'!L287 -> 4765 | C16: =+'12'!L292 -> 655 | D16: =+'12'!L290 -> 0 | E16: =+'12'!L288 -> 0 | F16: =+'12'!L291 -> 0 | G16: =+'12'!L289 -> 1210 | H16: =+B16-C16-D16-E16-F16-G16 -> 2900 | I16: =+'12'!L294 -> 2900 | J16: =+I16-H16 -> 0 | K16: =+G16+I16+J16 -> 4110
A17: 13 | B17: =+'13'!L287 -> 4810 | C17: =+'13'!L292 -> 530 | D17: =+'13'!L290 -> 0 | E17: =+'13'!L288 -> 0 | F17: =+'13'!L291 -> 0 | G17: =+'13'!L289 -> 955 | H17: =+B17-C17-D17-E17-F17-G17 -> 3325 | I17: =+'13'!L294 -> 3325 | J17: =+I17-H17 -> 0 | K17: =+G17+I17+J17 -> 4280
A18: 14 | B18: =+'14'!L287 -> 2175 | C18: =+'14'!L292 -> 220 | D18: =+'14'!L290 -> 0 | E18: =+'14'!L288 -> 0 | F18: =+'14'!L291 -> 0 | G18: =+'14'!L289 -> 235 | H18: =+B18-C18-D18-E18-F18-G18 -> 1720 | I18: =+'14'!L294 -> 1720 | J18: =+I18-H18 -> 0 | K18: =+G18+I18+J18 -> 1955
A19: 15 | B19: =+'15'!L287 -> 1980 | C19: =+'15'!L292 -> 330 | D19: =+'15'!L290 -> 0 | E19: =+'15'!L288 -> 0 | F19: =+'15'!L291 -> 0 | G19: =+'15'!L289 -> 1095 | H19: =+B19-C19-D19-E19-F19-G19 -> 555 | I19: =+'15'!L294 -> 555 | J19: =+I19-H19 -> 0 | K19: =+G19+I19+J19 -> 1650
A20: 16 | B20: =+'16'!L287 -> 2015 | C20: =+'16'!L292 -> 240 | D20: =+'16'!L290 -> 0 | E20: =+'16'!L288 -> 0 | F20: =+'16'!L291 -> 50 | G20: =+'16'!L289 -> 230 | H20: =+B20-C20-D20-E20-F20-G20 -> 1495 | I20: =+'16'!L294 -> 1495 | J20: =+I20-H20 -> 0 | K20: =+G20+I20+J20 -> 1725
A21: 17 | B21: =+'17'!L287 -> 2885 | C21: =+'17'!L292 -> 335 | D21: =+'17'!L290 -> 0 | E21: =+'17'!L288 -> 0 | F21: =+'17'!L291 -> 22 | G21: =+'17'!L289 -> 220 | H21: =+B21-C21-D21-E21-F21-G21 -> 2308 | I21: =+'17'!L294 -> 2308 | J21: =+I21-H21 -> 0 | K21: =+G21+I21+J21 -> 2528
A22: 18 | B22: =+'18'!L287 -> 2330 | C22: =+'18'!L292 -> 310 | D22: =+'18'!L290 -> 0 | E22: =+'18'!L288 -> 0 | F22: =+'18'!L291 -> 0 | G22: =+'18'!L289 -> 340 | H22: =+B22-C22-D22-E22-F22-G22 -> 1680 | I22: =+'18'!L294 -> 1680 | J22: =+I22-H22 -> 0 | K22: =+G22+I22+J22 -> 2020
A23: 19 | B23: =+'19'!L287 -> 1280 | C23: =+'19'!L292 -> 350 | D23: =+'19'!L290 -> 0 | E23: =+'19'!L288 -> 0 | F23: =+'19'!L291 -> 0 | G23: =+'19'!L289 -> 0 | H23: =+B23-C23-D23-E23-F23-G23 -> 930 | I23: =+'19'!L294 -> 930 | J23: =+I23-H23 -> 0 | K23: =+G23+I23+J23 -> 930
A24: 20 | B24: =+'20'!L287 -> 4115 | C24: =+'20'!L292 -> 655 | D24: =+'20'!L290 -> 0 | E24: =+'20'!L288 -> 0 | F24: =+'20'!L291 -> 0 | G24: =+'20'!L289 -> 145 | H24: =+B24-C24-D24-E24-F24-G24 -> 3315 | I24: =+'20'!L294 -> 3315 | J24: =+I24-H24 -> 0 | K24: =+G24+I24+J24 -> 3460
A25: 21 | B25: =+'21'!L287 -> 2100 | C25: =+'21'!L292 -> 340 | D25: =+'21'!L290 -> 0 | E25: =+'21'!L288 -> 0 | F25: =+'21'!L291 -> 50 | G25: =+'21'!L289 -> 150 | H25: =+B25-C25-D25-E25-F25-G25 -> 1560 | I25: =+'21'!L294 -> 1560 | J25: =+I25-H25 -> 0 | K25: =+G25+I25+J25 -> 1710
A26: 22 | B26: =+'22'!L287 -> 5780 | C26: =+'22'!L292 -> 1805 | D26: =+'22'!L290 -> 0 | E26: =+'22'!L288 -> 0 | F26: =+'22'!L291 -> 50 | G26: =+'22'!L289 -> 515 | H26: =+B26-C26-D26-E26-F26-G26 -> 3410 | I26: =+'22'!L294 -> 3410 | J26: =+I26-H26 -> 0 | K26: =+G26+I26+J26 -> 3925
A27: 23 | B27: =+'23'!L287 -> 4875 | C27: =+'23'!L292 -> 720 | D27: =+'23'!L290 -> 0 | E27: =+'23'!L288 -> 0 | F27: =+'23'!L291 -> 0 | G27: =+'23'!L289 -> 490 | H27: =+B27-C27-D27-E27-F27-G27 -> 3665 | I27: =+'23'!L294 -> 3665 | J27: =+I27-H27 -> 0 | K27: =+G27+I27+J27 -> 4155
A28: 24 | B28: =+'24'!L287 -> 3630 | C28: =+'24'!L292 -> 450 | D28: =+'24'!L290 -> 0 | E28: =+'24'!L288 -> 0 | F28: =+'24'!L291 -> 50 | G28: =+'24'!L289 -> 765 | H28: =+B28-C28-D28-E28-F28-G28 -> 2365 | I28: =+'24'!L294 -> 2365 | J28: =+I28-H28 -> 0 | K28: =+G28+I28+J28 -> 3130
A29: 25 | B29: =+'25'!L287 -> 1680 | C29: =+'25'!L292 -> 275 | D29: =+'25'!L290 -> 0 | E29: =+'25'!L288 -> 0 | F29: =+'25'!L291 -> 0 | G29: =+'25'!L289 -> 700 | H29: =+B29-C29-D29-E29-F29-G29 -> 705 | I29: =+'25'!L294 -> 705 | J29: =+I29-H29 -> 0 | K29: =+G29+I29+J29 -> 1405
A30: 26 | B30: =+'26'!L287 -> 2430 | C30: =+'26'!L292 -> 360 | D30: =+'26'!L290 -> 0 | E30: =+'26'!L288 -> 0 | F30: =+'26'!L291 -> 50 | G30: =+'26'!L289 -> 490 | H30: =+B30-C30-D30-E30-F30-G30 -> 1530 | I30: =+'26'!L294 -> 1530 | J30: =+I30-H30 -> 0 | K30: =+G30+I30+J30 -> 2020
A31: 27 | B31: =+'27'!L287 -> 2175 | C31: =+'27'!L292 -> 520 | D31: =+'27'!L290 -> 0 | E31: =+'27'!L288 -> 0 | F31: =+'27'!L291 -> 47 | G31: =+'27'!L289 -> 280 | H31: =+B31-C31-D31-E31-F31-G31 -> 1328 | I31: =+'27'!L294 -> 1328 | J31: =+I31-H31 -> 0 | K31: =+G31+I31+J31 -> 1608
A32: 28 | B32: =+'28'!L287 -> 1965 | C32: =+'28'!L292 -> 510 | D32: =+'28'!L290 -> 0 | E32: =+'28'!L288 -> 0 | F32: =+'28'!L291 -> 0 | G32: =+'28'!L289 -> 190 | H32: =+B32-C32-D32-E32-F32-G32 -> 1265 | I32: =+'28'!L294 -> 1265 | J32: =+I32-H32 -> 0 | K32: =+G32+I32+J32 -> 1455
A33: 29 | B33: =+'29'!L287 -> 3140 | C33: =+'29'!L292 -> 550 | D33: =+'29'!L290 -> 0 | E33: =+'29'!L288 -> 15 | F33: =+'29'!L291 -> 0 | G33: =+'29'!L289 -> 1160 | H33: =+B33-C33-D33-E33-F33-G33 -> 1415 | I33: =+'29'!L294 -> 1405 | J33: =+I33-H33 -> -10 | K33: =+G33+I33+J33 -> 2555
A34: 30 | B34: =+'30'!L287 -> 7015 | C34: =+'30'!L292 -> 1075 | D34: =+'30'!L290 -> 0 | E34: =+'30'!L288 -> 0 | F34: =+'30'!L291 -> 0 | G34: =+'30'!L289 -> 1845 | H34: =+B34-C34-D34-E34-F34-G34 -> 4095 | I34: =+'30'!L294 -> 4095 | J34: =+I34-H34 -> 0 | K34: =+G34+I34+J34 -> 5940
A35: 31 | B35: =+'31.'!L287 -> 5090 | C35: =+'31.'!L292 -> 875 | D35: =+'31.'!L290 -> 0 | E35: =+'31.'!L288 -> 0 | F35: =+'31.'!L291 -> 0 | G35: =+'31.'!L289 -> 1295 | H35: =+B35-C35-D35-E35-F35-G35 -> 2920 | I35: =+'31.'!L294 -> 2920 | J35: =+I35-H35 -> 0 | K35: =+G35+I35+J35 -> 4215
B36: =SUM(B5:B35) -> 103635 | C36: =SUM(C5:C35) -> 18280 | D36: =SUM(D5:D35) -> 0 | E36: =SUM(E5:E35) -> 15 | F36: =SUM(F5:F35) -> 569 | G36: =SUM(G5:G35) -> 21415 | H36: =SUM(H5:H35) -> 63356 | I36: =SUM(I5:I35) -> 63456 | J36: =SUM(J5:J35) -> 100

Sheet สรุป
A2: บูธ ตลาดดิโอโซน วันที่ 1-31 ส.ค. 67 | O2: สรุปยอดขาย บูธ ตลาดดิโอโซน วันที่ 1-31 ส.ค. 67
A3: ลำดับ | B3: รายการ | C3: ยกมา | D3: รับ | E3: รวม | F3: เปลี่ยน/ | G3: โยก | H3: คงเหลือ | I3: รายการขาย | L3: หมายเหตุ | M3: ราคาต้นทุน | N3: ยอดรวมต้นทุนสินค้า | O3: วันที่ | P3: ยอดเงิน | Q3: ส่วนลด | R3: สแกนใช้สิทธิ์ | S3: ค่าโอนเงิน | T3: ค่าใช้จ่ายอื่นๆ | U3: โอนหน้าร้าน | V3: รับสุทธิ | W3: ยอดโอนเงิน | X3: โอนเกิน/โอนขาด
F4: คืน/เสีย | I4: จำนวน | J4: @ | K4: เป็นเงิน
A5: 1 | B5: ชิฟฟ่อนเค้กสอดไส้ รวมรส (4 ชิ้น) กล่องชมพู | C5: =+ยกมา!H5 -> 33 | D5: =+'1'!D5+'2'!D5+'3'!D5+'4'!D5+'5'!D5+'6'!D5+'7'!D5+'8'!D5+'9'!D5+'10'!D5+'11'!D5+'12'!D5+'13'!D5+'14'!D5+'15'!D5+'16'!D5+'17'!D5+'18'!D5+'19'!D5+'20'!D5+'21'!D5+'22'!D5+'23'!D5+'24'!D5+'25'!D5+'26'!D5+'27'!D5+'28'!D5+'29'!D5+'30'!D5+'31.'!D5 -> 40 | E5: =+C5+D5 -> 73 | F5: =+'1'!F5+'2'!F5+'3'!F5+'4'!F5+'5'!F5+'6'!F5+'7'!F5+'8'!F5+'9'!F5+'10'!F5+'11'!F5+'12'!F5+'13'!F5+'14'!F5+'15'!F5+'16'!F5+'17'!F5+'18'!F5+'19'!F5+'20'!F5+'21'!F5+'22'!F5+'23'!F5+'24'!F5+'25'!F5+'26'!F5+'27'!F5+'28'!F5+'29'!F5+'30'!F5+'31.'!F5 -> 14 | G5: =+'1'!G5+'2'!G5+'3'!G5+'4'!G5+'5'!G5+'6'!G5+'7'!G5+'8'!G5+'9'!G5+'10'!G5+'11'!G5+'12'!G5+'13'!G5+'14'!G5+'15'!G5+'16'!G5+'17'!G5+'18'!G5+'19'!G5+'20'!G5+'21'!G5+'22'!G5+'23'!G5+'24'!G5+'25'!G5+'26'!G5+'27'!G5+'28'!G5+'29'!G5+'30'!G5+'31.'!G5 -> 0 | H5: =C5+D5-F5-I5-G5 -> 7 | I5: =+'1'!I5+'2'!I5+'3'!I5+'4'!I5+'5'!I5+'6'!I5+'7'!I5+'8'!I5+'9'!I5+'10'!I5+'11'!I5+'12'!I5+'13'!I5+'14'!I5+'15'!I5+'16'!I5+'17'!I5+'18'!I5+'19'!I5+'20'!I5+'21'!I5+'22'!I5+'23'!I5+'24'!I5+'25'!I5+'26'!I5+'27'!I5+'28'!I5+'29'!I5+'30'!I5+'31.'!I5 -> 52 | J5: 50 | K5: =+I5*J5 -> 2600 | M5: 19.58 | N5: =+I5*M5 -> 1018.16 | O5: 1 | P5: =+'1'!L287 -> 1620 | Q5: =+'1'!L292 -> 325 | R5: =+'1'!L290 -> 0 | S5: =+'1'!L288 -> 0 | T5: =+'1'!L291 -> 0 | U5: =+'1'!L289 -> 670 | V5: =+P5-Q5-R5-S5-T5-U5 -> 625 | W5: =+'1'!L294 -> 625 | X5: =+W5-V5 -> 0 | Y5: =+U5+W5+X5 -> 1295
A6: 2 | B6: ชิฟฟ่อนเค้กสอดไส้ รวมรส (8 ชิ้น) กล่องชมพู | C6: =+ยกมา!H6 -> 46 | D6: =+'1'!D6+'2'!D6+'3'!D6+'4'!D6+'5'!D6+'6'!D6+'7'!D6+'8'!D6+'9'!D6+'10'!D6+'11'!D6+'12'!D6+'13'!D6+'14'!D6+'15'!D6+'16'!D6+'17'!D6+'18'!D6+'19'!D6+'20'!D6+'21'!D6+'22'!D6+'23'!D6+'24'!D6+'25'!D6+'26'!D6+'27'!D6+'28'!D6+'29'!D6+'30'!D6+'31.'!D6 -> 168 | E6: =+C6+D6 -> 214 | F6: =+'1'!F6+'2'!F6+'3'!F6+'4'!F6+'5'!F6+'6'!F6+'7'!F6+'8'!F6+'9'!F6+'10'!F6+'11'!F6+'12'!F6+'13'!F6+'14'!F6+'15'!F6+'16'!F6+'17'!F6+'18'!F6+'19'!F6+'20'!F6+'21'!F6+'22'!F6+'23'!F6+'24'!F6+'25'!F6+'26'!F6+'27'!F6+'28'!F6+'29'!F6+'30'!F6+'31.'!F6 -> 6 | G6: =+'1'!G6+'2'!G6+'3'!G6+'4'!G6+'5'!G6+'6'!G6+'7'!G6+'8'!G6+'9'!G6+'10'!G6+'11'!G6+'12'!G6+'13'!G6+'14'!G6+'15'!G6+'16'!G6+'17'!G6+'18'!G6+'19'!G6+'20'!G6+'21'!G6+'22'!G6+'23'!G6+'24'!G6+'25'!G6+'26'!G6+'27'!G6+'28'!G6+'29'!G6+'30'!G6+'31.'!G6 -> 30 | H6: =C6+D6-F6-I6-G6 -> 47 | I6: =+'1'!I6+'2'!I6+'3'!I6+'4'!I6+'5'!I6+'6'!I6+'7'!I6+'8'!I6+'9'!I6+'10'!I6+'11'!I6+'12'!I6+'13'!I6+'14'!I6+'15'!I6+'16'!I6+'17'!I6+'18'!I6+'19'!I6+'20'!I6+'21'!I6+'22'!I6+'23'!I6+'24'!I6+'25'!I6+'26'!I6+'27'!I6+'28'!I6+'29'!I6+'30'!I6+'31.'!I6 -> 131 | J6: 100 | K6: =+I6*J6 -> 13100 | M6: 37.17 | N6: =+I6*M6 -> 4869.27 | O6: 2 | P6: =+'2'!L287 -> 4420 | Q6: =+'2'!L292 -> 1190 | R6: =+'2'!L290 -> 0 | S6: =+'2'!L288 -> 0 | T6: =+'2'!L291 -> 50 | U6: =+'2'!L289 -> 1180 | V6: =+P6-Q6-R6-S6-T6-U6 -> 2000 | W6: =+'2'!L294 -> 2000 | X6: =+W6-V6 -> 0 | Y6: =+U6+W6+X6 -> 3180
A7: 3 | B7: ชิฟฟ่อนเค้ก รสกาแฟ (4 ชิ้น) | C7: =+ยกมา!H7 -> 0 | D7: =+'1'!D7+'2'!D7+'3'!D7+'4'!D7+'5'!D7+'6'!D7+'7'!D7+'8'!D7+'9'!D7+'10'!D7+'11'!D7+'12'!D7+'13'!D7+'14'!D7+'15'!D7+'16'!D7+'17'!D7+'18'!D7+'19'!D7+'20'!D7+'21'!D7+'22'!D7+'23'!D7+'24'!D7+'25'!D7+'26'!D7+'27'!D7+'28'!D7+'29'!D7+'30'!D7+'31.'!D7 -> 0 | E7: =+C7+D7 -> 0 | F7: =+'1'!F7+'2'!F7+'3'!F7+'4'!F7+'5'!F7+'6'!F7+'7'!F7+'8'!F7+'9'!F7+'10'!F7+'11'!F7+'12'!F7+'13'!F7+'14'!F7+'15'!F7+'16'!F7+'17'!F7+'18'!F7+'19'!F7+'20'!F7+'21'!F7+'22'!F7+'23'!F7+'24'!F7+'25'!F7+'26'!F7+'27'!F7+'28'!F7+'29'!F7+'30'!F7+'31.'!F7 -> 0 | G7: =+'1'!G7+'2'!G7+'3'!G7+'4'!G7+'5'!G7+'6'!G7+'7'!G7+'8'!G7+'9'!G7+'10'!G7+'11'!G7+'12'!G7+'13'!G7+'14'!G7+'15'!G7+'16'!G7+'17'!G7+'18'!G7+'19'!G7+'20'!G7+'21'!G7+'22'!G7+'23'!G7+'24'!G7+'25'!G7+'26'!G7+'27'!G7+'28'!G7+'29'!G7+'30'!G7+'31.'!G7 -> 0 | H7: =C7+D7-F7-I7-G7 -> 0 | I7: =+'1'!I7+'2'!I7+'3'!I7+'4'!I7+'5'!I7+'6'!I7+'7'!I7+'8'!I7+'9'!I7+'10'!I7+'11'!I7+'12'!I7+'13'!I7+'14'!I7+'15'!I7+'16'!I7+'17'!I7+'18'!I7+'19'!I7+'20'!I7+'21'!I7+'22'!I7+'23'!I7+'24'!I7+'25'!I7+'26'!I7+'27'!I7+'28'!I7+'29'!I7+'30'!I7+'31.'!I7 -> 0 | J7: 50 | K7: =+I7*J7 -> 0 | M7: 26.11 | N7: =+I7*M7 -> 0 | O7: 3 | P7: =+'3'!L287 -> 2470 | Q7: =+'3'!L292 -> 505 | R7: =+'3'!L290 -> 0 | S7: =+'3'!L288 -> 0 | T7: =+'3'!L291 -> 50 | U7: =+'3'!L289 -> 980 | V7: =+P7-Q7-R7-S7-T7-U7 -> 935 | W7: =+'3'!L294 -> 935 | X7: =+W7-V7 -> 0 | Y7: =+U7+W7+X7 -> 1915
A8: 4 | B8: ชิฟฟ่อนเค้ก รสกาแฟ (8 ชิ้น) | C8: =+ยกมา!H8 -> 0 | D8: =+'1'!D8+'2'!D8+'3'!D8+'4'!D8+'5'!D8+'6'!D8+'7'!D8+'8'!D8+'9'!D8+'10'!D8+'11'!D8+'12'!D8+'13'!D8+'14'!D8+'15'!D8+'16'!D8+'17'!D8+'18'!D8+'19'!D8+'20'!D8+'21'!D8+'22'!D8+'23'!D8+'24'!D8+'25'!D8+'26'!D8+'27'!D8+'28'!D8+'29'!D8+'30'!D8+'31.'!D8 -> 0 | E8: =+C8+D8 -> 0 | F8: =+'1'!F8+'2'!F8+'3'!F8+'4'!F8+'5'!F8+'6'!F8+'7'!F8+'8'!F8+'9'!F8+'10'!F8+'11'!F8+'12'!F8+'13'!F8+'14'!F8+'15'!F8+'16'!F8+'17'!F8+'18'!F8+'19'!F8+'20'!F8+'21'!F8+'22'!F8+'23'!F8+'24'!F8+'25'!F8+'26'!F8+'27'!F8+'28'!F8+'29'!F8+'30'!F8+'31.'!F8 -> 0 | G8: =+'1'!G8+'2'!G8+'3'!G8+'4'!G8+'5'!G8+'6'!G8+'7'!G8+'8'!G8+'9'!G8+'10'!G8+'11'!G8+'12'!G8+'13'!G8+'14'!G8+'15'!G8+'16'!G8+'17'!G8+'18'!G8+'19'!G8+'20'!G8+'21'!G8+'22'!G8+'23'!G8+'24'!G8+'25'!G8+'26'!G8+'27'!G8+'28'!G8+'29'!G8+'30'!G8+'31.'!G8 -> 0 | H8: =C8+D8-F8-I8-G8 -> 0 | I8: =+'1'!I8+'2'!I8+'3'!I8+'4'!I8+'5'!I8+'6'!I8+'7'!I8+'8'!I8+'9'!I8+'10'!I8+'11'!I8+'12'!I8+'13'!I8+'14'!I8+'15'!I8+'16'!I8+'17'!I8+'18'!I8+'19'!I8+'20'!I8+'21'!I8+'22'!I8+'23'!I8+'24'!I8+'25'!I8+'26'!I8+'27'!I8+'28'!I8+'29'!I8+'30'!I8+'31.'!I8 -> 0 | J8: 100 | K8: =+I8*J8 -> 0 | M8: 33.89 | N8: =+I8*M8 -> 0 | O8: 4 | P8: =+'4'!L287 -> 2600 | Q8: =+'4'!L292 -> 75 | R8: =+'4'!L290 -> 0 | S8: =+'4'!L298 -> 0 | T8: =+'4'!L291 -> 0 | U8: =+'4'!L289 -> 345 | V8: =+P8-Q8-R8-S8-T8-U8 -> 2180 | W8: =+'4'!L294 -> 2290 | X8: =+W8-V8 -> 110 | Y8: =+U8+W8+X8 -> 2745
A9: 5 | B9: ชิฟฟ่อนเค้ก 1 ชิ้น | C9: =+ยกมา!H9 -> 0 | D9: =+'1'!D9+'2'!D9+'3'!D9+'4'!D9+'5'!D9+'6'!D9+'7'!D9+'8'!D9+'9'!D9+'10'!D9+'11'!D9+'12'!D9+'13'!D9+'14'!D9+'15'!D9+'16'!D9+'17'!D9+'18'!D9+'19'!D9+'20'!D9+'21'!D9+'22'!D9+'23'!D9+'24'!D9+'25'!D9+'26'!D9+'27'!D9+'28'!D9+'29'!D9+'30'!D9+'31.'!D9 -> 0 | E9: =+C9+D9 -> 0 | F9: =+'1'!F9+'2'!F9+'3'!F9+'4'!F9+'5'!F9+'6'!F9+'7'!F9+'8'!F9+'9'!F9+'10'!F9+'11'!F9+'12'!F9+'13'!F9+'14'!F9+'15'!F9+'16'!F9+'17'!F9+'18'!F9+'19'!F9+'20'!F9+'21'!F9+'22'!F9+'23'!F9+'24'!F9+'25'!F9+'26'!F9+'27'!F9+'28'!F9+'29'!F9+'30'!F9+'31.'!F9 -> 0 | G9: =+'1'!G9+'2'!G9+'3'!G9+'4'!G9+'5'!G9+'6'!G9+'7'!G9+'8'!G9+'9'!G9+'10'!G9+'11'!G9+'12'!G9+'13'!G9+'14'!G9+'15'!G9+'16'!G9+'17'!G9+'18'!G9+'19'!G9+'20'!G9+'21'!G9+'22'!G9+'23'!G9+'24'!G9+'25'!G9+'26'!G9+'27'!G9+'28'!G9+'29'!G9+'30'!G9+'31.'!G9 -> 0 | H9: =C9+D9-F9-I9-G9 -> 0 | I9: =+'1'!I9+'2'!I9+'3'!I9+'4'!I9+'5'!I9+'6'!I9+'7'!I9+'8'!I9+'9'!I9+'10'!I9+'11'!I9+'12'!I9+'13'!I9+'14'!I9+'15'!I9+'16'!I9+'17'!I9+'18'!I9+'19'!I9+'20'!I9+'21'!I9+'22'!I9+'23'!I9+'24'!I9+'25'!I9+'26'!I9+'27'!I9+'28'!I9+'29'!I9+'30'!I9+'31.'!I9 -> 0 | J9: 10 | K9: =+I9*J9 -> 0 | N9: =+I9*M9 -> 0 | O9: 5 | P9: =+'5'!L287 -> 1985 | Q9: =+'5'!L292 -> 265 | R9: =+'5'!L290 -> 0 | S9: =+'5'!L288 -> 0 | T9: =+'5'!L291 -> 0 | U9: =+'5'!L289 -> 655 | V9: =+P9-Q9-R9-S9-T9-U9 -> 1065 | W9: =+'5'!L294 -> 1065 | X9: =+W9-V9 -> 0 | Y9: =+U9+W9+X9 -> 1720
A10: 6 | B10: ชิฟฟ่อนเค้กสอดไส้แยม 1 ชิ้น | C10: =+ยกมา!H10 -> 0 | D10: =+'1'!D10+'2'!D10+'3'!D10+'4'!D10+'5'!D10+'6'!D10+'7'!D10+'8'!D10+'9'!D10+'10'!D10+'11'!D10+'12'!D10+'13'!D10+'14'!D10+'15'!D10+'16'!D10+'17'!D10+'18'!D10+'19'!D10+'20'!D10+'21'!D10+'22'!D10+'23'!D10+'24'!D10+'25'!D10+'26'!D10+'27'!D10+'28'!D10+'29'!D10+'30'!D10+'31.'!D10 -> 0 | E10: =+C10+D10 -> 0 | F10: =+'1'!F10+'2'!F10+'3'!F10+'4'!F10+'5'!F10+'6'!F10+'7'!F10+'8'!F10+'9'!F10+'10'!F10+'11'!F10+'12'!F10+'13'!F10+'14'!F10+'15'!F10+'16'!F10+'17'!F10+'18'!F10+'19'!F10+'20'!F10+'21'!F10+'22'!F10+'23'!F10+'24'!F10+'25'!F10+'26'!F10+'27'!F10+'28'!F10+'29'!F10+'30'!F10+'31.'!F10 -> 0 | G10: =+'1'!G10+'2'!G10+'3'!G10+'4'!G10+'5'!G10+'6'!G10+'7'!G10+'8'!G10+'9'!G10+'10'!G10+'11'!G10+'12'!G10+'13'!G10+'14'!G10+'15'!G10+'16'!G10+'17'!G10+'18'!G10+'19'!G10+'20'!G10+'21'!G10+'22'!G10+'23'!G10+'24'!G10+'25'!G10+'26'!G10+'27'!G10+'28'!G10+'29'!G10+'30'!G10+'31.'!G10 -> 0 | H10: =C10+D10-F10-I10-G10 -> 0 | I10: =+'1'!I10+'2'!I10+'3'!I10+'4'!I10+'5'!I10+'6'!I10+'7'!I10+'8'!I10+'9'!I10+'10'!I10+'11'!I10+'12'!I10+'13'!I10+'14'!I10+'15'!I10+'16'!I10+'17'!I10+'18'!I10+'19'!I10+'20'!I10+'21'!I10+'22'!I10+'23'!I10+'24'!I10+'25'!I10+'26'!I10+'27'!I10+'28'!I10+'29'!I10+'30'!I10+'31.'!I10 -> 0 | J10: 15 | K10: =+I10*J10 -> 0 | N10: =+I10*M10 -> 0 | O10: 6 | P10: =+'6'!L287 -> 4675 | Q10: =+'6'!L292 -> 1320 | R10: =+'6'!L290 -> 0 | S10: =+'6'!L288 -> 0 | T10: =+'6'!L291 -> 50 | U10: =+'6'!L289 -> 360 | V10: =+P10-Q10-R10-S10-T10-U10 -> 2945 | W10: =+'6'!L294 -> 2945 | X10: =+W10-V10 -> 0 | Y10: =+U10+W10+X10 -> 3305
A11: 7 | B11: ชิฟฟ่อนเค้กสอดไส้เนย รสมะพร้าว (2 ชิ้น) | C11: =+ยกมา!H11 -> 0 | D11: =+'1'!D11+'2'!D11+'3'!D11+'4'!D11+'5'!D11+'6'!D11+'7'!D11+'8'!D11+'9'!D11+'10'!D11+'11'!D11+'12'!D11+'13'!D11+'14'!D11+'15'!D11+'16'!D11+'17'!D11+'18'!D11+'19'!D11+'20'!D11+'21'!D11+'22'!D11+'23'!D11+'24'!D11+'25'!D11+'26'!D11+'27'!D11+'28'!D11+'29'!D11+'30'!D11+'31.'!D11 -> 0 | E11: =+C11+D11 -> 0 | F11: =+'1'!F11+'2'!F11+'3'!F11+'4'!F11+'5'!F11+'6'!F11+'7'!F11+'8'!F11+'9'!F11+'10'!F11+'11'!F11+'12'!F11+'13'!F11+'14'!F11+'15'!F11+'16'!F11+'17'!F11+'18'!F11+'19'!F11+'20'!F11+'21'!F11+'22'!F11+'23'!F11+'24'!F11+'25'!F11+'26'!F11+'27'!F11+'28'!F11+'29'!F11+'30'!F11+'31.'!F11 -> 0 | G11: =+'1'!G11+'2'!G11+'3'!G11+'4'!G11+'5'!G11+'6'!G11+'7'!G11+'8'!G11+'9'!G11+'10'!G11+'11'!G11+'12'!G11+'13'!G11+'14'!G11+'15'!G11+'16'!G11+'17'!G11+'18'!G11+'19'!G11+'20'!G11+'21'!G11+'22'!G11+'23'!G11+'24'!G11+'25'!G11+'26'!G11+'27'!G11+'28'!G11+'29'!G11+'30'!G11+'31.'!G11 -> 0 | H11: =C11+D11-F11-I11-G11 -> 0 | I11: =+'1'!I11+'2'!I11+'3'!I11+'4'!I11+'5'!I11+'6'!I11+'7'!I11+'8'!I11+'9'!I11+'10'!I11+'11'!I11+'12'!I11+'13'!I11+'14'!I11+'15'!I11+'16'!I11+'17'!I11+'18'!I11+'19'!I11+'20'!I11+'21'!I11+'22'!I11+'23'!I11+'24'!I11+'25'!I11+'26'!I11+'27'!I11+'28'!I11+'29'!I11+'30'!I11+'31.'!I11 -> 0 | J11: 40 | K11: =+I11*J11 -> 0 | M11: 12.74 | N11: =+I11*M11 -> 0 | O11: 7 | P11: =+'7'!L287 -> 2060 | Q11: =+'7'!L292 -> 395 | R11: =+'7'!L290 -> 0 | S11: =+'7'!L288 -> 0 | T11: =+'7'!L291 -> 0 | U11: =+'7'!L289 -> 665 | V11: =+P11-Q11-R11-S11-T11-U11 -> 1000 | W11: =+'7'!L294 -> 1000 | X11: =+W11-V11 -> 0 | Y11: =+U11+W11+X11 -> 1665
A12: 8 | B12: ชิฟฟ่อน (ญ) ห่อซีน | C12: =+ยกมา!H12 -> 0 | D12: =+'1'!D12+'2'!D12+'3'!D12+'4'!D12+'5'!D12+'6'!D12+'7'!D12+'8'!D12+'9'!D12+'10'!D12+'11'!D12+'12'!D12+'13'!D12+'14'!D12+'15'!D12+'16'!D12+'17'!D12+'18'!D12+'19'!D12+'20'!D12+'21'!D12+'22'!D12+'23'!D12+'24'!D12+'25'!D12+'26'!D12+'27'!D12+'28'!D12+'29'!D12+'30'!D12+'31.'!D12 -> 0 | E12: =+C12+D12 -> 0 | F12: =+'1'!F12+'2'!F12+'3'!F12+'4'!F12+'5'!F12+'6'!F12+'7'!F12+'8'!F12+'9'!F12+'10'!F12+'11'!F12+'12'!F12+'13'!F12+'14'!F12+'15'!F12+'16'!F12+'17'!F12+'18'!F12+'19'!F12+'20'!F12+'21'!F12+'22'!F12+'23'!F12+'24'!F12+'25'!F12+'26'!F12+'27'!F12+'28'!F12+'29'!F12+'30'!F12+'31.'!F12 -> 0 | G12: =+'1'!G12+'2'!G12+'3'!G12+'4'!G12+'5'!G12+'6'!G12+'7'!G12+'8'!G12+'9'!G12+'10'!G12+'11'!G12+'12'!G12+'13'!G12+'14'!G12+'15'!G12+'16'!G12+'17'!G12+'18'!G12+'19'!G12+'20'!G12+'21'!G12+'22'!G12+'23'!G12+'24'!G12+'25'!G12+'26'!G12+'27'!G12+'28'!G12+'29'!G12+'30'!G12+'31.'!G12 -> 0 | H12: =C12+D12-F12-I12-G12 -> 0 | I12: =+'1'!I12+'2'!I12+'3'!I12+'4'!I12+'5'!I12+'6'!I12+'7'!I12+'8'!I12+'9'!I12+'10'!I12+'11'!I12+'12'!I12+'13'!I12+'14'!I12+'15'!I12+'16'!I12+'17'!I12+'18'!I12+'19'!I12+'20'!I12+'21'!I12+'22'!I12+'23'!I12+'24'!I12+'25'!I12+'26'!I12+'27'!I12+'28'!I12+'29'!I12+'30'!I12+'31.'!I12 -> 0 | J12: 100 | K12: =+I12*J12 -> 0 | N12: =+I12*M12 -> 0 | O12: 8 | P12: =+'8'!L287 -> 5435 | Q12: =+'8'!L292 -> 1175 | R12: =+'8'!L290 -> 0 | S12: =+'8'!L288 -> 0 | T12: =+'8'!L291 -> 50 | U12: =+'8'!L289 -> 1850 | V12: =+P12-Q12-R12-S12-T12-U12 -> 2360 | W12: =+'8'!L294 -> 2360 | X12: =+W12-V12 -> 0 | Y12: =+U12+W12+X12 -> 4210
A13: 9 | B13: ชิฟฟ่อนเค้กสอดไส้ รวมรส (3 ชิ้น) | C13: =+ยกมา!H13 -> 22 | D13: =+'1'!D13+'2'!D13+'3'!D13+'4'!D13+'5'!D13+'6'!D13+'7'!D13+'8'!D13+'9'!D13+'10'!D13+'11'!D13+'12'!D13+'13'!D13+'14'!D13+'15'!D13+'16'!D13+'17'!D13+'18'!D13+'19'!D13+'20'!D13+'21'!D13+'22'!D13+'23'!D13+'24'!D13+'25'!D13+'26'!D13+'27'!D13+'28'!D13+'29'!D13+'30'!D13+'31.'!D13 -> 40 | E13: =+C13+D13 -> 62 | F13: =+'1'!F13+'2'!F13+'3'!F13+'4'!F13+'5'!F13+'6'!F13+'7'!F13+'8'!F13+'9'!F13+'10'!F13+'11'!F13+'12'!F13+'13'!F13+'14'!F13+'15'!F13+'16'!F13+'17'!F13+'18'!F13+'19'!F13+'20'!F13+'21'!F13+'22'!F13+'23'!F13+'24'!F13+'25'!F13+'26'!F13+'27'!F13+'28'!F13+'29'!F13+'30'!F13+'31.'!F13 -> 2 | G13: =+'1'!G13+'2'!G13+'3'!G13+'4'!G13+'5'!G13+'6'!G13+'7'!G13+'8'!G13+'9'!G13+'10'!G13+'11'!G13+'12'!G13+'13'!G13+'14'!G13+'15'!G13+'16'!G13+'17'!G13+'18'!G13+'19'!G13+'20'!G13+'21'!G13+'22'!G13+'23'!G13+'24'!G13+'25'!G13+'26'!G13+'27'!G13+'28'!G13+'29'!G13+'30'!G13+'31.'!G13 -> 0 | H13: =C13+D13-F13-I13-G13 -> 18 | I13: =+'1'!I13+'2'!I13+'3'!I13+'4'!I13+'5'!I13+'6'!I13+'7'!I13+'8'!I13+'9'!I13+'10'!I13+'11'!I13+'12'!I13+'13'!I13+'14'!I13+'15'!I13+'16'!I13+'17'!I13+'18'!I13+'19'!I13+'20'!I13+'21'!I13+'22'!I13+'23'!I13+'24'!I13+'25'!I13+'26'!I13+'27'!I13+'28'!I13+'29'!I13+'30'!I13+'31.'!I13 -> 42 | J13: 50 | K13: =+I13*J13 -> 2100 | M13: 11.38 | N13: =+I13*M13 -> 477.96 | O13: 9 | P13: =+'9'!L287 -> 1580 | Q13: =+'9'!L292 -> 310 | R13: =+'9'!L290 -> 0 | S13: =+'9'!L288 -> 0 | T13: =+'9'!L291 -> 0 | U13: =+'9'!L289 -> 300 | V13: =+P13-Q13-R13-S13-T13-U13 -> 970 | W13: =+'9'!L294 -> 970 | X13: =+W13-V13 -> 0 | Y13: =+U13+W13+X13 -> 1270
A14: 10 | B14: ชิฟฟ่อนเค้กสอดไส้ เมล่อน (3 ชิ้น) | C14: =+ยกมา!H14 -> 0 | D14: =+'1'!D14+'2'!D14+'3'!D14+'4'!D14+'5'!D14+'6'!D14+'7'!D14+'8'!D14+'9'!D14+'10'!D14+'11'!D14+'12'!D14+'13'!D14+'14'!D14+'15'!D14+'16'!D14+'17'!D14+'18'!D14+'19'!D14+'20'!D14+'21'!D14+'22'!D14+'23'!D14+'24'!D14+'25'!D14+'26'!D14+'27'!D14+'28'!D14+'29'!D14+'30'!D14+'31.'!D14 -> 0 | E14: =+C14+D14 -> 0 | F14: =+'1'!F14+'2'!F14+'3'!F14+'4'!F14+'5'!F14+'6'!F14+'7'!F14+'8'!F14+'9'!F14+'10'!F14+'11'!F14+'12'!F14+'13'!F14+'14'!F14+'15'!F14+'16'!F14+'17'!F14+'18'!F14+'19'!F14+'20'!F14+'21'!F14+'22'!F14+'23'!F14+'24'!F14+'25'!F14+'26'!F14+'27'!F14+'28'!F14+'29'!F14+'30'!F14+'31.'!F14 -> 0 | G14: =+'1'!G14+'2'!G14+'3'!G14+'4'!G14+'5'!G14+'6'!G14+'7'!G14+'8'!G14+'9'!G14+'10'!G14+'11'!G14+'12'!G14+'13'!G14+'14'!G14+'15'!G14+'16'!G14+'17'!G14+'18'!G14+'19'!G14+'20'!G14+'21'!G14+'22'!G14+'23'!G14+'24'!G14+'25'!G14+'26'!G14+'27'!G14+'28'!G14+'29'!G14+'30'!G14+'31.'!G14 -> 0 | H14: =C14+D14-F14-I14-G14 -> 0 | I14: =+'1'!I14+'2'!I14+'3'!I14+'4'!I14+'5'!I14+'6'!I14+'7'!I14+'8'!I14+'9'!I14+'10'!I14+'11'!I14+'12'!I14+'13'!I14+'14'!I14+'15'!I14+'16'!I14+'17'!I14+'18'!I14+'19'!I14+'20'!I14+'21'!I14+'22'!I14+'23'!I14+'24'!I14+'25'!I14+'26'!I14+'27'!I14+'28'!I14+'29'!I14+'30'!I14+'31.'!I14 -> 0 | J14: 50 | K14: =+I14*J14 -> 0 | N14: =+I14*M14 -> 0 | O14: 10 | P14: =+'10'!L287 -> 5805 | Q14: =+'10'!L292 -> 720 | R14: =+'10'!L290 -> 0 | S14: =+'10'!L288 -> 0 | T14: =+'10'!L291 -> 50 | U14: =+'10'!L289 -> 670 | V14: =+P14-Q14-R14-S14-T14-U14 -> 4365 | W14: =+'10'!L294 -> 4365 | X14: =+W14-V14 -> 0 | Y14: =+U14+W14+X14 -> 5035
A15: 11 | B15: ชิฟฟ่อนเค้กสอดไส้แยม รสบลูเบอร์รี่ (3 ชิ้น) | C15: =+ยกมา!H15 -> 0 | D15: =+'1'!D15+'2'!D15+'3'!D15+'4'!D15+'5'!D15+'6'!D15+'7'!D15+'8'!D15+'9'!D15+'10'!D15+'11'!D15+'12'!D15+'13'!D15+'14'!D15+'15'!D15+'16'!D15+'17'!D15+'18'!D15+'19'!D15+'20'!D15+'21'!D15+'22'!D15+'23'!D15+'24'!D15+'25'!D15+'26'!D15+'27'!D15+'28'!D15+'29'!D15+'30'!D15+'31.'!D15 -> 0 | E15: =+C15+D15 -> 0 | F15: =+'1'!F15+'2'!F15+'3'!F15+'4'!F15+'5'!F15+'6'!F15+'7'!F15+'8'!F15+'9'!F15+'10'!F15+'11'!F15+'12'!F15+'13'!F15+'14'!F15+'15'!F15+'16'!F15+'17'!F15+'18'!F15+'19'!F15+'20'!F15+'21'!F15+'22'!F15+'23'!F15+'24'!F15+'25'!F15+'26'!F15+'27'!F15+'28'!F15+'29'!F15+'30'!F15+'31.'!F15 -> 0 | G15: =+'1'!G15+'2'!G15+'3'!G15+'4'!G15+'5'!G15+'6'!G15+'7'!G15+'8'!G15+'9'!G15+'10'!G15+'11'!G15+'12'!G15+'13'!G15+'14'!G15+'15'!G15+'16'!G15+'17'!G15+'18'!G15+'19'!G15+'20'!G15+'21'!G15+'22'!G15+'23'!G15+'24'!G15+'25'!G15+'26'!G15+'27'!G15+'28'!G15+'29'!G15+'30'!G15+'31.'!G15 -> 0 | H15: =C15+D15-F15-I15-G15 -> 0 | I15: =+'1'!I15+'2'!I15+'3'!I15+'4'!I15+'5'!I15+'6'!I15+'7'!I15+'8'!I15+'9'!I15+'10'!I15+'11'!I15+'12'!I15+'13'!I15+'14'!I15+'15'!I15+'16'!I15+'17'!I15+'18'!I15+'19'!I15+'20'!I15+'21'!I15+'22'!I15+'23'!I15+'24'!I15+'25'!I15+'26'!I15+'27'!I15+'28'!I15+'29'!I15+'30'!I15+'31.'!I15 -> 0 | J15: 50 | K15: =+I15*J15 -> 0 | M15: 17.32 | N15: =+I15*M15 -> 0 | O15: 11 | P15: =+'11'!L287 -> 4750 | Q15: =+'11'!L292 -> 895 | R15: =+'11'!L290 -> 0 | S15: =+'11'!L288 -> 0 | T15: =+'11'!L291 -> 0 | U15: =+'11'!L289 -> 1430 | V15: =+P15-Q15-R15-S15-T15-U15 -> 2425 | W15: =+'11'!L294 -> 2425 | X15: =+W15-V15 -> 0 | Y15: =+U15+W15+X15 -> 3855
A16: 12 | B16: ชิฟฟ่อนเค้กสอดไส้แยม รสส้ม (3 ชิ้น) | C16: =+ยกมา!H16 -> 25 | D16: =+'1'!D16+'2'!D16+'3'!D16+'4'!D16+'5'!D16+'6'!D16+'7'!D16+'8'!D16+'9'!D16+'10'!D16+'11'!D16+'12'!D16+'13'!D16+'14'!D16+'15'!D16+'16'!D16+'17'!D16+'18'!D16+'19'!D16+'20'!D16+'21'!D16+'22'!D16+'23'!D16+'24'!D16+'25'!D16+'26'!D16+'27'!D16+'28'!D16+'29'!D16+'30'!D16+'31.'!D16 -> 35 | E16: =+C16+D16 -> 60 | F16: =+'1'!F16+'2'!F16+'3'!F16+'4'!F16+'5'!F16+'6'!F16+'7'!F16+'8'!F16+'9'!F16+'10'!F16+'11'!F16+'12'!F16+'13'!F16+'14'!F16+'15'!F16+'16'!F16+'17'!F16+'18'!F16+'19'!F16+'20'!F16+'21'!F16+'22'!F16+'23'!F16+'24'!F16+'25'!F16+'26'!F16+'27'!F16+'28'!F16+'29'!F16+'30'!F16+'31.'!F16 -> 16 | G16: =+'1'!G16+'2'!G16+'3'!G16+'4'!G16+'5'!G16+'6'!G16+'7'!G16+'8'!G16+'9'!G16+'10'!G16+'11'!G16+'12'!G16+'13'!G16+'14'!G16+'15'!G16+'16'!G16+'17'!G16+'18'!G16+'19'!G16+'20'!G16+'21'!G16+'22'!G16+'23'!G16+'24'!G16+'25'!G16+'26'!G16+'27'!G16+'28'!G16+'29'!G16+'30'!G16+'31.'!G16 -> 0 | H16: =C16+D16-F16-I16-G16 -> 21 | I16: =+'1'!I16+'2'!I16+'3'!I16+'4'!I16+'5'!I16+'6'!I16+'7'!I16+'8'!I16+'9'!I16+'10'!I16+'11'!I16+'12'!I16+'13'!I16+'14'!I16+'15'!I16+'16'!I16+'17'!I16+'18'!I16+'19'!I16+'20'!I16+'21'!I16+'22'!I16+'23'!I16+'24'!I16+'25'!I16+'26'!I16+'27'!I16+'28'!I16+'29'!I16+'30'!I16+'31.'!I16 -> 23 | J16: 50 | K16: =+I16*J16 -> 1150 | M16: 16.92 | O16: 12 | P16: =+'12'!L287 -> 4765 | Q16: =+'12'!L292 -> 655 | R16: =+'12'!L290 -> 0 | S16: =+'12'!L288 -> 0 | T16: =+'12'!L291 -> 0 | U16: =+'12'!L289 -> 1210 | V16: =+P16-Q16-R16-S16-T16-U16 -> 2900 | W16: =+'12'!L294 -> 2900 | X16: =+W16-V16 -> 0 | Y16: =+U16+W16+X16 -> 4110
A17: 13 | B17: ชิฟฟ่อนเค้กหน้าฝอยทอง สอดไส้แยมส้ม (3 ชิ้น) | C17: =+ยกมา!H17 -> 18 | D17: =+'1'!D17+'2'!D17+'3'!D17+'4'!D17+'5'!D17+'6'!D17+'7'!D17+'8'!D17+'9'!D17+'10'!D17+'11'!D17+'12'!D17+'13'!D17+'14'!D17+'15'!D17+'16'!D17+'17'!D17+'18'!D17+'19'!D17+'20'!D17+'21'!D17+'22'!D17+'23'!D17+'24'!D17+'25'!D17+'26'!D17+'27'!D17+'28'!D17+'29'!D17+'30'!D17+'31.'!D17 -> 35 | E17: =+C17+D17 -> 53 | F17: =+'1'!F17+'2'!F17+'3'!F17+'4'!F17+'5'!F17+'6'!F17+'7'!F17+'8'!F17+'9'!F17+'10'!F17+'11'!F17+'12'!F17+'13'!F17+'14'!F17+'15'!F17+'16'!F17+'17'!F17+'18'!F17+'19'!F17+'20'!F17+'21'!F17+'22'!F17+'23'!F17+'24'!F17+'25'!F17+'26'!F17+'27'!F17+'28'!F17+'29'!F17+'30'!F17+'31.'!F17 -> 3 | G17: =+'1'!G17+'2'!G17+'3'!G17+'4'!G17+'5'!G17+'6'!G17+'7'!G17+'8'!G17+'9'!G17+'10'!G17+'11'!G17+'12'!G17+'13'!G17+'14'!G17+'15'!G17+'16'!G17+'17'!G17+'18'!G17+'19'!G17+'20'!G17+'21'!G17+'22'!G17+'23'!G17+'24'!G17+'25'!G17+'26'!G17+'27'!G17+'28'!G17+'29'!G17+'30'!G17+'31.'!G17 -> 0 | H17: =C17+D17-F17-I17-G17 -> 20 | I17: =+'1'!I17+'2'!I17+'3'!I17+'4'!I17+'5'!I17+'6'!I17+'7'!I17+'8'!I17+'9'!I17+'10'!I17+'11'!I17+'12'!I17+'13'!I17+'14'!I17+'15'!I17+'16'!I17+'17'!I17+'18'!I17+'19'!I17+'20'!I17+'21'!I17+'22'!I17+'23'!I17+'24'!I17+'25'!I17+'26'!I17+'27'!I17+'28'!I17+'29'!I17+'30'!I17+'31.'!I17 -> 30 | J17: 50 | K17: =+I17*J17 -> 1500 | M17: 21.22 | N17: =+I17*M17 -> 636.6 | O17: 13 | P17: =+'13'!L287 -> 4810 | Q17: =+'13'!L292 -> 530 | R17: =+'13'!L290 -> 0 | S17: =+'13'!L288 -> 0 | T17: =+'13'!L291 -> 0 | U17: =+'13'!L289 -> 955 | V17: =+P17-Q17-R17-S17-T17-U17 -> 3325 | W17: =+'13'!L294 -> 3325 | X17: =+W17-V17 -> 0 | Y17: =+U17+W17+X17 -> 4280
A18: 14 | B18: ชิฟฟ่อนเค้กหน้าฝอยทองทูโทน สอดไส้แยมส้ม (3 ชิ้น) | C18: =+ยกมา!H17 -> 18 | D18: =+'1'!D18+'2'!D18+'3'!D18+'4'!D18+'5'!D18+'6'!D18+'7'!D18+'8'!D18+'9'!D18+'10'!D18+'11'!D18+'12'!D18+'13'!D18+'14'!D18+'15'!D18+'16'!D18+'17'!D18+'18'!D18+'19'!D18+'20'!D18+'21'!D18+'22'!D18+'23'!D18+'24'!D18+'25'!D18+'26'!D18+'27'!D18+'28'!D18+'29'!D18+'30'!D18+'31.'!D18 -> 0 | E18: =+C18+D18 -> 18 | F18: =+'1'!F18+'2'!F18+'3'!F18+'4'!F18+'5'!F18+'6'!F18+'7'!F18+'8'!F18+'9'!F18+'10'!F18+'11'!F18+'12'!F18+'13'!F18+'14'!F18+'15'!F18+'16'!F18+'17'!F18+'18'!F18+'19'!F18+'20'!F18+'21'!F18+'22'!F18+'23'!F18+'24'!F18+'25'!F18+'26'!F18+'27'!F18+'28'!F18+'29'!F18+'30'!F18+'31.'!F18 -> 0 | G18: =+'1'!G18+'2'!G18+'3'!G18+'4'!G18+'5'!G18+'6'!G18+'7'!G18+'8'!G18+'9'!G18+'10'!G18+'11'!G18+'12'!G18+'13'!G18+'14'!G18+'15'!G18+'16'!G18+'17'!G18+'18'!G18+'19'!G18+'20'!G18+'21'!G18+'22'!G18+'23'!G18+'24'!G18+'25'!G18+'26'!G18+'27'!G18+'28'!G18+'29'!G18+'30'!G18+'31.'!G18 -> 0 | H18: =C18+D18-F18-I18-G18 -> 18 | I18: =+'1'!I18+'2'!I18+'3'!I18+'4'!I18+'5'!I18+'6'!I18+'7'!I18+'8'!I18+'9'!I18+'10'!I18+'11'!I18+'12'!I18+'13'!I18+'14'!I18+'15'!I18+'16'!I18+'17'!I18+'18'!I18+'19'!I18+'20'!I18+'21'!I18+'22'!I18+'23'!I18+'24'!I18+'25'!I18+'26'!I18+'27'!I18+'28'!I18+'29'!I18+'30'!I18+'31.'!I18 -> 0 | J18: 50 | K18: =+I18*J18 -> 0 | N18: =+I18*M18 -> 0 | O18: 14 | P18: =+'14'!L287 -> 2175 | Q18: =+'14'!L292 -> 220 | R18: =+'14'!L290 -> 0 | S18: =+'14'!L288 -> 0 | T18: =+'14'!L291 -> 0 | U18: =+'14'!L289 -> 235 | V18: =+P18-Q18-R18-S18-T18-U18 -> 1720 | W18: =+'14'!L294 -> 1720 | X18: =+W18-V18 -> 0 | Y18: =+U18+W18+X18 -> 1955
A19: 15 | B19: ชิฟฟ่อนเค้กสอดไส้แยม รสสตรอว์เบอรี่ (3 ชิ้น) | C19: =+ยกมา!H18 -> 0 | D19: =+'1'!D19+'2'!D19+'3'!D19+'4'!D19+'5'!D19+'6'!D19+'7'!D19+'8'!D19+'9'!D19+'10'!D19+'11'!D19+'12'!D19+'13'!D19+'14'!D19+'15'!D19+'16'!D19+'17'!D19+'18'!D19+'19'!D19+'20'!D19+'21'!D19+'22'!D19+'23'!D19+'24'!D19+'25'!D19+'26'!D19+'27'!D19+'28'!D19+'29'!D19+'30'!D19+'31.'!D19 -> 0 | E19: =+C19+D19 -> 0 | F19: =+'1'!F19+'2'!F19+'3'!F19+'4'!F19+'5'!F19+'6'!F19+'7'!F19+'8'!F19+'9'!F19+'10'!F19+'11'!F19+'12'!F19+'13'!F19+'14'!F19+'15'!F19+'16'!F19+'17'!F19+'18'!F19+'19'!F19+'20'!F19+'21'!F19+'22'!F19+'23'!F19+'24'!F19+'25'!F19+'26'!F19+'27'!F19+'28'!F19+'29'!F19+'30'!F19+'31.'!F19 -> 0 | G19: =+'1'!G19+'2'!G19+'3'!G19+'4'!G19+'5'!G19+'6'!G19+'7'!G19+'8'!G19+'9'!G19+'10'!G19+'11'!G19+'12'!G19+'13'!G19+'14'!G19+'15'!G19+'16'!G19+'17'!G19+'18'!G19+'19'!G19+'20'!G19+'21'!G19+'22'!G19+'23'!G19+'24'!G19+'25'!G19+'26'!G19+'27'!G19+'28'!G19+'29'!G19+'30'!G19+'31.'!G19 -> 0 | H19: =C19+D19-F19-I19-G19 -> 0 | I19: =+'1'!I19+'2'!I19+'3'!I19+'4'!I19+'5'!I19+'6'!I19+'7'!I19+'8'!I19+'9'!I19+'10'!I19+'11'!I19+'12'!I19+'13'!I19+'14'!I19+'15'!I19+'16'!I19+'17'!I19+'18'!I19+'19'!I19+'20'!I19+'21'!I19+'22'!I19+'23'!I19+'24'!I19+'25'!I19+'26'!I19+'27'!I19+'28'!I19+'29'!I19+'30'!I19+'31.'!I19 -> 0 | J19: 50 | K19: =+I19*J19 -> 0 | M19: 15.05 | N19: =+I19*M19 -> 0 | O19: 15 | P19: =+'15'!L287 -> 1980 | Q19: =+'15'!L292 -> 330 | R19: =+'15'!L290 -> 0 | S19: =+'15'!L288 -> 0 | T19: =+'15'!L291 -> 0 | U19: =+'15'!L289 -> 1095 | V19: =+P19-Q19-R19-S19-T19-U19 -> 555 | W19: =+'15'!L294 -> 555 | X19: =+W19-V19 -> 0 | Y19: =+U19+W19+X19 -> 1650
A20: 16 | B20: ชิฟฟ่อนเค้กสอดไส้เนย รสมะพร้าว (3 ชิ้น) | C20: =+ยกมา!H19 -> 0 | D20: =+'1'!D20+'2'!D20+'3'!D20+'4'!D20+'5'!D20+'6'!D20+'7'!D20+'8'!D20+'9'!D20+'10'!D20+'11'!D20+'12'!D20+'13'!D20+'14'!D20+'15'!D20+'16'!D20+'17'!D20+'18'!D20+'19'!D20+'20'!D20+'21'!D20+'22'!D20+'23'!D20+'24'!D20+'25'!D20+'26'!D20+'27'!D20+'28'!D20+'29'!D20+'30'!D20+'31.'!D20 -> 36 | E20: =+C20+D20 -> 36 | F20: =+'1'!F20+'2'!F20+'3'!F20+'4'!F20+'5'!F20+'6'!F20+'7'!F20+'8'!F20+'9'!F20+'10'!F20+'11'!F20+'12'!F20+'13'!F20+'14'!F20+'15'!F20+'16'!F20+'17'!F20+'18'!F20+'19'!F20+'20'!F20+'21'!F20+'22'!F20+'23'!F20+'24'!F20+'25'!F20+'26'!F20+'27'!F20+'28'!F20+'29'!F20+'30'!F20+'31.'!F20 -> 6 | G20: =+'1'!G20+'2'!G20+'3'!G20+'4'!G20+'5'!G20+'6'!G20+'7'!G20+'8'!G20+'9'!G20+'10'!G20+'11'!G20+'12'!G20+'13'!G20+'14'!G20+'15'!G20+'16'!G20+'17'!G20+'18'!G20+'19'!G20+'20'!G20+'21'!G20+'22'!G20+'23'!G20+'24'!G20+'25'!G20+'26'!G20+'27'!G20+'28'!G20+'29'!G20+'30'!G20+'31.'!G20 -> 0 | H20: =C20+D20-F20-I20-G20 -> 5 | I20: =+'1'!I20+'2'!I20+'3'!I20+'4'!I20+'5'!I20+'6'!I20+'7'!I20+'8'!I20+'9'!I20+'10'!I20+'11'!I20+'12'!I20+'13'!I20+'14'!I20+'15'!I20+'16'!I20+'17'!I20+'18'!I20+'19'!I20+'20'!I20+'21'!I20+'22'!I20+'23'!I20+'24'!I20+'25'!I20+'26'!I20+'27'!I20+'28'!I20+'29'!I20+'30'!I20+'31.'!I20 -> 25 | J20: 50 | K20: =+I20*J20 -> 1250 | M20: 16.7 | N20: =+I20*M20 -> 417.5 | O20: 16 | P20: =+'16'!L287 -> 2015 | Q20: =+'16'!L292 -> 240 | R20: =+'16'!L290 -> 0 | S20: =+'16'!L288 -> 0 | T20: =+'16'!L291 -> 50 | U20: =+'16'!L289 -> 230 | V20: =+P20-Q20-R20-S20-T20-U20 -> 1495 | W20: =+'16'!L294 -> 1495 | X20: =+W20-V20 -> 0 | Y20: =+U20+W20+X20 -> 1725
A21: 17 | B21: ชิฟฟ่อนเค้กสอดไส้ นมชมพูฮอกไกโด (3 ชิ้น) | C21: =+ยกมา!H20 -> 13 | D21: =+'1'!D21+'2'!D21+'3'!D21+'4'!D21+'5'!D21+'6'!D21+'7'!D21+'8'!D21+'9'!D21+'10'!D21+'11'!D21+'12'!D21+'13'!D21+'14'!D21+'15'!D21+'16'!D21+'17'!D21+'18'!D21+'19'!D21+'20'!D21+'21'!D21+'22'!D21+'23'!D21+'24'!D21+'25'!D21+'26'!D21+'27'!D21+'28'!D21+'29'!D21+'30'!D21+'31.'!D21 -> 0 | E21: =+C21+D21 -> 13 | F21: =+'1'!F21+'2'!F21+'3'!F21+'4'!F21+'5'!F21+'6'!F21+'7'!F21+'8'!F21+'9'!F21+'10'!F21+'11'!F21+'12'!F21+'13'!F21+'14'!F21+'15'!F21+'16'!F21+'17'!F21+'18'!F21+'19'!F21+'20'!F21+'21'!F21+'22'!F21+'23'!F21+'24'!F21+'25'!F21+'26'!F21+'27'!F21+'28'!F21+'29'!F21+'30'!F21+'31.'!F21 -> 0 | G21: =+'1'!G21+'2'!G21+'3'!G21+'4'!G21+'5'!G21+'6'!G21+'7'!G21+'8'!G21+'9'!G21+'10'!G21+'11'!G21+'12'!G21+'13'!G21+'14'!G21+'15'!G21+'16'!G21+'17'!G21+'18'!G21+'19'!G21+'20'!G21+'21'!G21+'22'!G21+'23'!G21+'24'!G21+'25'!G21+'26'!G21+'27'!G21+'28'!G21+'29'!G21+'30'!G21+'31.'!G21 -> 0 | H21: =C21+D21-F21-I21-G21 -> 13 | I21: =+'1'!I21+'2'!I21+'3'!I21+'4'!I21+'5'!I21+'6'!I21+'7'!I21+'8'!I21+'9'!I21+'10'!I21+'11'!I21+'12'!I21+'13'!I21+'14'!I21+'15'!I21+'16'!I21+'17'!I21+'18'!I21+'19'!I21+'20'!I21+'21'!I21+'22'!I21+'23'!I21+'24'!I21+'25'!I21+'26'!I21+'27'!I21+'28'!I21+'29'!I21+'30'!I21+'31.'!I21 -> 0 | J21: 50 | K21: =+I21*J21 -> 0 | M21: 19.04 | N21: =+I21*M21 -> 0 | O21: 17 | P21: =+'17'!L287 -> 2885 | Q21: =+'17'!L292 -> 335 | R21: =+'17'!L290 -> 0 | S21: =+'17'!L288 -> 0 | T21: =+'17'!L291 -> 22 | U21: =+'17'!L289 -> 220 | V21: =+P21-Q21-R21-S21-T21-U21 -> 2308 | W21: =+'17'!L294 -> 2308 | X21: =+W21-V21 -> 0 | Y21: =+U21+W21+X21 -> 2528
A22: 18 | B22: ชิฟฟ่อนเค้กสอดไส้ ช็อคโกแลตนูเทลล่า (3 ชิ้น) | C22: =+ยกมา!H21 -> 0 | D22: =+'1'!D22+'2'!D22+'3'!D22+'4'!D22+'5'!D22+'6'!D22+'7'!D22+'8'!D22+'9'!D22+'10'!D22+'11'!D22+'12'!D22+'13'!D22+'14'!D22+'15'!D22+'16'!D22+'17'!D22+'18'!D22+'19'!D22+'20'!D22+'21'!D22+'22'!D22+'23'!D22+'24'!D22+'25'!D22+'26'!D22+'27'!D22+'28'!D22+'29'!D22+'30'!D22+'31.'!D22 -> 0 | E22: =+C22+D22 -> 0 | F22: =+'1'!F22+'2'!F22+'3'!F22+'4'!F22+'5'!F22+'6'!F22+'7'!F22+'8'!F22+'9'!F22+'10'!F22+'11'!F22+'12'!F22+'13'!F22+'14'!F22+'15'!F22+'16'!F22+'17'!F22+'18'!F22+'19'!F22+'20'!F22+'21'!F22+'22'!F22+'23'!F22+'24'!F22+'25'!F22+'26'!F22+'27'!F22+'28'!F22+'29'!F22+'30'!F22+'31.'!F22 -> 0 | G22: =+'1'!G22+'2'!G22+'3'!G22+'4'!G22+'5'!G22+'6'!G22+'7'!G22+'8'!G22+'9'!G22+'10'!G22+'11'!G22+'12'!G22+'13'!G22+'14'!G22+'15'!G22+'16'!G22+'17'!G22+'18'!G22+'19'!G22+'20'!G22+'21'!G22+'22'!G22+'23'!G22+'24'!G22+'25'!G22+'26'!G22+'27'!G22+'28'!G22+'29'!G22+'30'!G22+'31.'!G22 -> 0 | H22: =C22+D22-F22-I22-G22 -> 0 | I22: =+'1'!I22+'2'!I22+'3'!I22+'4'!I22+'5'!I22+'6'!I22+'7'!I22+'8'!I22+'9'!I22+'10'!I22+'11'!I22+'12'!I22+'13'!I22+'14'!I22+'15'!I22+'16'!I22+'17'!I22+'18'!I22+'19'!I22+'20'!I22+'21'!I22+'22'!I22+'23'!I22+'24'!I22+'25'!I22+'26'!I22+'27'!I22+'28'!I22+'29'!I22+'30'!I22+'31.'!I22 -> 0 | J22: 50 | K22: =+I22*J22 -> 0 | M22: 15.3 | N22: =+I22*M22 -> 0 | O22: 18 | P22: =+'18'!L287 -> 2330 | Q22: =+'18'!L292 -> 310 | R22: =+'18'!L290 -> 0 | S22: =+'18'!L288 -> 0 | T22: =+'18'!L291 -> 0 | U22: =+'18'!L289 -> 340 | V22: =+P22-Q22-R22-S22-T22-U22 -> 1680 | W22: =+'18'!L294 -> 1680 | X22: =+W22-V22 -> 0 | Y22: =+U22+W22+X22 -> 2020
A23: 19 | B23: ชิฟฟ่อน สอดไส้ (ล) 4 ชิ้น ครีมมะพร้าว | C23: =+ยกมา!H22 -> 0 | D23: =+'1'!D23+'2'!D23+'3'!D23+'4'!D23+'5'!D23+'6'!D23+'7'!D23+'8'!D23+'9'!D23+'10'!D23+'11'!D23+'12'!D23+'13'!D23+'14'!D23+'15'!D23+'16'!D23+'17'!D23+'18'!D23+'19'!D23+'20'!D23+'21'!D23+'22'!D23+'23'!D23+'24'!D23+'25'!D23+'26'!D23+'27'!D23+'28'!D23+'29'!D23+'30'!D23+'31.'!D23 -> 0 | E23: =+C23+D23 -> 0 | F23: =+'1'!F23+'2'!F23+'3'!F23+'4'!F23+'5'!F23+'6'!F23+'7'!F23+'8'!F23+'9'!F23+'10'!F23+'11'!F23+'12'!F23+'13'!F23+'14'!F23+'15'!F23+'16'!F23+'17'!F23+'18'!F23+'19'!F23+'20'!F23+'21'!F23+'22'!F23+'23'!F23+'24'!F23+'25'!F23+'26'!F23+'27'!F23+'28'!F23+'29'!F23+'30'!F23+'31.'!F23 -> 0 | G23: =+'1'!G23+'2'!G23+'3'!G23+'4'!G23+'5'!G23+'6'!G23+'7'!G23+'8'!G23+'9'!G23+'10'!G23+'11'!G23+'12'!G23+'13'!G23+'14'!G23+'15'!G23+'16'!G23+'17'!G23+'18'!G23+'19'!G23+'20'!G23+'21'!G23+'22'!G23+'23'!G23+'24'!G23+'25'!G23+'26'!G23+'27'!G23+'28'!G23+'29'!G23+'30'!G23+'31.'!G23 -> 0 | H23: =C23+D23-F23-I23-G23 -> 0 | I23: =+'1'!I23+'2'!I23+'3'!I23+'4'!I23+'5'!I23+'6'!I23+'7'!I23+'8'!I23+'9'!I23+'10'!I23+'11'!I23+'12'!I23+'13'!I23+'14'!I23+'15'!I23+'16'!I23+'17'!I23+'18'!I23+'19'!I23+'20'!I23+'21'!I23+'22'!I23+'23'!I23+'24'!I23+'25'!I23+'26'!I23+'27'!I23+'28'!I23+'29'!I23+'30'!I23+'31.'!I23 -> 0 | J23: 65 | K23: =+I23*J23 -> 0 | M23: 27.86 | N23: =+I23*M23 -> 0 | O23: 19 | P23: =+'19'!L287 -> 1280 | Q23: =+'19'!L292 -> 350 | R23: =+'19'!L290 -> 0 | S23: =+'19'!L288 -> 0 | T23: =+'19'!L291 -> 0 | U23: =+'19'!L289 -> 0 | V23: =+P23-Q23-R23-S23-T23-U23 -> 930 | W23: =+'19'!L294 -> 930 | X23: =+W23-V23 -> 0 | Y23: =+U23+W23+X23 -> 930
A24: 20 | B24: ชิฟฟ่อน สอดไส้ (ก) 5 ชิ้น ครีมมะพร้าว | C24: =+ยกมา!H23 -> 0 | D24: =+'1'!D24+'2'!D24+'3'!D24+'4'!D24+'5'!D24+'6'!D24+'7'!D24+'8'!D24+'9'!D24+'10'!D24+'11'!D24+'12'!D24+'13'!D24+'14'!D24+'15'!D24+'16'!D24+'17'!D24+'18'!D24+'19'!D24+'20'!D24+'21'!D24+'22'!D24+'23'!D24+'24'!D24+'25'!D24+'26'!D24+'27'!D24+'28'!D24+'29'!D24+'30'!D24+'31.'!D24 -> 0 | E24: =+C24+D24 -> 0 | F24: =+'1'!F24+'2'!F24+'3'!F24+'4'!F24+'5'!F24+'6'!F24+'7'!F24+'8'!F24+'9'!F24+'10'!F24+'11'!F24+'12'!F24+'13'!F24+'14'!F24+'15'!F24+'16'!F24+'17'!F24+'18'!F24+'19'!F24+'20'!F24+'21'!F24+'22'!F24+'23'!F24+'24'!F24+'25'!F24+'26'!F24+'27'!F24+'28'!F24+'29'!F24+'30'!F24+'31.'!F24 -> 0 | G24: =+'1'!G24+'2'!G24+'3'!G24+'4'!G24+'5'!G24+'6'!G24+'7'!G24+'8'!G24+'9'!G24+'10'!G24+'11'!G24+'12'!G24+'13'!G24+'14'!G24+'15'!G24+'16'!G24+'17'!G24+'18'!G24+'19'!G24+'20'!G24+'21'!G24+'22'!G24+'23'!G24+'24'!G24+'25'!G24+'26'!G24+'27'!G24+'28'!G24+'29'!G24+'30'!G24+'31.'!G24 -> 0 | H24: =C24+D24-F24-I24-G24 -> 0 | I24: =+'1'!I24+'2'!I24+'3'!I24+'4'!I24+'5'!I24+'6'!I24+'7'!I24+'8'!I24+'9'!I24+'10'!I24+'11'!I24+'12'!I24+'13'!I24+'14'!I24+'15'!I24+'16'!I24+'17'!I24+'18'!I24+'19'!I24+'20'!I24+'21'!I24+'22'!I24+'23'!I24+'24'!I24+'25'!I24+'26'!I24+'27'!I24+'28'!I24+'29'!I24+'30'!I24+'31.'!I24 -> 0 | J24: 85 | K24: =+I24*J24 -> 0 | M24: 26.91 | N24: =+I24*M24 -> 0 | O24: 20 | P24: =+'20'!L287 -> 4115 | Q24: =+'20'!L292 -> 655 | R24: =+'20'!L290 -> 0 | S24: =+'20'!L288 -> 0 | T24: =+'20'!L291 -> 0 | U24: =+'20'!L289 -> 145 | V24: =+P24-Q24-R24-S24-T24-U24 -> 3315 | W24: =+'20'!L294 -> 3315 | X24: =+W24-V24 -> 0 | Y24: =+U24+W24+X24 -> 3460
A25: 21 | B25: ชิฟฟ่อนเค้กสอดไส้ รวมรส (6 ชิ้น) | C25: =+ยกมา!H24 -> 0 | D25: =+'1'!D25+'2'!D25+'3'!D25+'4'!D25+'5'!D25+'6'!D25+'7'!D25+'8'!D25+'9'!D25+'10'!D25+'11'!D25+'12'!D25+'13'!D25+'14'!D25+'15'!D25+'16'!D25+'17'!D25+'18'!D25+'19'!D25+'20'!D25+'21'!D25+'22'!D25+'23'!D25+'24'!D25+'25'!D25+'26'!D25+'27'!D25+'28'!D25+'29'!D25+'30'!D25+'31.'!D25 -> 60 | E25: =+C25+D25 -> 60 | F25: =+'1'!F25+'2'!F25+'3'!F25+'4'!F25+'5'!F25+'6'!F25+'7'!F25+'8'!F25+'9'!F25+'10'!F25+'11'!F25+'12'!F25+'13'!F25+'14'!F25+'15'!F25+'16'!F25+'17'!F25+'18'!F25+'19'!F25+'20'!F25+'21'!F25+'22'!F25+'23'!F25+'24'!F25+'25'!F25+'26'!F25+'27'!F25+'28'!F25+'29'!F25+'30'!F25+'31.'!F25 -> 11 | G25: =+'1'!G25+'2'!G25+'3'!G25+'4'!G25+'5'!G25+'6'!G25+'7'!G25+'8'!G25+'9'!G25+'10'!G25+'11'!G25+'12'!G25+'13'!G25+'14'!G25+'15'!G25+'16'!G25+'17'!G25+'18'!G25+'19'!G25+'20'!G25+'21'!G25+'22'!G25+'23'!G25+'24'!G25+'25'!G25+'26'!G25+'27'!G25+'28'!G25+'29'!G25+'30'!G25+'31.'!G25 -> 0 | H25: =C25+D25-F25-I25-G25 -> -10 | I25: =+'1'!I25+'2'!I25+'3'!I25+'4'!I25+'5'!I25+'6'!I25+'7'!I25+'8'!I25+'9'!I25+'10'!I25+'11'!I25+'12'!I25+'13'!I25+'14'!I25+'15'!I25+'16'!I25+'17'!I25+'18'!I25+'19'!I25+'20'!I25+'21'!I25+'22'!I25+'23'!I25+'24'!I25+'25'!I25+'26'!I25+'27'!I25+'28'!I25+'29'!I25+'30'!I25+'31.'!I25 -> 59 | J25: 100 | K25: =+I25*J25 -> 5900 | M25: 24.8 | N25: =+I25*M25 -> 1463.2 | O25: 21 | P25: =+'21'!L287 -> 2100 | Q25: =+'21'!L292 -> 340 | R25: =+'21'!L290 -> 0 | S25: =+'21'!L288 -> 0 | T25: =+'21'!L291 -> 50 | U25: =+'21'!L289 -> 150 | V25: =+P25-Q25-R25-S25-T25-U25 -> 1560 | W25: =+'21'!L294 -> 1560 | X25: =+W25-V25 -> 0 | Y25: =+U25+W25+X25 -> 1710
A26: 22 | B26: ชิฟฟ่อนเค้กสอดไส้แยม รสส้ม (6 ชิ้น) | C26: =+ยกมา!H25 -> 28 | D26: =+'1'!D26+'2'!D26+'3'!D26+'4'!D26+'5'!D26+'6'!D26+'7'!D26+'8'!D26+'9'!D26+'10'!D26+'11'!D26+'12'!D26+'13'!D26+'14'!D26+'15'!D26+'16'!D26+'17'!D26+'18'!D26+'19'!D26+'20'!D26+'21'!D26+'22'!D26+'23'!D26+'24'!D26+'25'!D26+'26'!D26+'27'!D26+'28'!D26+'29'!D26+'30'!D26+'31.'!D26 -> 0 | E26: =+C26+D26 -> 28 | F26: =+'1'!F26+'2'!F26+'3'!F26+'4'!F26+'5'!F26+'6'!F26+'7'!F26+'8'!F26+'9'!F26+'10'!F26+'11'!F26+'12'!F26+'13'!F26+'14'!F26+'15'!F26+'16'!F26+'17'!F26+'18'!F26+'19'!F26+'20'!F26+'21'!F26+'22'!F26+'23'!F26+'24'!F26+'25'!F26+'26'!F26+'27'!F26+'28'!F26+'29'!F26+'30'!F26+'31.'!F26 -> 0 | G26: =+'1'!G26+'2'!G26+'3'!G26+'4'!G26+'5'!G26+'6'!G26+'7'!G26+'8'!G26+'9'!G26+'10'!G26+'11'!G26+'12'!G26+'13'!G26+'14'!G26+'15'!G26+'16'!G26+'17'!G26+'18'!G26+'19'!G26+'20'!G26+'21'!G26+'22'!G26+'23'!G26+'24'!G26+'25'!G26+'26'!G26+'27'!G26+'28'!G26+'29'!G26+'30'!G26+'31.'!G26 -> 0 | H26: =C26+D26-F26-I26-G26 -> 28 | I26: =+'1'!I26+'2'!I26+'3'!I26+'4'!I26+'5'!I26+'6'!I26+'7'!I26+'8'!I26+'9'!I26+'10'!I26+'11'!I26+'12'!I26+'13'!I26+'14'!I26+'15'!I26+'16'!I26+'17'!I26+'18'!I26+'19'!I26+'20'!I26+'21'!I26+'22'!I26+'23'!I26+'24'!I26+'25'!I26+'26'!I26+'27'!I26+'28'!I26+'29'!I26+'30'!I26+'31.'!I26 -> 0 | J26: 100 | K26: =+I26*J26 -> 0 | M26: 23.71 | N26: =+I26*M26 -> 0 | O26: 22 | P26: =+'22'!L287 -> 5780 | Q26: =+'22'!L292 -> 1805 | R26: =+'22'!L290 -> 0 | S26: =+'22'!L288 -> 0 | T26: =+'22'!L291 -> 50 | U26: =+'22'!L289 -> 515 | V26: =+P26-Q26-R26-S26-T26-U26 -> 3410 | W26: =+'22'!L294 -> 3410 | X26: =+W26-V26 -> 0 | Y26: =+U26+W26+X26 -> 3925
A27: 23 | B27: ชิฟฟ่อนเค้กหน้าฝอยทอง สอดไส้แยมส้ม (6 ชิ้น) | C27: =+ยกมา!H26 -> 0 | D27: =+'1'!D27+'2'!D27+'3'!D27+'4'!D27+'5'!D27+'6'!D27+'7'!D27+'8'!D27+'9'!D27+'10'!D27+'11'!D27+'12'!D27+'13'!D27+'14'!D27+'15'!D27+'16'!D27+'17'!D27+'18'!D27+'19'!D27+'20'!D27+'21'!D27+'22'!D27+'23'!D27+'24'!D27+'25'!D27+'26'!D27+'27'!D27+'28'!D27+'29'!D27+'30'!D27+'31.'!D27 -> 40 | E27: =+C27+D27 -> 40 | F27: =+'1'!F27+'2'!F27+'3'!F27+'4'!F27+'5'!F27+'6'!F27+'7'!F27+'8'!F27+'9'!F27+'10'!F27+'11'!F27+'12'!F27+'13'!F27+'14'!F27+'15'!F27+'16'!F27+'17'!F27+'18'!F27+'19'!F27+'20'!F27+'21'!F27+'22'!F27+'23'!F27+'24'!F27+'25'!F27+'26'!F27+'27'!F27+'28'!F27+'29'!F27+'30'!F27+'31.'!F27 -> 13 | G27: =+'1'!G27+'2'!G27+'3'!G27+'4'!G27+'5'!G27+'6'!G27+'7'!G27+'8'!G27+'9'!G27+'10'!G27+'11'!G27+'12'!G27+'13'!G27+'14'!G27+'15'!G27+'16'!G27+'17'!G27+'18'!G27+'19'!G27+'20'!G27+'21'!G27+'22'!G27+'23'!G27+'24'!G27+'25'!G27+'26'!G27+'27'!G27+'28'!G27+'29'!G27+'30'!G27+'31.'!G27 -> 0 | H27: =C27+D27-F27-I27-G27 -> -7 | I27: =+'1'!I27+'2'!I27+'3'!I27+'4'!I27+'5'!I27+'6'!I27+'7'!I27+'8'!I27+'9'!I27+'10'!I27+'11'!I27+'12'!I27+'13'!I27+'14'!I27+'15'!I27+'16'!I27+'17'!I27+'18'!I27+'19'!I27+'20'!I27+'21'!I27+'22'!I27+'23'!I27+'24'!I27+'25'!I27+'26'!I27+'27'!I27+'28'!I27+'29'!I27+'30'!I27+'31.'!I27 -> 34 | J27: 100 | K27: =+I27*J27 -> 3400 | M27: 37.51 | N27: =+I27*M27 -> 1275.34 | O27: 23 | P27: =+'23'!L287 -> 4875 | Q27: =+'23'!L292 -> 720 | R27: =+'23'!L290 -> 0 | S27: =+'23'!L288 -> 0 | T27: =+'23'!L291 -> 0 | U27: =+'23'!L289 -> 490 | V27: =+P27-Q27-R27-S27-T27-U27 -> 3665 | W27: =+'23'!L294 -> 3665 | X27: =+W27-V27 -> 0 | Y27: =+U27+W27+X27 -> 4155
A28: 24 | B28: ชิฟฟ่อนเค้กหน้าฝอยทองทูโทน สอดไส้แยมส้ม (6 ชิ้น) | C28: =+ยกมา!H27 -> 20 | D28: =+'1'!D28+'2'!D28+'3'!D28+'4'!D28+'5'!D28+'6'!D28+'7'!D28+'8'!D28+'9'!D28+'10'!D28+'11'!D28+'12'!D28+'13'!D28+'14'!D28+'15'!D28+'16'!D28+'17'!D28+'18'!D28+'19'!D28+'20'!D28+'21'!D28+'22'!D28+'23'!D28+'24'!D28+'25'!D28+'26'!D28+'27'!D28+'28'!D28+'29'!D28+'30'!D28+'31.'!D28 -> 0 | E28: =+C28+D28 -> 20 | F28: =+'1'!F28+'2'!F28+'3'!F28+'4'!F28+'5'!F28+'6'!F28+'7'!F28+'8'!F28+'9'!F28+'10'!F28+'11'!F28+'12'!F28+'13'!F28+'14'!F28+'15'!F28+'16'!F28+'17'!F28+'18'!F28+'19'!F28+'20'!F28+'21'!F28+'22'!F28+'23'!F28+'24'!F28+'25'!F28+'26'!F28+'27'!F28+'28'!F28+'29'!F28+'30'!F28+'31.'!F28 -> 0 | G28: =+'1'!G28+'2'!G28+'3'!G28+'4'!G28+'5'!G28+'6'!G28+'7'!G28+'8'!G28+'9'!G28+'10'!G28+'11'!G28+'12'!G28+'13'!G28+'14'!G28+'15'!G28+'16'!G28+'17'!G28+'18'!G28+'19'!G28+'20'!G28+'21'!G28+'22'!G28+'23'!G28+'24'!G28+'25'!G28+'26'!G28+'27'!G28+'28'!G28+'29'!G28+'30'!G28+'31.'!G28 -> 0 | H28: =C28+D28-F28-I28-G28 -> 20 | I28: =+'1'!I28+'2'!I28+'3'!I28+'4'!I28+'5'!I28+'6'!I28+'7'!I28+'8'!I28+'9'!I28+'10'!I28+'11'!I28+'12'!I28+'13'!I28+'14'!I28+'15'!I28+'16'!I28+'17'!I28+'18'!I28+'19'!I28+'20'!I28+'21'!I28+'22'!I28+'23'!I28+'24'!I28+'25'!I28+'26'!I28+'27'!I28+'28'!I28+'29'!I28+'30'!I28+'31.'!I28 -> 0 | J28: 100 | K28: =+I28*J28 -> 0 | M28: 39.77 | N28: =+I28*M28 -> 0 | O28: 24 | P28: =+'24'!L287 -> 3630 | Q28: =+'24'!L292 -> 450 | R28: =+'24'!L290 -> 0 | S28: =+'24'!L288 -> 0 | T28: =+'24'!L291 -> 50 | U28: =+'24'!L289 -> 765 | V28: =+P28-Q28-R28-S28-T28-U28 -> 2365 | W28: =+'24'!L294 -> 2365 | X28: =+W28-V28 -> 0 | Y28: =+U28+W28+X28 -> 3130
A29: 25 | B29: ชิฟฟ่อนเค้กสอดไส้ นมชมพูฮอกไกโด (6 ชิ้น) | C29: =+ยกมา!H27 -> 20 | D29: =+'1'!D29+'2'!D29+'3'!D29+'4'!D29+'5'!D29+'6'!D29+'7'!D29+'8'!D29+'9'!D29+'10'!D29+'11'!D29+'12'!D29+'13'!D29+'14'!D29+'15'!D29+'16'!D29+'17'!D29+'18'!D29+'19'!D29+'20'!D29+'21'!D29+'22'!D29+'23'!D29+'24'!D29+'25'!D29+'26'!D29+'27'!D29+'28'!D29+'29'!D29+'30'!D29+'31.'!D29 -> 0 | E29: =+C29+D29 -> 20 | F29: =+'1'!F29+'2'!F29+'3'!F29+'4'!F29+'5'!F29+'6'!F29+'7'!F29+'8'!F29+'9'!F29+'10'!F29+'11'!F29+'12'!F29+'13'!F29+'14'!F29+'15'!F29+'16'!F29+'17'!F29+'18'!F29+'19'!F29+'20'!F29+'21'!F29+'22'!F29+'23'!F29+'24'!F29+'25'!F29+'26'!F29+'27'!F29+'28'!F29+'29'!F29+'30'!F29+'31.'!F29 -> 0 | G29: =+'1'!G29+'2'!G29+'3'!G29+'4'!G29+'5'!G29+'6'!G29+'7'!G29+'8'!G29+'9'!G29+'10'!G29+'11'!G29+'12'!G29+'13'!G29+'14'!G29+'15'!G29+'16'!G29+'17'!G29+'18'!G29+'19'!G29+'20'!G29+'21'!G29+'22'!G29+'23'!G29+'24'!G29+'25'!G29+'26'!G29+'27'!G29+'28'!G29+'29'!G29+'30'!G29+'31.'!G29 -> 0 | H29: =C29+D29-F29-I29-G29 -> 20 | I29: =+'1'!I29+'2'!I29+'3'!I29+'4'!I29+'5'!I29+'6'!I29+'7'!I29+'8'!I29+'9'!I29+'10'!I29+'11'!I29+'12'!I29+'13'!I29+'14'!I29+'15'!I29+'16'!I29+'17'!I29+'18'!I29+'19'!I29+'20'!I29+'21'!I29+'22'!I29+'23'!I29+'24'!I29+'25'!I29+'26'!I29+'27'!I29+'28'!I29+'29'!I29+'30'!I29+'31.'!I29 -> 0 | J29: 100 | K29: =+I29*J29 -> 0 | M29: 33.59 | N29: =+I29*M29 -> 0 | O29: 25 | P29: =+'25'!L287 -> 1680 | Q29: =+'25'!L292 -> 275 | R29: =+'25'!L290 -> 0 | S29: =+'25'!L288 -> 0 | T29: =+'25'!L291 -> 0 | U29: =+'25'!L289 -> 700 | V29: =+P29-Q29-R29-S29-T29-U29 -> 705 | W29: =+'25'!L294 -> 705 | X29: =+W29-V29 -> 0 | Y29: =+U29+W29+X29 -> 1405
A30: 26 | B30: ชิฟฟ่อนเค้กสอดไส้แยม รสบลูเบอร์รี่ (6 ชิ้น) | C30: =+ยกมา!H28 -> 0 | D30: =+'1'!D30+'2'!D30+'3'!D30+'4'!D30+'5'!D30+'6'!D30+'7'!D30+'8'!D30+'9'!D30+'10'!D30+'11'!D30+'12'!D30+'13'!D30+'14'!D30+'15'!D30+'16'!D30+'17'!D30+'18'!D30+'19'!D30+'20'!D30+'21'!D30+'22'!D30+'23'!D30+'24'!D30+'25'!D30+'26'!D30+'27'!D30+'28'!D30+'29'!D30+'30'!D30+'31.'!D30 -> 0 | E30: =+C30+D30 -> 0 | F30: =+'1'!F30+'2'!F30+'3'!F30+'4'!F30+'5'!F30+'6'!F30+'7'!F30+'8'!F30+'9'!F30+'10'!F30+'11'!F30+'12'!F30+'13'!F30+'14'!F30+'15'!F30+'16'!F30+'17'!F30+'18'!F30+'19'!F30+'20'!F30+'21'!F30+'22'!F30+'23'!F30+'24'!F30+'25'!F30+'26'!F30+'27'!F30+'28'!F30+'29'!F30+'30'!F30+'31.'!F30 -> 0 | G30: =+'1'!G30+'2'!G30+'3'!G30+'4'!G30+'5'!G30+'6'!G30+'7'!G30+'8'!G30+'9'!G30+'10'!G30+'11'!G30+'12'!G30+'13'!G30+'14'!G30+'15'!G30+'16'!G30+'17'!G30+'18'!G30+'19'!G30+'20'!G30+'21'!G30+'22'!G30+'23'!G30+'24'!G30+'25'!G30+'26'!G30+'27'!G30+'28'!G30+'29'!G30+'30'!G30+'31.'!G30 -> 0 | H30: =C30+D30-F30-I30-G30 -> 0 | I30: =+'1'!I30+'2'!I30+'3'!I30+'4'!I30+'5'!I30+'6'!I30+'7'!I30+'8'!I30+'9'!I30+'10'!I30+'11'!I30+'12'!I30+'13'!I30+'14'!I30+'15'!I30+'16'!I30+'17'!I30+'18'!I30+'19'!I30+'20'!I30+'21'!I30+'22'!I30+'23'!I30+'24'!I30+'25'!I30+'26'!I30+'27'!I30+'28'!I30+'29'!I30+'30'!I30+'31.'!I30 -> 0 | J30: 100 | K30: =+I30*J30 -> 0 | M30: 31.62 | N30: =+I30*M30 -> 0 | O30: 26 | P30: =+'26'!L287 -> 2430 | Q30: =+'26'!L292 -> 360 | R30: =+'26'!L290 -> 0 | S30: =+'26'!L288 -> 0 | T30: =+'26'!L291 -> 50 | U30: =+'26'!L289 -> 490 | V30: =+P30-Q30-R30-S30-T30-U30 -> 1530 | W30: =+'26'!L294 -> 1530 | X30: =+W30-V30 -> 0 | Y30: =+U30+W30+X30 -> 2020
A31: 27 | B31: ชิฟฟ่อนเค้กสอดไส้ ช็อคโกแลตนูเทลล่า (6 ชิ้น) | C31: =+ยกมา!H29 -> 0 | D31: =+'1'!D31+'2'!D31+'3'!D31+'4'!D31+'5'!D31+'6'!D31+'7'!D31+'8'!D31+'9'!D31+'10'!D31+'11'!D31+'12'!D31+'13'!D31+'14'!D31+'15'!D31+'16'!D31+'17'!D31+'18'!D31+'19'!D31+'20'!D31+'21'!D31+'22'!D31+'23'!D31+'24'!D31+'25'!D31+'26'!D31+'27'!D31+'28'!D31+'29'!D31+'30'!D31+'31.'!D31 -> 0 | E31: =+C31+D31 -> 0 | F31: =+'1'!F31+'2'!F31+'3'!F31+'4'!F31+'5'!F31+'6'!F31+'7'!F31+'8'!F31+'9'!F31+'10'!F31+'11'!F31+'12'!F31+'13'!F31+'14'!F31+'15'!F31+'16'!F31+'17'!F31+'18'!F31+'19'!F31+'20'!F31+'21'!F31+'22'!F31+'23'!F31+'24'!F31+'25'!F31+'26'!F31+'27'!F31+'28'!F31+'29'!F31+'30'!F31+'31.'!F31 -> 0 | G31: =+'1'!G31+'2'!G31+'3'!G31+'4'!G31+'5'!G31+'6'!G31+'7'!G31+'8'!G31+'9'!G31+'10'!G31+'11'!G31+'12'!G31+'13'!G31+'14'!G31+'15'!G31+'16'!G31+'17'!G31+'18'!G31+'19'!G31+'20'!G31+'21'!G31+'22'!G31+'23'!G31+'24'!G31+'25'!G31+'26'!G31+'27'!G31+'28'!G31+'29'!G31+'30'!G31+'31.'!G31 -> 0 | H31: =C31+D31-F31-I31-G31 -> 0 | I31: =+'1'!I31+'2'!I31+'3'!I31+'4'!I31+'5'!I31+'6'!I31+'7'!I31+'8'!I31+'9'!I31+'10'!I31+'11'!I31+'12'!I31+'13'!I31+'14'!I31+'15'!I31+'16'!I31+'17'!I31+'18'!I31+'19'!I31+'20'!I31+'21'!I31+'22'!I31+'23'!I31+'24'!I31+'25'!I31+'26'!I31+'27'!I31+'28'!I31+'29'!I31+'30'!I31+'31.'!I31 -> 0 | J31: 100 | K31: =+I31*J31 -> 0 | M31: 33.96 | N31: =+I31*M31 -> 0 | O31: 27 | P31: =+'27'!L287 -> 2175 | Q31: =+'27'!L292 -> 520 | R31: =+'27'!L290 -> 0 | S31: =+'27'!L288 -> 0 | T31: =+'27'!L291 -> 47 | U31: =+'27'!L289 -> 280 | V31: =+P31-Q31-R31-S31-T31-U31 -> 1328 | W31: =+'27'!L294 -> 1328 | X31: =+W31-V31 -> 0 | Y31: =+U31+W31+X31 -> 1608
A32: 28 | B32: ชิฟฟ่อนเค้กสอดไส้ มะพร้าว (6 ชิ้น) | C32: =+ยกมา!H30 -> 0 | D32: =+'1'!D32+'2'!D32+'3'!D32+'4'!D32+'5'!D32+'6'!D32+'7'!D32+'8'!D32+'9'!D32+'10'!D32+'11'!D32+'12'!D32+'13'!D32+'14'!D32+'15'!D32+'16'!D32+'17'!D32+'18'!D32+'19'!D32+'20'!D32+'21'!D32+'22'!D32+'23'!D32+'24'!D32+'25'!D32+'26'!D32+'27'!D32+'28'!D32+'29'!D32+'30'!D32+'31.'!D32 -> 40 | E32: =+C32+D32 -> 40 | F32: =+'1'!F32+'2'!F32+'3'!F32+'4'!F32+'5'!F32+'6'!F32+'7'!F32+'8'!F32+'9'!F32+'10'!F32+'11'!F32+'12'!F32+'13'!F32+'14'!F32+'15'!F32+'16'!F32+'17'!F32+'18'!F32+'19'!F32+'20'!F32+'21'!F32+'22'!F32+'23'!F32+'24'!F32+'25'!F32+'26'!F32+'27'!F32+'28'!F32+'29'!F32+'30'!F32+'31.'!F32 -> 6 | G32: =+'1'!G32+'2'!G32+'3'!G32+'4'!G32+'5'!G32+'6'!G32+'7'!G32+'8'!G32+'9'!G32+'10'!G32+'11'!G32+'12'!G32+'13'!G32+'14'!G32+'15'!G32+'16'!G32+'17'!G32+'18'!G32+'19'!G32+'20'!G32+'21'!G32+'22'!G32+'23'!G32+'24'!G32+'25'!G32+'26'!G32+'27'!G32+'28'!G32+'29'!G32+'30'!G32+'31.'!G32 -> 0 | H32: =C32+D32-F32-I32-G32 -> -6 | I32: =+'1'!I32+'2'!I32+'3'!I32+'4'!I32+'5'!I32+'6'!I32+'7'!I32+'8'!I32+'9'!I32+'10'!I32+'11'!I32+'12'!I32+'13'!I32+'14'!I32+'15'!I32+'16'!I32+'17'!I32+'18'!I32+'19'!I32+'20'!I32+'21'!I32+'22'!I32+'23'!I32+'24'!I32+'25'!I32+'26'!I32+'27'!I32+'28'!I32+'29'!I32+'30'!I32+'31.'!I32 -> 40 | J32: 100 | K32: =+I32*J32 -> 4000 | M32: 29.84 | N32: =+I32*M32 -> 1193.6 | O32: 28 | P32: =+'28'!L287 -> 1965 | Q32: =+'28'!L292 -> 510 | R32: =+'28'!L290 -> 0 | S32: =+'28'!L288 -> 0 | T32: =+'28'!L291 -> 0 | U32: =+'28'!L289 -> 190 | V32: =+P32-Q32-R32-S32-T32-U32 -> 1265 | W32: =+'28'!L294 -> 1265 | X32: =+W32-V32 -> 0 | Y32: =+U32+W32+X32 -> 1455
