Workbook

Sheet สรุป 69
A1: สรุปยอดเคลมออเดอร์ขายออนไลน์ ปี 2569
A2: เดือน | B2: เคลม | D2: ยกเลิก ( CF เล่น) | F2: หมายเหตุ
B3: จำนวน | C3: ค่าขนส่ง | D3: จำนวน | E3: ยอดเงิน
A4: ม.ค. | B4: 50 | C4: =+'ม.ค. เคลม'!J1 -> 2745 | D4: 0 | E4: =+'ม.ค. ยกเลิก'!H76 -> 0
A5: ก.พ. | B5: 62 | C5: 2790 | D5: 0 | E5: 0
A6: มี.ค. | B6: 102 | C6: =+'มี.ค. เคลม'!J1 -> 4185 | D6: 0 | E6: 0
A7: เม.ย. | B7: =+สรุปสาเหตุเคลม!G57 -> 64 | C7: =+'เม.ย. เคลม'!J1 -> 2880 | D7: 0 | E7: 0
A8: พ.ค. | B8: =+'พ.ค. เคลม'!N1 -> 91 | C8: =+'พ.ค. เคลม'!J1 -> 4095 | D8: 0 | E8: 0
A9: มิ.ย. | B9: =+สรุปสาเหตุเคลม!I57 -> 86 | C9: =+'มิ.ย. เคลม'!J1 -> 3870 | D9: 0 | E9: 0
A10: ก.ค.
A11: ส.ค.
A12: ก.ย.
A13: ต.ค.
A14: พ.ย.
A15: ธ.ค.
A16: ยอดรวม | B16: =SUM(B4:B15) -> 455 | C16: =SUM(C4:C15) -> 20565 | D16: =SUM(D4:D15) -> 0 | E16: =SUM(E4:E15) -> 0 | F16: บาท

Sheet สรุปสาเหตุเคลม
A1: สรุปสาเหตุการส่งเคลมจากแพลตฟอร์ม ปี 2569 | C1: Total | D1: ม.ค. | E1: ก.พ. | F1: มี.ค. | G1: เม.ย. | H1: พ.ค. | I1: มิ.ย. | J1: ก.ค. | K1: ส.ค. | L1: ก.ย. | M1: ต.ค. | N1: พ.ย. | O1: ธ.ค.
A2: สาเหตุส่งเคลม | B2: ผู้รับผิดชอบดูแล | C2: จำนวน | D2: จำนวนออเดอร์ | E2: จำนวนออเดอร์ | F2: จำนวนออเดอร์ | G2: จำนวนออเดอร์ | H2: จำนวนออเดอร์ | I2: จำนวนออเดอร์ | J2: จำนวนออเดอร์ | K2: จำนวนออเดอร์ | L2: จำนวนออเดอร์ | M2: จำนวนออเดอร์ | N2: จำนวนออเดอร์ | O2: จำนวนออเดอร์
A3: ของเคลม LAZADA เนื่องจากลูกค้าได้รับสินค้าไม่ครบ | B3: Packing | C3: =SUM(D3:O3) -> 2 | D3: =+'ม.ค. เคลม'!N3 -> 1 | E3: =+'ก.พ. เคลม'!N3 -> 0 | F3: =+'มี.ค. เคลม'!N3 -> 0 | G3: =+'เม.ย. เคลม'!N3 -> 0 | H3: 1 | I3: =+'มิ.ย. เคลม'!N3 -> 0
A4: ของเคลม LAZADA เนื่องจากลูกค้าได้รับสินค้าผิดไม่ตรงตามที่สั่ง | B4: Packing / Online | C4: =SUM(D4:O4) -> 1 | D4: =+'ม.ค. เคลม'!N4 -> 0 | E4: =+'ก.พ. เคลม'!N4 -> 0 | F4: =+'มี.ค. เคลม'!N4 -> 0 | G4: =+'เม.ย. เคลม'!N4 -> 1 | H4: 0 | I4: =+'มิ.ย. เคลม'!N4 -> 0
A5: ของเคลม LAZADA เนื่องจากลูกค้าไม่ได้รับสินค้า | B5: ขนส่ง | C5: =SUM(D5:O5) -> 0 | D5: =+'ม.ค. เคลม'!N5 -> 0 | E5: =+'ก.พ. เคลม'!N5 -> 0 | F5: =+'มี.ค. เคลม'!N5 -> 0 | G5: =+'เม.ย. เคลม'!N5 -> 0 | H5: 0 | I5: =+'มิ.ย. เคลม'!N5 -> 0
A6: ของเคลม LAZADA เนื่องจากสินค้าเสียหายจากการขนส่ง | B6: ขนส่ง | C6: =SUM(D6:O6) -> 0 | D6: =+'ม.ค. เคลม'!N6 -> 0 | E6: =+'ก.พ. เคลม'!N6 -> 0 | F6: =+'มี.ค. เคลม'!N6 -> 0 | G6: =+'เม.ย. เคลม'!N6 -> 0 | H6: 0 | I6: =+'มิ.ย. เคลม'!N6 -> 0
A7: ของเคลม LAZADA เนื่องจากสินค้าเน่าเสียก่อนวันหมดอายุที่แจ้งข้างกล่อง | B7: ฝ่ายผลิต | C7: =SUM(D7:O7) -> 0 | D7: =+'ม.ค. เคลม'!N7 -> 0 | E7: =+'ก.พ. เคลม'!N7 -> 0 | F7: =+'มี.ค. เคลม'!N7 -> 0 | G7: =+'เม.ย. เคลม'!N7 -> 0 | H7: 0 | I7: =+'มิ.ย. เคลม'!N7 -> 0
A8: ของเคลม LAZADA เนื่องจากสินค้ามีรสชาติขม รสชาติ สีของขนม ผิดปกติ | B8: ฝ่ายผลิต | C8: =SUM(D8:O8) -> 0 | D8: =+'ม.ค. เคลม'!N8 -> 0 | E8: =+'ก.พ. เคลม'!N8 -> 0 | F8: =+'มี.ค. เคลม'!N8 -> 0 | G8: =+'เม.ย. เคลม'!N8 -> 0 | H8: 0 | I8: =+'มิ.ย. เคลม'!N8 -> 0
A9: ของเคลม LAZADA เนื่องจากสินค้าไม่มี | B9: ฝ่ายผลิต | C9: =SUM(D9:O9) -> 0 | D9: =+'ม.ค. เคลม'!N9 -> 0 | E9: =+'ก.พ. เคลม'!N9 -> 0 | F9: =+'มี.ค. เคลม'!N9 -> 0 | G9: =+'เม.ย. เคลม'!N9 -> 0 | H9: 0 | I9: =+'มิ.ย. เคลม'!N9 -> 0
A10: ของเคลม LAZADA ไม่ทราบเหตุผล | B10: Online | C10: =SUM(D10:O10) -> 0 | D10: =+'ม.ค. เคลม'!N10 -> 0 | E10: =+'ก.พ. เคลม'!N10 -> 0 | F10: =+'มี.ค. เคลม'!N10 -> 0 | G10: =+'เม.ย. เคลม'!N10 -> 0 | H10: 0 | I10: =+'มิ.ย. เคลม'!N10 -> 0
A11: ของเคลม Shopee เนื่องจากลูกค้าได้รับสินค้าไม่ครบ | B11: Packing | C11: =SUM(D11:O11) -> 2 | D11: =+'ม.ค. เคลม'!N11 -> 1 | E11: =+'ก.พ. เคลม'!N11 -> 0 | F11: =+'มี.ค. เคลม'!N11 -> 1 | G11: =+'เม.ย. เคลม'!N11 -> 0 | H11: 0 | I11: =+'มิ.ย. เคลม'!N11 -> 0
A12: ของเคลม Shopee เนื่องจากลูกค้าได้รับสินค้าผิดไม่ตรงตามที่สั่ง | B12: Packing / Online | C12: =SUM(D12:O12) -> 1 | D12: =+'ม.ค. เคลม'!N12 -> 0 | E12: =+'ก.พ. เคลม'!N12 -> 0 | F12: =+'มี.ค. เคลม'!N12 -> 1 | G12: =+'เม.ย. เคลม'!N12 -> 0 | H12: 0 | I12: =+'มิ.ย. เคลม'!N12 -> 0
A13: ของเคลม Shopee เนื่องจากลูกค้าไม่ได้รับสินค้า | B13: ขนส่ง | C13: =SUM(D13:O13) -> 0 | D13: =+'ม.ค. เคลม'!N13 -> 0 | E13: =+'ก.พ. เคลม'!N13 -> 0 | F13: =+'มี.ค. เคลม'!N13 -> 0 | G13: =+'เม.ย. เคลม'!N13 -> 0 | H13: 0 | I13: =+'มิ.ย. เคลม'!N13 -> 0
A14: ของเคลม Shopee เนื่องจากสินค้าเสียหายจากการขนส่ง | B14: ขนส่ง | C14: =SUM(D14:O14) -> 6 | D14: =+'ม.ค. เคลม'!N14 -> 0 | E14: =+'ก.พ. เคลม'!N14 -> 4 | F14: =+'มี.ค. เคลม'!N14 -> 1 | G14: =+'เม.ย. เคลม'!N14 -> 1 | H14: 0 | I14: =+'มิ.ย. เคลม'!N14 -> 0
... A56: ไม่ทราบสาเหตุ | B56: Online | C56: =SUM(D56:O56) -> 0 | D56: =+'ม.ค. เคลม'!N56 -> 0 | E56: =+'ก.พ. เคลม'!N56 -> 0 | F56: =+'มี.ค. เคลม'!N56 -> 0 | G56: =+'เม.ย. เคลม'!N56 -> 0 | H56: 0 | I56: =+'มิ.ย. เคลม'!N56 -> 0
C57: =SUM(C3:C56) -> 455 | D57: =SUM(D3:D56) -> 50 | E57: =SUM(E3:E56) -> 62 | F57: =SUM(F3:F56) -> 102 | G57: =SUM(G3:G56) -> 64 | H57: =SUM(H3:H56) -> 91 | I57: =SUM(I3:I56) -> 86 | J57: =SUM(J3:J56) -> 0 | ... O57: =SUM(O3:O56) -> 0

Sheet ม.ค. เคลม
A1: สรุปรายการส่งของเคลมสินค้า เดือนมกราคม 2569 | I1: รวมยอดเสียหายค่าขนส่งเพิ่มเติม | J1: =SUBTOTAL(9,J3:J100) -> 2745 | K1: บาท
A2: ลำดับ | B2: เลขที่ออเดอร์ | C2: ชื่อ | D2: ช่องทางติดต่อ | E2: ชื่อตามช่องทางติดต่อ | F2: ขนส่ง | G2: วันที่สร้าง | H2: ยอดขาย | I2: เลขพัสดุ | J2: ค่าใช้จ่ายส่งของ | K2: หมายเหตุ | M2: รายการ | N2: จำนวนออเดอร์
A3: 1 | B3: GOQ2 | C3: ศรัญญา ชิดกระโทก | D3: line_oa | E3: Ae | F3: EMS | G3: 01/01/2026 14:10 | H3: 0 | I3: TH270286FMP35G | J3: 45 | K3: ของเคลม Tiktok เนื่องจากลูกค้าได้รับสินค้าไม่ครบ | M3: ของเคลม LAZADA เนื่องจากลูกค้าได้รับสินค้าไม่ครบ | N3: 1
A4: 2 | B4: GOQ39 | C4: นิศากานต์ นวลอนันต์ | D4: facebook | F4: EMS | G4: 01/01/2026 14:22 | H4: 0 | I4: TH011786FMP39B1 | J4: 45 | K4: ของเคลม Tiktok เนื่องจากลูกค้าได้รับสินค้าไม่ครบ | M4: ของเคลม LAZADA เนื่องจากลูกค้าได้รับสินค้าผิดไม่ตรงตามที่สั่ง | N4: 0
A5: 3 | B5: GOS42 | C5: พรนิภา | D5: facebook | F5: EMS | G5: 01/01/2026 16:42 | H5: 0 | I5: TH070186GZNQ4I | J5: 45 | K5: ของเคลม Tiktok เนื่องจากลูกค้าได้รับสินค้าไม่ครบ | M5: ของเคลม LAZADA เนื่องจากลูกค้าไม่ได้รับสินค้า | N5: 0
A6: 4 | B6: GOS48 | C6: ดารารัตน์ ปาปะแพ (บ้านหัวเหล่า) | D6: facebook | F6: EMS | G6: 01/01/2026 16:46 | H6: 0 | I6: TH301286GZNR5B | J6: 45 | K6: ของเคลม Tiktok เนื่องจากลูกค้าได้รับสินค้าไม่ครบ | M6: ของเคลม LAZADA เนื่องจากสินค้าเสียหายจากการขนส่ง | N6: 0
A7: 5 | B7: GOS51 | C7: วรรณยุพา กรรณลา | D7: facebook | F7: EMS | G7: 01/01/2026 16:48 | H7: 0 | I7: TH391286GZNS3B | J7: 45 | K7: ของเคลม Tiktok เนื่องจากลูกค้าได้รับสินค้าไม่ครบ | M7: ของเคลม LAZADA เนื่องจากสินค้าเน่าเสียก่อนวันหมดอายุที่แจ้งข้างกล่อง | N7: 0
A8: 6 | B8: GOS56 | C8: นางสาวศิริพร ผลโพธิ์ | D8: facebook | F8: EMS | G8: 01/01/2026 16:52 | H8: 0 | I8: TH240386GZNS7E | J8: 45 | K8: ของเคลม Tiktok เนื่องจากลูกค้าได้รับสินค้าไม่ครบ | M8: ของเคลม LAZADA เนื่องจากสินค้ามีรสชาติขม รสชาติ สีของขนม ผิดปกติ | N8: 0
A9: 7 | B9: GOX69 | C9: ปาวีณา หนูเซ่ง | D9: facebook | F9: EMS | G9: 02/01/2026 08:48 | H9: 0 | I9: WB129879800TH | J9: 45 | K9: ของเคลม Tiktok เนื่องจากลูกค้าได้รับสินค้าไม่ครบ | M9: ของเคลม LAZADA เนื่องจากสินค้าไม่มี | N9: 0
A10: 8 | B10: GPY6 | C10: มะลิวัลย์ โพระกุ | D10: facebook | F10: EMS | G10: 05/01/2026 13:32 | H10: 0 | I10: WB130186947TH | J10: 45 | K10: ของเคลม Tiktok เนื่องจากลูกค้าได้รับสินค้าไม่ครบ | M10: ของเคลม LAZADA ไม่ทราบเหตุผล | N10: 0
A11: 9 | B11: GQR88 | C11: แจ็ค | D11: facebook | F11: EMS | G11: 08/01/2026 12:04 | H11: 0 | I11: WB130555770TH | J11: 45 | K11: ของเคลม Line OA เนื่องจากลูกค้าได้รับสินค้าไม่ครบ | M11: ของเคลม Shopee เนื่องจากลูกค้าได้รับสินค้าไม่ครบ | N11: 1
A12: 10 | B12: GQU75 | C12: วิมล ฤกษ์ไชย | D12: facebook | F12: EMS | G12: 09/01/2026 09:19 | H12: 0 | I12: WB130661915TH | J12: 45 | K12: ของเคลม Tiktok เนื่องจากลูกค้าได้รับสินค้าไม่ครบ | M12: ของเคลม Shopee เนื่องจากลูกค้าได้รับสินค้าผิดไม่ตรงตามที่สั่ง | N12: 0
A13: 11 | B13: GQU77 | C13: พรนภา ศรีกระจ่าง | D13: facebook | F13: EMS | G13: 09/01/2026 09:21 | H13: 0 | I13: WB130661932TH | J13: 45 | K13: ของเคลม Tiktok เนื่องจากลูกค้าได้รับสินค้าไม่ครบ | M13: ของเคลม Shopee เนื่องจากลูกค้าไม่ได้รับสินค้า | N13: 0
A14: 12 | B14: GQU78 | C14: คุณวาสนา ผลัดมณี | D14: facebook | F14: EMS | G14: 09/01/2026 09:24 | H14: 0 | I14: WB130661929TH | J14: 45 | K14: ของเคลม Tiktok เนื่องจากลูกค้าได้รับสินค้าไม่ครบ | M14: ของเคลม Shopee เนื่องจากสินค้าเสียหายจากการขนส่ง | N14: 0
A15: 13 | B15: GQV14 | C15: รสสุคนธ์ บุญชื่น | D15: facebook | F15: EMS | G15: 09/01/2026 12:02 | H15: 0 | I15: WB130661946TH | J15: 45 | K15: ของเคลม LAZADA เนื่องจากลูกค้าได้รับสินค้าไม่ครบ | M15: ของเคลม Shopee เนื่องจากสินค้าเน่าเสียก่อนวันหมดอายุที่แจ้งข้างกล่อง | N15: 0
... A19: 17 | B19: GRL4 | C19: พวงฟ้า สองเมืองสุข | D19: facebook | F19: EMS | G19: 14/01/2026 09:45 | H19: 0 | I19: GRL4 | J19: 45 | K19: ของเคลม Tiktok เนื่องจากลูกค้าได้รับสินค้าไม่ครบ | M19: ของเคลม Line OA เนื่องจากลูกค้าได้รับสินค้าไม่ครบ | N19: 1
A20: 18 | B20: GRN70 | C20: น***าวสุดารัตน์ | D20: Tiktok | E20: 7494231352524704760 | F20: J&T Express | G20: 15/01/2026 11:07 | H20: 0 | I20: 769465806981 | J20: 45 | K20: ของเคลม Tiktok เนื่องจากลูกค้าได้รับสินค้าไม่ครบ | M20: ของเคลม Line OA เนื่องจากลูกค้าได้รับสินค้าผิดไม่ตรงตามที่สั่ง | N20: 0
A21: 19 | B21: GRN69 | C21: ณ***รรณ ค***ซิ่ว | D21: Tiktok | E21: 7494816474235833199 | F21: J&T Express | G21: 15/01/2026 11:07 | H21: 0 | I21: 769479916984 | J21: 45 | K21: ของเคลม Tiktok เนื่องจากลูกค้าได้รับสินค้าไม่ครบ | M21: ของเคลม Line OA เนื่องจากลูกค้าไม่ได้รับสินค้า | N21: 0
A22: 20 | B22: GRN68 | C22: ธ*** ก***ามัยวงศ์ | D22: Tiktok | E22: 7494446324920846834 | F22: J&T Express | G22: 15/01/2026 11:07 | H22: 0 | I22: 769414024956 | J22: 45 | K22: ของเคลม Tiktok เนื่องจากลูกค้าได้รับสินค้าไม่ครบ | M22: ของเคลม Line OA เนื่องจากสินค้าเสียหายจากการขนส่ง | N22: 0
A23: 21 | B23: GRN74 | C23: น** | D23: Tiktok | E23: 7494313338316950374 | F23: J&T Express | G23: 15/01/2026 11:09 | H23: 0 | I23: 769493303961 | J23: 45 | K23: ของเคลม Tiktok เนื่องจากลูกค้าได้รับสินค้าไม่ครบ | M23: ของเคลม Line OA เนื่องจากสินค้าเน่าเสียก่อนวันหมดอายุที่แจ้งข้างกล่อง | N23: 0
A24: 22 | B24: GRN73 | C24: น***รณ ศ***ัย | D24: Tiktok | E24: 7494338799498464206 | F24: J&T Express | G24: 15/01/2026 11:09 | H24: 0 | I24: 769480911986 | J24: 45 | K24: ของเคลม Tiktok เนื่องจากลูกค้าได้รับสินค้าไม่ครบ | M24: ของเคลม Line OA เนื่องจากสินค้ามีรสชาติขม รสชาติ สีของขนม ผิดปกติ | N24: 0
A25: 23 | B25: GRN72 | C25: ศ***า ส***จ | D25: Tiktok | E25: 7494038583796139308 | F25: J&T Express | G25: 15/01/2026 11:09 | H25: 0 | I25: 769476694825 | J25: 45 | K25: ของเคลม Tiktok เนื่องจากลูกค้าได้รับสินค้าไม่ครบ | M25: ของเคลม Line OA เนื่องจากสินค้าไม่มี | N25: 0
A26: 24 | B26: GRN80 | C26: ร***พล จ***ุบผา | D26: Tiktok | E26: 7495794736454011207 | F26: Flash Express Thailand | G26: 15/01/2026 11:12 | H26: 0 | I26: THT04062DB5X70Z | J26: 45 | K26: ของเคลม Tiktok เนื่องจากลูกค้าได้รับสินค้าไม่ครบ | M26: ของเคลม Line OA ไม่ทราบเหตุผล | N26: 0
A27: 25 | B27: GRN78 | C27: ณ***ง | D27: Tiktok | E27: 7494024037090165868 | F27: J&T Express | G27: 15/01/2026 11:12 | H27: 0 | I27: 769402806992 | J27: 45 | K27: ของเคลม Tiktok เนื่องจากลูกค้าได้รับสินค้าไม่ครบ | M27: ของเคลม Facebook , Facebook Live เนื่องจากลูกค้าได้รับสินค้าไม่ครบ | N27: 0
A28: 26 | B28: GRN83 | C28: ก*** | D28: Tiktok | E28: 7495343380732939212 | F28: J&T Express | G28: 15/01/2026 11:27 | H28: 0 | I28: 769473505916 | J28: 45 | K28: ของเคลม Tiktok เนื่องจากลูกค้าได้รับสินค้าไม่ครบ | M28: ของเคลม Facebook , Facebook Live เนื่องจากลูกค้าได้รับสินค้าผิดไม่ตรงตามที่สั่ง | N28: 0
A29: 27 | B29: GRO65 | C29: อ*** จ***ร์รุ่ง | D29: Tiktok | E29: 7494033136711665377 | F29: J&T Express | G29: 15/01/2026 16:31 | H29: 0 | I29: 790081894372 | J29: 45 | K29: ของเคลม Tiktok เนื่องจากลูกค้าได้รับสินค้าไม่ครบ | M29: ของเคลม Facebook , Facebook Live เนื่องจากลูกค้าไม่ได้รับสินค้า | N29: 0
A30: 28 | B30: GRV24 | C30: อ***ตยา | D30: Tiktok | E30: 7494789786068682928 | F30: J&T Express | G30: 18/01/2026 11:14 | H30: 0 | I30: 790142637432 | J30: 45 | K30: ของเคลม Tiktok เนื่องจากลูกค้าได้รับสินค้าไม่ครบ | M30: ของเคลม Facebook , Facebook Live เนื่องจากสินค้าเสียหายจากการขนส่ง | N30: 0
A31: 29 | B31: GRV23 | C31: ว***วัลย์ พ***ณี | D31: Tiktok | E31: 7494022288695789055 | F31: J&T Express | G31: 18/01/2026 11:14 | H31: 0 | I31: 790118236456 | J31: 45 | K31: ของเคลม Tiktok เนื่องจากลูกค้าได้รับสินค้าไม่ครบ | M31: ของเคลม Facebook , Facebook Live เนื่องจากสินค้าเน่าเสียก่อนวันหมดอายุที่แจ้งข้างกล่อง | N31: 0
A32: 30 | B32: GRX75 | C32: นภัสวรรณ อาสว่าง | D32: facebook | F32: EMS | G32: 19/01/2026 09:12 | H32: 0 | I32: WB131776446TH | J32: 45 | K32: ของเคลม TikTok เนื่องจากสินค้าเสียหายจากการขนส่ง | M32: ของเคลม Facebook , Facebook Live เนื่องจากสินค้ามีรสชาติขม รสชาติ สีของขนม ผิดปกติ | N32: 0
A33: 31 | B33: GRX80 | C33: อรอุมา สามตรีกัน | D33: facebook | F33: EMS | G33: 19/01/2026 09:15 | H33: 0 | I33: WB131776432TH | J33: 45 | K33: ของเคลม Tiktok เนื่องจากลูกค้าได้รับสินค้าไม่ครบ | M33: ของเคลม Facebook , Facebook Live เนื่องจากสินค้าไม่มี | N33: 0
A34: 32 | B34: GRY32 | C34: ข***ีวิว | D34: Tiktok | E34: 7494072452429154071 | F34: J&T Express | G34: 19/01/2026 10:54 | H34: 0 | I34: 790157439035 | J34: 45 | K34: ของเคลม Tiktok เนื่องจากลูกค้าได้รับสินค้าไม่ครบ | M34: ของเคลม Facebook , Facebook Live ไม่ทราบเหตุผล | N34: 0
A35: 33 | B35: GRY37 | C35: พ***์วิไล ก***ะพันธุ์ ต***กี้ | D35: Tiktok | E35: 7494006153018115602 | F35: J&T Express | G35: 19/01/2026 11:01 | H35: 0 | I35: 790110931083 | J35: 45 | K35: ของเคลม Tiktok เนื่องจากลูกค้าได้รับสินค้าไม่ครบ | M35: ของเคลม Tiktok เนื่องจากลูกค้าได้รับสินค้าไม่ครบ | N35: 46
A36: 34 | B36: GSE6 | C36: ย***วา | D36: Tiktok | E36: 7495053470882629683 | F36: J&T Express | G36: 21/01/2026 11:49 | H36: 0 | I36: 790276395031 | J36: 45 | K36: ของเคลม Tiktok เนื่องจากลูกค้าได้รับสินค้าไม่ครบ | M36: ของเคลม Tiktok เนื่องจากลูกค้าได้รับสินค้าผิดไม่ตรงตามที่สั่ง | N36: 0
A37: 35 | B37: GSE5 | C37: ส***ภรณ์ เ***แก้ว | D37: Tiktok | E37: 7494050056517291688 | F37: J&T Express | G37: 21/01/2026 11:49 | H37: 0 | I37: 790275490082 | J37: 45 | K37: ของเคลม Tiktok เนื่องจากลูกค้าได้รับสินค้าไม่ครบ | M37: ของเคลม Tiktok เนื่องจากลูกค้าไม่ได้รับสินค้า | N37: 0
A38: 36 | B38: GSE8 | C38: พ***นิภา แ***บริบัตร | D38: Tiktok | E38: 7495861790361356826 | F38: J&T Express | G38: 21/01/2026 11:50 | H38: 0 | I38: 790249393032 | J38: 45 | K38: ของเคลม Tiktok เนื่องจากลูกค้าได้รับสินค้าไม่ครบ | M38: ของเคลม TikTok เนื่องจากสินค้าเสียหายจากการขนส่ง | N38: 1
A39: 37 | B39: GSE7 | C39: ก***ิยา ภ***ลิศ | D39: Tiktok | E39: 7494083520294651235 | F39: J&T Express | G39: 21/01/2026 11:50 | H39: 0 | I39: 790259391095 | J39: 45 | K39: ของเคลม Tiktok เนื่องจากลูกค้าได้รับสินค้าไม่ครบ | M39: ของเคลม TikTok เนื่องจากสินค้าเน่าเสียก่อนวันหมดอายุที่แจ้งข้างกล่อง | N39: 0
A40: 38 | B40: GSE9 | C40: ณ***ุฒิ จ***ุเรือง | D40: Tiktok | E40: 7494745161618262283 | F40: J&T Express | G40: 21/01/2026 11:51 | H40: 0 | I40: 790224189086 | J40: 45 | K40: ของเคลม Tiktok เนื่องจากลูกค้าได้รับสินค้าไม่ครบ | M40: ของเคลม Tiktok เนื่องจากสินค้ามีรสชาติขม รสชาติ สีของขนม ผิดปกติ | N40: 0
A41: 39 | B41: GSG94 | C41: ฐิติพร จิระวิทยาบุญ | D41: Lazada | F41: Kerry_dropoff | G41: 22/01/2026 11:31 | H41: 0 | I41: LEXPU0650514435 | J41: 45 | K41: ของเคลม Tiktok เนื่องจากลูกค้าได้รับสินค้าไม่ครบ | M41: ของเคลม Tiktok เนื่องจากสินค้าไม่มี | N41: 0
A42: 40 | B42: GSH56 | C42: ไ***ง ป***น | D42: Tiktok | E42: 7494030156276729263 | F42: J&T Express | G42: 22/01/2026 15:06 | H42: 0 | I42: 790398857986 | J42: 45 | K42: ของเคลม Tiktok เนื่องจากลูกค้าได้รับสินค้าไม่ครบ | M42: ของเคลม Tiktok ไม่ทราบเหตุผล | N42: 0
A43: 41 | B43: GSO99 | C43: S***yupa M***haisong | D43: Tiktok | E43: 7495160892235745465 | F43: J&T Express | G43: 25/01/2026 16:50 | H43: 0 | I43: 790557920622 | J43: 45 | K43: ของเคลม Tiktok เนื่องจากลูกค้าได้รับสินค้าไม่ครบ | M43: ของเคลม ไปรษณีย์ เนื่องจากลูกค้าได้รับสินค้าไม่ครบ | N43: 0
...

Sheet ม.ค. ยกเลิก
A1: สรุปรายการยกเลิกออเดอร์ ที่ออกเลขที่ออเดอร์แล้ว (เนื่องจากลูกค้าเอฟในไลฟ์สดแล้วไม่ยืนยันออเดอร์) เดือนมกราคม 2569
A2: ลำดับ | B2: เลขที่ออเดอร์ | C2: ชื่อ | D2: ช่องทางติดต่อ | E2: ชื่อตามช่องทางติดต่อ | F2: ขนส่ง | G2: วันที่สร้าง | H2: ยอดขาย | I2: หมายเหตุ
A3: 1
A4: 2
A5: 3
A6: 4
A7: 5
A8: 6
A9: 7
A10: 8
A11: 9
A12: 10
A13: 11
A14: 12
... A34: 32
G76: ยอดรวม | H76: =SUM(H3:H75) -> 0 | I76: บาท

Sheet ก.พ. เคลม
A1: สรุปรายการส่งของเคลมสินค้า เดือนกุมภาพันธ์ 2569 | I1: รวมยอดเสียหายค่าขนส่งเพิ่มเติม | J1: =SUBTOTAL(9,J3:J98) -> 2790 | K1: บาท
A2: ลำดับ | B2: เลขที่ออเดอร์ | C2: ชื่อ | D2: ช่องทางติดต่อ | E2: ชื่อตามช่องทางติดต่อ | F2: ขนส่ง | G2: วันที่สร้าง | H2: ยอดขาย | I2: เลขพัสดุ | J2: ค่าใช้จ่ายส่งของ | K2: หมายเหตุ | M2: รายการ | N2: จำนวนออเดอร์
A3: 1 | B3: GTD58 | C3: I** b*** | D3: Tiktok | E3: 7494016383697912857 | F3: J&T Express | G3: 01/02/2026 13:15 | H3: 0 | I3: 790967496664 | J3: 45 | K3: ของเคลม Tiktok เนื่องจากลูกค้าได้รับสินค้าไม่ครบ | M3: ของเคลม LAZADA เนื่องจากลูกค้าได้รับสินค้าไม่ครบ | N3: 0
A4: 2 | B4: GTD63 | C4: อ***รา ว***รัตน์ | D4: Tiktok | E4: 7495571973901093521 | F4: J&T Express | G4: 01/02/2026 13:37 | H4: 0 | I4: 790925389623 | J4: 45 | K4: ของเคลม Tiktok เนื่องจากลูกค้าได้รับสินค้าไม่ครบ | M4: ของเคลม LAZADA เนื่องจากลูกค้าได้รับสินค้าผิดไม่ตรงตามที่สั่ง | N4: 0
A5: 3 | B5: GTD65 | C5: ล***า ฤ***์อุดม | D5: Tiktok | E5: 7494007075709028229 | F5: J&T Express | G5: 01/02/2026 13:39 | H5: 0 | I5: 790917913520 | J5: 45 | K5: ของเคลม Tiktok เนื่องจากลูกค้าได้รับสินค้าไม่ครบ | M5: ของเคลม LAZADA เนื่องจากลูกค้าไม่ได้รับสินค้า | N5: 0
A6: 4 | B6: GTE0 | C6: น***าวสุดารัตน์ | D6: Tiktok | E6: 7494231352524704760 | F6: J&T Express | G6: 01/02/2026 15:47 | H6: 0 | I6: 790974368634 | J6: 45 | K6: ของเคลม Tiktok เนื่องจากลูกค้าได้รับสินค้าไม่ครบ | M6: ของเคลม LAZADA เนื่องจากสินค้าเสียหายจากการขนส่ง | N6: 0
A7: 5 | B7: GTE12 | C7: สุวิมล เชียงตันติ์ | D7: facebook | F7: EMS | G7: 01/02/2026 16:44 | H7: 0 | I7: WB133237775TH | J7: 45 | K7: ของเคลม Shopee เนื่องจากสินค้าเสียหายจากการขนส่ง | M7: ของเคลม LAZADA เนื่องจากสินค้าเน่าเสียก่อนวันหมดอายุที่แจ้งข้างกล่อง | N7: 0
A8: 6 | B8: GTE13 | C8: ม***์ที่ชอบกินขนม | D8: Tiktok | E8: 7495902790856838073 | F8: J&T Express | G8: 01/02/2026 16:49 | H8: 0 | I8: 790924216773 | J8: 45 | K8: ของเคลม Tiktok เนื่องจากลูกค้าได้รับสินค้าไม่ครบ | M8: ของเคลม LAZADA เนื่องจากสินค้ามีรสชาติขม รสชาติ สีของขนม ผิดปกติ | N8: 0
A9: 7 | B9: GTF1 | C9: เ***มี่ ก***ีพิศา | D9: Tiktok | E9: 7495084121840716290 | F9: J&T Express | G9: 02/02/2026 08:38 | H9: 0 | I9: 790971809891 | J9: 45 | K9: ของเคลม Tiktok เนื่องจากลูกค้าได้รับสินค้าไม่ครบ | M9: ของเคลม LAZADA เนื่องจากสินค้าไม่มี | N9: 0
A10: 8 | B10: GTF76 | C10: E***phyo | D10: Tiktok | E10: 7495976833517127892 | F10: J&T Express | G10: 02/02/2026 13:42 | H10: 0 | I10: 791057254326 | J10: 45 | K10: ของเคลม Tiktok เนื่องจากลูกค้าได้รับสินค้าไม่ครบ | M10: ของเคลม LAZADA ไม่ทราบเหตุผล | N10: 0
A11: 9 | B11: GTI30 | C11: ป***สุดา ล***น | D11: Tiktok | E11: 7495027642011126359 | F11: J&T Express | G11: 03/02/2026 11:47 | H11: 0 | I11: 791034202556 | J11: 45 | K11: ของเคลม Tiktok เนื่องจากลูกค้าได้รับสินค้าไม่ครบ | M11: ของเคลม Shopee เนื่องจากลูกค้าได้รับสินค้าไม่ครบ | N11: 0
A12: 10 | B12: GTI31 | C12: ภ***วรรณ | D12: Tiktok | E12: 7495961324883839333 | F12: J&T Express | G12: 03/02/2026 11:51 | H12: 0 | I12: 791085169486 | J12: 45 | K12: ของเคลม Tiktok เนื่องจากลูกค้าได้รับสินค้าไม่ครบ | M12: ของเคลม Shopee เนื่องจากลูกค้าได้รับสินค้าผิดไม่ตรงตามที่สั่ง | N12: 0
A13: 11 | B13: GTI32 | C13: ว***ี แ***ึง | D13: Tiktok | E13: 7494798597760583796 | F13: Flash Express Thailand | G13: 03/02/2026 11:52 | H13: 0 | I13: THT13062EKXYS5Z | J13: 45 | K13: ของเคลม Tiktok เนื่องจากลูกค้าได้รับสินค้าไม่ครบ | M13: ของเคลม Shopee เนื่องจากลูกค้าไม่ได้รับสินค้า | N13: 0
A14: 12 | B14: GTJ36 | C14: ว***วัณย์ ส***าลุนัย | D14: Tiktok | E14: 7493992842417374802 | F14: J&T Express | G14: 03/02/2026 17:13 | H14: 0 | I14: 791035236025 | J14: 45 | K14: ของเคลม Tiktok เนื่องจากลูกค้าได้รับสินค้าไม่ครบ | M14: ของเคลม Shopee เนื่องจากสินค้าเสียหายจากการขนส่ง | N14: 4
A15: 13 | B15: GTK52 | C15: เ***ก | D15: Tiktok | E15: 7495810758360206317 | F15: J&T Express | G15: 04/02/2026 08:54 | H15: 0 | I15: 791185401182 | J15: 45 | K15: ของเคลม Tiktok เนื่องจากลูกค้าได้รับสินค้าไม่ครบ | M15: ของเคลม Shopee เนื่องจากสินค้าเน่าเสียก่อนวันหมดอายุที่แจ้งข้างกล่อง | N15: 0
A16: 14 | B16: GTL62 | C16: ก***ทรา โ***ุลชัย | D16: Tiktok | E16: 7494009626345833682 | F16: J&T Express | G16: 04/02/2026 16:23 | H16: 0 | I16: 791215378122 | J16: 45 | K16: ของเคลม Tiktok เนื่องจากลูกค้าได้รับสินค้าไม่ครบ | M16: ของเคลม Shopee เนื่องจากสินค้ามีรสชาติขม รสชาติ สีของขนม ผิดปกติ | N16: 0
A17: 15 | B17: GTL64 | C17: เ***บบี๋ | D17: Tiktok | E17: 7493990083769500689 | F17: J&T Express | G17: 04/02/2026 16:26 | H17: 0 | I17: 791298576121 | J17: 45 | K17: ของเคลม Tiktok เนื่องจากลูกค้าได้รับสินค้าไม่ครบ | M17: ของเคลม Shopee เนื่องจากสินค้าไม่มี | N17: 0
A18: 16 | B18: GTM37 | C18: ส***ล่า บ***นา | D18: Tiktok | E18: 7494014761034352447 | F18: J&T Express | G18: 05/02/2026 08:30 | H18: 0 | I18: 791199294686 | J18: 45 | K18: ของเคลม Tiktok เนื่องจากลูกค้าได้รับสินค้าไม่ครบ | M18: ของเคลม Shopee ไม่ทราบเหตุผล | N18: 0
A19: 17 | B19: GTM39 | C19: ไ***น ห***วล | D19: Tiktok | E19: 7495727782205098038 | F19: J&T Express | G19: 05/02/2026 08:34 | H19: 0 | I19: 791146375600 | J19: 45 | K19: ของเคลม Tiktok เนื่องจากลูกค้าได้รับสินค้าไม่ครบ | M19: ของเคลม Line OA เนื่องจากลูกค้าได้รับสินค้าไม่ครบ | N19: 0
A20: 18 | B20: GTM43 | C20: ส***พร ธ***วงษ์ | D20: Tiktok | E20: 7495735669777336558 | F20: J&T Express | G20: 05/02/2026 08:37 | H20: 0 | I20: 791134969693 | J20: 45 | K20: ของเคลม Tiktok เนื่องจากลูกค้าได้รับสินค้าไม่ครบ | M20: ของเคลม Line OA เนื่องจากลูกค้าได้รับสินค้าผิดไม่ตรงตามที่สั่ง | N20: 0
A21: 19 | B21: GTN11 | C21: ปิยพร หม่องเหล็ก | D21: line | F21: EMS | G21: 05/02/2026 14:38 | H21: 0 | I21: WB133838846TH | J21: 45 | K21: ของเคลม Tiktok เนื่องจากลูกค้าได้รับสินค้าไม่ครบ | M21: ของเคลม Line OA เนื่องจากลูกค้าไม่ได้รับสินค้า | N21: 0
A22: 20 | B22: GTO68 | C22: ก***ัตน์ ส***ัน | D22: Tiktok | E22: 7494035347307726473 | F22: J&T Express | G22: 06/02/2026 10:06 | H22: 0 | I22: 791218147263 | J22: 45 | K22: ของเคลม Tiktok เนื่องจากลูกค้าได้รับสินค้าไม่ครบ | M22: ของเคลม Line OA เนื่องจากสินค้าเสียหายจากการขนส่ง | N22: 0
A23: 21 | B23: GTO70 | C23: แ***หอม | D23: Tiktok | E23: 7494474374203870161 | F23: J&T Express | G23: 06/02/2026 10:09 | H23: 0 | I23: 791235084242 | J23: 45 | K23: ของเคลม Tiktok เนื่องจากลูกค้าได้รับสินค้าไม่ครบ | M23: ของเคลม Line OA เนื่องจากสินค้าเน่าเสียก่อนวันหมดอายุที่แจ้งข้างกล่อง | N23: 0
A24: 22 | B24: GTO71 | C24: จ***วะดี ก***ทอง | D24: Tiktok | E24: 7494080422237406220 | F24: J&T Express | G24: 06/02/2026 10:12 | H24: 0 | I24: 791267398202 | J24: 45 | K24: ของเคลม Tiktok เนื่องจากลูกค้าได้รับสินค้าไม่ครบ | M24: ของเคลม Line OA เนื่องจากสินค้ามีรสชาติขม รสชาติ สีของขนม ผิดปกติ | N24: 0
A25: 23 | B25: GTO73 | C25: ม***ณี | D25: Tiktok | E25: 7494019245384434833 | F25: J&T Express | G25: 06/02/2026 10:17 | H25: 0 | I25: 791222474280 | J25: 45 | K25: ของเคลม Tiktok เนื่องจากลูกค้าได้รับสินค้าไม่ครบ | M25: ของเคลม Line OA เนื่องจากสินค้าไม่มี | N25: 0
A26: 24 | B26: GTO74 | C26: ป*** ห***ดี | D26: Tiktok | E26: 7494014566933234882 | F26: J&T Express | G26: 06/02/2026 10:20 | H26: 0 | I26: 791284743266 | J26: 45 | K26: ของเคลม Tiktok เนื่องจากลูกค้าได้รับสินค้าไม่ครบ | M26: ของเคลม Line OA ไม่ทราบเหตุผล | N26: 0
A27: 25 | B27: GTQ98 | C27: น** | D27: Tiktok | E27: 7494313338316950374 | F27: J&T Express | G27: 07/02/2026 13:36 | H27: 0 | I27: 791286281004 | J27: 45 | K27: ของเคลม Tiktok เนื่องจากลูกค้าได้รับสินค้าไม่ครบ | M27: ของเคลม Facebook , Facebook Live เนื่องจากลูกค้าได้รับสินค้าไม่ครบ | N27: 0
A28: 26 | B28: GTQ97 | C28: อ** ณ***ันท์ เ***นรอบ | D28: Tiktok | E28: 7494005259413521913 | F28: J&T Express | G28: 07/02/2026 13:36 | H28: 0 | I28: 791254692012 | J28: 45 | K28: ของเคลม Tiktok เนื่องจากลูกค้าได้รับสินค้าไม่ครบ | M28: ของเคลม Facebook , Facebook Live เนื่องจากลูกค้าได้รับสินค้าผิดไม่ตรงตามที่สั่ง | N28: 0
A29: 27 | B29: GTX46 | C29: ป***า | D29: Tiktok | E29: 7493991922176591587 | F29: J&T Express | G29: 09/02/2026 13:15 | H29: 0 | I29: 791414830360 | J29: 45 | K29: ของเคลม Tiktok เนื่องจากลูกค้าได้รับสินค้าไม่ครบ | M29: ของเคลม Facebook , Facebook Live เนื่องจากลูกค้าไม่ได้รับสินค้า | N29: 0
A30: 28 | B30: GTX47 | C30: น***ินดา ข***ยทอง | D30: Tiktok | E30: 7494909494009170069 | F30: J&T Express | G30: 09/02/2026 13:19 | H30: 0 | I30: 791465437361 | J30: 45 | K30: ของเคลม Tiktok เนื่องจากลูกค้าได้รับสินค้าไม่ครบ | M30: ของเคลม Facebook , Facebook Live เนื่องจากสินค้าเสียหายจากการขนส่ง | N30: 0
A31: 29 | B31: GUC15 | C31: เ***่าแซ่บ | D31: Tiktok | E31: 7495784409537087687 | F31: J&T Express | G31: 11/02/2026 08:20 | H31: 0 | I31: 791428674061 | J31: 45 | K31: ของเคลม Tiktok เนื่องจากลูกค้าได้รับสินค้าไม่ครบ | M31: ของเคลม Facebook , Facebook Live เนื่องจากสินค้าเน่าเสียก่อนวันหมดอายุที่แจ้งข้างกล่อง | N31: 0
A32: 30 | B32: GUH88 | C32: วีระศักดิ์ | D32: other | E32: Shopee | F32: EMS | G32: 12/02/2026 16:39 | H32: 0 | I32: WB169917090TH | J32: 45 | K32: ของเคลม Shopee เนื่องจากสินค้าเสียหายจากการขนส่ง | M32: ของเคลม Facebook , Facebook Live เนื่องจากสินค้ามีรสชาติขม รสชาติ สีของขนม ผิดปกติ | N32: 0
A33: 31 | B33: GUJ55 | C33: ม***า เ***งิน | D33: Tiktok | E33: 7494012030549198175 | F33: J&T Express | G33: 13/02/2026 09:42 | H33: 0 | I33: 791627731613 | J33: 45 | K33: ของเคลม Tiktok เนื่องจากลูกค้าได้รับสินค้าไม่ครบ | M33: ของเคลม Facebook , Facebook Live เนื่องจากสินค้าไม่มี | N33: 0
A34: 32 | B34: GUQ41 | C34: ธัญกมล อินทรีย์ | D34: facebook | F34: EMS | G34: 15/02/2026 13:43 | H34: 0 | I34: WB170203325TH | J34: 45 | K34: ของเคลม ไปรษณีย์ เนื่องจากลูกค้าได้รับสินค้าไม่ครบ | M34: ของเคลม Facebook , Facebook Live ไม่ทราบเหตุผล | N34: 0
A35: 33 | B35: GUR35 | C35: ว*** น***ะหะหมัด | D35: Tiktok | E35: 7494821270670969377 | F35: J&T Express | G35: 15/02/2026 16:54 | H35: 0 | I35: 791767243621 | J35: 45 | K35: ของเคลม Tiktok เนื่องจากลูกค้าได้รับสินค้าไม่ครบ | M35: ของเคลม Tiktok เนื่องจากลูกค้าได้รับสินค้าไม่ครบ | N35: 57
A36: 34 | B36: GUR36 | C36: แ** | D36: Tiktok | E36: 7495068185989975006 | F36: J&T Express | G36: 15/02/2026 16:55 | H36: 0 | I36: 791737046645 | J36: 45 | K36: ของเคลม Tiktok เนื่องจากลูกค้าได้รับสินค้าไม่ครบ | M36: ของเคลม Tiktok เนื่องจากลูกค้าได้รับสินค้าผิดไม่ตรงตามที่สั่ง | N36: 0
A37: 35 | B37: GUR37 | C37: ข***มุ่น | D37: Tiktok | E37: 7493993563406238792 | F37: J&T Express | G37: 15/02/2026 16:57 | H37: 0 | I37: 791720048652 | J37: 45 | K37: ของเคลม Tiktok เนื่องจากลูกค้าได้รับสินค้าไม่ครบ | M37: ของเคลม Tiktok เนื่องจากลูกค้าไม่ได้รับสินค้า | N37: 0
A38: 36 | B38: GUT57 | C38: อ๋อ | D38: facebook | F38: EMS | G38: 16/02/2026 11:56 | H38: 0 | I38: WB170255124TH | J38: 45 | K38: ของเคลม Shopee เนื่องจากสินค้าเสียหายจากการขนส่ง | M38: ของเคลม TikTok เนื่องจากสินค้าเสียหายจากการขนส่ง | N38: 1
A39: 37 | B39: GUX28 | C39: อ***ตย์ เ***กสอาด | D39: Tiktok | E39: 7495854812870904206 | F39: J&T Express | G39: 17/02/2026 15:15 | H39: 0 | I39: 791836442655 | J39: 45 | K39: ของเคลม Tiktok เนื่องจากลูกค้าได้รับสินค้าไม่ครบ | M39: ของเคลม TikTok เนื่องจากสินค้าเน่าเสียก่อนวันหมดอายุที่แจ้งข้างกล่อง | N39: 0
A40: 38 | B40: GUZ69 | C40: ก*** อ***ญา | D40: Tiktok | E40: 7493990193599580010 | F40: J&T Express | G40: 18/02/2026 12:04 | H40: 0 | I40: 791951001236 | J40: 45 | K40: ของเคลม Tiktok เนื่องจากลูกค้าได้รับสินค้าไม่ครบ | M40: ของเคลม Tiktok เนื่องจากสินค้ามีรสชาติขม รสชาติ สีของขนม ผิดปกติ | N40: 0
...

Sheet ก.พ. ยกเลิก
A1: สรุปรายการยกเลิกออเดอร์ ที่ออกเลขที่ออเดอร์แล้ว (เนื่องจากลูกค้าเอฟในไลฟ์สดแล้วไม่ยืนยันออเดอร์) เดือนกุมภาพันธ์ 2569
A2: ลำดับ | B2: เลขที่ออเดอร์ | C2: ชื่อ | D2: ช่องทางติดต่อ | E2: ชื่อตามช่องทางติดต่อ | F2: ขนส่ง | G2: วันที่สร้าง | H2: ยอดขาย | I2: หมายเหตุ
A3: 1
A4: 2
A5: 3
A6: 4
A7: 5
A8: 6
A9: 7
A10: 8
A11: 9
A12: 10
A13: 11
A14: 12
... A34: 32
G76: ยอดรวม | H76: =SUM(H3:H75) -> 0 | I76: บาท

Sheet มี.ค. เคลม
A1: สรุปรายการส่งของเคลมสินค้า เดือนมีนาคม 2569 | I1: รวมยอดเสียหายค่าขนส่งเพิ่มเติม | J1: =SUBTOTAL(9,J3:J95) -> 4185 | K1: บาท
A2: ลำดับ | B2: เลขที่ออเดอร์ | C2: ชื่อ | D2: ช่องทางติดต่อ | E2: ชื่อตามช่องทางติดต่อ | F2: ขนส่ง | G2: วันที่สร้าง | H2: ยอดขาย | I2: เลขพัสดุ | J2: ค่าใช้จ่ายส่งของ | K2: หมายเหตุ | M2: รายการ | N2: จำนวนออเดอร์
A3: 1 | B3: GVX29 | C3: ม*** ห***จิ่ง | D3: Tiktok | E3: 7493991239336888126 | F3: J&T Express | G3: 01/03/2026 13:16 | H3: 0 | I3: 792569432406 | J3: 45 | K3: ของเคลม Tiktok เนื่องจากลูกค้าได้รับสินค้าไม่ครบ | M3: ของเคลม LAZADA เนื่องจากลูกค้าได้รับสินค้าไม่ครบ | N3: 0
A4: 2 | B4: GWA66 | C4: น***หล้า | D4: Tiktok | E4: 7494703926240118803 | F4: J&T Express | G4: 02/03/2026 17:08 | H4: 0 | I4: 792696677113 | J4: 45 | K4: ของเคลม Tiktok เนื่องจากลูกค้าได้รับสินค้าไม่ครบ | M4: ของเคลม LAZADA เนื่องจากลูกค้าได้รับสินค้าผิดไม่ตรงตามที่สั่ง | N4: 0
A5: 3 | B5: GWD58 | C5: ช***่ | D5: Tiktok | E5: 7494026745096078965 | F5: J&T Express | G5: 03/03/2026 16:47 | H5: 0 | I5: 792787489550 | J5: 45 | K5: ของเคลม Tiktok เนื่องจากลูกค้าได้รับสินค้าไม่ครบ | M5: ของเคลม LAZADA เนื่องจากลูกค้าไม่ได้รับสินค้า | N5: 0
A6: 4 | B6: GWE37 | C6: ชนาธิป สุวรรณอ่อน | D6: facebook | F6: EMS | G6: 04/03/2026 09:13 | H6: 0 | I6: WB172074460TH | J6: 45 | K6: ของเคลม Tiktok เนื่องจากลูกค้าได้รับสินค้าไม่ครบ | M6: ของเคลม LAZADA เนื่องจากสินค้าเสียหายจากการขนส่ง | N6: 0
A7: 5 | B7: GWE73 | C7: ส่งที่บ้านกนกวรรณ | D7: Lazada | F7: Kerry_dropoff | G7: 04/03/2026 12:09 | H7: 0 | I7: LEXPU0664180294 | J7: 45 | K7: ของเคลม Tiktok เนื่องจากลูกค้าได้รับสินค้าไม่ครบ | M7: ของเคลม LAZADA เนื่องจากสินค้าเน่าเสียก่อนวันหมดอายุที่แจ้งข้างกล่อง | N7: 0
A8: 6 | B8: GWE85 | C8: ส่งบ้านกนกวรรณ | D8: Lazada | F8: Kerry_dropoff | G8: 04/03/2026 13:54 | H8: 0 | I8: LEXPU0664182274 | J8: 45 | K8: ของเคลม Tiktok เนื่องจากลูกค้าได้รับสินค้าไม่ครบ | M8: ของเคลม LAZADA เนื่องจากสินค้ามีรสชาติขม รสชาติ สีของขนม ผิดปกติ | N8: 0
A9: 7 | B9: GWF24 | C9: น***ัส ส***ช | D9: Tiktok | E9: 7495795239264029164 | F9: J&T Express | G9: 04/03/2026 16:56 | H9: 0 | I9: 792793425454 | J9: 45 | K9: ของเคลม Tiktok เนื่องจากลูกค้าได้รับสินค้าไม่ครบ | M9: ของเคลม LAZADA เนื่องจากสินค้าไม่มี | N9: 0
A10: 8 | B10: GWF25 | C10: ผ***้องนัว | D10: Tiktok | E10: 7494072452429154071 | F10: J&T Express | G10: 04/03/2026 16:58 | H10: 0 | I10: 792794232414 | J10: 45 | K10: ของเคลม Tiktok เนื่องจากลูกค้าได้รับสินค้าไม่ครบ | M10: ของเคลม LAZADA ไม่ทราบเหตุผล | N10: 0
A11: 9 | B11: GWF26 | C11: ก***นา เ***ญหมื่น | D11: Tiktok | E11: 7494049524749470891 | F11: J&T Express | G11: 04/03/2026 17:00 | H11: 0 | I11: 792725221411 | J11: 45 | K11: ของเคลม Tiktok เนื่องจากลูกค้าได้รับสินค้าไม่ครบ | M11: ของเคลม Shopee เนื่องจากลูกค้าได้รับสินค้าไม่ครบ | N11: 1
A12: 10 | B12: GWF75 | C12: ร***ร | D12: Tiktok | E12: 7495137003969873960 | F12: J&T Express | G12: 05/03/2026 08:50 | H12: 0 | I12: 792783430666 | J12: 45 | K12: ของเคลม Tiktok เนื่องจากลูกค้าได้รับสินค้าไม่ครบ | M12: ของเคลม Shopee เนื่องจากลูกค้าได้รับสินค้าผิดไม่ตรงตามที่สั่ง | N12: 1
A13: 11 | B13: GWF76 | C13: ภ***ชนก ม***มณี | D13: Tiktok | E13: 7494483625843002061 | F13: J&T Express | G13: 05/03/2026 09:02 | H13: 0 | I13: 792775038646 | J13: 45 | K13: ของเคลม Tiktok เนื่องจากลูกค้าได้รับสินค้าไม่ครบ | M13: ของเคลม Shopee เนื่องจากลูกค้าไม่ได้รับสินค้า | N13: 0
A14: 12 | B14: GWF86 | C14: ม***มีศรีสุข | D14: Tiktok | E14: 7494150898322277893 | F14: J&T Express | G14: 05/03/2026 09:49 | H14: 0 | I14: 792756030651 | J14: 45 | K14: ของเคลม Tiktok เนื่องจากลูกค้าได้รับสินค้าไม่ครบ | M14: ของเคลม Shopee เนื่องจากสินค้าเสียหายจากการขนส่ง | N14: 1
A15: 13 | B15: GWF91 | C15: ร***พล จ***ุบผา | D15: Tiktok | E15: 7495794736454011207 | F15: J&T Express | G15: 05/03/2026 09:58 | H15: 0 | I15: 792781625694 | J15: 45 | K15: ของเคลม Tiktok เนื่องจากลูกค้าได้รับสินค้าไม่ครบ | M15: ของเคลม Shopee เนื่องจากสินค้าเน่าเสียก่อนวันหมดอายุที่แจ้งข้างกล่อง | N15: 0
A16: 14 | B16: GWP49 | C16: สุริตา หนูกลับ | D16: facebook | F16: EMS | G16: 08/03/2026 16:31 | H16: 0 | I16: WB172476888TH | J16: 45 | K16: ของเคลม Shopee เนื่องจากลูกค้าได้รับสินค้าผิดไม่ตรงตามที่สั่ง | M16: ของเคลม Shopee เนื่องจากสินค้ามีรสชาติขม รสชาติ สีของขนม ผิดปกติ | N16: 0
A17: 15 | B17: GWR13 | C17: ส***พร เ***วละออ | D17: Tiktok | E17: 7494844118570469545 | F17: J&T Express | G17: 09/03/2026 13:53 | H17: 0 | I17: 793039008322 | J17: 45 | K17: ของเคลม Tiktok เนื่องจากลูกค้าได้รับสินค้าไม่ครบ | M17: ของเคลม Shopee เนื่องจากสินค้าไม่มี | N17: 0
A18: 16 | B18: GWR15 | C18: ส***ิศักดิ์ ว***นนทเดช | D18: Tiktok | E18: 7494787287983098420 | F18: J&T Express | G18: 09/03/2026 13:56 | H18: 0 | I18: 793041707345 | J18: 45 | K18: ของเคลม Tiktok เนื่องจากลูกค้าได้รับสินค้าไม่ครบ | M18: ของเคลม Shopee ไม่ทราบเหตุผล | N18: 0
A19: 17 | B19: GWR17 | C19: เ***อ้วน อ***ยบอกต่อ | D19: Tiktok | E19: 7494054646692285805 | F19: J&T Express | G19: 09/03/2026 14:01 | H19: 0 | I19: 793055503284 | J19: 45 | K19: ของเคลม Tiktok เนื่องจากลูกค้าได้รับสินค้าไม่ครบ | M19: ของเคลม Line OA เนื่องจากลูกค้าได้รับสินค้าไม่ครบ | N19: 0
A20: 18 | B20: GWR18 | C20: ส***ยันต์ ล***ีสานพากินพาเที่ยว | D20: Tiktok | E20: 7494471526940904113 | F20: J&T Express | G20: 09/03/2026 14:04 | H20: 0 | I20: 793026802330 | J20: 45 | K20: ของเคลม Tiktok เนื่องจากลูกค้าได้รับสินค้าไม่ครบ | M20: ของเคลม Line OA เนื่องจากลูกค้าได้รับสินค้าผิดไม่ตรงตามที่สั่ง | N20: 0
A21: 19 | B21: GWS52 | C21: ร***ร | D21: Tiktok | E21: 7495137003969873960 | F21: J&T Express | G21: 10/03/2026 08:13 | H21: 0 | I21: 793007674351 | J21: 45 | K21: ของเคลม Tiktok เนื่องจากลูกค้าได้รับสินค้าไม่ครบ | M21: ของเคลม Line OA เนื่องจากลูกค้าไม่ได้รับสินค้า | N21: 0
A22: 20 | B22: GWS55 | C22: แ***ตะ ก***ดดเตะ | D22: Tiktok | E22: 7494009368203527185 | F22: J&T Express | G22: 10/03/2026 08:34 | H22: 0 | I22: 793033076345 | J22: 45 | K22: ของเคลม Tiktok เนื่องจากลูกค้าได้รับสินค้าไม่ครบ | M22: ของเคลม Line OA เนื่องจากสินค้าเสียหายจากการขนส่ง | N22: 0
A23: 21 | B23: GWS62 | C23: น***ปุ้ย | D23: Tiktok | E23: 7495978653192588227 | F23: J&T Express | G23: 10/03/2026 09:22 | H23: 0 | I23: 793040079381 | J23: 45 | K23: ของเคลม Tiktok เนื่องจากลูกค้าได้รับสินค้าไม่ครบ | M23: ของเคลม Line OA เนื่องจากสินค้าเน่าเสียก่อนวันหมดอายุที่แจ้งข้างกล่อง | N23: 0
A24: 22 | B24: GWU42 | C24: น***ินดา ข***ยทอง | D24: Tiktok | E24: 7494909494009170069 | F24: J&T Express | G24: 10/03/2026 16:32 | H24: 0 | I24: 793034657855 | J24: 45 | K24: ของเคลม Tiktok เนื่องจากลูกค้าได้รับสินค้าไม่ครบ | M24: ของเคลม Line OA เนื่องจากสินค้ามีรสชาติขม รสชาติ สีของขนม ผิดปกติ | N24: 0
A25: 23 | B25: GWX38 | C25: ส***ตรา ล***มมา | D25: Tiktok | E25: 7494967750032329288 | F25: J&T Express | G25: 12/03/2026 12:00 | H25: 0 | I25: 793119340591 | J25: 45 | K25: ของเคลม Tiktok เนื่องจากลูกค้าได้รับสินค้าไม่ครบ | M25: ของเคลม Line OA เนื่องจากสินค้าไม่มี | N25: 0
A26: 24 | B26: GWY21 | C26: แ***ี่ | D26: Tiktok | E26: 7494130200567973581 | F26: J&T Express | G26: 12/03/2026 16:38 | H26: 0 | I26: 793143097924 | J26: 45 | K26: ของเคลม Tiktok เนื่องจากลูกค้าได้รับสินค้าไม่ครบ | M26: ของเคลม Line OA ไม่ทราบเหตุผล | N26: 0
A27: 25 | B27: GWY22 | C27: น***าวธัญลักษณ์ ช***ัย | D27: Tiktok | E27: 7494011839961007191 | F27: J&T Express | G27: 12/03/2026 16:40 | H27: 0 | I27: 793113350934 | J27: 45 | K27: ของเคลม Tiktok เนื่องจากลูกค้าได้รับสินค้าไม่ครบ | M27: ของเคลม Facebook , Facebook Live เนื่องจากลูกค้าได้รับสินค้าไม่ครบ | N27: 0
A28: 26 | B28: GWY23 | C28: น***ภัทรวัลลิ์ โ***ม | D28: Tiktok | E28: 7494014565415749212 | F28: J&T Express | G28: 12/03/2026 16:43 | H28: 0 | I28: 793103995806 | J28: 45 | K28: ของเคลม Tiktok เนื่องจากลูกค้าได้รับสินค้าไม่ครบ | M28: ของเคลม Facebook , Facebook Live เนื่องจากลูกค้าได้รับสินค้าผิดไม่ตรงตามที่สั่ง | N28: 0
A29: 27 | B29: GXA6 | C29: ผึ้ง | D29: facebook | F29: EMS | G29: 13/03/2026 16:23 | H29: 0 | I29: WB212748652TH | J29: 45 | K29: ของเคลม Shopee เนื่องจากสินค้าเสียหายจากการขนส่ง | M29: ของเคลม Facebook , Facebook Live เนื่องจากลูกค้าไม่ได้รับสินค้า | N29: 0
A30: 28 | B30: GXF70 | C30: I** b*** | D30: Tiktok | E30: 7494016383697912857 | F30: J&T Express | G30: 16/03/2026 08:24 | H30: 0 | I30: 793395938823 | J30: 45 | K30: ของเคลม Tiktok เนื่องจากลูกค้าได้รับสินค้าไม่ครบ | M30: ของเคลม Facebook , Facebook Live เนื่องจากสินค้าเสียหายจากการขนส่ง | N30: 0
A31: 29 | B31: GXF73 | C31: ศ***า ส***จ | D31: Tiktok | E31: 7494038583796139308 | F31: J&T Express | G31: 16/03/2026 08:29 | H31: 0 | I31: 793394432821 | J31: 45 | K31: ของเคลม Tiktok เนื่องจากลูกค้าได้รับสินค้าไม่ครบ | M31: ของเคลม Facebook , Facebook Live เนื่องจากสินค้าเน่าเสียก่อนวันหมดอายุที่แจ้งข้างกล่อง | N31: 0
A32: 30 | B32: GXF82 | C32: ป***ปักของอร่อย | D32: Tiktok | E32: 7494936129921714805 | F32: J&T Express | G32: 16/03/2026 08:59 | H32: 0 | I32: 793339246884 | J32: 45 | K32: ของเคลม Tiktok เนื่องจากลูกค้าได้รับสินค้าไม่ครบ | M32: ของเคลม Facebook , Facebook Live เนื่องจากสินค้ามีรสชาติขม รสชาติ สีของขนม ผิดปกติ | N32: 0
A33: 34 | B33: GXG34 | C33: อ***รา ว***รัตน์ | D33: Tiktok | E33: 7495571973901093521 | F33: J&T Express | G33: 16/03/2026 11:17 | H33: 0 | I33: 793373828866 | J33: 45 | K33: ของเคลม Tiktok เนื่องจากลูกค้าได้รับสินค้าไม่ครบ | M33: ของเคลม Facebook , Facebook Live เนื่องจากสินค้าไม่มี | N33: 0
A34: 35 | B34: GXG33 | C34: น***าวธัญลักษณ์ ช***ัย | D34: Tiktok | E34: 7494011839961007191 | F34: J&T Express | G34: 16/03/2026 11:17 | H34: 0 | I34: 793336336870 | J34: 45 | K34: ของเคลม Tiktok เนื่องจากลูกค้าได้รับสินค้าไม่ครบ | M34: ของเคลม Facebook , Facebook Live ไม่ทราบเหตุผล | N34: 0
A35: 36 | B35: GXJ74 | C35: ก***ิยา ภ***ลิศ | D35: Tiktok | E35: 7494083520294651235 | F35: J&T Express | G35: 17/03/2026 16:35 | H35: 0 | I35: 793462048724 | J35: 45 | K35: ของเคลม Tiktok เนื่องจากลูกค้าได้รับสินค้าไม่ครบ | M35: ของเคลม Tiktok เนื่องจากลูกค้าได้รับสินค้าไม่ครบ | N35: 99
A36: 37 | B36: GXJ75 | C36: ม***์ที่ชอบกินขนม | D36: Tiktok | E36: 7495902790856838073 | F36: J&T Express | G36: 17/03/2026 16:37 | H36: 0 | I36: 793424196751 | J36: 45 | K36: ของเคลม Tiktok เนื่องจากลูกค้าได้รับสินค้าไม่ครบ | M36: ของเคลม Tiktok เนื่องจากลูกค้าได้รับสินค้าผิดไม่ตรงตามที่สั่ง | N36: 0
A37: 38 | B37: GXJ78 | C37: จ** | D37: Tiktok | E37: 7494210307129051759 | F37: J&T Express | G37: 17/03/2026 16:53 | H37: 0 | I37: 793415392744 | J37: 45 | K37: ของเคลม Tiktok เนื่องจากลูกค้าได้รับสินค้าไม่ครบ | M37: ของเคลม Tiktok เนื่องจากลูกค้าไม่ได้รับสินค้า | N37: 0
A38: 39 | B38: GXJ80 | C38: อ** ณ***ันท์ เ***นรอบ | D38: Tiktok | E38: 7494005259413521913 | F38: J&T Express | G38: 17/03/2026 16:55 | H38: 0 | I38: 793422172874 | J38: 45 | K38: ของเคลม Tiktok เนื่องจากลูกค้าได้รับสินค้าไม่ครบ | M38: ของเคลม TikTok เนื่องจากสินค้าเสียหายจากการขนส่ง | N38: 0
A39: 40 | B39: GXJ83 | C39: ป***า | D39: Tiktok | E39: 7493991922176591587 | F39: J&T Express | G39: 17/03/2026 17:00 | H39: 0 | I39: 793431006981 | J39: 45 | K39: ของเคลม Tiktok เนื่องจากลูกค้าได้รับสินค้าไม่ครบ | M39: ของเคลม TikTok เนื่องจากสินค้าเน่าเสียก่อนวันหมดอายุที่แจ้งข้างกล่อง | N39: 0
A40: 45 | B40: GXM80 | C40: ส***ตรา ล***มมา | D40: Tiktok | E40: 7494972961409567404 | F40: J&T Express | G40: 18/03/2026 22:11 | H40: 0 | I40: 793523757375 | J40: 45 | K40: ของเคลม Tiktok เนื่องจากลูกค้าได้รับสินค้าไม่ครบ | M40: ของเคลม Tiktok เนื่องจากสินค้ามีรสชาติขม รสชาติ สีของขนม ผิดปกติ | N40: 0
...

Sheet มี.ค. ยกเลิก
A1: สรุปรายการยกเลิกออเดอร์ ที่ออกเลขที่ออเดอร์แล้ว (เนื่องจากลูกค้าเอฟในไลฟ์สดแล้วไม่ยืนยันออเดอร์) เดือนมีนาคม 2569
A2: ลำดับ | B2: เลขที่ออเดอร์ | C2: ชื่อ | D2: ช่องทางติดต่อ | E2: ชื่อตามช่องทางติดต่อ | F2: ขนส่ง | G2: วันที่สร้าง | H2: ยอดขาย | I2: หมายเหตุ
A3: 1
A4: 2
A5: 3
A6: 4
A7: 5
A8: 6
A9: 7
A10: 8
A11: 9
A12: 10
A13: 11
A14: 12
... A34: 32
G76: ยอดรวม | H76: =SUM(H3:H75) -> 0 | I76: บาท

Sheet เม.ย. เคลม
A1: สรุปรายการส่งของเคลมสินค้า เดือนเมษายน 2569 | I1: รวมยอดเสียหายค่าขนส่งเพิ่มเติม | J1: =SUBTOTAL(9,J3:J94) -> 2880 | K1: บาท
A2: ลำดับ | B2: เลขที่ออเดอร์ | C2: ชื่อ | D2: ช่องทางติดต่อ | E2: ชื่อตามช่องทางติดต่อ | F2: ขนส่ง | G2: วันที่สร้าง | H2: ยอดขาย | I2: เลขพัสดุ | J2: ค่าใช้จ่ายส่งของ | K2: หมายเหตุ | M2: รายการ | N2: จำนวนออเดอร์
A3: 1 | B3: GZD17 | C3: ส***ตรา | D3: Tiktok | E3: 7494263530888858462 | F3: J&T Express | G3: 02/04/2026 16:48 | H3: 0 | I3: 794418131371 | J3: 45 | K3: ของเคลม Tiktok เนื่องจากลูกค้าได้รับสินค้าไม่ครบ | M3: ของเคลม LAZADA เนื่องจากลูกค้าได้รับสินค้าไม่ครบ | N3: 0
A4: 2 | B4: GZD19 | C4: ส***ิศักดิ์ ว***นนทเดช | D4: Tiktok | E4: 7494787287983098420 | F4: J&T Express | G4: 02/04/2026 16:51 | H4: 0 | I4: 794422480224 | J4: 45 | K4: ของเคลม Tiktok เนื่องจากลูกค้าได้รับสินค้าไม่ครบ | M4: ของเคลม LAZADA เนื่องจากลูกค้าได้รับสินค้าผิดไม่ตรงตามที่สั่ง | N4: 1
A5: 3 | B5: GZD20 | C5: ภ***าภรณ์ ร***ึ้ง | D5: Tiktok | E5: 7495179107606235833 | F5: J&T Express | G5: 02/04/2026 16:52 | H5: 0 | I5: 794451132381 | J5: 45 | K5: ของเคลม Tiktok เนื่องจากลูกค้าได้รับสินค้าไม่ครบ | M5: ของเคลม LAZADA เนื่องจากลูกค้าไม่ได้รับสินค้า | N5: 0
A6: 4 | B6: GZF29 | C6: โ***า แ***จันทร์ | D6: Tiktok | E6: 7494079390104978505 | F6: J&T Express | G6: 03/04/2026 09:42 | H6: 0 | I6: 794446084401 | J6: 45 | K6: ของเคลม Tiktok เนื่องจากลูกค้าได้รับสินค้าไม่ครบ | M6: ของเคลม LAZADA เนื่องจากสินค้าเสียหายจากการขนส่ง | N6: 0
A7: 5 | B7: GZF30 | C7: ณ***รรณ ค***ซิ่ว | D7: Tiktok | E7: 7494816474235833199 | F7: J&T Express | G7: 03/04/2026 09:44 | H7: 0 | I7: 794496679421 | J7: 45 | K7: ของเคลม Tiktok เนื่องจากลูกค้าได้รับสินค้าไม่ครบ | M7: ของเคลม LAZADA เนื่องจากสินค้าเน่าเสียก่อนวันหมดอายุที่แจ้งข้างกล่อง | N7: 0
A8: 6 | B8: GZF31 | C8: ล***รดา ส***น | D8: Tiktok | E8: 7495298376533444892 | F8: J&T Express | G8: 03/04/2026 09:47 | H8: 0 | I8: 794424389485 | J8: 45 | K8: ของเคลม Tiktok เนื่องจากลูกค้าได้รับสินค้าไม่ครบ | M8: ของเคลม LAZADA เนื่องจากสินค้ามีรสชาติขม รสชาติ สีของขนม ผิดปกติ | N8: 0
A9: 7 | B9: GZF48 | C9: น***รา พ***งนอก | D9: Tiktok | E9: 7494007032485873270 | F9: J&T Express | G9: 03/04/2026 11:25 | H9: 0 | I9: 794404182471 | J9: 45 | K9: ของเคลม Tiktok เนื่องจากลูกค้าได้รับสินค้าไม่ครบ | M9: ของเคลม LAZADA เนื่องจากสินค้าไม่มี | N9: 0
A10: 8 | B10: GZF49 | C10: ท***ิยา | D10: Tiktok | E10: 7495327091468437673 | F10: J&T Express | G10: 03/04/2026 11:28 | H10: 0 | I10: 794426785471 | J10: 45 | K10: ของเคลม Tiktok เนื่องจากลูกค้าได้รับสินค้าไม่ครบ | M10: ของเคลม LAZADA ไม่ทราบเหตุผล | N10: 0
A11: 9 | B11: GZG6 | C11: ว*** น***ะหะหมัด | D11: Tiktok | E11: 7494821270670969377 | F11: J&T Express | G11: 03/04/2026 14:46 | H11: 0 | I11: 794487480006 | J11: 45 | K11: ของเคลม Tiktok เนื่องจากลูกค้าได้รับสินค้าไม่ครบ | M11: ของเคลม Shopee เนื่องจากลูกค้าได้รับสินค้าไม่ครบ | N11: 0
A12: 10 | B12: GZH0 | C12: ส*** | D12: Tiktok | E12: 7493995920830530578 | F12: J&T Express | G12: 03/04/2026 18:56 | H12: 0 | I12: 794593133106 | J12: 45 | K12: ของเคลม Tiktok เนื่องจากลูกค้าได้รับสินค้าไม่ครบ | M12: ของเคลม Shopee เนื่องจากลูกค้าได้รับสินค้าผิดไม่ตรงตามที่สั่ง | N12: 0
A13: 11 | B13: GZL73 | C13: สตางค์ เสาวภาคย์กุล | D13: other | F13: EMS | G13: 05/04/2026 10:10 | H13: 0 | I13: WB215235970TH | J13: 45 | K13: ของเคลม Shopee เนื่องจากสินค้าเน่าเสียก่อนวันหมดอายุที่แจ้งข้างกล่อง | M13: ของเคลม Shopee เนื่องจากลูกค้าไม่ได้รับสินค้า | N13: 0
A14: 12 | B14: GZN75 | C14: ป***ปักของอร่อย | D14: Tiktok | E14: 7494936129921714805 | F14: J&T Express | G14: 06/04/2026 00:22 | H14: 0 | I14: 794676624313 | J14: 45 | K14: ของเคลม Tiktok เนื่องจากลูกค้าได้รับสินค้าไม่ครบ | M14: ของเคลม Shopee เนื่องจากสินค้าเสียหายจากการขนส่ง | N14: 1
A15: 13 | B15: GZP15 | C15: ธ***ดา ห*** 1 | D15: Tiktok | E15: 7494004568861017911 | F15: J&T Express | G15: 06/04/2026 13:45 | H15: 0 | I15: 794774499105 | J15: 45 | K15: ของเคลม Tiktok เนื่องจากลูกค้าได้รับสินค้าไม่ครบ | M15: ของเคลม Shopee เนื่องจากสินค้าเน่าเสียก่อนวันหมดอายุที่แจ้งข้างกล่อง | N15: 2
A16: 14 | B16: GZY53 | C16: อรสา วารีอุดม | D16: facebook | F16: EMS | G16: 09/04/2026 11:52 | H16: 0 | I16: WB215768537TH | J16: 45 | K16: ของเคลม Shopee เนื่องจากสินค้าเน่าเสียก่อนวันหมดอายุที่แจ้งข้างกล่อง | M16: ของเคลม Shopee เนื่องจากสินค้ามีรสชาติขม รสชาติ สีของขนม ผิดปกติ | N16: 0
A17: 15 | B17: HAA50 | C17: ก***าอร ม***ะสพ | D17: Tiktok | E17: 7494014858771990167 | F17: J&T Express | G17: 10/04/2026 08:50 | H17: 0 | I17: 794851039032 | J17: 45 | K17: ของเคลม Tiktok เนื่องจากลูกค้าได้รับสินค้าไม่ครบ | M17: ของเคลม Shopee เนื่องจากสินค้าไม่มี | N17: 0
A18: 16 | B18: HAA51 | C18: น***ีย | D18: Tiktok | E18: 7494011215764817652 | F18: J&T Express | G18: 10/04/2026 08:53 | H18: 0 | I18: 794877115045 | J18: 45 | K18: ของเคลม Tiktok เนื่องจากลูกค้าได้รับสินค้าไม่ครบ | M18: ของเคลม Shopee ไม่ทราบเหตุผล | N18: 0
A19: 17 | B19: HAA53 | C19: ศ***พร น***สง | D19: Tiktok | E19: 7495088958683450039 | F19: J&T Express | G19: 10/04/2026 08:56 | H19: 0 | I19: 794827115003 | J19: 45 | K19: ของเคลม Tiktok เนื่องจากลูกค้าได้รับสินค้าไม่ครบ | M19: ของเคลม Line OA เนื่องจากลูกค้าได้รับสินค้าไม่ครบ | N19: 0
A20: 18 | B20: HAA57 | C20: ว***รณ์ | D20: Tiktok | E20: 7494166521026152276 | F20: J&T Express | G20: 10/04/2026 09:21 | H20: 0 | I20: 794855826096 | J20: 45 | K20: ของเคลม Tiktok เนื่องจากลูกค้าได้รับสินค้าไม่ครบ | M20: ของเคลม Line OA เนื่องจากลูกค้าได้รับสินค้าผิดไม่ตรงตามที่สั่ง | N20: 0
A21: 19 | B21: HAA59 | C21: อ***ชชา | D21: Tiktok | E21: 7494533746471766406 | F21: J&T Express | G21: 10/04/2026 09:44 | H21: 0 | I21: 794808228060 | J21: 45 | K21: ของเคลม Tiktok เนื่องจากลูกค้าได้รับสินค้าไม่ครบ | M21: ของเคลม Line OA เนื่องจากลูกค้าไม่ได้รับสินค้า | N21: 0
A22: 20 | B22: HAA75 | C22: ท***์ธัญญา ค***ง | D22: Tiktok | E22: 7495137890294073952 | F22: J&T Express | G22: 10/04/2026 10:04 | H22: 0 | I22: 794815831036 | J22: 45 | K22: ของเคลม Tiktok เนื่องจากลูกค้าได้รับสินค้าไม่ครบ | M22: ของเคลม Line OA เนื่องจากสินค้าเสียหายจากการขนส่ง | N22: 0
A23: 21 | B23: HAA84 | C23: ธ***์ ว***โต | D23: Tiktok | E23: 7494008068441933371 | F23: J&T Express | G23: 10/04/2026 10:13 | H23: 0 | I23: 794857508045 | J23: 45 | K23: ของเคลม Tiktok เนื่องจากลูกค้าได้รับสินค้าไม่ครบ | M23: ของเคลม Line OA เนื่องจากสินค้าเน่าเสียก่อนวันหมดอายุที่แจ้งข้างกล่อง | N23: 0
A24: 22 | B24: HAA92 | C24: น***รา ช***เอ้ | D24: Tiktok | E24: 7494055786535159128 | F24: J&T Express | G24: 10/04/2026 10:19 | H24: 0 | I24: 794870224072 | J24: 45 | K24: ของเคลม Tiktok เนื่องจากลูกค้าได้รับสินค้าไม่ครบ | M24: ของเคลม Line OA เนื่องจากสินค้ามีรสชาติขม รสชาติ สีของขนม ผิดปกติ | N24: 0
A25: 23 | B25: HAB4 | C25: อ*** | D25: Tiktok | E25: 7494017216048891148 | F25: J&T Express | G25: 10/04/2026 10:49 | H25: 0 | I25: 794846704094 | J25: 45 | K25: ของเคลม Tiktok เนื่องจากลูกค้าได้รับสินค้าไม่ครบ | M25: ของเคลม Line OA เนื่องจากสินค้าไม่มี | N25: 0
A26: 24 | B26: HAB6 | C26: ศ***พร ม***ดคำ | D26: Tiktok | E26: 7495071459274754659 | F26: J&T Express | G26: 10/04/2026 10:51 | H26: 0 | I26: 794843627023 | J26: 45 | K26: ของเคลม Tiktok เนื่องจากลูกค้าได้รับสินค้าไม่ครบ | M26: ของเคลม Line OA ไม่ทราบเหตุผล | N26: 0
A27: 25 | B27: HAB9 | C27: จ***รัตน์ โ***้ง | D27: Tiktok | E27: 7494022148417881907 | F27: J&T Express | G27: 10/04/2026 10:58 | H27: 0 | I27: 794801329033 | J27: 45 | K27: ของเคลม Tiktok เนื่องจากลูกค้าได้รับสินค้าไม่ครบ | M27: ของเคลม Facebook , Facebook Live เนื่องจากลูกค้าได้รับสินค้าไม่ครบ | N27: 0
A28: 26 | B28: HAB11 | C28: คุณยีนส์ครับ | D28: other | F28: EMS | G28: 10/04/2026 10:59 | H28: 0 | I28: TH19018KGDVH1A | J28: 45 | K28: ของเคลม Tiktok เนื่องจากลูกค้าได้รับสินค้าไม่ครบ | M28: ของเคลม Facebook , Facebook Live เนื่องจากลูกค้าได้รับสินค้าผิดไม่ตรงตามที่สั่ง | N28: 0
A29: 27 | B29: HAB17 | C29: ส***ตรา | D29: Tiktok | E29: 7494263530888858462 | F29: J&T Express | G29: 10/04/2026 11:18 | H29: 0 | I29: 794838460010 | J29: 45 | K29: ของเคลม Tiktok เนื่องจากลูกค้าได้รับสินค้าไม่ครบ | M29: ของเคลม Facebook , Facebook Live เนื่องจากลูกค้าไม่ได้รับสินค้า | N29: 0
A30: 28 | B30: HAB19 | C30: P***che | D30: Tiktok | E30: 7496306921294497915 | F30: J&T Express | G30: 10/04/2026 11:20 | H30: 0 | I30: 794815025093 | J30: 45 | K30: ของเคลม Tiktok เนื่องจากลูกค้าได้รับสินค้าไม่ครบ | M30: ของเคลม Facebook , Facebook Live เนื่องจากสินค้าเสียหายจากการขนส่ง | N30: 0
A31: 29 | B31: HAC9 | C31: จ***รัตน์ โ***้ง | D31: Tiktok | E31: 7494022148417881907 | F31: J&T Express | G31: 10/04/2026 15:53 | H31: 0 | I31: 794944733402 | J31: 45 | K31: ของเคลม Tiktok เนื่องจากลูกค้าได้รับสินค้าไม่ครบ | M31: ของเคลม Facebook , Facebook Live เนื่องจากสินค้าเน่าเสียก่อนวันหมดอายุที่แจ้งข้างกล่อง | N31: 0
A32: 30 | B32: HAH68 | C32: แ***้อย | D32: Tiktok | E32: 7495272213209843748 | F32: J&T Express | G32: 13/04/2026 08:15 | H32: 0 | I32: 795043363133 | J32: 45 | K32: ของเคลม Tiktok เนื่องจากลูกค้าได้รับสินค้าไม่ครบ | M32: ของเคลม Facebook , Facebook Live เนื่องจากสินค้ามีรสชาติขม รสชาติ สีของขนม ผิดปกติ | N32: 0
A33: 34 | B33: HAH72 | C33: ป***ัสสร น***หลม | D33: Tiktok | E33: 7493990091087185685 | F33: J&T Express | G33: 13/04/2026 08:24 | H33: 0 | I33: 795095880110 | J33: 45 | K33: ของเคลม Tiktok เนื่องจากลูกค้าได้รับสินค้าไม่ครบ | M33: ของเคลม Facebook , Facebook Live เนื่องจากสินค้าไม่มี | N33: 0
A34: 35 | B34: HAH74 | C34: ห***พันธน์ | D34: Tiktok | E34: 7494016992700302336 | F34: J&T Express | G34: 13/04/2026 08:27 | H34: 0 | I34: 795038564121 | J34: 45 | K34: ของเคลม Tiktok เนื่องจากลูกค้าได้รับสินค้าไม่ครบ | M34: ของเคลม Facebook , Facebook Live ไม่ทราบเหตุผล | N34: 0
A35: 36 | B35: HAH75 | C35: N***rat K***awart | D35: Tiktok | E35: 7495571714405927306 | F35: J&T Express | G35: 13/04/2026 08:29 | H35: 0 | I35: 795031964101 | J35: 45 | K35: ของเคลม Tiktok เนื่องจากลูกค้าได้รับสินค้าไม่ครบ | M35: ของเคลม Tiktok เนื่องจากลูกค้าได้รับสินค้าไม่ครบ | N35: 58
A36: 37 | B36: HAH76 | C36: ย***ร พ***ทอง | D36: Tiktok | E36: 7495304694973106707 | F36: J&T Express | G36: 13/04/2026 08:35 | H36: 0 | I36: 795098963120 | J36: 45 | K36: ของเคลม Tiktok เนื่องจากลูกค้าได้รับสินค้าไม่ครบ | M36: ของเคลม Tiktok เนื่องจากลูกค้าได้รับสินค้าผิดไม่ตรงตามที่สั่ง | N36: 0
A37: 38 | B37: HAI57 | C37: ป***ดี ศ***ิชา | D37: Tiktok | E37: 7494022314081290158 | F37: J&T Express | G37: 13/04/2026 15:57 | H37: 0 | I37: 795090354306 | J37: 45 | K37: ของเคลม Tiktok เนื่องจากลูกค้าได้รับสินค้าไม่ครบ | M37: ของเคลม Tiktok เนื่องจากลูกค้าไม่ได้รับสินค้า | N37: 0
A38: 39 | B38: HAJ24 | C38: ธ***รัตน์ ภ***ีรัตน์ | D38: Tiktok | E38: 7494013488440443921 | F38: J&T Express | G38: 14/04/2026 08:41 | H38: 0 | I38: 795065999350 | J38: 45 | K38: ของเคลม Tiktok เนื่องจากลูกค้าได้รับสินค้าไม่ครบ | M38: ของเคลม TikTok เนื่องจากสินค้าเสียหายจากการขนส่ง | N38: 0
A39: 40 | B39: HAJ25 | C39: โ***า | D39: Tiktok | E39: 7495175445935721210 | F39: J&T Express | G39: 14/04/2026 08:46 | H39: 0 | I39: 795024818416 | J39: 45 | K39: ของเคลม Tiktok เนื่องจากลูกค้าได้รับสินค้าไม่ครบ | M39: ของเคลม TikTok เนื่องจากสินค้าเน่าเสียก่อนวันหมดอายุที่แจ้งข้างกล่อง | N39: 0
A40: 45 | B40: HAJ26 | C40: ศ***พร ม***ดคำ | D40: Tiktok | E40: 7495071459274754659 | F40: J&T Express | G40: 14/04/2026 08:54 | H40: 0 | I40: 795095190352 | J40: 45 | K40: ของเคลม Tiktok เนื่องจากลูกค้าได้รับสินค้าไม่ครบ | M40: ของเคลม Tiktok เนื่องจากสินค้ามีรสชาติขม รสชาติ สีของขนม ผิดปกติ | N40: 0
...

Sheet เม.ย. ยกเลิก
A1: สรุปรายการยกเลิกออเดอร์ ที่ออกเลขที่ออเดอร์แล้ว (เนื่องจากลูกค้าเอฟในไลฟ์สดแล้วไม่ยืนยันออเดอร์) เดือนเมษายน 2569
A2: ลำดับ | B2: เลขที่ออเดอร์ | C2: ชื่อ | D2: ช่องทางติดต่อ | E2: ชื่อตามช่องทางติดต่อ | F2: ขนส่ง | G2: วันที่สร้าง | H2: ยอดขาย | I2: หมายเหตุ
A3: 1
A4: 2
A5: 3
A6: 4
A7: 5
A8: 6
A9: 7
A10: 8
A11: 9
A12: 10
A13: 11
A14: 12
... A34: 32
G76: ยอดรวม | H76: =SUM(H3:H75) -> 0 | I76: บาท

Sheet พ.ค. เคลม
A1: สรุปรายการส่งของเคลมสินค้า เดือนพฤษภาคม 2569 | I1: รวมยอดเสียหายค่าขนส่งเพิ่มเติม | J1: =SUBTOTAL(9,J3:J190) -> 4095 | K1: บาท | N1: =SUBTOTAL(9,N3:N56) -> 91
A2: ลำดับ | B2: เลขที่ออเดอร์ | C2: ชื่อ | D2: ช่องทางติดต่อ | E2: ชื่อตามช่องทางติดต่อ | F2: ขนส่ง | G2: วันที่สร้าง | H2: ยอดขาย | I2: เลขพัสดุ | J2: ค่าใช้จ่ายส่งของ | K2: หมายเหตุ | M2: รายการ | N2: จำนวนออเดอร์
A3: 1 | B3: HCA16 | C3: จ***ร์จิรา | D3: Tiktok | E3: 7494221624670455913 | F3: J&T Express | G3: 01/05/2026 13:25 | H3: 0 | I3: 796124851130 | J3: 45 | K3: ของเคลม Tiktok เนื่องจากลูกค้าได้รับสินค้าไม่ครบ | M3: ของเคลม LAZADA เนื่องจากลูกค้าได้รับสินค้าไม่ครบ | N3: 1
A4: 2 | B4: HCA17 | C4: ช***ิป ก***ิงห์ ข***ุ้ย | D4: Tiktok | E4: 7495194916169943784 | F4: J&T Express | G4: 01/05/2026 13:28 | H4: 0 | I4: 796118307176 | J4: 45 | K4: ของเคลม Tiktok เนื่องจากลูกค้าได้รับสินค้าไม่ครบ | M4: ของเคลม LAZADA เนื่องจากลูกค้าได้รับสินค้าผิดไม่ตรงตามที่สั่ง | N4: 0
A5: 3 | B5: HCA19 | C5: อ***รา ว***รัตน์ | D5: Tiktok | E5: 7495571973901093521 | F5: J&T Express | G5: 01/05/2026 13:34 | H5: 0 | I5: 796015664076 | J5: 45 | K5: ของเคลม Tiktok เนื่องจากลูกค้าได้รับสินค้าไม่ครบ | M5: ของเคลม LAZADA เนื่องจากลูกค้าไม่ได้รับสินค้า | N5: 0
A6: 4 | B6: HCK34 | C6: ศ***สรา | D6: Tiktok | E6: 7495124693039942280 | F6: J&T Express | G6: 04/05/2026 13:22 | H6: 0 | I6: 796324236374 | J6: 45 | K6: ของเคลม Tiktok เนื่องจากลูกค้าได้รับสินค้าไม่ครบ | M6: ของเคลม LAZADA เนื่องจากสินค้าเสียหายจากการขนส่ง | N6: 0
A7: 5 | B7: HCK37 | C7: ณ***ร ห***เเนวกลาง | D7: Tiktok | E7: 7495969654587755029 | F7: J&T Express | G7: 04/05/2026 13:27 | H7: 0 | I7: 796374706260 | J7: 45 | K7: ของเคลม Tiktok เนื่องจากลูกค้าได้รับสินค้าไม่ครบ | M7: ของเคลม LAZADA เนื่องจากสินค้าเน่าเสียก่อนวันหมดอายุที่แจ้งข้างกล่อง | N7: 0
A8: 6 | B8: HCK39 | C8: ณ***ุดาคนสวย | D8: Tiktok | E8: 7495644071862634506 | F8: J&T Express | G8: 04/05/2026 13:31 | H8: 0 | I8: 796334908320 | J8: 45 | K8: ของเคลม Tiktok เนื่องจากลูกค้าได้รับสินค้าไม่ครบ | M8: ของเคลม LAZADA เนื่องจากสินค้ามีรสชาติขม รสชาติ สีของขนม ผิดปกติ | N8: 0
A9: 7 | B9: HCK44 | C9: อ***รา ว***รัตน์ | D9: Tiktok | E9: 7495571973901093521 | F9: J&T Express | G9: 04/05/2026 13:35 | H9: 0 | I9: 796310504242 | J9: 45 | K9: ของเคลม Tiktok เนื่องจากลูกค้าได้รับสินค้าไม่ครบ | M9: ของเคลม LAZADA เนื่องจากสินค้าไม่มี | N9: 0
A10: 8 | B10: HCK43 | C10: ศ***า ส***จ | D10: Tiktok | E10: 7494038583796139308 | F10: J&T Express | G10: 04/05/2026 13:35 | H10: 0 | I10: 796335737105 | J10: 45 | K10: ของเคลม Tiktok เนื่องจากลูกค้าได้รับสินค้าไม่ครบ | M10: ของเคลม LAZADA ไม่ทราบเหตุผล | N10: 0
A11: 9 | B11: HCN74 | C11: ก*** อ***ญา | D11: Tiktok | E11: 7493990193599580010 | F11: J&T Express | G11: 05/05/2026 11:29 | H11: 0 | I11: 796341931324 | J11: 45 | K11: ของเคลม Tiktok เนื่องจากลูกค้าได้รับสินค้าไม่ครบ | M11: ของเคลม Shopee เนื่องจากลูกค้าได้รับสินค้าไม่ครบ | N11: 0
A12: 10 | B12: HCS21 | C12: ณ***รรณ ค***ซิ่ว | D12: Tiktok | E12: 7494816474235833199 | F12: J&T Express | G12: 06/05/2026 17:19 | H12: 0 | I12: 796419369594 | J12: 45 | K12: ของเคลม Tiktok เนื่องจากลูกค้าได้รับสินค้าไม่ครบ | M12: ของเคลม Shopee เนื่องจากลูกค้าได้รับสินค้าผิดไม่ตรงตามที่สั่ง | N12: 0
A13: 11 | B13: HCS20 | C13: เ***ญา อ***ณะนัย | D13: Tiktok | E13: 7494535141062380489 | F13: J&T Express | G13: 06/05/2026 17:19 | H13: 0 | I13: 796437522565 | J13: 45 | K13: ของเคลม Tiktok เนื่องจากลูกค้าได้รับสินค้าไม่ครบ | M13: ของเคลม Shopee เนื่องจากลูกค้าไม่ได้รับสินค้า | N13: 0
A14: 12 | B14: HCS19 | C14: ช***่ | D14: Tiktok | E14: 7494026745096078965 | F14: J&T Express | G14: 06/05/2026 17:19 | H14: 0 | I14: 796404971563 | J14: 45 | K14: ของเคลม Tiktok เนื่องจากลูกค้าได้รับสินค้าไม่ครบ | M14: ของเคลม Shopee เนื่องจากสินค้าเสียหายจากการขนส่ง | N14: 0
... A35: 33 | B35: HDI31 | C35: ข***จิรา เ***ญรัมย์ | D35: Tiktok | E35: 7494036568572200160 | F35: J&T Express | G35: 12/05/2026 11:23 | H35: 0 | I35: 796770757974 | J35: 45 | K35: ของเคลม Tiktok เนื่องจากลูกค้าได้รับสินค้าไม่ครบ | M35: ของเคลม Tiktok เนื่องจากลูกค้าได้รับสินค้าไม่ครบ | N35: 88
A36: 34 | B36: HDJ77 | C36: ผึ้ง | D36: facebook | F36: EMS | G36: 12/05/2026 13:43 | H36: 0 | I36: WB251517678TH | J36: 45 | K36: ของเคลม Tiktok เนื่องจากลูกค้าได้รับสินค้าไม่ครบ | M36: ของเคลม Tiktok เนื่องจากลูกค้าได้รับสินค้าผิดไม่ตรงตามที่สั่ง | N36: 0
A37: 35 | B37: HDN54 | C37: ก***นา เ***ญหมื่น | D37: Tiktok | E37: 7494049524749470891 | F37: J&T Express | G37: 13/05/2026 16:52 | H37: 0 | I37: 796801539004 | J37: 45 | K37: ของเคลม Tiktok เนื่องจากลูกค้าได้รับสินค้าไม่ครบ | M37: ของเคลม Tiktok เนื่องจากลูกค้าไม่ได้รับสินค้า | N37: 0
A38: 36 | B38: HDQ42 | C38: ธ***รัตน์ ภ***ีรัตน์ | D38: Tiktok | E38: 7494013488440443921 | F38: J&T Express | G38: 14/05/2026 17:00 | H38: 0 | I38: 796939317753 | J38: 45 | K38: ของเคลม Tiktok เนื่องจากลูกค้าได้รับสินค้าไม่ครบ | M38: ของเคลม TikTok เนื่องจากสินค้าเสียหายจากการขนส่ง | N38: 1
A39: 37 | B39: HDQ43 | C39: ส***ตรา ล***มมา | D39: Tiktok | E39: 7494972961409567404 | F39: J&T Express | G39: 14/05/2026 17:02 | H39: 0 | I39: 796975324681 | J39: 45 | K39: ของเคลม Tiktok เนื่องจากลูกค้าได้รับสินค้าไม่ครบ | M39: ของเคลม TikTok เนื่องจากสินค้าเน่าเสียก่อนวันหมดอายุที่แจ้งข้างกล่อง | N39: 0
A40: 38 | B40: HDR30 | C40: ณ***รรณ ค***ซิ่ว | D40: Tiktok | E40: 7494816474235833199 | F40: J&T Express | G40: 15/05/2026 08:22 | H40: 0 | I40: 796917521890 | J40: 45 | K40: ของเคลม Tiktok เนื่องจากลูกค้าได้รับสินค้าไม่ครบ | M40: ของเคลม Tiktok เนื่องจากสินค้ามีรสชาติขม รสชาติ สีของขนม ผิดปกติ | N40: 0
A41: 39 | B41: HDR36 | C41: แ** ส***ญญา | D41: Tiktok | E41: 7494236678238800894 | F41: J&T Express | G41: 15/05/2026 09:09 | H41: 0 | I41: 797096602293 | J41: 45 | K41: ของเคลม Tiktok เนื่องจากลูกค้าได้รับสินค้าไม่ครบ | M41: ของเคลม Tiktok เนื่องจากสินค้าไม่มี | N41: 0
A42: 40 | B42: HDT79 | C42: ณ***ร น***ิริ | D42: Tiktok | E42: 7495345237062486943 | F42: J&T Express | G42: 15/05/2026 16:55 | H42: 0 | I42: 797027662395 | J42: 45 | K42: ของเคลม Tiktok เนื่องจากลูกค้าได้รับสินค้าไม่ครบ | M42: ของเคลม Tiktok ไม่ทราบเหตุผล | N42: 0
A43: 41 | B43: HDT78 | C43: อ** ณ***ันท์ เ***นรอบ | D43: Tiktok | E43: 7494005259413521913 | F43: J&T Express | G43: 15/05/2026 16:55 | H43: 0 | I43: 797036522332 | J43: 45 | K43: ของเคลม Tiktok เนื่องจากลูกค้าได้รับสินค้าไม่ครบ | M43: ของเคลม ไปรษณีย์ เนื่องจากลูกค้าได้รับสินค้าไม่ครบ | N43: 0
A44: 42 | B44: HDT80 | C44: ก***ิยา ภ***ลิศ | D44: Tiktok | E44: 7494083520294651235 | F44: J&T Express | G44: 15/05/2026 16:56 | H44: 0 | I44: 797092123236 | J44: 45 | K44: ของเคลม Tiktok เนื่องจากลูกค้าได้รับสินค้าไม่ครบ | M44: ของเคลม ไปรษณีย์ เนื่องจากลูกค้าได้รับสินค้าผิดไม่ตรงตามที่สั่ง | N44: 0
A45: 43 | B45: HDT81 | C45: ส***พร เ***วละออ | D45: Tiktok | E45: 7494844118570469545 | F45: J&T Express | G45: 15/05/2026 17:00 | H45: 0 | I45: 797089127391 | J45: 45 | K45: ของเคลม Tiktok เนื่องจากลูกค้าได้รับสินค้าไม่ครบ | M45: ของเคลม ไปรษณีย์ เนื่องจากลูกค้าไม่ได้รับสินค้า | N45: 0
A46: 44 | B46: HDW82 | C46: ป***สุดา ล***น | D46: Tiktok | E46: 7495027642011126359 | F46: J&T Express | G46: 17/05/2026 12:00 | H46: 0 | I46: 797105537384 | J46: 45 | K46: ของเคลม Tiktok เนื่องจากลูกค้าได้รับสินค้าไม่ครบ | M46: ของเคลม ไปรษณีย์ เนื่องจากสินค้าเสียหายจากการขนส่ง | N46: 0
A47: 45 | B47: HED49 | C47: ข***ุ่น อ***ธิดา | D47: Tiktok | E47: 7494072452429154071 | F47: J&T Express | G47: 18/05/2026 08:44 | H47: 0 | I47: 797164584436 | J47: 45 | K47: ของเคลม Tiktok เนื่องจากลูกค้าได้รับสินค้าไม่ครบ | M47: ของเคลม ไปรษณีย์ เนื่องจากสินค้าเน่าเสียก่อนวันหมดอายุที่แจ้งข้างกล่อง | N47: 0
A48: 46 | B48: HED52 | C48: น***พร | D48: Tiktok | E48: 7496100342218459810 | F48: J&T Express | G48: 18/05/2026 08:47 | H48: 0 | I48: 797139623593 | J48: 45 | K48: ของเคลม Tiktok เนื่องจากลูกค้าได้รับสินค้าไม่ครบ | M48: ของเคลม ไปรษณีย์ เนื่องจากสินค้ามีรสชาติขม รสชาติ สีของขนม ผิดปกติ | N48: 0
... A54: 52 | B54: HEI89 | C54: P***che | D54: Tiktok | E54: 7496306921294497915 | F54: J&T Express | G54: 19/05/2026 10:02 | H54: 0 | I54: 797276359342 | J54: 45 | K54: ของเคลม Tiktok เนื่องจากลูกค้าได้รับสินค้าไม่ครบ | M54: เคลมสินค้าเนื่องจากกล่องชำรุด เสียหาย | N54: 0
A55: 53 | B55: HEJ18 | C55: กฤษณา อิศรานุวัตร | D55: facebook | F55: EMS | G55: 19/05/2026 11:18 | H55: 0 | I55: WB252216011TH | J55: 45 | K55: ของเคลม Tiktok เนื่องจากลูกค้าได้รับสินค้าไม่ครบ | M55: เคลมเนื่องจากส่งสินค้าผิด | N55: 0
A56: 54 | B56: HEJ68 | C56: แ***หอม | D56: Tiktok | E56: 7494474374203870161 | F56: J&T Express | G56: 19/05/2026 13:28 | H56: 0 | I56: 797211731411 | J56: 45 | K56: ของเคลม Tiktok เนื่องจากลูกค้าได้รับสินค้าไม่ครบ | M56: ไม่ทราบสาเหตุ | N56: 0
