Workbook

Sheet สรุป 68
A1: สรุปยอดเคลมออเดอร์ขายออนไลน์ ปี 2568
A2: เดือน | B2: เคลม | D2: ยกเลิก ( CF เล่น) | F2: หมายเหตุ
B3: จำนวน | C3: ค่าขนส่ง | D3: จำนวน | E3: ยอดเงิน
A4: ม.ค. | B4: 47 | C4: =+'ม.ค. เคลม'!J1 -> 1131 | D4: 32 | E4: =+'ม.ค. ยกเลิก'!H76 -> 21495.77
A5: ก.พ. | B5: 12 | C5: =+'ก.พ. เคลม'!J1 -> 271 | D5: 22 | E5: =+'ก.พ. ยกเลิก'!H25 -> 5138.96
A6: มี.ค. | B6: 6 | C6: =+'มี.ค. เคลม'!J1 -> 270 | D6: 23 | E6: =+'มี.ค. ยกเลิก'!H108 -> 3778.71
A7: เม.ย. | B7: 9 | C7: =+'เม.ย. เคลม'!J1 -> 315 | D7: 15 | E7: =+'เม.ย. ยกเลิก'!H18 -> 2614.09
A8: พ.ค. | B8: 5 | C8: =+'พ.ค. เคลม'!J1 -> 225 | D8: 5 | E8: =+'พ.ค. ยกเลิก'!H8 -> 1007.48
A9: มิ.ย. | B9: 19 | C9: =+'มิ.ย. เคลม'!J1 -> 495 | D9: 17 | E9: =+'มิ.ย. ยกเลิก'!H20 -> 2537.15
A10: ก.ค. | B10: 20 | C10: =+'ก.ค. เคลม'!J1 -> 900 | D10: 5 | E10: =+'ก.ค. ยกเลิก'!H8 -> 579.6
A11: ส.ค. | B11: 10 | C11: =+'ส.ค. เคลม'!J1 -> 450 | D11: 5 | E11: =+'ส.ค. ยกเลิก'!H8 -> 630.4
A12: ก.ย. | B12: 8 | C12: =+'ก.ย. เคลม'!J1 -> 360 | D12: 1 | E12: =+'ก.ย. ยกเลิก'!H4 -> 83
A13: ต.ค. | B13: 3 | C13: =+'ต.ค. เคลม'!J1 -> 135 | D13: 0 | E13: =+'ต.ค. ยกเลิก'!H58 -> 0
A14: พ.ย. | B14: 3 | C14: =+'พ.ย. เคลม'!J1 -> 135 | D14: 0 | E14: =+'พ.ย. ยกเลิก'!H51 -> 0
A15: ธ.ค. | B15: 35 | C15: =+'ธ.ค. เคลม'!J1 -> 1575 | D15: 0 | E15: =+'ธ.ค. ยกเลิก'!H108 -> 0
A16: ยอดรวม | B16: =SUM(B4:B15) -> 177 | C16: =SUM(C4:C15) -> 6262 | D16: =SUM(D4:D15) -> 125 | E16: =SUM(E4:E15) -> 37865.16 | F16: บาท

Sheet สรุปสาเหตุเคลม
A1: สรุปสาเหตุการส่งเคลมจากแพลตฟอร์ม ปี 2568 | C1: Total | D1: ม.ค. | E1: ก.พ. | F1: มี.ค. | G1: เม.ย. | H1: พ.ค. | I1: มิ.ย. | J1: ก.ค. | K1: ส.ค. | L1: ก.ย. | M1: ต.ค. | N1: พ.ย. | O1: ธ.ค.
A2: สาเหตุส่งเคลม | B2: ผู้รับผิดชอบดูแล | C2: จำนวน | D2: จำนวนออเดอร์ | E2: จำนวนออเดอร์ | F2: จำนวนออเดอร์ | G2: จำนวนออเดอร์ | H2: จำนวนออเดอร์ | I2: จำนวนออเดอร์ | J2: จำนวนออเดอร์ | K2: จำนวนออเดอร์ | L2: จำนวนออเดอร์ | M2: จำนวนออเดอร์ | N2: จำนวนออเดอร์ | O2: จำนวนออเดอร์
A3: ของเคลม LAZADA เนื่องจากลูกค้าได้รับสินค้าไม่ครบ | B3: Packing | C3: =SUM(D3:O3) -> 13 | D3: =+'ม.ค. เคลม'!N3 -> 7 | E3: =+'ก.พ. เคลม'!N3 -> 4 | F3: =+'มี.ค. เคลม'!N3 -> 0 | G3: =+'เม.ย. เคลม'!N3 -> 1 | H3: =+'พ.ค. เคลม'!N3 -> 0 | I3: =+'มิ.ย. เคลม'!N3 -> 0 | J3: =+'ก.ค. เคลม'!O3 -> 0 | K3: =+'ส.ค. เคลม'!O3 -> 0 | L3: =+'ก.ย. เคลม'!O3 -> 0 | M3: =+'ต.ค. เคลม'!O3 -> 0 | N3: =+'พ.ย. เคลม'!O3 -> 0 | O3: =+'ธ.ค. เคลม'!O3 -> 1
A4: ของเคลม LAZADA เนื่องจากลูกค้าได้รับสินค้าผิดไม่ตรงตามที่สั่ง | B4: Packing / Online | C4: =SUM(D4:O4) -> 1 | D4: =+'ม.ค. เคลม'!N4 -> 1 | E4: =+'ก.พ. เคลม'!N4 -> 0 | F4: =+'มี.ค. เคลม'!N4 -> 0 | G4: =+'เม.ย. เคลม'!N4 -> 0 | H4: =+'พ.ค. เคลม'!N4 -> 0 | I4: =+'มิ.ย. เคลม'!N4 -> 0 | J4: =+'ก.ค. เคลม'!O4 -> 0 | K4: =+'ส.ค. เคลม'!O4 -> 0 | L4: =+'ก.ย. เคลม'!O4 -> 0 | M4: =+'ต.ค. เคลม'!O4 -> 0 | N4: =+'พ.ย. เคลม'!O4 -> 0 | O4: =+'ธ.ค. เคลม'!O4 -> 0
A5: ของเคลม LAZADA เนื่องจากลูกค้าไม่ได้รับสินค้า | B5: ขนส่ง | C5: =SUM(D5:O5) -> 1 | D5: =+'ม.ค. เคลม'!N5 -> 1 | E5: =+'ก.พ. เคลม'!N5 -> 0 | F5: =+'มี.ค. เคลม'!N5 -> 0 | G5: =+'เม.ย. เคลม'!N5 -> 0 | H5: =+'พ.ค. เคลม'!N5 -> 0 | I5: =+'มิ.ย. เคลม'!N5 -> 0 | J5: =+'ก.ค. เคลม'!O5 -> 0 | K5: =+'ส.ค. เคลม'!O5 -> 0 | L5: =+'ก.ย. เคลม'!O5 -> 0 | M5: =+'ต.ค. เคลม'!O5 -> 0 | N5: =+'พ.ย. เคลม'!O5 -> 0 | O5: =+'ธ.ค. เคลม'!O5 -> 0
A6: ของเคลม LAZADA เนื่องจากสินค้าเสียหายจากการขนส่ง | B6: ขนส่ง | C6: =SUM(D6:O6) -> 1 | D6: =+'ม.ค. เคลม'!N6 -> 1 | E6: =+'ก.พ. เคลม'!N6 -> 0 | F6: =+'มี.ค. เคลม'!N6 -> 0 | G6: =+'เม.ย. เคลม'!N6 -> 0 | H6: =+'พ.ค. เคลม'!N6 -> 0 | I6: =+'มิ.ย. เคลม'!N6 -> 0 | J6: =+'ก.ค. เคลม'!O6 -> 0 | K6: =+'ส.ค. เคลม'!O6 -> 0 | L6: =+'ก.ย. เคลม'!O6 -> 0 | M6: =+'ต.ค. เคลม'!O6 -> 0 | N6: =+'พ.ย. เคลม'!O6 -> 0 | O6: =+'ธ.ค. เคลม'!O6 -> 0
A7: ของเคลม LAZADA เนื่องจากสินค้าเน่าเสียก่อนวันหมดอายุที่แจ้งข้างกล่อง | B7: ฝ่ายผลิต | C7: =SUM(D7:O7) -> 9 | D7: =+'ม.ค. เคลม'!N7 -> 0 | E7: =+'ก.พ. เคลม'!N7 -> 3 | F7: =+'มี.ค. เคลม'!N7 -> 0 | G7: =+'เม.ย. เคลม'!N7 -> 1 | H7: =+'พ.ค. เคลม'!N7 -> 0 | I7: =+'มิ.ย. เคลม'!N7 -> 0 | J7: =+'ก.ค. เคลม'!O7 -> 2 | K7: =+'ส.ค. เคลม'!O7 -> 0 | L7: =+'ก.ย. เคลม'!O7 -> 3 | M7: =+'ต.ค. เคลม'!O7 -> 0 | N7: =+'พ.ย. เคลม'!O7 -> 0 | O7: =+'ธ.ค. เคลม'!O7 -> 0
A8: ของเคลม LAZADA เนื่องจากสินค้ามีรสชาติขม รสชาติ สีของขนม ผิดปกติ | B8: ฝ่ายผลิต | C8: =SUM(D8:O8) -> 9 | D8: =+'ม.ค. เคลม'!N8 -> 7 | E8: =+'ก.พ. เคลม'!N8 -> 0 | F8: =+'มี.ค. เคลม'!N8 -> 1 | G8: =+'เม.ย. เคลม'!N8 -> 0 | H8: =+'พ.ค. เคลม'!N8 -> 0 | I8: =+'มิ.ย. เคลม'!N8 -> 1 | J8: =+'ก.ค. เคลม'!O8 -> 0 | K8: =+'ส.ค. เคลม'!O8 -> 0 | L8: =+'ก.ย. เคลม'!O8 -> 0 | M8: =+'ต.ค. เคลม'!O8 -> 0 | N8: =+'พ.ย. เคลม'!O8 -> 0 | O8: =+'ธ.ค. เคลม'!O8 -> 0
A9: ของเคลม LAZADA เนื่องจากสินค้าไม่มี | B9: ฝ่ายผลิต | C9: =SUM(D9:O9) -> 1 | D9: =+'ม.ค. เคลม'!N9 -> 1 | E9: =+'ก.พ. เคลม'!N9 -> 0 | F9: =+'มี.ค. เคลม'!N9 -> 0 | G9: =+'เม.ย. เคลม'!N9 -> 0 | H9: =+'พ.ค. เคลม'!N9 -> 0 | I9: =+'มิ.ย. เคลม'!N9 -> 0 | J9: =+'ก.ค. เคลม'!O9 -> 0 | K9: =+'ส.ค. เคลม'!O9 -> 0 | L9: =+'ก.ย. เคลม'!O9 -> 0 | M9: =+'ต.ค. เคลม'!O9 -> 0 | N9: =+'พ.ย. เคลม'!O9 -> 0 | O9: =+'ธ.ค. เคลม'!O9 -> 0
A10: ของเคลม LAZADA ไม่ทราบเหตุผล | B10: Online | C10: =SUM(D10:O10) -> 0 | D10: =+'ม.ค. เคลม'!N10 -> 0 | E10: =+'ก.พ. เคลม'!N10 -> 0 | F10: =+'มี.ค. เคลม'!N10 -> 0 | G10: =+'เม.ย. เคลม'!N10 -> 0 | H10: =+'พ.ค. เคลม'!N10 -> 0 | I10: =+'มิ.ย. เคลม'!N10 -> 0 | J10: =+'ก.ค. เคลม'!O10 -> 0 | K10: =+'ส.ค. เคลม'!O10 -> 0 | L10: =+'ก.ย. เคลม'!O10 -> 0 | M10: =+'ต.ค. เคลม'!O10 -> 0 | N10: =+'พ.ย. เคลม'!O10 -> 0 | O10: =+'ธ.ค. เคลม'!O10 -> 0
A11: ของเคลม Shopee เนื่องจากลูกค้าได้รับสินค้าไม่ครบ | B11: Packing | C11: =SUM(D11:O11) -> 14 | D11: =+'ม.ค. เคลม'!N11 -> 7 | E11: =+'ก.พ. เคลม'!N11 -> 0 | F11: =+'มี.ค. เคลม'!N11 -> 0 | G11: =+'เม.ย. เคลม'!N11 -> 0 | H11: =+'พ.ค. เคลม'!N11 -> 0 | I11: =+'มิ.ย. เคลม'!N11 -> 0 | J11: =+'ก.ค. เคลม'!O11 -> 0 | K11: =+'ส.ค. เคลม'!O11 -> 1 | L11: =+'ก.ย. เคลม'!O11 -> 0 | M11: =+'ต.ค. เคลม'!O11 -> 0 | N11: =+'พ.ย. เคลม'!O11 -> 0 | O11: =+'ธ.ค. เคลม'!O11 -> 6
A12: ของเคลม Shopee เนื่องจากลูกค้าได้รับสินค้าผิดไม่ตรงตามที่สั่ง | B12: Packing / Online | C12: =SUM(D12:O12) -> 2 | D12: =+'ม.ค. เคลม'!N12 -> 0 | E12: =+'ก.พ. เคลม'!N12 -> 0 | F12: =+'มี.ค. เคลม'!N12 -> 0 | G12: =+'เม.ย. เคลม'!N12 -> 0 | H12: =+'พ.ค. เคลม'!N12 -> 0 | I12: =+'มิ.ย. เคลม'!N12 -> 0 | J12: =+'ก.ค. เคลม'!O12 -> 0 | K12: =+'ส.ค. เคลม'!O12 -> 2 | L12: =+'ก.ย. เคลม'!O12 -> 0 | M12: =+'ต.ค. เคลม'!O12 -> 0 | N12: =+'พ.ย. เคลม'!O12 -> 0 | O12: =+'ธ.ค. เคลม'!O12 -> 0
A13: ของเคลม Shopee เนื่องจากลูกค้าไม่ได้รับสินค้า | B13: ขนส่ง | C13: =SUM(D13:O13) -> 0 | D13: =+'ม.ค. เคลม'!N13 -> 0 | E13: =+'ก.พ. เคลม'!N13 -> 0 | F13: =+'มี.ค. เคลม'!N13 -> 0 | G13: =+'เม.ย. เคลม'!N13 -> 0 | H13: =+'พ.ค. เคลม'!N13 -> 0 | I13: =+'มิ.ย. เคลม'!N13 -> 0 | J13: =+'ก.ค. เคลม'!O13 -> 0 | K13: =+'ส.ค. เคลม'!O13 -> 0 | L13: =+'ก.ย. เคลม'!O13 -> 0 | M13: =+'ต.ค. เคลม'!O13 -> 0 | N13: =+'พ.ย. เคลม'!O13 -> 0 | O13: =+'ธ.ค. เคลม'!O13 -> 0
A14: ของเคลม Shopee เนื่องจากสินค้าเสียหายจากการขนส่ง | B14: ขนส่ง | C14: =SUM(D14:O14) -> 1 | D14: =+'ม.ค. เคลม'!N14 -> 0 | E14: =+'ก.พ. เคลม'!N14 -> 0 | F14: =+'มี.ค. เคลม'!N14 -> 0 | G14: =+'เม.ย. เคลม'!N14 -> 0 | H14: =+'พ.ค. เคลม'!N14 -> 0 | I14: =+'มิ.ย. เคลม'!N14 -> 1 | J14: =+'ก.ค. เคลม'!O14 -> 0 | K14: =+'ส.ค. เคลม'!O14 -> 0 | L14: =+'ก.ย. เคลม'!O14 -> 0 | M14: =+'ต.ค. เคลม'!O14 -> 0 | N14: =+'พ.ย. เคลม'!O14 -> 0 | O14: =+'ธ.ค. เคลม'!O14 -> 0
... A56: ไม่ทราบสาเหตุ | B56: Online | C56: =SUM(D56:O56) -> 0 | D56: =+'ม.ค. เคลม'!N56 -> 0 | E56: =+'ก.พ. เคลม'!N56 -> 0 | F56: =+'มี.ค. เคลม'!N56 -> 0 | G56: =+'เม.ย. เคลม'!N56 -> 0 | H56: =+'พ.ค. เคลม'!N56 -> 0 | I56: =+'มิ.ย. เคลม'!N56 -> 0 | J56: =+'ก.ค. เคลม'!O56 -> 0 | K56: =+'ส.ค. เคลม'!O56 -> 0 | L56: =+'ก.ย. เคลม'!O56 -> 0 | M56: =+'ต.ค. เคลม'!O56 -> 0 | N56: =+'พ.ย. เคลม'!O56 -> 0 | O56: =+'ธ.ค. เคลม'!O56 -> 0
C57: =SUM(C3:C56) -> 175 | D57: =SUM(D3:D56) -> 47 | E57: =SUM(E3:E56) -> 11 | F57: =SUM(F3:F56) -> 6 | G57: =SUM(G3:G56) -> 9 | H57: =SUM(H3:H56) -> 5 | I57: =SUM(I3:I56) -> 19 | J57: =SUM(J3:J56) -> 19 | ... O57: =SUM(O3:O56) -> 35

Sheet ธ.ค. เคลม
A1: สรุปรายการส่งของเคลมสินค้า เดือนธันวาคม 2568 | I1: รวมยอดเสียหายค่าขนส่งเพิ่มเติม | J1: =SUBTOTAL(9,J3:J83) -> 1575 | K1: บาท
A2: ลำดับ | B2: เลขที่ออเดอร์ | C2: ชื่อ | D2: ช่องทางติดต่อ | E2: ชื่อตามช่องทางติดต่อ | F2: ขนส่ง | G2: วันที่สร้าง | H2: ยอดขาย | I2: เลขพัสดุ | J2: ค่าขนส่ง | K2: หมายเหตุ | L2: หมายเหตุ | N2: รายการ | O2: จำนวนออเดอร์
A3: 1 | B3: GDO61 | C3: คุณบุศรา สรณ์กุลจำรูญ | D3: facebook | E3: QuiltyCat Fabcottage | F3: EMS | G3: 04/12/2025 15:17 | H3: 0 | I3: WB107015223TH | J3: 45 | K3: ของเคลม LAZADA เนื่องจากลูกค้าได้รับสินค้าไม่ครบ | N3: ของเคลม LAZADA เนื่องจากลูกค้าได้รับสินค้าไม่ครบ | O3: 1
A4: 2 | B4: GDO62 | C4: สุวิตรา หาญสระคู | D4: facebook | E4: 1410_th | F4: EMS | G4: 04/12/2025 15:23 | H4: 0 | I4: WB107015237TH | J4: 45 | K4: ของเคลม Tiktok เนื่องจากลูกค้าได้รับสินค้าไม่ครบ | N4: ของเคลม LAZADA เนื่องจากลูกค้าได้รับสินค้าผิดไม่ตรงตามที่สั่ง | O4: 0
A5: 3 | B5: GEJ59 | C5: ศิริพันธ์​ ดวงแก้ว | D5: facebook | F5: EMS | G5: 08/12/2025 15:59 | H5: 0 | I5: WB107300360TH | J5: 45 | K5: ของเคลม Shopee เนื่องจากลูกค้าได้รับสินค้าไม่ครบ | N5: ของเคลม LAZADA เนื่องจากลูกค้าไม่ได้รับสินค้า | O5: 0
A6: 4 | B6: GFG61 | C6: วรรณภา สิงห์หลอด | D6: facebook | F6: EMS | G6: 12/12/2025 09:05 | H6: 0 | I6: WB107736089TH | J6: 45 | K6: ของเคลม Tiktok เนื่องจากสินค้ามีรสชาติขม รสชาติ สีของขนม ผิดปกติ | N6: ของเคลม LAZADA เนื่องจากสินค้าเสียหายจากการขนส่ง | O6: 0
A7: 5 | B7: GFZ38 | C7: คุณพิจิกา | D7: facebook | E7: user74929219205 | F7: EMS | G7: 14/12/2025 09:29 | H7: 0 | I7: WB107899011TH | J7: 45 | K7: ของเคลม Tiktok เนื่องจากลูกค้าได้รับสินค้าไม่ครบ | N7: ของเคลม LAZADA เนื่องจากสินค้าเน่าเสียก่อนวันหมดอายุที่แจ้งข้างกล่อง | O7: 0
A8: 6 | B8: GGE36 | C8: K.เป้า | D8: facebook | F8: EMS | G8: 14/12/2025 17:22 | H8: 0 | I8: WB107898957TH | J8: 45 | K8: ของเคลม Shopee เนื่องจากลูกค้าได้รับสินค้าไม่ครบ | N8: ของเคลม LAZADA เนื่องจากสินค้ามีรสชาติขม รสชาติ สีของขนม ผิดปกติ | O8: 0
A9: 7 | B9: GGI95 | C9: ชนิชา อิ่มเจริญ | D9: facebook | F9: EMS | G9: 15/12/2025 08:41 | H9: 0 | I9: WB108036105TH | J9: 45 | K9: ของเคลม Tiktok เนื่องจากลูกค้าได้รับสินค้าไม่ครบ | N9: ของเคลม LAZADA เนื่องจากสินค้าไม่มี | O9: 0
A10: 8 | B10: GGY59 | C10: ณัฐกฤตา บุษรา | D10: facebook | F10: EMS | G10: 16/12/2025 13:41 | H10: 0 | I10: WB108143555TH | J10: 45 | K10: ของเคลม Shopee เนื่องจากลูกค้าได้รับสินค้าไม่ครบ | N10: ของเคลม LAZADA ไม่ทราบเหตุผล | O10: 0
A11: 9 | B11: GIH76 | C11: พัชรินทร์ นิ่มเจริญ | D11: facebook | F11: EMS | G11: 19/12/2025 16:54 | H11: 0 | I11: WB108515795TH | J11: 45 | K11: ของเคลม Tiktok เนื่องจากลูกค้าได้รับสินค้าไม่ครบ | N11: ของเคลม Shopee เนื่องจากลูกค้าได้รับสินค้าไม่ครบ | O11: 6
A12: 10 | B12: GKQ91 | C12: K.Yui S. | D12: facebook | F12: EMS | G12: 23/12/2025 16:03 | H12: 0 | I12: WB108958100TH | J12: 45 | K12: ของเคลม Shopee เนื่องจากลูกค้าได้รับสินค้าไม่ครบ | N12: ของเคลม Shopee เนื่องจากลูกค้าได้รับสินค้าผิดไม่ตรงตามที่สั่ง | O12: 0
A13: 11 | B13: GKR14 | C13: ศิรินยา โคตกำพี้ | D13: facebook | F13: EMS | G13: 23/12/2025 16:10 | H13: 0 | I13: WB108958095TH | J13: 45 | K13: ของเคลม Tiktok เนื่องจากลูกค้าได้รับสินค้าผิดไม่ตรงตามที่สั่ง | N13: ของเคลม Shopee เนื่องจากลูกค้าไม่ได้รับสินค้า | O13: 0
A14: 12 | B14: GKR35 | C14: คุณพัชรี พูนเพ็ชรประดับ | D14: facebook | F14: EMS | G14: 23/12/2025 16:18 | H14: 0 | I14: WB108958087TH | J14: 45 | K14: ของเคลม Tiktok เนื่องจากลูกค้าได้รับสินค้าไม่ครบ | N14: ของเคลม Shopee เนื่องจากสินค้าเสียหายจากการขนส่ง | O14: 0
A15: 13 | B15: GLS25 | C15: ยุพาวดี ภวังคานนท์ | D15: facebook | F15: EMS | G15: 25/12/2025 06:50 | H15: 0 | I15: WB109187610TH | J15: 45 | K15: ของเคลม Tiktok เนื่องจากลูกค้าได้รับสินค้าไม่ครบ | N15: ของเคลม Shopee เนื่องจากสินค้าเน่าเสียก่อนวันหมดอายุที่แจ้งข้างกล่อง | O15: 0
A16: 14 | B16: GLT43 | C16: ธัญลักษณ์ ศรีแก้ว | D16: facebook | F16: EMS | G16: 25/12/2025 08:04 | H16: 0 | I16: WB109188632TH | J16: 45 | K16: ของเคลม Shopee เนื่องจากลูกค้าได้รับสินค้าไม่ครบ | N16: ของเคลม Shopee เนื่องจากสินค้ามีรสชาติขม รสชาติ สีของขนม ผิดปกติ | O16: 0
A17: 15 | B17: GLU22 | C17: ทิพาพร ชูวงศ์วรพินิจ | D17: facebook | F17: EMS | G17: 25/12/2025 09:50 | H17: 0 | I17: WB109187597TH | J17: 45 | K17: ของเคลม Tiktok เนื่องจากลูกค้าได้รับสินค้าไม่ครบ | N17: ของเคลม Shopee เนื่องจากสินค้าไม่มี | O17: 0
A18: 16 | B18: GLY26 | C18: แพรว | D18: facebook | F18: EMS | G18: 25/12/2025 14:36 | H18: 0 | I18: WB109188663TH | J18: 45 | K18: ของเคลม Tiktok เนื่องจากลูกค้าได้รับสินค้าไม่ครบ | N18: ของเคลม Shopee ไม่ทราบเหตุผล | O18: 0
A19: 17 | B19: GMF89 | C19: อรรรณ ต้นบุญ | D19: facebook | F19: EMS | G19: 26/12/2025 11:29 | H19: 0 | I19: WB109318275TH | J19: 45 | K19: ของเคลม Tiktok เนื่องจากลูกค้าได้รับสินค้าไม่ครบ | N19: ของเคลม Line OA เนื่องจากลูกค้าได้รับสินค้าไม่ครบ | O19: 0
... A34: 32 | B34: GOD89 | C34: สุขุมา จันทร์สะอาด | D34: facebook | F34: EMS | G34: 31/12/2025 09:38 | H34: 0 | I34: TH130686DYH91D | J34: 45 | K34: ของเคลม Tiktok เนื่องจากลูกค้าได้รับสินค้าไม่ครบ | N34: ของเคลม Facebook , Facebook Live ไม่ทราบเหตุผล | O34: 0
A35: 33 | B35: GOD93 | C35: พิจิตรา จิตตสำเริง | D35: facebook | E35: พิจิตรา จิตตสำเริง | F35: EMS | G35: 31/12/2025 09:41 | H35: 0 | I35: TH014886DYH94B | J35: 45 | K35: ของเคลม ไปรษณีย์ เนื่องจากลูกค้าได้รับสินค้าไม่ครบ | N35: ของเคลม Tiktok เนื่องจากลูกค้าได้รับสินค้าไม่ครบ | O35: 24
A36: 34 | B36: GOD95 | C36: ปริสุทธา บ้านนาน่าดู | D36: facebook | E36: Parisudha Sudhamongkala | F36: EMS | G36: 31/12/2025 09:44 | H36: 0 | I36: TH540186DYH96K | J36: 45 | K36: ของเคลม ไปรษณีย์ เนื่องจากลูกค้าได้รับสินค้าไม่ครบ | N36: ของเคลม Tiktok เนื่องจากลูกค้าได้รับสินค้าผิดไม่ตรงตามที่สั่ง | O36: 1
A37: 35 | B37: GOF77 | C37: คุณนฤมล จีนแส | D37: facebook | F37: EMS | G37: 31/12/2025 15:06 | H37: 0 | I37: TH101086E0UR5D | J37: 45 | K37: ของเคลม Tiktok เนื่องจากลูกค้าได้รับสินค้าไม่ครบ | N37: ของเคลม Tiktok เนื่องจากลูกค้าไม่ได้รับสินค้า | O37: 0
N38: ของเคลม TikTok เนื่องจากสินค้าเสียหายจากการขนส่ง | O38: 0
N39: ของเคลม TikTok เนื่องจากสินค้าเน่าเสียก่อนวันหมดอายุที่แจ้งข้างกล่อง | O39: 0
N40: ของเคลม Tiktok เนื่องจากสินค้ามีรสชาติขม รสชาติ สีของขนม ผิดปกติ | O40: 1
N41: ของเคลม Tiktok เนื่องจากสินค้าไม่มี | O41: 0
N42: ของเคลม Tiktok ไม่ทราบเหตุผล | O42: 0
N43: ของเคลม ไปรษณีย์ เนื่องจากลูกค้าได้รับสินค้าไม่ครบ | O43: 2
N44: ของเคลม ไปรษณีย์ เนื่องจากลูกค้าได้รับสินค้าผิดไม่ตรงตามที่สั่ง | O44: 0
N45: ของเคลม ไปรษณีย์ เนื่องจากลูกค้าไม่ได้รับสินค้า | O45: 0
N46: ของเคลม ไปรษณีย์ เนื่องจากสินค้าเสียหายจากการขนส่ง | O46: 0
N47: ของเคลม ไปรษณีย์ เนื่องจากสินค้าเน่าเสียก่อนวันหมดอายุที่แจ้งข้างกล่อง | O47: 0
N48: ของเคลม ไปรษณีย์ เนื่องจากสินค้ามีรสชาติขม รสชาติ สีของขนม ผิดปกติ | O48: 0
N49: ของเคลม ไปรษณีย์ เนื่องจากสินค้าไม่มี | O49: 0
... N56: ไม่ทราบสาเหตุ | O56: 0
O57: =SUM(O3:O56) -> 35

Sheet ธ.ค. ยกเลิก
A1: สรุปรายการยกเลิกออเดอร์ ที่ออกเลขที่ออเดอร์แล้ว (เนื่องจากลูกค้าเอฟในไลฟ์สดแล้วไม่ยืนยันออเดอร์) เดือนธันวาคม 2568
A2: ลำดับ | B2: เลขที่ออเดอร์ | C2: ชื่อ | D2: ช่องทางติดต่อ | E2: ชื่อตามช่องทางติดต่อ | F2: ขนส่ง | G2: วันที่สร้าง | H2: ยอดขาย | I2: หมายเหตุ
A3: 1
A4: 2
A5: 3
A6: 4
A7: 5
A8: 6
A9: 7
A10: 8
A11: 9
A12: 10
A13: 11
A14: 12
... A35: 33
A36: 34 | L36: 5 | M36: 0 | N36: 949445234794894
A37: 35 | L37: 0 | M37: 0 | N37: 579761121031981675
A38: 36 | L38: 0 | M38: 0 | N38: 579761453882968867
A39: 37 | L39: 29 | M39: 0 | N39: 950045632510422
A40: 38 | L40: 6 | M40: 0 | N40: 579761867468146737
A41: 39 | L41: 0 | M41: 0 | N41: 579762010646481072
A42: 40 | L42: 38 | M42: 36 | N42: 241214SDTPK12R
A43: 41 | L43: 45 | M43: 0 | N43: 579763446067136880
A44: 42 | L44: 45 | M44: 0 | N44: 956892714996174
A45: 43 | L45: 29 | M45: 45 | N45: 241215T05XRKSE
A46: 44 | L46: 4 | M46: 0 | N46: 956871784485869
A47: 45 | L47: 5 | M47: 0 | N47: 958115746233162
... A100: 98 | L100: 48 | M100: 128 | N100: 241226SWBDGA0H
A101: 99
A102: 100
A103: 101
A104: 102
A105: 103
A106: 104
A107: 105

Sheet พ.ย. เคลม
A1: สรุปรายการส่งของเคลมสินค้า เดือนพฤศจิกายน 2568 | I1: รวมยอดเสียหายค่าขนส่งเพิ่มเติม | J1: =SUBTOTAL(9,J3:J100) -> 135 | K1: บาท
A2: ลำดับ | B2: เลขที่ออเดอร์ | C2: ชื่อ | D2: ช่องทางติดต่อ | E2: ชื่อตามช่องทางติดต่อ | F2: ขนส่ง | G2: วันที่สร้าง | H2: ยอดขาย | I2: เลขพัสดุ | J2: ค่าขนส่ง | K2: หมายเหตุ | L2: หมายเหตุ | N2: รายการ | O2: จำนวนออเดอร์
A3: 1 | B3: GAO64 | C3: รัตนา หลีอรัญ​ | D3: facebook | F3: EMS | G3: 08/11/2025 11:13 | H3: 08/11/2025 11:13 | I3: WB055194399TH | J3: 45 | K3: ของเคลม Tiktok เนื่องจากลูกค้าได้รับสินค้าไม่ครบ | N3: ของเคลม LAZADA เนื่องจากลูกค้าได้รับสินค้าไม่ครบ | O3: 0
A4: 2 | B4: GBB22 | C4: บริพัตร แวงวรรณ | D4: facebook | F4: EMS | G4: 12/11/2025 09:04 | H4: 12/11/2025 09:04 | I4: WB055638971TH | J4: 45 | K4: ของเคลม Tiktok เนื่องจากลูกค้าได้รับสินค้าไม่ครบ | N4: ของเคลม LAZADA เนื่องจากลูกค้าได้รับสินค้าผิดไม่ตรงตามที่สั่ง | O4: 0
A5: 3 | B5: GBB24 | C5: ธัญยธรณ์ | D5: facebook | F5: EMS | G5: 12/11/2025 09:07 | H5: 12/11/2025 09:07 | I5: WB055638985TH | J5: 45 | K5: ของเคลม Tiktok เนื่องจากลูกค้าได้รับสินค้าไม่ครบ | N5: ของเคลม LAZADA เนื่องจากลูกค้าไม่ได้รับสินค้า | O5: 0
A6: 4 | N6: ของเคลม LAZADA เนื่องจากสินค้าเสียหายจากการขนส่ง | O6: 0
A7: 5 | N7: ของเคลม LAZADA เนื่องจากสินค้าเน่าเสียก่อนวันหมดอายุที่แจ้งข้างกล่อง | O7: 0
A8: 6 | N8: ของเคลม LAZADA เนื่องจากสินค้ามีรสชาติขม รสชาติ สีของขนม ผิดปกติ | O8: 0
A9: 7 | N9: ของเคลม LAZADA เนื่องจากสินค้าไม่มี | O9: 0
A10: 8 | N10: ของเคลม LAZADA ไม่ทราบเหตุผล | O10: 0
A11: 9 | N11: ของเคลม Shopee เนื่องจากลูกค้าได้รับสินค้าไม่ครบ | O11: 0
A12: 10 | N12: ของเคลม Shopee เนื่องจากลูกค้าได้รับสินค้าผิดไม่ตรงตามที่สั่ง | O12: 0
A13: 11 | N13: ของเคลม Shopee เนื่องจากลูกค้าไม่ได้รับสินค้า | O13: 0
A14: 12 | N14: ของเคลม Shopee เนื่องจากสินค้าเสียหายจากการขนส่ง | O14: 0
A15: 13 | N15: ของเคลม Shopee เนื่องจากสินค้าเน่าเสียก่อนวันหมดอายุที่แจ้งข้างกล่อง | O15: 0
A16: 14 | N16: ของเคลม Shopee เนื่องจากสินค้ามีรสชาติขม รสชาติ สีของขนม ผิดปกติ | O16: 0
A17: 15 | N17: ของเคลม Shopee เนื่องจากสินค้าไม่มี | O17: 0
... A56: 54 | N56: ไม่ทราบสาเหตุ | O56: 0
A57: 55 | O57: =SUM(O3:O56) -> 3
A58: 56
A59: 57
A60: 58
A61: 59
A62: 60
A63: 61
A64: 62
A65: 63 | Y65: -
A66: 64 | Y66: -
A67: 65 | Y67: -
A68: 66
A69: 67
A70: 68
A71: 69
A72: 70
A73: 71
A74: 72
A75: 73
A76: 74 | Y76: -
A77: 75 | Y77: -
A78: 76 | Y78: -
...

Sheet พ.ย. ยกเลิก
A1: สรุปรายการยกเลิกออเดอร์ ที่ออกเลขที่ออเดอร์แล้ว (เนื่องจากลูกค้าเอฟในไลฟ์สดแล้วไม่ยืนยันออเดอร์) เดือนพฤศจิกายน 2568
A2: ลำดับ | B2: เลขที่ออเดอร์ | C2: ชื่อ | D2: ช่องทางติดต่อ | E2: ชื่อตามช่องทางติดต่อ | F2: ขนส่ง | G2: วันที่สร้าง | H2: ยอดขาย | I2: หมายเหตุ
A3: 1
A4: 2
A5: 3
A6: 4
A7: 5
A8: 6
A9: 7
A10: 8
A11: 9
A12: 10
A13: 11
A14: 12
... A29: 27
A30: 28 | M30: 0 | N30: 900801206010597
A31: 29 | M31: 0 | N31: 906815728009721
A32: 30 | M32: 0 | N32: 579242639958051041
A33: 31 | M33: 0 | N33: 579242905526438911
A34: 32 | M34: 0 | N34: 579243224466492155
A35: 33 | M35: 0 | N35: 579243224846732027
A36: 34 | M36: 0 | N36: 579243248210118704
A37: 35 | M37: 0 | N37: 901053020741847
A38: 36
A39: 37
A40: 38
A41: 39
A42: 40
A43: 41
A44: 42
A45: 43
A46: 44
A47: 45
A48: 46
A49: 47
A50: 48
G51: ยอดรวม | H51: =SUM(H3:H50) -> 0 | I51: บาท

Sheet ต.ค. เคลม
A1: สรุปรายการส่งของเคลมสินค้า เดือนตุลาคม 2568 | I1: รวมยอดเสียหายค่าขนส่งเพิ่มเติม | J1: =SUBTOTAL(9,J3:J5) -> 135 | K1: บาท
A2: ลำดับ | B2: เลขที่ออเดอร์ | C2: ชื่อ | D2: ช่องทางติดต่อ | E2: ชื่อตามช่องทางติดต่อ | F2: ขนส่ง | G2: วันที่สร้าง | H2: ยอดขาย | I2: เลขพัสดุ | J2: ค่าขนส่ง | K2: หมายเหตุ | L2: หมายเหตุ | N2: รายการ | O2: จำนวนออเดอร์
A3: 1 | B3: FWP50 | C3: เกสร ฟักสกุล | D3: facebook | F3: EMS | G3: 02/10/2025 08:21 | H3: 0 | I3: WB010814469TH | J3: 45 | K3: ของเคลม Tiktok เนื่องจากลูกค้าได้รับสินค้าไม่ครบ | L3: เคลม tiktok หมายเลขคำสั่งซื้อ : 580486292627359126 | N3: ของเคลม LAZADA เนื่องจากลูกค้าได้รับสินค้าไม่ครบ | O3: 0
A4: 2 | B4: FWW99 | C4: นางสาวกุลิสรา ดาวกระจ่าง | D4: facebook | F4: EMS | G4: 04/10/2025 08:27 | H4: 0 | I4: WB011102725TH | J4: 45 | K4: ของเคลม Tiktok เนื่องจากลูกค้าได้รับสินค้าไม่ครบ | L4: **เคลมติ๊กต่อกคำสั่งซื้อ 580584770021000316 | N4: ของเคลม LAZADA เนื่องจากลูกค้าได้รับสินค้าผิดไม่ตรงตามที่สั่ง | O4: 0
A5: 3 | B5: FXF68 | C5: จันจิรา เทพนุกูล | D5: facebook | F5: EMS | G5: 06/10/2025 13:18 | H5: 0 | I5: WB011293716TH | J5: 45 | K5: ของเคลม Tiktok เนื่องจากลูกค้าได้รับสินค้าไม่ครบ | L5: *****เคลมติ๊กต่อกเลขออเดอร์: 580478328699586036 | N5: ของเคลม LAZADA เนื่องจากลูกค้าไม่ได้รับสินค้า | O5: 0
N6: ของเคลม LAZADA เนื่องจากสินค้าเสียหายจากการขนส่ง | O6: 0
N7: ของเคลม LAZADA เนื่องจากสินค้าเน่าเสียก่อนวันหมดอายุที่แจ้งข้างกล่อง | O7: 0
N8: ของเคลม LAZADA เนื่องจากสินค้ามีรสชาติขม รสชาติ สีของขนม ผิดปกติ | O8: 0
N9: ของเคลม LAZADA เนื่องจากสินค้าไม่มี | O9: 0
N10: ของเคลม LAZADA ไม่ทราบเหตุผล | O10: 0
N11: ของเคลม Shopee เนื่องจากลูกค้าได้รับสินค้าไม่ครบ | O11: 0
N12: ของเคลม Shopee เนื่องจากลูกค้าได้รับสินค้าผิดไม่ตรงตามที่สั่ง | O12: 0
N13: ของเคลม Shopee เนื่องจากลูกค้าไม่ได้รับสินค้า | O13: 0
N14: ของเคลม Shopee เนื่องจากสินค้าเสียหายจากการขนส่ง | O14: 0
N15: ของเคลม Shopee เนื่องจากสินค้าเน่าเสียก่อนวันหมดอายุที่แจ้งข้างกล่อง | O15: 0
N16: ของเคลม Shopee เนื่องจากสินค้ามีรสชาติขม รสชาติ สีของขนม ผิดปกติ | O16: 0
N17: ของเคลม Shopee เนื่องจากสินค้าไม่มี | O17: 0
... N56: ไม่ทราบสาเหตุ | O56: 0
O57: =SUM(O3:O56) -> 3
Y65: -
Y66: -
Y67: -
Y68: 915654159752305
Y69: -
Y70: -
Y71: -
Y72: -
Y73: -
Y74: 915772949752620
Y75: -
Y76: -
... Y95: -

Sheet ต.ค. ยกเลิก
A1: สรุปรายการยกเลิกออเดอร์ ที่ออกเลขที่ออเดอร์แล้ว (เนื่องจากลูกค้าเอฟในไลฟ์สดแล้วไม่ยืนยันออเดอร์) เดือนตุลาคม 2568
A2: ลำดับ | B2: เลขที่ออเดอร์ | C2: ชื่อ | D2: ช่องทางติดต่อ | E2: ชื่อตามช่องทางติดต่อ | F2: ขนส่ง | G2: วันที่สร้าง | H2: ยอดขาย | I2: หมายเหตุ
A3: 1
A4: 2
A5: 3
A6: 4
A7: 5
A8: 6
A9: 7
A10: 8
A11: 9
A12: 10
A13: 11
A14: 12
... A29: 27
A30: 28 | M30: 0 | N30: 900801206010597
A31: 29 | M31: 0 | N31: 906815728009721
A32: 30 | M32: 0 | N32: 579242639958051041
A33: 31 | M33: 0 | N33: 579242905526438911
A34: 32 | M34: 0 | N34: 579243224466492155
A35: 32 | M35: 0 | N35: 579243224846732027
A36: 32 | M36: 0 | N36: 579243248210118704
A37: 32 | M37: 0 | N37: 901053020741847
A38: 33
A39: 34
A40: 35
A41: 36
A42: 37
A43: 38
A44: 39
A45: 40
A46: 41
A47: 42
M54: 0 | N54: 901056403841847
M55: 0 | N55: 579244585222638440
M56: 112 | N56: 2408258PXV00HR
G58: ยอดรวม | H58: =SUM(H3:H57) -> 0 | I58: บาท

Sheet ก.ย. เคลม
A1: สรุปรายการส่งของเคลมสินค้า เดือนกันยายน 2568 | I1: รวมยอดเสียหายค่าขนส่งเพิ่มเติม | J1: =SUBTOTAL(9,J3:J10) -> 360 | K1: บาท
A2: ลำดับ | B2: เลขที่ออเดอร์ | C2: ชื่อ | D2: ช่องทางติดต่อ | E2: ชื่อตามช่องทางติดต่อ | F2: ขนส่ง | G2: วันที่สร้าง | H2: ยอดขาย | I2: เลขพัสดุ | J2: ค่าขนส่ง | K2: หมายเหตุ | L2: หมายเหตุ | N2: รายการ | O2: จำนวนออเดอร์
A3: 1 | B3: FTM90 | C3: กาญจณี พานนนท์ | D3: facebook | F3: EMS | G3: 06/09/2025 09:39 | H3: 0 | I3: JB341057895TH | J3: 45 | K3: ของเคลม TikTok เนื่องจากสินค้าเน่าเสียก่อนวันหมดอายุที่แจ้งข้างกล่อง | L3: เคลม tiktok หมายเลขคำสั่งซื้อ : 580100090685261487เนื่องจาก ขนมปังขึ้นราก่อนวันหมดอายุ | N3: ของเคลม LAZADA เนื่องจากลูกค้าได้รับสินค้าไม่ครบ | O3: 0
A4: 2 | B4: FTM92 | C4: น.ส.สุจินต์ นารอด | D4: facebook | F4: EMS | G4: 06/09/2025 09:40 | H4: 0 | I4: JB341057904TH | J4: 45 | K4: ของเคลม LAZADA เนื่องจากสินค้ามีรสชาติขม รสชาติ สีของขนม ผิดปกติ | L4: เคลม lazada หมายเลขคำสั่งซื้อ : 1040673311206033เนื่องจาก ขนมปังขึ้นราก่อนวันหมดอายุ | N4: ของเคลม LAZADA เนื่องจากลูกค้าได้รับสินค้าผิดไม่ตรงตามที่สั่ง | O4: 0
A5: 3 | B5: FTZ86 | C5: เรวัติ อินประสิทธิ์ | D5: facebook | F5: EMS | G5: 09/09/2025 13:48 | H5: 0 | I5: JB341395779TH | J5: 45 | K5: ของเคลม Shopee เนื่องจากสินค้าเน่าเสียก่อนวันหมดอายุที่แจ้งข้างกล่อง | L5: เคลม shopee หมายเลขคำสั่งซื้อ : 25092EGTDWU3Hเนื่องจาก ขึ้นราก่อนวันหมดอายุ | N5: ของเคลม LAZADA เนื่องจากลูกค้าไม่ได้รับสินค้า | O5: 0
A6: 4 | B6: FTZ95 | C6: สมถวิล. โป๊ะประนม | D6: facebook | F6: EMS | G6: 09/09/2025 14:11 | H6: 0 | I6: JB341395751TH | J6: 45 | K6: ของเคลม LAZADA เนื่องจากสินค้ามีรสชาติขม รสชาติ สีของขนม ผิดปกติ | L6: เคลม lazada1040668503644397,1034092490144397เนื่องจากขัึ้นราก่อนวันหมดอายุ | N6: ของเคลม LAZADA เนื่องจากสินค้าเสียหายจากการขนส่ง | O6: 0
A7: 5 | B7: FUA11 | C7: วัดถ้ำสหาย | D7: line_oa | E7: พุทโธ | F7: EMS | G7: 09/09/2025 14:44 | H7: 0 | I7: JB341395725TH | J7: 45 | K7: เคลมเนื่องจากส่งสินค้าผิด | L7: เคลมส่งของผิด | N7: ของเคลม LAZADA เนื่องจากสินค้าเน่าเสียก่อนวันหมดอายุที่แจ้งข้างกล่อง | O7: 3
A8: 6 | B8: FUC41 | C8: นางสาวศรวณีย์ ทุมโนน้อย | D8: facebook | F8: EMS | G8: 10/09/2025 13:29 | H8: 0 | I8: JB341511792TH | J8: 45 | K8: ของเคลม TikTok เนื่องจากสินค้าเน่าเสียก่อนวันหมดอายุที่แจ้งข้างกล่อง | L8: ช่องทางติ้กต่อก เลขออเดอร์ 580141956021584905**สินค้าขึ้นราก่อนวันหมดอายุ** | N8: ของเคลม LAZADA เนื่องจากสินค้ามีรสชาติขม รสชาติ สีของขนม ผิดปกติ | O8: 0
A9: 7 | B9: FUE71 | C9: ปริศนา โทแก้ว | D9: facebook | F9: EMS | G9: 11/09/2025 10:11 | H9: 0 | I9: JB341636038TH | J9: 45 | K9: ของเคลม LAZADA เนื่องจากสินค้ามีรสชาติขม รสชาติ สีของขนม ผิดปกติ | L9: เคลม lazada หมายเลขคำสั่งซื้อ : 1034801011400016เนื่องจากขึ้นราก่อนวันหมดอายุ | N9: ของเคลม LAZADA เนื่องจากสินค้าไม่มี | O9: 0
A10: 8 | B10: FVW11 | C10: พระวันชัย เฮงรวยบุญ | D10: facebook | F10: EMS | G10: 25/09/2025 11:59 | H10: 0 | I10: WB010444406TH | J10: 45 | K10: ของเคลม TikTok เนื่องจากสินค้าเน่าเสียก่อนวันหมดอายุที่แจ้งข้างกล่อง | L10: ***เคลมtiktokหมายเลขคำซื้อ 580453626340083661 | N10: ของเคลม LAZADA ไม่ทราบเหตุผล | O10: 0
N11: ของเคลม Shopee เนื่องจากลูกค้าได้รับสินค้าไม่ครบ | O11: 0
N12: ของเคลม Shopee เนื่องจากลูกค้าได้รับสินค้าผิดไม่ตรงตามที่สั่ง | O12: 0
N13: ของเคลม Shopee เนื่องจากลูกค้าไม่ได้รับสินค้า | O13: 0
N14: ของเคลม Shopee เนื่องจากสินค้าเสียหายจากการขนส่ง | O14: 0
N15: ของเคลม Shopee เนื่องจากสินค้าเน่าเสียก่อนวันหมดอายุที่แจ้งข้างกล่อง | O15: 1
N16: ของเคลม Shopee เนื่องจากสินค้ามีรสชาติขม รสชาติ สีของขนม ผิดปกติ | O16: 0
N17: ของเคลม Shopee เนื่องจากสินค้าไม่มี | O17: 0
N18: ของเคลม Shopee ไม่ทราบเหตุผล | O18: 0
N19: ของเคลม Line OA เนื่องจากลูกค้าได้รับสินค้าไม่ครบ | O19: 0
N20: ของเคลม Line OA เนื่องจากลูกค้าได้รับสินค้าผิดไม่ตรงตามที่สั่ง | O20: 0
N21: ของเคลม Line OA เนื่องจากลูกค้าไม่ได้รับสินค้า | O21: 0
N22: ของเคลม Line OA เนื่องจากสินค้าเสียหายจากการขนส่ง | O22: 0
... N56: ไม่ทราบสาเหตุ | O56: 0
O57: =SUM(O3:O56) -> 8
Z65: -
Z66: -
Z67: -
Z68: 915654159752305
Z69: -
Z70: -
Z71: -
Z72: -
Z73: -
Z74: 915772949752620
Z75: -
Z76: -
... Z95: -

Sheet ก.ย. ยกเลิก
A1: สรุปรายการยกเลิกออเดอร์ ที่ออกเลขที่ออเดอร์แล้ว (เนื่องจากลูกค้าเอฟในไลฟ์สดแล้วไม่ยืนยันออเดอร์) เดือนกันยายน 2568
A2: ลำดับ | B2: เลขที่ออเดอร์ | C2: ชื่อ | D2: ช่องทางติดต่อ | E2: ชื่อตามช่องทางติดต่อ | F2: ขนส่ง | G2: วันที่สร้าง | H2: ยอดขาย | I2: หมายเหตุ
A3: 1 | B3: FWH8 | C3: สุวรรณา ชินวงษเกตุ | D3: Lazada | F3: Kerry_dropoff | G3: 29/09/2025 15:10 | H3: 83 | I3: สรุปออเดอร์แล้ว ลูกค้ายกเลิก
G4: ยอดรวม | H4: 83 | I4: บาท
M30: 0 | N30: 900801206010597
M31: 0 | N31: 906815728009721
M32: 0 | N32: 579242639958051041
M33: 0 | N33: 579242905526438911
M34: 0 | N34: 579243224466492155
L35: 0 | M35: 579243224846732027
L36: 0 | M36: 579243248210118704

Sheet ส.ค. เคลม
A1: สรุปรายการส่งของเคลมสินค้า เดือนสิงหาคม 2568 | I1: รวมยอดเสียหายค่าขนส่งเพิ่มเติม | J1: =SUBTOTAL(9,J3:J12) -> 450 | K1: บาท
A2: ลำดับ | B2: เลขที่ออเดอร์ | C2: ชื่อ | D2: ช่องทางติดต่อ | E2: ชื่อตามช่องทางติดต่อ | F2: ขนส่ง | G2: วันที่สร้าง | H2: ยอดขาย | I2: เลขพัสดุ | J2: ค่าขนส่ง | K2: หมายเหตุ | L2: หมายเหตุ | N2: รายการ | O2: จำนวนออเดอร์
A3: 1 | B3: FQL85 | C3: ชนัญญา. คนึงเหตุ | D3: facebook | F3: EMS | G3: 01/08/2025 08:45 | H3: 0 | I3: JB294211029TH | J3: 45 | K3: ของเคลม ตัวแทนเส้น | L3: เคลม บิลเส้น ส่งของขาด | N3: ของเคลม LAZADA เนื่องจากลูกค้าได้รับสินค้าไม่ครบ | O3: 0
A4: 2 | B4: FQP57 | C4: ประทุม บูรณารมย์ | D4: facebook | F4: EMS | G4: 04/08/2025 08:53 | H4: 0 | I4: JB294683111TH | J4: 45 | K4: ของเคลม Tiktok เนื่องจากสินค้ามีรสชาติขม รสชาติ สีของขนม ผิดปกติ | L4: เคลม TIKTOK หมายเลขคำสั่งซื้อ : 579664450951546095เนื่องจากสินค้า ที่เป็นครีมฮอร์นของทางร้าน ผลิตไม่ทันจึงทำให้การจัดส่งออเดอร์ไม่ครบถ้วน จึงเคลมสินค้าตัวแื่นให้คุณลูกค้าแทน | N4: ของเคลม LAZADA เนื่องจากลูกค้าได้รับสินค้าผิดไม่ตรงตามที่สั่ง | O4: 0
A5: 3 | B5: FRA39 | C5: กิตติมา ฮวดวิเศษ | D5: facebook | F5: EMS | G5: 08/08/2025 14:12 | H5: 0 | I5: JB337938037TH | J5: 45 | K5: ของเคลม Shopee เนื่องจากสินค้าเน่าเสียก่อนวันหมดอายุที่แจ้งข้างกล่อง | L5: เคลม ช้อปปี้ เลขออเดอร์ 250729DB72FBYD**สินค้าขึ้นราก่อนหมดอายุ** | N5: ของเคลม LAZADA เนื่องจากลูกค้าไม่ได้รับสินค้า | O5: 0
A6: 4 | B6: FRH84 | C6: สุริตา หนูกลับ | D6: facebook | F6: EMS | G6: 13/08/2025 09:02 | H6: 0 | I6: JB338407769TH | J6: 45 | K6: ของเคลม Shopee เนื่องจากลูกค้าได้รับสินค้าผิดไม่ตรงตามที่สั่ง | L6: เคลม Shopee (1)50801N7QD5D1Sเนื่องจากสินค้าขึ้นราก่อนวันหมดอายุ 50804UEFHQCS2 เนื่องจากขนมปังมีกลิ่นเปรี้ยว ก่อนวันหมดอายุ | N6: ของเคลม LAZADA เนื่องจากสินค้าเสียหายจากการขนส่ง | O6: 0
A7: 5 | B7: FRI6 | C7: คุณสมชาย ฉาบเชย | D7: facebook | F7: EMS | G7: 13/08/2025 10:20 | H7: 0 | I7: JB338407786TH | J7: 45 | K7: ของเคลม Shopee เนื่องจากสินค้าเน่าเสียก่อนวันหมดอายุที่แจ้งข้างกล่อง | L7: เคลม LAZADA หมายเลขคำสั่งซื้อ : 103453793647678เนื่องจากขนมปังขึ้นราก่อนวันหมดอายุ | N7: ของเคลม LAZADA เนื่องจากสินค้าเน่าเสียก่อนวันหมดอายุที่แจ้งข้างกล่อง | O7: 0
A8: 6 | B8: FRP15 | C8: ปราณี ภาคสวรรค์ | D8: facebook | F8: EMS | G8: 17/08/2025 16:20 | H8: 0 | I8: JB338775556TH | J8: 45 | K8: ของเคลม ตัวแทนเส้น | L8: เคลมของเสีย ลูกค้าหน้าร้าน | N8: ของเคลม LAZADA เนื่องจากสินค้ามีรสชาติขม รสชาติ สีของขนม ผิดปกติ | O8: 0
A9: 7 | B9: FRR21 | C9: กนกลักษณ์ แจ้งกิจ | D9: facebook | F9: EMS | G9: 19/08/2025 08:42 | H9: 0 | I9: JB339022495TH | J9: 45 | K9: ของเคลม Shopee เนื่องจากสินค้าเน่าเสียก่อนวันหมดอายุที่แจ้งข้างกล่อง | L9: เคลม Shopee หมายเลขคำสั่งซื้อ : 250811FQPUKPDNขนมปังขึ้นราก่อนวันหมดอายุ | N9: ของเคลม LAZADA เนื่องจากสินค้าไม่มี | O9: 0
A10: 8 | B10: FRU19 | C10: กรแก้ว วิศวเวชเมธี | D10: facebook | F10: EMS | G10: 20/08/2025 11:48 | H10: 0 | I10: JB339141974TH | J10: 45 | K10: ของเคลม Shopee เนื่องจากลูกค้าได้รับสินค้าไม่ครบ | L10: เคลม Shopee หมายเลขคำสั่งซื้อ 25081848G1DMTC** ได้รับสินค้าไม่ครบ ** | N10: ของเคลม LAZADA ไม่ทราบเหตุผล | O10: 0
A11: 9 | B11: FSA52 | C11: พจนีย์ ชัยพานิช | D11: facebook | F11: EMS | G11: 22/08/2025 13:19 | H11: 0 | I11: JB339354740TH | J11: 45 | K11: ของเคลม Shopee เนื่องจากลูกค้าได้รับสินค้าผิดไม่ตรงตามที่สั่ง | L11: เคลม Shopee เลขออเดอร์ 250809AT2U5FGE** สินค้าในกล่องมีแค่ 2 รส ** | N11: ของเคลม Shopee เนื่องจากลูกค้าได้รับสินค้าไม่ครบ | O11: 1
A12: 10 | B12: FSJ72 | C12: เคลม TIKTOK | D12: facebook | F12: EMS | G12: 27/08/2025 08:36 | H12: 0 | I12: JB339921618TH | J12: 45 | K12: ของเคลม Tiktok เนื่องจากสินค้ามีรสชาติขม รสชาติ สีของขนม ผิดปกติ | L12: เคลม TIKTOK หมายเลขคำสั่งซื้อ : 580085332761216238เนื่องจากซีนไม่ดี ทำให้มดขึ้นในขนม | N12: ของเคลม Shopee เนื่องจากลูกค้าได้รับสินค้าผิดไม่ตรงตามที่สั่ง | O12: 2
N13: ของเคลม Shopee เนื่องจากลูกค้าไม่ได้รับสินค้า | O13: 0
N14: ของเคลม Shopee เนื่องจากสินค้าเสียหายจากการขนส่ง | O14: 0
N15: ของเคลม Shopee เนื่องจากสินค้าเน่าเสียก่อนวันหมดอายุที่แจ้งข้างกล่อง | O15: 3
N16: ของเคลม Shopee เนื่องจากสินค้ามีรสชาติขม รสชาติ สีของขนม ผิดปกติ | O16: 2
N17: ของเคลม Shopee เนื่องจากสินค้าไม่มี | O17: 0
N18: ของเคลม Shopee ไม่ทราบเหตุผล | O18: 0
N19: ของเคลม Line OA เนื่องจากลูกค้าได้รับสินค้าไม่ครบ | O19: 0
N20: ของเคลม Line OA เนื่องจากลูกค้าได้รับสินค้าผิดไม่ตรงตามที่สั่ง | O20: 0
N21: ของเคลม Line OA เนื่องจากลูกค้าไม่ได้รับสินค้า | O21: 0
N22: ของเคลม Line OA เนื่องจากสินค้าเสียหายจากการขนส่ง | O22: 0
N23: ของเคลม Line OA เนื่องจากสินค้าเน่าเสียก่อนวันหมดอายุที่แจ้งข้างกล่อง | O23: 0
N24: ของเคลม Line OA เนื่องจากสินค้ามีรสชาติขม รสชาติ สีของขนม ผิดปกติ | O24: 0
... N56: ไม่ทราบสาเหตุ | O56: 0
O57: =SUM(O3:O56) -> 10

Sheet ส.ค. ยกเลิก
A1: สรุปรายการยกเลิกออเดอร์ ที่ออกเลขที่ออเดอร์แล้ว (เนื่องจากลูกค้าเอฟในไลฟ์สดแล้วไม่ยืนยันออเดอร์) เดือนสิงหาคม 2568
A2: ลำดับ | B2: เลขที่ออเดอร์ | C2: ชื่อ | D2: ช่องทางติดต่อ | E2: ชื่อตามช่องทางติดต่อ | F2: ขนส่ง | G2: วันที่สร้าง | H2: ยอดขาย | I2: หมายเหตุ
A3: 1 | B3: FSS18 | C3: บังยูฮัน เลขที่ **, **********(อั้ม) | D3: Lazada | F3: Kerry_dropoff | G3: 30/08/2025 00:24 | H3: 261.8 | I3: สรุปออเดอร์แล้ว ลูกค้ายกเลิก
A4: 2 | B4: FSW19 | D4: Tiktok | E4: 7494202018835958588 | F4: Next-day delivery | G4: 31/08/2025 15:49 | H4: 100 | I4: สรุปออเดอร์แล้ว ลูกค้ายกเลิก
A5: 3 | B5: FSW39 | C5: นิรชร แสงรังสี | D5: Lazada | F5: Kerry_dropoff | G5: 31/08/2025 16:02 | H5: 68.6 | I5: สรุปออเดอร์แล้ว ลูกค้ายกเลิก
A6: 4 | B6: FSW78 | D6: Tiktok | E6: 7494027956654409254 | F6: Next-day delivery | G6: 31/08/2025 18:25 | H6: 100 | I6: สรุปออเดอร์แล้ว ลูกค้ายกเลิก
A7: 5 | B7: FSX16 | D7: Tiktok | E7: 7494037441075774952 | F7: Next-day delivery | G7: 31/08/2025 20:07 | H7: 100 | I7: สรุปออเดอร์แล้ว ลูกค้ายกเลิก
G8: ยอดรวม | H8: =SUM(H3:H7) -> 630.4 | I8: บาท
L30: 4 | M30: 0 | N30: 900801206010597
L31: 14 | M31: 0 | N31: 906815728009721
L32: 0 | M32: 0 | N32: 579242639958051041
L33: 45 | M33: 0 | N33: 579242905526438911
L34: 0 | M34: 0 | N34: 579243224466492155
L35: 29 | M35: 0 | N35: 579243224846732027
L36: 0 | M36: 0 | N36: 579243248210118704
L37: 5 | M37: 0 | N37: 901053020741847
L38: 5 | M38: 0 | N38: 901056403841847
L39: 0 | M39: 0 | N39: 579244585222638440
L40: 104 | M40: 112 | N40: 2408258PXV00HR

Sheet ก.ค. เคลม
A1: สรุปรายการส่งของเคลมสินค้า เดือนกรกฎาคม 2568 | I1: รวมยอดเสียหายค่าขนส่งเพิ่มเติม | J1: =SUBTOTAL(9,J3:J22) -> 900 | K1: บาท
A2: ลำดับ | B2: เลขที่ออเดอร์ | C2: ชื่อ | D2: ช่องทางติดต่อ | E2: ชื่อตามช่องทางติดต่อ | F2: ขนส่ง | G2: วันที่สร้าง | H2: ยอดขาย | I2: เลขพัสดุ | J2: ค่าขนส่ง | K2: หมายเหตุ | L2: หมายเหตุ | N2: รายการ | O2: จำนวนออเดอร์
A3: 1 | B3: FNQ87 | C3: ไพรัช ญาโนภาส | D3: facebook | E3: ลูกค้าเพื่อนคุณแม่ | F3: EMS | G3: 01/07/2025 08:56 | H3: 0 | I3: JB265877336TH | J3: 45 | K3: ของคุณแม่ส่งให้เพื่อน | N3: ของเคลม LAZADA เนื่องจากลูกค้าได้รับสินค้าไม่ครบ | O3: 0
A4: 2 | B4: FOP27 | C4: ธันยพร ประคำ | D4: facebook | F4: EMS | G4: 07/07/2025 11:18 | H4: 0 | I4: JB291765148TH | J4: 45 | K4: ของเคลม Tiktok เนื่องจากลูกค้าได้รับสินค้าไม่ครบ | N4: ของเคลม LAZADA เนื่องจากลูกค้าได้รับสินค้าผิดไม่ตรงตามที่สั่ง | O4: 0
A5: 3 | B5: FPG8 | C5: ธณัลฐิวรรธน์ | D5: facebook | F5: EMS | G5: 13/07/2025 08:31 | H5: 0 | I5: JB292321066TH | J5: 45 | K5: ของเคลม TikTok เนื่องจากสินค้าเน่าเสียก่อนวันหมดอายุที่แจ้งข้างกล่อง | N5: ของเคลม LAZADA เนื่องจากลูกค้าไม่ได้รับสินค้า | O5: 0
A6: 4 | B6: FPK30 | C6: ธนวรรณ เครือแป้น | D6: line_oa | E6: Tuck 91♾ | F6: EMS | G6: 14/07/2025 10:54 | H6: 0 | I6: JB292351385TH | J6: 45 | K6: ของเคลม ตัวแทนเส้น | N6: ของเคลม LAZADA เนื่องจากสินค้าเสียหายจากการขนส่ง | O6: 0
A7: 5 | B7: FPL94 | C7: น.ส.สุจินต์ นารอด | D7: facebook | F7: EMS | G7: 15/07/2025 08:51 | H7: 0 | I7: JB292555432TH | J7: 45 | K7: ของเคลม TikTok เนื่องจากสินค้าเน่าเสียก่อนวันหมดอายุที่แจ้งข้างกล่อง | N7: ของเคลม LAZADA เนื่องจากสินค้าเน่าเสียก่อนวันหมดอายุที่แจ้งข้างกล่อง | O7: 2
A8: 6 | B8: FPU1 | C8: วันเผด็จ อังคณา | D8: line_oa | E8: Sukanyar Angkana | F8: EMS | G8: 20/07/2025 11:50 | H8: 0 | I8: JB293031989TH | J8: 45 | K8: ของเคลม Tiktok เนื่องจากลูกค้าได้รับสินค้าไม่ครบ | N8: ของเคลม LAZADA เนื่องจากสินค้ามีรสชาติขม รสชาติ สีของขนม ผิดปกติ | O8: 0
A9: 7 | B9: FPU12 | C9: ปริศนา โทแก้ว | D9: facebook | F9: EMS | G9: 20/07/2025 13:33 | H9: 0 | I9: JB293031992TH | J9: 45 | K9: ของเคลม TikTok เนื่องจากสินค้าเน่าเสียก่อนวันหมดอายุที่แจ้งข้างกล่อง | N9: ของเคลม LAZADA เนื่องจากสินค้าไม่มี | O9: 0
A10: 8 | B10: FPU21 | C10: ยุพิน พันวา | D10: facebook | F10: EMS | G10: 20/07/2025 14:30 | H10: 0 | I10: JB293032009TH | J10: 45 | K10: ของเคลม Tiktok เนื่องจากลูกค้าได้รับสินค้าไม่ครบ | N10: ของเคลม LAZADA ไม่ทราบเหตุผล | O10: 0
A11: 9 | B11: FPU44 | C11: นิติญา | D11: facebook | F11: EMS | G11: 20/07/2025 15:43 | H11: 0 | I11: JB293031975TH | J11: 45 | K11: ของเคลม Tiktok เนื่องจากลูกค้าได้รับสินค้าไม่ครบ | N11: ของเคลม Shopee เนื่องจากลูกค้าได้รับสินค้าไม่ครบ | O11: 0
A12: 10 | B12: FPV33 | C12: นายพิศรุต เนตรคำ | D12: facebook | F12: EMS | G12: 21/07/2025 10:13 | H12: 0 | I12: JB293162247TH | J12: 45 | K12: ของเคลม Tiktok เนื่องจากลูกค้าได้รับสินค้าไม่ครบ | N12: ของเคลม Shopee เนื่องจากลูกค้าได้รับสินค้าผิดไม่ตรงตามที่สั่ง | O12: 0
A13: 11 | B13: FPV55 | C13: กรรณิการ์ ฉายเเก้ว | D13: facebook | F13: EMS | G13: 21/07/2025 13:31 | H13: 0 | I13: JB293162220TH | J13: 45 | K13: ของเคลม LAZADA เนื่องจากสินค้าเน่าเสียก่อนวันหมดอายุที่แจ้งข้างกล่อง | N13: ของเคลม Shopee เนื่องจากลูกค้าไม่ได้รับสินค้า | O13: 0
A14: 12 | B14: FPW55 | C14: สุวรรณา จอมทิพย์ | D14: facebook | F14: EMS | G14: 22/07/2025 08:48 | H14: 0 | I14: JB293265992TH | J14: 45 | K14: ของเคลม Tiktok เนื่องจากลูกค้าได้รับสินค้าไม่ครบ | N14: ของเคลม Shopee เนื่องจากสินค้าเสียหายจากการขนส่ง | O14: 0
A15: 13 | B15: FPW57 | C15: พิยดา ศิรินัย | D15: facebook | F15: EMS | G15: 22/07/2025 08:54 | H15: 0 | I15: JB293265989TH | J15: 45 | K15: ของเคลม Tiktok เนื่องจากลูกค้าได้รับสินค้าไม่ครบ | N15: ของเคลม Shopee เนื่องจากสินค้าเน่าเสียก่อนวันหมดอายุที่แจ้งข้างกล่อง | O15: 0
A16: 14 | B16: FPW60 | C16: K.เเบม | D16: facebook | F16: EMS | G16: 22/07/2025 08:57 | H16: 0 | I16: JB293265975TH | J16: 45 | K16: ของเคลม Tiktok เนื่องจากลูกค้าได้รับสินค้าไม่ครบ | N16: ของเคลม Shopee เนื่องจากสินค้ามีรสชาติขม รสชาติ สีของขนม ผิดปกติ | O16: 0
A17: 15 | B17: FPW62 | C17: นาย มงคล ประดิษฐจา | D17: facebook | F17: EMS | G17: 22/07/2025 08:58 | H17: 0 | I17: JB293265961TH | J17: 45 | K17: ของเคลม Tiktok เนื่องจากลูกค้าได้รับสินค้าไม่ครบ | N17: ของเคลม Shopee เนื่องจากสินค้าไม่มี | O17: 0
A18: 16 | B18: FPZ93 | C18: ไพรี | D18: facebook | F18: EMS | G18: 24/07/2025 08:24 | H18: 0 | I18: JB293486645TH | J18: 45 | K18: ของเคลม Tiktok เนื่องจากลูกค้าได้รับสินค้าไม่ครบ | N18: ของเคลม Shopee ไม่ทราบเหตุผล | O18: 0
A19: 17 | B19: FQC33 | C19: ครูบามิก พระปฏิภาณ จันทปัญโญ | D19: facebook | F19: EMS | G19: 25/07/2025 16:12 | H19: 0 | I19: JB293593397TH | J19: 45 | K19: ของเคลม Tiktok เนื่องจากลูกค้าได้รับสินค้าไม่ครบ | N19: ของเคลม Line OA เนื่องจากลูกค้าได้รับสินค้าไม่ครบ | O19: 0
A20: 18 | B20: FQC36 | C20: น.ส.อรอนงค์ ไชยศร | D20: line_oa | E20: W1750 | F20: EMS | G20: 25/07/2025 16:28 | H20: 0 | I20: JB293593383TH | J20: 45 | K20: เคลมลูกค้านัดรับ เส้น | N20: ของเคลม Line OA เนื่องจากลูกค้าได้รับสินค้าผิดไม่ตรงตามที่สั่ง | O20: 0
A21: 19 | B21: FQH58 | C21: คุณภรณ์พรรณ อิศรนาเวศ | D21: facebook | F21: EMS | G21: 29/07/2025 14:04 | H21: 0 | I21: JB293983698TH | J21: 45 | K21: ของเคลม Tiktok เนื่องจากลูกค้าได้รับสินค้าไม่ครบ | N21: ของเคลม Line OA เนื่องจากลูกค้าไม่ได้รับสินค้า | O21: 0
A22: 20 | B22: FQH59 | C22: น.ส.สุจินต์ นารอด | D22: facebook | F22: EMS | G22: 29/07/2025 14:05 | H22: 0 | I22: JB293983707TH | J22: 45 | K22: ของเคลม LAZADA เนื่องจากสินค้าเน่าเสียก่อนวันหมดอายุที่แจ้งข้างกล่อง | N22: ของเคลม Line OA เนื่องจากสินค้าเสียหายจากการขนส่ง | O22: 0
N23: ของเคลม Line OA เนื่องจากสินค้าเน่าเสียก่อนวันหมดอายุที่แจ้งข้างกล่อง | O23: 0
N24: ของเคลม Line OA เนื่องจากสินค้ามีรสชาติขม รสชาติ สีของขนม ผิดปกติ | O24: 0
N25: ของเคลม Line OA เนื่องจากสินค้าไม่มี | O25: 0
N26: ของเคลม Line OA ไม่ทราบเหตุผล | O26: 0
N27: ของเคลม Facebook , Facebook Live เนื่องจากลูกค้าได้รับสินค้าไม่ครบ | O27: 0
N28: ของเคลม Facebook , Facebook Live เนื่องจากลูกค้าได้รับสินค้าผิดไม่ตรงตามที่สั่ง | O28: 0
N29: ของเคลม Facebook , Facebook Live เนื่องจากลูกค้าไม่ได้รับสินค้า | O29: 0
N30: ของเคลม Facebook , Facebook Live เนื่องจากสินค้าเสียหายจากการขนส่ง | O30: 0
N31: ของเคลม Facebook , Facebook Live เนื่องจากสินค้าเน่าเสียก่อนวันหมดอายุที่แจ้งข้างกล่อง | O31: 0
N32: ของเคลม Facebook , Facebook Live เนื่องจากสินค้ามีรสชาติขม รสชาติ สีของขนม ผิดปกติ | O32: 0
N33: ของเคลม Facebook , Facebook Live เนื่องจากสินค้าไม่มี | O33: 0
N34: ของเคลม Facebook , Facebook Live ไม่ทราบเหตุผล | O34: 0
... N50: ของเคลม ไปรษณีย์ ไม่ทราบเหตุผล | O50: 0
N51: ของเคลม ตัวแทนเส้น | O51: 1 | U51: เนื่องจากของขาดไม่ครบ
N52: ของเคลม เนื่องจากสินค้ามีรสชาติไม่ปกติ (ขม) | O52: 0
N53: เคลมลูกค้านัดรับ เส้น | O53: 1 | T53: นื่องจากขนส่งซัพนอกไม่ได้ลงของให้ลูกค้า
N54: เคลมสินค้าเนื่องจากกล่องชำรุด เสียหาย | O54: 0
N55: เคลมเนื่องจากส่งสินค้าผิด | O55: 0
...

Sheet ก.ค. ยกเลิก
A1: สรุปรายการยกเลิกออเดอร์ ที่ออกเลขที่ออเดอร์แล้ว (เนื่องจากลูกค้าเอฟในไลฟ์สดแล้วไม่ยืนยันออเดอร์) เดือนกรกฎาคม 2568
A2: ลำดับ | B2: เลขที่ออเดอร์ | C2: ชื่อ | D2: ช่องทางติดต่อ | E2: ชื่อตามช่องทางติดต่อ | F2: ขนส่ง | G2: วันที่สร้าง | H2: ยอดขาย | I2: หมายเหตุ
A3: 1 | B3: FPL95 | C3: นิรชร แสงรังสี | D3: Lazada | F3: Kerry_dropoff | G3: 15/07/2025 08:52 | H3: 51.26 | I3: สรุปออเดอร์แล้ว ลูกค้ายกเลิก
A4: 2 | B4: FPL96 | C4: นิรชร แสงรังสี | D4: Lazada | F4: Kerry_dropoff | G4: 15/07/2025 08:53 | H4: 51.26 | I4: สรุปออเดอร์แล้ว ลูกค้ายกเลิก
A5: 3 | B5: FPL99 | C5: สุกัญญา พรหมณี | D5: Lazada | F5: Kerry_dropoff | G5: 15/07/2025 09:01 | H5: 137.33 | I5: สรุปออเดอร์แล้ว ลูกค้ายกเลิก
A6: 4 | B6: FPN28 | C6: เ******น | D6: Shopee | E6: ming_kewalin | G6: 15/07/2025 18:59 | H6: 100 | I6: สรุปออเดอร์แล้ว ลูกค้ายกเลิก
A7: 5 | B7: FQL59 | C7: นรัญ นรเศรษฐ์ | D7: Lazada | F7: Kerry_dropoff | G7: 31/07/2025 20:14 | H7: 239.75 | I7: สรุปออเดอร์แล้ว ลูกค้ายกเลิก
G8: ยอดรวม | H8: =SUM(H3:H7) -> 579.6 | I8: บาท

Sheet มิ.ย. เคลม
A1: สรุปรายการส่งของเคลมสินค้า เดือนมิถุนายน 2568 | I1: รวมยอดเสียหายค่าขนส่งเพิ่มเติม | J1: =SUBTOTAL(9,J3:J21) -> 495 | K1: บาท
A2: ลำดับ | B2: เลขที่ออเดอร์ | C2: ชื่อ | D2: ช่องทางติดต่อ | E2: ชื่อตามช่องทางติดต่อ | F2: ขนส่ง | G2: วันที่สร้าง | H2: ยอดขาย | I2: เลขพัสดุ | J2: ค่าขนส่ง | K2: หมายเหตุ | M2: รายการ | N2: จำนวนออเดอร์
A3: 1 | B3: FIT59 | C3: กิตติมา ฮวดวิเศษ | D3: facebook | F3: EMS | G3: 01/06/2025 12:33 | H3: 0 | I3: JB262860566TH | J3: 45 | K3: ของเคลม Shopee เนื่องจากสินค้ามีรสชาติขม รสชาติ สีของขนม ผิดปกติ | M3: ของเคลม LAZADA เนื่องจากลูกค้าได้รับสินค้าไม่ครบ | N3: 0
A4: 2 | B4: FIT57 | C4: จันทร์เพ็ญ เนตรวัน | D4: facebook | F4: EMS | G4: 01/06/2025 12:33 | H4: 0 | I4: JB262860570TH | J4: 45 | K4: ของเคลม Facebook , Facebook Live เนื่องจากสินค้าเสียหายจากการขนส่ง | M4: ของเคลม LAZADA เนื่องจากลูกค้าได้รับสินค้าผิดไม่ตรงตามที่สั่ง | N4: 0
A5: 3 | B5: FJG52 | C5: สมพร ปานสุข | D5: facebook | F5: EMS | G5: 04/06/2025 08:57 | H5: 0 | I5: JB263228758TH | J5: 45 | K5: ของเคลม Tiktok เนื่องจากสินค้ามีรสชาติขม รสชาติ สีของขนม ผิดปกติ | M5: ของเคลม LAZADA เนื่องจากลูกค้าไม่ได้รับสินค้า | N5: 0
A6: 4 | B6: FJG51 | C6: นายลภ คำวิเศษ | D6: facebook | F6: EMS | G6: 04/06/2025 08:57 | H6: 0 | I6: JB263228761TH | J6: 45 | K6: ของเคลม Tiktok เนื่องจากสินค้ามีรสชาติขม รสชาติ สีของขนม ผิดปกติ | M6: ของเคลม LAZADA เนื่องจากสินค้าเสียหายจากการขนส่ง | N6: 0
A7: 5 | B7: FJG75 | C7: สิราพร สุราฤทธิ์ | D7: facebook | F7: EMS | G7: 04/06/2025 09:52 | H7: 0 | I7: JB263231417TH | J7: 45 | K7: ของเคลม Tiktok เนื่องจากลูกค้าได้รับสินค้าไม่ครบ | M7: ของเคลม LAZADA เนื่องจากสินค้าเน่าเสียก่อนวันหมดอายุที่แจ้งข้างกล่อง | N7: 0
A8: 6 | B8: FJN49 | C8: K.หมวย ภัสสรา | D8: facebook | F8: EMS | G8: 05/06/2025 13:48 | H8: 0 | I8: JB263343869TH | J8: 45 | K8: ของเคลม Tiktok เนื่องจากลูกค้าได้รับสินค้าผิดไม่ตรงตามที่สั่ง | M8: ของเคลม LAZADA เนื่องจากสินค้ามีรสชาติขม รสชาติ สีของขนม ผิดปกติ | N8: 1
A9: 7 | B9: FJW6 | C9: น.ส.อรอนงค์ ไชยศร | D9: line_oa | E9: W1750 | F9: EMS | G9: 06/06/2025 18:35 | H9: 0 | I9: JB263451877TH | J9: 45 | K9: ของเคลม Line OA เนื่องจากลูกค้าได้รับสินค้าไม่ครบ | M9: ของเคลม LAZADA เนื่องจากสินค้าไม่มี | N9: 0
A10: 8 | B10: FJW22 | C10: กิตติมา | D10: facebook | F10: EMS | G10: 06/06/2025 19:08 | H10: 0 | I10: JB263451863TH | J10: 45 | K10: ของเคลม Shopee เนื่องจากสินค้ามีรสชาติขม รสชาติ สีของขนม ผิดปกติ | M10: ของเคลม LAZADA ไม่ทราบเหตุผล | N10: 0
A11: 9 | B11: FLI69 | C11: ศิริกฤติยา ศรีสุระ | D11: facebook | F11: EMS | G11: 15/06/2025 09:34 | H11: 0 | I11: JB264321391TH | J11: 45 | K11: ของเคลม Tiktok เนื่องจากลูกค้าได้รับสินค้าไม่ครบ | M11: ของเคลม Shopee เนื่องจากลูกค้าได้รับสินค้าไม่ครบ | N11: 0
A12: 10 | B12: FLJ49 | C12: K.ณัฐลภัส พาศประภัศร์ | D12: facebook | F12: EMS | G12: 15/06/2025 11:19 | H12: 0 | I12: JB264321357TH | J12: 45 | K12: ของเคลม Line OA เนื่องจากสินค้ามีรสชาติขม รสชาติ สีของขนม ผิดปกติ | M12: ของเคลม Shopee เนื่องจากลูกค้าได้รับสินค้าผิดไม่ตรงตามที่สั่ง | N12: 0
A13: 11 | B13: FLU96 | C13: เกศสิรินทร์ ออลทรี | D13: facebook | F13: EMS | G13: 19/06/2025 11:53 | H13: 0 | I13: JB264778487TH | J13: 45 | K13: ของเคลม Shopee เนื่องจากสินค้าเสียหายจากการขนส่ง | M13: ของเคลม Shopee เนื่องจากลูกค้าไม่ได้รับสินค้า | N13: 0
A14: 12 | B14: FLX23 | C14: ปนัดดา | D14: facebook | F14: EMS | G14: 20/06/2025 15:53 | H14: 0 | I14: JB264879097TH | J14: 45 | K14: ของเคลม Shopee เนื่องจากสินค้ามีรสชาติขม รสชาติ สีของขนม ผิดปกติ | M14: ของเคลม Shopee เนื่องจากสินค้าเสียหายจากการขนส่ง | N14: 1
A15: 13 | B15: FMD62 | C15: น.ส ชลดา โคลนกระโทก | D15: facebook | F15: EMS | G15: 22/06/2025 11:49 | H15: 0 | I15: JB265021861TH | J15: 45 | K15: ของเคลม TikTok เนื่องจากสินค้าเสียหายจากการขนส่ง | M15: ของเคลม Shopee เนื่องจากสินค้าเน่าเสียก่อนวันหมดอายุที่แจ้งข้างกล่อง | N15: 0
A16: 14 | B16: FMO50 | C16: วาสนา พรมสุพัฒน์ | D16: facebook | F16: EMS | G16: 24/06/2025 15:26 | H16: 0 | I16: JB265260668TH | J16: 45 | K16: ของเคลม Tiktok เนื่องจากสินค้ามีรสชาติขม รสชาติ สีของขนม ผิดปกติ | M16: ของเคลม Shopee เนื่องจากสินค้ามีรสชาติขม รสชาติ สีของขนม ผิดปกติ | N16: 5
A17: 15 | B17: FMX59 | C17: คุณรัตนา | D17: facebook | F17: EMS | G17: 26/06/2025 08:18 | H17: 0 | I17: JB265483268TH | J17: 45 | K17: ของเคลม LAZADA เนื่องจากสินค้ามีรสชาติขม รสชาติ สีของขนม ผิดปกติ | M17: ของเคลม Shopee เนื่องจากสินค้าไม่มี | N17: 0
A18: 16 | B18: FNB56 | C18: ชื่อผู้รับ ชมพู่ | D18: facebook | F18: EMS | G18: 27/06/2025 08:55 | H18: 0 | I18: JB265585899TH | J18: 45 | K18: ของเคลม Tiktok เนื่องจากสินค้ามีรสชาติขม รสชาติ สีของขนม ผิดปกติ | M18: ของเคลม Shopee ไม่ทราบเหตุผล | N18: 0
A19: 17 | B19: FNB62 | C19: กิตติมา ฮวดวิเศษ | D19: facebook | F19: EMS | G19: 27/06/2025 09:12 | H19: 0 | I19: JB265585885TH | J19: 45 | K19: ของเคลม Shopee เนื่องจากสินค้ามีรสชาติขม รสชาติ สีของขนม ผิดปกติ | M19: ของเคลม Line OA เนื่องจากลูกค้าได้รับสินค้าไม่ครบ | N19: 1
A20: 18 | B20: FNI2 | C20: หญิง | D20: facebook | F20: EMS | G20: 29/06/2025 09:26 | H20: ของเคลม | I20: JB265728782TH | J20: 45 | K20: ของเคลม Shopee เนื่องจากสินค้ามีรสชาติขม รสชาติ สีของขนม ผิดปกติ | M20: ของเคลม Line OA เนื่องจากลูกค้าได้รับสินค้าผิดไม่ตรงตามที่สั่ง | N20: 0
A21: 19 | B21: FNI4 | C21: พัชราภรณ์ ผ่องผา | D21: facebook | F21: EMS | G21: 29/06/2025 09:27 | H21: ของเคลม | I21: JB265728796TH | J21: 45 | K21: ของเคลม Tiktok เนื่องจากสินค้ามีรสชาติขม รสชาติ สีของขนม ผิดปกติ | M21: ของเคลม Line OA เนื่องจากลูกค้าไม่ได้รับสินค้า | N21: 0
M22: ของเคลม Line OA เนื่องจากสินค้าเสียหายจากการขนส่ง | N22: 0
M23: ของเคลม Line OA เนื่องจากสินค้าเน่าเสียก่อนวันหมดอายุที่แจ้งข้างกล่อง | N23: 0
M24: ของเคลม Line OA เนื่องจากสินค้ามีรสชาติขม รสชาติ สีของขนม ผิดปกติ | N24: 1
M25: ของเคลม Line OA เนื่องจากสินค้าไม่มี | N25: 0
M26: ของเคลม Line OA ไม่ทราบเหตุผล | N26: 0
M27: ของเคลม Facebook , Facebook Live เนื่องจากลูกค้าได้รับสินค้าไม่ครบ | N27: 0
M28: ของเคลม Facebook , Facebook Live เนื่องจากลูกค้าได้รับสินค้าผิดไม่ตรงตามที่สั่ง | N28: 0
M29: ของเคลม Facebook , Facebook Live เนื่องจากลูกค้าไม่ได้รับสินค้า | N29: 0
M30: ของเคลม Facebook , Facebook Live เนื่องจากสินค้าเสียหายจากการขนส่ง | N30: 1
M31: ของเคลม Facebook , Facebook Live เนื่องจากสินค้าเน่าเสียก่อนวันหมดอายุที่แจ้งข้างกล่อง | N31: 0
M32: ของเคลม Facebook , Facebook Live เนื่องจากสินค้ามีรสชาติขม รสชาติ สีของขนม ผิดปกติ | N32: 0
M33: ของเคลม Facebook , Facebook Live เนื่องจากสินค้าไม่มี | N33: 0
... M50: ของเคลม ไปรษณีย์ ไม่ทราบเหตุผล | N50: 0
M51: ของเคลม ตัวแทนเส้น | N51: 0 | T51: เนื่องจากของขาดไม่ครบ
M52: ของเคลม เนื่องจากสินค้ามีรสชาติไม่ปกติ (ขม) | N52: 0
M53: เคลมลูกค้านัดรับ เส้น | N53: 0 | S53: นื่องจากขนส่งซัพนอกไม่ได้ลงของให้ลูกค้า
M54: เคลมสินค้าเนื่องจากกล่องชำรุด เสียหาย | N54: 0
M55: เคลมเนื่องจากส่งสินค้าผิด | N55: 0
M56: ไม่ทราบสาเหตุ | N56: 0
...

Sheet มิ.ย. ยกเลิก
A1: สรุปรายการยกเลิกออเดอร์ ที่ออกเลขที่ออเดอร์แล้ว (เนื่องจากลูกค้าเอฟในไลฟ์สดแล้วไม่ยืนยันออเดอร์) เดือนมิถุนายน 2568
A2: ลำดับ | B2: เลขที่ออเดอร์ | C2: ชื่อ | D2: ช่องทางติดต่อ | E2: ชื่อตามช่องทางติดต่อ | F2: ขนส่ง | G2: วันที่สร้าง | H2: ยอดขาย | I2: หมายเหตุ
A3: 1 | B3: FJW67 | C3: มณี การพันทา | D3: Lazada | F3: Kerry_dropoff | G3: 06/06/2025 21:07 | H3: 220 | I3: สรุปออเดอร์แล้ว ลูกค้ายกเลิก
A4: 2 | B4: FKG86 | C4: ปรียารัตน์ ปะวาทัง | D4: Lazada | F4: Kerry_dropoff | G4: 08/06/2025 19:19 | H4: 177.43 | I4: สรุปออเดอร์แล้ว ลูกค้ายกเลิก
A5: 3 | B5: FKH60 | C5: เจริญขวัญ วงศ์วาณิชวัฒนา | D5: Lazada | F5: Kerry_dropoff | G5: 08/06/2025 22:36 | H5: 138 | I5: สรุปออเดอร์แล้ว ลูกค้ายกเลิก
A6: 4 | B6: FKK0 | C6: ส***ตรา | D6: Tiktok | E6: 7493996043997971573 | F6: J&T Express | G6: 09/06/2025 15:13 | H6: 180 | I6: สรุปออเดอร์แล้ว ลูกค้ายกเลิก
A7: 5 | B7: FJW67 | C7: มณี การพันทา | D7: Lazada | F7: Kerry_dropoff | G7: 06/06/2025 21:07 | H7: 220 | I7: สรุปออเดอร์แล้ว ลูกค้ายกเลิก
A8: 6 | B8: FKG86 | C8: ปรียารัตน์ ปะวาทัง | D8: Lazada | F8: Kerry_dropoff | G8: 08/06/2025 19:19 | H8: 177.43 | I8: สรุปออเดอร์แล้ว ลูกค้ายกเลิก
A9: 7 | B9: FKH60 | C9: เจริญขวัญ วงศ์วาณิชวัฒนา | D9: Lazada | F9: Kerry_dropoff | G9: 08/06/2025 22:36 | H9: 138 | I9: สรุปออเดอร์แล้ว ลูกค้ายกเลิก
A10: 8 | B10: FKK0 | C10: ส***ตรา | D10: Tiktok | E10: 7493996043997971573 | F10: J&T Express | G10: 09/06/2025 15:13 | H10: 180 | I10: สรุปออเดอร์แล้ว ลูกค้ายกเลิก
A11: 9 | B11: FNE30 | C11: นิรชร แสงรังสี | D11: Lazada | F11: Kerry_dropoff | G11: 27/06/2025 22:05 | H11: 484.11 | I11: สรุปออเดอร์แล้ว ลูกค้ายกเลิก
A12: 10 | B12: FNO33 | C12: ณ***ัย ผ***ข | D12: Tiktok | E12: 7495218315741727131 | F12: J&T Express | G12: 30/06/2025 16:22 | H12: 100 | I12: สรุปออเดอร์แล้ว ลูกค้ายกเลิก
A13: 11 | B13: FNO51 | C13: ณ******​ | D13: Shopee | E13: yyw3pe_j_y | G13: 30/06/2025 17:24 | H13: 95 | I13: สรุปออเดอร์แล้ว ลูกค้ายกเลิก
A14: 12 | B14: FNO88 | C14: ปารมี แสงรังสี | D14: Lazada | F14: Kerry_dropoff | G14: 30/06/2025 19:38 | H14: 16.09 | I14: สรุปออเดอร์แล้ว ลูกค้ายกเลิก
A15: 13 | B15: FNP45 | C15: O***o | D15: Tiktok | E15: 7495641246274324650 | F15: J&T Express | G15: 30/06/2025 23:44 | H15: 100 | I15: สรุปออเดอร์แล้ว ลูกค้ายกเลิก
A16: 14 | B16: FNO33 | C16: ณ***ัย ผ***ข | D16: Tiktok | E16: 7495218315741727131 | F16: J&T Express | G16: 30/06/2025 16:22 | H16: 100 | I16: สรุปออเดอร์แล้ว ลูกค้ายกเลิก
A17: 15 | B17: FNO51 | C17: ณ******​ | D17: Shopee | E17: yyw3pe_j_y | G17: 30/06/2025 17:24 | H17: 95 | I17: สรุปออเดอร์แล้ว ลูกค้ายกเลิก
A18: 16 | B18: FNO88 | C18: ปารมี แสงรังสี | D18: Lazada | F18: Kerry_dropoff | G18: 30/06/2025 19:38 | H18: 16.09 | I18: สรุปออเดอร์แล้ว ลูกค้ายกเลิก
A19: 17 | B19: FNP45 | C19: O***o | D19: Tiktok | E19: 7495641246274324650 | F19: J&T Express | G19: 30/06/2025 23:44 | H19: 100 | I19: สรุปออเดอร์แล้ว ลูกค้ายกเลิก
G20: ยอดรวม | H20: =SUM(H3:H19) -> 2537.15 | I20: บาท

Sheet พ.ค. เคลม
A1: สรุปรายการส่งของเคลมสินค้า เดือนพฤษภาคม 2568 | I1: รวมยอดเสียหายค่าขนส่งเพิ่มเติม | J1: =SUBTOTAL(9,J3:J7) -> 225 | K1: บาท
A2: ลำดับ | B2: เลขที่ออเดอร์ | C2: ชื่อ | D2: ช่องทางติดต่อ | E2: ชื่อตามช่องทางติดต่อ | F2: ขนส่ง | G2: วันที่สร้าง | H2: ยอดขาย | I2: เลขพัสดุ | J2: ค่าขนส่ง | K2: หมายเหตุ | M2: รายการ | N2: จำนวนออเดอร์
A3: 1 | B3: FCZ58 | C3: มณีรัตน์ พะวังสุข | D3: facebook | F3: EMS | G3: 04/05/2025 10:29 | H3: 0 | I3: JB218744910TH | J3: 45 | K3: ของเคลม Tiktok เนื่องจากลูกค้าได้รับสินค้าไม่ครบ | M3: ของเคลม LAZADA เนื่องจากลูกค้าได้รับสินค้าไม่ครบ | N3: 0
A4: 2 | B4: FCZ59 | C4: k jin | D4: facebook | F4: EMS | G4: 04/05/2025 10:31 | H4: 0 | I4: JB218744906TH | J4: 45 | K4: ของเคลม Shopee เนื่องจากสินค้ามีรสชาติขม รสชาติ สีของขนม ผิดปกติ | M4: ของเคลม LAZADA เนื่องจากลูกค้าได้รับสินค้าผิดไม่ตรงตามที่สั่ง | N4: 0
A5: 3 | B5: FFT90 | C5: เบนซ์ | D5: facebook | F5: EMS | G5: 14/05/2025 14:19 | H5: 0 | I5: JB219862762TH | J5: 45 | K5: ของเคลม TikTok เนื่องจากสินค้าเสียหายจากการขนส่ง | M5: ของเคลม LAZADA เนื่องจากลูกค้าไม่ได้รับสินค้า | N5: 0
A6: 4 | B6: FGH50 | C6: ศิริขวัญ | D6: siriployly | E6: ติ๊กต๊อก | F6: EMS | G6: 18/05/2025 08:32 | H6: 0 | I6: JB261380492TH | J6: 45 | K6: ของเคลม TikTok เนื่องจากสินค้าเสียหายจากการขนส่ง | M6: ของเคลม LAZADA เนื่องจากสินค้าเสียหายจากการขนส่ง | N6: 0
A7: 5 | B7: FGR98 | C7: ณัฏฐนิช แก้วรุ่งเรือง | D7: facebook | F7: EMS | G7: 20/05/2025 08:38 | H7: 0 | I7: JB261633395TH | J7: 45 | K7: ของเคลม Facebook , Facebook Live เนื่องจากสินค้าเน่าเสียก่อนวันหมดอายุที่แจ้งข้างกล่อง | M7: ของเคลม LAZADA เนื่องจากสินค้าเน่าเสียก่อนวันหมดอายุที่แจ้งข้างกล่อง | N7: 0
M8: ของเคลม LAZADA เนื่องจากสินค้ามีรสชาติขม รสชาติ สีของขนม ผิดปกติ | N8: 0
M9: ของเคลม LAZADA เนื่องจากสินค้าไม่มี | N9: 0
M10: ของเคลม LAZADA ไม่ทราบเหตุผล | N10: 0
M11: ของเคลม Shopee เนื่องจากลูกค้าได้รับสินค้าไม่ครบ | N11: 0
M12: ของเคลม Shopee เนื่องจากลูกค้าได้รับสินค้าผิดไม่ตรงตามที่สั่ง | N12: 0
M13: ของเคลม Shopee เนื่องจากลูกค้าไม่ได้รับสินค้า | N13: 0
M14: ของเคลม Shopee เนื่องจากสินค้าเสียหายจากการขนส่ง | N14: 0
M15: ของเคลม Shopee เนื่องจากสินค้าเน่าเสียก่อนวันหมดอายุที่แจ้งข้างกล่อง | N15: 0
M16: ของเคลม Shopee เนื่องจากสินค้ามีรสชาติขม รสชาติ สีของขนม ผิดปกติ | N16: 1
M17: ของเคลม Shopee เนื่องจากสินค้าไม่มี | N17: 0
M18: ของเคลม Shopee ไม่ทราบเหตุผล | N18: 0
M19: ของเคลม Line OA เนื่องจากลูกค้าได้รับสินค้าไม่ครบ | N19: 0
... M50: ของเคลม ไปรษณีย์ ไม่ทราบเหตุผล | N50: 0
M51: ของเคลม ตัวแทนเส้น | N51: 0 | T51: เนื่องจากของขาดไม่ครบ
M52: ของเคลม เนื่องจากสินค้ามีรสชาติไม่ปกติ (ขม) | N52: 0
M53: เคลมลูกค้านัดรับ เส้น | N53: 0 | S53: นื่องจากขนส่งซัพนอกไม่ได้ลงของให้ลูกค้า
M54: เคลมสินค้าเนื่องจากกล่องชำรุด เสียหาย | N54: 0
M55: เคลมเนื่องจากส่งสินค้าผิด | N55: 0
M56: ไม่ทราบสาเหตุ | N56: 0
N57: =SUM(N3:N56) -> 5

Sheet พ.ค. ยกเลิก
A1: สรุปรายการยกเลิกออเดอร์ ที่ออกเลขที่ออเดอร์แล้ว (เนื่องจากลูกค้าเอฟในไลฟ์สดแล้วไม่ยืนยันออเดอร์) เดือนพฤษภาคม 2568
A2: ลำดับ | B2: เลขที่ออเดอร์ | C2: ชื่อ | D2: ช่องทางติดต่อ | E2: ชื่อตามช่องทางติดต่อ | F2: ขนส่ง | G2: วันที่สร้าง | H2: ยอดขาย | I2: หมายเหตุ
A3: 1 | B3: FFW23 | C3: ปารมี แสงรังสี | D3: Lazada | F3: Kerry_dropoff | G3: 15/05/2025 00:41 | H3: 176.4 | I3: สรุปออเดอร์แล้ว ลูกค้ายกเลิก
A4: 2 | B4: FGA36 | C4: ช******ม | D4: Shopee | E4: ninzchanin | G4: 15/05/2025 21:59 | H4: 250 | I4: สรุปออเดอร์แล้ว ลูกค้ายกเลิก
A5: 3 | B5: FIJ96 | C5: คนึง จันทนะวรรธนะ | D5: Lazada | F5: Kerry_dropoff | G5: 30/05/2025 20:39 | H5: 136.08 | I5: สรุปออเดอร์แล้ว ลูกค้ายกเลิก
A6: 4 | B6: FIN26 | C6: น** อ***ัย ว***เอี่ยม | D6: Tiktok | E6: 7494009402206422396 | F6: J&T Express | G6: 31/05/2025 18:06 | H6: 145 | I6: สรุปออเดอร์แล้ว ลูกค้ายกเลิก
A7: 5 | B7: FIN48 | C7: จ*** | D7: Tiktok | E7: 7494083611572537108 | F7: J&T Express | G7: 31/05/2025 20:07 | H7: 300 | I7: สรุปออเดอร์แล้ว ลูกค้ายกเลิก
G8: ยอดรวม | H8: =SUM(H3:H7) -> 1007.48 | I8: บาท

Sheet เม.ย. เคลม
A1: สรุปรายการส่งของเคลมสินค้า เดือนเมษายน 2568 | I1: รวมยอดเสียหายค่าขนส่งเพิ่มเติม | J1: =SUBTOTAL(9,J3:J11) -> 315 | K1: บาท
A2: ลำดับ | B2: เลขที่ออเดอร์ | C2: ชื่อ | D2: ช่องทางติดต่อ | E2: ชื่อตามช่องทางติดต่อ | F2: ขนส่ง | G2: วันที่สร้าง | H2: ยอดขาย | I2: เลขพัสดุ | J2: ค่าขนส่ง | K2: หมายเหตุ | M2: รายการ | N2: จำนวนออเดอร์
A3: 1 | B3: EXA33 | C3: เกษร | D3: facebook | F3: EMS | G3: 05/04/2025 11:59 | H3: 0 | I3: TH090372HBVF8F | J3: 45 | K3: ของเคลม LAZADA เนื่องจากลูกค้าได้รับสินค้าไม่ครบ | M3: ของเคลม LAZADA เนื่องจากลูกค้าได้รับสินค้าไม่ครบ | N3: 1
A4: 2 | B4: EXM16 | C4: Tikky | D4: facebook | F4: EMS | G4: 08/04/2025 15:25 | H4: 0 | I4: JB216173976TH | J4: 45 | K4: ของเคลม LAZADA เนื่องจากสินค้าเน่าเสียก่อนวันหมดอายุที่แจ้งข้างกล่อง | M4: ของเคลม LAZADA เนื่องจากลูกค้าได้รับสินค้าผิดไม่ตรงตามที่สั่ง | N4: 0
A5: 3 | B5: EZN28 | C5: อุษา กองตุ้น | D5: line_oa | E5: Nui😊MCMXCI | F5: EMS | G5: 14/04/2025 14:47 | H5: 0 | I5: TH410673KC5F2K | J5: 45 | K5: ของเคลม Line OA ไม่ทราบเหตุผล | M5: ของเคลม LAZADA เนื่องจากลูกค้าไม่ได้รับสินค้า | N5: 0
A6: 4 | B6: EZX25 | C6: Panthong Khunkaew | D6: facebook | E6: Panthong Khunkaew | F6: EMS | G6: 15/04/2025 17:02 | H6: 0 | I6: TH371073PBGM3H | J6: 45 | K6: ของเคลม Tiktok เนื่องจากลูกค้าได้รับสินค้าไม่ครบ | M6: ของเคลม LAZADA เนื่องจากสินค้าเสียหายจากการขนส่ง | N6: 0
A7: 5 | B7: EZZ91 | C7: พัชราภรณ์ ผ่องผา | D7: facebook | F7: EMS | G7: 16/04/2025 11:52 | H7: 0 | I7: JB216744775TH | J7: 45 | K7: ของเคลม Tiktok เนื่องจากสินค้ามีรสชาติขม รสชาติ สีของขนม ผิดปกติ | M7: ของเคลม LAZADA เนื่องจากสินค้าเน่าเสียก่อนวันหมดอายุที่แจ้งข้างกล่อง | N7: 1
A8: 6 | B8: FAD8 | C8: อภิญญา อู่อรุณ | D8: facebook | F8: EMS | G8: 17/04/2025 08:20 | H8: 0 | I8: JB216877140TH | J8: 45 | K8: ของเคลม Tiktok เนื่องจากสินค้ามีรสชาติขม รสชาติ สีของขนม ผิดปกติ | M8: ของเคลม LAZADA เนื่องจากสินค้ามีรสชาติขม รสชาติ สีของขนม ผิดปกติ | N8: 0
A9: 7 | B9: FBU87 | C9: สุริตา หนูกลับ | D9: facebook | F9: EMS | G9: 27/04/2025 10:14 | H9: 0 | I9: JB217891412TH | J9: 45 | K9: ของเคลม Shopee เนื่องจากสินค้ามีรสชาติขม รสชาติ สีของขนม ผิดปกติ | M9: ของเคลม LAZADA เนื่องจากสินค้าไม่มี | N9: 0
A10: 8 | B10: FCH96 | C10: อุไรพร คงดำรงสกุล | D10: facebook | F10: EMS | G10: 30/04/2025 10:48 | H10: 0 | I10: JB218325674TH | J10: 45 | K10: ของเคลม Shopee เนื่องจากสินค้ามีรสชาติขม รสชาติ สีของขนม ผิดปกติ | M10: ของเคลม LAZADA ไม่ทราบเหตุผล | N10: 0
A11: 9 | B11: FCL5 | C11: สุริตา หนูกลับ | D11: facebook | F11: EMS | G11: 30/04/2025 16:17 | H11: 0 | I11: JB218325705TH | J11: 45 | K11: ของเคลม Shopee เนื่องจากสินค้ามีรสชาติขม รสชาติ สีของขนม ผิดปกติ | M11: ของเคลม Shopee เนื่องจากลูกค้าได้รับสินค้าไม่ครบ | N11: 0
M12: ของเคลม Shopee เนื่องจากลูกค้าได้รับสินค้าผิดไม่ตรงตามที่สั่ง | N12: 0
M13: ของเคลม Shopee เนื่องจากลูกค้าไม่ได้รับสินค้า | N13: 0
M14: ของเคลม Shopee เนื่องจากสินค้าเสียหายจากการขนส่ง | N14: 0
M15: ของเคลม Shopee เนื่องจากสินค้าเน่าเสียก่อนวันหมดอายุที่แจ้งข้างกล่อง | N15: 0
M16: ของเคลม Shopee เนื่องจากสินค้ามีรสชาติขม รสชาติ สีของขนม ผิดปกติ | N16: 3
M17: ของเคลม Shopee เนื่องจากสินค้าไม่มี | N17: 0
M18: ของเคลม Shopee ไม่ทราบเหตุผล | N18: 0
M19: ของเคลม Line OA เนื่องจากลูกค้าได้รับสินค้าไม่ครบ | N19: 0
M20: ของเคลม Line OA เนื่องจากลูกค้าได้รับสินค้าผิดไม่ตรงตามที่สั่ง | N20: 0
M21: ของเคลม Line OA เนื่องจากลูกค้าไม่ได้รับสินค้า | N21: 0
M22: ของเคลม Line OA เนื่องจากสินค้าเสียหายจากการขนส่ง | N22: 0
M23: ของเคลม Line OA เนื่องจากสินค้าเน่าเสียก่อนวันหมดอายุที่แจ้งข้างกล่อง | N23: 0
... M56: ไม่ทราบสาเหตุ | N56: 0
N57: =SUM(N3:N56) -> 9

Sheet เม.ย. ยกเลิก
A1: สรุปรายการยกเลิกออเดอร์ ที่ออกเลขที่ออเดอร์แล้ว (เนื่องจากลูกค้าเอฟในไลฟ์สดแล้วไม่ยืนยันออเดอร์) เดือนเมษายน 2568
A2: ลำดับ | B2: เลขที่ออเดอร์ | C2: ชื่อ | D2: ช่องทางติดต่อ | E2: ชื่อตามช่องทางติดต่อ | F2: ขนส่ง | G2: วันที่สร้าง | H2: ยอดขาย | I2: หมายเหตุ
A3: 1 | B3: EWQ89 | C3: น***มกริช ก***ชา | D3: Tiktok | E3: 7494506645064288960 | F3: J&T Express | G3: 02/04/2025 16:18 | H3: 239 | I3: สรุปออเดอร์แล้ว ลูกค้ายกเลิก
A4: 2 | B4: EWQ90 | C4: น***มกริช ก***ชา | D4: Tiktok | E4: 7494506645064288960 | F4: J&T Express | G4: 02/04/2025 16:21 | H4: 200 | I4: สรุปออเดอร์แล้ว ลูกค้ายกเลิก
A5: 3 | B5: EWR3 | C5: W***ida K***it | D5: Tiktok | E5: 7494016996956407718 | F5: J&T Express | G5: 02/04/2025 17:00 | H5: 300 | I5: สรุปออเดอร์แล้ว ลูกค้ายกเลิก
A6: 4 | B6: EWR24 | C6: จ***รัตน์ แ***มงคล | D6: Tiktok | E6: 7494015518347527800 | F6: J&T Express | G6: 02/04/2025 18:12 | H6: 145 | I6: สรุปออเดอร์แล้ว ลูกค้ายกเลิก
A7: 5 | B7: EXH81 | C7: ก***ิพย์ ข***ริญ | D7: Tiktok | E7: 7494052008295368134 | F7: J&T Express | G7: 07/04/2025 13:47 | H7: 200 | I7: สรุปออเดอร์แล้ว ลูกค้ายกเลิก
A8: 6 | B8: EXI25 | C8: อ******ฐ | D8: Shopee | E8: birdadministation | G8: 07/04/2025 15:06 | H8: 81 | I8: สรุปออเดอร์แล้ว ลูกค้ายกเลิก
A9: 7 | B9: EXI47 | C9: น** ต***้าว ก***ิลาภ | D9: Tiktok | E9: 7494009310987715836 | F9: J&T Express | G9: 07/04/2025 15:38 | H9: 106 | I9: สรุปออเดอร์แล้ว ลูกค้ายกเลิก
A10: 8 | B10: EXJ42 | C10: พ***าภรณ์ ผ***ผา | D10: Tiktok | E10: 7494020776509277718 | F10: J&T Express | G10: 07/04/2025 21:29 | H10: 552 | I10: สรุปออเดอร์แล้ว ลูกค้ายกเลิก
A11: 9 | B11: FAQ5 | C11: ณ***ร ช***มวัน | D11: Tiktok | E11: 7495220980313000013 | F11: J&T Express | G11: 19/04/2025 23:07 | H11: 106 | I11: สรุปออเดอร์แล้ว ลูกค้ายกเลิก
A12: 10 | B12: FBX28 | C12: ศศิธร ควรพจน์ | D12: Lazada | F12: Kerry_dropoff | G12: 27/04/2025 21:21 | H12: 182.04 | I12: สรุปออเดอร์แล้ว ลูกค้ายกเลิก
A13: 11 | B13: FBY84 | C13: นิรชร แสงรังสี | D13: Lazada | F13: Kerry_dropoff | G13: 28/04/2025 12:53 | H13: 68.35 | I13: สรุปออเดอร์แล้ว ลูกค้ายกเลิก
