Workbook

Sheet สรุป 67
A1: สรุปอดเคลมออเดอร์ขายออนไลน์ ปี 2567
A2: เดือน | B2: เคลม | D2: ยกเลิก ( CF เล่น) | F2: หมายเหตุ
B3: จำนวน | C3: ค่าขนส่ง | D3: จำนวน | E3: ยอดเงิน
A4: ม.ค. | B4: 95 | C4: =+'ม.ค. เคลม'!J100 -> 1979.82 | D4: 73 | E4: =+'ม.ค. ยกเลิก'!H76 -> 23769.81
A5: ก.พ. | B5: 27 | C5: =+'ก.พ. เคลม'!J33 -> 799 | D5: 119 | E5: =+'ก.พ. ยกเลิก'!H122 -> 29400.33
A6: มี.ค. | B6: 12 | C6: =+'มี.ค. เคลม'!J78 -> 223 | D6: 105 | E6: =+'มี.ค. ยกเลิก'!H108 -> 18848.37
A7: เม.ย. | B7: 66 | C7: =+'เม.ย. เคลม'!J122 -> 1718 | D7: 130 | E7: =+'เม.ย. ยกเลิก'!H132 -> 22556.21
A8: พ.ค. | B8: 211 | C8: =+'พ.ค. เคลม'!J269 -> 4531 | D8: 111 | E8: =+'พ.ค. ยกเลิก'!H115 -> 20426.8
A9: มิ.ย. | B9: 143 | C9: =+'มิ.ย. เคลม'!J221 -> 1950 | D9: 109 | E9: =+'มิ.ย. ยกเลิก'!H132 -> 31551.87
A10: ก.ค. | B10: 107 | C10: =+'ก.ค. เคลม'!J124 -> 2046.09 | D10: 72 | E10: =+'ก.ค. ยกเลิก'!H75 -> 17879.8
A11: ส.ค. | B11: 79 | C11: =+'ส.ค. เคลม'!J126 -> 1343 | D11: 39 | E11: =+'ส.ค. ยกเลิก'!H42 -> 7981.36
A12: ก.ย. | B12: 68 | C12: 1394 | D12: 34 | E12: =+'ก.ย. ยกเลิก'!H37 -> 5043.65
A13: ต.ค. | B13: 182 | C13: =+'ต.ค. เคลม'!J186 -> 2010 | D13: 42 | E13: =+'ต.ค. ยกเลิก'!H58 -> 7350.06
A14: พ.ย. | B14: 132 | C14: =+'พ.ย. เคลม'!J149 -> 2482 | D14: 48 | E14: =+'พ.ย. ยกเลิก'!H51 -> 8379.03
A15: ธ.ค. | B15: 52 | C15: =+'ธ.ค. เคลม'!J55 -> 2116 | D15: 105 | E15: =+'ธ.ค. ยกเลิก'!H108 -> 25984.06
A16: ยอดรวม | B16: =SUM(B4:B15) -> 1174 | C16: =SUM(C4:C15) -> 22591.91 | D16: =SUM(D4:D15) -> 987 | E16: =SUM(E4:E15) -> 219171.35 | F16: บาท

Sheet สรุปสาเหตุเคลม
A1: สรุปสาเหตุการส่งเคลมจากแพลตฟอร์ม ปี 2567 | C1: Total | D1: ม.ค. | E1: ก.พ. | F1: มี.ค. | G1: เม.ย. | H1: พ.ค. | I1: มิ.ย. | J1: ก.ค. | K1: ส.ค. | L1: ก.ย. | M1: ต.ค. | N1: พ.ย. | O1: ธ.ค.
A2: สาเหตุส่งเคลม | B2: ผู้รับผิดชอบดูแล | C2: จำนวน | D2: จำนวนออเดอร์ | E2: จำนวนออเดอร์ | F2: จำนวนออเดอร์ | G2: จำนวนออเดอร์ | H2: จำนวนออเดอร์ | I2: จำนวนออเดอร์ | J2: จำนวนออเดอร์ | K2: จำนวนออเดอร์ | L2: จำนวนออเดอร์ | M2: จำนวนออเดอร์ | N2: จำนวนออเดอร์ | O2: จำนวนออเดอร์
A3: ของเคลม LAZADA เนื่องจากลูกค้าได้รับสินค้าไม่ครบ | B3: Packing | C3: =SUM(D3:O3) -> 124 | D3: =+'ม.ค. เคลม'!N3 -> 41 | E3: =+'ก.พ. เคลม'!N3 -> 8 | F3: =+'มี.ค. เคลม'!N3 -> 1 | G3: =+'เม.ย. เคลม'!N3 -> 10 | H3: =+'พ.ค. เคลม'!N3 -> 18 | I3: =+'มิ.ย. เคลม'!N3 -> 17 | J3: =+'ก.ค. เคลม'!O3 -> 14 | K3: =+'ส.ค. เคลม'!O3 -> 3 | L3: =+'ก.ย. เคลม'!O3 -> 1 | M3: =+'ต.ค. เคลม'!O3 -> 2 | N3: =+'พ.ย. เคลม'!O3 -> 0 | O3: =+'ธ.ค. เคลม'!O3 -> 9
A4: ของเคลม LAZADA เนื่องจากลูกค้าได้รับสินค้าผิดไม่ตรงตามที่สั่ง | B4: Packing / Online | C4: =SUM(D4:O4) -> 8 | D4: =+'ม.ค. เคลม'!N4 -> 3 | E4: =+'ก.พ. เคลม'!N4 -> 0 | F4: =+'มี.ค. เคลม'!N4 -> 0 | G4: =+'เม.ย. เคลม'!N4 -> 2 | H4: =+'พ.ค. เคลม'!N4 -> 1 | I4: =+'มิ.ย. เคลม'!N4 -> 0 | J4: =+'ก.ค. เคลม'!O4 -> 1 | K4: =+'ส.ค. เคลม'!O4 -> 1 | L4: =+'ก.ย. เคลม'!O4 -> 0 | M4: =+'ต.ค. เคลม'!O4 -> 0 | N4: =+'พ.ย. เคลม'!O4 -> 0 | O4: =+'ธ.ค. เคลม'!O4 -> 0
A5: ของเคลม LAZADA เนื่องจากลูกค้าไม่ได้รับสินค้า | B5: ขนส่ง | C5: =SUM(D5:O5) -> 5 | D5: =+'ม.ค. เคลม'!N5 -> 4 | E5: =+'ก.พ. เคลม'!N5 -> 1 | F5: =+'มี.ค. เคลม'!N5 -> 0 | G5: =+'เม.ย. เคลม'!N5 -> 0 | H5: =+'พ.ค. เคลม'!N5 -> 0 | I5: =+'มิ.ย. เคลม'!N5 -> 0 | J5: =+'ก.ค. เคลม'!O5 -> 0 | K5: =+'ส.ค. เคลม'!O5 -> 0 | L5: =+'ก.ย. เคลม'!O5 -> 0 | M5: =+'ต.ค. เคลม'!O5 -> 0 | N5: =+'พ.ย. เคลม'!O5 -> 0 | O5: =+'ธ.ค. เคลม'!O5 -> 0
A6: ของเคลม LAZADA เนื่องจากสินค้าเสียหายจากการขนส่ง | B6: ขนส่ง | C6: =SUM(D6:O6) -> 10 | D6: =+'ม.ค. เคลม'!N6 -> 1 | E6: =+'ก.พ. เคลม'!N6 -> 0 | F6: =+'มี.ค. เคลม'!N6 -> 0 | G6: =+'เม.ย. เคลม'!N6 -> 2 | H6: =+'พ.ค. เคลม'!N6 -> 0 | I6: =+'มิ.ย. เคลม'!N6 -> 0 | J6: =+'ก.ค. เคลม'!O6 -> 2 | K6: =+'ส.ค. เคลม'!O6 -> 0 | L6: =+'ก.ย. เคลม'!O6 -> 4 | M6: =+'ต.ค. เคลม'!O6 -> 0 | N6: =+'พ.ย. เคลม'!O6 -> 1 | O6: =+'ธ.ค. เคลม'!O6 -> 0
A7: ของเคลม LAZADA เนื่องจากสินค้าเน่าเสียก่อนวันหมดอายุที่แจ้งข้างกล่อง | B7: ฝ่ายผลิต | C7: =SUM(D7:O7) -> 17 | D7: =+'ม.ค. เคลม'!N7 -> 1 | E7: =+'ก.พ. เคลม'!N7 -> 0 | F7: =+'มี.ค. เคลม'!N7 -> 0 | G7: =+'เม.ย. เคลม'!N7 -> 4 | H7: =+'พ.ค. เคลม'!N7 -> 1 | I7: =+'มิ.ย. เคลม'!N7 -> 2 | J7: =+'ก.ค. เคลม'!O7 -> 5 | K7: =+'ส.ค. เคลม'!O7 -> 4 | L7: =+'ก.ย. เคลม'!O7 -> 0 | M7: =+'ต.ค. เคลม'!O7 -> 0 | N7: =+'พ.ย. เคลม'!O7 -> 0 | O7: =+'ธ.ค. เคลม'!O7 -> 0
A8: ของเคลม LAZADA เนื่องจากสินค้ามีรสชาติขม รสชาติ สีของขนม ผิดปกติ | B8: ฝ่ายผลิต | C8: =SUM(D8:O8) -> 1 | D8: =+'ม.ค. เคลม'!N8 -> 0 | E8: =+'ก.พ. เคลม'!N8 -> 0 | F8: =+'มี.ค. เคลม'!N8 -> 0 | G8: =+'เม.ย. เคลม'!N8 -> 0 | H8: =+'พ.ค. เคลม'!N8 -> 0 | I8: =+'มิ.ย. เคลม'!N8 -> 0 | J8: =+'ก.ค. เคลม'!O8 -> 0 | K8: =+'ส.ค. เคลม'!O8 -> 0 | L8: =+'ก.ย. เคลม'!O8 -> 0 | M8: =+'ต.ค. เคลม'!O8 -> 1 | N8: =+'พ.ย. เคลม'!O8 -> 0 | O8: =+'ธ.ค. เคลม'!O8 -> 0
A9: ของเคลม LAZADA เนื่องจากสินค้าไม่มี | B9: ฝ่ายผลิต | C9: =SUM(D9:O9) -> 72 | D9: =+'ม.ค. เคลม'!N9 -> 0 | E9: =+'ก.พ. เคลม'!N9 -> 0 | F9: =+'มี.ค. เคลม'!N9 -> 0 | G9: =+'เม.ย. เคลม'!N9 -> 16 | H9: =+'พ.ค. เคลม'!N9 -> 20 | I9: =+'มิ.ย. เคลม'!N9 -> 22 | J9: =+'ก.ค. เคลม'!O9 -> 1 | K9: =+'ส.ค. เคลม'!O9 -> 0 | L9: =+'ก.ย. เคลม'!O9 -> 0 | M9: =+'ต.ค. เคลม'!O9 -> 0 | N9: =+'พ.ย. เคลม'!O9 -> 0 | O9: =+'ธ.ค. เคลม'!O9 -> 13
A10: ของเคลม LAZADA ไม่ทราบเหตุผล | B10: Online | C10: =SUM(D10:O10) -> 629 | D10: =+'ม.ค. เคลม'!N10 -> 0 | E10: =+'ก.พ. เคลม'!N10 -> 0 | F10: =+'มี.ค. เคลม'!N10 -> 61 | G10: =+'เม.ย. เคลม'!N10 -> 53 | H10: =+'พ.ค. เคลม'!N10 -> 57 | I10: =+'มิ.ย. เคลม'!N10 -> 75 | J10: =+'ก.ค. เคลม'!O10 -> 8 | K10: =+'ส.ค. เคลม'!O10 -> 44 | L10: =+'ก.ย. เคลม'!O10 -> 53 | M10: =+'ต.ค. เคลม'!O10 -> 143 | N10: =+'พ.ย. เคลม'!O10 -> 128 | O10: =+'ธ.ค. เคลม'!O10 -> 7
A11: ของเคลม Shopee เนื่องจากลูกค้าได้รับสินค้าไม่ครบ | B11: Packing | C11: =SUM(D11:O11) -> 74 | D11: =+'ม.ค. เคลม'!N11 -> 3 | E11: =+'ก.พ. เคลม'!N11 -> 3 | F11: =+'มี.ค. เคลม'!N11 -> 0 | G11: =+'เม.ย. เคลม'!N11 -> 3 | H11: =+'พ.ค. เคลม'!N11 -> 6 | I11: =+'มิ.ย. เคลม'!N11 -> 10 | J11: =+'ก.ค. เคลม'!O11 -> 2 | K11: =+'ส.ค. เคลม'!O11 -> 18 | L11: =+'ก.ย. เคลม'!O11 -> 22 | M11: =+'ต.ค. เคลม'!O11 -> 6 | N11: =+'พ.ย. เคลม'!O11 -> 1 | O11: =+'ธ.ค. เคลม'!O11 -> 0
A12: ของเคลม Shopee เนื่องจากลูกค้าได้รับสินค้าผิดไม่ตรงตามที่สั่ง | B12: Packing / Online | C12: =SUM(D12:O12) -> 7 | D12: =+'ม.ค. เคลม'!N12 -> 1 | E12: =+'ก.พ. เคลม'!N12 -> 2 | F12: =+'มี.ค. เคลม'!N12 -> 0 | G12: =+'เม.ย. เคลม'!N12 -> 0 | H12: =+'พ.ค. เคลม'!N12 -> 0 | I12: =+'มิ.ย. เคลม'!N12 -> 2 | J12: =+'ก.ค. เคลม'!O12 -> 0 | K12: =+'ส.ค. เคลม'!O12 -> 1 | L12: =+'ก.ย. เคลม'!O12 -> 1 | M12: =+'ต.ค. เคลม'!O12 -> 0 | N12: =+'พ.ย. เคลม'!O12 -> 0 | O12: =+'ธ.ค. เคลม'!O12 -> 0
A13: ของเคลม Shopee เนื่องจากลูกค้าไม่ได้รับสินค้า | B13: ขนส่ง | C13: =SUM(D13:O13) -> 0 | D13: =+'ม.ค. เคลม'!N13 -> 0 | E13: =+'ก.พ. เคลม'!N13 -> 0 | F13: =+'มี.ค. เคลม'!N13 -> 0 | G13: =+'เม.ย. เคลม'!N13 -> 0 | H13: =+'พ.ค. เคลม'!N13 -> 0 | I13: =+'มิ.ย. เคลม'!N13 -> 0 | J13: =+'ก.ค. เคลม'!O13 -> 0 | K13: =+'ส.ค. เคลม'!O13 -> 0 | L13: =+'ก.ย. เคลม'!O13 -> 0 | M13: =+'ต.ค. เคลม'!O13 -> 0 | N13: =+'พ.ย. เคลม'!O13 -> 0 | O13: =+'ธ.ค. เคลม'!O13 -> 0
A14: ของเคลม Shopee เนื่องจากสินค้าเสียหายจากการขนส่ง | B14: ขนส่ง | C14: =SUM(D14:O14) -> 7 | D14: =+'ม.ค. เคลม'!N14 -> 1 | E14: =+'ก.พ. เคลม'!N14 -> 0 | F14: =+'มี.ค. เคลม'!N14 -> 0 | G14: =+'เม.ย. เคลม'!N14 -> 0 | H14: =+'พ.ค. เคลม'!N14 -> 0 | I14: =+'มิ.ย. เคลม'!N14 -> 0 | J14: =+'ก.ค. เคลม'!O14 -> 1 | K14: =+'ส.ค. เคลม'!O14 -> 2 | L14: =+'ก.ย. เคลม'!O14 -> 2 | M14: =+'ต.ค. เคลม'!O14 -> 0 | N14: =+'พ.ย. เคลม'!O14 -> 0 | O14: =+'ธ.ค. เคลม'!O14 -> 1
... A56: ไม่ทราบสาเหตุ | B56: Online | C56: =SUM(D56:O56) -> 13 | D56: =+'ม.ค. เคลม'!N56 -> 1 | E56: =+'ก.พ. เคลม'!N56 -> 2 | F56: =+'มี.ค. เคลม'!N56 -> 1 | G56: =+'เม.ย. เคลม'!N56 -> 0 | H56: =+'พ.ค. เคลม'!N56 -> 0 | I56: =+'มิ.ย. เคลม'!N56 -> 5 | J56: =+'ก.ค. เคลม'!O56 -> 4 | K56: =+'ส.ค. เคลม'!O56 -> 0 | L56: =+'ก.ย. เคลม'!O56 -> 0 | M56: =+'ต.ค. เคลม'!O56 -> 0 | N56: =+'พ.ย. เคลม'!O56 -> 0 | O56: =+'ธ.ค. เคลม'!O56 -> 0
C57: =SUM(C3:C56) -> 1543 | D57: =SUM(D3:D56) -> 96 | E57: =SUM(E3:E56) -> 29 | F57: =SUM(F3:F56) -> 75 | G57: =SUM(G3:G56) -> 119 | H57: =SUM(H3:H56) -> 262 | I57: =SUM(I3:I56) -> 218 | J57: =SUM(J3:J56) -> 121 | ... O57: =SUM(O3:O56) -> 52
D59: ไล่กรอกสาเหตุใหม่ เนื่องจากเดิมทำผิด

Sheet ธ.ค. เคลม
A1: สรุปรายการส่งของเคลมสินค้า เดือนธันวาคม 2567
A2: ลำดับ | B2: เลขที่ออเดอร์ | C2: ชื่อ | D2: ช่องทางติดต่อ | E2: ชื่อตามช่องทางติดต่อ | F2: ขนส่ง | G2: วันที่สร้าง | H2: ยอดขาย | I2: เลขพัสดุ | J2: ค่าขนส่ง | K2: หมายเหตุ | L2: หมายเหตุ | N2: รายการ | O2: จำนวนออเดอร์
A3: 1 | B3: EIB17 | D3: Lazchoice | E3: Lazchoice | F3: EMS | G3: 02/12/2024 09:03 | H3: 0 | I3: LBX024766814365390 | J3: 17 | K3: ของเคลม LAZADA ไม่ทราบเหตุผล | N3: ของเคลม LAZADA เนื่องจากลูกค้าได้รับสินค้าไม่ครบ | O3: 9
A4: 2 | B4: EIB24 | D4: Lazchoice | E4: Lazchoice | F4: EMS | G4: 02/12/2024 09:10 | H4: 0 | I4: LBX024766814360806 | J4: 17 | K4: ของเคลม LAZADA ไม่ทราบเหตุผล | N4: ของเคลม LAZADA เนื่องจากลูกค้าได้รับสินค้าผิดไม่ตรงตามที่สั่ง
A5: 3 | B5: EIC26 | D5: Lazchoice | E5: Lazchoice | F5: EMS | G5: 02/12/2024 11:23 | H5: 0 | I5: LEXPU0428190984 | J5: 17 | K5: ของเคลม LAZADA ไม่ทราบเหตุผล | N5: ของเคลม LAZADA เนื่องจากลูกค้าไม่ได้รับสินค้า
A6: 4 | B6: EIE1 | D6: Lazchoice | E6: Lazchoice | F6: EMS | G6: 02/12/2024 15:36 | H6: 0 | I6: LEXPU0428266659 | J6: 17 | K6: ของเคลม LAZADA ไม่ทราบเหตุผล | N6: ของเคลม LAZADA เนื่องจากสินค้าเสียหายจากการขนส่ง
A7: 5 | B7: EIE29 | D7: Lazchoice | E7: Lazchoice | F7: EMS | G7: 02/12/2024 16:22 | H7: 0 | I7: LBX024766814640921 | J7: 17 | K7: ของเคลม LAZADA ไม่ทราบเหตุผล | N7: ของเคลม LAZADA เนื่องจากสินค้าเน่าเสียก่อนวันหมดอายุที่แจ้งข้างกล่อง
A8: 6 | B8: EIG68 | D8: Lazchoice | E8: Lazchoice | F8: EMS | G8: 03/12/2024 09:07 | H8: 0 | I8: LEXPU0428559974 | J8: 17 | K8: ของเคลม LAZADA ไม่ทราบเหตุผล | N8: ของเคลม LAZADA เนื่องจากสินค้ามีรสชาติขม รสชาติ สีของขนม ผิดปกติ
A9: 7 | B9: EIG83 | D9: Lazchoice | E9: Lazchoice | F9: EMS | G9: 03/12/2024 09:15 | H9: 0 | I9: LEXPU0428560150 | J9: 17 | K9: ของเคลม LAZADA ไม่ทราบเหตุผล | N9: ของเคลม LAZADA เนื่องจากสินค้าไม่มี | O9: 13
A10: 8 | B10: EIU88 | C10: สุธิดา แก้วนุ่น | D10: facebook | F10: EMS | G10: 06/12/2024 10:44 | H10: 0 | I10: JB122045315TH | J10: 17 | K10: ของเคลม LAZADA เนื่องจากลูกค้าได้รับสินค้าไม่ครบ | L10: ลาซาด้า เลขออเดอร์ 943823476764458**ได้ของไม่ครบเพราะใบออเดอร์สลับ** | N10: ของเคลม LAZADA ไม่ทราบเหตุผล | O10: 7
A11: 9 | B11: EJD52 | C11: ปริศนา โทแก้ว | D11: facebook | F11: EMS | G11: 08/12/2024 13:57 | H11: 0 | I11: JB127573067TH | J11: 45 | K11: ของเคลม Shopee เนื่องจากสินค้าเสียหายจากการขนส่ง | L11: เคลมช้อปปี้ 241203U44YKXAY**สินค้าบี้เสียหาย** | N11: ของเคลม Shopee เนื่องจากลูกค้าได้รับสินค้าไม่ครบ
A12: 10 | B12: EJJ3 | C12: คุณ กนกพร แดงกุล | D12: line_oa | E12: สายสุนีย์ สายวารี | F12: EMS | G12: 09/12/2024 19:14 | H12: 0 | I12: JB127721211TH | J12: 45 | K12: ของเคลม TikTok เนื่องจากสินค้าเสียหายจากการขนส่ง | L12: เคลมเนื่องสินค้าลูกค้าเสียหายลูกค้าตต | N12: ของเคลม Shopee เนื่องจากลูกค้าได้รับสินค้าผิดไม่ตรงตามที่สั่ง
A13: 11 | B13: EJN52 | C13: วิธวิทย์ | D13: facebook | E13: Wit-Witthawit Panichsuay | F13: EMS | G13: 10/12/2024 16:11 | H13: 0 | I13: JB127829479TH | J13: 45 | K13: ของเคลม Facebook , Facebook Live เนื่องจากลูกค้าได้รับสินค้าไม่ครบ | L13: เคลมเนื่องจากลูกค้าได้ของไม่ครบ EJH54 จากเฟสหลัก | N13: ของเคลม Shopee เนื่องจากลูกค้าไม่ได้รับสินค้า
A14: 12 | B14: EJU24 | C14: ขนิษฐา แก้วสกุล | D14: facebook | E14: Khanittha Kaewsakul | F14: EMS | G14: 11/12/2024 17:40 | H14: 0 | I14: JB127961415TH | J14: 45 | K14: ของเคลม Facebook , Facebook Live เนื่องจากลูกค้าได้รับสินค้าไม่ครบ | L14: เคลิมเนื่องจากลูกค้าได้ของไม่ครบ EJH21 | N14: ของเคลม Shopee เนื่องจากสินค้าเสียหายจากการขนส่ง | O14: 1
A15: 13 | B15: EKT72 | C15: ตรีสุคนธ์ ชูประสิทธิ์ | D15: facebook | E15: ตรีสุคนธ์ ชูประสิทธิ์ | F15: EMS | G15: 15/12/2024 14:01 | H15: 0 | I15: JB128388424TH | J15: 45 | K15: ของเคลม Facebook , Facebook Live เนื่องจากลูกค้าได้รับสินค้าไม่ครบ | L15: เคลมเนื่องจากสินค้าเสียหายEJY79 | N15: ของเคลม Shopee เนื่องจากสินค้าเน่าเสียก่อนวันหมดอายุที่แจ้งข้างกล่อง
A16: 14 | B16: EKT81 | C16: จิตตรา สาริกา | D16: facebook | E16: จิตตรา สาริกา | F16: EMS | G16: 15/12/2024 14:13 | H16: 0 | I16: JB128388469TH | J16: 45 | K16: ของเคลม Facebook , Facebook Live เนื่องจากลูกค้าได้รับสินค้าไม่ครบ | L16: ลูกค้าคุณวรรณที่โอนผิด | N16: ของเคลม Shopee เนื่องจากสินค้ามีรสชาติขม รสชาติ สีของขนม ผิดปกติ
A17: 15 | B17: EKT96 | C17: น.ส.อรอนงค์ ไชยศร ( | D17: line_oa | E17: W1750 | F17: EMS | G17: 15/12/2024 14:32 | H17: 0 | I17: JB128388509TH | J17: 45 | K17: ของเคลม Facebook , Facebook Live เนื่องจากลูกค้าได้รับสินค้าไม่ครบ | N17: ของเคลม Shopee เนื่องจากสินค้าไม่มี | O17: 4
A18: 16 | B18: ELA10 | C18: ปภัสสร | D18: line_oa | E18: aui | F18: EMS | G18: 16/12/2024 15:51 | H18: 0 | I18: JB128542168TH | J18: 45 | K18: ของเคลม Facebook , Facebook Live เนื่องจากลูกค้าได้รับสินค้าไม่ครบ | L18: **กล่องเปล่า** รสกาแฟ1 เนยนม1 ฝอยทอง1 กล้วยหอม1 &nbsp;ตาล1 | N18: ของเคลม Shopee ไม่ทราบเหตุผล
A19: 17 | B19: ELF30 | C19: นิศารัตน์ แซ่ลิ้ม | D19: facebook | E19: June Nisarat | F19: EMS | G19: 17/12/2024 16:27 | H19: 0 | I19: JB128681995TH | J19: 45 | K19: ของเคลม Facebook , Facebook Live เนื่องจากลูกค้าได้รับสินค้าไม่ครบ | L19: รสฝอยทองทั้งหมด18กล่อง | N19: ของเคลม Line OA เนื่องจากลูกค้าได้รับสินค้าไม่ครบ | O19: 1
A20: 18 | B20: ELG42 | C20: ขวัญลดา นพศิริ | D20: line_oa | E20: Eye | F20: EMS | G20: 17/12/2024 19:20 | H20: 0 | I20: JB128682103TH | J20: 45 | K20: ของเคลม Facebook , Facebook Live เนื่องจากลูกค้าได้รับสินค้าไม่ครบ | L20: ขอกล่องป่าวเปี๊ยะ450กรัม | N20: ของเคลม Line OA เนื่องจากลูกค้าได้รับสินค้าผิดไม่ตรงตามที่สั่ง
A21: 19 | B21: ELY0 | C21: นัฐฏิญา | D21: facebook | F21: EMS | G21: 19/12/2024 19:50 | H21: 0 | I21: JB128964166TH | J21: 45 | K21: ของเคลม Facebook , Facebook Live เนื่องจากสินค้าเสียหายจากการขนส่ง | L21: เคลมช้อปปี้ เลขออเดอร์ 24121748RDDEJV**กล่องบี้** | N21: ของเคลม Line OA เนื่องจากลูกค้าไม่ได้รับสินค้า
A22: 20 | B22: ENS14 | C22: อนุสรา เส็งประสิทธิ์ | D22: line_oa | E22: Anusara 59😊 | F22: EMS | G22: 24/12/2024 11:46 | H22: 0 | I22: JB129620215TH | J22: 45 | K22: ของเคลม Facebook , Facebook Live เนื่องจากสินค้าเสียหายจากการขนส่ง | L22: กล่องเปี๊ยะ 450กรัม 📌รบกวนห่อกล่องหนาๆ📌 📌ส่งของวันที่ 25/12/67 เท่านั้น‼️ เคลมกล่องบุบ | N22: ของเคลม Line OA เนื่องจากสินค้าเสียหายจากการขนส่ง
A23: 21 | B23: ENW49 | C23: คุณพรรณภัทร ช้างป่าดี | D23: facebook | F23: EMS | G23: 24/12/2024 16:25 | H23: 0 | I23: JB129620184TH | J23: 45 | K23: ของเคลม LAZADA เนื่องจากลูกค้าได้รับสินค้าไม่ครบ | L23: เคลม LAZADA ร้าน 9 เลขออเดอร์ : 952485091269800เนื่องจากคุณลูกค้าได้สินค้าไม่ครบค่ะ | N23: ของเคลม Line OA เนื่องจากสินค้าเน่าเสียก่อนวันหมดอายุที่แจ้งข้างกล่อง
A24: 22 | B24: EOB61 | C24: นายมนตรี บุตรเสือ | D24: facebook | F24: EMS | G24: 25/12/2024 11:07 | H24: 0 | I24: JB129763832TH | J24: 45 | K24: ของเคลม LAZADA เนื่องจากลูกค้าได้รับสินค้าไม่ครบ | L24: เคลม ลาซาด้า เลขออเดอร์ : 959083304567938เนื่องจากคุณลูกค้าได้สินค้าไม่ครบค่ะ | N24: ของเคลม Line OA เนื่องจากสินค้ามีรสชาติขม รสชาติ สีของขนม ผิดปกติ
A25: 23 | B25: EOC23 | C25: วรนัฐ สุขอ่อน | D25: facebook | E25: Surisa Ponpichai | F25: EMS | G25: 25/12/2024 14:51 | H25: 0 | I25: JB129763775TH | J25: 45 | K25: ของเคลม Facebook , Facebook Live เนื่องจากสินค้าเสียหายจากการขนส่ง | L25: เคลมเนื่องจากสินค้าเสียหาย EMX34 จากเพจ | N25: ของเคลม Line OA เนื่องจากสินค้าไม่มี
A26: 24 | B26: EOC42 | C26: น.ส.สุรัตนา ใสทา | D26: facebook | F26: EMS | G26: 25/12/2024 16:51 | H26: 0 | I26: JB129763789TH | J26: 45 | K26: ของเคลม LAZADA เนื่องจากลูกค้าได้รับสินค้าไม่ครบ | L26: เคลมลาซาด้า เลขออเดอร์ : 952641067988057เนื่องจากคุณลูกค้าได้สินค้าไม่ครบค่ะ | N26: ของเคลม Line OA ไม่ทราบเหตุผล
A27: 25 | B27: EOD76 | C27: นางธนันณัฏฐ์ พรหมอุปถัมถ์ | D27: facebook | F27: EMS | G27: 26/12/2024 12:28 | H27: 0 | I27: JB129847400TH | J27: 45 | K27: ของเคลม Facebook , Facebook Live เนื่องจากลูกค้าได้รับสินค้าไม่ครบ | L27: เคลม เพจตัวแทน ออเดอร์ ENA41 | N27: ของเคลม Facebook , Facebook Live เนื่องจากลูกค้าได้รับสินค้าไม่ครบ | O27: 10
A28: 26 | B28: EOD96 | C28: ธนิสร ภูหัตสวน | D28: line_oa | E28: waraporn &nbsp;Chiangmai | F28: EMS | G28: 26/12/2024 13:21 | H28: 0 | I28: JB129847413TH | J28: 45 | K28: ของเคลม Line OA เนื่องจากลูกค้าได้รับสินค้าไม่ครบ | L28: เคลมเนื่องจากลูกค้าได้ของไม่ครบ | N28: ของเคลม Facebook , Facebook Live เนื่องจากลูกค้าได้รับสินค้าผิดไม่ตรงตามที่สั่ง
A29: 27 | B29: EOE88 | C29: คุณกัลยา สุกสอาด | D29: facebook | F29: EMS | G29: 26/12/2024 17:11 | H29: 0 | I29: - | J29: 45 | K29: ของเคลม Facebook , Facebook Live เนื่องจากลูกค้าได้รับสินค้าไม่ครบ | L29: เคลม ลาซาด้า ออเดอร์ ENA28 | N29: ของเคลม Facebook , Facebook Live เนื่องจากลูกค้าไม่ได้รับสินค้า
A30: 28 | B30: EOE89 | C30: คุณสิรินาถ รูปสม | D30: facebook | F30: EMS | G30: 26/12/2024 17:12 | H30: 0 | I30: - | J30: 45 | K30: ของเคลม LAZADA เนื่องจากสินค้าไม่มี | L30: เคลม ลาซาด้า ออเดอร์ ENA37เนื่องจากสินค้ามีไม่เพียงพอในการจัดส่ง | N30: ของเคลม Facebook , Facebook Live เนื่องจากสินค้าเสียหายจากการขนส่ง | O30: 3
A31: 29 | B31: EOG7 | C31: คุณชนัญญา กู้เจริญศิริสุข | D31: facebook | F31: EMS | G31: 27/12/2024 13:50 | H31: 0 | I31: TH16016MRZJP6N | J31: 45 | K31: ของเคลม LAZADA เนื่องจากสินค้าไม่มี | L31: เคลม ลาซาด้า เลขออเดอร์ 959916735315253เนื่องจากมีสินค้าไม่เพียงพอตอนแพ็ก | N31: ของเคลม Facebook , Facebook Live เนื่องจากสินค้าเน่าเสียก่อนวันหมดอายุที่แจ้งข้างกล่อง
A32: 30 | B32: EOG8 | C32: ดิว | D32: facebook | F32: EMS | G32: 27/12/2024 13:51 | H32: 0 | I32: TH04016MRZJQ3G | J32: 45 | K32: ของเคลม Shopee เนื่องจากสินค้าไม่มี | L32: เคลมช็อปปี้ ส่งของไม่ครบของไม่มี241220ARHV7N1Q | N32: ของเคลม Facebook , Facebook Live เนื่องจากสินค้ามีรสชาติขม รสชาติ สีของขนม ผิดปกติ
A33: 31 | B33: EOG9 | C33: น.ส.ณัฐธยาน์ วิเศษชนธีร์ | D33: facebook | F33: EMS | G33: 27/12/2024 13:52 | H33: 0 | I33: TH33126MRZJR0C | J33: 45 | K33: ของเคลม TikTok เนื่องจากสินค้าเสียหายจากการขนส่ง | L33: เครมติ๊กต๊อก เลขออเดอร์ 579796915732056353เนื่องจากขนมปังเสียหาย | N33: ของเคลม Facebook , Facebook Live เนื่องจากสินค้าไม่มี
A34: 32 | B34: EOG10 | C34: คุณฉัตรสุดา พรมหาญ | D34: facebook | F34: EMS | G34: 27/12/2024 13:53 | H34: 0 | I34: TH63016MRZJS0A | J34: 45 | K34: ของเคลม LAZADA เนื่องจากสินค้าไม่มี | L34: เคลม ลาซาด้า เลขออเดอร์ : 953071818636262เนื่องจากไม่มีสินค้าเพียงพอตอนแพ็ก | N34: ของเคลม Facebook , Facebook Live ไม่ทราบเหตุผล | O34: 1
A35: 33 | B35: EOG11 | C35: ชื่อผู้รับ น.ส.จันทร์จิรา ไชยะมณี | D35: facebook | F35: EMS | G35: 27/12/2024 13:56 | H35: 0 | I35: TH04036MS1E32A1 | J35: 45 | K35: ของเคลม LAZADA เนื่องจากสินค้าไม่มี | L35: เคลมลาซาด้า ของไม่มีเลยส่งตาม 953313659709173 | N35: ของเคลม Tiktok เนื่องจากลูกค้าได้รับสินค้าไม่ครบ
A36: 34 | B36: EOG12 | C36: อรวรรณ หน่อทอง | D36: facebook | F36: EMS | G36: 27/12/2024 13:57 | H36: 0 | I36: TH09046MRZJT4B | J36: 45 | K36: ของเคลม Tiktok เนื่องจากสินค้าไม่มี | L36: เคลม TIKTOK ออเดอร์ EMI9เนื่องจากตอนแพ็กมีสินค้าไม่เพียงพอ | N36: ของเคลม Tiktok เนื่องจากลูกค้าได้รับสินค้าผิดไม่ตรงตามที่สั่ง
A37: 35 | B37: EOG31 | C37: สายพิณ พรหมศิริ | D37: facebook | E37: Saipin Promsiri | F37: EMS | G37: 27/12/2024 16:03 | H37: 0 | I37: TH24046MRZJU4J | J37: 45 | K37: ของเคลม Facebook , Facebook Live ไม่ทราบเหตุผล | N37: ของเคลม Tiktok เนื่องจากลูกค้าไม่ได้รับสินค้า
A38: 36 | B38: EOG46 | C38: คุณสุรัตน์ดา เสลี่ยงรังษี | D38: facebook | F38: EMS | G38: 27/12/2024 17:28 | H38: 0 | I38: TH15066MRZJZ6C | J38: 45 | K38: ของเคลม LAZADA เนื่องจากสินค้าไม่มี | L38: เคลม ลาซาด้า เลขออเดอร์ : 959952197586011(เนื่องจากตอนแพ็กมีสินค้าไม่เพียงพอ) | N38: ของเคลม TikTok เนื่องจากสินค้าเสียหายจากการขนส่ง | O38: 2
A39: 37 | B39: EOH93 | C39: วราพร ปังคานนท์ | D39: other | F39: EMS | G39: 28/12/2024 13:07 | H39: 0 | I39: TH63036MT8666A | J39: 45 | K39: ของเคลม LAZADA เนื่องจากสินค้าไม่มี | L39: เคลม ช็อปปี้ 241220BR199XA2(เนื่องจากตอนแพ็กมีสินค้าไม่เพียงพอ) | N39: ของเคลม TikTok เนื่องจากสินค้าเน่าเสียก่อนวันหมดอายุที่แจ้งข้างกล่อง
A40: 38 | B40: EOH94 | C40: คุณกิจ คุณประกิจ มีวงค์ | D40: facebook | F40: EMS | G40: 28/12/2024 13:08 | H40: 0 | I40: TH63106MT8671A | J40: 45 | K40: ของเคลม LAZADA เนื่องจากสินค้าไม่มี | L40: เคลม ลาซาด้า ออเดอร์ : 952491225916738 (เนื่องจากสินค้าที่แพ็กไม่เพียงพอ) | N40: ของเคลม Tiktok เนื่องจากสินค้ามีรสชาติขม รสชาติ สีของขนม ผิดปกติ
...

Sheet ธ.ค. ยกเลิก
A1: สรุปรายการยกเลิกออเดอร์ ที่ออกเลขที่ออเดอร์แล้ว (เนื่องจากลูกค้าเอฟในไลฟ์สดแล้วไม่ยืนยันออเดอร์) เดือนธันวาคม 2567
A2: ลำดับ | B2: เลขที่ออเดอร์ | C2: ชื่อ | D2: ช่องทางติดต่อ | E2: ชื่อตามช่องทางติดต่อ | F2: ขนส่ง | G2: วันที่สร้าง | H2: ยอดขาย | I2: หมายเหตุ
A3: 1 | B3: EKE93 | D3: Facebook Live | E3: เต็ม เต็ม | F3: EMS | G3: 13/12/2024 10:47 | H3: 120
A4: 2 | B4: EJW11 | C4: ส******​ | D4: Shopee | E4: rat3141 | G4: 12/12/2024 00:36 | H4: 636
A5: 3 | B5: EKE93 | D5: Facebook Live | E5: เต็ม เต็ม | F5: EMS | G5: 13/12/2024 10:47 | H5: 120
A6: 4 | B6: EKE92 | C6: ลักษณวตี นามศรี | D6: Lazada | F6: Kerry_dropoff | G6: 13/12/2024 10:47 | H6: 154.8
A7: 5 | B7: EKO41 | C7: น***แทททู | D7: Tiktok | E7: 7494052928168232555 | F7: J&T Express | G7: 14/12/2024 11:36 | H7: 180
A8: 6 | B8: EKO97 | C8: k***ม | D8: Tiktok | E8: 7495529006722222883 | F8: J&T Express | G8: 14/12/2024 12:54 | H8: 150
A9: 7 | B9: EKP49 | C9: รัชนก เจริญผล | D9: Lazada | F9: Kerry_dropoff | G9: 14/12/2024 14:52 | H9: 478.4
A10: 8 | B10: EKP50 | C10: ป***ญาภรณ์ ศ***ันทร์ | D10: Tiktok | E10: 7494791606773385265 | F10: J&T Express | G10: 14/12/2024 14:54 | H10: 66
A11: 9 | B11: EKP86 | C11: ส***ตรา | D11: Tiktok | E11: 7494786027287906480 | F11: J&T Express | G11: 14/12/2024 15:40 | H11: 150
A12: 10 | B12: EKQ26 | C12: ร******M | D12: Shopee | E12: rattanaporn10684 | G12: 14/12/2024 18:10 | H12: 236
A13: 11 | B13: EKQ97 | C13: อ***อิ๋ง​ ป***ติ | D13: Tiktok | E13: 7495428167976782192 | F13: J&T Express | G13: 14/12/2024 21:38 | H13: 145
A14: 12 | B14: EKR33 | C14: CCM Mary | D14: Lazada | F14: Kerry_dropoff | G14: 14/12/2024 22:59 | H14: 140
A15: 13 | B15: EKR52 | C15: ศ******ี | D15: Shopee | E15: goodsupakarn | G15: 14/12/2024 23:39 | H15: 268
A16: 14 | B16: EKR53 | C16: ธิราวรรณ เหล่าทองสาร | D16: Lazada | F16: Kerry_dropoff | G16: 14/12/2024 23:40 | H16: 285.66
A17: 15 | B17: ELI36 | C17: มินตรา ศรีวิรัตน์ | D17: Lazada | F17: Kerry_dropoff | G17: 18/12/2024 05:41 | H17: 63.97
A18: 16 | B18: ELO10 | C18: konnit mee | D18: Lazada | F18: Kerry_dropoff | G18: 18/12/2024 20:04 | H18: 87.97
A19: 17 | B19: ELO27 | C19: อ******ว | D19: Shopee | E19: cs4n_2a2aa | G19: 18/12/2024 20:26 | H19: 456
A20: 18 | B20: ELO32 | C20: ฉ******ะ | D20: Shopee | E20: yju73f9hoa | G20: 18/12/2024 20:31 | H20: 114
A21: 19 | B21: ELO39 | C21: น******ว | D21: Shopee | E21: udorntit | G21: 18/12/2024 20:46 | H21: 181
A22: 20 | B22: ELO96 | C22: M***ah | D22: Tiktok | E22: 7494750478699104938 | F22: J&T Express | G22: 18/12/2024 22:49 | H22: 399
A23: 21 | B23: EMF16 | C23: 0863993214 | D23: Lazada | F23: Kerry_dropoff | G23: 20/12/2024 21:34 | H23: 571.21
A24: 22 | B24: EMF30 | C24: 0863993214 | D24: Lazada | F24: Kerry_dropoff | G24: 20/12/2024 21:39 | H24: 514.07
A25: 23 | B25: EMM17 | C25: ต***นซ์ เ***เซ | D25: Tiktok | E25: 7494370671035714267 | F25: J&T Express | G25: 21/12/2024 15:01 | H25: 200
A26: 24 | B26: EMM81 | C26: ช*** อ***พันธ์ | D26: Tiktok | E26: 7494051389371878760 | F26: J&T Express | G26: 21/12/2024 16:29 | H26: 200
A27: 25 | B27: EMN29 | C27: W******t | D27: Shopee | E27: waraporn_59 | G27: 21/12/2024 17:55 | H27: 224
A28: 26 | B28: EMN81 | C28: ก******ี | D28: Shopee | E28: fff37v9id0 | G28: 21/12/2024 18:58 | H28: 196
A29: 27 | B29: EMO33 | C29: น***า..แต้มทอง | D29: Tiktok | E29: 7494069101978027580 | F29: J&T Express | G29: 21/12/2024 19:43 | H29: 200
A30: 28 | B30: EMO68 | C30: นิรชร แสงรังสี | D30: Lazada | F30: Kerry_dropoff | G30: 21/12/2024 20:19 | H30: 151.33
A31: 29 | B31: EMO88 | C31: อ******ย | D31: Shopee | E31: smild_aw | G31: 21/12/2024 20:32 | H31: 320
A32: 30 | B32: EMO91 | C32: น******์ | D32: Shopee | E32: smild_aw | G32: 21/12/2024 20:38 | H32: 259
A33: 31 | B33: EMP72 | C33: เล็ก | D33: Lazada | F33: Kerry_dropoff | G33: 21/12/2024 22:57 | H33: 106.91
A34: 32 | B34: EMP85 | C34: จ***พงศ์ | D34: Tiktok | E34: 7494008725295170604 | F34: J&T Express | G34: 21/12/2024 23:27 | H34: 106
A35: 33 | B35: EMP96 | C35: ภ***วดี จ***เย็น | D35: Tiktok | E35: 7494006913694533046 | F35: J&T Express | G35: 21/12/2024 23:55 | H35: 129
A36: 34 | B36: EKE92 | C36: ลักษณวตี นามศรี | D36: Lazada | F36: Kerry_dropoff | G36: 13/12/2024 10:47 | H36: 154.8 | L36: 5 | M36: 0 | N36: 949445234794894
A37: 35 | B37: EKO41 | C37: น***แทททู | D37: Tiktok | E37: 7494052928168232555 | F37: J&T Express | G37: 14/12/2024 11:36 | H37: 180 | L37: 0 | M37: 0 | N37: 579761121031981675
A38: 36 | B38: EKO97 | C38: k***ม | D38: Tiktok | E38: 7495529006722222883 | F38: J&T Express | G38: 14/12/2024 12:54 | H38: 150 | L38: 0 | M38: 0 | N38: 579761453882968867
A39: 37 | B39: EKP49 | C39: รัชนก เจริญผล | D39: Lazada | F39: Kerry_dropoff | G39: 14/12/2024 14:52 | H39: 478.4 | L39: 29 | M39: 0 | N39: 950045632510422
A40: 38 | B40: EKP50 | C40: ป***ญาภรณ์ ศ***ันทร์ | D40: Tiktok | E40: 7494791606773385265 | F40: J&T Express | G40: 14/12/2024 14:54 | H40: 66 | L40: 6 | M40: 0 | N40: 579761867468146737
...

Sheet พ.ย. เคลม
A1: สรุปรายการส่งของเคลมสินค้า เดือนพฤศจิกายน 2567
A2: ลำดับ | B2: เลขที่ออเดอร์ | C2: ชื่อ | D2: ช่องทางติดต่อ | E2: ชื่อตามช่องทางติดต่อ | F2: ขนส่ง | G2: วันที่สร้าง | H2: ยอดขาย | I2: เลขพัสดุ | J2: ค่าขนส่ง | K2: หมายเหตุ | L2: หมายเหตุ | N2: รายการ | O2: จำนวนออเดอร์
A3: 1 | B3: ECC27 | C3: คุณพรพิมล มะภู่ทอง | D3: phone | E3: Shopee (lekky.pornpimol) | F3: EMS | G3: 01/11/2024 14:37 | H3: 0 | I3: JB117850551TH | J3: 17 | K3: ของเคลม Facebook , Facebook Live ไม่ทราบเหตุผล | N3: ของเคลม LAZADA เนื่องจากลูกค้าได้รับสินค้าไม่ครบ
A4: 2 | B4: ECC38 | D4: Lazchoice | E4: Lazchoice | F4: EMS | G4: 01/11/2024 14:51 | H4: 0 | I4: LBX024766785558966 | J4: 17 | K4: ของเคลม LAZADA ไม่ทราบเหตุผล | N4: ของเคลม LAZADA เนื่องจากลูกค้าได้รับสินค้าผิดไม่ตรงตามที่สั่ง
A5: 3 | B5: ECC41 | D5: Lazchoice | E5: Lazchoice | F5: EMS | G5: 01/11/2024 14:53 | H5: 0 | I5: LBX024766785568325 | J5: 17 | K5: ของเคลม LAZADA ไม่ทราบเหตุผล | N5: ของเคลม LAZADA เนื่องจากลูกค้าไม่ได้รับสินค้า
A6: 4 | B6: ECC68 | C6: กรภัทร อรรถคีรี | D6: facebook | E6: เปาเปา อังเปา | F6: EMS | G6: 01/11/2024 15:28 | H6: 0 | I6: JB117850565TH | J6: 17 | K6: ของเคลม Facebook , Facebook Live ไม่ทราบเหตุผล | N6: ของเคลม LAZADA เนื่องจากสินค้าเสียหายจากการขนส่ง | O6: 1
A7: 5 | B7: ECG69 | D7: Lazchoice | E7: Lazchoice | F7: EMS | G7: 02/11/2024 08:02 | H7: 0 | I7: LBX024766786082134 | J7: 17 | K7: ของเคลม LAZADA ไม่ทราบเหตุผล | N7: ของเคลม LAZADA เนื่องจากสินค้าเน่าเสียก่อนวันหมดอายุที่แจ้งข้างกล่อง
A8: 6 | B8: ECG70 | D8: Lazchoice | E8: Lazchoice | F8: EMS | G8: 02/11/2024 08:05 | H8: 0 | I8: LBX024766786072890 | J8: 17 | K8: ของเคลม LAZADA ไม่ทราบเหตุผล | N8: ของเคลม LAZADA เนื่องจากสินค้ามีรสชาติขม รสชาติ สีของขนม ผิดปกติ
A9: 7 | B9: ECH58 | D9: Lazchoice | E9: Lazchoice | F9: EMS | G9: 02/11/2024 12:09 | H9: 0 | I9: LBX024766786069970 | J9: 17 | K9: ของเคลม LAZADA ไม่ทราบเหตุผล | N9: ของเคลม LAZADA เนื่องจากสินค้าไม่มี
A10: 8 | B10: ECH60 | D10: Lazchoice | E10: Lazchoice | F10: EMS | G10: 02/11/2024 12:11 | H10: 0 | I10: LBX024766786071906 | J10: 17 | K10: ของเคลม LAZADA ไม่ทราบเหตุผล | N10: ของเคลม LAZADA ไม่ทราบเหตุผล | O10: 128
A11: 9 | B11: ECI67 | C11: คุณจิตนา | D11: facebook | F11: EMS | G11: 02/11/2024 14:46 | H11: 0 | I11: JB118037803TH | J11: 17 | K11: ของเคลม Facebook , Facebook Live ไม่ทราบเหตุผล | N11: ของเคลม Shopee เนื่องจากลูกค้าได้รับสินค้าไม่ครบ | O11: 1
A12: 10 | B12: ECP59 | C12: สุวรรณา ดาราไกร | D12: line_oa | E12: ชื่อปัด | F12: EMS | G12: 03/11/2024 15:22 | H12: 0 | I12: JB118209962TH | J12: 17 | K12: ของเคลม Line OA ไม่ทราบเหตุผล | N12: ของเคลม Shopee เนื่องจากลูกค้าได้รับสินค้าผิดไม่ตรงตามที่สั่ง
A13: 11 | B13: ECV9 | D13: Lazchoice | E13: Lazchoice | F13: EMS | G13: 04/11/2024 14:53 | H13: 0 | I13: LBX024766787848959 | J13: 17 | K13: ของเคลม LAZADA ไม่ทราบเหตุผล | N13: ของเคลม Shopee เนื่องจากลูกค้าไม่ได้รับสินค้า
A14: 12 | B14: ECV12 | D14: Lazchoice | E14: Lazchoice | F14: EMS | G14: 04/11/2024 14:55 | H14: 0 | I14: LBX024766787855427 | J14: 17 | K14: ของเคลม LAZADA ไม่ทราบเหตุผล | N14: ของเคลม Shopee เนื่องจากสินค้าเสียหายจากการขนส่ง
A15: 13 | B15: ECV15 | D15: Lazchoice | E15: Lazchoice | F15: EMS | G15: 04/11/2024 14:59 | H15: 0 | I15: LBX024766787849884 | J15: 17 | K15: ของเคลม LAZADA ไม่ทราบเหตุผล | N15: ของเคลม Shopee เนื่องจากสินค้าเน่าเสียก่อนวันหมดอายุที่แจ้งข้างกล่อง
A16: 14 | B16: ECV18 | D16: Lazchoice | E16: Lazchoice | F16: EMS | G16: 04/11/2024 15:02 | H16: 0 | I16: LEXPU0415621302 | J16: 17 | K16: ของเคลม LAZADA ไม่ทราบเหตุผล | N16: ของเคลม Shopee เนื่องจากสินค้ามีรสชาติขม รสชาติ สีของขนม ผิดปกติ
A17: 15 | B17: ECV27 | D17: Lazchoice | E17: Lazchoice | F17: EMS | G17: 04/11/2024 15:07 | H17: 0 | I17: LEXPU0415621112 | J17: 17 | K17: ของเคลม LAZADA ไม่ทราบเหตุผล | N17: ของเคลม Shopee เนื่องจากสินค้าไม่มี
A18: 16 | B18: ECV38 | D18: Lazchoice | E18: Lazchoice | F18: EMS | G18: 04/11/2024 15:18 | H18: 0 | I18: LEXPU0415621859 | J18: 17 | K18: ของเคลม LAZADA ไม่ทราบเหตุผล | N18: ของเคลม Shopee ไม่ทราบเหตุผล
A19: 17 | B19: EDG3 | D19: Lazchoice | E19: Lazchoice | F19: EMS | G19: 06/11/2024 14:07 | H19: 0 | I19: - | J19: 17 | K19: ของเคลม LAZADA ไม่ทราบเหตุผล | N19: ของเคลม Line OA เนื่องจากลูกค้าได้รับสินค้าไม่ครบ
A20: 18 | B20: EDG55 | D20: Lazchoice | E20: Lazchoice | F20: EMS | G20: 06/11/2024 16:00 | H20: 0 | I20: - | J20: 17 | K20: ของเคลม LAZADA ไม่ทราบเหตุผล | N20: ของเคลม Line OA เนื่องจากลูกค้าได้รับสินค้าผิดไม่ตรงตามที่สั่ง
A21: 19 | B21: EDG3 | D21: Lazchoice | E21: Lazchoice | F21: EMS | G21: 06/11/2024 14:07 | H21: 0 | I21: - | J21: 17 | K21: ของเคลม LAZADA ไม่ทราบเหตุผล | N21: ของเคลม Line OA เนื่องจากลูกค้าไม่ได้รับสินค้า
A22: 20 | B22: EDG55 | D22: Lazchoice | E22: Lazchoice | F22: EMS | G22: 06/11/2024 16:00 | H22: 0 | I22: - | J22: 17 | K22: ของเคลม LAZADA ไม่ทราบเหตุผล | N22: ของเคลม Line OA เนื่องจากสินค้าเสียหายจากการขนส่ง | O22: 1
A23: 21 | B23: EDJ35 | D23: Lazchoice | E23: Lazchoice | F23: EMS | G23: 07/11/2024 06:53 | H23: 0 | I23: LEXPU0416606131 | J23: 17 | K23: ของเคลม LAZADA ไม่ทราบเหตุผล | N23: ของเคลม Line OA เนื่องจากสินค้าเน่าเสียก่อนวันหมดอายุที่แจ้งข้างกล่อง
A24: 22 | B24: EDJ36 | D24: Lazchoice | E24: Lazchoice | F24: EMS | G24: 07/11/2024 07:00 | H24: 0 | I24: LBX024766791952941 | J24: 17 | K24: ของเคลม LAZADA ไม่ทราบเหตุผล | N24: ของเคลม Line OA เนื่องจากสินค้ามีรสชาติขม รสชาติ สีของขนม ผิดปกติ
A25: 23 | B25: EDK44 | D25: Lazchoice | E25: Lazchoice | F25: EMS | G25: 07/11/2024 13:20 | H25: 0 | I25: LBX024766792210284 | J25: 17 | K25: ของเคลม LAZADA ไม่ทราบเหตุผล | N25: ของเคลม Line OA เนื่องจากสินค้าไม่มี
A26: 24 | B26: EDN22 | D26: Lazchoice | E26: Lazchoice | F26: EMS | G26: 08/11/2024 09:26 | H26: 0 | I26: LBX024766792865035 | J26: 17 | K26: ของเคลม LAZADA ไม่ทราบเหตุผล | N26: ของเคลม Line OA ไม่ทราบเหตุผล | O26: 2
A27: 25 | B27: EDN64 | D27: Lazchoice | E27: Lazchoice | F27: EMS | G27: 08/11/2024 12:19 | H27: 0 | I27: LBX024766792973126 | J27: 17 | K27: ของเคลม LAZADA ไม่ทราบเหตุผล | N27: ของเคลม Facebook , Facebook Live เนื่องจากลูกค้าได้รับสินค้าไม่ครบ
A28: 26 | B28: EDN66 | D28: Lazchoice | E28: Lazchoice | F28: EMS | G28: 08/11/2024 12:24 | H28: 0 | I28: LBX024766792967603 | J28: 17 | K28: ของเคลม LAZADA ไม่ทราบเหตุผล | N28: ของเคลม Facebook , Facebook Live เนื่องจากลูกค้าได้รับสินค้าผิดไม่ตรงตามที่สั่ง
A29: 27 | B29: EDX3 | C29: Lazchoice | D29: other | E29: Lazchoice | F29: EMS | G29: 10/11/2024 09:20 | H29: 0 | I29: LEXPU0418191982 | J29: 17 | K29: ของเคลม LAZADA ไม่ทราบเหตุผล | N29: ของเคลม Facebook , Facebook Live เนื่องจากลูกค้าไม่ได้รับสินค้า
A30: 28 | B30: EDX8 | C30: Lazchoice | D30: other | E30: Lazchoice | F30: EMS | G30: 10/11/2024 09:24 | H30: 0 | I30: LBX024766794737620 | J30: 17 | K30: ของเคลม LAZADA ไม่ทราบเหตุผล | N30: ของเคลม Facebook , Facebook Live เนื่องจากสินค้าเสียหายจากการขนส่ง
A31: 29 | B31: EDX13 | C31: Lazchoice | D31: other | E31: Lazchoice | F31: EMS | G31: 10/11/2024 09:27 | H31: 0 | I31: BSTPU041747995 | J31: 17 | K31: ของเคลม LAZADA ไม่ทราบเหตุผล | N31: ของเคลม Facebook , Facebook Live เนื่องจากสินค้าเน่าเสียก่อนวันหมดอายุที่แจ้งข้างกล่อง
A32: 30 | B32: EDX15 | C32: Lazchoice | D32: other | E32: Lazchoice | F32: EMS | G32: 10/11/2024 09:29 | H32: 0 | I32: 22775015199 | J32: 17 | K32: ของเคลม LAZADA ไม่ทราบเหตุผล | N32: ของเคลม Facebook , Facebook Live เนื่องจากสินค้ามีรสชาติขม รสชาติ สีของขนม ผิดปกติ
A33: 31 | B33: EDX16 | C33: Lazchoice | D33: other | E33: Lazchoice | F33: EMS | G33: 10/11/2024 09:30 | H33: 0 | I33: 22775015199 | J33: 17 | K33: ของเคลม LAZADA ไม่ทราบเหตุผล | N33: ของเคลม Facebook , Facebook Live เนื่องจากสินค้าไม่มี
A34: 32 | B34: EDX17 | C34: Lazchoice | D34: other | E34: Lazchoice | F34: EMS | G34: 10/11/2024 09:31 | H34: 0 | I34: LBX024766794733802 | J34: 17 | K34: ของเคลม LAZADA ไม่ทราบเหตุผล | N34: ของเคลม Facebook , Facebook Live ไม่ทราบเหตุผล | O34: 3
A35: 33 | B35: EDX19 | C35: Lazchoice | D35: other | E35: Lazchoice | F35: EMS | G35: 10/11/2024 09:33 | H35: 0 | I35: LBX024766794736667 | J35: 17 | K35: ของเคลม LAZADA ไม่ทราบเหตุผล | N35: ของเคลม Tiktok เนื่องจากลูกค้าได้รับสินค้าไม่ครบ | O35: 3
A36: 34 | B36: EDX22 | C36: Lazchoice | D36: other | E36: Lazchoice | F36: EMS | G36: 10/11/2024 09:34 | H36: 0 | I36: LBX024766794736665 | J36: 17 | K36: ของเคลม LAZADA ไม่ทราบเหตุผล | N36: ของเคลม Tiktok เนื่องจากลูกค้าได้รับสินค้าผิดไม่ตรงตามที่สั่ง
A37: 35 | B37: EDX27 | C37: Lazchoice | D37: other | E37: Lazchoice | F37: EMS | G37: 10/11/2024 09:36 | H37: 0 | I37: LBX024766794740344 | J37: 17 | K37: ของเคลม LAZADA ไม่ทราบเหตุผล | N37: ของเคลม Tiktok เนื่องจากลูกค้าไม่ได้รับสินค้า
A38: 36 | B38: EDX28 | D38: Lazchoice | E38: Lazchoice | F38: EMS | G38: 10/11/2024 09:37 | H38: 0 | I38: LEXPU0418221933 | J38: 17 | K38: ของเคลม LAZADA ไม่ทราบเหตุผล | N38: ของเคลม TikTok เนื่องจากสินค้าเสียหายจากการขนส่ง | O38: 3
A39: 37 | B39: EDX52 | C39: Lazchoice | D39: other | E39: Lazchoice | F39: EMS | G39: 10/11/2024 10:36 | H39: 0 | I39: LBX024766794733801 | J39: 17 | K39: ของเคลม LAZADA ไม่ทราบเหตุผล | N39: ของเคลม TikTok เนื่องจากสินค้าเน่าเสียก่อนวันหมดอายุที่แจ้งข้างกล่อง
A40: 38 | B40: EDX53 | C40: Lazchoice | D40: other | E40: Lazchoice | F40: EMS | G40: 10/11/2024 10:40 | H40: 0 | I40: LBX024766794732853 | J40: 17 | K40: ของเคลม LAZADA ไม่ทราบเหตุผล | N40: ของเคลม Tiktok เนื่องจากสินค้ามีรสชาติขม รสชาติ สีของขนม ผิดปกติ | O40: 4
...

Sheet พ.ย. ยกเลิก
A1: สรุปรายการยกเลิกออเดอร์ ที่ออกเลขที่ออเดอร์แล้ว (เนื่องจากลูกค้าเอฟในไลฟ์สดแล้วไม่ยืนยันออเดอร์) เดือนพฤศจิกายน 2567
A2: ลำดับ | B2: เลขที่ออเดอร์ | C2: ชื่อ | D2: ช่องทางติดต่อ | E2: ชื่อตามช่องทางติดต่อ | F2: ขนส่ง | G2: วันที่สร้าง | H2: ยอดขาย | I2: หมายเหตุ
A3: 1 | B3: EDE96 | C3: ส******์ | D3: Shopee | E3: fahsunisanopparat | G3: 06/11/2024 11:00 | H3: 206 | I3: สรุปออเดอร์แล้ว ลูกค้ายกเลิก
A4: 2 | B4: EDG50 | C4: K***ika k***khai | D4: Tiktok | E4: 7494830282744040169 | F4: J&T Express | G4: 06/11/2024 15:45 | H4: 200 | I4: สรุปออเดอร์แล้ว ลูกค้ายกเลิก
A5: 3 | B5: EDG61 | C5: ร***ขนมของฝาก | D5: Tiktok | E5: 7493994974073882577 | F5: J&T Express | G5: 06/11/2024 16:12 | H5: 245 | I5: สรุปออเดอร์แล้ว ลูกค้ายกเลิก
A6: 4 | B6: EDG73 | C6: พ******ง | D6: Shopee | E6: luckythong616 | G6: 06/11/2024 16:46 | H6: 135 | I6: สรุปออเดอร์แล้ว ลูกค้ายกเลิก
A7: 5 | B7: EDG92 | C7: จ***ามณี ค*** | D7: Tiktok | E7: 7495368184325965973 | F7: J&T Express | G7: 06/11/2024 17:20 | H7: 100 | I7: สรุปออเดอร์แล้ว ลูกค้ายกเลิก
A8: 6 | B8: EDI0 | C8: บ******์ | D8: Shopee | E8: kuntika_ice | G8: 06/11/2024 20:35 | H8: 228 | I8: สรุปออเดอร์แล้ว ลูกค้ายกเลิก
A9: 7 | B9: EDI37 | C9: น**า | D9: Shopee | E9: rmoe4h6owf | G9: 06/11/2024 21:59 | H9: 69 | I9: สรุปออเดอร์แล้ว ลูกค้ายกเลิก
A10: 8 | B10: EDI62 | C10: ณ***ล | D10: Tiktok | E10: 7494009311204837149 | F10: J&T Express | G10: 06/11/2024 22:45 | H10: 106 | I10: สรุปออเดอร์แล้ว ลูกค้ายกเลิก
A11: 9 | B11: EDI88 | C11: mulan /ซื้อให้จ่ะ | D11: Lazada | F11: Kerry_dropoff | G11: 06/11/2024 23:48 | H11: 90.56 | I11: สรุปออเดอร์แล้ว ลูกค้ายกเลิก
A12: 10 | B12: EDQ28 | C12: ปารมี แสงรังสี | D12: Lazada | F12: Kerry_dropoff | G12: 08/11/2024 21:12 | H12: 209.87 | I12: สรุปออเดอร์แล้ว ลูกค้ายกเลิก
A13: 11 | B13: EDS22 | C13: พรสุทธิ พื้นแสน | D13: Lazada | F13: Kerry_dropoff | G13: 09/11/2024 05:04 | H13: 230.82 | I13: สรุปออเดอร์แล้ว ลูกค้ายกเลิก
A14: 12 | B14: EDT24 | C14: ธ***วรรณ น***ะผาย | D14: Tiktok | E14: 7494551413219821782 | F14: J&T Express | G14: 09/11/2024 10:34 | H14: 145 | I14: สรุปออเดอร์แล้ว ลูกค้ายกเลิก
A15: 13 | B15: EDT82 | C15: พ******ล | D15: Shopee | E15: nana25458 | G15: 09/11/2024 12:55 | H15: 130 | I15: สรุปออเดอร์แล้ว ลูกค้ายกเลิก
A16: 14 | B16: EDU26 | C16: นางสาว ปวีณา ขุนเทพ | D16: Lazada | F16: Kerry_dropoff | G16: 09/11/2024 14:49 | H16: 59.8 | I16: สรุปออเดอร์แล้ว ลูกค้ายกเลิก
A17: 15 | B17: EDV44 | C17: ส***ภัทร ร***ติดดาวสมใจ | D17: Tiktok | E17: 7494045310378673816 | F17: J&T Express | G17: 09/11/2024 19:53 | H17: 229 | I17: สรุปออเดอร์แล้ว ลูกค้ายกเลิก
A18: 16 | B18: EDV70 | C18: อ***ร ส***ส | D18: Tiktok | E18: 7494010927431321189 | F18: J&T Express | G18: 09/11/2024 20:51 | H18: 200 | I18: สรุปออเดอร์แล้ว ลูกค้ายกเลิก
A19: 17 | B19: EDV78 | C19: ต* ท** | D19: Tiktok | E19: 7494078380477875798 | F19: J&T Express | G19: 09/11/2024 21:20 | H19: 400 | I19: สรุปออเดอร์แล้ว ลูกค้ายกเลิก
A20: 18 | B20: EEB36 | C20: จรรยวรรธน์ พิมายรัตน์ | D20: Lazada | F20: Kerry_dropoff | G20: 11/11/2024 01:45 | H20: 191.69 | I20: สรุปออเดอร์แล้ว ลูกค้ายกเลิก
A21: 19 | B21: EEJ27 | C21: ปารมี แสงรังสี | D21: Lazada | F21: Kerry_dropoff | G21: 11/11/2024 18:47 | H21: 44.95 | I21: สรุปออเดอร์แล้ว ลูกค้ายกเลิก
A22: 20 | B22: EEP97 | C22: ปารมี แสงรังสี | D22: Lazada | F22: Kerry_dropoff | G22: 12/11/2024 19:44 | H22: 44.95 | I22: สรุปออเดอร์แล้ว ลูกค้ายกเลิก
A23: 21 | B23: EEP95 | C23: ส***ดา ส***ง | D23: Tiktok | E23: 7495482028569299571 | F23: J&T Express | G23: 12/11/2024 19:44 | H23: 215 | I23: สรุปออเดอร์แล้ว ลูกค้ายกเลิก
A24: 22 | B24: EEQ55 | C24: จำลอง ประเสริฐ | D24: Lazada | F24: Kerry_dropoff | G24: 12/11/2024 21:26 | H24: 87.4 | I24: สรุปออเดอร์แล้ว ลูกค้ายกเลิก
A25: 23 | B25: EEQ56 | C25: จำลอง ประเสริฐ | D25: Lazada | F25: Kerry_dropoff | G25: 12/11/2024 21:27 | H25: 58.97 | I25: สรุปออเดอร์แล้ว ลูกค้ายกเลิก
A26: 24 | B26: EFC33 | C26: นรธีร์ | D26: Lazada | F26: Kerry_dropoff | G26: 16/11/2024 08:46 | H26: 386.97 | I26: สรุปออเดอร์แล้ว ลูกค้ายกเลิก
A27: 25 | B27: EFG32 | C27: รุจิรา ฤทธิเดช | D27: Lazada | F27: Kerry_dropoff | G27: 17/11/2024 13:42 | H27: 105.52 | I27: สรุปออเดอร์แล้ว ลูกค้ายกเลิก
A28: 26 | B28: EFH95 | C28: Charinee​ Sangthong | D28: Lazada | F28: Kerry_dropoff | G28: 17/11/2024 22:28 | H28: 124.41 | I28: สรุปออเดอร์แล้ว ลูกค้ายกเลิก
A29: 27 | B29: EFI12 | C29: น.ส.พิรญาณ์ วังคีรี | D29: Lazada | F29: Kerry_dropoff | G29: 17/11/2024 23:44 | H29: 85 | I29: สรุปออเดอร์แล้ว ลูกค้ายกเลิก
A30: 28 | B30: EFI18 | C30: pitak | D30: Lazada | F30: Kerry_dropoff | G30: 17/11/2024 23:58 | H30: 5 | I30: สรุปออเดอร์แล้ว ลูกค้ายกเลิก | M30: 0 | N30: 900801206010597
A31: 29 | B31: EFN48 | C31: สิริกร ใหญ่ผล | D31: Lazada | F31: Kerry_dropoff | G31: 19/11/2024 12:55 | H31: 222 | I31: สรุปออเดอร์แล้ว ลูกค้ายกเลิก | M31: 0 | N31: 906815728009721
A32: 30 | B32: EFO23 | C32: k*** v* | D32: Tiktok | E32: 7494961843965757548 | F32: J&T Express | G32: 19/11/2024 17:17 | H32: 106 | I32: สรุปออเดอร์แล้ว ลูกค้ายกเลิก | M32: 0 | N32: 579242639958051041
A33: 31 | B33: EFP19 | C33: ส******์ | D33: Shopee | E33: daowsopisda | G33: 19/11/2024 23:45 | H33: 62 | I33: สรุปออเดอร์แล้ว ลูกค้ายกเลิก | M33: 0 | N33: 579242905526438911
A34: 32 | B34: EGC49 | C34: ม******์ | D34: Shopee | E34: puengallday | G34: 21/11/2024 21:57 | H34: 226 | I34: สรุปออเดอร์แล้ว ลูกค้ายกเลิก | M34: 0 | N34: 579243224466492155
A35: 33 | B35: EGC54 | C35: Charinee​ Sangthong | D35: Lazada | F35: Kerry_dropoff | G35: 21/11/2024 22:32 | H35: 61.15 | I35: สรุปออเดอร์แล้ว ลูกค้ายกเลิก | M35: 0 | N35: 579243224846732027
A36: 34 | B36: EHR96 | C36: ณ******ฑ | D36: Shopee | E36: gaynutsiree | G36: 30/11/2024 23:33 | H36: 107 | I36: สรุปออเดอร์แล้ว ลูกค้ายกเลิก | M36: 0 | N36: 579243248210118704
A37: 35 | B37: EHR72 | C37: ន* វ***់ | D37: Tiktok | E37: 7495900767768972281 | F37: J&T Express | G37: 30/11/2024 21:02 | H37: 106 | I37: สรุปออเดอร์แล้ว ลูกค้ายกเลิก | M37: 0 | N37: 901053020741847
A38: 36 | B38: EHQ72 | C38: ว***า | D38: Tiktok | E38: 7494009825603913682 | F38: J&T Express | G38: 30/11/2024 15:45 | H38: 106 | I38: สรุปออเดอร์แล้ว ลูกค้ายกเลิก
A39: 37 | B39: EHP86 | C39: ก***พงศ์ แ***่อง | D39: Tiktok | E39: 7494344064601590181 | F39: J&T Express | G39: 30/11/2024 12:28 | H39: 157 | I39: สรุปออเดอร์แล้ว ลูกค้ายกเลิก
A40: 38 | B40: EHP84 | C40: จ***มาศ​ ไ***ันท์ | D40: Tiktok | E40: 7494026149808605012 | F40: J&T Express | G40: 30/11/2024 12:19 | H40: 200 | I40: สรุปออเดอร์แล้ว ลูกค้ายกเลิก
...

Sheet ต.ค. เคลม
A1: สรุปรายการส่งของเคลมสินค้า เดือนตุลาคม 2567
A2: ลำดับ | B2: เลขที่ออเดอร์ | C2: ชื่อ | D2: ช่องทางติดต่อ | E2: ชื่อตามช่องทางติดต่อ | F2: ขนส่ง | G2: วันที่สร้าง | H2: ยอดขาย | I2: เลขพัสดุ | J2: ค่าขนส่ง | K2: หมายเหตุ | L2: หมายเหตุ | N2: รายการ | O2: จำนวนออเดอร์
A3: 1 | B3: DVR2 | C3: นางสุจินดา ภักดีสอน | D3: facebook | F3: EMS | G3: 01/10/2024 12:19 | H3: 0 | I3: JB087059903TH | J3: 17 | K3: ของเคลม Shopee เนื่องจากสินค้ามีรสชาติขม รสชาติ สีของขนม ผิดปกติ | L3: ช้อปปี้ เลขออเดอร์ 240925V9KBTQR0**สินค้ามีสิ่งแปลกปลอม** | N3: ของเคลม LAZADA เนื่องจากลูกค้าได้รับสินค้าไม่ครบ | O3: 2
A4: 2 | B4: DVR3 | C4: Yanakorn | D4: facebook | F4: EMS | G4: 01/10/2024 12:20 | H4: 0 | I4: JB087059917TH | J4: 17 | K4: ของเคลม Shopee เนื่องจากสินค้ามีรสชาติขม รสชาติ สีของขนม ผิดปกติ | L4: ช้อปปี้ เลขออเดอร์ 240923QBHRGX5D**สินค้าเสีย** | N4: ของเคลม LAZADA เนื่องจากลูกค้าได้รับสินค้าผิดไม่ตรงตามที่สั่ง
A5: 3 | B5: DVS23 | C5: Lazchoice | D5: other | E5: Lazchoice | F5: EMS | G5: 01/10/2024 16:05 | H5: 0 | I5: LBX024766754493706 | J5: 17 | K5: ของเคลม LAZADA ไม่ทราบเหตุผล | N5: ของเคลม LAZADA เนื่องจากลูกค้าไม่ได้รับสินค้า
A6: 4 | B6: DVS32 | C6: Lazchoice | D6: Lazchoice | E6: Lazchoice | F6: EMS | G6: 01/10/2024 16:10 | H6: 0 | I6: LBX024766754491748 | J6: 17 | K6: ของเคลม LAZADA ไม่ทราบเหตุผล | N6: ของเคลม LAZADA เนื่องจากสินค้าเสียหายจากการขนส่ง
A7: 5 | B7: DVV88 | C7: เดียคู้ซ้าย กิตติชัย สิบ ซ.มิตรไมตรี แปด ทับ หนึ่ง | D7: Lazada | F7: Kerry_dropoff | G7: 02/10/2024 10:02 | H7: 0 | I7: LEXPU0402170619 | J7: 17 | K7: ของเคลม LAZADA ไม่ทราบเหตุผล | N7: ของเคลม LAZADA เนื่องจากสินค้าเน่าเสียก่อนวันหมดอายุที่แจ้งข้างกล่อง
A8: 6 | B8: DVW3 | C8: นายวีระศักดิ์ แตงมีแสง | D8: facebook | F8: EMS | G8: 02/10/2024 11:59 | H8: 0 | I8: JB087286091TH | J8: 17 | K8: ของเคลม LAZADA ไม่ทราบเหตุผล | L8: ช้อปปี้ เลขออเดอร์ 24092971CRH9WX**สินค้าเสีย** | N8: ของเคลม LAZADA เนื่องจากสินค้ามีรสชาติขม รสชาติ สีของขนม ผิดปกติ | O8: 1
A9: 7 | B9: DVW33 | C9: Lazchoice | D9: other | E9: Lazchoice | F9: EMS | G9: 02/10/2024 13:35 | H9: 0 | I9: LBX024766755184008 | J9: 17 | K9: ของเคลม LAZADA ไม่ทราบเหตุผล | N9: ของเคลม LAZADA เนื่องจากสินค้าไม่มี
A10: 8 | B10: DVW35 | C10: Lazchoice | D10: other | E10: Lazchoice | F10: EMS | G10: 02/10/2024 13:37 | H10: 0 | I10: LBX024766755184009 | J10: 17 | K10: ของเคลม LAZADA ไม่ทราบเหตุผล | N10: ของเคลม LAZADA ไม่ทราบเหตุผล | O10: =129+14 -> 143
A11: 9 | B11: DVW36 | C11: Lazchoice | D11: other | E11: Lazchoice | F11: EMS | G11: 02/10/2024 13:38 | H11: 0 | I11: LBX024766755172423 | J11: 17 | K11: ของเคลม LAZADA ไม่ทราบเหตุผล | N11: ของเคลม Shopee เนื่องจากลูกค้าได้รับสินค้าไม่ครบ | O11: 6
A12: 10 | B12: DVW40 | C12: Lazchoice | D12: other | E12: Lazchoice | F12: EMS | G12: 02/10/2024 13:40 | H12: 0 | I12: LBX024766755171390 | J12: 17 | K12: ของเคลม LAZADA ไม่ทราบเหตุผล | N12: ของเคลม Shopee เนื่องจากลูกค้าได้รับสินค้าผิดไม่ตรงตามที่สั่ง
A13: 11 | B13: DVZ41 | C13: คุณอชิระวิชญ์ เอกหิรัญนันทชัย | D13: Lazada | F13: Kerry_dropoff | G13: 03/10/2024 00:19 | H13: 0 | I13: LEXPU0402159467 | J13: 17 | K13: ของเคลม LAZADA ไม่ทราบเหตุผล | N13: ของเคลม Shopee เนื่องจากลูกค้าไม่ได้รับสินค้า
A14: 12 | B14: DVZ49 | C14: Yuni Mopa | D14: Lazada | F14: Kerry_dropoff | G14: 03/10/2024 02:03 | H14: 0 | I14: LEXDO0114902314 | J14: 17 | K14: ของเคลม LAZADA ไม่ทราบเหตุผล | N14: ของเคลม Shopee เนื่องจากสินค้าเสียหายจากการขนส่ง
A15: 13 | B15: DVZ68 | C15: พิษณุ พิทักษ์ | D15: facebook | F15: EMS | G15: 03/10/2024 08:11 | H15: 0 | I15: JB087286088TH | J15: 22 | K15: ของเคลม LAZADA ไม่ทราบเหตุผล | L15: ⭕ลูกค้าของคุณแม่ ส่งด่วนวันนี้⭕ | N15: ของเคลม Shopee เนื่องจากสินค้าเน่าเสียก่อนวันหมดอายุที่แจ้งข้างกล่อง
A16: 14 | B16: DWA12 | C16: Lazchoice | D16: facebook | E16: Lazchoice | F16: EMS | G16: 03/10/2024 11:41 | H16: 0 | I16: LEXDO0114910545 | J16: 17 | K16: ของเคลม LAZADA ไม่ทราบเหตุผล | N16: ของเคลม Shopee เนื่องจากสินค้ามีรสชาติขม รสชาติ สีของขนม ผิดปกติ | O16: 4
A17: 15 | B17: DWA15 | C17: Lazchoice | D17: facebook | E17: Lazchoice | F17: EMS | G17: 03/10/2024 11:42 | H17: 0 | I17: LBX024766756014435 | J17: 17 | K17: ของเคลม LAZADA ไม่ทราบเหตุผล | N17: ของเคลม Shopee เนื่องจากสินค้าไม่มี
A18: 16 | B18: DWA46 | C18: พจนี เกตุแก้ว | D18: line_oa | E18: noon | F18: EMS | G18: 03/10/2024 13:23 | H18: 0 | I18: JB087515832TH | J18: 17 | K18: ของเคลม LAZADA ไม่ทราบเหตุผล | L18: เคลมเนื่องจากสินค้าลูกค้าซีนแตก | N18: ของเคลม Shopee ไม่ทราบเหตุผล
A19: 17 | B19: DWD16 | C19: คุณกมลรัตน์ เส็งวงศ์ | D19: line | E19: Ann Kamonrat | F19: EMS | G19: 03/10/2024 22:57 | H19: 0 | I19: JB087758026TH | J19: 17 | K19: ของเคลม LAZADA ไม่ทราบเหตุผล | N19: ของเคลม Line OA เนื่องจากลูกค้าได้รับสินค้าไม่ครบ | O19: 4
A20: 18 | B20: DWD44 | C20: นุสรา เลาหพิบูลรัตนา | D20: Lazada | F20: Kerry_dropoff | G20: 04/10/2024 01:27 | H20: 0 | I20: LEXPU0402566384 | J20: 17 | K20: ของเคลม LAZADA ไม่ทราบเหตุผล | N20: ของเคลม Line OA เนื่องจากลูกค้าได้รับสินค้าผิดไม่ตรงตามที่สั่ง
A21: 19 | B21: DWD51 | C21: นุสรา | D21: Lazada | F21: Kerry_dropoff | G21: 04/10/2024 04:27 | H21: 0 | I21: LEXPU0402566834 | J21: 17 | K21: ของเคลม LAZADA ไม่ทราบเหตุผล | N21: ของเคลม Line OA เนื่องจากลูกค้าไม่ได้รับสินค้า
A22: 20 | B22: DWE3 | C22: คุณจิรัชญา นัยธนิช | D22: facebook | F22: EMS | G22: 04/10/2024 11:15 | H22: 0 | I22: JB087758043TH | J22: 17 | K22: ของเคลม Shopee เนื่องจากสินค้ามีรสชาติขม รสชาติ สีของขนม ผิดปกติ | L22: หมายเลขคำสั่งซื้อ 240907B9D7UB5P 📍เคลมช็อปปี้ เคลมเพราะตัวสินค้ายังไม่หมดอายุแต่มีรสชาติเปรี้ยวและบูดค่ะ | N22: ของเคลม Line OA เนื่องจากสินค้าเสียหายจากการขนส่ง | O22: 3
A23: 21 | B23: DWE4 | C23: รุ่งตะวัน กาญจนศิลป์ | D23: facebook | F23: EMS | G23: 04/10/2024 11:16 | H23: 0 | I23: JB087758065TH | J23: 17 | K23: ของเคลม Shopee เนื่องจากสินค้ามีรสชาติขม รสชาติ สีของขนม ผิดปกติ | L23: หมายเลขคำสั่งซื้อ 240817HF11XP81📍เคลมช็อปปี้ ขาดครีมฮอร์น | N23: ของเคลม Line OA เนื่องจากสินค้าเน่าเสียก่อนวันหมดอายุที่แจ้งข้างกล่อง
A24: 22 | B24: DWJ46 | C24: ศกวรรณ กฤตเวทิน | D24: facebook | E24: Aree Kongcompomg | F24: EMS | G24: 05/10/2024 14:23 | H24: 0 | I24: JB087946449TH | J24: 17 | K24: ของเคลม Facebook , Facebook Live เนื่องจากลูกค้าได้รับสินค้าไม่ครบ | L24: **เคลมของขาดส่ง | N24: ของเคลม Line OA เนื่องจากสินค้ามีรสชาติขม รสชาติ สีของขนม ผิดปกติ
A25: 23 | B25: DWM53 | C25: น.ส.อังคณา คุณเทียน | D25: line_oa | E25: NAJA | F25: EMS | G25: 06/10/2024 12:18 | H25: 0 | I25: JB088115765TH | J25: 17 | K25: ของเคลม Line OA เนื่องจากลูกค้าได้รับสินค้าไม่ครบ | L25: เคลมสินค้าสินค้าเสีย | N25: ของเคลม Line OA เนื่องจากสินค้าไม่มี
A26: 24 | B26: DWM74 | C26: นรินทร น้ำแก้ว | D26: line_oa | E26: ตุ้ยนุ้ยค่ะ | F26: EMS | G26: 06/10/2024 13:22 | H26: 0 | I26: JB088107018TH | J26: 17 | K26: ของเคลม Line OA เนื่องจากลูกค้าได้รับสินค้าไม่ครบ | L26: เคลมส่งของผิด | N26: ของเคลม Line OA ไม่ทราบเหตุผล
A27: 25 | B27: DWN34 | C27: คุณณิชานาฏ ศรัทธากุล | D27: facebook | F27: EMS | G27: 06/10/2024 15:34 | H27: 0 | I27: JB088106525TH | J27: 17 | K27: ของเคลม Shopee เนื่องจากลูกค้าได้รับสินค้าไม่ครบ | L27: เคลม ช็อปปี้241004KN5VGUNE ส่งสินค้าไม่ครบ | N27: ของเคลม Facebook , Facebook Live เนื่องจากลูกค้าได้รับสินค้าไม่ครบ | O27: 4
A28: 26 | B28: DWO95 | C28: อัจฉราภรณ์ สุขประเสริฐ | D28: LINE_OA | E28: สิทธิ์&แนน | F28: EMS | G28: 06/10/2024 22:53 | H28: 0 | I28: JB088105312TH | J28: 17 | K28: ของเคลม Line OA เนื่องจากสินค้าเสียหายจากการขนส่ง | L28: **สินค้าเคลมกล่องแตก** | N28: ของเคลม Facebook , Facebook Live เนื่องจากลูกค้าได้รับสินค้าผิดไม่ตรงตามที่สั่ง | O28: 5
A29: 27 | B29: DXA73 | C29: ศิรดา ทิ้งมิตรชั่ว | D29: line_oa | E29: lolxvip_CU | F29: EMS | G29: 09/10/2024 16:34 | H29: 0 | I29: JB088837555TH | J29: 17 | K29: ของเคลม Line OA เนื่องจากสินค้าเสียหายจากการขนส่ง | L29: เคลมเนื่องจากสินค้าเสียหาย | N29: ของเคลม Facebook , Facebook Live เนื่องจากลูกค้าไม่ได้รับสินค้า
A30: 28 | B30: DXA74 | C30: ธีรดา เนื้อมี | D30: line_oa | E30: Teerada | F30: EMS | G30: 09/10/2024 16:36 | H30: 0 | I30: JB088837564TH | J30: 17 | K30: ของเคลม Line OA เนื่องจากสินค้าเสียหายจากการขนส่ง | L30: เคลลมเนื่องจากสินค้าเสียหายเลขคำสั่งซื้อ 579428871394265686 | N30: ของเคลม Facebook , Facebook Live เนื่องจากสินค้าเสียหายจากการขนส่ง | O30: 1
A31: 29 | B31: DXD13 | C31: ปุ๊กปิ๊ก-SaiEaw | D31: Lazada | F31: Kerry_dropoff | G31: 09/10/2024 22:51 | H31: 0 | I31: LEXPU0405163443 | J31: 17 | K31: ของเคลม LAZADA ไม่ทราบเหตุผล | N31: ของเคลม Facebook , Facebook Live เนื่องจากสินค้าเน่าเสียก่อนวันหมดอายุที่แจ้งข้างกล่อง
A32: 30 | B32: DXD43 | C32: ปุ๊กปิ๊ก-SaiEaw | D32: Lazada | F32: Kerry_dropoff | G32: 09/10/2024 23:48 | H32: 0 | I32: LEXPU0405215321 | J32: 17 | K32: ของเคลม LAZADA ไม่ทราบเหตุผล | N32: ของเคลม Facebook , Facebook Live เนื่องจากสินค้ามีรสชาติขม รสชาติ สีของขนม ผิดปกติ
A33: 31 | B33: DXD98 | C33: อรจิรา | D33: Lazada | F33: Kerry_dropoff | G33: 10/10/2024 02:53 | H33: 0 | I33: LEXDO0115601688 | J33: 17 | K33: ของเคลม LAZADA ไม่ทราบเหตุผล | N33: ของเคลม Facebook , Facebook Live เนื่องจากสินค้าไม่มี
A34: 32 | B34: DXE89 | C34: ปิยะฉัตร มิเถาวัลย์ | D34: line | E34: ปิยะฉัตร มิเถาวัลย์ | F34: EMS | G34: 10/10/2024 09:07 | H34: 0 | I34: JB088985510TH | J34: 22 | K34: ของเคลม Tiktok เนื่องจากลูกค้าได้รับสินค้าไม่ครบ | L34: ***เคลมสินค้าขาดส่งจากติ๊กต๊อก ** | N34: ของเคลม Facebook , Facebook Live ไม่ทราบเหตุผล
A35: 33 | B35: DXE98 | C35: กาญจนา หลาบงาม | D35: Lazada | F35: Kerry_dropoff | G35: 10/10/2024 09:33 | H35: 0 | I35: LEXPU0406037110 | J35: 17 | K35: ของเคลม LAZADA ไม่ทราบเหตุผล | N35: ของเคลม Tiktok เนื่องจากลูกค้าได้รับสินค้าไม่ครบ | O35: 8
A36: 34 | B36: DXF1 | C36: กาญจนา หลาบงาม | D36: Lazada | F36: Kerry_dropoff | G36: 10/10/2024 09:36 | H36: 0 | I36: LEXPU0405957380 | J36: 17 | K36: ของเคลม LAZADA ไม่ทราบเหตุผล | N36: ของเคลม Tiktok เนื่องจากลูกค้าได้รับสินค้าผิดไม่ตรงตามที่สั่ง
A37: 35 | B37: DXF2 | C37: Third-Party-User | D37: Lazada | F37: Kerry_dropoff | G37: 10/10/2024 09:38 | H37: 0 | I37: TH660668HERD0A | J37: 17 | K37: ของเคลม LAZADA ไม่ทราบเหตุผล | N37: ของเคลม Tiktok เนื่องจากลูกค้าไม่ได้รับสินค้า
A38: 36 | B38: DXG60 | C38: คุณกิตติกา เปรินกุล | D38: facebook | E38: Kittika Peringul | F38: EMS | G38: 10/10/2024 12:45 | H38: 0 | I38: JB088985695TH | J38: 17 | K38: ของเคลม Facebook , Facebook Live เนื่องจากลูกค้าได้รับสินค้าไม่ครบ | L38: เคลมเนื่ิองจากลูกค้าได้ของไม่ครบ DQD62 | N38: ของเคลม TikTok เนื่องจากสินค้าเสียหายจากการขนส่ง
A39: 37 | B39: DXH11 | C39: สาวาลี เพียงชัยภูมิ | D39: facebook | E39: Sawalee Phangchaiyaphum | F39: EMS | G39: 10/10/2024 13:24 | H39: 0 | I39: JB088985775TH | J39: 17 | K39: ของเคลม Facebook , Facebook Live เนื่องจากลูกค้าได้รับสินค้าไม่ครบ | L39: เคลมเนื่องจากลูกค้าได้ของไม่ครบDWW91 | N39: ของเคลม TikTok เนื่องจากสินค้าเน่าเสียก่อนวันหมดอายุที่แจ้งข้างกล่อง
A40: 38 | B40: DXH55 | C40: Lazchoice | D40: other | E40: Lazchoice | F40: EMS | G40: 10/10/2024 14:14 | H40: 0 | I40: LBX024766762537572 | J40: 17 | K40: ของเคลม LAZADA ไม่ทราบเหตุผล | N40: ของเคลม Tiktok เนื่องจากสินค้ามีรสชาติขม รสชาติ สีของขนม ผิดปกติ
...

Sheet ต.ค. ยกเลิก
A1: สรุปรายการยกเลิกออเดอร์ ที่ออกเลขที่ออเดอร์แล้ว (เนื่องจากลูกค้าเอฟในไลฟ์สดแล้วไม่ยืนยันออเดอร์) เดือนตุลาคม 2567
A2: ลำดับ | B2: เลขที่ออเดอร์ | C2: ชื่อ | D2: ช่องทางติดต่อ | E2: ชื่อตามช่องทางติดต่อ | F2: ขนส่ง | G2: วันที่สร้าง | H2: ยอดขาย | I2: หมายเหตุ
A3: 1 | B3: DWM51 | C3: อ******์ | D3: Shopee | E3: mim_thi | G3: 06/10/2024 12:08 | H3: 22 | I3: สรุปออเดอร์แล้ว ลูกค้ายกเลิก
A4: 2 | B4: DWM87 | D4: Facebook Live | E4: Namrin Namrin | F4: EMS | G4: 06/10/2024 13:43 | H4: 120 | I4: สรุปออเดอร์แล้ว ลูกค้ายกเลิก
A5: 3 | B5: DWN36 | C5: ก***า โ***กราน | D5: Tiktok | E5: 7493994627956508228 | F5: J&T Express | G5: 06/10/2024 15:50 | H5: 106 | I5: สรุปออเดอร์แล้ว ลูกค้ายกเลิก
A6: 4 | B6: DWN44 | C6: ส***ตรี เ***งประยูร | D6: Tiktok | E6: 7493990576149136878 | F6: J&T Express | G6: 06/10/2024 16:24 | H6: 106 | I6: สรุปออเดอร์แล้ว ลูกค้ายกเลิก
A7: 5 | B7: DWO36 | C7: เบนซ์ (โทรหาก่อนนะคะ รบกวนด้วยค่ะ) | D7: Lazada | F7: Kerry_dropoff | G7: 06/10/2024 20:33 | H7: 102.5 | I7: สรุปออเดอร์แล้ว ลูกค้ายกเลิก
A8: 6 | B8: DWO54 | C8: น******น | D8: Shopee | E8: som1699 | G8: 06/10/2024 21:16 | H8: 230 | I8: สรุปออเดอร์แล้ว ลูกค้ายกเลิก
A9: 7 | B9: DWO61 | C9: จ******น | D9: Shopee | E9: puerd9l5vd | G9: 06/10/2024 21:21 | H9: 102 | I9: สรุปออเดอร์แล้ว ลูกค้ายกเลิก
A10: 8 | B10: DWW67 | C10: ส***ธนา ป***ทองคำ | D10: Tiktok | E10: 7494050329082499060 | F10: J&T Express | G10: 08/10/2024 20:38 | H10: 200 | I10: สรุปออเดอร์แล้ว ลูกค้ายกเลิก
A11: 9 | B11: DXZ15 | C11: ค***เบม | D11: Tiktok | E11: 7494020781218956580 | F11: J&T Express | G11: 13/10/2024 12:43 | H11: 106 | I11: สรุปออเดอร์แล้ว ลูกค้ายกเลิก
A12: 10 | B12: DXZ30 | C12: Plawan | D12: Lazada | F12: Kerry_dropoff | G12: 13/10/2024 13:05 | H12: 162.1 | I12: สรุปออเดอร์แล้ว ลูกค้ายกเลิก
A13: 11 | B13: DYA19 | C13: K เ***ล | D13: Tiktok | E13: 7495358982934727178 | F13: J&T Express | G13: 13/10/2024 14:18 | H13: 145 | I13: สรุปออเดอร์แล้ว ลูกค้ายกเลิก
A14: 12 | B14: DYA58 | C14: ว***ช ต***แก้ว | D14: Tiktok | E14: 7494660609183025848 | F14: J&T Express | G14: 13/10/2024 15:01 | H14: 106 | I14: สรุปออเดอร์แล้ว ลูกค้ายกเลิก
A15: 13 | B15: DYA90 | C15: supawanpearpear | D15: Lazada | F15: Kerry_dropoff | G15: 13/10/2024 15:25 | H15: 1074 | I15: สรุปออเดอร์แล้ว ลูกค้ายกเลิก
A16: 14 | B16: DYB56 | C16: อ***ยา ด***คกสูง | D16: Tiktok | E16: 7494007083455317750 | F16: J&T Express | G16: 13/10/2024 16:07 | H16: 106 | I16: สรุปออเดอร์แล้ว ลูกค้ายกเลิก
A17: 15 | B17: DYC91 | C17: ต***น | D17: Tiktok | E17: 7495880332428544057 | F17: J&T Express | G17: 13/10/2024 17:34 | H17: 145 | I17: สรุปออเดอร์แล้ว ลูกค้ายกเลิก
A18: 16 | B18: DYD15 | C18: อ***า | D18: Tiktok | E18: 7494036498816075387 | F18: J&T Express | G18: 13/10/2024 17:59 | H18: 106 | I18: สรุปออเดอร์แล้ว ลูกค้ายกเลิก
A19: 17 | B19: DYE20 | C19: คุณอนิษา คงดำ | D19: line | E19: Jibani💕 | F19: EMS | G19: 13/10/2024 20:02 | H19: 0 | I19: ***เคลมสินค้าขาดส่งจากติ๊กต๊อก **
A20: 18 | B20: DYE24 | C20: อ*** ส***สิงห์ | D20: Tiktok | E20: 7495064757439859221 | F20: J&T Express | G20: 13/10/2024 20:07 | H20: 100 | I20: สรุปออเดอร์แล้ว ลูกค้ายกเลิก
A21: 19 | B21: DYE33 | C21: เมรีญา ซอเซ็น | D21: facebook | E21: Meriya Sosen | F21: EMS COD | G21: 13/10/2024 20:21 | H21: 130 | I21: สรุปออเดอร์แล้ว ลูกค้ายกเลิก
A22: 20 | B22: DYF3 | C22: ก***นา เ***งอนันต์ | D22: Tiktok | E22: 7494787739012467638 | F22: J&T Express | G22: 13/10/2024 21:39 | H22: 106 | I22: สรุปออเดอร์แล้ว ลูกค้ายกเลิก
A23: 21 | B23: DYF44 | C23: น***ต | D23: Shopee | E23: rut9169 | G23: 13/10/2024 22:55 | H23: 60 | I23: สรุปออเดอร์แล้ว ลูกค้ายกเลิก
A24: 22 | B24: EAK34 | C24: ศ******น | D24: Shopee | E24: aoqkt65r5s | G24: 22/10/2024 18:14 | H24: 78 | I24: สรุปออเดอร์แล้ว ลูกค้ายกเลิก
A25: 23 | B25: EAK38 | C25: ป******ะ | D25: Shopee | E25: b33ejkilx7 | G25: 22/10/2024 18:27 | H25: 78 | I25: สรุปออเดอร์แล้ว ลูกค้ายกเลิก
A26: 24 | B26: EAK61 | C26: ก******้ | D26: Shopee | E26: kandapakky | G26: 22/10/2024 20:16 | H26: 214 | I26: สรุปออเดอร์แล้ว ลูกค้ายกเลิก
A27: 25 | B27: EAK64 | C27: ศ******น | D27: Shopee | E27: aoqkt65r5s | G27: 22/10/2024 20:21 | H27: 500 | I27: สรุปออเดอร์แล้ว ลูกค้ายกเลิก
A28: 26 | B28: EAK66 | C28: จ******ฐ | D28: Shopee | E28: thajorn | G28: 22/10/2024 20:23 | H28: 40 | I28: สรุปออเดอร์แล้ว ลูกค้ายกเลิก
A29: 27 | B29: EAK70 | C29: ธ***รณ เ***ร์กูล | D29: Tiktok | E29: 7494216766075079186 | F29: J&T Express | G29: 22/10/2024 20:47 | H29: 96 | I29: สรุปออเดอร์แล้ว ลูกค้ายกเลิก
A30: 28 | B30: EAK86 | C30: ท******ุ | D30: Shopee | E30: popier6104 | G30: 22/10/2024 22:15 | H30: 47 | I30: สรุปออเดอร์แล้ว ลูกค้ายกเลิก | M30: 0 | N30: 900801206010597
A31: 29 | B31: EAL93 | C31: ก******์ | D31: Shopee | E31: tarapark | G31: 23/10/2024 14:26 | H31: 319 | I31: สรุปออเดอร์แล้ว ลูกค้ายกเลิก | M31: 0 | N31: 906815728009721
A32: 30 | B32: EAM36 | C32: จ***้ | D32: Tiktok | E32: 7494052301448449476 | F32: J&T Express | G32: 23/10/2024 16:19 | H32: 100 | I32: สรุปออเดอร์แล้ว ลูกค้ายกเลิก | M32: 0 | N32: 579242639958051041
A33: 31 | B33: EAM77 | C33: ว***ิสาข์ อ***เหว่า | D33: Tiktok | E33: 7494035221167179571 | F33: J&T Express | G33: 23/10/2024 16:34 | H33: 106 | I33: สรุปออเดอร์แล้ว ลูกค้ายกเลิก | M33: 0 | N33: 579242905526438911
A34: 32 | B34: EAM98 | C34: ก******) | D34: Shopee | E34: kwangsk13 | G34: 23/10/2024 16:48 | H34: 245 | I34: สรุปออเดอร์แล้ว ลูกค้ายกเลิก | M34: 0 | N34: 579243224466492155
A35: 32 | B35: EAN60 | C35: ณ***ุดา ป***โปร่ง | D35: Tiktok | E35: 7494016060015871172 | F35: J&T Express | G35: 23/10/2024 17:58 | H35: 106 | I35: สรุปออเดอร์แล้ว ลูกค้ายกเลิก | M35: 0 | N35: 579243224846732027
A36: 32 | B36: EAO63 | C36: ส******์ | D36: Shopee | E36: sutharat.w | G36: 23/10/2024 21:25 | H36: 227 | I36: สรุปออเดอร์แล้ว ลูกค้ายกเลิก | M36: 0 | N36: 579243248210118704
A37: 32 | B37: EAO78 | C37: ก** | D37: Tiktok | E37: 7495883405345065251 | F37: J&T Express | G37: 23/10/2024 22:07 | H37: 125 | I37: สรุปออเดอร์แล้ว ลูกค้ายกเลิก | M37: 0 | N37: 901053020741847
A38: 33 | B38: EAZ20 | C38: อมรรัตน์ มะธิปะ | D38: Lazada | F38: Kerry_dropoff | G38: 26/10/2024 22:01 | H38: 57.38 | I38: สรุปออเดอร์แล้ว ลูกค้ายกเลิก
A39: 34 | B39: EBJ14 | C39: ด***นตร ส***ินดี | D39: Tiktok | E39: 7495478486544845528 | F39: J&T Express | G39: 28/10/2024 13:34 | H39: 189 | I39: สรุปออเดอร์แล้ว ลูกค้ายกเลิก
A40: 35 | B40: EBJ49 | C40: ป***ี แ***ฤาชัย ค***อ | D40: Tiktok | E40: 7494981886424156470 | F40: J&T Express | G40: 28/10/2024 14:32 | H40: 600 | I40: สรุปออเดอร์แล้ว ลูกค้ายกเลิก
...

Sheet ก.ย. เคลม
A1: สรุปรายการส่งของเคลมสินค้า เดือนกันยายน 2567
A2: ลำดับ | B2: เลขที่ออเดอร์ | C2: ชื่อ | D2: ช่องทางติดต่อ | E2: ชื่อตามช่องทางติดต่อ | F2: ขนส่ง | G2: วันที่สร้าง | H2: ยอดขาย | I2: เลขพัสดุ | J2: ค่าขนส่ง | K2: หมายเหตุ | L2: หมายเหตุ | N2: รายการ | O2: จำนวนออเดอร์
A3: 1 | B3: DPH82 | C3: พิไลวรรณ ทองจันทร์ | D3: facebook | F3: EMS | G3: 01/09/2024 10:39 | H3: 0 | I3: JB056318276TH | J3: 22 | K3: ของเคลม Tiktok เนื่องจากลูกค้าได้รับสินค้าไม่ครบ | L3: ‼️‼️เคลม ลูกค้า ตต. ของไม่ครบ‼️‼️ | N3: ของเคลม LAZADA เนื่องจากลูกค้าได้รับสินค้าไม่ครบ | O3: 1
A4: 2 | B4: DPH85 | C4: กรรณิกา หอมทอง | D4: facebook | F4: EMS | G4: 01/09/2024 10:40 | H4: 0 | I4: JB056318280TH | J4: 22 | K4: ของเคลม Tiktok เนื่องจากลูกค้าได้รับสินค้าไม่ครบ | L4: เคลมติ๊กต๊อก ส่งของไม่ครบ | N4: ของเคลม LAZADA เนื่องจากลูกค้าได้รับสินค้าผิดไม่ตรงตามที่สั่ง
A5: 3 | B5: DPJ92 | C5: ภาฝัน วันลักษณ์ | D5: facebook | F5: EMS | G5: 01/09/2024 14:40 | H5: 0 | I5: JB056318355TH | J5: 17 | K5: ของเคลม Tiktok เนื่องจากลูกค้าได้รับสินค้าไม่ครบ | L5: เคลมติ๊กต๊ิอก ส่งสินค้าไม่ครบ 579249743107688815 | N5: ของเคลม LAZADA เนื่องจากลูกค้าไม่ได้รับสินค้า
A6: 4 | B6: DPP55 | C6: เคลมติ๊กต๊อก | D6: facebook | F6: EMS | G6: 02/09/2024 13:25 | H6: 0 | I6: JB056599302TH | J6: 17 | K6: ของเคลม Tiktok เนื่องจากลูกค้าได้รับสินค้าไม่ครบ | L6: ติ๊กต่อกได้ของไม่ครบ | N6: ของเคลม LAZADA เนื่องจากสินค้าเสียหายจากการขนส่ง | O6: 4
A7: 5 | B7: DPP82 | C7: กนกรัตน์ | D7: facebook | F7: EMS | G7: 02/09/2024 14:03 | H7: 0 | I7: JB056599320TH | J7: 17 | K7: ของเคลม Tiktok เนื่องจากลูกค้าได้รับสินค้าไม่ครบ | L7: เคลมติ๊กต๊อก ส่งสินค้าไม่ครบ 579262315393419817 | N7: ของเคลม LAZADA เนื่องจากสินค้าเน่าเสียก่อนวันหมดอายุที่แจ้งข้างกล่อง
