Workbook

Sheet สรุป
A2: สรุป บูธ ลาดหลุมแก้ว วันที่ 1-29/02/2567
A3: ลำดับ | B3: รายการ | C3: ยกมา | D3: รับ | E3: รวม | F3: เปลี่ยน/ | G3: คงเหลือ | H3: รายการขาย | K3: หมายเหตุ | L3: วันที่ | M3: ยอดเงิน | N3: ส่วนลด | O3: สแกนใช้สิทธิ์ | P3: ค่าโอนเงิน | Q3: ค่าใช้จ่ายอื่นๆ | R3: โอนหน้าร้าน | S3: รับสุทธิ | T3: ยอดโอนเงิน | U3: โอนเกิน/โอนขาด
F4: คืน/เสีย | H4: จำนวน | I4: @ | J4: เป็นเงิน
A5: 1 | B5: ชิฟฟ่อน (ล) | C5: =+ยกมา!G4 -> 10 | D5: =+'11'!D4+'12'!D4+'13'!D4+'14'!D4+'15'!D4+'16'!D4+'17'!D4+'18'!D4 -> 30 | E5: =+C5+D5 -> 40 | F5: =+'11'!F4+'12'!F4+'13'!F4+'14'!F4+'15'!F4+'16'!F4+'17'!F4+'18'!F4 -> 0 | G5: =E5-F5-H5 -> 17 | H5: =+'11'!H4+'12'!H4+'13'!H4+'14'!H4+'15'!H4+'16'!H4+'17'!H4+'18'!H4 -> 23 | I5: 50 | J5: =+'11'!J4+'12'!J4+'13'!J4+'14'!J4+'15'!J4+'16'!J4+'17'!J4+'18'!J4 -> 1150 | L5: 1 | M5: 0 | N5: 0 | O5: 0 | P5: 0 | Q5: 0 | R5: 0 | S5: =+M5-N5-P5-R5-Q5 -> 0 | T5: 0 | U5: =+T5-S5 -> 0
A6: 2 | B6: ชิฟฟ่อน (ญ) | C6: =+ยกมา!G5 -> 5 | D6: =+'11'!D5+'12'!D5+'13'!D5+'14'!D5+'15'!D5+'16'!D5+'17'!D5+'18'!D5 -> 40 | E6: =+C6+D6 -> 45 | F6: =+'11'!F5+'12'!F5+'13'!F5+'14'!F5+'15'!F5+'16'!F5+'17'!F5+'18'!F5 -> 0 | G6: =E6-F6-H6 -> 28 | H6: =+'11'!H5+'12'!H5+'13'!H5+'14'!H5+'15'!H5+'16'!H5+'17'!H5+'18'!H5 -> 17 | I6: 100 | J6: =+'11'!J5+'12'!J5+'13'!J5+'14'!J5+'15'!J5+'16'!J5+'17'!J5+'18'!J5 -> 1700 | L6: 2 | M6: 0 | N6: 0 | O6: 0 | P6: 0 | Q6: 0 | R6: 0 | S6: =+M6-N6-P6-R6-Q6 -> 0 | T6: 0 | U6: =+T6-S6 -> 0
A7: 3 | B7: ชิฟฟ่อน (ล) กาแฟ | C7: =+ยกมา!G6 -> 0 | D7: =+'11'!D6+'12'!D6+'13'!D6+'14'!D6+'15'!D6+'16'!D6+'17'!D6+'18'!D6 -> 5 | E7: =+C7+D7 -> 5 | F7: =+'11'!F6+'12'!F6+'13'!F6+'14'!F6+'15'!F6+'16'!F6+'17'!F6+'18'!F6 -> 0 | G7: =E7-F7-H7 -> 4 | H7: =+'11'!H6+'12'!H6+'13'!H6+'14'!H6+'15'!H6+'16'!H6+'17'!H6+'18'!H6 -> 1 | I7: 50 | J7: =+'11'!J6+'12'!J6+'13'!J6+'14'!J6+'15'!J6+'16'!J6+'17'!J6+'18'!J6 -> 50 | L7: 3 | M7: 0 | N7: 0 | O7: 0 | P7: 0 | Q7: 0 | R7: 0 | S7: =+M7-N7-P7-R7-Q7 -> 0 | T7: 0 | U7: =+T7-S7 -> 0
A8: 4 | B8: ชิฟฟ่อน (ญ) กาแฟ | C8: =+ยกมา!G7 -> 0 | D8: =+'11'!D7+'12'!D7+'13'!D7+'14'!D7+'15'!D7+'16'!D7+'17'!D7+'18'!D7 -> 0 | E8: =+C8+D8 -> 0 | F8: =+'11'!F7+'12'!F7+'13'!F7+'14'!F7+'15'!F7+'16'!F7+'17'!F7+'18'!F7 -> 0 | G8: =E8-F8-H8 -> 0 | H8: =+'11'!H7+'12'!H7+'13'!H7+'14'!H7+'15'!H7+'16'!H7+'17'!H7+'18'!H7 -> 0 | I8: 100 | J8: =+'11'!J7+'12'!J7+'13'!J7+'14'!J7+'15'!J7+'16'!J7+'17'!J7+'18'!J7 -> 0 | L8: 4 | M8: 0 | N8: 0 | O8: 0 | P8: 0 | Q8: 0 | R8: 0 | S8: =+M8-N8-P8-R8-Q8 -> 0 | T8: 0 | U8: =+T8-S8 -> 0
A9: 5 | B9: ชิฟฟ่อนเค้ก 1 ชิ้น | C9: =+ยกมา!G8 -> 0 | D9: =+'11'!D8+'12'!D8+'13'!D8+'14'!D8+'15'!D8+'16'!D8+'17'!D8+'18'!D8 -> 0 | E9: =+C9+D9 -> 0 | F9: =+'11'!F8+'12'!F8+'13'!F8+'14'!F8+'15'!F8+'16'!F8+'17'!F8+'18'!F8 -> 0 | G9: =E9-F9-H9 -> 0 | H9: =+'11'!H8+'12'!H8+'13'!H8+'14'!H8+'15'!H8+'16'!H8+'17'!H8+'18'!H8 -> 0 | I9: 10 | J9: =+'11'!J8+'12'!J8+'13'!J8+'14'!J8+'15'!J8+'16'!J8+'17'!J8+'18'!J8 -> 0 | L9: 5 | M9: 0 | N9: 0 | O9: 0 | P9: 0 | Q9: 0 | R9: 0 | S9: =+M9-N9-P9-R9-Q9 -> 0 | T9: 0 | U9: =+T9-S9 -> 0
A10: 6 | B10: ชิฟฟ่อนเค้กสอดไส้แยม 1 ชิ้น | C10: =+ยกมา!G9 -> 0 | D10: =+'11'!D9+'12'!D9+'13'!D9+'14'!D9+'15'!D9+'16'!D9+'17'!D9+'18'!D9 -> 0 | E10: =+C10+D10 -> 0 | F10: =+'11'!F9+'12'!F9+'13'!F9+'14'!F9+'15'!F9+'16'!F9+'17'!F9+'18'!F9 -> 0 | G10: =E10-F10-H10 -> 0 | H10: =+'11'!H9+'12'!H9+'13'!H9+'14'!H9+'15'!H9+'16'!H9+'17'!H9+'18'!H9 -> 0 | I10: 12 | J10: =+'11'!J9+'12'!J9+'13'!J9+'14'!J9+'15'!J9+'16'!J9+'17'!J9+'18'!J9 -> 0 | L10: 6 | M10: 0 | N10: 0 | O10: 0 | P10: 0 | Q10: 0 | R10: 0 | S10: =+M10-N10-P10-R10-Q10 -> 0 | T10: 0 | U10: =+T10-S10 -> 0
A11: 7 | B11: ชิฟฟ่อน สอดไส้ (ล) 2 ชิ้น ครีมมะพร้าว | C11: =+ยกมา!G10 -> 0 | D11: =+'11'!D10+'12'!D10+'13'!D10+'14'!D10+'15'!D10+'16'!D10+'17'!D10+'18'!D10 -> 0 | E11: =+C11+D11 -> 0 | F11: =+'11'!F10+'12'!F10+'13'!F10+'14'!F10+'15'!F10+'16'!F10+'17'!F10+'18'!F10 -> 0 | G11: =E11-F11-H11 -> 0 | H11: =+'11'!H10+'12'!H10+'13'!H10+'14'!H10+'15'!H10+'16'!H10+'17'!H10+'18'!H10 -> 0 | I11: 40 | J11: =+'11'!J10+'12'!J10+'13'!J10+'14'!J10+'15'!J10+'16'!J10+'17'!J10+'18'!J10 -> 0 | L11: 7 | M11: 0 | N11: 0 | O11: 0 | P11: 0 | Q11: 0 | R11: 0 | S11: =+M11-N11-P11-R11-Q11 -> 0 | T11: 0 | U11: =+T11-S11 -> 0
A12: 8 | B12: ชิฟฟ่อน สอดไส้ (ล) 3 ชิ้น รวมรส | C12: =+ยกมา!G11 -> 0 | D12: =+'11'!D11+'12'!D11+'13'!D11+'14'!D11+'15'!D11+'16'!D11+'17'!D11+'18'!D11 -> 10 | E12: =+C12+D12 -> 10 | F12: =+'11'!F11+'12'!F11+'13'!F11+'14'!F11+'15'!F11+'16'!F11+'17'!F11+'18'!F11 -> 0 | G12: =E12-F12-H12 -> 3 | H12: =+'11'!H11+'12'!H11+'13'!H11+'14'!H11+'15'!H11+'16'!H11+'17'!H11+'18'!H11 -> 7 | I12: 50 | J12: =+'11'!J11+'12'!J11+'13'!J11+'14'!J11+'15'!J11+'16'!J11+'17'!J11+'18'!J11 -> 350 | L12: 8 | M12: 0 | N12: 0 | O12: 0 | P12: 0 | Q12: 0 | R12: 0 | S12: =+M12-N12-P12-R12-Q12 -> 0 | T12: 0 | U12: =+T12-S12 -> 0
A13: 9 | B13: ชิฟฟ่อน สอดไส้ (ล) 3 ชิ้น เมล่อน | C13: =+ยกมา!G12 -> 0 | D13: =+'11'!D12+'12'!D12+'13'!D12+'14'!D12+'15'!D12+'16'!D12+'17'!D12+'18'!D12 -> 0 | E13: =+C13+D13 -> 0 | F13: =+'11'!F12+'12'!F12+'13'!F12+'14'!F12+'15'!F12+'16'!F12+'17'!F12+'18'!F12 -> 0 | G13: =E13-F13-H13 -> 0 | H13: =+'11'!H12+'12'!H12+'13'!H12+'14'!H12+'15'!H12+'16'!H12+'17'!H12+'18'!H12 -> 0 | I13: 55 | J13: =+'11'!J12+'12'!J12+'13'!J12+'14'!J12+'15'!J12+'16'!J12+'17'!J12+'18'!J12 -> 0 | L13: 9 | M13: 0 | N13: 0 | O13: 0 | P13: 0 | Q13: 0 | R13: 0 | S13: =+M13-N13-P13-R13-Q13 -> 0 | T13: 0 | U13: =+T13-S13 -> 0
A14: 10 | B14: ชิฟฟ่อน สอดไส้ (ล) 4 ชิ้น ครีมมะพร้าว | C14: =+ยกมา!G13 -> 0 | D14: =+'11'!D13+'12'!D13+'13'!D13+'14'!D13+'15'!D13+'16'!D13+'17'!D13+'18'!D13 -> 0 | E14: =+C14+D14 -> 0 | F14: =+'11'!F13+'12'!F13+'13'!F13+'14'!F13+'15'!F13+'16'!F13+'17'!F13+'18'!F13 -> 0 | G14: =E14-F14-H14 -> 0 | H14: =+'11'!H13+'12'!H13+'13'!H13+'14'!H13+'15'!H13+'16'!H13+'17'!H13+'18'!H13 -> 0 | I14: 65 | J14: =+'11'!J13+'12'!J13+'13'!J13+'14'!J13+'15'!J13+'16'!J13+'17'!J13+'18'!J13 -> 0 | L14: 10 | M14: 0 | N14: 0 | O14: 0 | P14: 0 | Q14: 0 | R14: 0 | S14: =+M14-N14-P14-R14-Q14 -> 0 | T14: 0 | U14: =+T14-S14 -> 0
A15: 11 | B15: ชิฟฟ่อน สอดไส้ (ล) 3 ชิ้น แยมส้ม | C15: =+ยกมา!G14 -> 0 | D15: =+'11'!D14+'12'!D14+'13'!D14+'14'!D14+'15'!D14+'16'!D14+'17'!D14+'18'!D14 -> 5 | E15: =+C15+D15 -> 5 | F15: =+'11'!F14+'12'!F14+'13'!F14+'14'!F14+'15'!F14+'16'!F14+'17'!F14+'18'!F14 -> 0 | G15: =E15-F15-H15 -> 3 | H15: =+'11'!H14+'12'!H14+'13'!H14+'14'!H14+'15'!H14+'16'!H14+'17'!H14+'18'!H14 -> 2 | I15: 50 | J15: =+'11'!J14+'12'!J14+'13'!J14+'14'!J14+'15'!J14+'16'!J14+'17'!J14+'18'!J14 -> 100 | L15: 11 | M15: =+'11'!K206 -> 4695 | N15: =+'11'!K211 -> 295 | O15: =+'11'!K209 -> 0 | P15: =+'11'!K207 -> 15 | Q15: =+'11'!K210 -> 0 | R15: =+'11'!K208 -> 1550 | S15: =+M15-N15-P15-R15-Q15 -> 2835 | T15: =+'11'!K213 -> 1635 | U15: =+T15-S15 -> -1200 | V15: เงินทอน 1000
A16: 12 | B16: ชิฟฟ่อน สอดไส้ (ล) 3 ชิ้น บลูเบอรี่ | C16: =+ยกมา!G15 -> 0 | D16: =+'11'!D15+'12'!D15+'13'!D15+'14'!D15+'15'!D15+'16'!D15+'17'!D15+'18'!D15 -> 0 | E16: =+C16+D16 -> 0 | F16: =+'11'!F15+'12'!F15+'13'!F15+'14'!F15+'15'!F15+'16'!F15+'17'!F15+'18'!F15 -> 0 | G16: =E16-F16-H16 -> 0 | H16: =+'11'!H15+'12'!H15+'13'!H15+'14'!H15+'15'!H15+'16'!H15+'17'!H15+'18'!H15 -> 0 | I16: 50 | J16: =+'11'!J15+'12'!J15+'13'!J15+'14'!J15+'15'!J15+'16'!J15+'17'!J15+'18'!J15 -> 0 | L16: 12 | M16: =+'12'!K206 -> 2070 | N16: =+'12'!K211 -> 130 | O16: =+'12'!K209 -> 0 | P16: =+'12'!K207 -> 0 | Q16: =+'12'!K210 -> 0 | R16: =+'12'!K208 -> 835 | S16: =+M16-N16-P16-R16-Q16 -> 1105 | T16: =+'12'!K213 -> 1095 | U16: =+T16-S16 -> -10
A17: 13 | B17: ชิฟฟ่อน สอดไส้ (ล) 3 ชิ้น ฝอยทอง | C17: =+ยกมา!G16 -> 0 | D17: =+'11'!D16+'12'!D16+'13'!D16+'14'!D16+'15'!D16+'16'!D16+'17'!D16+'18'!D16 -> 3 | E17: =+C17+D17 -> 3 | F17: =+'11'!F16+'12'!F16+'13'!F16+'14'!F16+'15'!F16+'16'!F16+'17'!F16+'18'!F16 -> 0 | G17: =E17-F17-H17 -> 2 | H17: =+'11'!H16+'12'!H16+'13'!H16+'14'!H16+'15'!H16+'16'!H16+'17'!H16+'18'!H16 -> 1 | I17: 50 | J17: =+'11'!J16+'12'!J16+'13'!J16+'14'!J16+'15'!J16+'16'!J16+'17'!J16+'18'!J16 -> 50 | L17: 13 | M17: =+'13'!K206 -> 400 | N17: =+'13'!K211 -> 0 | O17: =+'13'!K209 -> 0 | P17: =+'13'!K207 -> 0 | Q17: =+'13'!K210 -> 0 | R17: =+'13'!K208 -> 0 | S17: =+M17-N17-P17-R17-Q17 -> 400 | T17: =+'13'!K213 -> 600 | U17: =+T17-S17 -> 200
A18: 14 | B18: ชิฟฟ่อน สอดไส้ (ล) 3 ชิ้น แยมสตรอเบอรี่ | C18: =+ยกมา!G17 -> 0 | D18: =+'11'!D17+'12'!D17+'13'!D17+'14'!D17+'15'!D17+'16'!D17+'17'!D17+'18'!D17 -> 0 | E18: =+C18+D18 -> 0 | F18: =+'11'!F17+'12'!F17+'13'!F17+'14'!F17+'15'!F17+'16'!F17+'17'!F17+'18'!F17 -> 0 | G18: =E18-F18-H18 -> 0 | H18: =+'11'!H17+'12'!H17+'13'!H17+'14'!H17+'15'!H17+'16'!H17+'17'!H17+'18'!H17 -> 0 | I18: 50 | J18: =+'11'!J17+'12'!J17+'13'!J17+'14'!J17+'15'!J17+'16'!J17+'17'!J17+'18'!J17 -> 0 | L18: 14 | M18: =+'14'!K206 -> 910 | N18: =+'14'!K211 -> 0 | O18: =+'14'!K209 -> 0 | P18: =+'14'!K207 -> 15 | Q18: =+'14'!K210 -> 0 | R18: =+'14'!K208 -> 450 | S18: =+M18-N18-P18-R18-Q18 -> 445 | T18: =+'14'!K213 -> 490 | U18: =+T18-S18 -> 45
A19: 15 | B19: ชิฟฟ่อน สอดไส้ (ล) 3 ชิ้น เนยมพะร้าว | C19: =+ยกมา!G18 -> 0 | D19: =+'11'!D18+'12'!D18+'13'!D18+'14'!D18+'15'!D18+'16'!D18+'17'!D18+'18'!D18 -> 10 | E19: =+C19+D19 -> 10 | F19: =+'11'!F18+'12'!F18+'13'!F18+'14'!F18+'15'!F18+'16'!F18+'17'!F18+'18'!F18 -> 0 | G19: =E19-F19-H19 -> 1 | H19: =+'11'!H18+'12'!H18+'13'!H18+'14'!H18+'15'!H18+'16'!H18+'17'!H18+'18'!H18 -> 9 | I19: 50 | J19: =+'11'!J18+'12'!J18+'13'!J18+'14'!J18+'15'!J18+'16'!J18+'17'!J18+'18'!J18 -> 450 | L19: 15 | M19: =+'15'!K206 -> 1400 | N19: =+'15'!K211 -> 0 | O19: =+'15'!K209 -> 0 | P19: =+'15'!K207 -> 15 | Q19: =+'15'!K210 -> 0 | R19: =+'15'!K208 -> 420 | S19: =+M19-N19-P19-R19-Q19 -> 965 | T19: =+'15'!K213 -> 880 | U19: =+T19-S19 -> -85
A20: 16 | B20: ชิฟฟ่อน สอดไส้ (ล) 3 ชิ้น นมชมพู | C20: =+ยกมา!G19 -> 0 | D20: =+'11'!D19+'12'!D19+'13'!D19+'14'!D19+'15'!D19+'16'!D19+'17'!D19+'18'!D19 -> 0 | E20: =+C20+D20 -> 0 | F20: =+'11'!F19+'12'!F19+'13'!F19+'14'!F19+'15'!F19+'16'!F19+'17'!F19+'18'!F19 -> 0 | G20: =E20-F20-H20 -> 0 | H20: =+'11'!H19+'12'!H19+'13'!H19+'14'!H19+'15'!H19+'16'!H19+'17'!H19+'18'!H19 -> 0 | I20: 50 | J20: =+'11'!J19+'12'!J19+'13'!J19+'14'!J19+'15'!J19+'16'!J19+'17'!J19+'18'!J19 -> 0 | L20: 16 | M20: =+'16'!K206 -> 600 | N20: =+'16'!K211 -> 0 | O20: =+'16'!K209 -> 0 | P20: =+'16'!K207 -> 15 | Q20: =+'16'!K210 -> 0 | R20: =+'16'!K208 -> 200 | S20: =+M20-N20-P20-R20-Q20 -> 385 | T20: =+'16'!K208 -> 200 | U20: =+T20-S20 -> -185
A21: 17 | B21: ชิฟฟ่อน สอดไส้ (ล) 3 ชิ้น ช็อคโกแลต | C21: =+ยกมา!G20 -> 0 | D21: =+'11'!D20+'12'!D20+'13'!D20+'14'!D20+'15'!D20+'16'!D20+'17'!D20+'18'!D20 -> 0 | E21: =+C21+D21 -> 0 | F21: =+'11'!F20+'12'!F20+'13'!F20+'14'!F20+'15'!F20+'16'!F20+'17'!F20+'18'!F20 -> 0 | G21: =E21-F21-H21 -> 0 | H21: =+'11'!H20+'12'!H20+'13'!H20+'14'!H20+'15'!H20+'16'!H20+'17'!H20+'18'!H20 -> 0 | I21: 50 | J21: =+'11'!J20+'12'!J20+'13'!J20+'14'!J20+'15'!J20+'16'!J20+'17'!J20+'18'!J20 -> 0 | L21: 17 | M21: =+'17'!K206 -> 1490 | N21: =+'17'!K211 -> 0 | O21: =+'17'!K209 -> 0 | P21: =+'17'!K207 -> 15 | Q21: =+'17'!K210 -> 0 | R21: =+'17'!K208 -> 550 | S21: =+M21-N21-P21-R21-Q21 -> 925 | T21: =+'17'!K213 -> 1010 | U21: =+T21-S21 -> 85
A22: 18 | B22: ชิฟฟ่อน สอดไส้ (ก) 5 ชิ้น | C22: =+ยกมา!G21 -> 0 | D22: =+'11'!D21+'12'!D21+'13'!D21+'14'!D21+'15'!D21+'16'!D21+'17'!D21+'18'!D21 -> 0 | E22: =+C22+D22 -> 0 | F22: =+'11'!F21+'12'!F21+'13'!F21+'14'!F21+'15'!F21+'16'!F21+'17'!F21+'18'!F21 -> 0 | G22: =E22-F22-H22 -> 0 | H22: =+'11'!H21+'12'!H21+'13'!H21+'14'!H21+'15'!H21+'16'!H21+'17'!H21+'18'!H21 -> 0 | I22: 85 | J22: =+'11'!J21+'12'!J21+'13'!J21+'14'!J21+'15'!J21+'16'!J21+'17'!J21+'18'!J21 -> 0 | L22: 18 | M22: =+'18'!K206 -> 3505 | N22: =+'18'!K211 -> 0 | O22: =+'18'!K209 -> 0 | P22: =+'18'!K207 -> 15 | Q22: =+'18'!K210 -> 0 | R22: =+'18'!K208 -> 1250 | S22: =+M22-N22-P22-R22-Q22 -> 2240 | T22: =+'18'!K213 -> 2240 | U22: =+T22-S22 -> 0
A23: 19 | B23: ชิฟฟ่อน สอดไส้ 6 ชิ้น รวมรส | C23: =+ยกมา!G22 -> 5 | D23: =+'11'!D22+'12'!D22+'13'!D22+'14'!D22+'15'!D22+'16'!D22+'17'!D22+'18'!D22 -> 25 | E23: =+C23+D23 -> 30 | F23: =+'11'!F22+'12'!F22+'13'!F22+'14'!F22+'15'!F22+'16'!F22+'17'!F22+'18'!F22 -> 0 | G23: =E23-F23-H23 -> 17 | H23: =+'11'!H22+'12'!H22+'13'!H22+'14'!H22+'15'!H22+'16'!H22+'17'!H22+'18'!H22 -> 13 | I23: 100 | J23: =+'11'!J22+'12'!J22+'13'!J22+'14'!J22+'15'!J22+'16'!J22+'17'!J22+'18'!J22 -> 1300 | L23: 19 | S23: =+M23-N23-P23-R23-Q23 -> 0 | U23: =+T23-S23 -> 0
A24: 20 | B24: ชิฟฟ่อน สอดไส้ 6 ชิ้น ฝอยทอง | C24: =+ยกมา!G23 -> 2 | D24: =+'11'!D23+'12'!D23+'13'!D23+'14'!D23+'15'!D23+'16'!D23+'17'!D23+'18'!D23 -> 7 | E24: =+C24+D24 -> 9 | F24: =+'11'!F23+'12'!F23+'13'!F23+'14'!F23+'15'!F23+'16'!F23+'17'!F23+'18'!F23 -> 0 | G24: =E24-F24-H24 -> 3 | H24: =+'11'!H23+'12'!H23+'13'!H23+'14'!H23+'15'!H23+'16'!H23+'17'!H23+'18'!H23 -> 6 | I24: 100 | J24: =+'11'!J23+'12'!J23+'13'!J23+'14'!J23+'15'!J23+'16'!J23+'17'!J23+'18'!J23 -> 600 | L24: 20 | S24: =+M24-N24-P24-R24-Q24 -> 0 | U24: =+T24-S24 -> 0
A25: 21 | B25: ชิฟฟ่อน สอดไส้ 6 ชิ้น ทูโทน | C25: =+ยกมา!G24 -> 0 | D25: =+'11'!D24+'12'!D24+'13'!D24+'14'!D24+'15'!D24+'16'!D24+'17'!D24+'18'!D24 -> 0 | E25: =+C25+D25 -> 0 | F25: =+'11'!F24+'12'!F24+'13'!F24+'14'!F24+'15'!F24+'16'!F24+'17'!F24+'18'!F24 -> 0 | G25: =E25-F25-H25 -> 0 | H25: =+'11'!H24+'12'!H24+'13'!H24+'14'!H24+'15'!H24+'16'!H24+'17'!H24+'18'!H24 -> 0 | I25: 100 | J25: =+'11'!J24+'12'!J24+'13'!J24+'14'!J24+'15'!J24+'16'!J24+'17'!J24+'18'!J24 -> 0 | L25: 21 | S25: =+M25-N25-P25-R25-Q25 -> 0 | U25: =+T25-S25 -> 0
A26: 22 | B26: ชิฟฟ่อน สอดไส้ 6 ชิ้น นมชมพู | C26: =+ยกมา!G25 -> 0 | D26: =+'11'!D25+'12'!D25+'13'!D25+'14'!D25+'15'!D25+'16'!D25+'17'!D25+'18'!D25 -> 4 | E26: =+C26+D26 -> 4 | F26: =+'11'!F25+'12'!F25+'13'!F25+'14'!F25+'15'!F25+'16'!F25+'17'!F25+'18'!F25 -> 0 | G26: =E26-F26-H26 -> 0 | H26: =+'11'!H25+'12'!H25+'13'!H25+'14'!H25+'15'!H25+'16'!H25+'17'!H25+'18'!H25 -> 4 | I26: 100 | J26: =+'11'!J25+'12'!J25+'13'!J25+'14'!J25+'15'!J25+'16'!J25+'17'!J25+'18'!J25 -> 400 | L26: 22 | S26: =+M26-N26-P26-R26-Q26 -> 0 | U26: =+T26-S26 -> 0
A27: 23 | B27: ชิฟฟ่อน สอดไส้ 6 ชิ้น บลูเบอรี่ | C27: =+ยกมา!G26 -> 2 | D27: =+'11'!D26+'12'!D26+'13'!D26+'14'!D26+'15'!D26+'16'!D26+'17'!D26+'18'!D26 -> 2 | E27: =+C27+D27 -> 4 | F27: =+'11'!F26+'12'!F26+'13'!F26+'14'!F26+'15'!F26+'16'!F26+'17'!F26+'18'!F26 -> 0 | G27: =E27-F27-H27 -> 3 | H27: =+'11'!H26+'12'!H26+'13'!H26+'14'!H26+'15'!H26+'16'!H26+'17'!H26+'18'!H26 -> 1 | I27: 100 | J27: =+'11'!J26+'12'!J26+'13'!J26+'14'!J26+'15'!J26+'16'!J26+'17'!J26+'18'!J26 -> 100 | L27: 23 | S27: =+M27-N27-P27-R27-Q27 -> 0 | U27: =+T27-S27 -> 0
A28: 24 | B28: ชิฟฟ่อน สอดไส้ 6 ชิ้น ช็อคโกแลต | C28: =+ยกมา!G27 -> 0 | D28: =+'11'!D27+'12'!D27+'13'!D27+'14'!D27+'15'!D27+'16'!D27+'17'!D27+'18'!D27 -> 0 | E28: =+C28+D28 -> 0 | F28: =+'11'!F27+'12'!F27+'13'!F27+'14'!F27+'15'!F27+'16'!F27+'17'!F27+'18'!F27 -> 0 | G28: =E28-F28-H28 -> 0 | H28: =+'11'!H27+'12'!H27+'13'!H27+'14'!H27+'15'!H27+'16'!H27+'17'!H27+'18'!H27 -> 0 | I28: 100 | J28: =+'11'!J27+'12'!J27+'13'!J27+'14'!J27+'15'!J27+'16'!J27+'17'!J27+'18'!J27 -> 0 | L28: 24 | S28: =+M28-N28-P28-R28-Q28 -> 0 | U28: =+T28-S28 -> 0
A29: 25 | B29: ชิฟฟ่อน สอดไส้ 6 ชิ้น มะพร้าว | C29: =+ยกมา!G28 -> 3 | D29: =+'11'!D28+'12'!D28+'13'!D28+'14'!D28+'15'!D28+'16'!D28+'17'!D28+'18'!D28 -> 10 | E29: =+C29+D29 -> 13 | F29: =+'11'!F28+'12'!F28+'13'!F28+'14'!F28+'15'!F28+'16'!F28+'17'!F28+'18'!F28 -> 0 | G29: =E29-F29-H29 -> 11 | H29: =+'11'!H28+'12'!H28+'13'!H28+'14'!H28+'15'!H28+'16'!H28+'17'!H28+'18'!H28 -> 2 | I29: 100 | J29: =+'11'!J28+'12'!J28+'13'!J28+'14'!J28+'15'!J28+'16'!J28+'17'!J28+'18'!J28 -> 200 | L29: 25 | S29: =+M29-N29-P29-R29-Q29 -> 0 | U29: =+T29-S29 -> 0
A30: 26 | B30: ชิฟฟ่อน สอดไส้ 6 ชิ้น ส้ม | C30: =+ยกมา!G29 -> 2 | D30: =+'11'!D29+'12'!D29+'13'!D29+'14'!D29+'15'!D29+'16'!D29+'17'!D29+'18'!D29 -> 0 | E30: =+C30+D30 -> 2 | F30: =+'11'!F29+'12'!F29+'13'!F29+'14'!F29+'15'!F29+'16'!F29+'17'!F29+'18'!F29 -> 0 | G30: =E30-F30-H30 -> 0 | H30: =+'11'!H29+'12'!H29+'13'!H29+'14'!H29+'15'!H29+'16'!H29+'17'!H29+'18'!H29 -> 2 | I30: 100 | J30: =+'11'!J29+'12'!J29+'13'!J29+'14'!J29+'15'!J29+'16'!J29+'17'!J29+'18'!J29 -> 200 | L30: 26 | S30: =+M30-N30-P30-R30-Q30 -> 0 | U30: =+T30-S30 -> 0
A31: 27 | B31: ชิฟฟ่อน สอดไส้ 6 ชิ้น สตรอเบอรี่ | C31: =+ยกมา!G30 -> 2 | D31: =+'11'!D30+'12'!D30+'13'!D30+'14'!D30+'15'!D30+'16'!D30+'17'!D30+'18'!D30 -> 2 | E31: =+C31+D31 -> 4 | F31: =+'11'!F30+'12'!F30+'13'!F30+'14'!F30+'15'!F30+'16'!F30+'17'!F30+'18'!F30 -> 0 | G31: =E31-F31-H31 -> 3 | H31: =+'11'!H30+'12'!H30+'13'!H30+'14'!H30+'15'!H30+'16'!H30+'17'!H30+'18'!H30 -> 1 | I31: 100 | J31: =+'11'!J30+'12'!J30+'13'!J30+'14'!J30+'15'!J30+'16'!J30+'17'!J30+'18'!J30 -> 100 | L31: 27 | S31: =+M31-N31-P31-R31-Q31 -> 0 | U31: =+T31-S31 -> 0
A32: 28 | B32: ชิฟฟ่อน สอดไส้ (ญ) 8 ชิ้น ใบเตย | C32: =+ยกมา!G31 -> 0 | D32: =+'11'!D31+'12'!D31+'13'!D31+'14'!D31+'15'!D31+'16'!D31+'17'!D31+'18'!D31 -> 0 | E32: =+C32+D32 -> 0 | F32: =+'11'!F31+'12'!F31+'13'!F31+'14'!F31+'15'!F31+'16'!F31+'17'!F31+'18'!F31 -> 0 | G32: =E32-F32-H32 -> 0 | H32: =+'11'!H31+'12'!H31+'13'!H31+'14'!H31+'15'!H31+'16'!H31+'17'!H31+'18'!H31 -> 0 | I32: 130 | J32: =+'11'!J31+'12'!J31+'13'!J31+'14'!J31+'15'!J31+'16'!J31+'17'!J31+'18'!J31 -> 0 | L32: 28 | S32: =+M32-N32-P32-R32-Q32 -> 0 | U32: =+T32-S32 -> 0
A33: 29 | B33: ชิฟฟ่อน สอดไส้ (ญ) 8 ชิ้น ทูโทนใบเตย | C33: =+ยกมา!G32 -> 0 | D33: =+'11'!D32+'12'!D32+'13'!D32+'14'!D32+'15'!D32+'16'!D32+'17'!D32+'18'!D32 -> 0 | E33: =+C33+D33 -> 0 | F33: =+'11'!F32+'12'!F32+'13'!F32+'14'!F32+'15'!F32+'16'!F32+'17'!F32+'18'!F32 -> 0 | G33: =E33-F33-H33 -> 0 | H33: =+'11'!H32+'12'!H32+'13'!H32+'14'!H32+'15'!H32+'16'!H32+'17'!H32+'18'!H32 -> 0 | I33: 130 | J33: =+'11'!J32+'12'!J32+'13'!J32+'14'!J32+'15'!J32+'16'!J32+'17'!J32+'18'!J32 -> 0 | L33: 29 | S33: =+M33-N33-P33-R33-Q33 -> 0 | U33: =+T33-S33 -> 0
A34: 30 | B34: ชิฟฟ่อน สอดไส้ (ญ) 8 ชิ้น รวมรส | C34: =+ยกมา!G33 -> 0 | D34: =+'11'!D33+'12'!D33+'13'!D33+'14'!D33+'15'!D33+'16'!D33+'17'!D33+'18'!D33 -> 0 | E34: =+C34+D34 -> 0 | F34: =+'11'!F33+'12'!F33+'13'!F33+'14'!F33+'15'!F33+'16'!F33+'17'!F33+'18'!F33 -> 0 | G34: =E34-F34-H34 -> 0 | H34: =+'11'!H33+'12'!H33+'13'!H33+'14'!H33+'15'!H33+'16'!H33+'17'!H33+'18'!H33 -> 0 | I34: 130 | J34: =+'11'!J33+'12'!J33+'13'!J33+'14'!J33+'15'!J33+'16'!J33+'17'!J33+'18'!J33 -> 0 | L34: 30 | S34: =+M34-N34-P34-R34-Q34 -> 0 | U34: =+T34-S34 -> 0
A35: 31 | B35: ชิฟฟ่อน สอดไส้ (ญ) 8 ชิ้น มะพร้าว | C35: =+ยกมา!G34 -> 0 | D35: =+'11'!D34+'12'!D34+'13'!D34+'14'!D34+'15'!D34+'16'!D34+'17'!D34+'18'!D34 -> 5 | E35: =+C35+D35 -> 5 | F35: =+'11'!F34+'12'!F34+'13'!F34+'14'!F34+'15'!F34+'16'!F34+'17'!F34+'18'!F34 -> 0 | G35: =E35-F35-H35 -> 1 | H35: =+'11'!H34+'12'!H34+'13'!H34+'14'!H34+'15'!H34+'16'!H34+'17'!H34+'18'!H34 -> 4 | I35: 130 | J35: =+'11'!J34+'12'!J34+'13'!J34+'14'!J34+'15'!J34+'16'!J34+'17'!J34+'18'!J34 -> 520 | L35: 31 | S35: =+M35-N35-P35-R35-Q35 -> 0 | U35: =+T35-S35 -> 0
A36: 32 | B36: ชิฟฟ่อน 8 ชิ้น มะลิ | C36: =+ยกมา!G35 -> 0 | D36: =+'11'!D35+'12'!D35+'13'!D35+'14'!D35+'15'!D35+'16'!D35+'17'!D35+'18'!D35 -> 0 | E36: =+C36+D36 -> 0 | F36: =+'11'!F35+'12'!F35+'13'!F35+'14'!F35+'15'!F35+'16'!F35+'17'!F35+'18'!F35 -> 0 | G36: =E36-F36-H36 -> 0 | H36: =+'11'!H35+'12'!H35+'13'!H35+'14'!H35+'15'!H35+'16'!H35+'17'!H35+'18'!H35 -> 0 | I36: 100 | J36: =+'11'!J35+'12'!J35+'13'!J35+'14'!J35+'15'!J35+'16'!J35+'17'!J35+'18'!J35 -> 0 | L36: รวม | M36: =SUM(M5:M35) -> 15070 | N36: =SUM(N5:N35) -> 425 | O36: =SUM(O5:O35) -> 0 | P36: =SUM(P5:P35) -> 90 | Q36: =SUM(Q5:Q35) -> 0 | R36: =SUM(R5:R35) -> 5255 | S36: =SUM(S5:S35) -> 9300 | T36: =SUM(T5:T35) -> 8150 | U36: =+U16+U18+U19+U20+U21+U22+U23+U24+U25+U26+U27+U28+U29+U30+U31+U32+U33+U34+U35 -> -150
A37: 33 | B37: ชิฟฟ่อนรวมรส ยอดฮิต 8 ชิ้น | C37: =+ยกมา!G36 -> 5 | D37: =+'11'!D36+'12'!D36+'13'!D36+'14'!D36+'15'!D36+'16'!D36+'17'!D36+'18'!D36 -> 10 | E37: =+C37+D37 -> 15 | F37: =+'11'!F36+'12'!F36+'13'!F36+'14'!F36+'15'!F36+'16'!F36+'17'!F36+'18'!F36 -> 0 | G37: =E37-F37-H37 -> 10 | H37: =+'11'!H36+'12'!H36+'13'!H36+'14'!H36+'15'!H36+'16'!H36+'17'!H36+'18'!H36 -> 5 | I37: 100 | J37: =+'11'!J36+'12'!J36+'13'!J36+'14'!J36+'15'!J36+'16'!J36+'17'!J36+'18'!J36 -> 500
A38: 34 | B38: ครีมฮอร์น วนิลา | C38: =+ยกมา!G37 -> 0 | D38: =+'11'!D37+'12'!D37+'13'!D37+'14'!D37+'15'!D37+'16'!D37+'17'!D37+'18'!D37 -> 10 | E38: =+C38+D38 -> 10 | F38: =+'11'!F37+'12'!F37+'13'!F37+'14'!F37+'15'!F37+'16'!F37+'17'!F37+'18'!F37 -> 0 | G38: =E38-F38-H38 -> 2 | H38: =+'11'!H37+'12'!H37+'13'!H37+'14'!H37+'15'!H37+'16'!H37+'17'!H37+'18'!H37 -> 8 | I38: 50 | J38: =+'11'!J37+'12'!J37+'13'!J37+'14'!J37+'15'!J37+'16'!J37+'17'!J37+'18'!J37 -> 400
A39: 35 | B39: ครีมฮอร์น ใบเตย | C39: =+ยกมา!G38 -> 0 | D39: =+'11'!D38+'12'!D38+'13'!D38+'14'!D38+'15'!D38+'16'!D38+'17'!D38+'18'!D38 -> 10 | E39: =+C39+D39 -> 10 | F39: =+'11'!F38+'12'!F38+'13'!F38+'14'!F38+'15'!F38+'16'!F38+'17'!F38+'18'!F38 -> 0 | G39: =E39-F39-H39 -> 4 | H39: =+'11'!H38+'12'!H38+'13'!H38+'14'!H38+'15'!H38+'16'!H38+'17'!H38+'18'!H38 -> 6 | I39: 50 | J39: =+'11'!J38+'12'!J38+'13'!J38+'14'!J38+'15'!J38+'16'!J38+'17'!J38+'18'!J38 -> 300
A40: 36 | B40: ครีมฮอร์น ช็อคโกแลต | C40: =+ยกมา!G39 -> 0 | D40: =+'11'!D39+'12'!D39+'13'!D39+'14'!D39+'15'!D39+'16'!D39+'17'!D39+'18'!D39 -> 10 | E40: =+C40+D40 -> 10 | F40: =+'11'!F39+'12'!F39+'13'!F39+'14'!F39+'15'!F39+'16'!F39+'17'!F39+'18'!F39 -> 0 | G40: =E40-F40-H40 -> 3 | H40: =+'11'!H39+'12'!H39+'13'!H39+'14'!H39+'15'!H39+'16'!H39+'17'!H39+'18'!H39 -> 7 | I40: 50 | J40: =+'11'!J39+'12'!J39+'13'!J39+'14'!J39+'15'!J39+'16'!J39+'17'!J39+'18'!J39 -> 350
A41: 37 | B41: เบาหวิว (ล) ใหม่ รสกล้วยหอมมะพร้าวเผา | C41: =+ยกมา!G40 -> 0 | D41: =+'11'!D40+'12'!D40+'13'!D40+'14'!D40+'15'!D40+'16'!D40+'17'!D40+'18'!D40 -> 0 | E41: =+C41+D41 -> 0 | F41: =+'11'!F40+'12'!F40+'13'!F40+'14'!F40+'15'!F40+'16'!F40+'17'!F40+'18'!F40 -> 0 | G41: =E41-F41-H41 -> 0 | H41: =+'11'!H40+'12'!H40+'13'!H40+'14'!H40+'15'!H40+'16'!H40+'17'!H40+'18'!H40 -> 0 | I41: 50 | J41: =+'11'!J40+'12'!J40+'13'!J40+'14'!J40+'15'!J40+'16'!J40+'17'!J40+'18'!J40 -> 0
...

Sheet ยกมา
A1: บูธลาดหลุมแก้ว วันที่ 1-29/02/2567 | O1: สินค้า SALE
A2: ลำดับ | B2: รายการ | C2: ยกมา | D2: รับ | E2: รวม | F2: เปลี่ยน/ | G2: คงเหลือ | H2: รายการขาย | K2: หมายเหตุ | L2: ส่วนลด | O2: ลำดับ | P2: รายการ | Q2: ยกมา | R2: รับ | S2: รวม | T2: เปลี่ยน/ | U2: คงเหลือ | V2: รายการขาย | Y2: หมายเหตุ | Z2: ส่วนลด
F3: คืน/เสีย | H3: จำนวน | I3: @ | J3: เป็นเงิน | T3: คืน/เสีย | V3: จำนวน | W3: @ | X3: เป็นเงิน
A4: 1 | B4: ชิฟฟ่อน (ล) | C4: 10 | D4: 0 | E4: =C4+D4 -> 10 | F4: 0 | G4: =E4-F4-H4 -> 10 | H4: 0 | I4: 50 | J4: =+I4*H4 -> 0 | K4: - | L4: 0 | M4: =+J4-L4 -> 0 | O4: 1 | Q4: 0 | R4: 0 | S4: =Q4+R4 -> 0 | T4: 0 | U4: =S4-T4-V4 -> 0 | V4: 0 | X4: =+W4*V4 -> 0 | Y4: - | Z4: 0
A5: 2 | B5: ชิฟฟ่อน (ญ) | C5: 5 | D5: 0 | E5: =C5+D5 -> 5 | F5: 0 | G5: =E5-F5-H5 -> 5 | H5: 0 | I5: 100 | J5: =+I5*H5 -> 0 | K5: - | L5: 0 | M5: =+J5-L5 -> 0 | O5: 2 | Q5: 0 | R5: 0 | S5: =Q5+R5 -> 0 | T5: 0 | U5: =S5-T5-V5 -> 0 | V5: 0 | X5: =+W5*V5 -> 0 | Y5: - | Z5: 0
A6: 3 | B6: ชิฟฟ่อน (ล) กาแฟ | C6: 0 | D6: 0 | E6: =C6+D6 -> 0 | F6: 0 | G6: =E6-F6-H6 -> 0 | H6: 0 | I6: 50 | J6: =+I6*H6 -> 0 | K6: - | L6: 0 | M6: =+J6-L6 -> 0 | O6: 3 | Q6: 0 | R6: 0 | S6: =Q6+R6 -> 0 | T6: 0 | U6: =S6-T6-V6 -> 0 | V6: 0 | X6: =+W6*V6 -> 0 | Y6: - | Z6: 0
A7: 4 | B7: ชิฟฟ่อน (ญ) กาแฟ | C7: 0 | D7: 0 | E7: =C7+D7 -> 0 | F7: 0 | G7: =E7-F7-H7 -> 0 | H7: 0 | I7: 100 | J7: =+I7*H7 -> 0 | K7: - | L7: 0 | M7: =+J7-L7 -> 0 | O7: 4 | Q7: 0 | R7: 0 | S7: =Q7+R7 -> 0 | T7: 0 | U7: =S7-T7-V7 -> 0 | V7: 0 | X7: =+W7*V7 -> 0 | Y7: - | Z7: 0
A8: 5 | B8: ชิฟฟ่อนเค้ก 1 ชิ้น | C8: 0 | D8: 0 | E8: =C8+D8 -> 0 | F8: 0 | G8: =E8-F8-H8 -> 0 | H8: 0 | I8: 10 | J8: =+I8*H8 -> 0 | K8: - | L8: 0 | M8: =+J8-L8 -> 0 | O8: 5 | Q8: 0 | R8: 0 | S8: =Q8+R8 -> 0 | T8: 0 | U8: =S8-T8-V8 -> 0 | V8: 0 | X8: =+W8*V8 -> 0 | Y8: - | Z8: 0
A9: 6 | B9: ชิฟฟ่อนเค้กสอดไส้แยม 1 ชิ้น | C9: 0 | D9: 0 | E9: =C9+D9 -> 0 | F9: 0 | G9: =E9-F9-H9 -> 0 | H9: 0 | I9: 12 | J9: =+I9*H9 -> 0 | K9: - | L9: 0 | M9: =+J9-L9 -> 0 | O9: 6 | Q9: 0 | R9: 0 | S9: =Q9+R9 -> 0 | T9: 0 | U9: =S9-T9-V9 -> 0 | V9: 0 | X9: =+W9*V9 -> 0 | Y9: - | Z9: 0
A10: 7 | B10: ชิฟฟ่อน สอดไส้ (ล) 2 ชิ้น ครีมมะพร้าว | C10: 0 | D10: 0 | E10: =C10+D10 -> 0 | F10: 0 | G10: =E10-F10-H10 -> 0 | H10: 0 | I10: 40 | J10: =+I10*H10 -> 0 | K10: - | L10: 0 | M10: =+J10-L10 -> 0 | O10: 7 | Q10: 0 | R10: 0 | S10: =Q10+R10 -> 0 | T10: 0 | U10: =S10-T10-V10 -> 0 | V10: 0 | X10: =+W10*V10 -> 0 | Y10: - | Z10: 0
A11: 8 | B11: ชิฟฟ่อน สอดไส้ (ล) 3 ชิ้น รวมรส | C11: 0 | D11: 0 | E11: =C11+D11 -> 0 | F11: 0 | G11: =E11-F11-H11 -> 0 | H11: 0 | I11: 50 | J11: =+I11*H11 -> 0 | K11: - | L11: 0 | M11: =+J11-L11 -> 0 | O11: 8 | Q11: 0 | R11: 0 | S11: =Q11+R11 -> 0 | T11: 0 | U11: =S11-T11-V11 -> 0 | V11: 0 | X11: =+W11*V11 -> 0 | Y11: - | Z11: 0
A12: 9 | B12: ชิฟฟ่อน สอดไส้ (ล) 3 ชิ้น เมล่อน | C12: 0 | D12: 0 | E12: =C12+D12 -> 0 | F12: 0 | G12: =E12-F12-H12 -> 0 | H12: 0 | I12: 55 | J12: =+I12*H12 -> 0 | K12: - | L12: 0 | M12: =+J12-L12 -> 0 | O12: 9 | Q12: 0 | R12: 0 | S12: =Q12+R12 -> 0 | T12: 0 | U12: =S12-T12-V12 -> 0 | V12: 0 | X12: =+W12*V12 -> 0 | Y12: - | Z12: 0
A13: 10 | B13: ชิฟฟ่อน สอดไส้ (ล) 4 ชิ้น ครีมมะพร้าว | C13: 0 | D13: 0 | E13: =C13+D13 -> 0 | F13: 0 | G13: =E13-F13-H13 -> 0 | H13: 0 | I13: 65 | J13: =+I13*H13 -> 0 | K13: - | L13: 0 | M13: =+J13-L13 -> 0 | O13: 10 | Q13: 0 | R13: 0 | S13: =Q13+R13 -> 0 | T13: 0 | U13: =S13-T13-V13 -> 0 | V13: 0 | X13: =+W13*V13 -> 0 | Y13: - | Z13: 0
A14: 11 | B14: ชิฟฟ่อน สอดไส้ (ล) 3 ชิ้น แยมส้ม | C14: 0 | D14: 0 | E14: =C14+D14 -> 0 | F14: 0 | G14: =E14-F14-H14 -> 0 | H14: 0 | I14: 50 | J14: =+I14*H14 -> 0 | K14: - | L14: 0 | M14: =+J14-L14 -> 0 | O14: 11 | Q14: 0 | R14: 0 | S14: =Q14+R14 -> 0 | T14: 0 | U14: =S14-T14-V14 -> 0 | V14: 0 | X14: =+W14*V14 -> 0 | Y14: - | Z14: 0
A15: 12 | B15: ชิฟฟ่อน สอดไส้ (ล) 3 ชิ้น บลูเบอรี่ | C15: 0 | D15: 0 | E15: =C15+D15 -> 0 | F15: 0 | G15: =E15-F15-H15 -> 0 | H15: 0 | I15: 50 | J15: =+I15*H15 -> 0 | K15: - | L15: 0 | M15: =+J15-L15 -> 0 | O15: 12 | Q15: 0 | R15: 0 | S15: =Q15+R15 -> 0 | T15: 0 | U15: =S15-T15-V15 -> 0 | V15: 0 | X15: =+W15*V15 -> 0 | Y15: - | Z15: 0
... A102: 99 | B102: ไดฟุกุ 8 ชิ้น | C102: 0 | D102: 0 | E102: =C102+D102 -> 0 | F102: 0 | G102: =E102-F102-H102 -> 0 | H102: 0 | I102: 100 | J102: =+I102*H102 -> 0 | K102: - | L102: 0 | M102: =+J102-L102 -> 0 | O102: 99 | Q102: 0 | R102: 0 | S102: =Q102+R102 -> 0 | T102: 0 | U102: =S102-T102-V102 -> 0 | V102: 0 | X102: =+W102*V102 -> 0 | Y102: - | Z102: 0
A103: 100 | B103: หมูทุบ | C103: 0 | D103: 0 | E103: =C103+D103 -> 0 | F103: 0 | G103: =E103-F103-H103 -> 0 | H103: 0 | I103: 100 | J103: =+I103*H103 -> 0 | K103: - | L103: 0 | M103: =+J103-L103 -> 0 | O103: 100 | Q103: 0 | R103: 0 | S103: =Q103+R103 -> 0 | T103: 0 | U103: =S103-T103-V103 -> 0 | V103: 0 | X103: =+W103*V103 -> 0 | Z103: 0
A104: 101 | B104: ดอกจอก | C104: 0 | D104: 0 | E104: =C104+D104 -> 0 | F104: 0 | G104: =E104-F104-H104 -> 0 | H104: 0 | I104: 30 | J104: =+I104*H104 -> 0 | K104: - | L104: 0 | M104: =+J104-L104 -> 0 | Z104: =SUM(Z4:Z103) -> 0
A105: 102 | B105: เทียน | C105: 0 | D105: 0 | E105: =C105+D105 -> 0 | F105: 0 | G105: =E105-F105-H105 -> 0 | H105: 0 | I105: 20 | J105: =+I105*H105 -> 0 | K105: - | L105: 0 | M105: =+J105-L105 -> 0
A106: 103 | B106: ขนมอาลัวแฟนซี | C106: 0 | D106: 0 | E106: =C106+D106 -> 0 | F106: 0 | G106: =E106-F106-H106 -> 0 | H106: 0 | I106: 100 | J106: =+I106*H106 -> 0 | K106: - | L106: 0 | M106: =+J106-L106 -> 0 | P106: รวม | X106: =SUM(X4:X103) -> 0
A107: 104 | B107: ชูนัทคุกกี้ | C107: 0 | D107: 0 | E107: =C107+D107 -> 0 | F107: 0 | G107: =E107-F107-H107 -> 0 | H107: 0 | I107: 80 | J107: =+I107*H107 -> 0 | K107: - | L107: 0 | M107: =+J107-L107 -> 0
A108: 105 | B108: วุ้นแฟนซี | C108: 0 | D108: 0 | E108: =C108+D108 -> 0 | F108: 0 | G108: =E108-F108-H108 -> 0 | H108: 0 | I108: 60 | J108: =+I108*H108 -> 0 | K108: - | L108: 0 | M108: =+J108-L108 -> 0
A109: 106 | B109: เค้กสามเหลี่ยม มะพร้าว | C109: 0 | D109: 0 | E109: =C109+D109 -> 0 | F109: 0 | G109: =E109-F109-H109 -> 0 | H109: 0 | I109: 35 | J109: =+I109*H109 -> 0 | K109: - | L109: 0 | M109: =+J109-L109 -> 0
A110: 107 | B110: เค้กสามเหลี่ยม สตอเบอรี่ | C110: 0 | D110: 0 | E110: =C110+D110 -> 0 | F110: 0 | G110: =E110-F110-H110 -> 0 | H110: 0 | I110: 35 | J110: =+I110*H110 -> 0 | K110: - | L110: 0 | M110: =+J110-L110 -> 0
A111: 108 | B111: เค้กสามเหลี่ยม บลูเบอรี่ | C111: 0 | D111: 0 | E111: =C111+D111 -> 0 | F111: 0 | G111: =E111-F111-H111 -> 0 | H111: 0 | I111: 35 | J111: =+I111*H111 -> 0 | K111: - | L111: 0 | M111: =+J111-L111 -> 0
A112: 109 | B112: เค้กสามเหลี่ยม รสส้ม | C112: 0 | D112: 0 | E112: =C112+D112 -> 0 | F112: 0 | G112: =E112-F112-H112 -> 0 | H112: 0 | I112: 35 | J112: =+I112*H112 -> 0 | K112: - | L112: 0 | M112: =+J112-L112 -> 0
A113: 110 | B113: เค้กสามเหลี่ยม รสช็อกโกโอริโอ้ | C113: 0 | D113: 0 | E113: =C113+D113 -> 0 | F113: 0 | G113: =E113-F113-H113 -> 0 | H113: 0 | I113: 35 | J113: =+I113*H113 -> 0 | K113: - | L113: 0 | M113: =+J113-L113 -> 0
A114: 111 | B114: สตอเบอร์รี่ครีมเค้ก | C114: 0 | D114: 0 | E114: =C114+D114 -> 0 | F114: 0 | G114: =E114-F114-H114 -> 0 | H114: 0 | I114: 50 | J114: =+I114*H114 -> 0 | K114: - | L114: 0 | M114: =+J114-L114 -> 0
A115: 112 | B115: บลูเบอร์รี่ครีมเค้ก | C115: 0 | D115: 0 | E115: =C115+D115 -> 0 | F115: 0 | G115: =E115-F115-H115 -> 0 | H115: 0 | I115: 50 | J115: =+I115*H115 -> 0 | K115: - | L115: 0 | M115: =+J115-L115 -> 0
A116: 113 | B116: เค้กส้ม | C116: 0 | D116: 0 | E116: =C116+D116 -> 0 | F116: 0 | G116: =E116-F116-H116 -> 0 | H116: 0 | I116: 50 | J116: =+I116*H116 -> 0 | K116: - | L116: 0 | M116: =+J116-L116 -> 0
A117: 114 | B117: วนิลาครีมเค้ก | C117: 0 | D117: 0 | E117: =C117+D117 -> 0 | F117: 0 | G117: =E117-F117-H117 -> 0 | H117: 0 | I117: 50 | J117: =+I117*H117 -> 0 | K117: - | L117: 0 | M117: =+J117-L117 -> 0
A118: 115 | B118: ใบเตยครีมเค้ก | C118: 0 | D118: 0 | E118: =C118+D118 -> 0 | F118: 0 | G118: =E118-F118-H118 -> 0 | H118: 0 | I118: 50 | J118: =+I118*H118 -> 0 | K118: - | L118: 0 | M118: =+J118-L118 -> 0
... A193: 190 | B193: ฝอยทองกรอบ | C193: 0 | D193: 0 | E193: =C193+D193 -> 0 | F193: 0 | G193: =E193-F193-H193 -> 0 | H193: 0 | I193: 65 | J193: =+I193*H193 -> 0 | K193: - | L193: 0 | M193: =+J193-L193 -> 0
A194: 191 | C194: 0 | D194: 0 | E194: =C194+D194 -> 0 | F194: 0 | G194: =E194-F194-H194 -> 0 | H194: 0 | I194: 0 | J194: =+I194*H194 -> 0 | K194: - | L194: 0 | M194: =+J194-L194 -> 0
A195: 192 | C195: 0 | D195: 0 | E195: =C195+D195 -> 0 | F195: 0 | G195: =E195-F195-H195 -> 0 | H195: 0 | I195: 0 | J195: =+I195*H195 -> 0 | K195: - | L195: 0 | M195: =+J195-L195 -> 0
A196: 193 | C196: 0 | D196: 0 | E196: =C196+D196 -> 0 | F196: 0 | G196: =E196-F196-H196 -> 0 | H196: 0 | I196: 0 | J196: =+I196*H196 -> 0 | K196: - | L196: 0 | M196: =+J196-L196 -> 0
A197: 194 | C197: 0 | D197: 0 | E197: =C197+D197 -> 0 | F197: 0 | G197: =E197-F197-H197 -> 0 | H197: 0 | I197: 0 | J197: =+I197*H197 -> 0 | K197: - | L197: 0 | M197: =+J197-L197 -> 0
A198: 195 | C198: 0 | D198: 0 | E198: =C198+D198 -> 0 | F198: 0 | G198: =E198-F198-H198 -> 0 | H198: 0 | I198: 0 | J198: =+I198*H198 -> 0 | K198: - | L198: 0 | M198: =+J198-L198 -> 0
A199: 196 | C199: 0 | D199: 0 | E199: =C199+D199 -> 0 | F199: 0 | G199: =E199-F199-H199 -> 0 | H199: 0 | I199: 0 | J199: =+I199*H199 -> 0 | K199: - | L199: 0 | M199: =+J199-L199 -> 0
A200: 197 | C200: 0 | D200: 0 | E200: =C200+D200 -> 0 | F200: 0 | G200: =E200-F200-H200 -> 0 | H200: 0 | I200: 0 | J200: =+I200*H200 -> 0 | K200: - | L200: 0 | M200: =+J200-L200 -> 0
...

Sheet 11
A1: บูธลาดหลุมแก้ว วันที่ 1-29/02/2567 | O1: สินค้า SALE
A2: ลำดับ | B2: รายการ | C2: ยกมา | D2: รับ | E2: รวม | F2: เปลี่ยน/ | G2: คงเหลือ | H2: รายการขาย | K2: หมายเหตุ | L2: ส่วนลด | O2: ลำดับ | P2: รายการ | Q2: ยกมา | R2: รับ | S2: รวม | T2: เปลี่ยน/ | U2: คงเหลือ | V2: รายการขาย | Y2: หมายเหตุ | Z2: ส่วนลด
F3: คืน/เสีย | H3: จำนวน | I3: @ | J3: เป็นเงิน | T3: คืน/เสีย | V3: จำนวน | W3: @ | X3: เป็นเงิน
A4: 1 | B4: ชิฟฟ่อน (ล) | C4: =+ยกมา!G4 -> 10 | D4: 20 | E4: =C4+D4 -> 30 | F4: 0 | G4: =E4-F4-H4 -> 25 | H4: 5 | I4: 50 | J4: =+I4*H4 -> 250 | K4: - | L4: 0 | M4: =+J4-L4 -> 250 | O4: 1 | Q4: 0 | R4: 0 | S4: =Q4+R4 -> 0 | T4: 0 | U4: =S4-T4-V4 -> 0 | V4: 0 | X4: =+W4*V4 -> 0 | Y4: - | Z4: 0
A5: 2 | B5: ชิฟฟ่อน (ญ) | C5: =+ยกมา!G5 -> 5 | D5: 20 | E5: =C5+D5 -> 25 | F5: 0 | G5: =E5-F5-H5 -> 18 | H5: 7 | I5: 100 | J5: =+I5*H5 -> 700 | K5: - | L5: 0 | M5: =+J5-L5 -> 700 | O5: 2 | Q5: 0 | R5: 0 | S5: =Q5+R5 -> 0 | T5: 0 | U5: =S5-T5-V5 -> 0 | V5: 0 | X5: =+W5*V5 -> 0 | Y5: - | Z5: 0
A6: 3 | B6: ชิฟฟ่อน (ล) กาแฟ | C6: =+ยกมา!G6 -> 0 | D6: 0 | E6: =C6+D6 -> 0 | F6: 0 | G6: =E6-F6-H6 -> 0 | H6: 0 | I6: 50 | J6: =+I6*H6 -> 0 | K6: - | L6: 0 | M6: =+J6-L6 -> 0 | O6: 3 | Q6: 0 | R6: 0 | S6: =Q6+R6 -> 0 | T6: 0 | U6: =S6-T6-V6 -> 0 | V6: 0 | X6: =+W6*V6 -> 0 | Y6: - | Z6: 0
A7: 4 | B7: ชิฟฟ่อน (ญ) กาแฟ | C7: =+ยกมา!G7 -> 0 | D7: 0 | E7: =C7+D7 -> 0 | F7: 0 | G7: =E7-F7-H7 -> 0 | H7: 0 | I7: 100 | J7: =+I7*H7 -> 0 | K7: - | L7: 0 | M7: =+J7-L7 -> 0 | O7: 4 | Q7: 0 | R7: 0 | S7: =Q7+R7 -> 0 | T7: 0 | U7: =S7-T7-V7 -> 0 | V7: 0 | X7: =+W7*V7 -> 0 | Y7: - | Z7: 0
A8: 5 | B8: ชิฟฟ่อนเค้ก 1 ชิ้น | C8: =+ยกมา!G8 -> 0 | D8: 0 | E8: =C8+D8 -> 0 | F8: 0 | G8: =E8-F8-H8 -> 0 | H8: 0 | I8: 10 | J8: =+I8*H8 -> 0 | K8: - | L8: 0 | M8: =+J8-L8 -> 0 | O8: 5 | Q8: 0 | R8: 0 | S8: =Q8+R8 -> 0 | T8: 0 | U8: =S8-T8-V8 -> 0 | V8: 0 | X8: =+W8*V8 -> 0 | Y8: - | Z8: 0
A9: 6 | B9: ชิฟฟ่อนเค้กสอดไส้แยม 1 ชิ้น | C9: =+ยกมา!G9 -> 0 | D9: 0 | E9: =C9+D9 -> 0 | F9: 0 | G9: =E9-F9-H9 -> 0 | H9: 0 | I9: 12 | J9: =+I9*H9 -> 0 | K9: - | L9: 0 | M9: =+J9-L9 -> 0 | O9: 6 | Q9: 0 | R9: 0 | S9: =Q9+R9 -> 0 | T9: 0 | U9: =S9-T9-V9 -> 0 | V9: 0 | X9: =+W9*V9 -> 0 | Y9: - | Z9: 0
A10: 7 | B10: ชิฟฟ่อน สอดไส้ (ล) 2 ชิ้น ครีมมะพร้าว | C10: =+ยกมา!G10 -> 0 | D10: 0 | E10: =C10+D10 -> 0 | F10: 0 | G10: =E10-F10-H10 -> 0 | H10: 0 | I10: 40 | J10: =+I10*H10 -> 0 | K10: - | L10: 0 | M10: =+J10-L10 -> 0 | O10: 7 | Q10: 0 | R10: 0 | S10: =Q10+R10 -> 0 | T10: 0 | U10: =S10-T10-V10 -> 0 | V10: 0 | X10: =+W10*V10 -> 0 | Y10: - | Z10: 0
A11: 8 | B11: ชิฟฟ่อน สอดไส้ (ล) 3 ชิ้น รวมรส | C11: =+ยกมา!G11 -> 0 | D11: 10 | E11: =C11+D11 -> 10 | F11: 0 | G11: =E11-F11-H11 -> 10 | H11: 0 | I11: 50 | J11: =+I11*H11 -> 0 | K11: - | L11: 0 | M11: =+J11-L11 -> 0 | O11: 8 | Q11: 0 | R11: 0 | S11: =Q11+R11 -> 0 | T11: 0 | U11: =S11-T11-V11 -> 0 | V11: 0 | X11: =+W11*V11 -> 0 | Y11: - | Z11: 0
A12: 9 | B12: ชิฟฟ่อน สอดไส้ (ล) 3 ชิ้น เมล่อน | C12: =+ยกมา!G12 -> 0 | D12: 0 | E12: =C12+D12 -> 0 | F12: 0 | G12: =E12-F12-H12 -> 0 | H12: 0 | I12: 55 | J12: =+I12*H12 -> 0 | K12: - | L12: 0 | M12: =+J12-L12 -> 0 | O12: 9 | Q12: 0 | R12: 0 | S12: =Q12+R12 -> 0 | T12: 0 | U12: =S12-T12-V12 -> 0 | V12: 0 | X12: =+W12*V12 -> 0 | Y12: - | Z12: 0
A13: 10 | B13: ชิฟฟ่อน สอดไส้ (ล) 4 ชิ้น ครีมมะพร้าว | C13: =+ยกมา!G13 -> 0 | D13: 0 | E13: =C13+D13 -> 0 | F13: 0 | G13: =E13-F13-H13 -> 0 | H13: 0 | I13: 65 | J13: =+I13*H13 -> 0 | K13: - | L13: 0 | M13: =+J13-L13 -> 0 | O13: 10 | Q13: 0 | R13: 0 | S13: =Q13+R13 -> 0 | T13: 0 | U13: =S13-T13-V13 -> 0 | V13: 0 | X13: =+W13*V13 -> 0 | Y13: - | Z13: 0
A14: 11 | B14: ชิฟฟ่อน สอดไส้ (ล) 3 ชิ้น แยมส้ม | C14: =+ยกมา!G14 -> 0 | D14: 2 | E14: =C14+D14 -> 2 | F14: 0 | G14: =E14-F14-H14 -> 0 | H14: 2 | I14: 50 | J14: =+I14*H14 -> 100 | K14: แถม | L14: 100 | M14: =+J14-L14 -> 0 | O14: 11 | Q14: 0 | R14: 0 | S14: =Q14+R14 -> 0 | T14: 0 | U14: =S14-T14-V14 -> 0 | V14: 0 | X14: =+W14*V14 -> 0 | Y14: - | Z14: 0
A15: 12 | B15: ชิฟฟ่อน สอดไส้ (ล) 3 ชิ้น บลูเบอรี่ | C15: =+ยกมา!G15 -> 0 | D15: 0 | E15: =C15+D15 -> 0 | F15: 0 | G15: =E15-F15-H15 -> 0 | H15: 0 | I15: 50 | J15: =+I15*H15 -> 0 | K15: - | L15: 0 | M15: =+J15-L15 -> 0 | O15: 12 | Q15: 0 | R15: 0 | S15: =Q15+R15 -> 0 | T15: 0 | U15: =S15-T15-V15 -> 0 | V15: 0 | X15: =+W15*V15 -> 0 | Y15: - | Z15: 0
... A102: 99 | B102: ไดฟุกุ 8 ชิ้น | C102: =+ยกมา!G102 -> 0 | D102: 0 | E102: =C102+D102 -> 0 | F102: 0 | G102: =E102-F102-H102 -> 0 | H102: 0 | I102: 100 | J102: =+I102*H102 -> 0 | K102: - | L102: 0 | M102: =+J102-L102 -> 0 | O102: 99 | Q102: 0 | R102: 0 | S102: =Q102+R102 -> 0 | T102: 0 | U102: =S102-T102-V102 -> 0 | V102: 0 | X102: =+W102*V102 -> 0 | Y102: - | Z102: 0
A103: 100 | B103: หมูทุบ | C103: =+ยกมา!G103 -> 0 | D103: 0 | E103: =C103+D103 -> 0 | F103: 0 | G103: =E103-F103-H103 -> 0 | H103: 0 | I103: 100 | J103: =+I103*H103 -> 0 | K103: - | L103: 0 | M103: =+J103-L103 -> 0 | O103: 100 | Q103: 0 | R103: 0 | S103: =Q103+R103 -> 0 | T103: 0 | U103: =S103-T103-V103 -> 0 | V103: 0 | X103: =+W103*V103 -> 0 | Z103: 0
A104: 101 | B104: ดอกจอก | C104: =+ยกมา!G104 -> 0 | D104: 0 | E104: =C104+D104 -> 0 | F104: 0 | G104: =E104-F104-H104 -> 0 | H104: 0 | I104: 30 | J104: =+I104*H104 -> 0 | K104: - | L104: 0 | M104: =+J104-L104 -> 0 | Z104: =SUM(Z4:Z103) -> 0
A105: 102 | B105: เทียน | C105: =+ยกมา!G105 -> 0 | D105: 0 | E105: =C105+D105 -> 0 | F105: 0 | G105: =E105-F105-H105 -> 0 | H105: 0 | I105: 20 | J105: =+I105*H105 -> 0 | K105: - | L105: 0 | M105: =+J105-L105 -> 0
A106: 103 | B106: ขนมอาลัวแฟนซี | C106: =+ยกมา!G106 -> 0 | D106: 0 | E106: =C106+D106 -> 0 | F106: 0 | G106: =E106-F106-H106 -> 0 | H106: 0 | I106: 100 | J106: =+I106*H106 -> 0 | K106: - | L106: 0 | M106: =+J106-L106 -> 0 | P106: รวม | X106: =SUM(X4:X103) -> 0
A107: 104 | B107: ชูนัทคุกกี้ | C107: =+ยกมา!G107 -> 0 | D107: 0 | E107: =C107+D107 -> 0 | F107: 0 | G107: =E107-F107-H107 -> 0 | H107: 0 | I107: 80 | J107: =+I107*H107 -> 0 | K107: - | L107: 0 | M107: =+J107-L107 -> 0
A108: 105 | B108: วุ้นแฟนซี | C108: =+ยกมา!G108 -> 0 | D108: 0 | E108: =C108+D108 -> 0 | F108: 0 | G108: =E108-F108-H108 -> 0 | H108: 0 | I108: 60 | J108: =+I108*H108 -> 0 | K108: - | L108: 0 | M108: =+J108-L108 -> 0
A109: 106 | B109: เค้กสามเหลี่ยม มะพร้าว | C109: =+ยกมา!G109 -> 0 | D109: 0 | E109: =C109+D109 -> 0 | F109: 0 | G109: =E109-F109-H109 -> 0 | H109: 0 | I109: 35 | J109: =+I109*H109 -> 0 | K109: - | L109: 0 | M109: =+J109-L109 -> 0
A110: 107 | B110: เค้กสามเหลี่ยม สตอเบอรี่ | C110: =+ยกมา!G110 -> 0 | D110: 0 | E110: =C110+D110 -> 0 | F110: 0 | G110: =E110-F110-H110 -> 0 | H110: 0 | I110: 35 | J110: =+I110*H110 -> 0 | K110: - | L110: 0 | M110: =+J110-L110 -> 0
A111: 108 | B111: เค้กสามเหลี่ยม บลูเบอรี่ | C111: =+ยกมา!G111 -> 0 | D111: 0 | E111: =C111+D111 -> 0 | F111: 0 | G111: =E111-F111-H111 -> 0 | H111: 0 | I111: 35 | J111: =+I111*H111 -> 0 | K111: - | L111: 0 | M111: =+J111-L111 -> 0
A112: 109 | B112: เค้กสามเหลี่ยม รสส้ม | C112: =+ยกมา!G112 -> 0 | D112: 0 | E112: =C112+D112 -> 0 | F112: 0 | G112: =E112-F112-H112 -> 0 | H112: 0 | I112: 35 | J112: =+I112*H112 -> 0 | K112: - | L112: 0 | M112: =+J112-L112 -> 0
A113: 110 | B113: เค้กสามเหลี่ยม รสช็อกโกโอริโอ้ | C113: =+ยกมา!G113 -> 0 | D113: 0 | E113: =C113+D113 -> 0 | F113: 0 | G113: =E113-F113-H113 -> 0 | H113: 0 | I113: 35 | J113: =+I113*H113 -> 0 | K113: - | L113: 0 | M113: =+J113-L113 -> 0
A114: 111 | B114: สตอเบอร์รี่ครีมเค้ก | C114: =+ยกมา!G114 -> 0 | D114: 0 | E114: =C114+D114 -> 0 | F114: 0 | G114: =E114-F114-H114 -> 0 | H114: 0 | I114: 50 | J114: =+I114*H114 -> 0 | K114: - | L114: 0 | M114: =+J114-L114 -> 0
A115: 112 | B115: บลูเบอร์รี่ครีมเค้ก | C115: =+ยกมา!G115 -> 0 | D115: 0 | E115: =C115+D115 -> 0 | F115: 0 | G115: =E115-F115-H115 -> 0 | H115: 0 | I115: 50 | J115: =+I115*H115 -> 0 | K115: - | L115: 0 | M115: =+J115-L115 -> 0
A116: 113 | B116: เค้กส้ม | C116: =+ยกมา!G116 -> 0 | D116: 0 | E116: =C116+D116 -> 0 | F116: 0 | G116: =E116-F116-H116 -> 0 | H116: 0 | I116: 50 | J116: =+I116*H116 -> 0 | K116: - | L116: 0 | M116: =+J116-L116 -> 0
A117: 114 | B117: วนิลาครีมเค้ก | C117: =+ยกมา!G117 -> 0 | D117: 0 | E117: =C117+D117 -> 0 | F117: 0 | G117: =E117-F117-H117 -> 0 | H117: 0 | I117: 50 | J117: =+I117*H117 -> 0 | K117: - | L117: 0 | M117: =+J117-L117 -> 0
A118: 115 | B118: ใบเตยครีมเค้ก | C118: =+ยกมา!G118 -> 0 | D118: 0 | E118: =C118+D118 -> 0 | F118: 0 | G118: =E118-F118-H118 -> 0 | H118: 0 | I118: 50 | J118: =+I118*H118 -> 0 | K118: - | L118: 0 | M118: =+J118-L118 -> 0
... A193: 190 | B193: ฝอยทองกรอบ | C193: =+ยกมา!G193 -> 0 | D193: 10 | E193: =C193+D193 -> 10 | F193: 0 | G193: =E193-F193-H193 -> 5 | H193: 5 | I193: 65 | J193: =+I193*H193 -> 325 | K193: โปร | L193: 75 | M193: =+J193-L193 -> 250
A194: 191 | C194: =+ยกมา!G194 -> 0 | D194: 0 | E194: =C194+D194 -> 0 | F194: 0 | G194: =E194-F194-H194 -> 0 | H194: 0 | I194: 0 | J194: =+I194*H194 -> 0 | K194: - | L194: 0 | M194: =+J194-L194 -> 0
A195: 192 | C195: =+ยกมา!G195 -> 0 | D195: 0 | E195: =C195+D195 -> 0 | F195: 0 | G195: =E195-F195-H195 -> 0 | H195: 0 | I195: 0 | J195: =+I195*H195 -> 0 | K195: - | L195: 0 | M195: =+J195-L195 -> 0
A196: 193 | C196: =+ยกมา!G196 -> 0 | D196: 0 | E196: =C196+D196 -> 0 | F196: 0 | G196: =E196-F196-H196 -> 0 | H196: 0 | I196: 0 | J196: =+I196*H196 -> 0 | K196: - | L196: 0 | M196: =+J196-L196 -> 0
A197: 194 | C197: =+ยกมา!G197 -> 0 | D197: 0 | E197: =C197+D197 -> 0 | F197: 0 | G197: =E197-F197-H197 -> 0 | H197: 0 | I197: 0 | J197: =+I197*H197 -> 0 | K197: - | L197: 0 | M197: =+J197-L197 -> 0
A198: 195 | C198: =+ยกมา!G198 -> 0 | D198: 0 | E198: =C198+D198 -> 0 | F198: 0 | G198: =E198-F198-H198 -> 0 | H198: 0 | I198: 0 | J198: =+I198*H198 -> 0 | K198: - | L198: 0 | M198: =+J198-L198 -> 0
A199: 196 | C199: =+ยกมา!G199 -> 0 | D199: 0 | E199: =C199+D199 -> 0 | F199: 0 | G199: =E199-F199-H199 -> 0 | H199: 0 | I199: 0 | J199: =+I199*H199 -> 0 | K199: - | L199: 0 | M199: =+J199-L199 -> 0
A200: 197 | C200: =+ยกมา!G200 -> 0 | D200: 0 | E200: =C200+D200 -> 0 | F200: 0 | G200: =E200-F200-H200 -> 0 | H200: 0 | I200: 0 | J200: =+I200*H200 -> 0 | K200: - | L200: 0 | M200: =+J200-L200 -> 0
...

Sheet 12
A1: บูธลาดหลุมแก้ว วันที่ 1-29/02/2567 | O1: สินค้า SALE
A2: ลำดับ | B2: รายการ | C2: ยกมา | D2: รับ | E2: รวม | F2: เปลี่ยน/ | G2: คงเหลือ | H2: รายการขาย | K2: หมายเหตุ | L2: ส่วนลด | O2: ลำดับ | P2: รายการ | Q2: ยกมา | R2: รับ | S2: รวม | T2: เปลี่ยน/ | U2: คงเหลือ | V2: รายการขาย | Y2: หมายเหตุ | Z2: ส่วนลด
F3: คืน/เสีย | H3: จำนวน | I3: @ | J3: เป็นเงิน | T3: คืน/เสีย | V3: จำนวน | W3: @ | X3: เป็นเงิน
A4: 1 | B4: ชิฟฟ่อน (ล) | C4: =+'11'!G4 -> 25 | D4: 0 | E4: =C4+D4 -> 25 | F4: 0 | G4: =E4-F4-H4 -> 20 | H4: 5 | I4: 50 | J4: =+I4*H4 -> 250 | K4: - | L4: 0 | M4: =+J4-L4 -> 250 | O4: 1 | Q4: 0 | R4: 0 | S4: =Q4+R4 -> 0 | T4: 0 | U4: =S4-T4-V4 -> 0 | V4: 0 | X4: =+W4*V4 -> 0 | Y4: - | Z4: 0
A5: 2 | B5: ชิฟฟ่อน (ญ) | C5: =+'11'!G5 -> 18 | D5: 0 | E5: =C5+D5 -> 18 | F5: 0 | G5: =E5-F5-H5 -> 17 | H5: 1 | I5: 100 | J5: =+I5*H5 -> 100 | K5: - | L5: 0 | M5: =+J5-L5 -> 100 | O5: 2 | Q5: 0 | R5: 0 | S5: =Q5+R5 -> 0 | T5: 0 | U5: =S5-T5-V5 -> 0 | V5: 0 | X5: =+W5*V5 -> 0 | Y5: - | Z5: 0
A6: 3 | B6: ชิฟฟ่อน (ล) กาแฟ | C6: =+'11'!G6 -> 0 | D6: 0 | E6: =C6+D6 -> 0 | F6: 0 | G6: =E6-F6-H6 -> 0 | H6: 0 | I6: 50 | J6: =+I6*H6 -> 0 | K6: - | L6: 0 | M6: =+J6-L6 -> 0 | O6: 3 | Q6: 0 | R6: 0 | S6: =Q6+R6 -> 0 | T6: 0 | U6: =S6-T6-V6 -> 0 | V6: 0 | X6: =+W6*V6 -> 0 | Y6: - | Z6: 0
A7: 4 | B7: ชิฟฟ่อน (ญ) กาแฟ | C7: =+'11'!G7 -> 0 | D7: 0 | E7: =C7+D7 -> 0 | F7: 0 | G7: =E7-F7-H7 -> 0 | H7: 0 | I7: 100 | J7: =+I7*H7 -> 0 | K7: - | L7: 0 | M7: =+J7-L7 -> 0 | O7: 4 | Q7: 0 | R7: 0 | S7: =Q7+R7 -> 0 | T7: 0 | U7: =S7-T7-V7 -> 0 | V7: 0 | X7: =+W7*V7 -> 0 | Y7: - | Z7: 0
A8: 5 | B8: ชิฟฟ่อนเค้ก 1 ชิ้น | C8: =+'11'!G8 -> 0 | D8: 0 | E8: =C8+D8 -> 0 | F8: 0 | G8: =E8-F8-H8 -> 0 | H8: 0 | I8: 10 | J8: =+I8*H8 -> 0 | K8: - | L8: 0 | M8: =+J8-L8 -> 0 | O8: 5 | Q8: 0 | R8: 0 | S8: =Q8+R8 -> 0 | T8: 0 | U8: =S8-T8-V8 -> 0 | V8: 0 | X8: =+W8*V8 -> 0 | Y8: - | Z8: 0
A9: 6 | B9: ชิฟฟ่อนเค้กสอดไส้แยม 1 ชิ้น | C9: =+'11'!G9 -> 0 | D9: 0 | E9: =C9+D9 -> 0 | F9: 0 | G9: =E9-F9-H9 -> 0 | H9: 0 | I9: 12 | J9: =+I9*H9 -> 0 | K9: - | L9: 0 | M9: =+J9-L9 -> 0 | O9: 6 | Q9: 0 | R9: 0 | S9: =Q9+R9 -> 0 | T9: 0 | U9: =S9-T9-V9 -> 0 | V9: 0 | X9: =+W9*V9 -> 0 | Y9: - | Z9: 0
A10: 7 | B10: ชิฟฟ่อน สอดไส้ (ล) 2 ชิ้น ครีมมะพร้าว | C10: =+'11'!G10 -> 0 | D10: 0 | E10: =C10+D10 -> 0 | F10: 0 | G10: =E10-F10-H10 -> 0 | H10: 0 | I10: 40 | J10: =+I10*H10 -> 0 | K10: - | L10: 0 | M10: =+J10-L10 -> 0 | O10: 7 | Q10: 0 | R10: 0 | S10: =Q10+R10 -> 0 | T10: 0 | U10: =S10-T10-V10 -> 0 | V10: 0 | X10: =+W10*V10 -> 0 | Y10: - | Z10: 0
A11: 8 | B11: ชิฟฟ่อน สอดไส้ (ล) 3 ชิ้น รวมรส | C11: =+'11'!G11 -> 10 | D11: 0 | E11: =C11+D11 -> 10 | F11: 0 | G11: =E11-F11-H11 -> 10 | H11: 0 | I11: 50 | J11: =+I11*H11 -> 0 | K11: - | L11: 0 | M11: =+J11-L11 -> 0 | O11: 8 | Q11: 0 | R11: 0 | S11: =Q11+R11 -> 0 | T11: 0 | U11: =S11-T11-V11 -> 0 | V11: 0 | X11: =+W11*V11 -> 0 | Y11: - | Z11: 0
A12: 9 | B12: ชิฟฟ่อน สอดไส้ (ล) 3 ชิ้น เมล่อน | C12: =+'11'!G12 -> 0 | D12: 0 | E12: =C12+D12 -> 0 | F12: 0 | G12: =E12-F12-H12 -> 0 | H12: 0 | I12: 55 | J12: =+I12*H12 -> 0 | K12: - | L12: 0 | M12: =+J12-L12 -> 0 | O12: 9 | Q12: 0 | R12: 0 | S12: =Q12+R12 -> 0 | T12: 0 | U12: =S12-T12-V12 -> 0 | V12: 0 | X12: =+W12*V12 -> 0 | Y12: - | Z12: 0
A13: 10 | B13: ชิฟฟ่อน สอดไส้ (ล) 4 ชิ้น ครีมมะพร้าว | C13: =+'11'!G13 -> 0 | D13: 0 | E13: =C13+D13 -> 0 | F13: 0 | G13: =E13-F13-H13 -> 0 | H13: 0 | I13: 65 | J13: =+I13*H13 -> 0 | K13: - | L13: 0 | M13: =+J13-L13 -> 0 | O13: 10 | Q13: 0 | R13: 0 | S13: =Q13+R13 -> 0 | T13: 0 | U13: =S13-T13-V13 -> 0 | V13: 0 | X13: =+W13*V13 -> 0 | Y13: - | Z13: 0
A14: 11 | B14: ชิฟฟ่อน สอดไส้ (ล) 3 ชิ้น แยมส้ม | C14: =+'11'!G14 -> 0 | D14: 0 | E14: =C14+D14 -> 0 | F14: 0 | G14: =E14-F14-H14 -> 0 | H14: 0 | I14: 50 | J14: =+I14*H14 -> 0 | K14: - | L14: 0 | M14: =+J14-L14 -> 0 | O14: 11 | Q14: 0 | R14: 0 | S14: =Q14+R14 -> 0 | T14: 0 | U14: =S14-T14-V14 -> 0 | V14: 0 | X14: =+W14*V14 -> 0 | Y14: - | Z14: 0
A15: 12 | B15: ชิฟฟ่อน สอดไส้ (ล) 3 ชิ้น บลูเบอรี่ | C15: =+'11'!G15 -> 0 | D15: 0 | E15: =C15+D15 -> 0 | F15: 0 | G15: =E15-F15-H15 -> 0 | H15: 0 | I15: 50 | J15: =+I15*H15 -> 0 | K15: - | L15: 0 | M15: =+J15-L15 -> 0 | O15: 12 | Q15: 0 | R15: 0 | S15: =Q15+R15 -> 0 | T15: 0 | U15: =S15-T15-V15 -> 0 | V15: 0 | X15: =+W15*V15 -> 0 | Y15: - | Z15: 0
... A102: 99 | B102: ไดฟุกุ 8 ชิ้น | C102: =+'11'!G102 -> 0 | D102: 0 | E102: =C102+D102 -> 0 | F102: 0 | G102: =E102-F102-H102 -> 0 | H102: 0 | I102: 100 | J102: =+I102*H102 -> 0 | K102: - | L102: 0 | M102: =+J102-L102 -> 0 | O102: 99 | Q102: 0 | R102: 0 | S102: =Q102+R102 -> 0 | T102: 0 | U102: =S102-T102-V102 -> 0 | V102: 0 | X102: =+W102*V102 -> 0 | Y102: - | Z102: 0
A103: 100 | B103: หมูทุบ | C103: =+'11'!G103 -> 0 | D103: 0 | E103: =C103+D103 -> 0 | F103: 0 | G103: =E103-F103-H103 -> 0 | H103: 0 | I103: 100 | J103: =+I103*H103 -> 0 | K103: - | L103: 0 | M103: =+J103-L103 -> 0 | O103: 100 | Q103: 0 | R103: 0 | S103: =Q103+R103 -> 0 | T103: 0 | U103: =S103-T103-V103 -> 0 | V103: 0 | X103: =+W103*V103 -> 0 | Z103: 0
A104: 101 | B104: ดอกจอก | C104: =+'11'!G104 -> 0 | D104: 0 | E104: =C104+D104 -> 0 | F104: 0 | G104: =E104-F104-H104 -> 0 | H104: 0 | I104: 30 | J104: =+I104*H104 -> 0 | K104: - | L104: 0 | M104: =+J104-L104 -> 0 | Z104: =SUM(Z4:Z103) -> 0
A105: 102 | B105: เทียน | C105: =+'11'!G105 -> 0 | D105: 0 | E105: =C105+D105 -> 0 | F105: 0 | G105: =E105-F105-H105 -> 0 | H105: 0 | I105: 20 | J105: =+I105*H105 -> 0 | K105: - | L105: 0 | M105: =+J105-L105 -> 0
A106: 103 | B106: ขนมอาลัวแฟนซี | C106: =+'11'!G106 -> 0 | D106: 0 | E106: =C106+D106 -> 0 | F106: 0 | G106: =E106-F106-H106 -> 0 | H106: 0 | I106: 100 | J106: =+I106*H106 -> 0 | K106: - | L106: 0 | M106: =+J106-L106 -> 0 | P106: รวม | X106: =SUM(X4:X103) -> 0
A107: 104 | B107: ชูนัทคุกกี้ | C107: =+'11'!G107 -> 0 | D107: 0 | E107: =C107+D107 -> 0 | F107: 0 | G107: =E107-F107-H107 -> 0 | H107: 0 | I107: 80 | J107: =+I107*H107 -> 0 | K107: - | L107: 0 | M107: =+J107-L107 -> 0
A108: 105 | B108: วุ้นแฟนซี | C108: =+'11'!G108 -> 0 | D108: 0 | E108: =C108+D108 -> 0 | F108: 0 | G108: =E108-F108-H108 -> 0 | H108: 0 | I108: 60 | J108: =+I108*H108 -> 0 | K108: - | L108: 0 | M108: =+J108-L108 -> 0
A109: 106 | B109: เค้กสามเหลี่ยม มะพร้าว | C109: =+'11'!G109 -> 0 | D109: 0 | E109: =C109+D109 -> 0 | F109: 0 | G109: =E109-F109-H109 -> 0 | H109: 0 | I109: 35 | J109: =+I109*H109 -> 0 | K109: - | L109: 0 | M109: =+J109-L109 -> 0
A110: 107 | B110: เค้กสามเหลี่ยม สตอเบอรี่ | C110: =+'11'!G110 -> 0 | D110: 0 | E110: =C110+D110 -> 0 | F110: 0 | G110: =E110-F110-H110 -> 0 | H110: 0 | I110: 35 | J110: =+I110*H110 -> 0 | K110: - | L110: 0 | M110: =+J110-L110 -> 0
A111: 108 | B111: เค้กสามเหลี่ยม บลูเบอรี่ | C111: =+'11'!G111 -> 0 | D111: 0 | E111: =C111+D111 -> 0 | F111: 0 | G111: =E111-F111-H111 -> 0 | H111: 0 | I111: 35 | J111: =+I111*H111 -> 0 | K111: - | L111: 0 | M111: =+J111-L111 -> 0
A112: 109 | B112: เค้กสามเหลี่ยม รสส้ม | C112: =+'11'!G112 -> 0 | D112: 0 | E112: =C112+D112 -> 0 | F112: 0 | G112: =E112-F112-H112 -> 0 | H112: 0 | I112: 35 | J112: =+I112*H112 -> 0 | K112: - | L112: 0 | M112: =+J112-L112 -> 0
A113: 110 | B113: เค้กสามเหลี่ยม รสช็อกโกโอริโอ้ | C113: =+'11'!G113 -> 0 | D113: 0 | E113: =C113+D113 -> 0 | F113: 0 | G113: =E113-F113-H113 -> 0 | H113: 0 | I113: 35 | J113: =+I113*H113 -> 0 | K113: - | L113: 0 | M113: =+J113-L113 -> 0
A114: 111 | B114: สตอเบอร์รี่ครีมเค้ก | C114: =+'11'!G114 -> 0 | D114: 0 | E114: =C114+D114 -> 0 | F114: 0 | G114: =E114-F114-H114 -> 0 | H114: 0 | I114: 50 | J114: =+I114*H114 -> 0 | K114: - | L114: 0 | M114: =+J114-L114 -> 0
A115: 112 | B115: บลูเบอร์รี่ครีมเค้ก | C115: =+'11'!G115 -> 0 | D115: 0 | E115: =C115+D115 -> 0 | F115: 0 | G115: =E115-F115-H115 -> 0 | H115: 0 | I115: 50 | J115: =+I115*H115 -> 0 | K115: - | L115: 0 | M115: =+J115-L115 -> 0
A116: 113 | B116: เค้กส้ม | C116: =+'11'!G116 -> 0 | D116: 0 | E116: =C116+D116 -> 0 | F116: 0 | G116: =E116-F116-H116 -> 0 | H116: 0 | I116: 50 | J116: =+I116*H116 -> 0 | K116: - | L116: 0 | M116: =+J116-L116 -> 0
A117: 114 | B117: วนิลาครีมเค้ก | C117: =+'11'!G117 -> 0 | D117: 0 | E117: =C117+D117 -> 0 | F117: 0 | G117: =E117-F117-H117 -> 0 | H117: 0 | I117: 50 | J117: =+I117*H117 -> 0 | K117: - | L117: 0 | M117: =+J117-L117 -> 0
A118: 115 | B118: ใบเตยครีมเค้ก | C118: =+'11'!G118 -> 0 | D118: 0 | E118: =C118+D118 -> 0 | F118: 0 | G118: =E118-F118-H118 -> 0 | H118: 0 | I118: 50 | J118: =+I118*H118 -> 0 | K118: - | L118: 0 | M118: =+J118-L118 -> 0
... A193: 190 | B193: ฝอยทองกรอบ | C193: =+'11'!G193 -> 5 | D193: 0 | E193: =C193+D193 -> 5 | F193: 0 | G193: =E193-F193-H193 -> 3 | H193: 2 | I193: 65 | J193: =+I193*H193 -> 130 | K193: โปร | L193: 30 | M193: =+J193-L193 -> 100
A194: 191 | C194: =+'11'!G194 -> 0 | D194: 0 | E194: =C194+D194 -> 0 | F194: 0 | G194: =E194-F194-H194 -> 0 | H194: 0 | I194: 0 | J194: =+I194*H194 -> 0 | K194: - | L194: 0 | M194: =+J194-L194 -> 0
A195: 192 | C195: =+'11'!G195 -> 0 | D195: 0 | E195: =C195+D195 -> 0 | F195: 0 | G195: =E195-F195-H195 -> 0 | H195: 0 | I195: 0 | J195: =+I195*H195 -> 0 | K195: - | L195: 0 | M195: =+J195-L195 -> 0
A196: 193 | C196: =+'11'!G196 -> 0 | D196: 0 | E196: =C196+D196 -> 0 | F196: 0 | G196: =E196-F196-H196 -> 0 | H196: 0 | I196: 0 | J196: =+I196*H196 -> 0 | K196: - | L196: 0 | M196: =+J196-L196 -> 0
A197: 194 | C197: =+'11'!G197 -> 0 | D197: 0 | E197: =C197+D197 -> 0 | F197: 0 | G197: =E197-F197-H197 -> 0 | H197: 0 | I197: 0 | J197: =+I197*H197 -> 0 | K197: - | L197: 0 | M197: =+J197-L197 -> 0
A198: 195 | C198: =+'11'!G198 -> 0 | D198: 0 | E198: =C198+D198 -> 0 | F198: 0 | G198: =E198-F198-H198 -> 0 | H198: 0 | I198: 0 | J198: =+I198*H198 -> 0 | K198: - | L198: 0 | M198: =+J198-L198 -> 0
A199: 196 | C199: =+'11'!G199 -> 0 | D199: 0 | E199: =C199+D199 -> 0 | F199: 0 | G199: =E199-F199-H199 -> 0 | H199: 0 | I199: 0 | J199: =+I199*H199 -> 0 | K199: - | L199: 0 | M199: =+J199-L199 -> 0
A200: 197 | C200: =+'11'!G200 -> 0 | D200: 0 | E200: =C200+D200 -> 0 | F200: 0 | G200: =E200-F200-H200 -> 0 | H200: 0 | I200: 0 | J200: =+I200*H200 -> 0 | K200: - | L200: 0 | M200: =+J200-L200 -> 0
...

Sheet 13
A1: บูธลาดหลุมแก้ว วันที่ 1-29/02/2567 | O1: สินค้า SALE
A2: ลำดับ | B2: รายการ | C2: ยกมา | D2: รับ | E2: รวม | F2: เปลี่ยน/ | G2: คงเหลือ | H2: รายการขาย | K2: หมายเหตุ | L2: ส่วนลด | O2: ลำดับ | P2: รายการ | Q2: ยกมา | R2: รับ | S2: รวม | T2: เปลี่ยน/ | U2: คงเหลือ | V2: รายการขาย | Y2: หมายเหตุ | Z2: ส่วนลด
F3: คืน/เสีย | H3: จำนวน | I3: @ | J3: เป็นเงิน | T3: คืน/เสีย | V3: จำนวน | W3: @ | X3: เป็นเงิน
A4: 1 | B4: ชิฟฟ่อน (ล) | C4: =+'12'!G4 -> 20 | D4: 0 | E4: =C4+D4 -> 20 | F4: 0 | G4: =E4-F4-H4 -> 19 | H4: 1 | I4: 50 | J4: =+I4*H4 -> 50 | K4: - | L4: 0 | M4: =+J4-L4 -> 50 | O4: 1 | Q4: 0 | R4: 0 | S4: =Q4+R4 -> 0 | T4: 0 | U4: =S4-T4-V4 -> 0 | V4: 0 | X4: =+W4*V4 -> 0 | Y4: - | Z4: 0
A5: 2 | B5: ชิฟฟ่อน (ญ) | C5: =+'12'!G5 -> 17 | D5: 0 | E5: =C5+D5 -> 17 | F5: 0 | G5: =E5-F5-H5 -> 17 | H5: 0 | I5: 100 | J5: =+I5*H5 -> 0 | K5: - | L5: 0 | M5: =+J5-L5 -> 0 | O5: 2 | Q5: 0 | R5: 0 | S5: =Q5+R5 -> 0 | T5: 0 | U5: =S5-T5-V5 -> 0 | V5: 0 | X5: =+W5*V5 -> 0 | Y5: - | Z5: 0
A6: 3 | B6: ชิฟฟ่อน (ล) กาแฟ | C6: =+'12'!G6 -> 0 | D6: 0 | E6: =C6+D6 -> 0 | F6: 0 | G6: =E6-F6-H6 -> 0 | H6: 0 | I6: 50 | J6: =+I6*H6 -> 0 | K6: - | L6: 0 | M6: =+J6-L6 -> 0 | O6: 3 | Q6: 0 | R6: 0 | S6: =Q6+R6 -> 0 | T6: 0 | U6: =S6-T6-V6 -> 0 | V6: 0 | X6: =+W6*V6 -> 0 | Y6: - | Z6: 0
A7: 4 | B7: ชิฟฟ่อน (ญ) กาแฟ | C7: =+'12'!G7 -> 0 | D7: 0 | E7: =C7+D7 -> 0 | F7: 0 | G7: =E7-F7-H7 -> 0 | H7: 0 | I7: 100 | J7: =+I7*H7 -> 0 | K7: - | L7: 0 | M7: =+J7-L7 -> 0 | O7: 4 | Q7: 0 | R7: 0 | S7: =Q7+R7 -> 0 | T7: 0 | U7: =S7-T7-V7 -> 0 | V7: 0 | X7: =+W7*V7 -> 0 | Y7: - | Z7: 0
A8: 5 | B8: ชิฟฟ่อนเค้ก 1 ชิ้น | C8: =+'12'!G8 -> 0 | D8: 0 | E8: =C8+D8 -> 0 | F8: 0 | G8: =E8-F8-H8 -> 0 | H8: 0 | I8: 10 | J8: =+I8*H8 -> 0 | K8: - | L8: 0 | M8: =+J8-L8 -> 0 | O8: 5 | Q8: 0 | R8: 0 | S8: =Q8+R8 -> 0 | T8: 0 | U8: =S8-T8-V8 -> 0 | V8: 0 | X8: =+W8*V8 -> 0 | Y8: - | Z8: 0
A9: 6 | B9: ชิฟฟ่อนเค้กสอดไส้แยม 1 ชิ้น | C9: =+'12'!G9 -> 0 | D9: 0 | E9: =C9+D9 -> 0 | F9: 0 | G9: =E9-F9-H9 -> 0 | H9: 0 | I9: 12 | J9: =+I9*H9 -> 0 | K9: - | L9: 0 | M9: =+J9-L9 -> 0 | O9: 6 | Q9: 0 | R9: 0 | S9: =Q9+R9 -> 0 | T9: 0 | U9: =S9-T9-V9 -> 0 | V9: 0 | X9: =+W9*V9 -> 0 | Y9: - | Z9: 0
A10: 7 | B10: ชิฟฟ่อน สอดไส้ (ล) 2 ชิ้น ครีมมะพร้าว | C10: =+'12'!G10 -> 0 | D10: 0 | E10: =C10+D10 -> 0 | F10: 0 | G10: =E10-F10-H10 -> 0 | H10: 0 | I10: 40 | J10: =+I10*H10 -> 0 | K10: - | L10: 0 | M10: =+J10-L10 -> 0 | O10: 7 | Q10: 0 | R10: 0 | S10: =Q10+R10 -> 0 | T10: 0 | U10: =S10-T10-V10 -> 0 | V10: 0 | X10: =+W10*V10 -> 0 | Y10: - | Z10: 0
A11: 8 | B11: ชิฟฟ่อน สอดไส้ (ล) 3 ชิ้น รวมรส | C11: =+'12'!G11 -> 10 | D11: 0 | E11: =C11+D11 -> 10 | F11: 0 | G11: =E11-F11-H11 -> 10 | H11: 0 | I11: 50 | J11: =+I11*H11 -> 0 | K11: - | L11: 0 | M11: =+J11-L11 -> 0 | O11: 8 | Q11: 0 | R11: 0 | S11: =Q11+R11 -> 0 | T11: 0 | U11: =S11-T11-V11 -> 0 | V11: 0 | X11: =+W11*V11 -> 0 | Y11: - | Z11: 0
A12: 9 | B12: ชิฟฟ่อน สอดไส้ (ล) 3 ชิ้น เมล่อน | C12: =+'12'!G12 -> 0 | D12: 0 | E12: =C12+D12 -> 0 | F12: 0 | G12: =E12-F12-H12 -> 0 | H12: 0 | I12: 55 | J12: =+I12*H12 -> 0 | K12: - | L12: 0 | M12: =+J12-L12 -> 0 | O12: 9 | Q12: 0 | R12: 0 | S12: =Q12+R12 -> 0 | T12: 0 | U12: =S12-T12-V12 -> 0 | V12: 0 | X12: =+W12*V12 -> 0 | Y12: - | Z12: 0
A13: 10 | B13: ชิฟฟ่อน สอดไส้ (ล) 4 ชิ้น ครีมมะพร้าว | C13: =+'12'!G13 -> 0 | D13: 0 | E13: =C13+D13 -> 0 | F13: 0 | G13: =E13-F13-H13 -> 0 | H13: 0 | I13: 65 | J13: =+I13*H13 -> 0 | K13: - | L13: 0 | M13: =+J13-L13 -> 0 | O13: 10 | Q13: 0 | R13: 0 | S13: =Q13+R13 -> 0 | T13: 0 | U13: =S13-T13-V13 -> 0 | V13: 0 | X13: =+W13*V13 -> 0 | Y13: - | Z13: 0
A14: 11 | B14: ชิฟฟ่อน สอดไส้ (ล) 3 ชิ้น แยมส้ม | C14: =+'12'!G14 -> 0 | D14: 0 | E14: =C14+D14 -> 0 | F14: 0 | G14: =E14-F14-H14 -> 0 | H14: 0 | I14: 50 | J14: =+I14*H14 -> 0 | K14: - | L14: 0 | M14: =+J14-L14 -> 0 | O14: 11 | Q14: 0 | R14: 0 | S14: =Q14+R14 -> 0 | T14: 0 | U14: =S14-T14-V14 -> 0 | V14: 0 | X14: =+W14*V14 -> 0 | Y14: - | Z14: 0
A15: 12 | B15: ชิฟฟ่อน สอดไส้ (ล) 3 ชิ้น บลูเบอรี่ | C15: =+'12'!G15 -> 0 | D15: 0 | E15: =C15+D15 -> 0 | F15: 0 | G15: =E15-F15-H15 -> 0 | H15: 0 | I15: 50 | J15: =+I15*H15 -> 0 | K15: - | L15: 0 | M15: =+J15-L15 -> 0 | O15: 12 | Q15: 0 | R15: 0 | S15: =Q15+R15 -> 0 | T15: 0 | U15: =S15-T15-V15 -> 0 | V15: 0 | X15: =+W15*V15 -> 0 | Y15: - | Z15: 0
... A102: 99 | B102: ไดฟุกุ 8 ชิ้น | C102: =+'12'!G102 -> 0 | D102: 0 | E102: =C102+D102 -> 0 | F102: 0 | G102: =E102-F102-H102 -> 0 | H102: 0 | I102: 100 | J102: =+I102*H102 -> 0 | K102: - | L102: 0 | M102: =+J102-L102 -> 0 | O102: 99 | Q102: 0 | R102: 0 | S102: =Q102+R102 -> 0 | T102: 0 | U102: =S102-T102-V102 -> 0 | V102: 0 | X102: =+W102*V102 -> 0 | Y102: - | Z102: 0
A103: 100 | B103: หมูทุบ | C103: =+'12'!G103 -> 0 | D103: 0 | E103: =C103+D103 -> 0 | F103: 0 | G103: =E103-F103-H103 -> 0 | H103: 0 | I103: 100 | J103: =+I103*H103 -> 0 | K103: - | L103: 0 | M103: =+J103-L103 -> 0 | O103: 100 | Q103: 0 | R103: 0 | S103: =Q103+R103 -> 0 | T103: 0 | U103: =S103-T103-V103 -> 0 | V103: 0 | X103: =+W103*V103 -> 0 | Z103: 0
A104: 101 | B104: ดอกจอก | C104: =+'12'!G104 -> 0 | D104: 0 | E104: =C104+D104 -> 0 | F104: 0 | G104: =E104-F104-H104 -> 0 | H104: 0 | I104: 30 | J104: =+I104*H104 -> 0 | K104: - | L104: 0 | M104: =+J104-L104 -> 0 | Z104: =SUM(Z4:Z103) -> 0
A105: 102 | B105: เทียน | C105: =+'12'!G105 -> 0 | D105: 0 | E105: =C105+D105 -> 0 | F105: 0 | G105: =E105-F105-H105 -> 0 | H105: 0 | I105: 20 | J105: =+I105*H105 -> 0 | K105: - | L105: 0 | M105: =+J105-L105 -> 0
A106: 103 | B106: ขนมอาลัวแฟนซี | C106: =+'12'!G106 -> 0 | D106: 0 | E106: =C106+D106 -> 0 | F106: 0 | G106: =E106-F106-H106 -> 0 | H106: 0 | I106: 100 | J106: =+I106*H106 -> 0 | K106: - | L106: 0 | M106: =+J106-L106 -> 0 | P106: รวม | X106: =SUM(X4:X103) -> 0
A107: 104 | B107: ชูนัทคุกกี้ | C107: =+'12'!G107 -> 0 | D107: 0 | E107: =C107+D107 -> 0 | F107: 0 | G107: =E107-F107-H107 -> 0 | H107: 0 | I107: 80 | J107: =+I107*H107 -> 0 | K107: - | L107: 0 | M107: =+J107-L107 -> 0
A108: 105 | B108: วุ้นแฟนซี | C108: =+'12'!G108 -> 0 | D108: 0 | E108: =C108+D108 -> 0 | F108: 0 | G108: =E108-F108-H108 -> 0 | H108: 0 | I108: 60 | J108: =+I108*H108 -> 0 | K108: - | L108: 0 | M108: =+J108-L108 -> 0
A109: 106 | B109: เค้กสามเหลี่ยม มะพร้าว | C109: =+'12'!G109 -> 0 | D109: 0 | E109: =C109+D109 -> 0 | F109: 0 | G109: =E109-F109-H109 -> 0 | H109: 0 | I109: 35 | J109: =+I109*H109 -> 0 | K109: - | L109: 0 | M109: =+J109-L109 -> 0
A110: 107 | B110: เค้กสามเหลี่ยม สตอเบอรี่ | C110: =+'12'!G110 -> 0 | D110: 0 | E110: =C110+D110 -> 0 | F110: 0 | G110: =E110-F110-H110 -> 0 | H110: 0 | I110: 35 | J110: =+I110*H110 -> 0 | K110: - | L110: 0 | M110: =+J110-L110 -> 0
A111: 108 | B111: เค้กสามเหลี่ยม บลูเบอรี่ | C111: =+'12'!G111 -> 0 | D111: 0 | E111: =C111+D111 -> 0 | F111: 0 | G111: =E111-F111-H111 -> 0 | H111: 0 | I111: 35 | J111: =+I111*H111 -> 0 | K111: - | L111: 0 | M111: =+J111-L111 -> 0
A112: 109 | B112: เค้กสามเหลี่ยม รสส้ม | C112: =+'12'!G112 -> 0 | D112: 0 | E112: =C112+D112 -> 0 | F112: 0 | G112: =E112-F112-H112 -> 0 | H112: 0 | I112: 35 | J112: =+I112*H112 -> 0 | K112: - | L112: 0 | M112: =+J112-L112 -> 0
A113: 110 | B113: เค้กสามเหลี่ยม รสช็อกโกโอริโอ้ | C113: =+'12'!G113 -> 0 | D113: 0 | E113: =C113+D113 -> 0 | F113: 0 | G113: =E113-F113-H113 -> 0 | H113: 0 | I113: 35 | J113: =+I113*H113 -> 0 | K113: - | L113: 0 | M113: =+J113-L113 -> 0
A114: 111 | B114: สตอเบอร์รี่ครีมเค้ก | C114: =+'12'!G114 -> 0 | D114: 0 | E114: =C114+D114 -> 0 | F114: 0 | G114: =E114-F114-H114 -> 0 | H114: 0 | I114: 50 | J114: =+I114*H114 -> 0 | K114: - | L114: 0 | M114: =+J114-L114 -> 0
A115: 112 | B115: บลูเบอร์รี่ครีมเค้ก | C115: =+'12'!G115 -> 0 | D115: 0 | E115: =C115+D115 -> 0 | F115: 0 | G115: =E115-F115-H115 -> 0 | H115: 0 | I115: 50 | J115: =+I115*H115 -> 0 | K115: - | L115: 0 | M115: =+J115-L115 -> 0
A116: 113 | B116: เค้กส้ม | C116: =+'12'!G116 -> 0 | D116: 0 | E116: =C116+D116 -> 0 | F116: 0 | G116: =E116-F116-H116 -> 0 | H116: 0 | I116: 50 | J116: =+I116*H116 -> 0 | K116: - | L116: 0 | M116: =+J116-L116 -> 0
A117: 114 | B117: วนิลาครีมเค้ก | C117: =+'12'!G117 -> 0 | D117: 0 | E117: =C117+D117 -> 0 | F117: 0 | G117: =E117-F117-H117 -> 0 | H117: 0 | I117: 50 | J117: =+I117*H117 -> 0 | K117: - | L117: 0 | M117: =+J117-L117 -> 0
A118: 115 | B118: ใบเตยครีมเค้ก | C118: =+'12'!G118 -> 0 | D118: 0 | E118: =C118+D118 -> 0 | F118: 0 | G118: =E118-F118-H118 -> 0 | H118: 0 | I118: 50 | J118: =+I118*H118 -> 0 | K118: - | L118: 0 | M118: =+J118-L118 -> 0
