Workbook

Sheet สรุป
A2: สรุป บูธ ร้านใหม่ลำ 3 วันที่ 1-31/12/2566
A3: ลำดับ | B3: รายการ | C3: ยกมา | D3: รับ | E3: รวม | F3: เปลี่ยน/ | G3: คงเหลือ | H3: รายการขาย | K3: หมายเหตุ | L3: วันที่ | M3: ยอดเงิน | N3: ส่วนลด | O3: สแกนใช้สิทธิ์ | P3: ค่าโอนเงิน | Q3: ค่าใช้จ่ายอื่นๆ | R3: โอนหน้าร้าน | S3: รับสุทธิ | T3: ยอดโอนเงิน | U3: โอนเกิน/โอนขาด
F4: คืน/เสีย | H4: จำนวน | I4: @ | J4: เป็นเงิน
A5: 1 | B5: ชิฟฟ่อน (ล) | C5: =+'วันที่ 1'!C5 -> 6 | D5: =+'วันที่ 1'!D5+'วันที่ 2'!D5+'วันที่ 3'!D5+'วันที่ 4'!D5+'วันที่ 5'!D5+'วันที่ 6'!D5+'วันที่ 7'!D5+'วันที่ 8'!D5+'วันที่ 9'!D5+'วันที่ 10'!D5+'วันที่ 11'!D5+'วันที่ 12'!D5+'วันที่ 13'!D5+'วันที่ 14'!D5+'วันที่ 15'!D5+'วันที่ 16'!D5+'วันที่ 17'!D5+'วันที่ 18'!D5+'วันที่ 19'!D5+'วันที่ 20'!D5+'วันที่ 21'!D5+'วันที่ 22'!D5+'วันที่ 23'!D5+'วันที่ 24'!D5+'วันที่ 25'!D5+'วันที่ 26'!D5+'วันที่ 27'!D5+'วันที่ 28'!D5+'วันที่ 29'!D5+'วันที่ 30'!D5+'วันที่ 31'!D5 -> 60 | E5: =+C5+D5 -> 66 | F5: =+'วันที่ 1'!F5+'วันที่ 2'!F5+'วันที่ 3'!F5+'วันที่ 4'!F5+'วันที่ 5'!F5+'วันที่ 6'!F5+'วันที่ 7'!F5+'วันที่ 8'!F5+'วันที่ 9'!F5+'วันที่ 10'!F5+'วันที่ 11'!F5+'วันที่ 12'!F5+'วันที่ 13'!F5+'วันที่ 14'!F5+'วันที่ 15'!F5+'วันที่ 16'!F5+'วันที่ 17'!F5+'วันที่ 18'!F5+'วันที่ 19'!F5+'วันที่ 20'!F5+'วันที่ 21'!F5+'วันที่ 22'!F5+'วันที่ 23'!F5+'วันที่ 24'!F5+'วันที่ 25'!F5+'วันที่ 26'!F5+'วันที่ 27'!F5+'วันที่ 28'!F5+'วันที่ 29'!F5+'วันที่ 30'!F5+'วันที่ 31'!F5 -> 0 | G5: =E5-F5-H5 -> 18 | H5: =+'วันที่ 1'!H5+'วันที่ 2'!H5+'วันที่ 3'!H5+'วันที่ 4'!H5+'วันที่ 5'!H5+'วันที่ 6'!H5+'วันที่ 7'!H5+'วันที่ 8'!H5+'วันที่ 9'!H5+'วันที่ 10'!H5+'วันที่ 11'!H5+'วันที่ 12'!H5+'วันที่ 13'!H5+'วันที่ 14'!H5+'วันที่ 15'!H5+'วันที่ 16'!H5+'วันที่ 17'!H5+'วันที่ 18'!H5+'วันที่ 19'!H5+'วันที่ 20'!H5+'วันที่ 21'!H5+'วันที่ 22'!H5+'วันที่ 23'!H5+'วันที่ 24'!H5+'วันที่ 25'!H5+'วันที่ 26'!H5+'วันที่ 27'!H5+'วันที่ 28'!H5+'วันที่ 29'!H5+'วันที่ 30'!H5+'วันที่ 31'!H5 -> 48 | I5: 50 | J5: =+'วันที่ 1'!J5+'วันที่ 2'!J5+'วันที่ 3'!J5+'วันที่ 4'!J5+'วันที่ 5'!J5+'วันที่ 6'!J5+'วันที่ 7'!J5+'วันที่ 8'!J5+'วันที่ 9'!J5+'วันที่ 10'!J5+'วันที่ 11'!J5+'วันที่ 12'!J5+'วันที่ 13'!J5+'วันที่ 14'!J5+'วันที่ 15'!J5+'วันที่ 16'!J5+'วันที่ 17'!J5+'วันที่ 18'!J5+'วันที่ 19'!J5+'วันที่ 20'!J5+'วันที่ 21'!J5+'วันที่ 22'!J5+'วันที่ 23'!J5+'วันที่ 24'!J5+'วันที่ 25'!J5+'วันที่ 26'!J5+'วันที่ 27'!J5+'วันที่ 28'!J5+'วันที่ 29'!J5+'วันที่ 30'!J5+'วันที่ 31'!J5 -> 2400 | L5: 1 | M5: =+'วันที่ 1'!K207 -> 2780 | N5: =+'วันที่ 1'!K212 -> 50 | O5: =+'วันที่ 1'!K210 -> 0 | P5: =+'วันที่ 1'!K208 -> 15 | Q5: =+'วันที่ 1'!K211 -> 0 | R5: =+'วันที่ 1'!K209 -> 1065 | S5: =+M5-N5-P5-R5-Q5 -> 1650 | T5: =+'วันที่ 1'!K214 -> 1650 | U5: =+T5-S5 -> 0
A6: 2 | B6: ชิฟฟ่อน (ญ) | C6: =+'วันที่ 1'!C6 -> 19 | D6: =+'วันที่ 1'!D6+'วันที่ 2'!D6+'วันที่ 3'!D6+'วันที่ 4'!D6+'วันที่ 5'!D6+'วันที่ 6'!D6+'วันที่ 7'!D6+'วันที่ 8'!D6+'วันที่ 9'!D6+'วันที่ 10'!D6+'วันที่ 11'!D6+'วันที่ 12'!D6+'วันที่ 13'!D6+'วันที่ 14'!D6+'วันที่ 15'!D6+'วันที่ 16'!D6+'วันที่ 17'!D6+'วันที่ 18'!D6+'วันที่ 19'!D6+'วันที่ 20'!D6+'วันที่ 21'!D6+'วันที่ 22'!D6+'วันที่ 23'!D6+'วันที่ 24'!D6+'วันที่ 25'!D6+'วันที่ 26'!D6+'วันที่ 27'!D6+'วันที่ 28'!D6+'วันที่ 29'!D6+'วันที่ 30'!D6+'วันที่ 31'!D6 -> 60 | E6: =+C6+D6 -> 79 | F6: =+'วันที่ 1'!F6+'วันที่ 2'!F6+'วันที่ 3'!F6+'วันที่ 4'!F6+'วันที่ 5'!F6+'วันที่ 6'!F6+'วันที่ 7'!F6+'วันที่ 8'!F6+'วันที่ 9'!F6+'วันที่ 10'!F6+'วันที่ 11'!F6+'วันที่ 12'!F6+'วันที่ 13'!F6+'วันที่ 14'!F6+'วันที่ 15'!F6+'วันที่ 16'!F6+'วันที่ 17'!F6+'วันที่ 18'!F6+'วันที่ 19'!F6+'วันที่ 20'!F6+'วันที่ 21'!F6+'วันที่ 22'!F6+'วันที่ 23'!F6+'วันที่ 24'!F6+'วันที่ 25'!F6+'วันที่ 26'!F6+'วันที่ 27'!F6+'วันที่ 28'!F6+'วันที่ 29'!F6+'วันที่ 30'!F6+'วันที่ 31'!F6 -> 0 | G6: =E6-F6-H6 -> 36 | H6: =+'วันที่ 1'!H6+'วันที่ 2'!H6+'วันที่ 3'!H6+'วันที่ 4'!H6+'วันที่ 5'!H6+'วันที่ 6'!H6+'วันที่ 7'!H6+'วันที่ 8'!H6+'วันที่ 9'!H6+'วันที่ 10'!H6+'วันที่ 11'!H6+'วันที่ 12'!H6+'วันที่ 13'!H6+'วันที่ 14'!H6+'วันที่ 15'!H6+'วันที่ 16'!H6+'วันที่ 17'!H6+'วันที่ 18'!H6+'วันที่ 19'!H6+'วันที่ 20'!H6+'วันที่ 21'!H6+'วันที่ 22'!H6+'วันที่ 23'!H6+'วันที่ 24'!H6+'วันที่ 25'!H6+'วันที่ 26'!H6+'วันที่ 27'!H6+'วันที่ 28'!H6+'วันที่ 29'!H6+'วันที่ 30'!H6+'วันที่ 31'!H6 -> 43 | I6: 100 | J6: =+'วันที่ 1'!J6+'วันที่ 2'!J6+'วันที่ 3'!J6+'วันที่ 4'!J6+'วันที่ 5'!J6+'วันที่ 6'!J6+'วันที่ 7'!J6+'วันที่ 8'!J6+'วันที่ 9'!J6+'วันที่ 10'!J6+'วันที่ 11'!J6+'วันที่ 12'!J6+'วันที่ 13'!J6+'วันที่ 14'!J6+'วันที่ 15'!J6+'วันที่ 16'!J6+'วันที่ 17'!J6+'วันที่ 18'!J6+'วันที่ 19'!J6+'วันที่ 20'!J6+'วันที่ 21'!J6+'วันที่ 22'!J6+'วันที่ 23'!J6+'วันที่ 24'!J6+'วันที่ 25'!J6+'วันที่ 26'!J6+'วันที่ 27'!J6+'วันที่ 28'!J6+'วันที่ 29'!J6+'วันที่ 30'!J6+'วันที่ 31'!J6 -> 4300 | L6: 2 | M6: =+'วันที่ 2'!K207 -> 3275 | N6: =+'วันที่ 2'!K212 -> 0 | O6: =+'วันที่ 2'!K210 -> 0 | P6: =+'วันที่ 2'!K208 -> 15 | Q6: =+'วันที่ 2'!K211 -> 0 | R6: =+'วันที่ 2'!K209 -> 940 | S6: =+M6-N6-P6-R6-Q6 -> 2320 | T6: =+'วันที่ 2'!K214 -> 2320 | U6: =+T6-S6 -> 0
A7: 3 | B7: ชิฟฟ่อน (ล) กาแฟ | C7: =+'วันที่ 1'!C7 -> 0 | D7: =+'วันที่ 1'!D7+'วันที่ 2'!D7+'วันที่ 3'!D7+'วันที่ 4'!D7+'วันที่ 5'!D7+'วันที่ 6'!D7+'วันที่ 7'!D7+'วันที่ 8'!D7+'วันที่ 9'!D7+'วันที่ 10'!D7+'วันที่ 11'!D7+'วันที่ 12'!D7+'วันที่ 13'!D7+'วันที่ 14'!D7+'วันที่ 15'!D7+'วันที่ 16'!D7+'วันที่ 17'!D7+'วันที่ 18'!D7+'วันที่ 19'!D7+'วันที่ 20'!D7+'วันที่ 21'!D7+'วันที่ 22'!D7+'วันที่ 23'!D7+'วันที่ 24'!D7+'วันที่ 25'!D7+'วันที่ 26'!D7+'วันที่ 27'!D7+'วันที่ 28'!D7+'วันที่ 29'!D7+'วันที่ 30'!D7+'วันที่ 31'!D7 -> 0 | E7: =+C7+D7 -> 0 | F7: =+'วันที่ 1'!F7+'วันที่ 2'!F7+'วันที่ 3'!F7+'วันที่ 4'!F7+'วันที่ 5'!F7+'วันที่ 6'!F7+'วันที่ 7'!F7+'วันที่ 8'!F7+'วันที่ 9'!F7+'วันที่ 10'!F7+'วันที่ 11'!F7+'วันที่ 12'!F7+'วันที่ 13'!F7+'วันที่ 14'!F7+'วันที่ 15'!F7+'วันที่ 16'!F7+'วันที่ 17'!F7+'วันที่ 18'!F7+'วันที่ 19'!F7+'วันที่ 20'!F7+'วันที่ 21'!F7+'วันที่ 22'!F7+'วันที่ 23'!F7+'วันที่ 24'!F7+'วันที่ 25'!F7+'วันที่ 26'!F7+'วันที่ 27'!F7+'วันที่ 28'!F7+'วันที่ 29'!F7+'วันที่ 30'!F7+'วันที่ 31'!F7 -> 0 | G7: =E7-F7-H7 -> 0 | H7: =+'วันที่ 1'!H7+'วันที่ 2'!H7+'วันที่ 3'!H7+'วันที่ 4'!H7+'วันที่ 5'!H7+'วันที่ 6'!H7+'วันที่ 7'!H7+'วันที่ 8'!H7+'วันที่ 9'!H7+'วันที่ 10'!H7+'วันที่ 11'!H7+'วันที่ 12'!H7+'วันที่ 13'!H7+'วันที่ 14'!H7+'วันที่ 15'!H7+'วันที่ 16'!H7+'วันที่ 17'!H7+'วันที่ 18'!H7+'วันที่ 19'!H7+'วันที่ 20'!H7+'วันที่ 21'!H7+'วันที่ 22'!H7+'วันที่ 23'!H7+'วันที่ 24'!H7+'วันที่ 25'!H7+'วันที่ 26'!H7+'วันที่ 27'!H7+'วันที่ 28'!H7+'วันที่ 29'!H7+'วันที่ 30'!H7+'วันที่ 31'!H7 -> 0 | I7: 50 | J7: =+'วันที่ 1'!J7+'วันที่ 2'!J7+'วันที่ 3'!J7+'วันที่ 4'!J7+'วันที่ 5'!J7+'วันที่ 6'!J7+'วันที่ 7'!J7+'วันที่ 8'!J7+'วันที่ 9'!J7+'วันที่ 10'!J7+'วันที่ 11'!J7+'วันที่ 12'!J7+'วันที่ 13'!J7+'วันที่ 14'!J7+'วันที่ 15'!J7+'วันที่ 16'!J7+'วันที่ 17'!J7+'วันที่ 18'!J7+'วันที่ 19'!J7+'วันที่ 20'!J7+'วันที่ 21'!J7+'วันที่ 22'!J7+'วันที่ 23'!J7+'วันที่ 24'!J7+'วันที่ 25'!J7+'วันที่ 26'!J7+'วันที่ 27'!J7+'วันที่ 28'!J7+'วันที่ 29'!J7+'วันที่ 30'!J7+'วันที่ 31'!J7 -> 0 | L7: 3 | M7: =+'วันที่ 3'!K207 -> 2790 | N7: =+'วันที่ 3'!K212 -> 50 | O7: =+'วันที่ 3'!K210 -> 0 | P7: =+'วันที่ 3'!K208 -> 15 | Q7: =+'วันที่ 3'!K211 -> 0 | R7: =+'วันที่ 3'!K209 -> 515 | S7: =+M7-N7-P7-R7-Q7 -> 2210 | T7: =+'วันที่ 3'!K214 -> 2210 | U7: =+T7-S7 -> 0
A8: 4 | B8: ชิฟฟ่อน (ญ) กาแฟ | C8: =+'วันที่ 1'!C8 -> 0 | D8: =+'วันที่ 1'!D8+'วันที่ 2'!D8+'วันที่ 3'!D8+'วันที่ 4'!D8+'วันที่ 5'!D8+'วันที่ 6'!D8+'วันที่ 7'!D8+'วันที่ 8'!D8+'วันที่ 9'!D8+'วันที่ 10'!D8+'วันที่ 11'!D8+'วันที่ 12'!D8+'วันที่ 13'!D8+'วันที่ 14'!D8+'วันที่ 15'!D8+'วันที่ 16'!D8+'วันที่ 17'!D8+'วันที่ 18'!D8+'วันที่ 19'!D8+'วันที่ 20'!D8+'วันที่ 21'!D8+'วันที่ 22'!D8+'วันที่ 23'!D8+'วันที่ 24'!D8+'วันที่ 25'!D8+'วันที่ 26'!D8+'วันที่ 27'!D8+'วันที่ 28'!D8+'วันที่ 29'!D8+'วันที่ 30'!D8+'วันที่ 31'!D8 -> 0 | E8: =+C8+D8 -> 0 | F8: =+'วันที่ 1'!F8+'วันที่ 2'!F8+'วันที่ 3'!F8+'วันที่ 4'!F8+'วันที่ 5'!F8+'วันที่ 6'!F8+'วันที่ 7'!F8+'วันที่ 8'!F8+'วันที่ 9'!F8+'วันที่ 10'!F8+'วันที่ 11'!F8+'วันที่ 12'!F8+'วันที่ 13'!F8+'วันที่ 14'!F8+'วันที่ 15'!F8+'วันที่ 16'!F8+'วันที่ 17'!F8+'วันที่ 18'!F8+'วันที่ 19'!F8+'วันที่ 20'!F8+'วันที่ 21'!F8+'วันที่ 22'!F8+'วันที่ 23'!F8+'วันที่ 24'!F8+'วันที่ 25'!F8+'วันที่ 26'!F8+'วันที่ 27'!F8+'วันที่ 28'!F8+'วันที่ 29'!F8+'วันที่ 30'!F8+'วันที่ 31'!F8 -> 0 | G8: =E8-F8-H8 -> 0 | H8: =+'วันที่ 1'!H8+'วันที่ 2'!H8+'วันที่ 3'!H8+'วันที่ 4'!H8+'วันที่ 5'!H8+'วันที่ 6'!H8+'วันที่ 7'!H8+'วันที่ 8'!H8+'วันที่ 9'!H8+'วันที่ 10'!H8+'วันที่ 11'!H8+'วันที่ 12'!H8+'วันที่ 13'!H8+'วันที่ 14'!H8+'วันที่ 15'!H8+'วันที่ 16'!H8+'วันที่ 17'!H8+'วันที่ 18'!H8+'วันที่ 19'!H8+'วันที่ 20'!H8+'วันที่ 21'!H8+'วันที่ 22'!H8+'วันที่ 23'!H8+'วันที่ 24'!H8+'วันที่ 25'!H8+'วันที่ 26'!H8+'วันที่ 27'!H8+'วันที่ 28'!H8+'วันที่ 29'!H8+'วันที่ 30'!H8+'วันที่ 31'!H8 -> 0 | I8: 100 | J8: =+'วันที่ 1'!J8+'วันที่ 2'!J8+'วันที่ 3'!J8+'วันที่ 4'!J8+'วันที่ 5'!J8+'วันที่ 6'!J8+'วันที่ 7'!J8+'วันที่ 8'!J8+'วันที่ 9'!J8+'วันที่ 10'!J8+'วันที่ 11'!J8+'วันที่ 12'!J8+'วันที่ 13'!J8+'วันที่ 14'!J8+'วันที่ 15'!J8+'วันที่ 16'!J8+'วันที่ 17'!J8+'วันที่ 18'!J8+'วันที่ 19'!J8+'วันที่ 20'!J8+'วันที่ 21'!J8+'วันที่ 22'!J8+'วันที่ 23'!J8+'วันที่ 24'!J8+'วันที่ 25'!J8+'วันที่ 26'!J8+'วันที่ 27'!J8+'วันที่ 28'!J8+'วันที่ 29'!J8+'วันที่ 30'!J8+'วันที่ 31'!J8 -> 0 | L8: 4 | M8: =+'วันที่ 4'!K207 -> 7570 | N8: =+'วันที่ 4'!K212 -> 100 | O8: =+'วันที่ 4'!K210 -> 0 | P8: =+'วันที่ 4'!K208 -> 15 | Q8: =+'วันที่ 4'!K211 -> 0 | R8: =+'วันที่ 4'!K209 -> 1925 | S8: =+M8-N8-P8-R8-Q8 -> 5530 | T8: =+'วันที่ 4'!K214 -> 5530 | U8: =+T8-S8 -> 0
A9: 5 | B9: ชิฟฟ่อนเค้ก 1 ชิ้น | C9: =+'วันที่ 1'!C9 -> 0 | D9: =+'วันที่ 1'!D9+'วันที่ 2'!D9+'วันที่ 3'!D9+'วันที่ 4'!D9+'วันที่ 5'!D9+'วันที่ 6'!D9+'วันที่ 7'!D9+'วันที่ 8'!D9+'วันที่ 9'!D9+'วันที่ 10'!D9+'วันที่ 11'!D9+'วันที่ 12'!D9+'วันที่ 13'!D9+'วันที่ 14'!D9+'วันที่ 15'!D9+'วันที่ 16'!D9+'วันที่ 17'!D9+'วันที่ 18'!D9+'วันที่ 19'!D9+'วันที่ 20'!D9+'วันที่ 21'!D9+'วันที่ 22'!D9+'วันที่ 23'!D9+'วันที่ 24'!D9+'วันที่ 25'!D9+'วันที่ 26'!D9+'วันที่ 27'!D9+'วันที่ 28'!D9+'วันที่ 29'!D9+'วันที่ 30'!D9+'วันที่ 31'!D9 -> 0 | E9: =+C9+D9 -> 0 | F9: =+'วันที่ 1'!F9+'วันที่ 2'!F9+'วันที่ 3'!F9+'วันที่ 4'!F9+'วันที่ 5'!F9+'วันที่ 6'!F9+'วันที่ 7'!F9+'วันที่ 8'!F9+'วันที่ 9'!F9+'วันที่ 10'!F9+'วันที่ 11'!F9+'วันที่ 12'!F9+'วันที่ 13'!F9+'วันที่ 14'!F9+'วันที่ 15'!F9+'วันที่ 16'!F9+'วันที่ 17'!F9+'วันที่ 18'!F9+'วันที่ 19'!F9+'วันที่ 20'!F9+'วันที่ 21'!F9+'วันที่ 22'!F9+'วันที่ 23'!F9+'วันที่ 24'!F9+'วันที่ 25'!F9+'วันที่ 26'!F9+'วันที่ 27'!F9+'วันที่ 28'!F9+'วันที่ 29'!F9+'วันที่ 30'!F9+'วันที่ 31'!F9 -> 0 | G9: =E9-F9-H9 -> 0 | H9: =+'วันที่ 1'!H9+'วันที่ 2'!H9+'วันที่ 3'!H9+'วันที่ 4'!H9+'วันที่ 5'!H9+'วันที่ 6'!H9+'วันที่ 7'!H9+'วันที่ 8'!H9+'วันที่ 9'!H9+'วันที่ 10'!H9+'วันที่ 11'!H9+'วันที่ 12'!H9+'วันที่ 13'!H9+'วันที่ 14'!H9+'วันที่ 15'!H9+'วันที่ 16'!H9+'วันที่ 17'!H9+'วันที่ 18'!H9+'วันที่ 19'!H9+'วันที่ 20'!H9+'วันที่ 21'!H9+'วันที่ 22'!H9+'วันที่ 23'!H9+'วันที่ 24'!H9+'วันที่ 25'!H9+'วันที่ 26'!H9+'วันที่ 27'!H9+'วันที่ 28'!H9+'วันที่ 29'!H9+'วันที่ 30'!H9+'วันที่ 31'!H9 -> 0 | I9: 12 | J9: =+'วันที่ 1'!J9+'วันที่ 2'!J9+'วันที่ 3'!J9+'วันที่ 4'!J9+'วันที่ 5'!J9+'วันที่ 6'!J9+'วันที่ 7'!J9+'วันที่ 8'!J9+'วันที่ 9'!J9+'วันที่ 10'!J9+'วันที่ 11'!J9+'วันที่ 12'!J9+'วันที่ 13'!J9+'วันที่ 14'!J9+'วันที่ 15'!J9+'วันที่ 16'!J9+'วันที่ 17'!J9+'วันที่ 18'!J9+'วันที่ 19'!J9+'วันที่ 20'!J9+'วันที่ 21'!J9+'วันที่ 22'!J9+'วันที่ 23'!J9+'วันที่ 24'!J9+'วันที่ 25'!J9+'วันที่ 26'!J9+'วันที่ 27'!J9+'วันที่ 28'!J9+'วันที่ 29'!J9+'วันที่ 30'!J9+'วันที่ 31'!J9 -> 0 | L9: 5 | M9: =+'วันที่ 5'!K207 -> 2775 | N9: =+'วันที่ 5'!K212 -> 80 | O9: =+'วันที่ 5'!K210 -> 0 | P9: =+'วันที่ 5'!K208 -> 15 | Q9: =+'วันที่ 5'!K211 -> 0 | R9: =+'วันที่ 5'!K209 -> 455 | S9: =+M9-N9-P9-R9-Q9 -> 2225 | T9: =+'วันที่ 5'!K214 -> 2225 | U9: =+T9-S9 -> 0
A10: 6 | B10: ชิฟฟ่อนเค้กสอดไส้แยม 1 ชิ้น | C10: =+'วันที่ 1'!C10 -> 0 | D10: =+'วันที่ 1'!D10+'วันที่ 2'!D10+'วันที่ 3'!D10+'วันที่ 4'!D10+'วันที่ 5'!D10+'วันที่ 6'!D10+'วันที่ 7'!D10+'วันที่ 8'!D10+'วันที่ 9'!D10+'วันที่ 10'!D10+'วันที่ 11'!D10+'วันที่ 12'!D10+'วันที่ 13'!D10+'วันที่ 14'!D10+'วันที่ 15'!D10+'วันที่ 16'!D10+'วันที่ 17'!D10+'วันที่ 18'!D10+'วันที่ 19'!D10+'วันที่ 20'!D10+'วันที่ 21'!D10+'วันที่ 22'!D10+'วันที่ 23'!D10+'วันที่ 24'!D10+'วันที่ 25'!D10+'วันที่ 26'!D10+'วันที่ 27'!D10+'วันที่ 28'!D10+'วันที่ 29'!D10+'วันที่ 30'!D10+'วันที่ 31'!D10 -> 0 | E10: =+C10+D10 -> 0 | F10: =+'วันที่ 1'!F10+'วันที่ 2'!F10+'วันที่ 3'!F10+'วันที่ 4'!F10+'วันที่ 5'!F10+'วันที่ 6'!F10+'วันที่ 7'!F10+'วันที่ 8'!F10+'วันที่ 9'!F10+'วันที่ 10'!F10+'วันที่ 11'!F10+'วันที่ 12'!F10+'วันที่ 13'!F10+'วันที่ 14'!F10+'วันที่ 15'!F10+'วันที่ 16'!F10+'วันที่ 17'!F10+'วันที่ 18'!F10+'วันที่ 19'!F10+'วันที่ 20'!F10+'วันที่ 21'!F10+'วันที่ 22'!F10+'วันที่ 23'!F10+'วันที่ 24'!F10+'วันที่ 25'!F10+'วันที่ 26'!F10+'วันที่ 27'!F10+'วันที่ 28'!F10+'วันที่ 29'!F10+'วันที่ 30'!F10+'วันที่ 31'!F10 -> 0 | G10: =E10-F10-H10 -> 0 | H10: =+'วันที่ 1'!H10+'วันที่ 2'!H10+'วันที่ 3'!H10+'วันที่ 4'!H10+'วันที่ 5'!H10+'วันที่ 6'!H10+'วันที่ 7'!H10+'วันที่ 8'!H10+'วันที่ 9'!H10+'วันที่ 10'!H10+'วันที่ 11'!H10+'วันที่ 12'!H10+'วันที่ 13'!H10+'วันที่ 14'!H10+'วันที่ 15'!H10+'วันที่ 16'!H10+'วันที่ 17'!H10+'วันที่ 18'!H10+'วันที่ 19'!H10+'วันที่ 20'!H10+'วันที่ 21'!H10+'วันที่ 22'!H10+'วันที่ 23'!H10+'วันที่ 24'!H10+'วันที่ 25'!H10+'วันที่ 26'!H10+'วันที่ 27'!H10+'วันที่ 28'!H10+'วันที่ 29'!H10+'วันที่ 30'!H10+'วันที่ 31'!H10 -> 0 | I10: 15 | J10: =+'วันที่ 1'!J10+'วันที่ 2'!J10+'วันที่ 3'!J10+'วันที่ 4'!J10+'วันที่ 5'!J10+'วันที่ 6'!J10+'วันที่ 7'!J10+'วันที่ 8'!J10+'วันที่ 9'!J10+'วันที่ 10'!J10+'วันที่ 11'!J10+'วันที่ 12'!J10+'วันที่ 13'!J10+'วันที่ 14'!J10+'วันที่ 15'!J10+'วันที่ 16'!J10+'วันที่ 17'!J10+'วันที่ 18'!J10+'วันที่ 19'!J10+'วันที่ 20'!J10+'วันที่ 21'!J10+'วันที่ 22'!J10+'วันที่ 23'!J10+'วันที่ 24'!J10+'วันที่ 25'!J10+'วันที่ 26'!J10+'วันที่ 27'!J10+'วันที่ 28'!J10+'วันที่ 29'!J10+'วันที่ 30'!J10+'วันที่ 31'!J10 -> 0 | L10: 6 | M10: =+'วันที่ 6'!K207 -> 2215 | N10: =+'วันที่ 6'!K212 -> 210 | O10: =+'วันที่ 6'!K210 -> 0 | P10: =+'วันที่ 6'!K208 -> 15 | Q10: =+'วันที่ 6'!K211 -> 0 | R10: =+'วันที่ 6'!K209 -> 700 | S10: =+M10-N10-P10-R10-Q10 -> 1290 | T10: =+'วันที่ 6'!K214 -> 1290 | U10: =+T10-S10 -> 0
A11: 7 | B11: ชิฟฟ่อน สอดไส้ (ล) 2 ชิ้น ครีมมะพร้าว | C11: =+'วันที่ 1'!C11 -> 0 | D11: =+'วันที่ 1'!D11+'วันที่ 2'!D11+'วันที่ 3'!D11+'วันที่ 4'!D11+'วันที่ 5'!D11+'วันที่ 6'!D11+'วันที่ 7'!D11+'วันที่ 8'!D11+'วันที่ 9'!D11+'วันที่ 10'!D11+'วันที่ 11'!D11+'วันที่ 12'!D11+'วันที่ 13'!D11+'วันที่ 14'!D11+'วันที่ 15'!D11+'วันที่ 16'!D11+'วันที่ 17'!D11+'วันที่ 18'!D11+'วันที่ 19'!D11+'วันที่ 20'!D11+'วันที่ 21'!D11+'วันที่ 22'!D11+'วันที่ 23'!D11+'วันที่ 24'!D11+'วันที่ 25'!D11+'วันที่ 26'!D11+'วันที่ 27'!D11+'วันที่ 28'!D11+'วันที่ 29'!D11+'วันที่ 30'!D11+'วันที่ 31'!D11 -> 0 | E11: =+C11+D11 -> 0 | F11: =+'วันที่ 1'!F11+'วันที่ 2'!F11+'วันที่ 3'!F11+'วันที่ 4'!F11+'วันที่ 5'!F11+'วันที่ 6'!F11+'วันที่ 7'!F11+'วันที่ 8'!F11+'วันที่ 9'!F11+'วันที่ 10'!F11+'วันที่ 11'!F11+'วันที่ 12'!F11+'วันที่ 13'!F11+'วันที่ 14'!F11+'วันที่ 15'!F11+'วันที่ 16'!F11+'วันที่ 17'!F11+'วันที่ 18'!F11+'วันที่ 19'!F11+'วันที่ 20'!F11+'วันที่ 21'!F11+'วันที่ 22'!F11+'วันที่ 23'!F11+'วันที่ 24'!F11+'วันที่ 25'!F11+'วันที่ 26'!F11+'วันที่ 27'!F11+'วันที่ 28'!F11+'วันที่ 29'!F11+'วันที่ 30'!F11+'วันที่ 31'!F11 -> 0 | G11: =E11-F11-H11 -> 0 | H11: =+'วันที่ 1'!H11+'วันที่ 2'!H11+'วันที่ 3'!H11+'วันที่ 4'!H11+'วันที่ 5'!H11+'วันที่ 6'!H11+'วันที่ 7'!H11+'วันที่ 8'!H11+'วันที่ 9'!H11+'วันที่ 10'!H11+'วันที่ 11'!H11+'วันที่ 12'!H11+'วันที่ 13'!H11+'วันที่ 14'!H11+'วันที่ 15'!H11+'วันที่ 16'!H11+'วันที่ 17'!H11+'วันที่ 18'!H11+'วันที่ 19'!H11+'วันที่ 20'!H11+'วันที่ 21'!H11+'วันที่ 22'!H11+'วันที่ 23'!H11+'วันที่ 24'!H11+'วันที่ 25'!H11+'วันที่ 26'!H11+'วันที่ 27'!H11+'วันที่ 28'!H11+'วันที่ 29'!H11+'วันที่ 30'!H11+'วันที่ 31'!H11 -> 0 | I11: 40 | J11: =+'วันที่ 1'!J11+'วันที่ 2'!J11+'วันที่ 3'!J11+'วันที่ 4'!J11+'วันที่ 5'!J11+'วันที่ 6'!J11+'วันที่ 7'!J11+'วันที่ 8'!J11+'วันที่ 9'!J11+'วันที่ 10'!J11+'วันที่ 11'!J11+'วันที่ 12'!J11+'วันที่ 13'!J11+'วันที่ 14'!J11+'วันที่ 15'!J11+'วันที่ 16'!J11+'วันที่ 17'!J11+'วันที่ 18'!J11+'วันที่ 19'!J11+'วันที่ 20'!J11+'วันที่ 21'!J11+'วันที่ 22'!J11+'วันที่ 23'!J11+'วันที่ 24'!J11+'วันที่ 25'!J11+'วันที่ 26'!J11+'วันที่ 27'!J11+'วันที่ 28'!J11+'วันที่ 29'!J11+'วันที่ 30'!J11+'วันที่ 31'!J11 -> 0 | L11: 7 | M11: =+'วันที่ 7'!K207 -> 1800 | N11: =+'วันที่ 7'!K212 -> 0 | O11: =+'วันที่ 7'!K210 -> 0 | P11: =+'วันที่ 7'!K208 -> 15 | Q11: =+'วันที่ 7'!K211 -> 0 | R11: =+'วันที่ 7'!K209 -> 700 | S11: =+M11-N11-P11-R11-Q11 -> 1085 | T11: =+'วันที่ 7'!K214 -> 1085 | U11: =+T11-S11 -> 0
A12: 8 | B12: ชิฟฟ่อน สอดไส้ (ล) 3 ชิ้น รวมรส | C12: =+'วันที่ 1'!C12 -> 7 | D12: =+'วันที่ 1'!D12+'วันที่ 2'!D12+'วันที่ 3'!D12+'วันที่ 4'!D12+'วันที่ 5'!D12+'วันที่ 6'!D12+'วันที่ 7'!D12+'วันที่ 8'!D12+'วันที่ 9'!D12+'วันที่ 10'!D12+'วันที่ 11'!D12+'วันที่ 12'!D12+'วันที่ 13'!D12+'วันที่ 14'!D12+'วันที่ 15'!D12+'วันที่ 16'!D12+'วันที่ 17'!D12+'วันที่ 18'!D12+'วันที่ 19'!D12+'วันที่ 20'!D12+'วันที่ 21'!D12+'วันที่ 22'!D12+'วันที่ 23'!D12+'วันที่ 24'!D12+'วันที่ 25'!D12+'วันที่ 26'!D12+'วันที่ 27'!D12+'วันที่ 28'!D12+'วันที่ 29'!D12+'วันที่ 30'!D12+'วันที่ 31'!D12 -> 25 | E12: =+C12+D12 -> 32 | F12: =+'วันที่ 1'!F12+'วันที่ 2'!F12+'วันที่ 3'!F12+'วันที่ 4'!F12+'วันที่ 5'!F12+'วันที่ 6'!F12+'วันที่ 7'!F12+'วันที่ 8'!F12+'วันที่ 9'!F12+'วันที่ 10'!F12+'วันที่ 11'!F12+'วันที่ 12'!F12+'วันที่ 13'!F12+'วันที่ 14'!F12+'วันที่ 15'!F12+'วันที่ 16'!F12+'วันที่ 17'!F12+'วันที่ 18'!F12+'วันที่ 19'!F12+'วันที่ 20'!F12+'วันที่ 21'!F12+'วันที่ 22'!F12+'วันที่ 23'!F12+'วันที่ 24'!F12+'วันที่ 25'!F12+'วันที่ 26'!F12+'วันที่ 27'!F12+'วันที่ 28'!F12+'วันที่ 29'!F12+'วันที่ 30'!F12+'วันที่ 31'!F12 -> 0 | G12: =E12-F12-H12 -> 8 | H12: =+'วันที่ 1'!H12+'วันที่ 2'!H12+'วันที่ 3'!H12+'วันที่ 4'!H12+'วันที่ 5'!H12+'วันที่ 6'!H12+'วันที่ 7'!H12+'วันที่ 8'!H12+'วันที่ 9'!H12+'วันที่ 10'!H12+'วันที่ 11'!H12+'วันที่ 12'!H12+'วันที่ 13'!H12+'วันที่ 14'!H12+'วันที่ 15'!H12+'วันที่ 16'!H12+'วันที่ 17'!H12+'วันที่ 18'!H12+'วันที่ 19'!H12+'วันที่ 20'!H12+'วันที่ 21'!H12+'วันที่ 22'!H12+'วันที่ 23'!H12+'วันที่ 24'!H12+'วันที่ 25'!H12+'วันที่ 26'!H12+'วันที่ 27'!H12+'วันที่ 28'!H12+'วันที่ 29'!H12+'วันที่ 30'!H12+'วันที่ 31'!H12 -> 24 | I12: 50 | J12: =+'วันที่ 1'!J12+'วันที่ 2'!J12+'วันที่ 3'!J12+'วันที่ 4'!J12+'วันที่ 5'!J12+'วันที่ 6'!J12+'วันที่ 7'!J12+'วันที่ 8'!J12+'วันที่ 9'!J12+'วันที่ 10'!J12+'วันที่ 11'!J12+'วันที่ 12'!J12+'วันที่ 13'!J12+'วันที่ 14'!J12+'วันที่ 15'!J12+'วันที่ 16'!J12+'วันที่ 17'!J12+'วันที่ 18'!J12+'วันที่ 19'!J12+'วันที่ 20'!J12+'วันที่ 21'!J12+'วันที่ 22'!J12+'วันที่ 23'!J12+'วันที่ 24'!J12+'วันที่ 25'!J12+'วันที่ 26'!J12+'วันที่ 27'!J12+'วันที่ 28'!J12+'วันที่ 29'!J12+'วันที่ 30'!J12+'วันที่ 31'!J12 -> 1200 | L12: 8 | M12: =+'วันที่ 8'!K207 -> 2665 | N12: =+'วันที่ 8'!K212 -> 165 | O12: =+'วันที่ 8'!K210 -> 0 | P12: =+'วันที่ 8'!K208 -> 15 | Q12: =+'วันที่ 8'!K211 -> 0 | R12: =+'วันที่ 8'!K209 -> 1110 | S12: =+M12-N12-P12-R12-Q12 -> 1375 | T12: =+'วันที่ 8'!K214 -> 1375 | U12: =+T12-S12 -> 0
A13: 9 | B13: ชิฟฟ่อน สอดไส้ (ล) 3 ชิ้น เมล่อน | C13: =+'วันที่ 1'!C13 -> 0 | D13: =+'วันที่ 1'!D13+'วันที่ 2'!D13+'วันที่ 3'!D13+'วันที่ 4'!D13+'วันที่ 5'!D13+'วันที่ 6'!D13+'วันที่ 7'!D13+'วันที่ 8'!D13+'วันที่ 9'!D13+'วันที่ 10'!D13+'วันที่ 11'!D13+'วันที่ 12'!D13+'วันที่ 13'!D13+'วันที่ 14'!D13+'วันที่ 15'!D13+'วันที่ 16'!D13+'วันที่ 17'!D13+'วันที่ 18'!D13+'วันที่ 19'!D13+'วันที่ 20'!D13+'วันที่ 21'!D13+'วันที่ 22'!D13+'วันที่ 23'!D13+'วันที่ 24'!D13+'วันที่ 25'!D13+'วันที่ 26'!D13+'วันที่ 27'!D13+'วันที่ 28'!D13+'วันที่ 29'!D13+'วันที่ 30'!D13+'วันที่ 31'!D13 -> 0 | E13: =+C13+D13 -> 0 | F13: =+'วันที่ 1'!F13+'วันที่ 2'!F13+'วันที่ 3'!F13+'วันที่ 4'!F13+'วันที่ 5'!F13+'วันที่ 6'!F13+'วันที่ 7'!F13+'วันที่ 8'!F13+'วันที่ 9'!F13+'วันที่ 10'!F13+'วันที่ 11'!F13+'วันที่ 12'!F13+'วันที่ 13'!F13+'วันที่ 14'!F13+'วันที่ 15'!F13+'วันที่ 16'!F13+'วันที่ 17'!F13+'วันที่ 18'!F13+'วันที่ 19'!F13+'วันที่ 20'!F13+'วันที่ 21'!F13+'วันที่ 22'!F13+'วันที่ 23'!F13+'วันที่ 24'!F13+'วันที่ 25'!F13+'วันที่ 26'!F13+'วันที่ 27'!F13+'วันที่ 28'!F13+'วันที่ 29'!F13+'วันที่ 30'!F13+'วันที่ 31'!F13 -> 0 | G13: =E13-F13-H13 -> 0 | H13: =+'วันที่ 1'!H13+'วันที่ 2'!H13+'วันที่ 3'!H13+'วันที่ 4'!H13+'วันที่ 5'!H13+'วันที่ 6'!H13+'วันที่ 7'!H13+'วันที่ 8'!H13+'วันที่ 9'!H13+'วันที่ 10'!H13+'วันที่ 11'!H13+'วันที่ 12'!H13+'วันที่ 13'!H13+'วันที่ 14'!H13+'วันที่ 15'!H13+'วันที่ 16'!H13+'วันที่ 17'!H13+'วันที่ 18'!H13+'วันที่ 19'!H13+'วันที่ 20'!H13+'วันที่ 21'!H13+'วันที่ 22'!H13+'วันที่ 23'!H13+'วันที่ 24'!H13+'วันที่ 25'!H13+'วันที่ 26'!H13+'วันที่ 27'!H13+'วันที่ 28'!H13+'วันที่ 29'!H13+'วันที่ 30'!H13+'วันที่ 31'!H13 -> 0 | I13: 55 | J13: =+'วันที่ 1'!J13+'วันที่ 2'!J13+'วันที่ 3'!J13+'วันที่ 4'!J13+'วันที่ 5'!J13+'วันที่ 6'!J13+'วันที่ 7'!J13+'วันที่ 8'!J13+'วันที่ 9'!J13+'วันที่ 10'!J13+'วันที่ 11'!J13+'วันที่ 12'!J13+'วันที่ 13'!J13+'วันที่ 14'!J13+'วันที่ 15'!J13+'วันที่ 16'!J13+'วันที่ 17'!J13+'วันที่ 18'!J13+'วันที่ 19'!J13+'วันที่ 20'!J13+'วันที่ 21'!J13+'วันที่ 22'!J13+'วันที่ 23'!J13+'วันที่ 24'!J13+'วันที่ 25'!J13+'วันที่ 26'!J13+'วันที่ 27'!J13+'วันที่ 28'!J13+'วันที่ 29'!J13+'วันที่ 30'!J13+'วันที่ 31'!J13 -> 0 | L13: 9 | M13: =+'วันที่ 9'!K207 -> 4015 | N13: =+'วันที่ 9'!K212 -> 150 | O13: =+'วันที่ 9'!K210 -> 0 | P13: =+'วันที่ 9'!K208 -> 15 | Q13: =+'วันที่ 9'!K211 -> 0 | R13: =+'วันที่ 9'!K209 -> 855 | S13: =+M13-N13-P13-R13-Q13 -> 2995 | T13: =+'วันที่ 9'!K214 -> 2995 | U13: =+T13-S13 -> 0
A14: 10 | B14: ชิฟฟ่อน สอดไส้ (ล) 4 ชิ้น ครีมมะพร้าว | C14: =+'วันที่ 1'!C14 -> 3 | D14: =+'วันที่ 1'!D14+'วันที่ 2'!D14+'วันที่ 3'!D14+'วันที่ 4'!D14+'วันที่ 5'!D14+'วันที่ 6'!D14+'วันที่ 7'!D14+'วันที่ 8'!D14+'วันที่ 9'!D14+'วันที่ 10'!D14+'วันที่ 11'!D14+'วันที่ 12'!D14+'วันที่ 13'!D14+'วันที่ 14'!D14+'วันที่ 15'!D14+'วันที่ 16'!D14+'วันที่ 17'!D14+'วันที่ 18'!D14+'วันที่ 19'!D14+'วันที่ 20'!D14+'วันที่ 21'!D14+'วันที่ 22'!D14+'วันที่ 23'!D14+'วันที่ 24'!D14+'วันที่ 25'!D14+'วันที่ 26'!D14+'วันที่ 27'!D14+'วันที่ 28'!D14+'วันที่ 29'!D14+'วันที่ 30'!D14+'วันที่ 31'!D14 -> 25 | E14: =+C14+D14 -> 28 | F14: =+'วันที่ 1'!F14+'วันที่ 2'!F14+'วันที่ 3'!F14+'วันที่ 4'!F14+'วันที่ 5'!F14+'วันที่ 6'!F14+'วันที่ 7'!F14+'วันที่ 8'!F14+'วันที่ 9'!F14+'วันที่ 10'!F14+'วันที่ 11'!F14+'วันที่ 12'!F14+'วันที่ 13'!F14+'วันที่ 14'!F14+'วันที่ 15'!F14+'วันที่ 16'!F14+'วันที่ 17'!F14+'วันที่ 18'!F14+'วันที่ 19'!F14+'วันที่ 20'!F14+'วันที่ 21'!F14+'วันที่ 22'!F14+'วันที่ 23'!F14+'วันที่ 24'!F14+'วันที่ 25'!F14+'วันที่ 26'!F14+'วันที่ 27'!F14+'วันที่ 28'!F14+'วันที่ 29'!F14+'วันที่ 30'!F14+'วันที่ 31'!F14 -> 0 | G14: =E14-F14-H14 -> 5 | H14: =+'วันที่ 1'!H14+'วันที่ 2'!H14+'วันที่ 3'!H14+'วันที่ 4'!H14+'วันที่ 5'!H14+'วันที่ 6'!H14+'วันที่ 7'!H14+'วันที่ 8'!H14+'วันที่ 9'!H14+'วันที่ 10'!H14+'วันที่ 11'!H14+'วันที่ 12'!H14+'วันที่ 13'!H14+'วันที่ 14'!H14+'วันที่ 15'!H14+'วันที่ 16'!H14+'วันที่ 17'!H14+'วันที่ 18'!H14+'วันที่ 19'!H14+'วันที่ 20'!H14+'วันที่ 21'!H14+'วันที่ 22'!H14+'วันที่ 23'!H14+'วันที่ 24'!H14+'วันที่ 25'!H14+'วันที่ 26'!H14+'วันที่ 27'!H14+'วันที่ 28'!H14+'วันที่ 29'!H14+'วันที่ 30'!H14+'วันที่ 31'!H14 -> 23 | I14: 65 | J14: =+'วันที่ 1'!J14+'วันที่ 2'!J14+'วันที่ 3'!J14+'วันที่ 4'!J14+'วันที่ 5'!J14+'วันที่ 6'!J14+'วันที่ 7'!J14+'วันที่ 8'!J14+'วันที่ 9'!J14+'วันที่ 10'!J14+'วันที่ 11'!J14+'วันที่ 12'!J14+'วันที่ 13'!J14+'วันที่ 14'!J14+'วันที่ 15'!J14+'วันที่ 16'!J14+'วันที่ 17'!J14+'วันที่ 18'!J14+'วันที่ 19'!J14+'วันที่ 20'!J14+'วันที่ 21'!J14+'วันที่ 22'!J14+'วันที่ 23'!J14+'วันที่ 24'!J14+'วันที่ 25'!J14+'วันที่ 26'!J14+'วันที่ 27'!J14+'วันที่ 28'!J14+'วันที่ 29'!J14+'วันที่ 30'!J14+'วันที่ 31'!J14 -> 1495 | L14: 10 | M14: =+'วันที่ 10'!K207 -> 3355 | N14: =+'วันที่ 10'!K212 -> 0 | O14: =+'วันที่ 10'!K210 -> 0 | P14: =+'วันที่ 10'!K208 -> 15 | Q14: =+'วันที่ 10'!K211 -> 0 | R14: =+'วันที่ 10'!K209 -> 815 | S14: =+M14-N14-P14-R14-Q14 -> 2525 | T14: =+'วันที่ 10'!K214 -> 2525 | U14: =+T14-S14 -> 0
A15: 11 | B15: ชิฟฟ่อน สอดไส้ (ล) 3 ชิ้น แยมส้ม | C15: =+'วันที่ 1'!C15 -> 0 | D15: =+'วันที่ 1'!D15+'วันที่ 2'!D15+'วันที่ 3'!D15+'วันที่ 4'!D15+'วันที่ 5'!D15+'วันที่ 6'!D15+'วันที่ 7'!D15+'วันที่ 8'!D15+'วันที่ 9'!D15+'วันที่ 10'!D15+'วันที่ 11'!D15+'วันที่ 12'!D15+'วันที่ 13'!D15+'วันที่ 14'!D15+'วันที่ 15'!D15+'วันที่ 16'!D15+'วันที่ 17'!D15+'วันที่ 18'!D15+'วันที่ 19'!D15+'วันที่ 20'!D15+'วันที่ 21'!D15+'วันที่ 22'!D15+'วันที่ 23'!D15+'วันที่ 24'!D15+'วันที่ 25'!D15+'วันที่ 26'!D15+'วันที่ 27'!D15+'วันที่ 28'!D15+'วันที่ 29'!D15+'วันที่ 30'!D15+'วันที่ 31'!D15 -> 0 | E15: =+C15+D15 -> 0 | F15: =+'วันที่ 1'!F15+'วันที่ 2'!F15+'วันที่ 3'!F15+'วันที่ 4'!F15+'วันที่ 5'!F15+'วันที่ 6'!F15+'วันที่ 7'!F15+'วันที่ 8'!F15+'วันที่ 9'!F15+'วันที่ 10'!F15+'วันที่ 11'!F15+'วันที่ 12'!F15+'วันที่ 13'!F15+'วันที่ 14'!F15+'วันที่ 15'!F15+'วันที่ 16'!F15+'วันที่ 17'!F15+'วันที่ 18'!F15+'วันที่ 19'!F15+'วันที่ 20'!F15+'วันที่ 21'!F15+'วันที่ 22'!F15+'วันที่ 23'!F15+'วันที่ 24'!F15+'วันที่ 25'!F15+'วันที่ 26'!F15+'วันที่ 27'!F15+'วันที่ 28'!F15+'วันที่ 29'!F15+'วันที่ 30'!F15+'วันที่ 31'!F15 -> 0 | G15: =E15-F15-H15 -> 0 | H15: =+'วันที่ 1'!H15+'วันที่ 2'!H15+'วันที่ 3'!H15+'วันที่ 4'!H15+'วันที่ 5'!H15+'วันที่ 6'!H15+'วันที่ 7'!H15+'วันที่ 8'!H15+'วันที่ 9'!H15+'วันที่ 10'!H15+'วันที่ 11'!H15+'วันที่ 12'!H15+'วันที่ 13'!H15+'วันที่ 14'!H15+'วันที่ 15'!H15+'วันที่ 16'!H15+'วันที่ 17'!H15+'วันที่ 18'!H15+'วันที่ 19'!H15+'วันที่ 20'!H15+'วันที่ 21'!H15+'วันที่ 22'!H15+'วันที่ 23'!H15+'วันที่ 24'!H15+'วันที่ 25'!H15+'วันที่ 26'!H15+'วันที่ 27'!H15+'วันที่ 28'!H15+'วันที่ 29'!H15+'วันที่ 30'!H15+'วันที่ 31'!H15 -> 0 | I15: 50 | J15: =+'วันที่ 1'!J15+'วันที่ 2'!J15+'วันที่ 3'!J15+'วันที่ 4'!J15+'วันที่ 5'!J15+'วันที่ 6'!J15+'วันที่ 7'!J15+'วันที่ 8'!J15+'วันที่ 9'!J15+'วันที่ 10'!J15+'วันที่ 11'!J15+'วันที่ 12'!J15+'วันที่ 13'!J15+'วันที่ 14'!J15+'วันที่ 15'!J15+'วันที่ 16'!J15+'วันที่ 17'!J15+'วันที่ 18'!J15+'วันที่ 19'!J15+'วันที่ 20'!J15+'วันที่ 21'!J15+'วันที่ 22'!J15+'วันที่ 23'!J15+'วันที่ 24'!J15+'วันที่ 25'!J15+'วันที่ 26'!J15+'วันที่ 27'!J15+'วันที่ 28'!J15+'วันที่ 29'!J15+'วันที่ 30'!J15+'วันที่ 31'!J15 -> 0 | L15: 11 | M15: =+'วันที่ 11'!K207 -> 9535 | N15: =+'วันที่ 11'!K212 -> 380 | O15: =+'วันที่ 11'!K210 -> 0 | P15: =+'วันที่ 11'!K208 -> 15 | Q15: =+'วันที่ 11'!K211 -> 0 | R15: =+'วันที่ 11'!K209 -> 2670 | S15: =+M15-N15-P15-R15-Q15 -> 6470 | T15: =+'วันที่ 11'!K214 -> 6470 | U15: =+T15-S15 -> 0
A16: 12 | B16: ชิฟฟ่อน สอดไส้ (ล) 3 ชิ้น บลูเบอรี่ | C16: =+'วันที่ 1'!C16 -> 0 | D16: =+'วันที่ 1'!D16+'วันที่ 2'!D16+'วันที่ 3'!D16+'วันที่ 4'!D16+'วันที่ 5'!D16+'วันที่ 6'!D16+'วันที่ 7'!D16+'วันที่ 8'!D16+'วันที่ 9'!D16+'วันที่ 10'!D16+'วันที่ 11'!D16+'วันที่ 12'!D16+'วันที่ 13'!D16+'วันที่ 14'!D16+'วันที่ 15'!D16+'วันที่ 16'!D16+'วันที่ 17'!D16+'วันที่ 18'!D16+'วันที่ 19'!D16+'วันที่ 20'!D16+'วันที่ 21'!D16+'วันที่ 22'!D16+'วันที่ 23'!D16+'วันที่ 24'!D16+'วันที่ 25'!D16+'วันที่ 26'!D16+'วันที่ 27'!D16+'วันที่ 28'!D16+'วันที่ 29'!D16+'วันที่ 30'!D16+'วันที่ 31'!D16 -> 0 | E16: =+C16+D16 -> 0 | F16: =+'วันที่ 1'!F16+'วันที่ 2'!F16+'วันที่ 3'!F16+'วันที่ 4'!F16+'วันที่ 5'!F16+'วันที่ 6'!F16+'วันที่ 7'!F16+'วันที่ 8'!F16+'วันที่ 9'!F16+'วันที่ 10'!F16+'วันที่ 11'!F16+'วันที่ 12'!F16+'วันที่ 13'!F16+'วันที่ 14'!F16+'วันที่ 15'!F16+'วันที่ 16'!F16+'วันที่ 17'!F16+'วันที่ 18'!F16+'วันที่ 19'!F16+'วันที่ 20'!F16+'วันที่ 21'!F16+'วันที่ 22'!F16+'วันที่ 23'!F16+'วันที่ 24'!F16+'วันที่ 25'!F16+'วันที่ 26'!F16+'วันที่ 27'!F16+'วันที่ 28'!F16+'วันที่ 29'!F16+'วันที่ 30'!F16+'วันที่ 31'!F16 -> 0 | G16: =E16-F16-H16 -> 0 | H16: =+'วันที่ 1'!H16+'วันที่ 2'!H16+'วันที่ 3'!H16+'วันที่ 4'!H16+'วันที่ 5'!H16+'วันที่ 6'!H16+'วันที่ 7'!H16+'วันที่ 8'!H16+'วันที่ 9'!H16+'วันที่ 10'!H16+'วันที่ 11'!H16+'วันที่ 12'!H16+'วันที่ 13'!H16+'วันที่ 14'!H16+'วันที่ 15'!H16+'วันที่ 16'!H16+'วันที่ 17'!H16+'วันที่ 18'!H16+'วันที่ 19'!H16+'วันที่ 20'!H16+'วันที่ 21'!H16+'วันที่ 22'!H16+'วันที่ 23'!H16+'วันที่ 24'!H16+'วันที่ 25'!H16+'วันที่ 26'!H16+'วันที่ 27'!H16+'วันที่ 28'!H16+'วันที่ 29'!H16+'วันที่ 30'!H16+'วันที่ 31'!H16 -> 0 | I16: 50 | J16: =+'วันที่ 1'!J16+'วันที่ 2'!J16+'วันที่ 3'!J16+'วันที่ 4'!J16+'วันที่ 5'!J16+'วันที่ 6'!J16+'วันที่ 7'!J16+'วันที่ 8'!J16+'วันที่ 9'!J16+'วันที่ 10'!J16+'วันที่ 11'!J16+'วันที่ 12'!J16+'วันที่ 13'!J16+'วันที่ 14'!J16+'วันที่ 15'!J16+'วันที่ 16'!J16+'วันที่ 17'!J16+'วันที่ 18'!J16+'วันที่ 19'!J16+'วันที่ 20'!J16+'วันที่ 21'!J16+'วันที่ 22'!J16+'วันที่ 23'!J16+'วันที่ 24'!J16+'วันที่ 25'!J16+'วันที่ 26'!J16+'วันที่ 27'!J16+'วันที่ 28'!J16+'วันที่ 29'!J16+'วันที่ 30'!J16+'วันที่ 31'!J16 -> 0 | L16: 12 | M16: =+'วันที่ 12'!K207 -> 3615 | N16: =+'วันที่ 12'!K212 -> 120 | O16: =+'วันที่ 12'!K210 -> 0 | P16: =+'วันที่ 12'!K208 -> 15 | Q16: =+'วันที่ 12'!K211 -> 0 | R16: =+'วันที่ 12'!K209 -> 1215 | S16: =+M16-N16-P16-R16-Q16 -> 2265 | T16: =+'วันที่ 12'!K214 -> 2265 | U16: =+T16-S16 -> 0
A17: 13 | B17: ชิฟฟ่อน สอดไส้ (ล) 3 ชิ้น ฝอยทอง | C17: =+'วันที่ 1'!C17 -> 7 | D17: =+'วันที่ 1'!D17+'วันที่ 2'!D17+'วันที่ 3'!D17+'วันที่ 4'!D17+'วันที่ 5'!D17+'วันที่ 6'!D17+'วันที่ 7'!D17+'วันที่ 8'!D17+'วันที่ 9'!D17+'วันที่ 10'!D17+'วันที่ 11'!D17+'วันที่ 12'!D17+'วันที่ 13'!D17+'วันที่ 14'!D17+'วันที่ 15'!D17+'วันที่ 16'!D17+'วันที่ 17'!D17+'วันที่ 18'!D17+'วันที่ 19'!D17+'วันที่ 20'!D17+'วันที่ 21'!D17+'วันที่ 22'!D17+'วันที่ 23'!D17+'วันที่ 24'!D17+'วันที่ 25'!D17+'วันที่ 26'!D17+'วันที่ 27'!D17+'วันที่ 28'!D17+'วันที่ 29'!D17+'วันที่ 30'!D17+'วันที่ 31'!D17 -> 25 | E17: =+C17+D17 -> 32 | F17: =+'วันที่ 1'!F17+'วันที่ 2'!F17+'วันที่ 3'!F17+'วันที่ 4'!F17+'วันที่ 5'!F17+'วันที่ 6'!F17+'วันที่ 7'!F17+'วันที่ 8'!F17+'วันที่ 9'!F17+'วันที่ 10'!F17+'วันที่ 11'!F17+'วันที่ 12'!F17+'วันที่ 13'!F17+'วันที่ 14'!F17+'วันที่ 15'!F17+'วันที่ 16'!F17+'วันที่ 17'!F17+'วันที่ 18'!F17+'วันที่ 19'!F17+'วันที่ 20'!F17+'วันที่ 21'!F17+'วันที่ 22'!F17+'วันที่ 23'!F17+'วันที่ 24'!F17+'วันที่ 25'!F17+'วันที่ 26'!F17+'วันที่ 27'!F17+'วันที่ 28'!F17+'วันที่ 29'!F17+'วันที่ 30'!F17+'วันที่ 31'!F17 -> 0 | G17: =E17-F17-H17 -> 8 | H17: =+'วันที่ 1'!H17+'วันที่ 2'!H17+'วันที่ 3'!H17+'วันที่ 4'!H17+'วันที่ 5'!H17+'วันที่ 6'!H17+'วันที่ 7'!H17+'วันที่ 8'!H17+'วันที่ 9'!H17+'วันที่ 10'!H17+'วันที่ 11'!H17+'วันที่ 12'!H17+'วันที่ 13'!H17+'วันที่ 14'!H17+'วันที่ 15'!H17+'วันที่ 16'!H17+'วันที่ 17'!H17+'วันที่ 18'!H17+'วันที่ 19'!H17+'วันที่ 20'!H17+'วันที่ 21'!H17+'วันที่ 22'!H17+'วันที่ 23'!H17+'วันที่ 24'!H17+'วันที่ 25'!H17+'วันที่ 26'!H17+'วันที่ 27'!H17+'วันที่ 28'!H17+'วันที่ 29'!H17+'วันที่ 30'!H17+'วันที่ 31'!H17 -> 24 | I17: 50 | J17: =+'วันที่ 1'!J17+'วันที่ 2'!J17+'วันที่ 3'!J17+'วันที่ 4'!J17+'วันที่ 5'!J17+'วันที่ 6'!J17+'วันที่ 7'!J17+'วันที่ 8'!J17+'วันที่ 9'!J17+'วันที่ 10'!J17+'วันที่ 11'!J17+'วันที่ 12'!J17+'วันที่ 13'!J17+'วันที่ 14'!J17+'วันที่ 15'!J17+'วันที่ 16'!J17+'วันที่ 17'!J17+'วันที่ 18'!J17+'วันที่ 19'!J17+'วันที่ 20'!J17+'วันที่ 21'!J17+'วันที่ 22'!J17+'วันที่ 23'!J17+'วันที่ 24'!J17+'วันที่ 25'!J17+'วันที่ 26'!J17+'วันที่ 27'!J17+'วันที่ 28'!J17+'วันที่ 29'!J17+'วันที่ 30'!J17+'วันที่ 31'!J17 -> 1200 | L17: 13 | M17: =+'วันที่ 13'!K207 -> 2105 | N17: =+'วันที่ 13'!K212 -> 50 | O17: =+'วันที่ 13'!K210 -> 0 | P17: =+'วันที่ 13'!K208 -> 15 | Q17: =+'วันที่ 13'!K211 -> 0 | R17: =+'วันที่ 13'!K209 -> 865 | S17: =+M17-N17-P17-R17-Q17 -> 1175 | T17: =+'วันที่ 13'!K214 -> 1175 | U17: =+T17-S17 -> 0
A18: 14 | B18: ชิฟฟ่อน สอดไส้ (ล) 3 ชิ้น แยมสตรอเบอรี่ | C18: =+'วันที่ 1'!C18 -> 0 | D18: =+'วันที่ 1'!D18+'วันที่ 2'!D18+'วันที่ 3'!D18+'วันที่ 4'!D18+'วันที่ 5'!D18+'วันที่ 6'!D18+'วันที่ 7'!D18+'วันที่ 8'!D18+'วันที่ 9'!D18+'วันที่ 10'!D18+'วันที่ 11'!D18+'วันที่ 12'!D18+'วันที่ 13'!D18+'วันที่ 14'!D18+'วันที่ 15'!D18+'วันที่ 16'!D18+'วันที่ 17'!D18+'วันที่ 18'!D18+'วันที่ 19'!D18+'วันที่ 20'!D18+'วันที่ 21'!D18+'วันที่ 22'!D18+'วันที่ 23'!D18+'วันที่ 24'!D18+'วันที่ 25'!D18+'วันที่ 26'!D18+'วันที่ 27'!D18+'วันที่ 28'!D18+'วันที่ 29'!D18+'วันที่ 30'!D18+'วันที่ 31'!D18 -> 0 | E18: =+C18+D18 -> 0 | F18: =+'วันที่ 1'!F18+'วันที่ 2'!F18+'วันที่ 3'!F18+'วันที่ 4'!F18+'วันที่ 5'!F18+'วันที่ 6'!F18+'วันที่ 7'!F18+'วันที่ 8'!F18+'วันที่ 9'!F18+'วันที่ 10'!F18+'วันที่ 11'!F18+'วันที่ 12'!F18+'วันที่ 13'!F18+'วันที่ 14'!F18+'วันที่ 15'!F18+'วันที่ 16'!F18+'วันที่ 17'!F18+'วันที่ 18'!F18+'วันที่ 19'!F18+'วันที่ 20'!F18+'วันที่ 21'!F18+'วันที่ 22'!F18+'วันที่ 23'!F18+'วันที่ 24'!F18+'วันที่ 25'!F18+'วันที่ 26'!F18+'วันที่ 27'!F18+'วันที่ 28'!F18+'วันที่ 29'!F18+'วันที่ 30'!F18+'วันที่ 31'!F18 -> 0 | G18: =E18-F18-H18 -> 0 | H18: =+'วันที่ 1'!H18+'วันที่ 2'!H18+'วันที่ 3'!H18+'วันที่ 4'!H18+'วันที่ 5'!H18+'วันที่ 6'!H18+'วันที่ 7'!H18+'วันที่ 8'!H18+'วันที่ 9'!H18+'วันที่ 10'!H18+'วันที่ 11'!H18+'วันที่ 12'!H18+'วันที่ 13'!H18+'วันที่ 14'!H18+'วันที่ 15'!H18+'วันที่ 16'!H18+'วันที่ 17'!H18+'วันที่ 18'!H18+'วันที่ 19'!H18+'วันที่ 20'!H18+'วันที่ 21'!H18+'วันที่ 22'!H18+'วันที่ 23'!H18+'วันที่ 24'!H18+'วันที่ 25'!H18+'วันที่ 26'!H18+'วันที่ 27'!H18+'วันที่ 28'!H18+'วันที่ 29'!H18+'วันที่ 30'!H18+'วันที่ 31'!H18 -> 0 | I18: 50 | J18: =+'วันที่ 1'!J18+'วันที่ 2'!J18+'วันที่ 3'!J18+'วันที่ 4'!J18+'วันที่ 5'!J18+'วันที่ 6'!J18+'วันที่ 7'!J18+'วันที่ 8'!J18+'วันที่ 9'!J18+'วันที่ 10'!J18+'วันที่ 11'!J18+'วันที่ 12'!J18+'วันที่ 13'!J18+'วันที่ 14'!J18+'วันที่ 15'!J18+'วันที่ 16'!J18+'วันที่ 17'!J18+'วันที่ 18'!J18+'วันที่ 19'!J18+'วันที่ 20'!J18+'วันที่ 21'!J18+'วันที่ 22'!J18+'วันที่ 23'!J18+'วันที่ 24'!J18+'วันที่ 25'!J18+'วันที่ 26'!J18+'วันที่ 27'!J18+'วันที่ 28'!J18+'วันที่ 29'!J18+'วันที่ 30'!J18+'วันที่ 31'!J18 -> 0 | L18: 14 | M18: =+'วันที่ 14'!K207 -> 1520 | N18: =+'วันที่ 14'!K212 -> 70 | O18: =+'วันที่ 14'!K210 -> 0 | P18: =+'วันที่ 14'!K208 -> 15 | Q18: =+'วันที่ 14'!K211 -> 0 | R18: =+'วันที่ 14'!K209 -> 670 | S18: =+M18-N18-P18-R18-Q18 -> 765 | T18: =+'วันที่ 14'!K214 -> 765 | U18: =+T18-S18 -> 0
A19: 15 | B19: ชิฟฟ่อน สอดไส้ (ล) 3 ชิ้น เนยมพะร้าว | C19: =+'วันที่ 1'!C19 -> 7 | D19: =+'วันที่ 1'!D19+'วันที่ 2'!D19+'วันที่ 3'!D19+'วันที่ 4'!D19+'วันที่ 5'!D19+'วันที่ 6'!D19+'วันที่ 7'!D19+'วันที่ 8'!D19+'วันที่ 9'!D19+'วันที่ 10'!D19+'วันที่ 11'!D19+'วันที่ 12'!D19+'วันที่ 13'!D19+'วันที่ 14'!D19+'วันที่ 15'!D19+'วันที่ 16'!D19+'วันที่ 17'!D19+'วันที่ 18'!D19+'วันที่ 19'!D19+'วันที่ 20'!D19+'วันที่ 21'!D19+'วันที่ 22'!D19+'วันที่ 23'!D19+'วันที่ 24'!D19+'วันที่ 25'!D19+'วันที่ 26'!D19+'วันที่ 27'!D19+'วันที่ 28'!D19+'วันที่ 29'!D19+'วันที่ 30'!D19+'วันที่ 31'!D19 -> 35 | E19: =+C19+D19 -> 42 | F19: =+'วันที่ 1'!F19+'วันที่ 2'!F19+'วันที่ 3'!F19+'วันที่ 4'!F19+'วันที่ 5'!F19+'วันที่ 6'!F19+'วันที่ 7'!F19+'วันที่ 8'!F19+'วันที่ 9'!F19+'วันที่ 10'!F19+'วันที่ 11'!F19+'วันที่ 12'!F19+'วันที่ 13'!F19+'วันที่ 14'!F19+'วันที่ 15'!F19+'วันที่ 16'!F19+'วันที่ 17'!F19+'วันที่ 18'!F19+'วันที่ 19'!F19+'วันที่ 20'!F19+'วันที่ 21'!F19+'วันที่ 22'!F19+'วันที่ 23'!F19+'วันที่ 24'!F19+'วันที่ 25'!F19+'วันที่ 26'!F19+'วันที่ 27'!F19+'วันที่ 28'!F19+'วันที่ 29'!F19+'วันที่ 30'!F19+'วันที่ 31'!F19 -> 4 | G19: =E19-F19-H19 -> 12 | H19: =+'วันที่ 1'!H19+'วันที่ 2'!H19+'วันที่ 3'!H19+'วันที่ 4'!H19+'วันที่ 5'!H19+'วันที่ 6'!H19+'วันที่ 7'!H19+'วันที่ 8'!H19+'วันที่ 9'!H19+'วันที่ 10'!H19+'วันที่ 11'!H19+'วันที่ 12'!H19+'วันที่ 13'!H19+'วันที่ 14'!H19+'วันที่ 15'!H19+'วันที่ 16'!H19+'วันที่ 17'!H19+'วันที่ 18'!H19+'วันที่ 19'!H19+'วันที่ 20'!H19+'วันที่ 21'!H19+'วันที่ 22'!H19+'วันที่ 23'!H19+'วันที่ 24'!H19+'วันที่ 25'!H19+'วันที่ 26'!H19+'วันที่ 27'!H19+'วันที่ 28'!H19+'วันที่ 29'!H19+'วันที่ 30'!H19+'วันที่ 31'!H19 -> 26 | I19: 50 | J19: =+'วันที่ 1'!J19+'วันที่ 2'!J19+'วันที่ 3'!J19+'วันที่ 4'!J19+'วันที่ 5'!J19+'วันที่ 6'!J19+'วันที่ 7'!J19+'วันที่ 8'!J19+'วันที่ 9'!J19+'วันที่ 10'!J19+'วันที่ 11'!J19+'วันที่ 12'!J19+'วันที่ 13'!J19+'วันที่ 14'!J19+'วันที่ 15'!J19+'วันที่ 16'!J19+'วันที่ 17'!J19+'วันที่ 18'!J19+'วันที่ 19'!J19+'วันที่ 20'!J19+'วันที่ 21'!J19+'วันที่ 22'!J19+'วันที่ 23'!J19+'วันที่ 24'!J19+'วันที่ 25'!J19+'วันที่ 26'!J19+'วันที่ 27'!J19+'วันที่ 28'!J19+'วันที่ 29'!J19+'วันที่ 30'!J19+'วันที่ 31'!J19 -> 1300 | L19: 15 | M19: =+'วันที่ 15'!K207 -> 2215 | N19: =+'วันที่ 15'!K212 -> 120 | O19: =+'วันที่ 15'!K210 -> 0 | P19: =+'วันที่ 15'!K208 -> 15 | Q19: =+'วันที่ 15'!K211 -> 0 | R19: =+'วันที่ 15'!K209 -> 210 | S19: =+M19-N19-P19-R19-Q19 -> 1870 | T19: =+'วันที่ 15'!K214 -> 1870 | U19: =+T19-S19 -> 0
A20: 16 | B20: ชิฟฟ่อน สอดไส้ (ล) 3 ชิ้น นมชมพู | C20: =+'วันที่ 1'!C20 -> 0 | D20: =+'วันที่ 1'!D20+'วันที่ 2'!D20+'วันที่ 3'!D20+'วันที่ 4'!D20+'วันที่ 5'!D20+'วันที่ 6'!D20+'วันที่ 7'!D20+'วันที่ 8'!D20+'วันที่ 9'!D20+'วันที่ 10'!D20+'วันที่ 11'!D20+'วันที่ 12'!D20+'วันที่ 13'!D20+'วันที่ 14'!D20+'วันที่ 15'!D20+'วันที่ 16'!D20+'วันที่ 17'!D20+'วันที่ 18'!D20+'วันที่ 19'!D20+'วันที่ 20'!D20+'วันที่ 21'!D20+'วันที่ 22'!D20+'วันที่ 23'!D20+'วันที่ 24'!D20+'วันที่ 25'!D20+'วันที่ 26'!D20+'วันที่ 27'!D20+'วันที่ 28'!D20+'วันที่ 29'!D20+'วันที่ 30'!D20+'วันที่ 31'!D20 -> 0 | E20: =+C20+D20 -> 0 | F20: =+'วันที่ 1'!F20+'วันที่ 2'!F20+'วันที่ 3'!F20+'วันที่ 4'!F20+'วันที่ 5'!F20+'วันที่ 6'!F20+'วันที่ 7'!F20+'วันที่ 8'!F20+'วันที่ 9'!F20+'วันที่ 10'!F20+'วันที่ 11'!F20+'วันที่ 12'!F20+'วันที่ 13'!F20+'วันที่ 14'!F20+'วันที่ 15'!F20+'วันที่ 16'!F20+'วันที่ 17'!F20+'วันที่ 18'!F20+'วันที่ 19'!F20+'วันที่ 20'!F20+'วันที่ 21'!F20+'วันที่ 22'!F20+'วันที่ 23'!F20+'วันที่ 24'!F20+'วันที่ 25'!F20+'วันที่ 26'!F20+'วันที่ 27'!F20+'วันที่ 28'!F20+'วันที่ 29'!F20+'วันที่ 30'!F20+'วันที่ 31'!F20 -> 0 | G20: =E20-F20-H20 -> 0 | H20: =+'วันที่ 1'!H20+'วันที่ 2'!H20+'วันที่ 3'!H20+'วันที่ 4'!H20+'วันที่ 5'!H20+'วันที่ 6'!H20+'วันที่ 7'!H20+'วันที่ 8'!H20+'วันที่ 9'!H20+'วันที่ 10'!H20+'วันที่ 11'!H20+'วันที่ 12'!H20+'วันที่ 13'!H20+'วันที่ 14'!H20+'วันที่ 15'!H20+'วันที่ 16'!H20+'วันที่ 17'!H20+'วันที่ 18'!H20+'วันที่ 19'!H20+'วันที่ 20'!H20+'วันที่ 21'!H20+'วันที่ 22'!H20+'วันที่ 23'!H20+'วันที่ 24'!H20+'วันที่ 25'!H20+'วันที่ 26'!H20+'วันที่ 27'!H20+'วันที่ 28'!H20+'วันที่ 29'!H20+'วันที่ 30'!H20+'วันที่ 31'!H20 -> 0 | I20: 50 | J20: =+'วันที่ 1'!J20+'วันที่ 2'!J20+'วันที่ 3'!J20+'วันที่ 4'!J20+'วันที่ 5'!J20+'วันที่ 6'!J20+'วันที่ 7'!J20+'วันที่ 8'!J20+'วันที่ 9'!J20+'วันที่ 10'!J20+'วันที่ 11'!J20+'วันที่ 12'!J20+'วันที่ 13'!J20+'วันที่ 14'!J20+'วันที่ 15'!J20+'วันที่ 16'!J20+'วันที่ 17'!J20+'วันที่ 18'!J20+'วันที่ 19'!J20+'วันที่ 20'!J20+'วันที่ 21'!J20+'วันที่ 22'!J20+'วันที่ 23'!J20+'วันที่ 24'!J20+'วันที่ 25'!J20+'วันที่ 26'!J20+'วันที่ 27'!J20+'วันที่ 28'!J20+'วันที่ 29'!J20+'วันที่ 30'!J20+'วันที่ 31'!J20 -> 0 | L20: 16 | M20: =+'วันที่ 16'!K207 -> 0 | N20: =+'วันที่ 16'!K212 -> 0 | O20: =+'วันที่ 16'!K210 -> 0 | P20: =+'วันที่ 16'!K208 -> 0 | Q20: =+'วันที่ 16'!K211 -> 0 | R20: =+'วันที่ 16'!K209 -> 0 | S20: =+M20-N20-P20-R20-Q20 -> 0 | T20: =+'วันที่ 16'!K214 -> 0 | U20: =+T20-S20 -> 0
A21: 17 | B21: ชิฟฟ่อน สอดไส้ (ล) 3 ชิ้น ช็อคโกแลต | C21: =+'วันที่ 1'!C21 -> 0 | D21: =+'วันที่ 1'!D21+'วันที่ 2'!D21+'วันที่ 3'!D21+'วันที่ 4'!D21+'วันที่ 5'!D21+'วันที่ 6'!D21+'วันที่ 7'!D21+'วันที่ 8'!D21+'วันที่ 9'!D21+'วันที่ 10'!D21+'วันที่ 11'!D21+'วันที่ 12'!D21+'วันที่ 13'!D21+'วันที่ 14'!D21+'วันที่ 15'!D21+'วันที่ 16'!D21+'วันที่ 17'!D21+'วันที่ 18'!D21+'วันที่ 19'!D21+'วันที่ 20'!D21+'วันที่ 21'!D21+'วันที่ 22'!D21+'วันที่ 23'!D21+'วันที่ 24'!D21+'วันที่ 25'!D21+'วันที่ 26'!D21+'วันที่ 27'!D21+'วันที่ 28'!D21+'วันที่ 29'!D21+'วันที่ 30'!D21+'วันที่ 31'!D21 -> 0 | E21: =+C21+D21 -> 0 | F21: =+'วันที่ 1'!F21+'วันที่ 2'!F21+'วันที่ 3'!F21+'วันที่ 4'!F21+'วันที่ 5'!F21+'วันที่ 6'!F21+'วันที่ 7'!F21+'วันที่ 8'!F21+'วันที่ 9'!F21+'วันที่ 10'!F21+'วันที่ 11'!F21+'วันที่ 12'!F21+'วันที่ 13'!F21+'วันที่ 14'!F21+'วันที่ 15'!F21+'วันที่ 16'!F21+'วันที่ 17'!F21+'วันที่ 18'!F21+'วันที่ 19'!F21+'วันที่ 20'!F21+'วันที่ 21'!F21+'วันที่ 22'!F21+'วันที่ 23'!F21+'วันที่ 24'!F21+'วันที่ 25'!F21+'วันที่ 26'!F21+'วันที่ 27'!F21+'วันที่ 28'!F21+'วันที่ 29'!F21+'วันที่ 30'!F21+'วันที่ 31'!F21 -> 0 | G21: =E21-F21-H21 -> 0 | H21: =+'วันที่ 1'!H21+'วันที่ 2'!H21+'วันที่ 3'!H21+'วันที่ 4'!H21+'วันที่ 5'!H21+'วันที่ 6'!H21+'วันที่ 7'!H21+'วันที่ 8'!H21+'วันที่ 9'!H21+'วันที่ 10'!H21+'วันที่ 11'!H21+'วันที่ 12'!H21+'วันที่ 13'!H21+'วันที่ 14'!H21+'วันที่ 15'!H21+'วันที่ 16'!H21+'วันที่ 17'!H21+'วันที่ 18'!H21+'วันที่ 19'!H21+'วันที่ 20'!H21+'วันที่ 21'!H21+'วันที่ 22'!H21+'วันที่ 23'!H21+'วันที่ 24'!H21+'วันที่ 25'!H21+'วันที่ 26'!H21+'วันที่ 27'!H21+'วันที่ 28'!H21+'วันที่ 29'!H21+'วันที่ 30'!H21+'วันที่ 31'!H21 -> 0 | I21: 50 | J21: =+'วันที่ 1'!J21+'วันที่ 2'!J21+'วันที่ 3'!J21+'วันที่ 4'!J21+'วันที่ 5'!J21+'วันที่ 6'!J21+'วันที่ 7'!J21+'วันที่ 8'!J21+'วันที่ 9'!J21+'วันที่ 10'!J21+'วันที่ 11'!J21+'วันที่ 12'!J21+'วันที่ 13'!J21+'วันที่ 14'!J21+'วันที่ 15'!J21+'วันที่ 16'!J21+'วันที่ 17'!J21+'วันที่ 18'!J21+'วันที่ 19'!J21+'วันที่ 20'!J21+'วันที่ 21'!J21+'วันที่ 22'!J21+'วันที่ 23'!J21+'วันที่ 24'!J21+'วันที่ 25'!J21+'วันที่ 26'!J21+'วันที่ 27'!J21+'วันที่ 28'!J21+'วันที่ 29'!J21+'วันที่ 30'!J21+'วันที่ 31'!J21 -> 0 | L21: 17 | M21: =+'วันที่ 17'!K207 -> 0 | N21: =+'วันที่ 17'!K212 -> 0 | O21: =+'วันที่ 17'!K210 -> 0 | P21: =+'วันที่ 17'!K208 -> 0 | Q21: =+'วันที่ 17'!K211 -> 0 | R21: =+'วันที่ 17'!K209 -> 0 | S21: =+M21-N21-P21-R21-Q21 -> 0 | T21: =+'วันที่ 17'!K214 -> 0 | U21: =+T21-S21 -> 0
A22: 18 | B22: ชิฟฟ่อน สอดไส้ (ก) 5 ชิ้น | C22: =+'วันที่ 1'!C22 -> 5 | D22: =+'วันที่ 1'!D22+'วันที่ 2'!D22+'วันที่ 3'!D22+'วันที่ 4'!D22+'วันที่ 5'!D22+'วันที่ 6'!D22+'วันที่ 7'!D22+'วันที่ 8'!D22+'วันที่ 9'!D22+'วันที่ 10'!D22+'วันที่ 11'!D22+'วันที่ 12'!D22+'วันที่ 13'!D22+'วันที่ 14'!D22+'วันที่ 15'!D22+'วันที่ 16'!D22+'วันที่ 17'!D22+'วันที่ 18'!D22+'วันที่ 19'!D22+'วันที่ 20'!D22+'วันที่ 21'!D22+'วันที่ 22'!D22+'วันที่ 23'!D22+'วันที่ 24'!D22+'วันที่ 25'!D22+'วันที่ 26'!D22+'วันที่ 27'!D22+'วันที่ 28'!D22+'วันที่ 29'!D22+'วันที่ 30'!D22+'วันที่ 31'!D22 -> 13 | E22: =+C22+D22 -> 18 | F22: =+'วันที่ 1'!F22+'วันที่ 2'!F22+'วันที่ 3'!F22+'วันที่ 4'!F22+'วันที่ 5'!F22+'วันที่ 6'!F22+'วันที่ 7'!F22+'วันที่ 8'!F22+'วันที่ 9'!F22+'วันที่ 10'!F22+'วันที่ 11'!F22+'วันที่ 12'!F22+'วันที่ 13'!F22+'วันที่ 14'!F22+'วันที่ 15'!F22+'วันที่ 16'!F22+'วันที่ 17'!F22+'วันที่ 18'!F22+'วันที่ 19'!F22+'วันที่ 20'!F22+'วันที่ 21'!F22+'วันที่ 22'!F22+'วันที่ 23'!F22+'วันที่ 24'!F22+'วันที่ 25'!F22+'วันที่ 26'!F22+'วันที่ 27'!F22+'วันที่ 28'!F22+'วันที่ 29'!F22+'วันที่ 30'!F22+'วันที่ 31'!F22 -> 0 | G22: =E22-F22-H22 -> 5 | H22: =+'วันที่ 1'!H22+'วันที่ 2'!H22+'วันที่ 3'!H22+'วันที่ 4'!H22+'วันที่ 5'!H22+'วันที่ 6'!H22+'วันที่ 7'!H22+'วันที่ 8'!H22+'วันที่ 9'!H22+'วันที่ 10'!H22+'วันที่ 11'!H22+'วันที่ 12'!H22+'วันที่ 13'!H22+'วันที่ 14'!H22+'วันที่ 15'!H22+'วันที่ 16'!H22+'วันที่ 17'!H22+'วันที่ 18'!H22+'วันที่ 19'!H22+'วันที่ 20'!H22+'วันที่ 21'!H22+'วันที่ 22'!H22+'วันที่ 23'!H22+'วันที่ 24'!H22+'วันที่ 25'!H22+'วันที่ 26'!H22+'วันที่ 27'!H22+'วันที่ 28'!H22+'วันที่ 29'!H22+'วันที่ 30'!H22+'วันที่ 31'!H22 -> 13 | I22: 85 | J22: =+'วันที่ 1'!J22+'วันที่ 2'!J22+'วันที่ 3'!J22+'วันที่ 4'!J22+'วันที่ 5'!J22+'วันที่ 6'!J22+'วันที่ 7'!J22+'วันที่ 8'!J22+'วันที่ 9'!J22+'วันที่ 10'!J22+'วันที่ 11'!J22+'วันที่ 12'!J22+'วันที่ 13'!J22+'วันที่ 14'!J22+'วันที่ 15'!J22+'วันที่ 16'!J22+'วันที่ 17'!J22+'วันที่ 18'!J22+'วันที่ 19'!J22+'วันที่ 20'!J22+'วันที่ 21'!J22+'วันที่ 22'!J22+'วันที่ 23'!J22+'วันที่ 24'!J22+'วันที่ 25'!J22+'วันที่ 26'!J22+'วันที่ 27'!J22+'วันที่ 28'!J22+'วันที่ 29'!J22+'วันที่ 30'!J22+'วันที่ 31'!J22 -> 1105 | L22: 18 | M22: =+'วันที่ 18'!K207 -> 0 | N22: =+'วันที่ 18'!K212 -> 0 | O22: =+'วันที่ 18'!K210 -> 0 | P22: =+'วันที่ 18'!K208 -> 0 | Q22: =+'วันที่ 18'!K211 -> 0 | R22: =+'วันที่ 18'!K209 -> 0 | S22: =+M22-N22-P22-R22-Q22 -> 0 | T22: =+'วันที่ 18'!K214 -> 0 | U22: =+T22-S22 -> 0
A23: 19 | B23: ชิฟฟ่อน สอดไส้ 6 ชิ้น รวมรส | C23: =+'วันที่ 1'!C23 -> 9 | D23: =+'วันที่ 1'!D23+'วันที่ 2'!D23+'วันที่ 3'!D23+'วันที่ 4'!D23+'วันที่ 5'!D23+'วันที่ 6'!D23+'วันที่ 7'!D23+'วันที่ 8'!D23+'วันที่ 9'!D23+'วันที่ 10'!D23+'วันที่ 11'!D23+'วันที่ 12'!D23+'วันที่ 13'!D23+'วันที่ 14'!D23+'วันที่ 15'!D23+'วันที่ 16'!D23+'วันที่ 17'!D23+'วันที่ 18'!D23+'วันที่ 19'!D23+'วันที่ 20'!D23+'วันที่ 21'!D23+'วันที่ 22'!D23+'วันที่ 23'!D23+'วันที่ 24'!D23+'วันที่ 25'!D23+'วันที่ 26'!D23+'วันที่ 27'!D23+'วันที่ 28'!D23+'วันที่ 29'!D23+'วันที่ 30'!D23+'วันที่ 31'!D23 -> 45 | E23: =+C23+D23 -> 54 | F23: =+'วันที่ 1'!F23+'วันที่ 2'!F23+'วันที่ 3'!F23+'วันที่ 4'!F23+'วันที่ 5'!F23+'วันที่ 6'!F23+'วันที่ 7'!F23+'วันที่ 8'!F23+'วันที่ 9'!F23+'วันที่ 10'!F23+'วันที่ 11'!F23+'วันที่ 12'!F23+'วันที่ 13'!F23+'วันที่ 14'!F23+'วันที่ 15'!F23+'วันที่ 16'!F23+'วันที่ 17'!F23+'วันที่ 18'!F23+'วันที่ 19'!F23+'วันที่ 20'!F23+'วันที่ 21'!F23+'วันที่ 22'!F23+'วันที่ 23'!F23+'วันที่ 24'!F23+'วันที่ 25'!F23+'วันที่ 26'!F23+'วันที่ 27'!F23+'วันที่ 28'!F23+'วันที่ 29'!F23+'วันที่ 30'!F23+'วันที่ 31'!F23 -> 0 | G23: =E23-F23-H23 -> 5 | H23: =+'วันที่ 1'!H23+'วันที่ 2'!H23+'วันที่ 3'!H23+'วันที่ 4'!H23+'วันที่ 5'!H23+'วันที่ 6'!H23+'วันที่ 7'!H23+'วันที่ 8'!H23+'วันที่ 9'!H23+'วันที่ 10'!H23+'วันที่ 11'!H23+'วันที่ 12'!H23+'วันที่ 13'!H23+'วันที่ 14'!H23+'วันที่ 15'!H23+'วันที่ 16'!H23+'วันที่ 17'!H23+'วันที่ 18'!H23+'วันที่ 19'!H23+'วันที่ 20'!H23+'วันที่ 21'!H23+'วันที่ 22'!H23+'วันที่ 23'!H23+'วันที่ 24'!H23+'วันที่ 25'!H23+'วันที่ 26'!H23+'วันที่ 27'!H23+'วันที่ 28'!H23+'วันที่ 29'!H23+'วันที่ 30'!H23+'วันที่ 31'!H23 -> 49 | I23: 100 | J23: =+'วันที่ 1'!J23+'วันที่ 2'!J23+'วันที่ 3'!J23+'วันที่ 4'!J23+'วันที่ 5'!J23+'วันที่ 6'!J23+'วันที่ 7'!J23+'วันที่ 8'!J23+'วันที่ 9'!J23+'วันที่ 10'!J23+'วันที่ 11'!J23+'วันที่ 12'!J23+'วันที่ 13'!J23+'วันที่ 14'!J23+'วันที่ 15'!J23+'วันที่ 16'!J23+'วันที่ 17'!J23+'วันที่ 18'!J23+'วันที่ 19'!J23+'วันที่ 20'!J23+'วันที่ 21'!J23+'วันที่ 22'!J23+'วันที่ 23'!J23+'วันที่ 24'!J23+'วันที่ 25'!J23+'วันที่ 26'!J23+'วันที่ 27'!J23+'วันที่ 28'!J23+'วันที่ 29'!J23+'วันที่ 30'!J23+'วันที่ 31'!J23 -> 4900 | L23: 19 | M23: =+'วันที่ 19'!K207 -> 0 | N23: =+'วันที่ 19'!K212 -> 0 | O23: =+'วันที่ 19'!K210 -> 0 | P23: =+'วันที่ 19'!K208 -> 0 | Q23: =+'วันที่ 19'!K210 -> 0 | R23: =+'วันที่ 19'!K209 -> 0 | S23: =+M23-N23-P23-R23-Q23 -> 0 | T23: =+'วันที่ 19'!K214 -> 0 | U23: =+T23-S23 -> 0
A24: 20 | B24: ชิฟฟ่อน สอดไส้ 6 ชิ้น ฝอยทอง | C24: =+'วันที่ 1'!C24 -> 11 | D24: =+'วันที่ 1'!D24+'วันที่ 2'!D24+'วันที่ 3'!D24+'วันที่ 4'!D24+'วันที่ 5'!D24+'วันที่ 6'!D24+'วันที่ 7'!D24+'วันที่ 8'!D24+'วันที่ 9'!D24+'วันที่ 10'!D24+'วันที่ 11'!D24+'วันที่ 12'!D24+'วันที่ 13'!D24+'วันที่ 14'!D24+'วันที่ 15'!D24+'วันที่ 16'!D24+'วันที่ 17'!D24+'วันที่ 18'!D24+'วันที่ 19'!D24+'วันที่ 20'!D24+'วันที่ 21'!D24+'วันที่ 22'!D24+'วันที่ 23'!D24+'วันที่ 24'!D24+'วันที่ 25'!D24+'วันที่ 26'!D24+'วันที่ 27'!D24+'วันที่ 28'!D24+'วันที่ 29'!D24+'วันที่ 30'!D24+'วันที่ 31'!D24 -> 15 | E24: =+C24+D24 -> 26 | F24: =+'วันที่ 1'!F24+'วันที่ 2'!F24+'วันที่ 3'!F24+'วันที่ 4'!F24+'วันที่ 5'!F24+'วันที่ 6'!F24+'วันที่ 7'!F24+'วันที่ 8'!F24+'วันที่ 9'!F24+'วันที่ 10'!F24+'วันที่ 11'!F24+'วันที่ 12'!F24+'วันที่ 13'!F24+'วันที่ 14'!F24+'วันที่ 15'!F24+'วันที่ 16'!F24+'วันที่ 17'!F24+'วันที่ 18'!F24+'วันที่ 19'!F24+'วันที่ 20'!F24+'วันที่ 21'!F24+'วันที่ 22'!F24+'วันที่ 23'!F24+'วันที่ 24'!F24+'วันที่ 25'!F24+'วันที่ 26'!F24+'วันที่ 27'!F24+'วันที่ 28'!F24+'วันที่ 29'!F24+'วันที่ 30'!F24+'วันที่ 31'!F24 -> 1 | G24: =E24-F24-H24 -> 6 | H24: =+'วันที่ 1'!H24+'วันที่ 2'!H24+'วันที่ 3'!H24+'วันที่ 4'!H24+'วันที่ 5'!H24+'วันที่ 6'!H24+'วันที่ 7'!H24+'วันที่ 8'!H24+'วันที่ 9'!H24+'วันที่ 10'!H24+'วันที่ 11'!H24+'วันที่ 12'!H24+'วันที่ 13'!H24+'วันที่ 14'!H24+'วันที่ 15'!H24+'วันที่ 16'!H24+'วันที่ 17'!H24+'วันที่ 18'!H24+'วันที่ 19'!H24+'วันที่ 20'!H24+'วันที่ 21'!H24+'วันที่ 22'!H24+'วันที่ 23'!H24+'วันที่ 24'!H24+'วันที่ 25'!H24+'วันที่ 26'!H24+'วันที่ 27'!H24+'วันที่ 28'!H24+'วันที่ 29'!H24+'วันที่ 30'!H24+'วันที่ 31'!H24 -> 19 | I24: 100 | J24: =+'วันที่ 1'!J24+'วันที่ 2'!J24+'วันที่ 3'!J24+'วันที่ 4'!J24+'วันที่ 5'!J24+'วันที่ 6'!J24+'วันที่ 7'!J24+'วันที่ 8'!J24+'วันที่ 9'!J24+'วันที่ 10'!J24+'วันที่ 11'!J24+'วันที่ 12'!J24+'วันที่ 13'!J24+'วันที่ 14'!J24+'วันที่ 15'!J24+'วันที่ 16'!J24+'วันที่ 17'!J24+'วันที่ 18'!J24+'วันที่ 19'!J24+'วันที่ 20'!J24+'วันที่ 21'!J24+'วันที่ 22'!J24+'วันที่ 23'!J24+'วันที่ 24'!J24+'วันที่ 25'!J24+'วันที่ 26'!J24+'วันที่ 27'!J24+'วันที่ 28'!J24+'วันที่ 29'!J24+'วันที่ 30'!J24+'วันที่ 31'!J24 -> 1900 | L24: 20 | M24: =+'วันที่ 20'!K207 -> 0 | N24: =+'วันที่ 20'!K212 -> 0 | O24: =+'วันที่ 20'!K210 -> 0 | P24: =+'วันที่ 20'!K208 -> 0 | Q24: =+'วันที่ 20'!K211 -> 0 | R24: =+'วันที่ 20'!K209 -> 0 | S24: =+M24-N24-P24-R24-Q24 -> 0 | T24: =+'วันที่ 20'!K214 -> 0 | U24: =+T24-S24 -> 0
A25: 21 | B25: ชิฟฟ่อน สอดไส้ 6 ชิ้น ทูโทน | C25: =+'วันที่ 1'!C25 -> 0 | D25: =+'วันที่ 1'!D25+'วันที่ 2'!D25+'วันที่ 3'!D25+'วันที่ 4'!D25+'วันที่ 5'!D25+'วันที่ 6'!D25+'วันที่ 7'!D25+'วันที่ 8'!D25+'วันที่ 9'!D25+'วันที่ 10'!D25+'วันที่ 11'!D25+'วันที่ 12'!D25+'วันที่ 13'!D25+'วันที่ 14'!D25+'วันที่ 15'!D25+'วันที่ 16'!D25+'วันที่ 17'!D25+'วันที่ 18'!D25+'วันที่ 19'!D25+'วันที่ 20'!D25+'วันที่ 21'!D25+'วันที่ 22'!D25+'วันที่ 23'!D25+'วันที่ 24'!D25+'วันที่ 25'!D25+'วันที่ 26'!D25+'วันที่ 27'!D25+'วันที่ 28'!D25+'วันที่ 29'!D25+'วันที่ 30'!D25+'วันที่ 31'!D25 -> 0 | E25: =+C25+D25 -> 0 | F25: =+'วันที่ 1'!F25+'วันที่ 2'!F25+'วันที่ 3'!F25+'วันที่ 4'!F25+'วันที่ 5'!F25+'วันที่ 6'!F25+'วันที่ 7'!F25+'วันที่ 8'!F25+'วันที่ 9'!F25+'วันที่ 10'!F25+'วันที่ 11'!F25+'วันที่ 12'!F25+'วันที่ 13'!F25+'วันที่ 14'!F25+'วันที่ 15'!F25+'วันที่ 16'!F25+'วันที่ 17'!F25+'วันที่ 18'!F25+'วันที่ 19'!F25+'วันที่ 20'!F25+'วันที่ 21'!F25+'วันที่ 22'!F25+'วันที่ 23'!F25+'วันที่ 24'!F25+'วันที่ 25'!F25+'วันที่ 26'!F25+'วันที่ 27'!F25+'วันที่ 28'!F25+'วันที่ 29'!F25+'วันที่ 30'!F25+'วันที่ 31'!F25 -> 0 | G25: =E25-F25-H25 -> 0 | H25: =+'วันที่ 1'!H25+'วันที่ 2'!H25+'วันที่ 3'!H25+'วันที่ 4'!H25+'วันที่ 5'!H25+'วันที่ 6'!H25+'วันที่ 7'!H25+'วันที่ 8'!H25+'วันที่ 9'!H25+'วันที่ 10'!H25+'วันที่ 11'!H25+'วันที่ 12'!H25+'วันที่ 13'!H25+'วันที่ 14'!H25+'วันที่ 15'!H25+'วันที่ 16'!H25+'วันที่ 17'!H25+'วันที่ 18'!H25+'วันที่ 19'!H25+'วันที่ 20'!H25+'วันที่ 21'!H25+'วันที่ 22'!H25+'วันที่ 23'!H25+'วันที่ 24'!H25+'วันที่ 25'!H25+'วันที่ 26'!H25+'วันที่ 27'!H25+'วันที่ 28'!H25+'วันที่ 29'!H25+'วันที่ 30'!H25+'วันที่ 31'!H25 -> 0 | I25: 100 | J25: =+'วันที่ 1'!J25+'วันที่ 2'!J25+'วันที่ 3'!J25+'วันที่ 4'!J25+'วันที่ 5'!J25+'วันที่ 6'!J25+'วันที่ 7'!J25+'วันที่ 8'!J25+'วันที่ 9'!J25+'วันที่ 10'!J25+'วันที่ 11'!J25+'วันที่ 12'!J25+'วันที่ 13'!J25+'วันที่ 14'!J25+'วันที่ 15'!J25+'วันที่ 16'!J25+'วันที่ 17'!J25+'วันที่ 18'!J25+'วันที่ 19'!J25+'วันที่ 20'!J25+'วันที่ 21'!J25+'วันที่ 22'!J25+'วันที่ 23'!J25+'วันที่ 24'!J25+'วันที่ 25'!J25+'วันที่ 26'!J25+'วันที่ 27'!J25+'วันที่ 28'!J25+'วันที่ 29'!J25+'วันที่ 30'!J25+'วันที่ 31'!J25 -> 0 | L25: 21 | M25: =+'วันที่ 21'!K207 -> 0 | N25: =+'วันที่ 21'!K212 -> 0 | O25: =+'วันที่ 21'!K210 -> 0 | P25: =+'วันที่ 21'!K208 -> 0 | Q25: =+'วันที่ 21'!K211 -> 0 | R25: =+'วันที่ 21'!K209 -> 0 | S25: =+M25-N25-P25-R25-Q25 -> 0 | T25: =+'วันที่ 21'!K214 -> 0 | U25: =+T25-S25 -> 0
A26: 22 | B26: ชิฟฟ่อน สอดไส้ 6 ชิ้น นมชมพู | C26: =+'วันที่ 1'!C26 -> 0 | D26: =+'วันที่ 1'!D26+'วันที่ 2'!D26+'วันที่ 3'!D26+'วันที่ 4'!D26+'วันที่ 5'!D26+'วันที่ 6'!D26+'วันที่ 7'!D26+'วันที่ 8'!D26+'วันที่ 9'!D26+'วันที่ 10'!D26+'วันที่ 11'!D26+'วันที่ 12'!D26+'วันที่ 13'!D26+'วันที่ 14'!D26+'วันที่ 15'!D26+'วันที่ 16'!D26+'วันที่ 17'!D26+'วันที่ 18'!D26+'วันที่ 19'!D26+'วันที่ 20'!D26+'วันที่ 21'!D26+'วันที่ 22'!D26+'วันที่ 23'!D26+'วันที่ 24'!D26+'วันที่ 25'!D26+'วันที่ 26'!D26+'วันที่ 27'!D26+'วันที่ 28'!D26+'วันที่ 29'!D26+'วันที่ 30'!D26+'วันที่ 31'!D26 -> 0 | E26: =+C26+D26 -> 0 | F26: =+'วันที่ 1'!F26+'วันที่ 2'!F26+'วันที่ 3'!F26+'วันที่ 4'!F26+'วันที่ 5'!F26+'วันที่ 6'!F26+'วันที่ 7'!F26+'วันที่ 8'!F26+'วันที่ 9'!F26+'วันที่ 10'!F26+'วันที่ 11'!F26+'วันที่ 12'!F26+'วันที่ 13'!F26+'วันที่ 14'!F26+'วันที่ 15'!F26+'วันที่ 16'!F26+'วันที่ 17'!F26+'วันที่ 18'!F26+'วันที่ 19'!F26+'วันที่ 20'!F26+'วันที่ 21'!F26+'วันที่ 22'!F26+'วันที่ 23'!F26+'วันที่ 24'!F26+'วันที่ 25'!F26+'วันที่ 26'!F26+'วันที่ 27'!F26+'วันที่ 28'!F26+'วันที่ 29'!F26+'วันที่ 30'!F26+'วันที่ 31'!F26 -> 0 | G26: =E26-F26-H26 -> 0 | H26: =+'วันที่ 1'!H26+'วันที่ 2'!H26+'วันที่ 3'!H26+'วันที่ 4'!H26+'วันที่ 5'!H26+'วันที่ 6'!H26+'วันที่ 7'!H26+'วันที่ 8'!H26+'วันที่ 9'!H26+'วันที่ 10'!H26+'วันที่ 11'!H26+'วันที่ 12'!H26+'วันที่ 13'!H26+'วันที่ 14'!H26+'วันที่ 15'!H26+'วันที่ 16'!H26+'วันที่ 17'!H26+'วันที่ 18'!H26+'วันที่ 19'!H26+'วันที่ 20'!H26+'วันที่ 21'!H26+'วันที่ 22'!H26+'วันที่ 23'!H26+'วันที่ 24'!H26+'วันที่ 25'!H26+'วันที่ 26'!H26+'วันที่ 27'!H26+'วันที่ 28'!H26+'วันที่ 29'!H26+'วันที่ 30'!H26+'วันที่ 31'!H26 -> 0 | I26: 100 | J26: =+'วันที่ 1'!J26+'วันที่ 2'!J26+'วันที่ 3'!J26+'วันที่ 4'!J26+'วันที่ 5'!J26+'วันที่ 6'!J26+'วันที่ 7'!J26+'วันที่ 8'!J26+'วันที่ 9'!J26+'วันที่ 10'!J26+'วันที่ 11'!J26+'วันที่ 12'!J26+'วันที่ 13'!J26+'วันที่ 14'!J26+'วันที่ 15'!J26+'วันที่ 16'!J26+'วันที่ 17'!J26+'วันที่ 18'!J26+'วันที่ 19'!J26+'วันที่ 20'!J26+'วันที่ 21'!J26+'วันที่ 22'!J26+'วันที่ 23'!J26+'วันที่ 24'!J26+'วันที่ 25'!J26+'วันที่ 26'!J26+'วันที่ 27'!J26+'วันที่ 28'!J26+'วันที่ 29'!J26+'วันที่ 30'!J26+'วันที่ 31'!J26 -> 0 | L26: 22 | M26: =+'วันที่ 22'!K207 -> 0 | N26: =+'วันที่ 22'!K212 -> 0 | O26: =+'วันที่ 22'!K210 -> 0 | P26: =+'วันที่ 22'!K208 -> 0 | Q26: =+'วันที่ 22'!K211 -> 0 | R26: =+'วันที่ 22'!K209 -> 0 | S26: =+M26-N26-P26-R26-Q26 -> 0 | T26: =+'วันที่ 22'!K214 -> 0 | U26: =+T26-S26 -> 0
A27: 23 | B27: ชิฟฟ่อน สอดไส้ 6 ชิ้น บลูเบอรี่ | C27: =+'วันที่ 1'!C27 -> 0 | D27: =+'วันที่ 1'!D27+'วันที่ 2'!D27+'วันที่ 3'!D27+'วันที่ 4'!D27+'วันที่ 5'!D27+'วันที่ 6'!D27+'วันที่ 7'!D27+'วันที่ 8'!D27+'วันที่ 9'!D27+'วันที่ 10'!D27+'วันที่ 11'!D27+'วันที่ 12'!D27+'วันที่ 13'!D27+'วันที่ 14'!D27+'วันที่ 15'!D27+'วันที่ 16'!D27+'วันที่ 17'!D27+'วันที่ 18'!D27+'วันที่ 19'!D27+'วันที่ 20'!D27+'วันที่ 21'!D27+'วันที่ 22'!D27+'วันที่ 23'!D27+'วันที่ 24'!D27+'วันที่ 25'!D27+'วันที่ 26'!D27+'วันที่ 27'!D27+'วันที่ 28'!D27+'วันที่ 29'!D27+'วันที่ 30'!D27+'วันที่ 31'!D27 -> 0 | E27: =+C27+D27 -> 0 | F27: =+'วันที่ 1'!F27+'วันที่ 2'!F27+'วันที่ 3'!F27+'วันที่ 4'!F27+'วันที่ 5'!F27+'วันที่ 6'!F27+'วันที่ 7'!F27+'วันที่ 8'!F27+'วันที่ 9'!F27+'วันที่ 10'!F27+'วันที่ 11'!F27+'วันที่ 12'!F27+'วันที่ 13'!F27+'วันที่ 14'!F27+'วันที่ 15'!F27+'วันที่ 16'!F27+'วันที่ 17'!F27+'วันที่ 18'!F27+'วันที่ 19'!F27+'วันที่ 20'!F27+'วันที่ 21'!F27+'วันที่ 22'!F27+'วันที่ 23'!F27+'วันที่ 24'!F27+'วันที่ 25'!F27+'วันที่ 26'!F27+'วันที่ 27'!F27+'วันที่ 28'!F27+'วันที่ 29'!F27+'วันที่ 30'!F27+'วันที่ 31'!F27 -> 0 | G27: =E27-F27-H27 -> 0 | H27: =+'วันที่ 1'!H27+'วันที่ 2'!H27+'วันที่ 3'!H27+'วันที่ 4'!H27+'วันที่ 5'!H27+'วันที่ 6'!H27+'วันที่ 7'!H27+'วันที่ 8'!H27+'วันที่ 9'!H27+'วันที่ 10'!H27+'วันที่ 11'!H27+'วันที่ 12'!H27+'วันที่ 13'!H27+'วันที่ 14'!H27+'วันที่ 15'!H27+'วันที่ 16'!H27+'วันที่ 17'!H27+'วันที่ 18'!H27+'วันที่ 19'!H27+'วันที่ 20'!H27+'วันที่ 21'!H27+'วันที่ 22'!H27+'วันที่ 23'!H27+'วันที่ 24'!H27+'วันที่ 25'!H27+'วันที่ 26'!H27+'วันที่ 27'!H27+'วันที่ 28'!H27+'วันที่ 29'!H27+'วันที่ 30'!H27+'วันที่ 31'!H27 -> 0 | I27: 100 | J27: =+'วันที่ 1'!J27+'วันที่ 2'!J27+'วันที่ 3'!J27+'วันที่ 4'!J27+'วันที่ 5'!J27+'วันที่ 6'!J27+'วันที่ 7'!J27+'วันที่ 8'!J27+'วันที่ 9'!J27+'วันที่ 10'!J27+'วันที่ 11'!J27+'วันที่ 12'!J27+'วันที่ 13'!J27+'วันที่ 14'!J27+'วันที่ 15'!J27+'วันที่ 16'!J27+'วันที่ 17'!J27+'วันที่ 18'!J27+'วันที่ 19'!J27+'วันที่ 20'!J27+'วันที่ 21'!J27+'วันที่ 22'!J27+'วันที่ 23'!J27+'วันที่ 24'!J27+'วันที่ 25'!J27+'วันที่ 26'!J27+'วันที่ 27'!J27+'วันที่ 28'!J27+'วันที่ 29'!J27+'วันที่ 30'!J27+'วันที่ 31'!J27 -> 0 | L27: 23 | M27: =+'วันที่ 23'!K207 -> 0 | N27: =+'วันที่ 23'!K212 -> 0 | O27: =+'วันที่ 23'!K210 -> 0 | P27: =+'วันที่ 23'!K208 -> 0 | Q27: =+'วันที่ 23'!K211 -> 0 | R27: =+'วันที่ 23'!K209 -> 0 | S27: =+M27-N27-P27-R27-Q27 -> 0 | T27: =+'วันที่ 23'!K214 -> 0 | U27: =+T27-S27 -> 0
A28: 24 | B28: ชิฟฟ่อน สอดไส้ 6 ชิ้น ช็อคโกแลต | C28: =+'วันที่ 1'!C28 -> 0 | D28: =+'วันที่ 1'!D28+'วันที่ 2'!D28+'วันที่ 3'!D28+'วันที่ 4'!D28+'วันที่ 5'!D28+'วันที่ 6'!D28+'วันที่ 7'!D28+'วันที่ 8'!D28+'วันที่ 9'!D28+'วันที่ 10'!D28+'วันที่ 11'!D28+'วันที่ 12'!D28+'วันที่ 13'!D28+'วันที่ 14'!D28+'วันที่ 15'!D28+'วันที่ 16'!D28+'วันที่ 17'!D28+'วันที่ 18'!D28+'วันที่ 19'!D28+'วันที่ 20'!D28+'วันที่ 21'!D28+'วันที่ 22'!D28+'วันที่ 23'!D28+'วันที่ 24'!D28+'วันที่ 25'!D28+'วันที่ 26'!D28+'วันที่ 27'!D28+'วันที่ 28'!D28+'วันที่ 29'!D28+'วันที่ 30'!D28+'วันที่ 31'!D28 -> 0 | E28: =+C28+D28 -> 0 | F28: =+'วันที่ 1'!F28+'วันที่ 2'!F28+'วันที่ 3'!F28+'วันที่ 4'!F28+'วันที่ 5'!F28+'วันที่ 6'!F28+'วันที่ 7'!F28+'วันที่ 8'!F28+'วันที่ 9'!F28+'วันที่ 10'!F28+'วันที่ 11'!F28+'วันที่ 12'!F28+'วันที่ 13'!F28+'วันที่ 14'!F28+'วันที่ 15'!F28+'วันที่ 16'!F28+'วันที่ 17'!F28+'วันที่ 18'!F28+'วันที่ 19'!F28+'วันที่ 20'!F28+'วันที่ 21'!F28+'วันที่ 22'!F28+'วันที่ 23'!F28+'วันที่ 24'!F28+'วันที่ 25'!F28+'วันที่ 26'!F28+'วันที่ 27'!F28+'วันที่ 28'!F28+'วันที่ 29'!F28+'วันที่ 30'!F28+'วันที่ 31'!F28 -> 0 | G28: =E28-F28-H28 -> 0 | H28: =+'วันที่ 1'!H28+'วันที่ 2'!H28+'วันที่ 3'!H28+'วันที่ 4'!H28+'วันที่ 5'!H28+'วันที่ 6'!H28+'วันที่ 7'!H28+'วันที่ 8'!H28+'วันที่ 9'!H28+'วันที่ 10'!H28+'วันที่ 11'!H28+'วันที่ 12'!H28+'วันที่ 13'!H28+'วันที่ 14'!H28+'วันที่ 15'!H28+'วันที่ 16'!H28+'วันที่ 17'!H28+'วันที่ 18'!H28+'วันที่ 19'!H28+'วันที่ 20'!H28+'วันที่ 21'!H28+'วันที่ 22'!H28+'วันที่ 23'!H28+'วันที่ 24'!H28+'วันที่ 25'!H28+'วันที่ 26'!H28+'วันที่ 27'!H28+'วันที่ 28'!H28+'วันที่ 29'!H28+'วันที่ 30'!H28+'วันที่ 31'!H28 -> 0 | I28: 100 | J28: =+'วันที่ 1'!J28+'วันที่ 2'!J28+'วันที่ 3'!J28+'วันที่ 4'!J28+'วันที่ 5'!J28+'วันที่ 6'!J28+'วันที่ 7'!J28+'วันที่ 8'!J28+'วันที่ 9'!J28+'วันที่ 10'!J28+'วันที่ 11'!J28+'วันที่ 12'!J28+'วันที่ 13'!J28+'วันที่ 14'!J28+'วันที่ 15'!J28+'วันที่ 16'!J28+'วันที่ 17'!J28+'วันที่ 18'!J28+'วันที่ 19'!J28+'วันที่ 20'!J28+'วันที่ 21'!J28+'วันที่ 22'!J28+'วันที่ 23'!J28+'วันที่ 24'!J28+'วันที่ 25'!J28+'วันที่ 26'!J28+'วันที่ 27'!J28+'วันที่ 28'!J28+'วันที่ 29'!J28+'วันที่ 30'!J28+'วันที่ 31'!J28 -> 0 | L28: 24 | M28: =+'วันที่ 24'!K207 -> 0 | N28: =+'วันที่ 24'!K212 -> 0 | O28: =+'วันที่ 24'!K210 -> 0 | P28: =+'วันที่ 24'!K208 -> 0 | Q28: =+'วันที่ 24'!K211 -> 0 | R28: =+'วันที่ 24'!K209 -> 0 | S28: =+M28-N28-P28-R28-Q28 -> 0 | T28: =+'วันที่ 24'!K214 -> 0 | U28: =+T28-S28 -> 0
