Workbook

Sheet สรุป
A1: สรุปค่าขนส่งสินค้าออนไลน์ ปี 2569
A2: เดือน | B2: จำนวนที่ส่ง(ชิ้น) | C2: จำนวนที่ส่ง(ชิ้น) | D2: รวมยอด COD | E2: รวมยอด COD Fee 2% | F2: รวมค่า COD Fee VAT 7% | G2: รวมค่าพื้นที่เกาะ | H2: รวมค่าขนส่ง | I2: Total Charge
A3: มกราคม | B3: =+'รวมส่ง ม.ค.'!E34 -> 202 | C3: =+'รวมส่ง ม.ค.'!F34 -> 415 | D3: =+'รวมส่ง ม.ค.'!G34 -> 61977 | E3: =+'รวมส่ง ม.ค.'!H34 -> 955.01 | F3: =+'รวมส่ง ม.ค.'!I34 -> 66.86 | G3: =+'รวมส่ง ม.ค.'!J34 -> 35 | H3: =+'รวมส่ง ม.ค.'!K34 -> 11607 | I3: =+'รวมส่ง ม.ค.'!L34 -> 12628.87
A4: กุมภาพันธ์ | B4: =+'รวมส่ง ก.พ.'!E34 -> 309 | C4: =+'รวมส่ง ก.พ.'!F34 -> 534 | D4: =+'รวมส่ง ก.พ.'!G34 -> 91568 | E4: =+'รวมส่ง ก.พ.'!H34 -> 1401.22 | F4: =+'รวมส่ง ก.พ.'!I34 -> 98.11 | G4: =+'รวมส่ง ก.พ.'!J34 -> 340 | H4: =+'รวมส่ง ก.พ.'!K34 -> 15146 | I4: =+'รวมส่ง ก.พ.'!L34 -> 16645.33
A5: มีนาคม | B5: 312 | C5: 544 | D5: 69540 | E5: 1043.17 | F5: 73.04 | G5: 240 | H5: 12550 | I5: 13666.21
A6: เมษายน | B6: =+'รวมส่ง เม.ย.'!E33 -> 603 | C6: =+'รวมส่ง เม.ย.'!F33 -> 880 | D6: =+'รวมส่ง เม.ย.'!G33 -> 144319 | E6: =+'รวมส่ง เม.ย.'!H33 -> 2281.75 | F6: =+'รวมส่ง เม.ย.'!I33 -> 159.73 | G6: =+'รวมส่ง เม.ย.'!J33 -> 480 | H6: =+'รวมส่ง เม.ย.'!K33 -> 23024 | I6: =+'รวมส่ง เม.ย.'!L33 -> 25465.48
A7: พฤษภาคม | B7: =+'รวมส่ง พ.ค.'!E34 -> 505 | C7: =+'รวมส่ง พ.ค.'!F34 -> 758 | D7: =+'รวมส่ง พ.ค.'!G34 -> 116253 | E7: =+'รวมส่ง พ.ค.'!H34 -> 1743.86 | F7: =+'รวมส่ง พ.ค.'!I34 -> 122.09 | G7: =+'รวมส่ง พ.ค.'!J34 -> 360 | H7: =+'รวมส่ง พ.ค.'!K34 -> 16877 | I7: =+'รวมส่ง พ.ค.'!L34 -> 18742.95
A8: มิถุนายน | B8: =+'รวมส่ง มิ.ย.'!E32 -> 337 | C8: =+'รวมส่ง มิ.ย.'!F32 -> 453 | D8: =+'รวมส่ง มิ.ย.'!G32 -> 68689 | E8: =+'รวมส่ง มิ.ย.'!H32 -> 1030.4 | F8: =+'รวมส่ง มิ.ย.'!I32 -> 72.12 | G8: =+'รวมส่ง มิ.ย.'!J32 -> 420 | H8: =+'รวมส่ง มิ.ย.'!K32 -> 9780 | I8: =+'รวมส่ง มิ.ย.'!L32 -> 10882.52
A9: กรกฎาคม | I9: =+'รวมส่ง ม.ค.'!L40 -> 0
A10: สิงหาคม | I10: =+'รวมส่ง ม.ค.'!L41 -> 0
A11: กันยายน | I11: =+'รวมส่ง ม.ค.'!L42 -> 0
A12: ตุลาคม | I12: =+'รวมส่ง ม.ค.'!L43 -> 0
A13: พฤศจิกายน | I13: =+'รวมส่ง ม.ค.'!L44 -> 0
A14: ธันวาคม | I14: =+'รวมส่ง ม.ค.'!L45 -> 0
A15: ยอดรวม | B15: =SUM(B3:B14) -> 2268 | C15: =SUM(C3:C14) -> 3584 | D15: =SUM(D3:D14) -> 552346 | E15: =SUM(E3:E14) -> 8455.41 | F15: =SUM(F3:F14) -> 591.95 | G15: =SUM(G3:G14) -> 1875 | H15: =SUM(H3:H14) -> 88984 | I15: =SUM(I3:I14) -> 98031.36

Sheet รายการส่งของ ม.ค.
A1: ลำดับ | B1: วันที่ส่ง | C1: Email | D1: Tel | E1: Team Name | F1: ขนส่ง | G1: Team Percent COD Fee | H1: Page | I1: Tracking No. | J1: Consignee | K1: Phone number | L1: Address | M1: Item type | N1: Weight（kg) | O1: Demensions | P1: COD Amount | Q1: Total COD Fee | R1: COD VAT 7% | S1: Freight | T1: Total Charge
A2: 1 | B2: 244350 | C2: suckjakkure@hotmail.com | D2: 642427575 | E2: วรรณวนัชเบเกอรี่ | F2: เอกชน | G2: 2 | H2: FACEBOOK | I2: TH660586BUTY5D | J2: สมหวัง สิทธิพจน์ | K2: 874894970 | L2: 92 หมู่ ที่ 2 บ้านน้ำเค็ม ตะกั่วป่า บางม่วง พังงา Thailand | N2: 8 | O2: 5×️5×️8 | P2: 0 | Q2: 0 | R2: 0 | S2: 170 | T2: 170
A3: 2 | B3: 244350 | C3: suckjakkure@hotmail.com | D3: 642427575 | E3: วรรณวนัชเบเกอรี่ | F3: เอกชน | G3: 2 | H3: FACEBOOK | I3: TH130686DYH91D | J3: สุขุมา จันทร์สะอาด | K3: 927043962 | L3: 75 ม.16 บ่อพลอย หนองกุ่ม กาญจนบุรี Thailand | N3: 5 | O3: 5×️5×️8 | P3: 0 | Q3: 0 | R3: 0 | S3: 50 | T3: 50
A4: 3 | B4: 244350 | C4: suckjakkure@hotmail.com | D4: 642427575 | E4: วรรณวนัชเบเกอรี่ | F4: เอกชน | G4: 2 | H4: FACEBOOK | I4: TH050986BUTW9A | J4: นาย สวัสดิ์ วงษ์ภักดี | K4: 915951411 | L4: 27 หมู่ 4 ภาชี ภาชี พระนครศรีอยุธยา Thailand | N4: 10 | O4: 18×️5×️8 | P4: 0 | Q4: 0 | R4: 0 | S4: 100 | T4: 100
A5: 4 | B5: 244350 | C5: suckjakkure@hotmail.com | D5: 642427575 | E5: วรรณวนัชเบเกอรี่ | F5: เอกชน | G5: 2 | H5: FACEBOOK | I5: TH014786BUU22B | J5: บุญศรี ทองเสทื้อน | K5: 638266593 | L5: 68/13 ม.2 ซ.วาสนากุล สายไหม สายไหม กรุงเทพ Thailand | N5: 3.99 | O5: 5×️5×️8 | P5: 0 | Q5: 0 | R5: 0 | S5: 42 | T5: 42
A6: 5 | B6: 244350 | C6: suckjakkure@hotmail.com | D6: 642427575 | E6: วรรณวนัชเบเกอรี่ | F6: เอกชน | G6: 2 | H6: FACEBOOK | I6: TH130386BUU32J | J6: นาย อรญา คุ้มครอง | K6: 958244976 | L6: 13/15 ซอย1 ม 4 ท่าม่วง วังขนาย กาญจนบุรี Thailand | N6: 3 | O6: 8×️8×️10 | P6: 0 | Q6: 0 | R6: 0 | S6: 29 | T6: 29
A7: 6 | B7: 244350 | C7: suckjakkure@hotmail.com | D7: 642427575 | E7: วรรณวนัชเบเกอรี่ | F7: เอกชน | G7: 2 | H7: FACEBOOK | I7: TH260586DYHA8C | J7: นางสาว วาสนา ทูคำมี | K7: 988765466 | L7: บ้านเลขที่ 33 หมู่ 10 วัฒนานคร ผักขะ สระแก้ว Thailand | N7: 0.81 | O7: 26×️20×️15 | P7: 199 | Q7: 3.98 | R7: 0.28 | S7: 20 | T7: 24.26
A8: 7 | B8: 244350 | C8: suckjakkure@hotmail.com | D8: 642427575 | E8: วรรณวนัชเบเกอรี่ | F8: เอกชน | G8: 2 | H8: FACEBOOK | I8: TH610186BUTR9G | J8: คุณ วาสนา คุยดี | K8: 634736569 | L8: บ้านเลขที่ 21/65 ( บ้านเเทน คุณ สาขาบึงราชนก ) หมู่ ที่ 4 เมืองพิษณุโลก สมอแข พิษณุโลก Thailand | N8: 2.99 | O8: 5×️5×️8 | P8: 0 | Q8: 0 | R8: 0 | S8: 29 | T8: 29
A9: 8 | B9: 244350 | C9: suckjakkure@hotmail.com | D9: 642427575 | E9: วรรณวนัชเบเกอรี่ | F9: เอกชน | G9: 2 | H9: FACEBOOK | I9: TH520186BUTW6C | J9: ชีวรรณเทียมทินกฤต | K9: 955913464 | L9: 141/6 หมู่ ที่ 6 ซ 2 หมู่ บ้านมงคลนิมิต( แถวสนามบิน) เข้า ซอยเดอะชาลี เมืองน่าน ผาสิงห์ น่าน Thailand | N9: 2.99 | O9: 5×️5×️10 | P9: 199 | Q9: 3.98 | R9: 0.28 | S9: 29 | T9: 33.26
A10: 9 | B10: 244350 | C10: suckjakkure@hotmail.com | D10: 642427575 | E10: วรรณวนัชเบเกอรี่ | F10: เอกชน | G10: 2 | H10: FACEBOOK | I10: TH013986BUTX6E | J10: น้ำค้าง สิงห์ราช | K10: 844650086 | L10: 188 ถนนประชาทร ลาดกระบัง ซอย3 ลาดกระบัง ลาดกระบัง กรุงเทพ Thailand | N10: 2.99 | O10: 5×️5×️10 | P10: 399 | Q10: 7.98 | R10: 0.56 | S10: 27 | T10: 35.54
A11: 10 | B11: 244350 | C11: suckjakkure@hotmail.com | D11: 642427575 | E11: วรรณวนัชเบเกอรี่ | F11: เอกชน | G11: 2 | H11: FACEBOOK | I11: TH101186DYHB1F | J11: Jiranun Naksiri | K11: 942958686 | L11: 99 หมู่ 15 บ้านซับสุวรรณ, บ้านหลังสีเหลือง มวกเหล็ก ซับสนุ่น สระบุรี Thailand | N11: 2.99 | O11: 5×️5×️9 | P11: 399 | Q11: 7.98 | R11: 0.56 | S11: 29 | T11: 37.54
A12: 11 | B12: 244350 | C12: suckjakkure@hotmail.com | D12: 642427575 | E12: วรรณวนัชเบเกอรี่ | F12: เอกชน | G12: 2 | H12: FACEBOOK | I12: TH011786BUTR2A1 | J12: นันทนา สวัสดิ์ธนากุล | K12: 816355780 | L12: 622/235 หมู่ บ้านคาซ่าซิตี้ บางขุนเทียน ( หน้าปาก ซอยเทียนทะเล 24) ถนนบางขุนเทียน-ชายทะเล บางขุนเทียน ท่าข้าม กรุงเทพ Thailand | N12: 2.99 | O12: 5×️5×️8 | P12: 0 | Q12: 0 | R12: 0 | S12: 27 | T12: 27
A13: 12 | B13: 244350 | C13: suckjakkure@hotmail.com | D13: 642427575 | E13: วรรณวนัชเบเกอรี่ | F13: เอกชน | G13: 2 | H13: FACEBOOK | I13: TH410486E0UR9A | J13: รำพรรณ. ชาญวิรัตน์ | K13: 817698318 | L13: 218 หมู่ ที่ 2 กันทรวิชัย โคกพระ มหาสารคาม Thailand | N13: 5 | O13: 5×️5×️12 | P13: 399 | Q13: 7.98 | R13: 0.56 | S13: 50 | T13: 58.54
... A35: 34 | B35: 244350 | C35: suckjakkure@hotmail.com | D35: 642427575 | E35: วรรณวนัชเบเกอรี่ | F35: เอกชน | G35: 2 | H35: FACEBOOK | I35: TH010686BUTQ9C | J35: อุษณีษ์ สุทธิสารสุนทร | K35: 942900509 | L35: 99/329 บ้านกลางเมือง สาทร-ตากสิน 2 ถ.ราชพฤกษ์ จอมทอง บางค้อ กรุงเทพ Thailand | N35: 0.5 | O35: 15×️15×️25 | P35: 398 | Q35: 7.96 | R35: 0.56 | S35: 18 | T35: 26.52
A36: 35 | B36: 244350 | C36: suckjakkure@hotmail.com | D36: 642427575 | E36: วรรณวนัชเบเกอรี่ | F36: ปณ | G36: 2 | H36: FACEBOOK | I36: WA066796386TH | J36: อัจจิมา | K36: 999390053 | L36: 40 หมู่ 5 บ้านหนองจิก ดงลาน เมืองร้อยเอ็ด ร้อยเอ็ด 45000 | N36: 0.762 | O36: 199 | P36: 2.985 | Q36: 0.209 | R36: 0 | S36: 17 | T36: 20.19
A37: 36 | B37: 244350 | C37: suckjakkure@hotmail.com | D37: 642427575 | E37: วรรณวนัชเบเกอรี่ | F37: ปณ | G37: 2 | H37: FACEBOOK | I37: WA066796430TH | J37: วาสนา พุ่มจุ่น | K37: 846467470 | L37: 53 ม.4 ทองเอน อินทร์บุรี สิงห์บุรี 16110 | N37: 1.158 | O37: 299 | P37: 4.485 | Q37: 0.314 | R37: 0 | S37: 23 | T37: 27.8
A38: 37 | B38: 244350 | C38: suckjakkure@hotmail.com | D38: 642427575 | E38: วรรณวนัชเบเกอรี่ | F38: ปณ | G38: 2 | H38: FACEBOOK | I38: WB109584117TH | J38: ณัฐพร | K38: 621282168 | L38: 2/15 หมู่ 4 ซอยตะวันออก 50 คลองหก คลองหลวง ปทุมธานี 12120 | N38: 0.246 | O38: 0 | P38: 0 | Q38: 0 | R38: 0 | S38: 17 | T38: 17
A39: 38 | B39: 244350 | C39: suckjakkure@hotmail.com | D39: 642427575 | E39: วรรณวนัชเบเกอรี่ | F39: ปณ | G39: 2 | H39: FACEBOOK | I39: WB109584103TH | J39: คุณ สุภรณ์ ลิ้มอารีย์ | K39: 897115807 | L39: 143/40 บ้านเฮา ถ.ถีนานนท์ ตลาด เมืองมหาสารคาม มหาสารคาม 44000 | N39: 1.194 | O39: 0 | P39: 0 | Q39: 0 | R39: 0 | S39: 23 | T39: 23
A40: 39 | B40: 244350 | C40: suckjakkure@hotmail.com | D40: 642427575 | E40: วรรณวนัชเบเกอรี่ | F40: ปณ | G40: 2 | H40: FACEBOOK | I40: WB109584094TH | J40: อัญชิษฐา บุญไพโรจน์ | K40: 840706249 | L40: 50 ม.4 วังสะพุง วังสะพุง เลย 42130 | N40: 3.428 | O40: 0 | P40: 0 | Q40: 0 | R40: 0 | S40: 44 | T40: 44
A41: 40 | B41: 244350 | C41: suckjakkure@hotmail.com | D41: 642427575 | E41: วรรณวนัชเบเกอรี่ | F41: ปณ | G41: 2 | H41: FACEBOOK | I41: WB109584085TH | J41: จำลอง | K41: 895156196 | L41: 78 หมู่ 2 ( ร้านบ้านของฝาก) ไชยภูมิ ไชโย อ่างทอง 14140 | N41: 0.534 | O41: 0 | P41: 0 | Q41: 0 | R41: 0 | S41: 17 | T41: 17
A42: 41 | B42: 244350 | C42: suckjakkure@hotmail.com | D42: 642427575 | E42: วรรณวนัชเบเกอรี่ | F42: ปณ | G42: 2 | H42: FACEBOOK | I42: WB109584077TH | J42: วีริยา กงพลี | K42: 926018065 | L42: 40 หมู่ 1 บ้านหนองขา หนองขาม จักราช นครราชสีมา 30230 | N42: 0.514 | O42: 0 | P42: 0 | Q42: 0 | R42: 0 | S42: 17 | T42: 17
A43: 42 | B43: 244350 | C43: suckjakkure@hotmail.com | D43: 642427575 | E43: วรรณวนัชเบเกอรี่ | F43: ปณ | G43: 2 | H43: FACEBOOK | I43: WB109584063TH | J43: นัท | K43: 651135388 | L43: 395/1 หมู่ 11 เมืองปัก ปักธงชัย นครราชสีมา 30150 | N43: 1.104 | O43: 0 | P43: 0 | Q43: 0 | R43: 0 | S43: 23 | T43: 23
A44: 43 | B44: 244350 | C44: suckjakkure@hotmail.com | D44: 642427575 | E44: วรรณวนัชเบเกอรี่ | F44: ปณ | G44: 2 | H44: FACEBOOK | I44: WB109584050TH | J44: นาง สำรวย ชนะภัย | K44: 980014719 | L44: 27/1 ม.5 มะค่า โนนไทย นครราชสีมา 30220 | N44: 1.094 | O44: 0 | P44: 0 | Q44: 0 | R44: 0 | S44: 23 | T44: 23
A45: 44 | B45: 244350 | C45: suckjakkure@hotmail.com | D45: 642427575 | E45: วรรณวนัชเบเกอรี่ | F45: ปณ | G45: 2 | H45: FACEBOOK | I45: WB109584046TH | J45: อัจจิมา เอียดเกลี้ยง | K45: 931638485 | L45: 6 ถ.ศรีมาประสิทธิ์ ซ.2 ชะอวด ชะอวด นครศรีธรรมราช 80180 | N45: 0.496 | O45: 0 | P45: 0 | Q45: 0 | R45: 0 | S45: 17 | T45: 17
A46: 45 | B46: 244350 | C46: suckjakkure@hotmail.com | D46: 642427575 | E46: วรรณวนัชเบเกอรี่ | F46: ปณ | G46: 2 | H46: FACEBOOK | I46: WB109584032TH | J46: วีรวัฒน์ ทานอุดม | K46: 983395962 | L46: 176 ม.12 พวา แก่งหางแมว จันทบุรี 22160 | N46: 0.726 | O46: 0 | P46: 0 | Q46: 0 | R46: 0 | S46: 17 | T46: 17
A47: 46 | B47: 244350 | C47: suckjakkure@hotmail.com | D47: 642427575 | E47: วรรณวนัชเบเกอรี่ | F47: ปณ | G47: 2 | H47: FACEBOOK | I47: WB109584029TH | J47: วชิราภรณ์ | K47: 939567247 | L47: 349 หมู่ 4 ถนนสุขุมวิท แพรกษา เมืองสมุทรปราการ สมุทรปราการ 10280 | N47: 0.544 | O47: 0 | P47: 0 | Q47: 0 | R47: 0 | S47: 17 | T47: 17
... A110: 109 | B110: 244350 | C110: suckjakkure@hotmail.com | D110: 642427575 | E110: วรรณวนัชเบเกอรี่ | F110: ปณ | G110: 2 | H110: FACEBOOK | I110: WB109619213TH | J110: นภสร สถากุลเจริญ (ปาล์ม) | K110: 955939901 | L110: ส่วนปฏิบัติการร้านคาเพื่อเมชอนส่วนกลาง ( บค. บอธ. ) บริษัทปดท. น้ำมันและการค้าปลีก จำกัด ( มหาชน) สำนักงานักงานใหญ่ เลขที่ 555/2 ศูนย์เอนเนอร์ขี่คอมเพล็กซ์ อาคาร บี ชั้น 18 ถนนวิกาวคีรังสิต จตุจักร จตุจักร กรุงเทพ 10900 | N110: 0.494 | O110: 0 | P110: 0 | Q110: 0 | R110: 0 | S110: 17 | T110: 17
A111: 110 | B111: 244409 | C111: suckjakkure@hotmail.com | D111: 642427575 | E111: วรรณวนัชเบเกอรี่ | F111: เอกชน | G111: 2 | H111: FACEBOOK | I111: TH011786FMP39B1 | J111: นิศากานต์ นวลอนันต์ | K111: 997529148 | L111: 91/187 ซ.พระราม 2 ( 69) ถ.พระราม 2 บางขุนเทียน แสมดำ กรุงเทพ Thailand | N111: 1 | O111: 25×️17×️18 | P111: 0 | Q111: 0 | R111: 0 | S111: 18 | T111: 18
A112: 111 | B112: 244470 | C112: suckjakkure@hotmail.com | D112: 642427575 | E112: วรรณวนัชเบเกอรี่ | F112: ปณ | G112: 2 | H112: FACEBOOK | I112: WB129879800TH | J112: ปาวีณา หนูเซ่ง | K112: 924159816 | L112: 86 ม.1 ลำภูรา ห้วยยอด ตรัง 92190 | N112: 0.232 | O112: 0 | P112: 0 | Q112: 0 | R112: 0 | S112: 17 | T112: 17
A113: 112 | B113: 244470 | C113: suckjakkure@hotmail.com | D113: 642427575 | E113: วรรณวนัชเบเกอรี่ | F113: ปณ | G113: 2 | H113: FACEBOOK | I113: WA067364651TH | J113: ประสงค์ อภิวัฒน์ชาติ | K113: 816260641 | L113: 268 ซ.รัชดา 13 ดินแดง ดินแดง กรุงเทพ 10400 | N113: 1.296 | O113: 215 | P113: 3.225 | Q113: 0.2258 | R113: 0 | S113: 23 | T113: 26.45
A114: 113 | B114: 244470 | C114: suckjakkure@hotmail.com | D114: 642427575 | E114: วรรณวนัชเบเกอรี่ | F114: ปณ | G114: 2 | H114: FACEBOOK | I114: WA067364648TH | J114: เดือนเพ็ญ กรงเข็ม | K114: 972263309 | L114: 17/13 ม 6 ถนนขาด เมืองนครปฐม นครปฐม 73000 | N114: 2.468 | O114: 399 | P114: 5.985 | Q114: 0.419 | R114: 0 | S114: 34 | T114: 40.4
A115: 114 | B115: 244470 | C115: suckjakkure@hotmail.com | D115: 642427575 | E115: วรรณวนัชเบเกอรี่ | F115: ปณ | G115: 2 | H115: FACEBOOK | I115: WA067364634TH | J115: สมศรี แสนสุข | K115: 639979726 | L115: 20/5 ถ.ภูมิรักษ์ ท่าราบ เมืองเพชรบุรี เพชรบุรี 76000 | N115: 0.798 | O115: 199 | P115: 2.985 | Q115: 0.209 | R115: 0 | S115: 17 | T115: 20.19
A116: 115 | B116: 244470 | C116: suckjakkure@hotmail.com | D116: 642427575 | E116: วรรณวนัชเบเกอรี่ | F116: ปณ | G116: 2 | H116: FACEBOOK | I116: WB129879795TH | J116: เจ สิทธิศักดิ์ | K116: 990404228 | L116: 22/1-3 ห้อง เบอร์ 7 ม.6 โป่ง บางละมุง ชลบุรี 20150 | N116: 0.69 | O116: 0 | P116: 0 | Q116: 0 | R116: 0 | S116: 17 | T116: 17
A117: 116 | B117: 244470 | C117: suckjakkure@hotmail.com | D117: 642427575 | E117: วรรณวนัชเบเกอรี่ | F117: ปณ | G117: 2 | H117: FACEBOOK | I117: WB129879787TH | J117: ขวัญชัย สุวรรณ | K117: 960480586 | L117: 133 ม.6 สะอาดสมบูรณ์ เมืองร้อยเอ็ด ร้อยเอ็ด 45000 | N117: 0.696 | O117: 0 | P117: 0 | Q117: 0 | R117: 0 | S117: 17 | T117: 17
A118: 117 | B118: 244470 | C118: suckjakkure@hotmail.com | D118: 642427575 | E118: วรรณวนัชเบเกอรี่ | F118: ปณ | G118: 2 | H118: FACEBOOK | I118: WB129879773TH | J118: สกาวรัตน์ ศรีชาย | K118: 640089441 | L118: 125 ม.1 พิปูน พิปูน นครศรีธรรมราช 80270 | N118: 0.69 | O118: 0 | P118: 0 | Q118: 0 | R118: 0 | S118: 17 | T118: 17
A119: 118 | B119: 244470 | C119: suckjakkure@hotmail.com | D119: 642427575 | E119: วรรณวนัชเบเกอรี่ | F119: ปณ | G119: 2 | H119: FACEBOOK | I119: WB129879760TH | J119: K.FON (ร้านดอกไม้) | K119: 887847197 | L119: 39 ถ.รัตนอุทิศ หาดใหญ่ หาดใหญ่ สงขลา 90110 | N119: 4.258 | O119: 0 | P119: 0 | Q119: 0 | R119: 0 | S119: 54 | T119: 54
A120: 119 | B120: 244470 | C120: suckjakkure@hotmail.com | D120: 642427575 | E120: วรรณวนัชเบเกอรี่ | F120: ปณ | G120: 2 | H120: FACEBOOK | I120: WB129879756TH | J120: ยุพเนตร | K120: 871624991 | L120: 107 หมู่ 12 ปากช่อง จอมบึง ราชบุรี 70150 | N120: 0.856 | O120: 0 | P120: 0 | Q120: 0 | R120: 0 | S120: 17 | T120: 17
A121: 120 | B121: 244470 | C121: suckjakkure@hotmail.com | D121: 642427575 | E121: วรรณวนัชเบเกอรี่ | F121: ปณ | G121: 2 | H121: FACEBOOK | I121: WA067364625TH | J121: จิรัชยา ประเสริฐ | K121: 813055207 | L121: 574/2 หอพักครูเฮง ห้อง 1 ถนนสรรพสิทธิ์ ในเมือง เมืองอุบลราชธานี อุบลราชธานี 34000 | N121: 1.31 | O121: 215 | P121: 3.225 | Q121: 0.2258 | R121: 0 | S121: 23 | T121: 26.45
A122: 121 | B122: 244470 | C122: suckjakkure@hotmail.com | D122: 642427575 | E122: วรรณวนัชเบเกอรี่ | F122: ปณ | G122: 2 | H122: FACEBOOK | I122: WB129879742TH | J122: ครรชิต อยู่เสน | K122: 639434033 | L122: 41 สุขุมวิท 49/14 แยก 1 ซอยประเสริฐสิษฐ์ คลองตันเหนือ วัฒนา กรุงเทพ 10110 | N122: 0.702 | O122: 0 | P122: 0 | Q122: 0 | R122: 0 | S122: 17 | T122: 17
A123: 122 | B123: 244470 | C123: suckjakkure@hotmail.com | D123: 642427575 | E123: วรรณวนัชเบเกอรี่ | F123: ปณ | G123: 2 | H123: FACEBOOK | I123: WA067364617TH | J123: ปริสุทธา บ้านนาน่าดู | K123: 819935033 | L123: 291/3 หมู่ 3 ริมกก เมืองเชียงราย เชียงราย 57100 | N123: 3.666 | O123: 645 | P123: 9.675 | Q123: 0.6773 | R123: 0 | S123: 44 | T123: 54.35
...

Sheet รวมส่ง ม.ค.
A1: วันที่ส่ง | B1: Email | C1: Tel | D1: ขนส่ง | E1: จำนวนพัสดุที่มี COD(ชิ้น) | F1: จำนวนที่ส่ง(ชิ้น) | G1: รวมยอด COD | H1: รวมยอด COD Fee 2% | I1: รวมค่า COD Fee VAT 7% | J1: รวมค่าพื้นที่เกาะ | K1: รวมค่าขนส่ง | L1: Total Charge
A2: 244350 | B2: suckjakkure@hotmail.com | C2: 642427575 | D2: เอกชน | E2: 15 | F2: 34 | G2: 5061 | H2: 101.22 | I2: 7.09 | J2: - | K2: 1758 | L2: 1866.31
A3: 244350 | B3: suckjakkure@hotmail.com | C3: 642427575 | D3: ปณ | E3: 50 | F3: 75 | G3: 13997 | H3: 209.96 | I3: 14.7 | J3: 15 | K3: 1746 | L3: 1970.66
A4: 244381 | B4: ไม่มียอดเก็บ COD
A5: 244409 | B5: suckjakkure@hotmail.com | C5: 642427575 | D5: ปณ | E5: 0 | F5: 1 | G5: 0 | H5: 0 | I5: 0 | J5: - | K5: 18 | L5: 18
A6: 244440 | B6: ไม่มียอดเก็บ COD
A7: 244470 | B7: suckjakkure@hotmail.com | C7: 642427575 | D7: ปณ | E7: 9 | F7: 17 | G7: 2801 | H7: 42.02 | I7: 2.94 | J7: 0 | K7: 417 | L7: 461.96
A8: 244501 | B8: ไม่มียอดเก็บ COD
A9: 244531 | B9: suckjakkure@hotmail.com | C9: 642427575 | D9: ปณ | E9: 6 | F9: 11 | G9: 1641 | H9: 24.62 | I9: 1.72 | J9: 0 | K9: 279 | L9: 305.34
A10: 244562 | B10: suckjakkure@hotmail.com | C10: 642427575 | D10: ปณ | E10: 0 | F10: 4 | G10: 0 | H10: 0 | I10: 0 | J10: 0 | K10: 80 | L10: 80
A11: 244593 | B11: suckjakkure@hotmail.com | C11: 642427575 | D11: ปณ | E11: 5 | F11: 6 | G11: 1807 | H11: 27.11 | I11: 1.9 | J11: 0 | K11: 192 | L11: 221.01
A12: 244623 | B12: suckjakkure@hotmail.com | C12: 642427575 | D12: ปณ | E12: 6 | F12: 15 | G12: 1842 | H12: 27.63 | I12: 1.93 | J12: 0 | K12: 420 | L12: 449.56
A13: 244654 | B13: suckjakkure@hotmail.com | C13: 642427575 | D13: ปณ | E13: 1 | F13: 6 | G13: 215 | H13: 3.23 | I13: 0.23 | J13: 0 | K13: 168 | L13: 171.46
A14: 244684 | B14: suckjakkure@hotmail.com | C14: 642427575 | D14: ปณ | E14: 3 | F14: 8 | G14: 1470 | H14: 22.05 | I14: 1.54 | J14: 0 | K14: 210 | L14: 233.59
A15: 13/1/2569 | B15: ไม่มียอดเก็บ COD
A16: 14/1/2569 | B16: suckjakkure@hotmail.com | C16: 642427575 | D16: ปณ | E16: 10 | F16: 21 | G16: 4958 | H16: 74.37 | I16: 5.21 | J16: 20 | K16: 1334 | L16: 1413.58
A17: 15/1/2569 | B17: suckjakkure@hotmail.com | C17: 642427575 | D17: ปณ | E17: 2 | F17: 18 | G17: 2045 | H17: 30.68 | I17: 2.15 | J17: 0 | K17: 488 | L17: 520.83
A18: 16/1/2569 | B18: suckjakkure@hotmail.com | C18: 642427575 | D18: ปณ | E18: 3 | F18: 4 | G18: 680 | H18: 10.2 | I18: 0.71 | J18: 0 | K18: 92 | L18: 102.91
A19: 17/1/2569 | B19: suckjakkure@hotmail.com | C19: 642427575 | D19: ปณ | E19: 5 | F19: 12 | G19: 1274 | H19: 19.11 | I19: 1.34 | J19: 0 | K19: 246 | L19: 266.45
A20: 18/1/2569 | B20: suckjakkure@hotmail.com | C20: 642427575 | D20: ปณ | E20: 2 | F20: 8 | G20: 639 | H20: 9.59 | I20: 0.67 | J20: 0 | K20: 178 | L20: 188.26
A21: 19/1/2569 | B21: suckjakkure@hotmail.com | C21: 642427575 | D21: ปณ | E21: 13 | F21: 18 | G21: 4394 | H21: 65.91 | I21: 4.61 | J21: 0 | K21: 556 | L21: 626.52
A22: 20/1/2569 | B22: ไม่มียอดเก็บ COD
A23: 21/1/2569 | B23: suckjakkure@hotmail.com | C23: 642427575 | D23: ปณ | E23: 6 | F23: 18 | G23: 1528 | H23: 22.92 | I23: 1.6 | J23: 0 | K23: 388 | L23: 412.52
A24: 22/1/2569 | B24: suckjakkure@hotmail.com | C24: 642427575 | D24: ปณ | E24: 7 | F24: 17 | G24: 1943 | H24: 29.15 | I24: 2.04 | J24: 0 | K24: 371 | L24: 402.19
A25: 23/1/2569 | B25: suckjakkure@hotmail.com | C25: 642427575 | D25: ปณ | E25: 2 | F25: 27 | G25: 698 | H25: 10.47 | I25: 0.73 | J25: 0 | K25: 500 | L25: 511.2
A26: 24/1/2569 | B26: suckjakkure@hotmail.com | C26: 642427575 | D26: ปณ | E26: 9 | F26: 11 | G26: 2103 | H26: 31.55 | I26: 2.21 | J26: 0 | K26: 258 | L26: 291.76
A27: 25/1/2569 | B27: suckjakkure@hotmail.com | C27: 642427575 | D27: ปณ | E27: 3 | F27: 9 | G27: 580 | H27: 8.7 | I27: 0.61 | J27: 0 | K27: 204 | L27: 213.31
A28: 26/1/2569 | B28: suckjakkure@hotmail.com | C28: 642427575 | D28: ปณ | E28: 7 | F28: 11 | G28: 1758 | H28: 26.37 | I28: 1.85 | J28: 0 | K28: 278 | L28: 306.22
A29: 27/1/2569 | B29: ไม่มียอดเก็บ COD
A30: 28/1/2569 | B30: suckjakkure@hotmail.com | C30: 642427575 | D30: ปณ | E30: 14 | F30: 18 | G30: 3857 | H30: 57.86 | I30: 4.05 | J30: 0 | K30: 430 | L30: 491.91
A31: 29/1/2569 | B31: suckjakkure@hotmail.com | C31: 642427575 | D31: ปณ | E31: 7 | F31: 17 | G31: 1960 | H31: 29.4 | I31: 2.06 | J31: 0 | K31: 337 | L31: 368.46
A32: 30/1/2569 | B32: suckjakkure@hotmail.com | C32: 642427575 | D32: ปณ | E32: 10 | F32: 13 | G32: 2654 | H32: 39.81 | I32: 2.79 | J32: 0 | K32: 299 | L32: 341.6
A33: 31/1/2569 | B33: suckjakkure@hotmail.com | C33: 642427575 | D33: ปณ | E33: 7 | F33: 16 | G33: 2072 | H33: 31.08 | I33: 2.18 | J33: 0 | K33: 360 | L33: 393.26
A34: ยอดรวม | E34: =SUM(E2:E33) -> 202 | F34: =SUM(F2:F33) -> 415 | G34: =SUM(G2:G33) -> 61977 | H34: =SUM(H2:H33) -> 955.01 | I34: =SUM(I2:I33) -> 66.86 | J34: =SUM(J2:J33) -> 35 | K34: =SUM(K2:K33) -> 11607 | L34: =SUM(L2:L33) -> 12628.87

Sheet  รายการส่งของ ก.พ.
A1: ลำดับ | B1: วันที่ส่ง | C1: Email | D1: Tel | E1: Team Name | F1: ขนส่ง | G1: Team Percent COD Fee | H1: Page | I1: Tracking No. | J1: Consignee | K1: Phone number | L1: Address | M1: Item type | N1: Weight（kg) | O1: Demensions | P1: COD Amount | Q1: Total COD Fee | R1: COD VAT 7% | S1: Freight | T1: Total Charge
A2: 1 | B2: 244351 | C2: suckjakkure@hotmail.com | D2: 642427575 | E2: วรรณวนัชเบเกอรี่ | F2: ปณ | G2: 2 | H2: FACEBOOK | I2: WA085178956TH | J2: เสรี-ช่วยชูกลิ่น | K2: 813642006 | L2: 51-ม-2 ยางหย่อง ท่ายาง เพชรบุรี 76130 | N2: 2.484 | O2: 399 | P2: 5.985 | Q2: 0.419 | R2: 0 | S2: 34 | T2: 40.4
A3: 2 | B3: 244351 | C3: suckjakkure@hotmail.com | D3: 642427575 | E3: วรรณวนัชเบเกอรี่ | F3: ปณ | G3: 2 | H3: FACEBOOK | I3: WA085178973TH | J3: ไอรีน ตะเภาพงศ์ | K3: 926355388 | L3: 66/1 ถนนเทศบาลเมืองปู่เจ้าสมิงพราย 11 สำโรงใต้ พระประแดง สมุทรปราการ 10130 | N3: 1.574 | O3: 299 | P3: 4.485 | Q3: 0.314 | R3: 0 | S3: 23 | T3: 27.8
A4: 3 | B4: 244351 | C4: suckjakkure@hotmail.com | D4: 642427575 | E4: วรรณวนัชเบเกอรี่ | F4: ปณ | G4: 2 | H4: FACEBOOK | I4: WA085178995TH | J4: กันยารัตน์ จิตรานุเคราะห์ | K4: 819380588 | L4: บจก. แอ๊ดวานซ์ โซลูชั่น อินเตอร์เนชั่นแนล 54/25 หมู่ 6 ถ.เลียบคลองเทพกาญจนา บางน้ำจืด เมืองสมุทรสาคร สมุทรสาคร 74000 | N4: 1.304 | O4: 215 | P4: 3.225 | Q4: 0.2258 | R4: 0 | S4: 23 | T4: 26.45
A5: 4 | B5: 244351 | C5: suckjakkure@hotmail.com | D5: 642427575 | E5: วรรณวนัชเบเกอรี่ | F5: ปณ | G5: 2 | H5: FACEBOOK | I5: WB132930331TH | J5: นาย เฉลิมพล ศรีทองจ้อย | K5: 945511807 | L5: 34 ม.15 เมืองใหม่ ศรีบุญเรือง หนองบัวลำภู 39180 | N5: 1.516 | O5: 0 | P5: 0 | Q5: 0 | R5: 0 | S5: 23 | T5: 23
A6: 5 | B6: 244351 | C6: suckjakkure@hotmail.com | D6: 642427575 | E6: วรรณวนัชเบเกอรี่ | F6: ปณ | G6: 2 | H6: FACEBOOK | I6: WB132930345TH | J6: ไอซ์ ไวกิ้ง | K6: 973459540 | L6: สวนสนุกในงาน เวทีกลางสะพานหิน ถนนภูเก็ต วิชิต เมืองภูเก็ต ภูเก็ต 83000 | N6: 1.71 | O6: 0 | P6: 0 | Q6: 0 | R6: 20 | S6: 43 | T6: 43
A7: 6 | B7: 244351 | C7: suckjakkure@hotmail.com | D7: 642427575 | E7: วรรณวนัชเบเกอรี่ | F7: ปณ | G7: 2 | H7: FACEBOOK | I7: WB132994155TH | J7: สำรวย สัตยภิรมณ์ | K7: 894425738 | L7: 127/10 หมู่ 1 บ้านโพธิ์ บ้านโพธิ์ ฉะเชิงเทรา 24140 | N7: 9 | O7: 0 | P7: 0 | Q7: 0 | R7: 0 | S7: 101 | T7: 101
A8: 7 | B8: 244351 | C8: suckjakkure@hotmail.com | D8: 642427575 | E8: วรรณวนัชเบเกอรี่ | F8: ปณ | G8: 2 | H8: FACEBOOK | I8: WB132999436TH | J8: คุณ ปัทมา | K8: 21465959 | L8: บม จ. บิ๊กซีซูเปอร์เซ็นเตอร์ ( สำนักงานใหญ่) ( ฝ่ายบัญชี อาคาร เบอร์ ลี่ยุคเกอร์ ( B) ชั้น 6) 88/9 ซอยสมานฉันท์-บาร์โบส พระโขนง คลองเตย กรุงเทพ 10110 | N8: 0.026 | O8: 0 | P8: 0 | Q8: 0 | R8: 0 | S8: 17 | T8: 17
A9: 8 | B9: 244351 | C9: suckjakkure@hotmail.com | D9: 642427575 | E9: วรรณวนัชเบเกอรี่ | F9: ปณ | G9: 2 | H9: FACEBOOK | I9: WB132999440TH | J9: คุณ เจนนี่ | K9: 926728038 | L9: บริษัทซี. เ จ. เอ็กซ์เพรส กรุ๊ป จำกัด 393 อาคาร 393 สีลม ชั้น 2, 4 และ 5 ถนนสีลม สีลม บางรัก กรุงเทพ 10500 | N9: 0.046 | O9: 0 | P9: 0 | Q9: 0 | R9: 0 | S9: 17 | T9: 17
A10: 9 | B10: 244351 | C10: suckjakkure@hotmail.com | D10: 642427575 | E10: วรรณวนัชเบเกอรี่ | F10: ปณ | G10: 2 | H10: FACEBOOK | I10: WB133006295TH | J10: คุณ นิกกี้ | K10: 929963891 | L10: คอน โด Whizdom the Forestia Petopia in เพทโท i ปีย เลขที่ 182/35 ก ม.7 ทางคู่ขนาน ถนนบางนา-ตราด บางแก้ว บางพลี สมุทรปราการ 10540 | N10: 0.03 | O10: 0 | P10: 0 | Q10: 0 | R10: 0 | S10: 17 | T10: 17
A11: 10 | B11: 244382 | C11: suckjakkure@hotmail.com | D11: 642427575 | E11: วรรณวนัชเบเกอรี่ | F11: ปณ | G11: 2 | H11: FACEBOOK | I11: WB133045926TH | J11: คุณ นรัตต์ธพร หมดจด | K11: 827653059 | L11: 193/44 หมู่ 4 เอื้ออาทร( วัดพระเงิน) อาคาร 44 ซอยวัดส้มเกลี้ยง ถนนกาญจนาภิเษก ปลายบาง บางกรวย นนทบุรี 11130 | N11: 1.338 | O11: 0 | P11: 0 | Q11: 0 | R11: 0 | S11: 23 | T11: 23
A12: 11 | B12: 244382 | C12: suckjakkure@hotmail.com | D12: 642427575 | E12: วรรณวนัชเบเกอรี่ | F12: ปณ | G12: 2 | H12: FACEBOOK | I12: WB133045930TH | J12: สุภาวดี | K12: 853715717 | L12: 95 ถ.บริพัตร ท่าราบ เมืองเพชรบุรี เพชรบุรี 76000 | N12: 1.038 | O12: 0 | P12: 0 | Q12: 0 | R12: 0 | S12: 23 | T12: 23
A13: 12 | B13: 244382 | C13: suckjakkure@hotmail.com | D13: 642427575 | E13: วรรณวนัชเบเกอรี่ | F13: ปณ | G13: 2 | H13: FACEBOOK | I13: WA085529649TH | J13: วาริน. คชเผือก | K13: 616133586 | L13: 1065/125 หนองกี่ กบินทร์บุรี ปราจีนบุรี 25110 | N13: 1.306 | O13: 215 | P13: 3.225 | Q13: 0.2258 | R13: 0 | S13: 23 | T13: 26.45
... A32: 31 | B32: 244441 | C32: suckjakkure@hotmail.com | D32: 642427575 | E32: วรรณวนัชเบเกอรี่ | F32: ปณ | G32: 2 | H32: FACEBOOK | I32: WA086251635TH | J32: เนาวรัตน่ จันทร่สมปอง | K32: 840046503 | L32: คาร์แคร์ โพไซดอน 207/56 ม.6 นาเกลือ บางละมุง ชลบุรี 20150 | N32: 1.302 | O32: 215 | P32: 3.225 | Q32: 0.2258 | R32: 20 | S32: 43 | T32: 46.45
A33: 32 | B33: 244471 | C33: suckjakkure@hotmail.com | D33: 642427575 | E33: วรรณวนัชเบเกอรี่ | F33: เอกชน | G33: 2 | H33: FACEBOOK | I33: TH012586JDE58D | J33: คุณ เจนนี่ | K33: 926728038 | L33: บริษัทซี. เ จ. เอ็กซ์เพรส กรุ๊ป จำกัด 393 อาคาร 393 สีลม ชั้น 2, 4 และ 5 ถนนสีลม สีลม บางรัก กรุงเทพ | N33: 0.08 | O33: 1x1x1 | P33: 0 | Q33: 0 | R33: 0 | S33: 18 | T33: 18
A34: 33 | B34: 244471 | C34: suckjakkure@hotmail.com | D34: 642427575 | E34: วรรณวนัชเบเกอรี่ | F34: เอกชน | G34: 2 | H34: FACEBOOK | I34: TH013486HCD96A1 | J34: คุณ อัจฉรา บุตรสาร | K34: 949599796 | L34: 148/521 ซอยรามคำแหง 190 มีนบุรี มีนบุรี กรุงเทพ | N34: 0.21 | O34: 1x1x1 | P34: 0 | Q34: 0 | R34: 0 | S34: 18 | T34: 18
A35: 34 | B35: 244471 | C35: suckjakkure@hotmail.com | D35: 642427575 | E35: วรรณวนัชเบเกอรี่ | F35: เอกชน | G35: 2 | H35: FACEBOOK | I35: TH013786FMP41C | J35: นาย ภิรมย์ กรมพามัย | K35: 805550135 | L35: 315 ถ.ราชวิถี ทุ่งพญาไท ราชเทวี กรุงเทพ | N35: 1.31 | O35: 24x24x17 | P35: 215 | Q35: 4.3 | R35: 0.3 | S35: 22 | T35: 26.6
A36: 35 | B36: 244471 | C36: suckjakkure@hotmail.com | D36: 642427575 | E36: วรรณวนัชเบเกอรี่ | F36: เอกชน | G36: 2 | H36: FACEBOOK | I36: TH040686FMP43C | J36: หทัยกร. ยอดแสง | K36: 639821598 | L36: 39/343 ม.ศุภลักษณ์ซิตี้ บึงคำพร้อย ลำลูกกา ปทุมธานี | N36: 2.34 | O36: 1x1x1 | P36: 399 | Q36: 7.98 | R36: 0.56 | S36: 27 | T36: 35.54
A37: 36 | B37: 244471 | C37: suckjakkure@hotmail.com | D37: 642427575 | E37: วรรณวนัชเบเกอรี่ | F37: เอกชน | G37: 2 | H37: FACEBOOK | I37: TH070186GZNQ4I | J37: พรนิภา | K37: 618263122 | L37: 11/7 ม.1 โคกตูม เมืองลพบุรี ลพบุรี | N37: 1.3 | O37: 1x1x1 | P37: 0 | Q37: 0 | R37: 0 | S37: 24 | T37: 24
A38: 37 | B38: 244471 | C38: suckjakkure@hotmail.com | D38: 642427575 | E38: วรรณวนัชเบเกอรี่ | F38: เอกชน | G38: 2 | H38: FACEBOOK | I38: TH110386HDMN1F | J38: นาย เพ็ญจันทร์ เอี่ยมสะอาด | K38: 636539803 | L38: 39 หมู่ 8 บางอ้อ บ้านนา นครนายก | N38: 2.44 | O38: 54x20x16 | P38: 199 | Q38: 3.98 | R38: 0.28 | S38: 29 | T38: 33.26
A39: 38 | B39: 244471 | C39: suckjakkure@hotmail.com | D39: 642427575 | E39: วรรณวนัชเบเกอรี่ | F39: เอกชน | G39: 2 | H39: FACEBOOK | I39: TH130386HCD90J | J39: คุณ นุ้ย แผนกบัญชี เอกสารวางบิล | K39: 34613074 | L39: บริษัทศรีฟ้าโฟรเซนฟูดส์ จำกัด 208-209 หมู่ 3 วังขนาย ท่าม่วง กาญจนบุรี | N39: 0.19 | O39: 1x1x1 | P39: 0 | Q39: 0 | R39: 0 | S39: 20 | T39: 20
A40: 39 | B40: 244471 | C40: suckjakkure@hotmail.com | D40: 642427575 | E40: วรรณวนัชเบเกอรี่ | F40: เอกชน | G40: 2 | H40: FACEBOOK | I40: TH220586GZNT1A | J40: ตามจิต สาวิไสย | K40: 956310450 | L40: 156/10 ม.1 มะขาม มะขาม จันทบุรี | N40: 1.3 | O40: 1x1x1 | P40: 215 | Q40: 4.3 | R40: 0.3 | S40: 24 | T40: 28.6
A41: 40 | B41: 244471 | C41: suckjakkure@hotmail.com | D41: 642427575 | E41: วรรณวนัชเบเกอรี่ | F41: เอกชน | G41: 2 | H41: FACEBOOK | I41: TH240386FMP33E | J41: สาลี่ หมื่นนรินทร์ | K41: 855202129 | L41: 44/2 ม.10 บึงน้ำรักษ์ บางน้ำเปรี้ยว ฉะเชิงเทรา | N41: 4.92 | O41: 46x20x27 | P41: 0 | Q41: 0 | R41: 0 | S41: 50 | T41: 50
A42: 41 | B42: 244471 | C42: suckjakkure@hotmail.com | D42: 642427575 | E42: วรรณวนัชเบเกอรี่ | F42: เอกชน | G42: 2 | H42: FACEBOOK | I42: TH240386GZNS7E | J42: นางสาว ศิริพร ผลโพธิ์ | K42: 996092164 | L42: 1/2 ม.6 บึงน้ำรักษ์ บางน้ำเปรี้ยว ฉะเชิงเทรา | N42: 1.2 | O42: 1x1x1 | P42: 0 | Q42: 0 | R42: 0 | S42: 24 | T42: 24
A43: 42 | B43: 244471 | C43: suckjakkure@hotmail.com | D43: 642427575 | E43: วรรณวนัชเบเกอรี่ | F43: เอกชน | G43: 2 | H43: FACEBOOK | I43: TH270286FMP35G | J43: ศรัญญา ชิดกระโทก | K43: 653792846 | L43: ( ร้านยายอึ่ง) 106 ม.6 อรพิมพ์ ครบุรี นครราชสีมา | N43: 1.3 | O43: 1x1x1 | P43: 0 | Q43: 0 | R43: 0 | S43: 24 | T43: 24
A44: 43 | B44: 244471 | C44: suckjakkure@hotmail.com | D44: 642427575 | E44: วรรณวนัชเบเกอรี่ | F44: เอกชน | G44: 2 | H44: FACEBOOK | I44: TH301286GZNR5B | J44: ดารารัตน์ ปาปะแพ | K44: 826597712 | L44: ( บ้านหัวเหล่า) 130 หมู่ 6 บก โนนคูณ ศรีสะเกษ | N44: 3.46 | O44: 1x1x1 | P44: 0 | Q44: 0 | R44: 0 | S44: 42 | T44: 42
... A47: 46 | B47: 244471 | C47: suckjakkure@hotmail.com | D47: 642427575 | E47: วรรณวนัชเบเกอรี่ | F47: เอกชน | G47: 2 | H47: FACEBOOK | I47: TH640386FMP37B | J47: สาริกา บูรณะพล | K47: 848402312 | L47: 105 หมู่ 5 ลานสกา ลานสกา นครศรีธรรมราช | N47: 1.02 | O47: 1x1x1 | P47: 0 | Q47: 0 | R47: 0 | S47: 24 | T47: 24
A48: 47 | B48: 244471 | C48: suckjakkure@hotmail.com | D48: 642427575 | E48: วรรณวนัชเบเกอรี่ | F48: ปณ | G48: 2 | H48: FACEBOOK | I48: WB133352232TH | J48: คุณ นุ้ย แผนกบัญชี เอกสารวางบิล | K48: 34613074 | L48: บริษัทศรีฟ้าโฟรเซนฟูดส์ จำกัด 208-209 หมู่ 3 วังขนาย ท่าม่วง กาญจนบุรี 71110 | N48: 0.084 | O48: 0 | P48: 0 | Q48: 0 | R48: 0 | S48: 17 | T48: 17
A49: 48 | B49: 244471 | C49: suckjakkure@hotmail.com | D49: 642427575 | E49: วรรณวนัชเบเกอรี่ | F49: ปณ | G49: 2 | H49: FACEBOOK | I49: WB133352246TH | J49: คุณ อัจฉรา บุตรสาร | K49: 949599796 | L49: 148/521 ซอยรามคำแหง 190 มีนบุรี มีนบุรี กรุงเทพ 10510 | N49: 0.132 | O49: 0 | P49: 0 | Q49: 0 | R49: 0 | S49: 17 | T49: 17
A50: 49 | B50: 244471 | C50: suckjakkure@hotmail.com | D50: 642427575 | E50: วรรณวนัชเบเกอรี่ | F50: ปณ | G50: 2 | H50: FACEBOOK | I50: WA088129795TH | J50: บุตรรินทร์ ต๊ะอ้าย | K50: 983706325 | L50: 69/1 ม.2 พบพระ พบพระ ตาก 63160 | N50: 1.312 | O50: 268 | P50: 4.02 | Q50: 0.2814 | R50: 0 | S50: 23 | T50: 27.3
A51: 50 | B51: 244471 | C51: suckjakkure@hotmail.com | D51: 642427575 | E51: วรรณวนัชเบเกอรี่ | F51: ปณ | G51: 2 | H51: FACEBOOK | I51: WA088129781TH | J51: กิตติภพ จินตนาถาวร | K51: 839422461 | L51: 6/26 หมู่ 3 ซอยบุญนำ พนานิคม นิคมพัฒนา ระยอง 21180 | N51: 2.478 | O51: 486 | P51: 7.29 | Q51: 0.5103 | R51: 0 | S51: 34 | T51: 41.8
A52: 51 | B52: 244471 | C52: suckjakkure@hotmail.com | D52: 642427575 | E52: วรรณวนัชเบเกอรี่ | F52: ปณ | G52: 2 | H52: FACEBOOK | I52: WB133406973TH | J52: ณัฏ | K52: 813424234 | L52: บ้าน 66/3 ถ.ขุมทอง-ต้อยติ่ง 1 ( แยก ลีลาวดี) ขุมทอง ลาดกระบัง กรุงเทพ 10520 | N52: 16.995 | O52: 0 | P52: 0 | Q52: 0 | R52: 0 | S52: 181 | T52: 181
A53: 52 | B53: 244471 | C53: suckjakkure@hotmail.com | D53: 642427575 | E53: วรรณวนัชเบเกอรี่ | F53: ปณ | G53: 2 | H53: FACEBOOK | I53: WA088129778TH | J53: นุชิตา ไสยกุล | K53: 949136200 | L53: 83 ม 12 นามน นามน กาฬสินธุ์ 46230 | N53: 3.118 | O53: 595 | P53: 8.925 | Q53: 0.6248 | R53: 0 | S53: 44 | T53: 53.55
A54: 53 | B54: 244471 | C54: suckjakkure@hotmail.com | D54: 642427575 | E54: วรรณวนัชเบเกอรี่ | F54: ปณ | G54: 2 | H54: FACEBOOK | I54: WB133406956TH | J54: สันติภาพ ปินตาติ๊บ | K54: 987608155 | L54: 127 ม.13. บ้านเด่น พิชัย เมืองลำปาง ลำปาง 52000 | N54: 2.46 | O54: 0 | P54: 0 | Q54: 0 | R54: 0 | S54: 34 | T54: 34
A55: 54 | B55: 244471 | C55: suckjakkure@hotmail.com | D55: 642427575 | E55: วรรณวนัชเบเกอรี่ | F55: ปณ | G55: 2 | H55: FACEBOOK | I55: WA088129764TH | J55: อ้อ | K55: 898995506 | L55: 21 ซอยพระราม 3/29 ถนนพระราม 3 บางโพงพาง ยานนาวา กรุงเทพ 10120 | N55: 1.932 | O55: 377 | P55: 5.655 | Q55: 0.3959 | R55: 0 | S55: 23 | T55: 29.05
A56: 55 | B56: 244471 | C56: suckjakkure@hotmail.com | D56: 642427575 | E56: วรรณวนัชเบเกอรี่ | F56: ปณ | G56: 2 | H56: FACEBOOK | I56: WB133406925TH | J56: สุภาพร กิจสัมพันธ์ | K56: 818752389 | L56: 2 ประชาอุทิศ 22 แยก 3 ราษฎร์บูรณะ ราษฎร์บูรณะ กรุงเทพ 10140 | N56: 2.476 | O56: 0 | P56: 0 | Q56: 0 | R56: 0 | S56: 34 | T56: 34
A57: 56 | B57: 244471 | C57: suckjakkure@hotmail.com | D57: 642427575 | E57: วรรณวนัชเบเกอรี่ | F57: ปณ | G57: 2 | H57: FACEBOOK | I57: WA088129755TH | J57: มลฤดี เลี้ยงพรพรรณ | K57: 943545392 | L57: 62 หมู่ 1 ถ.บ้านกล้วย-ไทรน้อย ไทรน้อย ไทรน้อย นนทบุรี 11150 | N57: 1.676 | O57: 394 | P57: 5.91 | Q57: 0.4137 | R57: 0 | S57: 23 | T57: 29.32
A58: 57 | B58: 244471 | C58: suckjakkure@hotmail.com | D58: 642427575 | E58: วรรณวนัชเบเกอรี่ | F58: ปณ | G58: 2 | H58: FACEBOOK | I58: WA088129733TH | J58: พวงทอง พงษ์พัฒนกิตติ | K58: 899553089 | L58: ร้านซีพีอรุโณทัย 27/3 ม.10 เมืองนะ เชียงดาว เชียงใหม่ 50170 | N58: 2.464 | O58: 486 | P58: 7.29 | Q58: 0.5103 | R58: 0 | S58: 34 | T58: 41.8
A59: 58 | B59: 244471 | C59: suckjakkure@hotmail.com | D59: 642427575 | E59: วรรณวนัชเบเกอรี่ | F59: ปณ | G59: 2 | H59: FACEBOOK | I59: WA088129720TH | J59: ชนะกานต์ คล้ายสมบูรณ์ | K59: 916629706 | L59: 67 ม.14 วังหมี วังน้ำเขียว นครราชสีมา 30370 | N59: 1.908 | O59: 377 | P59: 5.655 | Q59: 0.3959 | R59: 0 | S59: 23 | T59: 29.05
... A183: 182 | B183: 244685 | C183: suckjakkure@hotmail.com | D183: 642427575 | E183: วรรณวนัชเบเกอรี่ | F183: ปณ | G183: 2 | H183: FACEBOOK | I183: WB134415835TH | J183: ภิญญดา เดชธนาปกรณ์ | K183: 897553926 | L183: ( บจก. ทรัพย์แสงดาว ) 256 ม.3 ถ.ยันตรกิจโกศล ดู่ใต้ เมืองน่าน น่าน 55000 | N183: 7.34 | O183: 0 | P183: 0 | Q183: 0 | R183: 0 | S183: 91 | T183: 91
...

Sheet รวมส่ง ก.พ.
A1: วันที่ส่ง | B1: Email | C1: Tel | D1: ขนส่ง | E1: จำนวนพัสดุที่มี COD(ชิ้น) | F1: จำนวนที่ส่ง(ชิ้น) | G1: รวมยอด COD | H1: รวมยอด COD Fee 2% | I1: รวมค่า COD Fee VAT 7% | J1: รวมค่าพื้นที่เกาะ | K1: รวมค่าขนส่ง | L1: Total Charge
A2: 244351 | B2: suckjakkure@hotmail.com | C2: 642427575 | D2: ปณ | E2: 3 | F2: 9 | G2: 913 | H2: 13.7 | I2: 0.96 | J2: 20 | K2: 298 | L2: 312.66
A3: 244382 | B3: suckjakkure@hotmail.com | C3: 642427575 | D3: ปณ | E3: 2 | F3: 4 | G3: 614 | H3: 9.21 | I3: 0.64 | J3: 0 | K3: 103 | L3: 112.85
A4: 244410 | B4: ไม่มียอดเก็บ COD
A5: 244441 | B5: suckjakkure@hotmail.com | C5: 642427575 | D5: ปณ | E5: 9 | F5: 18 | G5: 2851 | H5: 42.77 | I5: 2.99 | J5: 40 | K5: 492 | L5: 537.76
A6: 244471 | B6: suckjakkure@hotmail.com | C6: 642427575 | D6: เอกชน | E6: 5 | F6: 15 | G6: 1227 | H6: 24.54 | I6: 1.72 | J6: - | K6: 390 | L6: 416.26
A7: 244471 | B7: suckjakkure@hotmail.com | C7: 642427575 | D7: ปณ | E7: 12 | F7: 21 | G7: 4518 | H7: 67.77 | I7: 4.74 | J7: 0 | K7: 698 | L7: 770.51
A8: 244501 | B8: suckjakkure@hotmail.com | C8: 642427575 | D8: ปณ | E8: 15 | F8: 25 | G8: 5937 | H8: 89.06 | I8: 6.23 | J8: 0 | K8: 805 | L8: 900.29
A9: 244531 | B9: suckjakkure@hotmail.com | C9: 642427575 | D9: ปณ | E9: 5 | F9: 12 | G9: 1474 | H9: 22.11 | I9: 1.55 | J9: 0 | K9: 268 | L9: 291.66
A10: 244562 | B10: suckjakkure@hotmail.com | C10: 642427575 | D10: ปณ | E10: 9 | F10: 17 | G10: 3074 | H10: 46.11 | I10: 3.23 | J10: 20 | K10: 453 | L10: 502.34
A11: 244593 | B11: suckjakkure@hotmail.com | C11: 642427575 | D11: ปณ | E11: 4 | F11: 22 | G11: 1402 | H11: 21.03 | I11: 1.47 | J11: 0 | K11: 450 | L11: 472.5
A12: 244623 | B12: ไม่มียอดเก็บ COD
A13: 244654 | B13: suckjakkure@hotmail.com | C13: 642427575 | D13: ปณ | E13: 2 | F13: 4 | G13: 544 | H13: 8.16 | I13: 0.57 | J13: 0 | K13: 86 | L13: 94.73
A14: 244684 | B14: suckjakkure@hotmail.com | C14: 642427575 | D14: ปณ | E14: 19 | F14: 35 | G14: 6959 | H14: 104.39 | I14: 7.31 | J14: 0 | K14: 1234 | L14: 1345.7
A15: 13/1/2569 | B15: suckjakkure@hotmail.com | C15: 642427575 | D15: ปณ | E15: 28 | F15: 50 | G15: 10350 | H15: 155.25 | I15: 10.87 | J15: 100 | K15: 2123 | L15: 2289.12
A16: 14/1/2569 | B16: suckjakkure@hotmail.com | C16: 642427575 | D16: ปณ | E16: 19 | F16: 47 | G16: 5047 | H16: 75.71 | I16: 5.3 | J16: 0 | K16: 999 | L16: 1080.01
A17: 15/1/2569 | B17: suckjakkure@hotmail.com | C17: 642427575 | D17: เอกชน | E17: 13 | F17: 16 | G17: 3496 | H17: 69.92 | I17: 4.89 | J17: - | K17: 385 | L17: 459.81
A18: 15/2/2569 | B18: suckjakkure@hotmail.com | C18: 642427575 | D18: ปณ | E18: 42 | F18: 51 | G18: 13303 | H18: 199.55 | I18: 13.97 | J18: 60 | K18: 1614 | L18: 1827.52
A19: 16/2/2569 | B19: suckjakkure@hotmail.com | C19: 642427575 | D19: ปณ | E19: 13 | F19: 17 | G19: 3644 | H19: 54.66 | I19: 3.83 | J19: 0 | K19: 418 | L19: 476.49
A20: 17/2/2569 | B20: ไม่มียอดเก็บ COD
A21: 18/2/2569 | B21: ไม่มียอดเก็บ COD
A22: 19/2/2569 | B22: suckjakkure@hotmail.com | C22: 642427575 | D22: ปณ | E22: 27 | F22: 38 | G22: 7969 | H22: 119.54 | I22: 8.37 | J22: 40 | K22: 983 | L22: 1110.91
A23: 20/2/2569 | B23: suckjakkure@hotmail.com | C23: 642427575 | D23: ปณ | E23: 16 | F23: 23 | G23: 4301 | H23: 64.52 | I23: 4.52 | J23: 20 | K23: 602 | L23: 671.04
A24: 21/2/2569 | B24: suckjakkure@hotmail.com | C24: 642427575 | D24: ปณ | E24: 11 | F24: 20 | G24: 2463 | H24: 36.95 | I24: 2.59 | J24: 0 | K24: 541 | L24: 580.54
A25: 22/2/2569 | B25: suckjakkure@hotmail.com | C25: 642427575 | D25: เอกชน | E25: 3 | F25: 6 | G25: 807 | H25: 16.14 | I25: 1.13 | J25: - | K25: 142 | L25: 159.27
A26: 22/2/2569 | B26: suckjakkure@hotmail.com | C26: 642427575 | D26: ปณ | E26: 8 | F26: 9 | G26: 1720 | H26: 25.8 | I26: 1.81 | J26: 0 | K26: 207 | L26: 234.61
A27: 23/2/2569 | B27: suckjakkure@hotmail.com | C27: 642427575 | D27: ปณ | E27: 3 | F27: 11 | G27: 645 | H27: 9.68 | I27: 0.68 | J27: 0 | K27: 271 | L27: 281.36
A28: 24/2/2569 | B28: ไม่มียอดเก็บ COD
A29: 25/2/2569 | B29: suckjakkure@hotmail.com | C29: 642427575 | D29: ปณ | E29: 8 | F29: 11 | G29: 1720 | H29: 25.8 | I29: 1.81 | J29: 20 | K29: 425 | L29: 452.61
A30: 26/2/2569 | B30: suckjakkure@hotmail.com | C30: 642427575 | D30: ปณ | E30: 21 | F30: 35 | G30: 4262 | H30: 63.93 | I30: 4.48 | J30: 0 | K30: 755 | L30: 823.41
A31: 27/2/2569 | B31: suckjakkure@hotmail.com | C31: 642427575 | D31: ปณ | E31: 8 | F31: 13 | G31: 1618 | H31: 24.27 | I31: 1.7 | J31: 20 | K31: 301 | L31: 326.97
A32: 28/2/2569 | B32: suckjakkure@hotmail.com | C32: 642427575 | D32: ปณ | E32: 4 | F32: 5 | G32: 710 | H32: 10.65 | I32: 0.75 | J32: 0 | K32: 103 | L32: 114.4
A34: ยอดรวม | E34: =SUM(E2:E33) -> 309 | F34: =SUM(F2:F33) -> 534 | G34: =SUM(G2:G33) -> 91568 | H34: =SUM(H2:H33) -> 1401.22 | I34: =SUM(I2:I33) -> 98.11 | J34: =SUM(J2:J33) -> 340 | K34: =SUM(K2:K33) -> 15146 | L34: =SUM(L2:L33) -> 16645.33

Sheet รายการส่งของ มี.ค.
A1: ลำดับ | B1: วันที่ส่ง | C1: Email | D1: Tel | E1: Team Name | F1: ขนส่ง | G1: Team Percent COD Fee | H1: Page | I1: Tracking No. | J1: Consignee | K1: Phone number | L1: Address | M1: Item type | N1: Weight（kg) | O1: Demensions | P1: COD Amount | Q1: Total COD Fee | R1: COD VAT 7% | S1: Freight | T1: Total Charge
A2: 1 | B2: 244352 | C2: suckjakkure@hotmail.com | D2: 642427575 | E2: วรรณวนัชเบเกอรี่ | F2: ปณ | G2: 2 | H2: FACEBOOK | I2: WA096397780TH | J2: แพรวพรรณ มณีโชติ | K2: 658969109 | L2: 59 หมู่ 5 บางขนาก บางน้ำเปรี้ยว ฉะเชิงเทรา 24150 | N2: 0.75 | O2: 99 | P2: 1.485 | Q2: 0.104 | R2: 0 | S2: 17 | T2: 18.59
A3: 2 | B3: 244352 | C3: suckjakkure@hotmail.com | D3: 642427575 | E3: วรรณวนัชเบเกอรี่ | F3: ปณ | G3: 2 | H3: FACEBOOK | I3: WB171469506TH | J3: คุณ นักรบ | K3: 886255646 | L3: 999/22 หมู่บ้านโฮมมี่โฮม หมู่ 5 สุรนารีซอย1 ปรุใหญ่ เมืองนครราชสีมา นครราชสีมา 30000 | N3: 0.342 | O3: 0 | P3: 0 | Q3: 0 | R3: 0 | S3: 17 | T3: 17
A4: 3 | B4: 244352 | C4: suckjakkure@hotmail.com | D4: 642427575 | E4: วรรณวนัชเบเกอรี่ | F4: ปณ | G4: 2 | H4: FACEBOOK | I4: WA096397833TH | J4: อ้อ | K4: 898995506 | L4: 21 ซอยพระราม 3/29 ถนนพระราม 3 บางโพงพาง ยานนาวา กรุงเทพ 10120 | N4: 2.418 | O4: 430 | P4: 6.45 | Q4: 0.4515 | R4: 0 | S4: 34 | T4: 40.9
A5: 4 | B5: 244352 | C5: suckjakkure@hotmail.com | D5: 642427575 | E5: วรรณวนัชเบเกอรี่ | F5: ปณ | G5: 2 | H5: FACEBOOK | I5: WB171429802TH | J5: สุพันธ์ โฆษา | K5: 620089044 | L5: 24/141 หมู่ 3 ถนนสหกรณ์ บางหญ้าแพรก เมืองสมุทรสาคร สมุทรสาคร 74000 | N5: 1.852 | O5: 0 | P5: 0 | Q5: 0 | R5: 0 | S5: 23 | T5: 23
A6: 5 | B6: 244352 | C6: suckjakkure@hotmail.com | D6: 642427575 | E6: วรรณวนัชเบเกอรี่ | F6: ปณ | G6: 2 | H6: FACEBOOK | I6: WB171469510TH | J6: บริษัท รักษิ พี สเตเบิ้ล เวลธ์ จำกัด(สำนักงานใหญ่) | K6: 658875551 | L6: 124/208 ซอยมนตรีสุริยวงค์ 3 หน้าเมือง เมืองราชบุรี ราชบุรี 70000 | N6: 0.378 | O6: 0 | P6: 0 | Q6: 0 | R6: 0 | S6: 17 | T6: 17
A7: 6 | B7: 244352 | C7: suckjakkure@hotmail.com | D7: 642427575 | E7: วรรณวนัชเบเกอรี่ | F7: ปณ | G7: 2 | H7: FACEBOOK | I7: WB171482034TH | J7: คุณคนชล พนายุทธชัย | K7: 914131886 | L7: 102/122 หมู่ 2 ซอย9/2 หมู่บ้านศรีราชาพาร์ควิว สุรศักดิ์ ศรีราชา ชลบุรี 20110 | N7: 0.344 | O7: 0 | P7: 0 | Q7: 0 | R7: 0 | S7: 17 | T7: 17
A8: 7 | B8: 244352 | C8: suckjakkure@hotmail.com | D8: 642427575 | E8: วรรณวนัชเบเกอรี่ | F8: ปณ | G8: 2 | H8: FACEBOOK | I8: WB171429780TH | J8: คุณ พรรณี | K8: 832865027 | L8: 55/58 ซ.วัดโพธิ์วนาราม หมากแข้ง เมืองอุดรธานี อุดรธานี 41000 | N8: 2.418 | O8: 0 | P8: 0 | Q8: 0 | R8: 0 | S8: 34 | T8: 34
A9: 8 | B9: 244352 | C9: suckjakkure@hotmail.com | D9: 642427575 | E9: วรรณวนัชเบเกอรี่ | F9: ปณ | G9: 2 | H9: FACEBOOK | I9: WB171429793TH | J9: แจ๋วมณี ชานุชิต | K9: 897154471 | L9: 384/12 บึงโขงหลง บึงโขงหลง บึงกาฬ 38220 | N9: 16.995 | O9: 0 | P9: 0 | Q9: 0 | R9: 0 | S9: 181 | T9: 181
A10: 9 | B10: 244411 | C10: suckjakkure@hotmail.com | D10: 642427575 | E10: วรรณวนัชเบเกอรี่ | F10: ปณ | G10: 2 | H10: FACEBOOK | I10: WA096397691TH | J10: แสงดาว ละเมิด | K10: 849483928 | L10: 129 ม 7 บ้านขอ เมืองปาน ลำปาง 52240 | N10: 1.296 | O10: 215 | P10: 3.225 | Q10: 0.2258 | R10: 0 | S10: 23 | T10: 26.45
A11: 10 | B11: 244411 | C11: suckjakkure@hotmail.com | D11: 642427575 | E11: วรรณวนัชเบเกอรี่ | F11: ปณ | G11: 2 | H11: FACEBOOK | I11: WA096397714TH | J11: Nit Joเรณู.อยู่สบาย | K11: 959957358 | L11: 36/1 ม.7 ถ.ระแงะมรรคา 36 กรีนสกายค้าเหล็ก&รีไซเคิล ตันหยงมัส ระแงะ นราธิวาส 96130 | N11: 1.27 | O11: 215 | P11: 3.225 | Q11: 0.2258 | R11: 20 | S11: 43 | T11: 46.45
A12: 11 | B12: 244411 | C12: suckjakkure@hotmail.com | D12: 642427575 | E12: วรรณวนัชเบเกอรี่ | F12: ปณ | G12: 2 | H12: FACEBOOK | I12: WA096397731TH | J12: จิตติมา กุลกั้ง | K12: 910640843 | L12: 19 ม.4 บ้านคำกั้ง เหล่าใหญ่ กุฉินารายณ์ กาฬสินธุ์ 46110 | N12: 1.266 | O12: 198 | P12: 2.97 | Q12: 0.2079 | R12: 0 | S12: 23 | T12: 26.18
A13: 12 | B13: 244411 | C13: suckjakkure@hotmail.com | D13: 642427575 | E13: วรรณวนัชเบเกอรี่ | F13: ปณ | G13: 2 | H13: FACEBOOK | I13: WA096397745TH | J13: สุพรรษา ปิยะวงษ์ | K13: 930748806 | L13: ( หจก. ท่าทรายพนมศักดิ์ ราษีสินฯ) 3-3/1 ม.1 ถ.บริหาร เมืองคง ราษีไศล ศรีสะเกษ 33160 | N13: 1.282 | O13: 215 | P13: 3.225 | Q13: 0.2258 | R13: 0 | S13: 23 | T13: 26.45
... A137: 136 | B137: 244595 | C137: suckjakkure@hotmail.com | D137: 642427575 | E137: วรรณวนัชเบเกอรี่ | F137: ปณ | G137: 2 | H137: FACEBOOK | I137: WB172270835TH | J137: คุณ ปู | K137: 925922478 | L137: บริษัทเจี้ยนชา จำกัด เร 5/41 ถ.จรัสเมือง วังใหม่ ปทุมวัน กรุงเทพ 10330 | N137: 0.04 | O137: 0 | P137: 0 | Q137: 0 | R137: 0 | S137: 17 | T137: 17
A138: 137 | B138: 244595 | C138: suckjakkure@hotmail.com | D138: 642427575 | E138: วรรณวนัชเบเกอรี่ | F138: เอกชน | G138: 2 | H138: FACEBOOK | I138: TH01288F76R34B0 | J138: บริษัท กรีนวู้ด แคปปิตอล(ประเทศไทย) จำกัด | K138: 623105425 | L138: 6 ถนนกาญจนาภิเษก ประเวศ ประเวศ กรุงเทพ Thailand | N138: 0.1 | O138: 1×️1×️1 | P138: 0 | Q138: 0 | R138: 0 | S138: 18 | T138: 18
A139: 138 | B139: 244656 | C139: suckjakkure@hotmail.com | D139: 642427575 | E139: วรรณวนัชเบเกอรี่ | F139: ปณ | G139: 2 | H139: FACEBOOK | I139: WA105791459TH | J139: พิศเพลิน ปานนพภา | K139: 640213371 | L139: ใต้คอนโดบุญบัญชา อ่อนนุช 27 สวนหลวง สวนหลวง กรุงเทพ 10250 | N139: 1.298 | O139: 215 | P139: 3.225 | Q139: 0.2258 | R139: 0 | S139: 23 | T139: 26.45
A140: 139 | B140: 244656 | C140: suckjakkure@hotmail.com | D140: 642427575 | E140: วรรณวนัชเบเกอรี่ | F140: ปณ | G140: 2 | H140: FACEBOOK | I140: WA105791462TH | J140: Sukanya Srinako | K140: 971350064 | L140: เขต ห้ามล่าสัตว์ป่าชะอำ 246/1 ชะอำ ชะอำ เพชรบุรี 76120 | N140: 1.278 | O140: 215 | P140: 3.225 | Q140: 0.2258 | R140: 0 | S140: 23 | T140: 26.45
A141: 140 | B141: 244656 | C141: suckjakkure@hotmail.com | D141: 642427575 | E141: วรรณวนัชเบเกอรี่ | F141: ปณ | G141: 2 | H141: FACEBOOK | I141: WA105791476TH | J141: เพียงใจ แซ่ตั้ง | K141: 652692589 | L141: 80 ซอยสาธุ 34 ตรงข้าม แยก หนึ่ง ถนนสาธุประดิษฐ์ บางโพงพาง ยานนาวา กรุงเทพ 10120 | N141: 1.286 | O141: 215 | P141: 3.225 | Q141: 0.2258 | R141: 0 | S141: 23 | T141: 26.45
A142: 141 | B142: 244656 | C142: suckjakkure@hotmail.com | D142: 642427575 | E142: วรรณวนัชเบเกอรี่ | F142: ปณ | G142: 2 | H142: FACEBOOK | I142: WA105791493TH | J142: ธฤษณุ พิณอุดม | K142: 613953568 | L142: 999/195 ม.สราญสิริ ศีรษะจรเข้น้อย บางเสาธง สมุทรปราการ 10570 | N142: 1.278 | O142: 215 | P142: 3.225 | Q142: 0.2258 | R142: 0 | S142: 23 | T142: 26.45
A143: 142 | B143: 244656 | C143: suckjakkure@hotmail.com | D143: 642427575 | E143: วรรณวนัชเบเกอรี่ | F143: ปณ | G143: 2 | H143: FACEBOOK | I143: WA105791502TH | J143: นิภา พงษ์เจริญ | K143: 819326334 | L143: บ. ดีจี เอ็นจิเนียริ่ง จก. 14/4 ม.7 บางเตย สามโคก ปทุมธานี 12160 | N143: 1.29 | O143: 215 | P143: 3.225 | Q143: 0.2258 | R143: 0 | S143: 23 | T143: 26.45
A144: 143 | B144: 244656 | C144: suckjakkure@hotmail.com | D144: 642427575 | E144: วรรณวนัชเบเกอรี่ | F144: ปณ | G144: 2 | H144: FACEBOOK | I144: WA105791516TH | J144: พระอุบล วราสโภ | K144: 904441678 | L144: ที่พักสงฆ์ภูต่าง ม.10 บ่อเบี้ย บ้านโคก อุตรดิตถ์ 53180 | N144: 1.278 | O144: 215 | P144: 3.225 | Q144: 0.2258 | R144: 0 | S144: 23 | T144: 26.45
A145: 144 | B145: 244656 | C145: suckjakkure@hotmail.com | D145: 642427575 | E145: วรรณวนัชเบเกอรี่ | F145: ปณ | G145: 2 | H145: FACEBOOK | I145: WA105791520TH | J145: สันติชัย เหล่าปาทาน | K145: 964242557 | L145: 286/ข ม 2 ป่าโมก ป่าโมก อ่างทอง 14130 | N145: 1.284 | O145: 215 | P145: 3.225 | Q145: 0.2258 | R145: 0 | S145: 23 | T145: 26.45
A146: 145 | B146: 244656 | C146: suckjakkure@hotmail.com | D146: 642427575 | E146: วรรณวนัชเบเกอรี่ | F146: ปณ | G146: 2 | H146: FACEBOOK | I146: WA105791533TH | J146: วรนุช โคกแก้ว | K146: 910151140 | L146: ตลาดสดสาย 5 555 พุทธมนทลสาย 5 อ้อมน้อย กระทุ่มแบน สมุทรสาคร 74130 | N146: 1.286 | O146: 215 | P146: 3.225 | Q146: 0.2258 | R146: 0 | S146: 23 | T146: 26.45
A147: 146 | B147: 244656 | C147: suckjakkure@hotmail.com | D147: 642427575 | E147: วรรณวนัชเบเกอรี่ | F147: ปณ | G147: 2 | H147: FACEBOOK | I147: WA105791547TH | J147: ชาตรี วาสนารุ่เรือง | K147: 623298699 | L147: 90 ซอยแสนสุข แยก 2 ถนนพระราม 4 คลองตัน คลองเตย กรุงเทพ 10110 | N147: 1.296 | O147: 215 | P147: 3.225 | Q147: 0.2258 | R147: 0 | S147: 23 | T147: 26.45
A148: 147 | B148: 244656 | C148: suckjakkure@hotmail.com | D148: 642427575 | E148: วรรณวนัชเบเกอรี่ | F148: ปณ | G148: 2 | H148: FACEBOOK | I148: WA105791564TH | J148: ผ่องพรรณ สร้อยมุข | K148: 968989632 | L148: 24 ตรอกศรีบุญเรือง ( ซอยร้านขนมจีนหน้าวัดไพรสณฑ์) หล่มสัก หล่มสัก เพชรบูรณ์ 67110 | N148: 1.294 | O148: 215 | P148: 3.225 | Q148: 0.2258 | R148: 0 | S148: 23 | T148: 26.45
A149: 148 | B149: 244656 | C149: suckjakkure@hotmail.com | D149: 642427575 | E149: วรรณวนัชเบเกอรี่ | F149: ปณ | G149: 2 | H149: FACEBOOK | I149: WA105791578TH | J149: Waleerat Asavakittikun | K149: 891594704 | L149: 169/181 หมู่ บ้านมัณฑนา วงแหวน- อ่อนนุช 3 ถ.กาญจนาภิเษก ดอกไม้ ประเวศ กรุงเทพ 10250 | N149: 1.294 | O149: 215 | P149: 3.225 | Q149: 0.2258 | R149: 0 | S149: 23 | T149: 26.45
A150: 149 | B150: 244656 | C150: suckjakkure@hotmail.com | D150: 642427575 | E150: วรรณวนัชเบเกอรี่ | F150: ปณ | G150: 2 | H150: FACEBOOK | I150: WA105791581TH | J150: ยุพา นาเจริญ | K150: 839094338 | L150: 160/11 ชุมชน ซอยพัทลุง ลาดพร้าว 48 แยก 8-4 สามเสนนอก ห้วยขวาง กรุงเทพ 10310 | N150: 1.282 | O150: 215 | P150: 3.225 | Q150: 0.2258 | R150: 0 | S150: 23 | T150: 26.45
... A200: 199 | B200: 244686 | C200: suckjakkure@hotmail.com | D200: 642427575 | E200: วรรณวนัชเบเกอรี่ | F200: ปณ | G200: 2 | H200: FACEBOOK | I200: WB172701632TH | J200: บริษัท แกร็บแท็กซี่(ประเทศไทย)จำกัด(สำนักงานใหญ่) | K200: 20212530 | L200: เลขที่ 252 อาคาร เอสพีอี ชั้น 10 ถนนพหลโยธิน สามเสนใน พญาไท กรุงเทพ 10400 | N200: 0.032 | O200: 0 | P200: 0 | Q200: 0 | R200: 0 | S200: 17 | T200: 17
A201: 200 | B201: 13/3/2569 | C201: suckjakkure@hotmail.com | D201: 642427575 | E201: วรรณวนัชเบเกอรี่ | F201: ปณ | G201: 2 | H201: FACEBOOK | I201: WB172752546TH | J201: แพรวพรรณ. ฟักฉ่ำ | K201: 890857245 | L201: 44/1 ม 3. หันตะเภา วังน้อย พระนครศรีอยุธยา 13170 | N201: 1.27 | O201: 0 | P201: 0 | Q201: 0 | R201: 0 | S201: 23 | T201: 23
A202: 201 | B202: 13/3/2569 | C202: suckjakkure@hotmail.com | D202: 642427575 | E202: วรรณวนัชเบเกอรี่ | F202: ปณ | G202: 2 | H202: FACEBOOK | I202: WA106638828TH | J202: พิทักษ์ รักโข | K202: 897395087 | L202: 49 ม.4 นาทวี นาทวี สงขลา 90160 | N202: 1.274 | O202: 215 | P202: 3.225 | Q202: 0.2258 | R202: 0 | S202: 23 | T202: 26.45
A203: 202 | B203: 13/3/2569 | C203: suckjakkure@hotmail.com | D203: 642427575 | E203: วรรณวนัชเบเกอรี่ | F203: ปณ | G203: 2 | H203: FACEBOOK | I203: WA106638831TH | J203: ณัฐ | K203: 810192929 | L203: 319/47 ม.1 สนามชัย เมืองสุพรรณบุรี สุพรรณบุรี 72000 | N203: 1.276 | O203: 215 | P203: 3.225 | Q203: 0.2258 | R203: 0 | S203: 23 | T203: 26.45
A204: 203 | B204: 13/3/2569 | C204: suckjakkure@hotmail.com | D204: 642427575 | E204: วรรณวนัชเบเกอรี่ | F204: ปณ | G204: 2 | H204: FACEBOOK | I204: WA106638845TH | J204: อัญชุลี มัคคีธรรม | K204: 658831687 | L204: 234/205 หมู่ บ้านเทพารักษ์วิลล่า ( ซอย4 หลังสุดท้ายซ้ายมือ) เทพารักษ์ เมืองสมุทรปราการ สมุทรปราการ 10270 | N204: 1.816 | O204: 499 | P204: 7.485 | Q204: 0.524 | R204: 0 | S204: 23 | T204: 31.01
A205: 204 | B205: 13/3/2569 | C205: suckjakkure@hotmail.com | D205: 642427575 | E205: วรรณวนัชเบเกอรี่ | F205: ปณ | G205: 2 | H205: FACEBOOK | I205: WA106638814TH | J205: รัตติกาลแก้วดวงเล็ก | K205: 972194553 | L205: 58/96 นิมิตรใหม่ ซอย11 อินทาวิลล์ แยก 1 มีนบุรี มีนบุรี กรุงเทพ 10510 | N205: 1.8 | O205: 399 | P205: 5.985 | Q205: 0.419 | R205: 0 | S205: 23 | T205: 29.4
A206: 205 | B206: 13/3/2569 | C206: suckjakkure@hotmail.com | D206: 642427575 | E206: วรรณวนัชเบเกอรี่ | F206: ปณ | G206: 2 | H206: FACEBOOK | I206: WA106638859TH | J206: เสาวลักษณ์ ศิริแท้ | K206: 834637404 | L206: 46 หมู่ 16 บ้านทุ่งบอน บุ่งหวาย วารินชำราบ อุบลราชธานี 34310 | N206: 1.286 | O206: 215 | P206: 3.225 | Q206: 0.2258 | R206: 0 | S206: 23 | T206: 26.45
A207: 206 | B207: 13/3/2569 | C207: suckjakkure@hotmail.com | D207: 642427575 | E207: วรรณวนัชเบเกอรี่ | F207: ปณ | G207: 2 | H207: FACEBOOK | I207: WA106638862TH | J207: กาญจนา_วรวัฒนา | K207: 971912682 | L207: _102/6_1 ท่ากระชับ นครชัยศรี นครปฐม 73120 | N207: 1.276 | O207: 215 | P207: 3.225 | Q207: 0.2258 | R207: 0 | S207: 23 | T207: 26.45
A208: 207 | B208: 13/3/2569 | C208: suckjakkure@hotmail.com | D208: 642427575 | E208: วรรณวนัชเบเกอรี่ | F208: ปณ | G208: 2 | H208: FACEBOOK | I208: WA106639531TH | J208: Sorapat Chillananda | K208: 817024900 | L208: 89/277 ซอย13/4 หมู่ บ้านคาซ่าวิลล์ วัชรพล ถนนวัชรพล คลองถนน สายไหม กรุงเทพ 10220 | N208: 1.27 | O208: 215 | P208: 3.225 | Q208: 0.2258 | R208: 0 | S208: 23 | T208: 26.45
A209: 208 | B209: 13/3/2569 | C209: suckjakkure@hotmail.com | D209: 642427575 | E209: วรรณวนัชเบเกอรี่ | F209: ปณ | G209: 2 | H209: FACEBOOK | I209: WB172752550TH | J209: คุณ จรี ชูกิจการรุ่ง 2/2 | K209: 822984360 | L209: 121/2 หมู่ . 9. ซ.เกษตร 6 หนองลู สังขละบุรี กาญจนบุรี 71240 | N209: 7.19 | O209: 0 | P209: 0 | Q209: 0 | R209: 20 | S209: 111 | T209: 111
A210: 209 | B210: 13/3/2569 | C210: suckjakkure@hotmail.com | D210: 642427575 | E210: วรรณวนัชเบเกอรี่ | F210: ปณ | G210: 2 | H210: FACEBOOK | I210: WB172813333TH | J210: นาย ธนนิจ ยิ่งยงยุทธ | K210: 801631324 | L210: 37 ม.2 บุฤาษี เมืองสุรินทร์ สุรินทร์ 32000 | N210: 1.616 | O210: 0 | P210: 0 | Q210: 0 | R210: 0 | S210: 23 | T210: 23
A211: 210 | B211: 13/3/2569 | C211: suckjakkure@hotmail.com | D211: 642427575 | E211: วรรณวนัชเบเกอรี่ | F211: ปณ | G211: 2 | H211: FACEBOOK | I211: WA106638876TH | J211: เสมอเทพ เสมอตน | K211: 927823748 | L211: 100 ม.7 บ้านเสม็ด เชื้อเพลิง ปราสาท สุรินทร์ 32140 | N211: 1.274 | O211: 215 | P211: 3.225 | Q211: 0.2258 | R211: 0 | S211: 23 | T211: 26.45
A212: 211 | B212: 13/3/2569 | C212: suckjakkure@hotmail.com | D212: 642427575 | E212: วรรณวนัชเบเกอรี่ | F212: ปณ | G212: 2 | H212: FACEBOOK | I212: WB172752563TH | J212: คุณ จรี ชูกิจการรุ่ง 1/2 | K212: 822984360 | L212: 121/2 หมู่ . 9. ซ.เกษตร 6 หนองลู สังขละบุรี กาญจนบุรี 71240 | N212: 13.19 | O212: 0 | P212: 0 | Q212: 0 | R212: 20 | S212: 171 | T212: 171
...

Sheet  รวมส่ง มี.ค.
A1: วันที่ส่ง | B1: Email | C1: Tel | D1: ขนส่ง | E1: จำนวนพัสดุที่มี COD(ชิ้น) | F1: จำนวนที่ส่ง(ชิ้น) | G1: รวมยอด COD | H1: รวมยอด COD Fee 2% | I1: รวมค่า COD Fee VAT 7% | J1: รวมค่าพื้นที่เกาะ | K1: รวมค่าขนส่ง | L1: Total Charge
A2: 244350 | B2: suckjakkure@hotmail.com | C2: 642427575 | D2: ปณ | E2: 2 | F2: 8 | G2: 529 | H2: 7.94 | I2: 0.56 | J2: 0 | K2: 340 | L2: 348.5
A3: 244350
A4: 244381 | B4: ไม่มียอดเก็บ COD
A5: 244409 | B5: suckjakkure@hotmail.com | C5: 642427575 | D5: ปณ | E5: 9 | F5: 14 | G5: 1918 | H5: 28.77 | I5: 2.01 | J5: 20 | K5: 324 | L5: 354.78
A6: 244440 | B6: suckjakkure@hotmail.com | C6: 642427575 | D6: ปณ | E6: 40 | F6: 49 | G6: 9785 | H6: 146.78 | I6: 10.27 | J6: 20 | K6: 1195 | L6: 1352.05
A7: 244470 | B7: suckjakkure@hotmail.com | C7: 642427575 | D7: ปณ | E7: 5 | F7: 27 | G7: 1558 | H7: 23.37 | I7: 1.64 | J7: 0 | K7: 522 | L7: 547.01
A8: 244501 | B8: suckjakkure@hotmail.com | C8: 642427575 | D8: ปณ | E8: 3 | F8: 10 | G8: 645 | H8: 9.68 | I8: 0.68 | J8: 0 | K8: 200 | L8: 210.36
A9: 244531 | B9: suckjakkure@hotmail.com | C9: 642427575 | D9: ปณ | E9: 1 | F9: 9 | G9: 215 | H9: 3.23 | I9: 0.23 | J9: 0 | K9: 194 | L9: 197.46
A10: 244562 | B10: suckjakkure@hotmail.com | C10: 642427575 | D10: ปณ | E10: 7 | F10: 10 | G10: 1640 | H10: 24.6 | I10: 1.72 | J10: 0 | K10: 229 | L10: 255.32
A11: 244593 | B11: suckjakkure@hotmail.com | C11: 642427575 | D11: ปณ | E11: 7 | F11: 9 | G11: 1694 | H11: 25.41 | I11: 1.78 | J11: 20 | K11: 220 | L11: 247.19
A12: 244593 | B12: suckjakkure@hotmail.com | C12: 642427575 | D12: เอกชน | E12: 0 | F12: 1 | G12: 0 | H12: 0 | I12: 0 | J12: - | K12: 18 | L12: 18
A13: 244625 | B13: ไม่มียอดเก็บ COD
A14: 244656 | B14: suckjakkure@hotmail.com | C14: 642427575 | D14: ปณ | E14: 28 | F14: 37 | G14: 6169 | H14: 92.54 | I14: 6.48 | J14: 20 | K14: 892 | L14: 991.02
A15: 244686 | B15: suckjakkure@hotmail.com | C15: 642427575 | D15: ปณ | E15: 16 | F15: 25 | G15: 3839 | H15: 57.59 | I15: 4.03 | J15: 20 | K15: 624 | L15: 685.62
A16: 13/3/2569 | B16: suckjakkure@hotmail.com | C16: 642427575 | D16: ปณ | E16: 8 | F16: 12 | G16: 2188 | H16: 32.82 | I16: 2.3 | J16: 40 | K16: 512 | L16: 547.12
A17: 14/3/2569 | B17: suckjakkure@hotmail.com | C17: 642427575 | D17: ปณ | E17: 0 | F17: 4 | G17: 0 | H17: 0 | I17: 0 | J17: 0 | K17: 68 | L17: 68
A18: 15/3/2569 | B18: suckjakkure@hotmail.com | C18: 642427575 | D18: ปณ | E18: 8 | F18: 14 | G18: 2114 | H18: 31.71 | I18: 2.22 | J18: 60 | K18: 374 | L18: 407.93
A19: 16/3/2569 | B19: suckjakkure@hotmail.com | C19: 642427575 | D19: ปณ | E19: 9 | F19: 11 | G19: 1932 | H19: 28.98 | I19: 2.03 | J19: 0 | K19: 229 | L19: 260.01
A20: 17/3/2569 | B20: ไม่มียอดเก็บ COD
A21: 18/3/2569 | B21: suckjakkure@hotmail.com | C21: 642427575 | D21: ปณ | E21: 43 | F21: 77 | G21: 9970 | H21: 149.55 | I21: 10.47 | J21: 0 | K21: 1663 | L21: 1823.02
A22: 19/3/2569 | B22: suckjakkure@hotmail.com | C22: 642427575 | D22: ปณ | E22: 19 | F22: 29 | G22: 2968 | H22: 44.52 | I22: 3.12 | J22: 20 | K22: 561 | L22: 608.64
A23: 20/3/2569 | B23: suckjakkure@hotmail.com | C23: 642427575 | D23: ปณ | E23: 10 | F23: 15 | G23: 1831 | H23: 27.47 | I23: 1.92 | J23: 0 | K23: 279 | L23: 308.39
A24: 21/3/2569 | B24: suckjakkure@hotmail.com | C24: 642427575 | D24: ปณ | E24: 9 | F24: 19 | G24: 1821 | H24: 27.32 | I24: 1.91 | J24: 0 | K24: 557 | L24: 586.23
A25: 22/3/2569 | B25: suckjakkure@hotmail.com | C25: 642427575 | D25: ปณ | E25: 13 | F25: 31 | G25: 2345 | H25: 35.18 | I25: 2.46 | J25: 0 | K25: 574 | L25: 611.64
A26: 23/3/2569 | B26: suckjakkure@hotmail.com | C26: 642427575 | D26: ปณ | E26: 8 | F26: 10 | G26: 2135 | H26: 32.03 | I26: 2.24 | J26: 0 | K26: 239 | L26: 273.27
A27: 24/3/2569 | B27: ไม่มียอดเก็บ COD
A28: 25/3/2569 | B28: suckjakkure@hotmail.com | C28: 642427575 | D28: ปณ | E28: 6 | F28: 29 | G28: 929 | H28: 13.94 | I28: 0.98 | J28: 20 | K28: 537 | L28: 551.92
A29: 26/3/2569 | B29: suckjakkure@hotmail.com | C29: 642427575 | D29: ปณ | E29: 9 | F29: 18 | G29: 1924 | H29: 28.86 | I29: 2.02 | J29: 0 | K29: 336 | L29: 366.88
A30: 27/3/2569 | B30: suckjakkure@hotmail.com | C30: 642427575 | D30: ปณ | E30: 37 | F30: 47 | G30: 7997 | H30: 119.96 | I30: 8.4 | J30: 0 | K30: 1086 | L30: 1214.36
A31: 28/3/2569 | B31: suckjakkure@hotmail.com | C31: 642427575 | D31: ปณ | E31: 2 | F31: 8 | G31: 845 | H31: 12.68 | I31: 0.89 | J31: 0 | K31: 360 | L31: 373.57
A32: 29/3/2569 | B32: suckjakkure@hotmail.com | C32: 642427575 | D32: ปณ | E32: 7 | F32: 12 | G32: 1390 | H32: 20.85 | I32: 1.46 | J32: 0 | K32: 240 | L32: 262.31
A33: 30/3/2569 | B33: suckjakkure@hotmail.com | C33: 642427575 | D33: ปณ | E33: 6 | F33: 9 | G33: 1159 | H33: 17.39 | I33: 1.22 | J33: 0 | K33: 177 | L33: 195.61
A34: 31/3/2569 | B34: ไม่มียอดเก็บ COD
A35: ยอดรวม | E35: =SUM(E2:E34) -> 312 | F35: =SUM(F2:F34) -> 544 | G35: =SUM(G2:G34) -> 69540 | H35: =SUM(H2:H34) -> 1043.17 | I35: =SUM(I2:I34) -> 73.04 | J35: =SUM(J2:J34) -> 240 | K35: =SUM(K2:K34) -> 12550 | L35: =SUM(L2:L34) -> 13666.21

Sheet รายการส่งของ  เม.ย.
A1: ลำดับ | B1: วันที่ส่ง | C1: Email | D1: Tel | E1: Team Name | F1: ขนส่ง | G1: Team Percent COD Fee | H1: Page | I1: Tracking No. | J1: Consignee | K1: Phone number | L1: Address | M1: Item type | N1: Weight（kg) | O1: Demensions | P1: COD Amount | Q1: Total COD Fee | R1: COD VAT 7% | S1: Freight | T1: Total Charge
A2: 1 | B2: 244353 | C2: suckjakkure@hotmail.com | D2: 642427575 | E2: วรรณวนัชเบเกอรี่ | F2: ปณ | G2: 2 | H2: FACEBOOK | I2: WA111795106TH | J2: เยาวนารถบุญเพ็ง | K2: 812536120 | L2: 103/7 หมู่ที่ 2 โคกตูม เมืองลพบุรี ลพบุรี 15210 | N2: 0.834 | O2: 200 | P2: 3 | Q2: 0.21 | R2: 0 | S2: 17 | T2: 20.21
A3: 2 | B3: 244353 | C3: suckjakkure@hotmail.com | D3: 642427575 | E3: วรรณวนัชเบเกอรี่ | F3: ปณ | G3: 2 | H3: FACEBOOK | I3: WA111795145TH | J3: คุณ นราธิป อาภรณ์รัตน์ | K3: 934492999 | L3: ดลนราคอร์ส 16/5 ซอย1 ข ถนนทุ่งโฮเต็ล วัดเกต เมืองเชียงใหม่ เชียงใหม่ 50000 | N3: 0.84 | O3: 200 | P3: 3 | Q3: 0.21 | R3: 0 | S3: 17 | T3: 20.21
A4: 3 | B4: 244353 | C4: suckjakkure@hotmail.com | D4: 642427575 | E4: วรรณวนัชเบเกอรี่ | F4: ปณ | G4: 2 | H4: FACEBOOK | I4: WA111795171TH | J4: วรรณภา ธูปงาม | K4: 634438840 | L4: 201 ม 8 หนองบัวใต้ ศรีบุญเรือง หนองบัวลำภู 39180 | N4: 0.956 | O4: 199 | P4: 2.985 | Q4: 0.209 | R4: 0 | S4: 17 | T4: 20.19
A5: 4 | B5: 244353 | C5: suckjakkure@hotmail.com | D5: 642427575 | E5: วรรณวนัชเบเกอรี่ | F5: ปณ | G5: 2 | H5: FACEBOOK | I5: WA111795185TH | J5: อรอนงค์ นวลทอง | K5: 897195449 | L5: ร้านต้นกล้าพานิชย์ 222 ม.4 พระเหลา พนา อำนาจเจริญ 37180 | N5: 0.926 | O5: 199 | P5: 2.985 | Q5: 0.209 | R5: 0 | S5: 17 | T5: 20.19
A6: 5 | B6: 244353 | C6: suckjakkure@hotmail.com | D6: 642427575 | E6: วรรณวนัชเบเกอรี่ | F6: ปณ | G6: 2 | H6: FACEBOOK | I6: WA111795208TH | J6: วรรณี พวงสุข | K6: 849097527 | L6: 101 ม.1 เขาพระ เดิมบางนางบวช สุพรรณบุรี 72120 | N6: 1.24 | O6: 215 | P6: 3.225 | Q6: 0.2258 | R6: 0 | S6: 23 | T6: 26.45
