Workbook

Sheet ม.ค. 68
A1: ข้อมูลเทียบกำไร - ขาดทุน ของบู๊ซ เดือน มกราคม 2568
A2: ลำดับ | B2: รหัส | C2: บูธ | D2: ยอดขาย | E2: ส่วนลด | F2: คงเหลือยอดขาย | G2: ค่าต้นทุนขนม | H2: คงเหลือกำไรหลังจากหักต้นทุน | I2: ค่าแรงพนักงานบู๊ช | J2: ค่าคอมพนักงานบู๊ซ | K2: ค่าคอม (พิเศษ)พนักงานบู๊ซ | L2: ค่าพนักงานรายเดือนที่เกี่ยวข้อง | M2: ค่าเช่า | N2: ค่าภาษีโรงเรือน | O2: ค่าน้ำ | P2: ค่าไฟ | Q2: ค่าธรรมเนียมโอนเงิน | R2: ค่าเน็ต | S2: ค่าโทรศัพท์ | T2: ค่าส่วนกลาง | U2: ค่าน้ำแข็ง | V2: ค่าขนมนอก | W2: ค่าป้าย | X2: ค่าขนส่ง | Y2: ค่าใช้จ่ายอื่น ๆ | Z2: คงเหลือกำไรหลังจากหักต้นทุน และ ค่าใช้จ่าย
A3: 1 | B3: 10203 | C3: ลำพยา 3 (ใหม่) | D3: 128861 | E3: 7753 | F3: =+D3-E3 -> 121108 | G3: =+D3*0.5 -> 64430.5 | H3: =+F3-G3 -> 56677.5 | I3: =17988.319-844.32-200 -> 16943.999 | J3: 844.32 | K3: 200 | L3: 5272.7273 | M3: =14884+14884 -> 29768 | N3: 1041.88 | O3: 0 | P3: 5623.92 | Q3: 0 | R3: 642 | S3: 206.96 | T3: 0 | U3: 0 | V3: 0 | Y3: 0 | Z3: =+H3-I3-J3-L3-M3-O3-P3-S3-T3-U3-V3-W3-X3-Y3-Q3-R3-K3-N3 -> -3866.3063
A4: 2 | B4: 10204 | C4: ร้านใหม่ (ปตท.คุณาวรรณ) | D4: 220203 | E4: 51628 | F4: =+D4-E4 -> 168575 | G4: =+D4*0.5 -> 110101.5 | H4: =+F4-G4 -> 58473.5 | I4: =17988.319-2743-500 -> 14745.319 | J4: 2743 | K4: 500 | L4: 5272.7273 | M4: 5820 | N4: 1041.88 | O4: 35 | P4: 2823.16 | Q4: 465 | R4: 0 | S4: 206.96 | T4: 0 | U4: 0 | V4: 0 | Y4: 0 | Z4: =+H4-I4-J4-L4-M4-O4-P4-S4-T4-U4-V4-W4-X4-Y4-Q4-R4-K4-N4 -> 24820.454
A5: 3 | B5: 10205 | C5: หน้ามอ (ม.เกษตร) | D5: 133710 | E5: 19125 | F5: =+D5-E5 -> 114585 | G5: =+D5*0.5 -> 66855 | H5: =+F5-G5 -> 47730 | I5: =17988.319-583.4-300 -> 17104.919 | J5: 583.4 | K5: 300 | L5: 5272.7273 | M5: 0 | N5: 0 | O5: 0 | P5: 12343.79 | Q5: 0 | R5: 961.93 | S5: 206.96 | T5: 0 | U5: 94 | V5: 580 | Y5: 99 | Z5: =+H5-I5-J5-L5-M5-O5-P5-S5-T5-U5-V5-W5-X5-Y5-Q5-R5-K5-N5 -> 10183.274
A6: 4 | B6: 10207 | C6: ลำพยา 3 (เก่า) | D6: 154600 | E6: 6916 | F6: =+D6-E6 -> 147684 | G6: =+D6*0.5 -> 77300 | H6: =+F6-G6 -> 70384 | I6: =17988.319-1907.36-400 -> 15680.959 | J6: 1907.36 | K6: 400 | L6: 5272.7273 | M6: 11000 | N6: 0 | O6: 0 | P6: 2730 | Q6: 0 | R6: 0 | S6: 206.96 | T6: 0 | U6: 0 | V6: 0 | Y6: 0 | Z6: =+H6-I6-J6-L6-M6-O6-P6-S6-T6-U6-V6-W6-X6-Y6-Q6-R6-K6-N6 -> 33185.994
A7: 5 | B7: 10208 | C7: ไทวัสดุ | D7: 54540 | E7: 7470 | F7: =+D7-E7 -> 47070 | G7: =+D7*0.5 -> 27270 | H7: =+F7-G7 -> 19800 | I7: 17988.319 | J7: 0 | K7: 0 | L7: 5272.7273 | M7: 6741 | N7: 441 | O7: 0 | P7: 1171.01 | Q7: 0 | R7: 0 | S7: 206.96 | T7: 259.37 | U7: 0 | V7: 0 | Y7: 100 | Z7: =+H7-I7-J7-L7-M7-O7-P7-S7-T7-U7-V7-W7-X7-Y7-Q7-R7-K7-N7 -> -12380.386
A8: 6 | B8: 10209 | C8: แก้วมณีกาญ | D8: 154050 | E8: 22555 | F8: =+D8-E8 -> 131495 | G8: =+D8*0.5 -> 77025 | H8: =+F8-G8 -> 54470 | I8: =17988.319-1259.8-200 -> 16528.519 | J8: 1259.8 | K8: 200 | L8: 5272.7273 | M8: 16000 | N8: 212.52 | O8: 0 | P8: 3036 | Q8: 0 | R8: 642 | S8: 206.96 | T8: 0 | U8: 0 | V8: 0 | Y8: 69 | Z8: =+H8-I8-J8-L8-M8-O8-P8-S8-T8-U8-V8-W8-X8-Y8-Q8-R8-K8-N8 -> 11042.474
A9: 7 | B9: 10210 | C9: ลำพยา 2 (ใหม่) | D9: 144070 | E9: 13198 | F9: =+D9-E9 -> 130872 | G9: =+D9*0.5 -> 72035 | H9: =+F9-G9 -> 58837 | I9: =17988.319-1234.88-100 -> 16653.439 | J9: 1234.88 | K9: 100 | L9: 5272.7273 | M9: =14884+14884 -> 29768 | N9: 0 | O9: 0 | P9: 6278.76 | Q9: 465 | R9: 642 | S9: 206.96 | T9: 0 | U9: 0 | V9: 0 | Y9: 0 | Z9: =+H9-I9-J9-L9-M9-O9-P9-S9-T9-U9-V9-W9-X9-Y9-Q9-R9-K9-N9 -> -1784.7663
A10: 8 | B10: 10219 | C10: ธรรมศาลา | D10: 109220 | E10: 13561 | F10: =+D10-E10 -> 95659 | G10: =+D10*0.5 -> 54610 | H10: =+F10-G10 -> 41049 | I10: =17988.319-100 -> 17888.319 | J10: 0 | K10: 100 | L10: 5272.7273 | M10: 16500 | N10: 301.83 | O10: 0 | P10: 3844.5 | Q10: 450 | R10: 0 | S10: 206.96 | T10: 467.29 | U10: 0 | V10: 0 | Y10: 69 | Z10: =+H10-I10-J10-L10-M10-O10-P10-S10-T10-U10-V10-W10-X10-Y10-Q10-R10-K10-N10 -> -4051.6263
A11: 9 | B11: 10235 | C11: ตลาดดิโอโซน | D11: 130539 | E11: 17342 | F11: =+D11-E11 -> 113197 | G11: =+D11*0.5 -> 65269.5 | H11: =+F11-G11 -> 47927.5 | I11: =17988.319-527-300 -> 17161.319 | J11: 527 | K11: 300 | L11: 5272.7273 | M11: 12000 | N11: 0 | O11: 0 | P11: 4609.56 | Q11: 0 | R11: 642 | S11: 212.72 | T11: 0 | U11: 0 | V11: 0 | Y11: 0 | Z11: =+H11-I11-J11-L11-M11-O11-P11-S11-T11-U11-V11-W11-X11-Y11-Q11-R11-K11-N11 -> 7202.1737
A12: 10 | B12: 10264 | C12: ปตท.ราชบุรี | D12: 162953 | E12: 25706 | F12: =+D12-E12 -> 137247 | G12: =+D12*0.5 -> 81476.5 | H12: =+F12-G12 -> 55770.5 | I12: =17988.319-1489-300 -> 16199.319 | J12: 1489 | K12: 300 | L12: 5272.7273 | M12: 21000 | N12: 0 | O12: 0 | P12: 4609.56 | Q12: 420 | R12: 0 | S12: 0 | T12: 0 | U12: 0 | V12: 0 | Y12: 0 | Z12: =+H12-I12-J12-L12-M12-O12-P12-S12-T12-U12-V12-W12-X12-Y12-Q12-R12-K12-N12 -> 6479.8937
A13: 11 | B13: 10377 | C13: ปิ่นเกล้า -ศาลายา | D13: 73879 | E13: 6305 | F13: =+D13-E13 -> 67574 | G13: =+D13*0.5 -> 36939.5 | H13: =+F13-G13 -> 30634.5 | I13: 17988.319 | J13: 0 | K13: 0 | L13: 5272.7273 | M13: 22000 | N13: 708.75 | O13: 0 | P13: 0 | Q13: 0 | R13: 0 | S13: 0 | T13: 0 | U13: 0 | V13: 0 | Y13: 0 | Z13: =+H13-I13-J13-L13-M13-O13-P13-S13-T13-U13-V13-W13-X13-Y13-Q13-R13-K13-N13 -> -15335.296
A14: 12 | B14: 10371 | C14: ชัยพฤกษ์ - นนทบุรี | D14: 49462 | E14: 6518 | F14: =+D14-E14 -> 42944 | G14: =+D14*0.5 -> 24731 | H14: =+F14-G14 -> 18213 | I14: 17988.319 | J14: 0 | K14: 0 | L14: 5272.7273 | M14: 12000 | N14: 420 | O14: 0 | P14: 5213.04 | Q14: 0 | R14: 0 | S14: 0 | T14: 0 | U14: 0 | V14: 0 | Y14: 75 | Z14: =+H14-I14-J14-L14-M14-O14-P14-S14-T14-U14-V14-W14-X14-Y14-Q14-R14-K14-N14 -> -22756.086
C15: รวม | D15: =SUM(D3:D14) -> 1516087 | E15: =SUM(E3:E14) -> 198077 | F15: =SUM(F3:F14) -> 1318010 | G15: =SUM(G3:G14) -> 758043.5 | H15: =SUM(H3:H14) -> 559966.5 | I15: =SUM(I3:I14) -> 202871.07 | J15: =SUM(J3:J14) -> 10588.76 | K15: =SUM(K3:K14) -> 2400 | ... Z15: =SUM(Z3:Z14) -> 32739.795 | AA15: บาท
C16: กำไร | D16: =+Z15 -> 32739.795
C17: คิดเป็น % | D17: =+D16/D15 -> 0.021594931

Sheet ก.พ. 68
A1: ข้อมูลเทียบกำไร - ขาดทุน ของบู๊ซ เดือน มกราคม 2568
A2: ลำดับ | B2: รหัส | C2: บูธ | D2: ยอดขาย | E2: ส่วนลด | F2: คงเหลือยอดขาย | G2: ค่าต้นทุนขนม | H2: คงเหลือกำไรหลังจากหักต้นทุน | I2: ค่าแรงพนักงานบู๊ช | J2: ค่าคอมพนักงานบู๊ซ | K2: ค่าคอม (พิเศษ)พนักงานบู๊ซ | L2: ค่าพนักงานรายเดือนที่เกี่ยวข้อง | M2: ค่าเช่า | N2: ค่าภาษีโรงเรือน | O2: ค่าน้ำ | P2: ค่าไฟ | Q2: ค่าธรรมเนียมโอนเงิน | R2: ค่าเน็ต | S2: ค่าโทรศัพท์ | T2: ค่าส่วนกลาง | U2: ค่าน้ำแข็ง | V2: ค่าขนมนอก | W2: ค่าป้าย | X2: ค่าขนส่ง | Y2: ค่าใช้จ่ายอื่น ๆ | Z2: คงเหลือกำไรหลังจากหักต้นทุน และ ค่าใช้จ่าย
A3: 1 | B3: 10203 | C3: ลำพยา 3 (ใหม่) | D3: 76605 | E3: 1370 | F3: =+D3-E3 -> 75235 | G3: =+D3*0.5 -> 38302.5 | H3: =+F3-G3 -> 36932.5 | I3: =17988.319-844.32-200 -> 16943.999 | J3: 0 | K3: 0 | L3: 5272.7273 | M3: =14884+14884 -> 29768 | N3: 0 | O3: 0 | P3: 5534.04 | Q3: 405 | R3: 642 | S3: 206.96 | T3: 0 | U3: 0 | V3: 0 | Y3: 56 | Z3: =+H3-I3-J3-L3-M3-O3-P3-S3-T3-U3-V3-W3-X3-Y3-Q3-R3-K3-N3 -> -21896.226
A4: 2 | B4: 10204 | C4: ร้านใหม่ (ปตท.คุณาวรรณ) | D4: 100514 | E4: 14479 | F4: =+D4-E4 -> 86035 | G4: =+D4*0.5 -> 50257 | H4: =+F4-G4 -> 35778 | I4: =17988.319-2743-500 -> 14745.319 | J4: 0 | K4: 100 | L4: 5272.7273 | M4: 5820 | N4: 0 | O4: 0 | P4: 3249.27 | Q4: 135 | R4: 0 | S4: 206.96 | T4: 0 | U4: 0 | V4: 0 | Y4: 56 | Z4: =+H4-I4-J4-L4-M4-O4-P4-S4-T4-U4-V4-W4-X4-Y4-Q4-R4-K4-N4 -> 6192.7237
A5: 3 | B5: 10205 | C5: หน้ามอ (ม.เกษตร) | D5: 83633 | E5: 10423 | F5: =+D5-E5 -> 73210 | G5: =+D5*0.5 -> 41816.5 | H5: =+F5-G5 -> 31393.5 | I5: =17988.319-583.4-300 -> 17104.919 | J5: 0 | K5: 0 | L5: 5272.7273 | M5: 0 | N5: 0 | O5: 0 | P5: 3249.27 | Q5: 0 | R5: 961.93 | S5: 206.96 | T5: 0 | U5: 50 | V5: 895 | Y5: 20 | Z5: =+H5-I5-J5-L5-M5-O5-P5-S5-T5-U5-V5-W5-X5-Y5-Q5-R5-K5-N5 -> 3632.6937
A6: 4 | B6: 10207 | C6: ลำพยา 3 (เก่า) | D6: 92105 | E6: 2480 | F6: =+D6-E6 -> 89625 | G6: =+D6*0.5 -> 46052.5 | H6: =+F6-G6 -> 43572.5 | I6: =17988.319-1907.36-400 -> 15680.959 | J6: 0 | K6: 0 | L6: 5272.7273 | M6: 11000 | N6: 0 | O6: 0 | P6: 2604 | Q6: 0 | R6: 0 | S6: 206.96 | T6: 0 | U6: 0 | V6: 0 | Y6: 0 | Z6: =+H6-I6-J6-L6-M6-O6-P6-S6-T6-U6-V6-W6-X6-Y6-Q6-R6-K6-N6 -> 8807.8537
A7: 5 | B7: 10208 | C7: ไทวัสดุ | D7: 43015 | E7: 2360 | F7: =+D7-E7 -> 40655 | G7: =+D7*0.5 -> 21507.5 | H7: =+F7-G7 -> 19147.5 | I7: 17988.319 | J7: 0 | K7: 0 | L7: 5272.7273 | M7: 6741 | N7: 441 | O7: 0 | P7: 1073 | Q7: 0 | R7: 0 | S7: 206.96 | T7: 259.37 | U7: 0 | V7: 0 | Y7: 0 | Z7: =+H7-I7-J7-L7-M7-O7-P7-S7-T7-U7-V7-W7-X7-Y7-Q7-R7-K7-N7 -> -12834.876
A8: 6 | B8: 10209 | C8: แก้วมณีกาญ | D8: 101970 | E8: 17724 | F8: =+D8-E8 -> 84246 | G8: =+D8*0.5 -> 50985 | H8: =+F8-G8 -> 33261 | I8: =17988.319-1259.8-200 -> 16528.519 | J8: 0 | K8: 0 | L8: 5272.7273 | M8: 16000 | N8: 0 | O8: 0 | P8: 3388 | Q8: 0 | R8: 642 | S8: 206.96 | T8: 0 | U8: 0 | V8: 0 | Y8: 79 | Z8: =+H8-I8-J8-L8-M8-O8-P8-S8-T8-U8-V8-W8-X8-Y8-Q8-R8-K8-N8 -> -8856.2063
A9: 7 | B9: 10210 | C9: ลำพยา 2 (ใหม่) | D9: 89145 | E9: 2705 | F9: =+D9-E9 -> 86440 | G9: =+D9*0.5 -> 44572.5 | H9: =+F9-G9 -> 41867.5 | I9: =17988.319-1234.88-100 -> 16653.439 | J9: 0 | K9: 0 | L9: 5272.7273 | M9: =14884+14884 -> 29768 | N9: 0 | O9: 0 | P9: 5091 | Q9: 405 | R9: 642 | S9: 206.96 | T9: 0 | U9: 0 | V9: 0 | Y9: 0 | Z9: =+H9-I9-J9-L9-M9-O9-P9-S9-T9-U9-V9-W9-X9-Y9-Q9-R9-K9-N9 -> -16171.626
A10: 8 | B10: 10219 | C10: ธรรมศาลา | D10: 62385 | E10: 8640 | F10: =+D10-E10 -> 53745 | G10: =+D10*0.5 -> 31192.5 | H10: =+F10-G10 -> 22552.5 | I10: =17988.319-100 -> 17888.319 | J10: 0 | K10: 0 | L10: 5272.7273 | M10: 16500 | N10: 0 | O10: 0 | P10: 3514 | Q10: 420 | R10: 0 | S10: 206.96 | T10: 467.29 | U10: 0 | V10: 0 | Y10: 123 | Z10: =+H10-I10-J10-L10-M10-O10-P10-S10-T10-U10-V10-W10-X10-Y10-Q10-R10-K10-N10 -> -21839.796
A11: 9 | B11: 10235 | C11: ตลาดดิโอโซน | D11: 57961 | E11: 8816 | F11: =+D11-E11 -> 49145 | G11: =+D11*0.5 -> 28980.5 | H11: =+F11-G11 -> 20164.5 | I11: =17988.319-527-300 -> 17161.319 | J11: 0 | K11: 0 | L11: 5272.7273 | M11: 12000 | N11: 0 | O11: 0 | P11: 5065.38 | Q11: 0 | R11: 642 | S11: 212.72 | T11: 0 | U11: 0 | V11: 0 | Y11: 0 | Z11: =+H11-I11-J11-L11-M11-O11-P11-S11-T11-U11-V11-W11-X11-Y11-Q11-R11-K11-N11 -> -20189.646
A12: 10 | B12: 10264 | C12: ปตท.ราชบุรี | D12: 64522 | E12: 5214 | F12: =+D12-E12 -> 59308 | G12: =+D12*0.5 -> 32261 | H12: =+F12-G12 -> 27047 | I12: =17988.319-1489-300 -> 16199.319 | J12: 0 | K12: 0 | L12: 5272.7273 | M12: 21000 | N12: 0 | O12: 0 | P12: 3922.62 | Q12: 360 | R12: 0 | S12: 0 | T12: 0 | U12: 0 | V12: 0 | Y12: 0 | Z12: =+H12-I12-J12-L12-M12-O12-P12-S12-T12-U12-V12-W12-X12-Y12-Q12-R12-K12-N12 -> -19707.666
A13: 11 | B13: 10377 | C13: ปิ่นเกล้า -ศาลายา | D13: 49485 | E13: 4273 | F13: =+D13-E13 -> 45212 | G13: =+D13*0.5 -> 24742.5 | H13: =+F13-G13 -> 20469.5 | I13: 17988.319 | J13: 0 | K13: 0 | L13: 5272.7273 | M13: 22000 | N13: 0 | O13: 0 | P13: 0 | Q13: 0 | R13: 0 | S13: 0 | T13: 0 | U13: 0 | V13: 0 | Y13: 0 | Z13: =+H13-I13-J13-L13-M13-O13-P13-S13-T13-U13-V13-W13-X13-Y13-Q13-R13-K13-N13 -> -24791.546
A14: 12 | B14: 10371 | C14: ชัยพฤกษ์ - นนทบุรี | D14: 36350 | E14: 4465 | F14: =+D14-E14 -> 31885 | G14: =+D14*0.5 -> 18175 | H14: =+F14-G14 -> 13710 | I14: 17988.319 | J14: 0 | K14: 0 | L14: 5272.7273 | M14: 12000 | N14: 0 | O14: 0 | P14: 5155.26 | Q14: 0 | R14: 0 | S14: 0 | T14: 0 | U14: 0 | V14: 0 | Y14: 0 | Z14: =+H14-I14-J14-L14-M14-O14-P14-S14-T14-U14-V14-W14-X14-Y14-Q14-R14-K14-N14 -> -26706.306
C15: รวม | D15: =SUM(D3:D14) -> 857690 | E15: =SUM(E3:E14) -> 82949 | F15: =SUM(F3:F14) -> 774741 | G15: =SUM(G3:G14) -> 428845 | H15: =SUM(H3:H14) -> 345896 | I15: =SUM(I3:I14) -> 202871.07 | J15: =SUM(J3:J14) -> 0 | K15: =SUM(K3:K14) -> 100 | ... Z15: =SUM(Z3:Z14) -> -154360.63 | AA15: บาท
C16: กำไร | D16: =+Z15 -> -154360.63
C17: คิดเป็น % | D17: =+D16/D15 -> -0.17997251

Sheet มี.ค. 68
A1: ข้อมูลเทียบกำไร - ขาดทุน ของบู๊ซ เดือน มกราคม 2568
A2: ลำดับ | B2: รหัส | C2: บูธ | D2: ยอดขาย | E2: ส่วนลด | F2: คงเหลือยอดขาย | G2: ค่าต้นทุนขนม | H2: คงเหลือกำไรหลังจากหักต้นทุน | I2: ค่าแรงพนักงานบู๊ช | J2: ค่าคอมพนักงานบู๊ซ | K2: ค่าคอม (พิเศษ)พนักงานบู๊ซ | L2: ค่าพนักงานรายเดือนที่เกี่ยวข้อง | M2: ค่าเช่า | N2: ค่าภาษีโรงเรือน | O2: ค่าน้ำ | P2: ค่าไฟ | Q2: ค่าธรรมเนียมโอนเงิน | R2: ค่าเน็ต | S2: ค่าโทรศัพท์ | T2: ค่าส่วนกลาง | U2: ค่าน้ำแข็ง | V2: ค่าขนมนอก | W2: ค่าป้าย | X2: ค่าขนส่งพนักงานรายเดือน | Y2: ค่าใช้จ่ายอื่น ๆ | Z2: คงเหลือกำไรหลังจากหักต้นทุน และ ค่าใช้จ่าย
A3: 1 | B3: 10203 | C3: ลำพยา 3 (ใหม่) | D3: 87995 | E3: 3285 | F3: =+D3-E3 -> 84710 | G3: =+D3*0.5 -> 43997.5 | H3: =+F3-G3 -> 40712.5 | I3: =+[1]รายชื่อพนักงานรายเดือน!G10 -> 17553.886 | J3: 0 | K3: 0 | L3: =+[1]รายชื่อพนักงานรายเดือน!C9 -> 3580.5558 | M3: =14884+14884 -> 29768 | N3: 0 | O3: 0 | P3: 5340 | Q3: 420 | R3: 0 | S3: 206.96 | T3: 0 | U3: 0 | V3: 0 | X3: =+[1]รายชื่อพนักงานรายเดือน!K8 -> 230.76923 | Y3: 39 | Z3: =+H3-I3-J3-L3-M3-O3-P3-S3-T3-U3-V3-W3-X3-Y3-Q3-R3-K3-N3 -> -16426.671
A4: 2 | B4: 10204 | C4: ร้านใหม่ (ปตท.คุณาวรรณ) | D4: 109670 | E4: 17060 | F4: =+D4-E4 -> 92610 | G4: =+D4*0.5 -> 54835 | H4: =+F4-G4 -> 37775 | I4: =+[1]รายชื่อพนักงานรายเดือน!G10 -> 17553.886 | J4: 0 | K4: 0 | L4: =+[1]รายชื่อพนักงานรายเดือน!C9 -> 3580.5558 | M4: 5820 | N4: 0 | O4: 38 | P4: 3249 | Q4: 75 | R4: 0 | S4: 206.96 | T4: 0 | U4: 0 | V4: 0 | X4: =+[1]รายชื่อพนักงานรายเดือน!K8 -> 230.76923 | Y4: 100 | Z4: =+H4-I4-J4-L4-M4-O4-P4-S4-T4-U4-V4-W4-X4-Y4-Q4-R4-K4-N4 -> 6920.8291
A5: 3 | B5: 10205 | C5: หน้ามอ (ม.เกษตร) | D5: 100135 | E5: 16250 | F5: =+D5-E5 -> 83885 | G5: =+D5*0.5 -> 50067.5 | H5: =+F5-G5 -> 33817.5 | I5: =+[1]รายชื่อพนักงานรายเดือน!G10 -> 17553.886 | J5: 0 | K5: 0 | L5: =+[1]รายชื่อพนักงานรายเดือน!C9 -> 3580.5558 | M5: 0 | N5: 0 | O5: 110 | P5: 14787.99 | Q5: 0 | R5: 0 | S5: 206.96 | T5: 0 | U5: 70 | V5: 120 | X5: =+[1]รายชื่อพนักงานรายเดือน!K8 -> 230.76923 | Y5: 163 | Z5: =+H5-I5-J5-L5-M5-O5-P5-S5-T5-U5-V5-W5-X5-Y5-Q5-R5-K5-N5 -> -3005.6609
A6: 4 | B6: 10207 | C6: ลำพยา 3 (เก่า) | D6: 105850 | E6: 1585 | F6: =+D6-E6 -> 104265 | G6: =+D6*0.5 -> 52925 | H6: =+F6-G6 -> 51340 | I6: =+[1]รายชื่อพนักงานรายเดือน!G10 -> 17553.886 | J6: 170.6 | K6: 0 | L6: =+[1]รายชื่อพนักงานรายเดือน!C9 -> 3580.5558 | M6: 9000 | N6: 0 | O6: 0 | P6: 2868 | Q6: 450 | R6: 0 | S6: 206.96 | T6: 0 | U6: 0 | V6: 0 | X6: =+[1]รายชื่อพนักงานรายเดือน!K8 -> 230.76923 | Y6: 0 | Z6: =+H6-I6-J6-L6-M6-O6-P6-S6-T6-U6-V6-W6-X6-Y6-Q6-R6-K6-N6 -> 17279.229
A7: 5 | B7: 10208 | C7: ไทวัสดุ | D7: 46320 | E7: 2215 | F7: =+D7-E7 -> 44105 | G7: =+D7*0.5 -> 23160 | H7: =+F7-G7 -> 20945 | I7: =+[1]รายชื่อพนักงานรายเดือน!G10 -> 17553.886 | J7: 0 | K7: 0 | L7: =+[1]รายชื่อพนักงานรายเดือน!C9 -> 3580.5558 | M7: 6741 | N7: 441 | O7: 0 | P7: 1171.01 | Q7: 0 | R7: 0 | S7: 206.96 | T7: 259.37 | U7: 0 | V7: 0 | X7: =+[1]รายชื่อพนักงานรายเดือน!K8 -> 230.76923 | Y7: 0 | Z7: =+H7-I7-J7-L7-M7-O7-P7-S7-T7-U7-V7-W7-X7-Y7-Q7-R7-K7-N7 -> -9239.5509
A8: 6 | B8: 10209 | C8: แก้วมณีกาญ | D8: 100690 | E8: 21122 | F8: =+D8-E8 -> 79568 | G8: =+D8*0.5 -> 50345 | H8: =+F8-G8 -> 29223 | I8: =+[1]รายชื่อพนักงานรายเดือน!G10 -> 17553.886 | J8: 0 | K8: 0 | L8: =+[1]รายชื่อพนักงานรายเดือน!C9 -> 3580.5558 | M8: 16000 | N8: 0 | O8: 0 | P8: 3784 | Q8: 0 | R8: 0 | S8: 206.96 | T8: 0 | U8: 0 | V8: 0 | X8: =+[1]รายชื่อพนักงานรายเดือน!K8 -> 230.76923 | Y8: 0 | Z8: =+H8-I8-J8-L8-M8-O8-P8-S8-T8-U8-V8-W8-X8-Y8-Q8-R8-K8-N8 -> -12133.171
A9: 7 | B9: 10210 | C9: ลำพยา 2 (ใหม่) | D9: 104635 | E9: 2139 | F9: =+D9-E9 -> 102496 | G9: =+D9*0.5 -> 52317.5 | H9: =+F9-G9 -> 50178.5 | I9: =+[1]รายชื่อพนักงานรายเดือน!G10 -> 17553.886 | J9: 99.84 | K9: 0 | L9: =+[1]รายชื่อพนักงานรายเดือน!C9 -> 3580.5558 | M9: =14884+14884 -> 29768 | N9: 0 | O9: 0 | P9: 4795.74 | Q9: 465 | R9: 0 | S9: 206.96 | T9: 0 | U9: 0 | V9: 0 | X9: =+[1]รายชื่อพนักงานรายเดือน!K8 -> 230.76923 | Y9: 0 | Z9: =+H9-I9-J9-L9-M9-O9-P9-S9-T9-U9-V9-W9-X9-Y9-Q9-R9-K9-N9 -> -6522.2509
A10: 8 | B10: 10219 | C10: ธรรมศาลา | D10: 82715 | E10: 10325 | F10: =+D10-E10 -> 72390 | G10: =+D10*0.5 -> 41357.5 | H10: =+F10-G10 -> 31032.5 | I10: =+[1]รายชื่อพนักงานรายเดือน!G10 -> 17553.886 | J10: 0 | K10: 0 | L10: =+[1]รายชื่อพนักงานรายเดือน!C9 -> 3580.5558 | M10: 16500 | N10: 0 | O10: 0 | P10: 3674 | Q10: 450 | R10: 0 | S10: 0 | T10: 467.29 | U10: 0 | V10: 0 | X10: =+[1]รายชื่อพนักงานรายเดือน!K8 -> 230.76923 | Y10: 0 | Z10: =+H10-I10-J10-L10-M10-O10-P10-S10-T10-U10-V10-W10-X10-Y10-Q10-R10-K10-N10 -> -11424.001
A11: 9 | B11: 10235 | C11: ตลาดดิโอโซน | D11: 66893 | E11: 7988 | F11: =+D11-E11 -> 58905 | G11: =+D11*0.5 -> 33446.5 | H11: =+F11-G11 -> 25458.5 | I11: =+[1]รายชื่อพนักงานรายเดือน!G10 -> 17553.886 | J11: 0 | K11: 0 | L11: =+[1]รายชื่อพนักงานรายเดือน!C9 -> 3580.5558 | M11: 12000 | N11: 0 | O11: 0 | P11: 5616 | Q11: 0 | R11: 0 | S11: 212.72 | T11: 0 | U11: 0 | V11: 0 | X11: =+[1]รายชื่อพนักงานรายเดือน!K8 -> 230.76923 | Y11: 0 | Z11: =+H11-I11-J11-L11-M11-O11-P11-S11-T11-U11-V11-W11-X11-Y11-Q11-R11-K11-N11 -> -13735.431
A12: 10 | B12: 10264 | C12: ปตท.ราชบุรี | D12: 75085 | E12: 3690 | F12: =+D12-E12 -> 71395 | G12: =+D12*0.5 -> 37542.5 | H12: =+F12-G12 -> 33852.5 | I12: =+[1]รายชื่อพนักงานรายเดือน!G10 -> 17553.886 | J12: 0 | K12: 0 | L12: =+[1]รายชื่อพนักงานรายเดือน!C9 -> 3580.5558 | M12: 22050 | N12: 0 | O12: 0 | P12: 4416.96 | Q12: 450 | R12: 0 | S12: 0 | T12: 0 | U12: 0 | V12: 0 | X12: =+[1]รายชื่อพนักงานรายเดือน!K8 -> 230.76923 | Y12: 79 | Z12: =+H12-I12-J12-L12-M12-O12-P12-S12-T12-U12-V12-W12-X12-Y12-Q12-R12-K12-N12 -> -14508.671
A13: 11 | B13: 10377 | C13: ปิ่นเกล้า -ศาลายา | D13: 55720 | E13: 6001 | F13: =+D13-E13 -> 49719 | G13: =+D13*0.5 -> 27860 | H13: =+F13-G13 -> 21859 | I13: =+[1]รายชื่อพนักงานรายเดือน!G10 -> 17553.886 | J13: 0 | K13: 0 | L13: =+[1]รายชื่อพนักงานรายเดือน!C9 -> 3580.5558 | M13: 20250 | N13: 0 | O13: 0 | P13: 0 | Q13: 0 | R13: 0 | S13: 0 | T13: 0 | U13: 0 | V13: 0 | X13: =+[1]รายชื่อพนักงานรายเดือน!K8 -> 230.76923 | Y13: 0 | Z13: =+H13-I13-J13-L13-M13-O13-P13-S13-T13-U13-V13-W13-X13-Y13-Q13-R13-K13-N13 -> -19756.211
A14: 12 | B14: 10371 | C14: ชัยพฤกษ์ - นนทบุรี | D14: 33315 | E14: 5583 | F14: =+D14-E14 -> 27732 | G14: =+D14*0.5 -> 16657.5 | H14: =+F14-G14 -> 11074.5 | I14: =+[1]รายชื่อพนักงานรายเดือน!G10 -> 17553.886 | J14: 0 | K14: 0 | L14: =+[1]รายชื่อพนักงานรายเดือน!C9 -> 3580.5558 | M14: 12000 | N14: 0 | O14: 0 | P14: 6201.72 | Q14: 0 | R14: 1070 | S14: 0 | T14: 0 | U14: 0 | V14: 0 | X14: =+[1]รายชื่อพนักงานรายเดือน!K8 -> 230.76923 | Y14: 53 | Z14: =+H14-I14-J14-L14-M14-O14-P14-S14-T14-U14-V14-W14-X14-Y14-Q14-R14-K14-N14 -> -29615.431
A15: 13 | B15: 10380 | C15: Event เซ็นทรัลโคราช | D15: 12265 | E15: 281 | F15: =+D15-E15 -> 11984 | G15: =+D15*0.5 -> 6132.5 | H15: =+F15-G15 -> 5851.5 | I15: =600*6 -> 3600 | J15: 0 | K15: 0 | L15: =1516.67+3033.333 -> 4550.003 | M15: 0 | N15: 0 | O15: 0 | P15: 0 | Q15: 0 | R15: 0 | S15: 0 | T15: 0 | U15: 0 | V15: 0 | X15: =+[1]รายชื่อพนักงานรายเดือน!K8 -> 230.76923 | Y15: =750*1.5*6 -> 6750 | Z15: =+H15-I15-J15-L15-M15-O15-P15-S15-T15-U15-V15-W15-X15-Y15-Q15-R15-K15-N15 -> -9279.2722
C16: รวม | D16: =SUM(D3:D15) -> 981288 | E16: =SUM(E3:E15) -> 97524 | F16: =SUM(F3:F15) -> 883764 | G16: =SUM(G3:G15) -> 490644 | H16: =SUM(H3:H15) -> 393120 | I16: =SUM(I3:I15) -> 214246.63 | J16: =SUM(J3:J15) -> 270.44 | K16: =SUM(K3:K15) -> 0 | ... Z16: =SUM(Z3:Z15) -> -121446.26 | AA16: บาท
C17: กำไร | D17: =+Z16 -> -121446.26
C18: คิดเป็น % | D18: =+D17/D16 -> -0.1237621

Sheet เม.ย. 68
A1: ข้อมูลเทียบกำไร - ขาดทุน ของบู๊ซ เดือน เมษายน 2568
A2: ลำดับ | B2: รหัส | C2: บูธ | D2: ยอดขาย | E2: ส่วนลด | F2: คงเหลือยอดขาย | G2: ค่าต้นทุนขนม | H2: คงเหลือกำไรหลังจากหักต้นทุน | I2: ค่าแรงพนักงานบู๊ช | J2: ค่าคอมพนักงานบู๊ซ | K2: ค่าคอม (พิเศษ)พนักงานบู๊ซ | L2: ค่าพนักงานรายเดือนที่เกี่ยวข้อง | M2: ค่าเช่า | N2: ค่าภาษีโรงเรือน | O2: ค่าน้ำ | P2: ค่าไฟ | Q2: ค่าธรรมเนียมโอนเงิน | R2: ค่าเน็ต | S2: ค่าโทรศัพท์ | T2: ค่าส่วนกลาง | U2: ค่าน้ำแข็ง | V2: ค่าขนมนอก | W2: ค่าป้าย | X2: ค่าขนส่งพนักงานรายเดือน | Y2: ค่าใช้จ่ายอื่น ๆ | Z2: คงเหลือกำไรหลังจากหักต้นทุน และ ค่าใช้จ่าย
A3: 1 | B3: 10203 | C3: ลำพยา 3 (ใหม่) | D3: 85432 | E3: 7845 | F3: =+D3-E3 -> 77587 | G3: =+D3*0.5 -> 42716 | H3: =+F3-G3 -> 34871 | I3: =+[1]รายชื่อพนักงานรายเดือน!G10 -> 17553.886 | J3: 0 | K3: 100 | L3: =+[1]รายชื่อพนักงานรายเดือน!C9 -> 3580.5558 | M3: =14884+14884 -> 29768 | N3: 0 | O3: 0 | P3: 5442 | Q3: 315 | R3: 0 | S3: 206.96 | T3: 0 | U3: 0 | V3: 0 | X3: =+[1]รายชื่อพนักงานรายเดือน!K8 -> 230.76923 | Y3: 39 | Z3: =+H3-I3-J3-L3-M3-O3-P3-S3-T3-U3-V3-W3-X3-Y3-Q3-R3-K3-N3 -> -22365.171
A4: 2 | B4: 10204 | C4: ร้านใหม่ (ปตท.คุณาวรรณ) | D4: 85089 | E4: 12239 | F4: =+D4-E4 -> 72850 | G4: =+D4*0.5 -> 42544.5 | H4: =+F4-G4 -> 30305.5 | I4: =+[1]รายชื่อพนักงานรายเดือน!G10 -> 17553.886 | J4: 0 | K4: 0 | L4: =+[1]รายชื่อพนักงานรายเดือน!C9 -> 3580.5558 | M4: 5820 | N4: 0 | O4: 38 | P4: 4011.95 | Q4: 15 | R4: 0 | S4: 206.96 | T4: 0 | U4: 0 | V4: 0 | X4: =+[1]รายชื่อพนักงานรายเดือน!K8 -> 230.76923 | Z4: =+H4-I4-J4-L4-M4-O4-P4-S4-T4-U4-V4-W4-X4-Y4-Q4-R4-K4-N4 -> -1151.6209
A5: 3 | B5: 10205 | C5: หน้ามอ (ม.เกษตร) | D5: 92555 | E5: 10547 | F5: =+D5-E5 -> 82008 | G5: =+D5*0.5 -> 46277.5 | H5: =+F5-G5 -> 35730.5 | I5: =+[1]รายชื่อพนักงานรายเดือน!G10 -> 17553.886 | J5: 0 | K5: 0 | L5: =+[1]รายชื่อพนักงานรายเดือน!C9 -> 3580.5558 | M5: 0 | N5: 0 | O5: 40 | P5: 14009.12 | Q5: 0 | R5: 0 | S5: 206.96 | T5: 0 | U5: 100 | V5: 405 | X5: =+[1]รายชื่อพนักงานรายเดือน!K8 -> 230.76923 | Y5: 15 | Z5: =+H5-I5-J5-L5-M5-O5-P5-S5-T5-U5-V5-W5-X5-Y5-Q5-R5-K5-N5 -> -410.7909
A6: 4 | B6: 10207 | C6: ลำพยา 3 (เก่า) | D6: 106235 | E6: 1250 | F6: =+D6-E6 -> 104985 | G6: =+D6*0.5 -> 53117.5 | H6: =+F6-G6 -> 51867.5 | I6: =+[1]รายชื่อพนักงานรายเดือน!G10 -> 17553.886 | J6: 199.4 | K6: 100 | L6: =+[1]รายชื่อพนักงานรายเดือน!C9 -> 3580.5558 | M6: 9000 | N6: 0 | O6: 0 | P6: 3195 | Q6: 405 | R6: 0 | S6: 206.96 | T6: 0 | U6: 0 | V6: 0 | X6: =+[1]รายชื่อพนักงานรายเดือน!K8 -> 230.76923 | Y6: 0 | Z6: =+H6-I6-J6-L6-M6-O6-P6-S6-T6-U6-V6-W6-X6-Y6-Q6-R6-K6-N6 -> 17395.929
A7: 5 | B7: 10208 | C7: ไทวัสดุ | D7: 48945 | E7: 1335 | F7: =+D7-E7 -> 47610 | G7: =+D7*0.5 -> 24472.5 | H7: =+F7-G7 -> 23137.5 | I7: =+[1]รายชื่อพนักงานรายเดือน!G10 -> 17553.886 | J7: 0 | K7: 0 | L7: =+[1]รายชื่อพนักงานรายเดือน!C9 -> 3580.5558 | M7: 6741 | N7: 441 | O7: 0 | P7: 1361 | Q7: 0 | R7: 0 | S7: 206.96 | T7: 242.4 | U7: 0 | V7: 0 | X7: =+[1]รายชื่อพนักงานรายเดือน!K8 -> 230.76923 | Y7: 0 | Z7: =+H7-I7-J7-L7-M7-O7-P7-S7-T7-U7-V7-W7-X7-Y7-Q7-R7-K7-N7 -> -7220.0709
A8: 6 | B8: 10209 | C8: แก้วมณีกาญ | D8: 121395 | E8: 22644 | F8: =+D8-E8 -> 98751 | G8: =+D8*0.5 -> 60697.5 | H8: =+F8-G8 -> 38053.5 | I8: =+[1]รายชื่อพนักงานรายเดือน!G10 -> 17553.886 | J8: 0 | K8: 200 | L8: =+[1]รายชื่อพนักงานรายเดือน!C9 -> 3580.5558 | M8: 16000 | N8: 0 | O8: 0 | P8: 3982 | Q8: 0 | R8: 0 | S8: 206.96 | T8: 0 | U8: 0 | V8: 0 | X8: =+[1]รายชื่อพนักงานรายเดือน!K8 -> 230.76923 | Y8: 89 | Z8: =+H8-I8-J8-L8-M8-O8-P8-S8-T8-U8-V8-W8-X8-Y8-Q8-R8-K8-N8 -> -3789.6709
A9: 7 | B9: 10210 | C9: ลำพยา 2 (ใหม่) | D9: 128085 | E9: 3885 | F9: =+D9-E9 -> 124200 | G9: =+D9*0.5 -> 64042.5 | H9: =+F9-G9 -> 60157.5 | I9: =+[1]รายชื่อพนักงานรายเดือน!G10 -> 17553.886 | J9: 968 | K9: 200 | L9: =+[1]รายชื่อพนักงานรายเดือน!C9 -> 3580.5558 | M9: =14884+14884 -> 29768 | N9: 0 | O9: 0 | P9: 5730 | Q9: 435 | R9: 0 | S9: 206.96 | T9: 0 | U9: 0 | V9: 0 | X9: =+[1]รายชื่อพนักงานรายเดือน!K8 -> 230.76923 | Y9: 0 | Z9: =+H9-I9-J9-L9-M9-O9-P9-S9-T9-U9-V9-W9-X9-Y9-Q9-R9-K9-N9 -> 1484.3291
A10: 8 | B10: 10219 | C10: ธรรมศาลา | D10: 88441 | E10: 10501 | F10: =+D10-E10 -> 77940 | G10: =+D10*0.5 -> 44220.5 | H10: =+F10-G10 -> 33719.5 | I10: =+[1]รายชื่อพนักงานรายเดือน!G10 -> 17553.886 | J10: 0 | K10: 0 | L10: =+[1]รายชื่อพนักงานรายเดือน!C9 -> 3580.5558 | M10: 16500 | N10: 0 | O10: 0 | P10: 3663 | Q10: 450 | R10: 0 | S10: 0 | T10: 467.29 | U10: 0 | V10: 0 | X10: =+[1]รายชื่อพนักงานรายเดือน!K8 -> 230.76923 | Y10: 83 | Z10: =+H10-I10-J10-L10-M10-O10-P10-S10-T10-U10-V10-W10-X10-Y10-Q10-R10-K10-N10 -> -8809.0009
A11: 9 | B11: 10235 | C11: ตลาดดิโอโซน | D11: 69085 | E11: 8210 | F11: =+D11-E11 -> 60875 | G11: =+D11*0.5 -> 34542.5 | H11: =+F11-G11 -> 26332.5 | I11: =+[1]รายชื่อพนักงานรายเดือน!G10 -> 17553.886 | J11: 0 | K11: 0 | L11: =+[1]รายชื่อพนักงานรายเดือน!C9 -> 3580.5558 | M11: 12000 | N11: 0 | O11: 15 | P11: 5370 | Q11: 0 | R11: 0 | S11: 212.72 | T11: 0 | U11: 0 | V11: 0 | X11: =+[1]รายชื่อพนักงานรายเดือน!K8 -> 230.76923 | Y11: 0 | Z11: =+H11-I11-J11-L11-M11-O11-P11-S11-T11-U11-V11-W11-X11-Y11-Q11-R11-K11-N11 -> -12630.431
A12: 10 | B12: 10264 | C12: ปตท.ราชบุรี | D12: 92460 | E12: 7545 | F12: =+D12-E12 -> 84915 | G12: =+D12*0.5 -> 46230 | H12: =+F12-G12 -> 38685 | I12: =+[1]รายชื่อพนักงานรายเดือน!G10 -> 17553.886 | J12: 0 | K12: 0 | L12: =+[1]รายชื่อพนักงานรายเดือน!C9 -> 3580.5558 | M12: 22050 | N12: 0 | O12: 0 | P12: 4974 | Q12: 420 | R12: 0 | S12: 0 | T12: 0 | U12: 0 | V12: 0 | X12: =+[1]รายชื่อพนักงานรายเดือน!K8 -> 230.76923 | Y12: 59 | Z12: =+H12-I12-J12-L12-M12-O12-P12-S12-T12-U12-V12-W12-X12-Y12-Q12-R12-K12-N12 -> -10183.211
A13: 11 | B13: 10377 | C13: ปิ่นเกล้า -ศาลายา | D13: 67365 | E13: 8125 | F13: =+D13-E13 -> 59240 | G13: =+D13*0.5 -> 33682.5 | H13: =+F13-G13 -> 25557.5 | I13: =+[1]รายชื่อพนักงานรายเดือน!G10 -> 17553.886 | J13: 0 | K13: 0 | L13: =+[1]รายชื่อพนักงานรายเดือน!C9 -> 3580.5558 | M13: 20250 | N13: 0 | O13: 0 | Q13: 0 | R13: 0 | S13: 0 | T13: 0 | U13: 0 | V13: 0 | X13: =+[1]รายชื่อพนักงานรายเดือน!K8 -> 230.76923 | Y13: 0 | Z13: =+H13-I13-J13-L13-M13-O13-P13-S13-T13-U13-V13-W13-X13-Y13-Q13-R13-K13-N13 -> -16057.711
A14: 12 | B14: 10371 | C14: ชัยพฤกษ์ - นนทบุรี | D14: 32595 | E14: 5100 | F14: =+D14-E14 -> 27495 | G14: =+D14*0.5 -> 16297.5 | H14: =+F14-G14 -> 11197.5 | I14: =+[1]รายชื่อพนักงานรายเดือน!G10 -> 17553.886 | J14: 0 | K14: 0 | L14: =+[1]รายชื่อพนักงานรายเดือน!C9 -> 3580.5558 | M14: 12000 | N14: 0 | O14: 0 | P14: 4614 | Q14: 0 | R14: 1070 | S14: 0 | T14: 0 | U14: 0 | V14: 0 | X14: =+[1]รายชื่อพนักงานรายเดือน!K8 -> 230.76923 | Y14: 53 | Z14: =+H14-I14-J14-L14-M14-O14-P14-S14-T14-U14-V14-W14-X14-Y14-Q14-R14-K14-N14 -> -27904.711
C15: รวม | D15: =SUM(D3:D14) -> 1017682 | E15: =SUM(E3:E14) -> 99226 | F15: =SUM(F3:F14) -> 918456 | G15: =SUM(G3:G14) -> 508841 | H15: =SUM(H3:H14) -> 409615 | I15: =SUM(I3:I14) -> 210646.63 | J15: =SUM(J3:J14) -> 1167.4 | K15: =SUM(K3:K14) -> 600 | ... Z15: =SUM(Z3:Z14) -> -91642.131 | AA15: บาท
C16: กำไร | D16: =+Z15 -> -91642.131
C17: คิดเป็น % | D17: =+D16/D15 -> -0.090049869

Sheet พ.ค. 68
A1: ข้อมูลเทียบกำไร - ขาดทุน ของบู๊ซ เดือน พฤษาคม 2568
A2: ลำดับ | B2: รหัส | C2: บูธ | D2: ยอดขาย | E2: ส่วนลด | F2: คงเหลือยอดขาย | G2: ค่าต้นทุนขนม | H2: คงเหลือกำไรหลังจากหักต้นทุน | I2: ค่าแรงพนักงานบู๊ช | J2: ค่าคอมพนักงานบู๊ซ | K2: ค่าคอม (พิเศษ)พนักงานบู๊ซ | L2: ค่าพนักงานรายเดือนที่เกี่ยวข้อง | M2: ค่าเช่า | N2: ค่าภาษีโรงเรือน | O2: ค่าน้ำ | P2: ค่าไฟ | Q2: ค่าธรรมเนียมโอนเงิน | R2: ค่าเน็ต | S2: ค่าโทรศัพท์ | T2: ค่าส่วนกลาง | U2: ค่าน้ำแข็ง | V2: ค่าขนมนอก | W2: ค่าป้าย | X2: ค่าขนส่งพนักงานรายเดือน | Y2: ค่าใช้จ่ายอื่น ๆ | Z2: คงเหลือกำไรหลังจากหักต้นทุน และ ค่าใช้จ่าย
A3: 1 | B3: 10203 | C3: ลำพยา 3 (ใหม่) | D3: 97740 | E3: 7050 | F3: =+D3-E3 -> 90690 | G3: =+D3*0.5 -> 48870 | H3: =+F3-G3 -> 41820 | I3: =+[1]รายชื่อพนักงานรายเดือน!G10 -> 17553.886 | J3: 0 | L3: =+[1]รายชื่อพนักงานรายเดือน!C9 -> 3580.5558 | M3: =14884+14884 -> 29768 | N3: 0 | O3: 0 | P3: 5243 | Q3: 270 | R3: 0 | S3: 206.96 | T3: 0 | U3: 0 | V3: 0 | X3: =+[1]รายชื่อพนักงานรายเดือน!K8 -> 230.76923 | Y3: 79 | Z3: =+H3-I3-J3-L3-M3-O3-P3-S3-T3-U3-V3-W3-X3-Y3-Q3-R3-K3-N3 -> -15112.171
A4: 2 | B4: 10204 | C4: ร้านใหม่ (ปตท.คุณาวรรณ) | D4: 78800 | E4: 14251 | F4: =+D4-E4 -> 64549 | G4: =+D4*0.5 -> 39400 | H4: =+F4-G4 -> 25149 | I4: =+[1]รายชื่อพนักงานรายเดือน!G10 -> 17553.886 | J4: 0 | K4: 0 | L4: =+[1]รายชื่อพนักงานรายเดือน!C9 -> 3580.5558 | M4: 5820 | N4: 0 | O4: 35 | P4: 4074.41 | R4: 0 | S4: 206.96 | T4: 0 | U4: 0 | V4: 0 | X4: =+[1]รายชื่อพนักงานรายเดือน!K8 -> 230.76923 | Y4: 46 | Z4: =+H4-I4-J4-L4-M4-O4-P4-S4-T4-U4-V4-W4-X4-Y4-Q4-R4-K4-N4 -> -6398.5809
A5: 3 | B5: 10205 | C5: หน้ามอ (ม.เกษตร) | D5: 82134 | E5: 15966 | F5: =+D5-E5 -> 66168 | G5: =+D5*0.5 -> 41067 | H5: =+F5-G5 -> 25101 | I5: =+[1]รายชื่อพนักงานรายเดือน!G10 -> 17553.886 | J5: 0 | K5: 0 | L5: =+[1]รายชื่อพนักงานรายเดือน!C9 -> 3580.5558 | M5: 0 | N5: 0 | O5: 40 | P5: 12491 | Q5: 0 | R5: 0 | S5: 206.96 | T5: 0 | U5: 79 | V5: 310 | X5: =+[1]รายชื่อพนักงานรายเดือน!K8 -> 230.76923 | Y5: 321 | Z5: =+H5-I5-J5-L5-M5-O5-P5-S5-T5-U5-V5-W5-X5-Y5-Q5-R5-K5-N5 -> -9712.1709
A6: 4 | B6: 10207 | C6: ลำพยา 3 (เก่า) | D6: 105714 | E6: 1454 | F6: =+D6-E6 -> 104260 | G6: =+D6*0.5 -> 52857 | H6: =+F6-G6 -> 51403 | I6: =+[1]รายชื่อพนักงานรายเดือน!G10 -> 17553.886 | J6: 170.4 | L6: =+[1]รายชื่อพนักงานรายเดือน!C9 -> 3580.5558 | M6: 9000 | N6: 0 | O6: 0 | P6: 2850 | R6: 0 | S6: 206.96 | T6: 0 | U6: 0 | V6: 0 | X6: =+[1]รายชื่อพนักงานรายเดือน!K8 -> 230.76923 | Y6: 0 | Z6: =+H6-I6-J6-L6-M6-O6-P6-S6-T6-U6-V6-W6-X6-Y6-Q6-R6-K6-N6 -> 17810.429
A7: 5 | B7: 10208 | C7: ไทวัสดุ | D7: 62176 | E7: 8931 | F7: =+D7-E7 -> 53245 | G7: =+D7*0.5 -> 31088 | H7: =+F7-G7 -> 22157 | I7: =+[1]รายชื่อพนักงานรายเดือน!G10 -> 17553.886 | J7: 0 | K7: 0 | L7: =+[1]รายชื่อพนักงานรายเดือน!C9 -> 3580.5558 | M7: 6741 | O7: 0 | P7: 1332.02 | Q7: 0 | R7: 0 | S7: 206.96 | T7: 242.4 | U7: 0 | V7: 0 | X7: =+[1]รายชื่อพนักงานรายเดือน!K8 -> 230.76923 | Y7: 330 | Z7: =+H7-I7-J7-L7-M7-O7-P7-S7-T7-U7-V7-W7-X7-Y7-Q7-R7-K7-N7 -> -8060.5909
A8: 6 | B8: 10209 | C8: แก้วมณีกาญ | D8: 117315 | E8: 18697 | F8: =+D8-E8 -> 98618 | G8: =+D8*0.5 -> 58657.5 | H8: =+F8-G8 -> 39960.5 | I8: =+[1]รายชื่อพนักงานรายเดือน!G10 -> 17553.886 | J8: 0 | K8: 100 | L8: =+[1]รายชื่อพนักงานรายเดือน!C9 -> 3580.5558 | M8: 16000 | N8: 0 | O8: 0 | P8: 3901.26 | Q8: 0 | R8: 0 | S8: 206.96 | T8: 0 | U8: 0 | V8: 0 | X8: =+[1]รายชื่อพนักงานรายเดือน!K8 -> 230.76923 | Y8: 65 | Z8: =+H8-I8-J8-L8-M8-O8-P8-S8-T8-U8-V8-W8-X8-Y8-Q8-R8-K8-N8 -> -1677.9309
A9: 7 | B9: 10210 | C9: ลำพยา 2 (ใหม่) | D9: 102104 | E9: 2949 | F9: =+D9-E9 -> 99155 | G9: =+D9*0.5 -> 51052 | H9: =+F9-G9 -> 48103 | I9: =+[1]รายชื่อพนักงานรายเดือน!G10 -> 17553.886 | L9: =+[1]รายชื่อพนักงานรายเดือน!C9 -> 3580.5558 | M9: =14884+14884 -> 29768 | N9: 0 | O9: 0 | P9: 5670 | Q9: 465 | R9: 0 | S9: 206.96 | T9: 0 | U9: 0 | V9: 0 | X9: =+[1]รายชื่อพนักงานรายเดือน!K8 -> 230.76923 | Y9: 0 | Z9: =+H9-I9-J9-L9-M9-O9-P9-S9-T9-U9-V9-W9-X9-Y9-Q9-R9-K9-N9 -> -9372.1709
A10: 8 | B10: 10219 | C10: ธรรมศาลา | D10: 83276 | E10: 7387 | F10: =+D10-E10 -> 75889 | G10: =+D10*0.5 -> 41638 | H10: =+F10-G10 -> 34251 | I10: =+[1]รายชื่อพนักงานรายเดือน!G10 -> 17553.886 | J10: 0 | K10: 0 | L10: =+[1]รายชื่อพนักงานรายเดือน!C9 -> 3580.5558 | M10: 16500 | N10: 0 | O10: 0 | P10: 3645 | Q10: 420 | R10: 0 | S10: 0 | T10: 467.29 | U10: 0 | V10: 0 | X10: =+[1]รายชื่อพนักงานรายเดือน!K8 -> 230.76923 | Y10: 561 | Z10: =+H10-I10-J10-L10-M10-O10-P10-S10-T10-U10-V10-W10-X10-Y10-Q10-R10-K10-N10 -> -8707.5009
A11: 9 | B11: 10235 | C11: ตลาดดิโอโซน | D11: 75229 | E11: 10661 | F11: =+D11-E11 -> 64568 | G11: =+D11*0.5 -> 37614.5 | H11: =+F11-G11 -> 26953.5 | I11: =+[1]รายชื่อพนักงานรายเดือน!G10 -> 17553.886 | J11: 0 | K11: 0 | L11: =+[1]รายชื่อพนักงานรายเดือน!C9 -> 3580.5558 | M11: 12000 | N11: 0 | P11: 5814 | Q11: 0 | R11: 0 | S11: 212.72 | T11: 0 | U11: 0 | V11: 0 | X11: =+[1]รายชื่อพนักงานรายเดือน!K8 -> 230.76923 | Y11: 0 | Z11: =+H11-I11-J11-L11-M11-O11-P11-S11-T11-U11-V11-W11-X11-Y11-Q11-R11-K11-N11 -> -12438.431
A12: 10 | B12: 10264 | C12: ปตท.ราชบุรี | D12: 99440 | E12: 6960 | F12: =+D12-E12 -> 92480 | G12: =+D12*0.5 -> 49720 | H12: =+F12-G12 -> 42760 | I12: =+[1]รายชื่อพนักงานรายเดือน!G10 -> 17553.886 | J12: 0 | K12: 0 | L12: =+[1]รายชื่อพนักงานรายเดือน!C9 -> 3580.5558 | M12: 22050 | N12: 0 | O12: 0 | P12: 4886 | Q12: 345 | R12: 0 | S12: 0 | T12: 0 | U12: 0 | V12: 0 | X12: =+[1]รายชื่อพนักงานรายเดือน!K8 -> 230.76923 | Z12: =+H12-I12-J12-L12-M12-O12-P12-S12-T12-U12-V12-W12-X12-Y12-Q12-R12-K12-N12 -> -5886.2109
A13: 11 | B13: 10377 | C13: ปิ่นเกล้า -ศาลายา | D13: 55265 | E13: 9442 | F13: =+D13-E13 -> 45823 | G13: =+D13*0.5 -> 27632.5 | H13: =+F13-G13 -> 18190.5 | I13: =+[1]รายชื่อพนักงานรายเดือน!G10 -> 17553.886 | J13: 0 | K13: 0 | L13: =+[1]รายชื่อพนักงานรายเดือน!C9 -> 3580.5558 | M13: 20250 | N13: 0 | O13: 0 | Q13: 0 | R13: 0 | S13: 0 | T13: 0 | U13: 0 | V13: 0 | X13: =+[1]รายชื่อพนักงานรายเดือน!K8 -> 230.76923 | Y13: 0 | Z13: =+H13-I13-J13-L13-M13-O13-P13-S13-T13-U13-V13-W13-X13-Y13-Q13-R13-K13-N13 -> -23424.711
A14: 12 | B14: 10371 | C14: ชัยพฤกษ์ - นนทบุรี | D14: 36058 | E14: 5824 | F14: =+D14-E14 -> 30234 | G14: =+D14*0.5 -> 18029 | H14: =+F14-G14 -> 12205 | I14: =+[1]รายชื่อพนักงานรายเดือน!G10 -> 17553.886 | J14: 0 | K14: 0 | L14: =+[1]รายชื่อพนักงานรายเดือน!C9 -> 3580.5558 | M14: 12000 | N14: 0 | O14: 0 | P14: 4618 | Q14: 0 | R14: 1070 | S14: 0 | T14: 0 | U14: 0 | V14: 0 | X14: =+[1]รายชื่อพนักงานรายเดือน!K8 -> 230.76923 | Z14: =+H14-I14-J14-L14-M14-O14-P14-S14-T14-U14-V14-W14-X14-Y14-Q14-R14-K14-N14 -> -26848.211
C15: รวม | D15: =SUM(D3:D14) -> 995251 | E15: =SUM(E3:E14) -> 109572 | F15: =SUM(F3:F14) -> 885679 | G15: =SUM(G3:G14) -> 497625.5 | H15: =SUM(H3:H14) -> 388053.5 | I15: =SUM(I3:I14) -> 210646.63 | J15: =SUM(J3:J14) -> 170.4 | K15: =SUM(K3:K14) -> 100 | ... Z15: =SUM(Z3:Z14) -> -109828.25 | AA15: บาท
C16: กำไร | D16: =+Z15 -> -109828.25
C17: คิดเป็น % | D17: =+D16/D15 -> -0.11035231

Sheet มิ.ย.68
A1: ข้อมูลเทียบกำไร - ขาดทุน ของบู๊ซ เดือน มิถุนายน 2568
A2: ลำดับ | B2: รหัส | C2: บูธ | D2: ยอดขาย | E2: ส่วนลด | F2: คงเหลือยอดขาย | G2: ค่าต้นทุนขนม | H2: คงเหลือกำไรหลังจากหักต้นทุน | I2: ค่าแรงพนักงานบู๊ช | J2: ค่าคอมพนักงานบู๊ซ | K2: ค่าคอม (พิเศษ)พนักงานบู๊ซ | L2: ค่าพนักงานรายเดือนที่เกี่ยวข้อง | M2: ค่าเช่า | N2: ค่าภาษีโรงเรือน | O2: ค่าน้ำ | P2: ค่าไฟ | Q2: ค่าธรรมเนียมโอนเงิน | R2: ค่าเน็ต | S2: ค่าโทรศัพท์ | T2: ค่าส่วนกลาง | U2: ค่าน้ำแข็ง | V2: ค่าขนมนอก | W2: ค่าป้าย | X2: ค่าขนส่งพนักงานรายเดือน | Y2: ค่าใช้จ่ายอื่น ๆ | Z2: คงเหลือกำไรหลังจากหักต้นทุน และ ค่าใช้จ่าย
A3: 1 | B3: 10203 | C3: ลำพยา 3 (ใหม่) | D3: 94145 | E3: 2690 | F3: =+D3-E3 -> 91455 | G3: =+D3*0.5 -> 47072.5 | H3: =+F3-G3 -> 44382.5 | I3: =+[1]รายชื่อพนักงานรายเดือน!G10 -> 17553.886 | J3: 0 | K3: 0 | L3: =+[1]รายชื่อพนักงานรายเดือน!C9 -> 3580.5558 | M3: =14884+14884 -> 29768 | N3: 0 | O3: 0 | P3: 6099 | Q3: 120 | R3: 0 | S3: 206.96 | T3: 0 | U3: 0 | V3: 0 | X3: =+[1]รายชื่อพนักงานรายเดือน!K8 -> 230.76923 | Y3: 25 | Z3: =+H3-I3-J3-L3-M3-O3-P3-S3-T3-U3-V3-W3-X3-Y3-Q3-R3-K3-N3 -> -13201.671
A4: 2 | B4: 10204 | C4: ร้านใหม่ (ปตท.คุณาวรรณ) | D4: 79465 | E4: 15115 | F4: =+D4-E4 -> 64350 | G4: =+D4*0.5 -> 39732.5 | H4: =+F4-G4 -> 24617.5 | I4: =+[1]รายชื่อพนักงานรายเดือน!G10 -> 17553.886 | J4: 0 | K4: 0 | L4: =+[1]รายชื่อพนักงานรายเดือน!C9 -> 3580.5558 | M4: 5820 | N4: 0 | O4: 41 | P4: 4707 | Q4: 75 | R4: 0 | S4: 206.96 | T4: 0 | U4: 0 | V4: 0 | X4: =+[1]รายชื่อพนักงานรายเดือน!K8 -> 230.76923 | Y4: 46 | Z4: =+H4-I4-J4-L4-M4-O4-P4-S4-T4-U4-V4-W4-X4-Y4-Q4-R4-K4-N4 -> -7643.6709
A5: 3 | B5: 10205 | C5: หน้ามอ (ม.เกษตร) | D5: 93345 | E5: 15693 | F5: =+D5-E5 -> 77652 | G5: =+D5*0.5 -> 46672.5 | H5: =+F5-G5 -> 30979.5 | I5: =+[1]รายชื่อพนักงานรายเดือน!G10 -> 17553.886 | J5: 0 | K5: 0 | L5: =+[1]รายชื่อพนักงานรายเดือน!C9 -> 3580.5558 | M5: 0 | N5: 0 | O5: 25 | P5: 12491 | Q5: 0 | R5: 0 | S5: 206.96 | T5: 0 | U5: 50 | V5: 170 | X5: =+[1]รายชื่อพนักงานรายเดือน!K8 -> 230.76923 | Y5: 1343.25 | Z5: =+H5-I5-J5-L5-M5-O5-P5-S5-T5-U5-V5-W5-X5-Y5-Q5-R5-K5-N5 -> -4671.9209
A6: 4 | B6: 10207 | C6: ลำพยา 3 (เก่า) | D6: 80975 | E6: 845 | F6: =+D6-E6 -> 80130 | G6: =+D6*0.5 -> 40487.5 | H6: =+F6-G6 -> 39642.5 | I6: =+[1]รายชื่อพนักงานรายเดือน!G10 -> 17553.886 | J6: 0 | K6: 0 | L6: =+[1]รายชื่อพนักงานรายเดือน!C9 -> 3580.5558 | M6: 9000 | N6: 0 | O6: 0 | P6: 2826 | Q6: 405 | R6: 0 | S6: 206.96 | T6: 0 | U6: 0 | V6: 0 | X6: =+[1]รายชื่อพนักงานรายเดือน!K8 -> 230.76923 | Y6: 1236 | Z6: =+H6-I6-J6-L6-M6-O6-P6-S6-T6-U6-V6-W6-X6-Y6-Q6-R6-K6-N6 -> 4603.3291
A7: 5 | B7: 10208 | C7: ไทวัสดุ | D7: 63340 | E7: 7910 | F7: =+D7-E7 -> 55430 | G7: =+D7*0.5 -> 31670 | H7: =+F7-G7 -> 23760 | I7: =+[1]รายชื่อพนักงานรายเดือน!G10 -> 17553.886 | J7: 0 | K7: 0 | L7: =+[1]รายชื่อพนักงานรายเดือน!C9 -> 3580.5558 | M7: 6741 | O7: 0 | P7: 1463.76 | Q7: 0 | R7: 0 | S7: 206.96 | T7: 259.37 | U7: 0 | V7: 0 | X7: =+[1]รายชื่อพนักงานรายเดือน!K8 -> 230.76923 | Y7: 330 | Z7: =+H7-I7-J7-L7-M7-O7-P7-S7-T7-U7-V7-W7-X7-Y7-Q7-R7-K7-N7 -> -6606.3009
A8: 6 | B8: 10209 | C8: แก้วมณีกาญ | D8: 111105 | E8: 14837 | F8: =+D8-E8 -> 96268 | G8: =+D8*0.5 -> 55552.5 | H8: =+F8-G8 -> 40715.5 | I8: =+[1]รายชื่อพนักงานรายเดือน!G10 -> 17553.886 | J8: 0 | K8: 0 | L8: =+[1]รายชื่อพนักงานรายเดือน!C9 -> 3580.5558 | M8: 16000 | N8: 0 | O8: 0 | P8: 3307.5 | Q8: 0 | R8: 0 | S8: 206.96 | T8: 0 | U8: 0 | V8: 0 | X8: =+[1]รายชื่อพนักงานรายเดือน!K8 -> 230.76923 | Y8: 65 | Z8: =+H8-I8-J8-L8-M8-O8-P8-S8-T8-U8-V8-W8-X8-Y8-Q8-R8-K8-N8 -> -229.1709
A9: 7 | B9: 10210 | C9: ลำพยา 2 (ใหม่) | D9: 89530 | E9: 3730 | F9: =+D9-E9 -> 85800 | G9: =+D9*0.5 -> 44765 | H9: =+F9-G9 -> 41035 | I9: =+[1]รายชื่อพนักงานรายเดือน!G10 -> 17553.886 | K9: 0 | L9: =+[1]รายชื่อพนักงานรายเดือน!C9 -> 3580.5558 | M9: =14884+14884 -> 29768 | N9: 0 | O9: 0 | P9: 5578.98 | Q9: 435 | R9: 0 | S9: 206.96 | T9: 0 | U9: 0 | V9: 0 | X9: =+[1]รายชื่อพนักงานรายเดือน!K8 -> 230.76923 | Y9: 0 | Z9: =+H9-I9-J9-L9-M9-O9-P9-S9-T9-U9-V9-W9-X9-Y9-Q9-R9-K9-N9 -> -16319.151
A10: 8 | B10: 10219 | C10: ธรรมศาลา | D10: 87655 | E10: 5985 | F10: =+D10-E10 -> 81670 | G10: =+D10*0.5 -> 43827.5 | H10: =+F10-G10 -> 37842.5 | I10: =+[1]รายชื่อพนักงานรายเดือน!G10 -> 17553.886 | J10: 0 | K10: 0 | L10: =+[1]รายชื่อพนักงานรายเดือน!C9 -> 3580.5558 | M10: 16500 | N10: 0 | O10: 0 | P10: 3558.5 | Q10: 435 | R10: 0 | S10: 0 | T10: 467.29 | U10: 0 | V10: 0 | X10: =+[1]รายชื่อพนักงานรายเดือน!K8 -> 230.76923 | Y10: 78 | Z10: =+H10-I10-J10-L10-M10-O10-P10-S10-T10-U10-V10-W10-X10-Y10-Q10-R10-K10-N10 -> -4561.5009
A11: 9 | B11: 10235 | C11: ตลาดดิโอโซน | D11: 89170 | E11: 12030 | F11: =+D11-E11 -> 77140 | G11: =+D11*0.5 -> 44585 | H11: =+F11-G11 -> 32555 | I11: =+[1]รายชื่อพนักงานรายเดือน!G10 -> 17553.886 | J11: 0 | K11: 0 | L11: =+[1]รายชื่อพนักงานรายเดือน!C9 -> 3580.5558 | M11: 12000 | N11: 0 | P11: 5856 | Q11: 0 | R11: 0 | S11: 212.72 | T11: 0 | U11: 0 | V11: 0 | X11: =+[1]รายชื่อพนักงานรายเดือน!K8 -> 230.76923 | Y11: 0 | Z11: =+H11-I11-J11-L11-M11-O11-P11-S11-T11-U11-V11-W11-X11-Y11-Q11-R11-K11-N11 -> -6878.9309
A12: 10 | B12: 10264 | C12: ปตท.ราชบุรี | D12: 95940 | E12: 6955 | F12: =+D12-E12 -> 88985 | G12: =+D12*0.5 -> 47970 | H12: =+F12-G12 -> 41015 | I12: =+[1]รายชื่อพนักงานรายเดือน!G10 -> 17553.886 | J12: 0 | K12: 0 | L12: =+[1]รายชื่อพนักงานรายเดือน!C9 -> 3580.5558 | M12: 22050 | N12: 0 | O12: 0 | P12: 4770 | Q12: 375 | R12: 0 | S12: 0 | T12: 0 | U12: 0 | V12: 0 | X12: =+[1]รายชื่อพนักงานรายเดือน!K8 -> 230.76923 | Y12: 25 | Z12: =+H12-I12-J12-L12-M12-O12-P12-S12-T12-U12-V12-W12-X12-Y12-Q12-R12-K12-N12 -> -7570.2109
A13: 11 | B13: 10377 | C13: ปิ่นเกล้า -ศาลายา | D13: 58665 | E13: 7197 | F13: =+D13-E13 -> 51468 | G13: =+D13*0.5 -> 29332.5 | H13: =+F13-G13 -> 22135.5 | I13: =+[1]รายชื่อพนักงานรายเดือน!G10 -> 17553.886 | J13: 0 | K13: 0 | L13: =+[1]รายชื่อพนักงานรายเดือน!C9 -> 3580.5558 | M13: 20250 | N13: 0 | O13: 0 | Q13: 0 | R13: 0 | S13: 0 | T13: 0 | U13: 0 | V13: 0 | X13: =+[1]รายชื่อพนักงานรายเดือน!K8 -> 230.76923 | Y13: 0 | Z13: =+H13-I13-J13-L13-M13-O13-P13-S13-T13-U13-V13-W13-X13-Y13-Q13-R13-K13-N13 -> -19479.711
A14: 12 | B14: 10371 | C14: ชัยพฤกษ์ - นนทบุรี | D14: 35425 | E14: 4982 | F14: =+D14-E14 -> 30443 | G14: =+D14*0.5 -> 17712.5 | H14: =+F14-G14 -> 12730.5 | I14: =+[1]รายชื่อพนักงานรายเดือน!G10 -> 17553.886 | J14: 0 | K14: 0 | L14: =+[1]รายชื่อพนักงานรายเดือน!C9 -> 3580.5558 | M14: 12000 | N14: 0 | O14: 0 | P14: 4618 | Q14: 0 | R14: 1070 | S14: 0 | T14: 0 | U14: 0 | V14: 0 | X14: =+[1]รายชื่อพนักงานรายเดือน!K8 -> 230.76923 | Z14: =+H14-I14-J14-L14-M14-O14-P14-S14-T14-U14-V14-W14-X14-Y14-Q14-R14-K14-N14 -> -26322.711
C15: รวม | D15: =SUM(D3:D14) -> 978760 | E15: =SUM(E3:E14) -> 97969 | F15: =SUM(F3:F14) -> 880791 | G15: =SUM(G3:G14) -> 489380 | H15: =SUM(H3:H14) -> 391411 | I15: =SUM(I3:I14) -> 210646.63 | J15: =SUM(J3:J14) -> 0 | K15: =SUM(K3:K14) -> 0 | ... Z15: =SUM(Z3:Z14) -> -108881.62 | AA15: บาท
C16: กำไร | D16: =+Z15 -> -108881.62
C17: คิดเป็น % | D17: =+D16/D15 -> -0.11124445

Sheet ก.ค. 68
A1: ข้อมูลเทียบกำไร - ขาดทุน ของบู๊ซ เดือน กรกฏาคม 2568
A2: ลำดับ | B2: รหัส | C2: บูธ | D2: ยอดขาย | E2: ส่วนลด | F2: คงเหลือยอดขาย | G2: ค่าต้นทุนขนม | H2: คงเหลือกำไรหลังจากหักต้นทุน | I2: ค่าแรงพนักงานบู๊ช | J2: ค่าคอมพนักงานบู๊ซ | K2: ค่าคอม (พิเศษ)พนักงานบู๊ซ | L2: ค่าพนักงานรายเดือนที่เกี่ยวข้อง | M2: ค่าเช่า | N2: ค่าภาษีโรงเรือน | O2: ค่าน้ำ | P2: ค่าไฟ | Q2: ค่าธรรมเนียมโอนเงิน | R2: ค่าเน็ต | S2: ค่าโทรศัพท์ | T2: ค่าส่วนกลาง | U2: ค่าน้ำแข็ง | V2: ค่าขนมนอก | W2: ค่าป้าย | X2: ค่าขนส่งพนักงานรายเดือน | Y2: ค่าใช้จ่ายอื่น ๆ | Z2: คงเหลือกำไรหลังจากหักต้นทุน และ ค่าใช้จ่าย
A3: 1 | B3: 10203 | C3: ลำพยา 3 (ใหม่) | D3: 112715 | E3: 5093 | F3: =+D3-E3 -> 107622 | G3: =+D3*0.5 -> 56357.5 | H3: =+F3-G3 -> 51264.5 | I3: =+[1]รายชื่อพนักงานรายเดือน!G10 -> 17553.886 | J3: 304.88 | K3: 100 | L3: =+[1]รายชื่อพนักงานรายเดือน!C9 -> 3580.5558 | M3: =14884+14884 -> 29768 | N3: 0 | O3: 0 | P3: 6381.48 | Q3: 450 | R3: 0 | S3: 206.96 | T3: 0 | U3: 0 | V3: 0 | W3: 0 | X3: =+[1]รายชื่อพนักงานรายเดือน!K8 -> 230.76923 | Y3: 65 | Z3: =+H3-I3-J3-L3-M3-O3-P3-S3-T3-U3-V3-W3-X3-Y3-Q3-R3-K3-N3 -> -7377.0309
A4: 2 | B4: 10204 | C4: ร้านใหม่ (ปตท.คุณาวรรณ) | D4: 109775 | E4: 31607 | F4: =+D4-E4 -> 78168 | G4: =+D4*0.5 -> 54887.5 | H4: =+F4-G4 -> 23280.5 | I4: =+[1]รายชื่อพนักงานรายเดือน!G10 -> 17553.886 | J4: 0 | K4: 0 | L4: =+[1]รายชื่อพนักงานรายเดือน!C9 -> 3580.5558 | M4: 5820 | N4: 0 | O4: 48 | P4: 5052.97 | Q4: 45 | R4: 0 | S4: 206.96 | T4: 0 | U4: 100 | V4: 630 | W4: 0 | X4: =+[1]รายชื่อพนักงานรายเดือน!K8 -> 230.76923 | Y4: 10 | Z4: =+H4-I4-J4-L4-M4-O4-P4-S4-T4-U4-V4-W4-X4-Y4-Q4-R4-K4-N4 -> -9997.6409
A5: 3 | B5: 10205 | C5: หน้ามอ (ม.เกษตร) | D5: 101790 | E5: 21232 | F5: =+D5-E5 -> 80558 | G5: =+D5*0.5 -> 50895 | H5: =+F5-G5 -> 29663 | I5: =+[1]รายชื่อพนักงานรายเดือน!G10 -> 17553.886 | J5: 0 | K5: 0 | L5: =+[1]รายชื่อพนักงานรายเดือน!C9 -> 3580.5558 | M5: 0 | N5: 0 | O5: 40 | P5: 12639.28 | Q5: 0 | R5: 0 | S5: 206.96 | T5: 0 | W5: 0 | X5: =+[1]รายชื่อพนักงานรายเดือน!K8 -> 230.76923 | Z5: =+H5-I5-J5-L5-M5-O5-P5-S5-T5-U5-V5-W5-X5-Y5-Q5-R5-K5-N5 -> -4588.4509
A6: 4 | B6: 10207 | C6: ลำพยา 3 (เก่า) | D6: 106341 | E6: 3225 | F6: =+D6-E6 -> 103116 | G6: =+D6*0.5 -> 53170.5 | H6: =+F6-G6 -> 49945.5 | I6: =+[1]รายชื่อพนักงานรายเดือน!G10 -> 17553.886 | J6: 124.64 | K6: 0 | L6: =+[1]รายชื่อพนักงานรายเดือน!C9 -> 3580.5558 | M6: 9000 | N6: 0 | O6: 0 | P6: 2560 | Q6: 465 | R6: 0 | S6: 206.96 | T6: 0 | U6: 0 | V6: 0 | W6: 0 | X6: =+[1]รายชื่อพนักงานรายเดือน!K8 -> 230.76923 | Y6: 94 | Z6: =+H6-I6-J6-L6-M6-O6-P6-S6-T6-U6-V6-W6-X6-Y6-Q6-R6-K6-N6 -> 16129.689
A7: 5 | B7: 10208 | C7: ไทวัสดุ | D7: 77604 | E7: 18192 | F7: =+D7-E7 -> 59412 | G7: =+D7*0.5 -> 38802 | H7: =+F7-G7 -> 20610 | I7: =+[1]รายชื่อพนักงานรายเดือน!G10 -> 17553.886 | J7: 0 | K7: 0 | L7: =+[1]รายชื่อพนักงานรายเดือน!C9 -> 3580.5558 | M7: 6741 | N7: 0 | O7: 0 | P7: 1288.11 | Q7: 0 | R7: 0 | S7: 206.96 | T7: 259.37 | U7: 0 | V7: 0 | W7: 0 | X7: =+[1]รายชื่อพนักงานรายเดือน!K8 -> 230.76923 | Z7: =+H7-I7-J7-L7-M7-O7-P7-S7-T7-U7-V7-W7-X7-Y7-Q7-R7-K7-N7 -> -9250.6509
A8: 6 | B8: 10209 | C8: แก้วมณีกาญ | D8: 154824 | E8: 36143 | F8: =+D8-E8 -> 118681 | G8: =+D8*0.5 -> 77412 | H8: =+F8-G8 -> 41269 | I8: =+[1]รายชื่อพนักงานรายเดือน!G10 -> 17553.886 | J8: 747.24 | K8: 200 | L8: =+[1]รายชื่อพนักงานรายเดือน!C9 -> 3580.5558 | M8: 16000 | N8: 0 | O8: 0 | P8: 2979 | Q8: 0 | R8: 0 | S8: 206.96 | T8: 0 | U8: 0 | V8: 0 | W8: 0 | X8: =+[1]รายชื่อพนักงานรายเดือน!K8 -> 230.76923 | Y8: 239 | Z8: =+H8-I8-J8-L8-M8-O8-P8-S8-T8-U8-V8-W8-X8-Y8-Q8-R8-K8-N8 -> -468.4109
A9: 7 | B9: 10210 | C9: ลำพยา 2 (ใหม่) | D9: 107861 | E9: 7683 | F9: =+D9-E9 -> 100178 | G9: =+D9*0.5 -> 53930.5 | H9: =+F9-G9 -> 46247.5 | I9: =+[1]รายชื่อพนักงานรายเดือน!G10 -> 17553.886 | J9: 7.12 | K9: 100 | L9: =+[1]รายชื่อพนักงานรายเดือน!C9 -> 3580.5558 | M9: =14884+14884 -> 29768 | N9: 0 | O9: 0 | P9: 5560 | Q9: 465 | R9: 0 | S9: 206.96 | T9: 0 | U9: 0 | V9: 0 | W9: 0 | X9: =+[1]รายชื่อพนักงานรายเดือน!K8 -> 230.76923 | Y9: 10 | Z9: =+H9-I9-J9-L9-M9-O9-P9-S9-T9-U9-V9-W9-X9-Y9-Q9-R9-K9-N9 -> -11234.791
A10: 8 | B10: 10219 | C10: ธรรมศาลา | D10: 95690 | E10: 10335 | F10: =+D10-E10 -> 85355 | G10: =+D10*0.5 -> 47845 | H10: =+F10-G10 -> 37510 | I10: =+[1]รายชื่อพนักงานรายเดือน!G10 -> 17553.886 | J10: 0 | K10: 0 | L10: =+[1]รายชื่อพนักงานรายเดือน!C9 -> 3580.5558 | M10: 16500 | N10: 0 | O10: 0 | P10: 3833.5 | Q10: 465 | R10: 0 | S10: 0 | T10: 467.29 | U10: 0 | V10: 0 | W10: 0 | X10: =+[1]รายชื่อพนักงานรายเดือน!K8 -> 230.76923 | Z10: =+H10-I10-J10-L10-M10-O10-P10-S10-T10-U10-V10-W10-X10-Y10-Q10-R10-K10-N10 -> -5121.0009
A11: 9 | B11: 10235 | C11: ตลาดดิโอโซน | D11: 94145 | E11: 19525 | F11: =+D11-E11 -> 74620 | G11: =+D11*0.5 -> 47072.5 | H11: =+F11-G11 -> 27547.5 | I11: =+[1]รายชื่อพนักงานรายเดือน!G10 -> 17553.886 | J11: 0 | K11: 0 | L11: =+[1]รายชื่อพนักงานรายเดือน!C9 -> 3580.5558 | M11: 12000 | N11: 0 | O11: 15 | P11: 5838 | Q11: 0 | R11: 0 | S11: 212.72 | T11: 0 | U11: 0 | V11: 0 | W11: 0 | X11: =+[1]รายชื่อพนักงานรายเดือน!K8 -> 230.76923 | Y11: 0 | Z11: =+H11-I11-J11-L11-M11-O11-P11-S11-T11-U11-V11-W11-X11-Y11-Q11-R11-K11-N11 -> -11883.431
A12: 10 | B12: 10264 | C12: ปตท.ราชบุรี | D12: 84433 | E12: 10592 | F12: =+D12-E12 -> 73841 | G12: =+D12*0.5 -> 42216.5 | H12: =+F12-G12 -> 31624.5 | I12: =+[1]รายชื่อพนักงานรายเดือน!G10 -> 17553.886 | J12: 0 | K12: 0 | L12: =+[1]รายชื่อพนักงานรายเดือน!C9 -> 3580.5558 | M12: 22050 | N12: 0 | O12: 0 | P12: 5257 | Q12: 330 | R12: 0 | S12: 0 | T12: 0 | U12: 0 | V12: 0 | W12: 0 | X12: =+[1]รายชื่อพนักงานรายเดือน!K8 -> 230.76923 | Z12: =+H12-I12-J12-L12-M12-O12-P12-S12-T12-U12-V12-W12-X12-Y12-Q12-R12-K12-N12 -> -17377.711
A13: 11 | B13: 10377 | C13: ปิ่นเกล้า -ศาลายา | D13: 76285 | E13: 12066 | F13: =+D13-E13 -> 64219 | G13: =+D13*0.5 -> 38142.5 | H13: =+F13-G13 -> 26076.5 | I13: =+[1]รายชื่อพนักงานรายเดือน!G10 -> 17553.886 | J13: 0 | K13: 0 | L13: =+[1]รายชื่อพนักงานรายเดือน!C9 -> 3580.5558 | M13: 20250 | N13: 0 | O13: 0 | P13: 5758.74 | Q13: 0 | R13: 0 | S13: 0 | T13: 0 | U13: 0 | V13: 0 | W13: 0 | X13: =+[1]รายชื่อพนักงานรายเดือน!K8 -> 230.76923 | Y13: 0 | Z13: =+H13-I13-J13-L13-M13-O13-P13-S13-T13-U13-V13-W13-X13-Y13-Q13-R13-K13-N13 -> -21297.451
C14: รวม | D14: =SUM(D3:D13) -> 1121463 | E14: =SUM(E3:E13) -> 175693 | F14: =SUM(F3:F13) -> 945770 | G14: =SUM(G3:G13) -> 560731.5 | H14: =SUM(H3:H13) -> 385038.5 | I14: =SUM(I3:I13) -> 193092.74 | J14: =SUM(J3:J13) -> 1183.88 | K14: =SUM(K3:K13) -> 400 | ... Z14: =SUM(Z3:Z13) -> -82466.88 | AA14: บาท
C15: กำไร | D15: =+Z14 -> -82466.88
C16: คิดเป็น % | D16: =+D15/D14 -> -0.073535088

Sheet ส.ค. 68
A1: ข้อมูลเทียบกำไร - ขาดทุน ของบู๊ซ เดือน สิงหาคม 2568
A2: ลำดับ | B2: รหัส | C2: บูธ | D2: ยอดขาย | E2: ส่วนลด | F2: คงเหลือยอดขาย | G2: ค่าต้นทุนขนม | H2: คงเหลือกำไรหลังจากหักต้นทุน | I2: ค่าแรงพนักงานบู๊ช | J2: ค่าคอมพนักงานบู๊ซ | K2: ค่าคอม (พิเศษ)พนักงานบู๊ซ | L2: ค่าพนักงานรายเดือนที่เกี่ยวข้อง | M2: ค่าเช่า | N2: ค่าภาษีโรงเรือน | O2: ค่าน้ำประปา | P2: ค่าไฟ | Q2: ค่าธรรมเนียมโอนเงิน | R2: ค่าเน็ต | S2: ค่าโทรศัพท์ | T2: ค่าส่วนกลาง | U2: ค่าน้ำแข็ง | V2: ค่าขนมนอก | W2: ค่าป้าย | X2: ค่าขนส่งพนักงานรายเดือน | Y2: ค่าใช้จ่ายอื่น ๆ | Z2: คงเหลือกำไรหลังจากหักต้นทุน และ ค่าใช้จ่าย
A3: 1 | B3: 10203 | C3: ลำพยา 3 (ใหม่) | D3: 98384 | E3: 6485 | F3: =+D3-E3 -> 91899 | G3: =+D3*0.5 -> 49192 | H3: =+F3-G3 -> 42707 | I3: =+[1]รายชื่อพนักงานรายเดือน!G10 -> 17553.886 | J3: 0 | K3: 100 | L3: =+[1]รายชื่อพนักงานรายเดือน!C9 -> 3580.5558 | M3: =14884+14884 -> 29768 | N3: 0 | O3: 0 | P3: 5964 | Q3: 465 | R3: 0 | S3: 206.96 | T3: 0 | U3: 0 | V3: 0 | W3: 0 | X3: =+[1]รายชื่อพนักงานรายเดือน!K8 -> 230.76923 | Y3: 65 | Z3: =+H3-I3-J3-L3-M3-O3-P3-S3-T3-U3-V3-W3-X3-Y3-Q3-R3-K3-N3 -> -15227.171
A4: 2 | B4: 10204 | C4: ร้านใหม่ (ปตท.คุณาวรรณ) | D4: 103566 | E4: 20351 | F4: =+D4-E4 -> 83215 | G4: =+D4*0.5 -> 51783 | H4: =+F4-G4 -> 31432 | I4: =+[1]รายชื่อพนักงานรายเดือน!G10 -> 17553.886 | J4: 0 | K4: 0 | L4: =+[1]รายชื่อพนักงานรายเดือน!C9 -> 3580.5558 | M4: 5820 | N4: 0 | O4: 60 | P4: 5235.83 | Q4: 120 | R4: 0 | S4: 206.96 | T4: 0 | U4: 0 | V4: 0 | W4: 0 | X4: =+[1]รายชื่อพนักงานรายเดือน!K8 -> 230.76923 | Y4: 204 | Z4: =+H4-I4-J4-L4-M4-O4-P4-S4-T4-U4-V4-W4-X4-Y4-Q4-R4-K4-N4 -> -1580.0009
A5: 3 | B5: 10205 | C5: หน้ามอ (ม.เกษตร) | D5: 102926 | E5: 17947 | F5: =+D5-E5 -> 84979 | G5: =+D5*0.5 -> 51463 | H5: =+F5-G5 -> 33516 | I5: =+[1]รายชื่อพนักงานรายเดือน!G10 -> 17553.886 | J5: 0 | K5: 0 | L5: =+[1]รายชื่อพนักงานรายเดือน!C9 -> 3580.5558 | M5: 0 | N5: 0 | O5: 40 | P5: 12743.07 | Q5: 0 | R5: 0 | S5: 206.96 | T5: 0 | U5: 0 | V5: 830 | W5: 0 | X5: =+[1]รายชื่อพนักงานรายเดือน!K8 -> 230.76923 | Y5: 374 | Z5: =+H5-I5-J5-L5-M5-O5-P5-S5-T5-U5-V5-W5-X5-Y5-Q5-R5-K5-N5 -> -2043.2409
A6: 4 | B6: 10207 | C6: ลำพยา 3 (เก่า) | D6: 94162 | E6: 1995 | F6: =+D6-E6 -> 92167 | G6: =+D6*0.5 -> 47081 | H6: =+F6-G6 -> 45086 | I6: =+[1]รายชื่อพนักงานรายเดือน!G10 -> 17553.886 | J6: 0 | K6: 100 | L6: =+[1]รายชื่อพนักงานรายเดือน!C9 -> 3580.5558 | M6: 8100 | N6: 0 | O6: 0 | P6: 2497 | Q6: 450 | R6: 0 | S6: 206.96 | T6: 0 | U6: 0 | V6: 0 | W6: 0 | X6: =+[1]รายชื่อพนักงานรายเดือน!K8 -> 230.76923 | Y6: 69 | Z6: =+H6-I6-J6-L6-M6-O6-P6-S6-T6-U6-V6-W6-X6-Y6-Q6-R6-K6-N6 -> 12297.829
A7: 5 | B7: 10208 | C7: ไทวัสดุ | D7: 58440 | E7: 10080 | F7: =+D7-E7 -> 48360 | G7: =+D7*0.5 -> 29220 | H7: =+F7-G7 -> 19140 | I7: =+[1]รายชื่อพนักงานรายเดือน!G10 -> 17553.886 | J7: 0 | K7: 0 | L7: =+[1]รายชื่อพนักงานรายเดือน!C9 -> 3580.5558 | M7: 0 | N7: 0 | O7: 0 | P7: 1320 | Q7: 0 | R7: 0 | S7: 206.96 | T7: 0 | U7: 0 | V7: 0 | W7: 0 | X7: =+[1]รายชื่อพนักงานรายเดือน!K8 -> 230.76923 | Y7: 0 | Z7: =+H7-I7-J7-L7-M7-O7-P7-S7-T7-U7-V7-W7-X7-Y7-Q7-R7-K7-N7 -> -3752.1709
A8: 6 | B8: 10209 | C8: แก้วมณีกาญ | D8: 124018 | E8: 21524 | F8: =+D8-E8 -> 102494 | G8: =+D8*0.5 -> 62009 | H8: =+F8-G8 -> 40485 | I8: =+[1]รายชื่อพนักงานรายเดือน!G10 -> 17553.886 | J8: 99.76 | K8: 100 | L8: =+[1]รายชื่อพนักงานรายเดือน!C9 -> 3580.5558 | M8: 16000 | N8: 0 | O8: 0 | P8: 3307.5 | Q8: 0 | R8: 0 | S8: 206.96 | T8: 0 | U8: 0 | V8: 0 | W8: 0 | X8: =+[1]รายชื่อพนักงานรายเดือน!K8 -> 230.76923 | Y8: 95 | Z8: =+H8-I8-J8-L8-M8-O8-P8-S8-T8-U8-V8-W8-X8-Y8-Q8-R8-K8-N8 -> -689.4309
A9: 7 | B9: 10210 | C9: ลำพยา 2 (ใหม่) | D9: 106692 | E9: 5270 | F9: =+D9-E9 -> 101422 | G9: =+D9*0.5 -> 53346 | H9: =+F9-G9 -> 48076 | I9: =+[1]รายชื่อพนักงานรายเดือน!G10 -> 17553.886 | J9: 56.88 | K9: 0 | L9: =+[1]รายชื่อพนักงานรายเดือน!C9 -> 3580.5558 | M9: =14884+14884 -> 29768 | N9: 0 | O9: 0 | P9: 11020 | Q9: 465 | R9: 0 | S9: 206.96 | T9: 0 | U9: 0 | V9: 0 | W9: 0 | X9: =+[1]รายชื่อพนักงานรายเดือน!K8 -> 230.76923 | Y9: 0 | Z9: =+H9-I9-J9-L9-M9-O9-P9-S9-T9-U9-V9-W9-X9-Y9-Q9-R9-K9-N9 -> -14806.051
A10: 8 | B10: 10219 | C10: ธรรมศาลา | D10: 94062 | E10: 10487 | F10: =+D10-E10 -> 83575 | G10: =+D10*0.5 -> 47031 | H10: =+F10-G10 -> 36544 | I10: =+[1]รายชื่อพนักงานรายเดือน!G10 -> 17553.886 | J10: 0 | K10: 100 | L10: =+[1]รายชื่อพนักงานรายเดือน!C9 -> 3580.5558 | M10: 16500 | N10: 0 | O10: 0 | P10: 4625.39 | Q10: 465 | R10: 0 | S10: 0 | T10: 233.64 | U10: 0 | V10: 0 | W10: 0 | X10: =+[1]รายชื่อพนักงานรายเดือน!K8 -> 230.76923 | Y10: 0 | Z10: =+H10-I10-J10-L10-M10-O10-P10-S10-T10-U10-V10-W10-X10-Y10-Q10-R10-K10-N10 -> -6745.2409
A11: 9 | B11: 10235 | C11: ตลาดดิโอโซน | D11: 93364 | E11: 17390 | F11: =+D11-E11 -> 75974 | G11: =+D11*0.5 -> 46682 | H11: =+F11-G11 -> 29292 | I11: =+[1]รายชื่อพนักงานรายเดือน!G10 -> 17553.886 | J11: 0 | K11: 0 | L11: =+[1]รายชื่อพนักงานรายเดือน!C9 -> 3580.5558 | M11: 12000 | N11: 0 | O11: 0 | P11: 6606 | Q11: 0 | R11: 0 | S11: 212.72 | T11: 0 | U11: 0 | V11: 0 | W11: 0 | X11: =+[1]รายชื่อพนักงานรายเดือน!K8 -> 230.76923 | Y11: 19 | Z11: =+H11-I11-J11-L11-M11-O11-P11-S11-T11-U11-V11-W11-X11-Y11-Q11-R11-K11-N11 -> -10910.931
A12: 10 | B12: 10264 | C12: ปตท.ราชบุรี | D12: 81099 | E12: 7790 | F12: =+D12-E12 -> 73309 | G12: =+D12*0.5 -> 40549.5 | H12: =+F12-G12 -> 32759.5 | I12: =+[1]รายชื่อพนักงานรายเดือน!G10 -> 17553.886 | J12: 0 | K12: 0 | L12: =+[1]รายชื่อพนักงานรายเดือน!C9 -> 3580.5558 | M12: 22050 | N12: 0 | O12: 0 | P12: 5257 | Q12: 465 | R12: 0 | S12: 0 | T12: 0 | U12: 0 | V12: 0 | W12: 0 | X12: =+[1]รายชื่อพนักงานรายเดือน!K8 -> 230.76923 | Y12: 0 | Z12: =+H12-I12-J12-L12-M12-O12-P12-S12-T12-U12-V12-W12-X12-Y12-Q12-R12-K12-N12 -> -16377.711
A13: 11 | B13: 10377 | C13: ปิ่นเกล้า -ศาลายา | D13: 75174 | E13: 10391 | F13: =+D13-E13 -> 64783 | G13: =+D13*0.5 -> 37587 | H13: =+F13-G13 -> 27196 | I13: =+[1]รายชื่อพนักงานรายเดือน!G10 -> 17553.886 | J13: 0 | K13: 0 | L13: =+[1]รายชื่อพนักงานรายเดือน!C9 -> 3580.5558 | M13: 20250 | N13: 0 | O13: 0 | P13: 5358 | Q13: 0 | R13: 0 | S13: 0 | T13: 0 | U13: 0 | V13: 0 | W13: 0 | X13: =+[1]รายชื่อพนักงานรายเดือน!K8 -> 230.76923 | Y13: 138 | Z13: =+H13-I13-J13-L13-M13-O13-P13-S13-T13-U13-V13-W13-X13-Y13-Q13-R13-K13-N13 -> -19915.211
C14: รวม | D14: =SUM(D3:D13) -> 1031887 | E14: =SUM(E3:E13) -> 129710 | F14: =SUM(F3:F13) -> 902177 | G14: =SUM(G3:G13) -> 515943.5 | H14: =SUM(H3:H13) -> 386233.5 | I14: =SUM(I3:I13) -> 193092.74 | J14: =SUM(J3:J13) -> 156.64 | K14: =SUM(K3:K13) -> 400 | ... Z14: =SUM(Z3:Z13) -> -79749.33 | AA14: บาท
C15: กำไร | D15: =+Z14 -> -79749.33
C16: คิดเป็น % | D16: =+D15/D14 -> -0.077284945

Sheet ก.ย. 68
A1: ข้อมูลเทียบกำไร - ขาดทุน ของบู๊ซ เดือน กันยายน 2568
A2: ลำดับ | B2: รหัส | C2: บูธ | D2: ยอดขาย | E2: ส่วนลด | F2: คงเหลือยอดขาย | G2: ค่าต้นทุนขนม | H2: คงเหลือกำไรหลังจากหักต้นทุน | I2: ค่าแรงพนักงานบู๊ช | J2: ค่าคอมพนักงานบู๊ซ | K2: ค่าคอม (พิเศษ)พนักงานบู๊ซ | L2: ค่าพนักงานรายเดือนที่เกี่ยวข้อง | M2: ค่าเช่า | N2: ค่าภาษีโรงเรือน | O2: ค่าน้ำประปา | P2: ค่าไฟ | Q2: ค่าธรรมเนียมโอนเงิน | R2: ค่าเน็ต | S2: ค่าโทรศัพท์ | T2: ค่าส่วนกลาง | U2: ค่าน้ำแข็ง | V2: ค่าขนมนอก | W2: ค่าป้าย | X2: ค่าขนส่งพนักงานรายเดือน | Y2: ค่าใช้จ่ายอื่น ๆ | Z2: คงเหลือกำไรหลังจากหักต้นทุน และ ค่าใช้จ่าย
A3: 1 | B3: 10203 | C3: ลำพยา 3 (ใหม่) | D3: 130338 | E3: 10180 | F3: =+D3-E3 -> 120158 | G3: =+D3*0.5 -> 65169 | H3: =+F3-G3 -> 54989 | I3: =+[1]รายชื่อพนักงานรายเดือน!G10 -> 17553.886 | J3: 0 | K3: 0 | L3: =+[1]รายชื่อพนักงานรายเดือน!C9 -> 3580.5558 | M3: =14884+14884 -> 29768 | N3: 0 | O3: 0 | P3: 5706 | Q3: 30 | R3: 0 | S3: 206.96 | T3: 0 | U3: 0 | V3: 0 | W3: 0 | X3: =+[1]รายชื่อพนักงานรายเดือน!K8 -> 230.76923 | Y3: 55 | Z3: =+H3-I3-J3-L3-M3-O3-P3-S3-T3-U3-V3-W3-X3-Y3-Q3-R3-K3-N3 -> -2142.1709
A4: 2 | B4: 10204 | C4: คุณาวรรณ | D4: 99389 | E4: 22483 | F4: =+D4-E4 -> 76906 | G4: 22483 | H4: =+F4-G4 -> 54423 | I4: =+[1]รายชื่อพนักงานรายเดือน!G10 -> 17553.886 | J4: 0 | K4: 100 | L4: =+[1]รายชื่อพนักงานรายเดือน!C9 -> 3580.5558 | M4: 5820 | N4: 0 | O4: 44 | P4: 4639.88 | Q4: 150 | R4: 0 | S4: 206.96 | T4: 0 | U4: 0 | V4: 0 | W4: 0 | X4: =+[1]รายชื่อพนักงานรายเดือน!K8 -> 230.76923 | Y4: 309 | Z4: =+H4-I4-J4-L4-M4-O4-P4-S4-T4-U4-V4-W4-X4-Y4-Q4-R4-K4-N4 -> 21787.949
A5: 3 | B5: 10205 | C5: หน้ามอ (ม.เกษตร) | D5: 100126 | E5: 16775 | F5: =+D5-E5 -> 83351 | G5: =+D5*0.5 -> 50063 | H5: =+F5-G5 -> 33288 | I5: =+[1]รายชื่อพนักงานรายเดือน!G10 -> 17553.886 | J5: 0 | K5: 0 | L5: =+[1]รายชื่อพนักงานรายเดือน!C9 -> 3580.5558 | M5: 0 | N5: 0 | O5: 40 | P5: 11641.15 | Q5: 0 | R5: 0 | S5: 206.96 | T5: 0 | U5: 50 | V5: 290 | W5: 0 | X5: =+[1]รายชื่อพนักงานรายเดือน!K8 -> 230.76923 | Y5: 55 | Z5: =+H5-I5-J5-L5-M5-O5-P5-S5-T5-U5-V5-W5-X5-Y5-Q5-R5-K5-N5 -> -360.3209
A6: 4 | B6: 10207 | C6: ลำพยา 3 (เก่า) | D6: 79294 | E6: 1401 | F6: =+D6-E6 -> 77893 | G6: =+D6*0.5 -> 39647 | H6: =+F6-G6 -> 38246 | I6: =+[1]รายชื่อพนักงานรายเดือน!G10 -> 17553.886 | J6: 0 | K6: 0 | L6: =+[1]รายชื่อพนักงานรายเดือน!C9 -> 3580.5558 | M6: 8100 | N6: 0 | O6: 0 | P6: 2270 | Q6: 435 | R6: 0 | S6: 206.96 | T6: 0 | U6: 0 | V6: 0 | W6: 0 | X6: =+[1]รายชื่อพนักงานรายเดือน!K8 -> 230.76923 | Y6: 2496 | Z6: =+H6-I6-J6-L6-M6-O6-P6-S6-T6-U6-V6-W6-X6-Y6-Q6-R6-K6-N6 -> 3372.8291
A7: 5 | B7: 10209 | C7: แก้วมณีกาญ | D7: 109483 | E7: 18549 | F7: =+D7-E7 -> 90934 | G7: =+D7*0.5 -> 54741.5 | H7: =+F7-G7 -> 36192.5 | I7: =+[1]รายชื่อพนักงานรายเดือน!G10 -> 17553.886 | J7: 0 | K7: 0 | L7: =+[1]รายชื่อพนักงานรายเดือน!C9 -> 3580.5558 | M7: 16000 | N7: 0 | O7: 0 | P7: 3415 | Q7: 0 | R7: 0 | S7: 206.96 | T7: 0 | U7: 0 | V7: 0 | W7: 0 | X7: =+[1]รายชื่อพนักงานรายเดือน!K8 -> 230.76923 | Y7: 95 | Z7: =+H7-I7-J7-L7-M7-O7-P7-S7-T7-U7-V7-W7-X7-Y7-Q7-R7-K7-N7 -> -4889.6709
A8: 6 | B8: 10210 | C8: ลำพยา 2 (ใหม่) | D8: 97598 | E8: 4010 | F8: =+D8-E8 -> 93588 | G8: =+D8*0.5 -> 48799 | H8: =+F8-G8 -> 44789 | I8: =+[1]รายชื่อพนักงานรายเดือน!G10 -> 17553.886 | J8: 0 | K8: 0 | L8: =+[1]รายชื่อพนักงานรายเดือน!C9 -> 3580.5558 | M8: =14884+14884 -> 29768 | N8: 0 | O8: 0 | P8: 4380 | Q8: 450 | R8: 0 | S8: 206.96 | T8: 0 | U8: 0 | V8: 0 | W8: 0 | X8: =+[1]รายชื่อพนักงานรายเดือน!K8 -> 230.76923 | Y8: 300 | Z8: =+H8-I8-J8-L8-M8-O8-P8-S8-T8-U8-V8-W8-X8-Y8-Q8-R8-K8-N8 -> -11681.171
A9: 7 | B9: 10219 | C9: ธรรมศาลา | D9: 76633 | E9: 7996 | F9: =+D9-E9 -> 68637 | G9: =+D9*0.5 -> 38316.5 | H9: =+F9-G9 -> 30320.5 | I9: =+[1]รายชื่อพนักงานรายเดือน!G10 -> 17553.886 | J9: 0 | K9: 0 | L9: =+[1]รายชื่อพนักงานรายเดือน!C9 -> 3580.5558 | M9: 16500 | N9: 0 | O9: 0 | P9: 3503.5 | Q9: 450 | R9: 0 | S9: 206.96 | T9: 467.29 | U9: 0 | V9: 0 | W9: 0 | X9: =+[1]รายชื่อพนักงานรายเดือน!K8 -> 230.76923 | Y9: 0 | Z9: =+H9-I9-J9-L9-M9-O9-P9-S9-T9-U9-V9-W9-X9-Y9-Q9-R9-K9-N9 -> -12172.461
A10: 8 | B10: 10235 | C10: ตลาดดิโอโซน | D10: 98784 | E10: 18186 | F10: =+D10-E10 -> 80598 | G10: =+D10*0.5 -> 49392 | H10: =+F10-G10 -> 31206 | I10: =+[1]รายชื่อพนักงานรายเดือน!G10 -> 17553.886 | J10: 0 | K10: 0 | L10: =+[1]รายชื่อพนักงานรายเดือน!C9 -> 3580.5558 | M10: 12000 | N10: 0 | O10: 0 | P10: 5610 | Q10: 0 | R10: 0 | S10: 0 | T10: 0 | U10: 0 | V10: 0 | W10: 0 | X10: =+[1]รายชื่อพนักงานรายเดือน!K8 -> 230.76923 | Y10: 0 | Z10: =+H10-I10-J10-L10-M10-O10-P10-S10-T10-U10-V10-W10-X10-Y10-Q10-R10-K10-N10 -> -7769.2109
A11: 9 | B11: 10264 | C11: ปตท.ราชบุรี | D11: 75227 | E11: 6734 | F11: =+D11-E11 -> 68493 | G11: 6734 | H11: =+F11-G11 -> 61759 | I11: =+[1]รายชื่อพนักงานรายเดือน!G10 -> 17553.886 | J11: 0 | K11: 0 | L11: =+[1]รายชื่อพนักงานรายเดือน!C9 -> 3580.5558 | M11: 22050 | N11: 0 | O11: 0 | P11: 4188 | Q11: 420 | R11: 0 | S11: 212.72 | T11: 0 | U11: 0 | V11: 0 | W11: 0 | X11: =+[1]รายชื่อพนักงานรายเดือน!K8 -> 230.76923 | Y11: 38 | Z11: =+H11-I11-J11-L11-M11-O11-P11-S11-T11-U11-V11-W11-X11-Y11-Q11-R11-K11-N11 -> 13485.069
A12: 10 | B12: 10377 | C12: ปิ่นเกล้า -ศาลายา | D12: 66437 | E12: 10245 | F12: =+D12-E12 -> 56192 | G12: =+D12*0.5 -> 33218.5 | H12: =+F12-G12 -> 22973.5 | I12: =+[1]รายชื่อพนักงานรายเดือน!G10 -> 17553.886 | J12: 0 | K12: 0 | L12: =+[1]รายชื่อพนักงานรายเดือน!C9 -> 3580.5558 | M12: 20250 | N12: 0 | O12: 0 | P12: 5832 | Q12: 0 | R12: 0 | S12: 0 | T12: 0 | U12: 0 | V12: 0 | W12: 0 | X12: =+[1]รายชื่อพนักงานรายเดือน!K8 -> 230.76923 | Y12: 0 | Z12: =+H12-I12-J12-L12-M12-O12-P12-S12-T12-U12-V12-W12-X12-Y12-Q12-R12-K12-N12 -> -24473.711
C13: รวม | D13: =SUM(D3:D12) -> 933309 | E13: =SUM(E3:E12) -> 116559 | F13: =SUM(F3:F12) -> 816750 | G13: =SUM(G3:G12) -> 408563.5 | H13: =SUM(H3:H12) -> 408186.5 | I13: =SUM(I3:I12) -> 175538.86 | J13: =SUM(J3:J12) -> 0 | K13: =SUM(K3:K12) -> 100 | ... Z13: =SUM(Z3:Z12) -> -24842.869 | AA13: บาท
C14: กำไร | D14: =+Z13 -> -24842.869
C15: คิดเป็น % | D15: =+D14/D13 -> -0.026618054

Sheet ต.ค. 68
A1: ข้อมูลเทียบกำไร - ขาดทุน ของบู๊ซ เดือน กันยายน 2568
A2: ลำดับ | B2: รหัส | C2: บูธ | D2: ยอดขาย | E2: ส่วนลด | F2: คงเหลือยอดขาย | G2: ค่าต้นทุนขนม | H2: คงเหลือกำไรหลังจากหักต้นทุน | I2: ค่าแรงพนักงานบู๊ช | J2: ค่าคอมพนักงานบู๊ซ | K2: ค่าคอม (พิเศษ)พนักงานบู๊ซ | L2: ค่าพนักงานรายเดือนที่เกี่ยวข้อง | M2: ค่าเช่า | N2: ค่าภาษีโรงเรือน | O2: ค่าน้ำประปา | P2: ค่าไฟ | Q2: ค่าธรรมเนียมโอนเงิน | R2: ค่าเน็ต | S2: ค่าโทรศัพท์ | T2: ค่าส่วนกลาง | U2: ค่าน้ำแข็ง | V2: ค่าขนมนอก | W2: ค่าป้าย | X2: ค่าขนส่งพนักงานรายเดือน | Y2: ค่าใช้จ่ายอื่น ๆ | Z2: คงเหลือกำไรหลังจากหักต้นทุน และ ค่าใช้จ่าย
