Workbook

Sheet ALL
A1: รายการขายสินค้าออนไลน์แยกจำนวนชิ้นรายวัน เดือนสิงหาคม 2568
D2: =SUBTOTAL(9,D5:D10474) -> 29446 | E2: =SUBTOTAL(9,E5:E10474) -> 0 | F2: =SUBTOTAL(9,F5:F10474) -> 484612.33 | G2: =SUBTOTAL(9,G5:G10474) -> 523 | H2: =SUBTOTAL(9,H5:H10474) -> 0 | I2: =SUBTOTAL(9,I5:I10474) -> 8601.44 | J2: =SUBTOTAL(9,J5:J10474) -> 432 | K2: =SUBTOTAL(9,K5:K10474) -> 0 | ... CX2: =SUBTOTAL(9,CX5:CX10474) -> 0
A3: รหัสสินค้า | B3: ชื่อสินค้า | C3: ราคาต้นทุน | D3: เดือนสิงหาคม | G3: 244197 | J3: 244198 | M3: 244199 | P3: 244200 | S3: 244201 | V3: 244202 | Y3: 244203 | AB3: 244204 | AE3: 244205 | AH3: 244206 | AK3: 244207 | AN3: 244208 | AQ3: 244209 | AT3: 244210 | AW3: 244211 | AZ3: 244212 | BC3: 244213 | BF3: 244214 | BI3: 244215 | BL3: 244216 | BO3: 244217 | BR3: 244218 | BU3: 244219 | BX3: 244220 | CA3: 244221 | CD3: 244222 | CG3: 244223 | CJ3: 244224 | CM3: 244225 | CP3: 244226 | CS3: 244227 | CV3: เซตวันที่ 1-31/08/2568
D4: จำนวน | E4: หน่วย | F4: ยอดต้นทุน/วัน | G4: จำนวน | H4: หน่วย | I4: ยอดต้นทุน/วัน | J4: จำนวน | K4: หน่วย | L4: ยอดต้นทุน/วัน | M4: จำนวน | N4: หน่วย | O4: ยอดต้นทุน/วัน | P4: จำนวน | Q4: หน่วย | R4: ยอดต้นทุน/วัน | S4: จำนวน | T4: หน่วย | U4: ยอดต้นทุน/วัน | V4: จำนวน | W4: หน่วย | X4: ยอดต้นทุน/วัน | Y4: จำนวน | Z4: หน่วย | AA4: ยอดต้นทุน/วัน | AB4: จำนวน | AC4: หน่วย | AD4: ยอดต้นทุน/วัน | AE4: จำนวน | AF4: หน่วย | AG4: ยอดต้นทุน/วัน | AH4: จำนวน | AI4: หน่วย | AJ4: ยอดต้นทุน/วัน | AK4: จำนวน | AL4: หน่วย | AM4: ยอดต้นทุน/วัน | AN4: จำนวน | AO4: หน่วย | AP4: ยอดต้นทุน/วัน | AQ4: จำนวน | AR4: หน่วย | AS4: ยอดต้นทุน/วัน | AT4: จำนวน | AU4: หน่วย | AV4: ยอดต้นทุน/วัน | AW4: จำนวน | AX4: หน่วย | AY4: ยอดต้นทุน/วัน | AZ4: จำนวน | BA4: หน่วย | BB4: ยอดต้นทุน/วัน | BC4: จำนวน | BD4: หน่วย | BE4: ยอดต้นทุน/วัน | BF4: จำนวน | BG4: หน่วย | BH4: ยอดต้นทุน/วัน | BI4: จำนวน | BJ4: หน่วย | BK4: ยอดต้นทุน/วัน | BL4: จำนวน | BM4: หน่วย | BN4: ยอดต้นทุน/วัน | BO4: จำนวน | BP4: หน่วย | BQ4: ยอดต้นทุน/วัน | BR4: จำนวน | BS4: หน่วย | BT4: ยอดต้นทุน/วัน | BU4: จำนวน | BV4: หน่วย | BW4: ยอดต้นทุน/วัน | BX4: จำนวน | BY4: หน่วย | BZ4: ยอดต้นทุน/วัน | CA4: จำนวน | CB4: หน่วย | CC4: ยอดต้นทุน/วัน | CD4: จำนวน | CE4: หน่วย | CF4: ยอดต้นทุน/วัน | CG4: จำนวน | CH4: หน่วย | CI4: ยอดต้นทุน/วัน | CJ4: จำนวน | CK4: หน่วย | CL4: ยอดต้นทุน/วัน | CM4: จำนวน | CN4: หน่วย | CO4: ยอดต้นทุน/วัน | CP4: จำนวน | CQ4: หน่วย | CR4: ยอดต้นทุน/วัน | CS4: จำนวน | CT4: หน่วย | CU4: ยอดต้นทุน/วัน | CV4: จำนวน | CW4: หน่วย | CX4: ยอดต้นทุน/วัน
A5: 0006 | B5: เค้กเบาหวิวเล็ก 1กล่องขนาด 100 กรัม (คละรส) | C5: 14.05 | D5: =+G5+J5+M5+P5+S5+V5+Y5+AB5+AE5+AH5+AK5+AN5+AQ5+AT5+AW5+AZ5+BC5+BF5+BI5+BL5+BO5+BR5+BU5+BX5+CA5+CD5+CG5+CJ5+CM5+CP5+CS5+CV5 -> 9795 | E5: กล่อง | F5: =+D5*C5 -> 137619.75 | G5: =IFERROR(VLOOKUP(A5,'1'!U:V,2,0),"0") -> 230 | H5: กล่อง | I5: =+G5*C5 -> 3231.5 | J5: =IFERROR(VLOOKUP(A5,'2'!U:V,2,0),"0") -> 131 | K5: กล่อง | L5: =+J5*C5 -> 1840.55 | M5: =IFERROR(VLOOKUP(A5,'3'!U:V,2,0),"0") -> 160 | N5: กล่อง | O5: =+M5*C5 -> 2248 | P5: =IFERROR(VLOOKUP(A5,'4'!U:V,2,0),"0") -> 160 | Q5: กล่อง | R5: =+P5*C5 -> 2248 | S5: =IFERROR(VLOOKUP(A5,'5'!U:V,2,0),"0") -> 196 | T5: กล่อง | U5: =+S5*C5 -> 2753.8 | V5: =IFERROR(VLOOKUP(A5,'6'!U:V,2,0),"0") -> 257 | W5: กล่อง | X5: =+V5*C5 -> 3610.85 | Y5: =IFERROR(VLOOKUP(A5,'7'!U:V,2,0),"0") -> 319 | Z5: กล่อง | AA5: =+Y5*C5 -> 4481.95 | AB5: =IFERROR(VLOOKUP(A5,'8'!U:V,2,0),"0") -> 323 | AC5: กล่อง | AD5: =+AB5*C5 -> 4538.15 | AE5: =IFERROR(VLOOKUP(A5,'9'!U:V,2,0),"0") -> 249 | AF5: กล่อง | AG5: =+AE5*C5 -> 3498.45 | AH5: =IFERROR(VLOOKUP(A5,'10'!U:V,2,0),"0") -> 393 | AI5: กล่อง | AJ5: =+AH5*C5 -> 5521.65 | AK5: =IFERROR(VLOOKUP(A5,'11'!U:V,2,0),"0") -> 367 | AL5: กล่อง | AM5: =+AK5*C5 -> 5156.35 | AN5: =IFERROR(VLOOKUP(A5,'12'!U:V,2,0),"0") -> 254 | AO5: กล่อง | AP5: =+AN5*C5 -> 3568.7 | AQ5: =IFERROR(VLOOKUP(A5,'13'!U:V,2,0),"0") -> 219 | AR5: กล่อง | AS5: =+AQ5*C5 -> 3076.95 | AT5: =IFERROR(VLOOKUP(A5,'14'!U:V,2,0),"0") -> 207 | AU5: กล่อง | AV5: =+AT5*C5 -> 2908.35 | AW5: =IFERROR(VLOOKUP(A5,'15'!U:V,2,0),"0") -> 270 | AX5: กล่อง | AY5: =+AW5*C5 -> 3793.5 | AZ5: =IFERROR(VLOOKUP(A5,'16'!U:V,2,0),"0") -> 357 | BA5: กล่อง | BB5: =+AZ5*C5 -> 5015.85 | BC5: =IFERROR(VLOOKUP(A5,'17'!U:V,2,0),"0") -> 339 | BD5: กล่อง | BE5: =+BC5*C5 -> 4762.95 | BF5: =IFERROR(VLOOKUP(A5,'18'!U:V,2,0),"0") -> 204 | BG5: กล่อง | BH5: =+BF5*C5 -> 2866.2 | BI5: =IFERROR(VLOOKUP(A5,'19'!U:V,2,0),"0") -> 417 | BJ5: กล่อง | BK5: =+BI5*C5 -> 5858.85 | BL5: =IFERROR(VLOOKUP(A5,'20'!U:V,2,0),"0") -> 433 | BM5: กล่อง | BN5: =+BL5*C5 -> 6083.65 | BO5: =IFERROR(VLOOKUP(A5,'21'!U:V,2,0),"0") -> 547 | BP5: กล่อง | BQ5: =+BO5*C5 -> 7685.35 | BR5: =IFERROR(VLOOKUP(A5,'22'!U:V,2,0),"0") -> 448 | BS5: กล่อง | BT5: =+BR5*C5 -> 6294.4 | BU5: =IFERROR(VLOOKUP(A5,'23'!U:V,2,0),"0") -> 363 | BV5: กล่อง | BW5: =+BU5*C5 -> 5100.15 | BX5: =IFERROR(VLOOKUP(A5,'24'!U:V,2,0),"0") -> 393 | BY5: กล่อง | BZ5: =+BX5*C5 -> 5521.65 | CA5: =IFERROR(VLOOKUP(A5,'25'!U:V,2,0),"0") -> 386 | CB5: กล่อง | CC5: =+CA5*C5 -> 5423.3 | CD5: =IFERROR(VLOOKUP(A5,'26'!U:V,2,0),"0") -> 325 | CE5: กล่อง | CF5: =+CD5*C5 -> 4566.25 | CG5: =IFERROR(VLOOKUP(A5,'27'!U:V,2,0),"0") -> 387 | CH5: กล่อง | CI5: =+CG5*C5 -> 5437.35 | CJ5: =IFERROR(VLOOKUP(A5,'28'!U:V,2,0),"0") -> 387 | CK5: กล่อง | CL5: =+CJ5*C5 -> 5437.35 | CM5: =IFERROR(VLOOKUP(A5,'29'!U:V,2,0),"0") -> 263 | CN5: กล่อง | CO5: =+CM5*C5 -> 3695.15 | CP5: =IFERROR(VLOOKUP(A5,'30'!U:V,2,0),"0") -> 303 | CQ5: กล่อง | CR5: =+CP5*C5 -> 4257.15 | CS5: =IFERROR(VLOOKUP(A5,'31'!U:V,2,0),"0") -> 508 | CT5: กล่อง | CU5: =+CS5*C5 -> 7137.4 | CV5: =IFERROR(VLOOKUP(A5,'เซต1-31'!V:W,2,0),"0") -> 0 | CW5: กล่อง | CX5: =+CV5*CO5 -> 0
A6: 1004055 | B6: ชิฟฟ่อน รวมรส 1กล่อง4ชิ้น | C6: 19.58 | D6: =+G6+J6+M6+P6+S6+V6+Y6+AB6+AE6+AH6+AK6+AN6+AQ6+AT6+AW6+AZ6+BC6+BF6+BI6+BL6+BO6+BR6+BU6+BX6+CA6+CD6+CG6+CJ6+CM6+CP6+CS6+CV6 -> 1356 | E6: กล่อง | F6: =+D6*C6 -> 26550.48 | G6: =IFERROR(VLOOKUP(A6,'1'!U:V,2,0),"0") -> 5 | H6: กล่อง | I6: =+G6*C6 -> 97.9 | J6: =IFERROR(VLOOKUP(A6,'2'!U:V,2,0),"0") -> 0 | K6: กล่อง | L6: =+J6*C6 -> 0 | M6: =IFERROR(VLOOKUP(A6,'3'!U:V,2,0),"0") -> 0 | N6: กล่อง | O6: =+M6*C6 -> 0 | P6: =IFERROR(VLOOKUP(A6,'4'!U:V,2,0),"0") -> 133 | Q6: กล่อง | R6: =+P6*C6 -> 2604.14 | S6: =IFERROR(VLOOKUP(A6,'5'!U:V,2,0),"0") -> 42 | T6: กล่อง | U6: =+S6*C6 -> 822.36 | V6: =IFERROR(VLOOKUP(A6,'6'!U:V,2,0),"0") -> 28 | W6: กล่อง | X6: =+V6*C6 -> 548.24 | Y6: =IFERROR(VLOOKUP(A6,'7'!U:V,2,0),"0") -> 53 | Z6: กล่อง | AA6: =+Y6*C6 -> 1037.74 | AB6: =IFERROR(VLOOKUP(A6,'8'!U:V,2,0),"0") -> 114 | AC6: กล่อง | AD6: =+AB6*C6 -> 2232.12 | AE6: =IFERROR(VLOOKUP(A6,'9'!U:V,2,0),"0") -> 9 | AF6: กล่อง | AG6: =+AE6*C6 -> 176.22 | AH6: =IFERROR(VLOOKUP(A6,'10'!U:V,2,0),"0") -> 30 | AI6: กล่อง | AJ6: =+AH6*C6 -> 587.4 | AK6: =IFERROR(VLOOKUP(A6,'11'!U:V,2,0),"0") -> 9 | AL6: กล่อง | AM6: =+AK6*C6 -> 176.22 | AN6: =IFERROR(VLOOKUP(A6,'12'!U:V,2,0),"0") -> 47 | AO6: กล่อง | AP6: =+AN6*C6 -> 920.26 | AQ6: =IFERROR(VLOOKUP(A6,'13'!U:V,2,0),"0") -> 24 | AR6: กล่อง | AS6: =+AQ6*C6 -> 469.92 | AT6: =IFERROR(VLOOKUP(A6,'14'!U:V,2,0),"0") -> 19 | AU6: กล่อง | AV6: =+AT6*C6 -> 372.02 | AW6: =IFERROR(VLOOKUP(A6,'15'!U:V,2,0),"0") -> 43 | AX6: กล่อง | AY6: =+AW6*C6 -> 841.94 | AZ6: =IFERROR(VLOOKUP(A6,'16'!U:V,2,0),"0") -> 51 | BA6: กล่อง | BB6: =+AZ6*C6 -> 998.58 | BC6: =IFERROR(VLOOKUP(A6,'17'!U:V,2,0),"0") -> 42 | BD6: กล่อง | BE6: =+BC6*C6 -> 822.36 | BF6: =IFERROR(VLOOKUP(A6,'18'!U:V,2,0),"0") -> 64 | BG6: กล่อง | BH6: =+BF6*C6 -> 1253.12 | BI6: =IFERROR(VLOOKUP(A6,'19'!U:V,2,0),"0") -> 46 | BJ6: กล่อง | BK6: =+BI6*C6 -> 900.68 | BL6: =IFERROR(VLOOKUP(A6,'20'!U:V,2,0),"0") -> 27 | BM6: กล่อง | BN6: =+BL6*C6 -> 528.66 | BO6: =IFERROR(VLOOKUP(A6,'21'!U:V,2,0),"0") -> 60 | BP6: กล่อง | BQ6: =+BO6*C6 -> 1174.8 | BR6: =IFERROR(VLOOKUP(A6,'22'!U:V,2,0),"0") -> 54 | BS6: กล่อง | BT6: =+BR6*C6 -> 1057.32 | BU6: =IFERROR(VLOOKUP(A6,'23'!U:V,2,0),"0") -> 10 | BV6: กล่อง | BW6: =+BU6*C6 -> 195.8 | BX6: =IFERROR(VLOOKUP(A6,'24'!U:V,2,0),"0") -> 24 | BY6: กล่อง | BZ6: =+BX6*C6 -> 469.92 | CA6: =IFERROR(VLOOKUP(A6,'25'!U:V,2,0),"0") -> 63 | CB6: กล่อง | CC6: =+CA6*C6 -> 1233.54 | CD6: =IFERROR(VLOOKUP(A6,'26'!U:V,2,0),"0") -> 88 | CE6: กล่อง | CF6: =+CD6*C6 -> 1723.04 | CG6: =IFERROR(VLOOKUP(A6,'27'!U:V,2,0),"0") -> 52 | CH6: กล่อง | CI6: =+CG6*C6 -> 1018.16 | CJ6: =IFERROR(VLOOKUP(A6,'28'!U:V,2,0),"0") -> 54 | CK6: กล่อง | CL6: =+CJ6*C6 -> 1057.32 | CM6: =IFERROR(VLOOKUP(A6,'29'!U:V,2,0),"0") -> 54 | CN6: กล่อง | CO6: =+CM6*C6 -> 1057.32 | CP6: =IFERROR(VLOOKUP(A6,'30'!U:V,2,0),"0") -> 57 | CQ6: กล่อง | CR6: =+CP6*C6 -> 1116.06 | CS6: =IFERROR(VLOOKUP(A6,'31'!U:V,2,0),"0") -> 54 | CT6: กล่อง | CU6: =+CS6*C6 -> 1057.32 | CV6: =IFERROR(VLOOKUP(A6,'เซต1-31'!V:W,2,0),"0") -> 0 | CW6: กล่อง | CX6: =+CV6*CO6 -> 0
A7: 1005761 | B7: ขนมปังกรอบคาราเมล(ถุง) | C7: 17.5 | D7: =+G7+J7+M7+P7+S7+V7+Y7+AB7+AE7+AH7+AK7+AN7+AQ7+AT7+AW7+AZ7+BC7+BF7+BI7+BL7+BO7+BR7+BU7+BX7+CA7+CD7+CG7+CJ7+CM7+CP7+CS7+CV7 -> 0 | E7: ถุง | F7: =+D7*C7 -> 0 | G7: =IFERROR(VLOOKUP(A7,'1'!U:V,2,0),"0") -> 0 | H7: ถุง | I7: =+G7*C7 -> 0 | J7: =IFERROR(VLOOKUP(A7,'2'!U:V,2,0),"0") -> 0 | K7: ถุง | L7: =+J7*C7 -> 0 | M7: =IFERROR(VLOOKUP(A7,'3'!U:V,2,0),"0") -> 0 | N7: ถุง | O7: =+M7*C7 -> 0 | P7: =IFERROR(VLOOKUP(A7,'4'!U:V,2,0),"0") -> 0 | Q7: ถุง | R7: =+P7*C7 -> 0 | S7: =IFERROR(VLOOKUP(A7,'5'!U:V,2,0),"0") -> 0 | T7: ถุง | U7: =+S7*C7 -> 0 | V7: =IFERROR(VLOOKUP(A7,'6'!U:V,2,0),"0") -> 0 | W7: ถุง | X7: =+V7*C7 -> 0 | Y7: =IFERROR(VLOOKUP(A7,'7'!U:V,2,0),"0") -> 0 | Z7: ถุง | AA7: =+Y7*C7 -> 0 | AB7: =IFERROR(VLOOKUP(A7,'8'!U:V,2,0),"0") -> 0 | AC7: ถุง | AD7: =+AB7*C7 -> 0 | AE7: =IFERROR(VLOOKUP(A7,'9'!U:V,2,0),"0") -> 0 | AF7: ถุง | AG7: =+AE7*C7 -> 0 | AH7: =IFERROR(VLOOKUP(A7,'10'!U:V,2,0),"0") -> 0 | AI7: ถุง | AJ7: =+AH7*C7 -> 0 | AK7: =IFERROR(VLOOKUP(A7,'11'!U:V,2,0),"0") -> 0 | AL7: ถุง | AM7: =+AK7*C7 -> 0 | AN7: =IFERROR(VLOOKUP(A7,'12'!U:V,2,0),"0") -> 0 | AO7: ถุง | AP7: =+AN7*C7 -> 0 | AQ7: =IFERROR(VLOOKUP(A7,'13'!U:V,2,0),"0") -> 0 | AR7: ถุง | AS7: =+AQ7*C7 -> 0 | AT7: =IFERROR(VLOOKUP(A7,'14'!U:V,2,0),"0") -> 0 | AU7: ถุง | AV7: =+AT7*C7 -> 0 | AW7: =IFERROR(VLOOKUP(A7,'15'!U:V,2,0),"0") -> 0 | AX7: ถุง | AY7: =+AW7*C7 -> 0 | AZ7: =IFERROR(VLOOKUP(A7,'16'!U:V,2,0),"0") -> 0 | BA7: ถุง | BB7: =+AZ7*C7 -> 0 | BC7: =IFERROR(VLOOKUP(A7,'17'!U:V,2,0),"0") -> 0 | BD7: ถุง | BE7: =+BC7*C7 -> 0 | BF7: =IFERROR(VLOOKUP(A7,'18'!U:V,2,0),"0") -> 0 | BG7: ถุง | BH7: =+BF7*C7 -> 0 | BI7: =IFERROR(VLOOKUP(A7,'19'!U:V,2,0),"0") -> 0 | BJ7: ถุง | BK7: =+BI7*C7 -> 0 | BL7: =IFERROR(VLOOKUP(A7,'20'!U:V,2,0),"0") -> 0 | BM7: ถุง | BN7: =+BL7*C7 -> 0 | BO7: =IFERROR(VLOOKUP(A7,'21'!U:V,2,0),"0") -> 0 | BP7: ถุง | BQ7: =+BO7*C7 -> 0 | BR7: =IFERROR(VLOOKUP(A7,'22'!U:V,2,0),"0") -> 0 | BS7: ถุง | BT7: =+BR7*C7 -> 0 | BU7: =IFERROR(VLOOKUP(A7,'23'!U:V,2,0),"0") -> 0 | BV7: ถุง | BW7: =+BU7*C7 -> 0 | BX7: =IFERROR(VLOOKUP(A7,'24'!U:V,2,0),"0") -> 0 | BY7: ถุง | BZ7: =+BX7*C7 -> 0 | CA7: =IFERROR(VLOOKUP(A7,'25'!U:V,2,0),"0") -> 0 | CB7: ถุง | CC7: =+CA7*C7 -> 0 | CD7: =IFERROR(VLOOKUP(A7,'26'!U:V,2,0),"0") -> 0 | CE7: ถุง | CF7: =+CD7*C7 -> 0 | CG7: =IFERROR(VLOOKUP(A7,'27'!U:V,2,0),"0") -> 0 | CH7: ถุง | CI7: =+CG7*C7 -> 0 | CJ7: =IFERROR(VLOOKUP(A7,'28'!U:V,2,0),"0") -> 0 | CK7: ถุง | CL7: =+CJ7*C7 -> 0 | CM7: =IFERROR(VLOOKUP(A7,'29'!U:V,2,0),"0") -> 0 | CN7: ถุง | CO7: =+CM7*C7 -> 0 | CP7: =IFERROR(VLOOKUP(A7,'30'!U:V,2,0),"0") -> 0 | CQ7: ถุง | CR7: =+CP7*C7 -> 0 | CS7: =IFERROR(VLOOKUP(A7,'31'!U:V,2,0),"0") -> 0 | CT7: ถุง | CU7: =+CS7*C7 -> 0 | CV7: =IFERROR(VLOOKUP(A7,'เซต1-31'!V:W,2,0),"0") -> 0 | CW7: ถุง | CX7: =+CV7*CO7 -> 0
A8: 1100001 | B8: ทาร์ตสับปะรดแบบชิ้น อร่อยนุ่ม (1 ชิ้น) | C8: 4.43 | D8: =+G8+J8+M8+P8+S8+V8+Y8+AB8+AE8+AH8+AK8+AN8+AQ8+AT8+AW8+AZ8+BC8+BF8+BI8+BL8+BO8+BR8+BU8+BX8+CA8+CD8+CG8+CJ8+CM8+CP8+CS8+CV8 -> 0 | E8: ชิ้น | F8: =+D8*C8 -> 0 | G8: =IFERROR(VLOOKUP(A8,'1'!U:V,2,0),"0") -> 0 | H8: ชิ้น | I8: =+G8*C8 -> 0 | J8: =IFERROR(VLOOKUP(A8,'2'!U:V,2,0),"0") -> 0 | K8: ชิ้น | L8: =+J8*C8 -> 0 | M8: =IFERROR(VLOOKUP(A8,'3'!U:V,2,0),"0") -> 0 | N8: ชิ้น | O8: =+M8*C8 -> 0 | P8: =IFERROR(VLOOKUP(A8,'4'!U:V,2,0),"0") -> 0 | Q8: ชิ้น | R8: =+P8*C8 -> 0 | S8: =IFERROR(VLOOKUP(A8,'5'!U:V,2,0),"0") -> 0 | T8: ชิ้น | U8: =+S8*C8 -> 0 | V8: =IFERROR(VLOOKUP(A8,'6'!U:V,2,0),"0") -> 0 | W8: ชิ้น | X8: =+V8*C8 -> 0 | Y8: =IFERROR(VLOOKUP(A8,'7'!U:V,2,0),"0") -> 0 | Z8: ชิ้น | AA8: =+Y8*C8 -> 0 | AB8: =IFERROR(VLOOKUP(A8,'8'!U:V,2,0),"0") -> 0 | AC8: ชิ้น | AD8: =+AB8*C8 -> 0 | AE8: =IFERROR(VLOOKUP(A8,'9'!U:V,2,0),"0") -> 0 | AF8: ชิ้น | AG8: =+AE8*C8 -> 0 | AH8: =IFERROR(VLOOKUP(A8,'10'!U:V,2,0),"0") -> 0 | AI8: ชิ้น | AJ8: =+AH8*C8 -> 0 | AK8: =IFERROR(VLOOKUP(A8,'11'!U:V,2,0),"0") -> 0 | AL8: ชิ้น | AM8: =+AK8*C8 -> 0 | AN8: =IFERROR(VLOOKUP(A8,'12'!U:V,2,0),"0") -> 0 | AO8: ชิ้น | AP8: =+AN8*C8 -> 0 | AQ8: =IFERROR(VLOOKUP(A8,'13'!U:V,2,0),"0") -> 0 | AR8: ชิ้น | AS8: =+AQ8*C8 -> 0 | AT8: =IFERROR(VLOOKUP(A8,'14'!U:V,2,0),"0") -> 0 | AU8: ชิ้น | AV8: =+AT8*C8 -> 0 | AW8: =IFERROR(VLOOKUP(A8,'15'!U:V,2,0),"0") -> 0 | AX8: ชิ้น | AY8: =+AW8*C8 -> 0 | AZ8: =IFERROR(VLOOKUP(A8,'16'!U:V,2,0),"0") -> 0 | BA8: ชิ้น | BB8: =+AZ8*C8 -> 0 | BC8: =IFERROR(VLOOKUP(A8,'17'!U:V,2,0),"0") -> 0 | BD8: ชิ้น | BE8: =+BC8*C8 -> 0 | BF8: =IFERROR(VLOOKUP(A8,'18'!U:V,2,0),"0") -> 0 | BG8: ชิ้น | BH8: =+BF8*C8 -> 0 | BI8: =IFERROR(VLOOKUP(A8,'19'!U:V,2,0),"0") -> 0 | BJ8: ชิ้น | BK8: =+BI8*C8 -> 0 | BL8: =IFERROR(VLOOKUP(A8,'20'!U:V,2,0),"0") -> 0 | BM8: ชิ้น | BN8: =+BL8*C8 -> 0 | BO8: =IFERROR(VLOOKUP(A8,'21'!U:V,2,0),"0") -> 0 | BP8: ชิ้น | BQ8: =+BO8*C8 -> 0 | BR8: =IFERROR(VLOOKUP(A8,'22'!U:V,2,0),"0") -> 0 | BS8: ชิ้น | BT8: =+BR8*C8 -> 0 | BU8: =IFERROR(VLOOKUP(A8,'23'!U:V,2,0),"0") -> 0 | BV8: ชิ้น | BW8: =+BU8*C8 -> 0 | BX8: =IFERROR(VLOOKUP(A8,'24'!U:V,2,0),"0") -> 0 | BY8: ชิ้น | BZ8: =+BX8*C8 -> 0 | CA8: =IFERROR(VLOOKUP(A8,'25'!U:V,2,0),"0") -> 0 | CB8: ชิ้น | CC8: =+CA8*C8 -> 0 | CD8: =IFERROR(VLOOKUP(A8,'26'!U:V,2,0),"0") -> 0 | CE8: ชิ้น | CF8: =+CD8*C8 -> 0 | CG8: =IFERROR(VLOOKUP(A8,'27'!U:V,2,0),"0") -> 0 | CH8: ชิ้น | CI8: =+CG8*C8 -> 0 | CJ8: =IFERROR(VLOOKUP(A8,'28'!U:V,2,0),"0") -> 0 | CK8: ชิ้น | CL8: =+CJ8*C8 -> 0 | CM8: =IFERROR(VLOOKUP(A8,'29'!U:V,2,0),"0") -> 0 | CN8: ชิ้น | CO8: =+CM8*C8 -> 0 | CP8: =IFERROR(VLOOKUP(A8,'30'!U:V,2,0),"0") -> 0 | CQ8: ชิ้น | CR8: =+CP8*C8 -> 0 | CS8: =IFERROR(VLOOKUP(A8,'31'!U:V,2,0),"0") -> 0 | CT8: ชิ้น | CU8: =+CS8*C8 -> 0 | CV8: =IFERROR(VLOOKUP(A8,'เซต1-31'!V:W,2,0),"0") -> 0 | CW8: ชิ้น | CX8: =+CV8*CO8 -> 0
A9: 1100002 | B9: ทาร์ตสับปะรด (ทาร์ตสับปะรดกล่อง 4 ชิ้น) | C9: 22.02 | D9: =+G9+J9+M9+P9+S9+V9+Y9+AB9+AE9+AH9+AK9+AN9+AQ9+AT9+AW9+AZ9+BC9+BF9+BI9+BL9+BO9+BR9+BU9+BX9+CA9+CD9+CG9+CJ9+CM9+CP9+CS9+CV9 -> 2 | E9: กล่อง | F9: =+D9*C9 -> 44.04 | G9: =IFERROR(VLOOKUP(A9,'1'!U:V,2,0),"0") -> 0 | H9: กล่อง | I9: =+G9*C9 -> 0 | J9: =IFERROR(VLOOKUP(A9,'2'!U:V,2,0),"0") -> 0 | K9: กล่อง | L9: =+J9*C9 -> 0 | M9: =IFERROR(VLOOKUP(A9,'3'!U:V,2,0),"0") -> 0 | N9: กล่อง | O9: =+M9*C9 -> 0 | P9: =IFERROR(VLOOKUP(A9,'4'!U:V,2,0),"0") -> 0 | Q9: กล่อง | R9: =+P9*C9 -> 0 | S9: =IFERROR(VLOOKUP(A9,'5'!U:V,2,0),"0") -> 0 | T9: กล่อง | U9: =+S9*C9 -> 0 | V9: =IFERROR(VLOOKUP(A9,'6'!U:V,2,0),"0") -> 0 | W9: กล่อง | X9: =+V9*C9 -> 0 | Y9: =IFERROR(VLOOKUP(A9,'7'!U:V,2,0),"0") -> 0 | Z9: กล่อง | AA9: =+Y9*C9 -> 0 | AB9: =IFERROR(VLOOKUP(A9,'8'!U:V,2,0),"0") -> 0 | AC9: กล่อง | AD9: =+AB9*C9 -> 0 | AE9: =IFERROR(VLOOKUP(A9,'9'!U:V,2,0),"0") -> 0 | AF9: กล่อง | AG9: =+AE9*C9 -> 0 | AH9: =IFERROR(VLOOKUP(A9,'10'!U:V,2,0),"0") -> 0 | AI9: กล่อง | AJ9: =+AH9*C9 -> 0 | AK9: =IFERROR(VLOOKUP(A9,'11'!U:V,2,0),"0") -> 0 | AL9: กล่อง | AM9: =+AK9*C9 -> 0 | AN9: =IFERROR(VLOOKUP(A9,'12'!U:V,2,0),"0") -> 0 | AO9: กล่อง | AP9: =+AN9*C9 -> 0 | AQ9: =IFERROR(VLOOKUP(A9,'13'!U:V,2,0),"0") -> 1 | AR9: กล่อง | AS9: =+AQ9*C9 -> 22.02 | AT9: =IFERROR(VLOOKUP(A9,'14'!U:V,2,0),"0") -> 0 | AU9: กล่อง | AV9: =+AT9*C9 -> 0 | AW9: =IFERROR(VLOOKUP(A9,'15'!U:V,2,0),"0") -> 0 | AX9: กล่อง | AY9: =+AW9*C9 -> 0 | AZ9: =IFERROR(VLOOKUP(A9,'16'!U:V,2,0),"0") -> 0 | BA9: กล่อง | BB9: =+AZ9*C9 -> 0 | BC9: =IFERROR(VLOOKUP(A9,'17'!U:V,2,0),"0") -> 0 | BD9: กล่อง | BE9: =+BC9*C9 -> 0 | BF9: =IFERROR(VLOOKUP(A9,'18'!U:V,2,0),"0") -> 0 | BG9: กล่อง | BH9: =+BF9*C9 -> 0 | BI9: =IFERROR(VLOOKUP(A9,'19'!U:V,2,0),"0") -> 0 | BJ9: กล่อง | BK9: =+BI9*C9 -> 0 | BL9: =IFERROR(VLOOKUP(A9,'20'!U:V,2,0),"0") -> 0 | BM9: กล่อง | BN9: =+BL9*C9 -> 0 | BO9: =IFERROR(VLOOKUP(A9,'21'!U:V,2,0),"0") -> 0 | BP9: กล่อง | BQ9: =+BO9*C9 -> 0 | BR9: =IFERROR(VLOOKUP(A9,'22'!U:V,2,0),"0") -> 0 | BS9: กล่อง | BT9: =+BR9*C9 -> 0 | BU9: =IFERROR(VLOOKUP(A9,'23'!U:V,2,0),"0") -> 0 | BV9: กล่อง | BW9: =+BU9*C9 -> 0 | BX9: =IFERROR(VLOOKUP(A9,'24'!U:V,2,0),"0") -> 0 | BY9: กล่อง | BZ9: =+BX9*C9 -> 0 | CA9: =IFERROR(VLOOKUP(A9,'25'!U:V,2,0),"0") -> 0 | CB9: กล่อง | CC9: =+CA9*C9 -> 0 | CD9: =IFERROR(VLOOKUP(A9,'26'!U:V,2,0),"0") -> 1 | CE9: กล่อง | CF9: =+CD9*C9 -> 22.02 | CG9: =IFERROR(VLOOKUP(A9,'27'!U:V,2,0),"0") -> 0 | CH9: กล่อง | CI9: =+CG9*C9 -> 0 | CJ9: =IFERROR(VLOOKUP(A9,'28'!U:V,2,0),"0") -> 0 | CK9: กล่อง | CL9: =+CJ9*C9 -> 0 | CM9: =IFERROR(VLOOKUP(A9,'29'!U:V,2,0),"0") -> 0 | CN9: กล่อง | CO9: =+CM9*C9 -> 0 | CP9: =IFERROR(VLOOKUP(A9,'30'!U:V,2,0),"0") -> 0 | CQ9: กล่อง | CR9: =+CP9*C9 -> 0 | CS9: =IFERROR(VLOOKUP(A9,'31'!U:V,2,0),"0") -> 0 | CT9: กล่อง | CU9: =+CS9*C9 -> 0 | CV9: =IFERROR(VLOOKUP(A9,'เซต1-31'!V:W,2,0),"0") -> 0 | CW9: กล่อง | CX9: =+CV9*CO9 -> 0
A10: 1100003 | B10: เมอแรงก์กระปุก (เก็บไว้ได้ 60 วัน) | C10: 11.91 | D10: =+G10+J10+M10+P10+S10+V10+Y10+AB10+AE10+AH10+AK10+AN10+AQ10+AT10+AW10+AZ10+BC10+BF10+BI10+BL10+BO10+BR10+BU10+BX10+CA10+CD10+CG10+CJ10+CM10+CP10+CS10+CV10 -> 0 | E10: กระปุก | F10: =+D10*C10 -> 0 | G10: =IFERROR(VLOOKUP(A10,'1'!U:V,2,0),"0") -> 0 | H10: กระปุก | I10: =+G10*C10 -> 0 | J10: =IFERROR(VLOOKUP(A10,'2'!U:V,2,0),"0") -> 0 | K10: กระปุก | L10: =+J10*C10 -> 0 | M10: =IFERROR(VLOOKUP(A10,'3'!U:V,2,0),"0") -> 0 | N10: กระปุก | O10: =+M10*C10 -> 0 | P10: =IFERROR(VLOOKUP(A10,'4'!U:V,2,0),"0") -> 0 | Q10: กระปุก | R10: =+P10*C10 -> 0 | S10: =IFERROR(VLOOKUP(A10,'5'!U:V,2,0),"0") -> 0 | T10: กระปุก | U10: =+S10*C10 -> 0 | V10: =IFERROR(VLOOKUP(A10,'6'!U:V,2,0),"0") -> 0 | W10: กระปุก | X10: =+V10*C10 -> 0 | Y10: =IFERROR(VLOOKUP(A10,'7'!U:V,2,0),"0") -> 0 | Z10: กระปุก | AA10: =+Y10*C10 -> 0 | AB10: =IFERROR(VLOOKUP(A10,'8'!U:V,2,0),"0") -> 0 | AC10: กระปุก | AD10: =+AB10*C10 -> 0 | AE10: =IFERROR(VLOOKUP(A10,'9'!U:V,2,0),"0") -> 0 | AF10: กระปุก | AG10: =+AE10*C10 -> 0 | AH10: =IFERROR(VLOOKUP(A10,'10'!U:V,2,0),"0") -> 0 | AI10: กระปุก | AJ10: =+AH10*C10 -> 0 | AK10: =IFERROR(VLOOKUP(A10,'11'!U:V,2,0),"0") -> 0 | AL10: กระปุก | AM10: =+AK10*C10 -> 0 | AN10: =IFERROR(VLOOKUP(A10,'12'!U:V,2,0),"0") -> 0 | AO10: กระปุก | AP10: =+AN10*C10 -> 0 | AQ10: =IFERROR(VLOOKUP(A10,'13'!U:V,2,0),"0") -> 0 | AR10: กระปุก | AS10: =+AQ10*C10 -> 0 | AT10: =IFERROR(VLOOKUP(A10,'14'!U:V,2,0),"0") -> 0 | AU10: กระปุก | AV10: =+AT10*C10 -> 0 | AW10: =IFERROR(VLOOKUP(A10,'15'!U:V,2,0),"0") -> 0 | AX10: กระปุก | AY10: =+AW10*C10 -> 0 | AZ10: =IFERROR(VLOOKUP(A10,'16'!U:V,2,0),"0") -> 0 | BA10: กระปุก | BB10: =+AZ10*C10 -> 0 | BC10: =IFERROR(VLOOKUP(A10,'17'!U:V,2,0),"0") -> 0 | BD10: กระปุก | BE10: =+BC10*C10 -> 0 | BF10: =IFERROR(VLOOKUP(A10,'18'!U:V,2,0),"0") -> 0 | BG10: กระปุก | BH10: =+BF10*C10 -> 0 | BI10: =IFERROR(VLOOKUP(A10,'19'!U:V,2,0),"0") -> 0 | BJ10: กระปุก | BK10: =+BI10*C10 -> 0 | BL10: =IFERROR(VLOOKUP(A10,'20'!U:V,2,0),"0") -> 0 | BM10: กระปุก | BN10: =+BL10*C10 -> 0 | BO10: =IFERROR(VLOOKUP(A10,'21'!U:V,2,0),"0") -> 0 | BP10: กระปุก | BQ10: =+BO10*C10 -> 0 | BR10: =IFERROR(VLOOKUP(A10,'22'!U:V,2,0),"0") -> 0 | BS10: กระปุก | BT10: =+BR10*C10 -> 0 | BU10: =IFERROR(VLOOKUP(A10,'23'!U:V,2,0),"0") -> 0 | BV10: กระปุก | BW10: =+BU10*C10 -> 0 | BX10: =IFERROR(VLOOKUP(A10,'24'!U:V,2,0),"0") -> 0 | BY10: กระปุก | BZ10: =+BX10*C10 -> 0 | CA10: =IFERROR(VLOOKUP(A10,'25'!U:V,2,0),"0") -> 0 | CB10: กระปุก | CC10: =+CA10*C10 -> 0 | CD10: =IFERROR(VLOOKUP(A10,'26'!U:V,2,0),"0") -> 0 | CE10: กระปุก | CF10: =+CD10*C10 -> 0 | CG10: =IFERROR(VLOOKUP(A10,'27'!U:V,2,0),"0") -> 0 | CH10: กระปุก | CI10: =+CG10*C10 -> 0 | CJ10: =IFERROR(VLOOKUP(A10,'28'!U:V,2,0),"0") -> 0 | CK10: กระปุก | CL10: =+CJ10*C10 -> 0 | CM10: =IFERROR(VLOOKUP(A10,'29'!U:V,2,0),"0") -> 0 | CN10: กระปุก | CO10: =+CM10*C10 -> 0 | CP10: =IFERROR(VLOOKUP(A10,'30'!U:V,2,0),"0") -> 0 | CQ10: กระปุก | CR10: =+CP10*C10 -> 0 | CS10: =IFERROR(VLOOKUP(A10,'31'!U:V,2,0),"0") -> 0 | CT10: กระปุก | CU10: =+CS10*C10 -> 0 | CV10: =IFERROR(VLOOKUP(A10,'เซต1-31'!V:W,2,0),"0") -> 0 | CW10: กระปุก | CX10: =+CV10*CO10 -> 0
A11: 1100004 | B11: เมอแรงค์ อัลม่อนเม็ดมะม่วงหิมพานต์ (ถุง) | C11: 13.03 | D11: =+G11+J11+M11+P11+S11+V11+Y11+AB11+AE11+AH11+AK11+AN11+AQ11+AT11+AW11+AZ11+BC11+BF11+BI11+BL11+BO11+BR11+BU11+BX11+CA11+CD11+CG11+CJ11+CM11+CP11+CS11+CV11 -> 0 | E11: ถุง | F11: =+D11*C11 -> 0 | G11: =IFERROR(VLOOKUP(A11,'1'!U:V,2,0),"0") -> 0 | H11: ถุง | I11: =+G11*C11 -> 0 | J11: =IFERROR(VLOOKUP(A11,'2'!U:V,2,0),"0") -> 0 | K11: ถุง | L11: =+J11*C11 -> 0 | M11: =IFERROR(VLOOKUP(A11,'3'!U:V,2,0),"0") -> 0 | N11: ถุง | O11: =+M11*C11 -> 0 | P11: =IFERROR(VLOOKUP(A11,'4'!U:V,2,0),"0") -> 0 | Q11: ถุง | R11: =+P11*C11 -> 0 | S11: =IFERROR(VLOOKUP(A11,'5'!U:V,2,0),"0") -> 0 | T11: ถุง | U11: =+S11*C11 -> 0 | V11: =IFERROR(VLOOKUP(A11,'6'!U:V,2,0),"0") -> 0 | W11: ถุง | X11: =+V11*C11 -> 0 | Y11: =IFERROR(VLOOKUP(A11,'7'!U:V,2,0),"0") -> 0 | Z11: ถุง | AA11: =+Y11*C11 -> 0 | AB11: =IFERROR(VLOOKUP(A11,'8'!U:V,2,0),"0") -> 0 | AC11: ถุง | AD11: =+AB11*C11 -> 0 | AE11: =IFERROR(VLOOKUP(A11,'9'!U:V,2,0),"0") -> 0 | AF11: ถุง | AG11: =+AE11*C11 -> 0 | AH11: =IFERROR(VLOOKUP(A11,'10'!U:V,2,0),"0") -> 0 | AI11: ถุง | AJ11: =+AH11*C11 -> 0 | AK11: =IFERROR(VLOOKUP(A11,'11'!U:V,2,0),"0") -> 0 | AL11: ถุง | AM11: =+AK11*C11 -> 0 | AN11: =IFERROR(VLOOKUP(A11,'12'!U:V,2,0),"0") -> 0 | AO11: ถุง | AP11: =+AN11*C11 -> 0 | AQ11: =IFERROR(VLOOKUP(A11,'13'!U:V,2,0),"0") -> 0 | AR11: ถุง | AS11: =+AQ11*C11 -> 0 | AT11: =IFERROR(VLOOKUP(A11,'14'!U:V,2,0),"0") -> 0 | AU11: ถุง | AV11: =+AT11*C11 -> 0 | AW11: =IFERROR(VLOOKUP(A11,'15'!U:V,2,0),"0") -> 0 | AX11: ถุง | AY11: =+AW11*C11 -> 0 | AZ11: =IFERROR(VLOOKUP(A11,'16'!U:V,2,0),"0") -> 0 | BA11: ถุง | BB11: =+AZ11*C11 -> 0 | BC11: =IFERROR(VLOOKUP(A11,'17'!U:V,2,0),"0") -> 0 | BD11: ถุง | BE11: =+BC11*C11 -> 0 | BF11: =IFERROR(VLOOKUP(A11,'18'!U:V,2,0),"0") -> 0 | BG11: ถุง | BH11: =+BF11*C11 -> 0 | BI11: =IFERROR(VLOOKUP(A11,'19'!U:V,2,0),"0") -> 0 | BJ11: ถุง | BK11: =+BI11*C11 -> 0 | BL11: =IFERROR(VLOOKUP(A11,'20'!U:V,2,0),"0") -> 0 | BM11: ถุง | BN11: =+BL11*C11 -> 0 | BO11: =IFERROR(VLOOKUP(A11,'21'!U:V,2,0),"0") -> 0 | BP11: ถุง | BQ11: =+BO11*C11 -> 0 | BR11: =IFERROR(VLOOKUP(A11,'22'!U:V,2,0),"0") -> 0 | BS11: ถุง | BT11: =+BR11*C11 -> 0 | BU11: =IFERROR(VLOOKUP(A11,'23'!U:V,2,0),"0") -> 0 | BV11: ถุง | BW11: =+BU11*C11 -> 0 | BX11: =IFERROR(VLOOKUP(A11,'24'!U:V,2,0),"0") -> 0 | BY11: ถุง | BZ11: =+BX11*C11 -> 0 | CA11: =IFERROR(VLOOKUP(A11,'25'!U:V,2,0),"0") -> 0 | CB11: ถุง | CC11: =+CA11*C11 -> 0 | CD11: =IFERROR(VLOOKUP(A11,'26'!U:V,2,0),"0") -> 0 | CE11: ถุง | CF11: =+CD11*C11 -> 0 | CG11: =IFERROR(VLOOKUP(A11,'27'!U:V,2,0),"0") -> 0 | CH11: ถุง | CI11: =+CG11*C11 -> 0 | CJ11: =IFERROR(VLOOKUP(A11,'28'!U:V,2,0),"0") -> 0 | CK11: ถุง | CL11: =+CJ11*C11 -> 0 | CM11: =IFERROR(VLOOKUP(A11,'29'!U:V,2,0),"0") -> 0 | CN11: ถุง | CO11: =+CM11*C11 -> 0 | CP11: =IFERROR(VLOOKUP(A11,'30'!U:V,2,0),"0") -> 0 | CQ11: ถุง | CR11: =+CP11*C11 -> 0 | CS11: =IFERROR(VLOOKUP(A11,'31'!U:V,2,0),"0") -> 0 | CT11: ถุง | CU11: =+CS11*C11 -> 0 | CV11: =IFERROR(VLOOKUP(A11,'เซต1-31'!V:W,2,0),"0") -> 0 | CW11: ถุง | CX11: =+CV11*CO11 -> 0
A12: 1111001 | B12: ชิฟฟอนไม่มีไส้เเบบเเยกชิ้น เลือกรสชาติได้ (คละรส) | C12: 4.33 | D12: =+G12+J12+M12+P12+S12+V12+Y12+AB12+AE12+AH12+AK12+AN12+AQ12+AT12+AW12+AZ12+BC12+BF12+BI12+BL12+BO12+BR12+BU12+BX12+CA12+CD12+CG12+CJ12+CM12+CP12+CS12+CV12 -> 2530 | E12: ชิ้น | F12: =+D12*C12 -> 10954.9 | G12: =IFERROR(VLOOKUP(A12,'1'!U:V,2,0),"0") -> 0 | H12: ชิ้น | I12: =+G12*C12 -> 0 | J12: =IFERROR(VLOOKUP(A12,'2'!U:V,2,0),"0") -> 150 | K12: ชิ้น | L12: =+J12*C12 -> 649.5 | M12: =IFERROR(VLOOKUP(A12,'3'!U:V,2,0),"0") -> 50 | N12: ชิ้น | O12: =+M12*C12 -> 216.5 | P12: =IFERROR(VLOOKUP(A12,'4'!U:V,2,0),"0") -> 0 | Q12: ชิ้น | R12: =+P12*C12 -> 0 | S12: =IFERROR(VLOOKUP(A12,'5'!U:V,2,0),"0") -> 0 | T12: ชิ้น | U12: =+S12*C12 -> 0 | V12: =IFERROR(VLOOKUP(A12,'6'!U:V,2,0),"0") -> 20 | W12: ชิ้น | X12: =+V12*C12 -> 86.6 | Y12: =IFERROR(VLOOKUP(A12,'7'!U:V,2,0),"0") -> 290 | Z12: ชิ้น | AA12: =+Y12*C12 -> 1255.7 | AB12: =IFERROR(VLOOKUP(A12,'8'!U:V,2,0),"0") -> 200 | AC12: ชิ้น | AD12: =+AB12*C12 -> 866 | AE12: =IFERROR(VLOOKUP(A12,'9'!U:V,2,0),"0") -> 90 | AF12: ชิ้น | AG12: =+AE12*C12 -> 389.7 | AH12: =IFERROR(VLOOKUP(A12,'10'!U:V,2,0),"0") -> 20 | AI12: ชิ้น | AJ12: =+AH12*C12 -> 86.6 | AK12: =IFERROR(VLOOKUP(A12,'11'!U:V,2,0),"0") -> 0 | AL12: ชิ้น | AM12: =+AK12*C12 -> 0 | AN12: =IFERROR(VLOOKUP(A12,'12'!U:V,2,0),"0") -> 0 | AO12: ชิ้น | AP12: =+AN12*C12 -> 0 | AQ12: =IFERROR(VLOOKUP(A12,'13'!U:V,2,0),"0") -> 120 | AR12: ชิ้น | AS12: =+AQ12*C12 -> 519.6 | AT12: =IFERROR(VLOOKUP(A12,'14'!U:V,2,0),"0") -> 50 | AU12: ชิ้น | AV12: =+AT12*C12 -> 216.5 | AW12: =IFERROR(VLOOKUP(A12,'15'!U:V,2,0),"0") -> 90 | AX12: ชิ้น | AY12: =+AW12*C12 -> 389.7 | AZ12: =IFERROR(VLOOKUP(A12,'16'!U:V,2,0),"0") -> 20 | BA12: ชิ้น | BB12: =+AZ12*C12 -> 86.6 | BC12: =IFERROR(VLOOKUP(A12,'17'!U:V,2,0),"0") -> 90 | BD12: ชิ้น | BE12: =+BC12*C12 -> 389.7 | BF12: =IFERROR(VLOOKUP(A12,'18'!U:V,2,0),"0") -> 120 | BG12: ชิ้น | BH12: =+BF12*C12 -> 519.6 | BI12: =IFERROR(VLOOKUP(A12,'19'!U:V,2,0),"0") -> 30 | BJ12: ชิ้น | BK12: =+BI12*C12 -> 129.9 | BL12: =IFERROR(VLOOKUP(A12,'20'!U:V,2,0),"0") -> 220 | BM12: ชิ้น | BN12: =+BL12*C12 -> 952.6 | BO12: =IFERROR(VLOOKUP(A12,'21'!U:V,2,0),"0") -> 70 | BP12: ชิ้น | BQ12: =+BO12*C12 -> 303.1 | BR12: =IFERROR(VLOOKUP(A12,'22'!U:V,2,0),"0") -> 20 | BS12: ชิ้น | BT12: =+BR12*C12 -> 86.6 | BU12: =IFERROR(VLOOKUP(A12,'23'!U:V,2,0),"0") -> 70 | BV12: ชิ้น | BW12: =+BU12*C12 -> 303.1 | BX12: =IFERROR(VLOOKUP(A12,'24'!U:V,2,0),"0") -> 30 | BY12: ชิ้น | BZ12: =+BX12*C12 -> 129.9 | CA12: =IFERROR(VLOOKUP(A12,'25'!U:V,2,0),"0") -> 170 | CB12: ชิ้น | CC12: =+CA12*C12 -> 736.1 | CD12: =IFERROR(VLOOKUP(A12,'26'!U:V,2,0),"0") -> 20 | CE12: ชิ้น | CF12: =+CD12*C12 -> 86.6 | CG12: =IFERROR(VLOOKUP(A12,'27'!U:V,2,0),"0") -> 190 | CH12: ชิ้น | CI12: =+CG12*C12 -> 822.7 | CJ12: =IFERROR(VLOOKUP(A12,'28'!U:V,2,0),"0") -> 200 | CK12: ชิ้น | CL12: =+CJ12*C12 -> 866 | CM12: =IFERROR(VLOOKUP(A12,'29'!U:V,2,0),"0") -> 70 | CN12: ชิ้น | CO12: =+CM12*C12 -> 303.1 | CP12: =IFERROR(VLOOKUP(A12,'30'!U:V,2,0),"0") -> 60 | CQ12: ชิ้น | CR12: =+CP12*C12 -> 259.8 | CS12: =IFERROR(VLOOKUP(A12,'31'!U:V,2,0),"0") -> 70 | CT12: ชิ้น | CU12: =+CS12*C12 -> 303.1 | CV12: =IFERROR(VLOOKUP(A12,'เซต1-31'!V:W,2,0),"0") -> 0 | CW12: ชิ้น | CX12: =+CV12*CO12 -> 0
A13: 1111002 | B13: ชิฟฟ่อนไม่มีไส้ แบบกล่อง8ชิ้น รวมรส | C13: 37.17 | D13: =+G13+J13+M13+P13+S13+V13+Y13+AB13+AE13+AH13+AK13+AN13+AQ13+AT13+AW13+AZ13+BC13+BF13+BI13+BL13+BO13+BR13+BU13+BX13+CA13+CD13+CG13+CJ13+CM13+CP13+CS13+CV13 -> 1819 | E13: กล่อง | F13: =+D13*C13 -> 67612.23 | G13: =IFERROR(VLOOKUP(A13,'1'!U:V,2,0),"0") -> 57 | H13: กล่อง | I13: =+G13*C13 -> 2118.69 | J13: =IFERROR(VLOOKUP(A13,'2'!U:V,2,0),"0") -> 21 | K13: กล่อง | L13: =+J13*C13 -> 780.57 | M13: =IFERROR(VLOOKUP(A13,'3'!U:V,2,0),"0") -> 60 | N13: กล่อง | O13: =+M13*C13 -> 2230.2 | P13: =IFERROR(VLOOKUP(A13,'4'!U:V,2,0),"0") -> 56 | Q13: กล่อง | R13: =+P13*C13 -> 2081.52 | S13: =IFERROR(VLOOKUP(A13,'5'!U:V,2,0),"0") -> 69 | T13: กล่อง | U13: =+S13*C13 -> 2564.73 | V13: =IFERROR(VLOOKUP(A13,'6'!U:V,2,0),"0") -> 103 | W13: กล่อง | X13: =+V13*C13 -> 3828.51 | Y13: =IFERROR(VLOOKUP(A13,'7'!U:V,2,0),"0") -> 47 | Z13: กล่อง | AA13: =+Y13*C13 -> 1746.99 | AB13: =IFERROR(VLOOKUP(A13,'8'!U:V,2,0),"0") -> 42 | AC13: กล่อง | AD13: =+AB13*C13 -> 1561.14 | AE13: =IFERROR(VLOOKUP(A13,'9'!U:V,2,0),"0") -> 72 | AF13: กล่อง | AG13: =+AE13*C13 -> 2676.24 | AH13: =IFERROR(VLOOKUP(A13,'10'!U:V,2,0),"0") -> 35 | AI13: กล่อง | AJ13: =+AH13*C13 -> 1300.95 | AK13: =IFERROR(VLOOKUP(A13,'11'!U:V,2,0),"0") -> 60 | AL13: กล่อง | AM13: =+AK13*C13 -> 2230.2 | AN13: =IFERROR(VLOOKUP(A13,'12'!U:V,2,0),"0") -> 29 | AO13: กล่อง | AP13: =+AN13*C13 -> 1077.93 | AQ13: =IFERROR(VLOOKUP(A13,'13'!U:V,2,0),"0") -> 57 | AR13: กล่อง | AS13: =+AQ13*C13 -> 2118.69 | AT13: =IFERROR(VLOOKUP(A13,'14'!U:V,2,0),"0") -> 56 | AU13: กล่อง | AV13: =+AT13*C13 -> 2081.52 | AW13: =IFERROR(VLOOKUP(A13,'15'!U:V,2,0),"0") -> 4 | AX13: กล่อง | AY13: =+AW13*C13 -> 148.68 | AZ13: =IFERROR(VLOOKUP(A13,'16'!U:V,2,0),"0") -> 32 | BA13: กล่อง | BB13: =+AZ13*C13 -> 1189.44 | BC13: =IFERROR(VLOOKUP(A13,'17'!U:V,2,0),"0") -> 56 | BD13: กล่อง | BE13: =+BC13*C13 -> 2081.52 | BF13: =IFERROR(VLOOKUP(A13,'18'!U:V,2,0),"0") -> 37 | BG13: กล่อง | BH13: =+BF13*C13 -> 1375.29 | BI13: =IFERROR(VLOOKUP(A13,'19'!U:V,2,0),"0") -> 92 | BJ13: กล่อง | BK13: =+BI13*C13 -> 3419.64 | BL13: =IFERROR(VLOOKUP(A13,'20'!U:V,2,0),"0") -> 67 | BM13: กล่อง | BN13: =+BL13*C13 -> 2490.39 | BO13: =IFERROR(VLOOKUP(A13,'21'!U:V,2,0),"0") -> 57 | BP13: กล่อง | BQ13: =+BO13*C13 -> 2118.69 | BR13: =IFERROR(VLOOKUP(A13,'22'!U:V,2,0),"0") -> 66 | BS13: กล่อง | BT13: =+BR13*C13 -> 2453.22 | BU13: =IFERROR(VLOOKUP(A13,'23'!U:V,2,0),"0") -> 33 | BV13: กล่อง | BW13: =+BU13*C13 -> 1226.61 | BX13: =IFERROR(VLOOKUP(A13,'24'!U:V,2,0),"0") -> 121 | BY13: กล่อง | BZ13: =+BX13*C13 -> 4497.57 | CA13: =IFERROR(VLOOKUP(A13,'25'!U:V,2,0),"0") -> 64 | CB13: กล่อง | CC13: =+CA13*C13 -> 2378.88 | CD13: =IFERROR(VLOOKUP(A13,'26'!U:V,2,0),"0") -> 83 | CE13: กล่อง | CF13: =+CD13*C13 -> 3085.11 | CG13: =IFERROR(VLOOKUP(A13,'27'!U:V,2,0),"0") -> 62 | CH13: กล่อง | CI13: =+CG13*C13 -> 2304.54 | CJ13: =IFERROR(VLOOKUP(A13,'28'!U:V,2,0),"0") -> 78 | CK13: กล่อง | CL13: =+CJ13*C13 -> 2899.26 | CM13: =IFERROR(VLOOKUP(A13,'29'!U:V,2,0),"0") -> 32 | CN13: กล่อง | CO13: =+CM13*C13 -> 1189.44 | CP13: =IFERROR(VLOOKUP(A13,'30'!U:V,2,0),"0") -> 99 | CQ13: กล่อง | CR13: =+CP13*C13 -> 3679.83 | CS13: =IFERROR(VLOOKUP(A13,'31'!U:V,2,0),"0") -> 72 | CT13: กล่อง | CU13: =+CS13*C13 -> 2676.24 | CV13: =IFERROR(VLOOKUP(A13,'เซต1-31'!V:W,2,0),"0") -> 0 | CW13: กล่อง | CX13: =+CV13*CO13 -> 0
A14: 1111002-A | B14: ชิฟฟ่อนไม่มีไส้ แบบกล่อง8ชิ้น รวมรส (รวมรส) | C14: 37.17 | D14: =+G14+J14+M14+P14+S14+V14+Y14+AB14+AE14+AH14+AK14+AN14+AQ14+AT14+AW14+AZ14+BC14+BF14+BI14+BL14+BO14+BR14+BU14+BX14+CA14+CD14+CG14+CJ14+CM14+CP14+CS14+CV14 -> 0 | E14: กล่อง | F14: =+D14*C14 -> 0 | G14: =IFERROR(VLOOKUP(A14,'1'!U:V,2,0),"0") -> 0 | H14: กล่อง | I14: =+G14*C14 -> 0 | J14: =IFERROR(VLOOKUP(A14,'2'!U:V,2,0),"0") -> 0 | K14: กล่อง | L14: =+J14*C14 -> 0 | M14: =IFERROR(VLOOKUP(A14,'3'!U:V,2,0),"0") -> 0 | N14: กล่อง | O14: =+M14*C14 -> 0 | P14: =IFERROR(VLOOKUP(A14,'4'!U:V,2,0),"0") -> 0 | Q14: กล่อง | R14: =+P14*C14 -> 0 | S14: =IFERROR(VLOOKUP(A14,'5'!U:V,2,0),"0") -> 0 | T14: กล่อง | U14: =+S14*C14 -> 0 | V14: =IFERROR(VLOOKUP(A14,'6'!U:V,2,0),"0") -> 0 | W14: กล่อง | X14: =+V14*C14 -> 0 | Y14: =IFERROR(VLOOKUP(A14,'7'!U:V,2,0),"0") -> 0 | Z14: กล่อง | AA14: =+Y14*C14 -> 0 | AB14: =IFERROR(VLOOKUP(A14,'8'!U:V,2,0),"0") -> 0 | AC14: กล่อง | AD14: =+AB14*C14 -> 0 | AE14: =IFERROR(VLOOKUP(A14,'9'!U:V,2,0),"0") -> 0 | AF14: กล่อง | AG14: =+AE14*C14 -> 0 | AH14: =IFERROR(VLOOKUP(A14,'10'!U:V,2,0),"0") -> 0 | AI14: กล่อง | AJ14: =+AH14*C14 -> 0 | AK14: =IFERROR(VLOOKUP(A14,'11'!U:V,2,0),"0") -> 0 | AL14: กล่อง | AM14: =+AK14*C14 -> 0 | AN14: =IFERROR(VLOOKUP(A14,'12'!U:V,2,0),"0") -> 0 | AO14: กล่อง | AP14: =+AN14*C14 -> 0 | AQ14: =IFERROR(VLOOKUP(A14,'13'!U:V,2,0),"0") -> 0 | AR14: กล่อง | AS14: =+AQ14*C14 -> 0 | AT14: =IFERROR(VLOOKUP(A14,'14'!U:V,2,0),"0") -> 0 | AU14: กล่อง | AV14: =+AT14*C14 -> 0 | AW14: =IFERROR(VLOOKUP(A14,'15'!U:V,2,0),"0") -> 0 | AX14: กล่อง | AY14: =+AW14*C14 -> 0 | AZ14: =IFERROR(VLOOKUP(A14,'16'!U:V,2,0),"0") -> 0 | BA14: กล่อง | BB14: =+AZ14*C14 -> 0 | BC14: =IFERROR(VLOOKUP(A14,'17'!U:V,2,0),"0") -> 0 | BD14: กล่อง | BE14: =+BC14*C14 -> 0 | BF14: =IFERROR(VLOOKUP(A14,'18'!U:V,2,0),"0") -> 0 | BG14: กล่อง | BH14: =+BF14*C14 -> 0 | BI14: =IFERROR(VLOOKUP(A14,'19'!U:V,2,0),"0") -> 0 | BJ14: กล่อง | BK14: =+BI14*C14 -> 0 | BL14: =IFERROR(VLOOKUP(A14,'20'!U:V,2,0),"0") -> 0 | BM14: กล่อง | BN14: =+BL14*C14 -> 0 | BO14: =IFERROR(VLOOKUP(A14,'21'!U:V,2,0),"0") -> 0 | BP14: กล่อง | BQ14: =+BO14*C14 -> 0 | BR14: =IFERROR(VLOOKUP(A14,'22'!U:V,2,0),"0") -> 0 | BS14: กล่อง | BT14: =+BR14*C14 -> 0 | BU14: =IFERROR(VLOOKUP(A14,'23'!U:V,2,0),"0") -> 0 | BV14: กล่อง | BW14: =+BU14*C14 -> 0 | BX14: =IFERROR(VLOOKUP(A14,'24'!U:V,2,0),"0") -> 0 | BY14: กล่อง | BZ14: =+BX14*C14 -> 0 | CA14: =IFERROR(VLOOKUP(A14,'25'!U:V,2,0),"0") -> 0 | CB14: กล่อง | CC14: =+CA14*C14 -> 0 | CD14: =IFERROR(VLOOKUP(A14,'26'!U:V,2,0),"0") -> 0 | CE14: กล่อง | CF14: =+CD14*C14 -> 0 | CG14: =IFERROR(VLOOKUP(A14,'27'!U:V,2,0),"0") -> 0 | CH14: กล่อง | CI14: =+CG14*C14 -> 0 | CJ14: =IFERROR(VLOOKUP(A14,'28'!U:V,2,0),"0") -> 0 | CK14: กล่อง | CL14: =+CJ14*C14 -> 0 | CM14: =IFERROR(VLOOKUP(A14,'29'!U:V,2,0),"0") -> 0 | CN14: กล่อง | CO14: =+CM14*C14 -> 0 | CP14: =IFERROR(VLOOKUP(A14,'30'!U:V,2,0),"0") -> 0 | CQ14: กล่อง | CR14: =+CP14*C14 -> 0 | CS14: =IFERROR(VLOOKUP(A14,'31'!U:V,2,0),"0") -> 0 | CT14: กล่อง | CU14: =+CS14*C14 -> 0 | CV14: =IFERROR(VLOOKUP(A14,'เซต1-31'!V:W,2,0),"0") -> 0 | CW14: กล่อง | CX14: =+CV14*CO14 -> 0
A15: 1111002-M | B15: ชิฟฟ่อนรวมรส แบบไม่มีไส้ 1 กล่องมี 8 ชิ้น เก็บได้ 20 วัน คละรสชาติให้ นุ่ม หอม อร่อย วรรณวนัช | C15: 37.17 | D15: =+G15+J15+M15+P15+S15+V15+Y15+AB15+AE15+AH15+AK15+AN15+AQ15+AT15+AW15+AZ15+BC15+BF15+BI15+BL15+BO15+BR15+BU15+BX15+CA15+CD15+CG15+CJ15+CM15+CP15+CS15+CV15 -> 0 | E15: กล่อง | F15: =+D15*C15 -> 0 | G15: =IFERROR(VLOOKUP(A15,'1'!U:V,2,0),"0") -> 0 | H15: กล่อง | I15: =+G15*C15 -> 0 | J15: =IFERROR(VLOOKUP(A15,'2'!U:V,2,0),"0") -> 0 | K15: กล่อง | L15: =+J15*C15 -> 0 | M15: =IFERROR(VLOOKUP(A15,'3'!U:V,2,0),"0") -> 0 | N15: กล่อง | O15: =+M15*C15 -> 0 | P15: =IFERROR(VLOOKUP(A15,'4'!U:V,2,0),"0") -> 0 | Q15: กล่อง | R15: =+P15*C15 -> 0 | S15: =IFERROR(VLOOKUP(A15,'5'!U:V,2,0),"0") -> 0 | T15: กล่อง | U15: =+S15*C15 -> 0 | V15: =IFERROR(VLOOKUP(A15,'6'!U:V,2,0),"0") -> 0 | W15: กล่อง | X15: =+V15*C15 -> 0 | Y15: =IFERROR(VLOOKUP(A15,'7'!U:V,2,0),"0") -> 0 | Z15: กล่อง | AA15: =+Y15*C15 -> 0 | AB15: =IFERROR(VLOOKUP(A15,'8'!U:V,2,0),"0") -> 0 | AC15: กล่อง | AD15: =+AB15*C15 -> 0 | AE15: =IFERROR(VLOOKUP(A15,'9'!U:V,2,0),"0") -> 0 | AF15: กล่อง | AG15: =+AE15*C15 -> 0 | AH15: =IFERROR(VLOOKUP(A15,'10'!U:V,2,0),"0") -> 0 | AI15: กล่อง | AJ15: =+AH15*C15 -> 0 | AK15: =IFERROR(VLOOKUP(A15,'11'!U:V,2,0),"0") -> 0 | AL15: กล่อง | AM15: =+AK15*C15 -> 0 | AN15: =IFERROR(VLOOKUP(A15,'12'!U:V,2,0),"0") -> 0 | AO15: กล่อง | AP15: =+AN15*C15 -> 0 | AQ15: =IFERROR(VLOOKUP(A15,'13'!U:V,2,0),"0") -> 0 | AR15: กล่อง | AS15: =+AQ15*C15 -> 0 | AT15: =IFERROR(VLOOKUP(A15,'14'!U:V,2,0),"0") -> 0 | AU15: กล่อง | AV15: =+AT15*C15 -> 0 | AW15: =IFERROR(VLOOKUP(A15,'15'!U:V,2,0),"0") -> 0 | AX15: กล่อง | AY15: =+AW15*C15 -> 0 | AZ15: =IFERROR(VLOOKUP(A15,'16'!U:V,2,0),"0") -> 0 | BA15: กล่อง | BB15: =+AZ15*C15 -> 0 | BC15: =IFERROR(VLOOKUP(A15,'17'!U:V,2,0),"0") -> 0 | BD15: กล่อง | BE15: =+BC15*C15 -> 0 | BF15: =IFERROR(VLOOKUP(A15,'18'!U:V,2,0),"0") -> 0 | BG15: กล่อง | BH15: =+BF15*C15 -> 0 | BI15: =IFERROR(VLOOKUP(A15,'19'!U:V,2,0),"0") -> 0 | BJ15: กล่อง | BK15: =+BI15*C15 -> 0 | BL15: =IFERROR(VLOOKUP(A15,'20'!U:V,2,0),"0") -> 0 | BM15: กล่อง | BN15: =+BL15*C15 -> 0 | BO15: =IFERROR(VLOOKUP(A15,'21'!U:V,2,0),"0") -> 0 | BP15: กล่อง | BQ15: =+BO15*C15 -> 0 | BR15: =IFERROR(VLOOKUP(A15,'22'!U:V,2,0),"0") -> 0 | BS15: กล่อง | BT15: =+BR15*C15 -> 0 | BU15: =IFERROR(VLOOKUP(A15,'23'!U:V,2,0),"0") -> 0 | BV15: กล่อง | BW15: =+BU15*C15 -> 0 | BX15: =IFERROR(VLOOKUP(A15,'24'!U:V,2,0),"0") -> 0 | BY15: กล่อง | BZ15: =+BX15*C15 -> 0 | CA15: =IFERROR(VLOOKUP(A15,'25'!U:V,2,0),"0") -> 0 | CB15: กล่อง | CC15: =+CA15*C15 -> 0 | CD15: =IFERROR(VLOOKUP(A15,'26'!U:V,2,0),"0") -> 0 | CE15: กล่อง | CF15: =+CD15*C15 -> 0 | CG15: =IFERROR(VLOOKUP(A15,'27'!U:V,2,0),"0") -> 0 | CH15: กล่อง | CI15: =+CG15*C15 -> 0 | CJ15: =IFERROR(VLOOKUP(A15,'28'!U:V,2,0),"0") -> 0 | CK15: กล่อง | CL15: =+CJ15*C15 -> 0 | CM15: =IFERROR(VLOOKUP(A15,'29'!U:V,2,0),"0") -> 0 | CN15: กล่อง | CO15: =+CM15*C15 -> 0 | CP15: =IFERROR(VLOOKUP(A15,'30'!U:V,2,0),"0") -> 0 | CQ15: กล่อง | CR15: =+CP15*C15 -> 0 | CS15: =IFERROR(VLOOKUP(A15,'31'!U:V,2,0),"0") -> 0 | CT15: กล่อง | CU15: =+CS15*C15 -> 0 | CV15: =IFERROR(VLOOKUP(A15,'เซต1-31'!V:W,2,0),"0") -> 0 | CW15: กล่อง | CX15: =+CV15*CO15 -> 0
A16: 1111008 | B16: ชิฟฟ่อน สอดไส้แยม ขนาด3 ชิ้น มีรสให้เลือก 7 รส (รวมรส) | C16: 11.38 | D16: =+G16+J16+M16+P16+S16+V16+Y16+AB16+AE16+AH16+AK16+AN16+AQ16+AT16+AW16+AZ16+BC16+BF16+BI16+BL16+BO16+BR16+BU16+BX16+CA16+CD16+CG16+CJ16+CM16+CP16+CS16+CV16 -> 1044 | E16: กล่อง | F16: =+D16*C16 -> 11880.72 | G16: =IFERROR(VLOOKUP(A16,'1'!U:V,2,0),"0") -> 27 | H16: กล่อง | I16: =+G16*C16 -> 307.26 | J16: =IFERROR(VLOOKUP(A16,'2'!U:V,2,0),"0") -> 3 | K16: กล่อง | L16: =+J16*C16 -> 34.14 | M16: =IFERROR(VLOOKUP(A16,'3'!U:V,2,0),"0") -> 12 | N16: กล่อง | O16: =+M16*C16 -> 136.56 | P16: =IFERROR(VLOOKUP(A16,'4'!U:V,2,0),"0") -> 39 | Q16: กล่อง | R16: =+P16*C16 -> 443.82 | S16: =IFERROR(VLOOKUP(A16,'5'!U:V,2,0),"0") -> 79 | T16: กล่อง | U16: =+S16*C16 -> 899.02 | V16: =IFERROR(VLOOKUP(A16,'6'!U:V,2,0),"0") -> 54 | W16: กล่อง | X16: =+V16*C16 -> 614.52 | Y16: =IFERROR(VLOOKUP(A16,'7'!U:V,2,0),"0") -> 66 | Z16: กล่อง | AA16: =+Y16*C16 -> 751.08 | AB16: =IFERROR(VLOOKUP(A16,'8'!U:V,2,0),"0") -> 18 | AC16: กล่อง | AD16: =+AB16*C16 -> 204.84 | AE16: =IFERROR(VLOOKUP(A16,'9'!U:V,2,0),"0") -> 3 | AF16: กล่อง | AG16: =+AE16*C16 -> 34.14 | AH16: =IFERROR(VLOOKUP(A16,'10'!U:V,2,0),"0") -> 32 | AI16: กล่อง | AJ16: =+AH16*C16 -> 364.16 | AK16: =IFERROR(VLOOKUP(A16,'11'!U:V,2,0),"0") -> 25 | AL16: กล่อง | AM16: =+AK16*C16 -> 284.5 | AN16: =IFERROR(VLOOKUP(A16,'12'!U:V,2,0),"0") -> 30 | AO16: กล่อง | AP16: =+AN16*C16 -> 341.4 | AQ16: =IFERROR(VLOOKUP(A16,'13'!U:V,2,0),"0") -> 24 | AR16: กล่อง | AS16: =+AQ16*C16 -> 273.12 | AT16: =IFERROR(VLOOKUP(A16,'14'!U:V,2,0),"0") -> 18 | AU16: กล่อง | AV16: =+AT16*C16 -> 204.84 | AW16: =IFERROR(VLOOKUP(A16,'15'!U:V,2,0),"0") -> 21 | AX16: กล่อง | AY16: =+AW16*C16 -> 238.98 | AZ16: =IFERROR(VLOOKUP(A16,'16'!U:V,2,0),"0") -> 66 | BA16: กล่อง | BB16: =+AZ16*C16 -> 751.08 | BC16: =IFERROR(VLOOKUP(A16,'17'!U:V,2,0),"0") -> 45 | BD16: กล่อง | BE16: =+BC16*C16 -> 512.1 | BF16: =IFERROR(VLOOKUP(A16,'18'!U:V,2,0),"0") -> 18 | BG16: กล่อง | BH16: =+BF16*C16 -> 204.84 | BI16: =IFERROR(VLOOKUP(A16,'19'!U:V,2,0),"0") -> 9 | BJ16: กล่อง | BK16: =+BI16*C16 -> 102.42 | BL16: =IFERROR(VLOOKUP(A16,'20'!U:V,2,0),"0") -> 42 | BM16: กล่อง | BN16: =+BL16*C16 -> 477.96 | BO16: =IFERROR(VLOOKUP(A16,'21'!U:V,2,0),"0") -> 33 | BP16: กล่อง | BQ16: =+BO16*C16 -> 375.54 | BR16: =IFERROR(VLOOKUP(A16,'22'!U:V,2,0),"0") -> 42 | BS16: กล่อง | BT16: =+BR16*C16 -> 477.96 | BU16: =IFERROR(VLOOKUP(A16,'23'!U:V,2,0),"0") -> 61 | BV16: กล่อง | BW16: =+BU16*C16 -> 694.18 | BX16: =IFERROR(VLOOKUP(A16,'24'!U:V,2,0),"0") -> 21 | BY16: กล่อง | BZ16: =+BX16*C16 -> 238.98 | CA16: =IFERROR(VLOOKUP(A16,'25'!U:V,2,0),"0") -> 25 | CB16: กล่อง | CC16: =+CA16*C16 -> 284.5 | CD16: =IFERROR(VLOOKUP(A16,'26'!U:V,2,0),"0") -> 36 | CE16: กล่อง | CF16: =+CD16*C16 -> 409.68 | CG16: =IFERROR(VLOOKUP(A16,'27'!U:V,2,0),"0") -> 52 | CH16: กล่อง | CI16: =+CG16*C16 -> 591.76 | CJ16: =IFERROR(VLOOKUP(A16,'28'!U:V,2,0),"0") -> 39 | CK16: กล่อง | CL16: =+CJ16*C16 -> 443.82 | CM16: =IFERROR(VLOOKUP(A16,'29'!U:V,2,0),"0") -> 24 | CN16: กล่อง | CO16: =+CM16*C16 -> 273.12 | CP16: =IFERROR(VLOOKUP(A16,'30'!U:V,2,0),"0") -> 29 | CQ16: กล่อง | CR16: =+CP16*C16 -> 330.02 | CS16: =IFERROR(VLOOKUP(A16,'31'!U:V,2,0),"0") -> 51 | CT16: กล่อง | CU16: =+CS16*C16 -> 580.38 | CV16: =IFERROR(VLOOKUP(A16,'เซต1-31'!V:W,2,0),"0") -> 0 | CW16: กล่อง | CX16: =+CV16*CO16 -> 0
... A110: ปกค1 | B110: ปังกรอบคาราเมล | C110: 17.5 | D110: =+G110+J110+M110+P110+S110+V110+Y110+AB110+AE110+AH110+AK110+AN110+AQ110+AT110+AW110+AZ110+BC110+BF110+BI110+BL110+BO110+BR110+BU110+BX110+CA110+CD110+CG110+CJ110+CM110+CP110+CS110+CV110 -> 0 | E110: ถุง | F110: =+D110*C110 -> 0 | G110: =IFERROR(VLOOKUP(A110,'1'!U:V,2,0),"0") -> 0 | H110: ถุง | I110: =+G110*C110 -> 0 | J110: =IFERROR(VLOOKUP(A110,'2'!U:V,2,0),"0") -> 0 | K110: ถุง | L110: =+J110*C110 -> 0 | M110: =IFERROR(VLOOKUP(A110,'3'!U:V,2,0),"0") -> 0 | N110: ถุง | O110: =+M110*C110 -> 0 | P110: =IFERROR(VLOOKUP(A110,'4'!U:V,2,0),"0") -> 0 | Q110: ถุง | R110: =+P110*C110 -> 0 | S110: =IFERROR(VLOOKUP(A110,'5'!U:V,2,0),"0") -> 0 | T110: ถุง | U110: =+S110*C110 -> 0 | V110: =IFERROR(VLOOKUP(A110,'6'!U:V,2,0),"0") -> 0 | W110: ถุง | X110: =+V110*C110 -> 0 | Y110: =IFERROR(VLOOKUP(A110,'7'!U:V,2,0),"0") -> 0 | Z110: ถุง | AA110: =+Y110*C110 -> 0 | AB110: =IFERROR(VLOOKUP(A110,'8'!U:V,2,0),"0") -> 0 | AC110: ถุง | AD110: =+AB110*C110 -> 0 | AE110: =IFERROR(VLOOKUP(A110,'9'!U:V,2,0),"0") -> 0 | AF110: ถุง | AG110: =+AE110*C110 -> 0 | AH110: =IFERROR(VLOOKUP(A110,'10'!U:V,2,0),"0") -> 0 | AI110: ถุง | AJ110: =+AH110*C110 -> 0 | AK110: =IFERROR(VLOOKUP(A110,'11'!U:V,2,0),"0") -> 0 | AL110: ถุง | AM110: =+AK110*C110 -> 0 | AN110: =IFERROR(VLOOKUP(A110,'12'!U:V,2,0),"0") -> 0 | AO110: ถุง | AP110: =+AN110*C110 -> 0 | AQ110: =IFERROR(VLOOKUP(A110,'13'!U:V,2,0),"0") -> 0 | AR110: ถุง | AS110: =+AQ110*C110 -> 0 | AT110: =IFERROR(VLOOKUP(A110,'14'!U:V,2,0),"0") -> 0 | AU110: ถุง | AV110: =+AT110*C110 -> 0 | AW110: =IFERROR(VLOOKUP(A110,'15'!U:V,2,0),"0") -> 0 | AX110: ถุง | AY110: =+AW110*C110 -> 0 | AZ110: =IFERROR(VLOOKUP(A110,'16'!U:V,2,0),"0") -> 0 | BA110: ถุง | BB110: =+AZ110*C110 -> 0 | BC110: =IFERROR(VLOOKUP(A110,'17'!U:V,2,0),"0") -> 0 | BD110: ถุง | BE110: =+BC110*C110 -> 0 | BF110: =IFERROR(VLOOKUP(A110,'18'!U:V,2,0),"0") -> 0 | BG110: ถุง | BH110: =+BF110*C110 -> 0 | BI110: =IFERROR(VLOOKUP(A110,'19'!U:V,2,0),"0") -> 0 | BJ110: ถุง | BK110: =+BI110*C110 -> 0 | BL110: =IFERROR(VLOOKUP(A110,'20'!U:V,2,0),"0") -> 0 | BM110: ถุง | BN110: =+BL110*C110 -> 0 | BO110: =IFERROR(VLOOKUP(A110,'21'!U:V,2,0),"0") -> 0 | BP110: ถุง | BQ110: =+BO110*C110 -> 0 | BR110: =IFERROR(VLOOKUP(A110,'22'!U:V,2,0),"0") -> 0 | BS110: ถุง | BT110: =+BR110*C110 -> 0 | BU110: =IFERROR(VLOOKUP(A110,'23'!U:V,2,0),"0") -> 0 | BV110: ถุง | BW110: =+BU110*C110 -> 0 | BX110: =IFERROR(VLOOKUP(A110,'24'!U:V,2,0),"0") -> 0 | BY110: ถุง | BZ110: =+BX110*C110 -> 0 | CA110: =IFERROR(VLOOKUP(A110,'25'!U:V,2,0),"0") -> 0 | CB110: ถุง | CC110: =+CA110*C110 -> 0 | CD110: =IFERROR(VLOOKUP(A110,'26'!U:V,2,0),"0") -> 0 | CE110: ถุง | CF110: =+CD110*C110 -> 0 | CG110: =IFERROR(VLOOKUP(A110,'27'!U:V,2,0),"0") -> 0 | CH110: ถุง | CI110: =+CG110*C110 -> 0 | CJ110: =IFERROR(VLOOKUP(A110,'28'!U:V,2,0),"0") -> 0 | CK110: ถุง | CL110: =+CJ110*C110 -> 0 | CM110: =IFERROR(VLOOKUP(A110,'29'!U:V,2,0),"0") -> 0 | CN110: ถุง | CO110: =+CM110*C110 -> 0 | CP110: =IFERROR(VLOOKUP(A110,'30'!U:V,2,0),"0") -> 0 | CQ110: ถุง | CR110: =+CP110*C110 -> 0 | CS110: =IFERROR(VLOOKUP(A110,'31'!U:V,2,0),"0") -> 0 | CT110: ถุง | CU110: =+CS110*C110 -> 0 | CV110: =IFERROR(VLOOKUP(A110,'เซต1-31'!V:W,2,0),"0") -> 0 | CW110: ถุง | CX110: =+CV110*CO110 -> 0
A111: เศษปัง | B111: เศษขนมปังปลา1กก. | C111: =7.5*1 -> 7.5 | D111: =+G111+J111+M111+P111+S111+V111+Y111+AB111+AE111+AH111+AK111+AN111+AQ111+AT111+AW111+AZ111+BC111+BF111+BI111+BL111+BO111+BR111+BU111+BX111+CA111+CD111+CG111+CJ111+CM111+CP111+CS111+CV111 -> 115 | E111: กิโลกรัม | F111: =+D111*C111 -> 862.5 | G111: =IFERROR(VLOOKUP(A111,'1'!U:V,2,0),"0") -> 17 | H111: กิโลกรัม | I111: =+G111*C111 -> 127.5 | J111: =IFERROR(VLOOKUP(A111,'2'!U:V,2,0),"0") -> 3 | K111: กิโลกรัม | L111: =+J111*C111 -> 22.5 | M111: =IFERROR(VLOOKUP(A111,'3'!U:V,2,0),"0") -> 0 | N111: กิโลกรัม | O111: =+M111*C111 -> 0 | P111: =IFERROR(VLOOKUP(A111,'4'!U:V,2,0),"0") -> 0 | Q111: กิโลกรัม | R111: =+P111*C111 -> 0 | S111: =IFERROR(VLOOKUP(A111,'5'!U:V,2,0),"0") -> 2 | T111: กิโลกรัม | U111: =+S111*C111 -> 15 | V111: =IFERROR(VLOOKUP(A111,'6'!U:V,2,0),"0") -> 0 | W111: กิโลกรัม | X111: =+V111*C111 -> 0 | Y111: =IFERROR(VLOOKUP(A111,'7'!U:V,2,0),"0") -> 0 | Z111: กิโลกรัม | AA111: =+Y111*C111 -> 0 | AB111: =IFERROR(VLOOKUP(A111,'8'!U:V,2,0),"0") -> 2 | AC111: กิโลกรัม | AD111: =+AB111*C111 -> 15 | AE111: =IFERROR(VLOOKUP(A111,'9'!U:V,2,0),"0") -> 3 | AF111: กิโลกรัม | AG111: =+AE111*C111 -> 22.5 | AH111: =IFERROR(VLOOKUP(A111,'10'!U:V,2,0),"0") -> 0 | AI111: กิโลกรัม | AJ111: =+AH111*C111 -> 0 | AK111: =IFERROR(VLOOKUP(A111,'11'!U:V,2,0),"0") -> 0 | AL111: กิโลกรัม | AM111: =+AK111*C111 -> 0 | AN111: =IFERROR(VLOOKUP(A111,'12'!U:V,2,0),"0") -> 0 | AO111: กิโลกรัม | AP111: =+AN111*C111 -> 0 | AQ111: =IFERROR(VLOOKUP(A111,'13'!U:V,2,0),"0") -> 8 | AR111: กิโลกรัม | AS111: =+AQ111*C111 -> 60 | AT111: =IFERROR(VLOOKUP(A111,'14'!U:V,2,0),"0") -> 2 | AU111: กิโลกรัม | AV111: =+AT111*C111 -> 15 | AW111: =IFERROR(VLOOKUP(A111,'15'!U:V,2,0),"0") -> 0 | AX111: กิโลกรัม | AY111: =+AW111*C111 -> 0 | AZ111: =IFERROR(VLOOKUP(A111,'16'!U:V,2,0),"0") -> 0 | BA111: กิโลกรัม | BB111: =+AZ111*C111 -> 0 | BC111: =IFERROR(VLOOKUP(A111,'17'!U:V,2,0),"0") -> 0 | BD111: กิโลกรัม | BE111: =+BC111*C111 -> 0 | BF111: =IFERROR(VLOOKUP(A111,'18'!U:V,2,0),"0") -> 3 | BG111: กิโลกรัม | BH111: =+BF111*C111 -> 22.5 | BI111: =IFERROR(VLOOKUP(A111,'19'!U:V,2,0),"0") -> 12 | BJ111: กิโลกรัม | BK111: =+BI111*C111 -> 90 | BL111: =IFERROR(VLOOKUP(A111,'20'!U:V,2,0),"0") -> 14 | BM111: กิโลกรัม | BN111: =+BL111*C111 -> 105 | BO111: =IFERROR(VLOOKUP(A111,'21'!U:V,2,0),"0") -> 4 | BP111: กิโลกรัม | BQ111: =+BO111*C111 -> 30 | BR111: =IFERROR(VLOOKUP(A111,'22'!U:V,2,0),"0") -> 6 | BS111: กิโลกรัม | BT111: =+BR111*C111 -> 45 | BU111: =IFERROR(VLOOKUP(A111,'23'!U:V,2,0),"0") -> 3 | BV111: กิโลกรัม | BW111: =+BU111*C111 -> 22.5 | BX111: =IFERROR(VLOOKUP(A111,'24'!U:V,2,0),"0") -> 5 | BY111: กิโลกรัม | BZ111: =+BX111*C111 -> 37.5 | CA111: =IFERROR(VLOOKUP(A111,'25'!U:V,2,0),"0") -> 2 | CB111: กิโลกรัม | CC111: =+CA111*C111 -> 15 | CD111: =IFERROR(VLOOKUP(A111,'26'!U:V,2,0),"0") -> 7 | CE111: กิโลกรัม | CF111: =+CD111*C111 -> 52.5 | CG111: =IFERROR(VLOOKUP(A111,'27'!U:V,2,0),"0") -> 14 | CH111: กิโลกรัม | CI111: =+CG111*C111 -> 105 | CJ111: =IFERROR(VLOOKUP(A111,'28'!U:V,2,0),"0") -> 6 | CK111: กิโลกรัม | CL111: =+CJ111*C111 -> 45 | CM111: =IFERROR(VLOOKUP(A111,'29'!U:V,2,0),"0") -> 0 | CN111: กิโลกรัม | CO111: =+CM111*C111 -> 0 | CP111: =IFERROR(VLOOKUP(A111,'30'!U:V,2,0),"0") -> 1 | CQ111: กิโลกรัม | CR111: =+CP111*C111 -> 7.5 | CS111: =IFERROR(VLOOKUP(A111,'31'!U:V,2,0),"0") -> 1 | CT111: กิโลกรัม | CU111: =+CS111*C111 -> 7.5 | CV111: =IFERROR(VLOOKUP(A111,'เซต1-31'!V:W,2,0),"0") -> 0 | CW111: กิโลกรัม | CX111: =+CV111*CO111 -> 0
A112: เศษปัง-1 | B112: เศษขนมปังปลา5กก. | C112: =7.5*5 -> 37.5 | D112: =+G112+J112+M112+P112+S112+V112+Y112+AB112+AE112+AH112+AK112+AN112+AQ112+AT112+AW112+AZ112+BC112+BF112+BI112+BL112+BO112+BR112+BU112+BX112+CA112+CD112+CG112+CJ112+CM112+CP112+CS112+CV112 -> 0 | E112: กิโลกรัม | F112: =+D112*C112 -> 0 | G112: =IFERROR(VLOOKUP(A112,'1'!U:V,2,0),"0") -> 0 | H112: กิโลกรัม | I112: =+G112*C112 -> 0 | J112: =IFERROR(VLOOKUP(A112,'2'!U:V,2,0),"0") -> 0 | K112: กิโลกรัม | L112: =+J112*C112 -> 0 | M112: =IFERROR(VLOOKUP(A112,'3'!U:V,2,0),"0") -> 0 | N112: กิโลกรัม | O112: =+M112*C112 -> 0 | P112: =IFERROR(VLOOKUP(A112,'4'!U:V,2,0),"0") -> 0 | Q112: กิโลกรัม | R112: =+P112*C112 -> 0 | S112: =IFERROR(VLOOKUP(A112,'5'!U:V,2,0),"0") -> 0 | T112: กิโลกรัม | U112: =+S112*C112 -> 0 | V112: =IFERROR(VLOOKUP(A112,'6'!U:V,2,0),"0") -> 0 | W112: กิโลกรัม | X112: =+V112*C112 -> 0 | Y112: =IFERROR(VLOOKUP(A112,'7'!U:V,2,0),"0") -> 0 | Z112: กิโลกรัม | AA112: =+Y112*C112 -> 0 | AB112: =IFERROR(VLOOKUP(A112,'8'!U:V,2,0),"0") -> 0 | AC112: กิโลกรัม | AD112: =+AB112*C112 -> 0 | AE112: =IFERROR(VLOOKUP(A112,'9'!U:V,2,0),"0") -> 0 | AF112: กิโลกรัม | AG112: =+AE112*C112 -> 0 | AH112: =IFERROR(VLOOKUP(A112,'10'!U:V,2,0),"0") -> 0 | AI112: กิโลกรัม | AJ112: =+AH112*C112 -> 0 | AK112: =IFERROR(VLOOKUP(A112,'11'!U:V,2,0),"0") -> 0 | AL112: กิโลกรัม | AM112: =+AK112*C112 -> 0 | AN112: =IFERROR(VLOOKUP(A112,'12'!U:V,2,0),"0") -> 0 | AO112: กิโลกรัม | AP112: =+AN112*C112 -> 0 | AQ112: =IFERROR(VLOOKUP(A112,'13'!U:V,2,0),"0") -> 0 | AR112: กิโลกรัม | AS112: =+AQ112*C112 -> 0 | AT112: =IFERROR(VLOOKUP(A112,'14'!U:V,2,0),"0") -> 0 | AU112: กิโลกรัม | AV112: =+AT112*C112 -> 0 | AW112: =IFERROR(VLOOKUP(A112,'15'!U:V,2,0),"0") -> 0 | AX112: กิโลกรัม | AY112: =+AW112*C112 -> 0 | AZ112: =IFERROR(VLOOKUP(A112,'16'!U:V,2,0),"0") -> 0 | BA112: กิโลกรัม | BB112: =+AZ112*C112 -> 0 | BC112: =IFERROR(VLOOKUP(A112,'17'!U:V,2,0),"0") -> 0 | BD112: กิโลกรัม | BE112: =+BC112*C112 -> 0 | BF112: =IFERROR(VLOOKUP(A112,'18'!U:V,2,0),"0") -> 0 | BG112: กิโลกรัม | BH112: =+BF112*C112 -> 0 | BI112: =IFERROR(VLOOKUP(A112,'19'!U:V,2,0),"0") -> 0 | BJ112: กิโลกรัม | BK112: =+BI112*C112 -> 0 | BL112: =IFERROR(VLOOKUP(A112,'20'!U:V,2,0),"0") -> 0 | BM112: กิโลกรัม | BN112: =+BL112*C112 -> 0 | BO112: =IFERROR(VLOOKUP(A112,'21'!U:V,2,0),"0") -> 0 | BP112: กิโลกรัม | BQ112: =+BO112*C112 -> 0 | BR112: =IFERROR(VLOOKUP(A112,'22'!U:V,2,0),"0") -> 0 | BS112: กิโลกรัม | BT112: =+BR112*C112 -> 0 | BU112: =IFERROR(VLOOKUP(A112,'23'!U:V,2,0),"0") -> 0 | BV112: กิโลกรัม | BW112: =+BU112*C112 -> 0 | BX112: =IFERROR(VLOOKUP(A112,'24'!U:V,2,0),"0") -> 0 | BY112: กิโลกรัม | BZ112: =+BX112*C112 -> 0 | CA112: =IFERROR(VLOOKUP(A112,'25'!U:V,2,0),"0") -> 0 | CB112: กิโลกรัม | CC112: =+CA112*C112 -> 0 | CD112: =IFERROR(VLOOKUP(A112,'26'!U:V,2,0),"0") -> 0 | CE112: กิโลกรัม | CF112: =+CD112*C112 -> 0 | CG112: =IFERROR(VLOOKUP(A112,'27'!U:V,2,0),"0") -> 0 | CH112: กิโลกรัม | CI112: =+CG112*C112 -> 0 | CJ112: =IFERROR(VLOOKUP(A112,'28'!U:V,2,0),"0") -> 0 | CK112: กิโลกรัม | CL112: =+CJ112*C112 -> 0 | CM112: =IFERROR(VLOOKUP(A112,'29'!U:V,2,0),"0") -> 0 | CN112: กิโลกรัม | CO112: =+CM112*C112 -> 0 | CP112: =IFERROR(VLOOKUP(A112,'30'!U:V,2,0),"0") -> 0 | CQ112: กิโลกรัม | CR112: =+CP112*C112 -> 0 | CS112: =IFERROR(VLOOKUP(A112,'31'!U:V,2,0),"0") -> 0 | CT112: กิโลกรัม | CU112: =+CS112*C112 -> 0 | CV112: =IFERROR(VLOOKUP(A112,'เซต1-31'!V:W,2,0),"0") -> 0 | CW112: กิโลกรัม | CX112: =+CV112*CO112 -> 0
A113: สอดไส้คละ 1ชิ้น | B113: ชิฟฟอนสอดไส้ เเบบเเยกชิ้น ชิฟฟ่อนเค้ก ชิฟฟ่อนคละรสชาติ (Default) | C113: 4.5 | D113: =+G113+J113+M113+P113+S113+V113+Y113+AB113+AE113+AH113+AK113+AN113+AQ113+AT113+AW113+AZ113+BC113+BF113+BI113+BL113+BO113+BR113+BU113+BX113+CA113+CD113+CG113+CJ113+CM113+CP113+CS113+CV113 -> 1 | E113: ชิ้น | F113: =+D113*C113 -> 4.5 | G113: =IFERROR(VLOOKUP(A113,'1'!U:V,2,0),"0") -> 0 | H113: ชิ้น | I113: =+G113*C113 -> 0 | J113: =IFERROR(VLOOKUP(A113,'2'!U:V,2,0),"0") -> 0 | K113: ชิ้น | L113: =+J113*C113 -> 0 | M113: =IFERROR(VLOOKUP(A113,'3'!U:V,2,0),"0") -> 0 | N113: ชิ้น | O113: =+M113*C113 -> 0 | P113: =IFERROR(VLOOKUP(A113,'4'!U:V,2,0),"0") -> 0 | Q113: ชิ้น | R113: =+P113*C113 -> 0 | S113: =IFERROR(VLOOKUP(A113,'5'!U:V,2,0),"0") -> 0 | T113: ชิ้น | U113: =+S113*C113 -> 0 | V113: =IFERROR(VLOOKUP(A113,'6'!U:V,2,0),"0") -> 0 | W113: ชิ้น | X113: =+V113*C113 -> 0 | Y113: =IFERROR(VLOOKUP(A113,'7'!U:V,2,0),"0") -> 0 | Z113: ชิ้น | AA113: =+Y113*C113 -> 0 | AB113: =IFERROR(VLOOKUP(A113,'8'!U:V,2,0),"0") -> 0 | AC113: ชิ้น | AD113: =+AB113*C113 -> 0 | AE113: =IFERROR(VLOOKUP(A113,'9'!U:V,2,0),"0") -> 0 | AF113: ชิ้น | AG113: =+AE113*C113 -> 0 | AH113: =IFERROR(VLOOKUP(A113,'10'!U:V,2,0),"0") -> 0 | AI113: ชิ้น | AJ113: =+AH113*C113 -> 0 | AK113: =IFERROR(VLOOKUP(A113,'11'!U:V,2,0),"0") -> 0 | AL113: ชิ้น | AM113: =+AK113*C113 -> 0 | AN113: =IFERROR(VLOOKUP(A113,'12'!U:V,2,0),"0") -> 0 | AO113: ชิ้น | AP113: =+AN113*C113 -> 0 | AQ113: =IFERROR(VLOOKUP(A113,'13'!U:V,2,0),"0") -> 0 | AR113: ชิ้น | AS113: =+AQ113*C113 -> 0 | AT113: =IFERROR(VLOOKUP(A113,'14'!U:V,2,0),"0") -> 0 | AU113: ชิ้น | AV113: =+AT113*C113 -> 0 | AW113: =IFERROR(VLOOKUP(A113,'15'!U:V,2,0),"0") -> 0 | AX113: ชิ้น | AY113: =+AW113*C113 -> 0 | AZ113: =IFERROR(VLOOKUP(A113,'16'!U:V,2,0),"0") -> 0 | BA113: ชิ้น | BB113: =+AZ113*C113 -> 0 | BC113: =IFERROR(VLOOKUP(A113,'17'!U:V,2,0),"0") -> 0 | BD113: ชิ้น | BE113: =+BC113*C113 -> 0 | BF113: =IFERROR(VLOOKUP(A113,'18'!U:V,2,0),"0") -> 0 | BG113: ชิ้น | BH113: =+BF113*C113 -> 0 | BI113: =IFERROR(VLOOKUP(A113,'19'!U:V,2,0),"0") -> 0 | BJ113: ชิ้น | BK113: =+BI113*C113 -> 0 | BL113: =IFERROR(VLOOKUP(A113,'20'!U:V,2,0),"0") -> 0 | BM113: ชิ้น | BN113: =+BL113*C113 -> 0 | BO113: =IFERROR(VLOOKUP(A113,'21'!U:V,2,0),"0") -> 0 | BP113: ชิ้น | BQ113: =+BO113*C113 -> 0 | BR113: =IFERROR(VLOOKUP(A113,'22'!U:V,2,0),"0") -> 0 | BS113: ชิ้น | BT113: =+BR113*C113 -> 0 | BU113: =IFERROR(VLOOKUP(A113,'23'!U:V,2,0),"0") -> 0 | BV113: ชิ้น | BW113: =+BU113*C113 -> 0 | BX113: =IFERROR(VLOOKUP(A113,'24'!U:V,2,0),"0") -> 0 | BY113: ชิ้น | BZ113: =+BX113*C113 -> 0 | CA113: =IFERROR(VLOOKUP(A113,'25'!U:V,2,0),"0") -> 0 | CB113: ชิ้น | CC113: =+CA113*C113 -> 0 | CD113: =IFERROR(VLOOKUP(A113,'26'!U:V,2,0),"0") -> 1 | CE113: ชิ้น | CF113: =+CD113*C113 -> 4.5 | CG113: =IFERROR(VLOOKUP(A113,'27'!U:V,2,0),"0") -> 0 | CH113: ชิ้น | CI113: =+CG113*C113 -> 0 | CJ113: =IFERROR(VLOOKUP(A113,'28'!U:V,2,0),"0") -> 0 | CK113: ชิ้น | CL113: =+CJ113*C113 -> 0 | CM113: =IFERROR(VLOOKUP(A113,'29'!U:V,2,0),"0") -> 0 | CN113: ชิ้น | CO113: =+CM113*C113 -> 0 | CP113: =IFERROR(VLOOKUP(A113,'30'!U:V,2,0),"0") -> 0 | CQ113: ชิ้น | CR113: =+CP113*C113 -> 0 | CS113: =IFERROR(VLOOKUP(A113,'31'!U:V,2,0),"0") -> 0 | CT113: ชิ้น | CU113: =+CS113*C113 -> 0 | CV113: =IFERROR(VLOOKUP(A113,'เซต1-31'!V:W,2,0),"0") -> 0 | CW113: ชิ้น | CX113: =+CV113*CO113 -> 0
A114: 1112010 | B114: เค้กเบาหวิว ใหญ่ 1 กล่องขนาด 300 กรัม (ฝอยทอง) | C114: 26.81 | D114: =+G114+J114+M114+P114+S114+V114+Y114+AB114+AE114+AH114+AK114+AN114+AQ114+AT114+AW114+AZ114+BC114+BF114+BI114+BL114+BO114+BR114+BU114+BX114+CA114+CD114+CG114+CJ114+CM114+CP114+CS114+CV114 -> 0 | E114: กล่อง | F114: =+D114*C114 -> 0 | G114: =IFERROR(VLOOKUP(A114,'1'!U:V,2,0),"0") -> 0 | H114: กล่อง | I114: =+G114*C114 -> 0 | J114: =IFERROR(VLOOKUP(A114,'2'!U:V,2,0),"0") -> 0 | K114: กล่อง | L114: =+J114*C114 -> 0 | M114: =IFERROR(VLOOKUP(A114,'3'!U:V,2,0),"0") -> 0 | N114: กล่อง | O114: =+M114*C114 -> 0 | P114: =IFERROR(VLOOKUP(A114,'4'!U:V,2,0),"0") -> 0 | Q114: กล่อง | R114: =+P114*C114 -> 0 | S114: =IFERROR(VLOOKUP(A114,'5'!U:V,2,0),"0") -> 0 | T114: กล่อง | U114: =+S114*C114 -> 0 | V114: =IFERROR(VLOOKUP(A114,'6'!U:V,2,0),"0") -> 0 | W114: กล่อง | X114: =+V114*C114 -> 0 | Y114: =IFERROR(VLOOKUP(A114,'7'!U:V,2,0),"0") -> 0 | Z114: กล่อง | AA114: =+Y114*C114 -> 0 | AB114: =IFERROR(VLOOKUP(A114,'8'!U:V,2,0),"0") -> 0 | AC114: กล่อง | AD114: =+AB114*C114 -> 0 | AE114: =IFERROR(VLOOKUP(A114,'9'!U:V,2,0),"0") -> 0 | AF114: กล่อง | AG114: =+AE114*C114 -> 0 | AH114: =IFERROR(VLOOKUP(A114,'10'!U:V,2,0),"0") -> 0 | AI114: กล่อง | AJ114: =+AH114*C114 -> 0 | AK114: =IFERROR(VLOOKUP(A114,'11'!U:V,2,0),"0") -> 0 | AL114: กล่อง | AM114: =+AK114*C114 -> 0 | AN114: =IFERROR(VLOOKUP(A114,'12'!U:V,2,0),"0") -> 0 | AO114: กล่อง | AP114: =+AN114*C114 -> 0 | AQ114: =IFERROR(VLOOKUP(A114,'13'!U:V,2,0),"0") -> 0 | AR114: กล่อง | AS114: =+AQ114*C114 -> 0 | AT114: =IFERROR(VLOOKUP(A114,'14'!U:V,2,0),"0") -> 0 | AU114: กล่อง | AV114: =+AT114*C114 -> 0 | AW114: =IFERROR(VLOOKUP(A114,'15'!U:V,2,0),"0") -> 0 | AX114: กล่อง | AY114: =+AW114*C114 -> 0 | AZ114: =IFERROR(VLOOKUP(A114,'16'!U:V,2,0),"0") -> 0 | BA114: กล่อง | BB114: =+AZ114*C114 -> 0 | BC114: =IFERROR(VLOOKUP(A114,'17'!U:V,2,0),"0") -> 0 | BD114: กล่อง | BE114: =+BC114*C114 -> 0 | BF114: =IFERROR(VLOOKUP(A114,'18'!U:V,2,0),"0") -> 0 | BG114: กล่อง | BH114: =+BF114*C114 -> 0 | BI114: =IFERROR(VLOOKUP(A114,'19'!U:V,2,0),"0") -> 0 | BJ114: กล่อง | BK114: =+BI114*C114 -> 0 | BL114: =IFERROR(VLOOKUP(A114,'20'!U:V,2,0),"0") -> 0 | BM114: กล่อง | BN114: =+BL114*C114 -> 0 | BO114: =IFERROR(VLOOKUP(A114,'21'!U:V,2,0),"0") -> 0 | BP114: กล่อง | BQ114: =+BO114*C114 -> 0 | BR114: =IFERROR(VLOOKUP(A114,'22'!U:V,2,0),"0") -> 0 | BS114: กล่อง | BT114: =+BR114*C114 -> 0 | BU114: =IFERROR(VLOOKUP(A114,'23'!U:V,2,0),"0") -> 0 | BV114: กล่อง | BW114: =+BU114*C114 -> 0 | BX114: =IFERROR(VLOOKUP(A114,'24'!U:V,2,0),"0") -> 0 | BY114: กล่อง | BZ114: =+BX114*C114 -> 0 | CA114: =IFERROR(VLOOKUP(A114,'25'!U:V,2,0),"0") -> 0 | CB114: กล่อง | CC114: =+CA114*C114 -> 0 | CD114: =IFERROR(VLOOKUP(A114,'26'!U:V,2,0),"0") -> 0 | CE114: กล่อง | CF114: =+CD114*C114 -> 0 | CG114: =IFERROR(VLOOKUP(A114,'27'!U:V,2,0),"0") -> 0 | CH114: กล่อง | CI114: =+CG114*C114 -> 0 | CJ114: =IFERROR(VLOOKUP(A114,'28'!U:V,2,0),"0") -> 0 | CK114: กล่อง | CL114: =+CJ114*C114 -> 0 | CM114: =IFERROR(VLOOKUP(A114,'29'!U:V,2,0),"0") -> 0 | CN114: กล่อง | CO114: =+CM114*C114 -> 0 | CP114: =IFERROR(VLOOKUP(A114,'30'!U:V,2,0),"0") -> 0 | CQ114: กล่อง | CR114: =+CP114*C114 -> 0 | CS114: =IFERROR(VLOOKUP(A114,'31'!U:V,2,0),"0") -> 0 | CT114: กล่อง | CU114: =+CS114*C114 -> 0 | CV114: =IFERROR(VLOOKUP(A114,'เซต1-31'!V:W,2,0),"0") -> 0 | CW114: กล่อง | CX114: =+CV114*CO114 -> 0
