Workbook

Sheet บ่าย
B1: ยอดจริง ออนไลน์ วันที่ - บ่าย
L2: ยอดรวมผลิต
L3: จำนวน
B4: รหัสสินค้า | C4: สินค้า | D4: ปณ | E4: ชอปปี้ | F4: ลาซาด้า | G4: ติ๊กตอก | H4: ติ๊กตอก 2 | I4: ติ๊กตอก3 | J4: ชอยส์ | K4: ยอดเส้น | L4: (กล่อง)
B6: ชิฟฟอนรวมรส
B7: 1111002 | C7: ชิฟฟอนรวมรส 8 ชิ้น | L7: =SUM(D7:K7) -> 0
C8: ชิฟฟอนแบบกล่องสุ่มอะไรก็ได้ที่มี | L8: =SUM(D8:K8) -> 0
B9: 1111084 | C9: ชิฟฟอน 8 ชิ้น กาแฟล้วน | L9: =SUM(D9:K9) -> 0
B10: 1111085 | C10: ชิฟฟอน 8 ชิ้น บลูเบอรี่ล้วน | L10: =SUM(D10:K10) -> 0
B11: 1111086 | C11: ชิฟฟอน 8 ชิ้น มะพร้าวล้วน | L11: =SUM(D11:K11) -> 0
B12: 1111087 | C12: ชิฟฟอน 8 ชิ้น สตอเบอรี่ล้วน | L12: =SUM(D12:K12) -> 0
B13: 1111088 | C13: ชิฟฟอน 8 ชิ้น ส้มล้วน | L13: =SUM(D13:K13) -> 0
B14: 1111089 | C14: ชิฟฟอน 8 ชิ้น เนยล้วน | L14: =SUM(D14:K14) -> 0
B15: 1111090 | C15: ชิฟฟอน 8 ชิ้น เผือกล้วน | L15: =SUM(D15:K15) -> 0
B16: 1111091 | C16: ชิฟฟอน 8 ชิ้น ใบเตยล้วน | L16: =SUM(D16:K16) -> 0
B17: 1111092 | C17: ชิฟฟอน 8 ชิ้น กล้วยหอม | L17: =SUM(D17:K17) -> 0
B18: 1111093 | C18: ชิฟฟอน 8 ชิ้น โกโก้ล้วน | L18: =SUM(D18:K18) -> 0
B19: 1111094 | C19: ชิฟฟอน 8 ชิ้น ชาไทยล้วน | L19: =SUM(D19:K19) -> 0
B20: 1111095 | C20: ชิฟฟอน 8 ชิ้น ชาเขียวล้วน | L20: =SUM(D20:K20) -> 0
... B66: 1111010 | C66: ชิฟฟอนไส้แยมแยกชิ้น คละรส | L66: =SUM(D66:K66) -> 0
C67: รวม | L67: =SUM(L7:L66) -> 0
B68: ชิฟฟอนไส้แยม 6 ชิ้น
B69: 1111009 | C69: ชิฟฟอนไส้แยมรวมรส 6 ชิ้น | L69: =SUM(D69:K69) -> 0
B70: 1111023 | C70: ชิฟฟอนไส้แยมรสสตอเบอร์รี่ล้วน 6 ชิ้น | L70: =SUM(D70:K70) -> 0
B71: 1111016 | C71: ชิฟฟอนไส้แยมรสมะพร้าวล้วน 6 ชิ้น | L71: =SUM(D71:K71) -> 0
B72: 1111014 | C72: ชิฟฟอนไส้แยมรสช็อกโกแลตนูเทลล่าล้วน 6 ชิ้น | L72: =SUM(D72:K72) -> 0
B73: 1111025 | C73: ชิฟฟอนไส้แยมรสส้มล้วน 6 ชิ้น | L73: =SUM(D73:K73) -> 0
B74: 1111018 | C74: ชิฟฟอนไส้แยมรสบลูเบอร์รี่ล้วน 6 ชิ้น | L74: =SUM(D74:K74) -> 0
B75: 1111012 | C75: ชิฟฟอนไส้แยมรสนมชมพูฮอกไกโดล้วน 6 ชิ้น | L75: =SUM(D75:K75) -> 0
B76: 1111020 | C76: ชิฟฟอนไส้แยมฝอยทองไส้ทะลัก 6 ชิ้น | L76: =SUM(D76:K76) -> 0
C77: รวม | L77: =SUM(L69:L76) -> 0
B78: ชิฟฟอนไส้แยม 3 ชิ้น
B79: 1111022 | C79: ชิฟฟอนไส้แยมรสสตอเบอร์รี่ล้วน 3 ชิ้น | L79: =SUM(D79:K79) -> 0
B80: 1111015 | C80: ชิฟฟอนไส้แยมรสมะพร้าวล้วน 3 ชิ้น | L80: =SUM(D80:K80) -> 0
B81: 1111013 | C81: ชิฟฟอนไส้แยมรสช็อกโกแลตนูเทลล่าล้วน 3 ชิ้น | L81: =SUM(D81:K81) -> 0
B82: 1111024 | C82: ชิฟฟอนไส้แยมรสส้มล้วน 3 ชิ้น | L82: =SUM(D82:K82) -> 0
B83: 1111017 | C83: ชิฟฟอนไส้แยมรสบลูเบอร์รี่ล้วน 3 ชิ้น | L83: =SUM(D83:K83) -> 0
B84: 1111011 | C84: ชิฟฟอนไส้แยมรสนมชมพูฮอกไกโดล้วน 3 ชิ้น | L84: =SUM(D84:K84) -> 0
B85: 1111019 | C85: ชิฟฟอนไส้แยมฝอยทองไส้ทะลัก 3 ชิ้น | L85: =SUM(D85:K85) -> 0
B86: 1113081 | C86: ชิฟฟอนไส้แยม วนิลา/ใบเตย/เมล่อน | L86: =SUM(D86:K86) -> 0
...

Sheet เย็น 
B1: ยอดจริง ออนไลน์ วันที่ - เย็น
L2: ยอดรวมผลิต
L3: จำนวน
B4: รหัสสินค้า | C4: สินค้า | D4: ปณ | E4: ชอปปี้ | F4: ลาซาด้า | G4: ติ๊กตอก | H4: ติ๊กตอก 2 | I4: ติ๊กตอก3 | J4: ชอยส์ | K4: ยอดเส้น | L4: (กล่อง)
B6: ชิฟฟอนรวมรส
B7: 1111002 | C7: ชิฟฟอนรวมรส 8 ชิ้น | L7: =SUM(D7:K7) -> 0
C8: ชิฟฟอนแบบกล่องสุ่มอะไรก็ได้ที่มี | L8: =SUM(D8:K8) -> 0
B9: 1111084 | C9: ชิฟฟอน 8 ชิ้น กาแฟล้วน | L9: =SUM(D9:K9) -> 0
B10: 1111085 | C10: ชิฟฟอน 8 ชิ้น บลูเบอรี่ล้วน | L10: =SUM(D10:K10) -> 0
B11: 1111086 | C11: ชิฟฟอน 8 ชิ้น มะพร้าวล้วน | L11: =SUM(D11:K11) -> 0
B12: 1111087 | C12: ชิฟฟอน 8 ชิ้น สตอเบอรี่ล้วน | L12: =SUM(D12:K12) -> 0
B13: 1111088 | C13: ชิฟฟอน 8 ชิ้น ส้มล้วน | L13: =SUM(D13:K13) -> 0
B14: 1111089 | C14: ชิฟฟอน 8 ชิ้น เนยล้วน | L14: =SUM(D14:K14) -> 0
B15: 1111090 | C15: ชิฟฟอน 8 ชิ้น เผือกล้วน | L15: =SUM(D15:K15) -> 0
B16: 1111091 | C16: ชิฟฟอน 8 ชิ้น ใบเตยล้วน | L16: =SUM(D16:K16) -> 0
B17: 1111092 | C17: ชิฟฟอน 8 ชิ้น กล้วยหอม | L17: =SUM(D17:K17) -> 0
B18: 1111093 | C18: ชิฟฟอน 8 ชิ้น โกโก้ล้วน | L18: =SUM(D18:K18) -> 0
B19: 1111094 | C19: ชิฟฟอน 8 ชิ้น ชาไทยล้วน | L19: =SUM(D19:K19) -> 0
B20: 1111095 | C20: ชิฟฟอน 8 ชิ้น ชาเขียวล้วน | L20: =SUM(D20:K20) -> 0
... B66: 1111010 | C66: ชิฟฟอนไส้แยมแยกชิ้น คละรส | L66: =SUM(D66:K66) -> 0
C67: รวม | L67: =SUM(L7:L66) -> 0
B68: ชิฟฟอนไส้แยม 6 ชิ้น
B69: 1111009 | C69: ชิฟฟอนไส้แยมรวมรส 6 ชิ้น | L69: =SUM(D69:K69) -> 0
B70: 1111023 | C70: ชิฟฟอนไส้แยมรสสตอเบอร์รี่ล้วน 6 ชิ้น | L70: =SUM(D70:K70) -> 0
B71: 1111016 | C71: ชิฟฟอนไส้แยมรสมะพร้าวล้วน 6 ชิ้น | L71: =SUM(D71:K71) -> 0
B72: 1111014 | C72: ชิฟฟอนไส้แยมรสช็อกโกแลตนูเทลล่าล้วน 6 ชิ้น | L72: =SUM(D72:K72) -> 0
B73: 1111025 | C73: ชิฟฟอนไส้แยมรสส้มล้วน 6 ชิ้น | L73: =SUM(D73:K73) -> 0
B74: 1111018 | C74: ชิฟฟอนไส้แยมรสบลูเบอร์รี่ล้วน 6 ชิ้น | L74: =SUM(D74:K74) -> 0
B75: 1111012 | C75: ชิฟฟอนไส้แยมรสนมชมพูฮอกไกโดล้วน 6 ชิ้น | L75: =SUM(D75:K75) -> 0
B76: 1111020 | C76: ชิฟฟอนไส้แยมฝอยทองไส้ทะลัก 6 ชิ้น | L76: =SUM(D76:K76) -> 0
C77: รวม | L77: =SUM(L69:L76) -> 0
B78: ชิฟฟอนไส้แยม 3 ชิ้น
B79: 1111022 | C79: ชิฟฟอนไส้แยมรสสตอเบอร์รี่ล้วน 3 ชิ้น | L79: =SUM(D79:K79) -> 0
B80: 1111015 | C80: ชิฟฟอนไส้แยมรสมะพร้าวล้วน 3 ชิ้น | L80: =SUM(D80:K80) -> 0
B81: 1111013 | C81: ชิฟฟอนไส้แยมรสช็อกโกแลตนูเทลล่าล้วน 3 ชิ้น | L81: =SUM(D81:K81) -> 0
B82: 1111024 | C82: ชิฟฟอนไส้แยมรสส้มล้วน 3 ชิ้น | L82: =SUM(D82:K82) -> 0
B83: 1111017 | C83: ชิฟฟอนไส้แยมรสบลูเบอร์รี่ล้วน 3 ชิ้น | L83: =SUM(D83:K83) -> 0
B84: 1111011 | C84: ชิฟฟอนไส้แยมรสนมชมพูฮอกไกโดล้วน 3 ชิ้น | L84: =SUM(D84:K84) -> 0
B85: 1111019 | C85: ชิฟฟอนไส้แยมฝอยทองไส้ทะลัก 3 ชิ้น | L85: =SUM(D85:K85) -> 0
B86: 1113081 | C86: ชิฟฟอนไส้แยม วนิลา/ใบเตย/เมล่อน | L86: =SUM(D86:K86) -> 0
...

Sheet 01.10.68
B1: ยอดจริง ออนไลน์ วันที่ 01/10/2568
B2: รหัสสินค้า | C2: สินค้า | D2: ปณ | G2: ชอปปี้ | J2: ลาซาด้า | M2: ติ๊กตอก | P2: ติ๊กตอก2 | S2: ติ๊กตอก3 | V2: ชอยส์ | Y2: ยอดเส้น | Z2: ยอดรวมผลิต(กล่อง) | AA2: ยอดForcast | AB2: ยอดStock | AC2: ยอดMemo | AD2: ยอดForcastวันพรุ่งนี้ | AE2: สินค้าที่ขายได้
D3: เช้า | E3: บ่าย | F3: รวม | G3: เช้า | H3: บ่าย | I3: รวม | J3: เช้า | K3: บ่าย | L3: รวม | M3: เช้า | N3: บ่าย | O3: รวม | P3: เช้า | Q3: บ่าย | R3: รวม | S3: เช้า | T3: บ่าย | U3: รวม | V3: เช้า | W3: บ่าย | X3: รวม
B4: 1004055 | C4: ชิฟฟ่อนเค้ก วรรณวนัช (รวมรส 4 ชิ้น) | D4: 4 | F4: =SUM(D4:E4) -> 4 | I4: =SUM(G4:H4) -> 0 | L4: =SUM(J4:K4) -> 0 | M4: 61 | O4: =SUM(M4:N4) -> 61 | P4: 69 | R4: =SUM(P4:Q4) -> 69 | U4: =SUM(S4:T4) -> 0 | X4: =SUM(V4:W4) -> 0 | Y4: 36 | Z4: =+F4+I4+L4+O4+R4+U4+X4+Y4 -> 170 | AA4: 91 | AB4: 54 | AC4: =+AA4+AB4-Z4 -> -25 | AD4: 50 | AE4: =AC4+AD4 -> 25
B5: 1111002 | C5: ชิฟฟ่อนเค้ก วรรณวนัช (รวมรส 8 ชิ้น) | D5: 6 | F5: =SUM(D5:E5) -> 6 | G5: 26 | I5: =SUM(G5:H5) -> 26 | J5: 13 | L5: =SUM(J5:K5) -> 13 | M5: 7 | O5: =SUM(M5:N5) -> 7 | P5: 12 | R5: =SUM(P5:Q5) -> 12 | U5: =SUM(S5:T5) -> 0 | X5: =SUM(V5:W5) -> 0 | Y5: 46 | Z5: =+F5+I5+L5+O5+R5+U5+X5+Y5 -> 110 | AA5: 150 | AB5: 9 | AC5: =+AA5+AB5-Z5 -> 49 | AD5: 100 | AE5: =AC5+AD5 -> 149
B6: 1111055 | C6: วรรณวนัช ชิฟฟ่อนรวมรส 8 ชิ้น | F6: =SUM(D6:E6) -> 0 | I6: =SUM(G6:H6) -> 0 | L6: =SUM(J6:K6) -> 0 | O6: =SUM(M6:N6) -> 0 | R6: =SUM(P6:Q6) -> 0 | U6: =SUM(S6:T6) -> 0 | X6: =SUM(V6:W6) -> 0 | Z6: =+F6+I6+L6+O6+R6+U6+X6+Y6 -> 0 | AC6: =+AA6+AB6-Z6 -> 0 | AE6: =AC6+AD6 -> 0
B7: 1111084 | C7: ชิฟฟ่อนเค้ก รสกาแฟ (8 ชิ้น) | F7: =SUM(D7:E7) -> 0 | I7: =SUM(G7:H7) -> 0 | L7: =SUM(J7:K7) -> 0 | O7: =SUM(M7:N7) -> 0 | R7: =SUM(P7:Q7) -> 0 | U7: =SUM(S7:T7) -> 0 | X7: =SUM(V7:W7) -> 0 | Z7: =+F7+I7+L7+O7+R7+U7+X7+Y7 -> 0 | AC7: =+AA7+AB7-Z7 -> 0 | AE7: =AC7+AD7 -> 0
B8: 1111043 | C8: ชิฟฟอนรสมะลิ 8 ชิ้น ห่อ ซีน | F8: =SUM(D8:E8) -> 0 | I8: =SUM(G8:H8) -> 0 | L8: =SUM(J8:K8) -> 0 | O8: =SUM(M8:N8) -> 0 | R8: =SUM(P8:Q8) -> 0 | U8: =SUM(S8:T8) -> 0 | X8: =SUM(V8:W8) -> 0 | Z8: =+F8+I8+L8+O8+R8+U8+X8+Y8 -> 0 | AC8: =+AA8+AB8-Z8 -> 0 | AE8: =AC8+AD8 -> 0
B9: 1111057 | C9: ชิฟฟอนแยกชิ้น กาแฟ | F9: =SUM(D9:E9) -> 0 | G9: 7 | I9: =SUM(G9:H9) -> 7 | L9: =SUM(J9:K9) -> 0 | O9: =SUM(M9:N9) -> 0 | R9: =SUM(P9:Q9) -> 0 | U9: =SUM(S9:T9) -> 0 | X9: =SUM(V9:W9) -> 0 | Z9: =+F9+I9+L9+O9+R9+U9+X9+Y9 -> 7 | AC9: =+AA9+AB9-Z9 -> -7 | AE9: =AC9+AD9 -> -7
B10: 1111058 | C10: ชิฟฟอนแยกชิ้น มะลิ | F10: =SUM(D10:E10) -> 0 | G10: 7 | I10: =SUM(G10:H10) -> 7 | L10: =SUM(J10:K10) -> 0 | O10: =SUM(M10:N10) -> 0 | R10: =SUM(P10:Q10) -> 0 | U10: =SUM(S10:T10) -> 0 | X10: =SUM(V10:W10) -> 0 | Z10: =+F10+I10+L10+O10+R10+U10+X10+Y10 -> 7 | AC10: =+AA10+AB10-Z10 -> -7 | AE10: =AC10+AD10 -> -7
B11: 1111059 | C11: ชิฟฟอนแยกชิ้น ใบเตย | F11: =SUM(D11:E11) -> 0 | G11: 7 | I11: =SUM(G11:H11) -> 7 | L11: =SUM(J11:K11) -> 0 | O11: =SUM(M11:N11) -> 0 | R11: =SUM(P11:Q11) -> 0 | U11: =SUM(S11:T11) -> 0 | X11: =SUM(V11:W11) -> 0 | Z11: =+F11+I11+L11+O11+R11+U11+X11+Y11 -> 7 | AC11: =+AA11+AB11-Z11 -> -7 | AE11: =AC11+AD11 -> -7
B12: 1111060 | C12: ชิฟฟอนแยกชิ้น กล้วยหอม | F12: =SUM(D12:E12) -> 0 | G12: 7 | I12: =SUM(G12:H12) -> 7 | L12: =SUM(J12:K12) -> 0 | O12: =SUM(M12:N12) -> 0 | R12: =SUM(P12:Q12) -> 0 | U12: =SUM(S12:T12) -> 0 | X12: =SUM(V12:W12) -> 0 | Z12: =+F12+I12+L12+O12+R12+U12+X12+Y12 -> 7 | AC12: =+AA12+AB12-Z12 -> -7 | AE12: =AC12+AD12 -> -7
B13: 1111061 | C13: ชิฟฟอนแยกชิ้น ชาไทย | F13: =SUM(D13:E13) -> 0 | G13: 7 | I13: =SUM(G13:H13) -> 7 | L13: =SUM(J13:K13) -> 0 | O13: =SUM(M13:N13) -> 0 | R13: =SUM(P13:Q13) -> 0 | U13: =SUM(S13:T13) -> 0 | X13: =SUM(V13:W13) -> 0 | Z13: =+F13+I13+L13+O13+R13+U13+X13+Y13 -> 7 | AC13: =+AA13+AB13-Z13 -> -7 | AE13: =AC13+AD13 -> -7
B14: 1111062 | C14: ชิฟฟอนแยกชิ้น โกโก้ | F14: =SUM(D14:E14) -> 0 | G14: 7 | I14: =SUM(G14:H14) -> 7 | L14: =SUM(J14:K14) -> 0 | O14: =SUM(M14:N14) -> 0 | R14: =SUM(P14:Q14) -> 0 | U14: =SUM(S14:T14) -> 0 | X14: =SUM(V14:W14) -> 0 | Z14: =+F14+I14+L14+O14+R14+U14+X14+Y14 -> 7 | AC14: =+AA14+AB14-Z14 -> -7 | AE14: =AC14+AD14 -> -7
B15: 1111063 | C15: ชิฟฟอนแยกชิ้น ส้ม | F15: =SUM(D15:E15) -> 0 | G15: 7 | I15: =SUM(G15:H15) -> 7 | L15: =SUM(J15:K15) -> 0 | O15: =SUM(M15:N15) -> 0 | R15: =SUM(P15:Q15) -> 0 | U15: =SUM(S15:T15) -> 0 | X15: =SUM(V15:W15) -> 0 | Z15: =+F15+I15+L15+O15+R15+U15+X15+Y15 -> 7 | AC15: =+AA15+AB15-Z15 -> -7 | AE15: =AC15+AD15 -> -7
B16: 1111064 | C16: ชิฟฟอนแยกชิ้น เผือก | F16: =SUM(D16:E16) -> 0 | G16: 7 | I16: =SUM(G16:H16) -> 7 | L16: =SUM(J16:K16) -> 0 | O16: =SUM(M16:N16) -> 0 | R16: =SUM(P16:Q16) -> 0 | U16: =SUM(S16:T16) -> 0 | X16: =SUM(V16:W16) -> 0 | Z16: =+F16+I16+L16+O16+R16+U16+X16+Y16 -> 7 | AC16: =+AA16+AB16-Z16 -> -7 | AE16: =AC16+AD16 -> -7
B17: 1111065 | C17: ชิฟฟอนแยกชิ้น สับปะรด | F17: =SUM(D17:E17) -> 0 | G17: 7 | I17: =SUM(G17:H17) -> 7 | L17: =SUM(J17:K17) -> 0 | O17: =SUM(M17:N17) -> 0 | R17: =SUM(P17:Q17) -> 0 | U17: =SUM(S17:T17) -> 0 | X17: =SUM(V17:W17) -> 0 | Z17: =+F17+I17+L17+O17+R17+U17+X17+Y17 -> 7 | AC17: =+AA17+AB17-Z17 -> -7 | AE17: =AC17+AD17 -> -7
B18: 1111066 | C18: ชิฟฟอนแยกชิ้น สตอเบอรี่ | F18: =SUM(D18:E18) -> 0 | G18: 7 | I18: =SUM(G18:H18) -> 7 | L18: =SUM(J18:K18) -> 0 | O18: =SUM(M18:N18) -> 0 | R18: =SUM(P18:Q18) -> 0 | U18: =SUM(S18:T18) -> 0 | X18: =SUM(V18:W18) -> 0 | Z18: =+F18+I18+L18+O18+R18+U18+X18+Y18 -> 7 | AC18: =+AA18+AB18-Z18 -> -7 | AE18: =AC18+AD18 -> -7
B19: 1111067 | C19: ชิฟฟอนแยกชิ้น มะพร้าว | F19: =SUM(D19:E19) -> 0 | G19: 7 | I19: =SUM(G19:H19) -> 7 | L19: =SUM(J19:K19) -> 0 | O19: =SUM(M19:N19) -> 0 | R19: =SUM(P19:Q19) -> 0 | U19: =SUM(S19:T19) -> 0 | X19: =SUM(V19:W19) -> 0 | Z19: =+F19+I19+L19+O19+R19+U19+X19+Y19 -> 7 | AC19: =+AA19+AB19-Z19 -> -7 | AE19: =AC19+AD19 -> -7
B20: 1111068 | C20: ชิฟฟอนแยกชิ้น เนย | F20: =SUM(D20:E20) -> 0 | G20: 7 | I20: =SUM(G20:H20) -> 7 | L20: =SUM(J20:K20) -> 0 | O20: =SUM(M20:N20) -> 0 | R20: =SUM(P20:Q20) -> 0 | U20: =SUM(S20:T20) -> 0 | X20: =SUM(V20:W20) -> 0 | Z20: =+F20+I20+L20+O20+R20+U20+X20+Y20 -> 7 | AC20: =+AA20+AB20-Z20 -> -7 | AE20: =AC20+AD20 -> -7
B21: 1111069 | C21: ชิฟฟอนแยกชิ้น บลูเบอรี่ | F21: =SUM(D21:E21) -> 0 | G21: 6 | I21: =SUM(G21:H21) -> 6 | L21: =SUM(J21:K21) -> 0 | O21: =SUM(M21:N21) -> 0 | R21: =SUM(P21:Q21) -> 0 | U21: =SUM(S21:T21) -> 0 | X21: =SUM(V21:W21) -> 0 | Z21: =+F21+I21+L21+O21+R21+U21+X21+Y21 -> 6 | AC21: =+AA21+AB21-Z21 -> -6 | AE21: =AC21+AD21 -> -6
B22: 1111070 | C22: ชิฟฟอนแยกชิ้น ทุเรียน | F22: =SUM(D22:E22) -> 0 | I22: =SUM(G22:H22) -> 0 | L22: =SUM(J22:K22) -> 0 | O22: =SUM(M22:N22) -> 0 | R22: =SUM(P22:Q22) -> 0 | U22: =SUM(S22:T22) -> 0 | X22: =SUM(V22:W22) -> 0 | Z22: =+F22+I22+L22+O22+R22+U22+X22+Y22 -> 0 | AC22: =+AA22+AB22-Z22 -> 0 | AE22: =AC22+AD22 -> 0
B23: 1111071 | C23: ชิฟฟอนแยกชิ้น ตาล | F23: =SUM(D23:E23) -> 0 | I23: =SUM(G23:H23) -> 0 | L23: =SUM(J23:K23) -> 0 | O23: =SUM(M23:N23) -> 0 | R23: =SUM(P23:Q23) -> 0 | U23: =SUM(S23:T23) -> 0 | X23: =SUM(V23:W23) -> 0 | Z23: =+F23+I23+L23+O23+R23+U23+X23+Y23 -> 0 | AC23: =+AA23+AB23-Z23 -> 0 | AE23: =AC23+AD23 -> 0
B24: 1111010 | C24: ชิฟฟ่อนเค้กสอดไส้แยม (1 ชิ้น) แยมสับปะรด | F24: =SUM(D24:E24) -> 0 | I24: =SUM(G24:H24) -> 0 | L24: =SUM(J24:K24) -> 0 | O24: =SUM(M24:N24) -> 0 | R24: =SUM(P24:Q24) -> 0 | U24: =SUM(S24:T24) -> 0 | X24: =SUM(V24:W24) -> 0 | Z24: =+F24+I24+L24+O24+R24+U24+X24+Y24 -> 0 | AC24: =+AA24+AB24-Z24 -> 0 | AE24: =AC24+AD24 -> 0
B25: 1111008 | C25: ชิฟฟ่อนเค้ก สอดไส้ (รวมรส 3 ชิ้น) | D25: 4 | F25: =SUM(D25:E25) -> 4 | I25: =SUM(G25:H25) -> 0 | J25: 3 | L25: =SUM(J25:K25) -> 3 | M25: 30 | O25: =SUM(M25:N25) -> 30 | P25: 12 | R25: =SUM(P25:Q25) -> 12 | U25: =SUM(S25:T25) -> 0 | X25: =SUM(V25:W25) -> 0 | Y25: 10 | Z25: =+F25+I25+L25+O25+R25+U25+X25+Y25 -> 59 | AA25: 60 | AC25: =+AA25+AB25-Z25 -> 1 | AD25: 50 | AE25: =AC25+AD25 -> 51
B26: 1111009 | C26: ชิฟฟ่อนเค้ก สอดไส้ (รวมรส 6 ชิ้น) | D26: 4 | F26: =SUM(D26:E26) -> 4 | G26: 3 | I26: =SUM(G26:H26) -> 3 | J26: 2 | L26: =SUM(J26:K26) -> 2 | M26: 1 | O26: =SUM(M26:N26) -> 1 | R26: =SUM(P26:Q26) -> 0 | U26: =SUM(S26:T26) -> 0 | X26: =SUM(V26:W26) -> 0 | Z26: =+F26+I26+L26+O26+R26+U26+X26+Y26 -> 10 | AA26: 20 | AC26: =+AA26+AB26-Z26 -> 10 | AD26: 20 | AE26: =AC26+AD26 -> 30
B27: 1111011 | C27: ชิฟฟ่อนเค้กสอดไส้ นมชมพูฮอกไกโด (3 ชิ้น) | F27: =SUM(D27:E27) -> 0 | I27: =SUM(G27:H27) -> 0 | L27: =SUM(J27:K27) -> 0 | O27: =SUM(M27:N27) -> 0 | R27: =SUM(P27:Q27) -> 0 | U27: =SUM(S27:T27) -> 0 | X27: =SUM(V27:W27) -> 0 | Z27: =+F27+I27+L27+O27+R27+U27+X27+Y27 -> 0 | AC27: =+AA27+AB27-Z27 -> 0 | AE27: =AC27+AD27 -> 0
B28: 1111012 | C28: ชิฟฟ่อนเค้กสอดไส้ นมชมพูฮอกไกโด (6 ชิ้น) | F28: =SUM(D28:E28) -> 0 | I28: =SUM(G28:H28) -> 0 | L28: =SUM(J28:K28) -> 0 | O28: =SUM(M28:N28) -> 0 | R28: =SUM(P28:Q28) -> 0 | U28: =SUM(S28:T28) -> 0 | X28: =SUM(V28:W28) -> 0 | Z28: =+F28+I28+L28+O28+R28+U28+X28+Y28 -> 0 | AC28: =+AA28+AB28-Z28 -> 0 | AE28: =AC28+AD28 -> 0
B29: 1111013 | C29: ชิฟฟ่อนเค้กสอดไส้ ช็อคโกแลตนูเทลล่า (3 ชิ้น) | F29: =SUM(D29:E29) -> 0 | I29: =SUM(G29:H29) -> 0 | L29: =SUM(J29:K29) -> 0 | O29: =SUM(M29:N29) -> 0 | R29: =SUM(P29:Q29) -> 0 | U29: =SUM(S29:T29) -> 0 | X29: =SUM(V29:W29) -> 0 | Z29: =+F29+I29+L29+O29+R29+U29+X29+Y29 -> 0 | AC29: =+AA29+AB29-Z29 -> 0 | AE29: =AC29+AD29 -> 0
B30: 1111014 | C30: ชิฟฟ่อนเค้กสอดไส้ ช็อคโกแลตนูเทลล่า (6 ชิ้น) | F30: =SUM(D30:E30) -> 0 | I30: =SUM(G30:H30) -> 0 | L30: =SUM(J30:K30) -> 0 | O30: =SUM(M30:N30) -> 0 | R30: =SUM(P30:Q30) -> 0 | U30: =SUM(S30:T30) -> 0 | X30: =SUM(V30:W30) -> 0 | Z30: =+F30+I30+L30+O30+R30+U30+X30+Y30 -> 0 | AC30: =+AA30+AB30-Z30 -> 0 | AE30: =AC30+AD30 -> 0
B31: 1111015 | C31: ชิฟฟ่อนเค้กสอดไส้เนย รสมะพร้าว (3 ชิ้น) | F31: =SUM(D31:E31) -> 0 | I31: =SUM(G31:H31) -> 0 | L31: =SUM(J31:K31) -> 0 | O31: =SUM(M31:N31) -> 0 | R31: =SUM(P31:Q31) -> 0 | U31: =SUM(S31:T31) -> 0 | X31: =SUM(V31:W31) -> 0 | Z31: =+F31+I31+L31+O31+R31+U31+X31+Y31 -> 0 | AC31: =+AA31+AB31-Z31 -> 0 | AE31: =AC31+AD31 -> 0
B32: 1111016 | C32: ชิฟฟ่อนเค้กสอดไส้เนย รสมะพร้าว (6 ชิ้น) | F32: =SUM(D32:E32) -> 0 | I32: =SUM(G32:H32) -> 0 | L32: =SUM(J32:K32) -> 0 | O32: =SUM(M32:N32) -> 0 | R32: =SUM(P32:Q32) -> 0 | U32: =SUM(S32:T32) -> 0 | X32: =SUM(V32:W32) -> 0 | Z32: =+F32+I32+L32+O32+R32+U32+X32+Y32 -> 0 | AC32: =+AA32+AB32-Z32 -> 0 | AE32: =AC32+AD32 -> 0
B33: 1111017 | C33: ชิฟฟ่อนเค้กสอดไส้แยม รสบลูเบอร์รี่ (3 ชิ้น) | F33: =SUM(D33:E33) -> 0 | I33: =SUM(G33:H33) -> 0 | L33: =SUM(J33:K33) -> 0 | O33: =SUM(M33:N33) -> 0 | R33: =SUM(P33:Q33) -> 0 | U33: =SUM(S33:T33) -> 0 | X33: =SUM(V33:W33) -> 0 | Z33: =+F33+I33+L33+O33+R33+U33+X33+Y33 -> 0 | AC33: =+AA33+AB33-Z33 -> 0 | AE33: =AC33+AD33 -> 0
B34: 1111018 | C34: ชิฟฟ่อนเค้กสอดไส้แยม รสบลูเบอร์รี่ (6 ชิ้น) | F34: =SUM(D34:E34) -> 0 | I34: =SUM(G34:H34) -> 0 | L34: =SUM(J34:K34) -> 0 | O34: =SUM(M34:N34) -> 0 | R34: =SUM(P34:Q34) -> 0 | U34: =SUM(S34:T34) -> 0 | X34: =SUM(V34:W34) -> 0 | Z34: =+F34+I34+L34+O34+R34+U34+X34+Y34 -> 0 | AC34: =+AA34+AB34-Z34 -> 0 | AE34: =AC34+AD34 -> 0
B35: 1111019 | C35: ชิฟฟ่อนเค้กหน้าฝอยทอง สอดไส้แยมส้ม (3 ชิ้น) | F35: =SUM(D35:E35) -> 0 | I35: =SUM(G35:H35) -> 0 | L35: =SUM(J35:K35) -> 0 | O35: =SUM(M35:N35) -> 0 | R35: =SUM(P35:Q35) -> 0 | U35: =SUM(S35:T35) -> 0 | X35: =SUM(V35:W35) -> 0 | Z35: =+F35+I35+L35+O35+R35+U35+X35+Y35 -> 0 | AC35: =+AA35+AB35-Z35 -> 0 | AE35: =AC35+AD35 -> 0
B36: 1111020 | C36: ชิฟฟ่อนเค้กหน้าฝอยทอง สอดไส้แยมส้ม (6 ชิ้น) | F36: =SUM(D36:E36) -> 0 | I36: =SUM(G36:H36) -> 0 | L36: =SUM(J36:K36) -> 0 | O36: =SUM(M36:N36) -> 0 | R36: =SUM(P36:Q36) -> 0 | U36: =SUM(S36:T36) -> 0 | X36: =SUM(V36:W36) -> 0 | Z36: =+F36+I36+L36+O36+R36+U36+X36+Y36 -> 0 | AC36: =+AA36+AB36-Z36 -> 0 | AE36: =AC36+AD36 -> 0
B37: 1111022 | C37: ชิฟฟ่อนเค้กสอดไส้แยม รสสตรอว์เบอร์รี (3 ชิ้น) | F37: =SUM(D37:E37) -> 0 | I37: =SUM(G37:H37) -> 0 | L37: =SUM(J37:K37) -> 0 | O37: =SUM(M37:N37) -> 0 | R37: =SUM(P37:Q37) -> 0 | U37: =SUM(S37:T37) -> 0 | X37: =SUM(V37:W37) -> 0 | Z37: =+F37+I37+L37+O37+R37+U37+X37+Y37 -> 0 | AC37: =+AA37+AB37-Z37 -> 0 | AE37: =AC37+AD37 -> 0
B38: 1111023 | C38: ชิฟฟ่อนเค้กสอดไส้แยม รสสตรอว์เบอร์รี (6 ชิ้น) | F38: =SUM(D38:E38) -> 0 | I38: =SUM(G38:H38) -> 0 | L38: =SUM(J38:K38) -> 0 | O38: =SUM(M38:N38) -> 0 | R38: =SUM(P38:Q38) -> 0 | U38: =SUM(S38:T38) -> 0 | X38: =SUM(V38:W38) -> 0 | Z38: =+F38+I38+L38+O38+R38+U38+X38+Y38 -> 0 | AC38: =+AA38+AB38-Z38 -> 0 | AE38: =AC38+AD38 -> 0
... B40: 1111025 | C40: ชิฟฟ่อนเค้กสอดไส้แยม รสส้ม (6 ชิ้น) | F40: =SUM(D40:E40) -> 0 | I40: =SUM(G40:H40) -> 0 | L40: =SUM(J40:K40) -> 0 | O40: =SUM(M40:N40) -> 0 | R40: =SUM(P40:Q40) -> 0 | U40: =SUM(S40:T40) -> 0 | X40: =SUM(V40:W40) -> 0 | Z40: =+F40+I40+L40+O40+R40+U40+X40+Y40 -> 0 | AC40: =+AA40+AB40-Z40 -> 0 | AE40: =AC40+AD40 -> 0
B41: 1111056 | C41: ชิฟฟอนรวมรสยอดฮิต 8 ชิ้น | F41: =SUM(D41:E41) -> 0 | G41: 6 | I41: =SUM(G41:H41) -> 6 | L41: =SUM(J41:K41) -> 0 | O41: =SUM(M41:N41) -> 0 | R41: =SUM(P41:Q41) -> 0 | U41: =SUM(S41:T41) -> 0 | X41: =SUM(V41:W41) -> 0 | Z41: =+F41+I41+L41+O41+R41+U41+X41+Y41 -> 6 | AB41: 14 | AC41: =+AA41+AB41-Z41 -> 8 | AD41: 10 | AE41: =AC41+AD41 -> 18
...

Sheet 02.10.68
B1: ยอดจริง ออนไลน์ วันที่ 02/10/2568
B2: รหัสสินค้า | C2: สินค้า | D2: ปณ | G2: ชอปปี้ | J2: ลาซาด้า | M2: ติ๊กตอก | P2: ติ๊กตอก2 | S2: ติ๊กตอก3 | V2: ชอยส์ | Y2: ยอดเส้น | Z2: ยอดรวมผลิต(กล่อง) | AA2: ยอดForcast | AB2: ยอดStock | AC2: ยอดMemo | AD2: ยอดForcastวันพรุ่งนี้ | AE2: สินค้าที่ขายได้
D3: เช้า | E3: บ่าย | F3: รวม | G3: เช้า | H3: บ่าย | I3: รวม | J3: เช้า | K3: บ่าย | L3: รวม | M3: เช้า | N3: บ่าย | O3: รวม | P3: เช้า | Q3: บ่าย | R3: รวม | S3: เช้า | T3: บ่าย | U3: รวม | V3: เช้า | W3: บ่าย | X3: รวม
B4: 1004055 | C4: ชิฟฟ่อนเค้ก วรรณวนัช (รวมรส 4 ชิ้น) | D4: 2 | F4: =SUM(D4:E4) -> 2 | I4: =SUM(G4:H4) -> 0 | L4: =SUM(J4:K4) -> 0 | M4: 78 | O4: =SUM(M4:N4) -> 78 | P4: 39 | R4: =SUM(P4:Q4) -> 39 | U4: =SUM(S4:T4) -> 0 | X4: =SUM(V4:W4) -> 0 | Z4: =+F4+I4+L4+O4+R4+U4+X4+Y4 -> 119 | AA4: 50 | AB4: 4 | AC4: =+AA4+AB4-Z4 -> -65 | AD4: 70 | AE4: =AC4+AD4 -> 5
B5: 1111002 | C5: ชิฟฟ่อนเค้ก วรรณวนัช (รวมรส 8 ชิ้น) | D5: 2 | F5: =SUM(D5:E5) -> 2 | G5: 34 | I5: =SUM(G5:H5) -> 34 | J5: 52 | L5: =SUM(J5:K5) -> 52 | M5: 9 | O5: =SUM(M5:N5) -> 9 | R5: =SUM(P5:Q5) -> 0 | U5: =SUM(S5:T5) -> 0 | X5: =SUM(V5:W5) -> 0 | Y5: 13 | Z5: =+F5+I5+L5+O5+R5+U5+X5+Y5 -> 110 | AA5: 110 | AB5: 30 | AC5: =+AA5+AB5-Z5 -> 30 | AD5: 120 | AE5: =AC5+AD5 -> 150
B6: 1111055 | C6: วรรณวนัช ชิฟฟ่อนรวมรส 8 ชิ้น | F6: =SUM(D6:E6) -> 0 | I6: =SUM(G6:H6) -> 0 | L6: =SUM(J6:K6) -> 0 | O6: =SUM(M6:N6) -> 0 | R6: =SUM(P6:Q6) -> 0 | U6: =SUM(S6:T6) -> 0 | X6: =SUM(V6:W6) -> 0 | Z6: =+F6+I6+L6+O6+R6+U6+X6+Y6 -> 0 | AC6: =+AA6+AB6-Z6 -> 0 | AE6: =AC6+AD6 -> 0
B7: 1111084 | C7: ชิฟฟ่อนเค้ก รสกาแฟ (8 ชิ้น) | F7: =SUM(D7:E7) -> 0 | I7: =SUM(G7:H7) -> 0 | L7: =SUM(J7:K7) -> 0 | O7: =SUM(M7:N7) -> 0 | R7: =SUM(P7:Q7) -> 0 | U7: =SUM(S7:T7) -> 0 | X7: =SUM(V7:W7) -> 0 | Z7: =+F7+I7+L7+O7+R7+U7+X7+Y7 -> 0 | AC7: =+AA7+AB7-Z7 -> 0 | AE7: =AC7+AD7 -> 0
B8: 1111043 | C8: ชิฟฟอนรสมะลิ 8 ชิ้น ห่อ ซีน | F8: =SUM(D8:E8) -> 0 | I8: =SUM(G8:H8) -> 0 | L8: =SUM(J8:K8) -> 0 | O8: =SUM(M8:N8) -> 0 | R8: =SUM(P8:Q8) -> 0 | U8: =SUM(S8:T8) -> 0 | X8: =SUM(V8:W8) -> 0 | Z8: =+F8+I8+L8+O8+R8+U8+X8+Y8 -> 0 | AC8: =+AA8+AB8-Z8 -> 0 | AE8: =AC8+AD8 -> 0
B9: 1111057 | C9: ชิฟฟอนแยกชิ้น กาแฟ | F9: =SUM(D9:E9) -> 0 | G9: 2 | I9: =SUM(G9:H9) -> 2 | L9: =SUM(J9:K9) -> 0 | O9: =SUM(M9:N9) -> 0 | R9: =SUM(P9:Q9) -> 0 | U9: =SUM(S9:T9) -> 0 | X9: =SUM(V9:W9) -> 0 | Z9: =+F9+I9+L9+O9+R9+U9+X9+Y9 -> 2 | AC9: =+AA9+AB9-Z9 -> -2 | AE9: =AC9+AD9 -> -2
B10: 1111058 | C10: ชิฟฟอนแยกชิ้น มะลิ | F10: =SUM(D10:E10) -> 0 | G10: 2 | I10: =SUM(G10:H10) -> 2 | L10: =SUM(J10:K10) -> 0 | O10: =SUM(M10:N10) -> 0 | R10: =SUM(P10:Q10) -> 0 | U10: =SUM(S10:T10) -> 0 | X10: =SUM(V10:W10) -> 0 | Z10: =+F10+I10+L10+O10+R10+U10+X10+Y10 -> 2 | AC10: =+AA10+AB10-Z10 -> -2 | AE10: =AC10+AD10 -> -2
B11: 1111059 | C11: ชิฟฟอนแยกชิ้น ใบเตย | F11: =SUM(D11:E11) -> 0 | G11: 2 | I11: =SUM(G11:H11) -> 2 | L11: =SUM(J11:K11) -> 0 | O11: =SUM(M11:N11) -> 0 | R11: =SUM(P11:Q11) -> 0 | U11: =SUM(S11:T11) -> 0 | X11: =SUM(V11:W11) -> 0 | Z11: =+F11+I11+L11+O11+R11+U11+X11+Y11 -> 2 | AC11: =+AA11+AB11-Z11 -> -2 | AE11: =AC11+AD11 -> -2
B12: 1111060 | C12: ชิฟฟอนแยกชิ้น กล้วยหอม | F12: =SUM(D12:E12) -> 0 | G12: 2 | I12: =SUM(G12:H12) -> 2 | L12: =SUM(J12:K12) -> 0 | O12: =SUM(M12:N12) -> 0 | R12: =SUM(P12:Q12) -> 0 | U12: =SUM(S12:T12) -> 0 | X12: =SUM(V12:W12) -> 0 | Z12: =+F12+I12+L12+O12+R12+U12+X12+Y12 -> 2 | AC12: =+AA12+AB12-Z12 -> -2 | AE12: =AC12+AD12 -> -2
B13: 1111061 | C13: ชิฟฟอนแยกชิ้น ชาไทย | F13: =SUM(D13:E13) -> 0 | G13: 2 | I13: =SUM(G13:H13) -> 2 | L13: =SUM(J13:K13) -> 0 | O13: =SUM(M13:N13) -> 0 | R13: =SUM(P13:Q13) -> 0 | U13: =SUM(S13:T13) -> 0 | X13: =SUM(V13:W13) -> 0 | Z13: =+F13+I13+L13+O13+R13+U13+X13+Y13 -> 2 | AC13: =+AA13+AB13-Z13 -> -2 | AE13: =AC13+AD13 -> -2
B14: 1111062 | C14: ชิฟฟอนแยกชิ้น โกโก้ | F14: =SUM(D14:E14) -> 0 | G14: 2 | I14: =SUM(G14:H14) -> 2 | L14: =SUM(J14:K14) -> 0 | O14: =SUM(M14:N14) -> 0 | R14: =SUM(P14:Q14) -> 0 | U14: =SUM(S14:T14) -> 0 | X14: =SUM(V14:W14) -> 0 | Z14: =+F14+I14+L14+O14+R14+U14+X14+Y14 -> 2 | AC14: =+AA14+AB14-Z14 -> -2 | AE14: =AC14+AD14 -> -2
B15: 1111063 | C15: ชิฟฟอนแยกชิ้น ส้ม | F15: =SUM(D15:E15) -> 0 | G15: 2 | I15: =SUM(G15:H15) -> 2 | L15: =SUM(J15:K15) -> 0 | O15: =SUM(M15:N15) -> 0 | R15: =SUM(P15:Q15) -> 0 | U15: =SUM(S15:T15) -> 0 | X15: =SUM(V15:W15) -> 0 | Z15: =+F15+I15+L15+O15+R15+U15+X15+Y15 -> 2 | AC15: =+AA15+AB15-Z15 -> -2 | AE15: =AC15+AD15 -> -2
B16: 1111064 | C16: ชิฟฟอนแยกชิ้น เผือก | F16: =SUM(D16:E16) -> 0 | G16: 1 | I16: =SUM(G16:H16) -> 1 | L16: =SUM(J16:K16) -> 0 | O16: =SUM(M16:N16) -> 0 | R16: =SUM(P16:Q16) -> 0 | U16: =SUM(S16:T16) -> 0 | X16: =SUM(V16:W16) -> 0 | Z16: =+F16+I16+L16+O16+R16+U16+X16+Y16 -> 1 | AC16: =+AA16+AB16-Z16 -> -1 | AE16: =AC16+AD16 -> -1
B17: 1111065 | C17: ชิฟฟอนแยกชิ้น สับปะรด | F17: =SUM(D17:E17) -> 0 | G17: 1 | I17: =SUM(G17:H17) -> 1 | L17: =SUM(J17:K17) -> 0 | O17: =SUM(M17:N17) -> 0 | R17: =SUM(P17:Q17) -> 0 | U17: =SUM(S17:T17) -> 0 | X17: =SUM(V17:W17) -> 0 | Z17: =+F17+I17+L17+O17+R17+U17+X17+Y17 -> 1 | AC17: =+AA17+AB17-Z17 -> -1 | AE17: =AC17+AD17 -> -1
B18: 1111066 | C18: ชิฟฟอนแยกชิ้น สตอเบอรี่ | F18: =SUM(D18:E18) -> 0 | G18: 1 | I18: =SUM(G18:H18) -> 1 | L18: =SUM(J18:K18) -> 0 | O18: =SUM(M18:N18) -> 0 | R18: =SUM(P18:Q18) -> 0 | U18: =SUM(S18:T18) -> 0 | X18: =SUM(V18:W18) -> 0 | Z18: =+F18+I18+L18+O18+R18+U18+X18+Y18 -> 1 | AC18: =+AA18+AB18-Z18 -> -1 | AE18: =AC18+AD18 -> -1
B19: 1111067 | C19: ชิฟฟอนแยกชิ้น มะพร้าว | F19: =SUM(D19:E19) -> 0 | G19: 1 | I19: =SUM(G19:H19) -> 1 | L19: =SUM(J19:K19) -> 0 | O19: =SUM(M19:N19) -> 0 | R19: =SUM(P19:Q19) -> 0 | U19: =SUM(S19:T19) -> 0 | X19: =SUM(V19:W19) -> 0 | Z19: =+F19+I19+L19+O19+R19+U19+X19+Y19 -> 1 | AC19: =+AA19+AB19-Z19 -> -1 | AE19: =AC19+AD19 -> -1
B20: 1111068 | C20: ชิฟฟอนแยกชิ้น เนย | F20: =SUM(D20:E20) -> 0 | G20: 1 | I20: =SUM(G20:H20) -> 1 | L20: =SUM(J20:K20) -> 0 | O20: =SUM(M20:N20) -> 0 | R20: =SUM(P20:Q20) -> 0 | U20: =SUM(S20:T20) -> 0 | X20: =SUM(V20:W20) -> 0 | Z20: =+F20+I20+L20+O20+R20+U20+X20+Y20 -> 1 | AC20: =+AA20+AB20-Z20 -> -1 | AE20: =AC20+AD20 -> -1
B21: 1111069 | C21: ชิฟฟอนแยกชิ้น บลูเบอรี่ | F21: =SUM(D21:E21) -> 0 | G21: 1 | I21: =SUM(G21:H21) -> 1 | L21: =SUM(J21:K21) -> 0 | O21: =SUM(M21:N21) -> 0 | R21: =SUM(P21:Q21) -> 0 | U21: =SUM(S21:T21) -> 0 | X21: =SUM(V21:W21) -> 0 | Z21: =+F21+I21+L21+O21+R21+U21+X21+Y21 -> 1 | AC21: =+AA21+AB21-Z21 -> -1 | AE21: =AC21+AD21 -> -1
B22: 1111070 | C22: ชิฟฟอนแยกชิ้น ทุเรียน | F22: =SUM(D22:E22) -> 0 | I22: =SUM(G22:H22) -> 0 | L22: =SUM(J22:K22) -> 0 | O22: =SUM(M22:N22) -> 0 | R22: =SUM(P22:Q22) -> 0 | U22: =SUM(S22:T22) -> 0 | X22: =SUM(V22:W22) -> 0 | Z22: =+F22+I22+L22+O22+R22+U22+X22+Y22 -> 0 | AC22: =+AA22+AB22-Z22 -> 0 | AE22: =AC22+AD22 -> 0
B23: 1111071 | C23: ชิฟฟอนแยกชิ้น ตาล | F23: =SUM(D23:E23) -> 0 | I23: =SUM(G23:H23) -> 0 | L23: =SUM(J23:K23) -> 0 | O23: =SUM(M23:N23) -> 0 | R23: =SUM(P23:Q23) -> 0 | U23: =SUM(S23:T23) -> 0 | X23: =SUM(V23:W23) -> 0 | Z23: =+F23+I23+L23+O23+R23+U23+X23+Y23 -> 0 | AC23: =+AA23+AB23-Z23 -> 0 | AE23: =AC23+AD23 -> 0
B24: 1111010 | C24: ชิฟฟ่อนเค้กสอดไส้แยม (1 ชิ้น) แยมสับปะรด | F24: =SUM(D24:E24) -> 0 | I24: =SUM(G24:H24) -> 0 | L24: =SUM(J24:K24) -> 0 | O24: =SUM(M24:N24) -> 0 | R24: =SUM(P24:Q24) -> 0 | U24: =SUM(S24:T24) -> 0 | X24: =SUM(V24:W24) -> 0 | Z24: =+F24+I24+L24+O24+R24+U24+X24+Y24 -> 0 | AC24: =+AA24+AB24-Z24 -> 0 | AE24: =AC24+AD24 -> 0
B25: 1111008 | C25: ชิฟฟ่อนเค้ก สอดไส้ (รวมรส 3 ชิ้น) | D25: 2 | F25: =SUM(D25:E25) -> 2 | G25: 16 | I25: =SUM(G25:H25) -> 16 | L25: =SUM(J25:K25) -> 0 | M25: 30 | O25: =SUM(M25:N25) -> 30 | R25: =SUM(P25:Q25) -> 0 | U25: =SUM(S25:T25) -> 0 | X25: =SUM(V25:W25) -> 0 | Y25: 3 | Z25: =+F25+I25+L25+O25+R25+U25+X25+Y25 -> 51 | AA25: 53 | AC25: =+AA25+AB25-Z25 -> 2 | AD25: 50 | AE25: =AC25+AD25 -> 52
B26: 1111009 | C26: ชิฟฟ่อนเค้ก สอดไส้ (รวมรส 6 ชิ้น) | D26: 2 | F26: =SUM(D26:E26) -> 2 | G26: 3 | I26: =SUM(G26:H26) -> 3 | J26: 4 | L26: =SUM(J26:K26) -> 4 | O26: =SUM(M26:N26) -> 0 | R26: =SUM(P26:Q26) -> 0 | U26: =SUM(S26:T26) -> 0 | X26: =SUM(V26:W26) -> 0 | Y26: 5 | Z26: =+F26+I26+L26+O26+R26+U26+X26+Y26 -> 14 | AA26: 25 | AB26: 1 | AC26: =+AA26+AB26-Z26 -> 12 | AD26: 30 | AE26: =AC26+AD26 -> 42
B27: 1111011 | C27: ชิฟฟ่อนเค้กสอดไส้ นมชมพูฮอกไกโด (3 ชิ้น) | F27: =SUM(D27:E27) -> 0 | I27: =SUM(G27:H27) -> 0 | L27: =SUM(J27:K27) -> 0 | O27: =SUM(M27:N27) -> 0 | R27: =SUM(P27:Q27) -> 0 | U27: =SUM(S27:T27) -> 0 | X27: =SUM(V27:W27) -> 0 | Z27: =+F27+I27+L27+O27+R27+U27+X27+Y27 -> 0 | AC27: =+AA27+AB27-Z27 -> 0 | AE27: =AC27+AD27 -> 0
B28: 1111012 | C28: ชิฟฟ่อนเค้กสอดไส้ นมชมพูฮอกไกโด (6 ชิ้น) | F28: =SUM(D28:E28) -> 0 | I28: =SUM(G28:H28) -> 0 | L28: =SUM(J28:K28) -> 0 | O28: =SUM(M28:N28) -> 0 | R28: =SUM(P28:Q28) -> 0 | U28: =SUM(S28:T28) -> 0 | X28: =SUM(V28:W28) -> 0 | Z28: =+F28+I28+L28+O28+R28+U28+X28+Y28 -> 0 | AC28: =+AA28+AB28-Z28 -> 0 | AE28: =AC28+AD28 -> 0
B29: 1111013 | C29: ชิฟฟ่อนเค้กสอดไส้ ช็อคโกแลตนูเทลล่า (3 ชิ้น) | F29: =SUM(D29:E29) -> 0 | I29: =SUM(G29:H29) -> 0 | L29: =SUM(J29:K29) -> 0 | O29: =SUM(M29:N29) -> 0 | R29: =SUM(P29:Q29) -> 0 | U29: =SUM(S29:T29) -> 0 | X29: =SUM(V29:W29) -> 0 | Z29: =+F29+I29+L29+O29+R29+U29+X29+Y29 -> 0 | AC29: =+AA29+AB29-Z29 -> 0 | AE29: =AC29+AD29 -> 0
B30: 1111014 | C30: ชิฟฟ่อนเค้กสอดไส้ ช็อคโกแลตนูเทลล่า (6 ชิ้น) | F30: =SUM(D30:E30) -> 0 | I30: =SUM(G30:H30) -> 0 | L30: =SUM(J30:K30) -> 0 | O30: =SUM(M30:N30) -> 0 | R30: =SUM(P30:Q30) -> 0 | U30: =SUM(S30:T30) -> 0 | X30: =SUM(V30:W30) -> 0 | Z30: =+F30+I30+L30+O30+R30+U30+X30+Y30 -> 0 | AC30: =+AA30+AB30-Z30 -> 0 | AE30: =AC30+AD30 -> 0
B31: 1111015 | C31: ชิฟฟ่อนเค้กสอดไส้เนย รสมะพร้าว (3 ชิ้น) | F31: =SUM(D31:E31) -> 0 | I31: =SUM(G31:H31) -> 0 | L31: =SUM(J31:K31) -> 0 | O31: =SUM(M31:N31) -> 0 | R31: =SUM(P31:Q31) -> 0 | U31: =SUM(S31:T31) -> 0 | X31: =SUM(V31:W31) -> 0 | Z31: =+F31+I31+L31+O31+R31+U31+X31+Y31 -> 0 | AC31: =+AA31+AB31-Z31 -> 0 | AE31: =AC31+AD31 -> 0
B32: 1111016 | C32: ชิฟฟ่อนเค้กสอดไส้เนย รสมะพร้าว (6 ชิ้น) | F32: =SUM(D32:E32) -> 0 | I32: =SUM(G32:H32) -> 0 | L32: =SUM(J32:K32) -> 0 | O32: =SUM(M32:N32) -> 0 | R32: =SUM(P32:Q32) -> 0 | U32: =SUM(S32:T32) -> 0 | X32: =SUM(V32:W32) -> 0 | Z32: =+F32+I32+L32+O32+R32+U32+X32+Y32 -> 0 | AC32: =+AA32+AB32-Z32 -> 0 | AE32: =AC32+AD32 -> 0
B33: 1111017 | C33: ชิฟฟ่อนเค้กสอดไส้แยม รสบลูเบอร์รี่ (3 ชิ้น) | F33: =SUM(D33:E33) -> 0 | I33: =SUM(G33:H33) -> 0 | L33: =SUM(J33:K33) -> 0 | O33: =SUM(M33:N33) -> 0 | R33: =SUM(P33:Q33) -> 0 | U33: =SUM(S33:T33) -> 0 | X33: =SUM(V33:W33) -> 0 | Z33: =+F33+I33+L33+O33+R33+U33+X33+Y33 -> 0 | AC33: =+AA33+AB33-Z33 -> 0 | AE33: =AC33+AD33 -> 0
B34: 1111018 | C34: ชิฟฟ่อนเค้กสอดไส้แยม รสบลูเบอร์รี่ (6 ชิ้น) | F34: =SUM(D34:E34) -> 0 | I34: =SUM(G34:H34) -> 0 | L34: =SUM(J34:K34) -> 0 | O34: =SUM(M34:N34) -> 0 | R34: =SUM(P34:Q34) -> 0 | U34: =SUM(S34:T34) -> 0 | X34: =SUM(V34:W34) -> 0 | Z34: =+F34+I34+L34+O34+R34+U34+X34+Y34 -> 0 | AC34: =+AA34+AB34-Z34 -> 0 | AE34: =AC34+AD34 -> 0
B35: 1111019 | C35: ชิฟฟ่อนเค้กหน้าฝอยทอง สอดไส้แยมส้ม (3 ชิ้น) | F35: =SUM(D35:E35) -> 0 | I35: =SUM(G35:H35) -> 0 | L35: =SUM(J35:K35) -> 0 | O35: =SUM(M35:N35) -> 0 | R35: =SUM(P35:Q35) -> 0 | U35: =SUM(S35:T35) -> 0 | X35: =SUM(V35:W35) -> 0 | Z35: =+F35+I35+L35+O35+R35+U35+X35+Y35 -> 0 | AC35: =+AA35+AB35-Z35 -> 0 | AE35: =AC35+AD35 -> 0
B36: 1111020 | C36: ชิฟฟ่อนเค้กหน้าฝอยทอง สอดไส้แยมส้ม (6 ชิ้น) | F36: =SUM(D36:E36) -> 0 | I36: =SUM(G36:H36) -> 0 | L36: =SUM(J36:K36) -> 0 | O36: =SUM(M36:N36) -> 0 | R36: =SUM(P36:Q36) -> 0 | U36: =SUM(S36:T36) -> 0 | X36: =SUM(V36:W36) -> 0 | Y36: 15 | Z36: =+F36+I36+L36+O36+R36+U36+X36+Y36 -> 15 | AA36: 15 | AC36: =+AA36+AB36-Z36 -> 0 | AE36: =AC36+AD36 -> 0
B37: 1111022 | C37: ชิฟฟ่อนเค้กสอดไส้แยม รสสตรอว์เบอร์รี (3 ชิ้น) | F37: =SUM(D37:E37) -> 0 | I37: =SUM(G37:H37) -> 0 | L37: =SUM(J37:K37) -> 0 | O37: =SUM(M37:N37) -> 0 | R37: =SUM(P37:Q37) -> 0 | U37: =SUM(S37:T37) -> 0 | X37: =SUM(V37:W37) -> 0 | Z37: =+F37+I37+L37+O37+R37+U37+X37+Y37 -> 0 | AC37: =+AA37+AB37-Z37 -> 0 | AE37: =AC37+AD37 -> 0
B38: 1111023 | C38: ชิฟฟ่อนเค้กสอดไส้แยม รสสตรอว์เบอร์รี (6 ชิ้น) | F38: =SUM(D38:E38) -> 0 | I38: =SUM(G38:H38) -> 0 | L38: =SUM(J38:K38) -> 0 | O38: =SUM(M38:N38) -> 0 | R38: =SUM(P38:Q38) -> 0 | U38: =SUM(S38:T38) -> 0 | X38: =SUM(V38:W38) -> 0 | Z38: =+F38+I38+L38+O38+R38+U38+X38+Y38 -> 0 | AC38: =+AA38+AB38-Z38 -> 0 | AE38: =AC38+AD38 -> 0
B39: 1111024 | C39: ชิฟฟ่อนเค้กสอดไส้แยม รสส้ม (3 ชิ้น) | F39: =SUM(D39:E39) -> 0 | I39: =SUM(G39:H39) -> 0 | L39: =SUM(J39:K39) -> 0 | O39: =SUM(M39:N39) -> 0 | R39: =SUM(P39:Q39) -> 0 | U39: =SUM(S39:T39) -> 0 | X39: =SUM(V39:W39) -> 0 | Z39: =+F39+I39+L39+O39+R39+U39+X39+Y39 -> 0 | AC39: =+AA39+AB39-Z39 -> 0 | AE39: =AC39+AD39 -> 0
B40: 1111025 | C40: ชิฟฟ่อนเค้กสอดไส้แยม รสส้ม (6 ชิ้น) | F40: =SUM(D40:E40) -> 0 | I40: =SUM(G40:H40) -> 0 | L40: =SUM(J40:K40) -> 0 | O40: =SUM(M40:N40) -> 0 | R40: =SUM(P40:Q40) -> 0 | U40: =SUM(S40:T40) -> 0 | X40: =SUM(V40:W40) -> 0 | Z40: =+F40+I40+L40+O40+R40+U40+X40+Y40 -> 0 | AC40: =+AA40+AB40-Z40 -> 0 | AE40: =AC40+AD40 -> 0
...

Sheet 03.10.68
B1: ยอดจริง ออนไลน์ วันที่ 03/10/2568
B2: รหัสสินค้า | C2: สินค้า | D2: ปณ | G2: ชอปปี้ | J2: ลาซาด้า | M2: ติ๊กตอก | P2: ติ๊กตอก2 | S2: ติ๊กตอก3 | V2: ชอยส์ | Y2: ยอดเส้น | Z2: ยอดรวมผลิต(กล่อง) | AA2: ยอดForcast | AB2: ยอดStock | AC2: ยอดMemo | AD2: ยอดForcastวันพรุ่งนี้ | AE2: สินค้าที่ขายได้
D3: เช้า | E3: บ่าย | F3: รวม | G3: เช้า | H3: บ่าย | I3: รวม | J3: เช้า | K3: บ่าย | L3: รวม | M3: เช้า | N3: บ่าย | O3: รวม | P3: เช้า | Q3: บ่าย | R3: รวม | S3: เช้า | T3: บ่าย | U3: รวม | V3: เช้า | W3: บ่าย | X3: รวม
B4: 1004055 | C4: ชิฟฟ่อนเค้ก วรรณวนัช (รวมรส 4 ชิ้น) | D4: 1 | F4: =SUM(D4:E4) -> 1 | G4: 5 | I4: =SUM(G4:H4) -> 5 | L4: =SUM(J4:K4) -> 0 | M4: 18 | N4: 24 | O4: =SUM(M4:N4) -> 42 | R4: =SUM(P4:Q4) -> 0 | U4: =SUM(S4:T4) -> 0 | X4: =SUM(V4:W4) -> 0 | Y4: 5 | Z4: =+F4+I4+L4+O4+R4+U4+X4+Y4 -> 53 | AA4: 75 | AB4: 3 | AC4: =+AA4+AB4-Z4 -> 25 | AD4: 70 | AE4: =AC4+AD4 -> 95
B5: 1111002 | C5: ชิฟฟ่อนเค้ก วรรณวนัช (รวมรส 8 ชิ้น) | D5: 9 | F5: =SUM(D5:E5) -> 9 | G5: 25 | H5: 17 | I5: =SUM(G5:H5) -> 42 | J5: 31 | L5: =SUM(J5:K5) -> 31 | M5: 9 | N5: 3 | O5: =SUM(M5:N5) -> 12 | P5: 3 | R5: =SUM(P5:Q5) -> 3 | U5: =SUM(S5:T5) -> 0 | X5: =SUM(V5:W5) -> 0 | Y5: 3 | Z5: =+F5+I5+L5+O5+R5+U5+X5+Y5 -> 100 | AA5: 123 | AB5: 3 | AC5: =+AA5+AB5-Z5 -> 26 | AD5: 120 | AE5: =AC5+AD5 -> 146
B6: 1111055 | C6: วรรณวนัช ชิฟฟ่อนรวมรส 8 ชิ้น | F6: =SUM(D6:E6) -> 0 | I6: =SUM(G6:H6) -> 0 | L6: =SUM(J6:K6) -> 0 | O6: =SUM(M6:N6) -> 0 | R6: =SUM(P6:Q6) -> 0 | U6: =SUM(S6:T6) -> 0 | X6: =SUM(V6:W6) -> 0 | Z6: =+F6+I6+L6+O6+R6+U6+X6+Y6 -> 0 | AC6: =+AA6+AB6-Z6 -> 0 | AE6: =AC6+AD6 -> 0
B7: 1111084 | C7: ชิฟฟ่อนเค้ก รสกาแฟ (8 ชิ้น) | F7: =SUM(D7:E7) -> 0 | I7: =SUM(G7:H7) -> 0 | L7: =SUM(J7:K7) -> 0 | O7: =SUM(M7:N7) -> 0 | R7: =SUM(P7:Q7) -> 0 | U7: =SUM(S7:T7) -> 0 | X7: =SUM(V7:W7) -> 0 | Z7: =+F7+I7+L7+O7+R7+U7+X7+Y7 -> 0 | AC7: =+AA7+AB7-Z7 -> 0 | AE7: =AC7+AD7 -> 0
B8: 1111043 | C8: ชิฟฟอนรสมะลิ 8 ชิ้น ห่อ ซีน | F8: =SUM(D8:E8) -> 0 | I8: =SUM(G8:H8) -> 0 | L8: =SUM(J8:K8) -> 0 | O8: =SUM(M8:N8) -> 0 | R8: =SUM(P8:Q8) -> 0 | U8: =SUM(S8:T8) -> 0 | X8: =SUM(V8:W8) -> 0 | Z8: =+F8+I8+L8+O8+R8+U8+X8+Y8 -> 0 | AC8: =+AA8+AB8-Z8 -> 0 | AE8: =AC8+AD8 -> 0
B9: 1111057 | C9: ชิฟฟอนแยกชิ้น กาแฟ | F9: =SUM(D9:E9) -> 0 | G9: 2 | I9: =SUM(G9:H9) -> 2 | L9: =SUM(J9:K9) -> 0 | M9: 1 | O9: =SUM(M9:N9) -> 1 | R9: =SUM(P9:Q9) -> 0 | U9: =SUM(S9:T9) -> 0 | X9: =SUM(V9:W9) -> 0 | Z9: =+F9+I9+L9+O9+R9+U9+X9+Y9 -> 3 | AC9: =+AA9+AB9-Z9 -> -3 | AE9: =AC9+AD9 -> -3
B10: 1111058 | C10: ชิฟฟอนแยกชิ้น มะลิ | F10: =SUM(D10:E10) -> 0 | G10: 2 | I10: =SUM(G10:H10) -> 2 | L10: =SUM(J10:K10) -> 0 | M10: 1 | O10: =SUM(M10:N10) -> 1 | R10: =SUM(P10:Q10) -> 0 | U10: =SUM(S10:T10) -> 0 | X10: =SUM(V10:W10) -> 0 | Z10: =+F10+I10+L10+O10+R10+U10+X10+Y10 -> 3 | AC10: =+AA10+AB10-Z10 -> -3 | AE10: =AC10+AD10 -> -3
B11: 1111059 | C11: ชิฟฟอนแยกชิ้น ใบเตย | F11: =SUM(D11:E11) -> 0 | G11: 2 | I11: =SUM(G11:H11) -> 2 | L11: =SUM(J11:K11) -> 0 | M11: 1 | O11: =SUM(M11:N11) -> 1 | R11: =SUM(P11:Q11) -> 0 | U11: =SUM(S11:T11) -> 0 | X11: =SUM(V11:W11) -> 0 | Z11: =+F11+I11+L11+O11+R11+U11+X11+Y11 -> 3 | AC11: =+AA11+AB11-Z11 -> -3 | AE11: =AC11+AD11 -> -3
B12: 1111060 | C12: ชิฟฟอนแยกชิ้น กล้วยหอม | F12: =SUM(D12:E12) -> 0 | G12: 2 | I12: =SUM(G12:H12) -> 2 | L12: =SUM(J12:K12) -> 0 | M12: 1 | O12: =SUM(M12:N12) -> 1 | R12: =SUM(P12:Q12) -> 0 | U12: =SUM(S12:T12) -> 0 | X12: =SUM(V12:W12) -> 0 | Z12: =+F12+I12+L12+O12+R12+U12+X12+Y12 -> 3 | AC12: =+AA12+AB12-Z12 -> -3 | AE12: =AC12+AD12 -> -3
B13: 1111061 | C13: ชิฟฟอนแยกชิ้น ชาไทย | F13: =SUM(D13:E13) -> 0 | G13: 2 | I13: =SUM(G13:H13) -> 2 | L13: =SUM(J13:K13) -> 0 | M13: 1 | O13: =SUM(M13:N13) -> 1 | R13: =SUM(P13:Q13) -> 0 | U13: =SUM(S13:T13) -> 0 | X13: =SUM(V13:W13) -> 0 | Z13: =+F13+I13+L13+O13+R13+U13+X13+Y13 -> 3 | AC13: =+AA13+AB13-Z13 -> -3 | AE13: =AC13+AD13 -> -3
B14: 1111062 | C14: ชิฟฟอนแยกชิ้น โกโก้ | F14: =SUM(D14:E14) -> 0 | G14: 2 | I14: =SUM(G14:H14) -> 2 | L14: =SUM(J14:K14) -> 0 | M14: 1 | O14: =SUM(M14:N14) -> 1 | R14: =SUM(P14:Q14) -> 0 | U14: =SUM(S14:T14) -> 0 | X14: =SUM(V14:W14) -> 0 | Z14: =+F14+I14+L14+O14+R14+U14+X14+Y14 -> 3 | AC14: =+AA14+AB14-Z14 -> -3 | AE14: =AC14+AD14 -> -3
B15: 1111063 | C15: ชิฟฟอนแยกชิ้น ส้ม | F15: =SUM(D15:E15) -> 0 | G15: 2 | I15: =SUM(G15:H15) -> 2 | L15: =SUM(J15:K15) -> 0 | M15: 1 | O15: =SUM(M15:N15) -> 1 | R15: =SUM(P15:Q15) -> 0 | U15: =SUM(S15:T15) -> 0 | X15: =SUM(V15:W15) -> 0 | Z15: =+F15+I15+L15+O15+R15+U15+X15+Y15 -> 3 | AC15: =+AA15+AB15-Z15 -> -3 | AE15: =AC15+AD15 -> -3
B16: 1111064 | C16: ชิฟฟอนแยกชิ้น เผือก | F16: =SUM(D16:E16) -> 0 | G16: 1 | I16: =SUM(G16:H16) -> 1 | L16: =SUM(J16:K16) -> 0 | M16: 1 | O16: =SUM(M16:N16) -> 1 | R16: =SUM(P16:Q16) -> 0 | U16: =SUM(S16:T16) -> 0 | X16: =SUM(V16:W16) -> 0 | Z16: =+F16+I16+L16+O16+R16+U16+X16+Y16 -> 2 | AC16: =+AA16+AB16-Z16 -> -2 | AE16: =AC16+AD16 -> -2
B17: 1111065 | C17: ชิฟฟอนแยกชิ้น สับปะรด | F17: =SUM(D17:E17) -> 0 | G17: 1 | I17: =SUM(G17:H17) -> 1 | L17: =SUM(J17:K17) -> 0 | M17: 1 | O17: =SUM(M17:N17) -> 1 | R17: =SUM(P17:Q17) -> 0 | U17: =SUM(S17:T17) -> 0 | X17: =SUM(V17:W17) -> 0 | Z17: =+F17+I17+L17+O17+R17+U17+X17+Y17 -> 2 | AC17: =+AA17+AB17-Z17 -> -2 | AE17: =AC17+AD17 -> -2
B18: 1111066 | C18: ชิฟฟอนแยกชิ้น สตอเบอรี่ | F18: =SUM(D18:E18) -> 0 | G18: 1 | I18: =SUM(G18:H18) -> 1 | L18: =SUM(J18:K18) -> 0 | M18: 1 | O18: =SUM(M18:N18) -> 1 | R18: =SUM(P18:Q18) -> 0 | U18: =SUM(S18:T18) -> 0 | X18: =SUM(V18:W18) -> 0 | Z18: =+F18+I18+L18+O18+R18+U18+X18+Y18 -> 2 | AA18: 10 | AC18: =+AA18+AB18-Z18 -> 8 | AE18: =AC18+AD18 -> 8
B19: 1111067 | C19: ชิฟฟอนแยกชิ้น มะพร้าว | F19: =SUM(D19:E19) -> 0 | G19: 1 | I19: =SUM(G19:H19) -> 1 | L19: =SUM(J19:K19) -> 0 | O19: =SUM(M19:N19) -> 0 | R19: =SUM(P19:Q19) -> 0 | U19: =SUM(S19:T19) -> 0 | X19: =SUM(V19:W19) -> 0 | Z19: =+F19+I19+L19+O19+R19+U19+X19+Y19 -> 1 | AA19: 10 | AC19: =+AA19+AB19-Z19 -> 9 | AE19: =AC19+AD19 -> 9
B20: 1111068 | C20: ชิฟฟอนแยกชิ้น เนย | F20: =SUM(D20:E20) -> 0 | G20: 1 | I20: =SUM(G20:H20) -> 1 | L20: =SUM(J20:K20) -> 0 | O20: =SUM(M20:N20) -> 0 | R20: =SUM(P20:Q20) -> 0 | U20: =SUM(S20:T20) -> 0 | X20: =SUM(V20:W20) -> 0 | Z20: =+F20+I20+L20+O20+R20+U20+X20+Y20 -> 1 | AC20: =+AA20+AB20-Z20 -> -1 | AE20: =AC20+AD20 -> -1
B21: 1111069 | C21: ชิฟฟอนแยกชิ้น บลูเบอรี่ | F21: =SUM(D21:E21) -> 0 | G21: 1 | I21: =SUM(G21:H21) -> 1 | L21: =SUM(J21:K21) -> 0 | O21: =SUM(M21:N21) -> 0 | R21: =SUM(P21:Q21) -> 0 | U21: =SUM(S21:T21) -> 0 | X21: =SUM(V21:W21) -> 0 | Z21: =+F21+I21+L21+O21+R21+U21+X21+Y21 -> 1 | AC21: =+AA21+AB21-Z21 -> -1 | AE21: =AC21+AD21 -> -1
B22: 1111070 | C22: ชิฟฟอนแยกชิ้น ทุเรียน | F22: =SUM(D22:E22) -> 0 | I22: =SUM(G22:H22) -> 0 | L22: =SUM(J22:K22) -> 0 | O22: =SUM(M22:N22) -> 0 | R22: =SUM(P22:Q22) -> 0 | U22: =SUM(S22:T22) -> 0 | X22: =SUM(V22:W22) -> 0 | Z22: =+F22+I22+L22+O22+R22+U22+X22+Y22 -> 0 | AC22: =+AA22+AB22-Z22 -> 0 | AE22: =AC22+AD22 -> 0
B23: 1111071 | C23: ชิฟฟอนแยกชิ้น ตาล | F23: =SUM(D23:E23) -> 0 | I23: =SUM(G23:H23) -> 0 | L23: =SUM(J23:K23) -> 0 | O23: =SUM(M23:N23) -> 0 | R23: =SUM(P23:Q23) -> 0 | U23: =SUM(S23:T23) -> 0 | X23: =SUM(V23:W23) -> 0 | Z23: =+F23+I23+L23+O23+R23+U23+X23+Y23 -> 0 | AC23: =+AA23+AB23-Z23 -> 0 | AE23: =AC23+AD23 -> 0
B24: 1111010 | C24: ชิฟฟ่อนเค้กสอดไส้แยม (1 ชิ้น) แยมสับปะรด | F24: =SUM(D24:E24) -> 0 | I24: =SUM(G24:H24) -> 0 | L24: =SUM(J24:K24) -> 0 | O24: =SUM(M24:N24) -> 0 | R24: =SUM(P24:Q24) -> 0 | U24: =SUM(S24:T24) -> 0 | X24: =SUM(V24:W24) -> 0 | Z24: =+F24+I24+L24+O24+R24+U24+X24+Y24 -> 0 | AC24: =+AA24+AB24-Z24 -> 0 | AE24: =AC24+AD24 -> 0
B25: 1111008 | C25: ชิฟฟ่อนเค้ก สอดไส้ (รวมรส 3 ชิ้น) | D25: 1 | F25: =SUM(D25:E25) -> 1 | G25: 6 | I25: =SUM(G25:H25) -> 6 | L25: =SUM(J25:K25) -> 0 | M25: 21 | N25: 27 | O25: =SUM(M25:N25) -> 48 | P25: 3 | R25: =SUM(P25:Q25) -> 3 | U25: =SUM(S25:T25) -> 0 | X25: =SUM(V25:W25) -> 0 | Z25: =+F25+I25+L25+O25+R25+U25+X25+Y25 -> 58 | AA25: 50 | AB25: 2 | AC25: =+AA25+AB25-Z25 -> -6 | AD25: 50 | AE25: =AC25+AD25 -> 44
B26: 1111009 | C26: ชิฟฟ่อนเค้ก สอดไส้ (รวมรส 6 ชิ้น) | D26: 3 | F26: =SUM(D26:E26) -> 3 | G26: 8 | H26: 2 | I26: =SUM(G26:H26) -> 10 | J26: 7 | L26: =SUM(J26:K26) -> 7 | O26: =SUM(M26:N26) -> 0 | R26: =SUM(P26:Q26) -> 0 | U26: =SUM(S26:T26) -> 0 | X26: =SUM(V26:W26) -> 0 | Z26: =+F26+I26+L26+O26+R26+U26+X26+Y26 -> 20 | AA26: 30 | AB26: 8 | AC26: =+AA26+AB26-Z26 -> 18 | AD26: 30 | AE26: =AC26+AD26 -> 48
B27: 1111011 | C27: ชิฟฟ่อนเค้กสอดไส้ นมชมพูฮอกไกโด (3 ชิ้น) | F27: =SUM(D27:E27) -> 0 | I27: =SUM(G27:H27) -> 0 | L27: =SUM(J27:K27) -> 0 | O27: =SUM(M27:N27) -> 0 | R27: =SUM(P27:Q27) -> 0 | U27: =SUM(S27:T27) -> 0 | X27: =SUM(V27:W27) -> 0 | Z27: =+F27+I27+L27+O27+R27+U27+X27+Y27 -> 0 | AC27: =+AA27+AB27-Z27 -> 0 | AE27: =AC27+AD27 -> 0
B28: 1111012 | C28: ชิฟฟ่อนเค้กสอดไส้ นมชมพูฮอกไกโด (6 ชิ้น) | F28: =SUM(D28:E28) -> 0 | I28: =SUM(G28:H28) -> 0 | L28: =SUM(J28:K28) -> 0 | O28: =SUM(M28:N28) -> 0 | R28: =SUM(P28:Q28) -> 0 | U28: =SUM(S28:T28) -> 0 | X28: =SUM(V28:W28) -> 0 | Z28: =+F28+I28+L28+O28+R28+U28+X28+Y28 -> 0 | AC28: =+AA28+AB28-Z28 -> 0 | AE28: =AC28+AD28 -> 0
B29: 1111013 | C29: ชิฟฟ่อนเค้กสอดไส้ ช็อคโกแลตนูเทลล่า (3 ชิ้น) | F29: =SUM(D29:E29) -> 0 | I29: =SUM(G29:H29) -> 0 | L29: =SUM(J29:K29) -> 0 | O29: =SUM(M29:N29) -> 0 | R29: =SUM(P29:Q29) -> 0 | U29: =SUM(S29:T29) -> 0 | X29: =SUM(V29:W29) -> 0 | Z29: =+F29+I29+L29+O29+R29+U29+X29+Y29 -> 0 | AC29: =+AA29+AB29-Z29 -> 0 | AE29: =AC29+AD29 -> 0
B30: 1111014 | C30: ชิฟฟ่อนเค้กสอดไส้ ช็อคโกแลตนูเทลล่า (6 ชิ้น) | F30: =SUM(D30:E30) -> 0 | I30: =SUM(G30:H30) -> 0 | L30: =SUM(J30:K30) -> 0 | O30: =SUM(M30:N30) -> 0 | R30: =SUM(P30:Q30) -> 0 | U30: =SUM(S30:T30) -> 0 | X30: =SUM(V30:W30) -> 0 | Z30: =+F30+I30+L30+O30+R30+U30+X30+Y30 -> 0 | AC30: =+AA30+AB30-Z30 -> 0 | AE30: =AC30+AD30 -> 0
B31: 1111015 | C31: ชิฟฟ่อนเค้กสอดไส้เนย รสมะพร้าว (3 ชิ้น) | F31: =SUM(D31:E31) -> 0 | I31: =SUM(G31:H31) -> 0 | L31: =SUM(J31:K31) -> 0 | O31: =SUM(M31:N31) -> 0 | R31: =SUM(P31:Q31) -> 0 | U31: =SUM(S31:T31) -> 0 | X31: =SUM(V31:W31) -> 0 | Z31: =+F31+I31+L31+O31+R31+U31+X31+Y31 -> 0 | AC31: =+AA31+AB31-Z31 -> 0 | AE31: =AC31+AD31 -> 0
B32: 1111016 | C32: ชิฟฟ่อนเค้กสอดไส้เนย รสมะพร้าว (6 ชิ้น) | F32: =SUM(D32:E32) -> 0 | I32: =SUM(G32:H32) -> 0 | L32: =SUM(J32:K32) -> 0 | O32: =SUM(M32:N32) -> 0 | R32: =SUM(P32:Q32) -> 0 | U32: =SUM(S32:T32) -> 0 | X32: =SUM(V32:W32) -> 0 | Z32: =+F32+I32+L32+O32+R32+U32+X32+Y32 -> 0 | AC32: =+AA32+AB32-Z32 -> 0 | AE32: =AC32+AD32 -> 0
B33: 1111017 | C33: ชิฟฟ่อนเค้กสอดไส้แยม รสบลูเบอร์รี่ (3 ชิ้น) | F33: =SUM(D33:E33) -> 0 | I33: =SUM(G33:H33) -> 0 | L33: =SUM(J33:K33) -> 0 | O33: =SUM(M33:N33) -> 0 | R33: =SUM(P33:Q33) -> 0 | U33: =SUM(S33:T33) -> 0 | X33: =SUM(V33:W33) -> 0 | Z33: =+F33+I33+L33+O33+R33+U33+X33+Y33 -> 0 | AC33: =+AA33+AB33-Z33 -> 0 | AE33: =AC33+AD33 -> 0
B34: 1111018 | C34: ชิฟฟ่อนเค้กสอดไส้แยม รสบลูเบอร์รี่ (6 ชิ้น) | F34: =SUM(D34:E34) -> 0 | I34: =SUM(G34:H34) -> 0 | L34: =SUM(J34:K34) -> 0 | O34: =SUM(M34:N34) -> 0 | R34: =SUM(P34:Q34) -> 0 | U34: =SUM(S34:T34) -> 0 | X34: =SUM(V34:W34) -> 0 | Z34: =+F34+I34+L34+O34+R34+U34+X34+Y34 -> 0 | AC34: =+AA34+AB34-Z34 -> 0 | AE34: =AC34+AD34 -> 0
B35: 1111019 | C35: ชิฟฟ่อนเค้กหน้าฝอยทอง สอดไส้แยมส้ม (3 ชิ้น) | F35: =SUM(D35:E35) -> 0 | I35: =SUM(G35:H35) -> 0 | L35: =SUM(J35:K35) -> 0 | O35: =SUM(M35:N35) -> 0 | R35: =SUM(P35:Q35) -> 0 | U35: =SUM(S35:T35) -> 0 | X35: =SUM(V35:W35) -> 0 | Z35: =+F35+I35+L35+O35+R35+U35+X35+Y35 -> 0 | AC35: =+AA35+AB35-Z35 -> 0 | AE35: =AC35+AD35 -> 0
B36: 1111020 | C36: ชิฟฟ่อนเค้กหน้าฝอยทอง สอดไส้แยมส้ม (6 ชิ้น) | F36: =SUM(D36:E36) -> 0 | I36: =SUM(G36:H36) -> 0 | L36: =SUM(J36:K36) -> 0 | O36: =SUM(M36:N36) -> 0 | R36: =SUM(P36:Q36) -> 0 | U36: =SUM(S36:T36) -> 0 | X36: =SUM(V36:W36) -> 0 | Z36: =+F36+I36+L36+O36+R36+U36+X36+Y36 -> 0 | AC36: =+AA36+AB36-Z36 -> 0 | AE36: =AC36+AD36 -> 0
B37: 1111022 | C37: ชิฟฟ่อนเค้กสอดไส้แยม รสสตรอว์เบอร์รี (3 ชิ้น) | F37: =SUM(D37:E37) -> 0 | I37: =SUM(G37:H37) -> 0 | L37: =SUM(J37:K37) -> 0 | O37: =SUM(M37:N37) -> 0 | R37: =SUM(P37:Q37) -> 0 | U37: =SUM(S37:T37) -> 0 | X37: =SUM(V37:W37) -> 0 | Z37: =+F37+I37+L37+O37+R37+U37+X37+Y37 -> 0 | AC37: =+AA37+AB37-Z37 -> 0 | AE37: =AC37+AD37 -> 0
B38: 1111023 | C38: ชิฟฟ่อนเค้กสอดไส้แยม รสสตรอว์เบอร์รี (6 ชิ้น) | F38: =SUM(D38:E38) -> 0 | I38: =SUM(G38:H38) -> 0 | L38: =SUM(J38:K38) -> 0 | O38: =SUM(M38:N38) -> 0 | R38: =SUM(P38:Q38) -> 0 | U38: =SUM(S38:T38) -> 0 | X38: =SUM(V38:W38) -> 0 | Z38: =+F38+I38+L38+O38+R38+U38+X38+Y38 -> 0 | AC38: =+AA38+AB38-Z38 -> 0 | AE38: =AC38+AD38 -> 0
... B40: 1111025 | C40: ชิฟฟ่อนเค้กสอดไส้แยม รสส้ม (6 ชิ้น) | F40: =SUM(D40:E40) -> 0 | I40: =SUM(G40:H40) -> 0 | L40: =SUM(J40:K40) -> 0 | O40: =SUM(M40:N40) -> 0 | R40: =SUM(P40:Q40) -> 0 | U40: =SUM(S40:T40) -> 0 | X40: =SUM(V40:W40) -> 0 | Z40: =+F40+I40+L40+O40+R40+U40+X40+Y40 -> 0 | AC40: =+AA40+AB40-Z40 -> 0 | AE40: =AC40+AD40 -> 0
B41: 1111056 | C41: ชิฟฟอนรวมรสยอดฮิต 8 ชิ้น | D41: 2 | F41: =SUM(D41:E41) -> 2 | G41: 2 | H41: 1 | I41: =SUM(G41:H41) -> 3 | J41: 3 | L41: =SUM(J41:K41) -> 3 | O41: =SUM(M41:N41) -> 0 | R41: =SUM(P41:Q41) -> 0 | U41: =SUM(S41:T41) -> 0 | X41: =SUM(V41:W41) -> 0 | Z41: =+F41+I41+L41+O41+R41+U41+X41+Y41 -> 8 | AA41: 10 | AB41: 1 | AC41: =+AA41+AB41-Z41 -> 3 | AE41: =AC41+AD41 -> 3
...

Sheet 04.10.68
B1: ยอดจริง ออนไลน์ วันที่ 04/10/2568
B2: รหัสสินค้า | C2: สินค้า | D2: ปณ | G2: ชอปปี้ | J2: ลาซาด้า | M2: ติ๊กตอก | P2: ติ๊กตอก2 | S2: ติ๊กตอก3 | V2: ชอยส์ | Y2: ยอดเส้น | Z2: ยอดรวมผลิต(กล่อง) | AA2: ยอดForcast | AB2: ยอดStock | AC2: ยอดMemo | AD2: ยอดForcastวันพรุ่งนี้ | AE2: สินค้าที่ขายได้
D3: เช้า | E3: บ่าย | F3: รวม | G3: เช้า | H3: บ่าย | I3: รวม | J3: เช้า | K3: บ่าย | L3: รวม | M3: เช้า | N3: บ่าย | O3: รวม | P3: เช้า | Q3: บ่าย | R3: รวม | S3: เช้า | T3: บ่าย | U3: รวม | V3: เช้า | W3: บ่าย | X3: รวม
B4: 1004055 | C4: ชิฟฟ่อนเค้ก วรรณวนัช (รวมรส 4 ชิ้น) | D4: 4 | F4: =SUM(D4:E4) -> 4 | I4: =SUM(G4:H4) -> 0 | J4: 3 | L4: =SUM(J4:K4) -> 3 | M4: 67 | N4: 36 | O4: =SUM(M4:N4) -> 103 | R4: =SUM(P4:Q4) -> 0 | U4: =SUM(S4:T4) -> 0 | X4: =SUM(V4:W4) -> 0 | Z4: =+F4+I4+L4+O4+R4+U4+X4+Y4 -> 110 | AA4: 70 | AB4: 24 | AC4: =+AA4+AB4-Z4 -> -16 | AD4: 90 | AE4: =AC4+AD4 -> 74
B5: 1111002 | C5: ชิฟฟ่อนเค้ก วรรณวนัช (รวมรส 8 ชิ้น) | D5: 4 | F5: =SUM(D5:E5) -> 4 | G5: 12 | H5: 5 | I5: =SUM(G5:H5) -> 17 | J5: 20 | L5: =SUM(J5:K5) -> 20 | M5: 7 | N5: 3 | O5: =SUM(M5:N5) -> 10 | R5: =SUM(P5:Q5) -> 0 | U5: =SUM(S5:T5) -> 0 | X5: =SUM(V5:W5) -> 0 | Z5: =+F5+I5+L5+O5+R5+U5+X5+Y5 -> 51 | AA5: 120 | AB5: 25 | AC5: =+AA5+AB5-Z5 -> 94 | AD5: 130 | AE5: =AC5+AD5 -> 224
B6: 1111055 | C6: วรรณวนัช ชิฟฟ่อนรวมรส 8 ชิ้น | F6: =SUM(D6:E6) -> 0 | I6: =SUM(G6:H6) -> 0 | L6: =SUM(J6:K6) -> 0 | O6: =SUM(M6:N6) -> 0 | R6: =SUM(P6:Q6) -> 0 | U6: =SUM(S6:T6) -> 0 | X6: =SUM(V6:W6) -> 0 | Z6: =+F6+I6+L6+O6+R6+U6+X6+Y6 -> 0 | AC6: =+AA6+AB6-Z6 -> 0 | AE6: =AC6+AD6 -> 0
B7: 1111084 | C7: ชิฟฟ่อนเค้ก รสกาแฟ (8 ชิ้น) | F7: =SUM(D7:E7) -> 0 | I7: =SUM(G7:H7) -> 0 | L7: =SUM(J7:K7) -> 0 | O7: =SUM(M7:N7) -> 0 | R7: =SUM(P7:Q7) -> 0 | U7: =SUM(S7:T7) -> 0 | X7: =SUM(V7:W7) -> 0 | Z7: =+F7+I7+L7+O7+R7+U7+X7+Y7 -> 0 | AC7: =+AA7+AB7-Z7 -> 0 | AE7: =AC7+AD7 -> 0
B8: 1111043 | C8: ชิฟฟอนรสมะลิ 8 ชิ้น ห่อ ซีน | F8: =SUM(D8:E8) -> 0 | I8: =SUM(G8:H8) -> 0 | L8: =SUM(J8:K8) -> 0 | O8: =SUM(M8:N8) -> 0 | R8: =SUM(P8:Q8) -> 0 | U8: =SUM(S8:T8) -> 0 | X8: =SUM(V8:W8) -> 0 | Z8: =+F8+I8+L8+O8+R8+U8+X8+Y8 -> 0 | AC8: =+AA8+AB8-Z8 -> 0 | AE8: =AC8+AD8 -> 0
B9: 1111057 | C9: ชิฟฟอนแยกชิ้น กาแฟ | F9: =SUM(D9:E9) -> 0 | G9: 2 | I9: =SUM(G9:H9) -> 2 | J9: 2 | L9: =SUM(J9:K9) -> 2 | O9: =SUM(M9:N9) -> 0 | R9: =SUM(P9:Q9) -> 0 | U9: =SUM(S9:T9) -> 0 | X9: =SUM(V9:W9) -> 0 | Z9: =+F9+I9+L9+O9+R9+U9+X9+Y9 -> 4 | AC9: =+AA9+AB9-Z9 -> -4 | AE9: =AC9+AD9 -> -4
B10: 1111058 | C10: ชิฟฟอนแยกชิ้น มะลิ | F10: =SUM(D10:E10) -> 0 | G10: 2 | I10: =SUM(G10:H10) -> 2 | J10: 2 | L10: =SUM(J10:K10) -> 2 | O10: =SUM(M10:N10) -> 0 | R10: =SUM(P10:Q10) -> 0 | U10: =SUM(S10:T10) -> 0 | X10: =SUM(V10:W10) -> 0 | Z10: =+F10+I10+L10+O10+R10+U10+X10+Y10 -> 4 | AC10: =+AA10+AB10-Z10 -> -4 | AE10: =AC10+AD10 -> -4
B11: 1111059 | C11: ชิฟฟอนแยกชิ้น ใบเตย | F11: =SUM(D11:E11) -> 0 | G11: 2 | I11: =SUM(G11:H11) -> 2 | J11: 2 | L11: =SUM(J11:K11) -> 2 | O11: =SUM(M11:N11) -> 0 | R11: =SUM(P11:Q11) -> 0 | U11: =SUM(S11:T11) -> 0 | X11: =SUM(V11:W11) -> 0 | Z11: =+F11+I11+L11+O11+R11+U11+X11+Y11 -> 4 | AC11: =+AA11+AB11-Z11 -> -4 | AE11: =AC11+AD11 -> -4
B12: 1111060 | C12: ชิฟฟอนแยกชิ้น กล้วยหอม | F12: =SUM(D12:E12) -> 0 | G12: 2 | I12: =SUM(G12:H12) -> 2 | J12: 2 | L12: =SUM(J12:K12) -> 2 | O12: =SUM(M12:N12) -> 0 | R12: =SUM(P12:Q12) -> 0 | U12: =SUM(S12:T12) -> 0 | X12: =SUM(V12:W12) -> 0 | Z12: =+F12+I12+L12+O12+R12+U12+X12+Y12 -> 4 | AC12: =+AA12+AB12-Z12 -> -4 | AE12: =AC12+AD12 -> -4
B13: 1111061 | C13: ชิฟฟอนแยกชิ้น ชาไทย | F13: =SUM(D13:E13) -> 0 | G13: 2 | I13: =SUM(G13:H13) -> 2 | J13: 2 | L13: =SUM(J13:K13) -> 2 | O13: =SUM(M13:N13) -> 0 | R13: =SUM(P13:Q13) -> 0 | U13: =SUM(S13:T13) -> 0 | X13: =SUM(V13:W13) -> 0 | Z13: =+F13+I13+L13+O13+R13+U13+X13+Y13 -> 4 | AC13: =+AA13+AB13-Z13 -> -4 | AE13: =AC13+AD13 -> -4
B14: 1111062 | C14: ชิฟฟอนแยกชิ้น โกโก้ | F14: =SUM(D14:E14) -> 0 | G14: 2 | I14: =SUM(G14:H14) -> 2 | J14: 2 | L14: =SUM(J14:K14) -> 2 | O14: =SUM(M14:N14) -> 0 | R14: =SUM(P14:Q14) -> 0 | U14: =SUM(S14:T14) -> 0 | X14: =SUM(V14:W14) -> 0 | Z14: =+F14+I14+L14+O14+R14+U14+X14+Y14 -> 4 | AC14: =+AA14+AB14-Z14 -> -4 | AE14: =AC14+AD14 -> -4
B15: 1111063 | C15: ชิฟฟอนแยกชิ้น ส้ม | F15: =SUM(D15:E15) -> 0 | G15: 2 | I15: =SUM(G15:H15) -> 2 | J15: 2 | L15: =SUM(J15:K15) -> 2 | O15: =SUM(M15:N15) -> 0 | R15: =SUM(P15:Q15) -> 0 | U15: =SUM(S15:T15) -> 0 | X15: =SUM(V15:W15) -> 0 | Z15: =+F15+I15+L15+O15+R15+U15+X15+Y15 -> 4 | AC15: =+AA15+AB15-Z15 -> -4 | AE15: =AC15+AD15 -> -4
B16: 1111064 | C16: ชิฟฟอนแยกชิ้น เผือก | F16: =SUM(D16:E16) -> 0 | G16: 1 | I16: =SUM(G16:H16) -> 1 | J16: 1 | L16: =SUM(J16:K16) -> 1 | O16: =SUM(M16:N16) -> 0 | R16: =SUM(P16:Q16) -> 0 | U16: =SUM(S16:T16) -> 0 | X16: =SUM(V16:W16) -> 0 | Z16: =+F16+I16+L16+O16+R16+U16+X16+Y16 -> 2 | AC16: =+AA16+AB16-Z16 -> -2 | AE16: =AC16+AD16 -> -2
B17: 1111065 | C17: ชิฟฟอนแยกชิ้น สับปะรด | F17: =SUM(D17:E17) -> 0 | G17: 1 | I17: =SUM(G17:H17) -> 1 | J17: 1 | L17: =SUM(J17:K17) -> 1 | O17: =SUM(M17:N17) -> 0 | R17: =SUM(P17:Q17) -> 0 | U17: =SUM(S17:T17) -> 0 | X17: =SUM(V17:W17) -> 0 | Z17: =+F17+I17+L17+O17+R17+U17+X17+Y17 -> 2 | AC17: =+AA17+AB17-Z17 -> -2 | AE17: =AC17+AD17 -> -2
B18: 1111066 | C18: ชิฟฟอนแยกชิ้น สตอเบอรี่ | F18: =SUM(D18:E18) -> 0 | G18: 1 | I18: =SUM(G18:H18) -> 1 | J18: 1 | L18: =SUM(J18:K18) -> 1 | O18: =SUM(M18:N18) -> 0 | R18: =SUM(P18:Q18) -> 0 | U18: =SUM(S18:T18) -> 0 | X18: =SUM(V18:W18) -> 0 | Z18: =+F18+I18+L18+O18+R18+U18+X18+Y18 -> 2 | AA18: 10 | AC18: =+AA18+AB18-Z18 -> 8 | AE18: =AC18+AD18 -> 8
B19: 1111067 | C19: ชิฟฟอนแยกชิ้น มะพร้าว | F19: =SUM(D19:E19) -> 0 | G19: 1 | I19: =SUM(G19:H19) -> 1 | J19: 1 | L19: =SUM(J19:K19) -> 1 | O19: =SUM(M19:N19) -> 0 | R19: =SUM(P19:Q19) -> 0 | U19: =SUM(S19:T19) -> 0 | X19: =SUM(V19:W19) -> 0 | Z19: =+F19+I19+L19+O19+R19+U19+X19+Y19 -> 2 | AA19: 10 | AC19: =+AA19+AB19-Z19 -> 8 | AE19: =AC19+AD19 -> 8
B20: 1111068 | C20: ชิฟฟอนแยกชิ้น เนย | F20: =SUM(D20:E20) -> 0 | G20: 1 | I20: =SUM(G20:H20) -> 1 | J20: 1 | L20: =SUM(J20:K20) -> 1 | O20: =SUM(M20:N20) -> 0 | R20: =SUM(P20:Q20) -> 0 | U20: =SUM(S20:T20) -> 0 | X20: =SUM(V20:W20) -> 0 | Z20: =+F20+I20+L20+O20+R20+U20+X20+Y20 -> 2 | AC20: =+AA20+AB20-Z20 -> -2 | AE20: =AC20+AD20 -> -2
B21: 1111069 | C21: ชิฟฟอนแยกชิ้น บลูเบอรี่ | F21: =SUM(D21:E21) -> 0 | G21: 1 | I21: =SUM(G21:H21) -> 1 | J21: 1 | L21: =SUM(J21:K21) -> 1 | O21: =SUM(M21:N21) -> 0 | R21: =SUM(P21:Q21) -> 0 | U21: =SUM(S21:T21) -> 0 | X21: =SUM(V21:W21) -> 0 | Z21: =+F21+I21+L21+O21+R21+U21+X21+Y21 -> 2 | AC21: =+AA21+AB21-Z21 -> -2 | AE21: =AC21+AD21 -> -2
B22: 1111070 | C22: ชิฟฟอนแยกชิ้น ทุเรียน | F22: =SUM(D22:E22) -> 0 | I22: =SUM(G22:H22) -> 0 | L22: =SUM(J22:K22) -> 0 | O22: =SUM(M22:N22) -> 0 | R22: =SUM(P22:Q22) -> 0 | U22: =SUM(S22:T22) -> 0 | X22: =SUM(V22:W22) -> 0 | Z22: =+F22+I22+L22+O22+R22+U22+X22+Y22 -> 0 | AC22: =+AA22+AB22-Z22 -> 0 | AE22: =AC22+AD22 -> 0
B23: 1111071 | C23: ชิฟฟอนแยกชิ้น ตาล | F23: =SUM(D23:E23) -> 0 | I23: =SUM(G23:H23) -> 0 | L23: =SUM(J23:K23) -> 0 | O23: =SUM(M23:N23) -> 0 | R23: =SUM(P23:Q23) -> 0 | U23: =SUM(S23:T23) -> 0 | X23: =SUM(V23:W23) -> 0 | Z23: =+F23+I23+L23+O23+R23+U23+X23+Y23 -> 0 | AC23: =+AA23+AB23-Z23 -> 0 | AE23: =AC23+AD23 -> 0
B24: 1111010 | C24: ชิฟฟ่อนเค้กสอดไส้แยม (1 ชิ้น) แยมสับปะรด | F24: =SUM(D24:E24) -> 0 | I24: =SUM(G24:H24) -> 0 | L24: =SUM(J24:K24) -> 0 | O24: =SUM(M24:N24) -> 0 | R24: =SUM(P24:Q24) -> 0 | U24: =SUM(S24:T24) -> 0 | X24: =SUM(V24:W24) -> 0 | Z24: =+F24+I24+L24+O24+R24+U24+X24+Y24 -> 0 | AC24: =+AA24+AB24-Z24 -> 0 | AE24: =AC24+AD24 -> 0
B25: 1111008 | C25: ชิฟฟ่อนเค้ก สอดไส้ (รวมรส 3 ชิ้น) | D25: 4 | F25: =SUM(D25:E25) -> 4 | G25: 6 | H25: 1 | I25: =SUM(G25:H25) -> 7 | J25: 3 | L25: =SUM(J25:K25) -> 3 | M25: 36 | N25: 18 | O25: =SUM(M25:N25) -> 54 | R25: =SUM(P25:Q25) -> 0 | U25: =SUM(S25:T25) -> 0 | X25: =SUM(V25:W25) -> 0 | Z25: =+F25+I25+L25+O25+R25+U25+X25+Y25 -> 68 | AA25: 50 | AC25: =+AA25+AB25-Z25 -> -18 | AD25: 70 | AE25: =AC25+AD25 -> 52
B26: 1111009 | C26: ชิฟฟ่อนเค้ก สอดไส้ (รวมรส 6 ชิ้น) | D26: 4 | F26: =SUM(D26:E26) -> 4 | H26: 3 | I26: =SUM(G26:H26) -> 3 | J26: 6 | L26: =SUM(J26:K26) -> 6 | N26: 3 | O26: =SUM(M26:N26) -> 3 | R26: =SUM(P26:Q26) -> 0 | U26: =SUM(S26:T26) -> 0 | X26: =SUM(V26:W26) -> 0 | Z26: =+F26+I26+L26+O26+R26+U26+X26+Y26 -> 16 | AA26: 30 | AC26: =+AA26+AB26-Z26 -> 14 | AD26: 50 | AE26: =AC26+AD26 -> 64
B27: 1111011 | C27: ชิฟฟ่อนเค้กสอดไส้ นมชมพูฮอกไกโด (3 ชิ้น) | F27: =SUM(D27:E27) -> 0 | I27: =SUM(G27:H27) -> 0 | L27: =SUM(J27:K27) -> 0 | O27: =SUM(M27:N27) -> 0 | R27: =SUM(P27:Q27) -> 0 | U27: =SUM(S27:T27) -> 0 | X27: =SUM(V27:W27) -> 0 | Z27: =+F27+I27+L27+O27+R27+U27+X27+Y27 -> 0 | AC27: =+AA27+AB27-Z27 -> 0 | AE27: =AC27+AD27 -> 0
B28: 1111012 | C28: ชิฟฟ่อนเค้กสอดไส้ นมชมพูฮอกไกโด (6 ชิ้น) | F28: =SUM(D28:E28) -> 0 | I28: =SUM(G28:H28) -> 0 | L28: =SUM(J28:K28) -> 0 | O28: =SUM(M28:N28) -> 0 | R28: =SUM(P28:Q28) -> 0 | U28: =SUM(S28:T28) -> 0 | X28: =SUM(V28:W28) -> 0 | Z28: =+F28+I28+L28+O28+R28+U28+X28+Y28 -> 0 | AC28: =+AA28+AB28-Z28 -> 0 | AE28: =AC28+AD28 -> 0
B29: 1111013 | C29: ชิฟฟ่อนเค้กสอดไส้ ช็อคโกแลตนูเทลล่า (3 ชิ้น) | F29: =SUM(D29:E29) -> 0 | I29: =SUM(G29:H29) -> 0 | L29: =SUM(J29:K29) -> 0 | O29: =SUM(M29:N29) -> 0 | R29: =SUM(P29:Q29) -> 0 | U29: =SUM(S29:T29) -> 0 | X29: =SUM(V29:W29) -> 0 | Z29: =+F29+I29+L29+O29+R29+U29+X29+Y29 -> 0 | AC29: =+AA29+AB29-Z29 -> 0 | AE29: =AC29+AD29 -> 0
B30: 1111014 | C30: ชิฟฟ่อนเค้กสอดไส้ ช็อคโกแลตนูเทลล่า (6 ชิ้น) | F30: =SUM(D30:E30) -> 0 | I30: =SUM(G30:H30) -> 0 | L30: =SUM(J30:K30) -> 0 | O30: =SUM(M30:N30) -> 0 | R30: =SUM(P30:Q30) -> 0 | U30: =SUM(S30:T30) -> 0 | X30: =SUM(V30:W30) -> 0 | Z30: =+F30+I30+L30+O30+R30+U30+X30+Y30 -> 0 | AC30: =+AA30+AB30-Z30 -> 0 | AE30: =AC30+AD30 -> 0
B31: 1111015 | C31: ชิฟฟ่อนเค้กสอดไส้เนย รสมะพร้าว (3 ชิ้น) | F31: =SUM(D31:E31) -> 0 | I31: =SUM(G31:H31) -> 0 | L31: =SUM(J31:K31) -> 0 | O31: =SUM(M31:N31) -> 0 | R31: =SUM(P31:Q31) -> 0 | U31: =SUM(S31:T31) -> 0 | X31: =SUM(V31:W31) -> 0 | Z31: =+F31+I31+L31+O31+R31+U31+X31+Y31 -> 0 | AC31: =+AA31+AB31-Z31 -> 0 | AE31: =AC31+AD31 -> 0
B32: 1111016 | C32: ชิฟฟ่อนเค้กสอดไส้เนย รสมะพร้าว (6 ชิ้น) | F32: =SUM(D32:E32) -> 0 | I32: =SUM(G32:H32) -> 0 | L32: =SUM(J32:K32) -> 0 | O32: =SUM(M32:N32) -> 0 | R32: =SUM(P32:Q32) -> 0 | U32: =SUM(S32:T32) -> 0 | X32: =SUM(V32:W32) -> 0 | Z32: =+F32+I32+L32+O32+R32+U32+X32+Y32 -> 0 | AC32: =+AA32+AB32-Z32 -> 0 | AE32: =AC32+AD32 -> 0
B33: 1111017 | C33: ชิฟฟ่อนเค้กสอดไส้แยม รสบลูเบอร์รี่ (3 ชิ้น) | F33: =SUM(D33:E33) -> 0 | I33: =SUM(G33:H33) -> 0 | L33: =SUM(J33:K33) -> 0 | O33: =SUM(M33:N33) -> 0 | R33: =SUM(P33:Q33) -> 0 | U33: =SUM(S33:T33) -> 0 | X33: =SUM(V33:W33) -> 0 | Z33: =+F33+I33+L33+O33+R33+U33+X33+Y33 -> 0 | AC33: =+AA33+AB33-Z33 -> 0 | AE33: =AC33+AD33 -> 0
B34: 1111018 | C34: ชิฟฟ่อนเค้กสอดไส้แยม รสบลูเบอร์รี่ (6 ชิ้น) | F34: =SUM(D34:E34) -> 0 | I34: =SUM(G34:H34) -> 0 | L34: =SUM(J34:K34) -> 0 | O34: =SUM(M34:N34) -> 0 | R34: =SUM(P34:Q34) -> 0 | U34: =SUM(S34:T34) -> 0 | X34: =SUM(V34:W34) -> 0 | Z34: =+F34+I34+L34+O34+R34+U34+X34+Y34 -> 0 | AC34: =+AA34+AB34-Z34 -> 0 | AE34: =AC34+AD34 -> 0
B35: 1111019 | C35: ชิฟฟ่อนเค้กหน้าฝอยทอง สอดไส้แยมส้ม (3 ชิ้น) | F35: =SUM(D35:E35) -> 0 | I35: =SUM(G35:H35) -> 0 | L35: =SUM(J35:K35) -> 0 | O35: =SUM(M35:N35) -> 0 | R35: =SUM(P35:Q35) -> 0 | U35: =SUM(S35:T35) -> 0 | X35: =SUM(V35:W35) -> 0 | Z35: =+F35+I35+L35+O35+R35+U35+X35+Y35 -> 0 | AC35: =+AA35+AB35-Z35 -> 0 | AE35: =AC35+AD35 -> 0
B36: 1111020 | C36: ชิฟฟ่อนเค้กหน้าฝอยทอง สอดไส้แยมส้ม (6 ชิ้น) | F36: =SUM(D36:E36) -> 0 | I36: =SUM(G36:H36) -> 0 | L36: =SUM(J36:K36) -> 0 | O36: =SUM(M36:N36) -> 0 | R36: =SUM(P36:Q36) -> 0 | U36: =SUM(S36:T36) -> 0 | X36: =SUM(V36:W36) -> 0 | Z36: =+F36+I36+L36+O36+R36+U36+X36+Y36 -> 0 | AC36: =+AA36+AB36-Z36 -> 0 | AE36: =AC36+AD36 -> 0
B37: 1111022 | C37: ชิฟฟ่อนเค้กสอดไส้แยม รสสตรอว์เบอร์รี (3 ชิ้น) | F37: =SUM(D37:E37) -> 0 | I37: =SUM(G37:H37) -> 0 | L37: =SUM(J37:K37) -> 0 | O37: =SUM(M37:N37) -> 0 | R37: =SUM(P37:Q37) -> 0 | U37: =SUM(S37:T37) -> 0 | X37: =SUM(V37:W37) -> 0 | Z37: =+F37+I37+L37+O37+R37+U37+X37+Y37 -> 0 | AC37: =+AA37+AB37-Z37 -> 0 | AE37: =AC37+AD37 -> 0
B38: 1111023 | C38: ชิฟฟ่อนเค้กสอดไส้แยม รสสตรอว์เบอร์รี (6 ชิ้น) | F38: =SUM(D38:E38) -> 0 | I38: =SUM(G38:H38) -> 0 | L38: =SUM(J38:K38) -> 0 | O38: =SUM(M38:N38) -> 0 | R38: =SUM(P38:Q38) -> 0 | U38: =SUM(S38:T38) -> 0 | X38: =SUM(V38:W38) -> 0 | Z38: =+F38+I38+L38+O38+R38+U38+X38+Y38 -> 0 | AC38: =+AA38+AB38-Z38 -> 0 | AE38: =AC38+AD38 -> 0
... B40: 1111025 | C40: ชิฟฟ่อนเค้กสอดไส้แยม รสส้ม (6 ชิ้น) | F40: =SUM(D40:E40) -> 0 | I40: =SUM(G40:H40) -> 0 | L40: =SUM(J40:K40) -> 0 | O40: =SUM(M40:N40) -> 0 | R40: =SUM(P40:Q40) -> 0 | U40: =SUM(S40:T40) -> 0 | X40: =SUM(V40:W40) -> 0 | Z40: =+F40+I40+L40+O40+R40+U40+X40+Y40 -> 0 | AC40: =+AA40+AB40-Z40 -> 0 | AE40: =AC40+AD40 -> 0
B41: 1111056 | C41: ชิฟฟอนรวมรสยอดฮิต 8 ชิ้น | F41: =SUM(D41:E41) -> 0 | H41: 3 | I41: =SUM(G41:H41) -> 3 | J41: 2 | L41: =SUM(J41:K41) -> 2 | O41: =SUM(M41:N41) -> 0 | R41: =SUM(P41:Q41) -> 0 | U41: =SUM(S41:T41) -> 0 | X41: =SUM(V41:W41) -> 0 | Z41: =+F41+I41+L41+O41+R41+U41+X41+Y41 -> 5 | AB41: 3 | AC41: =+AA41+AB41-Z41 -> -2 | AD41: 15 | AE41: =AC41+AD41 -> 13
...

Sheet 05.10.68
B1: ยอดจริง ออนไลน์ วันที่ 05/10/2568
B2: รหัสสินค้า | C2: สินค้า | D2: ปณ | G2: ชอปปี้ | J2: ลาซาด้า | M2: ติ๊กตอก | P2: ติ๊กตอก2 | S2: ติ๊กตอก3 | V2: ชอยส์ | Y2: ยอดเส้น | Z2: ยอดรวมผลิต(กล่อง) | AA2: ยอดForcast | AB2: ยอดStock | AC2: ยอดMemo | AD2: ยอดForcastวันพรุ่งนี้ | AE2: สินค้าที่ขายได้
D3: เช้า | E3: บ่าย | F3: รวม | G3: เช้า | H3: บ่าย | I3: รวม | J3: เช้า | K3: บ่าย | L3: รวม | M3: เช้า | N3: บ่าย | O3: รวม | P3: เช้า | Q3: บ่าย | R3: รวม | S3: เช้า | T3: บ่าย | U3: รวม | V3: เช้า | W3: บ่าย | X3: รวม
B4: 1004055 | C4: ชิฟฟ่อนเค้ก วรรณวนัช (รวมรส 4 ชิ้น) | D4: 4 | F4: =SUM(D4:E4) -> 4 | H4: 3 | I4: =SUM(G4:H4) -> 3 | L4: =SUM(J4:K4) -> 0 | M4: 35 | N4: 18 | O4: =SUM(M4:N4) -> 53 | R4: =SUM(P4:Q4) -> 0 | U4: =SUM(S4:T4) -> 0 | X4: =SUM(V4:W4) -> 0 | Y4: 15 | Z4: =+F4+I4+L4+O4+R4+U4+X4+Y4 -> 75 | AA4: 90 | AB4: 3 | AC4: =+AA4+AB4-Z4 -> 18 | AD4: 90 | AE4: =AC4+AD4 -> 108
B5: 1111002 | C5: ชิฟฟ่อนเค้ก วรรณวนัช (รวมรส 8 ชิ้น) | D5: 4 | F5: =SUM(D5:E5) -> 4 | G5: 9 | H5: 5 | I5: =SUM(G5:H5) -> 14 | J5: 16 | L5: =SUM(J5:K5) -> 16 | M5: 12 | N5: 3 | O5: =SUM(M5:N5) -> 15 | R5: =SUM(P5:Q5) -> 0 | U5: =SUM(S5:T5) -> 0 | X5: =SUM(V5:W5) -> 0 | Z5: =+F5+I5+L5+O5+R5+U5+X5+Y5 -> 49 | AA5: 145 | AB5: 83 | AC5: =+AA5+AB5-Z5 -> 179 | AD5: 130 | AE5: =AC5+AD5 -> 309
B6: 1111055 | C6: วรรณวนัช ชิฟฟ่อนรวมรส 8 ชิ้น | F6: =SUM(D6:E6) -> 0 | I6: =SUM(G6:H6) -> 0 | L6: =SUM(J6:K6) -> 0 | O6: =SUM(M6:N6) -> 0 | R6: =SUM(P6:Q6) -> 0 | U6: =SUM(S6:T6) -> 0 | X6: =SUM(V6:W6) -> 0 | Z6: =+F6+I6+L6+O6+R6+U6+X6+Y6 -> 0 | AC6: =+AA6+AB6-Z6 -> 0 | AE6: =AC6+AD6 -> 0
B7: 1111084 | C7: ชิฟฟ่อนเค้ก รสกาแฟ (8 ชิ้น) | F7: =SUM(D7:E7) -> 0 | I7: =SUM(G7:H7) -> 0 | L7: =SUM(J7:K7) -> 0 | O7: =SUM(M7:N7) -> 0 | R7: =SUM(P7:Q7) -> 0 | U7: =SUM(S7:T7) -> 0 | X7: =SUM(V7:W7) -> 0 | Z7: =+F7+I7+L7+O7+R7+U7+X7+Y7 -> 0 | AC7: =+AA7+AB7-Z7 -> 0 | AE7: =AC7+AD7 -> 0
