Workbook

Sheet รับ-จ่าย ประจำวัน
A1: รหัสสินค้าเก่า | B1: รหัสสินค้า | C1: ชื่อสินค้า | D1: หน่วย | E1: ราคา | F1: RJ | G1: LOT สินค้า | H1: ยอดยกมา | I1: วันที่รับเข้า 1 | J1: วันที่รับเข้า 2 | K1: วันที่รับเข้า 3 | L1: วันที่4 | M1: วันที่5 | N1: วันที่6 | O1: วันที่รับเข้า7 | P1: วันที่รับเข้า 8 | Q1: วันที่รับเข้า9 | R1: วันที่รับเข้า 10 | S1: วันที่รับเข้า 11 | T1: วันที่รับเข้า 12 | U1: วันที่รับเข้า 13 | V1: วันที่รับเข้า 14 | W1: วันที่รับเข้า 15 | X1: วันที่รับเข้า 16 | Y1: วันที่รับเข้า 17 | Z1: วันที่รับเข้า 18 | AA1: วันที่รับเข้า 19 | AB1: วันที่รับ 20 | AC1: วันที่ 21 | AD1: วันที่รับเข้า 22 | AE1: วันที่รับเข้า 23 | AF1: วันที่รับเข้า 24 | AG1: วันที่รับเข้า 25 | AH1: วันที่รับเข้า 26 | AI1: วันที่รับเข้า 27 | AJ1: วันที่รับเข้า 28 | AK1: วันที่รับเข้า 29 | AL1: วันที่รับเข้า 30 | AM1: วันที่รับเข้า 31 | AN1: ยอดรับเข้าสุทธิทั้งหมด | AO1: วันที่จ่ายออก 1 | AP1: วันที่จ่ายออก2 | AQ1: วันที่จ่ายออก3 | AR1: วันที่จ่ายออก 4 | AS1: วันที่จ่ายออก 5 | AT1: วันที่จ่ายออก6 | AU1: วันที่จ่ายออก7 | AV1: วันที่จ่ายออก 8 | AW1: วันที่จ่ายออก9 | AX1: วันที่จ่ายออก 10 | AY1: วันที่จ่ายออก 11 | AZ1: วันที่จ่ายออก12 | BA1: วันที่13 | BB1: วันที่14 | BC1: วันที่จ่ายออก 15 | BD1: วันที่จ่ายออก 16 | BE1: วันที่จ่ายออก 17 | BF1: วันที่จ่ายออก 18 | BG1: วันที่จ่ายออก 19 | BH1: วันที่จ่าย 20 | BI1: วันที่จ่าย 21 | BJ1: วันที่จ่ายออก 22 | BK1: วันที่จ่ายออก 23 | BL1: วันที่จ่ายออก 24 | BM1: วันที่จ่ายออก 25 | BN1: วันที่จ่ายออก 26 | BO1: วันที่จ่ายออก 27 | BP1: วันที่จ่ายออก 28 | BQ1: วันที่จ่ายออก 29 | BR1: วันที่จ่ายออก 30 | BS1: วันที่จ่ายออก 31 | BT1: ยอดจ่ายออกสุทธิทั้งหมดเดือน4 | BU1: ยอดจริงนับวันที่ 1 | BV1: คงเหลือสุทธิ | BW1: รอบส่งหลัง PO อนุมัติ | BX1: ยอดใช้/วัน | BY1: จำนวนวันเหลือใช้ | BZ1: วันที่สินค้าหมด | CA1: ของค้าง | CB1: ของค้าง | CC1: ของค้าง | CD1: ของค้าง | CE1: ของค้าง | CF1: ของค้าง | CG1: ของค้าง | CH1: ของค้าง | CI1: ของค้าง | CJ1: ของเข้า
A2: 02-BB03 | B2: 1020501001 | C2: กล่องเค้กเบาหวิวกล้วยมะพร้าวเผา 100g. New(1ห่อ*200ใบ) | D2: ใบ | E2: 0 | G2: - | H2: 5700 | AN2: =I2+J2+K2+L2+M2+N2+O2+P2+Q2+R2+S2+T2+U2+V2+W2+X2+Y2+Z2+AA2+AB2+AC2+AD2+AE2+AF2+AG2+AH2+AI2+AJ2+AK2+AL2+AM2 -> 0 | AO2: =SUMIF(เตรียมส่วนผสม!$C:$C,'รับ-จ่าย ประจำวัน'!$B2,เตรียมส่วนผสม!H:H)+SUMIF(กวนไส้!$C:$C,'รับ-จ่าย ประจำวัน'!$B2,กวนไส้!H:H)+SUMIF(ผลิต1!$C:$C,'รับ-จ่าย ประจำวัน'!$B2,ผลิต1!H:H)+SUMIF(ผลิต2!$C:$C,'รับ-จ่าย ประจำวัน'!$B2,ผลิต2!H:H)+SUMIF(เส้นแต่งหน้าขนมเค้ก!$C:$C,'รับ-จ่าย ประจำวัน'!$B2,เส้นแต่งหน้าขนมเค้ก!H:H)+SUMIF(แพ็ค!$C:$C,'รับ-จ่าย ประจำวัน'!$B2,แพ็ค!H:H)+SUMIF(ธุรการ!$C:$C,'รับ-จ่าย ประจำวัน'!$B2,ธุรการ!H:H)+SUMIF(เส้นแต่งหน้าขนมปัง!$C:$C,'รับ-จ่าย ประจำวัน'!$B2,เส้นแต่งหน้าขนมปัง!H:H)+SUMIF('วางแผนBC,CJ'!$C:$C,'รับ-จ่าย ประจำวัน'!$B2,'วางแผนBC,CJ'!H:H)+SUMIF(RD!$C:$C,'รับ-จ่าย ประจำวัน'!$B2,RD!H:H)+SUMIF('FG,ออนไล,คัดแยก'!$C:$C,'รับ-จ่าย ประจำวัน'!$B2,'FG,ออนไล,คัดแยก'!H:H) -> 0 | AP2: =SUMIF(เตรียมส่วนผสม!$C:$C,'รับ-จ่าย ประจำวัน'!$B2,เตรียมส่วนผสม!I:I)+SUMIF(กวนไส้!$C:$C,'รับ-จ่าย ประจำวัน'!$B2,กวนไส้!I:I)+SUMIF(ผลิต1!$C:$C,'รับ-จ่าย ประจำวัน'!$B2,ผลิต1!I:I)+SUMIF(ผลิต2!$C:$C,'รับ-จ่าย ประจำวัน'!$B2,ผลิต2!I:I)+SUMIF(เส้นแต่งหน้าขนมเค้ก!$C:$C,'รับ-จ่าย ประจำวัน'!$B2,เส้นแต่งหน้าขนมเค้ก!I:I)+SUMIF(แพ็ค!$C:$C,'รับ-จ่าย ประจำวัน'!$B2,แพ็ค!I:I)+SUMIF(ธุรการ!$C:$C,'รับ-จ่าย ประจำวัน'!$B2,ธุรการ!I:I)+SUMIF(เส้นแต่งหน้าขนมปัง!$C:$C,'รับ-จ่าย ประจำวัน'!$B2,เส้นแต่งหน้าขนมปัง!I:I)+SUMIF('วางแผนBC,CJ'!$C:$C,'รับ-จ่าย ประจำวัน'!$B2,'วางแผนBC,CJ'!I:I)+SUMIF(RD!$C:$C,'รับ-จ่าย ประจำวัน'!$B2,RD!I:I)+SUMIF('FG,ออนไล,คัดแยก'!$C:$C,'รับ-จ่าย ประจำวัน'!$B2,'FG,ออนไล,คัดแยก'!I:I) -> 200 | AQ2: =SUMIF(เตรียมส่วนผสม!$C:$C,'รับ-จ่าย ประจำวัน'!$B2,เตรียมส่วนผสม!J:J)+SUMIF(กวนไส้!$C:$C,'รับ-จ่าย ประจำวัน'!$B2,กวนไส้!J:J)+SUMIF(ผลิต1!$C:$C,'รับ-จ่าย ประจำวัน'!$B2,ผลิต1!J:J)+SUMIF(ผลิต2!$C:$C,'รับ-จ่าย ประจำวัน'!$B2,ผลิต2!J:J)+SUMIF(เส้นแต่งหน้าขนมเค้ก!$C:$C,'รับ-จ่าย ประจำวัน'!$B2,เส้นแต่งหน้าขนมเค้ก!J:J)+SUMIF(แพ็ค!$C:$C,'รับ-จ่าย ประจำวัน'!$B2,แพ็ค!J:J)+SUMIF(ธุรการ!$C:$C,'รับ-จ่าย ประจำวัน'!$B2,ธุรการ!J:J)+SUMIF(เส้นแต่งหน้าขนมปัง!$C:$C,'รับ-จ่าย ประจำวัน'!$B2,เส้นแต่งหน้าขนมปัง!J:J)+SUMIF('วางแผนBC,CJ'!$C:$C,'รับ-จ่าย ประจำวัน'!$B2,'วางแผนBC,CJ'!J:J)+SUMIF(RD!$C:$C,'รับ-จ่าย ประจำวัน'!$B2,RD!J:J)+SUMIF('FG,ออนไล,คัดแยก'!$C:$C,'รับ-จ่าย ประจำวัน'!$B2,'FG,ออนไล,คัดแยก'!J:J) -> 0 | AR2: =SUMIF(เตรียมส่วนผสม!$C:$C,'รับ-จ่าย ประจำวัน'!$B2,เตรียมส่วนผสม!K:K)+SUMIF(กวนไส้!$C:$C,'รับ-จ่าย ประจำวัน'!$B2,กวนไส้!K:K)+SUMIF(ผลิต1!$C:$C,'รับ-จ่าย ประจำวัน'!$B2,ผลิต1!K:K)+SUMIF(ผลิต2!$C:$C,'รับ-จ่าย ประจำวัน'!$B2,ผลิต2!K:K)+SUMIF(เส้นแต่งหน้าขนมเค้ก!$C:$C,'รับ-จ่าย ประจำวัน'!$B2,เส้นแต่งหน้าขนมเค้ก!K:K)+SUMIF(แพ็ค!$C:$C,'รับ-จ่าย ประจำวัน'!$B2,แพ็ค!K:K)+SUMIF(ธุรการ!$C:$C,'รับ-จ่าย ประจำวัน'!$B2,ธุรการ!K:K)+SUMIF(เส้นแต่งหน้าขนมปัง!$C:$C,'รับ-จ่าย ประจำวัน'!$B2,เส้นแต่งหน้าขนมปัง!K:K)+SUMIF('วางแผนBC,CJ'!$C:$C,'รับ-จ่าย ประจำวัน'!$B2,'วางแผนBC,CJ'!K:K)+SUMIF(RD!$C:$C,'รับ-จ่าย ประจำวัน'!$B2,RD!K:K)+SUMIF('FG,ออนไล,คัดแยก'!$C:$C,'รับ-จ่าย ประจำวัน'!$B2,'FG,ออนไล,คัดแยก'!K:K) -> 200 | AS2: =SUMIF(เตรียมส่วนผสม!$C:$C,'รับ-จ่าย ประจำวัน'!$B2,เตรียมส่วนผสม!L:L)+SUMIF(กวนไส้!$C:$C,'รับ-จ่าย ประจำวัน'!$B2,กวนไส้!L:L)+SUMIF(ผลิต1!$C:$C,'รับ-จ่าย ประจำวัน'!$B2,ผลิต1!L:L)+SUMIF(ผลิต2!$C:$C,'รับ-จ่าย ประจำวัน'!$B2,ผลิต2!L:L)+SUMIF(เส้นแต่งหน้าขนมเค้ก!$C:$C,'รับ-จ่าย ประจำวัน'!$B2,เส้นแต่งหน้าขนมเค้ก!L:L)+SUMIF(แพ็ค!$C:$C,'รับ-จ่าย ประจำวัน'!$B2,แพ็ค!L:L)+SUMIF(ธุรการ!$C:$C,'รับ-จ่าย ประจำวัน'!$B2,ธุรการ!L:L)+SUMIF(เส้นแต่งหน้าขนมปัง!$C:$C,'รับ-จ่าย ประจำวัน'!$B2,เส้นแต่งหน้าขนมปัง!L:L)+SUMIF('วางแผนBC,CJ'!$C:$C,'รับ-จ่าย ประจำวัน'!$B2,'วางแผนBC,CJ'!L:L)+SUMIF(RD!$C:$C,'รับ-จ่าย ประจำวัน'!$B2,RD!L:L)+SUMIF('FG,ออนไล,คัดแยก'!$C:$C,'รับ-จ่าย ประจำวัน'!$B2,'FG,ออนไล,คัดแยก'!L:L) -> 200 | AT2: =SUMIF(เตรียมส่วนผสม!$C:$C,'รับ-จ่าย ประจำวัน'!$B2,เตรียมส่วนผสม!M:M)+SUMIF(กวนไส้!$C:$C,'รับ-จ่าย ประจำวัน'!$B2,กวนไส้!M:M)+SUMIF(ผลิต1!$C:$C,'รับ-จ่าย ประจำวัน'!$B2,ผลิต1!M:M)+SUMIF(ผลิต2!$C:$C,'รับ-จ่าย ประจำวัน'!$B2,ผลิต2!M:M)+SUMIF(เส้นแต่งหน้าขนมเค้ก!$C:$C,'รับ-จ่าย ประจำวัน'!$B2,เส้นแต่งหน้าขนมเค้ก!M:M)+SUMIF(แพ็ค!$C:$C,'รับ-จ่าย ประจำวัน'!$B2,แพ็ค!M:M)+SUMIF(ธุรการ!$C:$C,'รับ-จ่าย ประจำวัน'!$B2,ธุรการ!M:M)+SUMIF(เส้นแต่งหน้าขนมปัง!$C:$C,'รับ-จ่าย ประจำวัน'!$B2,เส้นแต่งหน้าขนมปัง!M:M)+SUMIF('วางแผนBC,CJ'!$C:$C,'รับ-จ่าย ประจำวัน'!$B2,'วางแผนBC,CJ'!M:M)+SUMIF(RD!$C:$C,'รับ-จ่าย ประจำวัน'!$B2,RD!M:M)+SUMIF('FG,ออนไล,คัดแยก'!$C:$C,'รับ-จ่าย ประจำวัน'!$B2,'FG,ออนไล,คัดแยก'!M:M) -> 0 | AU2: =SUMIF(เตรียมส่วนผสม!$C:$C,'รับ-จ่าย ประจำวัน'!$B2,เตรียมส่วนผสม!N:N)+SUMIF(กวนไส้!$C:$C,'รับ-จ่าย ประจำวัน'!$B2,กวนไส้!N:N)+SUMIF(ผลิต1!$C:$C,'รับ-จ่าย ประจำวัน'!$B2,ผลิต1!N:N)+SUMIF(ผลิต2!$C:$C,'รับ-จ่าย ประจำวัน'!$B2,ผลิต2!N:N)+SUMIF(เส้นแต่งหน้าขนมเค้ก!$C:$C,'รับ-จ่าย ประจำวัน'!$B2,เส้นแต่งหน้าขนมเค้ก!N:N)+SUMIF(แพ็ค!$C:$C,'รับ-จ่าย ประจำวัน'!$B2,แพ็ค!N:N)+SUMIF(ธุรการ!$C:$C,'รับ-จ่าย ประจำวัน'!$B2,ธุรการ!N:N)+SUMIF(เส้นแต่งหน้าขนมปัง!$C:$C,'รับ-จ่าย ประจำวัน'!$B2,เส้นแต่งหน้าขนมปัง!N:N)+SUMIF('วางแผนBC,CJ'!$C:$C,'รับ-จ่าย ประจำวัน'!$B2,'วางแผนBC,CJ'!N:N)+SUMIF(RD!$C:$C,'รับ-จ่าย ประจำวัน'!$B2,RD!N:N)+SUMIF('FG,ออนไล,คัดแยก'!$C:$C,'รับ-จ่าย ประจำวัน'!$B2,'FG,ออนไล,คัดแยก'!N:N) -> 0 | AV2: =SUMIF(เตรียมส่วนผสม!$C:$C,'รับ-จ่าย ประจำวัน'!$B2,เตรียมส่วนผสม!O:O)+SUMIF(กวนไส้!$C:$C,'รับ-จ่าย ประจำวัน'!$B2,กวนไส้!O:O)+SUMIF(ผลิต1!$C:$C,'รับ-จ่าย ประจำวัน'!$B2,ผลิต1!O:O)+SUMIF(ผลิต2!$C:$C,'รับ-จ่าย ประจำวัน'!$B2,ผลิต2!O:O)+SUMIF(เส้นแต่งหน้าขนมเค้ก!$C:$C,'รับ-จ่าย ประจำวัน'!$B2,เส้นแต่งหน้าขนมเค้ก!O:O)+SUMIF(แพ็ค!$C:$C,'รับ-จ่าย ประจำวัน'!$B2,แพ็ค!O:O)+SUMIF(ธุรการ!$C:$C,'รับ-จ่าย ประจำวัน'!$B2,ธุรการ!O:O)+SUMIF(เส้นแต่งหน้าขนมปัง!$C:$C,'รับ-จ่าย ประจำวัน'!$B2,เส้นแต่งหน้าขนมปัง!O:O)+SUMIF('วางแผนBC,CJ'!$C:$C,'รับ-จ่าย ประจำวัน'!$B2,'วางแผนBC,CJ'!O:O)+SUMIF(RD!$C:$C,'รับ-จ่าย ประจำวัน'!$B2,RD!O:O)+SUMIF('FG,ออนไล,คัดแยก'!$C:$C,'รับ-จ่าย ประจำวัน'!$B2,'FG,ออนไล,คัดแยก'!O:O) -> 200 | AW2: =SUMIF(เตรียมส่วนผสม!$C:$C,'รับ-จ่าย ประจำวัน'!$B2,เตรียมส่วนผสม!P:P)+SUMIF(กวนไส้!$C:$C,'รับ-จ่าย ประจำวัน'!$B2,กวนไส้!P:P)+SUMIF(ผลิต1!$C:$C,'รับ-จ่าย ประจำวัน'!$B2,ผลิต1!P:P)+SUMIF(ผลิต2!$C:$C,'รับ-จ่าย ประจำวัน'!$B2,ผลิต2!P:P)+SUMIF(เส้นแต่งหน้าขนมเค้ก!$C:$C,'รับ-จ่าย ประจำวัน'!$B2,เส้นแต่งหน้าขนมเค้ก!P:P)+SUMIF(แพ็ค!$C:$C,'รับ-จ่าย ประจำวัน'!$B2,แพ็ค!P:P)+SUMIF(ธุรการ!$C:$C,'รับ-จ่าย ประจำวัน'!$B2,ธุรการ!P:P)+SUMIF(เส้นแต่งหน้าขนมปัง!$C:$C,'รับ-จ่าย ประจำวัน'!$B2,เส้นแต่งหน้าขนมปัง!P:P)+SUMIF('วางแผนBC,CJ'!$C:$C,'รับ-จ่าย ประจำวัน'!$B2,'วางแผนBC,CJ'!P:P)+SUMIF(RD!$C:$C,'รับ-จ่าย ประจำวัน'!$B2,RD!P:P)+SUMIF('FG,ออนไล,คัดแยก'!$C:$C,'รับ-จ่าย ประจำวัน'!$B2,'FG,ออนไล,คัดแยก'!P:P) -> 200 | AX2: =SUMIF(เตรียมส่วนผสม!$C:$C,'รับ-จ่าย ประจำวัน'!$B2,เตรียมส่วนผสม!Q:Q)+SUMIF(กวนไส้!$C:$C,'รับ-จ่าย ประจำวัน'!$B2,กวนไส้!Q:Q)+SUMIF(ผลิต1!$C:$C,'รับ-จ่าย ประจำวัน'!$B2,ผลิต1!Q:Q)+SUMIF(ผลิต2!$C:$C,'รับ-จ่าย ประจำวัน'!$B2,ผลิต2!Q:Q)+SUMIF(เส้นแต่งหน้าขนมเค้ก!$C:$C,'รับ-จ่าย ประจำวัน'!$B2,เส้นแต่งหน้าขนมเค้ก!Q:Q)+SUMIF(แพ็ค!$C:$C,'รับ-จ่าย ประจำวัน'!$B2,แพ็ค!Q:Q)+SUMIF(ธุรการ!$C:$C,'รับ-จ่าย ประจำวัน'!$B2,ธุรการ!Q:Q)+SUMIF(เส้นแต่งหน้าขนมปัง!$C:$C,'รับ-จ่าย ประจำวัน'!$B2,เส้นแต่งหน้าขนมปัง!Q:Q)+SUMIF('วางแผนBC,CJ'!$C:$C,'รับ-จ่าย ประจำวัน'!$B2,'วางแผนBC,CJ'!Q:Q)+SUMIF(RD!$C:$C,'รับ-จ่าย ประจำวัน'!$B2,RD!Q:Q)+SUMIF('FG,ออนไล,คัดแยก'!$C:$C,'รับ-จ่าย ประจำวัน'!$B2,'FG,ออนไล,คัดแยก'!Q:Q) -> 200 | AY2: =SUMIF(เตรียมส่วนผสม!$C:$C,'รับ-จ่าย ประจำวัน'!$B2,เตรียมส่วนผสม!R:R)+SUMIF(กวนไส้!$C:$C,'รับ-จ่าย ประจำวัน'!$B2,กวนไส้!R:R)+SUMIF(ผลิต1!$C:$C,'รับ-จ่าย ประจำวัน'!$B2,ผลิต1!R:R)+SUMIF(ผลิต2!$C:$C,'รับ-จ่าย ประจำวัน'!$B2,ผลิต2!R:R)+SUMIF(เส้นแต่งหน้าขนมเค้ก!$C:$C,'รับ-จ่าย ประจำวัน'!$B2,เส้นแต่งหน้าขนมเค้ก!R:R)+SUMIF(แพ็ค!$C:$C,'รับ-จ่าย ประจำวัน'!$B2,แพ็ค!R:R)+SUMIF(ธุรการ!$C:$C,'รับ-จ่าย ประจำวัน'!$B2,ธุรการ!R:R)+SUMIF(เส้นแต่งหน้าขนมปัง!$C:$C,'รับ-จ่าย ประจำวัน'!$B2,เส้นแต่งหน้าขนมปัง!R:R)+SUMIF('วางแผนBC,CJ'!$C:$C,'รับ-จ่าย ประจำวัน'!$B2,'วางแผนBC,CJ'!R:R)+SUMIF(RD!$C:$C,'รับ-จ่าย ประจำวัน'!$B2,RD!R:R)+SUMIF('FG,ออนไล,คัดแยก'!$C:$C,'รับ-จ่าย ประจำวัน'!$B2,'FG,ออนไล,คัดแยก'!R:R) -> 0 | AZ2: =SUMIF(เตรียมส่วนผสม!$C:$C,'รับ-จ่าย ประจำวัน'!$B2,เตรียมส่วนผสม!S:S)+SUMIF(กวนไส้!$C:$C,'รับ-จ่าย ประจำวัน'!$B2,กวนไส้!S:S)+SUMIF(ผลิต1!$C:$C,'รับ-จ่าย ประจำวัน'!$B2,ผลิต1!S:S)+SUMIF(ผลิต2!$C:$C,'รับ-จ่าย ประจำวัน'!$B2,ผลิต2!S:S)+SUMIF(เส้นแต่งหน้าขนมเค้ก!$C:$C,'รับ-จ่าย ประจำวัน'!$B2,เส้นแต่งหน้าขนมเค้ก!S:S)+SUMIF(แพ็ค!$C:$C,'รับ-จ่าย ประจำวัน'!$B2,แพ็ค!S:S)+SUMIF(ธุรการ!$C:$C,'รับ-จ่าย ประจำวัน'!$B2,ธุรการ!S:S)+SUMIF(เส้นแต่งหน้าขนมปัง!$C:$C,'รับ-จ่าย ประจำวัน'!$B2,เส้นแต่งหน้าขนมปัง!S:S)+SUMIF('วางแผนBC,CJ'!$C:$C,'รับ-จ่าย ประจำวัน'!$B2,'วางแผนBC,CJ'!S:S)+SUMIF(RD!$C:$C,'รับ-จ่าย ประจำวัน'!$B2,RD!S:S)+SUMIF('FG,ออนไล,คัดแยก'!$C:$C,'รับ-จ่าย ประจำวัน'!$B2,'FG,ออนไล,คัดแยก'!S:S) -> 200 | BA2: =SUMIF(เตรียมส่วนผสม!$C:$C,'รับ-จ่าย ประจำวัน'!$B2,เตรียมส่วนผสม!T:T)+SUMIF(กวนไส้!$C:$C,'รับ-จ่าย ประจำวัน'!$B2,กวนไส้!T:T)+SUMIF(ผลิต1!$C:$C,'รับ-จ่าย ประจำวัน'!$B2,ผลิต1!T:T)+SUMIF(ผลิต2!$C:$C,'รับ-จ่าย ประจำวัน'!$B2,ผลิต2!T:T)+SUMIF(เส้นแต่งหน้าขนมเค้ก!$C:$C,'รับ-จ่าย ประจำวัน'!$B2,เส้นแต่งหน้าขนมเค้ก!T:T)+SUMIF(แพ็ค!$C:$C,'รับ-จ่าย ประจำวัน'!$B2,แพ็ค!T:T)+SUMIF(ธุรการ!$C:$C,'รับ-จ่าย ประจำวัน'!$B2,ธุรการ!T:T)+SUMIF(เส้นแต่งหน้าขนมปัง!$C:$C,'รับ-จ่าย ประจำวัน'!$B2,เส้นแต่งหน้าขนมปัง!T:T)+SUMIF('วางแผนBC,CJ'!$C:$C,'รับ-จ่าย ประจำวัน'!$B2,'วางแผนBC,CJ'!T:T)+SUMIF(RD!$C:$C,'รับ-จ่าย ประจำวัน'!$B2,RD!T:T)+SUMIF('FG,ออนไล,คัดแยก'!$C:$C,'รับ-จ่าย ประจำวัน'!$B2,'FG,ออนไล,คัดแยก'!T:T) -> 0 | BB2: =SUMIF(เตรียมส่วนผสม!$C:$C,'รับ-จ่าย ประจำวัน'!$B2,เตรียมส่วนผสม!U:U)+SUMIF(กวนไส้!$C:$C,'รับ-จ่าย ประจำวัน'!$B2,กวนไส้!U:U)+SUMIF(ผลิต1!$C:$C,'รับ-จ่าย ประจำวัน'!$B2,ผลิต1!U:U)+SUMIF(ผลิต2!$C:$C,'รับ-จ่าย ประจำวัน'!$B2,ผลิต2!U:U)+SUMIF(เส้นแต่งหน้าขนมเค้ก!$C:$C,'รับ-จ่าย ประจำวัน'!$B2,เส้นแต่งหน้าขนมเค้ก!U:U)+SUMIF(แพ็ค!$C:$C,'รับ-จ่าย ประจำวัน'!$B2,แพ็ค!U:U)+SUMIF(ธุรการ!$C:$C,'รับ-จ่าย ประจำวัน'!$B2,ธุรการ!U:U)+SUMIF(เส้นแต่งหน้าขนมปัง!$C:$C,'รับ-จ่าย ประจำวัน'!$B2,เส้นแต่งหน้าขนมปัง!U:U)+SUMIF('วางแผนBC,CJ'!$C:$C,'รับ-จ่าย ประจำวัน'!$B2,'วางแผนBC,CJ'!U:U)+SUMIF(RD!$C:$C,'รับ-จ่าย ประจำวัน'!$B2,RD!U:U)+SUMIF('FG,ออนไล,คัดแยก'!$C:$C,'รับ-จ่าย ประจำวัน'!$B2,'FG,ออนไล,คัดแยก'!U:U) -> 0 | BC2: =SUMIF(เตรียมส่วนผสม!$C:$C,'รับ-จ่าย ประจำวัน'!$B2,เตรียมส่วนผสม!V:V)+SUMIF(กวนไส้!$C:$C,'รับ-จ่าย ประจำวัน'!$B2,กวนไส้!V:V)+SUMIF(ผลิต1!$C:$C,'รับ-จ่าย ประจำวัน'!$B2,ผลิต1!V:V)+SUMIF(ผลิต2!$C:$C,'รับ-จ่าย ประจำวัน'!$B2,ผลิต2!V:V)+SUMIF(เส้นแต่งหน้าขนมเค้ก!$C:$C,'รับ-จ่าย ประจำวัน'!$B2,เส้นแต่งหน้าขนมเค้ก!V:V)+SUMIF(แพ็ค!$C:$C,'รับ-จ่าย ประจำวัน'!$B2,แพ็ค!V:V)+SUMIF(ธุรการ!$C:$C,'รับ-จ่าย ประจำวัน'!$B2,ธุรการ!V:V)+SUMIF(เส้นแต่งหน้าขนมปัง!$C:$C,'รับ-จ่าย ประจำวัน'!$B2,เส้นแต่งหน้าขนมปัง!V:V)+SUMIF('วางแผนBC,CJ'!$C:$C,'รับ-จ่าย ประจำวัน'!$B2,'วางแผนBC,CJ'!V:V)+SUMIF(RD!$C:$C,'รับ-จ่าย ประจำวัน'!$B2,RD!V:V)+SUMIF('FG,ออนไล,คัดแยก'!$C:$C,'รับ-จ่าย ประจำวัน'!$B2,'FG,ออนไล,คัดแยก'!V:V) -> 0 | BD2: =SUMIF(เตรียมส่วนผสม!$C:$C,'รับ-จ่าย ประจำวัน'!$B2,เตรียมส่วนผสม!W:W)+SUMIF(กวนไส้!$C:$C,'รับ-จ่าย ประจำวัน'!$B2,กวนไส้!W:W)+SUMIF(ผลิต1!$C:$C,'รับ-จ่าย ประจำวัน'!$B2,ผลิต1!W:W)+SUMIF(ผลิต2!$C:$C,'รับ-จ่าย ประจำวัน'!$B2,ผลิต2!W:W)+SUMIF(เส้นแต่งหน้าขนมเค้ก!$C:$C,'รับ-จ่าย ประจำวัน'!$B2,เส้นแต่งหน้าขนมเค้ก!W:W)+SUMIF(แพ็ค!$C:$C,'รับ-จ่าย ประจำวัน'!$B2,แพ็ค!W:W)+SUMIF(ธุรการ!$C:$C,'รับ-จ่าย ประจำวัน'!$B2,ธุรการ!W:W)+SUMIF(เส้นแต่งหน้าขนมปัง!$C:$C,'รับ-จ่าย ประจำวัน'!$B2,เส้นแต่งหน้าขนมปัง!W:W)+SUMIF('วางแผนBC,CJ'!$C:$C,'รับ-จ่าย ประจำวัน'!$B2,'วางแผนBC,CJ'!W:W)+SUMIF(RD!$C:$C,'รับ-จ่าย ประจำวัน'!$B2,RD!W:W)+SUMIF('FG,ออนไล,คัดแยก'!$C:$C,'รับ-จ่าย ประจำวัน'!$B2,'FG,ออนไล,คัดแยก'!W:W) -> 0 | BE2: =SUMIF(เตรียมส่วนผสม!$C:$C,'รับ-จ่าย ประจำวัน'!$B2,เตรียมส่วนผสม!X:X)+SUMIF(กวนไส้!$C:$C,'รับ-จ่าย ประจำวัน'!$B2,กวนไส้!X:X)+SUMIF(ผลิต1!$C:$C,'รับ-จ่าย ประจำวัน'!$B2,ผลิต1!X:X)+SUMIF(ผลิต2!$C:$C,'รับ-จ่าย ประจำวัน'!$B2,ผลิต2!X:X)+SUMIF(เส้นแต่งหน้าขนมเค้ก!$C:$C,'รับ-จ่าย ประจำวัน'!$B2,เส้นแต่งหน้าขนมเค้ก!X:X)+SUMIF(แพ็ค!$C:$C,'รับ-จ่าย ประจำวัน'!$B2,แพ็ค!X:X)+SUMIF(ธุรการ!$C:$C,'รับ-จ่าย ประจำวัน'!$B2,ธุรการ!X:X)+SUMIF(เส้นแต่งหน้าขนมปัง!$C:$C,'รับ-จ่าย ประจำวัน'!$B2,เส้นแต่งหน้าขนมปัง!X:X)+SUMIF('วางแผนBC,CJ'!$C:$C,'รับ-จ่าย ประจำวัน'!$B2,'วางแผนBC,CJ'!X:X)+SUMIF(RD!$C:$C,'รับ-จ่าย ประจำวัน'!$B2,RD!X:X)+SUMIF('FG,ออนไล,คัดแยก'!$C:$C,'รับ-จ่าย ประจำวัน'!$B2,'FG,ออนไล,คัดแยก'!X:X) -> 0 | BF2: =SUMIF(เตรียมส่วนผสม!$C:$C,'รับ-จ่าย ประจำวัน'!$B2,เตรียมส่วนผสม!Y:Y)+SUMIF(กวนไส้!$C:$C,'รับ-จ่าย ประจำวัน'!$B2,กวนไส้!Y:Y)+SUMIF(ผลิต1!$C:$C,'รับ-จ่าย ประจำวัน'!$B2,ผลิต1!Y:Y)+SUMIF(ผลิต2!$C:$C,'รับ-จ่าย ประจำวัน'!$B2,ผลิต2!Y:Y)+SUMIF(เส้นแต่งหน้าขนมเค้ก!$C:$C,'รับ-จ่าย ประจำวัน'!$B2,เส้นแต่งหน้าขนมเค้ก!Y:Y)+SUMIF(แพ็ค!$C:$C,'รับ-จ่าย ประจำวัน'!$B2,แพ็ค!Y:Y)+SUMIF(ธุรการ!$C:$C,'รับ-จ่าย ประจำวัน'!$B2,ธุรการ!Y:Y)+SUMIF(เส้นแต่งหน้าขนมปัง!$C:$C,'รับ-จ่าย ประจำวัน'!$B2,เส้นแต่งหน้าขนมปัง!Y:Y)+SUMIF('วางแผนBC,CJ'!$C:$C,'รับ-จ่าย ประจำวัน'!$B2,'วางแผนBC,CJ'!Y:Y)+SUMIF(RD!$C:$C,'รับ-จ่าย ประจำวัน'!$B2,RD!Y:Y)+SUMIF('FG,ออนไล,คัดแยก'!$C:$C,'รับ-จ่าย ประจำวัน'!$B2,'FG,ออนไล,คัดแยก'!Y:Y) -> 200 | BG2: =SUMIF(เตรียมส่วนผสม!$C:$C,'รับ-จ่าย ประจำวัน'!$B2,เตรียมส่วนผสม!Z:Z)+SUMIF(กวนไส้!$C:$C,'รับ-จ่าย ประจำวัน'!$B2,กวนไส้!Z:Z)+SUMIF(ผลิต1!$C:$C,'รับ-จ่าย ประจำวัน'!$B2,ผลิต1!Z:Z)+SUMIF(ผลิต2!$C:$C,'รับ-จ่าย ประจำวัน'!$B2,ผลิต2!Z:Z)+SUMIF(เส้นแต่งหน้าขนมเค้ก!$C:$C,'รับ-จ่าย ประจำวัน'!$B2,เส้นแต่งหน้าขนมเค้ก!Z:Z)+SUMIF(แพ็ค!$C:$C,'รับ-จ่าย ประจำวัน'!$B2,แพ็ค!Z:Z)+SUMIF(ธุรการ!$C:$C,'รับ-จ่าย ประจำวัน'!$B2,ธุรการ!Z:Z)+SUMIF(เส้นแต่งหน้าขนมปัง!$C:$C,'รับ-จ่าย ประจำวัน'!$B2,เส้นแต่งหน้าขนมปัง!Z:Z)+SUMIF('วางแผนBC,CJ'!$C:$C,'รับ-จ่าย ประจำวัน'!$B2,'วางแผนBC,CJ'!Z:Z)+SUMIF(RD!$C:$C,'รับ-จ่าย ประจำวัน'!$B2,RD!Z:Z)+SUMIF('FG,ออนไล,คัดแยก'!$C:$C,'รับ-จ่าย ประจำวัน'!$B2,'FG,ออนไล,คัดแยก'!Z:Z) -> 0 | BH2: =SUMIF(เตรียมส่วนผสม!$C:$C,'รับ-จ่าย ประจำวัน'!$B2,เตรียมส่วนผสม!AA:AA)+SUMIF(กวนไส้!$C:$C,'รับ-จ่าย ประจำวัน'!$B2,กวนไส้!AA:AA)+SUMIF(ผลิต1!$C:$C,'รับ-จ่าย ประจำวัน'!$B2,ผลิต1!AA:AA)+SUMIF(ผลิต2!$C:$C,'รับ-จ่าย ประจำวัน'!$B2,ผลิต2!AA:AA)+SUMIF(เส้นแต่งหน้าขนมเค้ก!$C:$C,'รับ-จ่าย ประจำวัน'!$B2,เส้นแต่งหน้าขนมเค้ก!AA:AA)+SUMIF(แพ็ค!$C:$C,'รับ-จ่าย ประจำวัน'!$B2,แพ็ค!AA:AA)+SUMIF(ธุรการ!$C:$C,'รับ-จ่าย ประจำวัน'!$B2,ธุรการ!AA:AA)+SUMIF(เส้นแต่งหน้าขนมปัง!$C:$C,'รับ-จ่าย ประจำวัน'!$B2,เส้นแต่งหน้าขนมปัง!AA:AA)+SUMIF('วางแผนBC,CJ'!$C:$C,'รับ-จ่าย ประจำวัน'!$B2,'วางแผนBC,CJ'!AA:AA)+SUMIF(RD!$C:$C,'รับ-จ่าย ประจำวัน'!$B2,RD!AA:AA)+SUMIF('FG,ออนไล,คัดแยก'!$C:$C,'รับ-จ่าย ประจำวัน'!$B2,'FG,ออนไล,คัดแยก'!AA:AA) -> 0 | BI2: =SUMIF(เตรียมส่วนผสม!$C:$C,'รับ-จ่าย ประจำวัน'!$B2,เตรียมส่วนผสม!AB:AB)+SUMIF(กวนไส้!$C:$C,'รับ-จ่าย ประจำวัน'!$B2,กวนไส้!AB:AB)+SUMIF(ผลิต1!$C:$C,'รับ-จ่าย ประจำวัน'!$B2,ผลิต1!AB:AB)+SUMIF(ผลิต2!$C:$C,'รับ-จ่าย ประจำวัน'!$B2,ผลิต2!AB:AB)+SUMIF(เส้นแต่งหน้าขนมเค้ก!$C:$C,'รับ-จ่าย ประจำวัน'!$B2,เส้นแต่งหน้าขนมเค้ก!AB:AB)+SUMIF(แพ็ค!$C:$C,'รับ-จ่าย ประจำวัน'!$B2,แพ็ค!AB:AB)+SUMIF(ธุรการ!$C:$C,'รับ-จ่าย ประจำวัน'!$B2,ธุรการ!AB:AB)+SUMIF(เส้นแต่งหน้าขนมปัง!$C:$C,'รับ-จ่าย ประจำวัน'!$B2,เส้นแต่งหน้าขนมปัง!AB:AB)+SUMIF('วางแผนBC,CJ'!$C:$C,'รับ-จ่าย ประจำวัน'!$B2,'วางแผนBC,CJ'!AB:AB)+SUMIF(RD!$C:$C,'รับ-จ่าย ประจำวัน'!$B2,RD!AB:AB)+SUMIF('FG,ออนไล,คัดแยก'!$C:$C,'รับ-จ่าย ประจำวัน'!$B2,'FG,ออนไล,คัดแยก'!AB:AB) -> 0 | BJ2: =SUMIF(เตรียมส่วนผสม!$C:$C,'รับ-จ่าย ประจำวัน'!$B2,เตรียมส่วนผสม!AC:AC)+SUMIF(กวนไส้!$C:$C,'รับ-จ่าย ประจำวัน'!$B2,กวนไส้!AC:AC)+SUMIF(ผลิต1!$C:$C,'รับ-จ่าย ประจำวัน'!$B2,ผลิต1!AC:AC)+SUMIF(ผลิต2!$C:$C,'รับ-จ่าย ประจำวัน'!$B2,ผลิต2!AC:AC)+SUMIF(เส้นแต่งหน้าขนมเค้ก!$C:$C,'รับ-จ่าย ประจำวัน'!$B2,เส้นแต่งหน้าขนมเค้ก!AC:AC)+SUMIF(แพ็ค!$C:$C,'รับ-จ่าย ประจำวัน'!$B2,แพ็ค!AC:AC)+SUMIF(ธุรการ!$C:$C,'รับ-จ่าย ประจำวัน'!$B2,ธุรการ!AC:AC)+SUMIF(เส้นแต่งหน้าขนมปัง!$C:$C,'รับ-จ่าย ประจำวัน'!$B2,เส้นแต่งหน้าขนมปัง!AC:AC)+SUMIF('วางแผนBC,CJ'!$C:$C,'รับ-จ่าย ประจำวัน'!$B2,'วางแผนBC,CJ'!AC:AC)+SUMIF(RD!$C:$C,'รับ-จ่าย ประจำวัน'!$B2,RD!AC:AC)+SUMIF('FG,ออนไล,คัดแยก'!$C:$C,'รับ-จ่าย ประจำวัน'!$B2,'FG,ออนไล,คัดแยก'!AC:AC) -> 200 | BK2: =SUMIF(เตรียมส่วนผสม!$C:$C,'รับ-จ่าย ประจำวัน'!$B2,เตรียมส่วนผสม!AD:AD)+SUMIF(กวนไส้!$C:$C,'รับ-จ่าย ประจำวัน'!$B2,กวนไส้!AD:AD)+SUMIF(ผลิต1!$C:$C,'รับ-จ่าย ประจำวัน'!$B2,ผลิต1!AD:AD)+SUMIF(ผลิต2!$C:$C,'รับ-จ่าย ประจำวัน'!$B2,ผลิต2!AD:AD)+SUMIF(เส้นแต่งหน้าขนมเค้ก!$C:$C,'รับ-จ่าย ประจำวัน'!$B2,เส้นแต่งหน้าขนมเค้ก!AD:AD)+SUMIF(แพ็ค!$C:$C,'รับ-จ่าย ประจำวัน'!$B2,แพ็ค!AD:AD)+SUMIF(ธุรการ!$C:$C,'รับ-จ่าย ประจำวัน'!$B2,ธุรการ!AD:AD)+SUMIF(เส้นแต่งหน้าขนมปัง!$C:$C,'รับ-จ่าย ประจำวัน'!$B2,เส้นแต่งหน้าขนมปัง!AD:AD)+SUMIF('วางแผนBC,CJ'!$C:$C,'รับ-จ่าย ประจำวัน'!$B2,'วางแผนBC,CJ'!AD:AD)+SUMIF(RD!$C:$C,'รับ-จ่าย ประจำวัน'!$B2,RD!AD:AD)+SUMIF('FG,ออนไล,คัดแยก'!$C:$C,'รับ-จ่าย ประจำวัน'!$B2,'FG,ออนไล,คัดแยก'!AD:AD) -> 0 | BL2: =SUMIF(เตรียมส่วนผสม!$C:$C,'รับ-จ่าย ประจำวัน'!$B2,เตรียมส่วนผสม!AE:AE)+SUMIF(กวนไส้!$C:$C,'รับ-จ่าย ประจำวัน'!$B2,กวนไส้!AE:AE)+SUMIF(ผลิต1!$C:$C,'รับ-จ่าย ประจำวัน'!$B2,ผลิต1!AE:AE)+SUMIF(ผลิต2!$C:$C,'รับ-จ่าย ประจำวัน'!$B2,ผลิต2!AE:AE)+SUMIF(เส้นแต่งหน้าขนมเค้ก!$C:$C,'รับ-จ่าย ประจำวัน'!$B2,เส้นแต่งหน้าขนมเค้ก!AE:AE)+SUMIF(แพ็ค!$C:$C,'รับ-จ่าย ประจำวัน'!$B2,แพ็ค!AE:AE)+SUMIF(ธุรการ!$C:$C,'รับ-จ่าย ประจำวัน'!$B2,ธุรการ!AE:AE)+SUMIF(เส้นแต่งหน้าขนมปัง!$C:$C,'รับ-จ่าย ประจำวัน'!$B2,เส้นแต่งหน้าขนมปัง!AE:AE)+SUMIF('วางแผนBC,CJ'!$C:$C,'รับ-จ่าย ประจำวัน'!$B2,'วางแผนBC,CJ'!AE:AE)+SUMIF(RD!$C:$C,'รับ-จ่าย ประจำวัน'!$B2,RD!AE:AE)+SUMIF('FG,ออนไล,คัดแยก'!$C:$C,'รับ-จ่าย ประจำวัน'!$B2,'FG,ออนไล,คัดแยก'!AE:AE) -> 0 | BM2: =SUMIF(เตรียมส่วนผสม!$C:$C,'รับ-จ่าย ประจำวัน'!$B2,เตรียมส่วนผสม!AF:AF)+SUMIF(กวนไส้!$C:$C,'รับ-จ่าย ประจำวัน'!$B2,กวนไส้!AF:AF)+SUMIF(ผลิต1!$C:$C,'รับ-จ่าย ประจำวัน'!$B2,ผลิต1!AF:AF)+SUMIF(ผลิต2!$C:$C,'รับ-จ่าย ประจำวัน'!$B2,ผลิต2!AF:AF)+SUMIF(เส้นแต่งหน้าขนมเค้ก!$C:$C,'รับ-จ่าย ประจำวัน'!$B2,เส้นแต่งหน้าขนมเค้ก!AF:AF)+SUMIF(แพ็ค!$C:$C,'รับ-จ่าย ประจำวัน'!$B2,แพ็ค!AF:AF)+SUMIF(ธุรการ!$C:$C,'รับ-จ่าย ประจำวัน'!$B2,ธุรการ!AF:AF)+SUMIF(เส้นแต่งหน้าขนมปัง!$C:$C,'รับ-จ่าย ประจำวัน'!$B2,เส้นแต่งหน้าขนมปัง!AF:AF)+SUMIF('วางแผนBC,CJ'!$C:$C,'รับ-จ่าย ประจำวัน'!$B2,'วางแผนBC,CJ'!AF:AF)+SUMIF(RD!$C:$C,'รับ-จ่าย ประจำวัน'!$B2,RD!AF:AF)+SUMIF('FG,ออนไล,คัดแยก'!$C:$C,'รับ-จ่าย ประจำวัน'!$B2,'FG,ออนไล,คัดแยก'!AF:AF) -> 200 | BN2: =SUMIF(เตรียมส่วนผสม!$C:$C,'รับ-จ่าย ประจำวัน'!$B2,เตรียมส่วนผสม!AG:AG)+SUMIF(กวนไส้!$C:$C,'รับ-จ่าย ประจำวัน'!$B2,กวนไส้!AG:AG)+SUMIF(ผลิต1!$C:$C,'รับ-จ่าย ประจำวัน'!$B2,ผลิต1!AG:AG)+SUMIF(ผลิต2!$C:$C,'รับ-จ่าย ประจำวัน'!$B2,ผลิต2!AG:AG)+SUMIF(เส้นแต่งหน้าขนมเค้ก!$C:$C,'รับ-จ่าย ประจำวัน'!$B2,เส้นแต่งหน้าขนมเค้ก!AG:AG)+SUMIF(แพ็ค!$C:$C,'รับ-จ่าย ประจำวัน'!$B2,แพ็ค!AG:AG)+SUMIF(ธุรการ!$C:$C,'รับ-จ่าย ประจำวัน'!$B2,ธุรการ!AG:AG)+SUMIF(เส้นแต่งหน้าขนมปัง!$C:$C,'รับ-จ่าย ประจำวัน'!$B2,เส้นแต่งหน้าขนมปัง!AG:AG)+SUMIF('วางแผนBC,CJ'!$C:$C,'รับ-จ่าย ประจำวัน'!$B2,'วางแผนBC,CJ'!AG:AG)+SUMIF(RD!$C:$C,'รับ-จ่าย ประจำวัน'!$B2,RD!AG:AG)+SUMIF('FG,ออนไล,คัดแยก'!$C:$C,'รับ-จ่าย ประจำวัน'!$B2,'FG,ออนไล,คัดแยก'!AG:AG) -> 0 | BO2: =SUMIF(เตรียมส่วนผสม!$C:$C,'รับ-จ่าย ประจำวัน'!$B2,เตรียมส่วนผสม!AH:AH)+SUMIF(กวนไส้!$C:$C,'รับ-จ่าย ประจำวัน'!$B2,กวนไส้!AH:AH)+SUMIF(ผลิต1!$C:$C,'รับ-จ่าย ประจำวัน'!$B2,ผลิต1!AH:AH)+SUMIF(ผลิต2!$C:$C,'รับ-จ่าย ประจำวัน'!$B2,ผลิต2!AH:AH)+SUMIF(เส้นแต่งหน้าขนมเค้ก!$C:$C,'รับ-จ่าย ประจำวัน'!$B2,เส้นแต่งหน้าขนมเค้ก!AH:AH)+SUMIF(แพ็ค!$C:$C,'รับ-จ่าย ประจำวัน'!$B2,แพ็ค!AH:AH)+SUMIF(ธุรการ!$C:$C,'รับ-จ่าย ประจำวัน'!$B2,ธุรการ!AH:AH)+SUMIF(เส้นแต่งหน้าขนมปัง!$C:$C,'รับ-จ่าย ประจำวัน'!$B2,เส้นแต่งหน้าขนมปัง!AH:AH)+SUMIF('วางแผนBC,CJ'!$C:$C,'รับ-จ่าย ประจำวัน'!$B2,'วางแผนBC,CJ'!AH:AH)+SUMIF(RD!$C:$C,'รับ-จ่าย ประจำวัน'!$B2,RD!AH:AH)+SUMIF('FG,ออนไล,คัดแยก'!$C:$C,'รับ-จ่าย ประจำวัน'!$B2,'FG,ออนไล,คัดแยก'!AH:AH) -> 0 | BP2: =SUMIF(เตรียมส่วนผสม!$C:$C,'รับ-จ่าย ประจำวัน'!$B2,เตรียมส่วนผสม!AI:AI)+SUMIF(กวนไส้!$C:$C,'รับ-จ่าย ประจำวัน'!$B2,กวนไส้!AI:AI)+SUMIF(ผลิต1!$C:$C,'รับ-จ่าย ประจำวัน'!$B2,ผลิต1!AI:AI)+SUMIF(ผลิต2!$C:$C,'รับ-จ่าย ประจำวัน'!$B2,ผลิต2!AI:AI)+SUMIF(เส้นแต่งหน้าขนมเค้ก!$C:$C,'รับ-จ่าย ประจำวัน'!$B2,เส้นแต่งหน้าขนมเค้ก!AI:AI)+SUMIF(แพ็ค!$C:$C,'รับ-จ่าย ประจำวัน'!$B2,แพ็ค!AI:AI)+SUMIF(ธุรการ!$C:$C,'รับ-จ่าย ประจำวัน'!$B2,ธุรการ!AI:AI)+SUMIF(เส้นแต่งหน้าขนมปัง!$C:$C,'รับ-จ่าย ประจำวัน'!$B2,เส้นแต่งหน้าขนมปัง!AI:AI)+SUMIF('วางแผนBC,CJ'!$C:$C,'รับ-จ่าย ประจำวัน'!$B2,'วางแผนBC,CJ'!AI:AI)+SUMIF(RD!$C:$C,'รับ-จ่าย ประจำวัน'!$B2,RD!AI:AI)+SUMIF('FG,ออนไล,คัดแยก'!$C:$C,'รับ-จ่าย ประจำวัน'!$B2,'FG,ออนไล,คัดแยก'!AI:AI) -> 200 | BQ2: =SUMIF(เตรียมส่วนผสม!$C:$C,'รับ-จ่าย ประจำวัน'!$B2,เตรียมส่วนผสม!AJ:AJ)+SUMIF(กวนไส้!$C:$C,'รับ-จ่าย ประจำวัน'!$B2,กวนไส้!AJ:AJ)+SUMIF(ผลิต1!$C:$C,'รับ-จ่าย ประจำวัน'!$B2,ผลิต1!AJ:AJ)+SUMIF(ผลิต2!$C:$C,'รับ-จ่าย ประจำวัน'!$B2,ผลิต2!AJ:AJ)+SUMIF(เส้นแต่งหน้าขนมเค้ก!$C:$C,'รับ-จ่าย ประจำวัน'!$B2,เส้นแต่งหน้าขนมเค้ก!AJ:AJ)+SUMIF(แพ็ค!$C:$C,'รับ-จ่าย ประจำวัน'!$B2,แพ็ค!AJ:AJ)+SUMIF(ธุรการ!$C:$C,'รับ-จ่าย ประจำวัน'!$B2,ธุรการ!AJ:AJ)+SUMIF(เส้นแต่งหน้าขนมปัง!$C:$C,'รับ-จ่าย ประจำวัน'!$B2,เส้นแต่งหน้าขนมปัง!AJ:AJ)+SUMIF('วางแผนBC,CJ'!$C:$C,'รับ-จ่าย ประจำวัน'!$B2,'วางแผนBC,CJ'!AJ:AJ)+SUMIF(RD!$C:$C,'รับ-จ่าย ประจำวัน'!$B2,RD!AJ:AJ)+SUMIF('FG,ออนไล,คัดแยก'!$C:$C,'รับ-จ่าย ประจำวัน'!$B2,'FG,ออนไล,คัดแยก'!AJ:AJ) -> 0 | BR2: =SUMIF(เตรียมส่วนผสม!$C:$C,'รับ-จ่าย ประจำวัน'!$B2,เตรียมส่วนผสม!AK:AK)+SUMIF(กวนไส้!$C:$C,'รับ-จ่าย ประจำวัน'!$B2,กวนไส้!AK:AK)+SUMIF(ผลิต1!$C:$C,'รับ-จ่าย ประจำวัน'!$B2,ผลิต1!AK:AK)+SUMIF(ผลิต2!$C:$C,'รับ-จ่าย ประจำวัน'!$B2,ผลิต2!AK:AK)+SUMIF(เส้นแต่งหน้าขนมเค้ก!$C:$C,'รับ-จ่าย ประจำวัน'!$B2,เส้นแต่งหน้าขนมเค้ก!AK:AK)+SUMIF(แพ็ค!$C:$C,'รับ-จ่าย ประจำวัน'!$B2,แพ็ค!AK:AK)+SUMIF(ธุรการ!$C:$C,'รับ-จ่าย ประจำวัน'!$B2,ธุรการ!AK:AK)+SUMIF(เส้นแต่งหน้าขนมปัง!$C:$C,'รับ-จ่าย ประจำวัน'!$B2,เส้นแต่งหน้าขนมปัง!AK:AK)+SUMIF('วางแผนBC,CJ'!$C:$C,'รับ-จ่าย ประจำวัน'!$B2,'วางแผนBC,CJ'!AK:AK)+SUMIF(RD!$C:$C,'รับ-จ่าย ประจำวัน'!$B2,RD!AK:AK)+SUMIF('FG,ออนไล,คัดแยก'!$C:$C,'รับ-จ่าย ประจำวัน'!$B2,'FG,ออนไล,คัดแยก'!AK:AK) -> 0 | BS2: =SUMIF(เตรียมส่วนผสม!$C:$C,'รับ-จ่าย ประจำวัน'!$B2,เตรียมส่วนผสม!AL:AL)+SUMIF(กวนไส้!$C:$C,'รับ-จ่าย ประจำวัน'!$B2,กวนไส้!AL:AL)+SUMIF(ผลิต1!$C:$C,'รับ-จ่าย ประจำวัน'!$B2,ผลิต1!AL:AL)+SUMIF(ผลิต2!$C:$C,'รับ-จ่าย ประจำวัน'!$B2,ผลิต2!AL:AL)+SUMIF(เส้นแต่งหน้าขนมเค้ก!$C:$C,'รับ-จ่าย ประจำวัน'!$B2,เส้นแต่งหน้าขนมเค้ก!AL:AL)+SUMIF(แพ็ค!$C:$C,'รับ-จ่าย ประจำวัน'!$B2,แพ็ค!AL:AL)+SUMIF(ธุรการ!$C:$C,'รับ-จ่าย ประจำวัน'!$B2,ธุรการ!AL:AL)+SUMIF(เส้นแต่งหน้าขนมปัง!$C:$C,'รับ-จ่าย ประจำวัน'!$B2,เส้นแต่งหน้าขนมปัง!AL:AL)+SUMIF('วางแผนBC,CJ'!$C:$C,'รับ-จ่าย ประจำวัน'!$B2,'วางแผนBC,CJ'!AL:AL)+SUMIF(RD!$C:$C,'รับ-จ่าย ประจำวัน'!$B2,RD!AL:AL)+SUMIF('FG,ออนไล,คัดแยก'!$C:$C,'รับ-จ่าย ประจำวัน'!$B2,'FG,ออนไล,คัดแยก'!AL:AL) -> 0 | BT2: =AO2+AP2+AQ2+AR2+AS2+AT2+AU2+AV2+AW2+AX2+AY2+AZ2+BA2+BB2+BC2+BD2+BE2+BF2+BG2+BH2+BI2+BJ2+BK2+BL2+BM2+BN2+BO2+BP2+BQ2+BR2+BS2 -> 2200 | BU2: 2525 | BV2: =H2+AN2-BT2 -> 3500 | BW2: 30 | BX2: =BT2/30 -> 73.333333 | BY2: =BV2/BX2 -> 47.727273 | BZ2: =+TODAY()+BY2 -> 46250.727 | CK2: =+BV2-BU2 -> 975
A3: 02-BB05 | B3: 1020501002 | C3: กล่องเค้กเบาหวิวรสกาแฟ 100g New(1ห่อ*200ใบ) รหัสไหม่ | D3: ใบ | H3: 7000 | AN3: =I3+J3+K3+L3+M3+N3+O3+P3+Q3+R3+S3+T3+U3+V3+W3+X3+Y3+Z3+AA3+AB3+AC3+AD3+AE3+AF3+AG3+AH3+AI3+AJ3+AK3+AL3+AM3 -> 0 | AO3: =SUMIF(เตรียมส่วนผสม!$C:$C,'รับ-จ่าย ประจำวัน'!$B3,เตรียมส่วนผสม!H:H)+SUMIF(กวนไส้!$C:$C,'รับ-จ่าย ประจำวัน'!$B3,กวนไส้!H:H)+SUMIF(ผลิต1!$C:$C,'รับ-จ่าย ประจำวัน'!$B3,ผลิต1!H:H)+SUMIF(ผลิต2!$C:$C,'รับ-จ่าย ประจำวัน'!$B3,ผลิต2!H:H)+SUMIF(เส้นแต่งหน้าขนมเค้ก!$C:$C,'รับ-จ่าย ประจำวัน'!$B3,เส้นแต่งหน้าขนมเค้ก!H:H)+SUMIF(แพ็ค!$C:$C,'รับ-จ่าย ประจำวัน'!$B3,แพ็ค!H:H)+SUMIF(ธุรการ!$C:$C,'รับ-จ่าย ประจำวัน'!$B3,ธุรการ!H:H)+SUMIF(เส้นแต่งหน้าขนมปัง!$C:$C,'รับ-จ่าย ประจำวัน'!$B3,เส้นแต่งหน้าขนมปัง!H:H)+SUMIF('วางแผนBC,CJ'!$C:$C,'รับ-จ่าย ประจำวัน'!$B3,'วางแผนBC,CJ'!H:H)+SUMIF(RD!$C:$C,'รับ-จ่าย ประจำวัน'!$B3,RD!H:H)+SUMIF('FG,ออนไล,คัดแยก'!$C:$C,'รับ-จ่าย ประจำวัน'!$B3,'FG,ออนไล,คัดแยก'!H:H) -> 0 | AP3: =SUMIF(เตรียมส่วนผสม!$C:$C,'รับ-จ่าย ประจำวัน'!$B3,เตรียมส่วนผสม!I:I)+SUMIF(กวนไส้!$C:$C,'รับ-จ่าย ประจำวัน'!$B3,กวนไส้!I:I)+SUMIF(ผลิต1!$C:$C,'รับ-จ่าย ประจำวัน'!$B3,ผลิต1!I:I)+SUMIF(ผลิต2!$C:$C,'รับ-จ่าย ประจำวัน'!$B3,ผลิต2!I:I)+SUMIF(เส้นแต่งหน้าขนมเค้ก!$C:$C,'รับ-จ่าย ประจำวัน'!$B3,เส้นแต่งหน้าขนมเค้ก!I:I)+SUMIF(แพ็ค!$C:$C,'รับ-จ่าย ประจำวัน'!$B3,แพ็ค!I:I)+SUMIF(ธุรการ!$C:$C,'รับ-จ่าย ประจำวัน'!$B3,ธุรการ!I:I)+SUMIF(เส้นแต่งหน้าขนมปัง!$C:$C,'รับ-จ่าย ประจำวัน'!$B3,เส้นแต่งหน้าขนมปัง!I:I)+SUMIF('วางแผนBC,CJ'!$C:$C,'รับ-จ่าย ประจำวัน'!$B3,'วางแผนBC,CJ'!I:I)+SUMIF(RD!$C:$C,'รับ-จ่าย ประจำวัน'!$B3,RD!I:I)+SUMIF('FG,ออนไล,คัดแยก'!$C:$C,'รับ-จ่าย ประจำวัน'!$B3,'FG,ออนไล,คัดแยก'!I:I) -> 200 | AQ3: =SUMIF(เตรียมส่วนผสม!$C:$C,'รับ-จ่าย ประจำวัน'!$B3,เตรียมส่วนผสม!J:J)+SUMIF(กวนไส้!$C:$C,'รับ-จ่าย ประจำวัน'!$B3,กวนไส้!J:J)+SUMIF(ผลิต1!$C:$C,'รับ-จ่าย ประจำวัน'!$B3,ผลิต1!J:J)+SUMIF(ผลิต2!$C:$C,'รับ-จ่าย ประจำวัน'!$B3,ผลิต2!J:J)+SUMIF(เส้นแต่งหน้าขนมเค้ก!$C:$C,'รับ-จ่าย ประจำวัน'!$B3,เส้นแต่งหน้าขนมเค้ก!J:J)+SUMIF(แพ็ค!$C:$C,'รับ-จ่าย ประจำวัน'!$B3,แพ็ค!J:J)+SUMIF(ธุรการ!$C:$C,'รับ-จ่าย ประจำวัน'!$B3,ธุรการ!J:J)+SUMIF(เส้นแต่งหน้าขนมปัง!$C:$C,'รับ-จ่าย ประจำวัน'!$B3,เส้นแต่งหน้าขนมปัง!J:J)+SUMIF('วางแผนBC,CJ'!$C:$C,'รับ-จ่าย ประจำวัน'!$B3,'วางแผนBC,CJ'!J:J)+SUMIF(RD!$C:$C,'รับ-จ่าย ประจำวัน'!$B3,RD!J:J)+SUMIF('FG,ออนไล,คัดแยก'!$C:$C,'รับ-จ่าย ประจำวัน'!$B3,'FG,ออนไล,คัดแยก'!J:J) -> 0 | AR3: =SUMIF(เตรียมส่วนผสม!$C:$C,'รับ-จ่าย ประจำวัน'!$B3,เตรียมส่วนผสม!K:K)+SUMIF(กวนไส้!$C:$C,'รับ-จ่าย ประจำวัน'!$B3,กวนไส้!K:K)+SUMIF(ผลิต1!$C:$C,'รับ-จ่าย ประจำวัน'!$B3,ผลิต1!K:K)+SUMIF(ผลิต2!$C:$C,'รับ-จ่าย ประจำวัน'!$B3,ผลิต2!K:K)+SUMIF(เส้นแต่งหน้าขนมเค้ก!$C:$C,'รับ-จ่าย ประจำวัน'!$B3,เส้นแต่งหน้าขนมเค้ก!K:K)+SUMIF(แพ็ค!$C:$C,'รับ-จ่าย ประจำวัน'!$B3,แพ็ค!K:K)+SUMIF(ธุรการ!$C:$C,'รับ-จ่าย ประจำวัน'!$B3,ธุรการ!K:K)+SUMIF(เส้นแต่งหน้าขนมปัง!$C:$C,'รับ-จ่าย ประจำวัน'!$B3,เส้นแต่งหน้าขนมปัง!K:K)+SUMIF('วางแผนBC,CJ'!$C:$C,'รับ-จ่าย ประจำวัน'!$B3,'วางแผนBC,CJ'!K:K)+SUMIF(RD!$C:$C,'รับ-จ่าย ประจำวัน'!$B3,RD!K:K)+SUMIF('FG,ออนไล,คัดแยก'!$C:$C,'รับ-จ่าย ประจำวัน'!$B3,'FG,ออนไล,คัดแยก'!K:K) -> 0 | AS3: =SUMIF(เตรียมส่วนผสม!$C:$C,'รับ-จ่าย ประจำวัน'!$B3,เตรียมส่วนผสม!L:L)+SUMIF(กวนไส้!$C:$C,'รับ-จ่าย ประจำวัน'!$B3,กวนไส้!L:L)+SUMIF(ผลิต1!$C:$C,'รับ-จ่าย ประจำวัน'!$B3,ผลิต1!L:L)+SUMIF(ผลิต2!$C:$C,'รับ-จ่าย ประจำวัน'!$B3,ผลิต2!L:L)+SUMIF(เส้นแต่งหน้าขนมเค้ก!$C:$C,'รับ-จ่าย ประจำวัน'!$B3,เส้นแต่งหน้าขนมเค้ก!L:L)+SUMIF(แพ็ค!$C:$C,'รับ-จ่าย ประจำวัน'!$B3,แพ็ค!L:L)+SUMIF(ธุรการ!$C:$C,'รับ-จ่าย ประจำวัน'!$B3,ธุรการ!L:L)+SUMIF(เส้นแต่งหน้าขนมปัง!$C:$C,'รับ-จ่าย ประจำวัน'!$B3,เส้นแต่งหน้าขนมปัง!L:L)+SUMIF('วางแผนBC,CJ'!$C:$C,'รับ-จ่าย ประจำวัน'!$B3,'วางแผนBC,CJ'!L:L)+SUMIF(RD!$C:$C,'รับ-จ่าย ประจำวัน'!$B3,RD!L:L)+SUMIF('FG,ออนไล,คัดแยก'!$C:$C,'รับ-จ่าย ประจำวัน'!$B3,'FG,ออนไล,คัดแยก'!L:L) -> 200 | AT3: =SUMIF(เตรียมส่วนผสม!$C:$C,'รับ-จ่าย ประจำวัน'!$B3,เตรียมส่วนผสม!M:M)+SUMIF(กวนไส้!$C:$C,'รับ-จ่าย ประจำวัน'!$B3,กวนไส้!M:M)+SUMIF(ผลิต1!$C:$C,'รับ-จ่าย ประจำวัน'!$B3,ผลิต1!M:M)+SUMIF(ผลิต2!$C:$C,'รับ-จ่าย ประจำวัน'!$B3,ผลิต2!M:M)+SUMIF(เส้นแต่งหน้าขนมเค้ก!$C:$C,'รับ-จ่าย ประจำวัน'!$B3,เส้นแต่งหน้าขนมเค้ก!M:M)+SUMIF(แพ็ค!$C:$C,'รับ-จ่าย ประจำวัน'!$B3,แพ็ค!M:M)+SUMIF(ธุรการ!$C:$C,'รับ-จ่าย ประจำวัน'!$B3,ธุรการ!M:M)+SUMIF(เส้นแต่งหน้าขนมปัง!$C:$C,'รับ-จ่าย ประจำวัน'!$B3,เส้นแต่งหน้าขนมปัง!M:M)+SUMIF('วางแผนBC,CJ'!$C:$C,'รับ-จ่าย ประจำวัน'!$B3,'วางแผนBC,CJ'!M:M)+SUMIF(RD!$C:$C,'รับ-จ่าย ประจำวัน'!$B3,RD!M:M)+SUMIF('FG,ออนไล,คัดแยก'!$C:$C,'รับ-จ่าย ประจำวัน'!$B3,'FG,ออนไล,คัดแยก'!M:M) -> 0 | AU3: =SUMIF(เตรียมส่วนผสม!$C:$C,'รับ-จ่าย ประจำวัน'!$B3,เตรียมส่วนผสม!N:N)+SUMIF(กวนไส้!$C:$C,'รับ-จ่าย ประจำวัน'!$B3,กวนไส้!N:N)+SUMIF(ผลิต1!$C:$C,'รับ-จ่าย ประจำวัน'!$B3,ผลิต1!N:N)+SUMIF(ผลิต2!$C:$C,'รับ-จ่าย ประจำวัน'!$B3,ผลิต2!N:N)+SUMIF(เส้นแต่งหน้าขนมเค้ก!$C:$C,'รับ-จ่าย ประจำวัน'!$B3,เส้นแต่งหน้าขนมเค้ก!N:N)+SUMIF(แพ็ค!$C:$C,'รับ-จ่าย ประจำวัน'!$B3,แพ็ค!N:N)+SUMIF(ธุรการ!$C:$C,'รับ-จ่าย ประจำวัน'!$B3,ธุรการ!N:N)+SUMIF(เส้นแต่งหน้าขนมปัง!$C:$C,'รับ-จ่าย ประจำวัน'!$B3,เส้นแต่งหน้าขนมปัง!N:N)+SUMIF('วางแผนBC,CJ'!$C:$C,'รับ-จ่าย ประจำวัน'!$B3,'วางแผนBC,CJ'!N:N)+SUMIF(RD!$C:$C,'รับ-จ่าย ประจำวัน'!$B3,RD!N:N)+SUMIF('FG,ออนไล,คัดแยก'!$C:$C,'รับ-จ่าย ประจำวัน'!$B3,'FG,ออนไล,คัดแยก'!N:N) -> 200 | AV3: =SUMIF(เตรียมส่วนผสม!$C:$C,'รับ-จ่าย ประจำวัน'!$B3,เตรียมส่วนผสม!O:O)+SUMIF(กวนไส้!$C:$C,'รับ-จ่าย ประจำวัน'!$B3,กวนไส้!O:O)+SUMIF(ผลิต1!$C:$C,'รับ-จ่าย ประจำวัน'!$B3,ผลิต1!O:O)+SUMIF(ผลิต2!$C:$C,'รับ-จ่าย ประจำวัน'!$B3,ผลิต2!O:O)+SUMIF(เส้นแต่งหน้าขนมเค้ก!$C:$C,'รับ-จ่าย ประจำวัน'!$B3,เส้นแต่งหน้าขนมเค้ก!O:O)+SUMIF(แพ็ค!$C:$C,'รับ-จ่าย ประจำวัน'!$B3,แพ็ค!O:O)+SUMIF(ธุรการ!$C:$C,'รับ-จ่าย ประจำวัน'!$B3,ธุรการ!O:O)+SUMIF(เส้นแต่งหน้าขนมปัง!$C:$C,'รับ-จ่าย ประจำวัน'!$B3,เส้นแต่งหน้าขนมปัง!O:O)+SUMIF('วางแผนBC,CJ'!$C:$C,'รับ-จ่าย ประจำวัน'!$B3,'วางแผนBC,CJ'!O:O)+SUMIF(RD!$C:$C,'รับ-จ่าย ประจำวัน'!$B3,RD!O:O)+SUMIF('FG,ออนไล,คัดแยก'!$C:$C,'รับ-จ่าย ประจำวัน'!$B3,'FG,ออนไล,คัดแยก'!O:O) -> 0 | AW3: =SUMIF(เตรียมส่วนผสม!$C:$C,'รับ-จ่าย ประจำวัน'!$B3,เตรียมส่วนผสม!P:P)+SUMIF(กวนไส้!$C:$C,'รับ-จ่าย ประจำวัน'!$B3,กวนไส้!P:P)+SUMIF(ผลิต1!$C:$C,'รับ-จ่าย ประจำวัน'!$B3,ผลิต1!P:P)+SUMIF(ผลิต2!$C:$C,'รับ-จ่าย ประจำวัน'!$B3,ผลิต2!P:P)+SUMIF(เส้นแต่งหน้าขนมเค้ก!$C:$C,'รับ-จ่าย ประจำวัน'!$B3,เส้นแต่งหน้าขนมเค้ก!P:P)+SUMIF(แพ็ค!$C:$C,'รับ-จ่าย ประจำวัน'!$B3,แพ็ค!P:P)+SUMIF(ธุรการ!$C:$C,'รับ-จ่าย ประจำวัน'!$B3,ธุรการ!P:P)+SUMIF(เส้นแต่งหน้าขนมปัง!$C:$C,'รับ-จ่าย ประจำวัน'!$B3,เส้นแต่งหน้าขนมปัง!P:P)+SUMIF('วางแผนBC,CJ'!$C:$C,'รับ-จ่าย ประจำวัน'!$B3,'วางแผนBC,CJ'!P:P)+SUMIF(RD!$C:$C,'รับ-จ่าย ประจำวัน'!$B3,RD!P:P)+SUMIF('FG,ออนไล,คัดแยก'!$C:$C,'รับ-จ่าย ประจำวัน'!$B3,'FG,ออนไล,คัดแยก'!P:P) -> 200 | AX3: =SUMIF(เตรียมส่วนผสม!$C:$C,'รับ-จ่าย ประจำวัน'!$B3,เตรียมส่วนผสม!Q:Q)+SUMIF(กวนไส้!$C:$C,'รับ-จ่าย ประจำวัน'!$B3,กวนไส้!Q:Q)+SUMIF(ผลิต1!$C:$C,'รับ-จ่าย ประจำวัน'!$B3,ผลิต1!Q:Q)+SUMIF(ผลิต2!$C:$C,'รับ-จ่าย ประจำวัน'!$B3,ผลิต2!Q:Q)+SUMIF(เส้นแต่งหน้าขนมเค้ก!$C:$C,'รับ-จ่าย ประจำวัน'!$B3,เส้นแต่งหน้าขนมเค้ก!Q:Q)+SUMIF(แพ็ค!$C:$C,'รับ-จ่าย ประจำวัน'!$B3,แพ็ค!Q:Q)+SUMIF(ธุรการ!$C:$C,'รับ-จ่าย ประจำวัน'!$B3,ธุรการ!Q:Q)+SUMIF(เส้นแต่งหน้าขนมปัง!$C:$C,'รับ-จ่าย ประจำวัน'!$B3,เส้นแต่งหน้าขนมปัง!Q:Q)+SUMIF('วางแผนBC,CJ'!$C:$C,'รับ-จ่าย ประจำวัน'!$B3,'วางแผนBC,CJ'!Q:Q)+SUMIF(RD!$C:$C,'รับ-จ่าย ประจำวัน'!$B3,RD!Q:Q)+SUMIF('FG,ออนไล,คัดแยก'!$C:$C,'รับ-จ่าย ประจำวัน'!$B3,'FG,ออนไล,คัดแยก'!Q:Q) -> 0 | AY3: =SUMIF(เตรียมส่วนผสม!$C:$C,'รับ-จ่าย ประจำวัน'!$B3,เตรียมส่วนผสม!R:R)+SUMIF(กวนไส้!$C:$C,'รับ-จ่าย ประจำวัน'!$B3,กวนไส้!R:R)+SUMIF(ผลิต1!$C:$C,'รับ-จ่าย ประจำวัน'!$B3,ผลิต1!R:R)+SUMIF(ผลิต2!$C:$C,'รับ-จ่าย ประจำวัน'!$B3,ผลิต2!R:R)+SUMIF(เส้นแต่งหน้าขนมเค้ก!$C:$C,'รับ-จ่าย ประจำวัน'!$B3,เส้นแต่งหน้าขนมเค้ก!R:R)+SUMIF(แพ็ค!$C:$C,'รับ-จ่าย ประจำวัน'!$B3,แพ็ค!R:R)+SUMIF(ธุรการ!$C:$C,'รับ-จ่าย ประจำวัน'!$B3,ธุรการ!R:R)+SUMIF(เส้นแต่งหน้าขนมปัง!$C:$C,'รับ-จ่าย ประจำวัน'!$B3,เส้นแต่งหน้าขนมปัง!R:R)+SUMIF('วางแผนBC,CJ'!$C:$C,'รับ-จ่าย ประจำวัน'!$B3,'วางแผนBC,CJ'!R:R)+SUMIF(RD!$C:$C,'รับ-จ่าย ประจำวัน'!$B3,RD!R:R)+SUMIF('FG,ออนไล,คัดแยก'!$C:$C,'รับ-จ่าย ประจำวัน'!$B3,'FG,ออนไล,คัดแยก'!R:R) -> 0 | AZ3: =SUMIF(เตรียมส่วนผสม!$C:$C,'รับ-จ่าย ประจำวัน'!$B3,เตรียมส่วนผสม!S:S)+SUMIF(กวนไส้!$C:$C,'รับ-จ่าย ประจำวัน'!$B3,กวนไส้!S:S)+SUMIF(ผลิต1!$C:$C,'รับ-จ่าย ประจำวัน'!$B3,ผลิต1!S:S)+SUMIF(ผลิต2!$C:$C,'รับ-จ่าย ประจำวัน'!$B3,ผลิต2!S:S)+SUMIF(เส้นแต่งหน้าขนมเค้ก!$C:$C,'รับ-จ่าย ประจำวัน'!$B3,เส้นแต่งหน้าขนมเค้ก!S:S)+SUMIF(แพ็ค!$C:$C,'รับ-จ่าย ประจำวัน'!$B3,แพ็ค!S:S)+SUMIF(ธุรการ!$C:$C,'รับ-จ่าย ประจำวัน'!$B3,ธุรการ!S:S)+SUMIF(เส้นแต่งหน้าขนมปัง!$C:$C,'รับ-จ่าย ประจำวัน'!$B3,เส้นแต่งหน้าขนมปัง!S:S)+SUMIF('วางแผนBC,CJ'!$C:$C,'รับ-จ่าย ประจำวัน'!$B3,'วางแผนBC,CJ'!S:S)+SUMIF(RD!$C:$C,'รับ-จ่าย ประจำวัน'!$B3,RD!S:S)+SUMIF('FG,ออนไล,คัดแยก'!$C:$C,'รับ-จ่าย ประจำวัน'!$B3,'FG,ออนไล,คัดแยก'!S:S) -> 200 | BA3: =SUMIF(เตรียมส่วนผสม!$C:$C,'รับ-จ่าย ประจำวัน'!$B3,เตรียมส่วนผสม!T:T)+SUMIF(กวนไส้!$C:$C,'รับ-จ่าย ประจำวัน'!$B3,กวนไส้!T:T)+SUMIF(ผลิต1!$C:$C,'รับ-จ่าย ประจำวัน'!$B3,ผลิต1!T:T)+SUMIF(ผลิต2!$C:$C,'รับ-จ่าย ประจำวัน'!$B3,ผลิต2!T:T)+SUMIF(เส้นแต่งหน้าขนมเค้ก!$C:$C,'รับ-จ่าย ประจำวัน'!$B3,เส้นแต่งหน้าขนมเค้ก!T:T)+SUMIF(แพ็ค!$C:$C,'รับ-จ่าย ประจำวัน'!$B3,แพ็ค!T:T)+SUMIF(ธุรการ!$C:$C,'รับ-จ่าย ประจำวัน'!$B3,ธุรการ!T:T)+SUMIF(เส้นแต่งหน้าขนมปัง!$C:$C,'รับ-จ่าย ประจำวัน'!$B3,เส้นแต่งหน้าขนมปัง!T:T)+SUMIF('วางแผนBC,CJ'!$C:$C,'รับ-จ่าย ประจำวัน'!$B3,'วางแผนBC,CJ'!T:T)+SUMIF(RD!$C:$C,'รับ-จ่าย ประจำวัน'!$B3,RD!T:T)+SUMIF('FG,ออนไล,คัดแยก'!$C:$C,'รับ-จ่าย ประจำวัน'!$B3,'FG,ออนไล,คัดแยก'!T:T) -> 0 | BB3: =SUMIF(เตรียมส่วนผสม!$C:$C,'รับ-จ่าย ประจำวัน'!$B3,เตรียมส่วนผสม!U:U)+SUMIF(กวนไส้!$C:$C,'รับ-จ่าย ประจำวัน'!$B3,กวนไส้!U:U)+SUMIF(ผลิต1!$C:$C,'รับ-จ่าย ประจำวัน'!$B3,ผลิต1!U:U)+SUMIF(ผลิต2!$C:$C,'รับ-จ่าย ประจำวัน'!$B3,ผลิต2!U:U)+SUMIF(เส้นแต่งหน้าขนมเค้ก!$C:$C,'รับ-จ่าย ประจำวัน'!$B3,เส้นแต่งหน้าขนมเค้ก!U:U)+SUMIF(แพ็ค!$C:$C,'รับ-จ่าย ประจำวัน'!$B3,แพ็ค!U:U)+SUMIF(ธุรการ!$C:$C,'รับ-จ่าย ประจำวัน'!$B3,ธุรการ!U:U)+SUMIF(เส้นแต่งหน้าขนมปัง!$C:$C,'รับ-จ่าย ประจำวัน'!$B3,เส้นแต่งหน้าขนมปัง!U:U)+SUMIF('วางแผนBC,CJ'!$C:$C,'รับ-จ่าย ประจำวัน'!$B3,'วางแผนBC,CJ'!U:U)+SUMIF(RD!$C:$C,'รับ-จ่าย ประจำวัน'!$B3,RD!U:U)+SUMIF('FG,ออนไล,คัดแยก'!$C:$C,'รับ-จ่าย ประจำวัน'!$B3,'FG,ออนไล,คัดแยก'!U:U) -> 0 | BC3: =SUMIF(เตรียมส่วนผสม!$C:$C,'รับ-จ่าย ประจำวัน'!$B3,เตรียมส่วนผสม!V:V)+SUMIF(กวนไส้!$C:$C,'รับ-จ่าย ประจำวัน'!$B3,กวนไส้!V:V)+SUMIF(ผลิต1!$C:$C,'รับ-จ่าย ประจำวัน'!$B3,ผลิต1!V:V)+SUMIF(ผลิต2!$C:$C,'รับ-จ่าย ประจำวัน'!$B3,ผลิต2!V:V)+SUMIF(เส้นแต่งหน้าขนมเค้ก!$C:$C,'รับ-จ่าย ประจำวัน'!$B3,เส้นแต่งหน้าขนมเค้ก!V:V)+SUMIF(แพ็ค!$C:$C,'รับ-จ่าย ประจำวัน'!$B3,แพ็ค!V:V)+SUMIF(ธุรการ!$C:$C,'รับ-จ่าย ประจำวัน'!$B3,ธุรการ!V:V)+SUMIF(เส้นแต่งหน้าขนมปัง!$C:$C,'รับ-จ่าย ประจำวัน'!$B3,เส้นแต่งหน้าขนมปัง!V:V)+SUMIF('วางแผนBC,CJ'!$C:$C,'รับ-จ่าย ประจำวัน'!$B3,'วางแผนBC,CJ'!V:V)+SUMIF(RD!$C:$C,'รับ-จ่าย ประจำวัน'!$B3,RD!V:V)+SUMIF('FG,ออนไล,คัดแยก'!$C:$C,'รับ-จ่าย ประจำวัน'!$B3,'FG,ออนไล,คัดแยก'!V:V) -> 0 | BD3: =SUMIF(เตรียมส่วนผสม!$C:$C,'รับ-จ่าย ประจำวัน'!$B3,เตรียมส่วนผสม!W:W)+SUMIF(กวนไส้!$C:$C,'รับ-จ่าย ประจำวัน'!$B3,กวนไส้!W:W)+SUMIF(ผลิต1!$C:$C,'รับ-จ่าย ประจำวัน'!$B3,ผลิต1!W:W)+SUMIF(ผลิต2!$C:$C,'รับ-จ่าย ประจำวัน'!$B3,ผลิต2!W:W)+SUMIF(เส้นแต่งหน้าขนมเค้ก!$C:$C,'รับ-จ่าย ประจำวัน'!$B3,เส้นแต่งหน้าขนมเค้ก!W:W)+SUMIF(แพ็ค!$C:$C,'รับ-จ่าย ประจำวัน'!$B3,แพ็ค!W:W)+SUMIF(ธุรการ!$C:$C,'รับ-จ่าย ประจำวัน'!$B3,ธุรการ!W:W)+SUMIF(เส้นแต่งหน้าขนมปัง!$C:$C,'รับ-จ่าย ประจำวัน'!$B3,เส้นแต่งหน้าขนมปัง!W:W)+SUMIF('วางแผนBC,CJ'!$C:$C,'รับ-จ่าย ประจำวัน'!$B3,'วางแผนBC,CJ'!W:W)+SUMIF(RD!$C:$C,'รับ-จ่าย ประจำวัน'!$B3,RD!W:W)+SUMIF('FG,ออนไล,คัดแยก'!$C:$C,'รับ-จ่าย ประจำวัน'!$B3,'FG,ออนไล,คัดแยก'!W:W) -> 0 | BE3: =SUMIF(เตรียมส่วนผสม!$C:$C,'รับ-จ่าย ประจำวัน'!$B3,เตรียมส่วนผสม!X:X)+SUMIF(กวนไส้!$C:$C,'รับ-จ่าย ประจำวัน'!$B3,กวนไส้!X:X)+SUMIF(ผลิต1!$C:$C,'รับ-จ่าย ประจำวัน'!$B3,ผลิต1!X:X)+SUMIF(ผลิต2!$C:$C,'รับ-จ่าย ประจำวัน'!$B3,ผลิต2!X:X)+SUMIF(เส้นแต่งหน้าขนมเค้ก!$C:$C,'รับ-จ่าย ประจำวัน'!$B3,เส้นแต่งหน้าขนมเค้ก!X:X)+SUMIF(แพ็ค!$C:$C,'รับ-จ่าย ประจำวัน'!$B3,แพ็ค!X:X)+SUMIF(ธุรการ!$C:$C,'รับ-จ่าย ประจำวัน'!$B3,ธุรการ!X:X)+SUMIF(เส้นแต่งหน้าขนมปัง!$C:$C,'รับ-จ่าย ประจำวัน'!$B3,เส้นแต่งหน้าขนมปัง!X:X)+SUMIF('วางแผนBC,CJ'!$C:$C,'รับ-จ่าย ประจำวัน'!$B3,'วางแผนBC,CJ'!X:X)+SUMIF(RD!$C:$C,'รับ-จ่าย ประจำวัน'!$B3,RD!X:X)+SUMIF('FG,ออนไล,คัดแยก'!$C:$C,'รับ-จ่าย ประจำวัน'!$B3,'FG,ออนไล,คัดแยก'!X:X) -> 0 | BF3: =SUMIF(เตรียมส่วนผสม!$C:$C,'รับ-จ่าย ประจำวัน'!$B3,เตรียมส่วนผสม!Y:Y)+SUMIF(กวนไส้!$C:$C,'รับ-จ่าย ประจำวัน'!$B3,กวนไส้!Y:Y)+SUMIF(ผลิต1!$C:$C,'รับ-จ่าย ประจำวัน'!$B3,ผลิต1!Y:Y)+SUMIF(ผลิต2!$C:$C,'รับ-จ่าย ประจำวัน'!$B3,ผลิต2!Y:Y)+SUMIF(เส้นแต่งหน้าขนมเค้ก!$C:$C,'รับ-จ่าย ประจำวัน'!$B3,เส้นแต่งหน้าขนมเค้ก!Y:Y)+SUMIF(แพ็ค!$C:$C,'รับ-จ่าย ประจำวัน'!$B3,แพ็ค!Y:Y)+SUMIF(ธุรการ!$C:$C,'รับ-จ่าย ประจำวัน'!$B3,ธุรการ!Y:Y)+SUMIF(เส้นแต่งหน้าขนมปัง!$C:$C,'รับ-จ่าย ประจำวัน'!$B3,เส้นแต่งหน้าขนมปัง!Y:Y)+SUMIF('วางแผนBC,CJ'!$C:$C,'รับ-จ่าย ประจำวัน'!$B3,'วางแผนBC,CJ'!Y:Y)+SUMIF(RD!$C:$C,'รับ-จ่าย ประจำวัน'!$B3,RD!Y:Y)+SUMIF('FG,ออนไล,คัดแยก'!$C:$C,'รับ-จ่าย ประจำวัน'!$B3,'FG,ออนไล,คัดแยก'!Y:Y) -> 0 | BG3: =SUMIF(เตรียมส่วนผสม!$C:$C,'รับ-จ่าย ประจำวัน'!$B3,เตรียมส่วนผสม!Z:Z)+SUMIF(กวนไส้!$C:$C,'รับ-จ่าย ประจำวัน'!$B3,กวนไส้!Z:Z)+SUMIF(ผลิต1!$C:$C,'รับ-จ่าย ประจำวัน'!$B3,ผลิต1!Z:Z)+SUMIF(ผลิต2!$C:$C,'รับ-จ่าย ประจำวัน'!$B3,ผลิต2!Z:Z)+SUMIF(เส้นแต่งหน้าขนมเค้ก!$C:$C,'รับ-จ่าย ประจำวัน'!$B3,เส้นแต่งหน้าขนมเค้ก!Z:Z)+SUMIF(แพ็ค!$C:$C,'รับ-จ่าย ประจำวัน'!$B3,แพ็ค!Z:Z)+SUMIF(ธุรการ!$C:$C,'รับ-จ่าย ประจำวัน'!$B3,ธุรการ!Z:Z)+SUMIF(เส้นแต่งหน้าขนมปัง!$C:$C,'รับ-จ่าย ประจำวัน'!$B3,เส้นแต่งหน้าขนมปัง!Z:Z)+SUMIF('วางแผนBC,CJ'!$C:$C,'รับ-จ่าย ประจำวัน'!$B3,'วางแผนBC,CJ'!Z:Z)+SUMIF(RD!$C:$C,'รับ-จ่าย ประจำวัน'!$B3,RD!Z:Z)+SUMIF('FG,ออนไล,คัดแยก'!$C:$C,'รับ-จ่าย ประจำวัน'!$B3,'FG,ออนไล,คัดแยก'!Z:Z) -> 0 | BH3: =SUMIF(เตรียมส่วนผสม!$C:$C,'รับ-จ่าย ประจำวัน'!$B3,เตรียมส่วนผสม!AA:AA)+SUMIF(กวนไส้!$C:$C,'รับ-จ่าย ประจำวัน'!$B3,กวนไส้!AA:AA)+SUMIF(ผลิต1!$C:$C,'รับ-จ่าย ประจำวัน'!$B3,ผลิต1!AA:AA)+SUMIF(ผลิต2!$C:$C,'รับ-จ่าย ประจำวัน'!$B3,ผลิต2!AA:AA)+SUMIF(เส้นแต่งหน้าขนมเค้ก!$C:$C,'รับ-จ่าย ประจำวัน'!$B3,เส้นแต่งหน้าขนมเค้ก!AA:AA)+SUMIF(แพ็ค!$C:$C,'รับ-จ่าย ประจำวัน'!$B3,แพ็ค!AA:AA)+SUMIF(ธุรการ!$C:$C,'รับ-จ่าย ประจำวัน'!$B3,ธุรการ!AA:AA)+SUMIF(เส้นแต่งหน้าขนมปัง!$C:$C,'รับ-จ่าย ประจำวัน'!$B3,เส้นแต่งหน้าขนมปัง!AA:AA)+SUMIF('วางแผนBC,CJ'!$C:$C,'รับ-จ่าย ประจำวัน'!$B3,'วางแผนBC,CJ'!AA:AA)+SUMIF(RD!$C:$C,'รับ-จ่าย ประจำวัน'!$B3,RD!AA:AA)+SUMIF('FG,ออนไล,คัดแยก'!$C:$C,'รับ-จ่าย ประจำวัน'!$B3,'FG,ออนไล,คัดแยก'!AA:AA) -> 0 | BI3: =SUMIF(เตรียมส่วนผสม!$C:$C,'รับ-จ่าย ประจำวัน'!$B3,เตรียมส่วนผสม!AB:AB)+SUMIF(กวนไส้!$C:$C,'รับ-จ่าย ประจำวัน'!$B3,กวนไส้!AB:AB)+SUMIF(ผลิต1!$C:$C,'รับ-จ่าย ประจำวัน'!$B3,ผลิต1!AB:AB)+SUMIF(ผลิต2!$C:$C,'รับ-จ่าย ประจำวัน'!$B3,ผลิต2!AB:AB)+SUMIF(เส้นแต่งหน้าขนมเค้ก!$C:$C,'รับ-จ่าย ประจำวัน'!$B3,เส้นแต่งหน้าขนมเค้ก!AB:AB)+SUMIF(แพ็ค!$C:$C,'รับ-จ่าย ประจำวัน'!$B3,แพ็ค!AB:AB)+SUMIF(ธุรการ!$C:$C,'รับ-จ่าย ประจำวัน'!$B3,ธุรการ!AB:AB)+SUMIF(เส้นแต่งหน้าขนมปัง!$C:$C,'รับ-จ่าย ประจำวัน'!$B3,เส้นแต่งหน้าขนมปัง!AB:AB)+SUMIF('วางแผนBC,CJ'!$C:$C,'รับ-จ่าย ประจำวัน'!$B3,'วางแผนBC,CJ'!AB:AB)+SUMIF(RD!$C:$C,'รับ-จ่าย ประจำวัน'!$B3,RD!AB:AB)+SUMIF('FG,ออนไล,คัดแยก'!$C:$C,'รับ-จ่าย ประจำวัน'!$B3,'FG,ออนไล,คัดแยก'!AB:AB) -> 200 | BJ3: =SUMIF(เตรียมส่วนผสม!$C:$C,'รับ-จ่าย ประจำวัน'!$B3,เตรียมส่วนผสม!AC:AC)+SUMIF(กวนไส้!$C:$C,'รับ-จ่าย ประจำวัน'!$B3,กวนไส้!AC:AC)+SUMIF(ผลิต1!$C:$C,'รับ-จ่าย ประจำวัน'!$B3,ผลิต1!AC:AC)+SUMIF(ผลิต2!$C:$C,'รับ-จ่าย ประจำวัน'!$B3,ผลิต2!AC:AC)+SUMIF(เส้นแต่งหน้าขนมเค้ก!$C:$C,'รับ-จ่าย ประจำวัน'!$B3,เส้นแต่งหน้าขนมเค้ก!AC:AC)+SUMIF(แพ็ค!$C:$C,'รับ-จ่าย ประจำวัน'!$B3,แพ็ค!AC:AC)+SUMIF(ธุรการ!$C:$C,'รับ-จ่าย ประจำวัน'!$B3,ธุรการ!AC:AC)+SUMIF(เส้นแต่งหน้าขนมปัง!$C:$C,'รับ-จ่าย ประจำวัน'!$B3,เส้นแต่งหน้าขนมปัง!AC:AC)+SUMIF('วางแผนBC,CJ'!$C:$C,'รับ-จ่าย ประจำวัน'!$B3,'วางแผนBC,CJ'!AC:AC)+SUMIF(RD!$C:$C,'รับ-จ่าย ประจำวัน'!$B3,RD!AC:AC)+SUMIF('FG,ออนไล,คัดแยก'!$C:$C,'รับ-จ่าย ประจำวัน'!$B3,'FG,ออนไล,คัดแยก'!AC:AC) -> 0 | BK3: =SUMIF(เตรียมส่วนผสม!$C:$C,'รับ-จ่าย ประจำวัน'!$B3,เตรียมส่วนผสม!AD:AD)+SUMIF(กวนไส้!$C:$C,'รับ-จ่าย ประจำวัน'!$B3,กวนไส้!AD:AD)+SUMIF(ผลิต1!$C:$C,'รับ-จ่าย ประจำวัน'!$B3,ผลิต1!AD:AD)+SUMIF(ผลิต2!$C:$C,'รับ-จ่าย ประจำวัน'!$B3,ผลิต2!AD:AD)+SUMIF(เส้นแต่งหน้าขนมเค้ก!$C:$C,'รับ-จ่าย ประจำวัน'!$B3,เส้นแต่งหน้าขนมเค้ก!AD:AD)+SUMIF(แพ็ค!$C:$C,'รับ-จ่าย ประจำวัน'!$B3,แพ็ค!AD:AD)+SUMIF(ธุรการ!$C:$C,'รับ-จ่าย ประจำวัน'!$B3,ธุรการ!AD:AD)+SUMIF(เส้นแต่งหน้าขนมปัง!$C:$C,'รับ-จ่าย ประจำวัน'!$B3,เส้นแต่งหน้าขนมปัง!AD:AD)+SUMIF('วางแผนBC,CJ'!$C:$C,'รับ-จ่าย ประจำวัน'!$B3,'วางแผนBC,CJ'!AD:AD)+SUMIF(RD!$C:$C,'รับ-จ่าย ประจำวัน'!$B3,RD!AD:AD)+SUMIF('FG,ออนไล,คัดแยก'!$C:$C,'รับ-จ่าย ประจำวัน'!$B3,'FG,ออนไล,คัดแยก'!AD:AD) -> 0 | BL3: =SUMIF(เตรียมส่วนผสม!$C:$C,'รับ-จ่าย ประจำวัน'!$B3,เตรียมส่วนผสม!AE:AE)+SUMIF(กวนไส้!$C:$C,'รับ-จ่าย ประจำวัน'!$B3,กวนไส้!AE:AE)+SUMIF(ผลิต1!$C:$C,'รับ-จ่าย ประจำวัน'!$B3,ผลิต1!AE:AE)+SUMIF(ผลิต2!$C:$C,'รับ-จ่าย ประจำวัน'!$B3,ผลิต2!AE:AE)+SUMIF(เส้นแต่งหน้าขนมเค้ก!$C:$C,'รับ-จ่าย ประจำวัน'!$B3,เส้นแต่งหน้าขนมเค้ก!AE:AE)+SUMIF(แพ็ค!$C:$C,'รับ-จ่าย ประจำวัน'!$B3,แพ็ค!AE:AE)+SUMIF(ธุรการ!$C:$C,'รับ-จ่าย ประจำวัน'!$B3,ธุรการ!AE:AE)+SUMIF(เส้นแต่งหน้าขนมปัง!$C:$C,'รับ-จ่าย ประจำวัน'!$B3,เส้นแต่งหน้าขนมปัง!AE:AE)+SUMIF('วางแผนBC,CJ'!$C:$C,'รับ-จ่าย ประจำวัน'!$B3,'วางแผนBC,CJ'!AE:AE)+SUMIF(RD!$C:$C,'รับ-จ่าย ประจำวัน'!$B3,RD!AE:AE)+SUMIF('FG,ออนไล,คัดแยก'!$C:$C,'รับ-จ่าย ประจำวัน'!$B3,'FG,ออนไล,คัดแยก'!AE:AE) -> 200 | BM3: =SUMIF(เตรียมส่วนผสม!$C:$C,'รับ-จ่าย ประจำวัน'!$B3,เตรียมส่วนผสม!AF:AF)+SUMIF(กวนไส้!$C:$C,'รับ-จ่าย ประจำวัน'!$B3,กวนไส้!AF:AF)+SUMIF(ผลิต1!$C:$C,'รับ-จ่าย ประจำวัน'!$B3,ผลิต1!AF:AF)+SUMIF(ผลิต2!$C:$C,'รับ-จ่าย ประจำวัน'!$B3,ผลิต2!AF:AF)+SUMIF(เส้นแต่งหน้าขนมเค้ก!$C:$C,'รับ-จ่าย ประจำวัน'!$B3,เส้นแต่งหน้าขนมเค้ก!AF:AF)+SUMIF(แพ็ค!$C:$C,'รับ-จ่าย ประจำวัน'!$B3,แพ็ค!AF:AF)+SUMIF(ธุรการ!$C:$C,'รับ-จ่าย ประจำวัน'!$B3,ธุรการ!AF:AF)+SUMIF(เส้นแต่งหน้าขนมปัง!$C:$C,'รับ-จ่าย ประจำวัน'!$B3,เส้นแต่งหน้าขนมปัง!AF:AF)+SUMIF('วางแผนBC,CJ'!$C:$C,'รับ-จ่าย ประจำวัน'!$B3,'วางแผนBC,CJ'!AF:AF)+SUMIF(RD!$C:$C,'รับ-จ่าย ประจำวัน'!$B3,RD!AF:AF)+SUMIF('FG,ออนไล,คัดแยก'!$C:$C,'รับ-จ่าย ประจำวัน'!$B3,'FG,ออนไล,คัดแยก'!AF:AF) -> 0 | BN3: =SUMIF(เตรียมส่วนผสม!$C:$C,'รับ-จ่าย ประจำวัน'!$B3,เตรียมส่วนผสม!AG:AG)+SUMIF(กวนไส้!$C:$C,'รับ-จ่าย ประจำวัน'!$B3,กวนไส้!AG:AG)+SUMIF(ผลิต1!$C:$C,'รับ-จ่าย ประจำวัน'!$B3,ผลิต1!AG:AG)+SUMIF(ผลิต2!$C:$C,'รับ-จ่าย ประจำวัน'!$B3,ผลิต2!AG:AG)+SUMIF(เส้นแต่งหน้าขนมเค้ก!$C:$C,'รับ-จ่าย ประจำวัน'!$B3,เส้นแต่งหน้าขนมเค้ก!AG:AG)+SUMIF(แพ็ค!$C:$C,'รับ-จ่าย ประจำวัน'!$B3,แพ็ค!AG:AG)+SUMIF(ธุรการ!$C:$C,'รับ-จ่าย ประจำวัน'!$B3,ธุรการ!AG:AG)+SUMIF(เส้นแต่งหน้าขนมปัง!$C:$C,'รับ-จ่าย ประจำวัน'!$B3,เส้นแต่งหน้าขนมปัง!AG:AG)+SUMIF('วางแผนBC,CJ'!$C:$C,'รับ-จ่าย ประจำวัน'!$B3,'วางแผนBC,CJ'!AG:AG)+SUMIF(RD!$C:$C,'รับ-จ่าย ประจำวัน'!$B3,RD!AG:AG)+SUMIF('FG,ออนไล,คัดแยก'!$C:$C,'รับ-จ่าย ประจำวัน'!$B3,'FG,ออนไล,คัดแยก'!AG:AG) -> 0 | BO3: =SUMIF(เตรียมส่วนผสม!$C:$C,'รับ-จ่าย ประจำวัน'!$B3,เตรียมส่วนผสม!AH:AH)+SUMIF(กวนไส้!$C:$C,'รับ-จ่าย ประจำวัน'!$B3,กวนไส้!AH:AH)+SUMIF(ผลิต1!$C:$C,'รับ-จ่าย ประจำวัน'!$B3,ผลิต1!AH:AH)+SUMIF(ผลิต2!$C:$C,'รับ-จ่าย ประจำวัน'!$B3,ผลิต2!AH:AH)+SUMIF(เส้นแต่งหน้าขนมเค้ก!$C:$C,'รับ-จ่าย ประจำวัน'!$B3,เส้นแต่งหน้าขนมเค้ก!AH:AH)+SUMIF(แพ็ค!$C:$C,'รับ-จ่าย ประจำวัน'!$B3,แพ็ค!AH:AH)+SUMIF(ธุรการ!$C:$C,'รับ-จ่าย ประจำวัน'!$B3,ธุรการ!AH:AH)+SUMIF(เส้นแต่งหน้าขนมปัง!$C:$C,'รับ-จ่าย ประจำวัน'!$B3,เส้นแต่งหน้าขนมปัง!AH:AH)+SUMIF('วางแผนBC,CJ'!$C:$C,'รับ-จ่าย ประจำวัน'!$B3,'วางแผนBC,CJ'!AH:AH)+SUMIF(RD!$C:$C,'รับ-จ่าย ประจำวัน'!$B3,RD!AH:AH)+SUMIF('FG,ออนไล,คัดแยก'!$C:$C,'รับ-จ่าย ประจำวัน'!$B3,'FG,ออนไล,คัดแยก'!AH:AH) -> 0 | BP3: =SUMIF(เตรียมส่วนผสม!$C:$C,'รับ-จ่าย ประจำวัน'!$B3,เตรียมส่วนผสม!AI:AI)+SUMIF(กวนไส้!$C:$C,'รับ-จ่าย ประจำวัน'!$B3,กวนไส้!AI:AI)+SUMIF(ผลิต1!$C:$C,'รับ-จ่าย ประจำวัน'!$B3,ผลิต1!AI:AI)+SUMIF(ผลิต2!$C:$C,'รับ-จ่าย ประจำวัน'!$B3,ผลิต2!AI:AI)+SUMIF(เส้นแต่งหน้าขนมเค้ก!$C:$C,'รับ-จ่าย ประจำวัน'!$B3,เส้นแต่งหน้าขนมเค้ก!AI:AI)+SUMIF(แพ็ค!$C:$C,'รับ-จ่าย ประจำวัน'!$B3,แพ็ค!AI:AI)+SUMIF(ธุรการ!$C:$C,'รับ-จ่าย ประจำวัน'!$B3,ธุรการ!AI:AI)+SUMIF(เส้นแต่งหน้าขนมปัง!$C:$C,'รับ-จ่าย ประจำวัน'!$B3,เส้นแต่งหน้าขนมปัง!AI:AI)+SUMIF('วางแผนBC,CJ'!$C:$C,'รับ-จ่าย ประจำวัน'!$B3,'วางแผนBC,CJ'!AI:AI)+SUMIF(RD!$C:$C,'รับ-จ่าย ประจำวัน'!$B3,RD!AI:AI)+SUMIF('FG,ออนไล,คัดแยก'!$C:$C,'รับ-จ่าย ประจำวัน'!$B3,'FG,ออนไล,คัดแยก'!AI:AI) -> 0 | BQ3: =SUMIF(เตรียมส่วนผสม!$C:$C,'รับ-จ่าย ประจำวัน'!$B3,เตรียมส่วนผสม!AJ:AJ)+SUMIF(กวนไส้!$C:$C,'รับ-จ่าย ประจำวัน'!$B3,กวนไส้!AJ:AJ)+SUMIF(ผลิต1!$C:$C,'รับ-จ่าย ประจำวัน'!$B3,ผลิต1!AJ:AJ)+SUMIF(ผลิต2!$C:$C,'รับ-จ่าย ประจำวัน'!$B3,ผลิต2!AJ:AJ)+SUMIF(เส้นแต่งหน้าขนมเค้ก!$C:$C,'รับ-จ่าย ประจำวัน'!$B3,เส้นแต่งหน้าขนมเค้ก!AJ:AJ)+SUMIF(แพ็ค!$C:$C,'รับ-จ่าย ประจำวัน'!$B3,แพ็ค!AJ:AJ)+SUMIF(ธุรการ!$C:$C,'รับ-จ่าย ประจำวัน'!$B3,ธุรการ!AJ:AJ)+SUMIF(เส้นแต่งหน้าขนมปัง!$C:$C,'รับ-จ่าย ประจำวัน'!$B3,เส้นแต่งหน้าขนมปัง!AJ:AJ)+SUMIF('วางแผนBC,CJ'!$C:$C,'รับ-จ่าย ประจำวัน'!$B3,'วางแผนBC,CJ'!AJ:AJ)+SUMIF(RD!$C:$C,'รับ-จ่าย ประจำวัน'!$B3,RD!AJ:AJ)+SUMIF('FG,ออนไล,คัดแยก'!$C:$C,'รับ-จ่าย ประจำวัน'!$B3,'FG,ออนไล,คัดแยก'!AJ:AJ) -> 0 | BR3: =SUMIF(เตรียมส่วนผสม!$C:$C,'รับ-จ่าย ประจำวัน'!$B3,เตรียมส่วนผสม!AK:AK)+SUMIF(กวนไส้!$C:$C,'รับ-จ่าย ประจำวัน'!$B3,กวนไส้!AK:AK)+SUMIF(ผลิต1!$C:$C,'รับ-จ่าย ประจำวัน'!$B3,ผลิต1!AK:AK)+SUMIF(ผลิต2!$C:$C,'รับ-จ่าย ประจำวัน'!$B3,ผลิต2!AK:AK)+SUMIF(เส้นแต่งหน้าขนมเค้ก!$C:$C,'รับ-จ่าย ประจำวัน'!$B3,เส้นแต่งหน้าขนมเค้ก!AK:AK)+SUMIF(แพ็ค!$C:$C,'รับ-จ่าย ประจำวัน'!$B3,แพ็ค!AK:AK)+SUMIF(ธุรการ!$C:$C,'รับ-จ่าย ประจำวัน'!$B3,ธุรการ!AK:AK)+SUMIF(เส้นแต่งหน้าขนมปัง!$C:$C,'รับ-จ่าย ประจำวัน'!$B3,เส้นแต่งหน้าขนมปัง!AK:AK)+SUMIF('วางแผนBC,CJ'!$C:$C,'รับ-จ่าย ประจำวัน'!$B3,'วางแผนBC,CJ'!AK:AK)+SUMIF(RD!$C:$C,'รับ-จ่าย ประจำวัน'!$B3,RD!AK:AK)+SUMIF('FG,ออนไล,คัดแยก'!$C:$C,'รับ-จ่าย ประจำวัน'!$B3,'FG,ออนไล,คัดแยก'!AK:AK) -> 0 | BS3: =SUMIF(เตรียมส่วนผสม!$C:$C,'รับ-จ่าย ประจำวัน'!$B3,เตรียมส่วนผสม!AL:AL)+SUMIF(กวนไส้!$C:$C,'รับ-จ่าย ประจำวัน'!$B3,กวนไส้!AL:AL)+SUMIF(ผลิต1!$C:$C,'รับ-จ่าย ประจำวัน'!$B3,ผลิต1!AL:AL)+SUMIF(ผลิต2!$C:$C,'รับ-จ่าย ประจำวัน'!$B3,ผลิต2!AL:AL)+SUMIF(เส้นแต่งหน้าขนมเค้ก!$C:$C,'รับ-จ่าย ประจำวัน'!$B3,เส้นแต่งหน้าขนมเค้ก!AL:AL)+SUMIF(แพ็ค!$C:$C,'รับ-จ่าย ประจำวัน'!$B3,แพ็ค!AL:AL)+SUMIF(ธุรการ!$C:$C,'รับ-จ่าย ประจำวัน'!$B3,ธุรการ!AL:AL)+SUMIF(เส้นแต่งหน้าขนมปัง!$C:$C,'รับ-จ่าย ประจำวัน'!$B3,เส้นแต่งหน้าขนมปัง!AL:AL)+SUMIF('วางแผนBC,CJ'!$C:$C,'รับ-จ่าย ประจำวัน'!$B3,'วางแผนBC,CJ'!AL:AL)+SUMIF(RD!$C:$C,'รับ-จ่าย ประจำวัน'!$B3,RD!AL:AL)+SUMIF('FG,ออนไล,คัดแยก'!$C:$C,'รับ-จ่าย ประจำวัน'!$B3,'FG,ออนไล,คัดแยก'!AL:AL) -> 0 | BT3: =AO3+AP3+AQ3+AR3+AS3+AT3+AU3+AV3+AW3+AX3+AY3+AZ3+BA3+BB3+BC3+BD3+BE3+BF3+BG3+BH3+BI3+BJ3+BK3+BL3+BM3+BN3+BO3+BP3+BQ3+BR3+BS3 -> 1400 | BV3: =H3+AN3-BT3 -> 5600 | BW3: 30 | BX3: =BT3/30 -> 46.666667 | BY3: =BV3/BX3 -> 120 | BZ3: =+TODAY()+BY3 -> 46323 | CK3: =+BV3-BU3 -> 5600
