Workbook

Sheet เย็น 
B1: ยอดจริง ออนไลน์ วันที่ 25/1/2568 - เย็น
L2: ยอดรวมผลิต
L3: จำนวน
B4: รหัสสินค้า | C4: สินค้า | D4: ปณ | E4: ชอปปี้ | F4: ลาซาด้า | G4: ติ๊กตอก | H4: ติ๊กตอก 2 | I4: ติ๊กตอก3 | J4: ชอยส์ | K4: ยอดเส้น | L4: (กล่อง)
B6: ชิฟฟอนรวมรส
B7: 1111002 | C7: ชิฟฟอนรวมรส 8 ชิ้น | L7: =SUM(D7:K7) -> 0
C8: ชิฟฟอนแบบกล่องสุ่มอะไรก็ได้ที่มี | L8: =SUM(D8:K8) -> 0
B9: 1111084 | C9: ชิฟฟอน 8 ชิ้น กาแฟล้วน | L9: =SUM(D9:K9) -> 0
B10: 1111085 | C10: ชิฟฟอน 8 ชิ้น บลูเบอรี่ล้วน | L10: =SUM(D10:K10) -> 0
B11: 1111086 | C11: ชิฟฟอน 8 ชิ้น มะพร้าวล้วน | L11: =SUM(D11:K11) -> 0
B12: 1111087 | C12: ชิฟฟอน 8 ชิ้น สตอเบอรี่ล้วน | L12: =SUM(D12:K12) -> 0
B13: 1111088 | C13: ชิฟฟอน 8 ชิ้น ส้มล้วน | L13: =SUM(D13:K13) -> 0
B14: 1111089 | C14: ชิฟฟอน 8 ชิ้น เนยล้วน | L14: =SUM(D14:K14) -> 0
B15: 1111090 | C15: ชิฟฟอน 8 ชิ้น เผือกล้วน | L15: =SUM(D15:K15) -> 0
B16: 1111091 | C16: ชิฟฟอน 8 ชิ้น ใบเตยล้วน | L16: =SUM(D16:K16) -> 0
B17: 1111092 | C17: ชิฟฟอน 8 ชิ้น กล้วยหอม | L17: =SUM(D17:K17) -> 0
B18: 1111093 | C18: ชิฟฟอน 8 ชิ้น โกโก้ล้วน | L18: =SUM(D18:K18) -> 0
B19: 1111094 | C19: ชิฟฟอน 8 ชิ้น ชาไทยล้วน | L19: =SUM(D19:K19) -> 0
B20: 1111095 | C20: ชิฟฟอน 8 ชิ้น ชาเขียวล้วน | L20: =SUM(D20:K20) -> 0
... B66: 1111010 | C66: ชิฟฟอนไส้แยมแยกชิ้น คละรส | L66: =SUM(D66:K66) -> 0
C67: รวม
B68: ชิฟฟอนไส้แยม 6 ชิ้น
B69: 1111009 | C69: ชิฟฟอนไส้แยมรวมรส 6 ชิ้น | L69: =SUM(D69:K69) -> 0
B70: 1111023 | C70: ชิฟฟอนไส้แยมรสสตอเบอร์รี่ล้วน 6 ชิ้น | L70: =SUM(D70:K70) -> 0
B71: 1111016 | C71: ชิฟฟอนไส้แยมรสมะพร้าวล้วน 6 ชิ้น | L71: =SUM(D71:K71) -> 0
B72: 1111014 | C72: ชิฟฟอนไส้แยมรสช็อกโกแลตนูเทลล่าล้วน 6 ชิ้น | L72: =SUM(D72:K72) -> 0
B73: 1111025 | C73: ชิฟฟอนไส้แยมรสส้มล้วน 6 ชิ้น | L73: =SUM(D73:K73) -> 0
B74: 1111018 | C74: ชิฟฟอนไส้แยมรสบลูเบอร์รี่ล้วน 6 ชิ้น | L74: =SUM(D74:K74) -> 0
B75: 1111012 | C75: ชิฟฟอนไส้แยมรสนมชมพูฮอกไกโดล้วน 6 ชิ้น | L75: =SUM(D75:K75) -> 0
B76: 1111020 | C76: ชิฟฟอนไส้แยมฝอยทองไส้ทะลัก 6 ชิ้น | L76: =SUM(D76:K76) -> 0
C77: รวม
B78: ชิฟฟอนไส้แยม 3 ชิ้น
B79: 1111022 | C79: ชิฟฟอนไส้แยมรสสตอเบอร์รี่ล้วน 3 ชิ้น | L79: =SUM(D79:K79) -> 0
B80: 1111015 | C80: ชิฟฟอนไส้แยมรสมะพร้าวล้วน 3 ชิ้น | L80: =SUM(D80:K80) -> 0
B81: 1111013 | C81: ชิฟฟอนไส้แยมรสช็อกโกแลตนูเทลล่าล้วน 3 ชิ้น | L81: =SUM(D81:K81) -> 0
B82: 1111024 | C82: ชิฟฟอนไส้แยมรสส้มล้วน 3 ชิ้น | L82: =SUM(D82:K82) -> 0
B83: 1111017 | C83: ชิฟฟอนไส้แยมรสบลูเบอร์รี่ล้วน 3 ชิ้น | L83: =SUM(D83:K83) -> 0
B84: 1111011 | C84: ชิฟฟอนไส้แยมรสนมชมพูฮอกไกโดล้วน 3 ชิ้น | L84: =SUM(D84:K84) -> 0
B85: 1111019 | C85: ชิฟฟอนไส้แยมฝอยทองไส้ทะลัก 3 ชิ้น | L85: =SUM(D85:K85) -> 0
B86: 1113081 | C86: ชิฟฟอนไส้แยม วนิลา/ใบเตย/เมล่อน | L86: =SUM(D86:K86) -> 0
...

Sheet เช้า 
B1: ยอดจริง ออนไลน์ วันที่ - เช้า
L2: ยอดรวมผลิต
L3: จำนวน
B4: รหัสสินค้า | C4: สินค้า | D4: ปณ | E4: ชอปปี้ | F4: ลาซาด้า | G4: ติ๊กตอก | H4: ติ๊กตอก 2 | I4: ติ๊กตอก3 | J4: ชอยส์ | K4: ยอดเส้น | L4: (กล่อง)
B6: ชิฟฟอนรวมรส
B7: 1111002 | C7: ชิฟฟอนรวมรส 8 ชิ้น | D7: 103 | E7: 31 | F7: 7 | G7: 11 | K7: 12 | L7: =SUM(D7:K7) -> 164
C8: ชิฟฟอนแบบกล่องสุ่มอะไรก็ได้ที่มี | L8: =SUM(D8:K8) -> 0
B9: 1111084 | C9: ชิฟฟอน 8 ชิ้น กาแฟล้วน | L9: =SUM(D9:K9) -> 0
B10: 1111085 | C10: ชิฟฟอน 8 ชิ้น บลูเบอรี่ล้วน | L10: =SUM(D10:K10) -> 0
B11: 1111086 | C11: ชิฟฟอน 8 ชิ้น มะพร้าวล้วน | L11: =SUM(D11:K11) -> 0
B12: 1111087 | C12: ชิฟฟอน 8 ชิ้น สตอเบอรี่ล้วน | L12: =SUM(D12:K12) -> 0
B13: 1111088 | C13: ชิฟฟอน 8 ชิ้น ส้มล้วน | L13: =SUM(D13:K13) -> 0
B14: 1111089 | C14: ชิฟฟอน 8 ชิ้น เนยล้วน | L14: =SUM(D14:K14) -> 0
B15: 1111090 | C15: ชิฟฟอน 8 ชิ้น เผือกล้วน | L15: =SUM(D15:K15) -> 0
B16: 1111091 | C16: ชิฟฟอน 8 ชิ้น ใบเตยล้วน | L16: =SUM(D16:K16) -> 0
B17: 1111092 | C17: ชิฟฟอน 8 ชิ้น กล้วยหอม | L17: =SUM(D17:K17) -> 0
B18: 1111093 | C18: ชิฟฟอน 8 ชิ้น โกโก้ล้วน | L18: =SUM(D18:K18) -> 0
B19: 1111094 | C19: ชิฟฟอน 8 ชิ้น ชาไทยล้วน | L19: =SUM(D19:K19) -> 0
B20: 1111095 | C20: ชิฟฟอน 8 ชิ้น ชาเขียวล้วน | L20: =SUM(D20:K20) -> 0
... B24: 1111043 | C24: ชิฟฟอน 8 ชิ้น มะลิ | L24: =SUM(D24:K24) -> 0
B25: 1111056 | C25: ชิฟฟอน 8 ชิ้น รวมรสยอดฮิต | E25: 12 | F25: 7 | G25: 3 | L25: =SUM(D25:K25) -> 22
B26: 1004055 | C26: ชิฟฟอนรวมรส 4 ชิ้น | D26: 19 | E26: 19 | G26: 1 | L26: =SUM(D26:K26) -> 39
B27: 1004055 | C27: ชิฟฟอน 4 ชิ้น โกโก้ล้วน | L27: =SUM(D27:K27) -> 0
B28: 1004055 | C28: ชิฟฟอน 4 ชิ้น มะพร้าวล้วน | L28: =SUM(D28:K28) -> 0
B29: 1004055 | C29: ชิฟฟอน 4 ชิ้น เนยล้วน | L29: =SUM(D29:K29) -> 0
B30: 1004055 | C30: ชิฟฟอน 4 ชิ้น กาแฟล้วน | L30: =SUM(D30:K30) -> 0
B31: 1004055 | C31: ชิฟฟอน 4 ชิ้น ใบเตยล้วน | L31: =SUM(D31:K31) -> 0
B32: 1004055 | C32: ชิฟฟอน 4 ชิ้น บลูเบอร์รี่ล้วน | L32: =SUM(D32:K32) -> 0
B33: 1004055 | C33: ชิฟฟอน 4 ชิ้น ส้มล้วน | L33: =SUM(D33:K33) -> 0
B34: 1004055 | C34: ชิฟฟอน 4 ชิ้น เผือกล้วน | L34: =SUM(D34:K34) -> 0
B35: 1004055 | C35: ชิฟฟอน 4 ชิ้น สตอเบอรี่ล้วน | L35: =SUM(D35:K35) -> 0
B36: 1004055 | C36: ชิฟฟอน 4 ชิ้น กล้วยหอมล้วน | L36: =SUM(D36:K36) -> 0
B37: 1004055 | C37: ชิฟฟอน 4 ชิ้น ชาเขียวล้วน | L37: =SUM(D37:K37) -> 0
B38: 1004055 | C38: ชิฟฟอน 4 ชิ้น ชาไทยล้วน | L38: =SUM(D38:K38) -> 0
... B66: 1111010 | C66: ชิฟฟอนไส้แยมแยกชิ้น คละรส | L66: =SUM(D66:K66) -> 0
C67: รวม
B68: ชิฟฟอนไส้แยม 6 ชิ้น
B69: 1111009 | C69: ชิฟฟอนไส้แยมรวมรส 6 ชิ้น | D69: 8 | E69: 14 | F69: 7 | G69: 13 | L69: =SUM(D69:K69) -> 42
B70: 1111023 | C70: ชิฟฟอนไส้แยมรสสตอเบอร์รี่ล้วน 6 ชิ้น | L70: =SUM(D70:K70) -> 0
B71: 1111016 | C71: ชิฟฟอนไส้แยมรสมะพร้าวล้วน 6 ชิ้น | L71: =SUM(D71:K71) -> 0
...

Sheet บ่าย
B1: ยอดจริง ออนไลน์ วันที่
L2: ยอดรวมผลิต
L3: จำนวน
B4: รหัสสินค้า | C4: สินค้า | D4: ปณ | E4: ชอปปี้ | F4: ลาซาด้า | G4: ติ๊กตอก | H4: ติ๊กตอก 2 | I4: ติ๊กตอก3 | J4: ชอยส์ | K4: ยอดเส้น | L4: (กล่อง)
B6: ชิฟฟอนรวมรส
B7: 1111002 | C7: ชิฟฟอนรวมรส 8 ชิ้น | L7: =SUM(D7:K7) -> 0
C8: ชิฟฟอนแบบกล่องสุ่มอะไรก็ได้ที่มี | L8: =SUM(D8:K8) -> 0
B9: 1111084 | C9: ชิฟฟอน 8 ชิ้น กาแฟล้วน | L9: =SUM(D9:K9) -> 0
B10: 1111085 | C10: ชิฟฟอน 8 ชิ้น บลูเบอรี่ล้วน | L10: =SUM(D10:K10) -> 0
B11: 1111086 | C11: ชิฟฟอน 8 ชิ้น มะพร้าวล้วน | L11: =SUM(D11:K11) -> 0
B12: 1111087 | C12: ชิฟฟอน 8 ชิ้น สตอเบอรี่ล้วน | L12: =SUM(D12:K12) -> 0
B13: 1111088 | C13: ชิฟฟอน 8 ชิ้น ส้มล้วน | L13: =SUM(D13:K13) -> 0
B14: 1111089 | C14: ชิฟฟอน 8 ชิ้น เนยล้วน | L14: =SUM(D14:K14) -> 0
B15: 1111090 | C15: ชิฟฟอน 8 ชิ้น เผือกล้วน | L15: =SUM(D15:K15) -> 0
B16: 1111091 | C16: ชิฟฟอน 8 ชิ้น ใบเตยล้วน | L16: =SUM(D16:K16) -> 0
B17: 1111092 | C17: ชิฟฟอน 8 ชิ้น กล้วยหอม | L17: =SUM(D17:K17) -> 0
B18: 1111093 | C18: ชิฟฟอน 8 ชิ้น โกโก้ล้วน | L18: =SUM(D18:K18) -> 0
B19: 1111094 | C19: ชิฟฟอน 8 ชิ้น ชาไทยล้วน | L19: =SUM(D19:K19) -> 0
B20: 1111095 | C20: ชิฟฟอน 8 ชิ้น ชาเขียวล้วน | L20: =SUM(D20:K20) -> 0
... B66: 1111010 | C66: ชิฟฟอนไส้แยมแยกชิ้น คละรส | L66: =SUM(D66:K66) -> 0
C67: รวม
B68: ชิฟฟอนไส้แยม 6 ชิ้น
B69: 1111009 | C69: ชิฟฟอนไส้แยมรวมรส 6 ชิ้น | L69: =SUM(D69:K69) -> 0
B70: 1111023 | C70: ชิฟฟอนไส้แยมรสสตอเบอร์รี่ล้วน 6 ชิ้น | L70: =SUM(D70:K70) -> 0
B71: 1111016 | C71: ชิฟฟอนไส้แยมรสมะพร้าวล้วน 6 ชิ้น | L71: =SUM(D71:K71) -> 0
B72: 1111014 | C72: ชิฟฟอนไส้แยมรสช็อกโกแลตนูเทลล่าล้วน 6 ชิ้น | L72: =SUM(D72:K72) -> 0
B73: 1111025 | C73: ชิฟฟอนไส้แยมรสส้มล้วน 6 ชิ้น | L73: =SUM(D73:K73) -> 0
B74: 1111018 | C74: ชิฟฟอนไส้แยมรสบลูเบอร์รี่ล้วน 6 ชิ้น | L74: =SUM(D74:K74) -> 0
B75: 1111012 | C75: ชิฟฟอนไส้แยมรสนมชมพูฮอกไกโดล้วน 6 ชิ้น | L75: =SUM(D75:K75) -> 0
B76: 1111020 | C76: ชิฟฟอนไส้แยมฝอยทองไส้ทะลัก 6 ชิ้น | L76: =SUM(D76:K76) -> 0
C77: รวม
B78: ชิฟฟอนไส้แยม 3 ชิ้น
B79: 1111022 | C79: ชิฟฟอนไส้แยมรสสตอเบอร์รี่ล้วน 3 ชิ้น | L79: =SUM(D79:K79) -> 0
B80: 1111015 | C80: ชิฟฟอนไส้แยมรสมะพร้าวล้วน 3 ชิ้น | L80: =SUM(D80:K80) -> 0
B81: 1111013 | C81: ชิฟฟอนไส้แยมรสช็อกโกแลตนูเทลล่าล้วน 3 ชิ้น | L81: =SUM(D81:K81) -> 0
B82: 1111024 | C82: ชิฟฟอนไส้แยมรสส้มล้วน 3 ชิ้น | L82: =SUM(D82:K82) -> 0
B83: 1111017 | C83: ชิฟฟอนไส้แยมรสบลูเบอร์รี่ล้วน 3 ชิ้น | L83: =SUM(D83:K83) -> 0
B84: 1111011 | C84: ชิฟฟอนไส้แยมรสนมชมพูฮอกไกโดล้วน 3 ชิ้น | L84: =SUM(D84:K84) -> 0
B85: 1111019 | C85: ชิฟฟอนไส้แยมฝอยทองไส้ทะลัก 3 ชิ้น | L85: =SUM(D85:K85) -> 0
B86: 1113081 | C86: ชิฟฟอนไส้แยม วนิลา/ใบเตย/เมล่อน | L86: =SUM(D86:K86) -> 0
...

Sheet รวม
B1: ยอดจริง ออนไลน์ วันที่ 7/2/68 รวม
L2: ยอดรวมผลิต | M2: ยอดฟอแคส | N2: ยอดสตอค | O2: ยอดเมโม่ | P2: ยอดฟอแคสวันพรุ่งนี้ | Q2: รวม
L3: จำนวน
B4: รหัสสินค้า | C4: สินค้า | D4: ปณ | E4: ชอปปี้ | F4: ลาซาด้า | G4: ติ๊กตอก | H4: ติ๊กตอก2 | I4: ติ๊กตอก3 | J4: ชอยส์ | K4: ยอดเส้น | L4: (กล่อง)
B6: ชิฟฟอนรวมรส
B7: 1111002 | C7: ชิฟฟอนรวมรส 8 ชิ้น | D7: ='เย็น '!D7+'เช้า '!D7+บ่าย!D7 -> 103 | E7: ='เย็น '!E7+'เช้า '!E7+บ่าย!E7 -> 31 | F7: ='เย็น '!F7+'เช้า '!F7+บ่าย!F7 -> 7 | G7: ='เย็น '!G7+'เช้า '!G7+บ่าย!G7 -> 11 | H7: ='เย็น '!H7+'เช้า '!H7+บ่าย!H7 -> 0 | I7: ='เย็น '!I7+'เช้า '!I7+บ่าย!I7 -> 0 | J7: ='เย็น '!J7+'เช้า '!J7+บ่าย!J7 -> 0 | K7: ='เย็น '!K7+'เช้า '!K7+บ่าย!K7 -> 12 | L7: =SUM(D7:K7) -> 164 | Q7: =(M7+N7+O7+P7)-L7 -> -164
C8: ชิฟฟอนแบบกล่องสุ่มอะไรก็ได้ที่มี | D8: ='เย็น '!D8+'เช้า '!D8+บ่าย!D8 -> 0 | E8: ='เย็น '!E8+'เช้า '!E8+บ่าย!E8 -> 0 | F8: ='เย็น '!F8+'เช้า '!F8+บ่าย!F8 -> 0 | G8: ='เย็น '!G8+'เช้า '!G8+บ่าย!G8 -> 0 | H8: ='เย็น '!H8+'เช้า '!H8+บ่าย!H8 -> 0 | I8: ='เย็น '!I8+'เช้า '!I8+บ่าย!I8 -> 0 | J8: ='เย็น '!J8+'เช้า '!J8+บ่าย!J8 -> 0 | K8: ='เย็น '!K8+'เช้า '!K8+บ่าย!K8 -> 0 | L8: =SUM(D8:K8) -> 0 | Q8: =(M8+N8+O8+P8)-L8 -> 0
B9: 1111084 | C9: ชิฟฟอน 8 ชิ้น กาแฟล้วน | D9: ='เย็น '!D9+'เช้า '!D9+บ่าย!D9 -> 0 | E9: ='เย็น '!E9+'เช้า '!E9+บ่าย!E9 -> 0 | F9: ='เย็น '!F9+'เช้า '!F9+บ่าย!F9 -> 0 | G9: ='เย็น '!G9+'เช้า '!G9+บ่าย!G9 -> 0 | H9: ='เย็น '!H9+'เช้า '!H9+บ่าย!H9 -> 0 | I9: ='เย็น '!I9+'เช้า '!I9+บ่าย!I9 -> 0 | J9: ='เย็น '!J9+'เช้า '!J9+บ่าย!J9 -> 0 | K9: ='เย็น '!K9+'เช้า '!K9+บ่าย!K9 -> 0 | L9: =SUM(D9:K9) -> 0 | Q9: =(M9+N9+O9+P9)-L9 -> 0
B10: 1111085 | C10: ชิฟฟอน 8 ชิ้น บลูเบอรี่ล้วน | D10: ='เย็น '!D10+'เช้า '!D10+บ่าย!D10 -> 0 | E10: ='เย็น '!E10+'เช้า '!E10+บ่าย!E10 -> 0 | F10: ='เย็น '!F10+'เช้า '!F10+บ่าย!F10 -> 0 | G10: ='เย็น '!G10+'เช้า '!G10+บ่าย!G10 -> 0 | H10: ='เย็น '!H10+'เช้า '!H10+บ่าย!H10 -> 0 | I10: ='เย็น '!I10+'เช้า '!I10+บ่าย!I10 -> 0 | J10: ='เย็น '!J10+'เช้า '!J10+บ่าย!J10 -> 0 | K10: ='เย็น '!K10+'เช้า '!K10+บ่าย!K10 -> 0 | L10: =SUM(D10:K10) -> 0 | Q10: =(M10+N10+O10+P10)-L10 -> 0
B11: 1111086 | C11: ชิฟฟอน 8 ชิ้น มะพร้าวล้วน | D11: ='เย็น '!D11+'เช้า '!D11+บ่าย!D11 -> 0 | E11: ='เย็น '!E11+'เช้า '!E11+บ่าย!E11 -> 0 | F11: ='เย็น '!F11+'เช้า '!F11+บ่าย!F11 -> 0 | G11: ='เย็น '!G11+'เช้า '!G11+บ่าย!G11 -> 0 | H11: ='เย็น '!H11+'เช้า '!H11+บ่าย!H11 -> 0 | I11: ='เย็น '!I11+'เช้า '!I11+บ่าย!I11 -> 0 | J11: ='เย็น '!J11+'เช้า '!J11+บ่าย!J11 -> 0 | K11: ='เย็น '!K11+'เช้า '!K11+บ่าย!K11 -> 0 | L11: =SUM(D11:K11) -> 0 | Q11: =(M11+N11+O11+P11)-L11 -> 0
B12: 1111087 | C12: ชิฟฟอน 8 ชิ้น สตอเบอรี่ล้วน | D12: ='เย็น '!D12+'เช้า '!D12+บ่าย!D12 -> 0 | E12: ='เย็น '!E12+'เช้า '!E12+บ่าย!E12 -> 0 | F12: ='เย็น '!F12+'เช้า '!F12+บ่าย!F12 -> 0 | G12: ='เย็น '!G12+'เช้า '!G12+บ่าย!G12 -> 0 | H12: ='เย็น '!H12+'เช้า '!H12+บ่าย!H12 -> 0 | I12: ='เย็น '!I12+'เช้า '!I12+บ่าย!I12 -> 0 | J12: ='เย็น '!J12+'เช้า '!J12+บ่าย!J12 -> 0 | K12: ='เย็น '!K12+'เช้า '!K12+บ่าย!K12 -> 0 | L12: =SUM(D12:K12) -> 0 | Q12: =(M12+N12+O12+P12)-L12 -> 0
B13: 1111088 | C13: ชิฟฟอน 8 ชิ้น ส้มล้วน | D13: ='เย็น '!D13+'เช้า '!D13+บ่าย!D13 -> 0 | E13: ='เย็น '!E13+'เช้า '!E13+บ่าย!E13 -> 0 | F13: ='เย็น '!F13+'เช้า '!F13+บ่าย!F13 -> 0 | G13: ='เย็น '!G13+'เช้า '!G13+บ่าย!G13 -> 0 | H13: ='เย็น '!H13+'เช้า '!H13+บ่าย!H13 -> 0 | I13: ='เย็น '!I13+'เช้า '!I13+บ่าย!I13 -> 0 | J13: ='เย็น '!J13+'เช้า '!J13+บ่าย!J13 -> 0 | K13: ='เย็น '!K13+'เช้า '!K13+บ่าย!K13 -> 0 | L13: =SUM(D13:K13) -> 0 | Q13: =(M13+N13+O13+P13)-L13 -> 0
B14: 1111089 | C14: ชิฟฟอน 8 ชิ้น เนยล้วน | D14: ='เย็น '!D14+'เช้า '!D14+บ่าย!D14 -> 0 | E14: ='เย็น '!E14+'เช้า '!E14+บ่าย!E14 -> 0 | F14: ='เย็น '!F14+'เช้า '!F14+บ่าย!F14 -> 0 | G14: ='เย็น '!G14+'เช้า '!G14+บ่าย!G14 -> 0 | H14: ='เย็น '!H14+'เช้า '!H14+บ่าย!H14 -> 0 | I14: ='เย็น '!I14+'เช้า '!I14+บ่าย!I14 -> 0 | J14: ='เย็น '!J14+'เช้า '!J14+บ่าย!J14 -> 0 | K14: ='เย็น '!K14+'เช้า '!K14+บ่าย!K14 -> 0 | L14: =SUM(D14:K14) -> 0 | Q14: =(M14+N14+O14+P14)-L14 -> 0
B15: 1111090 | C15: ชิฟฟอน 8 ชิ้น เผือกล้วน | D15: ='เย็น '!D15+'เช้า '!D15+บ่าย!D15 -> 0 | E15: ='เย็น '!E15+'เช้า '!E15+บ่าย!E15 -> 0 | F15: ='เย็น '!F15+'เช้า '!F15+บ่าย!F15 -> 0 | G15: ='เย็น '!G15+'เช้า '!G15+บ่าย!G15 -> 0 | H15: ='เย็น '!H15+'เช้า '!H15+บ่าย!H15 -> 0 | I15: ='เย็น '!I15+'เช้า '!I15+บ่าย!I15 -> 0 | J15: ='เย็น '!J15+'เช้า '!J15+บ่าย!J15 -> 0 | K15: ='เย็น '!K15+'เช้า '!K15+บ่าย!K15 -> 0 | L15: =SUM(D15:K15) -> 0 | Q15: =(M15+N15+O15+P15)-L15 -> 0
B16: 1111091 | C16: ชิฟฟอน 8 ชิ้น ใบเตยล้วน | D16: ='เย็น '!D16+'เช้า '!D16+บ่าย!D16 -> 0 | E16: ='เย็น '!E16+'เช้า '!E16+บ่าย!E16 -> 0 | F16: ='เย็น '!F16+'เช้า '!F16+บ่าย!F16 -> 0 | G16: ='เย็น '!G16+'เช้า '!G16+บ่าย!G16 -> 0 | H16: ='เย็น '!H16+'เช้า '!H16+บ่าย!H16 -> 0 | I16: ='เย็น '!I16+'เช้า '!I16+บ่าย!I16 -> 0 | J16: ='เย็น '!J16+'เช้า '!J16+บ่าย!J16 -> 0 | K16: ='เย็น '!K16+'เช้า '!K16+บ่าย!K16 -> 0 | L16: =SUM(D16:K16) -> 0 | Q16: =(M16+N16+O16+P16)-L16 -> 0
B17: 1111092 | C17: ชิฟฟอน 8 ชิ้น กล้วยหอม | D17: ='เย็น '!D17+'เช้า '!D17+บ่าย!D17 -> 0 | E17: ='เย็น '!E17+'เช้า '!E17+บ่าย!E17 -> 0 | F17: ='เย็น '!F17+'เช้า '!F17+บ่าย!F17 -> 0 | G17: ='เย็น '!G17+'เช้า '!G17+บ่าย!G17 -> 0 | H17: ='เย็น '!H17+'เช้า '!H17+บ่าย!H17 -> 0 | I17: ='เย็น '!I17+'เช้า '!I17+บ่าย!I17 -> 0 | J17: ='เย็น '!J17+'เช้า '!J17+บ่าย!J17 -> 0 | K17: ='เย็น '!K17+'เช้า '!K17+บ่าย!K17 -> 0 | L17: =SUM(D17:K17) -> 0 | Q17: =(M17+N17+O17+P17)-L17 -> 0
B18: 1111093 | C18: ชิฟฟอน 8 ชิ้น โกโก้ล้วน | D18: ='เย็น '!D18+'เช้า '!D18+บ่าย!D18 -> 0 | E18: ='เย็น '!E18+'เช้า '!E18+บ่าย!E18 -> 0 | F18: ='เย็น '!F18+'เช้า '!F18+บ่าย!F18 -> 0 | G18: ='เย็น '!G18+'เช้า '!G18+บ่าย!G18 -> 0 | H18: ='เย็น '!H18+'เช้า '!H18+บ่าย!H18 -> 0 | I18: ='เย็น '!I18+'เช้า '!I18+บ่าย!I18 -> 0 | J18: ='เย็น '!J18+'เช้า '!J18+บ่าย!J18 -> 0 | K18: ='เย็น '!K18+'เช้า '!K18+บ่าย!K18 -> 0 | L18: =SUM(D18:K18) -> 0 | Q18: =(M18+N18+O18+P18)-L18 -> 0
B19: 1111094 | C19: ชิฟฟอน 8 ชิ้น ชาไทยล้วน | D19: ='เย็น '!D19+'เช้า '!D19+บ่าย!D19 -> 0 | E19: ='เย็น '!E19+'เช้า '!E19+บ่าย!E19 -> 0 | F19: ='เย็น '!F19+'เช้า '!F19+บ่าย!F19 -> 0 | G19: ='เย็น '!G19+'เช้า '!G19+บ่าย!G19 -> 0 | H19: ='เย็น '!H19+'เช้า '!H19+บ่าย!H19 -> 0 | I19: ='เย็น '!I19+'เช้า '!I19+บ่าย!I19 -> 0 | J19: ='เย็น '!J19+'เช้า '!J19+บ่าย!J19 -> 0 | K19: ='เย็น '!K19+'เช้า '!K19+บ่าย!K19 -> 0 | L19: =SUM(D19:K19) -> 0 | Q19: =(M19+N19+O19+P19)-L19 -> 0
B20: 1111095 | C20: ชิฟฟอน 8 ชิ้น ชาเขียวล้วน | D20: ='เย็น '!D20+'เช้า '!D20+บ่าย!D20 -> 0 | E20: ='เย็น '!E20+'เช้า '!E20+บ่าย!E20 -> 0 | F20: ='เย็น '!F20+'เช้า '!F20+บ่าย!F20 -> 0 | G20: ='เย็น '!G20+'เช้า '!G20+บ่าย!G20 -> 0 | H20: ='เย็น '!H20+'เช้า '!H20+บ่าย!H20 -> 0 | I20: ='เย็น '!I20+'เช้า '!I20+บ่าย!I20 -> 0 | J20: ='เย็น '!J20+'เช้า '!J20+บ่าย!J20 -> 0 | K20: ='เย็น '!K20+'เช้า '!K20+บ่าย!K20 -> 0 | L20: =SUM(D20:K20) -> 0 | Q20: =(M20+N20+O20+P20)-L20 -> 0
... B65: 1111083 | C65: ชิฟฟอนไส้แยมแยกชิ้น เมล่อน | D65: ='เย็น '!D65+'เช้า '!D65+บ่าย!D65 -> 0 | E65: ='เย็น '!E65+'เช้า '!E65+บ่าย!E65 -> 0 | F65: ='เย็น '!F65+'เช้า '!F65+บ่าย!F65 -> 0 | G65: ='เย็น '!G65+'เช้า '!G65+บ่าย!G65 -> 0 | H65: ='เย็น '!H65+'เช้า '!H65+บ่าย!H65 -> 0 | I65: ='เย็น '!I65+'เช้า '!I65+บ่าย!I65 -> 0 | J65: ='เย็น '!J65+'เช้า '!J65+บ่าย!J65 -> 0 | K65: ='เย็น '!K65+'เช้า '!K65+บ่าย!K65 -> 0 | L65: =SUM(D65:K65) -> 0 | Q65: =(M65+N65+O65+P65)-L65 -> 0
B66: 1111010 | C66: ชิฟฟอนไส้แยมแยกชิ้น คละรส | D66: =บ่าย!D66+'เช้า '!D66+'เย็น '!D66 -> 0 | E66: =บ่าย!E66+'เช้า '!E66+'เย็น '!E66 -> 0 | F66: =บ่าย!F66+'เช้า '!F66+'เย็น '!F66 -> 0 | G66: =บ่าย!G66+'เช้า '!G66+'เย็น '!G66 -> 0 | H66: =บ่าย!H66+'เช้า '!H66+'เย็น '!H66 -> 0 | I66: =บ่าย!I66+'เช้า '!I66+'เย็น '!I66 -> 0 | J66: =บ่าย!J66+'เช้า '!J66+'เย็น '!J66 -> 0 | L66: =SUM(D66:K66) -> 0 | Q66: =(M66+N66+O66+P66)-L66 -> 0
C67: รวม | L67: =SUM(D67:J67) -> 0 | Q67: =(M67+N67+O67+P67)-L67 -> 0
B68: ชิฟฟอนไส้แยม 6 ชิ้น
B69: 1111009 | C69: ชิฟฟอนไส้แยมรวมรส 6 ชิ้น | D69: ='เย็น '!D69+'เช้า '!D69+บ่าย!D69 -> 8 | E69: ='เย็น '!E69+'เช้า '!E69+บ่าย!E69 -> 14 | F69: ='เย็น '!F69+'เช้า '!F69+บ่าย!F69 -> 7 | G69: ='เย็น '!G69+'เช้า '!G69+บ่าย!G69 -> 13 | H69: ='เย็น '!H69+'เช้า '!H69+บ่าย!H69 -> 0 | I69: ='เย็น '!I69+'เช้า '!I69+บ่าย!I69 -> 0 | J69: ='เย็น '!J69+'เช้า '!J69+บ่าย!J69 -> 0 | K69: ='เย็น '!K69+'เช้า '!K69+บ่าย!K69 -> 0 | L69: =SUM(D69:K69) -> 42 | Q69: =(M69+N69+O69+P69)-L69 -> -42
B70: 1111023 | C70: ชิฟฟอนไส้แยมรสสตอเบอร์รี่ล้วน 6 ชิ้น | D70: ='เย็น '!D70+'เช้า '!D70+บ่าย!D70 -> 0 | E70: ='เย็น '!E70+'เช้า '!E70+บ่าย!E70 -> 0 | F70: ='เย็น '!F70+'เช้า '!F70+บ่าย!F70 -> 0 | G70: ='เย็น '!G70+'เช้า '!G70+บ่าย!G70 -> 0 | H70: ='เย็น '!H70+'เช้า '!H70+บ่าย!H70 -> 0 | I70: ='เย็น '!I70+'เช้า '!I70+บ่าย!I70 -> 0 | J70: ='เย็น '!J70+'เช้า '!J70+บ่าย!J70 -> 0 | K70: ='เย็น '!K70+'เช้า '!K70+บ่าย!K70 -> 0 | L70: =SUM(D70:K70) -> 0 | Q70: =(M70+N70+O70+P70)-L70 -> 0
B71: 1111016 | C71: ชิฟฟอนไส้แยมรสมะพร้าวล้วน 6 ชิ้น | D71: ='เย็น '!D71+'เช้า '!D71+บ่าย!D71 -> 0 | E71: ='เย็น '!E71+'เช้า '!E71+บ่าย!E71 -> 0 | F71: ='เย็น '!F71+'เช้า '!F71+บ่าย!F71 -> 0 | G71: ='เย็น '!G71+'เช้า '!G71+บ่าย!G71 -> 0 | H71: ='เย็น '!H71+'เช้า '!H71+บ่าย!H71 -> 0 | I71: ='เย็น '!I71+'เช้า '!I71+บ่าย!I71 -> 0 | J71: ='เย็น '!J71+'เช้า '!J71+บ่าย!J71 -> 0 | K71: ='เย็น '!K71+'เช้า '!K71+บ่าย!K71 -> 0 | L71: =SUM(D71:K71) -> 0 | Q71: =(M71+N71+O71+P71)-L71 -> 0
B72: 1111014 | C72: ชิฟฟอนไส้แยมรสช็อกโกแลตนูเทลล่าล้วน 6 ชิ้น | D72: ='เย็น '!D72+'เช้า '!D72+บ่าย!D72 -> 0 | E72: ='เย็น '!E72+'เช้า '!E72+บ่าย!E72 -> 0 | F72: ='เย็น '!F72+'เช้า '!F72+บ่าย!F72 -> 0 | G72: ='เย็น '!G72+'เช้า '!G72+บ่าย!G72 -> 0 | H72: ='เย็น '!H72+'เช้า '!H72+บ่าย!H72 -> 0 | I72: ='เย็น '!I72+'เช้า '!I72+บ่าย!I72 -> 0 | J72: ='เย็น '!J72+'เช้า '!J72+บ่าย!J72 -> 0 | K72: ='เย็น '!K72+'เช้า '!K72+บ่าย!K72 -> 0 | L72: =SUM(D72:K72) -> 0 | Q72: =(M72+N72+O72+P72)-L72 -> 0
B73: 1111025 | C73: ชิฟฟอนไส้แยมรสส้มล้วน 6 ชิ้น | D73: ='เย็น '!D73+'เช้า '!D73+บ่าย!D73 -> 0 | E73: ='เย็น '!E73+'เช้า '!E73+บ่าย!E73 -> 0 | F73: ='เย็น '!F73+'เช้า '!F73+บ่าย!F73 -> 0 | G73: ='เย็น '!G73+'เช้า '!G73+บ่าย!G73 -> 0 | H73: ='เย็น '!H73+'เช้า '!H73+บ่าย!H73 -> 0 | I73: ='เย็น '!I73+'เช้า '!I73+บ่าย!I73 -> 0 | J73: ='เย็น '!J73+'เช้า '!J73+บ่าย!J73 -> 0 | K73: ='เย็น '!K73+'เช้า '!K73+บ่าย!K73 -> 0 | L73: =SUM(D73:K73) -> 0 | Q73: =(M73+N73+O73+P73)-L73 -> 0
B74: 1111018 | C74: ชิฟฟอนไส้แยมรสบลูเบอร์รี่ล้วน 6 ชิ้น | D74: ='เย็น '!D74+'เช้า '!D74+บ่าย!D74 -> 0 | E74: ='เย็น '!E74+'เช้า '!E74+บ่าย!E74 -> 0 | F74: ='เย็น '!F74+'เช้า '!F74+บ่าย!F74 -> 0 | G74: ='เย็น '!G74+'เช้า '!G74+บ่าย!G74 -> 0 | H74: ='เย็น '!H74+'เช้า '!H74+บ่าย!H74 -> 0 | I74: ='เย็น '!I74+'เช้า '!I74+บ่าย!I74 -> 0 | J74: ='เย็น '!J74+'เช้า '!J74+บ่าย!J74 -> 0 | K74: ='เย็น '!K74+'เช้า '!K74+บ่าย!K74 -> 0 | L74: =SUM(D74:K74) -> 0 | Q74: =(M74+N74+O74+P74)-L74 -> 0
B75: 1111012 | C75: ชิฟฟอนไส้แยมรสนมชมพูฮอกไกโดล้วน 6 ชิ้น | D75: ='เย็น '!D75+'เช้า '!D75+บ่าย!D75 -> 0 | E75: ='เย็น '!E75+'เช้า '!E75+บ่าย!E75 -> 0 | F75: ='เย็น '!F75+'เช้า '!F75+บ่าย!F75 -> 0 | G75: ='เย็น '!G75+'เช้า '!G75+บ่าย!G75 -> 0 | H75: ='เย็น '!H75+'เช้า '!H75+บ่าย!H75 -> 0 | I75: ='เย็น '!I75+'เช้า '!I75+บ่าย!I75 -> 0 | J75: ='เย็น '!J75+'เช้า '!J75+บ่าย!J75 -> 0 | K75: ='เย็น '!K75+'เช้า '!K75+บ่าย!K75 -> 0 | L75: =SUM(D75:K75) -> 0 | Q75: =(M75+N75+O75+P75)-L75 -> 0
B76: 1111020 | C76: ชิฟฟอนไส้แยมฝอยทองไส้ทะลัก 6 ชิ้น | D76: ='เย็น '!D76+'เช้า '!D76+บ่าย!D76 -> 0 | E76: ='เย็น '!E76+'เช้า '!E76+บ่าย!E76 -> 0 | F76: ='เย็น '!F76+'เช้า '!F76+บ่าย!F76 -> 0 | G76: ='เย็น '!G76+'เช้า '!G76+บ่าย!G76 -> 0 | H76: ='เย็น '!H76+'เช้า '!H76+บ่าย!H76 -> 0 | I76: ='เย็น '!I76+'เช้า '!I76+บ่าย!I76 -> 0 | J76: ='เย็น '!J76+'เช้า '!J76+บ่าย!J76 -> 0 | K76: ='เย็น '!K76+'เช้า '!K76+บ่าย!K76 -> 0 | L76: =SUM(D76:K76) -> 0 | Q76: =(M76+N76+O76+P76)-L76 -> 0
C77: รวม | Q77: =(M77+N77+O77+P77)-L77 -> 0
B78: ชิฟฟอนไส้แยม 3 ชิ้น
B79: 1111022 | C79: ชิฟฟอนไส้แยมรสสตอเบอร์รี่ล้วน 3 ชิ้น | D79: ='เย็น '!D79+'เช้า '!D79+บ่าย!D79 -> 0 | E79: ='เย็น '!E79+'เช้า '!E79+บ่าย!E79 -> 0 | F79: ='เย็น '!F79+'เช้า '!F79+บ่าย!F79 -> 0 | G79: ='เย็น '!G79+'เช้า '!G79+บ่าย!G79 -> 0 | H79: ='เย็น '!H79+'เช้า '!H79+บ่าย!H79 -> 0 | I79: ='เย็น '!I79+'เช้า '!I79+บ่าย!I79 -> 0 | J79: ='เย็น '!J79+'เช้า '!J79+บ่าย!J79 -> 0 | K79: ='เย็น '!K79+'เช้า '!K79+บ่าย!K79 -> 0 | L79: =SUM(D79:K79) -> 0 | Q79: =(M79+N79+O79+P79)-L79 -> 0
B80: 1111015 | C80: ชิฟฟอนไส้แยมรสมะพร้าวล้วน 3 ชิ้น | D80: ='เย็น '!D80+'เช้า '!D80+บ่าย!D80 -> 0 | E80: ='เย็น '!E80+'เช้า '!E80+บ่าย!E80 -> 0 | F80: ='เย็น '!F80+'เช้า '!F80+บ่าย!F80 -> 0 | G80: ='เย็น '!G80+'เช้า '!G80+บ่าย!G80 -> 0 | H80: ='เย็น '!H80+'เช้า '!H80+บ่าย!H80 -> 0 | I80: ='เย็น '!I80+'เช้า '!I80+บ่าย!I80 -> 0 | J80: ='เย็น '!J80+'เช้า '!J80+บ่าย!J80 -> 0 | K80: ='เย็น '!K80+'เช้า '!K80+บ่าย!K80 -> 0 | L80: =SUM(D80:K80) -> 0 | Q80: =(M80+N80+O80+P80)-L80 -> 0
B81: 1111013 | C81: ชิฟฟอนไส้แยมรสช็อกโกแลตนูเทลล่าล้วน 3 ชิ้น | D81: ='เย็น '!D81+'เช้า '!D81+บ่าย!D81 -> 0 | E81: ='เย็น '!E81+'เช้า '!E81+บ่าย!E81 -> 0 | F81: ='เย็น '!F81+'เช้า '!F81+บ่าย!F81 -> 0 | G81: ='เย็น '!G81+'เช้า '!G81+บ่าย!G81 -> 0 | H81: ='เย็น '!H81+'เช้า '!H81+บ่าย!H81 -> 0 | I81: ='เย็น '!I81+'เช้า '!I81+บ่าย!I81 -> 0 | J81: ='เย็น '!J81+'เช้า '!J81+บ่าย!J81 -> 0 | K81: ='เย็น '!K81+'เช้า '!K81+บ่าย!K81 -> 0 | L81: =SUM(D81:K81) -> 0 | Q81: =(M81+N81+O81+P81)-L81 -> 0
B82: 1111024 | C82: ชิฟฟอนไส้แยมรสส้มล้วน 3 ชิ้น | D82: ='เย็น '!D82+'เช้า '!D82+บ่าย!D82 -> 0 | E82: ='เย็น '!E82+'เช้า '!E82+บ่าย!E82 -> 0 | F82: ='เย็น '!F82+'เช้า '!F82+บ่าย!F82 -> 0 | G82: ='เย็น '!G82+'เช้า '!G82+บ่าย!G82 -> 0 | H82: ='เย็น '!H82+'เช้า '!H82+บ่าย!H82 -> 0 | I82: ='เย็น '!I82+'เช้า '!I82+บ่าย!I82 -> 0 | J82: ='เย็น '!J82+'เช้า '!J82+บ่าย!J82 -> 0 | K82: ='เย็น '!K82+'เช้า '!K82+บ่าย!K82 -> 0 | L82: =SUM(D82:K82) -> 0 | Q82: =(M82+N82+O82+P82)-L82 -> 0
B83: 1111017 | C83: ชิฟฟอนไส้แยมรสบลูเบอร์รี่ล้วน 3 ชิ้น | D83: ='เย็น '!D83+'เช้า '!D83+บ่าย!D83 -> 0 | E83: ='เย็น '!E83+'เช้า '!E83+บ่าย!E83 -> 0 | F83: ='เย็น '!F83+'เช้า '!F83+บ่าย!F83 -> 0 | G83: ='เย็น '!G83+'เช้า '!G83+บ่าย!G83 -> 0 | H83: ='เย็น '!H83+'เช้า '!H83+บ่าย!H83 -> 0 | I83: ='เย็น '!I83+'เช้า '!I83+บ่าย!I83 -> 0 | J83: ='เย็น '!J83+'เช้า '!J83+บ่าย!J83 -> 0 | K83: ='เย็น '!K83+'เช้า '!K83+บ่าย!K83 -> 0 | L83: =SUM(D83:K83) -> 0 | Q83: =(M83+N83+O83+P83)-L83 -> 0
B84: 1111011 | C84: ชิฟฟอนไส้แยมรสนมชมพูฮอกไกโดล้วน 3 ชิ้น | D84: ='เย็น '!D84+'เช้า '!D84+บ่าย!D84 -> 0 | E84: ='เย็น '!E84+'เช้า '!E84+บ่าย!E84 -> 0 | F84: ='เย็น '!F84+'เช้า '!F84+บ่าย!F84 -> 0 | G84: ='เย็น '!G84+'เช้า '!G84+บ่าย!G84 -> 0 | H84: ='เย็น '!H84+'เช้า '!H84+บ่าย!H84 -> 0 | I84: ='เย็น '!I84+'เช้า '!I84+บ่าย!I84 -> 0 | J84: ='เย็น '!J84+'เช้า '!J84+บ่าย!J84 -> 0 | K84: ='เย็น '!K84+'เช้า '!K84+บ่าย!K84 -> 0 | L84: =SUM(D84:K84) -> 0 | Q84: =(M84+N84+O84+P84)-L84 -> 0
B85: 1111019 | C85: ชิฟฟอนไส้แยมฝอยทองไส้ทะลัก 3 ชิ้น | D85: ='เย็น '!D85+'เช้า '!D85+บ่าย!D85 -> 0 | E85: ='เย็น '!E85+'เช้า '!E85+บ่าย!E85 -> 0 | F85: ='เย็น '!F85+'เช้า '!F85+บ่าย!F85 -> 0 | G85: ='เย็น '!G85+'เช้า '!G85+บ่าย!G85 -> 0 | H85: ='เย็น '!H85+'เช้า '!H85+บ่าย!H85 -> 0 | I85: ='เย็น '!I85+'เช้า '!I85+บ่าย!I85 -> 0 | J85: ='เย็น '!J85+'เช้า '!J85+บ่าย!J85 -> 0 | K85: ='เย็น '!K85+'เช้า '!K85+บ่าย!K85 -> 0 | L85: =SUM(D85:K85) -> 0 | Q85: =(M85+N85+O85+P85)-L85 -> 0
...
