Workbook

Sheet เย็น
B1: ยอดจริง ออนไลน์ วันที่ 12/11/2567 - เย็น
K2: ยอดรวมผลิต
K3: จำนวน
B4: รหัสสินค้า | C4: สินค้า | D4: ปณ | E4: ชอปปี้ | F4: ลาซาด้า | G4: ติ๊กตอก | H4: ติ๊กตอก2 | I4: ติ๊กตอก3 | J4: ชอยส์ | K4: (กล่อง)
B6: ชิฟฟอนรวมรส
B7: 1111002 | C7: ชิฟฟอนรวมรส 8 ชิ้น | E7: 9 | F7: 62 | G7: 1 | H7: 3 | K7: =SUM(D7:J7) -> 75
B8: 1111043 | C8: ชิฟฟอน 8 ชิ้น มะลิ | K8: =SUM(D8:J8) -> 0
B9: 1111056 | C9: ชิฟฟอน 8 ชิ้น รวมรสยอดฮิต | E9: 1 | F9: 8 | G9: 1 | K9: =SUM(D9:J9) -> 10
B10: 1004055 | C10: ชิฟฟอนรวมรส 4 ชิ้น | F10: 1 | G10: 21 | H10: 60 | K10: =SUM(D10:J10) -> 82
B11: 1111057 | C11: ชิฟฟอนแยกชิ้น กาแฟ | K11: =SUM(D11:J11) -> 0
B12: 1111058 | C12: ชิฟฟอนแยกชิ้น ชาเขียว | K12: =SUM(D12:J12) -> 0
B13: 1111059 | C13: ชิฟฟอนแยกชิ้น ใบเตย | K13: =SUM(D13:J13) -> 0
B14: 1111060 | C14: ชิฟฟอนแยกชิ้น กล้วยหอม | K14: =SUM(D14:J14) -> 0
B15: 1111061 | C15: ชิฟฟอนแยกชิ้น ชาไทย | K15: =SUM(D15:J15) -> 0
B16: 1111062 | C16: ชิฟฟอนแยกชิ้น โกโก้ | K16: =SUM(D16:J16) -> 0
B17: 1111063 | C17: ชิฟฟอนแยกชิ้น ส้ม | K17: =SUM(D17:J17) -> 0
B18: 1111064 | C18: ชิฟฟอนแยกชิ้น เผือก | K18: =SUM(D18:J18) -> 0
B19: 1111065 | C19: ชิฟฟอนแยกชิ้น สับปะรด | K19: =SUM(D19:J19) -> 0
B20: 1111066 | C20: ชิฟฟอนแยกชิ้น สตอเบอรี่ | K20: =SUM(D20:J20) -> 0
B21: 1111067 | C21: ชิฟฟอนแยกชิ้น มะพร้าว | K21: =SUM(D21:J21) -> 0
B22: 1111068 | C22: ชิฟฟอนแยกชิ้น เนย | K22: =SUM(D22:J22) -> 0
... B37: 1111010 | C37: ชิฟฟอนไส้แยมแยกชิ้น คละรส | K37: =SUM(D37:J37) -> 0
C38: รวม | K38: =SUM(D38:I38) -> 0
B39: ชิฟฟอนไส้แยม 6 ชิ้น
B40: 1111009 | C40: ชิฟฟอนไส้แยมรวมรส 6 ชิ้น | E40: 1 | F40: 5 | G40: 1 | K40: =SUM(D40:J40) -> 7
B41: ชิฟฟอนไส้แยม 3 ชิ้น
B42: 1111008 | C42: ชิฟฟอนไส้แยมรวมรส 3 ชิ้น | E42: 6 | G42: 66 | H42: 12 | K42: =SUM(D42:J42) -> 84
B43: เบาหวิว ล 110 กรัม
B44: 1112009 | C44: มะพร้าว | E44: 17 | F44: 7 | G44: 9 | K44: =SUM(D44:J44) -> 33
B45: 1112011 | C45: ฝอยทอง | E45: 17 | F45: 18 | G45: 9 | K45: =SUM(D45:J45) -> 44
B46: 1112003 | C46: กาแฟ | G46: 3 | K46: =SUM(D46:J46) -> 3
B47: 1112005 | C47: เนยนม | K47: =SUM(D47:J47) -> 0
B48: 1112007 | C48: ใบเตย | K48: =SUM(D48:J48) -> 0
B49: 1112019 | C49: ทุเรียน | K49: =SUM(D49:J49) -> 0
B50: 1112017 | C50: ตาลหอม | G50: 3 | K50: =SUM(D50:J50) -> 3
B51: 1112015 | C51: กล้วยหอมมะพร้าวเผา | G51: 3 | K51: =SUM(D51:J51) -> 3
B52: 1112013 | C52: เผือกมะพร้าวอ่อน | E52: 16 | F52: 10 | G52: 9 | K52: =SUM(D52:J52) -> 35
B53: 1124043 | C53: เบาหวิว คละรส | K53: =SUM(D53:J53) -> 0
C54: รวม
B55: อื่นๆ
...

Sheet เช้า
B1: ยอดจริง ออนไลน์ วันที่ 12/11/2567 - เช้า
K2: ยอดรวมผลิต
K3: จำนวน
B4: รหัสสินค้า | C4: สินค้า | D4: ปณ | E4: ชอปปี้ | F4: ลาซาด้า | G4: ติ๊กตอก | H4: ติ๊กตอก2 | I4: ติ๊กตอก3 | J4: ชอยส์ | K4: (กล่อง)
B6: ชิฟฟอนรวมรส
B7: 1111002 | C7: ชิฟฟอนรวมรส 8 ชิ้น | E7: 25 | F7: 111 | G7: 2 | J7: 1 | K7: =SUM(D7:J7) -> 139
B8: 1111043 | C8: ชิฟฟอน 8 ชิ้น มะลิ | K8: =SUM(D8:J8) -> 0
B9: 1111056 | C9: ชิฟฟอน 8 ชิ้น รวมรสยอดฮิต | F9: 20 | G9: 3 | K9: =SUM(D9:J9) -> 23
B10: 1004055 | C10: ชิฟฟอนรวมรส 4 ชิ้น | E10: 4 | G10: 50 | K10: =SUM(D10:J10) -> 54
B11: 1111057 | C11: ชิฟฟอนแยกชิ้น กาแฟ | D11: 11 | E11: 6 | F11: 1 | G11: 1 | K11: =SUM(D11:J11) -> 19
B12: 1111058 | C12: ชิฟฟอนแยกชิ้น ชาเขียว | D12: 11 | E12: 3 | G12: 1 | K12: =SUM(D12:J12) -> 15
B13: 1111059 | C13: ชิฟฟอนแยกชิ้น ใบเตย | D13: 11 | E13: 3 | G13: 1 | K13: =SUM(D13:J13) -> 15
B14: 1111060 | C14: ชิฟฟอนแยกชิ้น กล้วยหอม | D14: 11 | G14: 1 | K14: =SUM(D14:J14) -> 12
B15: 1111061 | C15: ชิฟฟอนแยกชิ้น ชาไทย | D15: 11 | E15: 3 | G15: 1 | K15: =SUM(D15:J15) -> 15
B16: 1111062 | C16: ชิฟฟอนแยกชิ้น โกโก้ | D16: 11 | E16: 3 | G16: 1 | K16: =SUM(D16:J16) -> 15
B17: 1111063 | C17: ชิฟฟอนแยกชิ้น ส้ม | D17: 11 | E17: 3 | G17: 1 | K17: =SUM(D17:J17) -> 15
B18: 1111064 | C18: ชิฟฟอนแยกชิ้น เผือก | D18: 11 | E18: 3 | K18: =SUM(D18:J18) -> 14
B19: 1111065 | C19: ชิฟฟอนแยกชิ้น สับปะรด | D19: 11 | K19: =SUM(D19:J19) -> 11
B20: 1111066 | C20: ชิฟฟอนแยกชิ้น สตอเบอรี่ | D20: 11 | E20: 3 | K20: =SUM(D20:J20) -> 14
B21: 1111067 | C21: ชิฟฟอนแยกชิ้น มะพร้าว | E21: 7 | K21: =SUM(D21:J21) -> 7
B22: 1111068 | C22: ชิฟฟอนแยกชิ้น เนย | E22: 3 | K22: =SUM(D22:J22) -> 3
B23: 1111069 | C23: ชิฟฟอนแยกชิ้น บลูเบอรี่ | E23: 3 | K23: =SUM(D23:J23) -> 3
B24: 1111070 | C24: ชิฟฟอนแยกชิ้น ทุเรียน | K24: =SUM(D24:J24) -> 0
B25: 1111071 | C25: ชิฟฟอนแยกชิ้น ตาล | K25: =SUM(D25:J25) -> 0
B26: 1111001 | C26: ชิฟฟอนแยกชิ้น คละรส | K26: =SUM(D26:J26) -> 0
B27: 1111074 | C27: ชิฟฟอนไส้แยมแยกชิ้น มะพร้าว | F27: 10 | G27: 11 | K27: =SUM(D27:J27) -> 21
B28: 1111075 | C28: ชิฟฟอนไส้แยมแยกชิ้น สตอเบอรี่ | F28: 10 | G28: 11 | K28: =SUM(D28:J28) -> 21
B29: 1111076 | C29: ชิฟฟอนไส้แยมแยกชิ้น ส้ม | F29: 10 | G29: 11 | K29: =SUM(D29:J29) -> 21
B30: 1111077 | C30: ชิฟฟอนไส้แยมแยกชิ้น บลูเบอรี่ | F30: 10 | G30: 11 | K30: =SUM(D30:J30) -> 21
B31: 1111078 | C31: ชิฟฟอนไส้แยมแยกชิ้น นมชมพู | F31: 10 | G31: 11 | K31: =SUM(D31:J31) -> 21
B32: 1111079 | C32: ชิฟฟอนไส้แยมแยกชิ้น ชอคโกแลต | F32: 10 | G32: 11 | K32: =SUM(D32:J32) -> 21
B33: 1111080 | C33: ชิฟฟอนไส้แยมแยกชิ้น ฝอยทอง | F33: 10 | G33: 1 | K33: =SUM(D33:J33) -> 11
B34: 1111081 | C34: ชิฟฟอนไส้แยมแยกชิ้น วนิลา | F34: 10 | G34: 1 | K34: =SUM(D34:J34) -> 11
B35: 1111082 | C35: ชิฟฟอนไส้แยมแยกชิ้น ใบเตย | F35: 10 | G35: 1 | K35: =SUM(D35:J35) -> 11
B36: 1111083 | C36: ชิฟฟอนไส้แยมแยกชิ้น เมล่อน | F36: 10 | G36: 1 | K36: =SUM(D36:J36) -> 11
B37: 1111010 | C37: ชิฟฟอนไส้แยมแยกชิ้น คละรส | K37: =SUM(D37:J37) -> 0
C38: รวม | K38: =SUM(D38:I38) -> 0
B39: ชิฟฟอนไส้แยม 6 ชิ้น
B40: 1111009 | C40: ชิฟฟอนไส้แยมรวมรส 6 ชิ้น | F40: 6 | G40: 1 | K40: =SUM(D40:J40) -> 7
B41: ชิฟฟอนไส้แยม 3 ชิ้น
...

Sheet บ่าย
B1: ยอดจริง ออนไลน์ วันที่ 10/11/2567 - บ่าย
K2: ยอดรวมผลิต
K3: จำนวน
B4: รหัสสินค้า | C4: สินค้า | D4: ปณ | E4: ชอปปี้ | F4: ลาซาด้า | G4: ติ๊กตอก | H4: ติ๊กตอก2 | I4: ติ๊กตอก3 | J4: ชอยส์ | K4: (กล่อง)
B6: ชิฟฟอนรวมรส
B7: 1111002 | C7: ชิฟฟอนรวมรส 8 ชิ้น | K7: =SUM(D7:J7) -> 0
B8: 1111043 | C8: ชิฟฟอน 8 ชิ้น มะลิ | K8: =SUM(D8:J8) -> 0
B9: 1111056 | C9: ชิฟฟอน 8 ชิ้น รวมรสยอดฮิต | K9: =SUM(D9:J9) -> 0
B10: 1004055 | C10: ชิฟฟอนรวมรส 4 ชิ้น | K10: =SUM(D10:J10) -> 0
B11: 1111057 | C11: ชิฟฟอนแยกชิ้น กาแฟ | K11: =SUM(D11:J11) -> 0
B12: 1111058 | C12: ชิฟฟอนแยกชิ้น ชาเขียว | K12: =SUM(D12:J12) -> 0
B13: 1111059 | C13: ชิฟฟอนแยกชิ้น ใบเตย | K13: =SUM(D13:J13) -> 0
B14: 1111060 | C14: ชิฟฟอนแยกชิ้น กล้วยหอม | K14: =SUM(D14:J14) -> 0
B15: 1111061 | C15: ชิฟฟอนแยกชิ้น ชาไทย | K15: =SUM(D15:J15) -> 0
B16: 1111062 | C16: ชิฟฟอนแยกชิ้น โกโก้ | K16: =SUM(D16:J16) -> 0
B17: 1111063 | C17: ชิฟฟอนแยกชิ้น ส้ม | K17: =SUM(D17:J17) -> 0
B18: 1111064 | C18: ชิฟฟอนแยกชิ้น เผือก | K18: =SUM(D18:J18) -> 0
... B37: 1111010 | C37: ชิฟฟอนไส้แยมแยกชิ้น คละรส | K37: =SUM(D37:J37) -> 0
C38: รวม | K38: =SUM(D38:I38) -> 0
B39: ชิฟฟอนไส้แยม 6 ชิ้น
B40: 1111009 | C40: ชิฟฟอนไส้แยมรวมรส 6 ชิ้น | K40: =SUM(D40:J40) -> 0
B41: ชิฟฟอนไส้แยม 3 ชิ้น
B42: 1111008 | C42: ชิฟฟอนไส้แยมรวมรส 3 ชิ้น | K42: =SUM(D42:J42) -> 0
B43: เบาหวิว ล 110 กรัม
B44: 1112009 | C44: มะพร้าว | K44: =SUM(D44:J44) -> 0
B45: 1112011 | C45: ฝอยทอง | K45: =SUM(D45:J45) -> 0
B46: 1112003 | C46: กาแฟ | K46: =SUM(D46:J46) -> 0
B47: 1112005 | C47: เนยนม | K47: =SUM(D47:J47) -> 0
B48: 1112007 | C48: ใบเตย | K48: =SUM(D48:J48) -> 0
B49: 1112019 | C49: ทุเรียน | K49: =SUM(D49:J49) -> 0
B50: 1112017 | C50: ตาลหอม | K50: =SUM(D50:J50) -> 0
B51: 1112015 | C51: กล้วยหอมมะพร้าวเผา | K51: =SUM(D51:J51) -> 0
B52: 1112013 | C52: เผือกมะพร้าวอ่อน | K52: =SUM(D52:J52) -> 0
B53: 1124043 | C53: เบาหวิว คละรส | K53: =SUM(D53:J53) -> 0
C54: รวม
B55: อื่นๆ
B56: 1100003 | C56: เมอแรงค์ กระปุก | K56: =SUM(D56:J56) -> 0
B57: 1100001 | C57: พายสับปรด 1 ชิ้น | K57: =SUM(D57:J57) -> 0
B58: 1100002 | C58: พายสับปรด 1 กล่อง | K58: =SUM(D58:J58) -> 0
B59: 1200001 | C59: คอนเฟลค | K59: =SUM(D59:J59) -> 0
...

Sheet รวม
B1: ยอดจริง ออนไลน์ วันที่ 12/11/2567 - รวม
K2: ยอดรวมผลิต | L2: ยอดสตอค | M2: ยอดฟอแคส | N2: รับเกิน | O2: ยังไม่ได้รับเข้า | P2: รวม
K3: จำนวน | R3: รับเข้าอาทิตย์ | S3: รับเข้าจันทร์ | T3: รวม
B4: รหัสสินค้า | C4: สินค้า | D4: ปณ | E4: ชอปปี้ | F4: ลาซาด้า | G4: ติ๊กตอก | H4: ติ๊กตอก2 | I4: ติ๊กตอก3 | J4: ชอยส์ | K4: (กล่อง)
B6: ชิฟฟอนรวมรส | W6: รหัสสินค้า | X6: ชื่อสินค้า | Y6: จำนวนที่ต้องการเบรค
B7: 1111002 | C7: ชิฟฟอนรวมรส 8 ชิ้น | D7: =เย็น!D7+เช้า!D7 -> 0 | E7: =เย็น!E7+เช้า!E7 -> 34 | F7: =เย็น!F7+เช้า!F7 -> 173 | G7: =เย็น!G7+เช้า!G7 -> 3 | H7: =เย็น!H7+เช้า!H7 -> 3 | I7: =เย็น!I7+เช้า!I7 -> 0 | J7: =เย็น!J7+เช้า!J7 -> 1 | K7: =SUM(D7:J7) -> 214 | P7: =(L7+M7+N7+O7)-K7 -> -214 | R7: 250 | S7: 250 | T7: =S7+R7+P7 -> 286 | W7: 1111002 | X7: ชิฟฟอนรวมรส 8 ชิ้น | Y7: 250
B8: 1111043 | C8: ชิฟฟอน 8 ชิ้น มะลิ | D8: =เย็น!D8+เช้า!D8 -> 0 | E8: =เย็น!E8+เช้า!E8 -> 0 | F8: =เย็น!F8+เช้า!F8 -> 0 | G8: =เย็น!G8+เช้า!G8 -> 0 | H8: =เย็น!H8+เช้า!H8 -> 0 | I8: =เย็น!I8+เช้า!I8 -> 0 | J8: =เย็น!J8+เช้า!J8 -> 0 | K8: =SUM(D8:J8) -> 0 | P8: =(L8+M8+N8+O8)-K8 -> 0 | T8: =S8+R8+P8 -> 0 | W8: 1111043 | X8: ชิฟฟอน 8 ชิ้น มะลิ
B9: 1111056 | C9: ชิฟฟอน 8 ชิ้น รวมรสยอดฮิต | D9: =เย็น!D9+เช้า!D9 -> 0 | E9: =เย็น!E9+เช้า!E9 -> 1 | F9: =เย็น!F9+เช้า!F9 -> 28 | G9: =เย็น!G9+เช้า!G9 -> 4 | H9: =เย็น!H9+เช้า!H9 -> 0 | I9: =เย็น!I9+เช้า!I9 -> 0 | J9: =เย็น!J9+เช้า!J9 -> 0 | K9: =SUM(D9:J9) -> 33 | P9: =(L9+M9+N9+O9)-K9 -> -33 | R9: 10 | T9: =S9+R9+P9 -> -23 | W9: 1004055 | X9: ชิฟฟอนรวมรส 4 ชิ้น | Y9: 250
B10: 1004055 | C10: ชิฟฟอนรวมรส 4 ชิ้น | D10: =เย็น!D10+เช้า!D10 -> 0 | E10: =เย็น!E10+เช้า!E10 -> 4 | F10: =เย็น!F10+เช้า!F10 -> 1 | G10: =เย็น!G10+เช้า!G10 -> 71 | H10: =เย็น!H10+เช้า!H10 -> 60 | I10: =เย็น!I10+เช้า!I10 -> 0 | J10: =เย็น!J10+เช้า!J10 -> 0 | K10: =SUM(D10:J10) -> 136 | P10: =(L10+M10+N10+O10)-K10 -> -136 | R10: 250 | S10: 250 | T10: =S10+R10+P10 -> 364 | W10: 1111057 | X10: ชิฟฟอนแยกชิ้น กาแฟ | Y10: 50
B11: 1111057 | C11: ชิฟฟอนแยกชิ้น กาแฟ | D11: =เย็น!D11+เช้า!D11 -> 11 | E11: =เย็น!E11+เช้า!E11 -> 6 | F11: =เย็น!F11+เช้า!F11 -> 1 | G11: =เย็น!G11+เช้า!G11 -> 1 | H11: =เย็น!H11+เช้า!H11 -> 0 | I11: =เย็น!I11+เช้า!I11 -> 0 | J11: =เย็น!J11+เช้า!J11 -> 0 | K11: =SUM(D11:J11) -> 19 | P11: =(L11+M11+N11+O11)-K11 -> -19 | S11: 50 | T11: =S11+R11+P11 -> 31 | W11: 1111058 | X11: ชิฟฟอนแยกชิ้น ชาเขียว | Y11: 50
B12: 1111058 | C12: ชิฟฟอนแยกชิ้น ชาเขียว | D12: =เย็น!D12+เช้า!D12 -> 11 | E12: =เย็น!E12+เช้า!E12 -> 3 | F12: =เย็น!F12+เช้า!F12 -> 0 | G12: =เย็น!G12+เช้า!G12 -> 1 | H12: =เย็น!H12+เช้า!H12 -> 0 | I12: =เย็น!I12+เช้า!I12 -> 0 | J12: =เย็น!J12+เช้า!J12 -> 0 | K12: =SUM(D12:J12) -> 15 | P12: =(L12+M12+N12+O12)-K12 -> -15 | S12: 50 | T12: =S12+R12+P12 -> 35 | W12: 1111059 | X12: ชิฟฟอนแยกชิ้น ใบเตย | Y12: 50
B13: 1111059 | C13: ชิฟฟอนแยกชิ้น ใบเตย | D13: =เย็น!D13+เช้า!D13 -> 11 | E13: =เย็น!E13+เช้า!E13 -> 3 | F13: =เย็น!F13+เช้า!F13 -> 0 | G13: =เย็น!G13+เช้า!G13 -> 1 | H13: =เย็น!H13+เช้า!H13 -> 0 | I13: =เย็น!I13+เช้า!I13 -> 0 | J13: =เย็น!J13+เช้า!J13 -> 0 | K13: =SUM(D13:J13) -> 15 | P13: =(L13+M13+N13+O13)-K13 -> -15 | S13: 50 | T13: =S13+R13+P13 -> 35 | W13: 1111060 | X13: ชิฟฟอนแยกชิ้น กล้วยหอม | Y13: 50
B14: 1111060 | C14: ชิฟฟอนแยกชิ้น กล้วยหอม | D14: =เย็น!D14+เช้า!D14 -> 11 | E14: =เย็น!E14+เช้า!E14 -> 0 | F14: =เย็น!F14+เช้า!F14 -> 0 | G14: =เย็น!G14+เช้า!G14 -> 1 | H14: =เย็น!H14+เช้า!H14 -> 0 | I14: =เย็น!I14+เช้า!I14 -> 0 | J14: =เย็น!J14+เช้า!J14 -> 0 | K14: =SUM(D14:J14) -> 12 | P14: =(L14+M14+N14+O14)-K14 -> -12 | S14: 50 | T14: =S14+R14+P14 -> 38 | W14: 1111061 | X14: ชิฟฟอนแยกชิ้น ชาไทย | Y14: 50
B15: 1111061 | C15: ชิฟฟอนแยกชิ้น ชาไทย | D15: =เย็น!D15+เช้า!D15 -> 11 | E15: =เย็น!E15+เช้า!E15 -> 3 | F15: =เย็น!F15+เช้า!F15 -> 0 | G15: =เย็น!G15+เช้า!G15 -> 1 | H15: =เย็น!H15+เช้า!H15 -> 0 | I15: =เย็น!I15+เช้า!I15 -> 0 | J15: =เย็น!J15+เช้า!J15 -> 0 | K15: =SUM(D15:J15) -> 15 | P15: =(L15+M15+N15+O15)-K15 -> -15 | S15: 50 | T15: =S15+R15+P15 -> 35 | W15: 1111062 | X15: ชิฟฟอนแยกชิ้น โกโก้ | Y15: 50
B16: 1111062 | C16: ชิฟฟอนแยกชิ้น โกโก้ | D16: =เย็น!D16+เช้า!D16 -> 11 | E16: =เย็น!E16+เช้า!E16 -> 3 | F16: =เย็น!F16+เช้า!F16 -> 0 | G16: =เย็น!G16+เช้า!G16 -> 1 | H16: =เย็น!H16+เช้า!H16 -> 0 | I16: =เย็น!I16+เช้า!I16 -> 0 | J16: =เย็น!J16+เช้า!J16 -> 0 | K16: =SUM(D16:J16) -> 15 | P16: =(L16+M16+N16+O16)-K16 -> -15 | S16: 50 | T16: =S16+R16+P16 -> 35 | W16: 1111063 | X16: ชิฟฟอนแยกชิ้น ส้ม | Y16: 50
B17: 1111063 | C17: ชิฟฟอนแยกชิ้น ส้ม | D17: =เย็น!D17+เช้า!D17 -> 11 | E17: =เย็น!E17+เช้า!E17 -> 3 | F17: =เย็น!F17+เช้า!F17 -> 0 | G17: =เย็น!G17+เช้า!G17 -> 1 | H17: =เย็น!H17+เช้า!H17 -> 0 | I17: =เย็น!I17+เช้า!I17 -> 0 | J17: =เย็น!J17+เช้า!J17 -> 0 | K17: =SUM(D17:J17) -> 15 | P17: =(L17+M17+N17+O17)-K17 -> -15 | S17: 50 | T17: =S17+R17+P17 -> 35 | W17: 1111064 | X17: ชิฟฟอนแยกชิ้น เผือก | Y17: 50
B18: 1111064 | C18: ชิฟฟอนแยกชิ้น เผือก | D18: =เย็น!D18+เช้า!D18 -> 11 | E18: =เย็น!E18+เช้า!E18 -> 3 | F18: =เย็น!F18+เช้า!F18 -> 0 | G18: =เย็น!G18+เช้า!G18 -> 0 | H18: =เย็น!H18+เช้า!H18 -> 0 | I18: =เย็น!I18+เช้า!I18 -> 0 | J18: =เย็น!J18+เช้า!J18 -> 0 | K18: =SUM(D18:J18) -> 14 | P18: =(L18+M18+N18+O18)-K18 -> -14 | S18: 50 | T18: =S18+R18+P18 -> 36 | W18: 1111065 | X18: ชิฟฟอนแยกชิ้น สับปะรด | Y18: 50
B19: 1111065 | C19: ชิฟฟอนแยกชิ้น สับปะรด | D19: =เย็น!D19+เช้า!D19 -> 11 | E19: =เย็น!E19+เช้า!E19 -> 0 | F19: =เย็น!F19+เช้า!F19 -> 0 | G19: =เย็น!G19+เช้า!G19 -> 0 | H19: =เย็น!H19+เช้า!H19 -> 0 | I19: =เย็น!I19+เช้า!I19 -> 0 | J19: =เย็น!J19+เช้า!J19 -> 0 | K19: =SUM(D19:J19) -> 11 | P19: =(L19+M19+N19+O19)-K19 -> -11 | S19: 50 | T19: =S19+R19+P19 -> 39 | W19: 1111066 | X19: ชิฟฟอนแยกชิ้น สตอเบอรี่ | Y19: 50
B20: 1111066 | C20: ชิฟฟอนแยกชิ้น สตอเบอรี่ | D20: =เย็น!D20+เช้า!D20 -> 11 | E20: =เย็น!E20+เช้า!E20 -> 3 | F20: =เย็น!F20+เช้า!F20 -> 0 | G20: =เย็น!G20+เช้า!G20 -> 0 | H20: =เย็น!H20+เช้า!H20 -> 0 | I20: =เย็น!I20+เช้า!I20 -> 0 | J20: =เย็น!J20+เช้า!J20 -> 0 | K20: =SUM(D20:J20) -> 14 | P20: =(L20+M20+N20+O20)-K20 -> -14 | S20: 50 | T20: =S20+R20+P20 -> 36 | W20: 1111067 | X20: ชิฟฟอนแยกชิ้น มะพร้าว | Y20: 50
B21: 1111067 | C21: ชิฟฟอนแยกชิ้น มะพร้าว | D21: =เย็น!D21+เช้า!D21 -> 0 | E21: =เย็น!E21+เช้า!E21 -> 7 | F21: =เย็น!F21+เช้า!F21 -> 0 | G21: =เย็น!G21+เช้า!G21 -> 0 | H21: =เย็น!H21+เช้า!H21 -> 0 | I21: =เย็น!I21+เช้า!I21 -> 0 | J21: =เย็น!J21+เช้า!J21 -> 0 | K21: =SUM(D21:J21) -> 7 | P21: =(L21+M21+N21+O21)-K21 -> -7 | S21: 50 | T21: =S21+R21+P21 -> 43 | W21: 1111068 | X21: ชิฟฟอนแยกชิ้น เนย | Y21: 50
B22: 1111068 | C22: ชิฟฟอนแยกชิ้น เนย | D22: =เย็น!D22+เช้า!D22 -> 0 | E22: =เย็น!E22+เช้า!E22 -> 3 | F22: =เย็น!F22+เช้า!F22 -> 0 | G22: =เย็น!G22+เช้า!G22 -> 0 | H22: =เย็น!H22+เช้า!H22 -> 0 | I22: =เย็น!I22+เช้า!I22 -> 0 | J22: =เย็น!J22+เช้า!J22 -> 0 | K22: =SUM(D22:J22) -> 3 | P22: =(L22+M22+N22+O22)-K22 -> -3 | S22: 50 | T22: =S22+R22+P22 -> 47 | W22: 1111069 | X22: ชิฟฟอนแยกชิ้น บลูเบอรี่ | Y22: 50
... B25: 1111071 | C25: ชิฟฟอนแยกชิ้น ตาล | D25: =เย็น!D25+เช้า!D25 -> 0 | E25: =เย็น!E25+เช้า!E25 -> 0 | F25: =เย็น!F25+เช้า!F25 -> 0 | G25: =เย็น!G25+เช้า!G25 -> 0 | H25: =เย็น!H25+เช้า!H25 -> 0 | I25: =เย็น!I25+เช้า!I25 -> 0 | J25: =เย็น!J25+เช้า!J25 -> 0 | K25: =SUM(D25:J25) -> 0 | P25: =(L25+M25+N25+O25)-K25 -> 0 | S25: 50 | T25: =S25+R25+P25 -> 50 | W25: 1111074 | X25: ชิฟฟอนไส้แยมแยกชิ้น มะพร้าว | Y25: 40
B26: 1111001 | C26: ชิฟฟอนแยกชิ้น คละรส | D26: =เย็น!D26+เช้า!D26 -> 0 | E26: =เย็น!E26+เช้า!E26 -> 0 | F26: =เย็น!F26+เช้า!F26 -> 0 | G26: =เย็น!G26+เช้า!G26 -> 0 | H26: =เย็น!H26+เช้า!H26 -> 0 | I26: =เย็น!I26+เช้า!I26 -> 0 | J26: =เย็น!J26+เช้า!J26 -> 0 | K26: =SUM(D26:J26) -> 0 | P26: =(L26+M26+N26+O26)-K26 -> 0 | T26: =S26+R26+P26 -> 0 | W26: 1111075 | X26: ชิฟฟอนไส้แยมแยกชิ้น สตอเบอรี่ | Y26: 40
B27: 1111074 | C27: ชิฟฟอนไส้แยมแยกชิ้น มะพร้าว | D27: =เย็น!D27+เช้า!D27 -> 0 | E27: =เย็น!E27+เช้า!E27 -> 0 | F27: =เย็น!F27+เช้า!F27 -> 10 | G27: =เย็น!G27+เช้า!G27 -> 11 | H27: =เย็น!H27+เช้า!H27 -> 0 | I27: =เย็น!I27+เช้า!I27 -> 0 | J27: =เย็น!J27+เช้า!J27 -> 0 | K27: =SUM(D27:J27) -> 21 | P27: =(L27+M27+N27+O27)-K27 -> -21 | S27: 40 | T27: =S27+R27+P27 -> 19 | W27: 1111076 | X27: ชิฟฟอนไส้แยมแยกชิ้น ส้ม | Y27: 40
B28: 1111075 | C28: ชิฟฟอนไส้แยมแยกชิ้น สตอเบอรี่ | D28: =เย็น!D28+เช้า!D28 -> 0 | E28: =เย็น!E28+เช้า!E28 -> 0 | F28: =เย็น!F28+เช้า!F28 -> 10 | G28: =เย็น!G28+เช้า!G28 -> 11 | H28: =เย็น!H28+เช้า!H28 -> 0 | I28: =เย็น!I28+เช้า!I28 -> 0 | J28: =เย็น!J28+เช้า!J28 -> 0 | K28: =SUM(D28:J28) -> 21 | P28: =(L28+M28+N28+O28)-K28 -> -21 | S28: 40 | T28: =S28+R28+P28 -> 19 | W28: 1111077 | X28: ชิฟฟอนไส้แยมแยกชิ้น บลูเบอรี่ | Y28: 40
B29: 1111076 | C29: ชิฟฟอนไส้แยมแยกชิ้น ส้ม | D29: =เย็น!D29+เช้า!D29 -> 0 | E29: =เย็น!E29+เช้า!E29 -> 0 | F29: =เย็น!F29+เช้า!F29 -> 10 | G29: =เย็น!G29+เช้า!G29 -> 11 | H29: =เย็น!H29+เช้า!H29 -> 0 | I29: =เย็น!I29+เช้า!I29 -> 0 | J29: =เย็น!J29+เช้า!J29 -> 0 | K29: =SUM(D29:J29) -> 21 | P29: =(L29+M29+N29+O29)-K29 -> -21 | S29: 40 | T29: =S29+R29+P29 -> 19 | W29: 1111078 | X29: ชิฟฟอนไส้แยมแยกชิ้น นมชมพู | Y29: 40
B30: 1111077 | C30: ชิฟฟอนไส้แยมแยกชิ้น บลูเบอรี่ | D30: =เย็น!D30+เช้า!D30 -> 0 | E30: =เย็น!E30+เช้า!E30 -> 0 | F30: =เย็น!F30+เช้า!F30 -> 10 | G30: =เย็น!G30+เช้า!G30 -> 11 | H30: =เย็น!H30+เช้า!H30 -> 0 | I30: =เย็น!I30+เช้า!I30 -> 0 | J30: =เย็น!J30+เช้า!J30 -> 0 | K30: =SUM(D30:J30) -> 21 | P30: =(L30+M30+N30+O30)-K30 -> -21 | S30: 40 | T30: =S30+R30+P30 -> 19 | W30: 1111079 | X30: ชิฟฟอนไส้แยมแยกชิ้น ชอคโกแลต | Y30: 40
B31: 1111078 | C31: ชิฟฟอนไส้แยมแยกชิ้น นมชมพู | D31: =เย็น!D31+เช้า!D31 -> 0 | E31: =เย็น!E31+เช้า!E31 -> 0 | F31: =เย็น!F31+เช้า!F31 -> 10 | G31: =เย็น!G31+เช้า!G31 -> 11 | H31: =เย็น!H31+เช้า!H31 -> 0 | I31: =เย็น!I31+เช้า!I31 -> 0 | J31: =เย็น!J31+เช้า!J31 -> 0 | K31: =SUM(D31:J31) -> 21 | P31: =(L31+M31+N31+O31)-K31 -> -21 | S31: 40 | T31: =S31+R31+P31 -> 19 | W31: 1111080 | X31: ชิฟฟอนไส้แยมแยกชิ้น ฝอยทอง | Y31: 40
B32: 1111079 | C32: ชิฟฟอนไส้แยมแยกชิ้น ชอคโกแลต | D32: =เย็น!D32+เช้า!D32 -> 0 | E32: =เย็น!E32+เช้า!E32 -> 0 | F32: =เย็น!F32+เช้า!F32 -> 10 | G32: =เย็น!G32+เช้า!G32 -> 11 | H32: =เย็น!H32+เช้า!H32 -> 0 | I32: =เย็น!I32+เช้า!I32 -> 0 | J32: =เย็น!J32+เช้า!J32 -> 0 | K32: =SUM(D32:J32) -> 21 | P32: =(L32+M32+N32+O32)-K32 -> -21 | S32: 40 | T32: =S32+R32+P32 -> 19 | W32: 1111081 | X32: ชิฟฟอนไส้แยมแยกชิ้น วนิลา | Y32: 40
B33: 1111080 | C33: ชิฟฟอนไส้แยมแยกชิ้น ฝอยทอง | D33: =เย็น!D33+เช้า!D33 -> 0 | E33: =เย็น!E33+เช้า!E33 -> 0 | F33: =เย็น!F33+เช้า!F33 -> 10 | G33: =เย็น!G33+เช้า!G33 -> 1 | H33: =เย็น!H33+เช้า!H33 -> 0 | I33: =เย็น!I33+เช้า!I33 -> 0 | J33: =เย็น!J33+เช้า!J33 -> 0 | K33: =SUM(D33:J33) -> 11 | P33: =(L33+M33+N33+O33)-K33 -> -11 | S33: 40 | T33: =S33+R33+P33 -> 29 | W33: 1111082 | X33: ชิฟฟอนไส้แยมแยกชิ้น ใบเตย | Y33: 40
B34: 1111081 | C34: ชิฟฟอนไส้แยมแยกชิ้น วนิลา | D34: =เย็น!D34+เช้า!D34 -> 0 | E34: =เย็น!E34+เช้า!E34 -> 0 | F34: =เย็น!F34+เช้า!F34 -> 10 | G34: =เย็น!G34+เช้า!G34 -> 1 | H34: =เย็น!H34+เช้า!H34 -> 0 | I34: =เย็น!I34+เช้า!I34 -> 0 | J34: =เย็น!J34+เช้า!J34 -> 0 | K34: =SUM(D34:J34) -> 11 | P34: =(L34+M34+N34+O34)-K34 -> -11 | S34: 40 | T34: =S34+R34+P34 -> 29 | W34: 1111083 | X34: ชิฟฟอนไส้แยมแยกชิ้น เมล่อน | Y34: 40
B35: 1111082 | C35: ชิฟฟอนไส้แยมแยกชิ้น ใบเตย | D35: =เย็น!D35+เช้า!D35 -> 0 | E35: =เย็น!E35+เช้า!E35 -> 0 | F35: =เย็น!F35+เช้า!F35 -> 10 | G35: =เย็น!G35+เช้า!G35 -> 1 | H35: =เย็น!H35+เช้า!H35 -> 0 | I35: =เย็น!I35+เช้า!I35 -> 0 | J35: =เย็น!J35+เช้า!J35 -> 0 | K35: =SUM(D35:J35) -> 11 | P35: =(L35+M35+N35+O35)-K35 -> -11 | S35: 40 | T35: =S35+R35+P35 -> 29 | W35: 1111009 | X35: ชิฟฟอนไส้แยมรวมรส 6 ชิ้น | Y35: 20
B36: 1111083 | C36: ชิฟฟอนไส้แยมแยกชิ้น เมล่อน | D36: =เย็น!D36+เช้า!D36 -> 0 | E36: =เย็น!E36+เช้า!E36 -> 0 | F36: =เย็น!F36+เช้า!F36 -> 10 | G36: =เย็น!G36+เช้า!G36 -> 1 | H36: =เย็น!H36+เช้า!H36 -> 0 | I36: =เย็น!I36+เช้า!I36 -> 0 | J36: =เย็น!J36+เช้า!J36 -> 0 | K36: =SUM(D36:J36) -> 11 | P36: =(L36+M36+N36+O36)-K36 -> -11 | S36: 40 | T36: =S36+R36+P36 -> 29 | W36: 1111008 | X36: ชิฟฟอนไส้แยมรวมรส 3 ชิ้น | Y36: 250
B37: 1111010 | C37: ชิฟฟอนไส้แยมแยกชิ้น คละรส | D37: =เย็น!D37+เช้า!D37 -> 0 | E37: =เย็น!E37+เช้า!E37 -> 0 | F37: =เย็น!F37+เช้า!F37 -> 0 | G37: =เย็น!G37+เช้า!G37 -> 0 | H37: =เย็น!H37+เช้า!H37 -> 0 | I37: =เย็น!I37+เช้า!I37 -> 0 | J37: =เย็น!J37+เช้า!J37 -> 0 | K37: =SUM(D37:J37) -> 0 | P37: =(L37+M37+N37+O37)-K37 -> 0 | T37: =S37+R37+P37 -> 0
C38: รวม | K38: =SUM(D38:J38) -> 0 | P38: =(L38+M38+N38+O38)-K38 -> 0 | T38: =S38+R38+P38 -> 0 | W38: 1114501 | X38: ครีมฮอร์นไส้เนย วนิลา | Y38: 400
B39: ชิฟฟอนไส้แยม 6 ชิ้น | T39: =S39+R39+P39 -> 0 | W39: 1114503 | X39: ครีมฮอร์นไส้เนย ชอค | Y39: 400
B40: 1111009 | C40: ชิฟฟอนไส้แยมรวมรส 6 ชิ้น | D40: =เย็น!D40+เช้า!D40 -> 0 | E40: =เย็น!E40+เช้า!E40 -> 1 | F40: =เย็น!F40+เช้า!F40 -> 11 | G40: =เย็น!G40+เช้า!G40 -> 2 | H40: =เย็น!H40+เช้า!H40 -> 0 | I40: =เย็น!I40+เช้า!I40 -> 0 | J40: =เย็น!J40+เช้า!J40 -> 0 | K40: =SUM(D40:J40) -> 14 | P40: =(L40+M40+N40+O40)-K40 -> -14 | S40: 20 | T40: =S40+R40+P40 -> 6 | W40: 1124021 | X40: ขนมปังหั่นสไลด์ | Y40: 400
B41: ชิฟฟอนไส้แยม 3 ชิ้น | T41: =S41+R41+P41 -> 0
B42: 1111008 | C42: ชิฟฟอนไส้แยมรวมรส 3 ชิ้น | D42: =เย็น!D42+เช้า!D42 -> 0 | E42: =เย็น!E42+เช้า!E42 -> 12 | F42: =เย็น!F42+เช้า!F42 -> 0 | G42: =เย็น!G42+เช้า!G42 -> 99 | H42: =เย็น!H42+เช้า!H42 -> 12 | I42: =เย็น!I42+เช้า!I42 -> 0 | J42: =เย็น!J42+เช้า!J42 -> 0 | K42: =SUM(D42:J42) -> 123 | P42: =(L42+M42+N42+O42)-K42 -> -123 | S42: 250 | T42: =S42+R42+P42 -> 127
B43: เบาหวิว ล 110 กรัม | T43: =S43+R43+P43 -> 0
...
