Workbook

Sheet เช้า
B1: ยอดจริง ออนไลน์ วันที่ 19/11/2567 - เช้า
K2: ยอดรวมผลิต
K3: จำนวน
B4: รหัสสินค้า | C4: สินค้า | D4: ปณ | E4: ชอปปี้ | F4: ลาซาด้า | G4: ติ๊กตอก | H4: ติ๊กตอก2 | I4: ติ๊กตอก3 | J4: ชอยส์ | K4: (กล่อง)
B6: ชิฟฟอนรวมรส
B7: 1111002 | C7: ชิฟฟอนรวมรส 8 ชิ้น | E7: 63 | F7: 29 | K7: =SUM(D7:J7) -> 92
B8: 1111043 | C8: ชิฟฟอน 8 ชิ้น มะลิ | K8: =SUM(D8:J8) -> 0
B9: 1111056 | C9: ชิฟฟอน 8 ชิ้น รวมรสยอดฮิต | E9: 1 | F9: 5 | G9: 2 | K9: =SUM(D9:J9) -> 8
B10: 1004055 | C10: ชิฟฟอนรวมรส 4 ชิ้น | D10: 6 | F10: 3 | G10: 52 | K10: =SUM(D10:J10) -> 61
B11: 1111057 | C11: ชิฟฟอนแยกชิ้น กาแฟ | D11: 1 | G11: 3 | K11: =SUM(D11:J11) -> 4
B12: 1111058 | C12: ชิฟฟอนแยกชิ้น ชาเขียว | D12: 1 | G12: 2 | K12: =SUM(D12:J12) -> 3
B13: 1111059 | C13: ชิฟฟอนแยกชิ้น ใบเตย | D13: 1 | G13: 2 | K13: =SUM(D13:J13) -> 3
B14: 1111060 | C14: ชิฟฟอนแยกชิ้น กล้วยหอม | D14: 1 | G14: 2 | K14: =SUM(D14:J14) -> 3
B15: 1111061 | C15: ชิฟฟอนแยกชิ้น ชาไทย | D15: 1 | G15: 2 | K15: =SUM(D15:J15) -> 3
B16: 1111062 | C16: ชิฟฟอนแยกชิ้น โกโก้ | D16: 1 | G16: 2 | K16: =SUM(D16:J16) -> 3
B17: 1111063 | C17: ชิฟฟอนแยกชิ้น ส้ม | D17: 1 | G17: 2 | K17: =SUM(D17:J17) -> 3
B18: 1111064 | C18: ชิฟฟอนแยกชิ้น เผือก | D18: 1 | G18: 2 | K18: =SUM(D18:J18) -> 3
B19: 1111065 | C19: ชิฟฟอนแยกชิ้น สับปะรด | D19: 1 | G19: 2 | K19: =SUM(D19:J19) -> 3
B20: 1111066 | C20: ชิฟฟอนแยกชิ้น สตอเบอรี่ | D20: 1 | G20: 2 | K20: =SUM(D20:J20) -> 3
B21: 1111067 | C21: ชิฟฟอนแยกชิ้น มะพร้าว | D21: 1 | G21: 2 | K21: =SUM(D21:J21) -> 3
B22: 1111068 | C22: ชิฟฟอนแยกชิ้น เนย | D22: 1 | G22: 2 | K22: =SUM(D22:J22) -> 3
... B25: 1111071 | C25: ชิฟฟอนแยกชิ้น ตาล | D25: 1 | G25: 2 | K25: =SUM(D25:J25) -> 3
B26: 1111001 | C26: ชิฟฟอนแยกชิ้น คละรส | K26: =SUM(D26:J26) -> 0
B27: 1111074 | C27: ชิฟฟอนไส้แยมแยกชิ้น มะพร้าว | E27: 1 | G27: 1 | K27: =SUM(D27:J27) -> 2
B28: 1111075 | C28: ชิฟฟอนไส้แยมแยกชิ้น สตอเบอรี่ | E28: 1 | G28: 1 | K28: =SUM(D28:J28) -> 2
B29: 1111076 | C29: ชิฟฟอนไส้แยมแยกชิ้น ส้ม | E29: 1 | G29: 1 | K29: =SUM(D29:J29) -> 2
B30: 1111077 | C30: ชิฟฟอนไส้แยมแยกชิ้น บลูเบอรี่ | E30: 1 | G30: 1 | K30: =SUM(D30:J30) -> 2
B31: 1111078 | C31: ชิฟฟอนไส้แยมแยกชิ้น นมชมพู | E31: 1 | G31: 1 | K31: =SUM(D31:J31) -> 2
B32: 1111079 | C32: ชิฟฟอนไส้แยมแยกชิ้น ชอคโกแลต | E32: 1 | K32: =SUM(D32:J32) -> 1
B33: 1111080 | C33: ชิฟฟอนไส้แยมแยกชิ้น ฝอยทอง | E33: 1 | K33: =SUM(D33:J33) -> 1
B34: 1111081 | C34: ชิฟฟอนไส้แยมแยกชิ้น วนิลา | E34: 1 | K34: =SUM(D34:J34) -> 1
B35: 1111082 | C35: ชิฟฟอนไส้แยมแยกชิ้น ใบเตย | E35: 1 | K35: =SUM(D35:J35) -> 1
B36: 1111083 | C36: ชิฟฟอนไส้แยมแยกชิ้น เมล่อน | E36: 1 | K36: =SUM(D36:J36) -> 1
B37: 1111010 | C37: ชิฟฟอนไส้แยมแยกชิ้น คละรส | K37: =SUM(D37:J37) -> 0
C38: รวม | K38: =SUM(D38:I38) -> 0
B39: ชิฟฟอนไส้แยม 6 ชิ้น
B40: 1111009 | C40: ชิฟฟอนไส้แยมรวมรส 6 ชิ้น | F40: 6 | G40: 8 | K40: =SUM(D40:J40) -> 14
B41: ชิฟฟอนไส้แยม 3 ชิ้น
B42: 1111008 | C42: ชิฟฟอนไส้แยมรวมรส 3 ชิ้น | D42: 30 | E42: 9 | G42: 77 | K42: =SUM(D42:J42) -> 116
B43: เบาหวิว ล 110 กรัม
...

Sheet บ่าย 
B1: ยอดจริง ออนไลน์ วันที่ 19/11/2567 - บ่าย
K2: ยอดรวมผลิต
K3: จำนวน
B4: รหัสสินค้า | C4: สินค้า | D4: ปณ | E4: ชอปปี้ | F4: ลาซาด้า | G4: ติ๊กตอก | H4: ติ๊กตอก2 | I4: ติ๊กตอก3 | J4: ชอยส์ | K4: (กล่อง)
B6: ชิฟฟอนรวมรส
B7: 1111002 | C7: ชิฟฟอนรวมรส 8 ชิ้น | E7: 14 | F7: 1 | K7: =SUM(D7:J7) -> 15
B8: 1111043 | C8: ชิฟฟอน 8 ชิ้น มะลิ | K8: =SUM(D8:J8) -> 0
B9: 1111056 | C9: ชิฟฟอน 8 ชิ้น รวมรสยอดฮิต | E9: 3 | K9: =SUM(D9:J9) -> 3
B10: 1004055 | C10: ชิฟฟอนรวมรส 4 ชิ้น | G10: 12 | K10: =SUM(D10:J10) -> 12
B11: 1111057 | C11: ชิฟฟอนแยกชิ้น กาแฟ | G11: 3 | J11: 1 | K11: =SUM(D11:J11) -> 4
B12: 1111058 | C12: ชิฟฟอนแยกชิ้น ชาเขียว | G12: 3 | K12: =SUM(D12:J12) -> 3
B13: 1111059 | C13: ชิฟฟอนแยกชิ้น ใบเตย | G13: 3 | K13: =SUM(D13:J13) -> 3
B14: 1111060 | C14: ชิฟฟอนแยกชิ้น กล้วยหอม | G14: 1 | K14: =SUM(D14:J14) -> 1
B15: 1111061 | C15: ชิฟฟอนแยกชิ้น ชาไทย | G15: 3 | K15: =SUM(D15:J15) -> 3
B16: 1111062 | C16: ชิฟฟอนแยกชิ้น โกโก้ | K16: =SUM(D16:J16) -> 0
B17: 1111063 | C17: ชิฟฟอนแยกชิ้น ส้ม | G17: 2 | K17: =SUM(D17:J17) -> 2
B18: 1111064 | C18: ชิฟฟอนแยกชิ้น เผือก | G18: 2 | K18: =SUM(D18:J18) -> 2
B19: 1111065 | C19: ชิฟฟอนแยกชิ้น สับปะรด | K19: =SUM(D19:J19) -> 0
B20: 1111066 | C20: ชิฟฟอนแยกชิ้น สตอเบอรี่ | G20: 2 | K20: =SUM(D20:J20) -> 2
B21: 1111067 | C21: ชิฟฟอนแยกชิ้น มะพร้าว | G21: 2 | K21: =SUM(D21:J21) -> 2
B22: 1111068 | C22: ชิฟฟอนแยกชิ้น เนย | G22: 2 | K22: =SUM(D22:J22) -> 2
B23: 1111069 | C23: ชิฟฟอนแยกชิ้น บลูเบอรี่ | G23: 2 | K23: =SUM(D23:J23) -> 2
B24: 1111070 | C24: ชิฟฟอนแยกชิ้น ทุเรียน | K24: =SUM(D24:J24) -> 0
B25: 1111071 | C25: ชิฟฟอนแยกชิ้น ตาล | K25: =SUM(D25:J25) -> 0
B26: 1111001 | C26: ชิฟฟอนแยกชิ้น คละรส | K26: =SUM(D26:J26) -> 0
B27: 1111074 | C27: ชิฟฟอนไส้แยมแยกชิ้น มะพร้าว | G27: 1 | K27: =SUM(D27:J27) -> 1
B28: 1111075 | C28: ชิฟฟอนไส้แยมแยกชิ้น สตอเบอรี่ | G28: 1 | K28: =SUM(D28:J28) -> 1
B29: 1111076 | C29: ชิฟฟอนไส้แยมแยกชิ้น ส้ม | G29: 1 | K29: =SUM(D29:J29) -> 1
B30: 1111077 | C30: ชิฟฟอนไส้แยมแยกชิ้น บลูเบอรี่ | G30: 1 | K30: =SUM(D30:J30) -> 1
B31: 1111078 | C31: ชิฟฟอนไส้แยมแยกชิ้น นมชมพู | G31: 1 | K31: =SUM(D31:J31) -> 1
B32: 1111079 | C32: ชิฟฟอนไส้แยมแยกชิ้น ชอคโกแลต | K32: =SUM(D32:J32) -> 0
B33: 1111080 | C33: ชิฟฟอนไส้แยมแยกชิ้น ฝอยทอง | K33: =SUM(D33:J33) -> 0
B34: 1111081 | C34: ชิฟฟอนไส้แยมแยกชิ้น วนิลา | K34: =SUM(D34:J34) -> 0
B35: 1111082 | C35: ชิฟฟอนไส้แยมแยกชิ้น ใบเตย | K35: =SUM(D35:J35) -> 0
B36: 1111083 | C36: ชิฟฟอนไส้แยมแยกชิ้น เมล่อน | K36: =SUM(D36:J36) -> 0
B37: 1111010 | C37: ชิฟฟอนไส้แยมแยกชิ้น คละรส | K37: =SUM(D37:J37) -> 0
C38: รวม | K38: =SUM(D38:I38) -> 0
B39: ชิฟฟอนไส้แยม 6 ชิ้น
B40: 1111009 | C40: ชิฟฟอนไส้แยมรวมรส 6 ชิ้น | K40: =SUM(D40:J40) -> 0
B41: ชิฟฟอนไส้แยม 3 ชิ้น
...

Sheet เย็น 
B1: ยอดจริง ออนไลน์ วันที่ 16/11/2567 - เย็น
K2: ยอดรวมผลิต
K3: จำนวน
B4: รหัสสินค้า | C4: สินค้า | D4: ปณ | E4: ชอปปี้ | F4: ลาซาด้า | G4: ติ๊กตอก | H4: ติ๊กตอก2 | I4: ติ๊กตอก3 | J4: ชอยส์ | K4: (กล่อง)
B6: ชิฟฟอนรวมรส
B7: 1111002 | C7: ชิฟฟอนรวมรส 8 ชิ้น | K7: =SUM(D7:J7) -> 0
B8: 1111043 | C8: ชิฟฟอน 8 ชิ้น มะลิ | K8: =SUM(D8:J8) -> 0
B9: 1111056 | C9: ชิฟฟอน 8 ชิ้น รวมรสยอดฮิต | K9: =SUM(D9:J9) -> 0
B10: 1004055 | C10: ชิฟฟอนรวมรส 4 ชิ้น | K10: =SUM(D10:J10) -> 0
B11: 1111057 | C11: ชิฟฟอนแยกชิ้น กาแฟ | K11: =SUM(D11:J11) -> 0
B12: 1111058 | C12: ชิฟฟอนแยกชิ้น ชาเขียว | K12: =SUM(D12:J12) -> 0
B13: 1111059 | C13: ชิฟฟอนแยกชิ้น ใบเตย | K13: =SUM(D13:J13) -> 0
B14: 1111060 | C14: ชิฟฟอนแยกชิ้น กล้วยหอม | K14: =SUM(D14:J14) -> 0
B15: 1111061 | C15: ชิฟฟอนแยกชิ้น ชาไทย | K15: =SUM(D15:J15) -> 0
B16: 1111062 | C16: ชิฟฟอนแยกชิ้น โกโก้ | K16: =SUM(D16:J16) -> 0
B17: 1111063 | C17: ชิฟฟอนแยกชิ้น ส้ม | K17: =SUM(D17:J17) -> 0
B18: 1111064 | C18: ชิฟฟอนแยกชิ้น เผือก | K18: =SUM(D18:J18) -> 0
... B37: 1111010 | C37: ชิฟฟอนไส้แยมแยกชิ้น คละรส | K37: =SUM(D37:J37) -> 0
C38: รวม | K38: =SUM(D38:I38) -> 0
B39: ชิฟฟอนไส้แยม 6 ชิ้น
B40: 1111009 | C40: ชิฟฟอนไส้แยมรวมรส 6 ชิ้น | K40: =SUM(D40:J40) -> 0
B41: ชิฟฟอนไส้แยม 3 ชิ้น
B42: 1111008 | C42: ชิฟฟอนไส้แยมรวมรส 3 ชิ้น | K42: =SUM(D42:J42) -> 0
B43: 1111017 | C43: ชิฟฟอนไส้แยมบลูเบอรี่ 3 ชิ้น
B44: 1111019 | C44: ชิฟฟอนไส้แยมฝอยทอง 3 ชิ้น
B45: 1111022 | C45: ชิฟฟอนไส้แยมสตอเบอรี่ 3 ชิ้น
B46: เบาหวิว ล 110 กรัม
B47: 1112009 | C47: มะพร้าว | K47: =SUM(D47:J47) -> 0
B48: 1112011 | C48: ฝอยทอง | K48: =SUM(D48:J48) -> 0
B49: 1112003 | C49: กาแฟ | K49: =SUM(D49:J49) -> 0
B50: 1112005 | C50: เนยนม | K50: =SUM(D50:J50) -> 0
B51: 1112007 | C51: ใบเตย | K51: =SUM(D51:J51) -> 0
B52: 1112019 | C52: ทุเรียน | K52: =SUM(D52:J52) -> 0
B53: 1112017 | C53: ตาลหอม | K53: =SUM(D53:J53) -> 0
B54: 1112015 | C54: กล้วยหอมมะพร้าวเผา | K54: =SUM(D54:J54) -> 0
B55: 1112013 | C55: เผือกมะพร้าวอ่อน | K55: =SUM(D55:J55) -> 0
B56: 1124043 | C56: เบาหวิว คละรส | K56: =SUM(D56:J56) -> 0
C57: รวม
B58: อื่นๆ
B59: 1100003 | C59: เมอแรงค์ กระปุก | K59: =SUM(D59:J59) -> 0
...

Sheet รวม
B1: ยอดจริง ออนไลน์ วันที่ 19/11/2567 - รวม
K2: ยอดรวมผลิต | L2: ยอดสตอค | M2: ยอดฟอแคส | N2: รับเกิน | O2: ยังไม่ได้รับเข้า | P2: รวม
K3: จำนวน | R3: รับเข้าอาทิตย์ | S3: รับเข้าจันทร์ | T3: รวม
B4: รหัสสินค้า | C4: สินค้า | D4: ปณ | E4: ชอปปี้ | F4: ลาซาด้า | G4: ติ๊กตอก | H4: ติ๊กตอก2 | I4: ติ๊กตอก3 | J4: ชอยส์ | K4: (กล่อง)
B6: ชิฟฟอนรวมรส | W6: รหัสสินค้า | X6: ชื่อสินค้า | Y6: จำนวนที่ต้องการเบรค
B7: 1111002 | C7: ชิฟฟอนรวมรส 8 ชิ้น | D7: =เช้า!D7+'บ่าย '!D7+'เย็น '!D7 -> 0 | E7: =เช้า!E7+'บ่าย '!E7+'เย็น '!E7 -> 77 | F7: =เช้า!F7+'บ่าย '!F7+'เย็น '!F7 -> 30 | G7: =เช้า!G7+'บ่าย '!G7+'เย็น '!G7 -> 0 | H7: =เช้า!H7+'บ่าย '!H7+'เย็น '!H7 -> 0 | I7: =เช้า!I7+'บ่าย '!I7+'เย็น '!I7 -> 0 | J7: =เช้า!J7+'บ่าย '!J7+'เย็น '!J7 -> 0 | K7: =SUM(D7:J7) -> 107 | P7: =(L7+M7+N7+O7)-K7 -> -107 | R7: 250 | S7: 250 | T7: =S7+R7+P7 -> 393 | W7: 1111002 | X7: ชิฟฟอนรวมรส 8 ชิ้น | Y7: 250
B8: 1111043 | C8: ชิฟฟอน 8 ชิ้น มะลิ | D8: =เช้า!D8+'บ่าย '!D8+'เย็น '!D8 -> 0 | E8: =เช้า!E8+'บ่าย '!E8+'เย็น '!E8 -> 0 | F8: =เช้า!F8+'บ่าย '!F8+'เย็น '!F8 -> 0 | G8: =เช้า!G8+'บ่าย '!G8+'เย็น '!G8 -> 0 | H8: =เช้า!H8+'บ่าย '!H8+'เย็น '!H8 -> 0 | I8: =เช้า!I8+'บ่าย '!I8+'เย็น '!I8 -> 0 | J8: =เช้า!J8+'บ่าย '!J8+'เย็น '!J8 -> 0 | K8: =SUM(D8:J8) -> 0 | P8: =(L8+M8+N8+O8)-K8 -> 0 | T8: =S8+R8+P8 -> 0 | W8: 1111043 | X8: ชิฟฟอน 8 ชิ้น มะลิ
B9: 1111056 | C9: ชิฟฟอน 8 ชิ้น รวมรสยอดฮิต | D9: =เช้า!D9+'บ่าย '!D9+'เย็น '!D9 -> 0 | E9: =เช้า!E9+'บ่าย '!E9+'เย็น '!E9 -> 4 | F9: =เช้า!F9+'บ่าย '!F9+'เย็น '!F9 -> 5 | G9: =เช้า!G9+'บ่าย '!G9+'เย็น '!G9 -> 2 | H9: =เช้า!H9+'บ่าย '!H9+'เย็น '!H9 -> 0 | I9: =เช้า!I9+'บ่าย '!I9+'เย็น '!I9 -> 0 | J9: =เช้า!J9+'บ่าย '!J9+'เย็น '!J9 -> 0 | K9: =SUM(D9:J9) -> 11 | P9: =(L9+M9+N9+O9)-K9 -> -11 | R9: 10 | T9: =S9+R9+P9 -> -1 | W9: 1004055 | X9: ชิฟฟอนรวมรส 4 ชิ้น | Y9: 250
B10: 1004055 | C10: ชิฟฟอนรวมรส 4 ชิ้น | D10: =เช้า!D10+'บ่าย '!D10+'เย็น '!D10 -> 6 | E10: =เช้า!E10+'บ่าย '!E10+'เย็น '!E10 -> 0 | F10: =เช้า!F10+'บ่าย '!F10+'เย็น '!F10 -> 3 | G10: =เช้า!G10+'บ่าย '!G10+'เย็น '!G10 -> 64 | H10: =เช้า!H10+'บ่าย '!H10+'เย็น '!H10 -> 0 | I10: =เช้า!I10+'บ่าย '!I10+'เย็น '!I10 -> 0 | J10: =เช้า!J10+'บ่าย '!J10+'เย็น '!J10 -> 0 | K10: =SUM(D10:J10) -> 73 | P10: =(L10+M10+N10+O10)-K10 -> -73 | R10: 250 | S10: 250 | T10: =S10+R10+P10 -> 427 | W10: 1111057 | X10: ชิฟฟอนแยกชิ้น กาแฟ | Y10: 50
B11: 1111057 | C11: ชิฟฟอนแยกชิ้น กาแฟ | D11: =เช้า!D11+'บ่าย '!D11+'เย็น '!D11 -> 1 | E11: =เช้า!E11+'บ่าย '!E11+'เย็น '!E11 -> 0 | F11: =เช้า!F11+'บ่าย '!F11+'เย็น '!F11 -> 0 | G11: =เช้า!G11+'บ่าย '!G11+'เย็น '!G11 -> 6 | H11: =เช้า!H11+'บ่าย '!H11+'เย็น '!H11 -> 0 | I11: =เช้า!I11+'บ่าย '!I11+'เย็น '!I11 -> 0 | J11: =เช้า!J11+'บ่าย '!J11+'เย็น '!J11 -> 1 | K11: =SUM(D11:J11) -> 8 | P11: =(L11+M11+N11+O11)-K11 -> -8 | S11: 50 | T11: =S11+R11+P11 -> 42 | W11: 1111058 | X11: ชิฟฟอนแยกชิ้น ชาเขียว | Y11: 50
B12: 1111058 | C12: ชิฟฟอนแยกชิ้น ชาเขียว | D12: =เช้า!D12+'บ่าย '!D12+'เย็น '!D12 -> 1 | E12: =เช้า!E12+'บ่าย '!E12+'เย็น '!E12 -> 0 | F12: =เช้า!F12+'บ่าย '!F12+'เย็น '!F12 -> 0 | G12: =เช้า!G12+'บ่าย '!G12+'เย็น '!G12 -> 5 | H12: =เช้า!H12+'บ่าย '!H12+'เย็น '!H12 -> 0 | I12: =เช้า!I12+'บ่าย '!I12+'เย็น '!I12 -> 0 | J12: =เช้า!J12+'บ่าย '!J12+'เย็น '!J12 -> 0 | K12: =SUM(D12:J12) -> 6 | P12: =(L12+M12+N12+O12)-K12 -> -6 | S12: 50 | T12: =S12+R12+P12 -> 44 | W12: 1111059 | X12: ชิฟฟอนแยกชิ้น ใบเตย | Y12: 50
B13: 1111059 | C13: ชิฟฟอนแยกชิ้น ใบเตย | D13: =เช้า!D13+'บ่าย '!D13+'เย็น '!D13 -> 1 | E13: =เช้า!E13+'บ่าย '!E13+'เย็น '!E13 -> 0 | F13: =เช้า!F13+'บ่าย '!F13+'เย็น '!F13 -> 0 | G13: =เช้า!G13+'บ่าย '!G13+'เย็น '!G13 -> 5 | H13: =เช้า!H13+'บ่าย '!H13+'เย็น '!H13 -> 0 | I13: =เช้า!I13+'บ่าย '!I13+'เย็น '!I13 -> 0 | J13: =เช้า!J13+'บ่าย '!J13+'เย็น '!J13 -> 0 | K13: =SUM(D13:J13) -> 6 | P13: =(L13+M13+N13+O13)-K13 -> -6 | S13: 50 | T13: =S13+R13+P13 -> 44 | W13: 1111060 | X13: ชิฟฟอนแยกชิ้น กล้วยหอม | Y13: 50
B14: 1111060 | C14: ชิฟฟอนแยกชิ้น กล้วยหอม | D14: =เช้า!D14+'บ่าย '!D14+'เย็น '!D14 -> 1 | E14: =เช้า!E14+'บ่าย '!E14+'เย็น '!E14 -> 0 | F14: =เช้า!F14+'บ่าย '!F14+'เย็น '!F14 -> 0 | G14: =เช้า!G14+'บ่าย '!G14+'เย็น '!G14 -> 3 | H14: =เช้า!H14+'บ่าย '!H14+'เย็น '!H14 -> 0 | I14: =เช้า!I14+'บ่าย '!I14+'เย็น '!I14 -> 0 | J14: =เช้า!J14+'บ่าย '!J14+'เย็น '!J14 -> 0 | K14: =SUM(D14:J14) -> 4 | P14: =(L14+M14+N14+O14)-K14 -> -4 | S14: 50 | T14: =S14+R14+P14 -> 46 | W14: 1111061 | X14: ชิฟฟอนแยกชิ้น ชาไทย | Y14: 50
B15: 1111061 | C15: ชิฟฟอนแยกชิ้น ชาไทย | D15: =เช้า!D15+'บ่าย '!D15+'เย็น '!D15 -> 1 | E15: =เช้า!E15+'บ่าย '!E15+'เย็น '!E15 -> 0 | F15: =เช้า!F15+'บ่าย '!F15+'เย็น '!F15 -> 0 | G15: =เช้า!G15+'บ่าย '!G15+'เย็น '!G15 -> 5 | H15: =เช้า!H15+'บ่าย '!H15+'เย็น '!H15 -> 0 | I15: =เช้า!I15+'บ่าย '!I15+'เย็น '!I15 -> 0 | J15: =เช้า!J15+'บ่าย '!J15+'เย็น '!J15 -> 0 | K15: =SUM(D15:J15) -> 6 | P15: =(L15+M15+N15+O15)-K15 -> -6 | S15: 50 | T15: =S15+R15+P15 -> 44 | W15: 1111062 | X15: ชิฟฟอนแยกชิ้น โกโก้ | Y15: 50
B16: 1111062 | C16: ชิฟฟอนแยกชิ้น โกโก้ | D16: =เช้า!D16+'บ่าย '!D16+'เย็น '!D16 -> 1 | E16: =เช้า!E16+'บ่าย '!E16+'เย็น '!E16 -> 0 | F16: =เช้า!F16+'บ่าย '!F16+'เย็น '!F16 -> 0 | G16: =เช้า!G16+'บ่าย '!G16+'เย็น '!G16 -> 2 | H16: =เช้า!H16+'บ่าย '!H16+'เย็น '!H16 -> 0 | I16: =เช้า!I16+'บ่าย '!I16+'เย็น '!I16 -> 0 | J16: =เช้า!J16+'บ่าย '!J16+'เย็น '!J16 -> 0 | K16: =SUM(D16:J16) -> 3 | P16: =(L16+M16+N16+O16)-K16 -> -3 | S16: 50 | T16: =S16+R16+P16 -> 47 | W16: 1111063 | X16: ชิฟฟอนแยกชิ้น ส้ม | Y16: 50
B17: 1111063 | C17: ชิฟฟอนแยกชิ้น ส้ม | D17: =เช้า!D17+'บ่าย '!D17+'เย็น '!D17 -> 1 | E17: =เช้า!E17+'บ่าย '!E17+'เย็น '!E17 -> 0 | F17: =เช้า!F17+'บ่าย '!F17+'เย็น '!F17 -> 0 | G17: =เช้า!G17+'บ่าย '!G17+'เย็น '!G17 -> 4 | H17: =เช้า!H17+'บ่าย '!H17+'เย็น '!H17 -> 0 | I17: =เช้า!I17+'บ่าย '!I17+'เย็น '!I17 -> 0 | J17: =เช้า!J17+'บ่าย '!J17+'เย็น '!J17 -> 0 | K17: =SUM(D17:J17) -> 5 | P17: =(L17+M17+N17+O17)-K17 -> -5 | S17: 50 | T17: =S17+R17+P17 -> 45 | W17: 1111064 | X17: ชิฟฟอนแยกชิ้น เผือก | Y17: 50
B18: 1111064 | C18: ชิฟฟอนแยกชิ้น เผือก | D18: =เช้า!D18+'บ่าย '!D18+'เย็น '!D18 -> 1 | E18: =เช้า!E18+'บ่าย '!E18+'เย็น '!E18 -> 0 | F18: =เช้า!F18+'บ่าย '!F18+'เย็น '!F18 -> 0 | G18: =เช้า!G18+'บ่าย '!G18+'เย็น '!G18 -> 4 | H18: =เช้า!H18+'บ่าย '!H18+'เย็น '!H18 -> 0 | I18: =เช้า!I18+'บ่าย '!I18+'เย็น '!I18 -> 0 | J18: =เช้า!J18+'บ่าย '!J18+'เย็น '!J18 -> 0 | K18: =SUM(D18:J18) -> 5 | P18: =(L18+M18+N18+O18)-K18 -> -5 | S18: 50 | T18: =S18+R18+P18 -> 45 | W18: 1111065 | X18: ชิฟฟอนแยกชิ้น สับปะรด | Y18: 50
B19: 1111065 | C19: ชิฟฟอนแยกชิ้น สับปะรด | D19: =เช้า!D19+'บ่าย '!D19+'เย็น '!D19 -> 1 | E19: =เช้า!E19+'บ่าย '!E19+'เย็น '!E19 -> 0 | F19: =เช้า!F19+'บ่าย '!F19+'เย็น '!F19 -> 0 | G19: =เช้า!G19+'บ่าย '!G19+'เย็น '!G19 -> 2 | H19: =เช้า!H19+'บ่าย '!H19+'เย็น '!H19 -> 0 | I19: =เช้า!I19+'บ่าย '!I19+'เย็น '!I19 -> 0 | J19: =เช้า!J19+'บ่าย '!J19+'เย็น '!J19 -> 0 | K19: =SUM(D19:J19) -> 3 | P19: =(L19+M19+N19+O19)-K19 -> -3 | S19: 50 | T19: =S19+R19+P19 -> 47 | W19: 1111066 | X19: ชิฟฟอนแยกชิ้น สตอเบอรี่ | Y19: 50
B20: 1111066 | C20: ชิฟฟอนแยกชิ้น สตอเบอรี่ | D20: =เช้า!D20+'บ่าย '!D20+'เย็น '!D20 -> 1 | E20: =เช้า!E20+'บ่าย '!E20+'เย็น '!E20 -> 0 | F20: =เช้า!F20+'บ่าย '!F20+'เย็น '!F20 -> 0 | G20: =เช้า!G20+'บ่าย '!G20+'เย็น '!G20 -> 4 | H20: =เช้า!H20+'บ่าย '!H20+'เย็น '!H20 -> 0 | I20: =เช้า!I20+'บ่าย '!I20+'เย็น '!I20 -> 0 | J20: =เช้า!J20+'บ่าย '!J20+'เย็น '!J20 -> 0 | K20: =SUM(D20:J20) -> 5 | P20: =(L20+M20+N20+O20)-K20 -> -5 | S20: 50 | T20: =S20+R20+P20 -> 45 | W20: 1111067 | X20: ชิฟฟอนแยกชิ้น มะพร้าว | Y20: 50
B21: 1111067 | C21: ชิฟฟอนแยกชิ้น มะพร้าว | D21: =เช้า!D21+'บ่าย '!D21+'เย็น '!D21 -> 1 | E21: =เช้า!E21+'บ่าย '!E21+'เย็น '!E21 -> 0 | F21: =เช้า!F21+'บ่าย '!F21+'เย็น '!F21 -> 0 | G21: =เช้า!G21+'บ่าย '!G21+'เย็น '!G21 -> 4 | H21: =เช้า!H21+'บ่าย '!H21+'เย็น '!H21 -> 0 | I21: =เช้า!I21+'บ่าย '!I21+'เย็น '!I21 -> 0 | J21: =เช้า!J21+'บ่าย '!J21+'เย็น '!J21 -> 0 | K21: =SUM(D21:J21) -> 5 | P21: =(L21+M21+N21+O21)-K21 -> -5 | S21: 50 | T21: =S21+R21+P21 -> 45 | W21: 1111068 | X21: ชิฟฟอนแยกชิ้น เนย | Y21: 50
B22: 1111068 | C22: ชิฟฟอนแยกชิ้น เนย | D22: =เช้า!D22+'บ่าย '!D22+'เย็น '!D22 -> 1 | E22: =เช้า!E22+'บ่าย '!E22+'เย็น '!E22 -> 0 | F22: =เช้า!F22+'บ่าย '!F22+'เย็น '!F22 -> 0 | G22: =เช้า!G22+'บ่าย '!G22+'เย็น '!G22 -> 4 | H22: =เช้า!H22+'บ่าย '!H22+'เย็น '!H22 -> 0 | I22: =เช้า!I22+'บ่าย '!I22+'เย็น '!I22 -> 0 | J22: =เช้า!J22+'บ่าย '!J22+'เย็น '!J22 -> 0 | K22: =SUM(D22:J22) -> 5 | P22: =(L22+M22+N22+O22)-K22 -> -5 | S22: 50 | T22: =S22+R22+P22 -> 45 | W22: 1111069 | X22: ชิฟฟอนแยกชิ้น บลูเบอรี่ | Y22: 50
... B25: 1111071 | C25: ชิฟฟอนแยกชิ้น ตาล | D25: =เช้า!D25+'บ่าย '!D25+'เย็น '!D25 -> 1 | E25: =เช้า!E25+'บ่าย '!E25+'เย็น '!E25 -> 0 | F25: =เช้า!F25+'บ่าย '!F25+'เย็น '!F25 -> 0 | G25: =เช้า!G25+'บ่าย '!G25+'เย็น '!G25 -> 2 | H25: =เช้า!H25+'บ่าย '!H25+'เย็น '!H25 -> 0 | I25: =เช้า!I25+'บ่าย '!I25+'เย็น '!I25 -> 0 | J25: =เช้า!J25+'บ่าย '!J25+'เย็น '!J25 -> 0 | K25: =SUM(D25:J25) -> 3 | P25: =(L25+M25+N25+O25)-K25 -> -3 | S25: 50 | T25: =S25+R25+P25 -> 47 | W25: 1111074 | X25: ชิฟฟอนไส้แยมแยกชิ้น มะพร้าว | Y25: 40
B26: 1111001 | C26: ชิฟฟอนแยกชิ้น คละรส | D26: =เช้า!D26+'บ่าย '!D26+'เย็น '!D26 -> 0 | E26: =เช้า!E26+'บ่าย '!E26+'เย็น '!E26 -> 0 | F26: =เช้า!F26+'บ่าย '!F26+'เย็น '!F26 -> 0 | G26: =เช้า!G26+'บ่าย '!G26+'เย็น '!G26 -> 0 | H26: =เช้า!H26+'บ่าย '!H26+'เย็น '!H26 -> 0 | I26: =เช้า!I26+'บ่าย '!I26+'เย็น '!I26 -> 0 | J26: =เช้า!J26+'บ่าย '!J26+'เย็น '!J26 -> 0 | K26: =SUM(D26:J26) -> 0 | P26: =(L26+M26+N26+O26)-K26 -> 0 | T26: =S26+R26+P26 -> 0 | W26: 1111075 | X26: ชิฟฟอนไส้แยมแยกชิ้น สตอเบอรี่ | Y26: 40
B27: 1111074 | C27: ชิฟฟอนไส้แยมแยกชิ้น มะพร้าว | D27: =เช้า!D27+'บ่าย '!D27+'เย็น '!D27 -> 0 | E27: =เช้า!E27+'บ่าย '!E27+'เย็น '!E27 -> 1 | F27: =เช้า!F27+'บ่าย '!F27+'เย็น '!F27 -> 0 | G27: =เช้า!G27+'บ่าย '!G27+'เย็น '!G27 -> 2 | H27: =เช้า!H27+'บ่าย '!H27+'เย็น '!H27 -> 0 | I27: =เช้า!I27+'บ่าย '!I27+'เย็น '!I27 -> 0 | J27: =เช้า!J27+'บ่าย '!J27+'เย็น '!J27 -> 0 | K27: =SUM(D27:J27) -> 3 | P27: =(L27+M27+N27+O27)-K27 -> -3 | S27: 40 | T27: =S27+R27+P27 -> 37 | W27: 1111076 | X27: ชิฟฟอนไส้แยมแยกชิ้น ส้ม | Y27: 40
B28: 1111075 | C28: ชิฟฟอนไส้แยมแยกชิ้น สตอเบอรี่ | D28: =เช้า!D28+'บ่าย '!D28+'เย็น '!D28 -> 0 | E28: =เช้า!E28+'บ่าย '!E28+'เย็น '!E28 -> 1 | F28: =เช้า!F28+'บ่าย '!F28+'เย็น '!F28 -> 0 | G28: =เช้า!G28+'บ่าย '!G28+'เย็น '!G28 -> 2 | H28: =เช้า!H28+'บ่าย '!H28+'เย็น '!H28 -> 0 | I28: =เช้า!I28+'บ่าย '!I28+'เย็น '!I28 -> 0 | J28: =เช้า!J28+'บ่าย '!J28+'เย็น '!J28 -> 0 | K28: =SUM(D28:J28) -> 3 | P28: =(L28+M28+N28+O28)-K28 -> -3 | S28: 40 | T28: =S28+R28+P28 -> 37 | W28: 1111077 | X28: ชิฟฟอนไส้แยมแยกชิ้น บลูเบอรี่ | Y28: 40
B29: 1111076 | C29: ชิฟฟอนไส้แยมแยกชิ้น ส้ม | D29: =เช้า!D29+'บ่าย '!D29+'เย็น '!D29 -> 0 | E29: =เช้า!E29+'บ่าย '!E29+'เย็น '!E29 -> 1 | F29: =เช้า!F29+'บ่าย '!F29+'เย็น '!F29 -> 0 | G29: =เช้า!G29+'บ่าย '!G29+'เย็น '!G29 -> 2 | H29: =เช้า!H29+'บ่าย '!H29+'เย็น '!H29 -> 0 | I29: =เช้า!I29+'บ่าย '!I29+'เย็น '!I29 -> 0 | J29: =เช้า!J29+'บ่าย '!J29+'เย็น '!J29 -> 0 | K29: =SUM(D29:J29) -> 3 | P29: =(L29+M29+N29+O29)-K29 -> -3 | S29: 40 | T29: =S29+R29+P29 -> 37 | W29: 1111078 | X29: ชิฟฟอนไส้แยมแยกชิ้น นมชมพู | Y29: 40
B30: 1111077 | C30: ชิฟฟอนไส้แยมแยกชิ้น บลูเบอรี่ | D30: =เช้า!D30+'บ่าย '!D30+'เย็น '!D30 -> 0 | E30: =เช้า!E30+'บ่าย '!E30+'เย็น '!E30 -> 1 | F30: =เช้า!F30+'บ่าย '!F30+'เย็น '!F30 -> 0 | G30: =เช้า!G30+'บ่าย '!G30+'เย็น '!G30 -> 2 | H30: =เช้า!H30+'บ่าย '!H30+'เย็น '!H30 -> 0 | I30: =เช้า!I30+'บ่าย '!I30+'เย็น '!I30 -> 0 | J30: =เช้า!J30+'บ่าย '!J30+'เย็น '!J30 -> 0 | K30: =SUM(D30:J30) -> 3 | P30: =(L30+M30+N30+O30)-K30 -> -3 | S30: 40 | T30: =S30+R30+P30 -> 37 | W30: 1111079 | X30: ชิฟฟอนไส้แยมแยกชิ้น ชอคโกแลต | Y30: 40
B31: 1111078 | C31: ชิฟฟอนไส้แยมแยกชิ้น นมชมพู | D31: =เช้า!D31+'บ่าย '!D31+'เย็น '!D31 -> 0 | E31: =เช้า!E31+'บ่าย '!E31+'เย็น '!E31 -> 1 | F31: =เช้า!F31+'บ่าย '!F31+'เย็น '!F31 -> 0 | G31: =เช้า!G31+'บ่าย '!G31+'เย็น '!G31 -> 2 | H31: =เช้า!H31+'บ่าย '!H31+'เย็น '!H31 -> 0 | I31: =เช้า!I31+'บ่าย '!I31+'เย็น '!I31 -> 0 | J31: =เช้า!J31+'บ่าย '!J31+'เย็น '!J31 -> 0 | K31: =SUM(D31:J31) -> 3 | P31: =(L31+M31+N31+O31)-K31 -> -3 | S31: 40 | T31: =S31+R31+P31 -> 37 | W31: 1111080 | X31: ชิฟฟอนไส้แยมแยกชิ้น ฝอยทอง | Y31: 40
B32: 1111079 | C32: ชิฟฟอนไส้แยมแยกชิ้น ชอคโกแลต | D32: =เช้า!D32+'บ่าย '!D32+'เย็น '!D32 -> 0 | E32: =เช้า!E32+'บ่าย '!E32+'เย็น '!E32 -> 1 | F32: =เช้า!F32+'บ่าย '!F32+'เย็น '!F32 -> 0 | G32: =เช้า!G32+'บ่าย '!G32+'เย็น '!G32 -> 0 | H32: =เช้า!H32+'บ่าย '!H32+'เย็น '!H32 -> 0 | I32: =เช้า!I32+'บ่าย '!I32+'เย็น '!I32 -> 0 | J32: =เช้า!J32+'บ่าย '!J32+'เย็น '!J32 -> 0 | K32: =SUM(D32:J32) -> 1 | P32: =(L32+M32+N32+O32)-K32 -> -1 | S32: 40 | T32: =S32+R32+P32 -> 39 | W32: 1111081 | X32: ชิฟฟอนไส้แยมแยกชิ้น วนิลา | Y32: 40
B33: 1111080 | C33: ชิฟฟอนไส้แยมแยกชิ้น ฝอยทอง | D33: =เช้า!D33+'บ่าย '!D33+'เย็น '!D33 -> 0 | E33: =เช้า!E33+'บ่าย '!E33+'เย็น '!E33 -> 1 | F33: =เช้า!F33+'บ่าย '!F33+'เย็น '!F33 -> 0 | G33: =เช้า!G33+'บ่าย '!G33+'เย็น '!G33 -> 0 | H33: =เช้า!H33+'บ่าย '!H33+'เย็น '!H33 -> 0 | I33: =เช้า!I33+'บ่าย '!I33+'เย็น '!I33 -> 0 | J33: =เช้า!J33+'บ่าย '!J33+'เย็น '!J33 -> 0 | K33: =SUM(D33:J33) -> 1 | P33: =(L33+M33+N33+O33)-K33 -> -1 | S33: 40 | T33: =S33+R33+P33 -> 39 | W33: 1111082 | X33: ชิฟฟอนไส้แยมแยกชิ้น ใบเตย | Y33: 40
B34: 1111081 | C34: ชิฟฟอนไส้แยมแยกชิ้น วนิลา | D34: =เช้า!D34+'บ่าย '!D34+'เย็น '!D34 -> 0 | E34: =เช้า!E34+'บ่าย '!E34+'เย็น '!E34 -> 1 | F34: =เช้า!F34+'บ่าย '!F34+'เย็น '!F34 -> 0 | G34: =เช้า!G34+'บ่าย '!G34+'เย็น '!G34 -> 0 | H34: =เช้า!H34+'บ่าย '!H34+'เย็น '!H34 -> 0 | I34: =เช้า!I34+'บ่าย '!I34+'เย็น '!I34 -> 0 | J34: =เช้า!J34+'บ่าย '!J34+'เย็น '!J34 -> 0 | K34: =SUM(D34:J34) -> 1 | P34: =(L34+M34+N34+O34)-K34 -> -1 | S34: 40 | T34: =S34+R34+P34 -> 39 | W34: 1111083 | X34: ชิฟฟอนไส้แยมแยกชิ้น เมล่อน | Y34: 40
B35: 1111082 | C35: ชิฟฟอนไส้แยมแยกชิ้น ใบเตย | D35: =เช้า!D35+'บ่าย '!D35+'เย็น '!D35 -> 0 | E35: =เช้า!E35+'บ่าย '!E35+'เย็น '!E35 -> 1 | F35: =เช้า!F35+'บ่าย '!F35+'เย็น '!F35 -> 0 | G35: =เช้า!G35+'บ่าย '!G35+'เย็น '!G35 -> 0 | H35: =เช้า!H35+'บ่าย '!H35+'เย็น '!H35 -> 0 | I35: =เช้า!I35+'บ่าย '!I35+'เย็น '!I35 -> 0 | J35: =เช้า!J35+'บ่าย '!J35+'เย็น '!J35 -> 0 | K35: =SUM(D35:J35) -> 1 | P35: =(L35+M35+N35+O35)-K35 -> -1 | S35: 40 | T35: =S35+R35+P35 -> 39 | W35: 1111009 | X35: ชิฟฟอนไส้แยมรวมรส 6 ชิ้น | Y35: 20
B36: 1111083 | C36: ชิฟฟอนไส้แยมแยกชิ้น เมล่อน | D36: =เช้า!D36+'บ่าย '!D36+'เย็น '!D36 -> 0 | E36: =เช้า!E36+'บ่าย '!E36+'เย็น '!E36 -> 1 | F36: =เช้า!F36+'บ่าย '!F36+'เย็น '!F36 -> 0 | G36: =เช้า!G36+'บ่าย '!G36+'เย็น '!G36 -> 0 | H36: =เช้า!H36+'บ่าย '!H36+'เย็น '!H36 -> 0 | I36: =เช้า!I36+'บ่าย '!I36+'เย็น '!I36 -> 0 | J36: =เช้า!J36+'บ่าย '!J36+'เย็น '!J36 -> 0 | K36: =SUM(D36:J36) -> 1 | P36: =(L36+M36+N36+O36)-K36 -> -1 | S36: 40 | T36: =S36+R36+P36 -> 39 | W36: 1111008 | X36: ชิฟฟอนไส้แยมรวมรส 3 ชิ้น | Y36: 250
B37: 1111010 | C37: ชิฟฟอนไส้แยมแยกชิ้น คละรส | D37: =เช้า!D37+'บ่าย '!D37+'เย็น '!D37 -> 0 | E37: =เช้า!E37+'บ่าย '!E37+'เย็น '!E37 -> 0 | F37: =เช้า!F37+'บ่าย '!F37+'เย็น '!F37 -> 0 | G37: =เช้า!G37+'บ่าย '!G37+'เย็น '!G37 -> 0 | H37: =เช้า!H37+'บ่าย '!H37+'เย็น '!H37 -> 0 | I37: =เช้า!I37+'บ่าย '!I37+'เย็น '!I37 -> 0 | J37: =เช้า!J37+'บ่าย '!J37+'เย็น '!J37 -> 0 | K37: =SUM(D37:J37) -> 0 | P37: =(L37+M37+N37+O37)-K37 -> 0 | T37: =S37+R37+P37 -> 0
C38: รวม | D38: =เช้า!D38+'บ่าย '!D38+'เย็น '!D38 -> 0 | E38: =เช้า!E38+'บ่าย '!E38+'เย็น '!E38 -> 0 | F38: =เช้า!F38+'บ่าย '!F38+'เย็น '!F38 -> 0 | G38: =เช้า!G38+'บ่าย '!G38+'เย็น '!G38 -> 0 | H38: =เช้า!H38+'บ่าย '!H38+'เย็น '!H38 -> 0 | I38: =เช้า!I38+'บ่าย '!I38+'เย็น '!I38 -> 0 | J38: =เช้า!J38+'บ่าย '!J38+'เย็น '!J38 -> 0 | K38: =SUM(D38:J38) -> 0 | P38: =(L38+M38+N38+O38)-K38 -> 0 | T38: =S38+R38+P38 -> 0 | W38: 1114501 | X38: ครีมฮอร์นไส้เนย วนิลา | Y38: 400
B39: ชิฟฟอนไส้แยม 6 ชิ้น | T39: =S39+R39+P39 -> 0 | W39: 1114503 | X39: ครีมฮอร์นไส้เนย ชอค | Y39: 400
B40: 1111009 | C40: ชิฟฟอนไส้แยมรวมรส 6 ชิ้น | D40: =เช้า!D40+'บ่าย '!D40+'เย็น '!D40 -> 0 | E40: =เช้า!E40+'บ่าย '!E40+'เย็น '!E40 -> 0 | F40: =เช้า!F40+'บ่าย '!F40+'เย็น '!F40 -> 6 | G40: =เช้า!G40+'บ่าย '!G40+'เย็น '!G40 -> 8 | H40: =เช้า!H40+'บ่าย '!H40+'เย็น '!H40 -> 0 | I40: =เช้า!I40+'บ่าย '!I40+'เย็น '!I40 -> 0 | J40: =เช้า!J40+'บ่าย '!J40+'เย็น '!J40 -> 0 | K40: =SUM(D40:J40) -> 14 | P40: =(L40+M40+N40+O40)-K40 -> -14 | S40: 20 | T40: =S40+R40+P40 -> 6 | W40: 1124021 | X40: ขนมปังหั่นสไลด์ | Y40: 400
B41: ชิฟฟอนไส้แยม 3 ชิ้น | T41: =S41+R41+P41 -> 0
B42: 1111008 | C42: ชิฟฟอนไส้แยมรวมรส 3 ชิ้น | D42: =เช้า!D42+'บ่าย '!D42+'เย็น '!D42 -> 30 | E42: =เช้า!E42+'บ่าย '!E42+'เย็น '!E42 -> 9 | F42: =เช้า!F42+'บ่าย '!F42+'เย็น '!F42 -> 0 | G42: =เช้า!G42+'บ่าย '!G42+'เย็น '!G42 -> 89 | H42: =เช้า!H42+'บ่าย '!H42+'เย็น '!H42 -> 0 | I42: =เช้า!I42+'บ่าย '!I42+'เย็น '!I42 -> 0 | J42: =เช้า!J42+'บ่าย '!J42+'เย็น '!J42 -> 0 | K42: =SUM(D42:J42) -> 128 | P42: =(L42+M42+N42+O42)-K42 -> -128 | S42: 250 | T42: =S42+R42+P42 -> 122
B43: เบาหวิว ล 110 กรัม | T43: =S43+R43+P43 -> 0
...
