Workbook

Sheet เย็น  
B1: ยอดจริง ออนไลน์ วันที่ 21/11/2567 - บ่าย
K2: ยอดรวมผลิต
K3: จำนวน
B4: รหัสสินค้า | C4: สินค้า | D4: ปณ | E4: ชอปปี้ | F4: ลาซาด้า | G4: ติ๊กตอก | H4: ติ๊กตอก2 | I4: ติ๊กตอก3 | J4: ชอยส์ | K4: (กล่อง)
B6: ชิฟฟอนรวมรส
B7: 1111002 | C7: ชิฟฟอนรวมรส 8 ชิ้น | K7: =SUM(D7:J7) -> 0
B8: 1111043 | C8: ชิฟฟอน 8 ชิ้น มะลิ | K8: =SUM(D8:J8) -> 0
B9: 1111056 | C9: ชิฟฟอน 8 ชิ้น รวมรสยอดฮิต | K9: =SUM(D9:J9) -> 0
B10: 1004055 | C10: ชิฟฟอนรวมรส 4 ชิ้น | K10: =SUM(D10:J10) -> 0
B11: 1111057 | C11: ชิฟฟอนแยกชิ้น กาแฟ | K11: =SUM(D11:J11) -> 0
B12: 1111058 | C12: ชิฟฟอนแยกชิ้น ชาเขียว | K12: =SUM(D12:J12) -> 0
B13: 1111059 | C13: ชิฟฟอนแยกชิ้น ใบเตย | K13: =SUM(D13:J13) -> 0
B14: 1111060 | C14: ชิฟฟอนแยกชิ้น กล้วยหอม | K14: =SUM(D14:J14) -> 0
B15: 1111061 | C15: ชิฟฟอนแยกชิ้น ชาไทย | K15: =SUM(D15:J15) -> 0
B16: 1111062 | C16: ชิฟฟอนแยกชิ้น โกโก้ | K16: =SUM(D16:J16) -> 0
B17: 1111063 | C17: ชิฟฟอนแยกชิ้น ส้ม | K17: =SUM(D17:J17) -> 0
B18: 1111064 | C18: ชิฟฟอนแยกชิ้น เผือก | K18: =SUM(D18:J18) -> 0
... B37: 1111010 | C37: ชิฟฟอนไส้แยมแยกชิ้น คละรส | K37: =SUM(D37:J37) -> 0
C38: รวม | K38: =SUM(D38:I38) -> 0
B39: ชิฟฟอนไส้แยม 6 ชิ้น
B40: 1111009 | C40: ชิฟฟอนไส้แยมรวมรส 6 ชิ้น | K40: =SUM(D40:J40) -> 0
B41: ชิฟฟอนไส้แยม 3 ชิ้น
B42: 1111008 | C42: ชิฟฟอนไส้แยมรวมรส 3 ชิ้น | K42: =SUM(D42:J42) -> 0
B43: เบาหวิว ล 110 กรัม
B44: 1112009 | C44: มะพร้าว | K44: =SUM(D44:J44) -> 0
B45: 1112011 | C45: ฝอยทอง | K45: =SUM(D45:J45) -> 0
B46: 1112003 | C46: กาแฟ | K46: =SUM(D46:J46) -> 0
B47: 1112005 | C47: เนยนม | K47: =SUM(D47:J47) -> 0
B48: 1112007 | C48: ใบเตย | K48: =SUM(D48:J48) -> 0
B49: 1112019 | C49: ทุเรียน | K49: =SUM(D49:J49) -> 0
B50: 1112017 | C50: ตาลหอม | K50: =SUM(D50:J50) -> 0
B51: 1112015 | C51: กล้วยหอมมะพร้าวเผา | K51: =SUM(D51:J51) -> 0
B52: 1112013 | C52: เผือกมะพร้าวอ่อน | K52: =SUM(D52:J52) -> 0
B53: 1124043 | C53: เบาหวิว คละรส | K53: =SUM(D53:J53) -> 0
C54: รวม
B55: อื่นๆ
B56: 1100003 | C56: เมอแรงค์ กระปุก | K56: =SUM(D56:J56) -> 0
B57: 1100001 | C57: พายสับปรด 1 ชิ้น | K57: =SUM(D57:J57) -> 0
B58: 1100002 | C58: พายสับปรด 1 กล่อง | K58: =SUM(D58:J58) -> 0
B59: 1200001 | C59: คอนเฟลค | K59: =SUM(D59:J59) -> 0
...

Sheet เช้า
B1: ยอดจริง ออนไลน์ วันที่ 21/11/2567 - เช้า
K2: ยอดรวมผลิต
K3: จำนวน
B4: รหัสสินค้า | C4: สินค้า | D4: ปณ | E4: ชอปปี้ | F4: ลาซาด้า | G4: ติ๊กตอก | H4: ติ๊กตอก2 | I4: ติ๊กตอก3 | J4: ชอยส์ | K4: (กล่อง)
B6: ชิฟฟอนรวมรส
B7: 1111002 | C7: ชิฟฟอนรวมรส 8 ชิ้น | E7: 9 | F7: 48 | K7: =SUM(D7:J7) -> 57
B8: 1111043 | C8: ชิฟฟอน 8 ชิ้น มะลิ | K8: =SUM(D8:J8) -> 0
B9: 1111056 | C9: ชิฟฟอน 8 ชิ้น รวมรสยอดฮิต | E9: 7 | F9: 6 | G9: 1 | K9: =SUM(D9:J9) -> 14
B10: 1004055 | C10: ชิฟฟอนรวมรส 4 ชิ้น | E10: 7 | G10: 52 | K10: =SUM(D10:J10) -> 59
B11: 1111057 | C11: ชิฟฟอนแยกชิ้น กาแฟ | G11: 6 | K11: =SUM(D11:J11) -> 6
B12: 1111058 | C12: ชิฟฟอนแยกชิ้น ชาเขียว | G12: 6 | K12: =SUM(D12:J12) -> 6
B13: 1111059 | C13: ชิฟฟอนแยกชิ้น ใบเตย | G13: 6 | K13: =SUM(D13:J13) -> 6
B14: 1111060 | C14: ชิฟฟอนแยกชิ้น กล้วยหอม | G14: 4 | K14: =SUM(D14:J14) -> 4
B15: 1111061 | C15: ชิฟฟอนแยกชิ้น ชาไทย | G15: 3 | K15: =SUM(D15:J15) -> 3
B16: 1111062 | C16: ชิฟฟอนแยกชิ้น โกโก้ | G16: 1 | K16: =SUM(D16:J16) -> 1
B17: 1111063 | C17: ชิฟฟอนแยกชิ้น ส้ม | G17: 5 | K17: =SUM(D17:J17) -> 5
B18: 1111064 | C18: ชิฟฟอนแยกชิ้น เผือก | G18: 3 | K18: =SUM(D18:J18) -> 3
B19: 1111065 | C19: ชิฟฟอนแยกชิ้น สับปะรด | G19: 3 | K19: =SUM(D19:J19) -> 3
B20: 1111066 | C20: ชิฟฟอนแยกชิ้น สตอเบอรี่ | G20: 4 | K20: =SUM(D20:J20) -> 4
B21: 1111067 | C21: ชิฟฟอนแยกชิ้น มะพร้าว | G21: 4 | K21: =SUM(D21:J21) -> 4
B22: 1111068 | C22: ชิฟฟอนแยกชิ้น เนย | G22: 4 | K22: =SUM(D22:J22) -> 4
B23: 1111069 | C23: ชิฟฟอนแยกชิ้น บลูเบอรี่ | G23: 4 | K23: =SUM(D23:J23) -> 4
B24: 1111070 | C24: ชิฟฟอนแยกชิ้น ทุเรียน | K24: =SUM(D24:J24) -> 0
B25: 1111071 | C25: ชิฟฟอนแยกชิ้น ตาล | K25: =SUM(D25:J25) -> 0
B26: 1111001 | C26: ชิฟฟอนแยกชิ้น คละรส | K26: =SUM(D26:J26) -> 0
B27: 1111074 | C27: ชิฟฟอนไส้แยมแยกชิ้น มะพร้าว | G27: 3 | K27: =SUM(D27:J27) -> 3
B28: 1111075 | C28: ชิฟฟอนไส้แยมแยกชิ้น สตอเบอรี่ | G28: 3 | K28: =SUM(D28:J28) -> 3
B29: 1111076 | C29: ชิฟฟอนไส้แยมแยกชิ้น ส้ม | G29: 3 | K29: =SUM(D29:J29) -> 3
B30: 1111077 | C30: ชิฟฟอนไส้แยมแยกชิ้น บลูเบอรี่ | E30: 1 | G30: 3 | K30: =SUM(D30:J30) -> 4
B31: 1111078 | C31: ชิฟฟอนไส้แยมแยกชิ้น นมชมพู | E31: 1 | G31: 3 | K31: =SUM(D31:J31) -> 4
B32: 1111079 | C32: ชิฟฟอนไส้แยมแยกชิ้น ชอคโกแลต | E32: 1 | G32: 3 | K32: =SUM(D32:J32) -> 4
B33: 1111080 | C33: ชิฟฟอนไส้แยมแยกชิ้น ฝอยทอง | G33: 3 | K33: =SUM(D33:J33) -> 3
B34: 1111081 | C34: ชิฟฟอนไส้แยมแยกชิ้น วนิลา | G34: 2 | K34: =SUM(D34:J34) -> 2
B35: 1111082 | C35: ชิฟฟอนไส้แยมแยกชิ้น ใบเตย | G35: 2 | K35: =SUM(D35:J35) -> 2
B36: 1111083 | C36: ชิฟฟอนไส้แยมแยกชิ้น เมล่อน | G36: 2 | K36: =SUM(D36:J36) -> 2
B37: 1111010 | C37: ชิฟฟอนไส้แยมแยกชิ้น คละรส | K37: =SUM(D37:J37) -> 0
C38: รวม | K38: =SUM(D38:I38) -> 0
B39: ชิฟฟอนไส้แยม 6 ชิ้น
B40: 1111009 | C40: ชิฟฟอนไส้แยมรวมรส 6 ชิ้น | F40: 8 | G40: 3 | K40: =SUM(D40:J40) -> 11
B41: ชิฟฟอนไส้แยม 3 ชิ้น
...

Sheet บ่าย
B1: ยอดจริง ออนไลน์ วันที่ 21/11/2567 - บ่าย
K2: ยอดรวมผลิต
K3: จำนวน
B4: รหัสสินค้า | C4: สินค้า | D4: ปณ | E4: ชอปปี้ | F4: ลาซาด้า | G4: ติ๊กตอก | H4: ติ๊กตอก2 | I4: ติ๊กตอก3 | J4: ชอยส์ | K4: (กล่อง)
B6: ชิฟฟอนรวมรส
B7: 1111002 | C7: ชิฟฟอนรวมรส 8 ชิ้น | E7: 10 | F7: 18 | K7: =SUM(D7:J7) -> 28
B8: 1111043 | C8: ชิฟฟอน 8 ชิ้น มะลิ | K8: =SUM(D8:J8) -> 0
B9: 1111056 | C9: ชิฟฟอน 8 ชิ้น รวมรสยอดฮิต | F9: 3 | G9: 1 | H9: 1 | K9: =SUM(D9:J9) -> 5
B10: 1004055 | C10: ชิฟฟอนรวมรส 4 ชิ้น | G10: 9 | H10: 6 | I10: 3 | K10: =SUM(D10:J10) -> 18
B11: 1111057 | C11: ชิฟฟอนแยกชิ้น กาแฟ | G11: 2 | I11: 1 | J11: 1 | K11: =SUM(D11:J11) -> 4
B12: 1111058 | C12: ชิฟฟอนแยกชิ้น ชาเขียว | G12: 2 | J12: 1 | K12: =SUM(D12:J12) -> 3
B13: 1111059 | C13: ชิฟฟอนแยกชิ้น ใบเตย | G13: 2 | J13: 1 | K13: =SUM(D13:J13) -> 3
B14: 1111060 | C14: ชิฟฟอนแยกชิ้น กล้วยหอม | G14: 2 | K14: =SUM(D14:J14) -> 2
B15: 1111061 | C15: ชิฟฟอนแยกชิ้น ชาไทย | K15: =SUM(D15:J15) -> 0
B16: 1111062 | C16: ชิฟฟอนแยกชิ้น โกโก้ | K16: =SUM(D16:J16) -> 0
B17: 1111063 | C17: ชิฟฟอนแยกชิ้น ส้ม | G17: 2 | K17: =SUM(D17:J17) -> 2
B18: 1111064 | C18: ชิฟฟอนแยกชิ้น เผือก | K18: =SUM(D18:J18) -> 0
B19: 1111065 | C19: ชิฟฟอนแยกชิ้น สับปะรด | G19: 2 | K19: =SUM(D19:J19) -> 2
B20: 1111066 | C20: ชิฟฟอนแยกชิ้น สตอเบอรี่ | G20: 2 | K20: =SUM(D20:J20) -> 2
B21: 1111067 | C21: ชิฟฟอนแยกชิ้น มะพร้าว | G21: 2 | K21: =SUM(D21:J21) -> 2
B22: 1111068 | C22: ชิฟฟอนแยกชิ้น เนย | G22: 2 | K22: =SUM(D22:J22) -> 2
B23: 1111069 | C23: ชิฟฟอนแยกชิ้น บลูเบอรี่ | G23: 2 | K23: =SUM(D23:J23) -> 2
B24: 1111070 | C24: ชิฟฟอนแยกชิ้น ทุเรียน | K24: =SUM(D24:J24) -> 0
B25: 1111071 | C25: ชิฟฟอนแยกชิ้น ตาล | K25: =SUM(D25:J25) -> 0
B26: 1111001 | C26: ชิฟฟอนแยกชิ้น คละรส | K26: =SUM(D26:J26) -> 0
B27: 1111074 | C27: ชิฟฟอนไส้แยมแยกชิ้น มะพร้าว | G27: 1 | I27: 1 | K27: =SUM(D27:J27) -> 2
B28: 1111075 | C28: ชิฟฟอนไส้แยมแยกชิ้น สตอเบอรี่ | G28: 1 | I28: 1 | K28: =SUM(D28:J28) -> 2
B29: 1111076 | C29: ชิฟฟอนไส้แยมแยกชิ้น ส้ม | G29: 1 | I29: 1 | K29: =SUM(D29:J29) -> 2
B30: 1111077 | C30: ชิฟฟอนไส้แยมแยกชิ้น บลูเบอรี่ | G30: 1 | I30: 1 | K30: =SUM(D30:J30) -> 2
B31: 1111078 | C31: ชิฟฟอนไส้แยมแยกชิ้น นมชมพู | G31: 1 | K31: =SUM(D31:J31) -> 1
B32: 1111079 | C32: ชิฟฟอนไส้แยมแยกชิ้น ชอคโกแลต | G32: 1 | K32: =SUM(D32:J32) -> 1
B33: 1111080 | C33: ชิฟฟอนไส้แยมแยกชิ้น ฝอยทอง | K33: =SUM(D33:J33) -> 0
B34: 1111081 | C34: ชิฟฟอนไส้แยมแยกชิ้น วนิลา | K34: =SUM(D34:J34) -> 0
B35: 1111082 | C35: ชิฟฟอนไส้แยมแยกชิ้น ใบเตย | K35: =SUM(D35:J35) -> 0
B36: 1111083 | C36: ชิฟฟอนไส้แยมแยกชิ้น เมล่อน | K36: =SUM(D36:J36) -> 0
B37: 1111010 | C37: ชิฟฟอนไส้แยมแยกชิ้น คละรส | K37: =SUM(D37:J37) -> 0
C38: รวม | K38: =SUM(D38:I38) -> 0
B39: ชิฟฟอนไส้แยม 6 ชิ้น
B40: 1111009 | C40: ชิฟฟอนไส้แยมรวมรส 6 ชิ้น | F40: 2 | G40: 2 | K40: =SUM(D40:J40) -> 4
B41: ชิฟฟอนไส้แยม 3 ชิ้น
...

Sheet รวม
B1: ยอดจริง ออนไลน์ วันที่ 21/11/2567 - รวม
K2: ยอดรวมผลิต | L2: ยอดสตอค | M2: ยอดฟอแคส | N2: รับเกิน | O2: ยังไม่ได้รับเข้า | P2: รวม
K3: จำนวน | R3: รับเข้าอาทิตย์ | S3: รับเข้าจันทร์ | T3: รวม
B4: รหัสสินค้า | C4: สินค้า | D4: ปณ | E4: ชอปปี้ | F4: ลาซาด้า | G4: ติ๊กตอก | H4: ติ๊กตอก2 | I4: ติ๊กตอก3 | J4: ชอยส์ | K4: (กล่อง)
B6: ชิฟฟอนรวมรส | W6: รหัสสินค้า | X6: ชื่อสินค้า | Y6: จำนวนที่ต้องการเบรค
B7: 1111002 | C7: ชิฟฟอนรวมรส 8 ชิ้น | D7: =เช้า!D7+'เย็น '!D7+บ่าย!D7 -> 0 | E7: =เช้า!E7+'เย็น '!E7+บ่าย!E7 -> 19 | F7: =เช้า!F7+'เย็น '!F7+บ่าย!F7 -> 66 | G7: =เช้า!G7+'เย็น '!G7+บ่าย!G7 -> 0 | H7: =เช้า!H7+'เย็น '!H7+บ่าย!H7 -> 0 | I7: =เช้า!I7+'เย็น '!I7+บ่าย!I7 -> 0 | J7: =เช้า!J7+'เย็น '!J7+บ่าย!J7 -> 0 | K7: =SUM(D7:J7) -> 85 | P7: =(L7+M7+N7+O7)-K7 -> -85 | R7: 250 | S7: 250 | T7: =S7+R7+P7 -> 415 | W7: 1111002 | X7: ชิฟฟอนรวมรส 8 ชิ้น | Y7: 250
B8: 1111043 | C8: ชิฟฟอน 8 ชิ้น มะลิ | D8: =เช้า!D8+'เย็น '!D8+บ่าย!D8 -> 0 | E8: =เช้า!E8+'เย็น '!E8+บ่าย!E8 -> 0 | F8: =เช้า!F8+'เย็น '!F8+บ่าย!F8 -> 0 | G8: =เช้า!G8+'เย็น '!G8+บ่าย!G8 -> 0 | H8: =เช้า!H8+'เย็น '!H8+บ่าย!H8 -> 0 | I8: =เช้า!I8+'เย็น '!I8+บ่าย!I8 -> 0 | J8: =เช้า!J8+'เย็น '!J8+บ่าย!J8 -> 0 | K8: =SUM(D8:J8) -> 0 | P8: =(L8+M8+N8+O8)-K8 -> 0 | T8: =S8+R8+P8 -> 0 | W8: 1111043 | X8: ชิฟฟอน 8 ชิ้น มะลิ
B9: 1111056 | C9: ชิฟฟอน 8 ชิ้น รวมรสยอดฮิต | D9: =เช้า!D9+'เย็น '!D9+บ่าย!D9 -> 0 | E9: =เช้า!E9+'เย็น '!E9+บ่าย!E9 -> 7 | F9: =เช้า!F9+'เย็น '!F9+บ่าย!F9 -> 9 | G9: =เช้า!G9+'เย็น '!G9+บ่าย!G9 -> 2 | H9: =เช้า!H9+'เย็น '!H9+บ่าย!H9 -> 1 | I9: =เช้า!I9+'เย็น '!I9+บ่าย!I9 -> 0 | J9: =เช้า!J9+'เย็น '!J9+บ่าย!J9 -> 0 | K9: =SUM(D9:J9) -> 19 | P9: =(L9+M9+N9+O9)-K9 -> -19 | R9: 10 | T9: =S9+R9+P9 -> -9 | W9: 1004055 | X9: ชิฟฟอนรวมรส 4 ชิ้น | Y9: 250
B10: 1004055 | C10: ชิฟฟอนรวมรส 4 ชิ้น | D10: =เช้า!D10+'เย็น '!D10+บ่าย!D10 -> 0 | E10: =เช้า!E10+'เย็น '!E10+บ่าย!E10 -> 7 | F10: =เช้า!F10+'เย็น '!F10+บ่าย!F10 -> 0 | G10: =เช้า!G10+'เย็น '!G10+บ่าย!G10 -> 61 | H10: =เช้า!H10+'เย็น '!H10+บ่าย!H10 -> 6 | I10: =เช้า!I10+'เย็น '!I10+บ่าย!I10 -> 3 | J10: =เช้า!J10+'เย็น '!J10+บ่าย!J10 -> 0 | K10: =SUM(D10:J10) -> 77 | P10: =(L10+M10+N10+O10)-K10 -> -77 | R10: 250 | S10: 250 | T10: =S10+R10+P10 -> 423 | W10: 1111057 | X10: ชิฟฟอนแยกชิ้น กาแฟ | Y10: 50
B11: 1111057 | C11: ชิฟฟอนแยกชิ้น กาแฟ | D11: =เช้า!D11+'เย็น '!D11+บ่าย!D11 -> 0 | E11: =เช้า!E11+'เย็น '!E11+บ่าย!E11 -> 0 | F11: =เช้า!F11+'เย็น '!F11+บ่าย!F11 -> 0 | G11: =เช้า!G11+'เย็น '!G11+บ่าย!G11 -> 8 | H11: =เช้า!H11+'เย็น '!H11+บ่าย!H11 -> 0 | I11: =เช้า!I11+'เย็น '!I11+บ่าย!I11 -> 1 | J11: =เช้า!J11+'เย็น '!J11+บ่าย!J11 -> 1 | K11: =SUM(D11:J11) -> 10 | P11: =(L11+M11+N11+O11)-K11 -> -10 | S11: 50 | T11: =S11+R11+P11 -> 40 | W11: 1111058 | X11: ชิฟฟอนแยกชิ้น ชาเขียว | Y11: 50
B12: 1111058 | C12: ชิฟฟอนแยกชิ้น ชาเขียว | D12: =เช้า!D12+'เย็น '!D12+บ่าย!D12 -> 0 | E12: =เช้า!E12+'เย็น '!E12+บ่าย!E12 -> 0 | F12: =เช้า!F12+'เย็น '!F12+บ่าย!F12 -> 0 | G12: =เช้า!G12+'เย็น '!G12+บ่าย!G12 -> 8 | H12: =เช้า!H12+'เย็น '!H12+บ่าย!H12 -> 0 | I12: =เช้า!I12+'เย็น '!I12+บ่าย!I12 -> 0 | J12: =เช้า!J12+'เย็น '!J12+บ่าย!J12 -> 1 | K12: =SUM(D12:J12) -> 9 | P12: =(L12+M12+N12+O12)-K12 -> -9 | S12: 50 | T12: =S12+R12+P12 -> 41 | W12: 1111059 | X12: ชิฟฟอนแยกชิ้น ใบเตย | Y12: 50
B13: 1111059 | C13: ชิฟฟอนแยกชิ้น ใบเตย | D13: =เช้า!D13+'เย็น '!D13+บ่าย!D13 -> 0 | E13: =เช้า!E13+'เย็น '!E13+บ่าย!E13 -> 0 | F13: =เช้า!F13+'เย็น '!F13+บ่าย!F13 -> 0 | G13: =เช้า!G13+'เย็น '!G13+บ่าย!G13 -> 8 | H13: =เช้า!H13+'เย็น '!H13+บ่าย!H13 -> 0 | I13: =เช้า!I13+'เย็น '!I13+บ่าย!I13 -> 0 | J13: =เช้า!J13+'เย็น '!J13+บ่าย!J13 -> 1 | K13: =SUM(D13:J13) -> 9 | P13: =(L13+M13+N13+O13)-K13 -> -9 | S13: 50 | T13: =S13+R13+P13 -> 41 | W13: 1111060 | X13: ชิฟฟอนแยกชิ้น กล้วยหอม | Y13: 50
B14: 1111060 | C14: ชิฟฟอนแยกชิ้น กล้วยหอม | D14: =เช้า!D14+'เย็น '!D14+บ่าย!D14 -> 0 | E14: =เช้า!E14+'เย็น '!E14+บ่าย!E14 -> 0 | F14: =เช้า!F14+'เย็น '!F14+บ่าย!F14 -> 0 | G14: =เช้า!G14+'เย็น '!G14+บ่าย!G14 -> 6 | H14: =เช้า!H14+'เย็น '!H14+บ่าย!H14 -> 0 | I14: =เช้า!I14+'เย็น '!I14+บ่าย!I14 -> 0 | J14: =เช้า!J14+'เย็น '!J14+บ่าย!J14 -> 0 | K14: =SUM(D14:J14) -> 6 | P14: =(L14+M14+N14+O14)-K14 -> -6 | S14: 50 | T14: =S14+R14+P14 -> 44 | W14: 1111061 | X14: ชิฟฟอนแยกชิ้น ชาไทย | Y14: 50
B15: 1111061 | C15: ชิฟฟอนแยกชิ้น ชาไทย | D15: =เช้า!D15+'เย็น '!D15+บ่าย!D15 -> 0 | E15: =เช้า!E15+'เย็น '!E15+บ่าย!E15 -> 0 | F15: =เช้า!F15+'เย็น '!F15+บ่าย!F15 -> 0 | G15: =เช้า!G15+'เย็น '!G15+บ่าย!G15 -> 3 | H15: =เช้า!H15+'เย็น '!H15+บ่าย!H15 -> 0 | I15: =เช้า!I15+'เย็น '!I15+บ่าย!I15 -> 0 | J15: =เช้า!J15+'เย็น '!J15+บ่าย!J15 -> 0 | K15: =SUM(D15:J15) -> 3 | P15: =(L15+M15+N15+O15)-K15 -> -3 | S15: 50 | T15: =S15+R15+P15 -> 47 | W15: 1111062 | X15: ชิฟฟอนแยกชิ้น โกโก้ | Y15: 50
B16: 1111062 | C16: ชิฟฟอนแยกชิ้น โกโก้ | D16: =เช้า!D16+'เย็น '!D16+บ่าย!D16 -> 0 | E16: =เช้า!E16+'เย็น '!E16+บ่าย!E16 -> 0 | F16: =เช้า!F16+'เย็น '!F16+บ่าย!F16 -> 0 | G16: =เช้า!G16+'เย็น '!G16+บ่าย!G16 -> 1 | H16: =เช้า!H16+'เย็น '!H16+บ่าย!H16 -> 0 | I16: =เช้า!I16+'เย็น '!I16+บ่าย!I16 -> 0 | J16: =เช้า!J16+'เย็น '!J16+บ่าย!J16 -> 0 | K16: =SUM(D16:J16) -> 1 | P16: =(L16+M16+N16+O16)-K16 -> -1 | S16: 50 | T16: =S16+R16+P16 -> 49 | W16: 1111063 | X16: ชิฟฟอนแยกชิ้น ส้ม | Y16: 50
B17: 1111063 | C17: ชิฟฟอนแยกชิ้น ส้ม | D17: =เช้า!D17+'เย็น '!D17+บ่าย!D17 -> 0 | E17: =เช้า!E17+'เย็น '!E17+บ่าย!E17 -> 0 | F17: =เช้า!F17+'เย็น '!F17+บ่าย!F17 -> 0 | G17: =เช้า!G17+'เย็น '!G17+บ่าย!G17 -> 7 | H17: =เช้า!H17+'เย็น '!H17+บ่าย!H17 -> 0 | I17: =เช้า!I17+'เย็น '!I17+บ่าย!I17 -> 0 | J17: =เช้า!J17+'เย็น '!J17+บ่าย!J17 -> 0 | K17: =SUM(D17:J17) -> 7 | P17: =(L17+M17+N17+O17)-K17 -> -7 | S17: 50 | T17: =S17+R17+P17 -> 43 | W17: 1111064 | X17: ชิฟฟอนแยกชิ้น เผือก | Y17: 50
B18: 1111064 | C18: ชิฟฟอนแยกชิ้น เผือก | D18: =เช้า!D18+'เย็น '!D18+บ่าย!D18 -> 0 | E18: =เช้า!E18+'เย็น '!E18+บ่าย!E18 -> 0 | F18: =เช้า!F18+'เย็น '!F18+บ่าย!F18 -> 0 | G18: =เช้า!G18+'เย็น '!G18+บ่าย!G18 -> 3 | H18: =เช้า!H18+'เย็น '!H18+บ่าย!H18 -> 0 | I18: =เช้า!I18+'เย็น '!I18+บ่าย!I18 -> 0 | J18: =เช้า!J18+'เย็น '!J18+บ่าย!J18 -> 0 | K18: =SUM(D18:J18) -> 3 | P18: =(L18+M18+N18+O18)-K18 -> -3 | S18: 50 | T18: =S18+R18+P18 -> 47 | W18: 1111065 | X18: ชิฟฟอนแยกชิ้น สับปะรด | Y18: 50
B19: 1111065 | C19: ชิฟฟอนแยกชิ้น สับปะรด | D19: =เช้า!D19+'เย็น '!D19+บ่าย!D19 -> 0 | E19: =เช้า!E19+'เย็น '!E19+บ่าย!E19 -> 0 | F19: =เช้า!F19+'เย็น '!F19+บ่าย!F19 -> 0 | G19: =เช้า!G19+'เย็น '!G19+บ่าย!G19 -> 5 | H19: =เช้า!H19+'เย็น '!H19+บ่าย!H19 -> 0 | I19: =เช้า!I19+'เย็น '!I19+บ่าย!I19 -> 0 | J19: =เช้า!J19+'เย็น '!J19+บ่าย!J19 -> 0 | K19: =SUM(D19:J19) -> 5 | P19: =(L19+M19+N19+O19)-K19 -> -5 | S19: 50 | T19: =S19+R19+P19 -> 45 | W19: 1111066 | X19: ชิฟฟอนแยกชิ้น สตอเบอรี่ | Y19: 50
B20: 1111066 | C20: ชิฟฟอนแยกชิ้น สตอเบอรี่ | D20: =เช้า!D20+'เย็น '!D20+บ่าย!D20 -> 0 | E20: =เช้า!E20+'เย็น '!E20+บ่าย!E20 -> 0 | F20: =เช้า!F20+'เย็น '!F20+บ่าย!F20 -> 0 | G20: =เช้า!G20+'เย็น '!G20+บ่าย!G20 -> 6 | H20: =เช้า!H20+'เย็น '!H20+บ่าย!H20 -> 0 | I20: =เช้า!I20+'เย็น '!I20+บ่าย!I20 -> 0 | J20: =เช้า!J20+'เย็น '!J20+บ่าย!J20 -> 0 | K20: =SUM(D20:J20) -> 6 | P20: =(L20+M20+N20+O20)-K20 -> -6 | S20: 50 | T20: =S20+R20+P20 -> 44 | W20: 1111067 | X20: ชิฟฟอนแยกชิ้น มะพร้าว | Y20: 50
B21: 1111067 | C21: ชิฟฟอนแยกชิ้น มะพร้าว | D21: =เช้า!D21+'เย็น '!D21+บ่าย!D21 -> 0 | E21: =เช้า!E21+'เย็น '!E21+บ่าย!E21 -> 0 | F21: =เช้า!F21+'เย็น '!F21+บ่าย!F21 -> 0 | G21: =เช้า!G21+'เย็น '!G21+บ่าย!G21 -> 6 | H21: =เช้า!H21+'เย็น '!H21+บ่าย!H21 -> 0 | I21: =เช้า!I21+'เย็น '!I21+บ่าย!I21 -> 0 | J21: =เช้า!J21+'เย็น '!J21+บ่าย!J21 -> 0 | K21: =SUM(D21:J21) -> 6 | P21: =(L21+M21+N21+O21)-K21 -> -6 | S21: 50 | T21: =S21+R21+P21 -> 44 | W21: 1111068 | X21: ชิฟฟอนแยกชิ้น เนย | Y21: 50
B22: 1111068 | C22: ชิฟฟอนแยกชิ้น เนย | D22: =เช้า!D22+'เย็น '!D22+บ่าย!D22 -> 0 | E22: =เช้า!E22+'เย็น '!E22+บ่าย!E22 -> 0 | F22: =เช้า!F22+'เย็น '!F22+บ่าย!F22 -> 0 | G22: =เช้า!G22+'เย็น '!G22+บ่าย!G22 -> 6 | H22: =เช้า!H22+'เย็น '!H22+บ่าย!H22 -> 0 | I22: =เช้า!I22+'เย็น '!I22+บ่าย!I22 -> 0 | J22: =เช้า!J22+'เย็น '!J22+บ่าย!J22 -> 0 | K22: =SUM(D22:J22) -> 6 | P22: =(L22+M22+N22+O22)-K22 -> -6 | S22: 50 | T22: =S22+R22+P22 -> 44 | W22: 1111069 | X22: ชิฟฟอนแยกชิ้น บลูเบอรี่ | Y22: 50
... B25: 1111071 | C25: ชิฟฟอนแยกชิ้น ตาล | D25: =เช้า!D25+'เย็น '!D25+บ่าย!D25 -> 0 | E25: =เช้า!E25+'เย็น '!E25+บ่าย!E25 -> 0 | F25: =เช้า!F25+'เย็น '!F25+บ่าย!F25 -> 0 | G25: =เช้า!G25+'เย็น '!G25+บ่าย!G25 -> 0 | H25: =เช้า!H25+'เย็น '!H25+บ่าย!H25 -> 0 | I25: =เช้า!I25+'เย็น '!I25+บ่าย!I25 -> 0 | J25: =เช้า!J25+'เย็น '!J25+บ่าย!J25 -> 0 | K25: =SUM(D25:J25) -> 0 | P25: =(L25+M25+N25+O25)-K25 -> 0 | S25: 50 | T25: =S25+R25+P25 -> 50 | W25: 1111074 | X25: ชิฟฟอนไส้แยมแยกชิ้น มะพร้าว | Y25: 40
B26: 1111001 | C26: ชิฟฟอนแยกชิ้น คละรส | D26: =เช้า!D26+'เย็น '!D26+บ่าย!D26 -> 0 | E26: =เช้า!E26+'เย็น '!E26+บ่าย!E26 -> 0 | F26: =เช้า!F26+'เย็น '!F26+บ่าย!F26 -> 0 | G26: =เช้า!G26+'เย็น '!G26+บ่าย!G26 -> 0 | H26: =เช้า!H26+'เย็น '!H26+บ่าย!H26 -> 0 | I26: =เช้า!I26+'เย็น '!I26+บ่าย!I26 -> 0 | J26: =เช้า!J26+'เย็น '!J26+บ่าย!J26 -> 0 | K26: =SUM(D26:J26) -> 0 | P26: =(L26+M26+N26+O26)-K26 -> 0 | T26: =S26+R26+P26 -> 0 | W26: 1111075 | X26: ชิฟฟอนไส้แยมแยกชิ้น สตอเบอรี่ | Y26: 40
B27: 1111074 | C27: ชิฟฟอนไส้แยมแยกชิ้น มะพร้าว | D27: =เช้า!D27+'เย็น '!D27+บ่าย!D27 -> 0 | E27: =เช้า!E27+'เย็น '!E27+บ่าย!E27 -> 0 | F27: =เช้า!F27+'เย็น '!F27+บ่าย!F27 -> 0 | G27: =เช้า!G27+'เย็น '!G27+บ่าย!G27 -> 4 | H27: =เช้า!H27+'เย็น '!H27+บ่าย!H27 -> 0 | I27: =เช้า!I27+'เย็น '!I27+บ่าย!I27 -> 1 | J27: =เช้า!J27+'เย็น '!J27+บ่าย!J27 -> 0 | K27: =SUM(D27:J27) -> 5 | P27: =(L27+M27+N27+O27)-K27 -> -5 | S27: 40 | T27: =S27+R27+P27 -> 35 | W27: 1111076 | X27: ชิฟฟอนไส้แยมแยกชิ้น ส้ม | Y27: 40
B28: 1111075 | C28: ชิฟฟอนไส้แยมแยกชิ้น สตอเบอรี่ | D28: =เช้า!D28+'เย็น '!D28+บ่าย!D28 -> 0 | E28: =เช้า!E28+'เย็น '!E28+บ่าย!E28 -> 0 | F28: =เช้า!F28+'เย็น '!F28+บ่าย!F28 -> 0 | G28: =เช้า!G28+'เย็น '!G28+บ่าย!G28 -> 4 | H28: =เช้า!H28+'เย็น '!H28+บ่าย!H28 -> 0 | I28: =เช้า!I28+'เย็น '!I28+บ่าย!I28 -> 1 | J28: =เช้า!J28+'เย็น '!J28+บ่าย!J28 -> 0 | K28: =SUM(D28:J28) -> 5 | P28: =(L28+M28+N28+O28)-K28 -> -5 | S28: 40 | T28: =S28+R28+P28 -> 35 | W28: 1111077 | X28: ชิฟฟอนไส้แยมแยกชิ้น บลูเบอรี่ | Y28: 40
B29: 1111076 | C29: ชิฟฟอนไส้แยมแยกชิ้น ส้ม | D29: =เช้า!D29+'เย็น '!D29+บ่าย!D29 -> 0 | E29: =เช้า!E29+'เย็น '!E29+บ่าย!E29 -> 0 | F29: =เช้า!F29+'เย็น '!F29+บ่าย!F29 -> 0 | G29: =เช้า!G29+'เย็น '!G29+บ่าย!G29 -> 4 | H29: =เช้า!H29+'เย็น '!H29+บ่าย!H29 -> 0 | I29: =เช้า!I29+'เย็น '!I29+บ่าย!I29 -> 1 | J29: =เช้า!J29+'เย็น '!J29+บ่าย!J29 -> 0 | K29: =SUM(D29:J29) -> 5 | P29: =(L29+M29+N29+O29)-K29 -> -5 | S29: 40 | T29: =S29+R29+P29 -> 35 | W29: 1111078 | X29: ชิฟฟอนไส้แยมแยกชิ้น นมชมพู | Y29: 40
B30: 1111077 | C30: ชิฟฟอนไส้แยมแยกชิ้น บลูเบอรี่ | D30: =เช้า!D30+'เย็น '!D30+บ่าย!D30 -> 0 | E30: =เช้า!E30+'เย็น '!E30+บ่าย!E30 -> 1 | F30: =เช้า!F30+'เย็น '!F30+บ่าย!F30 -> 0 | G30: =เช้า!G30+'เย็น '!G30+บ่าย!G30 -> 4 | H30: =เช้า!H30+'เย็น '!H30+บ่าย!H30 -> 0 | I30: =เช้า!I30+'เย็น '!I30+บ่าย!I30 -> 1 | J30: =เช้า!J30+'เย็น '!J30+บ่าย!J30 -> 0 | K30: =SUM(D30:J30) -> 6 | P30: =(L30+M30+N30+O30)-K30 -> -6 | S30: 40 | T30: =S30+R30+P30 -> 34 | W30: 1111079 | X30: ชิฟฟอนไส้แยมแยกชิ้น ชอคโกแลต | Y30: 40
B31: 1111078 | C31: ชิฟฟอนไส้แยมแยกชิ้น นมชมพู | D31: =เช้า!D31+'เย็น '!D31+บ่าย!D31 -> 0 | E31: =เช้า!E31+'เย็น '!E31+บ่าย!E31 -> 1 | F31: =เช้า!F31+'เย็น '!F31+บ่าย!F31 -> 0 | G31: =เช้า!G31+'เย็น '!G31+บ่าย!G31 -> 4 | H31: =เช้า!H31+'เย็น '!H31+บ่าย!H31 -> 0 | I31: =เช้า!I31+'เย็น '!I31+บ่าย!I31 -> 0 | J31: =เช้า!J31+'เย็น '!J31+บ่าย!J31 -> 0 | K31: =SUM(D31:J31) -> 5 | P31: =(L31+M31+N31+O31)-K31 -> -5 | S31: 40 | T31: =S31+R31+P31 -> 35 | W31: 1111080 | X31: ชิฟฟอนไส้แยมแยกชิ้น ฝอยทอง | Y31: 40
B32: 1111079 | C32: ชิฟฟอนไส้แยมแยกชิ้น ชอคโกแลต | D32: =เช้า!D32+'เย็น '!D32+บ่าย!D32 -> 0 | E32: =เช้า!E32+'เย็น '!E32+บ่าย!E32 -> 1 | F32: =เช้า!F32+'เย็น '!F32+บ่าย!F32 -> 0 | G32: =เช้า!G32+'เย็น '!G32+บ่าย!G32 -> 4 | H32: =เช้า!H32+'เย็น '!H32+บ่าย!H32 -> 0 | I32: =เช้า!I32+'เย็น '!I32+บ่าย!I32 -> 0 | J32: =เช้า!J32+'เย็น '!J32+บ่าย!J32 -> 0 | K32: =SUM(D32:J32) -> 5 | P32: =(L32+M32+N32+O32)-K32 -> -5 | S32: 40 | T32: =S32+R32+P32 -> 35 | W32: 1111081 | X32: ชิฟฟอนไส้แยมแยกชิ้น วนิลา | Y32: 40
B33: 1111080 | C33: ชิฟฟอนไส้แยมแยกชิ้น ฝอยทอง | D33: =เช้า!D33+'เย็น '!D33+บ่าย!D33 -> 0 | E33: =เช้า!E33+'เย็น '!E33+บ่าย!E33 -> 0 | F33: =เช้า!F33+'เย็น '!F33+บ่าย!F33 -> 0 | G33: =เช้า!G33+'เย็น '!G33+บ่าย!G33 -> 3 | H33: =เช้า!H33+'เย็น '!H33+บ่าย!H33 -> 0 | I33: =เช้า!I33+'เย็น '!I33+บ่าย!I33 -> 0 | J33: =เช้า!J33+'เย็น '!J33+บ่าย!J33 -> 0 | K33: =SUM(D33:J33) -> 3 | P33: =(L33+M33+N33+O33)-K33 -> -3 | S33: 40 | T33: =S33+R33+P33 -> 37 | W33: 1111082 | X33: ชิฟฟอนไส้แยมแยกชิ้น ใบเตย | Y33: 40
B34: 1111081 | C34: ชิฟฟอนไส้แยมแยกชิ้น วนิลา | D34: =เช้า!D34+'เย็น '!D34+บ่าย!D34 -> 0 | E34: =เช้า!E34+'เย็น '!E34+บ่าย!E34 -> 0 | F34: =เช้า!F34+'เย็น '!F34+บ่าย!F34 -> 0 | G34: =เช้า!G34+'เย็น '!G34+บ่าย!G34 -> 2 | H34: =เช้า!H34+'เย็น '!H34+บ่าย!H34 -> 0 | I34: =เช้า!I34+'เย็น '!I34+บ่าย!I34 -> 0 | J34: =เช้า!J34+'เย็น '!J34+บ่าย!J34 -> 0 | K34: =SUM(D34:J34) -> 2 | P34: =(L34+M34+N34+O34)-K34 -> -2 | S34: 40 | T34: =S34+R34+P34 -> 38 | W34: 1111083 | X34: ชิฟฟอนไส้แยมแยกชิ้น เมล่อน | Y34: 40
B35: 1111082 | C35: ชิฟฟอนไส้แยมแยกชิ้น ใบเตย | D35: =เช้า!D35+'เย็น '!D35+บ่าย!D35 -> 0 | E35: =เช้า!E35+'เย็น '!E35+บ่าย!E35 -> 0 | F35: =เช้า!F35+'เย็น '!F35+บ่าย!F35 -> 0 | G35: =เช้า!G35+'เย็น '!G35+บ่าย!G35 -> 2 | H35: =เช้า!H35+'เย็น '!H35+บ่าย!H35 -> 0 | I35: =เช้า!I35+'เย็น '!I35+บ่าย!I35 -> 0 | J35: =เช้า!J35+'เย็น '!J35+บ่าย!J35 -> 0 | K35: =SUM(D35:J35) -> 2 | P35: =(L35+M35+N35+O35)-K35 -> -2 | S35: 40 | T35: =S35+R35+P35 -> 38 | W35: 1111009 | X35: ชิฟฟอนไส้แยมรวมรส 6 ชิ้น | Y35: 20
B36: 1111083 | C36: ชิฟฟอนไส้แยมแยกชิ้น เมล่อน | D36: =เช้า!D36+'เย็น '!D36+บ่าย!D36 -> 0 | E36: =เช้า!E36+'เย็น '!E36+บ่าย!E36 -> 0 | F36: =เช้า!F36+'เย็น '!F36+บ่าย!F36 -> 0 | G36: =เช้า!G36+'เย็น '!G36+บ่าย!G36 -> 2 | H36: =เช้า!H36+'เย็น '!H36+บ่าย!H36 -> 0 | I36: =เช้า!I36+'เย็น '!I36+บ่าย!I36 -> 0 | J36: =เช้า!J36+'เย็น '!J36+บ่าย!J36 -> 0 | K36: =SUM(D36:J36) -> 2 | P36: =(L36+M36+N36+O36)-K36 -> -2 | S36: 40 | T36: =S36+R36+P36 -> 38 | W36: 1111008 | X36: ชิฟฟอนไส้แยมรวมรส 3 ชิ้น | Y36: 250
B37: 1111010 | C37: ชิฟฟอนไส้แยมแยกชิ้น คละรส | D37: =เช้า!D37+'เย็น '!D37+บ่าย!D37 -> 0 | E37: =เช้า!E37+'เย็น '!E37+บ่าย!E37 -> 0 | F37: =เช้า!F37+'เย็น '!F37+บ่าย!F37 -> 0 | G37: =เช้า!G37+'เย็น '!G37+บ่าย!G37 -> 0 | H37: =เช้า!H37+'เย็น '!H37+บ่าย!H37 -> 0 | I37: =เช้า!I37+'เย็น '!I37+บ่าย!I37 -> 0 | J37: =เช้า!J37+'เย็น '!J37+บ่าย!J37 -> 0 | K37: =SUM(D37:J37) -> 0 | P37: =(L37+M37+N37+O37)-K37 -> 0 | T37: =S37+R37+P37 -> 0
C38: รวม | D38: =เช้า!D38+'เย็น '!D38+บ่าย!D38 -> 0 | E38: =เช้า!E38+'เย็น '!E38+บ่าย!E38 -> 0 | F38: =เช้า!F38+'เย็น '!F38+บ่าย!F38 -> 0 | G38: =เช้า!G38+'เย็น '!G38+บ่าย!G38 -> 0 | H38: =เช้า!H38+'เย็น '!H38+บ่าย!H38 -> 0 | I38: =เช้า!I38+'เย็น '!I38+บ่าย!I38 -> 0 | J38: =เช้า!J38+'เย็น '!J38+บ่าย!J38 -> 0 | K38: =SUM(D38:J38) -> 0 | P38: =(L38+M38+N38+O38)-K38 -> 0 | T38: =S38+R38+P38 -> 0 | W38: 1114501 | X38: ครีมฮอร์นไส้เนย วนิลา | Y38: 400
B39: ชิฟฟอนไส้แยม 6 ชิ้น | T39: =S39+R39+P39 -> 0 | W39: 1114503 | X39: ครีมฮอร์นไส้เนย ชอค | Y39: 400
B40: 1111009 | C40: ชิฟฟอนไส้แยมรวมรส 6 ชิ้น | D40: =เช้า!D40+'เย็น '!D40+บ่าย!D40 -> 0 | E40: =เช้า!E40+'เย็น '!E40+บ่าย!E40 -> 0 | F40: =เช้า!F40+'เย็น '!F40+บ่าย!F40 -> 10 | G40: =เช้า!G40+'เย็น '!G40+บ่าย!G40 -> 5 | H40: =เช้า!H40+'เย็น '!H40+บ่าย!H40 -> 0 | I40: =เช้า!I40+'เย็น '!I40+บ่าย!I40 -> 0 | J40: =เช้า!J40+'เย็น '!J40+บ่าย!J40 -> 0 | K40: =SUM(D40:J40) -> 15 | P40: =(L40+M40+N40+O40)-K40 -> -15 | S40: 20 | T40: =S40+R40+P40 -> 5 | W40: 1124021 | X40: ขนมปังหั่นสไลด์ | Y40: 400
B41: ชิฟฟอนไส้แยม 3 ชิ้น | T41: =S41+R41+P41 -> 0
B42: 1111008 | C42: ชิฟฟอนไส้แยมรวมรส 3 ชิ้น | D42: =เช้า!D42+'เย็น '!D42+บ่าย!D42 -> 9 | E42: =เช้า!E42+'เย็น '!E42+บ่าย!E42 -> 0 | F42: =เช้า!F42+'เย็น '!F42+บ่าย!F42 -> 0 | G42: =เช้า!G42+'เย็น '!G42+บ่าย!G42 -> 44 | H42: =เช้า!H42+'เย็น '!H42+บ่าย!H42 -> 0 | I42: =เช้า!I42+'เย็น '!I42+บ่าย!I42 -> 0 | J42: =เช้า!J42+'เย็น '!J42+บ่าย!J42 -> 0 | K42: =SUM(D42:J42) -> 53 | P42: =(L42+M42+N42+O42)-K42 -> -53 | S42: 250 | T42: =S42+R42+P42 -> 197
B43: เบาหวิว ล 110 กรัม | T43: =S43+R43+P43 -> 0
...
