Workbook

Sheet เย็น 102
B1: ยอดจริง ออนไลน์ วันที่ 25/10/2567 - เย็น
K2: ยอดรวมผลิต
K3: จำนวน
B4: รหัสสินค้า | C4: สินค้า | D4: ปณ | E4: ชอปปี้ | F4: ลาซาด้า | G4: ติ๊กตอก | H4: ติ๊กตอก 2 | I4: ติ๊กตอก3 | J4: ชอยส์ | K4: (กล่อง)
B6: ชิฟฟอนรวมรส
B7: 1111002 | C7: ชิฟฟอนรวมรส 8 ชิ้น | K7: =SUM(D7:J7) -> 0
C8: ชิฟฟอนแบบกล่องสุ่มอะไรก็ได้ที่มี | K8: =SUM(D8:J8) -> 0
B9: 1111084 | C9: ชิฟฟอน 8 ชิ้น กาแฟล้วน | K9: =SUM(D9:J9) -> 0
B10: 1111085 | C10: ชิฟฟอน 8 ชิ้น บลูเบอรี่ล้วน | K10: =SUM(D10:J10) -> 0
B11: 1111086 | C11: ชิฟฟอน 8 ชิ้น มะพร้าวล้วน | K11: =SUM(D11:J11) -> 0
B12: 1111087 | C12: ชิฟฟอน 8 ชิ้น สตอเบอรี่ล้วน | K12: =SUM(D12:J12) -> 0
B13: 1111088 | C13: ชิฟฟอน 8 ชิ้น ส้มล้วน | K13: =SUM(D13:J13) -> 0
B14: 1111089 | C14: ชิฟฟอน 8 ชิ้น เนยล้วน | K14: =SUM(D14:J14) -> 0
B15: 1111090 | C15: ชิฟฟอน 8 ชิ้น เผือกล้วน | K15: =SUM(D15:J15) -> 0
B16: 1111091 | C16: ชิฟฟอน 8 ชิ้น ใบเตยล้วน | K16: =SUM(D16:J16) -> 0
B17: 1111092 | C17: ชิฟฟอน 8 ชิ้น กล้วยหอม | K17: =SUM(D17:J17) -> 0
B18: 1111093 | C18: ชิฟฟอน 8 ชิ้น โกโก้ล้วน | K18: =SUM(D18:J18) -> 0
B19: 1111094 | C19: ชิฟฟอน 8 ชิ้น ชาไทยล้วน | K19: =SUM(D19:J19) -> 0
B20: 1111095 | C20: ชิฟฟอน 8 ชิ้น ชาเขียวล้วน | K20: =SUM(D20:J20) -> 0
... B66: 1111010 | C66: ชิฟฟอนไส้แยมแยกชิ้น คละรส | K66: =SUM(D66:J66) -> 0
C67: รวม
B68: ชิฟฟอนไส้แยม 6 ชิ้น
B69: 1111009 | C69: ชิฟฟอนไส้แยมรวมรส 6 ชิ้น | K69: =SUM(D69:J69) -> 0
B70: 1111023 | C70: ชิฟฟอนไส้แยมรสสตอเบอร์รี่ล้วน 6 ชิ้น | K70: =SUM(D70:J70) -> 0
B71: 1111016 | C71: ชิฟฟอนไส้แยมรสมะพร้าวล้วน 6 ชิ้น | K71: =SUM(D71:J71) -> 0
B72: 1111014 | C72: ชิฟฟอนไส้แยมรสช็อกโกแลตนูเทลล่าล้วน 6 ชิ้น | K72: =SUM(D72:J72) -> 0
B73: 1111025 | C73: ชิฟฟอนไส้แยมรสส้มล้วน 6 ชิ้น | K73: =SUM(D73:J73) -> 0
B74: 1111018 | C74: ชิฟฟอนไส้แยมรสบลูเบอร์รี่ล้วน 6 ชิ้น | K74: =SUM(D74:J74) -> 0
B75: 1111012 | C75: ชิฟฟอนไส้แยมรสนมชมพูฮอกไกโดล้วน 6 ชิ้น | K75: =SUM(D75:J75) -> 0
B76: 1111020 | C76: ชิฟฟอนไส้แยมฝอยทองไส้ทะลัก 6 ชิ้น | K76: =SUM(D76:J76) -> 0
C77: รวม
B78: ชิฟฟอนไส้แยม 3 ชิ้น
B79: 1111022 | C79: ชิฟฟอนไส้แยมรสสตอเบอร์รี่ล้วน 3 ชิ้น | K79: =SUM(D79:J79) -> 0
B80: 1111015 | C80: ชิฟฟอนไส้แยมรสมะพร้าวล้วน 3 ชิ้น | K80: =SUM(D80:J80) -> 0
B81: 1111013 | C81: ชิฟฟอนไส้แยมรสช็อกโกแลตนูเทลล่าล้วน 3 ชิ้น | K81: =SUM(D81:J81) -> 0
B82: 1111024 | C82: ชิฟฟอนไส้แยมรสส้มล้วน 3 ชิ้น | K82: =SUM(D82:J82) -> 0
B83: 1111017 | C83: ชิฟฟอนไส้แยมรสบลูเบอร์รี่ล้วน 3 ชิ้น | K83: =SUM(D83:J83) -> 0
B84: 1111011 | C84: ชิฟฟอนไส้แยมรสนมชมพูฮอกไกโดล้วน 3 ชิ้น | K84: =SUM(D84:J84) -> 0
B85: 1111019 | C85: ชิฟฟอนไส้แยมฝอยทองไส้ทะลัก 3 ชิ้น | K85: =SUM(D85:J85) -> 0
B86: 1113081 | C86: ชิฟฟอนไส้แยม วนิลา/ใบเตย/เมล่อน | K86: =SUM(D86:J86) -> 0
...

Sheet เย็น 
B1: ยอดจริง ออนไลน์ วันที่ 13/11/2567 - เย็น
K2: ยอดรวมผลิต
K3: จำนวน
B4: รหัสสินค้า | C4: สินค้า | D4: ปณ | E4: ชอปปี้ | F4: ลาซาด้า | G4: ติ๊กตอก | H4: ติ๊กตอก2 | I4: ติ๊กตอก3 | J4: ชอยส์ | K4: (กล่อง)
B6: ชิฟฟอนรวมรส
B7: 1111002 | C7: ชิฟฟอนรวมรส 8 ชิ้น | E7: 23 | F7: 56 | K7: =SUM(D7:J7) -> 79
C8: ชิฟฟอนแบบกล่องสุ่มอะไรก็ได้ที่มี | K8: =SUM(D8:J8) -> 0
B9: 1111084 | C9: ชิฟฟอน 8 ชิ้น กาแฟล้วน | K9: =SUM(D9:J9) -> 0
B10: 1111085 | C10: ชิฟฟอน 8 ชิ้น บลูเบอรี่ล้วน | K10: =SUM(D10:J10) -> 0
B11: 1111086 | C11: ชิฟฟอน 8 ชิ้น มะพร้าวล้วน | K11: =SUM(D11:J11) -> 0
B12: 1111087 | C12: ชิฟฟอน 8 ชิ้น สตอเบอรี่ล้วน | K12: =SUM(D12:J12) -> 0
B13: 1111088 | C13: ชิฟฟอน 8 ชิ้น ส้มล้วน | K13: =SUM(D13:J13) -> 0
B14: 1111089 | C14: ชิฟฟอน 8 ชิ้น เนยล้วน | K14: =SUM(D14:J14) -> 0
B15: 1111090 | C15: ชิฟฟอน 8 ชิ้น เผือกล้วน | K15: =SUM(D15:J15) -> 0
B16: 1111091 | C16: ชิฟฟอน 8 ชิ้น ใบเตยล้วน | K16: =SUM(D16:J16) -> 0
B17: 1111092 | C17: ชิฟฟอน 8 ชิ้น กล้วยหอม | K17: =SUM(D17:J17) -> 0
B18: 1111093 | C18: ชิฟฟอน 8 ชิ้น โกโก้ล้วน | K18: =SUM(D18:J18) -> 0
B19: 1111094 | C19: ชิฟฟอน 8 ชิ้น ชาไทยล้วน | K19: =SUM(D19:J19) -> 0
B20: 1111095 | C20: ชิฟฟอน 8 ชิ้น ชาเขียวล้วน | K20: =SUM(D20:J20) -> 0
... B24: 1111043 | C24: ชิฟฟอน 8 ชิ้น มะลิ | K24: =SUM(D24:J24) -> 0
B25: 1111056 | C25: ชิฟฟอน 8 ชิ้น รวมรสยอดฮิต | E25: 5 | F25: 17 | G25: 3 | K25: =SUM(D25:J25) -> 25
B26: 1004055 | C26: ชิฟฟอนรวมรส 4 ชิ้น | E26: 10 | G26: 54 | K26: =SUM(D26:J26) -> 64
B27: 1004055 | C27: ชิฟฟอน 4 ชิ้น โกโก้ล้วน | K27: =SUM(D27:J27) -> 0
B28: 1004055 | C28: ชิฟฟอน 4 ชิ้น มะพร้าวล้วน | K28: =SUM(D28:J28) -> 0
B29: 1004055 | C29: ชิฟฟอน 4 ชิ้น เนยล้วน | K29: =SUM(D29:J29) -> 0
B30: 1004055 | C30: ชิฟฟอน 4 ชิ้น กาแฟล้วน | K30: =SUM(D30:J30) -> 0
B31: 1004055 | C31: ชิฟฟอน 4 ชิ้น ใบเตยล้วน | K31: =SUM(D31:J31) -> 0
B32: 1004055 | C32: ชิฟฟอน 4 ชิ้น บลูเบอร์รี่ล้วน | K32: =SUM(D32:J32) -> 0
B33: 1004055 | C33: ชิฟฟอน 4 ชิ้น ส้มล้วน | K33: =SUM(D33:J33) -> 0
B34: 1004055 | C34: ชิฟฟอน 4 ชิ้น เผือกล้วน | K34: =SUM(D34:J34) -> 0
B35: 1004055 | C35: ชิฟฟอน 4 ชิ้น สตอเบอรี่ล้วน | K35: =SUM(D35:J35) -> 0
B36: 1004055 | C36: ชิฟฟอน 4 ชิ้น กล้วยหอมล้วน | K36: =SUM(D36:J36) -> 0
B37: 1004055 | C37: ชิฟฟอน 4 ชิ้น ชาเขียวล้วน | K37: =SUM(D37:J37) -> 0
B38: 1004055 | C38: ชิฟฟอน 4 ชิ้น ชาไทยล้วน | K38: =SUM(D38:J38) -> 0
B39: 1004055 | C39: ชิฟฟอน 4 ชิ้น สับปะรดล้วน | K39: =SUM(D39:J39) -> 0
B40: 1111057 | C40: ชิฟฟอนแยกชิ้น กาแฟ | F40: 1 | K40: =SUM(D40:J40) -> 1
B41: 1111058 | C41: ชิฟฟอนแยกชิ้น ชาเขียว | F41: 1 | K41: =SUM(D41:J41) -> 1
B42: 1111059 | C42: ชิฟฟอนแยกชิ้น ใบเตย | K42: =SUM(D42:J42) -> 0
B43: 1111060 | C43: ชิฟฟอนแยกชิ้น กล้วยหอม | K43: =SUM(D43:J43) -> 0
B44: 1111061 | C44: ชิฟฟอนแยกชิ้น ชาไทย | K44: =SUM(D44:J44) -> 0
...

Sheet เช้า 
B1: ยอดจริง ออนไลน์ วันที่ 13/11/2567 -เช้า
K2: ยอดรวมผลิต
K3: จำนวน
B4: รหัสสินค้า | C4: สินค้า | D4: ปณ | E4: ชอปปี้ | F4: ลาซาด้า | G4: ติ๊กตอก | H4: ติ๊กตอก2 | I4: ติ๊กตอก3 | J4: ชอยส์ | K4: (กล่อง)
B6: ชิฟฟอนรวมรส
B7: 1111002 | C7: ชิฟฟอนรวมรส 8 ชิ้น | E7: 20 | F7: 48 | G7: 1 | K7: =SUM(D7:J7) -> 69
C8: ชิฟฟอนแบบกล่องสุ่มอะไรก็ได้ที่มี | K8: =SUM(D8:J8) -> 0
B9: 1111084 | C9: ชิฟฟอน 8 ชิ้น กาแฟล้วน | K9: =SUM(D9:J9) -> 0
B10: 1111085 | C10: ชิฟฟอน 8 ชิ้น บลูเบอรี่ล้วน | K10: =SUM(D10:J10) -> 0
B11: 1111086 | C11: ชิฟฟอน 8 ชิ้น มะพร้าวล้วน | K11: =SUM(D11:J11) -> 0
B12: 1111087 | C12: ชิฟฟอน 8 ชิ้น สตอเบอรี่ล้วน | K12: =SUM(D12:J12) -> 0
B13: 1111088 | C13: ชิฟฟอน 8 ชิ้น ส้มล้วน | K13: =SUM(D13:J13) -> 0
B14: 1111089 | C14: ชิฟฟอน 8 ชิ้น เนยล้วน | K14: =SUM(D14:J14) -> 0
B15: 1111090 | C15: ชิฟฟอน 8 ชิ้น เผือกล้วน | K15: =SUM(D15:J15) -> 0
B16: 1111091 | C16: ชิฟฟอน 8 ชิ้น ใบเตยล้วน | K16: =SUM(D16:J16) -> 0
B17: 1111092 | C17: ชิฟฟอน 8 ชิ้น กล้วยหอม | K17: =SUM(D17:J17) -> 0
B18: 1111093 | C18: ชิฟฟอน 8 ชิ้น โกโก้ล้วน | K18: =SUM(D18:J18) -> 0
B19: 1111094 | C19: ชิฟฟอน 8 ชิ้น ชาไทยล้วน | K19: =SUM(D19:J19) -> 0
B20: 1111095 | C20: ชิฟฟอน 8 ชิ้น ชาเขียวล้วน | K20: =SUM(D20:J20) -> 0
... B24: 1111043 | C24: ชิฟฟอน 8 ชิ้น มะลิ | K24: =SUM(D24:J24) -> 0
B25: 1111056 | C25: ชิฟฟอน 8 ชิ้น รวมรสยอดฮิต | E25: 1 | F25: 3 | G25: 1 | K25: =SUM(D25:J25) -> 5
B26: 1004055 | C26: ชิฟฟอนรวมรส 4 ชิ้น | E26: 18 | G26: 69 | K26: =SUM(D26:J26) -> 87
B27: 1004055 | C27: ชิฟฟอน 4 ชิ้น โกโก้ล้วน | K27: =SUM(D27:J27) -> 0
B28: 1004055 | C28: ชิฟฟอน 4 ชิ้น มะพร้าวล้วน | K28: =SUM(D28:J28) -> 0
B29: 1004055 | C29: ชิฟฟอน 4 ชิ้น เนยล้วน | K29: =SUM(D29:J29) -> 0
B30: 1004055 | C30: ชิฟฟอน 4 ชิ้น กาแฟล้วน | K30: =SUM(D30:J30) -> 0
B31: 1004055 | C31: ชิฟฟอน 4 ชิ้น ใบเตยล้วน | K31: =SUM(D31:J31) -> 0
B32: 1004055 | C32: ชิฟฟอน 4 ชิ้น บลูเบอร์รี่ล้วน | K32: =SUM(D32:J32) -> 0
B33: 1004055 | C33: ชิฟฟอน 4 ชิ้น ส้มล้วน | K33: =SUM(D33:J33) -> 0
B34: 1004055 | C34: ชิฟฟอน 4 ชิ้น เผือกล้วน | K34: =SUM(D34:J34) -> 0
B35: 1004055 | C35: ชิฟฟอน 4 ชิ้น สตอเบอรี่ล้วน | K35: =SUM(D35:J35) -> 0
B36: 1004055 | C36: ชิฟฟอน 4 ชิ้น กล้วยหอมล้วน | K36: =SUM(D36:J36) -> 0
B37: 1004055 | C37: ชิฟฟอน 4 ชิ้น ชาเขียวล้วน | K37: =SUM(D37:J37) -> 0
B38: 1004055 | C38: ชิฟฟอน 4 ชิ้น ชาไทยล้วน | K38: =SUM(D38:J38) -> 0
B39: 1004055 | C39: ชิฟฟอน 4 ชิ้น สับปะรดล้วน | K39: =SUM(D39:J39) -> 0
B40: 1111057 | C40: ชิฟฟอนแยกชิ้น กาแฟ | D40: 16 | F40: 1 | G40: 1 | K40: =SUM(D40:J40) -> 18
B41: 1111058 | C41: ชิฟฟอนแยกชิ้น ชาเขียว | D41: 16 | K41: =SUM(D41:J41) -> 16
B42: 1111059 | C42: ชิฟฟอนแยกชิ้น ใบเตย | D42: 16 | K42: =SUM(D42:J42) -> 16
B43: 1111060 | C43: ชิฟฟอนแยกชิ้น กล้วยหอม | D43: 16 | K43: =SUM(D43:J43) -> 16
B44: 1111061 | C44: ชิฟฟอนแยกชิ้น ชาไทย | D44: 16 | K44: =SUM(D44:J44) -> 16
...

Sheet รวม
B1: ยอดจริง ออนไลน์ วันที่ 13/11/2567 รวม
K2: ยอดรวมผลิต | L2: ยอดฟอแคส | M2: ยอดสตอค | N2: รวม
K3: จำนวน
B4: รหัสสินค้า | C4: สินค้า | D4: ปณ | E4: ชอปปี้ | F4: ลาซาด้า | G4: ติ๊กตอก | H4: ติ๊กตอก2 | I4: ติ๊กตอก3 | J4: ชอยส์ | K4: (กล่อง)
B6: ชิฟฟอนรวมรส
B7: 1111002 | C7: ชิฟฟอนรวมรส 8 ชิ้น | D7: ='เย็น 102'!D7+'เช้า '!D7+'เย็น '!D7 -> 0 | E7: ='เย็น 102'!E7+'เช้า '!E7+'เย็น '!E7 -> 43 | F7: ='เย็น 102'!F7+'เช้า '!F7+'เย็น '!F7 -> 104 | G7: ='เย็น 102'!G7+'เช้า '!G7+'เย็น '!G7 -> 1 | H7: ='เย็น 102'!H7+'เช้า '!H7+'เย็น '!H7 -> 0 | I7: ='เย็น 102'!I7+'เช้า '!I7+'เย็น '!I7 -> 0 | J7: ='เย็น 102'!J7+'เช้า '!J7+'เย็น '!J7 -> 0 | K7: =SUM(D7:J7) -> 148 | L7: 150 | M7: 116 | N7: =SUM(L7+M7)-K7 -> 118
C8: ชิฟฟอนแบบกล่องสุ่มอะไรก็ได้ที่มี | D8: ='เย็น 102'!D8+'เช้า '!D8+'เย็น '!D8 -> 0 | E8: ='เย็น 102'!E8+'เช้า '!E8+'เย็น '!E8 -> 0 | F8: ='เย็น 102'!F8+'เช้า '!F8+'เย็น '!F8 -> 0 | G8: ='เย็น 102'!G8+'เช้า '!G8+'เย็น '!G8 -> 0 | H8: ='เย็น 102'!H8+'เช้า '!H8+'เย็น '!H8 -> 0 | I8: ='เย็น 102'!I8+'เช้า '!I8+'เย็น '!I8 -> 0 | J8: ='เย็น 102'!J8+'เช้า '!J8+'เย็น '!J8 -> 0 | K8: =SUM(D8:J8) -> 0 | N8: =SUM(L8+M8)-K8 -> 0
B9: 1111084 | C9: ชิฟฟอน 8 ชิ้น กาแฟล้วน | D9: ='เย็น 102'!D9+'เช้า '!D9+'เย็น '!D9 -> 0 | E9: ='เย็น 102'!E9+'เช้า '!E9+'เย็น '!E9 -> 0 | F9: ='เย็น 102'!F9+'เช้า '!F9+'เย็น '!F9 -> 0 | G9: ='เย็น 102'!G9+'เช้า '!G9+'เย็น '!G9 -> 0 | H9: ='เย็น 102'!H9+'เช้า '!H9+'เย็น '!H9 -> 0 | I9: ='เย็น 102'!I9+'เช้า '!I9+'เย็น '!I9 -> 0 | J9: ='เย็น 102'!J9+'เช้า '!J9+'เย็น '!J9 -> 0 | K9: =SUM(D9:J9) -> 0 | N9: =SUM(L9+M9)-K9 -> 0
B10: 1111085 | C10: ชิฟฟอน 8 ชิ้น บลูเบอรี่ล้วน | D10: ='เย็น 102'!D10+'เช้า '!D10+'เย็น '!D10 -> 0 | E10: ='เย็น 102'!E10+'เช้า '!E10+'เย็น '!E10 -> 0 | F10: ='เย็น 102'!F10+'เช้า '!F10+'เย็น '!F10 -> 0 | G10: ='เย็น 102'!G10+'เช้า '!G10+'เย็น '!G10 -> 0 | H10: ='เย็น 102'!H10+'เช้า '!H10+'เย็น '!H10 -> 0 | I10: ='เย็น 102'!I10+'เช้า '!I10+'เย็น '!I10 -> 0 | J10: ='เย็น 102'!J10+'เช้า '!J10+'เย็น '!J10 -> 0 | K10: =SUM(D10:J10) -> 0 | N10: =SUM(L10+M10)-K10 -> 0
B11: 1111086 | C11: ชิฟฟอน 8 ชิ้น มะพร้าวล้วน | D11: ='เย็น 102'!D11+'เช้า '!D11+'เย็น '!D11 -> 0 | E11: ='เย็น 102'!E11+'เช้า '!E11+'เย็น '!E11 -> 0 | F11: ='เย็น 102'!F11+'เช้า '!F11+'เย็น '!F11 -> 0 | G11: ='เย็น 102'!G11+'เช้า '!G11+'เย็น '!G11 -> 0 | H11: ='เย็น 102'!H11+'เช้า '!H11+'เย็น '!H11 -> 0 | I11: ='เย็น 102'!I11+'เช้า '!I11+'เย็น '!I11 -> 0 | J11: ='เย็น 102'!J11+'เช้า '!J11+'เย็น '!J11 -> 0 | K11: =SUM(D11:J11) -> 0 | N11: =SUM(L11+M11)-K11 -> 0
B12: 1111087 | C12: ชิฟฟอน 8 ชิ้น สตอเบอรี่ล้วน | D12: ='เย็น 102'!D12+'เช้า '!D12+'เย็น '!D12 -> 0 | E12: ='เย็น 102'!E12+'เช้า '!E12+'เย็น '!E12 -> 0 | F12: ='เย็น 102'!F12+'เช้า '!F12+'เย็น '!F12 -> 0 | G12: ='เย็น 102'!G12+'เช้า '!G12+'เย็น '!G12 -> 0 | H12: ='เย็น 102'!H12+'เช้า '!H12+'เย็น '!H12 -> 0 | I12: ='เย็น 102'!I12+'เช้า '!I12+'เย็น '!I12 -> 0 | J12: ='เย็น 102'!J12+'เช้า '!J12+'เย็น '!J12 -> 0 | K12: =SUM(D12:J12) -> 0 | N12: =SUM(L12+M12)-K12 -> 0
B13: 1111088 | C13: ชิฟฟอน 8 ชิ้น ส้มล้วน | D13: ='เย็น 102'!D13+'เช้า '!D13+'เย็น '!D13 -> 0 | E13: ='เย็น 102'!E13+'เช้า '!E13+'เย็น '!E13 -> 0 | F13: ='เย็น 102'!F13+'เช้า '!F13+'เย็น '!F13 -> 0 | G13: ='เย็น 102'!G13+'เช้า '!G13+'เย็น '!G13 -> 0 | H13: ='เย็น 102'!H13+'เช้า '!H13+'เย็น '!H13 -> 0 | I13: ='เย็น 102'!I13+'เช้า '!I13+'เย็น '!I13 -> 0 | J13: ='เย็น 102'!J13+'เช้า '!J13+'เย็น '!J13 -> 0 | K13: =SUM(D13:J13) -> 0 | N13: =SUM(L13+M13)-K13 -> 0
B14: 1111089 | C14: ชิฟฟอน 8 ชิ้น เนยล้วน | D14: ='เย็น 102'!D14+'เช้า '!D14+'เย็น '!D14 -> 0 | E14: ='เย็น 102'!E14+'เช้า '!E14+'เย็น '!E14 -> 0 | F14: ='เย็น 102'!F14+'เช้า '!F14+'เย็น '!F14 -> 0 | G14: ='เย็น 102'!G14+'เช้า '!G14+'เย็น '!G14 -> 0 | H14: ='เย็น 102'!H14+'เช้า '!H14+'เย็น '!H14 -> 0 | I14: ='เย็น 102'!I14+'เช้า '!I14+'เย็น '!I14 -> 0 | J14: ='เย็น 102'!J14+'เช้า '!J14+'เย็น '!J14 -> 0 | K14: =SUM(D14:J14) -> 0 | N14: =SUM(L14+M14)-K14 -> 0
B15: 1111090 | C15: ชิฟฟอน 8 ชิ้น เผือกล้วน | D15: ='เย็น 102'!D15+'เช้า '!D15+'เย็น '!D15 -> 0 | E15: ='เย็น 102'!E15+'เช้า '!E15+'เย็น '!E15 -> 0 | F15: ='เย็น 102'!F15+'เช้า '!F15+'เย็น '!F15 -> 0 | G15: ='เย็น 102'!G15+'เช้า '!G15+'เย็น '!G15 -> 0 | H15: ='เย็น 102'!H15+'เช้า '!H15+'เย็น '!H15 -> 0 | I15: ='เย็น 102'!I15+'เช้า '!I15+'เย็น '!I15 -> 0 | J15: ='เย็น 102'!J15+'เช้า '!J15+'เย็น '!J15 -> 0 | K15: =SUM(D15:J15) -> 0 | N15: =SUM(L15+M15)-K15 -> 0
B16: 1111091 | C16: ชิฟฟอน 8 ชิ้น ใบเตยล้วน | D16: ='เย็น 102'!D16+'เช้า '!D16+'เย็น '!D16 -> 0 | E16: ='เย็น 102'!E16+'เช้า '!E16+'เย็น '!E16 -> 0 | F16: ='เย็น 102'!F16+'เช้า '!F16+'เย็น '!F16 -> 0 | G16: ='เย็น 102'!G16+'เช้า '!G16+'เย็น '!G16 -> 0 | H16: ='เย็น 102'!H16+'เช้า '!H16+'เย็น '!H16 -> 0 | I16: ='เย็น 102'!I16+'เช้า '!I16+'เย็น '!I16 -> 0 | J16: ='เย็น 102'!J16+'เช้า '!J16+'เย็น '!J16 -> 0 | K16: =SUM(D16:J16) -> 0 | N16: =SUM(L16+M16)-K16 -> 0
B17: 1111092 | C17: ชิฟฟอน 8 ชิ้น กล้วยหอม | D17: ='เย็น 102'!D17+'เช้า '!D17+'เย็น '!D17 -> 0 | E17: ='เย็น 102'!E17+'เช้า '!E17+'เย็น '!E17 -> 0 | F17: ='เย็น 102'!F17+'เช้า '!F17+'เย็น '!F17 -> 0 | G17: ='เย็น 102'!G17+'เช้า '!G17+'เย็น '!G17 -> 0 | H17: ='เย็น 102'!H17+'เช้า '!H17+'เย็น '!H17 -> 0 | I17: ='เย็น 102'!I17+'เช้า '!I17+'เย็น '!I17 -> 0 | J17: ='เย็น 102'!J17+'เช้า '!J17+'เย็น '!J17 -> 0 | K17: =SUM(D17:J17) -> 0 | N17: =SUM(L17+M17)-K17 -> 0
B18: 1111093 | C18: ชิฟฟอน 8 ชิ้น โกโก้ล้วน | D18: ='เย็น 102'!D18+'เช้า '!D18+'เย็น '!D18 -> 0 | E18: ='เย็น 102'!E18+'เช้า '!E18+'เย็น '!E18 -> 0 | F18: ='เย็น 102'!F18+'เช้า '!F18+'เย็น '!F18 -> 0 | G18: ='เย็น 102'!G18+'เช้า '!G18+'เย็น '!G18 -> 0 | H18: ='เย็น 102'!H18+'เช้า '!H18+'เย็น '!H18 -> 0 | I18: ='เย็น 102'!I18+'เช้า '!I18+'เย็น '!I18 -> 0 | J18: ='เย็น 102'!J18+'เช้า '!J18+'เย็น '!J18 -> 0 | K18: =SUM(D18:J18) -> 0 | N18: =SUM(L18+M18)-K18 -> 0
B19: 1111094 | C19: ชิฟฟอน 8 ชิ้น ชาไทยล้วน | D19: ='เย็น 102'!D19+'เช้า '!D19+'เย็น '!D19 -> 0 | E19: ='เย็น 102'!E19+'เช้า '!E19+'เย็น '!E19 -> 0 | F19: ='เย็น 102'!F19+'เช้า '!F19+'เย็น '!F19 -> 0 | G19: ='เย็น 102'!G19+'เช้า '!G19+'เย็น '!G19 -> 0 | H19: ='เย็น 102'!H19+'เช้า '!H19+'เย็น '!H19 -> 0 | I19: ='เย็น 102'!I19+'เช้า '!I19+'เย็น '!I19 -> 0 | J19: ='เย็น 102'!J19+'เช้า '!J19+'เย็น '!J19 -> 0 | K19: =SUM(D19:J19) -> 0 | N19: =SUM(L19+M19)-K19 -> 0
B20: 1111095 | C20: ชิฟฟอน 8 ชิ้น ชาเขียวล้วน | D20: ='เย็น 102'!D20+'เช้า '!D20+'เย็น '!D20 -> 0 | E20: ='เย็น 102'!E20+'เช้า '!E20+'เย็น '!E20 -> 0 | F20: ='เย็น 102'!F20+'เช้า '!F20+'เย็น '!F20 -> 0 | G20: ='เย็น 102'!G20+'เช้า '!G20+'เย็น '!G20 -> 0 | H20: ='เย็น 102'!H20+'เช้า '!H20+'เย็น '!H20 -> 0 | I20: ='เย็น 102'!I20+'เช้า '!I20+'เย็น '!I20 -> 0 | J20: ='เย็น 102'!J20+'เช้า '!J20+'เย็น '!J20 -> 0 | K20: =SUM(D20:J20) -> 0 | N20: =SUM(L20+M20)-K20 -> 0
... B24: 1111043 | C24: ชิฟฟอน 8 ชิ้น มะลิ | D24: ='เย็น 102'!D24+'เช้า '!D24+'เย็น '!D24 -> 0 | E24: ='เย็น 102'!E24+'เช้า '!E24+'เย็น '!E24 -> 0 | F24: ='เย็น 102'!F24+'เช้า '!F24+'เย็น '!F24 -> 0 | G24: ='เย็น 102'!G24+'เช้า '!G24+'เย็น '!G24 -> 0 | H24: ='เย็น 102'!H24+'เช้า '!H24+'เย็น '!H24 -> 0 | I24: ='เย็น 102'!I24+'เช้า '!I24+'เย็น '!I24 -> 0 | J24: ='เย็น 102'!J24+'เช้า '!J24+'เย็น '!J24 -> 0 | K24: =SUM(D24:J24) -> 0 | N24: =SUM(L24+M24)-K24 -> 0
B25: 1111056 | C25: ชิฟฟอน 8 ชิ้น รวมรสยอดฮิต | D25: ='เย็น 102'!D25+'เช้า '!D25+'เย็น '!D25 -> 0 | E25: ='เย็น 102'!E25+'เช้า '!E25+'เย็น '!E25 -> 6 | F25: ='เย็น 102'!F25+'เช้า '!F25+'เย็น '!F25 -> 20 | G25: ='เย็น 102'!G25+'เช้า '!G25+'เย็น '!G25 -> 4 | H25: ='เย็น 102'!H25+'เช้า '!H25+'เย็น '!H25 -> 0 | I25: ='เย็น 102'!I25+'เช้า '!I25+'เย็น '!I25 -> 0 | J25: ='เย็น 102'!J25+'เช้า '!J25+'เย็น '!J25 -> 0 | K25: =SUM(D25:J25) -> 30 | L25: 30 | M25: 3 | N25: =SUM(L25+M25)-K25 -> 3
B26: 1004055 | C26: ชิฟฟอนรวมรส 4 ชิ้น | D26: ='เย็น 102'!D26+'เช้า '!D26+'เย็น '!D26 -> 0 | E26: ='เย็น 102'!E26+'เช้า '!E26+'เย็น '!E26 -> 28 | F26: ='เย็น 102'!F26+'เช้า '!F26+'เย็น '!F26 -> 0 | G26: ='เย็น 102'!G26+'เช้า '!G26+'เย็น '!G26 -> 123 | H26: ='เย็น 102'!H26+'เช้า '!H26+'เย็น '!H26 -> 0 | I26: ='เย็น 102'!I26+'เช้า '!I26+'เย็น '!I26 -> 0 | J26: ='เย็น 102'!J26+'เช้า '!J26+'เย็น '!J26 -> 0 | K26: =SUM(D26:J26) -> 151 | M26: 586 | N26: =SUM(L26+M26)-K26 -> 435
B27: 1004055 | C27: ชิฟฟอน 4 ชิ้น โกโก้ล้วน | D27: ='เย็น 102'!D27+'เช้า '!D27+'เย็น '!D27 -> 0 | E27: ='เย็น 102'!E27+'เช้า '!E27+'เย็น '!E27 -> 0 | F27: ='เย็น 102'!F27+'เช้า '!F27+'เย็น '!F27 -> 0 | G27: ='เย็น 102'!G27+'เช้า '!G27+'เย็น '!G27 -> 0 | H27: ='เย็น 102'!H27+'เช้า '!H27+'เย็น '!H27 -> 0 | I27: ='เย็น 102'!I27+'เช้า '!I27+'เย็น '!I27 -> 0 | J27: ='เย็น 102'!J27+'เช้า '!J27+'เย็น '!J27 -> 0 | K27: =SUM(D27:J27) -> 0 | N27: =SUM(L27+M27)-K27 -> 0
B28: 1004055 | C28: ชิฟฟอน 4 ชิ้น มะพร้าวล้วน | D28: ='เย็น 102'!D28+'เช้า '!D28+'เย็น '!D28 -> 0 | E28: ='เย็น 102'!E28+'เช้า '!E28+'เย็น '!E28 -> 0 | F28: ='เย็น 102'!F28+'เช้า '!F28+'เย็น '!F28 -> 0 | G28: ='เย็น 102'!G28+'เช้า '!G28+'เย็น '!G28 -> 0 | H28: ='เย็น 102'!H28+'เช้า '!H28+'เย็น '!H28 -> 0 | I28: ='เย็น 102'!I28+'เช้า '!I28+'เย็น '!I28 -> 0 | J28: ='เย็น 102'!J28+'เช้า '!J28+'เย็น '!J28 -> 0 | K28: =SUM(D28:J28) -> 0 | N28: =SUM(L28+M28)-K28 -> 0
B29: 1004055 | C29: ชิฟฟอน 4 ชิ้น เนยล้วน | D29: ='เย็น 102'!D29+'เช้า '!D29+'เย็น '!D29 -> 0 | E29: ='เย็น 102'!E29+'เช้า '!E29+'เย็น '!E29 -> 0 | F29: ='เย็น 102'!F29+'เช้า '!F29+'เย็น '!F29 -> 0 | G29: ='เย็น 102'!G29+'เช้า '!G29+'เย็น '!G29 -> 0 | H29: ='เย็น 102'!H29+'เช้า '!H29+'เย็น '!H29 -> 0 | I29: ='เย็น 102'!I29+'เช้า '!I29+'เย็น '!I29 -> 0 | J29: ='เย็น 102'!J29+'เช้า '!J29+'เย็น '!J29 -> 0 | K29: =SUM(D29:J29) -> 0 | N29: =SUM(L29+M29)-K29 -> 0
B30: 1004055 | C30: ชิฟฟอน 4 ชิ้น กาแฟล้วน | D30: ='เย็น 102'!D30+'เช้า '!D30+'เย็น '!D30 -> 0 | E30: ='เย็น 102'!E30+'เช้า '!E30+'เย็น '!E30 -> 0 | F30: ='เย็น 102'!F30+'เช้า '!F30+'เย็น '!F30 -> 0 | G30: ='เย็น 102'!G30+'เช้า '!G30+'เย็น '!G30 -> 0 | H30: ='เย็น 102'!H30+'เช้า '!H30+'เย็น '!H30 -> 0 | I30: ='เย็น 102'!I30+'เช้า '!I30+'เย็น '!I30 -> 0 | J30: ='เย็น 102'!J30+'เช้า '!J30+'เย็น '!J30 -> 0 | K30: =SUM(D30:J30) -> 0 | N30: =SUM(L30+M30)-K30 -> 0
B31: 1004055 | C31: ชิฟฟอน 4 ชิ้น ใบเตยล้วน | D31: ='เย็น 102'!D31+'เช้า '!D31+'เย็น '!D31 -> 0 | E31: ='เย็น 102'!E31+'เช้า '!E31+'เย็น '!E31 -> 0 | F31: ='เย็น 102'!F31+'เช้า '!F31+'เย็น '!F31 -> 0 | G31: ='เย็น 102'!G31+'เช้า '!G31+'เย็น '!G31 -> 0 | H31: ='เย็น 102'!H31+'เช้า '!H31+'เย็น '!H31 -> 0 | I31: ='เย็น 102'!I31+'เช้า '!I31+'เย็น '!I31 -> 0 | J31: ='เย็น 102'!J31+'เช้า '!J31+'เย็น '!J31 -> 0 | K31: =SUM(D31:J31) -> 0 | N31: =SUM(L31+M31)-K31 -> 0
B32: 1004055 | C32: ชิฟฟอน 4 ชิ้น บลูเบอร์รี่ล้วน | D32: ='เย็น 102'!D32+'เช้า '!D32+'เย็น '!D32 -> 0 | E32: ='เย็น 102'!E32+'เช้า '!E32+'เย็น '!E32 -> 0 | F32: ='เย็น 102'!F32+'เช้า '!F32+'เย็น '!F32 -> 0 | G32: ='เย็น 102'!G32+'เช้า '!G32+'เย็น '!G32 -> 0 | H32: ='เย็น 102'!H32+'เช้า '!H32+'เย็น '!H32 -> 0 | I32: ='เย็น 102'!I32+'เช้า '!I32+'เย็น '!I32 -> 0 | J32: ='เย็น 102'!J32+'เช้า '!J32+'เย็น '!J32 -> 0 | K32: =SUM(D32:J32) -> 0 | N32: =SUM(L32+M32)-K32 -> 0
B33: 1004055 | C33: ชิฟฟอน 4 ชิ้น ส้มล้วน | D33: ='เย็น 102'!D33+'เช้า '!D33+'เย็น '!D33 -> 0 | E33: ='เย็น 102'!E33+'เช้า '!E33+'เย็น '!E33 -> 0 | F33: ='เย็น 102'!F33+'เช้า '!F33+'เย็น '!F33 -> 0 | G33: ='เย็น 102'!G33+'เช้า '!G33+'เย็น '!G33 -> 0 | H33: ='เย็น 102'!H33+'เช้า '!H33+'เย็น '!H33 -> 0 | I33: ='เย็น 102'!I33+'เช้า '!I33+'เย็น '!I33 -> 0 | J33: ='เย็น 102'!J33+'เช้า '!J33+'เย็น '!J33 -> 0 | K33: =SUM(D33:J33) -> 0 | N33: =SUM(L33+M33)-K33 -> 0
B34: 1004055 | C34: ชิฟฟอน 4 ชิ้น เผือกล้วน | D34: ='เย็น 102'!D34+'เช้า '!D34+'เย็น '!D34 -> 0 | E34: ='เย็น 102'!E34+'เช้า '!E34+'เย็น '!E34 -> 0 | F34: ='เย็น 102'!F34+'เช้า '!F34+'เย็น '!F34 -> 0 | G34: ='เย็น 102'!G34+'เช้า '!G34+'เย็น '!G34 -> 0 | H34: ='เย็น 102'!H34+'เช้า '!H34+'เย็น '!H34 -> 0 | I34: ='เย็น 102'!I34+'เช้า '!I34+'เย็น '!I34 -> 0 | J34: ='เย็น 102'!J34+'เช้า '!J34+'เย็น '!J34 -> 0 | K34: =SUM(D34:J34) -> 0 | N34: =SUM(L34+M34)-K34 -> 0
B35: 1004055 | C35: ชิฟฟอน 4 ชิ้น สตอเบอรี่ล้วน | D35: ='เย็น 102'!D35+'เช้า '!D35+'เย็น '!D35 -> 0 | E35: ='เย็น 102'!E35+'เช้า '!E35+'เย็น '!E35 -> 0 | F35: ='เย็น 102'!F35+'เช้า '!F35+'เย็น '!F35 -> 0 | G35: ='เย็น 102'!G35+'เช้า '!G35+'เย็น '!G35 -> 0 | H35: ='เย็น 102'!H35+'เช้า '!H35+'เย็น '!H35 -> 0 | I35: ='เย็น 102'!I35+'เช้า '!I35+'เย็น '!I35 -> 0 | J35: ='เย็น 102'!J35+'เช้า '!J35+'เย็น '!J35 -> 0 | K35: =SUM(D35:J35) -> 0 | N35: =SUM(L35+M35)-K35 -> 0
B36: 1004055 | C36: ชิฟฟอน 4 ชิ้น กล้วยหอมล้วน | D36: ='เย็น 102'!D36+'เช้า '!D36+'เย็น '!D36 -> 0 | E36: ='เย็น 102'!E36+'เช้า '!E36+'เย็น '!E36 -> 0 | F36: ='เย็น 102'!F36+'เช้า '!F36+'เย็น '!F36 -> 0 | G36: ='เย็น 102'!G36+'เช้า '!G36+'เย็น '!G36 -> 0 | H36: ='เย็น 102'!H36+'เช้า '!H36+'เย็น '!H36 -> 0 | I36: ='เย็น 102'!I36+'เช้า '!I36+'เย็น '!I36 -> 0 | J36: ='เย็น 102'!J36+'เช้า '!J36+'เย็น '!J36 -> 0 | K36: =SUM(D36:J36) -> 0 | N36: =SUM(L36+M36)-K36 -> 0
B37: 1004055 | C37: ชิฟฟอน 4 ชิ้น ชาเขียวล้วน | D37: ='เย็น 102'!D37+'เช้า '!D37+'เย็น '!D37 -> 0 | E37: ='เย็น 102'!E37+'เช้า '!E37+'เย็น '!E37 -> 0 | F37: ='เย็น 102'!F37+'เช้า '!F37+'เย็น '!F37 -> 0 | G37: ='เย็น 102'!G37+'เช้า '!G37+'เย็น '!G37 -> 0 | H37: ='เย็น 102'!H37+'เช้า '!H37+'เย็น '!H37 -> 0 | I37: ='เย็น 102'!I37+'เช้า '!I37+'เย็น '!I37 -> 0 | J37: ='เย็น 102'!J37+'เช้า '!J37+'เย็น '!J37 -> 0 | K37: =SUM(D37:J37) -> 0 | N37: =SUM(L37+M37)-K37 -> 0
B38: 1004055 | C38: ชิฟฟอน 4 ชิ้น ชาไทยล้วน | D38: ='เย็น 102'!D38+'เช้า '!D38+'เย็น '!D38 -> 0 | E38: ='เย็น 102'!E38+'เช้า '!E38+'เย็น '!E38 -> 0 | F38: ='เย็น 102'!F38+'เช้า '!F38+'เย็น '!F38 -> 0 | G38: ='เย็น 102'!G38+'เช้า '!G38+'เย็น '!G38 -> 0 | H38: ='เย็น 102'!H38+'เช้า '!H38+'เย็น '!H38 -> 0 | I38: ='เย็น 102'!I38+'เช้า '!I38+'เย็น '!I38 -> 0 | J38: ='เย็น 102'!J38+'เช้า '!J38+'เย็น '!J38 -> 0 | K38: =SUM(D38:J38) -> 0 | N38: =SUM(L38+M38)-K38 -> 0
... B66: 1111010 | C66: ชิฟฟอนไส้แยมแยกชิ้น คละรส | D66: ='เย็น 102'!D66+'เช้า '!D66+'เย็น '!D66 -> 0 | E66: ='เย็น 102'!E66+'เช้า '!E66+'เย็น '!E66 -> 0 | F66: ='เย็น 102'!F66+'เช้า '!F66+'เย็น '!F66 -> 0 | G66: ='เย็น 102'!G66+'เช้า '!G66+'เย็น '!G66 -> 0 | H66: ='เย็น 102'!H66+'เช้า '!H66+'เย็น '!H66 -> 0 | I66: ='เย็น 102'!I66+'เช้า '!I66+'เย็น '!I66 -> 0 | J66: ='เย็น 102'!J66+'เช้า '!J66+'เย็น '!J66 -> 0 | K66: =SUM(D66:J66) -> 0 | N66: =SUM(L66+M66)-K66 -> 0
C67: รวม | K67: =SUM(D67:J67) -> 0 | N67: =SUM(L67:M67)-K67 -> 0
B68: ชิฟฟอนไส้แยม 6 ชิ้น
B69: 1111009 | C69: ชิฟฟอนไส้แยมรวมรส 6 ชิ้น | D69: ='เย็น 102'!D69+'เช้า '!D69+'เย็น '!D69 -> 3 | E69: ='เย็น 102'!E69+'เช้า '!E69+'เย็น '!E69 -> 2 | F69: ='เย็น 102'!F69+'เช้า '!F69+'เย็น '!F69 -> 9 | G69: ='เย็น 102'!G69+'เช้า '!G69+'เย็น '!G69 -> 0 | H69: ='เย็น 102'!H69+'เช้า '!H69+'เย็น '!H69 -> 0 | I69: ='เย็น 102'!I69+'เช้า '!I69+'เย็น '!I69 -> 0 | J69: ='เย็น 102'!J69+'เช้า '!J69+'เย็น '!J69 -> 0 | K69: =SUM(D69:J69) -> 14 | L69: 25 | M69: 69 | N69: =SUM(L69+M69)-K69 -> 80
B70: 1111023 | C70: ชิฟฟอนไส้แยมรสสตอเบอร์รี่ล้วน 6 ชิ้น | D70: ='เย็น 102'!D70+'เช้า '!D70+'เย็น '!D70 -> 0 | E70: ='เย็น 102'!E70+'เช้า '!E70+'เย็น '!E70 -> 0 | F70: ='เย็น 102'!F70+'เช้า '!F70+'เย็น '!F70 -> 0 | G70: ='เย็น 102'!G70+'เช้า '!G70+'เย็น '!G70 -> 0 | H70: ='เย็น 102'!H70+'เช้า '!H70+'เย็น '!H70 -> 0 | I70: ='เย็น 102'!I70+'เช้า '!I70+'เย็น '!I70 -> 0 | J70: ='เย็น 102'!J70+'เช้า '!J70+'เย็น '!J70 -> 0 | K70: =SUM(D70:J70) -> 0 | N70: =SUM(L70+M70)-K70 -> 0
B71: 1111016 | C71: ชิฟฟอนไส้แยมรสมะพร้าวล้วน 6 ชิ้น | D71: ='เย็น 102'!D71+'เช้า '!D71+'เย็น '!D71 -> 0 | E71: ='เย็น 102'!E71+'เช้า '!E71+'เย็น '!E71 -> 0 | F71: ='เย็น 102'!F71+'เช้า '!F71+'เย็น '!F71 -> 0 | G71: ='เย็น 102'!G71+'เช้า '!G71+'เย็น '!G71 -> 0 | H71: ='เย็น 102'!H71+'เช้า '!H71+'เย็น '!H71 -> 0 | I71: ='เย็น 102'!I71+'เช้า '!I71+'เย็น '!I71 -> 0 | J71: ='เย็น 102'!J71+'เช้า '!J71+'เย็น '!J71 -> 0 | K71: =SUM(D71:J71) -> 0 | N71: =SUM(L71+M71)-K71 -> 0
...
