Workbook

Sheet เย็น 162
B1: ยอดจริง ออนไลน์ วันที่ 1/11/2567 - เย็น
K2: ยอดรวมผลิต
K3: จำนวน
B4: รหัสสินค้า | C4: สินค้า | D4: ปณ | E4: ชอปปี้ | F4: ลาซาด้า | G4: ติ๊กตอก | H4: ติ๊กตอก2 | I4: ติ๊กตอก3 | J4: ชอยส์ | K4: (กล่อง)
B6: ชิฟฟอนรวมรส
B7: 1111002 | C7: ชิฟฟอนรวมรส 8 ชิ้น | E7: 6 | F7: 132 | K7: =SUM(D7:J7) -> 138
C8: ชิฟฟอนแบบกล่องสุ่มอะไรก็ได้ที่มี | K8: =SUM(D8:J8) -> 0
B9: 1111084 | C9: ชิฟฟอน 8 ชิ้น กาแฟล้วน | K9: =SUM(D9:J9) -> 0
B10: 1111085 | C10: ชิฟฟอน 8 ชิ้น บลูเบอรี่ล้วน | K10: =SUM(D10:J10) -> 0
B11: 1111086 | C11: ชิฟฟอน 8 ชิ้น มะพร้าวล้วน | K11: =SUM(D11:J11) -> 0
B12: 1111087 | C12: ชิฟฟอน 8 ชิ้น สตอเบอรี่ล้วน | K12: =SUM(D12:J12) -> 0
B13: 1111088 | C13: ชิฟฟอน 8 ชิ้น ส้มล้วน | K13: =SUM(D13:J13) -> 0
B14: 1111089 | C14: ชิฟฟอน 8 ชิ้น เนยล้วน | K14: =SUM(D14:J14) -> 0
B15: 1111090 | C15: ชิฟฟอน 8 ชิ้น เผือกล้วน | K15: =SUM(D15:J15) -> 0
B16: 1111091 | C16: ชิฟฟอน 8 ชิ้น ใบเตยล้วน | K16: =SUM(D16:J16) -> 0
B17: 1111092 | C17: ชิฟฟอน 8 ชิ้น กล้วยหอม | K17: =SUM(D17:J17) -> 0
B18: 1111093 | C18: ชิฟฟอน 8 ชิ้น โกโก้ล้วน | K18: =SUM(D18:J18) -> 0
B19: 1111094 | C19: ชิฟฟอน 8 ชิ้น ชาไทยล้วน | K19: =SUM(D19:J19) -> 0
B20: 1111095 | C20: ชิฟฟอน 8 ชิ้น ชาเขียวล้วน | K20: =SUM(D20:J20) -> 0
... B24: 1111043 | C24: ชิฟฟอน 8 ชิ้น มะลิ | K24: =SUM(D24:J24) -> 0
B25: 1111056 | C25: ชิฟฟอน 8 ชิ้น รวมรสยอดฮิต | E25: 3 | F25: 10 | K25: =SUM(D25:J25) -> 13
B26: 1004055 | C26: ชิฟฟอนรวมรส 4 ชิ้น | E26: 3 | G26: 39 | K26: =SUM(D26:J26) -> 42
B27: 1004055 | C27: ชิฟฟอน 4 ชิ้น โกโก้ล้วน | K27: =SUM(D27:J27) -> 0
B28: 1004055 | C28: ชิฟฟอน 4 ชิ้น มะพร้าวล้วน | K28: =SUM(D28:J28) -> 0
B29: 1004055 | C29: ชิฟฟอน 4 ชิ้น เนยล้วน | K29: =SUM(D29:J29) -> 0
B30: 1004055 | C30: ชิฟฟอน 4 ชิ้น กาแฟล้วน | K30: =SUM(D30:J30) -> 0
B31: 1004055 | C31: ชิฟฟอน 4 ชิ้น ใบเตยล้วน | K31: =SUM(D31:J31) -> 0
B32: 1004055 | C32: ชิฟฟอน 4 ชิ้น บลูเบอร์รี่ล้วน | K32: =SUM(D32:J32) -> 0
B33: 1004055 | C33: ชิฟฟอน 4 ชิ้น ส้มล้วน | K33: =SUM(D33:J33) -> 0
B34: 1004055 | C34: ชิฟฟอน 4 ชิ้น เผือกล้วน | K34: =SUM(D34:J34) -> 0
B35: 1004055 | C35: ชิฟฟอน 4 ชิ้น สตอเบอรี่ล้วน | K35: =SUM(D35:J35) -> 0
B36: 1004055 | C36: ชิฟฟอน 4 ชิ้น กล้วยหอมล้วน | K36: =SUM(D36:J36) -> 0
B37: 1004055 | C37: ชิฟฟอน 4 ชิ้น ชาเขียวล้วน | K37: =SUM(D37:J37) -> 0
B38: 1004055 | C38: ชิฟฟอน 4 ชิ้น ชาไทยล้วน | K38: =SUM(D38:J38) -> 0
B39: 1004055 | C39: ชิฟฟอน 4 ชิ้น สับปะรดล้วน | K39: =SUM(D39:J39) -> 0
B40: 1111057 | C40: ชิฟฟอนแยกชิ้น กาแฟ | E40: 8 | K40: =SUM(D40:J40) -> 8
B41: 1111058 | C41: ชิฟฟอนแยกชิ้น ชาเขียว | E41: 4 | K41: =SUM(D41:J41) -> 4
B42: 1111059 | C42: ชิฟฟอนแยกชิ้น ใบเตย | E42: 8 | K42: =SUM(D42:J42) -> 8
B43: 1111060 | C43: ชิฟฟอนแยกชิ้น กล้วยหอม | K43: =SUM(D43:J43) -> 0
B44: 1111061 | C44: ชิฟฟอนแยกชิ้น ชาไทย | E44: 2 | K44: =SUM(D44:J44) -> 2
...

Sheet เช้า 208
B1: ยอดจริง ออนไลน์ วันที่ 1/11/2567 - เช้า
K2: ยอดรวมผลิต
K3: จำนวน
B4: รหัสสินค้า | C4: สินค้า | D4: ปณ | E4: ชอปปี้ | F4: ลาซาด้า | G4: ติ๊กตอก | H4: ติ๊กตอก2 | I4: ติ๊กตอก3 | J4: ชอยส์ | K4: (กล่อง)
B6: ชิฟฟอนรวมรส
B7: 1111002 | C7: ชิฟฟอนรวมรส 8 ชิ้น | D7: 9 | E7: 18 | F7: 35 | G7: 1 | K7: =SUM(D7:J7) -> 63
C8: ชิฟฟอนแบบกล่องสุ่มอะไรก็ได้ที่มี | K8: =SUM(D8:J8) -> 0
B9: 1111084 | C9: ชิฟฟอน 8 ชิ้น กาแฟล้วน | K9: =SUM(D9:J9) -> 0
B10: 1111085 | C10: ชิฟฟอน 8 ชิ้น บลูเบอรี่ล้วน | K10: =SUM(D10:J10) -> 0
B11: 1111086 | C11: ชิฟฟอน 8 ชิ้น มะพร้าวล้วน | K11: =SUM(D11:J11) -> 0
B12: 1111087 | C12: ชิฟฟอน 8 ชิ้น สตอเบอรี่ล้วน | K12: =SUM(D12:J12) -> 0
B13: 1111088 | C13: ชิฟฟอน 8 ชิ้น ส้มล้วน | K13: =SUM(D13:J13) -> 0
B14: 1111089 | C14: ชิฟฟอน 8 ชิ้น เนยล้วน | K14: =SUM(D14:J14) -> 0
B15: 1111090 | C15: ชิฟฟอน 8 ชิ้น เผือกล้วน | K15: =SUM(D15:J15) -> 0
B16: 1111091 | C16: ชิฟฟอน 8 ชิ้น ใบเตยล้วน | K16: =SUM(D16:J16) -> 0
B17: 1111092 | C17: ชิฟฟอน 8 ชิ้น กล้วยหอม | K17: =SUM(D17:J17) -> 0
B18: 1111093 | C18: ชิฟฟอน 8 ชิ้น โกโก้ล้วน | K18: =SUM(D18:J18) -> 0
B19: 1111094 | C19: ชิฟฟอน 8 ชิ้น ชาไทยล้วน | K19: =SUM(D19:J19) -> 0
B20: 1111095 | C20: ชิฟฟอน 8 ชิ้น ชาเขียวล้วน | K20: =SUM(D20:J20) -> 0
... B24: 1111043 | C24: ชิฟฟอน 8 ชิ้น มะลิ | K24: =SUM(D24:J24) -> 0
B25: 1111056 | C25: ชิฟฟอน 8 ชิ้น รวมรสยอดฮิต | D25: 7 | F25: 1 | G25: 3 | K25: =SUM(D25:J25) -> 11
B26: 1004055 | C26: ชิฟฟอนรวมรส 4 ชิ้น | D26: 1 | E26: 3 | F26: 4 | G26: 30 | K26: =SUM(D26:J26) -> 38
B27: 1004055 | C27: ชิฟฟอน 4 ชิ้น โกโก้ล้วน | K27: =SUM(D27:J27) -> 0
B28: 1004055 | C28: ชิฟฟอน 4 ชิ้น มะพร้าวล้วน | K28: =SUM(D28:J28) -> 0
B29: 1004055 | C29: ชิฟฟอน 4 ชิ้น เนยล้วน | K29: =SUM(D29:J29) -> 0
B30: 1004055 | C30: ชิฟฟอน 4 ชิ้น กาแฟล้วน | K30: =SUM(D30:J30) -> 0
B31: 1004055 | C31: ชิฟฟอน 4 ชิ้น ใบเตยล้วน | K31: =SUM(D31:J31) -> 0
B32: 1004055 | C32: ชิฟฟอน 4 ชิ้น บลูเบอร์รี่ล้วน | K32: =SUM(D32:J32) -> 0
B33: 1004055 | C33: ชิฟฟอน 4 ชิ้น ส้มล้วน | K33: =SUM(D33:J33) -> 0
B34: 1004055 | C34: ชิฟฟอน 4 ชิ้น เผือกล้วน | K34: =SUM(D34:J34) -> 0
B35: 1004055 | C35: ชิฟฟอน 4 ชิ้น สตอเบอรี่ล้วน | K35: =SUM(D35:J35) -> 0
B36: 1004055 | C36: ชิฟฟอน 4 ชิ้น กล้วยหอมล้วน | K36: =SUM(D36:J36) -> 0
B37: 1004055 | C37: ชิฟฟอน 4 ชิ้น ชาเขียวล้วน | K37: =SUM(D37:J37) -> 0
B38: 1004055 | C38: ชิฟฟอน 4 ชิ้น ชาไทยล้วน | K38: =SUM(D38:J38) -> 0
B39: 1004055 | C39: ชิฟฟอน 4 ชิ้น สับปะรดล้วน | K39: =SUM(D39:J39) -> 0
B40: 1111057 | C40: ชิฟฟอนแยกชิ้น กาแฟ | D40: 17 | E40: 2 | G40: 3 | J40: 1 | K40: =SUM(D40:J40) -> 23
B41: 1111058 | C41: ชิฟฟอนแยกชิ้น ชาเขียว | D41: 17 | E41: 2 | K41: =SUM(D41:J41) -> 19
B42: 1111059 | C42: ชิฟฟอนแยกชิ้น ใบเตย | D42: 17 | E42: 2 | G42: 60 | K42: =SUM(D42:J42) -> 79
B43: 1111060 | C43: ชิฟฟอนแยกชิ้น กล้วยหอม | D43: 17 | E43: 2 | K43: =SUM(D43:J43) -> 19
B44: 1111061 | C44: ชิฟฟอนแยกชิ้น ชาไทย | D44: 17 | E44: 2 | K44: =SUM(D44:J44) -> 19
...

Sheet รวม
B1: ยอดจริง ออนไลน์ วันที่ 1/11/2567 - รวม
K2: ยอดรวมผลิต | L2: ยอดสตอค | M2: ยอดฟอแคส | N2: รับเกิน | O2: ยังไม่ได้รับเข้า | P2: รวม
K3: จำนวน
B4: รหัสสินค้า | C4: สินค้า | D4: ปณ | E4: ชอปปี้ | F4: ลาซาด้า | G4: ติ๊กตอก | H4: ติ๊กตอก2 | I4: ติ๊กตอก3 | J4: ชอยส์ | K4: (กล่อง)
B6: ชิฟฟอนรวมรส
B7: 1111002 | C7: ชิฟฟอนรวมรส 8 ชิ้น | D7: ='เย็น 162'!D7+'เช้า 208'!D7 -> 9 | E7: ='เย็น 162'!E7+'เช้า 208'!E7 -> 24 | F7: ='เย็น 162'!F7+'เช้า 208'!F7 -> 167 | G7: ='เย็น 162'!G7+'เช้า 208'!G7 -> 1 | H7: ='เย็น 162'!H7+'เช้า 208'!H7 -> 0 | I7: ='เย็น 162'!I7+'เช้า 208'!I7 -> 0 | J7: ='เย็น 162'!J7+'เช้า 208'!J7 -> 0 | K7: =SUM(D7:J7) -> 201 | P7: =(L7+M7+N7+O7)-K7 -> -201 | T7: 35 | U7: 100 | V7: 65
C8: ชิฟฟอนแบบกล่องสุ่มอะไรก็ได้ที่มี | D8: ='เย็น 162'!D8+'เช้า 208'!D8 -> 0 | E8: ='เย็น 162'!E8+'เช้า 208'!E8 -> 0 | F8: ='เย็น 162'!F8+'เช้า 208'!F8 -> 0 | G8: ='เย็น 162'!G8+'เช้า 208'!G8 -> 0 | H8: ='เย็น 162'!H8+'เช้า 208'!H8 -> 0 | I8: ='เย็น 162'!I8+'เช้า 208'!I8 -> 0 | J8: ='เย็น 162'!J8+'เช้า 208'!J8 -> 0 | K8: =SUM(D8:J8) -> 0 | P8: =(L8+M8+N8+O8)-K8 -> 0
B9: 1111084 | C9: ชิฟฟอน 8 ชิ้น กาแฟล้วน | D9: ='เย็น 162'!D9+'เช้า 208'!D9 -> 0 | E9: ='เย็น 162'!E9+'เช้า 208'!E9 -> 0 | F9: ='เย็น 162'!F9+'เช้า 208'!F9 -> 0 | G9: ='เย็น 162'!G9+'เช้า 208'!G9 -> 0 | H9: ='เย็น 162'!H9+'เช้า 208'!H9 -> 0 | I9: ='เย็น 162'!I9+'เช้า 208'!I9 -> 0 | J9: ='เย็น 162'!J9+'เช้า 208'!J9 -> 0 | K9: =SUM(D9:J9) -> 0 | P9: =(L9+M9+N9+O9)-K9 -> 0
B10: 1111085 | C10: ชิฟฟอน 8 ชิ้น บลูเบอรี่ล้วน | D10: ='เย็น 162'!D10+'เช้า 208'!D10 -> 0 | E10: ='เย็น 162'!E10+'เช้า 208'!E10 -> 0 | F10: ='เย็น 162'!F10+'เช้า 208'!F10 -> 0 | G10: ='เย็น 162'!G10+'เช้า 208'!G10 -> 0 | H10: ='เย็น 162'!H10+'เช้า 208'!H10 -> 0 | I10: ='เย็น 162'!I10+'เช้า 208'!I10 -> 0 | J10: ='เย็น 162'!J10+'เช้า 208'!J10 -> 0 | K10: =SUM(D10:J10) -> 0 | P10: =(L10+M10+N10+O10)-K10 -> 0
B11: 1111086 | C11: ชิฟฟอน 8 ชิ้น มะพร้าวล้วน | D11: ='เย็น 162'!D11+'เช้า 208'!D11 -> 0 | E11: ='เย็น 162'!E11+'เช้า 208'!E11 -> 0 | F11: ='เย็น 162'!F11+'เช้า 208'!F11 -> 0 | G11: ='เย็น 162'!G11+'เช้า 208'!G11 -> 0 | H11: ='เย็น 162'!H11+'เช้า 208'!H11 -> 0 | I11: ='เย็น 162'!I11+'เช้า 208'!I11 -> 0 | J11: ='เย็น 162'!J11+'เช้า 208'!J11 -> 0 | K11: =SUM(D11:J11) -> 0 | P11: =(L11+M11+N11+O11)-K11 -> 0
B12: 1111087 | C12: ชิฟฟอน 8 ชิ้น สตอเบอรี่ล้วน | D12: ='เย็น 162'!D12+'เช้า 208'!D12 -> 0 | E12: ='เย็น 162'!E12+'เช้า 208'!E12 -> 0 | F12: ='เย็น 162'!F12+'เช้า 208'!F12 -> 0 | G12: ='เย็น 162'!G12+'เช้า 208'!G12 -> 0 | H12: ='เย็น 162'!H12+'เช้า 208'!H12 -> 0 | I12: ='เย็น 162'!I12+'เช้า 208'!I12 -> 0 | J12: ='เย็น 162'!J12+'เช้า 208'!J12 -> 0 | K12: =SUM(D12:J12) -> 0 | P12: =(L12+M12+N12+O12)-K12 -> 0
B13: 1111088 | C13: ชิฟฟอน 8 ชิ้น ส้มล้วน | D13: ='เย็น 162'!D13+'เช้า 208'!D13 -> 0 | E13: ='เย็น 162'!E13+'เช้า 208'!E13 -> 0 | F13: ='เย็น 162'!F13+'เช้า 208'!F13 -> 0 | G13: ='เย็น 162'!G13+'เช้า 208'!G13 -> 0 | H13: ='เย็น 162'!H13+'เช้า 208'!H13 -> 0 | I13: ='เย็น 162'!I13+'เช้า 208'!I13 -> 0 | J13: ='เย็น 162'!J13+'เช้า 208'!J13 -> 0 | K13: =SUM(D13:J13) -> 0 | P13: =(L13+M13+N13+O13)-K13 -> 0
B14: 1111089 | C14: ชิฟฟอน 8 ชิ้น เนยล้วน | D14: ='เย็น 162'!D14+'เช้า 208'!D14 -> 0 | E14: ='เย็น 162'!E14+'เช้า 208'!E14 -> 0 | F14: ='เย็น 162'!F14+'เช้า 208'!F14 -> 0 | G14: ='เย็น 162'!G14+'เช้า 208'!G14 -> 0 | H14: ='เย็น 162'!H14+'เช้า 208'!H14 -> 0 | I14: ='เย็น 162'!I14+'เช้า 208'!I14 -> 0 | J14: ='เย็น 162'!J14+'เช้า 208'!J14 -> 0 | K14: =SUM(D14:J14) -> 0 | P14: =(L14+M14+N14+O14)-K14 -> 0
B15: 1111090 | C15: ชิฟฟอน 8 ชิ้น เผือกล้วน | D15: ='เย็น 162'!D15+'เช้า 208'!D15 -> 0 | E15: ='เย็น 162'!E15+'เช้า 208'!E15 -> 0 | F15: ='เย็น 162'!F15+'เช้า 208'!F15 -> 0 | G15: ='เย็น 162'!G15+'เช้า 208'!G15 -> 0 | H15: ='เย็น 162'!H15+'เช้า 208'!H15 -> 0 | I15: ='เย็น 162'!I15+'เช้า 208'!I15 -> 0 | J15: ='เย็น 162'!J15+'เช้า 208'!J15 -> 0 | K15: =SUM(D15:J15) -> 0 | P15: =(L15+M15+N15+O15)-K15 -> 0
B16: 1111091 | C16: ชิฟฟอน 8 ชิ้น ใบเตยล้วน | D16: ='เย็น 162'!D16+'เช้า 208'!D16 -> 0 | E16: ='เย็น 162'!E16+'เช้า 208'!E16 -> 0 | F16: ='เย็น 162'!F16+'เช้า 208'!F16 -> 0 | G16: ='เย็น 162'!G16+'เช้า 208'!G16 -> 0 | H16: ='เย็น 162'!H16+'เช้า 208'!H16 -> 0 | I16: ='เย็น 162'!I16+'เช้า 208'!I16 -> 0 | J16: ='เย็น 162'!J16+'เช้า 208'!J16 -> 0 | K16: =SUM(D16:J16) -> 0 | P16: =(L16+M16+N16+O16)-K16 -> 0
B17: 1111092 | C17: ชิฟฟอน 8 ชิ้น กล้วยหอม | D17: ='เย็น 162'!D17+'เช้า 208'!D17 -> 0 | E17: ='เย็น 162'!E17+'เช้า 208'!E17 -> 0 | F17: ='เย็น 162'!F17+'เช้า 208'!F17 -> 0 | G17: ='เย็น 162'!G17+'เช้า 208'!G17 -> 0 | H17: ='เย็น 162'!H17+'เช้า 208'!H17 -> 0 | I17: ='เย็น 162'!I17+'เช้า 208'!I17 -> 0 | J17: ='เย็น 162'!J17+'เช้า 208'!J17 -> 0 | K17: =SUM(D17:J17) -> 0 | P17: =(L17+M17+N17+O17)-K17 -> 0
B18: 1111093 | C18: ชิฟฟอน 8 ชิ้น โกโก้ล้วน | D18: ='เย็น 162'!D18+'เช้า 208'!D18 -> 0 | E18: ='เย็น 162'!E18+'เช้า 208'!E18 -> 0 | F18: ='เย็น 162'!F18+'เช้า 208'!F18 -> 0 | G18: ='เย็น 162'!G18+'เช้า 208'!G18 -> 0 | H18: ='เย็น 162'!H18+'เช้า 208'!H18 -> 0 | I18: ='เย็น 162'!I18+'เช้า 208'!I18 -> 0 | J18: ='เย็น 162'!J18+'เช้า 208'!J18 -> 0 | K18: =SUM(D18:J18) -> 0 | P18: =(L18+M18+N18+O18)-K18 -> 0
B19: 1111094 | C19: ชิฟฟอน 8 ชิ้น ชาไทยล้วน | D19: ='เย็น 162'!D19+'เช้า 208'!D19 -> 0 | E19: ='เย็น 162'!E19+'เช้า 208'!E19 -> 0 | F19: ='เย็น 162'!F19+'เช้า 208'!F19 -> 0 | G19: ='เย็น 162'!G19+'เช้า 208'!G19 -> 0 | H19: ='เย็น 162'!H19+'เช้า 208'!H19 -> 0 | I19: ='เย็น 162'!I19+'เช้า 208'!I19 -> 0 | J19: ='เย็น 162'!J19+'เช้า 208'!J19 -> 0 | K19: =SUM(D19:J19) -> 0 | P19: =(L19+M19+N19+O19)-K19 -> 0
B20: 1111095 | C20: ชิฟฟอน 8 ชิ้น ชาเขียวล้วน | D20: ='เย็น 162'!D20+'เช้า 208'!D20 -> 0 | E20: ='เย็น 162'!E20+'เช้า 208'!E20 -> 0 | F20: ='เย็น 162'!F20+'เช้า 208'!F20 -> 0 | G20: ='เย็น 162'!G20+'เช้า 208'!G20 -> 0 | H20: ='เย็น 162'!H20+'เช้า 208'!H20 -> 0 | I20: ='เย็น 162'!I20+'เช้า 208'!I20 -> 0 | J20: ='เย็น 162'!J20+'เช้า 208'!J20 -> 0 | K20: =SUM(D20:J20) -> 0 | P20: =(L20+M20+N20+O20)-K20 -> 0
... B25: 1111056 | C25: ชิฟฟอน 8 ชิ้น รวมรสยอดฮิต | D25: ='เย็น 162'!D25+'เช้า 208'!D25 -> 7 | E25: ='เย็น 162'!E25+'เช้า 208'!E25 -> 3 | F25: ='เย็น 162'!F25+'เช้า 208'!F25 -> 11 | G25: ='เย็น 162'!G25+'เช้า 208'!G25 -> 3 | H25: ='เย็น 162'!H25+'เช้า 208'!H25 -> 0 | I25: ='เย็น 162'!I25+'เช้า 208'!I25 -> 0 | J25: ='เย็น 162'!J25+'เช้า 208'!J25 -> 0 | K25: =SUM(D25:J25) -> 24 | P25: =(L25+M25+N25+O25)-K25 -> -24
B26: 1004055 | C26: ชิฟฟอนรวมรส 4 ชิ้น | D26: ='เย็น 162'!D26+'เช้า 208'!D26 -> 1 | E26: ='เย็น 162'!E26+'เช้า 208'!E26 -> 6 | F26: ='เย็น 162'!F26+'เช้า 208'!F26 -> 4 | G26: ='เย็น 162'!G26+'เช้า 208'!G26 -> 69 | H26: ='เย็น 162'!H26+'เช้า 208'!H26 -> 0 | I26: ='เย็น 162'!I26+'เช้า 208'!I26 -> 0 | J26: ='เย็น 162'!J26+'เช้า 208'!J26 -> 0 | K26: =SUM(D26:J26) -> 80 | P26: =(L26+M26+N26+O26)-K26 -> -80 | U26: 156 | V26: 200 | W26: =U26+V26-56 -> 300
B27: 1004055 | C27: ชิฟฟอน 4 ชิ้น โกโก้ล้วน | D27: ='เย็น 162'!D27+'เช้า 208'!D27 -> 0 | E27: ='เย็น 162'!E27+'เช้า 208'!E27 -> 0 | F27: ='เย็น 162'!F27+'เช้า 208'!F27 -> 0 | G27: ='เย็น 162'!G27+'เช้า 208'!G27 -> 0 | H27: ='เย็น 162'!H27+'เช้า 208'!H27 -> 0 | I27: ='เย็น 162'!I27+'เช้า 208'!I27 -> 0 | J27: ='เย็น 162'!J27+'เช้า 208'!J27 -> 0 | K27: =SUM(D27:J27) -> 0 | P27: =(L27+M27+N27+O27)-K27 -> 0
B28: 1004055 | C28: ชิฟฟอน 4 ชิ้น มะพร้าวล้วน | D28: ='เย็น 162'!D28+'เช้า 208'!D28 -> 0 | E28: ='เย็น 162'!E28+'เช้า 208'!E28 -> 0 | F28: ='เย็น 162'!F28+'เช้า 208'!F28 -> 0 | G28: ='เย็น 162'!G28+'เช้า 208'!G28 -> 0 | H28: ='เย็น 162'!H28+'เช้า 208'!H28 -> 0 | I28: ='เย็น 162'!I28+'เช้า 208'!I28 -> 0 | J28: ='เย็น 162'!J28+'เช้า 208'!J28 -> 0 | K28: =SUM(D28:J28) -> 0 | P28: =(L28+M28+N28+O28)-K28 -> 0
B29: 1004055 | C29: ชิฟฟอน 4 ชิ้น เนยล้วน | D29: ='เย็น 162'!D29+'เช้า 208'!D29 -> 0 | E29: ='เย็น 162'!E29+'เช้า 208'!E29 -> 0 | F29: ='เย็น 162'!F29+'เช้า 208'!F29 -> 0 | G29: ='เย็น 162'!G29+'เช้า 208'!G29 -> 0 | H29: ='เย็น 162'!H29+'เช้า 208'!H29 -> 0 | I29: ='เย็น 162'!I29+'เช้า 208'!I29 -> 0 | J29: ='เย็น 162'!J29+'เช้า 208'!J29 -> 0 | K29: =SUM(D29:J29) -> 0 | P29: =(L29+M29+N29+O29)-K29 -> 0
B30: 1004055 | C30: ชิฟฟอน 4 ชิ้น กาแฟล้วน | D30: ='เย็น 162'!D30+'เช้า 208'!D30 -> 0 | E30: ='เย็น 162'!E30+'เช้า 208'!E30 -> 0 | F30: ='เย็น 162'!F30+'เช้า 208'!F30 -> 0 | G30: ='เย็น 162'!G30+'เช้า 208'!G30 -> 0 | H30: ='เย็น 162'!H30+'เช้า 208'!H30 -> 0 | I30: ='เย็น 162'!I30+'เช้า 208'!I30 -> 0 | J30: ='เย็น 162'!J30+'เช้า 208'!J30 -> 0 | K30: =SUM(D30:J30) -> 0 | P30: =(L30+M30+N30+O30)-K30 -> 0
B31: 1004055 | C31: ชิฟฟอน 4 ชิ้น ใบเตยล้วน | D31: ='เย็น 162'!D31+'เช้า 208'!D31 -> 0 | E31: ='เย็น 162'!E31+'เช้า 208'!E31 -> 0 | F31: ='เย็น 162'!F31+'เช้า 208'!F31 -> 0 | G31: ='เย็น 162'!G31+'เช้า 208'!G31 -> 0 | H31: ='เย็น 162'!H31+'เช้า 208'!H31 -> 0 | I31: ='เย็น 162'!I31+'เช้า 208'!I31 -> 0 | J31: ='เย็น 162'!J31+'เช้า 208'!J31 -> 0 | K31: =SUM(D31:J31) -> 0 | P31: =(L31+M31+N31+O31)-K31 -> 0
B32: 1004055 | C32: ชิฟฟอน 4 ชิ้น บลูเบอร์รี่ล้วน | D32: ='เย็น 162'!D32+'เช้า 208'!D32 -> 0 | E32: ='เย็น 162'!E32+'เช้า 208'!E32 -> 0 | F32: ='เย็น 162'!F32+'เช้า 208'!F32 -> 0 | G32: ='เย็น 162'!G32+'เช้า 208'!G32 -> 0 | H32: ='เย็น 162'!H32+'เช้า 208'!H32 -> 0 | I32: ='เย็น 162'!I32+'เช้า 208'!I32 -> 0 | J32: ='เย็น 162'!J32+'เช้า 208'!J32 -> 0 | K32: =SUM(D32:J32) -> 0 | P32: =(L32+M32+N32+O32)-K32 -> 0
B33: 1004055 | C33: ชิฟฟอน 4 ชิ้น ส้มล้วน | D33: ='เย็น 162'!D33+'เช้า 208'!D33 -> 0 | E33: ='เย็น 162'!E33+'เช้า 208'!E33 -> 0 | F33: ='เย็น 162'!F33+'เช้า 208'!F33 -> 0 | G33: ='เย็น 162'!G33+'เช้า 208'!G33 -> 0 | H33: ='เย็น 162'!H33+'เช้า 208'!H33 -> 0 | I33: ='เย็น 162'!I33+'เช้า 208'!I33 -> 0 | J33: ='เย็น 162'!J33+'เช้า 208'!J33 -> 0 | K33: =SUM(D33:J33) -> 0 | P33: =(L33+M33+N33+O33)-K33 -> 0
B34: 1004055 | C34: ชิฟฟอน 4 ชิ้น เผือกล้วน | D34: ='เย็น 162'!D34+'เช้า 208'!D34 -> 0 | E34: ='เย็น 162'!E34+'เช้า 208'!E34 -> 0 | F34: ='เย็น 162'!F34+'เช้า 208'!F34 -> 0 | G34: ='เย็น 162'!G34+'เช้า 208'!G34 -> 0 | H34: ='เย็น 162'!H34+'เช้า 208'!H34 -> 0 | I34: ='เย็น 162'!I34+'เช้า 208'!I34 -> 0 | J34: ='เย็น 162'!J34+'เช้า 208'!J34 -> 0 | K34: =SUM(D34:J34) -> 0 | P34: =(L34+M34+N34+O34)-K34 -> 0
B35: 1004055 | C35: ชิฟฟอน 4 ชิ้น สตอเบอรี่ล้วน | D35: ='เย็น 162'!D35+'เช้า 208'!D35 -> 0 | E35: ='เย็น 162'!E35+'เช้า 208'!E35 -> 0 | F35: ='เย็น 162'!F35+'เช้า 208'!F35 -> 0 | G35: ='เย็น 162'!G35+'เช้า 208'!G35 -> 0 | H35: ='เย็น 162'!H35+'เช้า 208'!H35 -> 0 | I35: ='เย็น 162'!I35+'เช้า 208'!I35 -> 0 | J35: ='เย็น 162'!J35+'เช้า 208'!J35 -> 0 | K35: =SUM(D35:J35) -> 0 | P35: =(L35+M35+N35+O35)-K35 -> 0
B36: 1004055 | C36: ชิฟฟอน 4 ชิ้น กล้วยหอมล้วน | D36: ='เย็น 162'!D36+'เช้า 208'!D36 -> 0 | E36: ='เย็น 162'!E36+'เช้า 208'!E36 -> 0 | F36: ='เย็น 162'!F36+'เช้า 208'!F36 -> 0 | G36: ='เย็น 162'!G36+'เช้า 208'!G36 -> 0 | H36: ='เย็น 162'!H36+'เช้า 208'!H36 -> 0 | I36: ='เย็น 162'!I36+'เช้า 208'!I36 -> 0 | J36: ='เย็น 162'!J36+'เช้า 208'!J36 -> 0 | K36: =SUM(D36:J36) -> 0 | P36: =(L36+M36+N36+O36)-K36 -> 0
B37: 1004055 | C37: ชิฟฟอน 4 ชิ้น ชาเขียวล้วน | D37: ='เย็น 162'!D37+'เช้า 208'!D37 -> 0 | E37: ='เย็น 162'!E37+'เช้า 208'!E37 -> 0 | F37: ='เย็น 162'!F37+'เช้า 208'!F37 -> 0 | G37: ='เย็น 162'!G37+'เช้า 208'!G37 -> 0 | H37: ='เย็น 162'!H37+'เช้า 208'!H37 -> 0 | I37: ='เย็น 162'!I37+'เช้า 208'!I37 -> 0 | J37: ='เย็น 162'!J37+'เช้า 208'!J37 -> 0 | K37: =SUM(D37:J37) -> 0 | P37: =(L37+M37+N37+O37)-K37 -> 0
B38: 1004055 | C38: ชิฟฟอน 4 ชิ้น ชาไทยล้วน | D38: ='เย็น 162'!D38+'เช้า 208'!D38 -> 0 | E38: ='เย็น 162'!E38+'เช้า 208'!E38 -> 0 | F38: ='เย็น 162'!F38+'เช้า 208'!F38 -> 0 | G38: ='เย็น 162'!G38+'เช้า 208'!G38 -> 0 | H38: ='เย็น 162'!H38+'เช้า 208'!H38 -> 0 | I38: ='เย็น 162'!I38+'เช้า 208'!I38 -> 0 | J38: ='เย็น 162'!J38+'เช้า 208'!J38 -> 0 | K38: =SUM(D38:J38) -> 0 | P38: =(L38+M38+N38+O38)-K38 -> 0
... B54: 1111071 | C54: ชิฟฟอนแยกชิ้น ตาล | D54: ='เย็น 162'!D54+'เช้า 208'!D54 -> 16 | E54: ='เย็น 162'!E54+'เช้า 208'!E54 -> 2 | F54: ='เย็น 162'!F54+'เช้า 208'!F54 -> 0 | G54: ='เย็น 162'!G54+'เช้า 208'!G54 -> 0 | H54: ='เย็น 162'!H54+'เช้า 208'!H54 -> 0 | I54: ='เย็น 162'!I54+'เช้า 208'!I54 -> 0 | J54: ='เย็น 162'!J54+'เช้า 208'!J54 -> 0 | K54: =SUM(D54:J54) -> 18 | P54: =(L54+M54+N54+O54)-K54 -> -18
B55: 1111001 | C55: ชิฟฟอนแยกชิ้น คละรส | E55: ='เย็น 162'!E55+'เช้า 208'!E55 -> 0 | F55: ='เย็น 162'!F55+'เช้า 208'!F55 -> 0 | G55: ='เย็น 162'!G55+'เช้า 208'!G55 -> 0 | H55: ='เย็น 162'!H55+'เช้า 208'!H55 -> 0 | I55: ='เย็น 162'!I55+'เช้า 208'!I55 -> 0 | J55: ='เย็น 162'!J55+'เช้า 208'!J55 -> 0 | K55: =SUM(D55:J55) -> 0 | P55: =(L55+M55+N55+O55)-K55 -> 0
B56: 1111074 | C56: ชิฟฟอนไส้แยมแยกชิ้น มะพร้าว | D56: ='เย็น 162'!D56+'เช้า 208'!D56 -> 2 | E56: ='เย็น 162'!E56+'เช้า 208'!E56 -> 0 | F56: ='เย็น 162'!F56+'เช้า 208'!F56 -> 1 | G56: ='เย็น 162'!G56+'เช้า 208'!G56 -> 53 | H56: ='เย็น 162'!H56+'เช้า 208'!H56 -> 0 | I56: ='เย็น 162'!I56+'เช้า 208'!I56 -> 0 | J56: ='เย็น 162'!J56+'เช้า 208'!J56 -> 0 | K56: =SUM(D56:J56) -> 56 | P56: =(L56+M56+N56+O56)-K56 -> -56
B57: 1111075 | C57: ชิฟฟอนไส้แยมแยกชิ้น สตอเบอรี่ | D57: ='เย็น 162'!D57+'เช้า 208'!D57 -> 2 | E57: ='เย็น 162'!E57+'เช้า 208'!E57 -> 0 | F57: ='เย็น 162'!F57+'เช้า 208'!F57 -> 1 | G57: ='เย็น 162'!G57+'เช้า 208'!G57 -> 51 | H57: ='เย็น 162'!H57+'เช้า 208'!H57 -> 0 | I57: ='เย็น 162'!I57+'เช้า 208'!I57 -> 0 | J57: ='เย็น 162'!J57+'เช้า 208'!J57 -> 0 | K57: =SUM(D57:J57) -> 54 | P57: =(L57+M57+N57+O57)-K57 -> -54
B58: 1111076 | C58: ชิฟฟอนไส้แยมแยกชิ้น ส้ม | D58: ='เย็น 162'!D58+'เช้า 208'!D58 -> 2 | E58: ='เย็น 162'!E58+'เช้า 208'!E58 -> 0 | F58: ='เย็น 162'!F58+'เช้า 208'!F58 -> 1 | G58: ='เย็น 162'!G58+'เช้า 208'!G58 -> 51 | H58: ='เย็น 162'!H58+'เช้า 208'!H58 -> 0 | I58: ='เย็น 162'!I58+'เช้า 208'!I58 -> 0 | J58: ='เย็น 162'!J58+'เช้า 208'!J58 -> 0 | K58: =SUM(D58:J58) -> 54 | P58: =(L58+M58+N58+O58)-K58 -> -54
B59: 1111077 | C59: ชิฟฟอนไส้แยมแยกชิ้น บลูเบอรี่ | D59: ='เย็น 162'!D59+'เช้า 208'!D59 -> 2 | E59: ='เย็น 162'!E59+'เช้า 208'!E59 -> 0 | F59: ='เย็น 162'!F59+'เช้า 208'!F59 -> 1 | G59: ='เย็น 162'!G59+'เช้า 208'!G59 -> 51 | H59: ='เย็น 162'!H59+'เช้า 208'!H59 -> 0 | I59: ='เย็น 162'!I59+'เช้า 208'!I59 -> 0 | J59: ='เย็น 162'!J59+'เช้า 208'!J59 -> 0 | K59: =SUM(D59:J59) -> 54 | P59: =(L59+M59+N59+O59)-K59 -> -54
B60: 1111078 | C60: ชิฟฟอนไส้แยมแยกชิ้น นมชมพู | D60: ='เย็น 162'!D60+'เช้า 208'!D60 -> 2 | E60: ='เย็น 162'!E60+'เช้า 208'!E60 -> 0 | F60: ='เย็น 162'!F60+'เช้า 208'!F60 -> 1 | G60: ='เย็น 162'!G60+'เช้า 208'!G60 -> 51 | H60: ='เย็น 162'!H60+'เช้า 208'!H60 -> 0 | I60: ='เย็น 162'!I60+'เช้า 208'!I60 -> 0 | J60: ='เย็น 162'!J60+'เช้า 208'!J60 -> 0 | K60: =SUM(D60:J60) -> 54 | P60: =(L60+M60+N60+O60)-K60 -> -54
...
