Workbook

Sheet เย็น 102
B1: ยอดจริง ออนไลน์ วันที่ 25/10/2567 - เย็น
K2: ยอดรวมผลิต
K3: จำนวน
B4: รหัสสินค้า | C4: สินค้า | D4: ปณ | E4: ชอปปี้ | F4: ลาซาด้า | G4: ติ๊กตอก | H4: ติ๊กตอก 2 | I4: ติ๊กตอก3 | J4: ชอยส์ | K4: (กล่อง)
B6: ชิฟฟอนรวมรส
B7: 1111002 | C7: ชิฟฟอนรวมรส 8 ชิ้น | K7: =SUM(D7:J7) -> 0
C8: ชิฟฟอนแบบกล่องสุ่มอะไรก็ได้ที่มี | K8: =SUM(D8:J8) -> 0
B9: 1111084 | C9: ชิฟฟอน 8 ชิ้น กาแฟล้วน | K9: =SUM(D9:J9) -> 0
B10: 1111085 | C10: ชิฟฟอน 8 ชิ้น บลูเบอรี่ล้วน | K10: =SUM(D10:J10) -> 0
B11: 1111086 | C11: ชิฟฟอน 8 ชิ้น มะพร้าวล้วน | K11: =SUM(D11:J11) -> 0
B12: 1111087 | C12: ชิฟฟอน 8 ชิ้น สตอเบอรี่ล้วน | K12: =SUM(D12:J12) -> 0
B13: 1111088 | C13: ชิฟฟอน 8 ชิ้น ส้มล้วน | K13: =SUM(D13:J13) -> 0
B14: 1111089 | C14: ชิฟฟอน 8 ชิ้น เนยล้วน | K14: =SUM(D14:J14) -> 0
B15: 1111090 | C15: ชิฟฟอน 8 ชิ้น เผือกล้วน | K15: =SUM(D15:J15) -> 0
B16: 1111091 | C16: ชิฟฟอน 8 ชิ้น ใบเตยล้วน | K16: =SUM(D16:J16) -> 0
B17: 1111092 | C17: ชิฟฟอน 8 ชิ้น กล้วยหอม | K17: =SUM(D17:J17) -> 0
B18: 1111093 | C18: ชิฟฟอน 8 ชิ้น โกโก้ล้วน | K18: =SUM(D18:J18) -> 0
B19: 1111094 | C19: ชิฟฟอน 8 ชิ้น ชาไทยล้วน | K19: =SUM(D19:J19) -> 0
B20: 1111095 | C20: ชิฟฟอน 8 ชิ้น ชาเขียวล้วน | K20: =SUM(D20:J20) -> 0
... B66: 1111010 | C66: ชิฟฟอนไส้แยมแยกชิ้น คละรส | K66: =SUM(D66:J66) -> 0
C67: รวม
B68: ชิฟฟอนไส้แยม 6 ชิ้น
B69: 1111009 | C69: ชิฟฟอนไส้แยมรวมรส 6 ชิ้น | K69: =SUM(D69:J69) -> 0
B70: 1111023 | C70: ชิฟฟอนไส้แยมรสสตอเบอร์รี่ล้วน 6 ชิ้น | K70: =SUM(D70:J70) -> 0
B71: 1111016 | C71: ชิฟฟอนไส้แยมรสมะพร้าวล้วน 6 ชิ้น | K71: =SUM(D71:J71) -> 0
B72: 1111014 | C72: ชิฟฟอนไส้แยมรสช็อกโกแลตนูเทลล่าล้วน 6 ชิ้น | K72: =SUM(D72:J72) -> 0
B73: 1111025 | C73: ชิฟฟอนไส้แยมรสส้มล้วน 6 ชิ้น | K73: =SUM(D73:J73) -> 0
B74: 1111018 | C74: ชิฟฟอนไส้แยมรสบลูเบอร์รี่ล้วน 6 ชิ้น | K74: =SUM(D74:J74) -> 0
B75: 1111012 | C75: ชิฟฟอนไส้แยมรสนมชมพูฮอกไกโดล้วน 6 ชิ้น | K75: =SUM(D75:J75) -> 0
B76: 1111020 | C76: ชิฟฟอนไส้แยมฝอยทองไส้ทะลัก 6 ชิ้น | K76: =SUM(D76:J76) -> 0
C77: รวม
B78: ชิฟฟอนไส้แยม 3 ชิ้น
B79: 1111022 | C79: ชิฟฟอนไส้แยมรสสตอเบอร์รี่ล้วน 3 ชิ้น | K79: =SUM(D79:J79) -> 0
B80: 1111015 | C80: ชิฟฟอนไส้แยมรสมะพร้าวล้วน 3 ชิ้น | K80: =SUM(D80:J80) -> 0
B81: 1111013 | C81: ชิฟฟอนไส้แยมรสช็อกโกแลตนูเทลล่าล้วน 3 ชิ้น | K81: =SUM(D81:J81) -> 0
B82: 1111024 | C82: ชิฟฟอนไส้แยมรสส้มล้วน 3 ชิ้น | K82: =SUM(D82:J82) -> 0
B83: 1111017 | C83: ชิฟฟอนไส้แยมรสบลูเบอร์รี่ล้วน 3 ชิ้น | K83: =SUM(D83:J83) -> 0
B84: 1111011 | C84: ชิฟฟอนไส้แยมรสนมชมพูฮอกไกโดล้วน 3 ชิ้น | K84: =SUM(D84:J84) -> 0
B85: 1111019 | C85: ชิฟฟอนไส้แยมฝอยทองไส้ทะลัก 3 ชิ้น | K85: =SUM(D85:J85) -> 0
B86: 1113081 | C86: ชิฟฟอนไส้แยม วนิลา/ใบเตย/เมล่อน | K86: =SUM(D86:J86) -> 0
...

Sheet เช้า 
B1: ยอดจริง ออนไลน์ วันที่ 18/11/2567 เช้า
K2: ยอดรวมผลิต
K3: จำนวน
B4: รหัสสินค้า | C4: สินค้า | D4: ปณ | E4: ชอปปี้ | F4: ลาซาด้า | G4: ติ๊กตอก | H4: ติ๊กตอก2 | I4: ติ๊กตอก3 | J4: ชอยส์ | K4: (กล่อง)
B6: ชิฟฟอนรวมรส
B7: 1111002 | C7: ชิฟฟอนรวมรส 8 ชิ้น | E7: 16 | F7: 64 | G7: 2 | K7: =SUM(D7:J7) -> 82
C8: ชิฟฟอนแบบกล่องสุ่มอะไรก็ได้ที่มี | K8: =SUM(D8:J8) -> 0
B9: 1111084 | C9: ชิฟฟอน 8 ชิ้น กาแฟล้วน | K9: =SUM(D9:J9) -> 0
B10: 1111085 | C10: ชิฟฟอน 8 ชิ้น บลูเบอรี่ล้วน | K10: =SUM(D10:J10) -> 0
B11: 1111086 | C11: ชิฟฟอน 8 ชิ้น มะพร้าวล้วน | K11: =SUM(D11:J11) -> 0
B12: 1111087 | C12: ชิฟฟอน 8 ชิ้น สตอเบอรี่ล้วน | K12: =SUM(D12:J12) -> 0
B13: 1111088 | C13: ชิฟฟอน 8 ชิ้น ส้มล้วน | K13: =SUM(D13:J13) -> 0
B14: 1111089 | C14: ชิฟฟอน 8 ชิ้น เนยล้วน | K14: =SUM(D14:J14) -> 0
B15: 1111090 | C15: ชิฟฟอน 8 ชิ้น เผือกล้วน | K15: =SUM(D15:J15) -> 0
B16: 1111091 | C16: ชิฟฟอน 8 ชิ้น ใบเตยล้วน | K16: =SUM(D16:J16) -> 0
B17: 1111092 | C17: ชิฟฟอน 8 ชิ้น กล้วยหอม | K17: =SUM(D17:J17) -> 0
B18: 1111093 | C18: ชิฟฟอน 8 ชิ้น โกโก้ล้วน | K18: =SUM(D18:J18) -> 0
B19: 1111094 | C19: ชิฟฟอน 8 ชิ้น ชาไทยล้วน | K19: =SUM(D19:J19) -> 0
B20: 1111095 | C20: ชิฟฟอน 8 ชิ้น ชาเขียวล้วน | K20: =SUM(D20:J20) -> 0
... B24: 1111043 | C24: ชิฟฟอน 8 ชิ้น มะลิ | K24: =SUM(D24:J24) -> 0
B25: 1111056 | C25: ชิฟฟอน 8 ชิ้น รวมรสยอดฮิต | E25: 1 | G25: 1 | K25: =SUM(D25:J25) -> 2
B26: 1004055 | C26: ชิฟฟอนรวมรส 4 ชิ้น | F26: 10 | G26: 18 | H26: 6 | K26: =SUM(D26:J26) -> 34
B27: 1004055 | C27: ชิฟฟอน 4 ชิ้น โกโก้ล้วน | K27: =SUM(D27:J27) -> 0
B28: 1004055 | C28: ชิฟฟอน 4 ชิ้น มะพร้าวล้วน | K28: =SUM(D28:J28) -> 0
B29: 1004055 | C29: ชิฟฟอน 4 ชิ้น เนยล้วน | K29: =SUM(D29:J29) -> 0
B30: 1004055 | C30: ชิฟฟอน 4 ชิ้น กาแฟล้วน | K30: =SUM(D30:J30) -> 0
B31: 1004055 | C31: ชิฟฟอน 4 ชิ้น ใบเตยล้วน | K31: =SUM(D31:J31) -> 0
B32: 1004055 | C32: ชิฟฟอน 4 ชิ้น บลูเบอร์รี่ล้วน | K32: =SUM(D32:J32) -> 0
B33: 1004055 | C33: ชิฟฟอน 4 ชิ้น ส้มล้วน | K33: =SUM(D33:J33) -> 0
B34: 1004055 | C34: ชิฟฟอน 4 ชิ้น เผือกล้วน | K34: =SUM(D34:J34) -> 0
B35: 1004055 | C35: ชิฟฟอน 4 ชิ้น สตอเบอรี่ล้วน | K35: =SUM(D35:J35) -> 0
B36: 1004055 | C36: ชิฟฟอน 4 ชิ้น กล้วยหอมล้วน | K36: =SUM(D36:J36) -> 0
B37: 1004055 | C37: ชิฟฟอน 4 ชิ้น ชาเขียวล้วน | K37: =SUM(D37:J37) -> 0
B38: 1004055 | C38: ชิฟฟอน 4 ชิ้น ชาไทยล้วน | K38: =SUM(D38:J38) -> 0
B39: 1004055 | C39: ชิฟฟอน 4 ชิ้น สับปะรดล้วน | K39: =SUM(D39:J39) -> 0
B40: 1111057 | C40: ชิฟฟอนแยกชิ้น กาแฟ | D40: 1 | G40: 1 | K40: =SUM(D40:J40) -> 2
B41: 1111058 | C41: ชิฟฟอนแยกชิ้น ชาเขียว | D41: 1 | G41: 1 | K41: =SUM(D41:J41) -> 2
B42: 1111059 | C42: ชิฟฟอนแยกชิ้น ใบเตย | D42: 1 | G42: 1 | K42: =SUM(D42:J42) -> 2
B43: 1111060 | C43: ชิฟฟอนแยกชิ้น กล้วยหอม | D43: 1 | G43: 1 | K43: =SUM(D43:J43) -> 2
B44: 1111061 | C44: ชิฟฟอนแยกชิ้น ชาไทย | D44: 1 | G44: 1 | K44: =SUM(D44:J44) -> 2
...

Sheet บ่าย
B1: ยอดจริง ออนไลน์ วันที่ 18/11/2567 - บ่าย
K2: ยอดรวมผลิต
K3: จำนวน
B4: รหัสสินค้า | C4: สินค้า | D4: ปณ | E4: ชอปปี้ | F4: ลาซาด้า | G4: ติ๊กตอก | H4: ติ๊กตอก2 | I4: ติ๊กตอก3 | J4: ชอยส์ | K4: (กล่อง)
B6: ชิฟฟอนรวมรส
B7: 1111002 | C7: ชิฟฟอนรวมรส 8 ชิ้น | E7: 4 | F7: 2 | K7: =SUM(D7:J7) -> 6
C8: ชิฟฟอนแบบกล่องสุ่มอะไรก็ได้ที่มี | K8: =SUM(D8:J8) -> 0
B9: 1111084 | C9: ชิฟฟอน 8 ชิ้น กาแฟล้วน | K9: =SUM(D9:J9) -> 0
B10: 1111085 | C10: ชิฟฟอน 8 ชิ้น บลูเบอรี่ล้วน | K10: =SUM(D10:J10) -> 0
B11: 1111086 | C11: ชิฟฟอน 8 ชิ้น มะพร้าวล้วน | K11: =SUM(D11:J11) -> 0
B12: 1111087 | C12: ชิฟฟอน 8 ชิ้น สตอเบอรี่ล้วน | K12: =SUM(D12:J12) -> 0
B13: 1111088 | C13: ชิฟฟอน 8 ชิ้น ส้มล้วน | K13: =SUM(D13:J13) -> 0
B14: 1111089 | C14: ชิฟฟอน 8 ชิ้น เนยล้วน | K14: =SUM(D14:J14) -> 0
B15: 1111090 | C15: ชิฟฟอน 8 ชิ้น เผือกล้วน | K15: =SUM(D15:J15) -> 0
B16: 1111091 | C16: ชิฟฟอน 8 ชิ้น ใบเตยล้วน | K16: =SUM(D16:J16) -> 0
B17: 1111092 | C17: ชิฟฟอน 8 ชิ้น กล้วยหอม | K17: =SUM(D17:J17) -> 0
B18: 1111093 | C18: ชิฟฟอน 8 ชิ้น โกโก้ล้วน | K18: =SUM(D18:J18) -> 0
B19: 1111094 | C19: ชิฟฟอน 8 ชิ้น ชาไทยล้วน | K19: =SUM(D19:J19) -> 0
B20: 1111095 | C20: ชิฟฟอน 8 ชิ้น ชาเขียวล้วน | K20: =SUM(D20:J20) -> 0
... B24: 1111043 | C24: ชิฟฟอน 8 ชิ้น มะลิ | K24: =SUM(D24:J24) -> 0
B25: 1111056 | C25: ชิฟฟอน 8 ชิ้น รวมรสยอดฮิต | E25: 4 | F25: 3 | K25: =SUM(D25:J25) -> 7
B26: 1004055 | C26: ชิฟฟอนรวมรส 4 ชิ้น | G26: 27 | K26: =SUM(D26:J26) -> 27
B27: 1004055 | C27: ชิฟฟอน 4 ชิ้น โกโก้ล้วน | K27: =SUM(D27:J27) -> 0
B28: 1004055 | C28: ชิฟฟอน 4 ชิ้น มะพร้าวล้วน | K28: =SUM(D28:J28) -> 0
B29: 1004055 | C29: ชิฟฟอน 4 ชิ้น เนยล้วน | K29: =SUM(D29:J29) -> 0
B30: 1004055 | C30: ชิฟฟอน 4 ชิ้น กาแฟล้วน | K30: =SUM(D30:J30) -> 0
B31: 1004055 | C31: ชิฟฟอน 4 ชิ้น ใบเตยล้วน | K31: =SUM(D31:J31) -> 0
B32: 1004055 | C32: ชิฟฟอน 4 ชิ้น บลูเบอร์รี่ล้วน | K32: =SUM(D32:J32) -> 0
B33: 1004055 | C33: ชิฟฟอน 4 ชิ้น ส้มล้วน | K33: =SUM(D33:J33) -> 0
B34: 1004055 | C34: ชิฟฟอน 4 ชิ้น เผือกล้วน | K34: =SUM(D34:J34) -> 0
B35: 1004055 | C35: ชิฟฟอน 4 ชิ้น สตอเบอรี่ล้วน | K35: =SUM(D35:J35) -> 0
B36: 1004055 | C36: ชิฟฟอน 4 ชิ้น กล้วยหอมล้วน | K36: =SUM(D36:J36) -> 0
B37: 1004055 | C37: ชิฟฟอน 4 ชิ้น ชาเขียวล้วน | K37: =SUM(D37:J37) -> 0
B38: 1004055 | C38: ชิฟฟอน 4 ชิ้น ชาไทยล้วน | K38: =SUM(D38:J38) -> 0
B39: 1004055 | C39: ชิฟฟอน 4 ชิ้น สับปะรดล้วน | K39: =SUM(D39:J39) -> 0
B40: 1111057 | C40: ชิฟฟอนแยกชิ้น กาแฟ | G40: 1 | K40: =SUM(D40:J40) -> 1
B41: 1111058 | C41: ชิฟฟอนแยกชิ้น ชาเขียว | G41: 1 | K41: =SUM(D41:J41) -> 1
B42: 1111059 | C42: ชิฟฟอนแยกชิ้น ใบเตย | G42: 1 | K42: =SUM(D42:J42) -> 1
B43: 1111060 | C43: ชิฟฟอนแยกชิ้น กล้วยหอม | G43: 1 | K43: =SUM(D43:J43) -> 1
B44: 1111061 | C44: ชิฟฟอนแยกชิ้น ชาไทย | G44: 1 | K44: =SUM(D44:J44) -> 1
...

Sheet รวม
B1: ยอดจริง ออนไลน์ วันที่ 18/11/2567 รวม
K2: ยอดรวมผลิต | L2: ยอดฟอแคส | M2: ยอดสตอค | N2: รวม
K3: จำนวน
B4: รหัสสินค้า | C4: สินค้า | D4: ปณ | E4: ชอปปี้ | F4: ลาซาด้า | G4: ติ๊กตอก | H4: ติ๊กตอก2 | I4: ติ๊กตอก3 | J4: ชอยส์ | K4: (กล่อง)
B6: ชิฟฟอนรวมรส
B7: 1111002 | C7: ชิฟฟอนรวมรส 8 ชิ้น | D7: ='เช้า '!D7+บ่าย!D7 -> 0 | E7: ='เช้า '!E7+บ่าย!E7 -> 20 | F7: ='เช้า '!F7+บ่าย!F7 -> 66 | G7: ='เช้า '!G7+บ่าย!G7 -> 2 | H7: ='เช้า '!H7+บ่าย!H7 -> 0 | I7: ='เช้า '!I7+บ่าย!I7 -> 0 | J7: ='เช้า '!J7+บ่าย!J7 -> 0 | K7: =SUM(D7:J7) -> 88 | N7: =SUM(L7+M7)-K7 -> -88
C8: ชิฟฟอนแบบกล่องสุ่มอะไรก็ได้ที่มี | D8: ='เช้า '!D8+บ่าย!D8 -> 0 | E8: ='เช้า '!E8+บ่าย!E8 -> 0 | F8: ='เช้า '!F8+บ่าย!F8 -> 0 | G8: ='เช้า '!G8+บ่าย!G8 -> 0 | H8: ='เช้า '!H8+บ่าย!H8 -> 0 | I8: ='เช้า '!I8+บ่าย!I8 -> 0 | J8: ='เช้า '!J8+บ่าย!J8 -> 0 | K8: =SUM(D8:J8) -> 0 | N8: =SUM(L8+M8)-K8 -> 0
B9: 1111084 | C9: ชิฟฟอน 8 ชิ้น กาแฟล้วน | D9: ='เช้า '!D9+บ่าย!D9 -> 0 | E9: ='เช้า '!E9+บ่าย!E9 -> 0 | F9: ='เช้า '!F9+บ่าย!F9 -> 0 | G9: ='เช้า '!G9+บ่าย!G9 -> 0 | H9: ='เช้า '!H9+บ่าย!H9 -> 0 | I9: ='เช้า '!I9+บ่าย!I9 -> 0 | J9: ='เช้า '!J9+บ่าย!J9 -> 0 | K9: =SUM(D9:J9) -> 0 | N9: =SUM(L9+M9)-K9 -> 0
B10: 1111085 | C10: ชิฟฟอน 8 ชิ้น บลูเบอรี่ล้วน | D10: ='เช้า '!D10+บ่าย!D10 -> 0 | E10: ='เช้า '!E10+บ่าย!E10 -> 0 | F10: ='เช้า '!F10+บ่าย!F10 -> 0 | G10: ='เช้า '!G10+บ่าย!G10 -> 0 | H10: ='เช้า '!H10+บ่าย!H10 -> 0 | I10: ='เช้า '!I10+บ่าย!I10 -> 0 | J10: ='เช้า '!J10+บ่าย!J10 -> 0 | K10: =SUM(D10:J10) -> 0 | N10: =SUM(L10+M10)-K10 -> 0
B11: 1111086 | C11: ชิฟฟอน 8 ชิ้น มะพร้าวล้วน | D11: ='เช้า '!D11+บ่าย!D11 -> 0 | E11: ='เช้า '!E11+บ่าย!E11 -> 0 | F11: ='เช้า '!F11+บ่าย!F11 -> 0 | G11: ='เช้า '!G11+บ่าย!G11 -> 0 | H11: ='เช้า '!H11+บ่าย!H11 -> 0 | I11: ='เช้า '!I11+บ่าย!I11 -> 0 | J11: ='เช้า '!J11+บ่าย!J11 -> 0 | K11: =SUM(D11:J11) -> 0 | N11: =SUM(L11+M11)-K11 -> 0
B12: 1111087 | C12: ชิฟฟอน 8 ชิ้น สตอเบอรี่ล้วน | D12: ='เช้า '!D12+บ่าย!D12 -> 0 | E12: ='เช้า '!E12+บ่าย!E12 -> 0 | F12: ='เช้า '!F12+บ่าย!F12 -> 0 | G12: ='เช้า '!G12+บ่าย!G12 -> 0 | H12: ='เช้า '!H12+บ่าย!H12 -> 0 | I12: ='เช้า '!I12+บ่าย!I12 -> 0 | J12: ='เช้า '!J12+บ่าย!J12 -> 0 | K12: =SUM(D12:J12) -> 0 | N12: =SUM(L12+M12)-K12 -> 0
B13: 1111088 | C13: ชิฟฟอน 8 ชิ้น ส้มล้วน | D13: ='เช้า '!D13+บ่าย!D13 -> 0 | E13: ='เช้า '!E13+บ่าย!E13 -> 0 | F13: ='เช้า '!F13+บ่าย!F13 -> 0 | G13: ='เช้า '!G13+บ่าย!G13 -> 0 | H13: ='เช้า '!H13+บ่าย!H13 -> 0 | I13: ='เช้า '!I13+บ่าย!I13 -> 0 | J13: ='เช้า '!J13+บ่าย!J13 -> 0 | K13: =SUM(D13:J13) -> 0 | N13: =SUM(L13+M13)-K13 -> 0
B14: 1111089 | C14: ชิฟฟอน 8 ชิ้น เนยล้วน | D14: ='เช้า '!D14+บ่าย!D14 -> 0 | E14: ='เช้า '!E14+บ่าย!E14 -> 0 | F14: ='เช้า '!F14+บ่าย!F14 -> 0 | G14: ='เช้า '!G14+บ่าย!G14 -> 0 | H14: ='เช้า '!H14+บ่าย!H14 -> 0 | I14: ='เช้า '!I14+บ่าย!I14 -> 0 | J14: ='เช้า '!J14+บ่าย!J14 -> 0 | K14: =SUM(D14:J14) -> 0 | N14: =SUM(L14+M14)-K14 -> 0
B15: 1111090 | C15: ชิฟฟอน 8 ชิ้น เผือกล้วน | D15: ='เช้า '!D15+บ่าย!D15 -> 0 | E15: ='เช้า '!E15+บ่าย!E15 -> 0 | F15: ='เช้า '!F15+บ่าย!F15 -> 0 | G15: ='เช้า '!G15+บ่าย!G15 -> 0 | H15: ='เช้า '!H15+บ่าย!H15 -> 0 | I15: ='เช้า '!I15+บ่าย!I15 -> 0 | J15: ='เช้า '!J15+บ่าย!J15 -> 0 | K15: =SUM(D15:J15) -> 0 | N15: =SUM(L15+M15)-K15 -> 0
B16: 1111091 | C16: ชิฟฟอน 8 ชิ้น ใบเตยล้วน | D16: ='เช้า '!D16+บ่าย!D16 -> 0 | E16: ='เช้า '!E16+บ่าย!E16 -> 0 | F16: ='เช้า '!F16+บ่าย!F16 -> 0 | G16: ='เช้า '!G16+บ่าย!G16 -> 0 | H16: ='เช้า '!H16+บ่าย!H16 -> 0 | I16: ='เช้า '!I16+บ่าย!I16 -> 0 | J16: ='เช้า '!J16+บ่าย!J16 -> 0 | K16: =SUM(D16:J16) -> 0 | N16: =SUM(L16+M16)-K16 -> 0
B17: 1111092 | C17: ชิฟฟอน 8 ชิ้น กล้วยหอม | D17: ='เช้า '!D17+บ่าย!D17 -> 0 | E17: ='เช้า '!E17+บ่าย!E17 -> 0 | F17: ='เช้า '!F17+บ่าย!F17 -> 0 | G17: ='เช้า '!G17+บ่าย!G17 -> 0 | H17: ='เช้า '!H17+บ่าย!H17 -> 0 | I17: ='เช้า '!I17+บ่าย!I17 -> 0 | J17: ='เช้า '!J17+บ่าย!J17 -> 0 | K17: =SUM(D17:J17) -> 0 | N17: =SUM(L17+M17)-K17 -> 0
B18: 1111093 | C18: ชิฟฟอน 8 ชิ้น โกโก้ล้วน | D18: ='เช้า '!D18+บ่าย!D18 -> 0 | E18: ='เช้า '!E18+บ่าย!E18 -> 0 | F18: ='เช้า '!F18+บ่าย!F18 -> 0 | G18: ='เช้า '!G18+บ่าย!G18 -> 0 | H18: ='เช้า '!H18+บ่าย!H18 -> 0 | I18: ='เช้า '!I18+บ่าย!I18 -> 0 | J18: ='เช้า '!J18+บ่าย!J18 -> 0 | K18: =SUM(D18:J18) -> 0 | N18: =SUM(L18+M18)-K18 -> 0
B19: 1111094 | C19: ชิฟฟอน 8 ชิ้น ชาไทยล้วน | D19: ='เช้า '!D19+บ่าย!D19 -> 0 | E19: ='เช้า '!E19+บ่าย!E19 -> 0 | F19: ='เช้า '!F19+บ่าย!F19 -> 0 | G19: ='เช้า '!G19+บ่าย!G19 -> 0 | H19: ='เช้า '!H19+บ่าย!H19 -> 0 | I19: ='เช้า '!I19+บ่าย!I19 -> 0 | J19: ='เช้า '!J19+บ่าย!J19 -> 0 | K19: =SUM(D19:J19) -> 0 | N19: =SUM(L19+M19)-K19 -> 0
B20: 1111095 | C20: ชิฟฟอน 8 ชิ้น ชาเขียวล้วน | D20: ='เช้า '!D20+บ่าย!D20 -> 0 | E20: ='เช้า '!E20+บ่าย!E20 -> 0 | F20: ='เช้า '!F20+บ่าย!F20 -> 0 | G20: ='เช้า '!G20+บ่าย!G20 -> 0 | H20: ='เช้า '!H20+บ่าย!H20 -> 0 | I20: ='เช้า '!I20+บ่าย!I20 -> 0 | J20: ='เช้า '!J20+บ่าย!J20 -> 0 | K20: =SUM(D20:J20) -> 0 | N20: =SUM(L20+M20)-K20 -> 0
... B25: 1111056 | C25: ชิฟฟอน 8 ชิ้น รวมรสยอดฮิต | D25: ='เช้า '!D25+บ่าย!D25 -> 0 | E25: ='เช้า '!E25+บ่าย!E25 -> 5 | F25: ='เช้า '!F25+บ่าย!F25 -> 3 | G25: ='เช้า '!G25+บ่าย!G25 -> 1 | H25: ='เช้า '!H25+บ่าย!H25 -> 0 | I25: ='เช้า '!I25+บ่าย!I25 -> 0 | J25: ='เช้า '!J25+บ่าย!J25 -> 0 | K25: =SUM(D25:J25) -> 9 | N25: =SUM(L25+M25)-K25 -> -9
B26: 1004055 | C26: ชิฟฟอนรวมรส 4 ชิ้น | D26: ='เช้า '!D26+บ่าย!D26 -> 0 | E26: ='เช้า '!E26+บ่าย!E26 -> 0 | F26: ='เช้า '!F26+บ่าย!F26 -> 10 | G26: ='เช้า '!G26+บ่าย!G26 -> 45 | H26: ='เช้า '!H26+บ่าย!H26 -> 6 | I26: ='เช้า '!I26+บ่าย!I26 -> 0 | J26: ='เช้า '!J26+บ่าย!J26 -> 0 | K26: =SUM(D26:J26) -> 61 | L26: 150 | N26: =SUM(L26+M26)-K26 -> 89
B27: 1004055 | C27: ชิฟฟอน 4 ชิ้น โกโก้ล้วน | D27: ='เช้า '!D27+บ่าย!D27 -> 0 | E27: ='เช้า '!E27+บ่าย!E27 -> 0 | F27: ='เช้า '!F27+บ่าย!F27 -> 0 | G27: ='เช้า '!G27+บ่าย!G27 -> 0 | H27: ='เช้า '!H27+บ่าย!H27 -> 0 | I27: ='เช้า '!I27+บ่าย!I27 -> 0 | J27: ='เช้า '!J27+บ่าย!J27 -> 0 | K27: =SUM(D27:J27) -> 0 | N27: =SUM(L27+M27)-K27 -> 0
B28: 1004055 | C28: ชิฟฟอน 4 ชิ้น มะพร้าวล้วน | D28: ='เช้า '!D28+บ่าย!D28 -> 0 | E28: ='เช้า '!E28+บ่าย!E28 -> 0 | F28: ='เช้า '!F28+บ่าย!F28 -> 0 | G28: ='เช้า '!G28+บ่าย!G28 -> 0 | H28: ='เช้า '!H28+บ่าย!H28 -> 0 | I28: ='เช้า '!I28+บ่าย!I28 -> 0 | J28: ='เช้า '!J28+บ่าย!J28 -> 0 | K28: =SUM(D28:J28) -> 0 | N28: =SUM(L28+M28)-K28 -> 0
B29: 1004055 | C29: ชิฟฟอน 4 ชิ้น เนยล้วน | D29: ='เช้า '!D29+บ่าย!D29 -> 0 | E29: ='เช้า '!E29+บ่าย!E29 -> 0 | F29: ='เช้า '!F29+บ่าย!F29 -> 0 | G29: ='เช้า '!G29+บ่าย!G29 -> 0 | H29: ='เช้า '!H29+บ่าย!H29 -> 0 | I29: ='เช้า '!I29+บ่าย!I29 -> 0 | J29: ='เช้า '!J29+บ่าย!J29 -> 0 | K29: =SUM(D29:J29) -> 0 | N29: =SUM(L29+M29)-K29 -> 0
B30: 1004055 | C30: ชิฟฟอน 4 ชิ้น กาแฟล้วน | D30: ='เช้า '!D30+บ่าย!D30 -> 0 | E30: ='เช้า '!E30+บ่าย!E30 -> 0 | F30: ='เช้า '!F30+บ่าย!F30 -> 0 | G30: ='เช้า '!G30+บ่าย!G30 -> 0 | H30: ='เช้า '!H30+บ่าย!H30 -> 0 | I30: ='เช้า '!I30+บ่าย!I30 -> 0 | J30: ='เช้า '!J30+บ่าย!J30 -> 0 | K30: =SUM(D30:J30) -> 0 | N30: =SUM(L30+M30)-K30 -> 0
B31: 1004055 | C31: ชิฟฟอน 4 ชิ้น ใบเตยล้วน | D31: ='เช้า '!D31+บ่าย!D31 -> 0 | E31: ='เช้า '!E31+บ่าย!E31 -> 0 | F31: ='เช้า '!F31+บ่าย!F31 -> 0 | G31: ='เช้า '!G31+บ่าย!G31 -> 0 | H31: ='เช้า '!H31+บ่าย!H31 -> 0 | I31: ='เช้า '!I31+บ่าย!I31 -> 0 | J31: ='เช้า '!J31+บ่าย!J31 -> 0 | K31: =SUM(D31:J31) -> 0 | N31: =SUM(L31+M31)-K31 -> 0
B32: 1004055 | C32: ชิฟฟอน 4 ชิ้น บลูเบอร์รี่ล้วน | D32: ='เช้า '!D32+บ่าย!D32 -> 0 | E32: ='เช้า '!E32+บ่าย!E32 -> 0 | F32: ='เช้า '!F32+บ่าย!F32 -> 0 | G32: ='เช้า '!G32+บ่าย!G32 -> 0 | H32: ='เช้า '!H32+บ่าย!H32 -> 0 | I32: ='เช้า '!I32+บ่าย!I32 -> 0 | J32: ='เช้า '!J32+บ่าย!J32 -> 0 | K32: =SUM(D32:J32) -> 0 | N32: =SUM(L32+M32)-K32 -> 0
B33: 1004055 | C33: ชิฟฟอน 4 ชิ้น ส้มล้วน | D33: ='เช้า '!D33+บ่าย!D33 -> 0 | E33: ='เช้า '!E33+บ่าย!E33 -> 0 | F33: ='เช้า '!F33+บ่าย!F33 -> 0 | G33: ='เช้า '!G33+บ่าย!G33 -> 0 | H33: ='เช้า '!H33+บ่าย!H33 -> 0 | I33: ='เช้า '!I33+บ่าย!I33 -> 0 | J33: ='เช้า '!J33+บ่าย!J33 -> 0 | K33: =SUM(D33:J33) -> 0 | N33: =SUM(L33+M33)-K33 -> 0
B34: 1004055 | C34: ชิฟฟอน 4 ชิ้น เผือกล้วน | D34: ='เช้า '!D34+บ่าย!D34 -> 0 | E34: ='เช้า '!E34+บ่าย!E34 -> 0 | F34: ='เช้า '!F34+บ่าย!F34 -> 0 | G34: ='เช้า '!G34+บ่าย!G34 -> 0 | H34: ='เช้า '!H34+บ่าย!H34 -> 0 | I34: ='เช้า '!I34+บ่าย!I34 -> 0 | J34: ='เช้า '!J34+บ่าย!J34 -> 0 | K34: =SUM(D34:J34) -> 0 | N34: =SUM(L34+M34)-K34 -> 0
B35: 1004055 | C35: ชิฟฟอน 4 ชิ้น สตอเบอรี่ล้วน | D35: ='เช้า '!D35+บ่าย!D35 -> 0 | E35: ='เช้า '!E35+บ่าย!E35 -> 0 | F35: ='เช้า '!F35+บ่าย!F35 -> 0 | G35: ='เช้า '!G35+บ่าย!G35 -> 0 | H35: ='เช้า '!H35+บ่าย!H35 -> 0 | I35: ='เช้า '!I35+บ่าย!I35 -> 0 | J35: ='เช้า '!J35+บ่าย!J35 -> 0 | K35: =SUM(D35:J35) -> 0 | N35: =SUM(L35+M35)-K35 -> 0
B36: 1004055 | C36: ชิฟฟอน 4 ชิ้น กล้วยหอมล้วน | D36: ='เช้า '!D36+บ่าย!D36 -> 0 | E36: ='เช้า '!E36+บ่าย!E36 -> 0 | F36: ='เช้า '!F36+บ่าย!F36 -> 0 | G36: ='เช้า '!G36+บ่าย!G36 -> 0 | H36: ='เช้า '!H36+บ่าย!H36 -> 0 | I36: ='เช้า '!I36+บ่าย!I36 -> 0 | J36: ='เช้า '!J36+บ่าย!J36 -> 0 | K36: =SUM(D36:J36) -> 0 | N36: =SUM(L36+M36)-K36 -> 0
B37: 1004055 | C37: ชิฟฟอน 4 ชิ้น ชาเขียวล้วน | D37: ='เช้า '!D37+บ่าย!D37 -> 0 | E37: ='เช้า '!E37+บ่าย!E37 -> 0 | F37: ='เช้า '!F37+บ่าย!F37 -> 0 | G37: ='เช้า '!G37+บ่าย!G37 -> 0 | H37: ='เช้า '!H37+บ่าย!H37 -> 0 | I37: ='เช้า '!I37+บ่าย!I37 -> 0 | J37: ='เช้า '!J37+บ่าย!J37 -> 0 | K37: =SUM(D37:J37) -> 0 | N37: =SUM(L37+M37)-K37 -> 0
B38: 1004055 | C38: ชิฟฟอน 4 ชิ้น ชาไทยล้วน | D38: ='เช้า '!D38+บ่าย!D38 -> 0 | E38: ='เช้า '!E38+บ่าย!E38 -> 0 | F38: ='เช้า '!F38+บ่าย!F38 -> 0 | G38: ='เช้า '!G38+บ่าย!G38 -> 0 | H38: ='เช้า '!H38+บ่าย!H38 -> 0 | I38: ='เช้า '!I38+บ่าย!I38 -> 0 | J38: ='เช้า '!J38+บ่าย!J38 -> 0 | K38: =SUM(D38:J38) -> 0 | N38: =SUM(L38+M38)-K38 -> 0
... B66: 1111010 | C66: ชิฟฟอนไส้แยมแยกชิ้น คละรส | D66: ='เช้า '!D66+บ่าย!D66 -> 0 | E66: ='เช้า '!E66+บ่าย!E66 -> 0 | F66: ='เช้า '!F66+บ่าย!F66 -> 0 | G66: ='เช้า '!G66+บ่าย!G66 -> 0 | H66: ='เช้า '!H66+บ่าย!H66 -> 0 | I66: ='เช้า '!I66+บ่าย!I66 -> 0 | J66: ='เช้า '!J66+บ่าย!J66 -> 0 | K66: =SUM(D66:J66) -> 0 | N66: =SUM(L66+M66)-K66 -> 0
C67: รวม | K67: =SUM(D67:J67) -> 0 | N67: =SUM(L67+M67)-K67 -> 0
B68: ชิฟฟอนไส้แยม 6 ชิ้น
B69: 1111009 | C69: ชิฟฟอนไส้แยมรวมรส 6 ชิ้น | D69: ='เช้า '!D69+บ่าย!D69 -> 0 | E69: ='เช้า '!E69+บ่าย!E69 -> 0 | F69: ='เช้า '!F69+บ่าย!F69 -> 2 | G69: ='เช้า '!G69+บ่าย!G69 -> 2 | H69: ='เช้า '!H69+บ่าย!H69 -> 0 | I69: ='เช้า '!I69+บ่าย!I69 -> 0 | J69: ='เช้า '!J69+บ่าย!J69 -> 0 | K69: =SUM(D69:J69) -> 4 | N69: =SUM(L69+M69)-K69 -> -4
B70: 1111023 | C70: ชิฟฟอนไส้แยมรสสตอเบอร์รี่ล้วน 6 ชิ้น | D70: ='เย็น 102'!D70+'เช้า '!D70+บ่าย!D70 -> 0 | E70: ='เย็น 102'!E70+'เช้า '!E70+บ่าย!E70 -> 0 | F70: ='เย็น 102'!F70+'เช้า '!F70+บ่าย!F70 -> 0 | G70: ='เย็น 102'!G70+'เช้า '!G70+บ่าย!G70 -> 0 | H70: ='เย็น 102'!H70+'เช้า '!H70+บ่าย!H70 -> 0 | I70: ='เย็น 102'!I70+'เช้า '!I70+บ่าย!I70 -> 0 | J70: ='เย็น 102'!J70+'เช้า '!J70+บ่าย!J70 -> 0 | K70: =SUM(D70:J70) -> 0 | N70: =SUM(L70+M70)-K70 -> 0
B71: 1111016 | C71: ชิฟฟอนไส้แยมรสมะพร้าวล้วน 6 ชิ้น | D71: ='เย็น 102'!D71+'เช้า '!D71+บ่าย!D71 -> 0 | E71: ='เย็น 102'!E71+'เช้า '!E71+บ่าย!E71 -> 0 | F71: ='เย็น 102'!F71+'เช้า '!F71+บ่าย!F71 -> 0 | G71: ='เย็น 102'!G71+'เช้า '!G71+บ่าย!G71 -> 0 | H71: ='เย็น 102'!H71+'เช้า '!H71+บ่าย!H71 -> 0 | I71: ='เย็น 102'!I71+'เช้า '!I71+บ่าย!I71 -> 0 | J71: ='เย็น 102'!J71+'เช้า '!J71+บ่าย!J71 -> 0 | K71: =SUM(D71:J71) -> 0 | N71: =SUM(L71+M71)-K71 -> 0
B72: 1111014 | C72: ชิฟฟอนไส้แยมรสช็อกโกแลตนูเทลล่าล้วน 6 ชิ้น | D72: ='เย็น 102'!D72+'เช้า '!D72+บ่าย!D72 -> 0 | E72: ='เย็น 102'!E72+'เช้า '!E72+บ่าย!E72 -> 0 | F72: ='เย็น 102'!F72+'เช้า '!F72+บ่าย!F72 -> 0 | G72: ='เย็น 102'!G72+'เช้า '!G72+บ่าย!G72 -> 0 | H72: ='เย็น 102'!H72+'เช้า '!H72+บ่าย!H72 -> 0 | I72: ='เย็น 102'!I72+'เช้า '!I72+บ่าย!I72 -> 0 | J72: ='เย็น 102'!J72+'เช้า '!J72+บ่าย!J72 -> 0 | K72: =SUM(D72:J72) -> 0 | N72: =SUM(L72+M72)-K72 -> 0
...
