Workbook

Sheet เย็น 386
B1: ยอดจริง ออนไลน์ วันที่ 2/11/2567 - เย็น
K2: ยอดรวมผลิต
K3: จำนวน
B4: รหัสสินค้า | C4: สินค้า | D4: ปณ | E4: ชอปปี้ | F4: ลาซาด้า | G4: ติ๊กตอก | H4: ติ๊กตอก2 | I4: ติ๊กตอก3 | J4: ชอยส์ | K4: (กล่อง)
B6: ชิฟฟอนรวมรส
B7: 1111002 | C7: ชิฟฟอนรวมรส 8 ชิ้น | E7: 16 | F7: 19 | K7: =SUM(D7:J7) -> 35
C8: ชิฟฟอนแบบกล่องสุ่มอะไรก็ได้ที่มี | K8: =SUM(D8:J8) -> 0
B9: 1111084 | C9: ชิฟฟอน 8 ชิ้น กาแฟล้วน | K9: =SUM(D9:J9) -> 0
B10: 1111085 | C10: ชิฟฟอน 8 ชิ้น บลูเบอรี่ล้วน | K10: =SUM(D10:J10) -> 0
B11: 1111086 | C11: ชิฟฟอน 8 ชิ้น มะพร้าวล้วน | K11: =SUM(D11:J11) -> 0
B12: 1111087 | C12: ชิฟฟอน 8 ชิ้น สตอเบอรี่ล้วน | K12: =SUM(D12:J12) -> 0
B13: 1111088 | C13: ชิฟฟอน 8 ชิ้น ส้มล้วน | K13: =SUM(D13:J13) -> 0
B14: 1111089 | C14: ชิฟฟอน 8 ชิ้น เนยล้วน | K14: =SUM(D14:J14) -> 0
B15: 1111090 | C15: ชิฟฟอน 8 ชิ้น เผือกล้วน | K15: =SUM(D15:J15) -> 0
B16: 1111091 | C16: ชิฟฟอน 8 ชิ้น ใบเตยล้วน | K16: =SUM(D16:J16) -> 0
B17: 1111092 | C17: ชิฟฟอน 8 ชิ้น กล้วยหอม | K17: =SUM(D17:J17) -> 0
B18: 1111093 | C18: ชิฟฟอน 8 ชิ้น โกโก้ล้วน | K18: =SUM(D18:J18) -> 0
B19: 1111094 | C19: ชิฟฟอน 8 ชิ้น ชาไทยล้วน | K19: =SUM(D19:J19) -> 0
B20: 1111095 | C20: ชิฟฟอน 8 ชิ้น ชาเขียวล้วน | K20: =SUM(D20:J20) -> 0
... B24: 1111043 | C24: ชิฟฟอน 8 ชิ้น มะลิ | K24: =SUM(D24:J24) -> 0
B25: 1111056 | C25: ชิฟฟอน 8 ชิ้น รวมรสยอดฮิต | E25: 1 | F25: 3 | G25: 1 | K25: =SUM(D25:J25) -> 5
B26: 1004055 | C26: ชิฟฟอนรวมรส 4 ชิ้น | G26: 67 | K26: =SUM(D26:J26) -> 67
B27: 1004055 | C27: ชิฟฟอน 4 ชิ้น โกโก้ล้วน | K27: =SUM(D27:J27) -> 0
B28: 1004055 | C28: ชิฟฟอน 4 ชิ้น มะพร้าวล้วน | K28: =SUM(D28:J28) -> 0
B29: 1004055 | C29: ชิฟฟอน 4 ชิ้น เนยล้วน | K29: =SUM(D29:J29) -> 0
B30: 1004055 | C30: ชิฟฟอน 4 ชิ้น กาแฟล้วน | K30: =SUM(D30:J30) -> 0
B31: 1004055 | C31: ชิฟฟอน 4 ชิ้น ใบเตยล้วน | K31: =SUM(D31:J31) -> 0
B32: 1004055 | C32: ชิฟฟอน 4 ชิ้น บลูเบอร์รี่ล้วน | K32: =SUM(D32:J32) -> 0
B33: 1004055 | C33: ชิฟฟอน 4 ชิ้น ส้มล้วน | K33: =SUM(D33:J33) -> 0
B34: 1004055 | C34: ชิฟฟอน 4 ชิ้น เผือกล้วน | K34: =SUM(D34:J34) -> 0
B35: 1004055 | C35: ชิฟฟอน 4 ชิ้น สตอเบอรี่ล้วน | K35: =SUM(D35:J35) -> 0
B36: 1004055 | C36: ชิฟฟอน 4 ชิ้น กล้วยหอมล้วน | K36: =SUM(D36:J36) -> 0
B37: 1004055 | C37: ชิฟฟอน 4 ชิ้น ชาเขียวล้วน | K37: =SUM(D37:J37) -> 0
B38: 1004055 | C38: ชิฟฟอน 4 ชิ้น ชาไทยล้วน | K38: =SUM(D38:J38) -> 0
B39: 1004055 | C39: ชิฟฟอน 4 ชิ้น สับปะรดล้วน | K39: =SUM(D39:J39) -> 0
B40: 1111057 | C40: ชิฟฟอนแยกชิ้น กาแฟ | F40: 1 | G40: 1 | H40: 1 | K40: =SUM(D40:J40) -> 3
B41: 1111058 | C41: ชิฟฟอนแยกชิ้น ชาเขียว | F41: 1 | G41: 1 | H41: 1 | K41: =SUM(D41:J41) -> 3
B42: 1111059 | C42: ชิฟฟอนแยกชิ้น ใบเตย | F42: 1 | G42: 1 | H42: 1 | K42: =SUM(D42:J42) -> 3
B43: 1111060 | C43: ชิฟฟอนแยกชิ้น กล้วยหอม | F43: 1 | H43: 1 | K43: =SUM(D43:J43) -> 2
B44: 1111061 | C44: ชิฟฟอนแยกชิ้น ชาไทย | K44: =SUM(D44:J44) -> 0
...

Sheet เช้า 212
B1: ยอดจริง ออนไลน์ วันที่ 2/11/2567 - เช้า
K2: ยอดรวมผลิต
K3: จำนวน
B4: รหัสสินค้า | C4: สินค้า | D4: ปณ | E4: ชอปปี้ | F4: ลาซาด้า | G4: ติ๊กตอก | H4: ติ๊กตอก2 | I4: ติ๊กตอก3 | J4: ชอยส์ | K4: (กล่อง)
B6: ชิฟฟอนรวมรส
B7: 1111002 | C7: ชิฟฟอนรวมรส 8 ชิ้น | D7: 4 | E7: 5 | F7: 38 | K7: =SUM(D7:J7) -> 47
C8: ชิฟฟอนแบบกล่องสุ่มอะไรก็ได้ที่มี | K8: =SUM(D8:J8) -> 0
B9: 1111084 | C9: ชิฟฟอน 8 ชิ้น กาแฟล้วน | K9: =SUM(D9:J9) -> 0
B10: 1111085 | C10: ชิฟฟอน 8 ชิ้น บลูเบอรี่ล้วน | K10: =SUM(D10:J10) -> 0
B11: 1111086 | C11: ชิฟฟอน 8 ชิ้น มะพร้าวล้วน | K11: =SUM(D11:J11) -> 0
B12: 1111087 | C12: ชิฟฟอน 8 ชิ้น สตอเบอรี่ล้วน | K12: =SUM(D12:J12) -> 0
B13: 1111088 | C13: ชิฟฟอน 8 ชิ้น ส้มล้วน | K13: =SUM(D13:J13) -> 0
B14: 1111089 | C14: ชิฟฟอน 8 ชิ้น เนยล้วน | K14: =SUM(D14:J14) -> 0
B15: 1111090 | C15: ชิฟฟอน 8 ชิ้น เผือกล้วน | K15: =SUM(D15:J15) -> 0
B16: 1111091 | C16: ชิฟฟอน 8 ชิ้น ใบเตยล้วน | K16: =SUM(D16:J16) -> 0
B17: 1111092 | C17: ชิฟฟอน 8 ชิ้น กล้วยหอม | K17: =SUM(D17:J17) -> 0
B18: 1111093 | C18: ชิฟฟอน 8 ชิ้น โกโก้ล้วน | K18: =SUM(D18:J18) -> 0
B19: 1111094 | C19: ชิฟฟอน 8 ชิ้น ชาไทยล้วน | K19: =SUM(D19:J19) -> 0
B20: 1111095 | C20: ชิฟฟอน 8 ชิ้น ชาเขียวล้วน | K20: =SUM(D20:J20) -> 0
... B24: 1111043 | C24: ชิฟฟอน 8 ชิ้น มะลิ | K24: =SUM(D24:J24) -> 0
B25: 1111056 | C25: ชิฟฟอน 8 ชิ้น รวมรสยอดฮิต | D25: 4 | E25: 1 | G25: 1 | K25: =SUM(D25:J25) -> 6
B26: 1004055 | C26: ชิฟฟอนรวมรส 4 ชิ้น | E26: 3 | G26: 57 | K26: =SUM(D26:J26) -> 60
B27: 1004055 | C27: ชิฟฟอน 4 ชิ้น โกโก้ล้วน | K27: =SUM(D27:J27) -> 0
B28: 1004055 | C28: ชิฟฟอน 4 ชิ้น มะพร้าวล้วน | K28: =SUM(D28:J28) -> 0
B29: 1004055 | C29: ชิฟฟอน 4 ชิ้น เนยล้วน | K29: =SUM(D29:J29) -> 0
B30: 1004055 | C30: ชิฟฟอน 4 ชิ้น กาแฟล้วน | K30: =SUM(D30:J30) -> 0
B31: 1004055 | C31: ชิฟฟอน 4 ชิ้น ใบเตยล้วน | K31: =SUM(D31:J31) -> 0
B32: 1004055 | C32: ชิฟฟอน 4 ชิ้น บลูเบอร์รี่ล้วน | K32: =SUM(D32:J32) -> 0
B33: 1004055 | C33: ชิฟฟอน 4 ชิ้น ส้มล้วน | K33: =SUM(D33:J33) -> 0
B34: 1004055 | C34: ชิฟฟอน 4 ชิ้น เผือกล้วน | K34: =SUM(D34:J34) -> 0
B35: 1004055 | C35: ชิฟฟอน 4 ชิ้น สตอเบอรี่ล้วน | K35: =SUM(D35:J35) -> 0
B36: 1004055 | C36: ชิฟฟอน 4 ชิ้น กล้วยหอมล้วน | K36: =SUM(D36:J36) -> 0
B37: 1004055 | C37: ชิฟฟอน 4 ชิ้น ชาเขียวล้วน | K37: =SUM(D37:J37) -> 0
B38: 1004055 | C38: ชิฟฟอน 4 ชิ้น ชาไทยล้วน | K38: =SUM(D38:J38) -> 0
B39: 1004055 | C39: ชิฟฟอน 4 ชิ้น สับปะรดล้วน | K39: =SUM(D39:J39) -> 0
B40: 1111057 | C40: ชิฟฟอนแยกชิ้น กาแฟ | D40: 1 | G40: 32 | J40: 1 | K40: =SUM(D40:J40) -> 34
B41: 1111058 | C41: ชิฟฟอนแยกชิ้น ชาเขียว | D41: 1 | G41: 16 | K41: =SUM(D41:J41) -> 17
B42: 1111059 | C42: ชิฟฟอนแยกชิ้น ใบเตย | D42: 1 | G42: 32 | K42: =SUM(D42:J42) -> 33
B43: 1111060 | C43: ชิฟฟอนแยกชิ้น กล้วยหอม | K43: =SUM(D43:J43) -> 0
B44: 1111061 | C44: ชิฟฟอนแยกชิ้น ชาไทย | G44: 8 | K44: =SUM(D44:J44) -> 8
...

Sheet รวม
B1: ยอดจริง ออนไลน์ วันที่ 2/11/2567 - รวม
K2: ยอดรวมผลิต | L2: ยอดสตอค | M2: ยอดฟอแคส | N2: รับเกิน | O2: ยังไม่ได้รับเข้า | P2: รวม
K3: จำนวน
B4: รหัสสินค้า | C4: สินค้า | D4: ปณ | E4: ชอปปี้ | F4: ลาซาด้า | G4: ติ๊กตอก | H4: ติ๊กตอก2 | I4: ติ๊กตอก3 | J4: ชอยส์ | K4: (กล่อง)
B6: ชิฟฟอนรวมรส
B7: 1111002 | C7: ชิฟฟอนรวมรส 8 ชิ้น | D7: ='เย็น 386'!D7+'เช้า 212'!D7 -> 4 | E7: ='เย็น 386'!E7+'เช้า 212'!E7 -> 21 | F7: ='เย็น 386'!F7+'เช้า 212'!F7 -> 57 | G7: ='เย็น 386'!G7+'เช้า 212'!G7 -> 0 | H7: ='เย็น 386'!H7+'เช้า 212'!H7 -> 0 | I7: ='เย็น 386'!I7+'เช้า 212'!I7 -> 0 | J7: ='เย็น 386'!J7+'เช้า 212'!J7 -> 0 | K7: =SUM(D7:J7) -> 82 | L7: 97 | M7: 100 | P7: =(L7+M7+N7+O7)-K7 -> 115 | R7: 25 | S7: =P7-R7 -> 90 | T7: 200 | U7: =S7+T7 -> 290
C8: ชิฟฟอนแบบกล่องสุ่มอะไรก็ได้ที่มี | D8: ='เย็น 386'!D8+'เช้า 212'!D8 -> 0 | E8: ='เย็น 386'!E8+'เช้า 212'!E8 -> 0 | F8: ='เย็น 386'!F8+'เช้า 212'!F8 -> 0 | G8: ='เย็น 386'!G8+'เช้า 212'!G8 -> 0 | H8: ='เย็น 386'!H8+'เช้า 212'!H8 -> 0 | I8: ='เย็น 386'!I8+'เช้า 212'!I8 -> 0 | J8: ='เย็น 386'!J8+'เช้า 212'!J8 -> 0 | K8: =SUM(D8:J8) -> 0 | P8: =(L8+M8+N8+O8)-K8 -> 0 | S8: =P8-R8 -> 0
B9: 1111084 | C9: ชิฟฟอน 8 ชิ้น กาแฟล้วน | D9: ='เย็น 386'!D9+'เช้า 212'!D9 -> 0 | E9: ='เย็น 386'!E9+'เช้า 212'!E9 -> 0 | F9: ='เย็น 386'!F9+'เช้า 212'!F9 -> 0 | G9: ='เย็น 386'!G9+'เช้า 212'!G9 -> 0 | H9: ='เย็น 386'!H9+'เช้า 212'!H9 -> 0 | I9: ='เย็น 386'!I9+'เช้า 212'!I9 -> 0 | J9: ='เย็น 386'!J9+'เช้า 212'!J9 -> 0 | K9: =SUM(D9:J9) -> 0 | P9: =(L9+M9+N9+O9)-K9 -> 0 | S9: =P9-R9 -> 0
B10: 1111085 | C10: ชิฟฟอน 8 ชิ้น บลูเบอรี่ล้วน | D10: ='เย็น 386'!D10+'เช้า 212'!D10 -> 0 | E10: ='เย็น 386'!E10+'เช้า 212'!E10 -> 0 | F10: ='เย็น 386'!F10+'เช้า 212'!F10 -> 0 | G10: ='เย็น 386'!G10+'เช้า 212'!G10 -> 0 | H10: ='เย็น 386'!H10+'เช้า 212'!H10 -> 0 | I10: ='เย็น 386'!I10+'เช้า 212'!I10 -> 0 | J10: ='เย็น 386'!J10+'เช้า 212'!J10 -> 0 | K10: =SUM(D10:J10) -> 0 | P10: =(L10+M10+N10+O10)-K10 -> 0 | S10: =P10-R10 -> 0
B11: 1111086 | C11: ชิฟฟอน 8 ชิ้น มะพร้าวล้วน | D11: ='เย็น 386'!D11+'เช้า 212'!D11 -> 0 | E11: ='เย็น 386'!E11+'เช้า 212'!E11 -> 0 | F11: ='เย็น 386'!F11+'เช้า 212'!F11 -> 0 | G11: ='เย็น 386'!G11+'เช้า 212'!G11 -> 0 | H11: ='เย็น 386'!H11+'เช้า 212'!H11 -> 0 | I11: ='เย็น 386'!I11+'เช้า 212'!I11 -> 0 | J11: ='เย็น 386'!J11+'เช้า 212'!J11 -> 0 | K11: =SUM(D11:J11) -> 0 | P11: =(L11+M11+N11+O11)-K11 -> 0 | S11: =P11-R11 -> 0
B12: 1111087 | C12: ชิฟฟอน 8 ชิ้น สตอเบอรี่ล้วน | D12: ='เย็น 386'!D12+'เช้า 212'!D12 -> 0 | E12: ='เย็น 386'!E12+'เช้า 212'!E12 -> 0 | F12: ='เย็น 386'!F12+'เช้า 212'!F12 -> 0 | G12: ='เย็น 386'!G12+'เช้า 212'!G12 -> 0 | H12: ='เย็น 386'!H12+'เช้า 212'!H12 -> 0 | I12: ='เย็น 386'!I12+'เช้า 212'!I12 -> 0 | J12: ='เย็น 386'!J12+'เช้า 212'!J12 -> 0 | K12: =SUM(D12:J12) -> 0 | P12: =(L12+M12+N12+O12)-K12 -> 0 | S12: =P12-R12 -> 0
B13: 1111088 | C13: ชิฟฟอน 8 ชิ้น ส้มล้วน | D13: ='เย็น 386'!D13+'เช้า 212'!D13 -> 0 | E13: ='เย็น 386'!E13+'เช้า 212'!E13 -> 0 | F13: ='เย็น 386'!F13+'เช้า 212'!F13 -> 0 | G13: ='เย็น 386'!G13+'เช้า 212'!G13 -> 0 | H13: ='เย็น 386'!H13+'เช้า 212'!H13 -> 0 | I13: ='เย็น 386'!I13+'เช้า 212'!I13 -> 0 | J13: ='เย็น 386'!J13+'เช้า 212'!J13 -> 0 | K13: =SUM(D13:J13) -> 0 | P13: =(L13+M13+N13+O13)-K13 -> 0 | S13: =P13-R13 -> 0
B14: 1111089 | C14: ชิฟฟอน 8 ชิ้น เนยล้วน | D14: ='เย็น 386'!D14+'เช้า 212'!D14 -> 0 | E14: ='เย็น 386'!E14+'เช้า 212'!E14 -> 0 | F14: ='เย็น 386'!F14+'เช้า 212'!F14 -> 0 | G14: ='เย็น 386'!G14+'เช้า 212'!G14 -> 0 | H14: ='เย็น 386'!H14+'เช้า 212'!H14 -> 0 | I14: ='เย็น 386'!I14+'เช้า 212'!I14 -> 0 | J14: ='เย็น 386'!J14+'เช้า 212'!J14 -> 0 | K14: =SUM(D14:J14) -> 0 | P14: =(L14+M14+N14+O14)-K14 -> 0 | S14: =P14-R14 -> 0
B15: 1111090 | C15: ชิฟฟอน 8 ชิ้น เผือกล้วน | D15: ='เย็น 386'!D15+'เช้า 212'!D15 -> 0 | E15: ='เย็น 386'!E15+'เช้า 212'!E15 -> 0 | F15: ='เย็น 386'!F15+'เช้า 212'!F15 -> 0 | G15: ='เย็น 386'!G15+'เช้า 212'!G15 -> 0 | H15: ='เย็น 386'!H15+'เช้า 212'!H15 -> 0 | I15: ='เย็น 386'!I15+'เช้า 212'!I15 -> 0 | J15: ='เย็น 386'!J15+'เช้า 212'!J15 -> 0 | K15: =SUM(D15:J15) -> 0 | P15: =(L15+M15+N15+O15)-K15 -> 0 | S15: =P15-R15 -> 0
B16: 1111091 | C16: ชิฟฟอน 8 ชิ้น ใบเตยล้วน | D16: ='เย็น 386'!D16+'เช้า 212'!D16 -> 0 | E16: ='เย็น 386'!E16+'เช้า 212'!E16 -> 0 | F16: ='เย็น 386'!F16+'เช้า 212'!F16 -> 0 | G16: ='เย็น 386'!G16+'เช้า 212'!G16 -> 0 | H16: ='เย็น 386'!H16+'เช้า 212'!H16 -> 0 | I16: ='เย็น 386'!I16+'เช้า 212'!I16 -> 0 | J16: ='เย็น 386'!J16+'เช้า 212'!J16 -> 0 | K16: =SUM(D16:J16) -> 0 | P16: =(L16+M16+N16+O16)-K16 -> 0 | S16: =P16-R16 -> 0
B17: 1111092 | C17: ชิฟฟอน 8 ชิ้น กล้วยหอม | D17: ='เย็น 386'!D17+'เช้า 212'!D17 -> 0 | E17: ='เย็น 386'!E17+'เช้า 212'!E17 -> 0 | F17: ='เย็น 386'!F17+'เช้า 212'!F17 -> 0 | G17: ='เย็น 386'!G17+'เช้า 212'!G17 -> 0 | H17: ='เย็น 386'!H17+'เช้า 212'!H17 -> 0 | I17: ='เย็น 386'!I17+'เช้า 212'!I17 -> 0 | J17: ='เย็น 386'!J17+'เช้า 212'!J17 -> 0 | K17: =SUM(D17:J17) -> 0 | P17: =(L17+M17+N17+O17)-K17 -> 0 | S17: =P17-R17 -> 0
B18: 1111093 | C18: ชิฟฟอน 8 ชิ้น โกโก้ล้วน | D18: ='เย็น 386'!D18+'เช้า 212'!D18 -> 0 | E18: ='เย็น 386'!E18+'เช้า 212'!E18 -> 0 | F18: ='เย็น 386'!F18+'เช้า 212'!F18 -> 0 | G18: ='เย็น 386'!G18+'เช้า 212'!G18 -> 0 | H18: ='เย็น 386'!H18+'เช้า 212'!H18 -> 0 | I18: ='เย็น 386'!I18+'เช้า 212'!I18 -> 0 | J18: ='เย็น 386'!J18+'เช้า 212'!J18 -> 0 | K18: =SUM(D18:J18) -> 0 | P18: =(L18+M18+N18+O18)-K18 -> 0 | S18: =P18-R18 -> 0
B19: 1111094 | C19: ชิฟฟอน 8 ชิ้น ชาไทยล้วน | D19: ='เย็น 386'!D19+'เช้า 212'!D19 -> 0 | E19: ='เย็น 386'!E19+'เช้า 212'!E19 -> 0 | F19: ='เย็น 386'!F19+'เช้า 212'!F19 -> 0 | G19: ='เย็น 386'!G19+'เช้า 212'!G19 -> 0 | H19: ='เย็น 386'!H19+'เช้า 212'!H19 -> 0 | I19: ='เย็น 386'!I19+'เช้า 212'!I19 -> 0 | J19: ='เย็น 386'!J19+'เช้า 212'!J19 -> 0 | K19: =SUM(D19:J19) -> 0 | P19: =(L19+M19+N19+O19)-K19 -> 0 | S19: =P19-R19 -> 0
B20: 1111095 | C20: ชิฟฟอน 8 ชิ้น ชาเขียวล้วน | D20: ='เย็น 386'!D20+'เช้า 212'!D20 -> 0 | E20: ='เย็น 386'!E20+'เช้า 212'!E20 -> 0 | F20: ='เย็น 386'!F20+'เช้า 212'!F20 -> 0 | G20: ='เย็น 386'!G20+'เช้า 212'!G20 -> 0 | H20: ='เย็น 386'!H20+'เช้า 212'!H20 -> 0 | I20: ='เย็น 386'!I20+'เช้า 212'!I20 -> 0 | J20: ='เย็น 386'!J20+'เช้า 212'!J20 -> 0 | K20: =SUM(D20:J20) -> 0 | P20: =(L20+M20+N20+O20)-K20 -> 0 | S20: =P20-R20 -> 0
... B24: 1111043 | C24: ชิฟฟอน 8 ชิ้น มะลิ | D24: ='เย็น 386'!D24+'เช้า 212'!D24 -> 0 | E24: ='เย็น 386'!E24+'เช้า 212'!E24 -> 0 | F24: ='เย็น 386'!F24+'เช้า 212'!F24 -> 0 | G24: ='เย็น 386'!G24+'เช้า 212'!G24 -> 0 | H24: ='เย็น 386'!H24+'เช้า 212'!H24 -> 0 | I24: ='เย็น 386'!I24+'เช้า 212'!I24 -> 0 | J24: ='เย็น 386'!J24+'เช้า 212'!J24 -> 0 | K24: =SUM(D24:J24) -> 0 | P24: =(L24+M24+N24+O24)-K24 -> 0 | S24: =P24-R24 -> 0
B25: 1111056 | C25: ชิฟฟอน 8 ชิ้น รวมรสยอดฮิต | D25: ='เย็น 386'!D25+'เช้า 212'!D25 -> 4 | E25: ='เย็น 386'!E25+'เช้า 212'!E25 -> 2 | F25: ='เย็น 386'!F25+'เช้า 212'!F25 -> 3 | G25: ='เย็น 386'!G25+'เช้า 212'!G25 -> 2 | H25: ='เย็น 386'!H25+'เช้า 212'!H25 -> 0 | I25: ='เย็น 386'!I25+'เช้า 212'!I25 -> 0 | J25: ='เย็น 386'!J25+'เช้า 212'!J25 -> 0 | K25: =SUM(D25:J25) -> 11 | L25: 16 | M25: 15 | P25: =(L25+M25+N25+O25)-K25 -> 20
B26: 1004055 | C26: ชิฟฟอนรวมรส 4 ชิ้น | D26: ='เย็น 386'!D26+'เช้า 212'!D26 -> 0 | E26: ='เย็น 386'!E26+'เช้า 212'!E26 -> 3 | F26: ='เย็น 386'!F26+'เช้า 212'!F26 -> 0 | G26: ='เย็น 386'!G26+'เช้า 212'!G26 -> 124 | H26: ='เย็น 386'!H26+'เช้า 212'!H26 -> 0 | I26: ='เย็น 386'!I26+'เช้า 212'!I26 -> 0 | J26: ='เย็น 386'!J26+'เช้า 212'!J26 -> 0 | K26: =SUM(D26:J26) -> 127 | L26: 113 | M26: 100 | P26: =(L26+M26+N26+O26)-K26 -> 86 | R26: 26 | S26: =P26-R26 -> 60 | T26: 100 | U26: =S26+T26 -> 160
B27: 1004055 | C27: ชิฟฟอน 4 ชิ้น โกโก้ล้วน | D27: ='เย็น 386'!D27+'เช้า 212'!D27 -> 0 | E27: ='เย็น 386'!E27+'เช้า 212'!E27 -> 0 | F27: ='เย็น 386'!F27+'เช้า 212'!F27 -> 0 | G27: ='เย็น 386'!G27+'เช้า 212'!G27 -> 0 | H27: ='เย็น 386'!H27+'เช้า 212'!H27 -> 0 | I27: ='เย็น 386'!I27+'เช้า 212'!I27 -> 0 | J27: ='เย็น 386'!J27+'เช้า 212'!J27 -> 0 | K27: =SUM(D27:J27) -> 0 | P27: =(L27+M27+N27+O27)-K27 -> 0 | S27: =P27-R27 -> 0
B28: 1004055 | C28: ชิฟฟอน 4 ชิ้น มะพร้าวล้วน | D28: ='เย็น 386'!D28+'เช้า 212'!D28 -> 0 | E28: ='เย็น 386'!E28+'เช้า 212'!E28 -> 0 | F28: ='เย็น 386'!F28+'เช้า 212'!F28 -> 0 | G28: ='เย็น 386'!G28+'เช้า 212'!G28 -> 0 | H28: ='เย็น 386'!H28+'เช้า 212'!H28 -> 0 | I28: ='เย็น 386'!I28+'เช้า 212'!I28 -> 0 | J28: ='เย็น 386'!J28+'เช้า 212'!J28 -> 0 | K28: =SUM(D28:J28) -> 0 | P28: =(L28+M28+N28+O28)-K28 -> 0 | S28: =P28-R28 -> 0
B29: 1004055 | C29: ชิฟฟอน 4 ชิ้น เนยล้วน | D29: ='เย็น 386'!D29+'เช้า 212'!D29 -> 0 | E29: ='เย็น 386'!E29+'เช้า 212'!E29 -> 0 | F29: ='เย็น 386'!F29+'เช้า 212'!F29 -> 0 | G29: ='เย็น 386'!G29+'เช้า 212'!G29 -> 0 | H29: ='เย็น 386'!H29+'เช้า 212'!H29 -> 0 | I29: ='เย็น 386'!I29+'เช้า 212'!I29 -> 0 | J29: ='เย็น 386'!J29+'เช้า 212'!J29 -> 0 | K29: =SUM(D29:J29) -> 0 | P29: =(L29+M29+N29+O29)-K29 -> 0 | S29: =P29-R29 -> 0
B30: 1004055 | C30: ชิฟฟอน 4 ชิ้น กาแฟล้วน | D30: ='เย็น 386'!D30+'เช้า 212'!D30 -> 0 | E30: ='เย็น 386'!E30+'เช้า 212'!E30 -> 0 | F30: ='เย็น 386'!F30+'เช้า 212'!F30 -> 0 | G30: ='เย็น 386'!G30+'เช้า 212'!G30 -> 0 | H30: ='เย็น 386'!H30+'เช้า 212'!H30 -> 0 | I30: ='เย็น 386'!I30+'เช้า 212'!I30 -> 0 | J30: ='เย็น 386'!J30+'เช้า 212'!J30 -> 0 | K30: =SUM(D30:J30) -> 0 | P30: =(L30+M30+N30+O30)-K30 -> 0 | S30: =P30-R30 -> 0
B31: 1004055 | C31: ชิฟฟอน 4 ชิ้น ใบเตยล้วน | D31: ='เย็น 386'!D31+'เช้า 212'!D31 -> 0 | E31: ='เย็น 386'!E31+'เช้า 212'!E31 -> 0 | F31: ='เย็น 386'!F31+'เช้า 212'!F31 -> 0 | G31: ='เย็น 386'!G31+'เช้า 212'!G31 -> 0 | H31: ='เย็น 386'!H31+'เช้า 212'!H31 -> 0 | I31: ='เย็น 386'!I31+'เช้า 212'!I31 -> 0 | J31: ='เย็น 386'!J31+'เช้า 212'!J31 -> 0 | K31: =SUM(D31:J31) -> 0 | P31: =(L31+M31+N31+O31)-K31 -> 0 | S31: =P31-R31 -> 0
B32: 1004055 | C32: ชิฟฟอน 4 ชิ้น บลูเบอร์รี่ล้วน | D32: ='เย็น 386'!D32+'เช้า 212'!D32 -> 0 | E32: ='เย็น 386'!E32+'เช้า 212'!E32 -> 0 | F32: ='เย็น 386'!F32+'เช้า 212'!F32 -> 0 | G32: ='เย็น 386'!G32+'เช้า 212'!G32 -> 0 | H32: ='เย็น 386'!H32+'เช้า 212'!H32 -> 0 | I32: ='เย็น 386'!I32+'เช้า 212'!I32 -> 0 | J32: ='เย็น 386'!J32+'เช้า 212'!J32 -> 0 | K32: =SUM(D32:J32) -> 0 | P32: =(L32+M32+N32+O32)-K32 -> 0 | S32: =P32-R32 -> 0
B33: 1004055 | C33: ชิฟฟอน 4 ชิ้น ส้มล้วน | D33: ='เย็น 386'!D33+'เช้า 212'!D33 -> 0 | E33: ='เย็น 386'!E33+'เช้า 212'!E33 -> 0 | F33: ='เย็น 386'!F33+'เช้า 212'!F33 -> 0 | G33: ='เย็น 386'!G33+'เช้า 212'!G33 -> 0 | H33: ='เย็น 386'!H33+'เช้า 212'!H33 -> 0 | I33: ='เย็น 386'!I33+'เช้า 212'!I33 -> 0 | J33: ='เย็น 386'!J33+'เช้า 212'!J33 -> 0 | K33: =SUM(D33:J33) -> 0 | P33: =(L33+M33+N33+O33)-K33 -> 0 | S33: =P33-R33 -> 0
B34: 1004055 | C34: ชิฟฟอน 4 ชิ้น เผือกล้วน | D34: ='เย็น 386'!D34+'เช้า 212'!D34 -> 0 | E34: ='เย็น 386'!E34+'เช้า 212'!E34 -> 0 | F34: ='เย็น 386'!F34+'เช้า 212'!F34 -> 0 | G34: ='เย็น 386'!G34+'เช้า 212'!G34 -> 0 | H34: ='เย็น 386'!H34+'เช้า 212'!H34 -> 0 | I34: ='เย็น 386'!I34+'เช้า 212'!I34 -> 0 | J34: ='เย็น 386'!J34+'เช้า 212'!J34 -> 0 | K34: =SUM(D34:J34) -> 0 | P34: =(L34+M34+N34+O34)-K34 -> 0 | S34: =P34-R34 -> 0
B35: 1004055 | C35: ชิฟฟอน 4 ชิ้น สตอเบอรี่ล้วน | D35: ='เย็น 386'!D35+'เช้า 212'!D35 -> 0 | E35: ='เย็น 386'!E35+'เช้า 212'!E35 -> 0 | F35: ='เย็น 386'!F35+'เช้า 212'!F35 -> 0 | G35: ='เย็น 386'!G35+'เช้า 212'!G35 -> 0 | H35: ='เย็น 386'!H35+'เช้า 212'!H35 -> 0 | I35: ='เย็น 386'!I35+'เช้า 212'!I35 -> 0 | J35: ='เย็น 386'!J35+'เช้า 212'!J35 -> 0 | K35: =SUM(D35:J35) -> 0 | P35: =(L35+M35+N35+O35)-K35 -> 0 | S35: =P35-R35 -> 0
B36: 1004055 | C36: ชิฟฟอน 4 ชิ้น กล้วยหอมล้วน | D36: ='เย็น 386'!D36+'เช้า 212'!D36 -> 0 | E36: ='เย็น 386'!E36+'เช้า 212'!E36 -> 0 | F36: ='เย็น 386'!F36+'เช้า 212'!F36 -> 0 | G36: ='เย็น 386'!G36+'เช้า 212'!G36 -> 0 | H36: ='เย็น 386'!H36+'เช้า 212'!H36 -> 0 | I36: ='เย็น 386'!I36+'เช้า 212'!I36 -> 0 | J36: ='เย็น 386'!J36+'เช้า 212'!J36 -> 0 | K36: =SUM(D36:J36) -> 0 | P36: =(L36+M36+N36+O36)-K36 -> 0 | S36: =P36-R36 -> 0
B37: 1004055 | C37: ชิฟฟอน 4 ชิ้น ชาเขียวล้วน | D37: ='เย็น 386'!D37+'เช้า 212'!D37 -> 0 | E37: ='เย็น 386'!E37+'เช้า 212'!E37 -> 0 | F37: ='เย็น 386'!F37+'เช้า 212'!F37 -> 0 | G37: ='เย็น 386'!G37+'เช้า 212'!G37 -> 0 | H37: ='เย็น 386'!H37+'เช้า 212'!H37 -> 0 | I37: ='เย็น 386'!I37+'เช้า 212'!I37 -> 0 | J37: ='เย็น 386'!J37+'เช้า 212'!J37 -> 0 | K37: =SUM(D37:J37) -> 0 | P37: =(L37+M37+N37+O37)-K37 -> 0 | S37: =P37-R37 -> 0
B38: 1004055 | C38: ชิฟฟอน 4 ชิ้น ชาไทยล้วน | D38: ='เย็น 386'!D38+'เช้า 212'!D38 -> 0 | E38: ='เย็น 386'!E38+'เช้า 212'!E38 -> 0 | F38: ='เย็น 386'!F38+'เช้า 212'!F38 -> 0 | G38: ='เย็น 386'!G38+'เช้า 212'!G38 -> 0 | H38: ='เย็น 386'!H38+'เช้า 212'!H38 -> 0 | I38: ='เย็น 386'!I38+'เช้า 212'!I38 -> 0 | J38: ='เย็น 386'!J38+'เช้า 212'!J38 -> 0 | K38: =SUM(D38:J38) -> 0 | P38: =(L38+M38+N38+O38)-K38 -> 0 | S38: =P38-R38 -> 0
B39: 1004055 | C39: ชิฟฟอน 4 ชิ้น สับปะรดล้วน | D39: ='เย็น 386'!D39+'เช้า 212'!D39 -> 0 | E39: ='เย็น 386'!E39+'เช้า 212'!E39 -> 0 | F39: ='เย็น 386'!F39+'เช้า 212'!F39 -> 0 | G39: ='เย็น 386'!G39+'เช้า 212'!G39 -> 0 | H39: ='เย็น 386'!H39+'เช้า 212'!H39 -> 0 | I39: ='เย็น 386'!I39+'เช้า 212'!I39 -> 0 | J39: ='เย็น 386'!J39+'เช้า 212'!J39 -> 0 | K39: =SUM(D39:J39) -> 0 | P39: =(L39+M39+N39+O39)-K39 -> 0 | S39: =P39-R39 -> 0
B40: 1111057 | C40: ชิฟฟอนแยกชิ้น กาแฟ | D40: ='เย็น 386'!D40+'เช้า 212'!D40 -> 1 | E40: ='เย็น 386'!E40+'เช้า 212'!E40 -> 0 | F40: ='เย็น 386'!F40+'เช้า 212'!F40 -> 1 | G40: ='เย็น 386'!G40+'เช้า 212'!G40 -> 33 | H40: ='เย็น 386'!H40+'เช้า 212'!H40 -> 1 | I40: ='เย็น 386'!I40+'เช้า 212'!I40 -> 0 | J40: ='เย็น 386'!J40+'เช้า 212'!J40 -> 1 | K40: =SUM(D40:J40) -> 37 | P40: =(L40+M40+N40+O40)-K40 -> -37
B41: 1111058 | C41: ชิฟฟอนแยกชิ้น ชาเขียว | D41: ='เย็น 386'!D41+'เช้า 212'!D41 -> 1 | E41: ='เย็น 386'!E41+'เช้า 212'!E41 -> 0 | F41: ='เย็น 386'!F41+'เช้า 212'!F41 -> 1 | G41: ='เย็น 386'!G41+'เช้า 212'!G41 -> 17 | H41: ='เย็น 386'!H41+'เช้า 212'!H41 -> 1 | I41: ='เย็น 386'!I41+'เช้า 212'!I41 -> 0 | J41: ='เย็น 386'!J41+'เช้า 212'!J41 -> 0 | K41: =SUM(D41:J41) -> 20 | P41: =(L41+M41+N41+O41)-K41 -> -20
B42: 1111059 | C42: ชิฟฟอนแยกชิ้น ใบเตย | D42: ='เย็น 386'!D42+'เช้า 212'!D42 -> 1 | E42: ='เย็น 386'!E42+'เช้า 212'!E42 -> 0 | F42: ='เย็น 386'!F42+'เช้า 212'!F42 -> 1 | G42: ='เย็น 386'!G42+'เช้า 212'!G42 -> 33 | H42: ='เย็น 386'!H42+'เช้า 212'!H42 -> 1 | I42: ='เย็น 386'!I42+'เช้า 212'!I42 -> 0 | J42: ='เย็น 386'!J42+'เช้า 212'!J42 -> 0 | K42: =SUM(D42:J42) -> 36 | P42: =(L42+M42+N42+O42)-K42 -> -36
B43: 1111060 | C43: ชิฟฟอนแยกชิ้น กล้วยหอม | D43: ='เย็น 386'!D43+'เช้า 212'!D43 -> 0 | E43: ='เย็น 386'!E43+'เช้า 212'!E43 -> 0 | F43: ='เย็น 386'!F43+'เช้า 212'!F43 -> 1 | G43: ='เย็น 386'!G43+'เช้า 212'!G43 -> 0 | H43: ='เย็น 386'!H43+'เช้า 212'!H43 -> 1 | I43: ='เย็น 386'!I43+'เช้า 212'!I43 -> 0 | J43: ='เย็น 386'!J43+'เช้า 212'!J43 -> 0 | K43: =SUM(D43:J43) -> 2 | P43: =(L43+M43+N43+O43)-K43 -> -2
B44: 1111061 | C44: ชิฟฟอนแยกชิ้น ชาไทย | D44: ='เย็น 386'!D44+'เช้า 212'!D44 -> 0 | E44: ='เย็น 386'!E44+'เช้า 212'!E44 -> 0 | F44: ='เย็น 386'!F44+'เช้า 212'!F44 -> 0 | G44: ='เย็น 386'!G44+'เช้า 212'!G44 -> 8 | H44: ='เย็น 386'!H44+'เช้า 212'!H44 -> 0 | I44: ='เย็น 386'!I44+'เช้า 212'!I44 -> 0 | J44: ='เย็น 386'!J44+'เช้า 212'!J44 -> 0 | K44: =SUM(D44:J44) -> 8 | P44: =(L44+M44+N44+O44)-K44 -> -8
...
