Workbook

Sheet เย็น
B1: ยอดจริง ออนไลน์ วันที่ 5/11/2567 - เย็น
K2: ยอดรวมผลิต
K3: จำนวน
B4: รหัสสินค้า | C4: สินค้า | D4: ปณ | E4: ชอปปี้ | F4: ลาซาด้า | G4: ติ๊กตอก | H4: ติ๊กตอก2 | I4: ติ๊กตอก3 | J4: ชอยส์ | K4: (กล่อง)
B6: ชิฟฟอนรวมรส
B7: 1111002 | C7: ชิฟฟอนรวมรส 8 ชิ้น | K7: =SUM(D7:J7) -> 0
C8: ชิฟฟอนแบบกล่องสุ่มอะไรก็ได้ที่มี | K8: =SUM(D8:J8) -> 0
B9: 1111084 | C9: ชิฟฟอน 8 ชิ้น กาแฟล้วน | K9: =SUM(D9:J9) -> 0
B10: 1111085 | C10: ชิฟฟอน 8 ชิ้น บลูเบอรี่ล้วน | K10: =SUM(D10:J10) -> 0
B11: 1111086 | C11: ชิฟฟอน 8 ชิ้น มะพร้าวล้วน | K11: =SUM(D11:J11) -> 0
B12: 1111087 | C12: ชิฟฟอน 8 ชิ้น สตอเบอรี่ล้วน | K12: =SUM(D12:J12) -> 0
B13: 1111088 | C13: ชิฟฟอน 8 ชิ้น ส้มล้วน | K13: =SUM(D13:J13) -> 0
B14: 1111089 | C14: ชิฟฟอน 8 ชิ้น เนยล้วน | K14: =SUM(D14:J14) -> 0
B15: 1111090 | C15: ชิฟฟอน 8 ชิ้น เผือกล้วน | K15: =SUM(D15:J15) -> 0
B16: 1111091 | C16: ชิฟฟอน 8 ชิ้น ใบเตยล้วน | K16: =SUM(D16:J16) -> 0
B17: 1111092 | C17: ชิฟฟอน 8 ชิ้น กล้วยหอม | K17: =SUM(D17:J17) -> 0
B18: 1111093 | C18: ชิฟฟอน 8 ชิ้น โกโก้ล้วน | K18: =SUM(D18:J18) -> 0
B19: 1111094 | C19: ชิฟฟอน 8 ชิ้น ชาไทยล้วน | K19: =SUM(D19:J19) -> 0
B20: 1111095 | C20: ชิฟฟอน 8 ชิ้น ชาเขียวล้วน | K20: =SUM(D20:J20) -> 0
... B66: 1111010 | C66: ชิฟฟอนไส้แยมแยกชิ้น คละรส | K66: =SUM(D66:J66) -> 0
C67: รวม | K67: =SUM(D67:I67) -> 0
B68: ชิฟฟอนไส้แยม 6 ชิ้น
B69: 1111009 | C69: ชิฟฟอนไส้แยมรวมรส 6 ชิ้น | K69: =SUM(D69:J69) -> 0
B70: 1111023 | C70: ชิฟฟอนไส้แยมรสสตอเบอร์รี่ล้วน 6 ชิ้น | K70: =SUM(D70:J70) -> 0
B71: 1111016 | C71: ชิฟฟอนไส้แยมรสมะพร้าวล้วน 6 ชิ้น | K71: =SUM(D71:J71) -> 0
B72: 1111014 | C72: ชิฟฟอนไส้แยมรสช็อกโกแลตนูเทลล่าล้วน 6 ชิ้น | K72: =SUM(D72:J72) -> 0
B73: 1111025 | C73: ชิฟฟอนไส้แยมรสส้มล้วน 6 ชิ้น | K73: =SUM(D73:J73) -> 0
B74: 1111018 | C74: ชิฟฟอนไส้แยมรสบลูเบอร์รี่ล้วน 6 ชิ้น | K74: =SUM(D74:J74) -> 0
B75: 1111012 | C75: ชิฟฟอนไส้แยมรสนมชมพูฮอกไกโดล้วน 6 ชิ้น | K75: =SUM(D75:J75) -> 0
B76: 1111020 | C76: ชิฟฟอนไส้แยมฝอยทองไส้ทะลัก 6 ชิ้น | K76: =SUM(D76:J76) -> 0
C77: รวม
B78: ชิฟฟอนไส้แยม 3 ชิ้น
B79: 1111022 | C79: ชิฟฟอนไส้แยมรสสตอเบอร์รี่ล้วน 3 ชิ้น | K79: =SUM(D79:J79) -> 0
B80: 1111015 | C80: ชิฟฟอนไส้แยมรสมะพร้าวล้วน 3 ชิ้น | K80: =SUM(D80:J80) -> 0
B81: 1111013 | C81: ชิฟฟอนไส้แยมรสช็อกโกแลตนูเทลล่าล้วน 3 ชิ้น | K81: =SUM(D81:J81) -> 0
B82: 1111024 | C82: ชิฟฟอนไส้แยมรสส้มล้วน 3 ชิ้น | K82: =SUM(D82:J82) -> 0
B83: 1111017 | C83: ชิฟฟอนไส้แยมรสบลูเบอร์รี่ล้วน 3 ชิ้น | K83: =SUM(D83:J83) -> 0
B84: 1111011 | C84: ชิฟฟอนไส้แยมรสนมชมพูฮอกไกโดล้วน 3 ชิ้น | K84: =SUM(D84:J84) -> 0
B85: 1111019 | C85: ชิฟฟอนไส้แยมฝอยทองไส้ทะลัก 3 ชิ้น | K85: =SUM(D85:J85) -> 0
B86: 1113081 | C86: ชิฟฟอนไส้แยม วนิลา/ใบเตย/เมล่อน | K86: =SUM(D86:J86) -> 0
...

Sheet เช้า
B1: ยอดจริง ออนไลน์ วันที่ 5/11/2567 - เช้า
K2: ยอดรวมผลิต
K3: จำนวน
B4: รหัสสินค้า | C4: สินค้า | D4: ปณ | E4: ชอปปี้ | F4: ลาซาด้า | G4: ติ๊กตอก | H4: ติ๊กตอก2 | I4: ติ๊กตอก3 | J4: ชอยส์ | K4: (กล่อง)
B6: ชิฟฟอนรวมรส
B7: 1111002 | C7: ชิฟฟอนรวมรส 8 ชิ้น | D7: 1 | E7: 73 | F7: 187 | G7: 7 | K7: =SUM(D7:J7) -> 268
C8: ชิฟฟอนแบบกล่องสุ่มอะไรก็ได้ที่มี | K8: =SUM(D8:J8) -> 0
B9: 1111084 | C9: ชิฟฟอน 8 ชิ้น กาแฟล้วน | K9: =SUM(D9:J9) -> 0
B10: 1111085 | C10: ชิฟฟอน 8 ชิ้น บลูเบอรี่ล้วน | K10: =SUM(D10:J10) -> 0
B11: 1111086 | C11: ชิฟฟอน 8 ชิ้น มะพร้าวล้วน | K11: =SUM(D11:J11) -> 0
B12: 1111087 | C12: ชิฟฟอน 8 ชิ้น สตอเบอรี่ล้วน | K12: =SUM(D12:J12) -> 0
B13: 1111088 | C13: ชิฟฟอน 8 ชิ้น ส้มล้วน | K13: =SUM(D13:J13) -> 0
B14: 1111089 | C14: ชิฟฟอน 8 ชิ้น เนยล้วน | K14: =SUM(D14:J14) -> 0
B15: 1111090 | C15: ชิฟฟอน 8 ชิ้น เผือกล้วน | K15: =SUM(D15:J15) -> 0
B16: 1111091 | C16: ชิฟฟอน 8 ชิ้น ใบเตยล้วน | K16: =SUM(D16:J16) -> 0
B17: 1111092 | C17: ชิฟฟอน 8 ชิ้น กล้วยหอม | K17: =SUM(D17:J17) -> 0
B18: 1111093 | C18: ชิฟฟอน 8 ชิ้น โกโก้ล้วน | K18: =SUM(D18:J18) -> 0
B19: 1111094 | C19: ชิฟฟอน 8 ชิ้น ชาไทยล้วน | K19: =SUM(D19:J19) -> 0
B20: 1111095 | C20: ชิฟฟอน 8 ชิ้น ชาเขียวล้วน | K20: =SUM(D20:J20) -> 0
... B24: 1111043 | C24: ชิฟฟอน 8 ชิ้น มะลิ | K24: =SUM(D24:J24) -> 0
B25: 1111056 | C25: ชิฟฟอน 8 ชิ้น รวมรสยอดฮิต | E25: 7 | F25: 9 | G25: 1 | H25: 1 | K25: =SUM(D25:J25) -> 18
B26: 1004055 | C26: ชิฟฟอนรวมรส 4 ชิ้น | D26: 4 | E26: 3 | G26: 98 | H26: 84 | K26: =SUM(D26:J26) -> 189
B27: 1004055 | C27: ชิฟฟอน 4 ชิ้น โกโก้ล้วน | K27: =SUM(D27:J27) -> 0
B28: 1004055 | C28: ชิฟฟอน 4 ชิ้น มะพร้าวล้วน | K28: =SUM(D28:J28) -> 0
B29: 1004055 | C29: ชิฟฟอน 4 ชิ้น เนยล้วน | K29: =SUM(D29:J29) -> 0
B30: 1004055 | C30: ชิฟฟอน 4 ชิ้น กาแฟล้วน | K30: =SUM(D30:J30) -> 0
B31: 1004055 | C31: ชิฟฟอน 4 ชิ้น ใบเตยล้วน | K31: =SUM(D31:J31) -> 0
B32: 1004055 | C32: ชิฟฟอน 4 ชิ้น บลูเบอร์รี่ล้วน | K32: =SUM(D32:J32) -> 0
B33: 1004055 | C33: ชิฟฟอน 4 ชิ้น ส้มล้วน | K33: =SUM(D33:J33) -> 0
B34: 1004055 | C34: ชิฟฟอน 4 ชิ้น เผือกล้วน | K34: =SUM(D34:J34) -> 0
B35: 1004055 | C35: ชิฟฟอน 4 ชิ้น สตอเบอรี่ล้วน | K35: =SUM(D35:J35) -> 0
B36: 1004055 | C36: ชิฟฟอน 4 ชิ้น กล้วยหอมล้วน | K36: =SUM(D36:J36) -> 0
B37: 1004055 | C37: ชิฟฟอน 4 ชิ้น ชาเขียวล้วน | K37: =SUM(D37:J37) -> 0
B38: 1004055 | C38: ชิฟฟอน 4 ชิ้น ชาไทยล้วน | K38: =SUM(D38:J38) -> 0
B39: 1004055 | C39: ชิฟฟอน 4 ชิ้น สับปะรดล้วน | K39: =SUM(D39:J39) -> 0
B40: 1111057 | C40: ชิฟฟอนแยกชิ้น กาแฟ | D40: 30 | E40: 22 | F40: 7 | G40: 3 | J40: 2 | K40: =SUM(D40:J40) -> 64
B41: 1111058 | C41: ชิฟฟอนแยกชิ้น ชาเขียว | D41: 30 | E41: 13 | G41: 3 | K41: =SUM(D41:J41) -> 46
B42: 1111059 | C42: ชิฟฟอนแยกชิ้น ใบเตย | D42: 30 | E42: 13 | F42: 7 | G42: 3 | K42: =SUM(D42:J42) -> 53
B43: 1111060 | C43: ชิฟฟอนแยกชิ้น กล้วยหอม | D43: 30 | E43: 2 | G43: 1 | K43: =SUM(D43:J43) -> 33
B44: 1111061 | C44: ชิฟฟอนแยกชิ้น ชาไทย | D44: 30 | E44: 13 | F44: 7 | G44: 3 | K44: =SUM(D44:J44) -> 53
...

Sheet รวม
B1: ยอดจริง ออนไลน์ วันที่ 5/11/2567 - รวม
K2: ยอดรวมผลิต | L2: ยอดสตอค | M2: ยอดฟอแคส | N2: รับเกิน | O2: ยังไม่ได้รับเข้า | P2: รวม
K3: จำนวน
B4: รหัสสินค้า | C4: สินค้า | D4: ปณ | E4: ชอปปี้ | F4: ลาซาด้า | G4: ติ๊กตอก | H4: ติ๊กตอก2 | I4: ติ๊กตอก3 | J4: ชอยส์ | K4: (กล่อง)
B6: ชิฟฟอนรวมรส
B7: 1111002 | C7: ชิฟฟอนรวมรส 8 ชิ้น | D7: =เย็น!D7+เช้า!D7 -> 1 | E7: =เย็น!E7+เช้า!E7 -> 73 | F7: =เย็น!F7+เช้า!F7 -> 187 | G7: =เย็น!G7+เช้า!G7 -> 7 | H7: =เย็น!H7+เช้า!H7 -> 0 | I7: =เย็น!I7+เช้า!I7 -> 0 | J7: =เย็น!J7+เช้า!J7 -> 0 | K7: =SUM(D7:J7) -> 268 | L7: 30 | M7: 200 | P7: =(L7+M7+N7+O7)-K7 -> -38
C8: ชิฟฟอนแบบกล่องสุ่มอะไรก็ได้ที่มี | D8: =เย็น!D8+เช้า!D8 -> 0 | E8: =เย็น!E8+เช้า!E8 -> 0 | F8: =เย็น!F8+เช้า!F8 -> 0 | G8: =เย็น!G8+เช้า!G8 -> 0 | H8: =เย็น!H8+เช้า!H8 -> 0 | I8: =เย็น!I8+เช้า!I8 -> 0 | J8: =เย็น!J8+เช้า!J8 -> 0 | K8: =SUM(D8:J8) -> 0 | P8: =(L8+M8+N8+O8)-K8 -> 0
B9: 1111084 | C9: ชิฟฟอน 8 ชิ้น กาแฟล้วน | D9: =เย็น!D9+เช้า!D9 -> 0 | E9: =เย็น!E9+เช้า!E9 -> 0 | F9: =เย็น!F9+เช้า!F9 -> 0 | G9: =เย็น!G9+เช้า!G9 -> 0 | H9: =เย็น!H9+เช้า!H9 -> 0 | I9: =เย็น!I9+เช้า!I9 -> 0 | J9: =เย็น!J9+เช้า!J9 -> 0 | K9: =SUM(D9:J9) -> 0 | P9: =(L9+M9+N9+O9)-K9 -> 0
B10: 1111085 | C10: ชิฟฟอน 8 ชิ้น บลูเบอรี่ล้วน | D10: =เย็น!D10+เช้า!D10 -> 0 | E10: =เย็น!E10+เช้า!E10 -> 0 | F10: =เย็น!F10+เช้า!F10 -> 0 | G10: =เย็น!G10+เช้า!G10 -> 0 | H10: =เย็น!H10+เช้า!H10 -> 0 | I10: =เย็น!I10+เช้า!I10 -> 0 | J10: =เย็น!J10+เช้า!J10 -> 0 | K10: =SUM(D10:J10) -> 0 | P10: =(L10+M10+N10+O10)-K10 -> 0
B11: 1111086 | C11: ชิฟฟอน 8 ชิ้น มะพร้าวล้วน | D11: =เย็น!D11+เช้า!D11 -> 0 | E11: =เย็น!E11+เช้า!E11 -> 0 | F11: =เย็น!F11+เช้า!F11 -> 0 | G11: =เย็น!G11+เช้า!G11 -> 0 | H11: =เย็น!H11+เช้า!H11 -> 0 | I11: =เย็น!I11+เช้า!I11 -> 0 | J11: =เย็น!J11+เช้า!J11 -> 0 | K11: =SUM(D11:J11) -> 0 | P11: =(L11+M11+N11+O11)-K11 -> 0
B12: 1111087 | C12: ชิฟฟอน 8 ชิ้น สตอเบอรี่ล้วน | D12: =เย็น!D12+เช้า!D12 -> 0 | E12: =เย็น!E12+เช้า!E12 -> 0 | F12: =เย็น!F12+เช้า!F12 -> 0 | G12: =เย็น!G12+เช้า!G12 -> 0 | H12: =เย็น!H12+เช้า!H12 -> 0 | I12: =เย็น!I12+เช้า!I12 -> 0 | J12: =เย็น!J12+เช้า!J12 -> 0 | K12: =SUM(D12:J12) -> 0 | P12: =(L12+M12+N12+O12)-K12 -> 0
B13: 1111088 | C13: ชิฟฟอน 8 ชิ้น ส้มล้วน | D13: =เย็น!D13+เช้า!D13 -> 0 | E13: =เย็น!E13+เช้า!E13 -> 0 | F13: =เย็น!F13+เช้า!F13 -> 0 | G13: =เย็น!G13+เช้า!G13 -> 0 | H13: =เย็น!H13+เช้า!H13 -> 0 | I13: =เย็น!I13+เช้า!I13 -> 0 | J13: =เย็น!J13+เช้า!J13 -> 0 | K13: =SUM(D13:J13) -> 0 | P13: =(L13+M13+N13+O13)-K13 -> 0
B14: 1111089 | C14: ชิฟฟอน 8 ชิ้น เนยล้วน | D14: =เย็น!D14+เช้า!D14 -> 0 | E14: =เย็น!E14+เช้า!E14 -> 0 | F14: =เย็น!F14+เช้า!F14 -> 0 | G14: =เย็น!G14+เช้า!G14 -> 0 | H14: =เย็น!H14+เช้า!H14 -> 0 | I14: =เย็น!I14+เช้า!I14 -> 0 | J14: =เย็น!J14+เช้า!J14 -> 0 | K14: =SUM(D14:J14) -> 0 | P14: =(L14+M14+N14+O14)-K14 -> 0
B15: 1111090 | C15: ชิฟฟอน 8 ชิ้น เผือกล้วน | D15: =เย็น!D15+เช้า!D15 -> 0 | E15: =เย็น!E15+เช้า!E15 -> 0 | F15: =เย็น!F15+เช้า!F15 -> 0 | G15: =เย็น!G15+เช้า!G15 -> 0 | H15: =เย็น!H15+เช้า!H15 -> 0 | I15: =เย็น!I15+เช้า!I15 -> 0 | J15: =เย็น!J15+เช้า!J15 -> 0 | K15: =SUM(D15:J15) -> 0 | P15: =(L15+M15+N15+O15)-K15 -> 0
B16: 1111091 | C16: ชิฟฟอน 8 ชิ้น ใบเตยล้วน | D16: =เย็น!D16+เช้า!D16 -> 0 | E16: =เย็น!E16+เช้า!E16 -> 0 | F16: =เย็น!F16+เช้า!F16 -> 0 | G16: =เย็น!G16+เช้า!G16 -> 0 | H16: =เย็น!H16+เช้า!H16 -> 0 | I16: =เย็น!I16+เช้า!I16 -> 0 | J16: =เย็น!J16+เช้า!J16 -> 0 | K16: =SUM(D16:J16) -> 0 | P16: =(L16+M16+N16+O16)-K16 -> 0
B17: 1111092 | C17: ชิฟฟอน 8 ชิ้น กล้วยหอม | D17: =เย็น!D17+เช้า!D17 -> 0 | E17: =เย็น!E17+เช้า!E17 -> 0 | F17: =เย็น!F17+เช้า!F17 -> 0 | G17: =เย็น!G17+เช้า!G17 -> 0 | H17: =เย็น!H17+เช้า!H17 -> 0 | I17: =เย็น!I17+เช้า!I17 -> 0 | J17: =เย็น!J17+เช้า!J17 -> 0 | K17: =SUM(D17:J17) -> 0 | P17: =(L17+M17+N17+O17)-K17 -> 0
B18: 1111093 | C18: ชิฟฟอน 8 ชิ้น โกโก้ล้วน | D18: =เย็น!D18+เช้า!D18 -> 0 | E18: =เย็น!E18+เช้า!E18 -> 0 | F18: =เย็น!F18+เช้า!F18 -> 0 | G18: =เย็น!G18+เช้า!G18 -> 0 | H18: =เย็น!H18+เช้า!H18 -> 0 | I18: =เย็น!I18+เช้า!I18 -> 0 | J18: =เย็น!J18+เช้า!J18 -> 0 | K18: =SUM(D18:J18) -> 0 | P18: =(L18+M18+N18+O18)-K18 -> 0
B19: 1111094 | C19: ชิฟฟอน 8 ชิ้น ชาไทยล้วน | D19: =เย็น!D19+เช้า!D19 -> 0 | E19: =เย็น!E19+เช้า!E19 -> 0 | F19: =เย็น!F19+เช้า!F19 -> 0 | G19: =เย็น!G19+เช้า!G19 -> 0 | H19: =เย็น!H19+เช้า!H19 -> 0 | I19: =เย็น!I19+เช้า!I19 -> 0 | J19: =เย็น!J19+เช้า!J19 -> 0 | K19: =SUM(D19:J19) -> 0 | P19: =(L19+M19+N19+O19)-K19 -> 0
B20: 1111095 | C20: ชิฟฟอน 8 ชิ้น ชาเขียวล้วน | D20: =เย็น!D20+เช้า!D20 -> 0 | E20: =เย็น!E20+เช้า!E20 -> 0 | F20: =เย็น!F20+เช้า!F20 -> 0 | G20: =เย็น!G20+เช้า!G20 -> 0 | H20: =เย็น!H20+เช้า!H20 -> 0 | I20: =เย็น!I20+เช้า!I20 -> 0 | J20: =เย็น!J20+เช้า!J20 -> 0 | K20: =SUM(D20:J20) -> 0 | P20: =(L20+M20+N20+O20)-K20 -> 0
... B24: 1111043 | C24: ชิฟฟอน 8 ชิ้น มะลิ | D24: =เย็น!D24+เช้า!D24 -> 0 | E24: =เย็น!E24+เช้า!E24 -> 0 | F24: =เย็น!F24+เช้า!F24 -> 0 | G24: =เย็น!G24+เช้า!G24 -> 0 | H24: =เย็น!H24+เช้า!H24 -> 0 | I24: =เย็น!I24+เช้า!I24 -> 0 | J24: =เย็น!J24+เช้า!J24 -> 0 | K24: =SUM(D24:J24) -> 0 | P24: =(L24+M24+N24+O24)-K24 -> 0
B25: 1111056 | C25: ชิฟฟอน 8 ชิ้น รวมรสยอดฮิต | D25: =เย็น!D25+เช้า!D25 -> 0 | E25: =เย็น!E25+เช้า!E25 -> 7 | F25: =เย็น!F25+เช้า!F25 -> 9 | G25: =เย็น!G25+เช้า!G25 -> 1 | H25: =เย็น!H25+เช้า!H25 -> 1 | I25: =เย็น!I25+เช้า!I25 -> 0 | J25: =เย็น!J25+เช้า!J25 -> 0 | K25: =SUM(D25:J25) -> 18 | L25: 10 | M25: 15 | P25: =(L25+M25+N25+O25)-K25 -> 7
B26: 1004055 | C26: ชิฟฟอนรวมรส 4 ชิ้น | D26: =เย็น!D26+เช้า!D26 -> 4 | E26: =เย็น!E26+เช้า!E26 -> 3 | F26: =เย็น!F26+เช้า!F26 -> 0 | G26: =เย็น!G26+เช้า!G26 -> 98 | H26: =เย็น!H26+เช้า!H26 -> 84 | I26: =เย็น!I26+เช้า!I26 -> 0 | J26: =เย็น!J26+เช้า!J26 -> 0 | K26: =SUM(D26:J26) -> 189 | M26: 100 | P26: =(L26+M26+N26+O26)-K26 -> -89
B27: 1004055 | C27: ชิฟฟอน 4 ชิ้น โกโก้ล้วน | D27: =เย็น!D27+เช้า!D27 -> 0 | E27: =เย็น!E27+เช้า!E27 -> 0 | F27: =เย็น!F27+เช้า!F27 -> 0 | G27: =เย็น!G27+เช้า!G27 -> 0 | H27: =เย็น!H27+เช้า!H27 -> 0 | I27: =เย็น!I27+เช้า!I27 -> 0 | J27: =เย็น!J27+เช้า!J27 -> 0 | K27: =SUM(D27:J27) -> 0 | P27: =(L27+M27+N27+O27)-K27 -> 0
B28: 1004055 | C28: ชิฟฟอน 4 ชิ้น มะพร้าวล้วน | D28: =เย็น!D28+เช้า!D28 -> 0 | E28: =เย็น!E28+เช้า!E28 -> 0 | F28: =เย็น!F28+เช้า!F28 -> 0 | G28: =เย็น!G28+เช้า!G28 -> 0 | H28: =เย็น!H28+เช้า!H28 -> 0 | I28: =เย็น!I28+เช้า!I28 -> 0 | J28: =เย็น!J28+เช้า!J28 -> 0 | K28: =SUM(D28:J28) -> 0 | P28: =(L28+M28+N28+O28)-K28 -> 0
B29: 1004055 | C29: ชิฟฟอน 4 ชิ้น เนยล้วน | D29: =เย็น!D29+เช้า!D29 -> 0 | E29: =เย็น!E29+เช้า!E29 -> 0 | F29: =เย็น!F29+เช้า!F29 -> 0 | G29: =เย็น!G29+เช้า!G29 -> 0 | H29: =เย็น!H29+เช้า!H29 -> 0 | I29: =เย็น!I29+เช้า!I29 -> 0 | J29: =เย็น!J29+เช้า!J29 -> 0 | K29: =SUM(D29:J29) -> 0 | P29: =(L29+M29+N29+O29)-K29 -> 0
B30: 1004055 | C30: ชิฟฟอน 4 ชิ้น กาแฟล้วน | D30: =เย็น!D30+เช้า!D30 -> 0 | E30: =เย็น!E30+เช้า!E30 -> 0 | F30: =เย็น!F30+เช้า!F30 -> 0 | G30: =เย็น!G30+เช้า!G30 -> 0 | H30: =เย็น!H30+เช้า!H30 -> 0 | I30: =เย็น!I30+เช้า!I30 -> 0 | J30: =เย็น!J30+เช้า!J30 -> 0 | K30: =SUM(D30:J30) -> 0 | P30: =(L30+M30+N30+O30)-K30 -> 0
B31: 1004055 | C31: ชิฟฟอน 4 ชิ้น ใบเตยล้วน | D31: =เย็น!D31+เช้า!D31 -> 0 | E31: =เย็น!E31+เช้า!E31 -> 0 | F31: =เย็น!F31+เช้า!F31 -> 0 | G31: =เย็น!G31+เช้า!G31 -> 0 | H31: =เย็น!H31+เช้า!H31 -> 0 | I31: =เย็น!I31+เช้า!I31 -> 0 | J31: =เย็น!J31+เช้า!J31 -> 0 | K31: =SUM(D31:J31) -> 0 | P31: =(L31+M31+N31+O31)-K31 -> 0
B32: 1004055 | C32: ชิฟฟอน 4 ชิ้น บลูเบอร์รี่ล้วน | D32: =เย็น!D32+เช้า!D32 -> 0 | E32: =เย็น!E32+เช้า!E32 -> 0 | F32: =เย็น!F32+เช้า!F32 -> 0 | G32: =เย็น!G32+เช้า!G32 -> 0 | H32: =เย็น!H32+เช้า!H32 -> 0 | I32: =เย็น!I32+เช้า!I32 -> 0 | J32: =เย็น!J32+เช้า!J32 -> 0 | K32: =SUM(D32:J32) -> 0 | P32: =(L32+M32+N32+O32)-K32 -> 0
B33: 1004055 | C33: ชิฟฟอน 4 ชิ้น ส้มล้วน | D33: =เย็น!D33+เช้า!D33 -> 0 | E33: =เย็น!E33+เช้า!E33 -> 0 | F33: =เย็น!F33+เช้า!F33 -> 0 | G33: =เย็น!G33+เช้า!G33 -> 0 | H33: =เย็น!H33+เช้า!H33 -> 0 | I33: =เย็น!I33+เช้า!I33 -> 0 | J33: =เย็น!J33+เช้า!J33 -> 0 | K33: =SUM(D33:J33) -> 0 | P33: =(L33+M33+N33+O33)-K33 -> 0
B34: 1004055 | C34: ชิฟฟอน 4 ชิ้น เผือกล้วน | D34: =เย็น!D34+เช้า!D34 -> 0 | E34: =เย็น!E34+เช้า!E34 -> 0 | F34: =เย็น!F34+เช้า!F34 -> 0 | G34: =เย็น!G34+เช้า!G34 -> 0 | H34: =เย็น!H34+เช้า!H34 -> 0 | I34: =เย็น!I34+เช้า!I34 -> 0 | J34: =เย็น!J34+เช้า!J34 -> 0 | K34: =SUM(D34:J34) -> 0 | P34: =(L34+M34+N34+O34)-K34 -> 0
B35: 1004055 | C35: ชิฟฟอน 4 ชิ้น สตอเบอรี่ล้วน | D35: =เย็น!D35+เช้า!D35 -> 0 | E35: =เย็น!E35+เช้า!E35 -> 0 | F35: =เย็น!F35+เช้า!F35 -> 0 | G35: =เย็น!G35+เช้า!G35 -> 0 | H35: =เย็น!H35+เช้า!H35 -> 0 | I35: =เย็น!I35+เช้า!I35 -> 0 | J35: =เย็น!J35+เช้า!J35 -> 0 | K35: =SUM(D35:J35) -> 0 | P35: =(L35+M35+N35+O35)-K35 -> 0
B36: 1004055 | C36: ชิฟฟอน 4 ชิ้น กล้วยหอมล้วน | D36: =เย็น!D36+เช้า!D36 -> 0 | E36: =เย็น!E36+เช้า!E36 -> 0 | F36: =เย็น!F36+เช้า!F36 -> 0 | G36: =เย็น!G36+เช้า!G36 -> 0 | H36: =เย็น!H36+เช้า!H36 -> 0 | I36: =เย็น!I36+เช้า!I36 -> 0 | J36: =เย็น!J36+เช้า!J36 -> 0 | K36: =SUM(D36:J36) -> 0 | P36: =(L36+M36+N36+O36)-K36 -> 0
B37: 1004055 | C37: ชิฟฟอน 4 ชิ้น ชาเขียวล้วน | D37: =เย็น!D37+เช้า!D37 -> 0 | E37: =เย็น!E37+เช้า!E37 -> 0 | F37: =เย็น!F37+เช้า!F37 -> 0 | G37: =เย็น!G37+เช้า!G37 -> 0 | H37: =เย็น!H37+เช้า!H37 -> 0 | I37: =เย็น!I37+เช้า!I37 -> 0 | J37: =เย็น!J37+เช้า!J37 -> 0 | K37: =SUM(D37:J37) -> 0 | P37: =(L37+M37+N37+O37)-K37 -> 0
B38: 1004055 | C38: ชิฟฟอน 4 ชิ้น ชาไทยล้วน | D38: =เย็น!D38+เช้า!D38 -> 0 | E38: =เย็น!E38+เช้า!E38 -> 0 | F38: =เย็น!F38+เช้า!F38 -> 0 | G38: =เย็น!G38+เช้า!G38 -> 0 | H38: =เย็น!H38+เช้า!H38 -> 0 | I38: =เย็น!I38+เช้า!I38 -> 0 | J38: =เย็น!J38+เช้า!J38 -> 0 | K38: =SUM(D38:J38) -> 0 | P38: =(L38+M38+N38+O38)-K38 -> 0
B39: 1004055 | C39: ชิฟฟอน 4 ชิ้น สับปะรดล้วน | D39: =เย็น!D39+เช้า!D39 -> 0 | E39: =เย็น!E39+เช้า!E39 -> 0 | F39: =เย็น!F39+เช้า!F39 -> 0 | G39: =เย็น!G39+เช้า!G39 -> 0 | H39: =เย็น!H39+เช้า!H39 -> 0 | I39: =เย็น!I39+เช้า!I39 -> 0 | J39: =เย็น!J39+เช้า!J39 -> 0 | K39: =SUM(D39:J39) -> 0 | P39: =(L39+M39+N39+O39)-K39 -> 0
B40: 1111057 | C40: ชิฟฟอนแยกชิ้น กาแฟ | D40: =เย็น!D40+เช้า!D40 -> 30 | E40: =เย็น!E40+เช้า!E40 -> 22 | F40: =เย็น!F40+เช้า!F40 -> 7 | G40: =เย็น!G40+เช้า!G40 -> 3 | H40: =เย็น!H40+เช้า!H40 -> 0 | I40: =เย็น!I40+เช้า!I40 -> 0 | J40: =เย็น!J40+เช้า!J40 -> 2 | K40: =SUM(D40:J40) -> 64 | M40: 10 | P40: =(L40+M40+N40+O40)-K40 -> -54
B41: 1111058 | C41: ชิฟฟอนแยกชิ้น ชาเขียว | D41: =เย็น!D41+เช้า!D41 -> 30 | E41: =เย็น!E41+เช้า!E41 -> 13 | F41: =เย็น!F41+เช้า!F41 -> 0 | G41: =เย็น!G41+เช้า!G41 -> 3 | H41: =เย็น!H41+เช้า!H41 -> 0 | I41: =เย็น!I41+เช้า!I41 -> 0 | J41: =เย็น!J41+เช้า!J41 -> 0 | K41: =SUM(D41:J41) -> 46 | M41: 10 | P41: =(L41+M41+N41+O41)-K41 -> -36
B42: 1111059 | C42: ชิฟฟอนแยกชิ้น ใบเตย | D42: =เย็น!D42+เช้า!D42 -> 30 | E42: =เย็น!E42+เช้า!E42 -> 13 | F42: =เย็น!F42+เช้า!F42 -> 7 | G42: =เย็น!G42+เช้า!G42 -> 3 | H42: =เย็น!H42+เช้า!H42 -> 0 | I42: =เย็น!I42+เช้า!I42 -> 0 | J42: =เย็น!J42+เช้า!J42 -> 0 | K42: =SUM(D42:J42) -> 53 | M42: 10 | P42: =(L42+M42+N42+O42)-K42 -> -43
B43: 1111060 | C43: ชิฟฟอนแยกชิ้น กล้วยหอม | D43: =เย็น!D43+เช้า!D43 -> 30 | E43: =เย็น!E43+เช้า!E43 -> 2 | F43: =เย็น!F43+เช้า!F43 -> 0 | G43: =เย็น!G43+เช้า!G43 -> 1 | H43: =เย็น!H43+เช้า!H43 -> 0 | I43: =เย็น!I43+เช้า!I43 -> 0 | J43: =เย็น!J43+เช้า!J43 -> 0 | K43: =SUM(D43:J43) -> 33 | M43: 10 | P43: =(L43+M43+N43+O43)-K43 -> -23
B44: 1111061 | C44: ชิฟฟอนแยกชิ้น ชาไทย | D44: =เย็น!D44+เช้า!D44 -> 30 | E44: =เย็น!E44+เช้า!E44 -> 13 | F44: =เย็น!F44+เช้า!F44 -> 7 | G44: =เย็น!G44+เช้า!G44 -> 3 | H44: =เย็น!H44+เช้า!H44 -> 0 | I44: =เย็น!I44+เช้า!I44 -> 0 | J44: =เย็น!J44+เช้า!J44 -> 0 | K44: =SUM(D44:J44) -> 53 | M44: 10 | P44: =(L44+M44+N44+O44)-K44 -> -43
...
