Workbook

Sheet 1
A1: ใบสต๊อกบูธ 11037 บูธวัดเขาทำเทียม
A2: ลำดับ | B2: รหัส | C2: รายการสินค้า | D2: ราคา | E2: ยอดยกมา | F2: รับเข้า | G2: ส่งคืน | H2: ขายออก | I2: คงเหลือ | J2: ยอดเงิน | K2: หมายเหตุ
A3: 1 | B3: 1111002 | C3: ชิฟฟ่อนรวมรส 8 ชิ้น | D3: 100 | E3: 23 | H3: 2 | I3: 21 | J3: 200
A4: 2 | B4: 1004055 | C4: ชิฟฟ่อนรวมรส 4 ชิ้น | D4: 50 | E4: 32 | H4: 6 | I4: 26 | J4: 300
A5: 3 | B5: 1111056 | C5: ชิฟฟ่อนยอดฮิต | D5: 100 | E5: 12 | H5: 3 | I5: 9 | J5: 300
A6: 4 | B6: 1111009 | C6: ชิฟฟ่อนสอดไส้รวมรส 6 ชิ้น | D6: 100 | E6: 11 | H6: 2 | I6: 9 | J6: 200
A7: 5 | B7: 1112013 | C7: เบาหวิวเผือกมะพร้าว 110 กรัม | D7: 50 | E7: 3 | I7: 3
A8: 6 | B8: 1112009 | C8: เบาหวิวมะพร้าวน้ำหอม 110 กรัม | D8: 50 | E8: 4 | I8: 4
A9: 7 | B9: 1112017 | C9: เบาหวิวตาลหอม 110 กรัม | D9: 50 | E9: 1 | H9: 1 | J9: 50
A10: 8 | B10: 1112019 | C10: เบาหวิวทุเรียน 110 กรัม | D10: 50 | E10: 4 | I10: 4
A11: 9 | B11: 1112005 | C11: เบาหวิวเนยสด 110 กรัม | D11: 50 | E11: 4 | H11: 1 | I11: 3 | J11: 50
A12: 10 | B12: 1100003 | C12: เมอแรงค์กระปุก | D12: 60 | E12: 19 | I12: 19
A13: 11 | B13: 1200002 | C13: ท๊อฟฟี่กล่อง | D13: 55 | E13: 7 | H13: 3 | I13: 4 | J13: 165
A14: 12 | B14: 1200003 | C14: ท๊อฟฟี่กระเช้า | D14: 100 | E14: 9 | I14: 9
A15: 13 | B15: 1112011 | C15: เบาหวิวฝอยทอง 110 กรัม | D15: 50 | E15: 3 | H15: 1 | I15: 2 | J15: 50
J16: =SUM(J3:J15) -> 1315
I18: โอน | J18: 200 | K18: =SUM(J18:J18) -> 200
I19: สด | J19: 1100 | K19: =SUM(J19:J19) -> 1100
K20: =SUM(K18:K19) -> 1300
K22: หักค่าธรรมเนียม 15 บาท

Sheet 2
A1: ใบสต๊อกบูธ 11037 บูธวัดเขาทำเทียม
A2: ลำดับ | B2: รหัส | C2: รายการสินค้า | D2: ราคา | E2: ยอดยกมา | F2: รับเข้า | G2: ส่งคืน | H2: ขายออก | I2: คงเหลือ | J2: ยอดเงิน | K2: หมายเหตุ
A3: 1 | B3: 1111002 | C3: ชิฟฟ่อนรวมรส 8 ชิ้น | D3: 100 | E3: 21 | H3: 3 | I3: 18 | J3: 300
A4: 2 | B4: 1004055 | C4: ชิฟฟ่อนรวมรส 4 ชิ้น | D4: 50 | E4: 26 | H4: 1 | I4: 25 | K4: แถมให้ลูกค้าซื้อครบ 500
A5: 3 | B5: 1111056 | C5: ชิฟฟ่อนยอดฮิต | D5: 100 | E5: 9 | H5: 2 | I5: 7 | J5: 200
A6: 4 | B6: 1111009 | C6: ชิฟฟ่อนสอดไส้รวมรส 6 ชิ้น | D6: 100 | E6: 9 | H6: 2 | I6: 7 | J6: 200
A7: 5 | B7: 1112013 | C7: เบาหวิวเผือกมะพร้าว 110 กรัม | D7: 50 | E7: 3 | H7: 1 | I7: 2 | J7: 50
A8: 6 | B8: 1112009 | C8: เบาหวิวมะพร้าวน้ำหอม 110 กรัม | D8: 50 | E8: 4 | I8: 4
A9: 7 | B9: 1112017 | C9: เบาหวิวตาลหอม 110 กรัม | D9: 50
A10: 8 | B10: 1112019 | C10: เบาหวิวทุเรียน 110 กรัม | D10: 50 | E10: 4 | I10: 4
A11: 9 | B11: 1112005 | C11: เบาหวิวเนยสด 110 กรัม | D11: 50 | E11: 3 | H11: 1 | I11: 2 | J11: 50
A12: 10 | B12: 1100003 | C12: เมอแรงค์กระปุก | D12: 60 | E12: 19 | I12: 19
A13: 11 | B13: 1200002 | C13: ท๊อฟฟี่กล่อง | D13: 55 | E13: 4 | H13: 1 | I13: 3 | J13: 55
A14: 12 | B14: 1200003 | C14: ท๊อฟฟี่กระเช้า | D14: 100 | E14: 9 | H14: 1 | I14: 8 | J14: 100
A15: 13 | B15: 1112011 | C15: เบาหวิวฝอยทอง 110 กรัม | D15: 50 | E15: 2 | I15: 2
J16: =SUM(J3:J15) -> 955
I18: โอน | J18: 100 | K18: =SUM(J18:J18) -> 100
I19: สด | J19: 855 | K19: =SUM(J19:J19) -> 855
K20: =SUM(K18:K19) -> 955

Sheet 3
A1: ใบสต๊อกบูธ 11037 บูธวัดเขาทำเทียม
A2: ลำดับ | B2: รหัส | C2: รายการสินค้า | D2: ราคา | E2: ยอดยกมา | F2: รับเข้า | G2: ส่งคืน | H2: ขายออก | I2: คงเหลือ | J2: ยอดเงิน | K2: หมายเหตุ
A3: 1 | B3: 1111002 | C3: ชิฟฟ่อนรวมรส 8 ชิ้น | D3: 100 | E3: 18 | I3: 18
A4: 2 | B4: 1004055 | C4: ชิฟฟ่อนรวมรส 4 ชิ้น | D4: 50 | E4: 25 | I4: 25
A5: 3 | B5: 1111056 | C5: ชิฟฟ่อนยอดฮิต | D5: 100 | E5: 7 | I5: 7
A6: 4 | B6: 1111009 | C6: ชิฟฟ่อนสอดไส้รวมรส 6 ชิ้น | D6: 100 | E6: 7 | I6: 7
A7: 5 | B7: 1112013 | C7: เบาหวิวเผือกมะพร้าว 110 กรัม | D7: 50 | E7: 2 | I7: 2
A8: 6 | B8: 1112009 | C8: เบาหวิวมะพร้าวน้ำหอม 110 กรัม | D8: 50 | E8: 4 | I8: 4 | L8: ขายไม่ได้
A9: 7 | B9: 1112017 | C9: เบาหวิวตาลหอม 110 กรัม | D9: 50
A10: 8 | B10: 1112019 | C10: เบาหวิวทุเรียน 110 กรัม | D10: 50 | E10: 4 | I10: 4
A11: 9 | B11: 1112005 | C11: เบาหวิวเนยสด 110 กรัม | D11: 50 | E11: 2 | I11: 2
A12: 10 | B12: 1100003 | C12: เมอแรงค์กระปุก | D12: 60 | E12: 19 | I12: 19
A13: 11 | B13: 1200002 | C13: ท๊อฟฟี่กล่อง | D13: 55 | E13: 3 | I13: 3
A14: 12 | B14: 1200003 | C14: ท๊อฟฟี่กระเช้า | D14: 100 | E14: 8 | I14: 8
A15: 13 | B15: 1112011 | C15: เบาหวิวฝอยทอง 110 กรัม | D15: 50 | E15: 2 | I15: 2
J16: =SUM(J3:J15) -> 0
I18: โอน | K18: =SUM(J18:J18) -> 0
I19: สด | K19: =SUM(J19:J19) -> 0
K20: =SUM(K18:K19) -> 0

Sheet 4
A1: ใบสต๊อกบูธ 11037 บูธวัดเขาทำเทียม
A2: ลำดับ | B2: รหัส | C2: รายการสินค้า | D2: ราคา | E2: ยอดยกมา | F2: รับเข้า | G2: ส่งคืน | H2: ขายออก | I2: คงเหลือ | J2: ยอดเงิน | K2: หมายเหตุ
A3: 1 | B3: 1111002 | C3: ชิฟฟ่อนรวมรส 8 ชิ้น | D3: 100 | E3: 18 | I3: 18
A4: 2 | B4: 1004055 | C4: ชิฟฟ่อนรวมรส 4 ชิ้น | D4: 50 | E4: 25 | I4: 25
A5: 3 | B5: 1111056 | C5: ชิฟฟ่อนยอดฮิต | D5: 100 | E5: 7 | I5: 7
A6: 4 | B6: 1111009 | C6: ชิฟฟ่อนสอดไส้รวมรส 6 ชิ้น | D6: 100 | E6: 7 | I6: 7
A7: 5 | B7: 1112013 | C7: เบาหวิวเผือกมะพร้าว 110 กรัม | D7: 50 | E7: 2 | I7: 2
A8: 6 | B8: 1112009 | C8: เบาหวิวมะพร้าวน้ำหอม 110 กรัม | D8: 50 | E8: 4 | I8: 4 | L8: ขายไม่ได้
A9: 7 | B9: 1112017 | C9: เบาหวิวตาลหอม 110 กรัม | D9: 50
A10: 8 | B10: 1112019 | C10: เบาหวิวทุเรียน 110 กรัม | D10: 50 | E10: 4 | I10: 4
A11: 9 | B11: 1112005 | C11: เบาหวิวเนยสด 110 กรัม | D11: 50 | E11: 2 | I11: 2
A12: 10 | B12: 1100003 | C12: เมอแรงค์กระปุก | D12: 60 | E12: 19 | I12: 19
A13: 11 | B13: 1200002 | C13: ท๊อฟฟี่กล่อง | D13: 55 | E13: 3 | I13: 3
A14: 12 | B14: 1200003 | C14: ท๊อฟฟี่กระเช้า | D14: 100 | E14: 8 | I14: 8
A15: 13 | B15: 1112011 | C15: เบาหวิวฝอยทอง 110 กรัม | D15: 50 | E15: 2 | I15: 2
J16: =SUM(J3:J15) -> 0
I18: โอน | K18: =SUM(J18:J18) -> 0
I19: สด | K19: =SUM(J19:J19) -> 0
K20: =SUM(K18:K19) -> 0

Sheet 5
A1: ใบสต๊อกบูธ 11037 บูธวัดเขาทำเทียม
A2: ลำดับ | B2: รหัส | C2: รายการสินค้า | D2: ราคา | E2: ยอดยกมา | F2: รับเข้า | G2: ส่งคืน | H2: ขายออก | I2: คงเหลือ | J2: ยอดเงิน | K2: หมายเหตุ
A3: 1 | B3: 1111002 | C3: ชิฟฟ่อนรวมรส 8 ชิ้น | D3: 100 | E3: 18 | I3: 18
A4: 2 | B4: 1004055 | C4: ชิฟฟ่อนรวมรส 4 ชิ้น | D4: 50 | E4: 25 | I4: 25
A5: 3 | B5: 1111056 | C5: ชิฟฟ่อนยอดฮิต | D5: 100 | E5: 7 | H5: 7 | J5: 350 | K5: ลด50%7กล่อง
A6: 4 | B6: 1111009 | C6: ชิฟฟ่อนสอดไส้รวมรส 6 ชิ้น | D6: 100 | E6: 7 | I6: 7
A7: 5 | B7: 1112013 | C7: เบาหวิวเผือกมะพร้าว 110 กรัม | D7: 50 | E7: 2 | I7: 2
A8: 6 | B8: 1112009 | C8: เบาหวิวมะพร้าวน้ำหอม 110 กรัม | D8: 50 | E8: 4 | I8: 4
A9: 7 | B9: 1112017 | C9: เบาหวิวตาลหอม 110 กรัม | D9: 50
A10: 8 | B10: 1112019 | C10: เบาหวิวทุเรียน 110 กรัม | D10: 50 | E10: 4 | I10: 4
A11: 9 | B11: 1112005 | C11: เบาหวิวเนยสด 110 กรัม | D11: 50 | E11: 2 | I11: 2
A12: 10 | B12: 1100003 | C12: เมอแรงค์กระปุก | D12: 60 | E12: 19 | I12: 19
A13: 11 | B13: 1200002 | C13: ท๊อฟฟี่กล่อง | D13: 55 | E13: 3 | I13: 3
A14: 12 | B14: 1200003 | C14: ท๊อฟฟี่กระเช้า | D14: 100 | E14: 8 | I14: 8
A15: 13 | B15: 1112011 | C15: เบาหวิวฝอยทอง 110 กรัม | D15: 50 | E15: 2 | I15: 2
J16: =SUM(J3:J15) -> 350
I18: โอน | K18: =SUM(J18:J18) -> 0
I19: สด | J19: 350 | K19: =SUM(J19:J19) -> 350
K20: =SUM(K18:K19) -> 350

Sheet 6
A1: ใบสต๊อกบูธ 11037 บูธวัดเขาทำเทียม
A2: ลำดับ | B2: รหัส | C2: รายการสินค้า | D2: ราคา | E2: ยอดยกมา | F2: รับเข้า | G2: ส่งคืน | H2: ขายออก | I2: คงเหลือ | J2: ยอดเงิน | K2: หมายเหตุ
A3: 1 | B3: 1111002 | C3: ชิฟฟ่อนรวมรส 8 ชิ้น | D3: 100 | E3: 18 | I3: 18
A4: 2 | B4: 1004055 | C4: ชิฟฟ่อนรวมรส 4 ชิ้น | D4: 50 | E4: 25 | H4: 1 | I4: 24 | J4: 50
A5: 3 | B5: 1111056 | C5: ชิฟฟ่อนยอดฮิต | D5: 100
A6: 4 | B6: 1111009 | C6: ชิฟฟ่อนสอดไส้รวมรส 6 ชิ้น | D6: 100 | E6: 7 | I6: 7
A7: 5 | B7: 1112013 | C7: เบาหวิวเผือกมะพร้าว 110 กรัม | D7: 50 | E7: 2 | I7: 2
A8: 6 | B8: 1112009 | C8: เบาหวิวมะพร้าวน้ำหอม 110 กรัม | D8: 50 | E8: 4 | I8: 4
A9: 7 | B9: 1112017 | C9: เบาหวิวตาลหอม 110 กรัม | D9: 50
A10: 8 | B10: 1112019 | C10: เบาหวิวทุเรียน 110 กรัม | D10: 50 | E10: 4 | I10: 4
A11: 9 | B11: 1112005 | C11: เบาหวิวเนยสด 110 กรัม | D11: 50 | E11: 2 | I11: 2
A12: 10 | B12: 1100003 | C12: เมอแรงค์กระปุก | D12: 60 | E12: 19 | I12: 19
A13: 11 | B13: 1200002 | C13: ท๊อฟฟี่กล่อง | D13: 55 | E13: 3 | H13: 1 | I13: 2 | J13: 55
A14: 12 | B14: 1200003 | C14: ท๊อฟฟี่กระเช้า | D14: 100 | E14: 8 | H14: 1 | I14: 7 | J14: 100
A15: 13 | B15: 1112011 | C15: เบาหวิวฝอยทอง 110 กรัม | D15: 50 | E15: 2 | I15: 2
J16: =SUM(J3:J15) -> 205
I18: โอน | K18: =SUM(J18:J18) -> 0
I19: สด | J19: 205 | K19: =SUM(J19:J19) -> 205
K20: =SUM(K18:K19) -> 205

Sheet 7
A1: ใบสต๊อกบูธ 11037 บูธวัดเขาทำเทียม
A2: ลำดับ | B2: รหัส | C2: รายการสินค้า | D2: ราคา | E2: ยอดยกมา | F2: รับเข้า | G2: ส่งคืน | H2: ขายออก | I2: คงเหลือ | J2: ยอดเงิน | K2: หมายเหตุ
A3: 1 | B3: 1111002 | C3: ชิฟฟ่อนรวมรส 8 ชิ้น | D3: 100 | E3: 18 | I3: 18
A4: 2 | B4: 1004055 | C4: ชิฟฟ่อนรวมรส 4 ชิ้น | D4: 50 | E4: 24 | I4: 24
A5: 3 | B5: 1111056 | C5: ชิฟฟ่อนยอดฮิต | D5: 100
A6: 4 | B6: 1111009 | C6: ชิฟฟ่อนสอดไส้รวมรส 6 ชิ้น | D6: 100 | E6: 7 | I6: 7
A7: 5 | B7: 1112013 | C7: เบาหวิวเผือกมะพร้าว 110 กรัม | D7: 50 | E7: 2 | I7: 2
A8: 6 | B8: 1112009 | C8: เบาหวิวมะพร้าวน้ำหอม 110 กรัม | D8: 50 | E8: 4 | I8: 4
A9: 7 | B9: 1112017 | C9: เบาหวิวตาลหอม 110 กรัม | D9: 50
A10: 8 | B10: 1112019 | C10: เบาหวิวทุเรียน 110 กรัม | D10: 50 | E10: 4 | I10: 4
A11: 9 | B11: 1112005 | C11: เบาหวิวเนยสด 110 กรัม | D11: 50 | E11: 2 | I11: 2
A12: 10 | B12: 1100003 | C12: เมอแรงค์กระปุก | D12: 60 | E12: 19 | I12: 19
A13: 11 | B13: 1200002 | C13: ท๊อฟฟี่กล่อง | D13: 55 | E13: 2 | I13: 2
A14: 12 | B14: 1200003 | C14: ท๊อฟฟี่กระเช้า | D14: 100 | E14: 7 | I14: 7
A15: 13 | B15: 1112011 | C15: เบาหวิวฝอยทอง 110 กรัม | D15: 50 | E15: 2 | I15: 2
J16: =SUM(J3:J15) -> 0
I18: โอน | K18: =SUM(J18:J18) -> 0
I19: สด | K19: =SUM(J19:J19) -> 0
K20: =SUM(K18:K19) -> 0

Sheet 9
A1: ใบสต๊อกบูธ 11037 บูธวัดเขาทำเทียม
A2: ลำดับ | B2: รหัส | C2: รายการสินค้า | D2: ราคา | E2: ยอดยกมา | F2: รับเข้า | G2: ส่งคืน | H2: ขายออก | I2: คงเหลือ | J2: ยอดเงิน | K2: หมายเหตุ
A3: 1 | B3: 1111002 | C3: ชิฟฟ่อนรวมรส 8 ชิ้น | D3: 100 | E3: 18 | I3: 18
A4: 2 | B4: 1004055 | C4: ชิฟฟ่อนรวมรส 4 ชิ้น | D4: 50 | E4: 24 | I4: 24
A5: 3 | B5: 1111056 | C5: ชิฟฟ่อนยอดฮิต | D5: 100
A6: 4 | B6: 1111009 | C6: ชิฟฟ่อนสอดไส้รวมรส 6 ชิ้น | D6: 100 | E6: 7 | I6: 7
A7: 5 | B7: 1112013 | C7: เบาหวิวเผือกมะพร้าว 110 กรัม | D7: 50 | E7: 2 | I7: 2
A8: 6 | B8: 1112009 | C8: เบาหวิวมะพร้าวน้ำหอม 110 กรัม | D8: 50 | E8: 4 | I8: 4
A9: 7 | B9: 1112017 | C9: เบาหวิวตาลหอม 110 กรัม | D9: 50
A10: 8 | B10: 1112019 | C10: เบาหวิวทุเรียน 110 กรัม | D10: 50 | E10: 4 | I10: 4
A11: 9 | B11: 1112005 | C11: เบาหวิวเนยสด 110 กรัม | D11: 50 | E11: 2 | I11: 2
A12: 10 | B12: 1100003 | C12: เมอแรงค์กระปุก | D12: 60 | E12: 19 | I12: 19
A13: 11 | B13: 1200002 | C13: ท๊อฟฟี่กล่อง | D13: 55 | E13: 2 | I13: 2
A14: 12 | B14: 1200003 | C14: ท๊อฟฟี่กระเช้า | D14: 100 | E14: 7 | I14: 7
A15: 13 | B15: 1112011 | C15: เบาหวิวฝอยทอง 110 กรัม | D15: 50 | E15: 2 | I15: 2
J16: =SUM(J3:J15) -> 0
I18: โอน | K18: =SUM(J18:J18) -> 0
I19: สด | K19: =SUM(J19:J19) -> 0
K20: =SUM(K18:K19) -> 0

Sheet 10
A1: ใบสต๊อกบูธ 11037 บูธวัดเขาทำเทียม
A2: ลำดับ | B2: รหัส | C2: รายการสินค้า | D2: ราคา | E2: ยอดยกมา | F2: รับเข้า | G2: ส่งคืน | H2: ขายออก | I2: คงเหลือ | J2: ยอดเงิน | K2: หมายเหตุ
A3: 1 | B3: 1111002 | C3: ชิฟฟ่อนรวมรส 8 ชิ้น | D3: 100 | E3: 18 | I3: 18
A4: 2 | B4: 1004055 | C4: ชิฟฟ่อนรวมรส 4 ชิ้น | D4: 50 | E4: 24 | I4: 24
A5: 3 | B5: 1111056 | C5: ชิฟฟ่อนยอดฮิต | D5: 100
A6: 4 | B6: 1111009 | C6: ชิฟฟ่อนสอดไส้รวมรส 6 ชิ้น | D6: 100 | E6: 7 | H6: 7 | J6: 350 | K6: ลด50%7กล่อง
A7: 5 | B7: 1112013 | C7: เบาหวิวเผือกมะพร้าว 110 กรัม | D7: 50 | E7: 2 | I7: 2
A8: 6 | B8: 1112009 | C8: เบาหวิวมะพร้าวน้ำหอม 110 กรัม | D8: 50 | E8: 4 | I8: 4
A9: 7 | B9: 1112017 | C9: เบาหวิวตาลหอม 110 กรัม | D9: 50
A10: 8 | B10: 1112019 | C10: เบาหวิวทุเรียน 110 กรัม | D10: 50 | E10: 4 | I10: 4
A11: 9 | B11: 1112005 | C11: เบาหวิวเนยสด 110 กรัม | D11: 50 | E11: 2 | I11: 2
A12: 10 | B12: 1100003 | C12: เมอแรงค์กระปุก | D12: 60 | E12: 19 | I12: 19
A13: 11 | B13: 1200002 | C13: ท๊อฟฟี่กล่อง | D13: 55 | E13: 2 | H13: 1 | I13: 1 | J13: 55
A14: 12 | B14: 1200003 | C14: ท๊อฟฟี่กระเช้า | D14: 100 | E14: 7 | I14: 7
A15: 13 | B15: 1112011 | C15: เบาหวิวฝอยทอง 110 กรัม | D15: 50 | E15: 2 | I15: 2
J16: =SUM(J3:J15) -> 405
I18: โอน | K18: =SUM(J18:J18) -> 0
I19: สด | J19: 405 | K19: =SUM(J19:J19) -> 405
K20: =SUM(K18:K19) -> 405

Sheet 12
A1: ใบสต๊อกบูธ 11037 บูธวัดเขาทำเทียม
A2: ลำดับ | B2: รหัส | C2: รายการสินค้า | D2: ราคา | E2: ยอดยกมา | F2: รับเข้า | G2: ส่งคืน | H2: ขายออก | I2: คงเหลือ | J2: ยอดเงิน | K2: หมายเหตุ
A3: 1 | B3: 1111002 | C3: ชิฟฟ่อนรวมรส 8 ชิ้น | D3: 100 | E3: 18 | I3: 18
A4: 2 | B4: 1004055 | C4: ชิฟฟ่อนรวมรส 4 ชิ้น | D4: 50 | E4: 24 | I4: 24
A5: 3 | B5: 1111056 | C5: ชิฟฟ่อนยอดฮิต | D5: 100
A6: 4 | B6: 1111009 | C6: ชิฟฟ่อนสอดไส้รวมรส 6 ชิ้น | D6: 100
A7: 5 | B7: 1112013 | C7: เบาหวิวเผือกมะพร้าว 110 กรัม | D7: 50 | E7: 2 | I7: 2
A8: 6 | B8: 1112009 | C8: เบาหวิวมะพร้าวน้ำหอม 110 กรัม | D8: 50 | E8: 4 | I8: 4
A9: 7 | B9: 1112017 | C9: เบาหวิวตาลหอม 110 กรัม | D9: 50
A10: 8 | B10: 1112019 | C10: เบาหวิวทุเรียน 110 กรัม | D10: 50 | E10: 4 | I10: 4
A11: 9 | B11: 1112005 | C11: เบาหวิวเนยสด 110 กรัม | D11: 50 | E11: 2 | I11: 2
A12: 10 | B12: 1100003 | C12: เมอแรงค์กระปุก | D12: 60 | E12: 19 | I12: 19
A13: 11 | B13: 1200002 | C13: ท๊อฟฟี่กล่อง | D13: 55 | E13: 1 | I13: 1
A14: 12 | B14: 1200003 | C14: ท๊อฟฟี่กระเช้า | D14: 100 | E14: 7 | I14: 7
A15: 13 | B15: 1112011 | C15: เบาหวิวฝอยทอง 110 กรัม | D15: 50 | E15: 2 | I15: 2
J16: =SUM(J3:J15) -> 0
I18: โอน | K18: =SUM(J18:J18) -> 0
I19: สด | K19: =SUM(J19:J19) -> 0
K20: =SUM(K18:K19) -> 0

Sheet 13
A1: ใบสต๊อกบูธ 11037 บูธวัดเขาทำเทียม
A2: ลำดับ | B2: รหัส | C2: รายการสินค้า | D2: ราคา | E2: ยอดยกมา | F2: รับเข้า | G2: ส่งคืน | H2: ขายออก | I2: คงเหลือ | J2: ยอดเงิน | K2: หมายเหตุ
A3: 1 | B3: 1111002 | C3: ชิฟฟ่อนรวมรส 8 ชิ้น | D3: 100 | E3: 18 | H3: 1 | I3: 17 | J3: 100
A4: 2 | B4: 1004055 | C4: ชิฟฟ่อนรวมรส 4 ชิ้น | D4: 50 | E4: 24 | H4: 5 | I4: 19 | J4: 250
A5: 3 | B5: 1111056 | C5: ชิฟฟ่อนยอดฮิต | D5: 100
A6: 4 | B6: 1111009 | C6: ชิฟฟ่อนสอดไส้รวมรส 6 ชิ้น | D6: 100
A7: 5 | B7: 1112013 | C7: เบาหวิวเผือกมะพร้าว 110 กรัม | D7: 50 | E7: 2 | I7: 2
A8: 6 | B8: 1112009 | C8: เบาหวิวมะพร้าวน้ำหอม 110 กรัม | D8: 50 | E8: 4 | H8: 1 | I8: 3 | J8: 50
A9: 7 | B9: 1112017 | C9: เบาหวิวตาลหอม 110 กรัม | D9: 50
A10: 8 | B10: 1112019 | C10: เบาหวิวทุเรียน 110 กรัม | D10: 50 | E10: 4 | I10: 4
A11: 9 | B11: 1112005 | C11: เบาหวิวเนยสด 110 กรัม | D11: 50 | E11: 2 | I11: 2
A12: 10 | B12: 1100003 | C12: เมอแรงค์กระปุก | D12: 60 | E12: 19 | I12: 19
A13: 11 | B13: 1200002 | C13: ท๊อฟฟี่กล่อง | D13: 55 | E13: 1 | H13: 1 | J13: 55
A14: 12 | B14: 1200003 | C14: ท๊อฟฟี่กระเช้า | D14: 100 | E14: 7 | H14: 1 | I14: 6 | J14: 100
A15: 13 | B15: 1112011 | C15: เบาหวิวฝอยทอง 110 กรัม | D15: 50 | E15: 2 | H15: 2 | J15: 100
J16: =SUM(J3:J15) -> 655
I18: โอน | J18: 150 | K18: =SUM(J18:J18) -> 150
I19: สด | J19: 505 | K19: =SUM(J19:J19) -> 505
K20: =SUM(K18:K19) -> 655

Sheet 14
A1: ใบสต๊อกบูธ 11037 บูธวัดเขาทำเทียม
A2: ลำดับ | B2: รหัส | C2: รายการสินค้า | D2: ราคา | E2: ยอดยกมา | F2: รับเข้า | G2: ส่งคืน | H2: ขายออก | I2: คงเหลือ | J2: ยอดเงิน | K2: หมายเหตุ
A3: 1 | B3: 1111002 | C3: ชิฟฟ่อนรวมรส 8 ชิ้น | D3: 100 | E3: 17 | I3: 17
A4: 2 | B4: 1004055 | C4: ชิฟฟ่อนรวมรส 4 ชิ้น | D4: 50 | E4: 19 | H4: 10 | I4: 9 | J4: 280 | K4: ลด50%8 ลด20%2
A5: 3 | B5: 1111056 | C5: ชิฟฟ่อนยอดฮิต | D5: 100
A6: 4 | B6: 1111009 | C6: ชิฟฟ่อนสอดไส้รวมรส 6 ชิ้น | D6: 100
A7: 5 | B7: 1112013 | C7: เบาหวิวเผือกมะพร้าว 110 กรัม | D7: 50 | E7: 2 | I7: 2
A8: 6 | B8: 1112009 | C8: เบาหวิวมะพร้าวน้ำหอม 110 กรัม | D8: 50 | E8: 3 | H8: 1 | I8: 2 | J8: 40 | K8: ลด20%
A9: 7 | B9: 1112017 | C9: เบาหวิวตาลหอม 110 กรัม | D9: 50
A10: 8 | B10: 1112019 | C10: เบาหวิวทุเรียน 110 กรัม | D10: 50 | E10: 4 | I10: 4
A11: 9 | B11: 1112005 | C11: เบาหวิวเนยสด 110 กรัม | D11: 50 | E11: 2 | I11: 2
A12: 10 | B12: 1100003 | C12: เมอแรงค์กระปุก | D12: 60 | E12: 19 | H12: 1 | I12: 18 | J12: 60
A13: 11 | B13: 1200002 | C13: ท๊อฟฟี่กล่อง | D13: 55
A14: 12 | B14: 1200003 | C14: ท๊อฟฟี่กระเช้า | D14: 100 | E14: 6 | I14: 6
A15: 13 | B15: 1112011 | C15: เบาหวิวฝอยทอง 110 กรัม | D15: 50
J16: =SUM(J3:J15) -> 380
I18: โอน | K18: =SUM(J18:J18) -> 0
I19: สด | J19: 380 | K19: =SUM(J19:J19) -> 380
K20: =SUM(K18:K19) -> 380

Sheet 16
A1: ใบสต๊อกบูธ 11037 บูธวัดเขาทำเทียม
A2: ลำดับ | B2: รหัส | C2: รายการสินค้า | D2: ราคา | E2: ยอดยกมา | F2: รับเข้า | G2: ส่งคืน | H2: ขายออก | I2: คงเหลือ | J2: ยอดเงิน | K2: หมายเหตุ
A3: 1 | B3: 1111002 | C3: ชิฟฟ่อนรวมรส 8 ชิ้น | D3: 100 | E3: 17 | F3: 20 | H3: 17 | I3: 20 | J3: 850 | K3: ลด50%
A4: 2 | B4: 1004055 | C4: ชิฟฟ่อนรวมรส 4 ชิ้น | D4: 50 | E4: 9 | F4: 20 | I4: 29
A5: 3 | B5: 1111056 | C5: ชิฟฟ่อนยอดฮิต | D5: 100
A6: 4 | B6: 1111009 | C6: ชิฟฟ่อนสอดไส้รวมรส 6 ชิ้น | D6: 100 | F6: 10 | I6: 10
A7: 5 | B7: 1112013 | C7: เบาหวิวเผือกมะพร้าว 110 กรัม | D7: 50 | E7: 2 | H7: 2 | J7: 50 | K7: ลด50%
A8: 6 | B8: 1112009 | C8: เบาหวิวมะพร้าวน้ำหอม 110 กรัม | D8: 50 | E8: 2 | H8: 1 | I8: 1 | J8: 25 | K8: ลด50%
A9: 7 | B9: 1112017 | C9: เบาหวิวตาลหอม 110 กรัม | D9: 50 | F9: 3 | I9: 3
A10: 8 | B10: 1112019 | C10: เบาหวิวทุเรียน 110 กรัม | D10: 50 | E10: 4 | H10: 2 | I10: 2 | J10: 50 | K10: ลด50%
A11: 9 | B11: 1112005 | C11: เบาหวิวเนยสด 110 กรัม | D11: 50 | E11: 2 | F11: 5 | H11: 2 | I11: 5 | J11: 50 | K11: ลด50%
A12: 10 | B12: 1100003 | C12: เมอแรงค์กระปุก | D12: 60 | E12: 18 | I12: 18
A13: 11 | B13: 1200002 | C13: ท๊อฟฟี่กล่อง | D13: 55 | F13: 6 | I13: 6
A14: 12 | B14: 1200003 | C14: ท๊อฟฟี่กระเช้า | D14: 100 | E14: 6 | I14: 6
A15: 13 | B15: 1112011 | C15: เบาหวิวฝอยทอง 110 กรัม | D15: 50 | F15: 3 | I15: 3
A16: 14 | B16: 1112003 | C16: เบาหวิวกาแฟ 110 กรัม | D16: 50 | F16: 3 | I16: 3
A17: 15 | B17: 1100002 | C17: พายสัปปะรด กล่อง | D17: 50 | F17: 5 | I17: 5
A18: 16 | B18: 1113121 | C18: ขนมเปี๊ยะถั่ว 350 กรัม | D18: 120 | F18: 3 | I18: 3
A19: 17 | B19: 1113122 | C19: ขนมเปี๊ยะฟัก 350 กรัม | D19: 120 | F19: 3 | I19: 3
A20: 18 | B20: 1004080 | C20: ครีมฮอร์น วนิลา | D20: 50 | F20: 3 | H20: 3 | J20: 150
A21: 19 | B21: 1004081 | C21: ครีมฮอร์น ใบเตย | D21: 50 | F21: 1 | H21: 1 | J21: 50
A22: 20 | B22: 3001200 | C22: ครีมฮอร์น ช๊อกโกแลต | D22: 50 | F22: 3 | H22: 3 | J22: 150
J23: =SUM(J3:J22) -> 1375
I25: โอน | K25: =SUM(J25:J25) -> 0
I26: สด | J26: 1360 | K26: =SUM(J26:J26) -> 1360
K27: =SUM(K25:K26) -> 1360
K29: หักค่าธรรมเนียม 15 บาท

Sheet 17
A1: ใบสต๊อกบูธ 11037 บูธวัดเขาทำเทียม
A2: ลำดับ | B2: รหัส | C2: รายการสินค้า | D2: ราคา | E2: ยอดยกมา | F2: รับเข้า | G2: ส่งคืน | H2: ขายออก | I2: คงเหลือ | J2: ยอดเงิน | K2: หมายเหตุ
A3: 1 | B3: 1111002 | C3: ชิฟฟ่อนรวมรส 8 ชิ้น | D3: 100 | E3: 20 | I3: 20
A4: 2 | B4: 1004055 | C4: ชิฟฟ่อนรวมรส 4 ชิ้น | D4: 50 | E4: 29 | H4: 4 | I4: 25 | J4: 100 | K4: ลด50%
A5: 3 | B5: 1111056 | C5: ชิฟฟ่อนยอดฮิต | D5: 100
A6: 4 | B6: 1111009 | C6: ชิฟฟ่อนสอดไส้รวมรส 6 ชิ้น | D6: 100 | E6: 10 | I6: 10
A7: 5 | B7: 1112013 | C7: เบาหวิวเผือกมะพร้าว 110 กรัม | D7: 50
A8: 6 | B8: 1112009 | C8: เบาหวิวมะพร้าวน้ำหอม 110 กรัม | D8: 50 | E8: 1 | I8: 1
A9: 7 | B9: 1112017 | C9: เบาหวิวตาลหอม 110 กรัม | D9: 50 | E9: 3 | I9: 3
A10: 8 | B10: 1112019 | C10: เบาหวิวทุเรียน 110 กรัม | D10: 50 | E10: 2 | I10: 2
A11: 9 | B11: 1112005 | C11: เบาหวิวเนยสด 110 กรัม | D11: 50 | E11: 5 | I11: 5
A12: 10 | B12: 1100003 | C12: เมอแรงค์กระปุก | D12: 60 | E12: 18 | I12: 18
A13: 11 | B13: 1200002 | C13: ท๊อฟฟี่กล่อง | D13: 55 | E13: 6 | I13: 6
A14: 12 | B14: 1200003 | C14: ท๊อฟฟี่กระเช้า | D14: 100 | E14: 6 | I14: 6
A15: 13 | B15: 1112011 | C15: เบาหวิวฝอยทอง 110 กรัม | D15: 50 | E15: 3 | I15: 3
A16: 14 | B16: 1112003 | C16: เบาหวิวกาแฟ 110 กรัม | D16: 50 | E16: 3 | H16: 1 | I16: 2 | J16: 50
A17: 15 | B17: 1100002 | C17: พายสัปปะรด กล่อง | D17: 50 | E17: 5 | H17: 1 | I17: 4 | J17: 50
A18: 16 | B18: 1113121 | C18: ขนมเปี๊ยะถั่ว 350 กรัม | D18: 120 | E18: 3 | I18: 3
A19: 17 | B19: 1113122 | C19: ขนมเปี๊ยะฟัก 350 กรัม | D19: 120 | E19: 3 | I19: 3
A20: 18 | B20: 1004080 | C20: ครีมฮอร์น วนิลา | D20: 50
A21: 19 | B21: 1004081 | C21: ครีมฮอร์น ใบเตย | D21: 50
A22: 20 | B22: 3001200 | C22: ครีมฮอร์น ช๊อกโกแลต | D22: 50
J23: =SUM(J3:J22) -> 200
I25: โอน | K25: =SUM(J25:J25) -> 0
I26: สด | J26: 200 | K26: =SUM(J26:J26) -> 200
K27: =SUM(K25:K26) -> 200

Sheet 19
A1: ใบสต๊อกบูธ 11037 บูธวัดเขาทำเทียม
A2: ลำดับ | B2: รหัส | C2: รายการสินค้า | D2: ราคา | E2: ยอดยกมา | F2: รับเข้า | G2: ส่งคืน | H2: ขายออก | I2: คงเหลือ | J2: ยอดเงิน | K2: หมายเหตุ
A3: 1 | B3: 1111002 | C3: ชิฟฟ่อนรวมรส 8 ชิ้น | D3: 100 | E3: 20 | I3: 20
A4: 2 | B4: 1004055 | C4: ชิฟฟ่อนรวมรส 4 ชิ้น | D4: 50 | E4: 25 | G4: 5 | I4: 20
A5: 3 | B5: 1111056 | C5: ชิฟฟ่อนยอดฮิต | D5: 100
A6: 4 | B6: 1111009 | C6: ชิฟฟ่อนสอดไส้รวมรส 6 ชิ้น | D6: 100 | E6: 10 | I6: 10
A7: 5 | B7: 1112013 | C7: เบาหวิวเผือกมะพร้าว 110 กรัม | D7: 50
A8: 6 | B8: 1112009 | C8: เบาหวิวมะพร้าวน้ำหอม 110 กรัม | D8: 50 | E8: 1 | G8: 1
A9: 7 | B9: 1112017 | C9: เบาหวิวตาลหอม 110 กรัม | D9: 50 | E9: 3 | I9: 3
A10: 8 | B10: 1112019 | C10: เบาหวิวทุเรียน 110 กรัม | D10: 50 | E10: 2 | G10: 2
A11: 9 | B11: 1112005 | C11: เบาหวิวเนยสด 110 กรัม | D11: 50 | E11: 5 | H11: 1 | I11: 4 | J11: 50
A12: 10 | B12: 1100003 | C12: เมอแรงค์กระปุก | D12: 60 | E12: 18 | I12: 18
A13: 11 | B13: 1200002 | C13: ท๊อฟฟี่กล่อง | D13: 55 | E13: 6 | I13: 6
A14: 12 | B14: 1200003 | C14: ท๊อฟฟี่กระเช้า | D14: 100 | E14: 6 | I14: 6
A15: 13 | B15: 1112011 | C15: เบาหวิวฝอยทอง 110 กรัม | D15: 50 | E15: 3 | H15: 1 | I15: 2 | J15: 50
A16: 14 | B16: 1112003 | C16: เบาหวิวกาแฟ 110 กรัม | D16: 50 | E16: 2 | I16: 2
A17: 15 | B17: 1100002 | C17: พายสัปปะรด กล่อง | D17: 50 | E17: 4 | I17: 4
A18: 16 | B18: 1113121 | C18: ขนมเปี๊ยะถั่ว 350 กรัม | D18: 120 | E18: 3 | I18: 3
A19: 17 | B19: 1113122 | C19: ขนมเปี๊ยะฟัก 350 กรัม | D19: 120 | E19: 3 | I19: 3
A20: 18 | B20: 1004080 | C20: ครีมฮอร์น วนิลา | D20: 50
A21: 19 | B21: 1004081 | C21: ครีมฮอร์น ใบเตย | D21: 50
A22: 20 | B22: 3001200 | C22: ครีมฮอร์น ช๊อกโกแลต | D22: 50
J23: =SUM(J3:J22) -> 100
I25: โอน | K25: =SUM(J25:J25) -> 0
I26: สด | J26: 100 | K26: =SUM(J26:J26) -> 100
K27: =SUM(K25:K26) -> 100

Sheet 20
A1: ใบสต๊อกบูธ 11037 บูธวัดเขาทำเทียม
A2: ลำดับ | B2: รหัส | C2: รายการสินค้า | D2: ราคา | E2: ยอดยกมา | F2: รับเข้า | G2: ส่งคืน | H2: ขายออก | I2: คงเหลือ | J2: ยอดเงิน | K2: หมายเหตุ
A3: 1 | B3: 1111002 | C3: ชิฟฟ่อนรวมรส 8 ชิ้น | D3: 100 | E3: 20 | H3: 1 | I3: 19 | J3: 100
A4: 2 | B4: 1004055 | C4: ชิฟฟ่อนรวมรส 4 ชิ้น | D4: 50 | E4: 20 | I4: 20
A5: 3 | B5: 1111056 | C5: ชิฟฟ่อนยอดฮิต | D5: 100
A6: 4 | B6: 1111009 | C6: ชิฟฟ่อนสอดไส้รวมรส 6 ชิ้น | D6: 100 | E6: 10 | I6: 10
A7: 5 | B7: 1112013 | C7: เบาหวิวเผือกมะพร้าว 110 กรัม | D7: 50
A8: 6 | B8: 1112009 | C8: เบาหวิวมะพร้าวน้ำหอม 110 กรัม | D8: 50
A9: 7 | B9: 1112017 | C9: เบาหวิวตาลหอม 110 กรัม | D9: 50 | E9: 3 | I9: 3
A10: 8 | B10: 1112019 | C10: เบาหวิวทุเรียน 110 กรัม | D10: 50
A11: 9 | B11: 1112005 | C11: เบาหวิวเนยสด 110 กรัม | D11: 50 | E11: 4 | I11: 4
A12: 10 | B12: 1100003 | C12: เมอแรงค์กระปุก | D12: 60 | E12: 18 | I12: 18
A13: 11 | B13: 1200002 | C13: ท๊อฟฟี่กล่อง | D13: 55 | E13: 6 | I13: 6
A14: 12 | B14: 1200003 | C14: ท๊อฟฟี่กระเช้า | D14: 100 | E14: 6 | I14: 6
A15: 13 | B15: 1112011 | C15: เบาหวิวฝอยทอง 110 กรัม | D15: 50 | E15: 2 | I15: 2
A16: 14 | B16: 1112003 | C16: เบาหวิวกาแฟ 110 กรัม | D16: 50 | E16: 2 | I16: 2
A17: 15 | B17: 1100002 | C17: พายสัปปะรด กล่อง | D17: 50 | E17: 4 | H17: 2 | I17: 2 | J17: 100
A18: 16 | B18: 1113121 | C18: ขนมเปี๊ยะถั่ว 350 กรัม | D18: 120 | E18: 3 | I18: 3
A19: 17 | B19: 1113122 | C19: ขนมเปี๊ยะฟัก 350 กรัม | D19: 120 | E19: 3 | I19: 3
A20: 18 | B20: 1004080 | C20: ครีมฮอร์น วนิลา | D20: 50
A21: 19 | B21: 1004081 | C21: ครีมฮอร์น ใบเตย | D21: 50
A22: 20 | B22: 3001200 | C22: ครีมฮอร์น ช๊อกโกแลต | D22: 50
J23: =SUM(J3:J22) -> 200
I25: โอน | K25: =SUM(J25:J25) -> 0
I26: สด | J26: 200 | K26: =SUM(J26:J26) -> 200
K27: =SUM(K25:K26) -> 200

Sheet 21
A1: ใบสต๊อกบูธ 11037 บูธวัดเขาทำเทียม
A2: ลำดับ | B2: รหัส | C2: รายการสินค้า | D2: ราคา | E2: ยอดยกมา | F2: รับเข้า | G2: ส่งคืน | H2: ขายออก | I2: คงเหลือ | J2: ยอดเงิน | K2: หมายเหตุ
A3: 1 | B3: 1111002 | C3: ชิฟฟ่อนรวมรส 8 ชิ้น | D3: 100 | E3: 19 | H3: 1 | I3: 18 | J3: 100
A4: 2 | B4: 1004055 | C4: ชิฟฟ่อนรวมรส 4 ชิ้น | D4: 50 | E4: 20 | H4: 2 | I4: 18 | J4: 100
A5: 3 | B5: 1111056 | C5: ชิฟฟ่อนยอดฮิต | D5: 100
A6: 4 | B6: 1111009 | C6: ชิฟฟ่อนสอดไส้รวมรส 6 ชิ้น | D6: 100 | E6: 10 | I6: 10
A7: 5 | B7: 1112013 | C7: เบาหวิวเผือกมะพร้าว 110 กรัม | D7: 50
A8: 6 | B8: 1112009 | C8: เบาหวิวมะพร้าวน้ำหอม 110 กรัม | D8: 50
A9: 7 | B9: 1112017 | C9: เบาหวิวตาลหอม 110 กรัม | D9: 50 | E9: 3 | I9: 3
A10: 8 | B10: 1112019 | C10: เบาหวิวทุเรียน 110 กรัม | D10: 50
A11: 9 | B11: 1112005 | C11: เบาหวิวเนยสด 110 กรัม | D11: 50 | E11: 4 | I11: 4
A12: 10 | B12: 1100003 | C12: เมอแรงค์กระปุก | D12: 60 | E12: 18 | I12: 18
A13: 11 | B13: 1200002 | C13: ท๊อฟฟี่กล่อง | D13: 55 | E13: 6 | I13: 6
A14: 12 | B14: 1200003 | C14: ท๊อฟฟี่กระเช้า | D14: 100 | E14: 6 | I14: 6
A15: 13 | B15: 1112011 | C15: เบาหวิวฝอยทอง 110 กรัม | D15: 50 | E15: 2 | I15: 2
A16: 14 | B16: 1112003 | C16: เบาหวิวกาแฟ 110 กรัม | D16: 50 | E16: 2 | I16: 2
A17: 15 | B17: 1100002 | C17: พายสัปปะรด กล่อง | D17: 50 | E17: 2 | I17: 2
A18: 16 | B18: 1113121 | C18: ขนมเปี๊ยะถั่ว 350 กรัม | D18: 120 | E18: 3 | I18: 3
A19: 17 | B19: 1113122 | C19: ขนมเปี๊ยะฟัก 350 กรัม | D19: 120 | E19: 3 | I19: 3
A20: 18 | B20: 1004080 | C20: ครีมฮอร์น วนิลา | D20: 50
A21: 19 | B21: 1004081 | C21: ครีมฮอร์น ใบเตย | D21: 50
A22: 20 | B22: 3001200 | C22: ครีมฮอร์น ช๊อกโกแลต | D22: 50
J23: =SUM(J3:J22) -> 200
I25: โอน | K25: =SUM(J25:J25) -> 0
I26: สด | J26: 200 | K26: =SUM(J26:J26) -> 200
K27: =SUM(K25:K26) -> 200

Sheet 23
A1: ใบสต๊อกบูธ 11037 บูธวัดเขาทำเทียม
A2: ลำดับ | B2: รหัส | C2: รายการสินค้า | D2: ราคา | E2: ยอดยกมา | F2: รับเข้า | G2: ส่งคืน | H2: ขายออก | I2: คงเหลือ | J2: ยอดเงิน | K2: หมายเหตุ
A3: 1 | B3: 1111002 | C3: ชิฟฟ่อนรวมรส 8 ชิ้น | D3: 100 | E3: 18 | I3: 18
A4: 2 | B4: 1004055 | C4: ชิฟฟ่อนรวมรส 4 ชิ้น | D4: 50 | E4: 18 | I4: 18
A5: 3 | B5: 1111056 | C5: ชิฟฟ่อนยอดฮิต | D5: 100
A6: 4 | B6: 1111009 | C6: ชิฟฟ่อนสอดไส้รวมรส 6 ชิ้น | D6: 100 | E6: 10 | I6: 10
A7: 5 | B7: 1112013 | C7: เบาหวิวเผือกมะพร้าว 110 กรัม | D7: 50
A8: 6 | B8: 1112009 | C8: เบาหวิวมะพร้าวน้ำหอม 110 กรัม | D8: 50
A9: 7 | B9: 1112017 | C9: เบาหวิวตาลหอม 110 กรัม | D9: 50 | E9: 3 | I9: 3
A10: 8 | B10: 1112019 | C10: เบาหวิวทุเรียน 110 กรัม | D10: 50
A11: 9 | B11: 1112005 | C11: เบาหวิวเนยสด 110 กรัม | D11: 50 | E11: 4 | I11: 4
A12: 10 | B12: 1100003 | C12: เมอแรงค์กระปุก | D12: 60 | E12: 18 | I12: 18
A13: 11 | B13: 1200002 | C13: ท๊อฟฟี่กล่อง | D13: 55 | E13: 6 | I13: 6
A14: 12 | B14: 1200003 | C14: ท๊อฟฟี่กระเช้า | D14: 100 | E14: 6 | I14: 6
A15: 13 | B15: 1112011 | C15: เบาหวิวฝอยทอง 110 กรัม | D15: 50 | E15: 2 | I15: 2
A16: 14 | B16: 1112003 | C16: เบาหวิวกาแฟ 110 กรัม | D16: 50 | E16: 2 | I16: 2
A17: 15 | B17: 1100002 | C17: พายสัปปะรด กล่อง | D17: 50 | E17: 2 | I17: 2
A18: 16 | B18: 1113121 | C18: ขนมเปี๊ยะถั่ว 350 กรัม | D18: 120 | E18: 3 | I18: 3
A19: 17 | B19: 1113122 | C19: ขนมเปี๊ยะฟัก 350 กรัม | D19: 120 | E19: 3 | I19: 3
A20: 18 | B20: 1004080 | C20: ครีมฮอร์น วนิลา | D20: 50
A21: 19 | B21: 1004081 | C21: ครีมฮอร์น ใบเตย | D21: 50
A22: 20 | B22: 3001200 | C22: ครีมฮอร์น ช๊อกโกแลต | D22: 50
J23: =SUM(J3:J22) -> 0
I25: โอน | K25: =SUM(J25:J25) -> 0
I26: สด | K26: =SUM(J26:J26) -> 0
K27: =SUM(K25:K26) -> 0

Sheet 24
A1: ใบสต๊อกบูธ 11037 บูธวัดเขาทำเทียม
A2: ลำดับ | B2: รหัส | C2: รายการสินค้า | D2: ราคา | E2: ยอดยกมา | F2: รับเข้า | G2: ส่งคืน | H2: ขายออก | I2: คงเหลือ | J2: ยอดเงิน | K2: หมายเหตุ
A3: 1 | B3: 1111002 | C3: ชิฟฟ่อนรวมรส 8 ชิ้น | D3: 100 | E3: 18 | I3: 18
A4: 2 | B4: 1004055 | C4: ชิฟฟ่อนรวมรส 4 ชิ้น | D4: 50 | E4: 18 | H4: 1 | I4: 17 | J4: 50
A5: 3 | B5: 1111056 | C5: ชิฟฟ่อนยอดฮิต | D5: 100
A6: 4 | B6: 1111009 | C6: ชิฟฟ่อนสอดไส้รวมรส 6 ชิ้น | D6: 100 | E6: 10 | I6: 10
A7: 5 | B7: 1112013 | C7: เบาหวิวเผือกมะพร้าว 110 กรัม | D7: 50
A8: 6 | B8: 1112009 | C8: เบาหวิวมะพร้าวน้ำหอม 110 กรัม | D8: 50
A9: 7 | B9: 1112017 | C9: เบาหวิวตาลหอม 110 กรัม | D9: 50 | E9: 3 | I9: 3
A10: 8 | B10: 1112019 | C10: เบาหวิวทุเรียน 110 กรัม | D10: 50
A11: 9 | B11: 1112005 | C11: เบาหวิวเนยสด 110 กรัม | D11: 50 | E11: 4 | I11: 4
A12: 10 | B12: 1100003 | C12: เมอแรงค์กระปุก | D12: 60 | E12: 18 | I12: 18
A13: 11 | B13: 1200002 | C13: ท๊อฟฟี่กล่อง | D13: 55 | E13: 6 | I13: 6
A14: 12 | B14: 1200003 | C14: ท๊อฟฟี่กระเช้า | D14: 100 | E14: 6 | I14: 6
A15: 13 | B15: 1112011 | C15: เบาหวิวฝอยทอง 110 กรัม | D15: 50 | E15: 2 | H15: 1 | I15: 1 | J15: 50
A16: 14 | B16: 1112003 | C16: เบาหวิวกาแฟ 110 กรัม | D16: 50 | E16: 2 | I16: 2
A17: 15 | B17: 1100002 | C17: พายสัปปะรด กล่อง | D17: 50 | E17: 2 | H17: 1 | I17: 1 | J17: 50
A18: 16 | B18: 1113121 | C18: ขนมเปี๊ยะถั่ว 350 กรัม | D18: 120 | E18: 3 | I18: 3
A19: 17 | B19: 1113122 | C19: ขนมเปี๊ยะฟัก 350 กรัม | D19: 120 | E19: 3 | I19: 3
A20: 18 | B20: 1004080 | C20: ครีมฮอร์น วนิลา | D20: 50
A21: 19 | B21: 1004081 | C21: ครีมฮอร์น ใบเตย | D21: 50
A22: 20 | B22: 3001200 | C22: ครีมฮอร์น ช๊อกโกแลต | D22: 50
J23: =SUM(J3:J22) -> 150
I25: โอน | K25: =SUM(J25:J25) -> 0
I26: สด | J26: 150 | K26: =SUM(J26:J26) -> 150
K27: =SUM(K25:K26) -> 150

Sheet 26
A1: ใบสต๊อกบูธ 11037 บูธวัดเขาทำเทียม
A2: ลำดับ | B2: รหัส | C2: รายการสินค้า | D2: ราคา | E2: ยอดยกมา | F2: รับเข้า | G2: ส่งคืน | H2: ขายออก | I2: คงเหลือ | J2: ยอดเงิน | K2: หมายเหตุ
A3: 1 | B3: 1111002 | C3: ชิฟฟ่อนรวมรส 8 ชิ้น | D3: 100 | E3: 18 | I3: 18
A4: 2 | B4: 1004055 | C4: ชิฟฟ่อนรวมรส 4 ชิ้น | D4: 50 | E4: 17 | I4: 17
A5: 3 | B5: 1111056 | C5: ชิฟฟ่อนยอดฮิต | D5: 100
A6: 4 | B6: 1111009 | C6: ชิฟฟ่อนสอดไส้รวมรส 6 ชิ้น | D6: 100 | E6: 10 | I6: 10
A7: 5 | B7: 1112013 | C7: เบาหวิวเผือกมะพร้าว 110 กรัม | D7: 50
A8: 6 | B8: 1112009 | C8: เบาหวิวมะพร้าวน้ำหอม 110 กรัม | D8: 50
A9: 7 | B9: 1112017 | C9: เบาหวิวตาลหอม 110 กรัม | D9: 50 | E9: 3 | I9: 3
A10: 8 | B10: 1112019 | C10: เบาหวิวทุเรียน 110 กรัม | D10: 50
A11: 9 | B11: 1112005 | C11: เบาหวิวเนยสด 110 กรัม | D11: 50 | E11: 4 | I11: 4
A12: 10 | B12: 1100003 | C12: เมอแรงค์กระปุก | D12: 60 | E12: 18 | I12: 18
A13: 11 | B13: 1200002 | C13: ท๊อฟฟี่กล่อง | D13: 55 | E13: 6 | I13: 6
A14: 12 | B14: 1200003 | C14: ท๊อฟฟี่กระเช้า | D14: 100 | E14: 6 | I14: 6
A15: 13 | B15: 1112011 | C15: เบาหวิวฝอยทอง 110 กรัม | D15: 50 | E15: 1 | I15: 1
A16: 14 | B16: 1112003 | C16: เบาหวิวกาแฟ 110 กรัม | D16: 50 | E16: 2 | I16: 2
A17: 15 | B17: 1100002 | C17: พายสัปปะรด กล่อง | D17: 50 | E17: 1 | I17: 1
A18: 16 | B18: 1113121 | C18: ขนมเปี๊ยะถั่ว 350 กรัม | D18: 120 | E18: 3 | I18: 3
A19: 17 | B19: 1113122 | C19: ขนมเปี๊ยะฟัก 350 กรัม | D19: 120 | E19: 3 | I19: 3
A20: 18 | B20: 1004080 | C20: ครีมฮอร์น วนิลา | D20: 50
A21: 19 | B21: 1004081 | C21: ครีมฮอร์น ใบเตย | D21: 50
A22: 20 | B22: 3001200 | C22: ครีมฮอร์น ช๊อกโกแลต | D22: 50
J23: =SUM(J3:J22) -> 0
I25: โอน | K25: =SUM(J25:J25) -> 0
I26: สด | K26: =SUM(J26:J26) -> 0
K27: =SUM(K25:K26) -> 0

Sheet 27
A1: ใบสต๊อกบูธ 11037 บูธวัดเขาทำเทียม
A2: ลำดับ | B2: รหัส | C2: รายการสินค้า | D2: ราคา | E2: ยอดยกมา | F2: รับเข้า | G2: ส่งคืน | H2: ขายออก | I2: คงเหลือ | J2: ยอดเงิน | K2: หมายเหตุ
A3: 1 | B3: 1111002 | C3: ชิฟฟ่อนรวมรส 8 ชิ้น | D3: 100 | E3: 18 | I3: 18
A4: 2 | B4: 1004055 | C4: ชิฟฟ่อนรวมรส 4 ชิ้น | D4: 50 | E4: 17 | H4: 2 | I4: 15 | J4: 100
A5: 3 | B5: 1111056 | C5: ชิฟฟ่อนยอดฮิต | D5: 100
A6: 4 | B6: 1111009 | C6: ชิฟฟ่อนสอดไส้รวมรส 6 ชิ้น | D6: 100 | E6: 10 | H6: 1 | I6: 9 | J6: 80 | K6: ลด20%
A7: 5 | B7: 1112013 | C7: เบาหวิวเผือกมะพร้าว 110 กรัม | D7: 50
A8: 6 | B8: 1112009 | C8: เบาหวิวมะพร้าวน้ำหอม 110 กรัม | D8: 50
A9: 7 | B9: 1112017 | C9: เบาหวิวตาลหอม 110 กรัม | D9: 50 | E9: 3 | I9: 3
A10: 8 | B10: 1112019 | C10: เบาหวิวทุเรียน 110 กรัม | D10: 50
A11: 9 | B11: 1112005 | C11: เบาหวิวเนยสด 110 กรัม | D11: 50 | E11: 4 | I11: 4
A12: 10 | B12: 1100003 | C12: เมอแรงค์กระปุก | D12: 60 | E12: 18 | I12: 18
A13: 11 | B13: 1200002 | C13: ท๊อฟฟี่กล่อง | D13: 55 | E13: 6 | H13: 1 | I13: 5 | J13: 55
A14: 12 | B14: 1200003 | C14: ท๊อฟฟี่กระเช้า | D14: 100 | E14: 6 | I14: 6
A15: 13 | B15: 1112011 | C15: เบาหวิวฝอยทอง 110 กรัม | D15: 50 | E15: 1 | I15: 1
A16: 14 | B16: 1112003 | C16: เบาหวิวกาแฟ 110 กรัม | D16: 50 | E16: 2 | I16: 2
A17: 15 | B17: 1100002 | C17: พายสัปปะรด กล่อง | D17: 50 | E17: 1 | I17: 1
A18: 16 | B18: 1113121 | C18: ขนมเปี๊ยะถั่ว 350 กรัม | D18: 120 | E18: 3 | I18: 3
A19: 17 | B19: 1113122 | C19: ขนมเปี๊ยะฟัก 350 กรัม | D19: 120 | E19: 3 | I19: 3
A20: 18 | B20: 1004080 | C20: ครีมฮอร์น วนิลา | D20: 50
A21: 19 | B21: 1004081 | C21: ครีมฮอร์น ใบเตย | D21: 50
A22: 20 | B22: 3001200 | C22: ครีมฮอร์น ช๊อกโกแลต | D22: 50
J23: =SUM(J3:J22) -> 235
I25: โอน | J25: 80 | K25: =SUM(J25:J25) -> 80
I26: สด | J26: 155 | K26: =SUM(J26:J26) -> 155
K27: =SUM(K25:K26) -> 235

Sheet 28
A1: ใบสต๊อกบูธ 11037 บูธวัดเขาทำเทียม
A2: ลำดับ | B2: รหัส | C2: รายการสินค้า | D2: ราคา | E2: ยอดยกมา | F2: รับเข้า | G2: ส่งคืน | H2: ขายออก | I2: คงเหลือ | J2: ยอดเงิน | K2: หมายเหตุ
A3: 1 | B3: 1111002 | C3: ชิฟฟ่อนรวมรส 8 ชิ้น | D3: 100 | E3: 18 | H3: 2 | I3: 16 | J3: 200
A4: 2 | B4: 1004055 | C4: ชิฟฟ่อนรวมรส 4 ชิ้น | D4: 50 | E4: 15 | I4: 15
A5: 3 | B5: 1111056 | C5: ชิฟฟ่อนยอดฮิต | D5: 100
A6: 4 | B6: 1111009 | C6: ชิฟฟ่อนสอดไส้รวมรส 6 ชิ้น | D6: 100 | E6: 9 | H6: 3 | I6: 6 | J6: 150 | K6: ลด50%
A7: 5 | B7: 1112013 | C7: เบาหวิวเผือกมะพร้าว 110 กรัม | D7: 50
A8: 6 | B8: 1112009 | C8: เบาหวิวมะพร้าวน้ำหอม 110 กรัม | D8: 50
A9: 7 | B9: 1112017 | C9: เบาหวิวตาลหอม 110 กรัม | D9: 50 | E9: 3 | I9: 3
A10: 8 | B10: 1112019 | C10: เบาหวิวทุเรียน 110 กรัม | D10: 50
A11: 9 | B11: 1112005 | C11: เบาหวิวเนยสด 110 กรัม | D11: 50 | E11: 4 | I11: 4
A12: 10 | B12: 1100003 | C12: เมอแรงค์กระปุก | D12: 60 | E12: 18 | I12: 18
A13: 11 | B13: 1200002 | C13: ท๊อฟฟี่กล่อง | D13: 55 | E13: 5 | I13: 5
A14: 12 | B14: 1200003 | C14: ท๊อฟฟี่กระเช้า | D14: 100 | E14: 6 | I14: 6
A15: 13 | B15: 1112011 | C15: เบาหวิวฝอยทอง 110 กรัม | D15: 50 | E15: 1 | I15: 1
A16: 14 | B16: 1112003 | C16: เบาหวิวกาแฟ 110 กรัม | D16: 50 | E16: 2 | I16: 2
A17: 15 | B17: 1100002 | C17: พายสัปปะรด กล่อง | D17: 50 | E17: 1 | I17: 1
A18: 16 | B18: 1113121 | C18: ขนมเปี๊ยะถั่ว 350 กรัม | D18: 120 | E18: 3 | I18: 3
A19: 17 | B19: 1113122 | C19: ขนมเปี๊ยะฟัก 350 กรัม | D19: 120 | E19: 3 | I19: 3
A20: 18 | B20: 1004080 | C20: ครีมฮอร์น วนิลา | D20: 50
A21: 19 | B21: 1004081 | C21: ครีมฮอร์น ใบเตย | D21: 50
A22: 20 | B22: 3001200 | C22: ครีมฮอร์น ช๊อกโกแลต | D22: 50
J23: =SUM(J3:J22) -> 350
I25: โอน | K25: =SUM(J25:J25) -> 0
I26: สด | J26: 350 | K26: =SUM(J26:J26) -> 350
K27: =SUM(K25:K26) -> 350

Sheet 30
A1: ใบสต๊อกบูธ 11037 บูธวัดเขาทำเทียม
A2: ลำดับ | B2: รหัส | C2: รายการสินค้า | D2: ราคา | E2: ยอดยกมา | F2: รับเข้า | G2: ส่งคืน | H2: ขายออก | I2: คงเหลือ | J2: ยอดเงิน | K2: หมายเหตุ
A3: 1 | B3: 1111002 | C3: ชิฟฟ่อนรวมรส 8 ชิ้น | D3: 100 | E3: 16 | I3: 16
A4: 2 | B4: 1004055 | C4: ชิฟฟ่อนรวมรส 4 ชิ้น | D4: 50 | E4: 15 | I4: 15
A5: 3 | B5: 1111056 | C5: ชิฟฟ่อนยอดฮิต | D5: 100
A6: 4 | B6: 1111009 | C6: ชิฟฟ่อนสอดไส้รวมรส 6 ชิ้น | D6: 100 | E6: 6 | G6: 6
A7: 5 | B7: 1112013 | C7: เบาหวิวเผือกมะพร้าว 110 กรัม | D7: 50
A8: 6 | B8: 1112009 | C8: เบาหวิวมะพร้าวน้ำหอม 110 กรัม | D8: 50
A9: 7 | B9: 1112017 | C9: เบาหวิวตาลหอม 110 กรัม | D9: 50 | E9: 3 | I9: 3
A10: 8 | B10: 1112019 | C10: เบาหวิวทุเรียน 110 กรัม | D10: 50
A11: 9 | B11: 1112005 | C11: เบาหวิวเนยสด 110 กรัม | D11: 50 | E11: 4 | I11: 4
A12: 10 | B12: 1100003 | C12: เมอแรงค์กระปุก | D12: 60 | E12: 18 | I12: 18
A13: 11 | B13: 1200002 | C13: ท๊อฟฟี่กล่อง | D13: 55 | E13: 5 | I13: 5
A14: 12 | B14: 1200003 | C14: ท๊อฟฟี่กระเช้า | D14: 100 | E14: 6 | I14: 6
A15: 13 | B15: 1112011 | C15: เบาหวิวฝอยทอง 110 กรัม | D15: 50 | E15: 1 | I15: 1
A16: 14 | B16: 1112003 | C16: เบาหวิวกาแฟ 110 กรัม | D16: 50 | E16: 2 | I16: 2
A17: 15 | B17: 1100002 | C17: พายสัปปะรด กล่อง | D17: 50 | E17: 1 | I17: 1
A18: 16 | B18: 1113121 | C18: ขนมเปี๊ยะถั่ว 350 กรัม | D18: 120 | E18: 3 | I18: 3
A19: 17 | B19: 1113122 | C19: ขนมเปี๊ยะฟัก 350 กรัม | D19: 120 | E19: 3 | I19: 3
A20: 18 | B20: 1004080 | C20: ครีมฮอร์น วนิลา | D20: 50
A21: 19 | B21: 1004081 | C21: ครีมฮอร์น ใบเตย | D21: 50
A22: 20 | B22: 3001200 | C22: ครีมฮอร์น ช๊อกโกแลต | D22: 50
J23: =SUM(J3:J22) -> 0
I25: โอน | K25: =SUM(J25:J25) -> 0
I26: สด | K26: =SUM(J26:J26) -> 0
K27: =SUM(K25:K26) -> 0

Sheet 31
A1: ใบสต๊อกบูธ 11037 บูธวัดเขาทำเทียม
A2: ลำดับ | B2: รหัส | C2: รายการสินค้า | D2: ราคา | E2: ยอดยกมา | F2: รับเข้า | G2: ส่งคืน | H2: ขายออก | I2: คงเหลือ | J2: ยอดเงิน | K2: หมายเหตุ
A3: 1 | B3: 1111002 | C3: ชิฟฟ่อนรวมรส 8 ชิ้น | D3: 100 | E3: 16 | H3: 9 | I3: 7 | J3: 900
A4: 2 | B4: 1004055 | C4: ชิฟฟ่อนรวมรส 4 ชิ้น | D4: 50 | E4: 15 | H4: 8 | I4: 7 | J4: 400
A5: 3 | B5: 1111056 | C5: ชิฟฟ่อนยอดฮิต | D5: 100
A6: 4 | B6: 1111009 | C6: ชิฟฟ่อนสอดไส้รวมรส 6 ชิ้น | D6: 100
A7: 5 | B7: 1112013 | C7: เบาหวิวเผือกมะพร้าว 110 กรัม | D7: 50
A8: 6 | B8: 1112009 | C8: เบาหวิวมะพร้าวน้ำหอม 110 กรัม | D8: 50
A9: 7 | B9: 1112017 | C9: เบาหวิวตาลหอม 110 กรัม | D9: 50 | E9: 3 | I9: 3
A10: 8 | B10: 1112019 | C10: เบาหวิวทุเรียน 110 กรัม | D10: 50
A11: 9 | B11: 1112005 | C11: เบาหวิวเนยสด 110 กรัม | D11: 50 | E11: 4 | H11: 1 | I11: 3 | J11: 50
A12: 10 | B12: 1100003 | C12: เมอแรงค์กระปุก | D12: 60 | E12: 18 | H12: 4 | I12: 14 | J12: 240
A13: 11 | B13: 1200002 | C13: ท๊อฟฟี่กล่อง | D13: 55 | E13: 5 | H13: 2 | I13: 3 | J13: 110
A14: 12 | B14: 1200003 | C14: ท๊อฟฟี่กระเช้า | D14: 100 | E14: 6 | I14: 6
A15: 13 | B15: 1112011 | C15: เบาหวิวฝอยทอง 110 กรัม | D15: 50 | E15: 1 | I15: 1
A16: 14 | B16: 1112003 | C16: เบาหวิวกาแฟ 110 กรัม | D16: 50 | E16: 2 | I16: 2
A17: 15 | B17: 1100002 | C17: พายสัปปะรด กล่อง | D17: 50 | E17: 1 | H17: 1 | J17: 50
A18: 16 | B18: 1113121 | C18: ขนมเปี๊ยะถั่ว 350 กรัม | D18: 120 | E18: 3 | I18: 3
A19: 17 | B19: 1113122 | C19: ขนมเปี๊ยะฟัก 350 กรัม | D19: 120 | E19: 3 | I19: 3
A20: 18 | B20: 1004080 | C20: ครีมฮอร์น วนิลา | D20: 50
A21: 19 | B21: 1004081 | C21: ครีมฮอร์น ใบเตย | D21: 50
A22: 20 | B22: 3001200 | C22: ครีมฮอร์น ช๊อกโกแลต | D22: 50
J23: =SUM(J3:J22) -> 1750
I25: โอน | K25: =SUM(J25:J25) -> 0
I26: สด | J26: 1750 | K26: =SUM(J26:J26) -> 1750
K27: =SUM(K25:K26) -> 1750

Sheet สรุป
A2: สรุป บูธ วัดเขาทำเทียม วันที่ 1-31/12/2566
A3: ลำดับ | B3: รายการ | C3: ยกมา | D3: รับ | E3: รวม | F3: เปลี่ยน/ | G3: คงเหลือ | H3: รายการขาย | K3: หมายเหตุ | L3: วันที่ | M3: ยอดเงิน | N3: ส่วนลด | O3: สแกนใช้สิทธิ์ | P3: ค่าโอนเงิน | Q3: ค่าใช้จ่ายอื่นๆ | R3: โอนหน้าร้าน | S3: รับสุทธิ | T3: ยอดโอนเงิน | U3: โอนเกิน/โอนขาด
F4: คืน/เสีย | H4: จำนวน | I4: @ | J4: เป็นเงิน
A5: 1 | B5: ชิฟฟ่อนรวมรส 8 ชิ้น | C5: 23 | D5: =+'16'!F3 -> 20 | E5: =+C5+D5 -> 43 | F5: =+'19'!G3+'30'!G3 -> 0 | G5: 7 | H5: =+'1'!H3+'2'!H3+'3'!H3+'4'!H3+'5'!H3+'6'!H3+'7'!H3+'9'!H3+'10'!H3+'12'!H3+'13'!H3+'14'!H3+'16'!H3+'17'!H3+'19'!H3+'20'!H3+'21'!H3+'23'!H3+'24'!H3+'27'!H3+'28'!H3+'30'!H3+'31'!H3 -> 36 | I5: 100 | J5: =+'1'!J3+'2'!J3+'3'!J3+'4'!J3+'5'!J3+'6'!J3+'7'!J3+'9'!J3+'10'!J3+'12'!J3+'13'!J3+'14'!J3+'16'!J3+'17'!J3+'19'!J3+'20'!J3+'21'!J3+'23'!J3+'24'!J3+'27'!J3+'28'!J3+'30'!J3+'31'!J3 -> 2750 | L5: 1 | M5: =+'1'!J16 -> 1315 | P5: 15 | R5: =+'1'!J18 -> 200 | S5: =+M5-N5-P5-R5-Q5 -> 1100 | T5: =+'1'!J19 -> 1100 | U5: =+T5-S5 -> 0
A6: 2 | B6: ชิฟฟ่อนรวมรส 4 ชิ้น | C6: 32 | D6: =+'16'!F4 -> 20 | E6: =+C6+D6 -> 52 | F6: =+'19'!G4+'30'!G4 -> 5 | G6: 7 | H6: =+'1'!H4+'2'!H4+'3'!H4+'4'!H4+'5'!H4+'6'!H4+'7'!H4+'9'!H4+'10'!H4+'12'!H4+'13'!H4+'14'!H4+'16'!H4+'17'!H4+'19'!H4+'20'!H4+'21'!H4+'23'!H4+'24'!H4+'27'!H4+'28'!H4+'30'!H4+'31'!H4 -> 40 | I6: 50 | J6: =+'1'!J4+'2'!J4+'3'!J4+'4'!J4+'5'!J4+'6'!J4+'7'!J4+'9'!J4+'10'!J4+'12'!J4+'13'!J4+'14'!J4+'16'!J4+'17'!J4+'19'!J4+'20'!J4+'21'!J4+'23'!J4+'24'!J4+'27'!J4+'28'!J4+'30'!J4+'31'!J4 -> 1630 | L6: 2 | M6: =+'2'!J16 -> 955 | R6: =+'2'!J18 -> 100 | S6: =+M6-N6-P6-R6-Q6 -> 855 | T6: =+'2'!J19 -> 855 | U6: =+T6-S6 -> 0
A7: 3 | B7: ชิฟฟ่อนยอดฮิต | C7: 12 | D7: =+'16'!F5 -> 0 | E7: =+C7+D7 -> 12 | F7: =+'19'!G5+'30'!G5 -> 0 | H7: =+'1'!H5+'2'!H5+'3'!H5+'4'!H5+'5'!H5+'6'!H5+'7'!H5+'9'!H5+'10'!H5+'12'!H5+'13'!H5+'14'!H5+'16'!H5+'17'!H5+'19'!H5+'20'!H5+'21'!H5+'23'!H5+'24'!H5+'27'!H5+'28'!H5+'30'!H5+'31'!H5 -> 12 | I7: 100 | J7: =+'1'!J5+'2'!J5+'3'!J5+'4'!J5+'5'!J5+'6'!J5+'7'!J5+'9'!J5+'10'!J5+'12'!J5+'13'!J5+'14'!J5+'16'!J5+'17'!J5+'19'!J5+'20'!J5+'21'!J5+'23'!J5+'24'!J5+'27'!J5+'28'!J5+'30'!J5+'31'!J5 -> 850 | L7: 3 | M7: =+'3'!J16 -> 0 | O7: ขายไม่ได้ | R7: 0 | S7: =+M7-N7-P7-R7-Q7 -> 0 | T7: 0 | U7: =+T7-S7 -> 0
A8: 4 | B8: ชิฟฟ่อนสอดไส้รวมรส 6 ชิ้น | C8: 11 | D8: =+'16'!F6 -> 10 | E8: =+C8+D8 -> 21 | F8: =+'19'!G6+'30'!G6 -> 6 | H8: =+'1'!H6+'2'!H6+'3'!H6+'4'!H6+'5'!H6+'6'!H6+'7'!H6+'9'!H6+'10'!H6+'12'!H6+'13'!H6+'14'!H6+'16'!H6+'17'!H6+'19'!H6+'20'!H6+'21'!H6+'23'!H6+'24'!H6+'27'!H6+'28'!H6+'30'!H6+'31'!H6 -> 15 | I8: 100 | J8: =+'1'!J6+'2'!J6+'3'!J6+'4'!J6+'5'!J6+'6'!J6+'7'!J6+'9'!J6+'10'!J6+'12'!J6+'13'!J6+'14'!J6+'16'!J6+'17'!J6+'19'!J6+'20'!J6+'21'!J6+'23'!J6+'24'!J6+'27'!J6+'28'!J6+'30'!J6+'31'!J6 -> 980 | L8: 4 | M8: =+'3'!J17 -> 0 | O8: ขายไม่ได้ | R8: 0 | S8: =+M8-N8-P8-R8-Q8 -> 0 | T8: 0 | U8: =+T8-S8 -> 0
A9: 5 | B9: เบาหวิวเผือกมะพร้าว 110 กรัม | C9: 3 | D9: =+'16'!F7 -> 0 | E9: =+C9+D9 -> 3 | F9: =+'19'!G7+'30'!G7 -> 0 | H9: =+'1'!H7+'2'!H7+'3'!H7+'4'!H7+'5'!H7+'6'!H7+'7'!H7+'9'!H7+'10'!H7+'12'!H7+'13'!H7+'14'!H7+'16'!H7+'17'!H7+'19'!H7+'20'!H7+'21'!H7+'23'!H7+'24'!H7+'27'!H7+'28'!H7+'30'!H7+'31'!H7 -> 3 | I9: 50 | J9: =+'1'!J7+'2'!J7+'3'!J7+'4'!J7+'5'!J7+'6'!J7+'7'!J7+'9'!J7+'10'!J7+'12'!J7+'13'!J7+'14'!J7+'16'!J7+'17'!J7+'19'!J7+'20'!J7+'21'!J7+'23'!J7+'24'!J7+'27'!J7+'28'!J7+'30'!J7+'31'!J7 -> 100 | L9: 5 | M9: =+'5'!J16 -> 350 | R9: =+'5'!J18 -> 0 | S9: =+M9-N9-P9-R9-Q9 -> 350 | T9: =+'5'!J19 -> 350 | U9: =+T9-S9 -> 0
A10: 6 | B10: เบาหวิวมะพร้าวน้ำหอม 110 กรัม | C10: 4 | D10: =+'16'!F8 -> 0 | E10: =+C10+D10 -> 4 | F10: =+'19'!G8+'30'!G8 -> 1 | H10: =+'1'!H8+'2'!H8+'3'!H8+'4'!H8+'5'!H8+'6'!H8+'7'!H8+'9'!H8+'10'!H8+'12'!H8+'13'!H8+'14'!H8+'16'!H8+'17'!H8+'19'!H8+'20'!H8+'21'!H8+'23'!H8+'24'!H8+'27'!H8+'28'!H8+'30'!H8+'31'!H8 -> 3 | I10: 50 | J10: =+'1'!J8+'2'!J8+'3'!J8+'4'!J8+'5'!J8+'6'!J8+'7'!J8+'9'!J8+'10'!J8+'12'!J8+'13'!J8+'14'!J8+'16'!J8+'17'!J8+'19'!J8+'20'!J8+'21'!J8+'23'!J8+'24'!J8+'27'!J8+'28'!J8+'30'!J8+'31'!J8 -> 115 | L10: 6 | M10: =+'6'!J16 -> 205 | R10: =+'6'!J18 -> 0 | S10: =+M10-N10-P10-R10-Q10 -> 205 | T10: =+'6'!J19 -> 205 | U10: =+T10-S10 -> 0
A11: 7 | B11: เบาหวิวตาลหอม 110 กรัม | C11: 1 | D11: =+'16'!F9 -> 3 | E11: =+C11+D11 -> 4 | F11: =+'19'!G9+'30'!G9 -> 0 | G11: 3 | H11: =+'1'!H9+'2'!H9+'3'!H9+'4'!H9+'5'!H9+'6'!H9+'7'!H9+'9'!H9+'10'!H9+'12'!H9+'13'!H9+'14'!H9+'16'!H9+'17'!H9+'19'!H9+'20'!H9+'21'!H9+'23'!H9+'24'!H9+'27'!H9+'28'!H9+'30'!H9+'31'!H9 -> 1 | I11: 50 | J11: =+'1'!J9+'2'!J9+'3'!J9+'4'!J9+'5'!J9+'6'!J9+'7'!J9+'9'!J9+'10'!J9+'12'!J9+'13'!J9+'14'!J9+'16'!J9+'17'!J9+'19'!J9+'20'!J9+'21'!J9+'23'!J9+'24'!J9+'27'!J9+'28'!J9+'30'!J9+'31'!J9 -> 50 | L11: 7 | M11: 0 | O11: ขายไม่ได้ | R11: 0 | S11: 0 | T11: 0 | U11: 0
A12: 8 | B12: เบาหวิวทุเรียน 110 กรัม | C12: 4 | D12: =+'16'!F10 -> 0 | E12: =+C12+D12 -> 4 | F12: =+'19'!G10+'30'!G10 -> 2 | H12: =+'1'!H10+'2'!H10+'3'!H10+'4'!H10+'5'!H10+'6'!H10+'7'!H10+'9'!H10+'10'!H10+'12'!H10+'13'!H10+'14'!H10+'16'!H10+'17'!H10+'19'!H10+'20'!H10+'21'!H10+'23'!H10+'24'!H10+'27'!H10+'28'!H10+'30'!H10+'31'!H10 -> 2 | I12: 50 | J12: =+'1'!J10+'2'!J10+'3'!J10+'4'!J10+'5'!J10+'6'!J10+'7'!J10+'9'!J10+'10'!J10+'12'!J10+'13'!J10+'14'!J10+'16'!J10+'17'!J10+'19'!J10+'20'!J10+'21'!J10+'23'!J10+'24'!J10+'27'!J10+'28'!J10+'30'!J10+'31'!J10 -> 50 | L12: 8 | M12: 0 | O12: หยุด | R12: 0 | S12: =+M12-N12-P12-R12-Q12 -> 0 | T12: 0 | U12: =+T12-S12 -> 0
A13: 9 | B13: เบาหวิวเนยสด 110 กรัม | C13: 4 | D13: =+'16'!F11 -> 5 | E13: =+C13+D13 -> 9 | F13: =+'19'!G11+'30'!G11 -> 0 | G13: 3 | H13: =+'1'!H11+'2'!H11+'3'!H11+'4'!H11+'5'!H11+'6'!H11+'7'!H11+'9'!H11+'10'!H11+'12'!H11+'13'!H11+'14'!H11+'16'!H11+'17'!H11+'19'!H11+'20'!H11+'21'!H11+'23'!H11+'24'!H11+'27'!H11+'28'!H11+'30'!H11+'31'!H11 -> 6 | I13: 50 | J13: =+'1'!J11+'2'!J11+'3'!J11+'4'!J11+'5'!J11+'6'!J11+'7'!J11+'9'!J11+'10'!J11+'12'!J11+'13'!J11+'14'!J11+'16'!J11+'17'!J11+'19'!J11+'20'!J11+'21'!J11+'23'!J11+'24'!J11+'27'!J11+'28'!J11+'30'!J11+'31'!J11 -> 250 | L13: 9 | M13: 0 | O13: ขายไม่ได้ | R13: 0 | S13: =+M13-N13-P13-R13-Q13 -> 0 | T13: 0 | U13: =+T13-S13 -> 0
A14: 10 | B14: เมอแรงค์กระปุก | C14: 19 | D14: =+'16'!F12 -> 0 | E14: =+C14+D14 -> 19 | F14: =+'19'!G12+'30'!G12 -> 0 | G14: 14 | H14: =+'1'!H12+'2'!H12+'3'!H12+'4'!H12+'5'!H12+'6'!H12+'7'!H12+'9'!H12+'10'!H12+'12'!H12+'13'!H12+'14'!H12+'16'!H12+'17'!H12+'19'!H12+'20'!H12+'21'!H12+'23'!H12+'24'!H12+'27'!H12+'28'!H12+'30'!H12+'31'!H12 -> 5 | I14: 60 | J14: =+'1'!J12+'2'!J12+'3'!J12+'4'!J12+'5'!J12+'6'!J12+'7'!J12+'9'!J12+'10'!J12+'12'!J12+'13'!J12+'14'!J12+'16'!J12+'17'!J12+'19'!J12+'20'!J12+'21'!J12+'23'!J12+'24'!J12+'27'!J12+'28'!J12+'30'!J12+'31'!J12 -> 300 | L14: 10 | M14: =+'10'!J16 -> 405 | R14: =+'10'!J18 -> 0 | S14: =+M14-N14-P14-R14-Q14 -> 405 | T14: =+'10'!J19 -> 405 | U14: =+T14-S14 -> 0
A15: 11 | B15: ท๊อฟฟี่กล่อง | C15: 7 | D15: =+'16'!F13 -> 6 | E15: =+C15+D15 -> 13 | F15: =+'19'!G13+'30'!G13 -> 0 | G15: 3 | H15: =+'1'!H13+'2'!H13+'3'!H13+'4'!H13+'5'!H13+'6'!H13+'7'!H13+'9'!H13+'10'!H13+'12'!H13+'13'!H13+'14'!H13+'16'!H13+'17'!H13+'19'!H13+'20'!H13+'21'!H13+'23'!H13+'24'!H13+'27'!H13+'28'!H13+'30'!H13+'31'!H13 -> 10 | I15: 55 | J15: =+'1'!J13+'2'!J13+'3'!J13+'4'!J13+'5'!J13+'6'!J13+'7'!J13+'9'!J13+'10'!J13+'12'!J13+'13'!J13+'14'!J13+'16'!J13+'17'!J13+'19'!J13+'20'!J13+'21'!J13+'23'!J13+'24'!J13+'27'!J13+'28'!J13+'30'!J13+'31'!J13 -> 550 | L15: 11 | M15: 0 | O15: หยุด | R15: 0 | S15: 0 | T15: 0 | U15: 0
A16: 12 | B16: ท๊อฟฟี่กระเช้า | C16: 9 | D16: =+'16'!F14 -> 0 | E16: =+C16+D16 -> 9 | F16: =+'19'!G14+'30'!G14 -> 0 | G16: 6 | H16: =+'1'!H14+'2'!H14+'3'!H14+'4'!H14+'5'!H14+'6'!H14+'7'!H14+'9'!H14+'10'!H14+'12'!H14+'13'!H14+'14'!H14+'16'!H14+'17'!H14+'19'!H14+'20'!H14+'21'!H14+'23'!H14+'24'!H14+'27'!H14+'28'!H14+'30'!H14+'31'!H14 -> 3 | I16: 100 | J16: =+'1'!J14+'2'!J14+'3'!J14+'4'!J14+'5'!J14+'6'!J14+'7'!J14+'9'!J14+'10'!J14+'12'!J14+'13'!J14+'14'!J14+'16'!J14+'17'!J14+'19'!J14+'20'!J14+'21'!J14+'23'!J14+'24'!J14+'27'!J14+'28'!J14+'30'!J14+'31'!J14 -> 300 | L16: 12 | M16: 0 | O16: ขายไม่ได้ | R16: 0 | S16: =+M16-N16-P16-R16-Q16 -> 0 | T16: 0 | U16: =+T16-S16 -> 0
A17: 13 | B17: เบาหวิวฝอยทอง 110 กรัม | C17: 3 | D17: =+'16'!F15 -> 3 | E17: =+C17+D17 -> 6 | F17: =+'19'!G15+'30'!G15 -> 0 | G17: 1 | H17: =+'1'!H15+'2'!H15+'3'!H15+'4'!H15+'5'!H15+'6'!H15+'7'!H15+'9'!H15+'10'!H15+'12'!H15+'13'!H15+'14'!H15+'16'!H15+'17'!H15+'19'!H15+'20'!H15+'21'!H15+'23'!H15+'24'!H15+'27'!H15+'28'!H15+'30'!H15+'31'!H15 -> 5 | I17: 50 | J17: =+'1'!J15+'2'!J15+'3'!J15+'4'!J15+'5'!J15+'6'!J15+'7'!J15+'9'!J15+'10'!J15+'12'!J15+'13'!J15+'14'!J15+'16'!J15+'17'!J15+'19'!J15+'20'!J15+'21'!J15+'23'!J15+'24'!J15+'27'!J15+'28'!J15+'30'!J15+'31'!J15 -> 250 | L17: 13 | M17: =+'13'!J16 -> 655 | R17: =+'13'!J18 -> 150 | S17: =+M17-N17-P17-R17-Q17 -> 505 | T17: =+'13'!J19 -> 505 | U17: =+T17-S17 -> 0
A18: 14 | B18: เบาหวิวกาแฟ 110 กรัม | C18: 0 | D18: =+'16'!F16 -> 3 | E18: =+C18+D18 -> 3 | F18: =+'19'!G16+'30'!G16 -> 0 | G18: 2 | H18: =+'1'!H16+'2'!H16+'3'!H16+'4'!H16+'5'!H16+'6'!H16+'7'!H16+'9'!H16+'10'!H16+'12'!H16+'13'!H16+'14'!H16+'16'!H16+'17'!H16+'19'!H16+'20'!H16+'21'!H16+'23'!H16+'24'!H16+'27'!H16+'28'!H16+'30'!H16+'31'!H16 -> 1 | I18: 50 | J18: 50 | L18: 14 | M18: =+'14'!J16 -> 380 | R18: =+'14'!J18 -> 0 | S18: =+M18-N18-P18-R18-Q18 -> 380 | T18: =+'14'!J19 -> 380 | U18: =+T18-S18 -> 0
A19: 15 | B19: พายสัปปะรด กล่อง | C19: 0 | D19: =+'16'!F17 -> 5 | E19: =+C19+D19 -> 5 | F19: =+'19'!G17+'30'!G17 -> 0 | H19: =+'1'!H17+'2'!H17+'3'!H17+'4'!H17+'5'!H17+'6'!H17+'7'!H17+'9'!H17+'10'!H17+'12'!H17+'13'!H17+'14'!H17+'16'!H17+'17'!H17+'19'!H17+'20'!H17+'21'!H17+'23'!H17+'24'!H17+'27'!H17+'28'!H17+'30'!H17+'31'!H17 -> 5 | I19: 50 | J19: =+'1'!J17+'2'!J17+'3'!J17+'4'!J17+'5'!J17+'6'!J17+'7'!J17+'9'!J17+'10'!J17+'12'!J17+'13'!J17+'14'!J17+'16'!J17+'17'!J17+'19'!J17+'20'!J17+'21'!J17+'23'!J17+'24'!J17+'27'!J17+'28'!J17+'30'!J17+'31'!J17 -> 250 | L19: 15 | M19: 0 | O19: หยุด | R19: 0 | S19: =+M19-N19-P19-R19-Q19 -> 0 | T19: 0 | U19: =+T19-S19 -> 0
A20: 16 | B20: ขนมเปี๊ยะถั่ว 350 กรัม | C20: 0 | D20: =+'16'!F18 -> 3 | E20: =+C20+D20 -> 3 | F20: =+'19'!G18+'30'!G18 -> 0 | G20: 3 | H20: =+'1'!H18+'2'!H18+'3'!H18+'4'!H18+'5'!H18+'6'!H18+'7'!H18+'9'!H18+'10'!H18+'12'!H18+'13'!H18+'14'!H18+'16'!H18+'17'!H18+'19'!H18+'20'!H18+'21'!H18+'23'!H18+'24'!H18+'27'!H18+'28'!H18+'30'!H18+'31'!H18 -> 0 | I20: 120 | J20: 0 | L20: 16 | M20: =+'16'!J23 -> 1375 | P20: 15 | R20: =+'16'!J25 -> 0 | S20: =+M20-N20-P20-R20-Q20 -> 1360 | T20: =+'16'!J26 -> 1360 | U20: =+T20-S20 -> 0
A21: 17 | B21: ขนมเปี๊ยะฟัก 350 กรัม | C21: 0 | D21: =+'16'!F19 -> 3 | E21: =+C21+D21 -> 3 | F21: =+'19'!G19+'30'!G19 -> 0 | G21: 3 | H21: =+'1'!H19+'2'!H19+'3'!H19+'4'!H19+'5'!H19+'6'!H19+'7'!H19+'9'!H19+'10'!H19+'12'!H19+'13'!H19+'14'!H19+'16'!H19+'17'!H19+'19'!H19+'20'!H19+'21'!H19+'23'!H19+'24'!H19+'27'!H19+'28'!H19+'30'!H19+'31'!H19 -> 0 | I21: 120 | J21: 0 | L21: 17 | M21: =+'17'!J23 -> 200 | R21: =+'17'!J25 -> 0 | S21: =+M21-N21-P21-R21-Q21 -> 200 | T21: =+'17'!J26 -> 200 | U21: =+T21-S21 -> 0
A22: 18 | B22: ครีมฮอร์น วนิลา | C22: 0 | D22: =+'16'!F20 -> 3 | E22: =+C22+D22 -> 3 | F22: =+'19'!G20+'30'!G20 -> 0 | H22: =+'1'!H20+'2'!H20+'3'!H20+'4'!H20+'5'!H20+'6'!H20+'7'!H20+'9'!H20+'10'!H20+'12'!H20+'13'!H20+'14'!H20+'16'!H20+'17'!H20+'19'!H20+'20'!H20+'21'!H20+'23'!H20+'24'!H20+'27'!H20+'28'!H20+'30'!H20+'31'!H20 -> 3 | I22: 50 | J22: =+'1'!J20+'2'!J20+'3'!J20+'4'!J20+'5'!J20+'6'!J20+'7'!J20+'9'!J20+'10'!J20+'12'!J20+'13'!J20+'14'!J20+'16'!J20+'17'!J20+'19'!J20+'20'!J20+'21'!J20+'23'!J20+'24'!J20+'27'!J20+'28'!J20+'30'!J20+'31'!J20 -> 150 | L22: 18 | M22: 0 | O22: หยุด | R22: 0 | S22: =+M22-N22-P22-R22-Q22 -> 0 | T22: 0 | U22: =+T22-S22 -> 0
A23: 19 | B23: ครีมฮอร์น ใบเตย | C23: 0 | D23: =+'16'!F21 -> 1 | E23: =+C23+D23 -> 1 | F23: =+'19'!G21+'30'!G21 -> 0 | H23: =+'1'!H21+'2'!H21+'3'!H21+'4'!H21+'5'!H21+'6'!H21+'7'!H21+'9'!H21+'10'!H21+'12'!H21+'13'!H21+'14'!H21+'16'!H21+'17'!H21+'19'!H21+'20'!H21+'21'!H21+'23'!H21+'24'!H21+'27'!H21+'28'!H21+'30'!H21+'31'!H21 -> 1 | I23: 50 | J23: =+'1'!J21+'2'!J21+'3'!J21+'4'!J21+'5'!J21+'6'!J21+'7'!J21+'9'!J21+'10'!J21+'12'!J21+'13'!J21+'14'!J21+'16'!J21+'17'!J21+'19'!J21+'20'!J21+'21'!J21+'23'!J21+'24'!J21+'27'!J21+'28'!J21+'30'!J21+'31'!J21 -> 50 | L23: 19 | M23: =+'19'!J23 -> 100 | R23: =+'19'!J25 -> 0 | S23: =+M23-N23-P23-R23-Q23 -> 100 | T23: =+'19'!J26 -> 100 | U23: =+T23-S23 -> 0
A24: 20 | B24: ครีมฮอร์น ช๊อกโกแลต | C24: 0 | D24: =+'16'!F22 -> 3 | E24: =+C24+D24 -> 3 | F24: =+'19'!G22+'30'!G22 -> 0 | G24: 0 | H24: =+'1'!H22+'2'!H22+'3'!H22+'4'!H22+'5'!H22+'6'!H22+'7'!H22+'9'!H22+'10'!H22+'12'!H22+'13'!H22+'14'!H22+'16'!H22+'17'!H22+'19'!H22+'20'!H22+'21'!H22+'23'!H22+'24'!H22+'27'!H22+'28'!H22+'30'!H22+'31'!H22 -> 3 | I24: 50 | J24: =+'1'!J22+'2'!J22+'3'!J22+'4'!J22+'5'!J22+'6'!J22+'7'!J22+'9'!J22+'10'!J22+'12'!J22+'13'!J22+'14'!J22+'16'!J22+'17'!J22+'19'!J22+'20'!J22+'21'!J22+'23'!J22+'24'!J22+'27'!J22+'28'!J22+'30'!J22+'31'!J22 -> 150 | L24: 20 | M24: =+'20'!J23 -> 200 | R24: =+'20'!J25 -> 0 | S24: =+M24-N24-P24-R24-Q24 -> 200 | T24: =+'20'!J26 -> 200 | U24: =+T24-S24 -> 0
A25: 21 | C25: 0 | D25: =+'16'!F23 -> 0 | E25: =+C25+D25 -> 0 | F25: =+'19'!G23+'30'!G23 -> 0 | G25: 0 | H25: =+'1'!H23+'2'!H23+'3'!H23+'4'!H23+'5'!H23+'6'!H23+'7'!H23+'9'!H23+'10'!H23+'12'!H23+'13'!H23+'14'!H23+'16'!H23+'17'!H23+'19'!H23+'20'!H23+'21'!H23+'23'!H23+'24'!H23+'27'!H23+'28'!H23+'30'!H23+'31'!H23 -> 0 | I25: 0 | J25: 0 | L25: 21 | M25: =+'21'!J23 -> 200 | R25: =+'21'!J25 -> 0 | S25: =+M25-N25-P25-R25-Q25 -> 200 | T25: =+'21'!J26 -> 200 | U25: =+T25-S25 -> 0
A26: 22 | C26: 0 | D26: =+'16'!F24 -> 0 | E26: =+C26+D26 -> 0 | F26: =+'19'!G24+'30'!G24 -> 0 | G26: 0 | H26: =+'1'!H24+'2'!H24+'3'!H24+'4'!H24+'5'!H24+'6'!H24+'7'!H24+'9'!H24+'10'!H24+'12'!H24+'13'!H24+'14'!H24+'16'!H24+'17'!H24+'19'!H24+'20'!H24+'21'!H24+'23'!H24+'24'!H24+'27'!H24+'28'!H24+'30'!H24+'31'!H24 -> 0 | I26: 0 | J26: =+'1'!J24+'2'!J24+'3'!J24+'4'!J24+'5'!J24+'6'!J24+'7'!J24+'9'!J24+'10'!J24+'12'!J24+'13'!J24+'14'!J24+'16'!J24+'17'!J24+'19'!J24+'20'!J24+'21'!J24+'23'!J24+'24'!J24+'27'!J24+'28'!J24+'30'!J24+'31'!J24 -> 0 | L26: 22 | M26: 0 | O26: หยุด | R26: 0 | S26: =+M26-N26-P26-R26-Q26 -> 0 | T26: 0 | U26: =+T26-S26 -> 0
A27: 23 | C27: 0 | D27: =+'16'!F25 -> 0 | E27: =+C27+D27 -> 0 | F27: =+'19'!G25+'30'!G25 -> 0 | G27: 0 | H27: =+'1'!H25+'2'!H25+'3'!H25+'4'!H25+'5'!H25+'6'!H25+'7'!H25+'9'!H25+'10'!H25+'12'!H25+'13'!H25+'14'!H25+'16'!H25+'17'!H25+'19'!H25+'20'!H25+'21'!H25+'23'!H25+'24'!H25+'27'!H25+'28'!H25+'30'!H25+'31'!H25 -> 0 | I27: 0 | J27: 0 | L27: 23 | M27: 0 | O27: ขายไม่ได้ | R27: 0 | S27: =+M27-N27-P27-R27-Q27 -> 0 | T27: 0 | U27: =+T27-S27 -> 0
A28: 24 | C28: 0 | D28: =+'16'!F26 -> 0 | E28: =+C28+D28 -> 0 | F28: =+'19'!G26+'30'!G26 -> 0 | G28: 0 | H28: =+'1'!H26+'2'!H26+'3'!H26+'4'!H26+'5'!H26+'6'!H26+'7'!H26+'9'!H26+'10'!H26+'12'!H26+'13'!H26+'14'!H26+'16'!H26+'17'!H26+'19'!H26+'20'!H26+'21'!H26+'23'!H26+'24'!H26+'27'!H26+'28'!H26+'30'!H26+'31'!H26 -> 0 | I28: 0 | J28: 0 | L28: 24 | M28: =+'24'!J23 -> 150 | R28: =+'24'!J25 -> 0 | S28: =+M28-N28-P28-R28-Q28 -> 150 | T28: =+'24'!J26 -> 150 | U28: =+T28-S28 -> 0
A29: 25 | C29: 0 | D29: =+'16'!F27 -> 0 | E29: =+C29+D29 -> 0 | F29: =+'19'!G27+'30'!G27 -> 0 | G29: 0 | H29: =+'1'!H27+'2'!H27+'3'!H27+'4'!H27+'5'!H27+'6'!H27+'7'!H27+'9'!H27+'10'!H27+'12'!H27+'13'!H27+'14'!H27+'16'!H27+'17'!H27+'19'!H27+'20'!H27+'21'!H27+'23'!H27+'24'!H27+'27'!H27+'28'!H27+'30'!H27+'31'!H27 -> 0 | I29: 0 | J29: =+'1'!J27+'2'!J27+'3'!J27+'4'!J27+'5'!J27+'6'!J27+'7'!J27+'9'!J27+'10'!J27+'12'!J27+'13'!J27+'14'!J27+'16'!J27+'17'!J27+'19'!J27+'20'!J27+'21'!J27+'23'!J27+'24'!J27+'27'!J27+'28'!J27+'30'!J27+'31'!J27 -> 0 | L29: 25 | M29: 0 | O29: หยุด | R29: 0 | S29: =+M29-N29-P29-R29-Q29 -> 0 | T29: 0 | U29: =+T29-S29 -> 0
A30: 26 | C30: 0 | D30: =+'16'!F28 -> 0 | E30: =+C30+D30 -> 0 | F30: =+'19'!G28+'30'!G28 -> 0 | G30: 0 | H30: =+'1'!H28+'2'!H28+'3'!H28+'4'!H28+'5'!H28+'6'!H28+'7'!H28+'9'!H28+'10'!H28+'12'!H28+'13'!H28+'14'!H28+'16'!H28+'17'!H28+'19'!H28+'20'!H28+'21'!H28+'23'!H28+'24'!H28+'27'!H28+'28'!H28+'30'!H28+'31'!H28 -> 0 | I30: 0 | J30: =+'1'!J28+'2'!J28+'3'!J28+'4'!J28+'5'!J28+'6'!J28+'7'!J28+'9'!J28+'10'!J28+'12'!J28+'13'!J28+'14'!J28+'16'!J28+'17'!J28+'19'!J28+'20'!J28+'21'!J28+'23'!J28+'24'!J28+'27'!J28+'28'!J28+'30'!J28+'31'!J28 -> 0 | L30: 26 | M30: 0 | O30: ขายไม่ได้ | R30: 0 | S30: =+M30-N30-P30-R30-Q30 -> 0 | T30: 0 | U30: =+T30-S30 -> 0
A31: 27 | C31: 0 | D31: =+'16'!F29 -> 0 | E31: =+C31+D31 -> 0 | F31: =+'19'!G29+'30'!G29 -> 0 | G31: 0 | H31: =+'1'!H29+'2'!H29+'3'!H29+'4'!H29+'5'!H29+'6'!H29+'7'!H29+'9'!H29+'10'!H29+'12'!H29+'13'!H29+'14'!H29+'16'!H29+'17'!H29+'19'!H29+'20'!H29+'21'!H29+'23'!H29+'24'!H29+'27'!H29+'28'!H29+'30'!H29+'31'!H29 -> 0 | I31: 0 | J31: =+'1'!J29+'2'!J29+'3'!J29+'4'!J29+'5'!J29+'6'!J29+'7'!J29+'9'!J29+'10'!J29+'12'!J29+'13'!J29+'14'!J29+'16'!J29+'17'!J29+'19'!J29+'20'!J29+'21'!J29+'23'!J29+'24'!J29+'27'!J29+'28'!J29+'30'!J29+'31'!J29 -> 0 | L31: 27 | M31: =+'27'!J23 -> 235 | R31: =+'27'!J25 -> 80 | S31: =+M31-N31-P31-R31-Q31 -> 155 | T31: =+'27'!J26 -> 155 | U31: =+T31-S31 -> 0
A32: 28 | C32: 0 | D32: =+'16'!F30 -> 0 | E32: =+C32+D32 -> 0 | F32: =+'19'!G30+'30'!G30 -> 0 | G32: 0 | H32: =+'1'!H30+'2'!H30+'3'!H30+'4'!H30+'5'!H30+'6'!H30+'7'!H30+'9'!H30+'10'!H30+'12'!H30+'13'!H30+'14'!H30+'16'!H30+'17'!H30+'19'!H30+'20'!H30+'21'!H30+'23'!H30+'24'!H30+'27'!H30+'28'!H30+'30'!H30+'31'!H30 -> 0 | I32: 0 | J32: =+'1'!J30+'2'!J30+'3'!J30+'4'!J30+'5'!J30+'6'!J30+'7'!J30+'9'!J30+'10'!J30+'12'!J30+'13'!J30+'14'!J30+'16'!J30+'17'!J30+'19'!J30+'20'!J30+'21'!J30+'23'!J30+'24'!J30+'27'!J30+'28'!J30+'30'!J30+'31'!J30 -> 0 | L32: 28 | M32: =+'28'!J23 -> 350 | R32: =+'28'!J25 -> 0 | S32: =+M32-N32-P32-R32-Q32 -> 350 | T32: =+'28'!J26 -> 350 | U32: =+T32-S32 -> 0
A33: 29 | C33: 0 | D33: =+'16'!F31 -> 0 | E33: =+C33+D33 -> 0 | F33: =+'19'!G31+'30'!G31 -> 0 | G33: 0 | H33: =+'1'!H31+'2'!H31+'3'!H31+'4'!H31+'5'!H31+'6'!H31+'7'!H31+'9'!H31+'10'!H31+'12'!H31+'13'!H31+'14'!H31+'16'!H31+'17'!H31+'19'!H31+'20'!H31+'21'!H31+'23'!H31+'24'!H31+'27'!H31+'28'!H31+'30'!H31+'31'!H31 -> 0 | I33: 0 | J33: =+'1'!J31+'2'!J31+'3'!J31+'4'!J31+'5'!J31+'6'!J31+'7'!J31+'9'!J31+'10'!J31+'12'!J31+'13'!J31+'14'!J31+'16'!J31+'17'!J31+'19'!J31+'20'!J31+'21'!J31+'23'!J31+'24'!J31+'27'!J31+'28'!J31+'30'!J31+'31'!J31 -> 0 | L33: 29 | M33: 0 | O33: หยุด | R33: 0 | S33: =+M33-N33-P33-R33-Q33 -> 0 | T33: 0 | U33: =+T33-S33 -> 0
A34: 30 | C34: 0 | D34: =+'16'!F32 -> 0 | E34: =+C34+D34 -> 0 | F34: =+'19'!G32+'30'!G32 -> 0 | G34: 0 | H34: =+'1'!H32+'2'!H32+'3'!H32+'4'!H32+'5'!H32+'6'!H32+'7'!H32+'9'!H32+'10'!H32+'12'!H32+'13'!H32+'14'!H32+'16'!H32+'17'!H32+'19'!H32+'20'!H32+'21'!H32+'23'!H32+'24'!H32+'27'!H32+'28'!H32+'30'!H32+'31'!H32 -> 0 | I34: 0 | J34: =+'1'!J32+'2'!J32+'3'!J32+'4'!J32+'5'!J32+'6'!J32+'7'!J32+'9'!J32+'10'!J32+'12'!J32+'13'!J32+'14'!J32+'16'!J32+'17'!J32+'19'!J32+'20'!J32+'21'!J32+'23'!J32+'24'!J32+'27'!J32+'28'!J32+'30'!J32+'31'!J32 -> 0 | L34: 30 | M34: 0 | O34: ขายไม่ได้ | P34: 0 | Q34: 0 | R34: =+'[1]30.12'!J18 -> 0 | S34: =+M34-N34-P34-R34-Q34 -> 0 | T34: 0 | U34: =+T34-S34 -> 0
A35: 31 | C35: 0 | D35: =+'16'!F33 -> 0 | E35: =+C35+D35 -> 0 | F35: =+'19'!G33+'30'!G33 -> 0 | G35: 0 | H35: =+'1'!H33+'2'!H33+'3'!H33+'4'!H33+'5'!H33+'6'!H33+'7'!H33+'9'!H33+'10'!H33+'12'!H33+'13'!H33+'14'!H33+'16'!H33+'17'!H33+'19'!H33+'20'!H33+'21'!H33+'23'!H33+'24'!H33+'27'!H33+'28'!H33+'30'!H33+'31'!H33 -> 0 | I35: 0 | J35: =+'1'!J33+'2'!J33+'3'!J33+'4'!J33+'5'!J33+'6'!J33+'7'!J33+'9'!J33+'10'!J33+'12'!J33+'13'!J33+'14'!J33+'16'!J33+'17'!J33+'19'!J33+'20'!J33+'21'!J33+'23'!J33+'24'!J33+'27'!J33+'28'!J33+'30'!J33+'31'!J33 -> 0 | L35: 31 | M35: =+'31'!J23 -> 1750 | R35: =+'31'!J25 -> 0 | S35: =+M35-N35-P35-R35-Q35 -> 1750 | T35: =+'31'!J26 -> 1750 | U35: =+T35-S35 -> 0
A36: 32 | C36: 0 | D36: =+'16'!F34 -> 0 | E36: =+C36+D36 -> 0 | F36: =+'19'!G34+'30'!G34 -> 0 | G36: 0 | H36: =+'1'!H34+'2'!H34+'3'!H34+'4'!H34+'5'!H34+'6'!H34+'7'!H34+'9'!H34+'10'!H34+'12'!H34+'13'!H34+'14'!H34+'16'!H34+'17'!H34+'19'!H34+'20'!H34+'21'!H34+'23'!H34+'24'!H34+'27'!H34+'28'!H34+'30'!H34+'31'!H34 -> 0 | I36: 0 | J36: =+'1'!J34+'2'!J34+'3'!J34+'4'!J34+'5'!J34+'6'!J34+'7'!J34+'9'!J34+'10'!J34+'12'!J34+'13'!J34+'14'!J34+'16'!J34+'17'!J34+'19'!J34+'20'!J34+'21'!J34+'23'!J34+'24'!J34+'27'!J34+'28'!J34+'30'!J34+'31'!J34 -> 0 | L36: รวม | M36: =SUM(M5:M35) -> 8825 | N36: =SUM(N5:N35) -> 0 | O36: =SUM(O5:O35) -> 0 | P36: =SUM(P5:P35) -> 30 | Q36: =SUM(Q5:Q35) -> 0 | R36: 0 | S36: =SUM(S5:S35) -> 8265 | T36: 0 | U36: =SUM(U5:U35) -> 0
A37: 33 | C37: 0 | D37: =+'16'!F35 -> 0 | E37: =+C37+D37 -> 0 | F37: =+'19'!G35+'30'!G35 -> 0 | G37: 0 | H37: =+'1'!H35+'2'!H35+'3'!H35+'4'!H35+'5'!H35+'6'!H35+'7'!H35+'9'!H35+'10'!H35+'12'!H35+'13'!H35+'14'!H35+'16'!H35+'17'!H35+'19'!H35+'20'!H35+'21'!H35+'23'!H35+'24'!H35+'27'!H35+'28'!H35+'30'!H35+'31'!H35 -> 0 | I37: 0 | J37: =+'1'!J35+'2'!J35+'3'!J35+'4'!J35+'5'!J35+'6'!J35+'7'!J35+'9'!J35+'10'!J35+'12'!J35+'13'!J35+'14'!J35+'16'!J35+'17'!J35+'19'!J35+'20'!J35+'21'!J35+'23'!J35+'24'!J35+'27'!J35+'28'!J35+'30'!J35+'31'!J35 -> 0
A38: 34 | C38: 0 | D38: =+'16'!F36 -> 0 | E38: =+C38+D38 -> 0 | F38: =+'19'!G36+'30'!G36 -> 0 | G38: 0 | H38: =+'1'!H36+'2'!H36+'3'!H36+'4'!H36+'5'!H36+'6'!H36+'7'!H36+'9'!H36+'10'!H36+'12'!H36+'13'!H36+'14'!H36+'16'!H36+'17'!H36+'19'!H36+'20'!H36+'21'!H36+'23'!H36+'24'!H36+'27'!H36+'28'!H36+'30'!H36+'31'!H36 -> 0 | I38: 0 | J38: =+'1'!J36+'2'!J36+'3'!J36+'4'!J36+'5'!J36+'6'!J36+'7'!J36+'9'!J36+'10'!J36+'12'!J36+'13'!J36+'14'!J36+'16'!J36+'17'!J36+'19'!J36+'20'!J36+'21'!J36+'23'!J36+'24'!J36+'27'!J36+'28'!J36+'30'!J36+'31'!J36 -> 0
A39: 35 | C39: 0 | D39: =+'16'!F37 -> 0 | E39: =+C39+D39 -> 0 | F39: =+'19'!G37+'30'!G37 -> 0 | G39: 0 | H39: =+'1'!H37+'2'!H37+'3'!H37+'4'!H37+'5'!H37+'6'!H37+'7'!H37+'9'!H37+'10'!H37+'12'!H37+'13'!H37+'14'!H37+'16'!H37+'17'!H37+'19'!H37+'20'!H37+'21'!H37+'23'!H37+'24'!H37+'27'!H37+'28'!H37+'30'!H37+'31'!H37 -> 0 | I39: 0 | J39: =+'1'!J37+'2'!J37+'3'!J37+'4'!J37+'5'!J37+'6'!J37+'7'!J37+'9'!J37+'10'!J37+'12'!J37+'13'!J37+'14'!J37+'16'!J37+'17'!J37+'19'!J37+'20'!J37+'21'!J37+'23'!J37+'24'!J37+'27'!J37+'28'!J37+'30'!J37+'31'!J37 -> 0
