Workbook

Sheet 1
A1: ใบสต๊อกบูธ 10323 วัดใหม่สุปดิษฐาราม
A2: ลำดับ | B2: รหัส | C2: รายการสินค้า | D2: ราคา | E2: ยอดยกมา | F2: รับเข้า | G2: ส่งคืน | H2: ขายออก | I2: คงเหลือ | J2: ยอดเงิน | K2: หมายเหตุ
A3: 1 | B3: 1005982 | C3: ปังเนยนิ่ม 3 ชิ้น | D3: 55 | E3: 1 | H3: 1 | J3: 55
A4: 2 | B4: 1200001 | C4: คอนเฟลกกระปุก | D4: 60 | E4: 2 | H4: 1 | I4: 1 | J4: 60
A5: 3 | B5: 1100003 | C5: เมอแรงค์กระปุก | D5: 55 | E5: 5 | H5: 1 | I5: 4 | J5: 55
A6: 4 | B6: 1200003 | C6: ท๊อฟฟี่กระเช้า | D6: 100 | E6: 2 | I6: 2
A7: 5 | B7: 1113121 | C7: เปี๊ยะไส้ถั่ว | D7: 120 | E7: 5 | H7: 1 | I7: 4 | J7: 120
A8: 6 | B8: 1113123 | C8: เปี๊ยะไส้เผือก | D8: 120 | E8: 1 | H8: 1 | J8: 120
A9: 7 | B9: 1113122 | C9: เปี๊ยะไส้ฟัก | D9: 120 | E9: 4 | I9: 4
A10: 8 | B10: 1004055 | C10: ชิฟฟ่อนรวมรส 4 ชิ้น | D10: 55 | E10: 2 | H10: 2 | J10: 110
A11: 9 | B11: 1111002 | C11: ชิฟฟ่อนรวมรส 8 ชิ้น | D11: 100 | E11: 9 | H11: 9 | J11: 900
A12: 10 | B12: 1111056 | C12: ชิฟฟ่อนยอดฮิต | D12: 100 | F12: 20 | H12: 14 | I12: 6 | J12: 1400
A13: 11 | B13: 1111009 | C13: ชิฟฟ่อนสอดไส้รวมรส 6 ชิ้น | D13: 100 | F13: 20 | H13: 8 | I13: 12 | J13: 800
A14: 12 | B14: 1112009 | C14: เบาหวิวมะพร้าวน้ำหอม 110 กรัม | D14: 50
A15: 13 | B15: 1112010 | C15: เบาหวิวฝอยทอง 300 กรัม | D15: 120
A16: 14 | B16: 1112011 | C16: เบาหวิวฝอยทอง 110 กรัม | D16: 50
A17: 15 | B17: 1111017 | C17: ชิฟฟ่อนสอดไส้แยมบลูเบอร์รี่ 3 ชิ้น | D17: 55
A18: 16 | B18: 1111012 | C18: ชิฟฟ่อนสอดไส้นมชมพูฮอกไกโด 6 ชิ้น | D18: 100
A19: 17 | B19: 1112012 | C19: เบาหวิวเผือกมะพร้าว 300 กรัม | D19: 120
A20: 18 | B20: 1112013 | C20: เบาหวิวเผือกมะพร้าว 110 กรัม | D20: 50 | E20: 1 | H20: 1 | J20: 50
A21: 19 | B21: 1113131 | C21: เปี๊ยะโมจิฟัก 350 กรัม | D21: 120
A22: 20 | B22: 1113135 | C22: เปี๊ยะโมจิฟัก 700 กรัม | D22: 185
A23: 21 | B23: 1112017 | C23: เบาหวิวตาลหอม 110 กรัม | D23: 50 | E23: 1 | H23: 1 | J23: 50
A24: 22 | B24: 1112015 | C24: เบาหวิวกล้วยหอมมะพร้าวเผา 110 กรัม | D24: 50 | E24: 1 | H24: 1 | J24: 50
A25: 23 | B25: 1112005 | C25: เบาหวิวเนยสด 110 กรัม | D25: 50
A26: 24 | C26: เบาหวิวทุเรียน 110 กรัม | D26: 50
A27: 25 | B27: 1112003 | C27: เบาหวิวกาแฟ 110 กรัม | D27: 50
A28: 26 | C28: รถลาน | D28: 45 | E28: 44 | F28: 6 | H28: 5 | I28: 45 | J28: 225
A29: 27 | C29: หัวรถไฟโทมัส | D29: 150 | E29: 3 | F29: 9 | G29: 1 | H29: 3 | I29: 8 | J29: 450
A30: 28 | C30: ปืน | D30: 150 | F30: 5 | I30: 5
A31: 29 | C31: โมเดลฮีโร่ | D31: 250
A32: 30 | C32: กระดานวาดเขียน | D32: 250
A33: 31 | C33: เป็ดแม่ | D33: 250
A34: 32 | C34: เป็ดลูก | D34: 150 | E34: 3 | I34: 3
A35: 33 | C35: ตัวบีบ | D35: 60 | E35: 10 | H35: 3 | I35: 7 | J35: 180
A36: 34 | C36: ลานม้า | D36: 100 | E36: 1 | I36: 1
A37: 35 | C37: กระดานวาดเขียน(ใหม่) | D37: 200
A38: 36 | C38: ตุ๊กตา | D38: 150
A39: 37 | C39: ตุ๊กตานางฟ้าเต้น | D39: 400 | E39: 1 | I39: 1
A40: 38 | C40: สลาม | D40: 100 | E40: 27 | F40: 12 | H40: 3 | I40: 36 | J40: 300
...

Sheet 3
A1: ใบสต๊อกบูธ 10323 วัดใหม่สุปดิษฐาราม
A2: ลำดับ | B2: รหัส | C2: รายการสินค้า | D2: ราคา | E2: ยอดยกมา | F2: รับเข้า | G2: ส่งคืน | H2: ขายออก | I2: คงเหลือ | J2: ยอดเงิน | K2: หมายเหตุ
A3: 1 | B3: 1005982 | C3: ปังเนยนิ่ม 3 ชิ้น | D3: 55 | F3: 3 | I3: 3
A4: 2 | B4: 1200001 | C4: คอนเฟลกกระปุก | D4: 60 | E4: 1 | I4: 1
A5: 3 | B5: 1100003 | C5: เมอแรงค์กระปุก | D5: 55 | E5: 4 | I5: 4
A6: 4 | B6: 1200003 | C6: ท๊อฟฟี่กระเช้า | D6: 100 | E6: 2 | F6: 5 | H6: 1 | I6: 6 | J6: 100
A7: 5 | B7: 1113121 | C7: เปี๊ยะไส้ถั่ว | D7: 120 | E7: 4 | I7: 4
A8: 6 | B8: 1113123 | C8: เปี๊ยะไส้เผือก | D8: 120 | F8: 5 | I8: 5
A9: 7 | B9: 1113122 | C9: เปี๊ยะไส้ฟัก | D9: 120 | E9: 4 | I9: 4
A10: 8 | B10: 1004055 | C10: ชิฟฟ่อนรวมรส 4 ชิ้น | D10: 55 | F10: 10 | I10: 10
A11: 9 | B11: 1111002 | C11: ชิฟฟ่อนรวมรส 8 ชิ้น | D11: 100 | F11: 10 | I11: 10
A12: 10 | B12: 1111056 | C12: ชิฟฟ่อนยอดฮิต | D12: 100 | E12: 6 | F12: 10 | H12: 2 | I12: 14 | J12: 200
A13: 11 | B13: 1111009 | C13: ชิฟฟ่อนสอดไส้รวมรส 6 ชิ้น | D13: 100 | E13: 12 | H13: 1 | I13: 11 | J13: 100
A14: 12 | B14: 1112009 | C14: เบาหวิวมะพร้าวน้ำหอม 110 กรัม | D14: 50 | F14: 10 | I14: 10
A15: 13 | B15: 1112010 | C15: เบาหวิวฝอยทอง 300 กรัม | D15: 120
A16: 14 | B16: 1112011 | C16: เบาหวิวฝอยทอง 110 กรัม | D16: 50
A17: 15 | B17: 1111017 | C17: ชิฟฟ่อนสอดไส้แยมบลูเบอร์รี่ 3 ชิ้น | D17: 55
A18: 16 | B18: 1111012 | C18: ชิฟฟ่อนสอดไส้นมชมพูฮอกไกโด 6 ชิ้น | D18: 100
A19: 17 | B19: 1112012 | C19: เบาหวิวเผือกมะพร้าว 300 กรัม | D19: 120
A20: 18 | B20: 1112013 | C20: เบาหวิวเผือกมะพร้าว 110 กรัม | D20: 50 | F20: 10 | I20: 10
A21: 19 | B21: 1113131 | C21: เปี๊ยะโมจิฟัก 350 กรัม | D21: 120
A22: 20 | B22: 1113135 | C22: เปี๊ยะโมจิฟัก 700 กรัม | D22: 185
A23: 21 | B23: 1112017 | C23: เบาหวิวตาลหอม 110 กรัม | D23: 50 | F23: 10 | I23: 10
A24: 22 | B24: 1112015 | C24: เบาหวิวกล้วยหอมมะพร้าวเผา 110 กรัม | D24: 50 | F24: 10 | I24: 10
A25: 23 | B25: 1112005 | C25: เบาหวิวเนยสด 110 กรัม | D25: 50
A26: 24 | C26: เบาหวิวทุเรียน 110 กรัม | D26: 50
A27: 25 | B27: 1112003 | C27: เบาหวิวกาแฟ 110 กรัม | D27: 50
A28: 26 | C28: รถลาน | D28: 45 | E28: 45 | I28: 45
A29: 27 | C29: หัวรถไฟโทมัส | D29: 150 | E29: 8 | G29: 1 | H29: 1 | I29: 6 | J29: 150
A30: 28 | C30: ปืน | D30: 150 | E30: 5 | I30: 5
A31: 29 | C31: โมเดลฮีโร่ | D31: 250
A32: 30 | C32: กระดานวาดเขียน | D32: 250
A33: 31 | C33: เป็ดแม่ | D33: 250
A34: 32 | C34: เป็ดลูก | D34: 150 | E34: 3 | I34: 3
A35: 33 | C35: ตัวบีบ | D35: 60 | E35: 7 | I35: 7
A36: 34 | C36: ลานม้า | D36: 100 | E36: 1 | I36: 1
A37: 35 | C37: กระดานวาดเขียน(ใหม่) | D37: 200
A38: 36 | C38: ตุ๊กตา | D38: 150
A39: 37 | C39: ตุ๊กตานางฟ้าเต้น | D39: 400 | E39: 1 | I39: 1
A40: 38 | C40: สลาม | D40: 100 | E40: 36 | I40: 36
...

Sheet 4
A1: ใบสต๊อกบูธ 10323 วัดใหม่สุปดิษฐาราม
A2: ลำดับ | B2: รหัส | C2: รายการสินค้า | D2: ราคา | E2: ยอดยกมา | F2: รับเข้า | G2: ส่งคืน | H2: ขายออก | I2: คงเหลือ | J2: ยอดเงิน | K2: หมายเหตุ
A3: 1 | B3: 1005982 | C3: ปังเนยนิ่ม 3 ชิ้น | D3: 55 | E3: 3 | H3: 1 | I3: 2 | J3: 55
A4: 2 | B4: 1200001 | C4: คอนเฟลกกระปุก | D4: 60 | E4: 1 | I4: 1
A5: 3 | B5: 1100003 | C5: เมอแรงค์กระปุก | D5: 55 | E5: 4 | I5: 4
A6: 4 | B6: 1200003 | C6: ท๊อฟฟี่กระเช้า | D6: 100 | E6: 6 | H6: 2 | I6: 4 | J6: 200
A7: 5 | B7: 1113121 | C7: เปี๊ยะไส้ถั่ว | D7: 120 | E7: 4 | I7: 4
A8: 6 | B8: 1113123 | C8: เปี๊ยะไส้เผือก | D8: 120 | E8: 5 | H8: 1 | I8: 4 | J8: 120
A9: 7 | B9: 1113122 | C9: เปี๊ยะไส้ฟัก | D9: 120 | E9: 4 | I9: 4
A10: 8 | B10: 1004055 | C10: ชิฟฟ่อนรวมรส 4 ชิ้น | D10: 55 | E10: 10 | H10: 1 | I10: 9 | J10: 55
A11: 9 | B11: 1111002 | C11: ชิฟฟ่อนรวมรส 8 ชิ้น | D11: 100 | E11: 10 | I11: 10
A12: 10 | B12: 1111056 | C12: ชิฟฟ่อนยอดฮิต | D12: 100 | E12: 14 | H12: 2 | I12: 12 | J12: 200
A13: 11 | B13: 1111009 | C13: ชิฟฟ่อนสอดไส้รวมรส 6 ชิ้น | D13: 100 | E13: 11 | H13: 2 | I13: 9 | J13: 200
A14: 12 | B14: 1112009 | C14: เบาหวิวมะพร้าวน้ำหอม 110 กรัม | D14: 50 | E14: 10 | H14: 1 | I14: 9 | J14: 50
A15: 13 | B15: 1112010 | C15: เบาหวิวฝอยทอง 300 กรัม | D15: 120
A16: 14 | B16: 1112011 | C16: เบาหวิวฝอยทอง 110 กรัม | D16: 50
A17: 15 | B17: 1111017 | C17: ชิฟฟ่อนสอดไส้แยมบลูเบอร์รี่ 3 ชิ้น | D17: 55
A18: 16 | B18: 1111012 | C18: ชิฟฟ่อนสอดไส้นมชมพูฮอกไกโด 6 ชิ้น | D18: 100
A19: 17 | B19: 1112012 | C19: เบาหวิวเผือกมะพร้าว 300 กรัม | D19: 120
A20: 18 | B20: 1112013 | C20: เบาหวิวเผือกมะพร้าว 110 กรัม | D20: 50 | E20: 10 | H20: 2 | I20: 8 | J20: 100
A21: 19 | B21: 1113131 | C21: เปี๊ยะโมจิฟัก 350 กรัม | D21: 120
A22: 20 | B22: 1113135 | C22: เปี๊ยะโมจิฟัก 700 กรัม | D22: 185
A23: 21 | B23: 1112017 | C23: เบาหวิวตาลหอม 110 กรัม | D23: 50 | E23: 10 | H23: 1 | I23: 9 | J23: 50
A24: 22 | B24: 1112015 | C24: เบาหวิวกล้วยหอมมะพร้าวเผา 110 กรัม | D24: 50 | E24: 10 | I24: 10
A25: 23 | B25: 1112005 | C25: เบาหวิวเนยสด 110 กรัม | D25: 50
A26: 24 | C26: เบาหวิวทุเรียน 110 กรัม | D26: 50
A27: 25 | B27: 1112003 | C27: เบาหวิวกาแฟ 110 กรัม | D27: 50
A28: 26 | C28: รถลาน | D28: 45 | E28: 45 | I28: 45
A29: 27 | C29: หัวรถไฟโทมัส | D29: 150 | E29: 6 | I29: 6
A30: 28 | C30: ปืน | D30: 150 | E30: 5 | I30: 5
A31: 29 | C31: โมเดลฮีโร่ | D31: 250
A32: 30 | C32: กระดานวาดเขียน | D32: 250
A33: 31 | C33: เป็ดแม่ | D33: 250
A34: 32 | C34: เป็ดลูก | D34: 150 | E34: 3 | I34: 3
A35: 33 | C35: ตัวบีบ | D35: 60 | E35: 7 | H35: 1 | I35: 6 | J35: 60
A36: 34 | C36: ลานม้า | D36: 100 | E36: 1 | I36: 1
A37: 35 | C37: กระดานวาดเขียน(ใหม่) | D37: 200
A38: 36 | C38: ตุ๊กตา | D38: 150
A39: 37 | C39: ตุ๊กตานางฟ้าเต้น | D39: 400 | E39: 1 | I39: 1
A40: 38 | C40: สลาม | D40: 100 | E40: 36 | H40: 2 | I40: 34 | J40: 200
...

Sheet 5
A1: ใบสต๊อกบูธ 10323 วัดใหม่สุปดิษฐาราม
A2: ลำดับ | B2: รหัส | C2: รายการสินค้า | D2: ราคา | E2: ยอดยกมา | F2: รับเข้า | G2: ส่งคืน | H2: ขายออก | I2: คงเหลือ | J2: ยอดเงิน | K2: หมายเหตุ
A3: 1 | B3: 1005982 | C3: ปังเนยนิ่ม 3 ชิ้น | D3: 55 | E3: 2 | H3: 2 | J3: 110
A4: 2 | B4: 1200001 | C4: คอนเฟลกกระปุก | D4: 60 | E4: 1 | I4: 1
A5: 3 | B5: 1100003 | C5: เมอแรงค์กระปุก | D5: 55 | E5: 4 | H5: 1 | I5: 3 | J5: 55
A6: 4 | B6: 1200003 | C6: ท๊อฟฟี่กระเช้า | D6: 100 | E6: 4 | H6: 2 | I6: 2 | J6: 200
A7: 5 | B7: 1113121 | C7: เปี๊ยะไส้ถั่ว | D7: 120 | E7: 4 | I7: 4
A8: 6 | B8: 1113123 | C8: เปี๊ยะไส้เผือก | D8: 120 | E8: 4 | H8: 1 | I8: 3 | J8: 120
A9: 7 | B9: 1113122 | C9: เปี๊ยะไส้ฟัก | D9: 120 | E9: 4 | H9: 1 | I9: 3 | J9: 120
A10: 8 | B10: 1004055 | C10: ชิฟฟ่อนรวมรส 4 ชิ้น | D10: 55 | E10: 9 | H10: 6 | I10: 3 | J10: 330
A11: 9 | B11: 1111002 | C11: ชิฟฟ่อนรวมรส 8 ชิ้น | D11: 100 | E11: 10 | H11: 1 | I11: 9 | J11: 100
A12: 10 | B12: 1111056 | C12: ชิฟฟ่อนยอดฮิต | D12: 100 | E12: 12 | H12: 2 | I12: 10 | J12: 200
A13: 11 | B13: 1111009 | C13: ชิฟฟ่อนสอดไส้รวมรส 6 ชิ้น | D13: 100 | E13: 9 | H13: 4 | I13: 5 | J13: 400
A14: 12 | B14: 1112009 | C14: เบาหวิวมะพร้าวน้ำหอม 110 กรัม | D14: 50 | E14: 9 | H14: 1 | I14: 8 | J14: 50
A15: 13 | B15: 1112010 | C15: เบาหวิวฝอยทอง 300 กรัม | D15: 120
A16: 14 | B16: 1112011 | C16: เบาหวิวฝอยทอง 110 กรัม | D16: 50
A17: 15 | B17: 1111017 | C17: ชิฟฟ่อนสอดไส้แยมบลูเบอร์รี่ 3 ชิ้น | D17: 55
A18: 16 | B18: 1111012 | C18: ชิฟฟ่อนสอดไส้นมชมพูฮอกไกโด 6 ชิ้น | D18: 100
A19: 17 | B19: 1112012 | C19: เบาหวิวเผือกมะพร้าว 300 กรัม | D19: 120
A20: 18 | B20: 1112013 | C20: เบาหวิวเผือกมะพร้าว 110 กรัม | D20: 50 | E20: 8 | H20: 2 | I20: 6 | J20: 100
A21: 19 | B21: 1113131 | C21: เปี๊ยะโมจิฟัก 350 กรัม | D21: 120
A22: 20 | B22: 1113135 | C22: เปี๊ยะโมจิฟัก 700 กรัม | D22: 185
A23: 21 | B23: 1112017 | C23: เบาหวิวตาลหอม 110 กรัม | D23: 50 | E23: 9 | H23: 1 | I23: 8 | J23: 50
A24: 22 | B24: 1112015 | C24: เบาหวิวกล้วยหอมมะพร้าวเผา 110 กรัม | D24: 50 | E24: 10 | H24: 1 | I24: 9 | J24: 50
A25: 23 | B25: 1112005 | C25: เบาหวิวเนยสด 110 กรัม | D25: 50
A26: 24 | C26: เบาหวิวทุเรียน 110 กรัม | D26: 50
A27: 25 | B27: 1112003 | C27: เบาหวิวกาแฟ 110 กรัม | D27: 50
A28: 26 | C28: รถลาน | D28: 45 | E28: 45 | I28: 45
A29: 27 | C29: หัวรถไฟโทมัส | D29: 150 | E29: 6 | I29: 6
A30: 28 | C30: ปืน | D30: 150 | E30: 5 | I30: 5
A31: 29 | C31: โมเดลฮีโร่ | D31: 250
A32: 30 | C32: กระดานวาดเขียน | D32: 250
A33: 31 | C33: เป็ดแม่ | D33: 250
A34: 32 | C34: เป็ดลูก | D34: 150 | E34: 3 | I34: 3
A35: 33 | C35: ตัวบีบ | D35: 60 | E35: 6 | I35: 6
A36: 34 | C36: ลานม้า | D36: 100 | E36: 1 | I36: 1
A37: 35 | C37: กระดานวาดเขียน(ใหม่) | D37: 200
A38: 36 | C38: ตุ๊กตา | D38: 150
A39: 37 | C39: ตุ๊กตานางฟ้าเต้น | D39: 400 | E39: 1 | I39: 1
A40: 38 | C40: สลาม | D40: 100 | E40: 34 | H40: 1 | I40: 33 | J40: 100
...

Sheet 6
A1: ใบสต๊อกบูธ 10323 วัดใหม่สุปดิษฐาราม
A2: ลำดับ | B2: รหัส | C2: รายการสินค้า | D2: ราคา | E2: ยอดยกมา | F2: รับเข้า | G2: ส่งคืน | H2: ขายออก | I2: คงเหลือ | J2: ยอดเงิน | K2: หมายเหตุ
A3: 1 | B3: 1005982 | C3: ปังเนยนิ่ม 3 ชิ้น | D3: 55
A4: 2 | B4: 1200001 | C4: คอนเฟลกกระปุก | D4: 60 | E4: 1 | I4: 1
A5: 3 | B5: 1100003 | C5: เมอแรงค์กระปุก | D5: 55 | E5: 3 | I5: 3
A6: 4 | B6: 1200003 | C6: ท๊อฟฟี่กระเช้า | D6: 100 | E6: 2 | H6: 1 | I6: 1 | J6: 100
A7: 5 | B7: 1113121 | C7: เปี๊ยะไส้ถั่ว | D7: 120 | E7: 4 | I7: 4
A8: 6 | B8: 1113123 | C8: เปี๊ยะไส้เผือก | D8: 120 | E8: 3 | I8: 3
A9: 7 | B9: 1113122 | C9: เปี๊ยะไส้ฟัก | D9: 120 | E9: 3 | I9: 3
A10: 8 | B10: 1004055 | C10: ชิฟฟ่อนรวมรส 4 ชิ้น | D10: 55 | E10: 3 | I10: 3
A11: 9 | B11: 1111002 | C11: ชิฟฟ่อนรวมรส 8 ชิ้น | D11: 100 | E11: 9 | I11: 9
A12: 10 | B12: 1111056 | C12: ชิฟฟ่อนยอดฮิต | D12: 100 | E12: 10 | H12: 3 | I12: 7 | J12: 300
A13: 11 | B13: 1111009 | C13: ชิฟฟ่อนสอดไส้รวมรส 6 ชิ้น | D13: 100 | E13: 5 | I13: 5
A14: 12 | B14: 1112009 | C14: เบาหวิวมะพร้าวน้ำหอม 110 กรัม | D14: 50 | E14: 8 | I14: 8
A15: 13 | B15: 1112010 | C15: เบาหวิวฝอยทอง 300 กรัม | D15: 120
A16: 14 | B16: 1112011 | C16: เบาหวิวฝอยทอง 110 กรัม | D16: 50
A17: 15 | B17: 1111017 | C17: ชิฟฟ่อนสอดไส้แยมบลูเบอร์รี่ 3 ชิ้น | D17: 55
A18: 16 | B18: 1111012 | C18: ชิฟฟ่อนสอดไส้นมชมพูฮอกไกโด 6 ชิ้น | D18: 100
A19: 17 | B19: 1112012 | C19: เบาหวิวเผือกมะพร้าว 300 กรัม | D19: 120
A20: 18 | B20: 1112013 | C20: เบาหวิวเผือกมะพร้าว 110 กรัม | D20: 50 | E20: 6 | I20: 6
A21: 19 | B21: 1113131 | C21: เปี๊ยะโมจิฟัก 350 กรัม | D21: 120
A22: 20 | B22: 1113135 | C22: เปี๊ยะโมจิฟัก 700 กรัม | D22: 185
A23: 21 | B23: 1112017 | C23: เบาหวิวตาลหอม 110 กรัม | D23: 50 | E23: 8 | I23: 8
A24: 22 | B24: 1112015 | C24: เบาหวิวกล้วยหอมมะพร้าวเผา 110 กรัม | D24: 50 | E24: 9 | I24: 9
A25: 23 | B25: 1112005 | C25: เบาหวิวเนยสด 110 กรัม | D25: 50
A26: 24 | C26: เบาหวิวทุเรียน 110 กรัม | D26: 50
A27: 25 | B27: 1112003 | C27: เบาหวิวกาแฟ 110 กรัม | D27: 50
A28: 26 | C28: รถลาน | D28: 45 | E28: 45 | I28: 45
A29: 27 | C29: หัวรถไฟโทมัส | D29: 150 | E29: 6 | I29: 6
A30: 28 | C30: ปืน | D30: 150 | E30: 5 | I30: 5
A31: 29 | C31: โมเดลฮีโร่ | D31: 250
A32: 30 | C32: กระดานวาดเขียน | D32: 250
A33: 31 | C33: เป็ดแม่ | D33: 250
A34: 32 | C34: เป็ดลูก | D34: 150 | E34: 3 | I34: 3
A35: 33 | C35: ตัวบีบ | D35: 60 | E35: 6 | I35: 6
A36: 34 | C36: ลานม้า | D36: 100 | E36: 1 | I36: 1
A37: 35 | C37: กระดานวาดเขียน(ใหม่) | D37: 200
A38: 36 | C38: ตุ๊กตา | D38: 150
A39: 37 | C39: ตุ๊กตานางฟ้าเต้น | D39: 400 | E39: 1 | I39: 1
A40: 38 | C40: สลาม | D40: 100 | E40: 33 | H40: 1 | I40: 32 | J40: 100
...

Sheet 7
A1: ใบสต๊อกบูธ 10323 วัดใหม่สุปดิษฐาราม
A2: ลำดับ | B2: รหัส | C2: รายการสินค้า | D2: ราคา | E2: ยอดยกมา | F2: รับเข้า | G2: ส่งคืน | H2: ขายออก | I2: คงเหลือ | J2: ยอดเงิน | K2: หมายเหตุ
A3: 1 | B3: 1005982 | C3: ปังเนยนิ่ม 3 ชิ้น | D3: 55
A4: 2 | B4: 1200001 | C4: คอนเฟลกกระปุก | D4: 60 | E4: 1 | I4: 1
A5: 3 | B5: 1100003 | C5: เมอแรงค์กระปุก | D5: 55 | E5: 3 | I5: 3
A6: 4 | B6: 1200003 | C6: ท๊อฟฟี่กระเช้า | D6: 100 | E6: 1 | I6: 1
A7: 5 | B7: 1113121 | C7: เปี๊ยะไส้ถั่ว | D7: 120 | E7: 4 | H7: 3 | I7: 1 | J7: 360
A8: 6 | B8: 1113123 | C8: เปี๊ยะไส้เผือก | D8: 120 | E8: 3 | I8: 3
A9: 7 | B9: 1113122 | C9: เปี๊ยะไส้ฟัก | D9: 120 | E9: 3 | I9: 3
A10: 8 | B10: 1004055 | C10: ชิฟฟ่อนรวมรส 4 ชิ้น | D10: 55 | E10: 3 | I10: 3
A11: 9 | B11: 1111002 | C11: ชิฟฟ่อนรวมรส 8 ชิ้น | D11: 100 | E11: 9 | H11: 3 | I11: 6 | J11: 300
A12: 10 | B12: 1111056 | C12: ชิฟฟ่อนยอดฮิต | D12: 100 | E12: 7 | H12: 4 | I12: 3 | J12: 400
A13: 11 | B13: 1111009 | C13: ชิฟฟ่อนสอดไส้รวมรส 6 ชิ้น | D13: 100 | E13: 5 | H13: 1 | I13: 4 | J13: 100
A14: 12 | B14: 1112009 | C14: เบาหวิวมะพร้าวน้ำหอม 110 กรัม | D14: 50 | E14: 8 | H14: 2 | I14: 6 | J14: 100
A15: 13 | B15: 1112010 | C15: เบาหวิวฝอยทอง 300 กรัม | D15: 120
A16: 14 | B16: 1112011 | C16: เบาหวิวฝอยทอง 110 กรัม | D16: 50
A17: 15 | B17: 1111017 | C17: ชิฟฟ่อนสอดไส้แยมบลูเบอร์รี่ 3 ชิ้น | D17: 55
A18: 16 | B18: 1111012 | C18: ชิฟฟ่อนสอดไส้นมชมพูฮอกไกโด 6 ชิ้น | D18: 100
A19: 17 | B19: 1112012 | C19: เบาหวิวเผือกมะพร้าว 300 กรัม | D19: 120
A20: 18 | B20: 1112013 | C20: เบาหวิวเผือกมะพร้าว 110 กรัม | D20: 50 | E20: 6 | H20: 1 | I20: 5 | J20: 50
A21: 19 | B21: 1113131 | C21: เปี๊ยะโมจิฟัก 350 กรัม | D21: 120
A22: 20 | B22: 1113135 | C22: เปี๊ยะโมจิฟัก 700 กรัม | D22: 185
A23: 21 | B23: 1112017 | C23: เบาหวิวตาลหอม 110 กรัม | D23: 50 | E23: 8 | H23: 1 | I23: 7 | J23: 50
A24: 22 | B24: 1112015 | C24: เบาหวิวกล้วยหอมมะพร้าวเผา 110 กรัม | D24: 50 | E24: 9 | H24: 3 | I24: 6 | J24: 150
A25: 23 | B25: 1112005 | C25: เบาหวิวเนยสด 110 กรัม | D25: 50
A26: 24 | C26: เบาหวิวทุเรียน 110 กรัม | D26: 50
A27: 25 | B27: 1112003 | C27: เบาหวิวกาแฟ 110 กรัม | D27: 50
A28: 26 | C28: รถลาน | D28: 45 | E28: 45 | I28: 45
A29: 27 | C29: หัวรถไฟโทมัส | D29: 150 | E29: 6 | H29: 1 | I29: 5 | J29: 150
A30: 28 | C30: ปืน | D30: 150 | E30: 5 | H30: 2 | I30: 3 | J30: 300
A31: 29 | C31: โมเดลฮีโร่ | D31: 250
A32: 30 | C32: กระดานวาดเขียน | D32: 250
A33: 31 | C33: เป็ดแม่ | D33: 250
A34: 32 | C34: เป็ดลูก | D34: 150 | E34: 3 | H34: 1 | I34: 2 | J34: 150
A35: 33 | C35: ตัวบีบ | D35: 60 | E35: 6 | I35: 6
A36: 34 | C36: ลานม้า | D36: 100 | E36: 1 | H36: 1 | J36: 100
A37: 35 | C37: กระดานวาดเขียน(ใหม่) | D37: 200
A38: 36 | C38: ตุ๊กตา | D38: 150
A39: 37 | C39: ตุ๊กตานางฟ้าเต้น | D39: 400 | E39: 1 | I39: 1
A40: 38 | C40: สลาม | D40: 100 | E40: 32 | H40: 1 | I40: 31 | J40: 100
...

Sheet 8
A1: ใบสต๊อกบูธ 10323 วัดใหม่สุปดิษฐาราม
A2: ลำดับ | B2: รหัส | C2: รายการสินค้า | D2: ราคา | E2: ยอดยกมา | F2: รับเข้า | G2: ส่งคืน | H2: ขายออก | I2: คงเหลือ | J2: ยอดเงิน | K2: หมายเหตุ
A3: 1 | B3: 1005982 | C3: ปังเนยนิ่ม 3 ชิ้น | D3: 55
A4: 2 | B4: 1200001 | C4: คอนเฟลกกระปุก | D4: 60 | E4: 1 | I4: 1
A5: 3 | B5: 1100003 | C5: เมอแรงค์กระปุก | D5: 55 | E5: 3 | I5: 3
A6: 4 | B6: 1200003 | C6: ท๊อฟฟี่กระเช้า | D6: 100 | E6: 1 | I6: 1
A7: 5 | B7: 1113121 | C7: เปี๊ยะไส้ถั่ว | D7: 120 | E7: 1 | I7: 1
A8: 6 | B8: 1113123 | C8: เปี๊ยะไส้เผือก | D8: 120 | E8: 3 | I8: 3
A9: 7 | B9: 1113122 | C9: เปี๊ยะไส้ฟัก | D9: 120 | E9: 3 | I9: 3
A10: 8 | B10: 1004055 | C10: ชิฟฟ่อนรวมรส 4 ชิ้น | D10: 55 | E10: 3 | I10: 3
A11: 9 | B11: 1111002 | C11: ชิฟฟ่อนรวมรส 8 ชิ้น | D11: 100 | E11: 6 | H11: 2 | I11: 4 | J11: 200
A12: 10 | B12: 1111056 | C12: ชิฟฟ่อนยอดฮิต | D12: 100 | E12: 3 | I12: 3
A13: 11 | B13: 1111009 | C13: ชิฟฟ่อนสอดไส้รวมรส 6 ชิ้น | D13: 100 | E13: 4 | H13: 1 | I13: 3 | J13: 100
A14: 12 | B14: 1112009 | C14: เบาหวิวมะพร้าวน้ำหอม 110 กรัม | D14: 50 | E14: 6 | I14: 6
A15: 13 | B15: 1112010 | C15: เบาหวิวฝอยทอง 300 กรัม | D15: 120
A16: 14 | B16: 1112011 | C16: เบาหวิวฝอยทอง 110 กรัม | D16: 50
A17: 15 | B17: 1111017 | C17: ชิฟฟ่อนสอดไส้แยมบลูเบอร์รี่ 3 ชิ้น | D17: 55
A18: 16 | B18: 1111012 | C18: ชิฟฟ่อนสอดไส้นมชมพูฮอกไกโด 6 ชิ้น | D18: 100
A19: 17 | B19: 1112012 | C19: เบาหวิวเผือกมะพร้าว 300 กรัม | D19: 120
A20: 18 | B20: 1112013 | C20: เบาหวิวเผือกมะพร้าว 110 กรัม | D20: 50 | E20: 5 | I20: 5
A21: 19 | B21: 1113131 | C21: เปี๊ยะโมจิฟัก 350 กรัม | D21: 120
A22: 20 | B22: 1113135 | C22: เปี๊ยะโมจิฟัก 700 กรัม | D22: 185
A23: 21 | B23: 1112017 | C23: เบาหวิวตาลหอม 110 กรัม | D23: 50 | E23: 7 | I23: 7
A24: 22 | B24: 1112015 | C24: เบาหวิวกล้วยหอมมะพร้าวเผา 110 กรัม | D24: 50 | E24: 6 | I24: 6
A25: 23 | B25: 1112005 | C25: เบาหวิวเนยสด 110 กรัม | D25: 50
A26: 24 | C26: เบาหวิวทุเรียน 110 กรัม | D26: 50
A27: 25 | B27: 1112003 | C27: เบาหวิวกาแฟ 110 กรัม | D27: 50
A28: 26 | C28: รถลาน | D28: 45 | E28: 45 | H28: 2 | I28: 43 | J28: 90
A29: 27 | C29: หัวรถไฟโทมัส | D29: 150 | E29: 5 | H29: 2 | I29: 3 | J29: 300
A30: 28 | C30: ปืน | D30: 150 | E30: 3 | I30: 3
A31: 29 | C31: โมเดลฮีโร่ | D31: 250
A32: 30 | C32: กระดานวาดเขียน | D32: 250
A33: 31 | C33: เป็ดแม่ | D33: 250
A34: 32 | C34: เป็ดลูก | D34: 150 | E34: 2 | I34: 2
A35: 33 | C35: ตัวบีบ | D35: 60 | E35: 6 | I35: 6
A36: 34 | C36: ลานม้า | D36: 100
A37: 35 | C37: กระดานวาดเขียน(ใหม่) | D37: 200
A38: 36 | C38: ตุ๊กตา | D38: 150
A39: 37 | C39: ตุ๊กตานางฟ้าเต้น | D39: 400 | E39: 1 | I39: 1
A40: 38 | C40: สลาม | D40: 100 | E40: 31 | H40: 1 | I40: 30 | J40: 100
...

Sheet 10
A1: ใบสต๊อกบูธ 10323 วัดใหม่สุปดิษฐาราม
A2: ลำดับ | B2: รหัส | C2: รายการสินค้า | D2: ราคา | E2: ยอดยกมา | F2: รับเข้า | G2: ส่งคืน | H2: ขายออก | I2: คงเหลือ | J2: ยอดเงิน | K2: หมายเหตุ
A3: 1 | B3: 1005982 | C3: ปังเนยนิ่ม 3 ชิ้น | D3: 55
A4: 2 | B4: 1200001 | C4: คอนเฟลกกระปุก | D4: 60 | E4: 1 | I4: 1
A5: 3 | B5: 1100003 | C5: เมอแรงค์กระปุก | D5: 55 | E5: 3 | I5: 3
A6: 4 | B6: 1200003 | C6: ท๊อฟฟี่กระเช้า | D6: 100 | E6: 1 | H6: 1 | J6: 100
A7: 5 | B7: 1113121 | C7: เปี๊ยะไส้ถั่ว | D7: 120 | E7: 1 | I7: 1
A8: 6 | B8: 1113123 | C8: เปี๊ยะไส้เผือก | D8: 120 | E8: 3 | H8: 2 | I8: 1 | J8: 240
A9: 7 | B9: 1113122 | C9: เปี๊ยะไส้ฟัก | D9: 120 | E9: 3 | I9: 3
A10: 8 | B10: 1004055 | C10: ชิฟฟ่อนรวมรส 4 ชิ้น | D10: 55 | E10: 3 | H10: 1 | I10: 2 | J10: 55
A11: 9 | B11: 1111002 | C11: ชิฟฟ่อนรวมรส 8 ชิ้น | D11: 100 | E11: 4 | H11: 4 | J11: 400
A12: 10 | B12: 1111056 | C12: ชิฟฟ่อนยอดฮิต | D12: 100 | E12: 3 | H12: 2 | I12: 1 | J12: 200
A13: 11 | B13: 1111009 | C13: ชิฟฟ่อนสอดไส้รวมรส 6 ชิ้น | D13: 100 | E13: 3 | I13: 3
A14: 12 | B14: 1112009 | C14: เบาหวิวมะพร้าวน้ำหอม 110 กรัม | D14: 50 | E14: 6 | H14: 2 | I14: 4 | J14: 100
A15: 13 | B15: 1112010 | C15: เบาหวิวฝอยทอง 300 กรัม | D15: 120
A16: 14 | B16: 1112011 | C16: เบาหวิวฝอยทอง 110 กรัม | D16: 50
A17: 15 | B17: 1111017 | C17: ชิฟฟ่อนสอดไส้แยมบลูเบอร์รี่ 3 ชิ้น | D17: 55
A18: 16 | B18: 1111012 | C18: ชิฟฟ่อนสอดไส้นมชมพูฮอกไกโด 6 ชิ้น | D18: 100
A19: 17 | B19: 1112012 | C19: เบาหวิวเผือกมะพร้าว 300 กรัม | D19: 120
A20: 18 | B20: 1112013 | C20: เบาหวิวเผือกมะพร้าว 110 กรัม | D20: 50 | E20: 5 | H20: 4 | I20: 1 | J20: 200
A21: 19 | B21: 1113131 | C21: เปี๊ยะโมจิฟัก 350 กรัม | D21: 120
A22: 20 | B22: 1113135 | C22: เปี๊ยะโมจิฟัก 700 กรัม | D22: 185
A23: 21 | B23: 1112017 | C23: เบาหวิวตาลหอม 110 กรัม | D23: 50 | E23: 7 | H23: 4 | I23: 3 | J23: 200
A24: 22 | B24: 1112015 | C24: เบาหวิวกล้วยหอมมะพร้าวเผา 110 กรัม | D24: 50 | E24: 6 | H24: 2 | I24: 4 | J24: 100
A25: 23 | B25: 1112005 | C25: เบาหวิวเนยสด 110 กรัม | D25: 50
A26: 24 | C26: เบาหวิวทุเรียน 110 กรัม | D26: 50
A27: 25 | B27: 1112003 | C27: เบาหวิวกาแฟ 110 กรัม | D27: 50
A28: 26 | C28: รถลาน | D28: 45 | E28: 43 | I28: 43
A29: 27 | C29: หัวรถไฟโทมัส | D29: 150 | E29: 3 | I29: 3
A30: 28 | C30: ปืน | D30: 150 | E30: 3 | I30: 3
A31: 29 | C31: โมเดลฮีโร่ | D31: 250
A32: 30 | C32: กระดานวาดเขียน | D32: 250
A33: 31 | C33: เป็ดแม่ | D33: 250
A34: 32 | C34: เป็ดลูก | D34: 150 | E34: 2 | I34: 2
A35: 33 | C35: ตัวบีบ | D35: 60 | E35: 6 | I35: 6
A36: 34 | C36: ลานม้า | D36: 100
A37: 35 | C37: กระดานวาดเขียน(ใหม่) | D37: 200
A38: 36 | C38: ตุ๊กตา | D38: 150
A39: 37 | C39: ตุ๊กตานางฟ้าเต้น | D39: 400 | E39: 1 | I39: 1
A40: 38 | C40: สลาม | D40: 100 | E40: 30 | I40: 30
...

Sheet 11
A1: ใบสต๊อกบูธ 10323 วัดใหม่สุปดิษฐาราม
A2: ลำดับ | B2: รหัส | C2: รายการสินค้า | D2: ราคา | E2: ยอดยกมา | F2: รับเข้า | G2: ส่งคืน | H2: ขายออก | I2: คงเหลือ | J2: ยอดเงิน | K2: หมายเหตุ
A3: 1 | B3: 1005982 | C3: ปังเนยนิ่ม 3 ชิ้น | D3: 55 | F3: 5 | H3: 1 | I3: 4 | J3: 55
A4: 2 | B4: 1200001 | C4: คอนเฟลกกระปุก | D4: 60 | E4: 1 | I4: 1
A5: 3 | B5: 1100003 | C5: เมอแรงค์กระปุก | D5: 55 | E5: 3 | F5: 10 | I5: 13
A6: 4 | B6: 1200003 | C6: ท๊อฟฟี่กระเช้า | D6: 100 | F6: 10 | H6: 1 | I6: 9 | J6: 100
A7: 5 | B7: 1113121 | C7: เปี๊ยะไส้ถั่ว | D7: 120 | E7: 1 | F7: 3 | I7: 4
A8: 6 | B8: 1113123 | C8: เปี๊ยะไส้เผือก | D8: 120 | E8: 1 | I8: 1
A9: 7 | B9: 1113122 | C9: เปี๊ยะไส้ฟัก | D9: 120 | E9: 3 | H9: 1 | I9: 2 | J9: 120
A10: 8 | B10: 1004055 | C10: ชิฟฟ่อนรวมรส 4 ชิ้น | D10: 55 | E10: 2 | F10: 15 | I10: 17
A11: 9 | B11: 1111002 | C11: ชิฟฟ่อนรวมรส 8 ชิ้น | D11: 100 | F11: 10 | I11: 10
A12: 10 | B12: 1111056 | C12: ชิฟฟ่อนยอดฮิต | D12: 100 | E12: 1 | F12: 15 | I12: 16
A13: 11 | B13: 1111009 | C13: ชิฟฟ่อนสอดไส้รวมรส 6 ชิ้น | D13: 100 | E13: 3 | F13: 15 | H13: 1 | I13: 17 | J13: 100
A14: 12 | B14: 1112009 | C14: เบาหวิวมะพร้าวน้ำหอม 110 กรัม | D14: 50 | E14: 4 | I14: 4
A15: 13 | B15: 1112010 | C15: เบาหวิวฝอยทอง 300 กรัม | D15: 120 | F15: 3 | I15: 3
A16: 14 | B16: 1112011 | C16: เบาหวิวฝอยทอง 110 กรัม | D16: 50 | F16: 10 | H16: 3 | I16: 7 | J16: 150
A17: 15 | B17: 1111017 | C17: ชิฟฟ่อนสอดไส้แยมบลูเบอร์รี่ 3 ชิ้น | D17: 55
A18: 16 | B18: 1111012 | C18: ชิฟฟ่อนสอดไส้นมชมพูฮอกไกโด 6 ชิ้น | D18: 100
A19: 17 | B19: 1112012 | C19: เบาหวิวเผือกมะพร้าว 300 กรัม | D19: 120
A20: 18 | B20: 1112013 | C20: เบาหวิวเผือกมะพร้าว 110 กรัม | D20: 50 | E20: 1 | I20: 1
A21: 19 | B21: 1113131 | C21: เปี๊ยะโมจิฟัก 350 กรัม | D21: 120
A22: 20 | B22: 1113135 | C22: เปี๊ยะโมจิฟัก 700 กรัม | D22: 185
A23: 21 | B23: 1112017 | C23: เบาหวิวตาลหอม 110 กรัม | D23: 50 | E23: 3 | I23: 3
A24: 22 | B24: 1112015 | C24: เบาหวิวกล้วยหอมมะพร้าวเผา 110 กรัม | D24: 50 | E24: 4 | I24: 4
A25: 23 | B25: 1112005 | C25: เบาหวิวเนยสด 110 กรัม | D25: 50
A26: 24 | C26: เบาหวิวทุเรียน 110 กรัม | D26: 50
A27: 25 | B27: 1112003 | C27: เบาหวิวกาแฟ 110 กรัม | D27: 50
A28: 26 | C28: รถลาน | D28: 45 | E28: 43 | H28: 1 | I28: 42 | J28: 45
A29: 27 | C29: หัวรถไฟโทมัส | D29: 150 | E29: 3 | I29: 3
A30: 28 | C30: ปืน | D30: 150 | E30: 3 | I30: 3
A31: 29 | C31: โมเดลฮีโร่ | D31: 250
A32: 30 | C32: กระดานวาดเขียน | D32: 250
A33: 31 | C33: เป็ดแม่ | D33: 250
A34: 32 | C34: เป็ดลูก | D34: 150 | E34: 2 | I34: 2
A35: 33 | C35: ตัวบีบ | D35: 60 | E35: 6 | H35: 1 | I35: 5 | J35: 60
A36: 34 | C36: ลานม้า | D36: 100
A37: 35 | C37: กระดานวาดเขียน(ใหม่) | D37: 200
A38: 36 | C38: ตุ๊กตา | D38: 150
A39: 37 | C39: ตุ๊กตานางฟ้าเต้น | D39: 400 | E39: 1 | I39: 1
A40: 38 | C40: สลาม | D40: 100 | E40: 30 | I40: 30
...

Sheet 12
A1: ใบสต๊อกบูธ 10323 วัดใหม่สุปดิษฐาราม
A2: ลำดับ | B2: รหัส | C2: รายการสินค้า | D2: ราคา | E2: ยอดยกมา | F2: รับเข้า | G2: ส่งคืน | H2: ขายออก | I2: คงเหลือ | J2: ยอดเงิน | K2: หมายเหตุ
A3: 1 | B3: 1005982 | C3: ปังเนยนิ่ม 3 ชิ้น | D3: 55 | E3: 4 | I3: 4
A4: 2 | B4: 1200001 | C4: คอนเฟลกกระปุก | D4: 60 | E4: 1 | I4: 1
A5: 3 | B5: 1100003 | C5: เมอแรงค์กระปุก | D5: 55 | E5: 13 | H5: 1 | I5: 12 | J5: 55
A6: 4 | B6: 1200003 | C6: ท๊อฟฟี่กระเช้า | D6: 100 | E6: 9 | H6: 2 | I6: 7 | J6: 200
A7: 5 | B7: 1113121 | C7: เปี๊ยะไส้ถั่ว | D7: 120 | E7: 4 | I7: 4
A8: 6 | B8: 1113123 | C8: เปี๊ยะไส้เผือก | D8: 120 | E8: 1 | I8: 1
A9: 7 | B9: 1113122 | C9: เปี๊ยะไส้ฟัก | D9: 120 | E9: 2 | H9: 2 | J9: 240
A10: 8 | B10: 1004055 | C10: ชิฟฟ่อนรวมรส 4 ชิ้น | D10: 55 | E10: 17 | I10: 17
A11: 9 | B11: 1111002 | C11: ชิฟฟ่อนรวมรส 8 ชิ้น | D11: 100 | E11: 10 | I11: 10
A12: 10 | B12: 1111056 | C12: ชิฟฟ่อนยอดฮิต | D12: 100 | E12: 16 | H12: 1 | I12: 15 | J12: 100
A13: 11 | B13: 1111009 | C13: ชิฟฟ่อนสอดไส้รวมรส 6 ชิ้น | D13: 100 | E13: 17 | I13: 17
A14: 12 | B14: 1112009 | C14: เบาหวิวมะพร้าวน้ำหอม 110 กรัม | D14: 50 | E14: 4 | H14: 1 | I14: 3 | J14: 50
A15: 13 | B15: 1112010 | C15: เบาหวิวฝอยทอง 300 กรัม | D15: 120 | E15: 3 | I15: 3
A16: 14 | B16: 1112011 | C16: เบาหวิวฝอยทอง 110 กรัม | D16: 50 | E16: 7 | I16: 7
A17: 15 | B17: 1111017 | C17: ชิฟฟ่อนสอดไส้แยมบลูเบอร์รี่ 3 ชิ้น | D17: 55
A18: 16 | B18: 1111012 | C18: ชิฟฟ่อนสอดไส้นมชมพูฮอกไกโด 6 ชิ้น | D18: 100
A19: 17 | B19: 1112012 | C19: เบาหวิวเผือกมะพร้าว 300 กรัม | D19: 120
A20: 18 | B20: 1112013 | C20: เบาหวิวเผือกมะพร้าว 110 กรัม | D20: 50 | E20: 1 | I20: 1
A21: 19 | B21: 1113131 | C21: เปี๊ยะโมจิฟัก 350 กรัม | D21: 120
A22: 20 | B22: 1113135 | C22: เปี๊ยะโมจิฟัก 700 กรัม | D22: 185
A23: 21 | B23: 1112017 | C23: เบาหวิวตาลหอม 110 กรัม | D23: 50 | E23: 3 | I23: 3
A24: 22 | B24: 1112015 | C24: เบาหวิวกล้วยหอมมะพร้าวเผา 110 กรัม | D24: 50 | E24: 4 | I24: 4
A25: 23 | B25: 1112005 | C25: เบาหวิวเนยสด 110 กรัม | D25: 50
A26: 24 | C26: เบาหวิวทุเรียน 110 กรัม | D26: 50
A27: 25 | B27: 1112003 | C27: เบาหวิวกาแฟ 110 กรัม | D27: 50
A28: 26 | C28: รถลาน | D28: 45 | E28: 42 | H28: 2 | I28: 40 | J28: 90
A29: 27 | C29: หัวรถไฟโทมัส | D29: 150 | E29: 3 | I29: 3
A30: 28 | C30: ปืน | D30: 150 | E30: 3 | I30: 3
A31: 29 | C31: โมเดลฮีโร่ | D31: 250
A32: 30 | C32: กระดานวาดเขียน | D32: 250
A33: 31 | C33: เป็ดแม่ | D33: 250
A34: 32 | C34: เป็ดลูก | D34: 150 | E34: 2 | I34: 2
A35: 33 | C35: ตัวบีบ | D35: 60 | E35: 5 | I35: 5
A36: 34 | C36: ลานม้า | D36: 100
A37: 35 | C37: กระดานวาดเขียน(ใหม่) | D37: 200
A38: 36 | C38: ตุ๊กตา | D38: 150
A39: 37 | C39: ตุ๊กตานางฟ้าเต้น | D39: 400 | E39: 1 | I39: 1
A40: 38 | C40: สลาม | D40: 100 | E40: 30 | H40: 2 | I40: 28 | J40: 200
...

Sheet 13
A1: ใบสต๊อกบูธ 10323 วัดใหม่สุปดิษฐาราม
A2: ลำดับ | B2: รหัส | C2: รายการสินค้า | D2: ราคา | E2: ยอดยกมา | F2: รับเข้า | G2: ส่งคืน | H2: ขายออก | I2: คงเหลือ | J2: ยอดเงิน | K2: หมายเหตุ
A3: 1 | B3: 1005982 | C3: ปังเนยนิ่ม 3 ชิ้น | D3: 55 | E3: 4 | H3: 1 | I3: 3 | J3: 55
A4: 2 | B4: 1200001 | C4: คอนเฟลกกระปุก | D4: 60 | E4: 1 | I4: 1
A5: 3 | B5: 1100003 | C5: เมอแรงค์กระปุก | D5: 55 | E5: 12 | I5: 12
A6: 4 | B6: 1200003 | C6: ท๊อฟฟี่กระเช้า | D6: 100 | E6: 7 | H6: 2 | I6: 5 | J6: 200
A7: 5 | B7: 1113121 | C7: เปี๊ยะไส้ถั่ว | D7: 120 | E7: 4 | I7: 4
A8: 6 | B8: 1113123 | C8: เปี๊ยะไส้เผือก | D8: 120 | E8: 1 | I8: 1
A9: 7 | B9: 1113122 | C9: เปี๊ยะไส้ฟัก | D9: 120
A10: 8 | B10: 1004055 | C10: ชิฟฟ่อนรวมรส 4 ชิ้น | D10: 55 | E10: 17 | I10: 17
A11: 9 | B11: 1111002 | C11: ชิฟฟ่อนรวมรส 8 ชิ้น | D11: 100 | E11: 10 | I11: 10
A12: 10 | B12: 1111056 | C12: ชิฟฟ่อนยอดฮิต | D12: 100 | E12: 15 | H12: 1 | I12: 14 | J12: 100
A13: 11 | B13: 1111009 | C13: ชิฟฟ่อนสอดไส้รวมรส 6 ชิ้น | D13: 100 | E13: 17 | I13: 17
A14: 12 | B14: 1112009 | C14: เบาหวิวมะพร้าวน้ำหอม 110 กรัม | D14: 50 | E14: 3 | I14: 3
A15: 13 | B15: 1112010 | C15: เบาหวิวฝอยทอง 300 กรัม | D15: 120 | E15: 3 | I15: 3
A16: 14 | B16: 1112011 | C16: เบาหวิวฝอยทอง 110 กรัม | D16: 50 | E16: 7 | H16: 1 | I16: 6 | J16: 50
A17: 15 | B17: 1111017 | C17: ชิฟฟ่อนสอดไส้แยมบลูเบอร์รี่ 3 ชิ้น | D17: 55
A18: 16 | B18: 1111012 | C18: ชิฟฟ่อนสอดไส้นมชมพูฮอกไกโด 6 ชิ้น | D18: 100
A19: 17 | B19: 1112012 | C19: เบาหวิวเผือกมะพร้าว 300 กรัม | D19: 120
A20: 18 | B20: 1112013 | C20: เบาหวิวเผือกมะพร้าว 110 กรัม | D20: 50 | E20: 1 | I20: 1
A21: 19 | B21: 1113131 | C21: เปี๊ยะโมจิฟัก 350 กรัม | D21: 120
A22: 20 | B22: 1113135 | C22: เปี๊ยะโมจิฟัก 700 กรัม | D22: 185
A23: 21 | B23: 1112017 | C23: เบาหวิวตาลหอม 110 กรัม | D23: 50 | E23: 3 | H23: 1 | I23: 2 | J23: 50
A24: 22 | B24: 1112015 | C24: เบาหวิวกล้วยหอมมะพร้าวเผา 110 กรัม | D24: 50 | E24: 4 | I24: 4
A25: 23 | B25: 1112005 | C25: เบาหวิวเนยสด 110 กรัม | D25: 50
A26: 24 | C26: เบาหวิวทุเรียน 110 กรัม | D26: 50
A27: 25 | B27: 1112003 | C27: เบาหวิวกาแฟ 110 กรัม | D27: 50
A28: 26 | C28: รถลาน | D28: 45 | E28: 40 | I28: 40
A29: 27 | C29: หัวรถไฟโทมัส | D29: 150 | E29: 3 | H29: 2 | I29: 1 | J29: 300
A30: 28 | C30: ปืน | D30: 150 | E30: 3 | I30: 3
A31: 29 | C31: โมเดลฮีโร่ | D31: 250
A32: 30 | C32: กระดานวาดเขียน | D32: 250
A33: 31 | C33: เป็ดแม่ | D33: 250
A34: 32 | C34: เป็ดลูก | D34: 150 | E34: 2 | I34: 2
A35: 33 | C35: ตัวบีบ | D35: 60 | E35: 5 | I35: 5
A36: 34 | C36: ลานม้า | D36: 100
A37: 35 | C37: กระดานวาดเขียน(ใหม่) | D37: 200
A38: 36 | C38: ตุ๊กตา | D38: 150
A39: 37 | C39: ตุ๊กตานางฟ้าเต้น | D39: 400 | E39: 1 | I39: 1
A40: 38 | C40: สลาม | D40: 100 | E40: 28 | H40: 1 | I40: 27 | J40: 100
...

Sheet 14
A1: ใบสต๊อกบูธ 10323 วัดใหม่สุปดิษฐาราม
A2: ลำดับ | B2: รหัส | C2: รายการสินค้า | D2: ราคา | E2: ยอดยกมา | F2: รับเข้า | G2: ส่งคืน | H2: ขายออก | I2: คงเหลือ | J2: ยอดเงิน | K2: หมายเหตุ
A3: 1 | B3: 1005982 | C3: ปังเนยนิ่ม 3 ชิ้น | D3: 55 | E3: 3 | I3: 3
A4: 2 | B4: 1200001 | C4: คอนเฟลกกระปุก | D4: 60 | E4: 1 | I4: 1
A5: 3 | B5: 1100003 | C5: เมอแรงค์กระปุก | D5: 55 | E5: 12 | I5: 12
A6: 4 | B6: 1200003 | C6: ท๊อฟฟี่กระเช้า | D6: 100 | E6: 5 | H6: 1 | I6: 4 | J6: 100
A7: 5 | B7: 1113121 | C7: เปี๊ยะไส้ถั่ว | D7: 120 | E7: 4 | I7: 4
A8: 6 | B8: 1113123 | C8: เปี๊ยะไส้เผือก | D8: 120 | E8: 1 | H8: 1 | J8: 120
A9: 7 | B9: 1113122 | C9: เปี๊ยะไส้ฟัก | D9: 120
A10: 8 | B10: 1004055 | C10: ชิฟฟ่อนรวมรส 4 ชิ้น | D10: 55 | E10: 17 | H10: 4 | I10: 13 | J10: 220
A11: 9 | B11: 1111002 | C11: ชิฟฟ่อนรวมรส 8 ชิ้น | D11: 100 | E11: 10 | H11: 2 | I11: 8 | J11: 200
A12: 10 | B12: 1111056 | C12: ชิฟฟ่อนยอดฮิต | D12: 100 | E12: 14 | I12: 14
A13: 11 | B13: 1111009 | C13: ชิฟฟ่อนสอดไส้รวมรส 6 ชิ้น | D13: 100 | E13: 17 | H13: 6 | I13: 11 | J13: 600
A14: 12 | B14: 1112009 | C14: เบาหวิวมะพร้าวน้ำหอม 110 กรัม | D14: 50 | E14: 3 | I14: 3
A15: 13 | B15: 1112010 | C15: เบาหวิวฝอยทอง 300 กรัม | D15: 120 | E15: 3 | I15: 3
A16: 14 | B16: 1112011 | C16: เบาหวิวฝอยทอง 110 กรัม | D16: 50 | E16: 6 | I16: 6
A17: 15 | B17: 1111017 | C17: ชิฟฟ่อนสอดไส้แยมบลูเบอร์รี่ 3 ชิ้น | D17: 55
A18: 16 | B18: 1111012 | C18: ชิฟฟ่อนสอดไส้นมชมพูฮอกไกโด 6 ชิ้น | D18: 100
A19: 17 | B19: 1112012 | C19: เบาหวิวเผือกมะพร้าว 300 กรัม | D19: 120
A20: 18 | B20: 1112013 | C20: เบาหวิวเผือกมะพร้าว 110 กรัม | D20: 50 | E20: 1 | I20: 1
A21: 19 | B21: 1113131 | C21: เปี๊ยะโมจิฟัก 350 กรัม | D21: 120
A22: 20 | B22: 1113135 | C22: เปี๊ยะโมจิฟัก 700 กรัม | D22: 185
A23: 21 | B23: 1112017 | C23: เบาหวิวตาลหอม 110 กรัม | D23: 50 | E23: 2 | I23: 2
A24: 22 | B24: 1112015 | C24: เบาหวิวกล้วยหอมมะพร้าวเผา 110 กรัม | D24: 50 | E24: 4 | I24: 4
A25: 23 | B25: 1112005 | C25: เบาหวิวเนยสด 110 กรัม | D25: 50
A26: 24 | C26: เบาหวิวทุเรียน 110 กรัม | D26: 50
A27: 25 | B27: 1112003 | C27: เบาหวิวกาแฟ 110 กรัม | D27: 50
A28: 26 | C28: รถลาน | D28: 45 | E28: 40 | I28: 40
A29: 27 | C29: หัวรถไฟโทมัส | D29: 150 | E29: 1 | I29: 1
A30: 28 | C30: ปืน | D30: 150 | E30: 3 | I30: 3
A31: 29 | C31: โมเดลฮีโร่ | D31: 250
A32: 30 | C32: กระดานวาดเขียน | D32: 250
A33: 31 | C33: เป็ดแม่ | D33: 250
A34: 32 | C34: เป็ดลูก | D34: 150 | E34: 2 | I34: 2
A35: 33 | C35: ตัวบีบ | D35: 60 | E35: 5 | G35: 1 | I35: 4
A36: 34 | C36: ลานม้า | D36: 100
A37: 35 | C37: กระดานวาดเขียน(ใหม่) | D37: 200
A38: 36 | C38: ตุ๊กตา | D38: 150
A39: 37 | C39: ตุ๊กตานางฟ้าเต้น | D39: 400 | E39: 1 | I39: 1
A40: 38 | C40: สลาม | D40: 100 | E40: 27 | H40: 4 | I40: 23 | J40: 400
...

Sheet 15
A1: ใบสต๊อกบูธ 10323 วัดใหม่สุปดิษฐาราม
A2: ลำดับ | B2: รหัส | C2: รายการสินค้า | D2: ราคา | E2: ยอดยกมา | F2: รับเข้า | G2: ส่งคืน | H2: ขายออก | I2: คงเหลือ | J2: ยอดเงิน | K2: หมายเหตุ
A3: 1 | B3: 1005982 | C3: ปังเนยนิ่ม 3 ชิ้น | D3: 55 | E3: 3 | H3: 1 | I3: 2 | J3: 55
A4: 2 | B4: 1200001 | C4: คอนเฟลกกระปุก | D4: 60 | E4: 1 | I4: 1
A5: 3 | B5: 1100003 | C5: เมอแรงค์กระปุก | D5: 55 | E5: 12 | I5: 12
A6: 4 | B6: 1200003 | C6: ท๊อฟฟี่กระเช้า | D6: 100 | E6: 4 | H6: 1 | I6: 3 | J6: 100
A7: 5 | B7: 1113121 | C7: เปี๊ยะไส้ถั่ว | D7: 120 | E7: 4 | I7: 4
A8: 6 | B8: 1113123 | C8: เปี๊ยะไส้เผือก | D8: 120
A9: 7 | B9: 1113122 | C9: เปี๊ยะไส้ฟัก | D9: 120
A10: 8 | B10: 1004055 | C10: ชิฟฟ่อนรวมรส 4 ชิ้น | D10: 55 | E10: 13 | H10: 3 | I10: 10 | J10: 165
A11: 9 | B11: 1111002 | C11: ชิฟฟ่อนรวมรส 8 ชิ้น | D11: 100 | E11: 8 | I11: 8
A12: 10 | B12: 1111056 | C12: ชิฟฟ่อนยอดฮิต | D12: 100 | E12: 14 | I12: 14
A13: 11 | B13: 1111009 | C13: ชิฟฟ่อนสอดไส้รวมรส 6 ชิ้น | D13: 100 | E13: 11 | I13: 11
A14: 12 | B14: 1112009 | C14: เบาหวิวมะพร้าวน้ำหอม 110 กรัม | D14: 50 | E14: 3 | I14: 3
A15: 13 | B15: 1112010 | C15: เบาหวิวฝอยทอง 300 กรัม | D15: 120 | E15: 3 | I15: 3
A16: 14 | B16: 1112011 | C16: เบาหวิวฝอยทอง 110 กรัม | D16: 50 | E16: 6 | I16: 6
A17: 15 | B17: 1111017 | C17: ชิฟฟ่อนสอดไส้แยมบลูเบอร์รี่ 3 ชิ้น | D17: 55
A18: 16 | B18: 1111012 | C18: ชิฟฟ่อนสอดไส้นมชมพูฮอกไกโด 6 ชิ้น | D18: 100
A19: 17 | B19: 1112012 | C19: เบาหวิวเผือกมะพร้าว 300 กรัม | D19: 120
A20: 18 | B20: 1112013 | C20: เบาหวิวเผือกมะพร้าว 110 กรัม | D20: 50 | E20: 1 | I20: 1
A21: 19 | B21: 1113131 | C21: เปี๊ยะโมจิฟัก 350 กรัม | D21: 120
A22: 20 | B22: 1113135 | C22: เปี๊ยะโมจิฟัก 700 กรัม | D22: 185
A23: 21 | B23: 1112017 | C23: เบาหวิวตาลหอม 110 กรัม | D23: 50 | E23: 2 | I23: 2
A24: 22 | B24: 1112015 | C24: เบาหวิวกล้วยหอมมะพร้าวเผา 110 กรัม | D24: 50 | E24: 4 | I24: 4
A25: 23 | B25: 1112005 | C25: เบาหวิวเนยสด 110 กรัม | D25: 50
A26: 24 | C26: เบาหวิวทุเรียน 110 กรัม | D26: 50
A27: 25 | B27: 1112003 | C27: เบาหวิวกาแฟ 110 กรัม | D27: 50
A28: 26 | C28: รถลาน | D28: 45 | E28: 40 | I28: 40
A29: 27 | C29: หัวรถไฟโทมัส | D29: 150 | E29: 1 | I29: 1
A30: 28 | C30: ปืน | D30: 150 | E30: 3 | I30: 3
A31: 29 | C31: โมเดลฮีโร่ | D31: 250
A32: 30 | C32: กระดานวาดเขียน | D32: 250
A33: 31 | C33: เป็ดแม่ | D33: 250
A34: 32 | C34: เป็ดลูก | D34: 150 | E34: 2 | I34: 2
A35: 33 | C35: ตัวบีบ | D35: 60 | E35: 4 | I35: 4
A36: 34 | C36: ลานม้า | D36: 100
A37: 35 | C37: กระดานวาดเขียน(ใหม่) | D37: 200
A38: 36 | C38: ตุ๊กตา | D38: 150
A39: 37 | C39: ตุ๊กตานางฟ้าเต้น | D39: 400 | E39: 1 | I39: 1
A40: 38 | C40: สลาม | D40: 100 | E40: 23 | I40: 23
...

Sheet 17
A1: ใบสต๊อกบูธ 10323 วัดใหม่สุปดิษฐาราม
A2: ลำดับ | B2: รหัส | C2: รายการสินค้า | D2: ราคา | E2: ยอดยกมา | F2: รับเข้า | G2: ส่งคืน | H2: ขายออก | I2: คงเหลือ | J2: ยอดเงิน | K2: หมายเหตุ
A3: 1 | B3: 1005982 | C3: ปังเนยนิ่ม 3 ชิ้น | D3: 55 | E3: 2 | I3: 2
A4: 2 | B4: 1200001 | C4: คอนเฟลกกระปุก | D4: 60 | E4: 1 | I4: 1
A5: 3 | B5: 1100003 | C5: เมอแรงค์กระปุก | D5: 55 | E5: 12 | I5: 12
A6: 4 | B6: 1200003 | C6: ท๊อฟฟี่กระเช้า | D6: 100 | E6: 3 | I6: 3
A7: 5 | B7: 1113121 | C7: เปี๊ยะไส้ถั่ว | D7: 120 | E7: 4 | I7: 4
A8: 6 | B8: 1113123 | C8: เปี๊ยะไส้เผือก | D8: 120
A9: 7 | B9: 1113122 | C9: เปี๊ยะไส้ฟัก | D9: 120
A10: 8 | B10: 1004055 | C10: ชิฟฟ่อนรวมรส 4 ชิ้น | D10: 55 | E10: 10 | I10: 10
A11: 9 | B11: 1111002 | C11: ชิฟฟ่อนรวมรส 8 ชิ้น | D11: 100 | E11: 8 | I11: 8
A12: 10 | B12: 1111056 | C12: ชิฟฟ่อนยอดฮิต | D12: 100 | E12: 14 | H12: 1 | I12: 13 | J12: 100
A13: 11 | B13: 1111009 | C13: ชิฟฟ่อนสอดไส้รวมรส 6 ชิ้น | D13: 100 | E13: 11 | H13: 3 | I13: 8 | J13: 300
A14: 12 | B14: 1112009 | C14: เบาหวิวมะพร้าวน้ำหอม 110 กรัม | D14: 50 | E14: 3 | I14: 3
A15: 13 | B15: 1112010 | C15: เบาหวิวฝอยทอง 300 กรัม | D15: 120 | E15: 3 | I15: 3
A16: 14 | B16: 1112011 | C16: เบาหวิวฝอยทอง 110 กรัม | D16: 50 | E16: 6 | I16: 6
A17: 15 | B17: 1111017 | C17: ชิฟฟ่อนสอดไส้แยมบลูเบอร์รี่ 3 ชิ้น | D17: 55
A18: 16 | B18: 1111012 | C18: ชิฟฟ่อนสอดไส้นมชมพูฮอกไกโด 6 ชิ้น | D18: 100
A19: 17 | B19: 1112012 | C19: เบาหวิวเผือกมะพร้าว 300 กรัม | D19: 120
A20: 18 | B20: 1112013 | C20: เบาหวิวเผือกมะพร้าว 110 กรัม | D20: 50 | E20: 1 | I20: 1
A21: 19 | B21: 1113131 | C21: เปี๊ยะโมจิฟัก 350 กรัม | D21: 120
A22: 20 | B22: 1113135 | C22: เปี๊ยะโมจิฟัก 700 กรัม | D22: 185
A23: 21 | B23: 1112017 | C23: เบาหวิวตาลหอม 110 กรัม | D23: 50 | E23: 2 | I23: 2
A24: 22 | B24: 1112015 | C24: เบาหวิวกล้วยหอมมะพร้าวเผา 110 กรัม | D24: 50 | E24: 4 | I24: 4
A25: 23 | B25: 1112005 | C25: เบาหวิวเนยสด 110 กรัม | D25: 50
A26: 24 | C26: เบาหวิวทุเรียน 110 กรัม | D26: 50
A27: 25 | B27: 1112003 | C27: เบาหวิวกาแฟ 110 กรัม | D27: 50
A28: 26 | C28: รถลาน | D28: 45 | E28: 40 | I28: 40
A29: 27 | C29: หัวรถไฟโทมัส | D29: 150 | E29: 1 | I29: 1
A30: 28 | C30: ปืน | D30: 150 | E30: 3 | I30: 3
A31: 29 | C31: โมเดลฮีโร่ | D31: 250
A32: 30 | C32: กระดานวาดเขียน | D32: 250
A33: 31 | C33: เป็ดแม่ | D33: 250
A34: 32 | C34: เป็ดลูก | D34: 150 | E34: 2 | I34: 2
A35: 33 | C35: ตัวบีบ | D35: 60 | E35: 4 | I35: 4
A36: 34 | C36: ลานม้า | D36: 100
A37: 35 | C37: กระดานวาดเขียน(ใหม่) | D37: 200
A38: 36 | C38: ตุ๊กตา | D38: 150
A39: 37 | C39: ตุ๊กตานางฟ้าเต้น | D39: 400 | E39: 1 | I39: 1
A40: 38 | C40: สลาม | D40: 100 | E40: 23 | I40: 23
...

Sheet 18
A1: ใบสต๊อกบูธ 10323 วัดใหม่สุปดิษฐาราม
A2: ลำดับ | B2: รหัส | C2: รายการสินค้า | D2: ราคา | E2: ยอดยกมา | F2: รับเข้า | G2: ส่งคืน | H2: ขายออก | I2: คงเหลือ | J2: ยอดเงิน | K2: หมายเหตุ
A3: 1 | B3: 1005982 | C3: ปังเนยนิ่ม 3 ชิ้น | D3: 55 | E3: 2 | I3: 2
A4: 2 | B4: 1200001 | C4: คอนเฟลกกระปุก | D4: 60 | E4: 1 | F4: 10 | I4: 11
A5: 3 | B5: 1100003 | C5: เมอแรงค์กระปุก | D5: 55 | E5: 12 | H5: 2 | I5: 10 | J5: 110
A6: 4 | B6: 1200003 | C6: ท๊อฟฟี่กระเช้า | D6: 100 | E6: 3 | F6: 10 | H6: 1 | I6: 12 | J6: 100
A7: 5 | B7: 1113121 | C7: เปี๊ยะไส้ถั่ว | D7: 120 | E7: 4 | I7: 4
A8: 6 | B8: 1113123 | C8: เปี๊ยะไส้เผือก | D8: 120 | F8: 5 | I8: 5
A9: 7 | B9: 1113122 | C9: เปี๊ยะไส้ฟัก | D9: 120 | F9: 5 | I9: 5
A10: 8 | B10: 1004055 | C10: ชิฟฟ่อนรวมรส 4 ชิ้น | D10: 55 | E10: 10 | F10: 10 | H10: 1 | I10: 19 | J10: 55
A11: 9 | B11: 1111002 | C11: ชิฟฟ่อนรวมรส 8 ชิ้น | D11: 100 | E11: 8 | F11: 10 | H11: 1 | I11: 17 | J11: 100
A12: 10 | B12: 1111056 | C12: ชิฟฟ่อนยอดฮิต | D12: 100 | E12: 13 | F12: 10 | I12: 23
A13: 11 | B13: 1111009 | C13: ชิฟฟ่อนสอดไส้รวมรส 6 ชิ้น | D13: 100 | E13: 8 | F13: 10 | I13: 18
A14: 12 | B14: 1112009 | C14: เบาหวิวมะพร้าวน้ำหอม 110 กรัม | D14: 50 | E14: 3 | F14: 10 | H14: 1 | I14: 12 | J14: 50
A15: 13 | B15: 1112010 | C15: เบาหวิวฝอยทอง 300 กรัม | D15: 120 | E15: 3 | F15: 10 | I15: 13
A16: 14 | B16: 1112011 | C16: เบาหวิวฝอยทอง 110 กรัม | D16: 50 | E16: 6 | H16: 1 | I16: 5 | J16: 50
A17: 15 | B17: 1111017 | C17: ชิฟฟ่อนสอดไส้แยมบลูเบอร์รี่ 3 ชิ้น | D17: 55
A18: 16 | B18: 1111012 | C18: ชิฟฟ่อนสอดไส้นมชมพูฮอกไกโด 6 ชิ้น | D18: 100
A19: 17 | B19: 1112012 | C19: เบาหวิวเผือกมะพร้าว 300 กรัม | D19: 120
A20: 18 | B20: 1112013 | C20: เบาหวิวเผือกมะพร้าว 110 กรัม | D20: 50 | E20: 1 | F20: 10 | I20: 11
A21: 19 | B21: 1113131 | C21: เปี๊ยะโมจิฟัก 350 กรัม | D21: 120
A22: 20 | B22: 1113135 | C22: เปี๊ยะโมจิฟัก 700 กรัม | D22: 185
A23: 21 | B23: 1112017 | C23: เบาหวิวตาลหอม 110 กรัม | D23: 50 | E23: 2 | F23: 8 | I23: 10
A24: 22 | B24: 1112015 | C24: เบาหวิวกล้วยหอมมะพร้าวเผา 110 กรัม | D24: 50 | E24: 4 | F24: 10 | H24: 1 | I24: 13 | J24: 50
A25: 23 | B25: 1112005 | C25: เบาหวิวเนยสด 110 กรัม | D25: 50
A26: 24 | C26: เบาหวิวทุเรียน 110 กรัม | D26: 50
A27: 25 | B27: 1112003 | C27: เบาหวิวกาแฟ 110 กรัม | D27: 50
A28: 26 | C28: รถลาน | D28: 45 | E28: 40 | H28: 2 | I28: 38 | J28: 90
A29: 27 | C29: หัวรถไฟโทมัส | D29: 150 | E29: 1 | I29: 1
A30: 28 | C30: ปืน | D30: 150 | E30: 3 | H30: 1 | I30: 2 | J30: 150
A31: 29 | C31: โมเดลฮีโร่ | D31: 250
A32: 30 | C32: กระดานวาดเขียน | D32: 250
A33: 31 | C33: เป็ดแม่ | D33: 250
A34: 32 | C34: เป็ดลูก | D34: 150 | E34: 2 | I34: 2
A35: 33 | C35: ตัวบีบ | D35: 60 | E35: 4 | I35: 4
A36: 34 | C36: ลานม้า | D36: 100
A37: 35 | C37: กระดานวาดเขียน(ใหม่) | D37: 200
A38: 36 | C38: ตุ๊กตา | D38: 150
A39: 37 | C39: ตุ๊กตานางฟ้าเต้น | D39: 400 | E39: 1 | I39: 1
A40: 38 | C40: สลาม | D40: 100 | E40: 23 | I40: 23
...

Sheet 19
A1: ใบสต๊อกบูธ 10323 วัดใหม่สุปดิษฐาราม
A2: ลำดับ | B2: รหัส | C2: รายการสินค้า | D2: ราคา | E2: ยอดยกมา | F2: รับเข้า | G2: ส่งคืน | H2: ขายออก | I2: คงเหลือ | J2: ยอดเงิน | K2: หมายเหตุ
A3: 1 | B3: 1005982 | C3: ปังเนยนิ่ม 3 ชิ้น | D3: 55 | E3: 2 | I3: 2
A4: 2 | B4: 1200001 | C4: คอนเฟลกกระปุก | D4: 60 | E4: 11 | H4: 1 | I4: 10 | J4: 60
A5: 3 | B5: 1100003 | C5: เมอแรงค์กระปุก | D5: 55 | E5: 10 | I5: 10
A6: 4 | B6: 1200003 | C6: ท๊อฟฟี่กระเช้า | D6: 100 | E6: 12 | I6: 12
A7: 5 | B7: 1113121 | C7: เปี๊ยะไส้ถั่ว | D7: 120 | E7: 4 | I7: 4
A8: 6 | B8: 1113123 | C8: เปี๊ยะไส้เผือก | D8: 120 | E8: 5 | I8: 5
A9: 7 | B9: 1113122 | C9: เปี๊ยะไส้ฟัก | D9: 120 | E9: 5 | I9: 5
A10: 8 | B10: 1004055 | C10: ชิฟฟ่อนรวมรส 4 ชิ้น | D10: 55 | E10: 19 | I10: 19
A11: 9 | B11: 1111002 | C11: ชิฟฟ่อนรวมรส 8 ชิ้น | D11: 100 | E11: 17 | I11: 17
A12: 10 | B12: 1111056 | C12: ชิฟฟ่อนยอดฮิต | D12: 100 | E12: 23 | H12: 13 | I12: 10 | J12: 650 | K12: ลด50%
A13: 11 | B13: 1111009 | C13: ชิฟฟ่อนสอดไส้รวมรส 6 ชิ้น | D13: 100 | E13: 18 | I13: 18
A14: 12 | B14: 1112009 | C14: เบาหวิวมะพร้าวน้ำหอม 110 กรัม | D14: 50 | E14: 12 | I14: 12
A15: 13 | B15: 1112010 | C15: เบาหวิวฝอยทอง 300 กรัม | D15: 120 | E15: 13 | I15: 13
A16: 14 | B16: 1112011 | C16: เบาหวิวฝอยทอง 110 กรัม | D16: 50 | E16: 5 | H16: 2 | I16: 3 | J16: 100
A17: 15 | B17: 1111017 | C17: ชิฟฟ่อนสอดไส้แยมบลูเบอร์รี่ 3 ชิ้น | D17: 55
A18: 16 | B18: 1111012 | C18: ชิฟฟ่อนสอดไส้นมชมพูฮอกไกโด 6 ชิ้น | D18: 100
A19: 17 | B19: 1112012 | C19: เบาหวิวเผือกมะพร้าว 300 กรัม | D19: 120
A20: 18 | B20: 1112013 | C20: เบาหวิวเผือกมะพร้าว 110 กรัม | D20: 50 | E20: 11 | H20: 2 | I20: 9 | J20: 100
A21: 19 | B21: 1113131 | C21: เปี๊ยะโมจิฟัก 350 กรัม | D21: 120
A22: 20 | B22: 1113135 | C22: เปี๊ยะโมจิฟัก 700 กรัม | D22: 185
A23: 21 | B23: 1112017 | C23: เบาหวิวตาลหอม 110 กรัม | D23: 50 | E23: 10 | I23: 10
A24: 22 | B24: 1112015 | C24: เบาหวิวกล้วยหอมมะพร้าวเผา 110 กรัม | D24: 50 | E24: 13 | I24: 13
A25: 23 | B25: 1112005 | C25: เบาหวิวเนยสด 110 กรัม | D25: 50
A26: 24 | C26: เบาหวิวทุเรียน 110 กรัม | D26: 50
A27: 25 | B27: 1112003 | C27: เบาหวิวกาแฟ 110 กรัม | D27: 50
A28: 26 | C28: รถลาน | D28: 45 | E28: 38 | I28: 38
A29: 27 | C29: หัวรถไฟโทมัส | D29: 150 | E29: 1 | I29: 1
A30: 28 | C30: ปืน | D30: 150 | E30: 2 | I30: 2
A31: 29 | C31: โมเดลฮีโร่ | D31: 250
A32: 30 | C32: กระดานวาดเขียน | D32: 250
A33: 31 | C33: เป็ดแม่ | D33: 250
A34: 32 | C34: เป็ดลูก | D34: 150 | E34: 2 | I34: 2
A35: 33 | C35: ตัวบีบ | D35: 60 | E35: 4 | I35: 4
A36: 34 | C36: ลานม้า | D36: 100
A37: 35 | C37: กระดานวาดเขียน(ใหม่) | D37: 200
A38: 36 | C38: ตุ๊กตา | D38: 150
A39: 37 | C39: ตุ๊กตานางฟ้าเต้น | D39: 400 | E39: 1 | I39: 1
A40: 38 | C40: สลาม | D40: 100 | E40: 23 | H40: 1 | I40: 22 | J40: 100
...

Sheet 20
A1: ใบสต๊อกบูธ 10323 วัดใหม่สุปดิษฐาราม
A2: ลำดับ | B2: รหัส | C2: รายการสินค้า | D2: ราคา | E2: ยอดยกมา | F2: รับเข้า | G2: ส่งคืน | H2: ขายออก | I2: คงเหลือ | J2: ยอดเงิน | K2: หมายเหตุ
A3: 1 | B3: 1005982 | C3: ปังเนยนิ่ม 3 ชิ้น | D3: 55 | E3: 2 | G3: 2
A4: 2 | B4: 1200001 | C4: คอนเฟลกกระปุก | D4: 60 | E4: 10 | H4: 3 | I4: 7 | J4: 180
A5: 3 | B5: 1100003 | C5: เมอแรงค์กระปุก | D5: 55 | E5: 10 | H5: 1 | I5: 9 | J5: 55
A6: 4 | B6: 1200003 | C6: ท๊อฟฟี่กระเช้า | D6: 100 | E6: 12 | H6: 1 | I6: 11 | J6: 100
A7: 5 | B7: 1113121 | C7: เปี๊ยะไส้ถั่ว | D7: 120 | E7: 4 | G7: 1 | H7: 1 | I7: 2 | J7: 120
A8: 6 | B8: 1113123 | C8: เปี๊ยะไส้เผือก | D8: 120 | E8: 5 | I8: 5
A9: 7 | B9: 1113122 | C9: เปี๊ยะไส้ฟัก | D9: 120 | E9: 5 | I9: 5
A10: 8 | B10: 1004055 | C10: ชิฟฟ่อนรวมรส 4 ชิ้น | D10: 55 | E10: 19 | H10: 1 | I10: 18 | J10: 55
A11: 9 | B11: 1111002 | C11: ชิฟฟ่อนรวมรส 8 ชิ้น | D11: 100 | E11: 17 | H11: 1 | I11: 16 | J11: 100
A12: 10 | B12: 1111056 | C12: ชิฟฟ่อนยอดฮิต | D12: 100 | E12: 10 | H12: 1 | I12: 9 | J12: 100
A13: 11 | B13: 1111009 | C13: ชิฟฟ่อนสอดไส้รวมรส 6 ชิ้น | D13: 100 | E13: 18 | H13: 1 | I13: 17 | J13: 100
A14: 12 | B14: 1112009 | C14: เบาหวิวมะพร้าวน้ำหอม 110 กรัม | D14: 50 | E14: 12 | H14: 2 | I14: 10 | J14: 100
A15: 13 | B15: 1112010 | C15: เบาหวิวฝอยทอง 300 กรัม | D15: 120 | E15: 13 | I15: 13
A16: 14 | B16: 1112011 | C16: เบาหวิวฝอยทอง 110 กรัม | D16: 50 | E16: 3 | I16: 3
A17: 15 | B17: 1111017 | C17: ชิฟฟ่อนสอดไส้แยมบลูเบอร์รี่ 3 ชิ้น | D17: 55
A18: 16 | B18: 1111012 | C18: ชิฟฟ่อนสอดไส้นมชมพูฮอกไกโด 6 ชิ้น | D18: 100
A19: 17 | B19: 1112012 | C19: เบาหวิวเผือกมะพร้าว 300 กรัม | D19: 120
A20: 18 | B20: 1112013 | C20: เบาหวิวเผือกมะพร้าว 110 กรัม | D20: 50 | E20: 9 | I20: 9
A21: 19 | B21: 1113131 | C21: เปี๊ยะโมจิฟัก 350 กรัม | D21: 120
A22: 20 | B22: 1113135 | C22: เปี๊ยะโมจิฟัก 700 กรัม | D22: 185
A23: 21 | B23: 1112017 | C23: เบาหวิวตาลหอม 110 กรัม | D23: 50 | E23: 10 | H23: 2 | I23: 8 | J23: 100
A24: 22 | B24: 1112015 | C24: เบาหวิวกล้วยหอมมะพร้าวเผา 110 กรัม | D24: 50 | E24: 13 | H24: 1 | I24: 12 | J24: 50
A25: 23 | B25: 1112005 | C25: เบาหวิวเนยสด 110 กรัม | D25: 50
A26: 24 | C26: เบาหวิวทุเรียน 110 กรัม | D26: 50
A27: 25 | B27: 1112003 | C27: เบาหวิวกาแฟ 110 กรัม | D27: 50
A28: 26 | C28: รถลาน | D28: 45 | E28: 38 | I28: 38
A29: 27 | C29: หัวรถไฟโทมัส | D29: 150 | E29: 1 | I29: 1
A30: 28 | C30: ปืน | D30: 150 | E30: 2 | I30: 2
A31: 29 | C31: โมเดลฮีโร่ | D31: 250
A32: 30 | C32: กระดานวาดเขียน | D32: 250
A33: 31 | C33: เป็ดแม่ | D33: 250
A34: 32 | C34: เป็ดลูก | D34: 150 | E34: 2 | I34: 2
A35: 33 | C35: ตัวบีบ | D35: 60 | E35: 4 | I35: 4
A36: 34 | C36: ลานม้า | D36: 100
A37: 35 | C37: กระดานวาดเขียน(ใหม่) | D37: 200
A38: 36 | C38: ตุ๊กตา | D38: 150
A39: 37 | C39: ตุ๊กตานางฟ้าเต้น | D39: 400 | E39: 1 | I39: 1
A40: 38 | C40: สลาม | D40: 100 | E40: 22 | I40: 22
...

Sheet 21
A1: ใบสต๊อกบูธ 10323 วัดใหม่สุปดิษฐาราม
A2: ลำดับ | B2: รหัส | C2: รายการสินค้า | D2: ราคา | E2: ยอดยกมา | F2: รับเข้า | G2: ส่งคืน | H2: ขายออก | I2: คงเหลือ | J2: ยอดเงิน | K2: หมายเหตุ
A3: 1 | B3: 1005982 | C3: ปังเนยนิ่ม 3 ชิ้น | D3: 55
A4: 2 | B4: 1200001 | C4: คอนเฟลกกระปุก | D4: 60 | E4: 7 | H4: 1 | I4: 6 | J4: 60
A5: 3 | B5: 1100003 | C5: เมอแรงค์กระปุก | D5: 55 | E5: 9 | I5: 9
A6: 4 | B6: 1200003 | C6: ท๊อฟฟี่กระเช้า | D6: 100 | E6: 11 | H6: 4 | I6: 7 | J6: 400
A7: 5 | B7: 1113121 | C7: เปี๊ยะไส้ถั่ว | D7: 120 | E7: 2 | H7: 2 | J7: 240
A8: 6 | B8: 1113123 | C8: เปี๊ยะไส้เผือก | D8: 120 | E8: 5 | H8: 1 | I8: 4 | J8: 120
A9: 7 | B9: 1113122 | C9: เปี๊ยะไส้ฟัก | D9: 120 | E9: 5 | I9: 5
A10: 8 | B10: 1004055 | C10: ชิฟฟ่อนรวมรส 4 ชิ้น | D10: 55 | E10: 18 | H10: 1 | I10: 17 | J10: 55
A11: 9 | B11: 1111002 | C11: ชิฟฟ่อนรวมรส 8 ชิ้น | D11: 100 | E11: 16 | H11: 2 | I11: 14 | J11: 200
A12: 10 | B12: 1111056 | C12: ชิฟฟ่อนยอดฮิต | D12: 100 | E12: 9 | H12: 4 | I12: 5 | J12: 400
A13: 11 | B13: 1111009 | C13: ชิฟฟ่อนสอดไส้รวมรส 6 ชิ้น | D13: 100 | E13: 17 | H13: 4 | I13: 13 | J13: 400
A14: 12 | B14: 1112009 | C14: เบาหวิวมะพร้าวน้ำหอม 110 กรัม | D14: 50 | E14: 10 | H14: 2 | I14: 8 | J14: 100
A15: 13 | B15: 1112010 | C15: เบาหวิวฝอยทอง 300 กรัม | D15: 120 | E15: 13 | I15: 13
A16: 14 | B16: 1112011 | C16: เบาหวิวฝอยทอง 110 กรัม | D16: 50 | E16: 3 | H16: 3 | J16: 150
A17: 15 | B17: 1111017 | C17: ชิฟฟ่อนสอดไส้แยมบลูเบอร์รี่ 3 ชิ้น | D17: 55
A18: 16 | B18: 1111012 | C18: ชิฟฟ่อนสอดไส้นมชมพูฮอกไกโด 6 ชิ้น | D18: 100
A19: 17 | B19: 1112012 | C19: เบาหวิวเผือกมะพร้าว 300 กรัม | D19: 120
A20: 18 | B20: 1112013 | C20: เบาหวิวเผือกมะพร้าว 110 กรัม | D20: 50 | E20: 9 | H20: 5 | I20: 4 | J20: 250
A21: 19 | B21: 1113131 | C21: เปี๊ยะโมจิฟัก 350 กรัม | D21: 120
A22: 20 | B22: 1113135 | C22: เปี๊ยะโมจิฟัก 700 กรัม | D22: 185
A23: 21 | B23: 1112017 | C23: เบาหวิวตาลหอม 110 กรัม | D23: 50 | E23: 8 | H23: 1 | I23: 7 | J23: 50
A24: 22 | B24: 1112015 | C24: เบาหวิวกล้วยหอมมะพร้าวเผา 110 กรัม | D24: 50 | E24: 12 | H24: 2 | I24: 10 | J24: 100
A25: 23 | B25: 1112005 | C25: เบาหวิวเนยสด 110 กรัม | D25: 50
A26: 24 | C26: เบาหวิวทุเรียน 110 กรัม | D26: 50
A27: 25 | B27: 1112003 | C27: เบาหวิวกาแฟ 110 กรัม | D27: 50
A28: 26 | C28: รถลาน | D28: 45 | E28: 38 | I28: 38
A29: 27 | C29: หัวรถไฟโทมัส | D29: 150 | E29: 1 | F29: 10 | G29: 1 | I29: 10
A30: 28 | C30: ปืน | D30: 150 | E30: 2 | H30: 1 | I30: 1 | J30: 150
A31: 29 | C31: โมเดลฮีโร่ | D31: 250
A32: 30 | C32: กระดานวาดเขียน | D32: 250
A33: 31 | C33: เป็ดแม่ | D33: 250
A34: 32 | C34: เป็ดลูก | D34: 150 | E34: 2 | I34: 2
A35: 33 | C35: ตัวบีบ | D35: 60 | E35: 4 | F35: 14 | H35: 4 | I35: 14 | J35: 240
A36: 34 | C36: ลานม้า | D36: 100
A37: 35 | C37: กระดานวาดเขียน(ใหม่) | D37: 200
A38: 36 | C38: ตุ๊กตา | D38: 150
A39: 37 | C39: ตุ๊กตานางฟ้าเต้น | D39: 400 | E39: 1 | I39: 1
A40: 38 | C40: สลาม | D40: 100 | E40: 22 | F40: 12 | H40: 6 | I40: 28 | J40: 600
...

Sheet 22
A1: ใบสต๊อกบูธ 10323 วัดใหม่สุปดิษฐาราม
A2: ลำดับ | B2: รหัส | C2: รายการสินค้า | D2: ราคา | E2: ยอดยกมา | F2: รับเข้า | G2: ส่งคืน | H2: ขายออก | I2: คงเหลือ | J2: ยอดเงิน | K2: หมายเหตุ
A3: 1 | B3: 1005982 | C3: ปังเนยนิ่ม 3 ชิ้น | D3: 55
A4: 2 | B4: 1200001 | C4: คอนเฟลกกระปุก | D4: 60 | E4: 6 | I4: 6
A5: 3 | B5: 1100003 | C5: เมอแรงค์กระปุก | D5: 55 | E5: 9 | H5: 1 | I5: 8 | J5: 55
A6: 4 | B6: 1200003 | C6: ท๊อฟฟี่กระเช้า | D6: 100 | E6: 7 | I6: 7
A7: 5 | B7: 1113121 | C7: เปี๊ยะไส้ถั่ว | D7: 120
A8: 6 | B8: 1113123 | C8: เปี๊ยะไส้เผือก | D8: 120 | E8: 4 | I8: 4
A9: 7 | B9: 1113122 | C9: เปี๊ยะไส้ฟัก | D9: 120 | E9: 5 | I9: 5
A10: 8 | B10: 1004055 | C10: ชิฟฟ่อนรวมรส 4 ชิ้น | D10: 55 | E10: 17 | I10: 17
A11: 9 | B11: 1111002 | C11: ชิฟฟ่อนรวมรส 8 ชิ้น | D11: 100 | E11: 14 | I11: 14
A12: 10 | B12: 1111056 | C12: ชิฟฟ่อนยอดฮิต | D12: 100 | E12: 5 | H12: 1 | I12: 4 | J12: 100
A13: 11 | B13: 1111009 | C13: ชิฟฟ่อนสอดไส้รวมรส 6 ชิ้น | D13: 100 | E13: 13 | H13: 1 | I13: 12 | J13: 100
A14: 12 | B14: 1112009 | C14: เบาหวิวมะพร้าวน้ำหอม 110 กรัม | D14: 50 | E14: 8 | H14: 1 | I14: 7 | J14: 50
A15: 13 | B15: 1112010 | C15: เบาหวิวฝอยทอง 300 กรัม | D15: 120 | E15: 13 | I15: 13
A16: 14 | B16: 1112011 | C16: เบาหวิวฝอยทอง 110 กรัม | D16: 50
A17: 15 | B17: 1111017 | C17: ชิฟฟ่อนสอดไส้แยมบลูเบอร์รี่ 3 ชิ้น | D17: 55
A18: 16 | B18: 1111012 | C18: ชิฟฟ่อนสอดไส้นมชมพูฮอกไกโด 6 ชิ้น | D18: 100
A19: 17 | B19: 1112012 | C19: เบาหวิวเผือกมะพร้าว 300 กรัม | D19: 120
A20: 18 | B20: 1112013 | C20: เบาหวิวเผือกมะพร้าว 110 กรัม | D20: 50 | E20: 4 | H20: 2 | I20: 2 | J20: 100
A21: 19 | B21: 1113131 | C21: เปี๊ยะโมจิฟัก 350 กรัม | D21: 120
A22: 20 | B22: 1113135 | C22: เปี๊ยะโมจิฟัก 700 กรัม | D22: 185
A23: 21 | B23: 1112017 | C23: เบาหวิวตาลหอม 110 กรัม | D23: 50 | E23: 7 | I23: 7
A24: 22 | B24: 1112015 | C24: เบาหวิวกล้วยหอมมะพร้าวเผา 110 กรัม | D24: 50 | E24: 10 | H24: 1 | I24: 9 | J24: 50
A25: 23 | B25: 1112005 | C25: เบาหวิวเนยสด 110 กรัม | D25: 50
A26: 24 | C26: เบาหวิวทุเรียน 110 กรัม | D26: 50
A27: 25 | B27: 1112003 | C27: เบาหวิวกาแฟ 110 กรัม | D27: 50
A28: 26 | C28: รถลาน | D28: 45 | E28: 38 | I28: 38
A29: 27 | C29: หัวรถไฟโทมัส | D29: 150 | E29: 10 | I29: 10
A30: 28 | C30: ปืน | D30: 150 | E30: 1 | I30: 1
A31: 29 | C31: โมเดลฮีโร่ | D31: 250
A32: 30 | C32: กระดานวาดเขียน | D32: 250
A33: 31 | C33: เป็ดแม่ | D33: 250
A34: 32 | C34: เป็ดลูก | D34: 150 | E34: 2 | I34: 2
A35: 33 | C35: ตัวบีบ | D35: 60 | E35: 14 | I35: 14
A36: 34 | C36: ลานม้า | D36: 100
A37: 35 | C37: กระดานวาดเขียน(ใหม่) | D37: 200
A38: 36 | C38: ตุ๊กตา | D38: 150
A39: 37 | C39: ตุ๊กตานางฟ้าเต้น | D39: 400 | E39: 1 | I39: 1
A40: 38 | C40: สลาม | D40: 100 | E40: 28 | H40: 2 | I40: 26 | J40: 200
...

Sheet 24
A1: ใบสต๊อกบูธ 10323 วัดใหม่สุปดิษฐาราม
A2: ลำดับ | B2: รหัส | C2: รายการสินค้า | D2: ราคา | E2: ยอดยกมา | F2: รับเข้า | G2: ส่งคืน | H2: ขายออก | I2: คงเหลือ | J2: ยอดเงิน | K2: หมายเหตุ
A3: 1 | B3: 1005982 | C3: ปังเนยนิ่ม 3 ชิ้น | D3: 55 | F3: 3 | I3: 3
A4: 2 | B4: 1200001 | C4: คอนเฟลกกระปุก | D4: 60 | E4: 6 | F4: 10 | I4: 16
A5: 3 | B5: 1100003 | C5: เมอแรงค์กระปุก | D5: 55 | E5: 8 | I5: 8
A6: 4 | B6: 1200003 | C6: ท๊อฟฟี่กระเช้า | D6: 100 | E6: 7 | H6: 3 | I6: 4 | J6: 300
A7: 5 | B7: 1113121 | C7: เปี๊ยะไส้ถั่ว | D7: 120 | F7: 5 | I7: 5
A8: 6 | B8: 1113123 | C8: เปี๊ยะไส้เผือก | D8: 120 | E8: 4 | I8: 4
A9: 7 | B9: 1113122 | C9: เปี๊ยะไส้ฟัก | D9: 120 | E9: 5 | I9: 5
A10: 8 | B10: 1004055 | C10: ชิฟฟ่อนรวมรส 4 ชิ้น | D10: 55 | E10: 17 | H10: 2 | I10: 15 | J10: 110
A11: 9 | B11: 1111002 | C11: ชิฟฟ่อนรวมรส 8 ชิ้น | D11: 100 | E11: 14 | I11: 14
A12: 10 | B12: 1111056 | C12: ชิฟฟ่อนยอดฮิต | D12: 100 | E12: 4 | F12: 15 | I12: 19
A13: 11 | B13: 1111009 | C13: ชิฟฟ่อนสอดไส้รวมรส 6 ชิ้น | D13: 100 | E13: 12 | F13: 10 | H13: 4 | I13: 18 | J13: 400
A14: 12 | B14: 1112009 | C14: เบาหวิวมะพร้าวน้ำหอม 110 กรัม | D14: 50 | E14: 7 | H14: 1 | I14: 6 | J14: 50
A15: 13 | B15: 1112010 | C15: เบาหวิวฝอยทอง 300 กรัม | D15: 120 | E15: 13 | H15: 2 | I15: 11 | J15: 240
A16: 14 | B16: 1112011 | C16: เบาหวิวฝอยทอง 110 กรัม | D16: 50 | F16: 10 | I16: 10
A17: 15 | B17: 1111017 | C17: ชิฟฟ่อนสอดไส้แยมบลูเบอร์รี่ 3 ชิ้น | D17: 55
A18: 16 | B18: 1111012 | C18: ชิฟฟ่อนสอดไส้นมชมพูฮอกไกโด 6 ชิ้น | D18: 100
A19: 17 | B19: 1112012 | C19: เบาหวิวเผือกมะพร้าว 300 กรัม | D19: 120
A20: 18 | B20: 1112013 | C20: เบาหวิวเผือกมะพร้าว 110 กรัม | D20: 50 | E20: 2 | F20: 10 | H20: 1 | I20: 11 | J20: 50
A21: 19 | B21: 1113131 | C21: เปี๊ยะโมจิฟัก 350 กรัม | D21: 120
A22: 20 | B22: 1113135 | C22: เปี๊ยะโมจิฟัก 700 กรัม | D22: 185
A23: 21 | B23: 1112017 | C23: เบาหวิวตาลหอม 110 กรัม | D23: 50 | E23: 7 | I23: 7
A24: 22 | B24: 1112015 | C24: เบาหวิวกล้วยหอมมะพร้าวเผา 110 กรัม | D24: 50 | E24: 9 | I24: 9
A25: 23 | B25: 1112005 | C25: เบาหวิวเนยสด 110 กรัม | D25: 50
A26: 24 | C26: เบาหวิวทุเรียน 110 กรัม | D26: 50
A27: 25 | B27: 1112003 | C27: เบาหวิวกาแฟ 110 กรัม | D27: 50
A28: 26 | C28: รถลาน | D28: 45 | E28: 38 | I28: 38
A29: 27 | C29: หัวรถไฟโทมัส | D29: 150 | E29: 10 | I29: 10
A30: 28 | C30: ปืน | D30: 150 | E30: 1 | I30: 1
A31: 29 | C31: โมเดลฮีโร่ | D31: 250
A32: 30 | C32: กระดานวาดเขียน | D32: 250
A33: 31 | C33: เป็ดแม่ | D33: 250
A34: 32 | C34: เป็ดลูก | D34: 150 | E34: 2 | I34: 2
A35: 33 | C35: ตัวบีบ | D35: 60 | E35: 14 | I35: 14
A36: 34 | C36: ลานม้า | D36: 100
A37: 35 | C37: กระดานวาดเขียน(ใหม่) | D37: 200
A38: 36 | C38: ตุ๊กตา | D38: 150
A39: 37 | C39: ตุ๊กตานางฟ้าเต้น | D39: 400 | E39: 1 | I39: 1
A40: 38 | C40: สลาม | D40: 100 | E40: 26 | I40: 26
...

Sheet 25
A1: ใบสต๊อกบูธ 10323 วัดใหม่สุปดิษฐาราม
A2: ลำดับ | B2: รหัส | C2: รายการสินค้า | D2: ราคา | E2: ยอดยกมา | F2: รับเข้า | G2: ส่งคืน | H2: ขายออก | I2: คงเหลือ | J2: ยอดเงิน | K2: หมายเหตุ
A3: 1 | B3: 1005982 | C3: ปังเนยนิ่ม 3 ชิ้น | D3: 55 | E3: 3 | I3: 3
A4: 2 | B4: 1200001 | C4: คอนเฟลกกระปุก | D4: 60 | E4: 16 | I4: 16
A5: 3 | B5: 1100003 | C5: เมอแรงค์กระปุก | D5: 55 | E5: 8 | I5: 8
A6: 4 | B6: 1200003 | C6: ท๊อฟฟี่กระเช้า | D6: 100 | E6: 4 | I6: 4
A7: 5 | B7: 1113121 | C7: เปี๊ยะไส้ถั่ว | D7: 120 | E7: 5 | I7: 5
A8: 6 | B8: 1113123 | C8: เปี๊ยะไส้เผือก | D8: 120 | E8: 4 | I8: 4
A9: 7 | B9: 1113122 | C9: เปี๊ยะไส้ฟัก | D9: 120 | E9: 5 | I9: 5
A10: 8 | B10: 1004055 | C10: ชิฟฟ่อนรวมรส 4 ชิ้น | D10: 55 | E10: 15 | I10: 15
A11: 9 | B11: 1111002 | C11: ชิฟฟ่อนรวมรส 8 ชิ้น | D11: 100 | E11: 14 | I11: 14
A12: 10 | B12: 1111056 | C12: ชิฟฟ่อนยอดฮิต | D12: 100 | E12: 19 | I12: 19
A13: 11 | B13: 1111009 | C13: ชิฟฟ่อนสอดไส้รวมรส 6 ชิ้น | D13: 100 | E13: 18 | I13: 18
A14: 12 | B14: 1112009 | C14: เบาหวิวมะพร้าวน้ำหอม 110 กรัม | D14: 50 | E14: 6 | H14: 2 | I14: 4 | J14: 100
A15: 13 | B15: 1112010 | C15: เบาหวิวฝอยทอง 300 กรัม | D15: 120 | E15: 11 | I15: 11
A16: 14 | B16: 1112011 | C16: เบาหวิวฝอยทอง 110 กรัม | D16: 50 | E16: 10 | I16: 10
A17: 15 | B17: 1111017 | C17: ชิฟฟ่อนสอดไส้แยมบลูเบอร์รี่ 3 ชิ้น | D17: 55
A18: 16 | B18: 1111012 | C18: ชิฟฟ่อนสอดไส้นมชมพูฮอกไกโด 6 ชิ้น | D18: 100
A19: 17 | B19: 1112012 | C19: เบาหวิวเผือกมะพร้าว 300 กรัม | D19: 120
A20: 18 | B20: 1112013 | C20: เบาหวิวเผือกมะพร้าว 110 กรัม | D20: 50 | E20: 11 | I20: 11
A21: 19 | B21: 1113131 | C21: เปี๊ยะโมจิฟัก 350 กรัม | D21: 120
A22: 20 | B22: 1113135 | C22: เปี๊ยะโมจิฟัก 700 กรัม | D22: 185
A23: 21 | B23: 1112017 | C23: เบาหวิวตาลหอม 110 กรัม | D23: 50 | E23: 7 | I23: 7
A24: 22 | B24: 1112015 | C24: เบาหวิวกล้วยหอมมะพร้าวเผา 110 กรัม | D24: 50 | E24: 9 | I24: 9
A25: 23 | B25: 1112005 | C25: เบาหวิวเนยสด 110 กรัม | D25: 50
A26: 24 | C26: เบาหวิวทุเรียน 110 กรัม | D26: 50
A27: 25 | B27: 1112003 | C27: เบาหวิวกาแฟ 110 กรัม | D27: 50
A28: 26 | C28: รถลาน | D28: 45 | E28: 38 | I28: 38
A29: 27 | C29: หัวรถไฟโทมัส | D29: 150 | E29: 10 | I29: 10
A30: 28 | C30: ปืน | D30: 150 | E30: 1 | I30: 1
A31: 29 | C31: โมเดลฮีโร่ | D31: 250
A32: 30 | C32: กระดานวาดเขียน | D32: 250
A33: 31 | C33: เป็ดแม่ | D33: 250
A34: 32 | C34: เป็ดลูก | D34: 150 | E34: 2 | I34: 2
A35: 33 | C35: ตัวบีบ | D35: 60 | E35: 14 | I35: 14
A36: 34 | C36: ลานม้า | D36: 100
A37: 35 | C37: กระดานวาดเขียน(ใหม่) | D37: 200
A38: 36 | C38: ตุ๊กตา | D38: 150
A39: 37 | C39: ตุ๊กตานางฟ้าเต้น | D39: 400 | E39: 1 | I39: 1
A40: 38 | C40: สลาม | D40: 100 | E40: 26 | I40: 26
...

Sheet 26
A1: ใบสต๊อกบูธ 10323 วัดใหม่สุปดิษฐาราม
A2: ลำดับ | B2: รหัส | C2: รายการสินค้า | D2: ราคา | E2: ยอดยกมา | F2: รับเข้า | G2: ส่งคืน | H2: ขายออก | I2: คงเหลือ | J2: ยอดเงิน | K2: หมายเหตุ
A3: 1 | B3: 1005982 | C3: ปังเนยนิ่ม 3 ชิ้น | D3: 55 | E3: 3 | I3: 3
A4: 2 | B4: 1200001 | C4: คอนเฟลกกระปุก | D4: 60 | E4: 16 | I4: 16
A5: 3 | B5: 1100003 | C5: เมอแรงค์กระปุก | D5: 55 | E5: 8 | I5: 8
A6: 4 | B6: 1200003 | C6: ท๊อฟฟี่กระเช้า | D6: 100 | E6: 4 | H6: 3 | I6: 1 | J6: 300
A7: 5 | B7: 1113121 | C7: เปี๊ยะไส้ถั่ว | D7: 120 | E7: 5 | I7: 5
A8: 6 | B8: 1113123 | C8: เปี๊ยะไส้เผือก | D8: 120 | E8: 4 | I8: 4
A9: 7 | B9: 1113122 | C9: เปี๊ยะไส้ฟัก | D9: 120 | E9: 5 | I9: 5
A10: 8 | B10: 1004055 | C10: ชิฟฟ่อนรวมรส 4 ชิ้น | D10: 55 | E10: 15 | I10: 15
A11: 9 | B11: 1111002 | C11: ชิฟฟ่อนรวมรส 8 ชิ้น | D11: 100 | E11: 14 | H11: 1 | I11: 13 | J11: 100
A12: 10 | B12: 1111056 | C12: ชิฟฟ่อนยอดฮิต | D12: 100 | E12: 19 | H12: 1 | I12: 18 | J12: 100
A13: 11 | B13: 1111009 | C13: ชิฟฟ่อนสอดไส้รวมรส 6 ชิ้น | D13: 100 | E13: 18 | H13: 6 | I13: 12 | J13: 600
A14: 12 | B14: 1112009 | C14: เบาหวิวมะพร้าวน้ำหอม 110 กรัม | D14: 50 | E14: 4 | H14: 1 | I14: 3 | J14: 50
A15: 13 | B15: 1112010 | C15: เบาหวิวฝอยทอง 300 กรัม | D15: 120 | E15: 11 | I15: 11
A16: 14 | B16: 1112011 | C16: เบาหวิวฝอยทอง 110 กรัม | D16: 50 | E16: 10 | H16: 2 | I16: 8 | J16: 100
A17: 15 | B17: 1111017 | C17: ชิฟฟ่อนสอดไส้แยมบลูเบอร์รี่ 3 ชิ้น | D17: 55
A18: 16 | B18: 1111012 | C18: ชิฟฟ่อนสอดไส้นมชมพูฮอกไกโด 6 ชิ้น | D18: 100
A19: 17 | B19: 1112012 | C19: เบาหวิวเผือกมะพร้าว 300 กรัม | D19: 120
A20: 18 | B20: 1112013 | C20: เบาหวิวเผือกมะพร้าว 110 กรัม | D20: 50 | E20: 11 | G20: 1 | H20: 2 | I20: 8 | J20: 100
A21: 19 | B21: 1113131 | C21: เปี๊ยะโมจิฟัก 350 กรัม | D21: 120
A22: 20 | B22: 1113135 | C22: เปี๊ยะโมจิฟัก 700 กรัม | D22: 185
A23: 21 | B23: 1112017 | C23: เบาหวิวตาลหอม 110 กรัม | D23: 50 | E23: 7 | G23: 1 | H23: 1 | I23: 5 | J23: 50
A24: 22 | B24: 1112015 | C24: เบาหวิวกล้วยหอมมะพร้าวเผา 110 กรัม | D24: 50 | E24: 9 | H24: 3 | I24: 6 | J24: 100 | K24: แถม1กล่อง
A25: 23 | B25: 1112005 | C25: เบาหวิวเนยสด 110 กรัม | D25: 50
