Workbook

Sheet Month
A1: ลำดับ | B1: ทีมโทร | C1: บูธ | D1: online | E1: Modern Trade | F1: รหัส | G1: ชื่อสินค้า | H1: ลูกค้า | I1: ขนาดบรรจุ | N1: week 1 (วันที่ 29-4 มกราคม 2567) | AI1: week 2 (วันที่ 5-11 มกราคม 2567) | BD1: week 3 (วันที่ 12-18 มกราคม 2567) | BY1: week 4 (วันที่ 19-25 มกราคม 2567) | CT1: week 4 (วันที่ 26-2 กุมภาพันธ์ 2567)
I2: จำนวน(ชิ้น) | J2: หน่วย(กล่อง) | K2: วัน | N2: วันอาทิตย์ | Q2: วันจันทร์ | T2: วันอังคาร | W2: วันพุธ | Z2: วันพฤหัสบดี | AC2: วันศุกร์ | AF2: เสาร์ | AI2: วันอาทิตย์ | AL2: วันจันทร์ | AO2: วันอังคาร | AR2: วันพุธ | AU2: วันพฤหัสบดี | AX2: วันศุกร์ | BA2: เสาร์ | BD2: วันอาทิตย์ | BG2: วันจันทร์ | BJ2: วันอังคาร | BM2: วันพุธ | BP2: วันพฤหัสบดี | BS2: วันศุกร์ | BV2: เสาร์ | BY2: วันอาทิตย์ | CB2: วันจันทร์ | CE2: วันอังคาร | CH2: วันพุธ | CK2: วันพฤหัสบดี | CN2: วันศุกร์ | CQ2: เสาร์ | CT2: วันอาทิตย์ | CW2: วันจันทร์ | CZ2: วันอังคาร | DC2: วันพุธ | DF2: วันพฤหัสบดี | DI2: วันศุกร์ | DL2: เสาร์
K3: วันที่ | O3: 29 | R3: 30 | U3: 31 | X3: 1 | AA3: 2 | AD3: 3 | AG3: 4 | AJ3: 5 | AM3: 6 | AP3: 7 | AS3: 8 | AV3: 9 | AY3: 10 | BB3: 11 | BE3: 12 | BH3: 13 | BK3: 14 | BN3: 15 | BQ3: 16 | BT3: 17 | BW3: 18 | BZ3: 19 | CC3: 20 | CF3: 21 | CI3: 22 | CL3: 23 | CO3: 24 | CR3: 25 | CU3: 26 | CX3: 27 | DA3: 28 | DD3: 29 | DF3: 30 | DI3: 31 | DL3: 1
K4: ติดป้าย Amezon | L4: ไม่ติดป้าย Amezon | M4: Non Logo | N4: ติดป้าย Amezon | O4: ไม่ติดป้าย Amezon | P4: Non Logo | Q4: ติดป้าย Amezon | R4: ไม่ติดป้าย Amezon | S4: Non Logo | T4: ติดป้าย Amezon | U4: ไม่ติดป้าย Amezon | V4: Non Logo | W4: ติดป้าย Amezon | X4: ไม่ติดป้าย Amezon | Y4: Non Logo | Z4: ติดป้าย Amezon | AA4: ไม่ติดป้าย Amezon | AB4: Non Logo | AC4: ติดป้าย Amezon | AD4: ไม่ติดป้าย Amezon | AE4: Non Logo | AF4: ติดป้าย Amezon | AG4: ไม่ติดป้าย Amezon | AH4: Non Logo | AI4: ติดป้าย Amezon | AJ4: ไม่ติดป้าย Amezon | AK4: Non Logo | AL4: ติดป้าย Amezon | AM4: ไม่ติดป้าย Amezon | AN4: Non Logo | AO4: ติดป้าย Amezon | AP4: ไม่ติดป้าย Amezon | AQ4: Non Logo | AR4: ติดป้าย Amezon | AS4: ไม่ติดป้าย Amezon | AT4: Non Logo | AU4: ติดป้าย Amezon | AV4: ไม่ติดป้าย Amezon | AW4: Non Logo | AX4: ติดป้าย Amezon | AY4: ไม่ติดป้าย Amezon | AZ4: Non Logo | BA4: ติดป้าย Amezon | BB4: ไม่ติดป้าย Amezon | BC4: Non Logo | BD4: ติดป้าย Amezon | BE4: ไม่ติดป้าย Amezon | BF4: Non Logo | BG4: ติดป้าย Amezon | BH4: ไม่ติดป้าย Amezon | BI4: Non Logo | BJ4: ติดป้าย Amezon | BK4: ไม่ติดป้าย Amezon | BL4: Non Logo | BM4: ติดป้าย Amezon | BN4: ไม่ติดป้าย Amezon | BO4: Non Logo | BP4: ติดป้าย Amezon | BQ4: ไม่ติดป้าย Amezon | BR4: Non Logo | BS4: ติดป้าย Amezon | BT4: ไม่ติดป้าย Amezon | BU4: Non Logo | BV4: ติดป้าย Amezon | BW4: ไม่ติดป้าย Amezon | BX4: Non Logo | BY4: ติดป้าย Amezon | BZ4: ไม่ติดป้าย Amezon | CA4: Non Logo | CB4: ติดป้าย Amezon | CC4: ไม่ติดป้าย Amezon | CD4: Non Logo | CE4: ติดป้าย Amezon | CF4: ไม่ติดป้าย Amezon | CG4: Non Logo | CH4: ติดป้าย Amezon | CI4: ไม่ติดป้าย Amezon | CJ4: Non Logo | CK4: ติดป้าย Amezon | CL4: ไม่ติดป้าย Amezon | CM4: Non Logo | CN4: ติดป้าย Amezon | CO4: ไม่ติดป้าย Amezon | CP4: Non Logo | CQ4: ติดป้าย Amezon | CR4: ไม่ติดป้าย Amezon | CS4: Non Logo | CT4: ติดป้าย Amezon | CU4: ไม่ติดป้าย Amezon | CV4: Non Logo | CW4: ติดป้าย Amezon | CX4: ไม่ติดป้าย Amezon | CY4: Non Logo | CZ4: ติดป้าย Amezon | DA4: ไม่ติดป้าย Amezon | DB4: Non Logo | DC4: ติดป้าย Amezon | DD4: ไม่ติดป้าย Amezon | DE4: Non Logo | DF4: ติดป้าย Amezon | DG4: ไม่ติดป้าย Amezon | DH4: Non Logo | DI4: ติดป้าย Amezon | DJ4: ไม่ติดป้าย Amezon | DK4: Non Logo | DL4: ติดป้าย Amezon | DM4: ไม่ติดป้าย Amezon | DN4: Non Logo
A5: 1 | F5: 1113036 | G5: ช็อกบอล | H5: Aeon | K5: 0 | L5: =SUM(O5,R5,U5,X5,AA5,AD5,AG5,AJ5,AM5,AP5,AS5,AV5,AY5,BB5,BE5,BH5,BK5,BN5,BQ5,BT5,BW5,BZ5,CC5,CF5,CI5,CL5,CO5,CR5) -> 0 | M5: 0
A6: 2 | F6: 1111001 | G6: ชิฟฟ่อนเค้ก (1 ชิ้น) | H6: Aeon | K6: 0 | L6: =SUM(O6,R6,U6,X6,AA6,AD6,AG6,AJ6,AM6,AP6,AS6,AV6,AY6,BB6,BE6,BH6,BK6,BN6,BQ6,BT6,BW6,BZ6,CC6,CF6,CI6,CL6,CO6,CR6) -> 0 | M6: 0
A7: 3 | F7: 1004055 | G7: ชิฟฟ่อนเค้ก วรรณวนัช (รวมรส 4 ชิ้น) | K7: 0 | L7: =SUM(O7,R7,U7,X7,AA7,AD7,AG7,AJ7,AM7,AP7,AS7,AV7,AY7,BB7,BE7,BH7,BK7,BN7,BQ7,BT7,BW7,BZ7,CC7,CF7,CI7,CL7,CO7,CR7) -> 0 | M7: 0
A8: 4 | F8: 1111002 | G8: ชิฟฟ่อนเค้ก วรรณวนัช (รวมรส 8 ชิ้น) | H8: Lotus | K8: 0 | L8: =SUM(O8,R8,U8,X8,AA8,AD8,AG8,AJ8,AM8,AP8,AS8,AV8,AY8,BB8,BE8,BH8,BK8,BN8,BQ8,BT8,BW8,BZ8,CC8,CF8,CI8,CL8,CO8,CR8) -> 0 | M8: 0
A9: 5 | F9: 1111055 | G9: วรรณวนัช ชิฟฟ่อนรวมรส 8 ชิ้น | H9: Makro | K9: 0 | L9: =SUM(O9,R9,U9,X9,AA9,AD9,AG9,AJ9,AM9,AP9,AS9,AV9,AY9,BB9,BE9,BH9,BK9,BN9,BQ9,BT9,BW9,BZ9,CC9,CF9,CI9,CL9,CO9,CR9) -> 0 | M9: 0
A10: 6 | F10: 1111030 | G10: ชิฟฟ่อนเค้ก รสกาแฟ (8 ชิ้น) | K10: 0 | L10: =SUM(O10,R10,U10,X10,AA10,AD10,AG10,AJ10,AM10,AP10,AS10,AV10,AY10,BB10,BE10,BH10,BK10,BN10,BQ10,BT10,BW10,BZ10,CC10,CF10,CI10,CL10,CO10,CR10) -> 0 | M10: 0
A11: 7 | F11: 1111036 | G11: ชิฟฟอนเค้ก วรรณวนัช ห่อกระดาษ (รวมรส 4 ชิ้น) | K11: 0 | L11: =SUM(O11,R11,U11,X11,AA11,AD11,AG11,AJ11,AM11,AP11,AS11,AV11,AY11,BB11,BE11,BH11,BK11,BN11,BQ11,BT11,BW11,BZ11,CC11,CF11,CI11,CL11,CO11,CR11) -> 0 | M11: 0
A12: 8 | F12: 1111037 | G12: ชิฟฟอนเค้ก วรรณวนัช ห่อกระดาษ (รวมรส 8 ชิ้น) | K12: 0 | L12: =SUM(O12,R12,U12,X12,AA12,AD12,AG12,AJ12,AM12,AP12,AS12,AV12,AY12,BB12,BE12,BH12,BK12,BN12,BQ12,BT12,BW12,BZ12,CC12,CF12,CI12,CL12,CO12,CR12) -> 0 | M12: 0
A13: 9 | F13: 1111040 | G13: ชิฟฟอนเค้กวรรณวนัช ห่อซีน (รวมรส 4 ชิ้น) | K13: 0 | L13: =SUM(O13,R13,U13,X13,AA13,AD13,AG13,AJ13,AM13,AP13,AS13,AV13,AY13,BB13,BE13,BH13,BK13,BN13,BQ13,BT13,BW13,BZ13,CC13,CF13,CI13,CL13,CO13,CR13) -> 0 | M13: 0
A14: 10 | F14: 1111039 | G14: ชิฟฟอนเค้ก วรรรณวนัช ห่อซีน (รวมรส 8 ชิ้น) | K14: 0 | L14: =SUM(O14,R14,U14,X14,AA14,AD14,AG14,AJ14,AM14,AP14,AS14,AV14,AY14,BB14,BE14,BH14,BK14,BN14,BQ14,BT14,BW14,BZ14,CC14,CF14,CI14,CL14,CO14,CR14) -> 0 | M14: 0
A15: 11 | F15: 1111041 | G15: ชิฟฟอนเค้ก วรรณวนัช กาแฟล้วน(รวมรส 4 ชิ้น) | K15: 0 | L15: =SUM(O15,R15,U15,X15,AA15,AD15,AG15,AJ15,AM15,AP15,AS15,AV15,AY15,BB15,BE15,BH15,BK15,BN15,BQ15,BT15,BW15,BZ15,CC15,CF15,CI15,CL15,CO15,CR15) -> 0 | M15: 0
A16: 12 | F16: 1111043 | G16: ชิฟฟอนรสมะลิ 8 ชิ้น ห่อ ซีน | K16: 0 | L16: =SUM(O16,R16,U16,X16,AA16,AD16,AG16,AJ16,AM16,AP16,AS16,AV16,AY16,BB16,BE16,BH16,BK16,BN16,BQ16,BT16,BW16,BZ16,CC16,CF16,CI16,CL16,CO16,CR16) -> 0 | M16: 0
A17: 13 | F17: 1113091 | G17: (BC) ชิฟฟ่อนรวมรส 4 ชิ้น | H17: BC | K17: 0 | L17: =SUM(O17,R17,U17,X17,AA17,AD17,AG17,AJ17,AM17,AP17,AS17,AV17,AY17,BB17,BE17,BH17,BK17,BN17,BQ17,BT17,BW17,BZ17,CC17,CF17,CI17,CL17,CO17,CR17) -> 0 | M17: 0
A18: 14 | F18: 1113083 | G18: (BC) ชิฟฟ่อนฝอยทอง 1 ชิ้น ไม่มีไส้ | K18: 0 | L18: =SUM(O18,R18,U18,X18,AA18,AD18,AG18,AJ18,AM18,AP18,AS18,AV18,AY18,BB18,BE18,BH18,BK18,BN18,BQ18,BT18,BW18,BZ18,CC18,CF18,CI18,CL18,CO18,CR18) -> 0 | M18: 0
A19: 15 | F19: 1111057 | G19: ชิฟฟอนแยกชิ้น กาแฟ | K19: 0 | L19: =SUM(O19,R19,U19,X19,AA19,AD19,AG19,AJ19,AM19,AP19,AS19,AV19,AY19,BB19,BE19,BH19,BK19,BN19,BQ19,BT19,BW19,BZ19,CC19,CF19,CI19,CL19,CO19,CR19) -> 0 | M19: 0
A20: 16 | F20: 1111058 | G20: ชิฟฟอนแยกชิ้น ชาเขียว | K20: 0 | L20: =SUM(O20,R20,U20,X20,AA20,AD20,AG20,AJ20,AM20,AP20,AS20,AV20,AY20,BB20,BE20,BH20,BK20,BN20,BQ20,BT20,BW20,BZ20,CC20,CF20,CI20,CL20,CO20,CR20) -> 0 | M20: 0
A21: 17 | F21: 1111059 | G21: ชิฟฟอนแยกชิ้น ใบเตย | K21: 0 | L21: =SUM(O21,R21,U21,X21,AA21,AD21,AG21,AJ21,AM21,AP21,AS21,AV21,AY21,BB21,BE21,BH21,BK21,BN21,BQ21,BT21,BW21,BZ21,CC21,CF21,CI21,CL21,CO21,CR21) -> 0 | M21: 0
A22: 18 | F22: 1111060 | G22: ชิฟฟอนแยกชิ้น กล้วยหอม | K22: 0 | L22: =SUM(O22,R22,U22,X22,AA22,AD22,AG22,AJ22,AM22,AP22,AS22,AV22,AY22,BB22,BE22,BH22,BK22,BN22,BQ22,BT22,BW22,BZ22,CC22,CF22,CI22,CL22,CO22,CR22) -> 0 | M22: 0
A23: 19 | F23: 1111061 | G23: ชิฟฟอนแยกชิ้น ชาไทย | K23: 0 | L23: =SUM(O23,R23,U23,X23,AA23,AD23,AG23,AJ23,AM23,AP23,AS23,AV23,AY23,BB23,BE23,BH23,BK23,BN23,BQ23,BT23,BW23,BZ23,CC23,CF23,CI23,CL23,CO23,CR23) -> 0 | M23: 0
A24: 20 | F24: 1111062 | G24: ชิฟฟอนแยกชิ้น โกโก้ | K24: 0 | L24: =SUM(O24,R24,U24,X24,AA24,AD24,AG24,AJ24,AM24,AP24,AS24,AV24,AY24,BB24,BE24,BH24,BK24,BN24,BQ24,BT24,BW24,BZ24,CC24,CF24,CI24,CL24,CO24,CR24) -> 0 | M24: 0
A25: 21 | F25: 1111063 | G25: ชิฟฟอนแยกชิ้น ส้ม | K25: 0 | L25: =SUM(O25,R25,U25,X25,AA25,AD25,AG25,AJ25,AM25,AP25,AS25,AV25,AY25,BB25,BE25,BH25,BK25,BN25,BQ25,BT25,BW25,BZ25,CC25,CF25,CI25,CL25,CO25,CR25) -> 0 | M25: 0
A26: 22 | F26: 1111064 | G26: ชิฟฟอนแยกชิ้น เผือก | K26: 0 | L26: =SUM(O26,R26,U26,X26,AA26,AD26,AG26,AJ26,AM26,AP26,AS26,AV26,AY26,BB26,BE26,BH26,BK26,BN26,BQ26,BT26,BW26,BZ26,CC26,CF26,CI26,CL26,CO26,CR26) -> 0 | M26: 0
A27: 23 | F27: 1111065 | G27: ชิฟฟอนแยกชิ้น สับปะรด | K27: 0 | L27: =SUM(O27,R27,U27,X27,AA27,AD27,AG27,AJ27,AM27,AP27,AS27,AV27,AY27,BB27,BE27,BH27,BK27,BN27,BQ27,BT27,BW27,BZ27,CC27,CF27,CI27,CL27,CO27,CR27) -> 0 | M27: 0
A28: 24 | F28: 1111066 | G28: ชิฟฟอนแยกชิ้น สตอเบอรี่ | K28: 0 | L28: =SUM(O28,R28,U28,X28,AA28,AD28,AG28,AJ28,AM28,AP28,AS28,AV28,AY28,BB28,BE28,BH28,BK28,BN28,BQ28,BT28,BW28,BZ28,CC28,CF28,CI28,CL28,CO28,CR28) -> 0 | M28: 0
A29: 25 | F29: 1111067 | G29: ชิฟฟอนแยกชิ้น มะพร้าว | K29: 0 | L29: =SUM(O29,R29,U29,X29,AA29,AD29,AG29,AJ29,AM29,AP29,AS29,AV29,AY29,BB29,BE29,BH29,BK29,BN29,BQ29,BT29,BW29,BZ29,CC29,CF29,CI29,CL29,CO29,CR29) -> 0 | M29: 0
... A31: 27 | F31: 1111069 | G31: ชิฟฟอนแยกชิ้น บลูเบอรี่ | K31: 0 | L31: =SUM(O31,R31,U31,X31,AA31,AD31,AG31,AJ31,AM31,AP31,AS31,AV31,AY31,BB31,BE31,BH31,BK31,BN31,BQ31,BT31,BW31,BZ31,CC31,CF31,CI31,CL31,CO31,CR31) -> 0 | M31: 0
A32: 28 | F32: 1004061 | G32: ชิฟฟ่อนเค้ก สอดไส้ครีมมะพร้าว (2 ชิ้น) | H32: Aeon | K32: 0 | L32: =SUM(O32,R32,U32,X32,AA32,AD32,AG32,AJ32,AM32,AP32,AS32,AV32,AY32,BB32,BE32,BH32,BK32,BN32,BQ32,BT32,BW32,BZ32,CC32,CF32,CI32,CL32,CO32,CR32) -> 0 | M32: 0
A33: 29 | F33: 1111051 | G33: ชิฟฟ่อนเค้กสอดไส้ครีมมะพร้าว (2ชิ้น) มะพร้าวล้วน | K33: 0 | L33: =SUM(O33,R33,U33,X33,AA33,AD33,AG33,AJ33,AM33,AP33,AS33,AV33,AY33,BB33,BE33,BH33,BK33,BN33,BQ33,BT33,BW33,BZ33,CC33,CF33,CI33,CL33,CO33,CR33) -> 0 | M33: 0
A34: 30 | F34: 1111004 | G34: ชิฟฟ่อนเค้ก สอดไส้ครีมมะพร้าว (4 ชิ้น) | K34: 0 | L34: =SUM(O34,R34,U34,X34,AA34,AD34,AG34,AJ34,AM34,AP34,AS34,AV34,AY34,BB34,BE34,BH34,BK34,BN34,BQ34,BT34,BW34,BZ34,CC34,CF34,CI34,CL34,CO34,CR34) -> 0 | M34: 0
A35: 31 | F35: 1111048 | G35: ชิฟฟอนเค้กสอดไส้ครีมมะพร้าว+เตย (4ชิ้น) | K35: 0 | L35: =SUM(O35,R35,U35,X35,AA35,AD35,AG35,AJ35,AM35,AP35,AS35,AV35,AY35,BB35,BE35,BH35,BK35,BN35,BQ35,BT35,BW35,BZ35,CC35,CF35,CI35,CL35,CO35,CR35) -> 0 | M35: 0
A36: 32 | F36: 1111005 | G36: ชิฟฟ่อนเค้ก สอดไส้ครีมมะพร้าว (5 ชิ้น) | K36: 0 | L36: =SUM(O36,R36,U36,X36,AA36,AD36,AG36,AJ36,AM36,AP36,AS36,AV36,AY36,BB36,BE36,BH36,BK36,BN36,BQ36,BT36,BW36,BZ36,CC36,CF36,CI36,CL36,CO36,CR36) -> 0 | M36: 0
A37: 33 | F37: 1111047 | G37: ชิฟฟอนเค้กสอดไส้ครีมมะพร้าว+เตย (5ชิ้น) | K37: 0 | L37: =SUM(O37,R37,U37,X37,AA37,AD37,AG37,AJ37,AM37,AP37,AS37,AV37,AY37,BB37,BE37,BH37,BK37,BN37,BQ37,BT37,BW37,BZ37,CC37,CF37,CI37,CL37,CO37,CR37) -> 0 | M37: 0
A38: 34 | F38: 1111006 | G38: ชิฟฟ่อนเค้ก วรรณวนัช (สอดไส้รวมรส 8 ชิ้น) | K38: 0 | L38: =SUM(O38,R38,U38,X38,AA38,AD38,AG38,AJ38,AM38,AP38,AS38,AV38,AY38,BB38,BE38,BH38,BK38,BN38,BQ38,BT38,BW38,BZ38,CC38,CF38,CI38,CL38,CO38,CR38) -> 0 | M38: 0
A39: 35 | F39: 1111034 | G39: ชิฟฟ่อนเค้กใบเตยสอดไส้ครีมมะพร้าว (8 ชิ้น ) | K39: 0 | L39: =SUM(O39,R39,U39,X39,AA39,AD39,AG39,AJ39,AM39,AP39,AS39,AV39,AY39,BB39,BE39,BH39,BK39,BN39,BQ39,BT39,BW39,BZ39,CC39,CF39,CI39,CL39,CO39,CR39) -> 0 | M39: 0
A40: 36 | F40: 1111035 | G40: ชิฟฟ่อนเค้กมะพร้าวสอดไส้ครีมมะพร้าว (8 ชิ้น) | K40: 0 | L40: =SUM(O40,R40,U40,X40,AA40,AD40,AG40,AJ40,AM40,AP40,AS40,AV40,AY40,BB40,BE40,BH40,BK40,BN40,BQ40,BT40,BW40,BZ40,CC40,CF40,CI40,CL40,CO40,CR40) -> 0 | M40: 0
A41: 37 | F41: 1111031 | G41: ชิฟฟ่อนเค้กทูโทนใบเตยและมะพร้าวสอดไส้ครีม (8 ชิ้น) | K41: 0 | L41: =SUM(O41,R41,U41,X41,AA41,AD41,AG41,AJ41,AM41,AP41,AS41,AV41,AY41,BB41,BE41,BH41,BK41,BN41,BQ41,BT41,BW41,BZ41,CC41,CF41,CI41,CL41,CO41,CR41) -> 0 | M41: 0
...

Sheet Week 1
A1: ลำดับ | B1: ทีมโทร | C1: บูธ | D1: online | E1: Modern Trade | F1: รหัส | G1: ชื่อสินค้า | H1: ลูกค้า | I1: ขนาดบรรจุ | N1: week 1 (วันที่ 30 พฤศจิกายน - 6 ธันวาคม 2568)
I2: จำนวน(ชิ้น) | J2: หน่วย(กล่อง) | K2: วัน | N2: วันอาทิตย์ | R2: ยอดจริง | X2: วันจันทร์ | AB2: ยอดจริง | AH2: วันอังคาร | AL2: ยอดจริง | AR2: วันพุธ | AV2: ยอดจริง | BB2: วันพฤหัสบดี | BF2: ยอดจริง | BL2: วันศุกร์ | BP2: ยอดจริง | BV2: เสาร์ | BZ2: ยอดจริง
K3: วันที่
K4: ติดป้าย Amezon | L4: ไม่ติดป้าย Amezon | M4: Non Logo | N4: ติดป้าย Amezon | O4: ไม่ติดป้าย Amezon | P4: Non Logo | Q4: รวม | R4: ติดป้าย Amezon | S4: ไม่ติดป้าย Amezon | T4: Non Logo | U4: ติดป้าย Amezon | V4: ไม่ติดป้าย Amezon | W4: Non Logo | X4: ติดป้าย Amezon | Y4: ไม่ติดป้าย Amezon | Z4: Non Logo | AA4: รวม | AB4: ติดป้าย Amezon | AC4: ไม่ติดป้าย Amezon | AD4: Non Logo | AE4: ติดป้าย Amezon | AF4: ไม่ติดป้าย Amezon | AG4: Non Logo | AH4: ติดป้าย Amezon | AI4: ไม่ติดป้าย Amezon | AJ4: Non Logo | AK4: รวม | AL4: ติดป้าย Amezon | AM4: ไม่ติดป้าย Amezon | AN4: Non Logo | AO4: ติดป้าย Amezon | AP4: ไม่ติดป้าย Amezon | AQ4: Non Logo | AR4: ติดป้าย Amezon | AS4: ไม่ติดป้าย Amezon | AT4: Non Logo | AU4: รวม | AV4: ติดป้าย Amezon | AW4: ไม่ติดป้าย Amezon | AX4: Non Logo | AY4: ติดป้าย Amezon | AZ4: ไม่ติดป้าย Amezon | BA4: Non Logo | BB4: ติดป้าย Amezon | BC4: ไม่ติดป้าย Amezon | BD4: Non Logo | BE4: รวม | BF4: ติดป้าย Amezon | BG4: ไม่ติดป้าย Amezon | BH4: Non Logo | BI4: ติดป้าย Amezon | BJ4: ไม่ติดป้าย Amezon | BK4: Non Logo | BL4: ติดป้าย Amezon | BM4: ไม่ติดป้าย Amezon | BN4: Non Logo | BO4: รวม | BP4: ติดป้าย Amezon | BQ4: ไม่ติดป้าย Amezon | BR4: Non Logo | BS4: ติดป้าย Amezon | BT4: ไม่ติดป้าย Amezon | BU4: Non Logo | BV4: ติดป้าย Amezon | BW4: ไม่ติดป้าย Amezon | BX4: Non Logo | BY4: รวม | BZ4: ติดป้าย Amezon | CA4: ไม่ติดป้าย Amezon | CB4: Non Logo | CC4: ติดป้าย Amezon | CD4: ไม่ติดป้าย Amezon | CE4: Non Logo
A5: 1 | F5: 1113036 | G5: ช๊อคบอล | H5: Aeon | K5: 0 | L5: =SUM(O5,Y5,AI5,AS5,BC5,BM5,BW5) -> 20 | M5: 0 | O5: 10 | BC5: 10 | BY5: =SUM(BV5:BX5) -> 0 | BZ5: 0 | CA5: 0 | CB5: 0 | CC5: 0 | CD5: =BW5-CA5 -> 0 | CE5: 0
A6: 2 | F6: 1111001 | G6: ชิฟฟ่อนเค้ก (1 ชิ้น) | H6: Aeon | K6: 0 | L6: =SUM(O6,Y6,AI6,AS6,BC6,BM6,BW6) -> 0 | M6: 0 | BY6: =SUM(BV6:BX6) -> 0 | BZ6: 0 | CA6: 0 | CB6: 0 | CC6: 0 | CD6: =BW6-CA6 -> 0 | CE6: 0
A7: 3 | F7: 1004055 | G7: ชิฟฟ่อนเค้ก วรรณวนัช (รวมรส 4 ชิ้น) | K7: 0 | L7: =SUM(O7,Y7,AI7,AS7,BC7,BM7,BW7) -> 0 | M7: 0 | BY7: =SUM(BV7:BX7) -> 0 | BZ7: 0 | CA7: 0 | CB7: 0 | CC7: 0 | CD7: =BW7-CA7 -> 0 | CE7: 0
A8: 4 | F8: 1111002 | G8: ชิฟฟ่อนเค้ก วรรณวนัช (รวมรส 8 ชิ้น) | H8: Lotus | K8: 0 | L8: =SUM(O8,Y8,AI8,AS8,BC8,BM8,BW8) -> 0 | M8: 0 | BY8: =SUM(BV8:BX8) -> 0 | BZ8: 0 | CA8: 0 | CB8: 0 | CC8: 0 | CD8: =BW8-CA8 -> 0 | CE8: 0
A9: 5 | F9: 1111055 | G9: วรรณวนัช ชิฟฟ่อนรวมรส 8 ชิ้น | H9: Makro | K9: 0 | L9: =SUM(O9,Y9,AI9,AS9,BC9,BM9,BW9) -> 1660 | M9: 0 | O9: 830 | AI9: 830 | BY9: =SUM(BV9:BX9) -> 0 | BZ9: 0 | CA9: 0 | CB9: 0 | CC9: 0 | CD9: =BW9-CA9 -> 0 | CE9: 0
A10: 6 | F10: 1111030 | G10: ชิฟฟ่อนเค้ก รสกาแฟ (8 ชิ้น) | K10: 0 | L10: =SUM(O10,Y10,AI10,AS10,BC10,BM10,BW10) -> 0 | M10: 0 | BY10: =SUM(BV10:BX10) -> 0 | BZ10: 0 | CA10: 0 | CB10: 0 | CC10: 0 | CD10: =BW10-CA10 -> 0 | CE10: 0
A11: 7 | F11: 1111036 | G11: ชิฟฟอนเค้ก วรรณวนัช ห่อกระดาษ (รวมรส 4 ชิ้น) | K11: 0 | L11: =SUM(O11,Y11,AI11,AS11,BC11,BM11,BW11) -> 0 | M11: 0 | BY11: =SUM(BV11:BX11) -> 0 | BZ11: 0 | CA11: 0 | CB11: 0 | CC11: 0 | CD11: =BW11-CA11 -> 0 | CE11: 0
A12: 8 | F12: 1111037 | G12: ชิฟฟอนเค้ก วรรณวนัช ห่อกระดาษ (รวมรส 8 ชิ้น) | K12: 0 | L12: =SUM(O12,Y12,AI12,AS12,BC12,BM12,BW12) -> 0 | M12: 0 | BY12: =SUM(BV12:BX12) -> 0 | BZ12: 0 | CA12: 0 | CB12: 0 | CC12: 0 | CD12: =BW12-CA12 -> 0 | CE12: 0
A13: 9 | F13: 1111040 | G13: ชิฟฟอนเค้กวรรณวนัช ห่อซีน (รวมรส 4 ชิ้น) | K13: 0 | L13: =SUM(O13,Y13,AI13,AS13,BC13,BM13,BW13) -> 0 | M13: 0 | BY13: =SUM(BV13:BX13) -> 0 | BZ13: 0 | CA13: 0 | CB13: 0 | CC13: 0 | CD13: =BW13-CA13 -> 0 | CE13: 0
A14: 10 | F14: 1111039 | G14: ชิฟฟอนเค้ก วรรรณวนัช ห่อซีน (รวมรส 8 ชิ้น) | K14: 0 | L14: =SUM(O14,Y14,AI14,AS14,BC14,BM14,BW14) -> 0 | M14: 0 | BY14: =SUM(BV14:BX14) -> 0 | BZ14: 0 | CA14: 0 | CB14: 0 | CC14: 0 | CD14: =BW14-CA14 -> 0 | CE14: 0
A15: 11 | F15: 1111041 | G15: ชิฟฟอนเค้ก วรรณวนัช กาแฟล้วน(รวมรส 4 ชิ้น) | K15: 0 | L15: =SUM(O15,Y15,AI15,AS15,BC15,BM15,BW15) -> 0 | M15: 0 | BY15: =SUM(BV15:BX15) -> 0 | BZ15: 0 | CA15: 0 | CB15: 0 | CC15: 0 | CD15: =BW15-CA15 -> 0 | CE15: 0
A16: 12 | F16: 1111043 | G16: ชิฟฟอนรสมะลิ 8 ชิ้น ห่อ ซีน | K16: 0 | L16: =SUM(O16,Y16,AI16,AS16,BC16,BM16,BW16) -> 0 | M16: 0 | BY16: =SUM(BV16:BX16) -> 0 | BZ16: 0 | CA16: 0 | CB16: 0 | CC16: 0 | CD16: =BW16-CA16 -> 0 | CE16: 0
A17: 13 | F17: 1113091 | G17: (BC) ชิฟฟ่อนรวมรส 4 ชิ้น | H17: BC | K17: 0 | L17: =SUM(O17,Y17,AI17,AS17,BC17,BM17,BW17) -> 695 | M17: 0 | Y17: 35 | AS17: 590 | BM17: 70 | BY17: =SUM(BV17:BX17) -> 0 | BZ17: 0 | CA17: 0 | CB17: 0 | CC17: 0 | CD17: =BW17-CA17 -> 0 | CE17: 0
A18: 14 | F18: 1113083 | G18: (BC) ชิฟฟ่อนฝอยทอง 1 ชิ้น ไม่มีไส้ | K18: 0 | L18: =SUM(O18,Y18,AI18,AS18,BC18,BM18,BW18) -> 0 | M18: 0 | BY18: =SUM(BV18:BX18) -> 0 | BZ18: 0 | CA18: 0 | CB18: 0 | CC18: 0 | CD18: =BW18-CA18 -> 0 | CE18: 0
A19: 15 | F19: 1111057 | G19: ชิฟฟอนแยกชิ้น กาแฟ | K19: 0 | L19: =SUM(O19,Y19,AI19,AS19,BC19,BM19,BW19) -> 0 | M19: 0 | BY19: =SUM(BV19:BX19) -> 0 | BZ19: 0 | CA19: 0 | CB19: 0 | CC19: 0 | CD19: =BW19-CA19 -> 0 | CE19: 0
A20: 16 | F20: 1111058 | G20: ชิฟฟอนแยกชิ้น ชาเขียว | K20: 0 | L20: =SUM(O20,Y20,AI20,AS20,BC20,BM20,BW20) -> 0 | M20: 0 | BY20: =SUM(BV20:BX20) -> 0 | BZ20: 0 | CA20: 0 | CB20: 0 | CC20: 0 | CD20: =BW20-CA20 -> 0 | CE20: 0
A21: 17 | F21: 1111059 | G21: ชิฟฟอนแยกชิ้น ใบเตย | K21: 0 | L21: =SUM(O21,Y21,AI21,AS21,BC21,BM21,BW21) -> 0 | M21: 0 | BY21: =SUM(BV21:BX21) -> 0 | BZ21: 0 | CA21: 0 | CB21: 0 | CC21: 0 | CD21: =BW21-CA21 -> 0 | CE21: 0
A22: 18 | F22: 1111060 | G22: ชิฟฟอนแยกชิ้น กล้วยหอม | K22: 0 | L22: =SUM(O22,Y22,AI22,AS22,BC22,BM22,BW22) -> 0 | M22: 0 | BY22: =SUM(BV22:BX22) -> 0 | BZ22: 0 | CA22: 0 | CB22: 0 | CC22: 0 | CD22: =BW22-CA22 -> 0 | CE22: 0
A23: 19 | F23: 1111061 | G23: ชิฟฟอนแยกชิ้น ชาไทย | K23: 0 | L23: =SUM(O23,Y23,AI23,AS23,BC23,BM23,BW23) -> 0 | M23: 0 | BY23: =SUM(BV23:BX23) -> 0 | BZ23: 0 | CA23: 0 | CB23: 0 | CC23: 0 | CD23: =BW23-CA23 -> 0 | CE23: 0
A24: 20 | F24: 1111062 | G24: ชิฟฟอนแยกชิ้น โกโก้ | K24: 0 | L24: =SUM(O24,Y24,AI24,AS24,BC24,BM24,BW24) -> 0 | M24: 0 | BY24: =SUM(BV24:BX24) -> 0 | BZ24: 0 | CA24: 0 | CB24: 0 | CC24: 0 | CD24: =BW24-CA24 -> 0 | CE24: 0
A25: 21 | F25: 1111063 | G25: ชิฟฟอนแยกชิ้น ส้ม | K25: 0 | L25: =SUM(O25,Y25,AI25,AS25,BC25,BM25,BW25) -> 0 | M25: 0 | BY25: =SUM(BV25:BX25) -> 0 | BZ25: 0 | CA25: 0 | CB25: 0 | CC25: 0 | CD25: =BW25-CA25 -> 0 | CE25: 0
A26: 22 | F26: 1111064 | G26: ชิฟฟอนแยกชิ้น เผือก | K26: 0 | L26: =SUM(O26,Y26,AI26,AS26,BC26,BM26,BW26) -> 0 | M26: 0 | BY26: =SUM(BV26:BX26) -> 0 | BZ26: 0 | CA26: 0 | CB26: 0 | CC26: 0 | CD26: =BW26-CA26 -> 0 | CE26: 0
A27: 23 | F27: 1111065 | G27: ชิฟฟอนแยกชิ้น สับปะรด | K27: 0 | L27: =SUM(O27,Y27,AI27,AS27,BC27,BM27,BW27) -> 0 | M27: 0 | BY27: =SUM(BV27:BX27) -> 0 | BZ27: 0 | CA27: 0 | CB27: 0 | CC27: 0 | CD27: =BW27-CA27 -> 0 | CE27: 0
A28: 24 | F28: 1111066 | G28: ชิฟฟอนแยกชิ้น สตอเบอรี่ | K28: 0 | L28: =SUM(O28,Y28,AI28,AS28,BC28,BM28,BW28) -> 0 | M28: 0 | BY28: =SUM(BV28:BX28) -> 0 | BZ28: 0 | CA28: 0 | CB28: 0 | CC28: 0 | CD28: =BW28-CA28 -> 0 | CE28: 0
A29: 25 | F29: 1111067 | G29: ชิฟฟอนแยกชิ้น มะพร้าว | K29: 0 | L29: =SUM(O29,Y29,AI29,AS29,BC29,BM29,BW29) -> 0 | M29: 0 | BY29: =SUM(BV29:BX29) -> 0 | BZ29: 0 | CA29: 0 | CB29: 0 | CC29: 0 | CD29: =BW29-CA29 -> 0 | CE29: 0
... A31: 27 | F31: 1111069 | G31: ชิฟฟอนแยกชิ้น บลูเบอรี่ | K31: 0 | L31: =SUM(O31,Y31,AI31,AS31,BC31,BM31,BW31) -> 0 | M31: 0 | BY31: =SUM(BV31:BX31) -> 0 | BZ31: 0 | CA31: 0 | CB31: 0 | CC31: 0 | CD31: =BW31-CA31 -> 0 | CE31: 0
A32: 28 | F32: 1004061 | G32: ชิฟฟ่อนเค้ก สอดไส้ครีมมะพร้าว (2 ชิ้น) | H32: Aeon | K32: 0 | L32: =SUM(O32,Y32,AI32,AS32,BC32,BM32,BW32) -> 28 | M32: 0 | O32: 13 | BC32: 15 | BY32: =SUM(BV32:BX32) -> 0 | BZ32: 0 | CA32: 0 | CB32: 0 | CC32: 0 | CD32: =BW32-CA32 -> 0 | CE32: 0
A33: 29 | F33: 1111051 | G33: ชิฟฟ่อนเค้กสอดไส้ครีมมะพร้าว (2ชิ้น) มะพร้าวล้วน | K33: 0 | L33: =SUM(O33,Y33,AI33,AS33,BC33,BM33,BW33) -> 0 | M33: 0 | BY33: =SUM(BV33:BX33) -> 0 | BZ33: 0 | CA33: 0 | CB33: 0 | CC33: 0 | CD33: =BW33-CA33 -> 0 | CE33: 0
A34: 30 | F34: 1111004 | G34: ชิฟฟ่อนเค้ก สอดไส้ครีมมะพร้าว (4 ชิ้น) | K34: 0 | L34: =SUM(O34,Y34,AI34,AS34,BC34,BM34,BW34) -> 0 | M34: 0 | BY34: =SUM(BV34:BX34) -> 0 | BZ34: 0 | CA34: 0 | CB34: 0 | CC34: 0 | CD34: =BW34-CA34 -> 0 | CE34: 0
A35: 31 | F35: 1111048 | G35: ชิฟฟอนเค้กสอดไส้ครีมมะพร้าว+เตย (4ชิ้น) | K35: 0 | L35: =SUM(O35,Y35,AI35,AS35,BC35,BM35,BW35) -> 0 | M35: 0 | BY35: =SUM(BV35:BX35) -> 0 | BZ35: 0 | CA35: 0 | CB35: 0 | CC35: 0 | CD35: =BW35-CA35 -> 0 | CE35: 0
A36: 32 | F36: 1111005 | G36: ชิฟฟ่อนเค้ก สอดไส้ครีมมะพร้าว (5 ชิ้น) | K36: 0 | L36: =SUM(O36,Y36,AI36,AS36,BC36,BM36,BW36) -> 0 | M36: 0 | BY36: =SUM(BV36:BX36) -> 0 | BZ36: 0 | CA36: 0 | CB36: 0 | CC36: 0 | CD36: =BW36-CA36 -> 0 | CE36: 0
A37: 33 | F37: 1111047 | G37: ชิฟฟอนเค้กสอดไส้ครีมมะพร้าว+เตย (5ชิ้น) | K37: 0 | L37: =SUM(O37,Y37,AI37,AS37,BC37,BM37,BW37) -> 0 | M37: 0 | BY37: =SUM(BV37:BX37) -> 0 | BZ37: 0 | CA37: 0 | CB37: 0 | CC37: 0 | CD37: =BW37-CA37 -> 0 | CE37: 0
A38: 34 | F38: 1111006 | G38: ชิฟฟ่อนเค้ก วรรณวนัช (สอดไส้รวมรส 8 ชิ้น) | K38: 0 | L38: =SUM(O38,Y38,AI38,AS38,BC38,BM38,BW38) -> 0 | M38: 0 | BY38: =SUM(BV38:BX38) -> 0 | BZ38: 0 | CA38: 0 | CB38: 0 | CC38: 0 | CD38: =BW38-CA38 -> 0 | CE38: 0
A39: 35 | F39: 1111034 | G39: ชิฟฟ่อนเค้กใบเตยสอดไส้ครีมมะพร้าว (8 ชิ้น ) | K39: 0 | L39: =SUM(O39,Y39,AI39,AS39,BC39,BM39,BW39) -> 0 | M39: 0 | BY39: =SUM(BV39:BX39) -> 0 | BZ39: 0 | CA39: 0 | CB39: 0 | CC39: 0 | CD39: =BW39-CA39 -> 0 | CE39: 0
A40: 36 | F40: 1111035 | G40: ชิฟฟ่อนเค้กมะพร้าวสอดไส้ครีมมะพร้าว (8 ชิ้น) | K40: 0 | L40: =SUM(O40,Y40,AI40,AS40,BC40,BM40,BW40) -> 0 | M40: 0 | BY40: =SUM(BV40:BX40) -> 0 | BZ40: 0 | CA40: 0 | CB40: 0 | CC40: 0 | CD40: =BW40-CA40 -> 0 | CE40: 0
A41: 37 | F41: 1111031 | G41: ชิฟฟ่อนเค้กทูโทนใบเตยและมะพร้าวสอดไส้ครีม (8 ชิ้น) | K41: 0 | L41: =SUM(O41,Y41,AI41,AS41,BC41,BM41,BW41) -> 0 | M41: 0 | BY41: =SUM(BV41:BX41) -> 0 | BZ41: 0 | CA41: 0 | CB41: 0 | CC41: 0 | CD41: =BW41-CA41 -> 0 | CE41: 0
...

Sheet ยอดจริง Week 1
A1: วันอาทิตย์ | H1: วันจันทร์ | O1: วันอังคาร | V1: วันพุธ | AC1: วันพฤหัส | AJ1: วันศุกร์ | AQ1: วันเสาร์ | BY1: week 4 (วันที่ 24-30 พฤศจิกายน 2567) | CT1: week 5
A2: รหัส | B2: รายการ | C2: A | D2: B | E2: N | F2: รวม | H2: รหัส | I2: รายการ | J2: A | K2: B | L2: N | M2: รวม | O2: รหัส | P2: รายการ | Q2: A | R2: B | S2: N | T2: รวม | V2: รหัส | W2: รายการ | X2: A | Y2: B | Z2: N | AA2: รวม | AC2: รหัส | AD2: รายการ | AE2: A | AF2: B | AG2: N | AH2: รวม | AJ2: รหัส | AK2: รายการ | AL2: A | AM2: B | AN2: N | AO2: รวม | AQ2: รหัส | AR2: รายการ | AS2: A | AT2: B | AU2: N | AV2: รวม | BB2: วันพฤหัสบดี | BF2: ยอดจริง | BL2: วันศุกร์ | BP2: ยอดจริง | BV2: เสาร์ | BY2: วันอาทิตย์ | CB2: วันจันทร์ | CE2: วันอังคาร | CH2: วันพุธ | CK2: วันพฤหัสบดี | CN2: วันศุกร์ | CQ2: เสาร์ | CT2: วันอาทิตย์ | CW2: วันจันทร์ | CZ2: วันอังคาร | DC2: วันพุธ | DF2: วันพฤหัสบดี | DI2: วันศุกร์ | DL2: เสาร์
A3: 1113036 | B3: ช็อกบอล | H3: 1113036 | I3: ช็อกบอล | O3: 1113036 | P3: ช็อกบอล | V3: 1113036 | W3: ช็อกบอล | AC3: 1113036 | AD3: ช็อกบอล | AJ3: 1113036 | AK3: ช็อกบอล | AQ3: 1113036 | AR3: ช็อกบอล | BZ3: 24 | CC3: 25 | CF3: 26 | CI3: 27 | CL3: 28 | CO3: 29 | CR3: 30
A4: 1111001 | B4: ชิฟฟ่อนเค้ก (1 ชิ้น) | H4: 1111001 | I4: ชิฟฟ่อนเค้ก (1 ชิ้น) | O4: 1111001 | P4: ชิฟฟ่อนเค้ก (1 ชิ้น) | V4: 1111001 | W4: ชิฟฟ่อนเค้ก (1 ชิ้น) | AC4: 1111001 | AD4: ชิฟฟ่อนเค้ก (1 ชิ้น) | AJ4: 1111001 | AK4: ชิฟฟ่อนเค้ก (1 ชิ้น) | AQ4: 1111001 | AR4: ชิฟฟ่อนเค้ก (1 ชิ้น) | AW4: ไม่ติดป้าย Amezon | AX4: Non Logo | AY4: ติดป้าย Amezon | AZ4: ไม่ติดป้าย Amezon | BA4: Non Logo | BB4: ติดป้าย Amezon | BC4: ไม่ติดป้าย Amezon | BD4: Non Logo | BE4: รวม | BF4: ติดป้าย Amezon | BG4: ไม่ติดป้าย Amezon | BH4: Non Logo | BI4: ติดป้าย Amezon | BJ4: ไม่ติดป้าย Amezon | BK4: Non Logo | BL4: ติดป้าย Amezon | BM4: ไม่ติดป้าย Amezon | BN4: Non Logo | BO4: รวม | BP4: ติดป้าย Amezon | BQ4: ไม่ติดป้าย Amezon | BR4: Non Logo | BS4: ติดป้าย Amezon | BT4: ไม่ติดป้าย Amezon | BU4: Non Logo | BV4: ติดป้าย Amezon | BW4: ไม่ติดป้าย Amezon | BX4: Non Logo | BY4: ติดป้าย Amezon | BZ4: ไม่ติดป้าย Amezon | CA4: Non Logo | CB4: ติดป้าย Amezon | CC4: ไม่ติดป้าย Amezon | CD4: Non Logo | CE4: ติดป้าย Amezon | CF4: ไม่ติดป้าย Amezon | CG4: Non Logo | CH4: ติดป้าย Amezon | CI4: ไม่ติดป้าย Amezon | CJ4: Non Logo | CK4: ติดป้าย Amezon | CL4: ไม่ติดป้าย Amezon | CM4: Non Logo | CN4: ติดป้าย Amezon | CO4: ไม่ติดป้าย Amezon | CP4: Non Logo | CQ4: ติดป้าย Amezon | CR4: ไม่ติดป้าย Amezon | CS4: Non Logo | CT4: ติดป้าย Amezon | CU4: ไม่ติดป้าย Amezon | CV4: Non Logo | CW4: ติดป้าย Amezon | CX4: ไม่ติดป้าย Amezon | CY4: Non Logo | CZ4: ติดป้าย Amezon | DA4: ไม่ติดป้าย Amezon | DB4: Non Logo | DC4: ติดป้าย Amezon | DD4: ไม่ติดป้าย Amezon | DE4: Non Logo | DF4: ติดป้าย Amezon | DG4: ไม่ติดป้าย Amezon | DH4: Non Logo | DI4: ติดป้าย Amezon | DJ4: ไม่ติดป้าย Amezon | DK4: Non Logo | DL4: ติดป้าย Amezon | DM4: ไม่ติดป้าย Amezon | DN4: Non Logo
A5: 1004061 | B5: ชิฟฟ่อนเค้ก สอดไส้ครีมมะพร้าว (2 ชิ้น) | H5: 1004061 | I5: ชิฟฟ่อนเค้ก สอดไส้ครีมมะพร้าว (2 ชิ้น) | O5: 1004061 | P5: ชิฟฟ่อนเค้ก สอดไส้ครีมมะพร้าว (2 ชิ้น) | V5: 1004061 | W5: ชิฟฟ่อนเค้ก สอดไส้ครีมมะพร้าว (2 ชิ้น) | AC5: 1004061 | AD5: ชิฟฟ่อนเค้ก สอดไส้ครีมมะพร้าว (2 ชิ้น) | AJ5: 1004061 | AK5: ชิฟฟ่อนเค้ก สอดไส้ครีมมะพร้าว (2 ชิ้น) | AQ5: 1004061 | AR5: ชิฟฟ่อนเค้ก สอดไส้ครีมมะพร้าว (2 ชิ้น) | AW5: 0 | AX5: 0 | AY5: 0 | AZ5: 0 | BA5: 0 | BC5: 10 | BE5: 10 | BF5: 0 | BG5: 0 | BH5: 0 | BI5: 0 | BJ5: 10 | BK5: 0 | BO5: 0 | BP5: 0 | BQ5: 0 | BR5: 0 | BS5: 0 | BT5: 0 | BU5: 0 | BZ5: 10 | CL5: 10
A6: 1004071 | B6: คัพเค้กกล้วยหอมไส้ครีมเนยสด (4 ชิ้น) | H6: 1004071 | I6: คัพเค้กกล้วยหอมไส้ครีมเนยสด (4 ชิ้น) | O6: 1004071 | P6: คัพเค้กกล้วยหอมไส้ครีมเนยสด (4 ชิ้น) | V6: 1004071 | W6: คัพเค้กกล้วยหอมไส้ครีมเนยสด (4 ชิ้น) | AC6: 1004071 | AD6: คัพเค้กกล้วยหอมไส้ครีมเนยสด (4 ชิ้น) | AJ6: 1004071 | AK6: คัพเค้กกล้วยหอมไส้ครีมเนยสด (4 ชิ้น) | AQ6: 1004071 | AR6: คัพเค้กกล้วยหอมไส้ครีมเนยสด (4 ชิ้น) | AW6: 0 | AX6: 0 | AY6: 0 | AZ6: 0 | BA6: 0 | BE6: 0 | BF6: 0 | BG6: 0 | BH6: 0 | BI6: 0 | BJ6: 0 | BK6: 0 | BO6: 0 | BP6: 0 | BQ6: 0 | BR6: 0 | BS6: 0 | BT6: 0 | BU6: 0
A7: 1004070 | B7: คัพเค้กมะพร้าวไส้ครีมเนยสด (4 ชิ้น) | H7: 1004070 | I7: คัพเค้กมะพร้าวไส้ครีมเนยสด (4 ชิ้น) | O7: 1004070 | P7: คัพเค้กมะพร้าวไส้ครีมเนยสด (4 ชิ้น) | V7: 1004070 | W7: คัพเค้กมะพร้าวไส้ครีมเนยสด (4 ชิ้น) | AC7: 1004070 | AD7: คัพเค้กมะพร้าวไส้ครีมเนยสด (4 ชิ้น) | AJ7: 1004070 | AK7: คัพเค้กมะพร้าวไส้ครีมเนยสด (4 ชิ้น) | AQ7: 1004070 | AR7: คัพเค้กมะพร้าวไส้ครีมเนยสด (4 ชิ้น) | AW7: 0 | AX7: 0 | AY7: 0 | AZ7: 0 | BA7: 0 | BE7: 0 | BF7: 0 | BG7: 0 | BH7: 0 | BI7: 0 | BJ7: 0 | BK7: 0 | BO7: 0 | BP7: 0 | BQ7: 0 | BR7: 0 | BS7: 0 | BT7: 0 | BU7: 0
A8: 1004063 | B8: ซอฟท์เค้กหน้าช็อกโกแลตมูส | H8: 1004063 | I8: ซอฟท์เค้กหน้าช็อกโกแลตมูส | O8: 1004063 | P8: ซอฟท์เค้กหน้าช็อกโกแลตมูส | V8: 1004063 | W8: ซอฟท์เค้กหน้าช็อกโกแลตมูส | AC8: 1004063 | AD8: ซอฟท์เค้กหน้าช็อกโกแลตมูส | AJ8: 1004063 | AK8: ซอฟท์เค้กหน้าช็อกโกแลตมูส | AQ8: 1004063 | AR8: ซอฟท์เค้กหน้าช็อกโกแลตมูส | AW8: 0 | AX8: 0 | AY8: 0 | AZ8: 0 | BA8: 0 | BE8: 0 | BF8: 0 | BG8: 0 | BH8: 0 | BI8: 0 | BJ8: 0 | BK8: 0 | BO8: 0 | BP8: 0 | BQ8: 0 | BR8: 0 | BS8: 0 | BT8: 0 | BU8: 0
A9: 1004065 | B9: ซอฟท์เค้กหน้ามะพร้าวนมสด | H9: 1004065 | I9: ซอฟท์เค้กหน้ามะพร้าวนมสด | O9: 1004065 | P9: ซอฟท์เค้กหน้ามะพร้าวนมสด | V9: 1004065 | W9: ซอฟท์เค้กหน้ามะพร้าวนมสด | AC9: 1004065 | AD9: ซอฟท์เค้กหน้ามะพร้าวนมสด | AJ9: 1004065 | AK9: ซอฟท์เค้กหน้ามะพร้าวนมสด | AQ9: 1004065 | AR9: ซอฟท์เค้กหน้ามะพร้าวนมสด | AW9: 0 | AX9: 0 | AY9: 0 | AZ9: 0 | BA9: 0 | BE9: 0 | BF9: 0 | BG9: 0 | BH9: 0 | BI9: 0 | BJ9: 0 | BK9: 0 | BO9: 0 | BP9: 0 | BQ9: 0 | BR9: 0 | BS9: 0 | BT9: 0 | BU9: 0 | BZ9: 1800 | CF9: 1000
A10: 1004074 | B10: ซอฟท์เค้กหน้าครีมสด | H10: 1004074 | I10: ซอฟท์เค้กหน้าครีมสด | O10: 1004074 | P10: ซอฟท์เค้กหน้าครีมสด | V10: 1004074 | W10: ซอฟท์เค้กหน้าครีมสด | AC10: 1004074 | AD10: ซอฟท์เค้กหน้าครีมสด | AJ10: 1004074 | AK10: ซอฟท์เค้กหน้าครีมสด | AQ10: 1004074 | AR10: ซอฟท์เค้กหน้าครีมสด | AW10: 0 | AX10: 0 | AY10: 0 | AZ10: 0 | BA10: 0 | BE10: 0 | BF10: 0 | BG10: 0 | BH10: 0 | BI10: 0 | BJ10: 0 | BK10: 0 | BO10: 0 | BP10: 0 | BQ10: 0 | BR10: 0 | BS10: 0 | BT10: 0 | BU10: 0
A11: 1004064 | B11: ซอฟท์เค้กฝอยทอง | H11: 1004064 | I11: ซอฟท์เค้กฝอยทอง | O11: 1004064 | P11: ซอฟท์เค้กฝอยทอง | V11: 1004064 | W11: ซอฟท์เค้กฝอยทอง | AC11: 1004064 | AD11: ซอฟท์เค้กฝอยทอง | AJ11: 1004064 | AK11: ซอฟท์เค้กฝอยทอง | AQ11: 1004064 | AR11: ซอฟท์เค้กฝอยทอง | AW11: 0 | AX11: 0 | AY11: 0 | AZ11: 0 | BA11: 0 | BE11: 0 | BF11: 0 | BG11: 0 | BH11: 0 | BI11: 0 | BJ11: 0 | BK11: 0 | BO11: 0 | BP11: 0 | BQ11: 0 | BR11: 0 | BS11: 0 | BT11: 0 | BU11: 0
A12: 1004072 | B12: เค้กโบราณ ครีม (2 ชิ้น) | H12: 1004072 | I12: เค้กโบราณ ครีม (2 ชิ้น) | O12: 1004072 | P12: เค้กโบราณ ครีม (2 ชิ้น) | V12: 1004072 | W12: เค้กโบราณ ครีม (2 ชิ้น) | AC12: 1004072 | AD12: เค้กโบราณ ครีม (2 ชิ้น) | AJ12: 1004072 | AK12: เค้กโบราณ ครีม (2 ชิ้น) | AQ12: 1004072 | AR12: เค้กโบราณ ครีม (2 ชิ้น) | AW12: 0 | AX12: 0 | AY12: 0 | AZ12: 0 | BA12: 0 | BE12: 0 | BF12: 0 | BG12: 0 | BH12: 0 | BI12: 0 | BJ12: 0 | BK12: 0 | BO12: 0 | BP12: 0 | BQ12: 0 | BR12: 0 | BS12: 0 | BT12: 0 | BU12: 0
A13: 1004073 | B13: เค้กโบราณ ผลไม้ (2 ชิ้น) | H13: 1004073 | I13: เค้กโบราณ ผลไม้ (2 ชิ้น) | O13: 1004073 | P13: เค้กโบราณ ผลไม้ (2 ชิ้น) | V13: 1004073 | W13: เค้กโบราณ ผลไม้ (2 ชิ้น) | AC13: 1004073 | AD13: เค้กโบราณ ผลไม้ (2 ชิ้น) | AJ13: 1004073 | AK13: เค้กโบราณ ผลไม้ (2 ชิ้น) | AQ13: 1004073 | AR13: เค้กโบราณ ผลไม้ (2 ชิ้น) | AW13: 0 | AX13: 0 | AY13: 0 | AZ13: 0 | BA13: 0 | BE13: 0 | BF13: 0 | BG13: 0 | BH13: 0 | BI13: 0 | BJ13: 0 | BK13: 0 | BO13: 0 | BP13: 0 | BQ13: 0 | BR13: 0 | BS13: 0 | BT13: 0 | BU13: 0
A14: 1113008 | B14: เค้กโบราณ รวมรส (4 ชิ้น) | H14: 1113008 | I14: เค้กโบราณ รวมรส (4 ชิ้น) | O14: 1113008 | P14: เค้กโบราณ รวมรส (4 ชิ้น) | V14: 1113008 | W14: เค้กโบราณ รวมรส (4 ชิ้น) | AC14: 1113008 | AD14: เค้กโบราณ รวมรส (4 ชิ้น) | AJ14: 1113008 | AK14: เค้กโบราณ รวมรส (4 ชิ้น) | AQ14: 1113008 | AR14: เค้กโบราณ รวมรส (4 ชิ้น) | AW14: 0 | AX14: 0 | AY14: 0 | AZ14: 0 | BA14: 0 | BE14: 0 | BF14: 0 | BG14: 0 | BH14: 0 | BI14: 0 | BJ14: 0 | BK14: 0 | BO14: 0 | BP14: 0 | BQ14: 0 | BR14: 0 | BS14: 0 | BT14: 0 | BU14: 0
A15: 1113106 | B15: มินิลาวาทูโทน | H15: 1113106 | I15: มินิลาวาทูโทน | O15: 1113106 | P15: มินิลาวาทูโทน | V15: 1113106 | W15: มินิลาวาทูโทน | AC15: 1113106 | AD15: มินิลาวาทูโทน | AJ15: 1113106 | AK15: มินิลาวาทูโทน | AQ15: 1113106 | AR15: มินิลาวาทูโทน | AW15: 0 | AX15: 0 | AY15: 0 | AZ15: 0 | BA15: 0 | BE15: 0 | BF15: 0 | BG15: 0 | BH15: 0 | BI15: 0 | BJ15: 0 | BK15: 0 | BO15: 0 | BP15: 0 | BQ15: 0 | BR15: 0 | BS15: 0 | BT15: 0 | BU15: 0
A16: 1113056 | B16: (MK) สตรอเบอร์รี่ครีมเค้ก 65 ก. (หน้าขาว) | H16: 1113056 | I16: (MK) สตรอเบอร์รี่ครีมเค้ก 65 ก. (หน้าขาว) | O16: 1113056 | P16: (MK) สตรอเบอร์รี่ครีมเค้ก 65 ก. (หน้าขาว) | V16: 1113056 | W16: (MK) สตรอเบอร์รี่ครีมเค้ก 65 ก. (หน้าขาว) | AC16: 1113056 | AD16: (MK) สตรอเบอร์รี่ครีมเค้ก 65 ก. (หน้าขาว) | AJ16: 1113056 | AK16: (MK) สตรอเบอร์รี่ครีมเค้ก 65 ก. (หน้าขาว) | AQ16: 1113056 | AR16: (MK) สตรอเบอร์รี่ครีมเค้ก 65 ก. (หน้าขาว) | AW16: 0 | AX16: 0 | AY16: 0 | AZ16: 0 | BA16: 0 | BE16: 0 | BF16: 0 | BG16: 0 | BH16: 0 | BI16: 0 | BJ16: 0 | BK16: 0 | BO16: 0 | BP16: 0 | BQ16: 0 | BR16: 0 | BS16: 0 | BT16: 0 | BU16: 0
A17: 1113059 | B17: (MK) เค้กสตรอเบอร์รี่ 65 ก. (หน้าชมพู) | H17: 1113059 | I17: (MK) เค้กสตรอเบอร์รี่ 65 ก. (หน้าชมพู) | O17: 1113059 | P17: (MK) เค้กสตรอเบอร์รี่ 65 ก. (หน้าชมพู) | V17: 1113059 | W17: (MK) เค้กสตรอเบอร์รี่ 65 ก. (หน้าชมพู) | AC17: 1113059 | AD17: (MK) เค้กสตรอเบอร์รี่ 65 ก. (หน้าชมพู) | AJ17: 1113059 | AK17: (MK) เค้กสตรอเบอร์รี่ 65 ก. (หน้าชมพู) | AQ17: 1113059 | AR17: (MK) เค้กสตรอเบอร์รี่ 65 ก. (หน้าชมพู) | AW17: 0 | AX17: 0 | AY17: 0 | AZ17: 0 | BA17: 0 | BC17: 200 | BE17: 200 | BF17: 0 | BG17: 0 | BH17: 0 | BI17: 0 | BJ17: 200 | BK17: 0 | BO17: 0 | BP17: 0 | BQ17: 0 | BR17: 0 | BS17: 0 | BT17: 0 | BU17: 0 | BZ17: 250 | CF17: 350 | CL17: 300
A18: 1005977 | B18: บลูเบอรี่ ครีมเค้ก (หน้าขาว) | H18: 1005977 | I18: บลูเบอรี่ ครีมเค้ก (หน้าขาว) | O18: 1005977 | P18: บลูเบอรี่ ครีมเค้ก (หน้าขาว) | V18: 1005977 | W18: บลูเบอรี่ ครีมเค้ก (หน้าขาว) | AC18: 1005977 | AD18: บลูเบอรี่ ครีมเค้ก (หน้าขาว) | AJ18: 1005977 | AK18: บลูเบอรี่ ครีมเค้ก (หน้าขาว) | AQ18: 1005977 | AR18: บลูเบอรี่ ครีมเค้ก (หน้าขาว) | AW18: 0 | AX18: 0 | AY18: 0 | AZ18: 0 | BA18: 0 | BE18: 0 | BF18: 0 | BG18: 0 | BH18: 0 | BI18: 0 | BJ18: 0 | BK18: 0 | BO18: 0 | BP18: 0 | BQ18: 0 | BR18: 0 | BS18: 0 | BT18: 0 | BU18: 0
A19: 1113098 | B19: วุ้นชิฟฟ่อน (ฝอยทอง) WWN | H19: 1113098 | I19: วุ้นชิฟฟ่อน (ฝอยทอง) WWN | O19: 1113098 | P19: วุ้นชิฟฟ่อน (ฝอยทอง) WWN | V19: 1113098 | W19: วุ้นชิฟฟ่อน (ฝอยทอง) WWN | AC19: 1113098 | AD19: วุ้นชิฟฟ่อน (ฝอยทอง) WWN | AJ19: 1113098 | AK19: วุ้นชิฟฟ่อน (ฝอยทอง) WWN | AQ19: 1113098 | AR19: วุ้นชิฟฟ่อน (ฝอยทอง) WWN | AW19: 0 | AX19: 0 | AY19: 0 | AZ19: 0 | BA19: 0 | BE19: 0 | BF19: 0 | BG19: 0 | BH19: 0 | BI19: 0 | BJ19: 0 | BK19: 0 | BO19: 0 | BP19: 0 | BQ19: 0 | BR19: 0 | BS19: 0 | BT19: 0 | BU19: 0
A20: 1005982 | B20: ขนมปังเนยนิ่ม 3 ชิ้น | H20: 1005982 | I20: ขนมปังเนยนิ่ม 3 ชิ้น | O20: 1005982 | P20: ขนมปังเนยนิ่ม 3 ชิ้น | V20: 1005982 | W20: ขนมปังเนยนิ่ม 3 ชิ้น | AC20: 1005982 | AD20: ขนมปังเนยนิ่ม 3 ชิ้น | AJ20: 1005982 | AK20: ขนมปังเนยนิ่ม 3 ชิ้น | AQ20: 1005982 | AR20: ขนมปังเนยนิ่ม 3 ชิ้น | AW20: 0 | AX20: 0 | AY20: 0 | AZ20: 0 | BA20: 0 | BE20: 0 | BF20: 0 | BG20: 0 | BH20: 0 | BI20: 0 | BJ20: 0 | BK20: 0 | BO20: 0 | BP20: 0 | BQ20: 0 | BR20: 0 | BS20: 0 | BT20: 0 | BU20: 0
A21: 1113087 | B21: (BC) เอแคลร์ 6 ชิ้น | H21: 1113087 | I21: (BC) เอแคลร์ 6 ชิ้น | O21: 1113087 | P21: (BC) เอแคลร์ 6 ชิ้น | V21: 1113087 | W21: (BC) เอแคลร์ 6 ชิ้น | AC21: 1113087 | AD21: (BC) เอแคลร์ 6 ชิ้น | AJ21: 1113087 | AK21: (BC) เอแคลร์ 6 ชิ้น | AQ21: 1113087 | AR21: (BC) เอแคลร์ 6 ชิ้น | AW21: 0 | AX21: 0 | AY21: 0 | AZ21: 0 | BA21: 0 | BE21: 0 | BF21: 0 | BG21: 0 | BH21: 0 | BI21: 0 | BJ21: 0 | BK21: 0 | BO21: 0 | BP21: 0 | BQ21: 0 | BR21: 0 | BS21: 0 | BT21: 0 | BU21: 0
A22: 1113093 | B22: (BC) ขนมปังสังขยา 4 ชิ้น | H22: 1113093 | I22: (BC) ขนมปังสังขยา 4 ชิ้น | O22: 1113093 | P22: (BC) ขนมปังสังขยา 4 ชิ้น | V22: 1113093 | W22: (BC) ขนมปังสังขยา 4 ชิ้น | AC22: 1113093 | AD22: (BC) ขนมปังสังขยา 4 ชิ้น | AJ22: 1113093 | AK22: (BC) ขนมปังสังขยา 4 ชิ้น | AQ22: 1113093 | AR22: (BC) ขนมปังสังขยา 4 ชิ้น | AW22: 0 | AX22: 0 | AY22: 0 | AZ22: 0 | BA22: 0 | BE22: 0 | BF22: 0 | BG22: 0 | BH22: 0 | BI22: 0 | BJ22: 0 | BK22: 0 | BO22: 0 | BP22: 0 | BQ22: 0 | BR22: 0 | BS22: 0 | BT22: 0 | BU22: 0
A23: 1113088 | B23: (BC) ครีมฮอร์นวนิลา 3 ชิ้น วิปครีม | H23: 1113088 | I23: (BC) ครีมฮอร์นวนิลา 3 ชิ้น วิปครีม | O23: 1113088 | P23: (BC) ครีมฮอร์นวนิลา 3 ชิ้น วิปครีม | V23: 1113088 | W23: (BC) ครีมฮอร์นวนิลา 3 ชิ้น วิปครีม | AC23: 1113088 | AD23: (BC) ครีมฮอร์นวนิลา 3 ชิ้น วิปครีม | AJ23: 1113088 | AK23: (BC) ครีมฮอร์นวนิลา 3 ชิ้น วิปครีม | AQ23: 1113088 | AR23: (BC) ครีมฮอร์นวนิลา 3 ชิ้น วิปครีม | AW23: 0 | AX23: 0 | AY23: 0 | AZ23: 0 | BA23: 0 | BE23: 0 | BF23: 0 | BG23: 0 | BH23: 0 | BI23: 0 | BJ23: 0 | BK23: 0 | BO23: 0 | BP23: 0 | BQ23: 0 | BR23: 0 | BS23: 0 | BT23: 0 | BU23: 0
A24: 1113091 | B24: (BC) ชิฟฟ่อนรวมรส 4 ชิ้น | H24: 1113091 | I24: (BC) ชิฟฟ่อนรวมรส 4 ชิ้น | O24: 1113091 | P24: (BC) ชิฟฟ่อนรวมรส 4 ชิ้น | V24: 1113091 | W24: (BC) ชิฟฟ่อนรวมรส 4 ชิ้น | AC24: 1113091 | AD24: (BC) ชิฟฟ่อนรวมรส 4 ชิ้น | AJ24: 1113091 | AK24: (BC) ชิฟฟ่อนรวมรส 4 ชิ้น | AQ24: 1113091 | AR24: (BC) ชิฟฟ่อนรวมรส 4 ชิ้น | AW24: 0 | AX24: 0 | AY24: 0 | AZ24: 0 | BA24: 0 | BE24: 0 | BF24: 0 | BG24: 0 | BH24: 0 | BI24: 0 | BJ24: 0 | BK24: 0 | BO24: 0 | BP24: 0 | BQ24: 0 | BR24: 0 | BS24: 0 | BT24: 0 | BU24: 0
A25: 1113081 | B25: (BC) ชิฟฟ่อนสอดไส้แยม 3 รสชาติ วนิลลา, เมล่อน, .ใบเตย | H25: 1113081 | I25: (BC) ชิฟฟ่อนสอดไส้แยม 3 รสชาติ วนิลลา, เมล่อน, .ใบเตย | O25: 1113081 | P25: (BC) ชิฟฟ่อนสอดไส้แยม 3 รสชาติ วนิลลา, เมล่อน, .ใบเตย | V25: 1113081 | W25: (BC) ชิฟฟ่อนสอดไส้แยม 3 รสชาติ วนิลลา, เมล่อน, .ใบเตย | AC25: 1113081 | AD25: (BC) ชิฟฟ่อนสอดไส้แยม 3 รสชาติ วนิลลา, เมล่อน, .ใบเตย | AJ25: 1113081 | AK25: (BC) ชิฟฟ่อนสอดไส้แยม 3 รสชาติ วนิลลา, เมล่อน, .ใบเตย | AQ25: 1113081 | AR25: (BC) ชิฟฟ่อนสอดไส้แยม 3 รสชาติ วนิลลา, เมล่อน, .ใบเตย | AW25: 0 | AX25: 0 | AY25: 0 | AZ25: 0 | BA25: 0 | BE25: 0 | BF25: 0 | BG25: 0 | BH25: 0 | BI25: 0 | BJ25: 0 | BK25: 0 | BO25: 0 | BP25: 0 | BQ25: 0 | BR25: 0 | BS25: 0 | BT25: 0 | BU25: 0
A26: 1113085 | B26: (BC) ชิฟฟ่อนหม้อแกง | H26: 1113085 | I26: (BC) ชิฟฟ่อนหม้อแกง | O26: 1113085 | P26: (BC) ชิฟฟ่อนหม้อแกง | V26: 1113085 | W26: (BC) ชิฟฟ่อนหม้อแกง | AC26: 1113085 | AD26: (BC) ชิฟฟ่อนหม้อแกง | AJ26: 1113085 | AK26: (BC) ชิฟฟ่อนหม้อแกง | AQ26: 1113085 | AR26: (BC) ชิฟฟ่อนหม้อแกง | AW26: 0 | AX26: 0 | AY26: 0 | AZ26: 0 | BA26: 0 | BE26: 0 | BF26: 0 | BG26: 0 | BH26: 0 | BI26: 0 | BJ26: 0 | BK26: 0 | BO26: 0 | BP26: 0 | BQ26: 0 | BR26: 0 | BS26: 0 | BT26: 0 | BU26: 0
A27: 1113157 | B27: (BC) เค้กลอดช่อง 85g | H27: 1113157 | I27: (BC) เค้กลอดช่อง 85g | O27: 1113157 | P27: (BC) เค้กลอดช่อง 85g | V27: 1113157 | W27: (BC) เค้กลอดช่อง 85g | AC27: 1113157 | AD27: (BC) เค้กลอดช่อง 85g | AJ27: 1113157 | AK27: (BC) เค้กลอดช่อง 85g | AQ27: 1113157 | AR27: (BC) เค้กลอดช่อง 85g | AW27: 0 | AX27: 0 | AY27: 0 | AZ27: 0 | BA27: 0 | BE27: 0 | BF27: 0 | BG27: 0 | BH27: 0 | BI27: 0 | BJ27: 0 | BK27: 0 | BO27: 0 | BP27: 0 | BQ27: 0 | BR27: 0 | BS27: 0 | BT27: 0 | BU27: 0
A28: 1113092 | B28: (BC) เค้กโบราณ 4 ชิ้น | H28: 1113092 | I28: (BC) เค้กโบราณ 4 ชิ้น | O28: 1113092 | P28: (BC) เค้กโบราณ 4 ชิ้น | V28: 1113092 | W28: (BC) เค้กโบราณ 4 ชิ้น | AC28: 1113092 | AD28: (BC) เค้กโบราณ 4 ชิ้น | AJ28: 1113092 | AK28: (BC) เค้กโบราณ 4 ชิ้น | AQ28: 1113092 | AR28: (BC) เค้กโบราณ 4 ชิ้น | AW28: 0 | AX28: 0 | AY28: 0 | AZ28: 0 | BA28: 0 | BE28: 0 | BF28: 0 | BG28: 0 | BH28: 0 | BI28: 0 | BJ28: 0 | BK28: 0 | BO28: 0 | BP28: 0 | BQ28: 0 | BR28: 0 | BS28: 0 | BT28: 0 | BU28: 0
A29: 1113090 | B29: (BC) เครปโรลใบเตย ท๊อปซีน | H29: 1113090 | I29: (BC) เครปโรลใบเตย ท๊อปซีน | O29: 1113090 | P29: (BC) เครปโรลใบเตย ท๊อปซีน | V29: 1113090 | W29: (BC) เครปโรลใบเตย ท๊อปซีน | AC29: 1113090 | AD29: (BC) เครปโรลใบเตย ท๊อปซีน | AJ29: 1113090 | AK29: (BC) เครปโรลใบเตย ท๊อปซีน | AQ29: 1113090 | AR29: (BC) เครปโรลใบเตย ท๊อปซีน | AW29: 0 | AX29: 0 | AY29: 0 | AZ29: 0 | BA29: 0 | BE29: 0 | BF29: 0 | BG29: 0 | BH29: 0 | BI29: 0 | BJ29: 0 | BK29: 0 | BO29: 0 | BP29: 0 | BQ29: 0 | BR29: 0 | BS29: 0 | BT29: 0 | BU29: 0
... A31: 1113086 | B31: (BC) ขนมปังเนยนิ่ม 3 ชิ้น | H31: 1113086 | I31: (BC) ขนมปังเนยนิ่ม 3 ชิ้น | O31: 1113086 | P31: (BC) ขนมปังเนยนิ่ม 3 ชิ้น | V31: 1113086 | W31: (BC) ขนมปังเนยนิ่ม 3 ชิ้น | AC31: 1113086 | AD31: (BC) ขนมปังเนยนิ่ม 3 ชิ้น | AJ31: 1113086 | AK31: (BC) ขนมปังเนยนิ่ม 3 ชิ้น | AQ31: 1113086 | AR31: (BC) ขนมปังเนยนิ่ม 3 ชิ้น | AW31: 0 | AX31: 0 | AY31: 0 | AZ31: 0 | BA31: 0 | BE31: 0 | BF31: 0 | BG31: 0 | BH31: 0 | BI31: 0 | BJ31: 0 | BK31: 0 | BO31: 0 | BP31: 0 | BQ31: 0 | BR31: 0 | BS31: 0 | BT31: 0 | BU31: 0
A32: 1113084 | B32: (BC) ปังเนยนิ่ม 90 g 2 ชิ้น | H32: 1113084 | I32: (BC) ปังเนยนิ่ม 90 g 2 ชิ้น | O32: 1113084 | P32: (BC) ปังเนยนิ่ม 90 g 2 ชิ้น | V32: 1113084 | W32: (BC) ปังเนยนิ่ม 90 g 2 ชิ้น | AC32: 1113084 | AD32: (BC) ปังเนยนิ่ม 90 g 2 ชิ้น | AJ32: 1113084 | AK32: (BC) ปังเนยนิ่ม 90 g 2 ชิ้น | AQ32: 1113084 | AR32: (BC) ปังเนยนิ่ม 90 g 2 ชิ้น | AW32: 0 | AX32: 0 | AY32: 0 | AZ32: 0 | BA32: 0 | BC32: 20 | BE32: 20 | BF32: 0 | BG32: 0 | BH32: 0 | BI32: 0 | BJ32: 20 | BK32: 0 | BO32: 0 | BP32: 0 | BQ32: 0 | BR32: 0 | BS32: 0 | BT32: 0 | BU32: 0 | BZ32: 10 | CL32: 10
A33: 20040386 | B33: Wanwanach_ชิฟฟ่อนเค้กสอดไส้มะพร้านมสด 105 g | H33: 20040386 | I33: Wanwanach_ชิฟฟ่อนเค้กสอดไส้มะพร้านมสด 105 g | O33: 20040386 | P33: Wanwanach_ชิฟฟ่อนเค้กสอดไส้มะพร้านมสด 105 g | V33: 20000000 | W33: Wanwanach_ชิฟฟ่อนเค้กสอดไส้มะพร้านมสด 105 g | AC33: 20000000 | AD33: Wanwanach_ชิฟฟ่อนเค้กสอดไส้มะพร้านมสด 105 g | AJ33: 20000000 | AK33: Wanwanach_ชิฟฟ่อนเค้กสอดไส้มะพร้านมสด 105 g | AQ33: 20000000 | AR33: Wanwanach_ชิฟฟ่อนเค้กสอดไส้มะพร้านมสด 105 g | AW33: 0 | AX33: 0 | AY33: 0 | AZ33: 0 | BA33: 0 | BE33: 0 | BF33: 0 | BG33: 0 | BH33: 0 | BI33: 0 | BJ33: 0 | BK33: 0 | BO33: 0 | BP33: 0 | BQ33: 0 | BR33: 0 | BS33: 0 | BT33: 0 | BU33: 0
A34: 20052085 | B34: วรรณวนัชเค้กเบาหวิวมะพร้าว 80g | H34: 20052085 | I34: วรรณวนัชเค้กเบาหวิวมะพร้าว 80g | O34: 20052085 | P34: วรรณวนัชเค้กเบาหวิวมะพร้าว 80g | V34: 20000000 | W34: วรรณวนัชเค้กเบาหวิวมะพร้าว 80g | AC34: 20000000 | AD34: วรรณวนัชเค้กเบาหวิวมะพร้าว 80g | AJ34: 20000000 | AK34: วรรณวนัชเค้กเบาหวิวมะพร้าว 80g | AQ34: 20000000 | AR34: วรรณวนัชเค้กเบาหวิวมะพร้าว 80g | AW34: 0 | AX34: 0 | AY34: 0 | AZ34: 0 | BA34: 0 | BE34: 0 | BF34: 0 | BG34: 0 | BH34: 0 | BI34: 0 | BJ34: 0 | BK34: 0 | BO34: 0 | BP34: 0 | BQ34: 0 | BR34: 0 | BS34: 0 | BT34: 0 | BU34: 0
A35: 20053053 | B35: วรรณนัชเค้กลอดช่อง 85 g | H35: 20053053 | I35: วรรณนัชเค้กลอดช่อง 85 g | O35: 20053053 | P35: วรรณนัชเค้กลอดช่อง 85 g | V35: 20000000 | W35: วรรณนัชเค้กลอดช่อง 85 g | AC35: 20000000 | AD35: วรรณนัชเค้กลอดช่อง 85 g | AJ35: 20000000 | AK35: วรรณนัชเค้กลอดช่อง 85 g | AQ35: 20000000 | AR35: วรรณนัชเค้กลอดช่อง 85 g | AW35: 0 | AX35: 0 | AY35: 0 | AZ35: 0 | BA35: 0 | BE35: 0 | BF35: 0 | BG35: 0 | BH35: 0 | BI35: 0 | BJ35: 0 | BK35: 0 | BO35: 0 | BP35: 0 | BQ35: 0 | BR35: 0 | BS35: 0 | BT35: 0 | BU35: 0
A36: 20052724 | B36: วรรณวนัชเค้กฝอยทองหน้านิ่ม 90g | H36: 20052724 | I36: วรรณวนัชเค้กฝอยทองหน้านิ่ม 90g | O36: 20052724 | P36: วรรณวนัชเค้กฝอยทองหน้านิ่ม 90g | V36: 20000000 | W36: วรรณวนัชเค้กฝอยทองหน้านิ่ม 90g | AC36: 20000000 | AD36: วรรณวนัชเค้กฝอยทองหน้านิ่ม 90g | AJ36: 20000000 | AK36: วรรณวนัชเค้กฝอยทองหน้านิ่ม 90g | AQ36: 20000000 | AR36: วรรณวนัชเค้กฝอยทองหน้านิ่ม 90g | AW36: 0 | AX36: 0 | AY36: 0 | AZ36: 0 | BA36: 0 | BE36: 0 | BF36: 0 | BG36: 0 | BH36: 0 | BI36: 0 | BJ36: 0 | BK36: 0 | BO36: 0 | BP36: 0 | BQ36: 0 | BR36: 0 | BS36: 0 | BT36: 0 | BU36: 0
A37: 20036350 | B37: Wanwanach_เค้กโบราณ 200 g | H37: 20036350 | I37: Wanwanach_เค้กโบราณ 200 g | O37: 20036350 | P37: Wanwanach_เค้กโบราณ 200 g | V37: 20000000 | W37: Wanwanach_เค้กโบราณ 200 g | AC37: 20000000 | AD37: Wanwanach_เค้กโบราณ 200 g | AJ37: 20000000 | AK37: Wanwanach_เค้กโบราณ 200 g | AQ37: 20000000 | AR37: Wanwanach_เค้กโบราณ 200 g | AW37: 0 | AX37: 0 | AY37: 0 | AZ37: 0 | BA37: 0 | BE37: 0 | BF37: 0 | BG37: 0 | BH37: 0 | BI37: 0 | BJ37: 0 | BK37: 0 | BO37: 0 | BP37: 0 | BQ37: 0 | BR37: 0 | BS37: 0 | BT37: 0 | BU37: 0
A38: 20047267 | B38: Bao_WanWN_เค้กมะพร้าว 65g | H38: 20047267 | I38: Bao_WanWN_เค้กมะพร้าว 65g | O38: 20047267 | P38: Bao_WanWN_เค้กมะพร้าว 65g | V38: 20000000 | W38: Bao_WanWN_เค้กมะพร้าว 65g | AC38: 20000000 | AD38: Bao_WanWN_เค้กมะพร้าว 65g | AJ38: 20000000 | AK38: Bao_WanWN_เค้กมะพร้าว 65g | AQ38: 20000000 | AR38: Bao_WanWN_เค้กมะพร้าว 65g | AW38: 0 | AX38: 0 | AY38: 0 | AZ38: 0 | BA38: 0 | BE38: 0 | BF38: 0 | BG38: 0 | BH38: 0 | BI38: 0 | BJ38: 0 | BK38: 0 | BO38: 0 | BP38: 0 | BQ38: 0 | BR38: 0 | BS38: 0 | BT38: 0 | BU38: 0
A39: 20039044 | B39: Wanwanach_เอแคลร์นมสด 125 g | H39: 20039044 | I39: Wanwanach_เอแคลร์นมสด 125 g | O39: 20039044 | P39: Wanwanach_เอแคลร์นมสด 125 g | V39: 20000000 | W39: Wanwanach_เอแคลร์นมสด 125 g | AC39: 20000000 | AD39: Wanwanach_เอแคลร์นมสด 125 g | AJ39: 20000000 | AK39: Wanwanach_เอแคลร์นมสด 125 g | AQ39: 20000000 | AR39: Wanwanach_เอแคลร์นมสด 125 g | AW39: 0 | AX39: 0 | AY39: 0 | AZ39: 0 | BA39: 0 | BE39: 0 | BF39: 0 | BG39: 0 | BH39: 0 | BI39: 0 | BJ39: 0 | BK39: 0 | BO39: 0 | BP39: 0 | BQ39: 0 | BR39: 0 | BS39: 0 | BT39: 0 | BU39: 0
A40: 20053054 | B40: วรรณนัชโดนัทไส้แยมสตอเบอรี่ 110 g | H40: 20053054 | I40: วรรณนัชโดนัทไส้แยมสตอเบอรี่ 110 g | O40: 20053054 | P40: วรรณนัชโดนัทไส้แยมสตอเบอรี่ 110 g | V40: 20000000 | W40: วรรณนัชโดนัทไส้แยมสตอเบอรี่ 110 g | AC40: 20000000 | AD40: วรรณนัชโดนัทไส้แยมสตอเบอรี่ 110 g | AJ40: 20000000 | AK40: วรรณนัชโดนัทไส้แยมสตอเบอรี่ 110 g | AQ40: 20000000 | AR40: วรรณนัชโดนัทไส้แยมสตอเบอรี่ 110 g | AW40: 0 | AX40: 0 | AY40: 0 | AZ40: 0 | BA40: 0 | BE40: 0 | BF40: 0 | BG40: 0 | BH40: 0 | BI40: 0 | BJ40: 0 | BK40: 0 | BO40: 0 | BP40: 0 | BQ40: 0 | BR40: 0 | BS40: 0 | BT40: 0 | BU40: 0
A41: 20039963 | B41: Wanwanach_ปังสังขยาใบเตยนมสด 190 g | H41: 20039963 | I41: Wanwanach_ปังสังขยาใบเตยนมสด 190 g | O41: 20039963 | P41: Wanwanach_ปังสังขยาใบเตยนมสด 190 g | V41: 20000000 | W41: Wanwanach_ปังสังขยาใบเตยนมสด 190 g | AC41: 20000000 | AD41: Wanwanach_ปังสังขยาใบเตยนมสด 190 g | AJ41: 20000000 | AK41: Wanwanach_ปังสังขยาใบเตยนมสด 190 g | AQ41: 20000000 | AR41: Wanwanach_ปังสังขยาใบเตยนมสด 190 g | AW41: 0 | AX41: 0 | AY41: 0 | AZ41: 0 | BA41: 0 | BE41: 0 | BF41: 0 | BG41: 0 | BH41: 0 | BI41: 0 | BJ41: 0 | BK41: 0 | BO41: 0 | BP41: 0 | BQ41: 0 | BR41: 0 | BS41: 0 | BT41: 0 | BU41: 0
...

Sheet Week 2
A1: ลำดับ | B1: ทีมโทร | C1: บูธ | D1: online | E1: Modern Trade | F1: รหัส | G1: ชื่อสินค้า | H1: ลูกค้า | I1: ขนาดบรรจุ | N1: week 2 (วันที่ 7 - 13 ธันวาคม 2568)
I2: จำนวน(ชิ้น) | J2: หน่วย(กล่อง) | K2: วัน | N2: วันอาทิตย์ | R2: ยอดจริง | X2: วันจันทร์ | AB2: ยอดจริง | AH2: วันอังคาร | AL2: ยอดจริง | AR2: วันพุธ | AV2: ยอดจริง | BB2: วันพฤหัสบดี | BF2: ยอดจริง | BL2: วันศุกร์ | BP2: ยอดจริง | BV2: เสาร์ | BZ2: ยอดจริง
K3: วันที่
K4: ติดป้าย Amezon | L4: ไม่ติดป้าย Amezon | M4: Non Logo | N4: ติดป้าย Amezon | O4: ไม่ติดป้าย Amezon | P4: Non Logo | Q4: รวม | R4: ติดป้าย Amezon | S4: ไม่ติดป้าย Amezon | T4: Non Logo | U4: ติดป้าย Amezon | V4: ไม่ติดป้าย Amezon | W4: Non Logo | X4: ติดป้าย Amezon | Y4: ไม่ติดป้าย Amezon | Z4: Non Logo | AA4: รวม | AB4: ติดป้าย Amezon | AC4: ไม่ติดป้าย Amezon | AD4: Non Logo | AE4: ติดป้าย Amezon | AF4: ไม่ติดป้าย Amezon | AG4: Non Logo | AH4: ติดป้าย Amezon | AI4: ไม่ติดป้าย Amezon | AJ4: Non Logo | AK4: รวม | AL4: ติดป้าย Amezon | AM4: ไม่ติดป้าย Amezon | AN4: Non Logo | AO4: ติดป้าย Amezon | AP4: ไม่ติดป้าย Amezon | AQ4: Non Logo | AR4: ติดป้าย Amezon | AS4: ไม่ติดป้าย Amezon | AT4: Non Logo | AU4: รวม | AV4: ติดป้าย Amezon | AW4: ไม่ติดป้าย Amezon | AX4: Non Logo | AY4: ติดป้าย Amezon | AZ4: ไม่ติดป้าย Amezon | BA4: Non Logo | BB4: ติดป้าย Amezon | BC4: ไม่ติดป้าย Amezon | BD4: Non Logo | BE4: รวม | BF4: ติดป้าย Amezon | BG4: ไม่ติดป้าย Amezon | BH4: Non Logo | BI4: ติดป้าย Amezon | BJ4: ไม่ติดป้าย Amezon | BK4: Non Logo | BL4: ติดป้าย Amezon | BM4: ไม่ติดป้าย Amezon | BN4: Non Logo | BO4: รวม | BP4: ติดป้าย Amezon | BQ4: ไม่ติดป้าย Amezon | BR4: Non Logo | BS4: ติดป้าย Amezon | BT4: ไม่ติดป้าย Amezon | BU4: Non Logo | BV4: ติดป้าย Amezon | BW4: ไม่ติดป้าย Amezon | BX4: Non Logo | BY4: รวม | BZ4: ติดป้าย Amezon | CA4: ไม่ติดป้าย Amezon | CB4: Non Logo | CC4: ติดป้าย Amezon | CD4: ไม่ติดป้าย Amezon | CE4: Non Logo
A5: 1 | F5: 1113036 | G5: ช็อกบอล | H5: Aeon | K5: 0 | L5: =SUM(O5,Y5,AI5,AS5,BC5,BM5,BW5) -> 19 | M5: 0 | O5: 9 | BC5: 10 | BY5: =SUM(BV5:BX5) -> 0 | BZ5: 0 | CA5: 0 | CB5: 0 | CC5: 0 | CD5: =BW5-CA5 -> 0 | CE5: 0
A6: 2 | F6: 1111001 | G6: ชิฟฟ่อนเค้ก (1 ชิ้น) | H6: Aeon | K6: 0 | L6: =SUM(O6,Y6,AI6,AS6,BC6,BM6,BW6) -> 0 | M6: 0 | BY6: =SUM(BV6:BX6) -> 0 | BZ6: 0 | CA6: 0 | CB6: 0 | CC6: 0 | CD6: =BW6-CA6 -> 0 | CE6: 0
A7: 3 | F7: 1004055 | G7: ชิฟฟ่อนเค้ก วรรณวนัช (รวมรส 4 ชิ้น) | K7: 0 | L7: =SUM(O7,Y7,AI7,AS7,BC7,BM7,BW7) -> 0 | M7: 0 | BY7: =SUM(BV7:BX7) -> 0 | BZ7: 0 | CA7: 0 | CB7: 0 | CC7: 0 | CD7: =BW7-CA7 -> 0 | CE7: 0
A8: 4 | F8: 1111002 | G8: ชิฟฟ่อนเค้ก วรรณวนัช (รวมรส 8 ชิ้น) | H8: Lotus | K8: 0 | L8: =SUM(O8,Y8,AI8,AS8,BC8,BM8,BW8) -> 0 | M8: 0 | BY8: =SUM(BV8:BX8) -> 0 | BZ8: 0 | CA8: 0 | CB8: 0 | CC8: 0 | CD8: =BW8-CA8 -> 0 | CE8: 0
A9: 5 | F9: 1111055 | G9: วรรณวนัช ชิฟฟ่อนรวมรส 8 ชิ้น | H9: Makro | K9: 0 | L9: =SUM(O9,Y9,AI9,AS9,BC9,BM9,BW9) -> 1760 | M9: 0 | O9: 920 | AI9: 840 | BY9: =SUM(BV9:BX9) -> 0 | BZ9: 0 | CA9: 0 | CB9: 0 | CC9: 0 | CD9: =BW9-CA9 -> 0 | CE9: 0
A10: 6 | F10: 1111030 | G10: ชิฟฟ่อนเค้ก รสกาแฟ (8 ชิ้น) | K10: 0 | L10: =SUM(O10,Y10,AI10,AS10,BC10,BM10,BW10) -> 0 | M10: 0 | BY10: =SUM(BV10:BX10) -> 0 | BZ10: 0 | CA10: 0 | CB10: 0 | CC10: 0 | CD10: =BW10-CA10 -> 0 | CE10: 0
A11: 7 | F11: 1111036 | G11: ชิฟฟอนเค้ก วรรณวนัช ห่อกระดาษ (รวมรส 4 ชิ้น) | K11: 0 | L11: =SUM(O11,Y11,AI11,AS11,BC11,BM11,BW11) -> 0 | M11: 0 | BY11: =SUM(BV11:BX11) -> 0 | BZ11: 0 | CA11: 0 | CB11: 0 | CC11: 0 | CD11: =BW11-CA11 -> 0 | CE11: 0
A12: 8 | F12: 1111037 | G12: ชิฟฟอนเค้ก วรรณวนัช ห่อกระดาษ (รวมรส 8 ชิ้น) | K12: 0 | L12: =SUM(O12,Y12,AI12,AS12,BC12,BM12,BW12) -> 0 | M12: 0 | BY12: =SUM(BV12:BX12) -> 0 | BZ12: 0 | CA12: 0 | CB12: 0 | CC12: 0 | CD12: =BW12-CA12 -> 0 | CE12: 0
A13: 9 | F13: 1111040 | G13: ชิฟฟอนเค้กวรรณวนัช ห่อซีน (รวมรส 4 ชิ้น) | K13: 0 | L13: =SUM(O13,Y13,AI13,AS13,BC13,BM13,BW13) -> 0 | M13: 0 | BY13: =SUM(BV13:BX13) -> 0 | BZ13: 0 | CA13: 0 | CB13: 0 | CC13: 0 | CD13: =BW13-CA13 -> 0 | CE13: 0
A14: 10 | F14: 1111039 | G14: ชิฟฟอนเค้ก วรรรณวนัช ห่อซีน (รวมรส 8 ชิ้น) | K14: 0 | L14: =SUM(O14,Y14,AI14,AS14,BC14,BM14,BW14) -> 0 | M14: 0 | BY14: =SUM(BV14:BX14) -> 0 | BZ14: 0 | CA14: 0 | CB14: 0 | CC14: 0 | CD14: =BW14-CA14 -> 0 | CE14: 0
A15: 11 | F15: 1111041 | G15: ชิฟฟอนเค้ก วรรณวนัช กาแฟล้วน(รวมรส 4 ชิ้น) | K15: 0 | L15: =SUM(O15,Y15,AI15,AS15,BC15,BM15,BW15) -> 0 | M15: 0 | BY15: =SUM(BV15:BX15) -> 0 | BZ15: 0 | CA15: 0 | CB15: 0 | CC15: 0 | CD15: =BW15-CA15 -> 0 | CE15: 0
A16: 12 | F16: 1111043 | G16: ชิฟฟอนรสมะลิ 8 ชิ้น ห่อ ซีน | K16: 0 | L16: =SUM(O16,Y16,AI16,AS16,BC16,BM16,BW16) -> 0 | M16: 0 | BY16: =SUM(BV16:BX16) -> 0 | BZ16: 0 | CA16: 0 | CB16: 0 | CC16: 0 | CD16: =BW16-CA16 -> 0 | CE16: 0
A17: 13 | F17: 1113091 | G17: (BC) ชิฟฟ่อนรวมรส 4 ชิ้น | H17: BC | K17: 0 | L17: =SUM(O17,Y17,AI17,AS17,BC17,BM17,BW17) -> 505 | M17: 0 | Y17: 35 | AS17: 400 | BM17: 70 | BY17: =SUM(BV17:BX17) -> 0 | BZ17: 0 | CA17: 0 | CB17: 0 | CC17: 0 | CD17: =BW17-CA17 -> 0 | CE17: 0
A18: 14 | F18: 1113083 | G18: (BC) ชิฟฟ่อนฝอยทอง 1 ชิ้น ไม่มีไส้ | K18: 0 | L18: =SUM(O18,Y18,AI18,AS18,BC18,BM18,BW18) -> 0 | M18: 0 | BY18: =SUM(BV18:BX18) -> 0 | BZ18: 0 | CA18: 0 | CB18: 0 | CC18: 0 | CD18: =BW18-CA18 -> 0 | CE18: 0
A19: 15 | F19: 1111057 | G19: ชิฟฟอนแยกชิ้น กาแฟ | K19: 0 | L19: =SUM(O19,Y19,AI19,AS19,BC19,BM19,BW19) -> 0 | M19: 0 | BY19: =SUM(BV19:BX19) -> 0 | BZ19: 0 | CA19: 0 | CB19: 0 | CC19: 0 | CD19: =BW19-CA19 -> 0 | CE19: 0
A20: 16 | F20: 1111058 | G20: ชิฟฟอนแยกชิ้น ชาเขียว | K20: 0 | L20: =SUM(O20,Y20,AI20,AS20,BC20,BM20,BW20) -> 0 | M20: 0 | BY20: =SUM(BV20:BX20) -> 0 | BZ20: 0 | CA20: 0 | CB20: 0 | CC20: 0 | CD20: =BW20-CA20 -> 0 | CE20: 0
A21: 17 | F21: 1111059 | G21: ชิฟฟอนแยกชิ้น ใบเตย | K21: 0 | L21: =SUM(O21,Y21,AI21,AS21,BC21,BM21,BW21) -> 0 | M21: 0 | BY21: =SUM(BV21:BX21) -> 0 | BZ21: 0 | CA21: 0 | CB21: 0 | CC21: 0 | CD21: =BW21-CA21 -> 0 | CE21: 0
A22: 18 | F22: 1111060 | G22: ชิฟฟอนแยกชิ้น กล้วยหอม | K22: 0 | L22: =SUM(O22,Y22,AI22,AS22,BC22,BM22,BW22) -> 0 | M22: 0 | BY22: =SUM(BV22:BX22) -> 0 | BZ22: 0 | CA22: 0 | CB22: 0 | CC22: 0 | CD22: =BW22-CA22 -> 0 | CE22: 0
A23: 19 | F23: 1111061 | G23: ชิฟฟอนแยกชิ้น ชาไทย | K23: 0 | L23: =SUM(O23,Y23,AI23,AS23,BC23,BM23,BW23) -> 0 | M23: 0 | BY23: =SUM(BV23:BX23) -> 0 | BZ23: 0 | CA23: 0 | CB23: 0 | CC23: 0 | CD23: =BW23-CA23 -> 0 | CE23: 0
A24: 20 | F24: 1111062 | G24: ชิฟฟอนแยกชิ้น โกโก้ | K24: 0 | L24: =SUM(O24,Y24,AI24,AS24,BC24,BM24,BW24) -> 0 | M24: 0 | BY24: =SUM(BV24:BX24) -> 0 | BZ24: 0 | CA24: 0 | CB24: 0 | CC24: 0 | CD24: =BW24-CA24 -> 0 | CE24: 0
A25: 21 | F25: 1111063 | G25: ชิฟฟอนแยกชิ้น ส้ม | K25: 0 | L25: =SUM(O25,Y25,AI25,AS25,BC25,BM25,BW25) -> 0 | M25: 0 | BY25: =SUM(BV25:BX25) -> 0 | BZ25: 0 | CA25: 0 | CB25: 0 | CC25: 0 | CD25: =BW25-CA25 -> 0 | CE25: 0
A26: 22 | F26: 1111064 | G26: ชิฟฟอนแยกชิ้น เผือก | K26: 0 | L26: =SUM(O26,Y26,AI26,AS26,BC26,BM26,BW26) -> 0 | M26: 0 | BY26: =SUM(BV26:BX26) -> 0 | BZ26: 0 | CA26: 0 | CB26: 0 | CC26: 0 | CD26: =BW26-CA26 -> 0 | CE26: 0
A27: 23 | F27: 1111065 | G27: ชิฟฟอนแยกชิ้น สับปะรด | K27: 0 | L27: =SUM(O27,Y27,AI27,AS27,BC27,BM27,BW27) -> 0 | M27: 0 | BY27: =SUM(BV27:BX27) -> 0 | BZ27: 0 | CA27: 0 | CB27: 0 | CC27: 0 | CD27: =BW27-CA27 -> 0 | CE27: 0
A28: 24 | F28: 1111066 | G28: ชิฟฟอนแยกชิ้น สตอเบอรี่ | K28: 0 | L28: =SUM(O28,Y28,AI28,AS28,BC28,BM28,BW28) -> 0 | M28: 0 | BY28: =SUM(BV28:BX28) -> 0 | BZ28: 0 | CA28: 0 | CB28: 0 | CC28: 0 | CD28: =BW28-CA28 -> 0 | CE28: 0
A29: 25 | F29: 1111067 | G29: ชิฟฟอนแยกชิ้น มะพร้าว | K29: 0 | L29: =SUM(O29,Y29,AI29,AS29,BC29,BM29,BW29) -> 0 | M29: 0 | BY29: =SUM(BV29:BX29) -> 0 | BZ29: 0 | CA29: 0 | CB29: 0 | CC29: 0 | CD29: =BW29-CA29 -> 0 | CE29: 0
... A31: 27 | F31: 1111069 | G31: ชิฟฟอนแยกชิ้น บลูเบอรี่ | K31: 0 | L31: =SUM(O31,Y31,AI31,AS31,BC31,BM31,BW31) -> 0 | M31: 0 | BY31: =SUM(BV31:BX31) -> 0 | BZ31: 0 | CA31: 0 | CB31: 0 | CC31: 0 | CD31: =BW31-CA31 -> 0 | CE31: 0
A32: 28 | F32: 1004061 | G32: ชิฟฟ่อนเค้ก สอดไส้ครีมมะพร้าว (2 ชิ้น) | H32: Aeon | K32: 0 | L32: =SUM(O32,Y32,AI32,AS32,BC32,BM32,BW32) -> 27 | M32: 0 | O32: 15 | BC32: 12 | BY32: =SUM(BV32:BX32) -> 0 | BZ32: 0 | CA32: 0 | CB32: 0 | CC32: 0 | CD32: =BW32-CA32 -> 0 | CE32: 0
A33: 29 | F33: 1111051 | G33: ชิฟฟ่อนเค้กสอดไส้ครีมมะพร้าว (2ชิ้น) มะพร้าวล้วน | K33: 0 | L33: =SUM(O33,Y33,AI33,AS33,BC33,BM33,BW33) -> 0 | M33: 0 | BY33: =SUM(BV33:BX33) -> 0 | BZ33: 0 | CA33: 0 | CB33: 0 | CC33: 0 | CD33: =BW33-CA33 -> 0 | CE33: 0
A34: 30 | F34: 1111004 | G34: ชิฟฟ่อนเค้ก สอดไส้ครีมมะพร้าว (4 ชิ้น) | K34: 0 | L34: =SUM(O34,Y34,AI34,AS34,BC34,BM34,BW34) -> 0 | M34: 0 | BY34: =SUM(BV34:BX34) -> 0 | BZ34: 0 | CA34: 0 | CB34: 0 | CC34: 0 | CD34: =BW34-CA34 -> 0 | CE34: 0
A35: 31 | F35: 1111048 | G35: ชิฟฟอนเค้กสอดไส้ครีมมะพร้าว+เตย (4ชิ้น) | K35: 0 | L35: =SUM(O35,Y35,AI35,AS35,BC35,BM35,BW35) -> 0 | M35: 0 | BY35: =SUM(BV35:BX35) -> 0 | BZ35: 0 | CA35: 0 | CB35: 0 | CC35: 0 | CD35: =BW35-CA35 -> 0 | CE35: 0
A36: 32 | F36: 1111005 | G36: ชิฟฟ่อนเค้ก สอดไส้ครีมมะพร้าว (5 ชิ้น) | K36: 0 | L36: =SUM(O36,Y36,AI36,AS36,BC36,BM36,BW36) -> 0 | M36: 0 | BY36: =SUM(BV36:BX36) -> 0 | BZ36: 0 | CA36: 0 | CB36: 0 | CC36: 0 | CD36: =BW36-CA36 -> 0 | CE36: 0
A37: 33 | F37: 1111047 | G37: ชิฟฟอนเค้กสอดไส้ครีมมะพร้าว+เตย (5ชิ้น) | K37: 0 | L37: =SUM(O37,Y37,AI37,AS37,BC37,BM37,BW37) -> 0 | M37: 0 | BY37: =SUM(BV37:BX37) -> 0 | BZ37: 0 | CA37: 0 | CB37: 0 | CC37: 0 | CD37: =BW37-CA37 -> 0 | CE37: 0
A38: 34 | F38: 1111006 | G38: ชิฟฟ่อนเค้ก วรรณวนัช (สอดไส้รวมรส 8 ชิ้น) | K38: 0 | L38: =SUM(O38,Y38,AI38,AS38,BC38,BM38,BW38) -> 0 | M38: 0 | BY38: =SUM(BV38:BX38) -> 0 | BZ38: 0 | CA38: 0 | CB38: 0 | CC38: 0 | CD38: =BW38-CA38 -> 0 | CE38: 0
A39: 35 | F39: 1111034 | G39: ชิฟฟ่อนเค้กใบเตยสอดไส้ครีมมะพร้าว (8 ชิ้น ) | K39: 0 | L39: =SUM(O39,Y39,AI39,AS39,BC39,BM39,BW39) -> 0 | M39: 0 | BY39: =SUM(BV39:BX39) -> 0 | BZ39: 0 | CA39: 0 | CB39: 0 | CC39: 0 | CD39: =BW39-CA39 -> 0 | CE39: 0
A40: 36 | F40: 1111035 | G40: ชิฟฟ่อนเค้กมะพร้าวสอดไส้ครีมมะพร้าว (8 ชิ้น) | K40: 0 | L40: =SUM(O40,Y40,AI40,AS40,BC40,BM40,BW40) -> 0 | M40: 0 | BY40: =SUM(BV40:BX40) -> 0 | BZ40: 0 | CA40: 0 | CB40: 0 | CC40: 0 | CD40: =BW40-CA40 -> 0 | CE40: 0
A41: 37 | F41: 1111031 | G41: ชิฟฟ่อนเค้กทูโทนใบเตยและมะพร้าวสอดไส้ครีม (8 ชิ้น) | K41: 0 | L41: =SUM(O41,Y41,AI41,AS41,BC41,BM41,BW41) -> 0 | M41: 0 | BY41: =SUM(BV41:BX41) -> 0 | BZ41: 0 | CA41: 0 | CB41: 0 | CC41: 0 | CD41: =BW41-CA41 -> 0 | CE41: 0
...

Sheet ยอดจริง Week 2
A1: วันอาทิตย์ | H1: วันจันทร์ | O1: วันอังคาร | V1: วันพุธ | AC1: วันพฤหัส | AJ1: วันศุกร์ | AQ1: วันเสาร์ | BY1: week 4 (วันที่ 24-30 พฤศจิกายน 2567) | CT1: week 5
A2: รหัส | B2: รายการ | C2: A | D2: B | E2: N | F2: รวม | H2: รหัส | I2: รายการ | J2: A | K2: B | L2: N | M2: รวม | O2: รหัส | P2: รายการ | Q2: A | R2: B | S2: N | T2: รวม | V2: รหัส | W2: รายการ | X2: A | Y2: B | Z2: N | AA2: รวม | AC2: รหัส | AD2: รายการ | AE2: A | AF2: B | AG2: N | AH2: รวม | AJ2: รหัส | AK2: รายการ | AL2: A | AM2: B | AN2: N | AO2: รวม | AQ2: รหัส | AR2: รายการ | AS2: A | AT2: B | AU2: N | AV2: รวม | BB2: วันพฤหัสบดี | BF2: ยอดจริง | BL2: วันศุกร์ | BP2: ยอดจริง | BV2: เสาร์ | BY2: วันอาทิตย์ | CB2: วันจันทร์ | CE2: วันอังคาร | CH2: วันพุธ | CK2: วันพฤหัสบดี | CN2: วันศุกร์ | CQ2: เสาร์ | CT2: วันอาทิตย์ | CW2: วันจันทร์ | CZ2: วันอังคาร | DC2: วันพุธ | DF2: วันพฤหัสบดี | DI2: วันศุกร์ | DL2: เสาร์
A3: 1113036 | B3: ช็อกบอล | H3: 1113036 | I3: ช็อกบอล | O3: 1113036 | P3: ช็อกบอล | V3: 1113036 | W3: ช็อกบอล | AC3: 1113036 | AD3: ช็อกบอล | AJ3: 1113036 | AK3: ช็อกบอล | AQ3: 1113036 | AR3: ช็อกบอล | BZ3: 24 | CC3: 25 | CF3: 26 | CI3: 27 | CL3: 28 | CO3: 29 | CR3: 30
A4: 1111001 | B4: ชิฟฟ่อนเค้ก (1 ชิ้น) | H4: 1111001 | I4: ชิฟฟ่อนเค้ก (1 ชิ้น) | O4: 1111001 | P4: ชิฟฟ่อนเค้ก (1 ชิ้น) | V4: 1111001 | W4: ชิฟฟ่อนเค้ก (1 ชิ้น) | AC4: 1111001 | AD4: ชิฟฟ่อนเค้ก (1 ชิ้น) | AJ4: 1111001 | AK4: ชิฟฟ่อนเค้ก (1 ชิ้น) | AQ4: 1111001 | AR4: ชิฟฟ่อนเค้ก (1 ชิ้น) | AW4: ไม่ติดป้าย Amezon | AX4: Non Logo | AY4: ติดป้าย Amezon | AZ4: ไม่ติดป้าย Amezon | BA4: Non Logo | BB4: ติดป้าย Amezon | BC4: ไม่ติดป้าย Amezon | BD4: Non Logo | BE4: รวม | BF4: ติดป้าย Amezon | BG4: ไม่ติดป้าย Amezon | BH4: Non Logo | BI4: ติดป้าย Amezon | BJ4: ไม่ติดป้าย Amezon | BK4: Non Logo | BL4: ติดป้าย Amezon | BM4: ไม่ติดป้าย Amezon | BN4: Non Logo | BO4: รวม | BP4: ติดป้าย Amezon | BQ4: ไม่ติดป้าย Amezon | BR4: Non Logo | BS4: ติดป้าย Amezon | BT4: ไม่ติดป้าย Amezon | BU4: Non Logo | BV4: ติดป้าย Amezon | BW4: ไม่ติดป้าย Amezon | BX4: Non Logo | BY4: ติดป้าย Amezon | BZ4: ไม่ติดป้าย Amezon | CA4: Non Logo | CB4: ติดป้าย Amezon | CC4: ไม่ติดป้าย Amezon | CD4: Non Logo | CE4: ติดป้าย Amezon | CF4: ไม่ติดป้าย Amezon | CG4: Non Logo | CH4: ติดป้าย Amezon | CI4: ไม่ติดป้าย Amezon | CJ4: Non Logo | CK4: ติดป้าย Amezon | CL4: ไม่ติดป้าย Amezon | CM4: Non Logo | CN4: ติดป้าย Amezon | CO4: ไม่ติดป้าย Amezon | CP4: Non Logo | CQ4: ติดป้าย Amezon | CR4: ไม่ติดป้าย Amezon | CS4: Non Logo | CT4: ติดป้าย Amezon | CU4: ไม่ติดป้าย Amezon | CV4: Non Logo | CW4: ติดป้าย Amezon | CX4: ไม่ติดป้าย Amezon | CY4: Non Logo | CZ4: ติดป้าย Amezon | DA4: ไม่ติดป้าย Amezon | DB4: Non Logo | DC4: ติดป้าย Amezon | DD4: ไม่ติดป้าย Amezon | DE4: Non Logo | DF4: ติดป้าย Amezon | DG4: ไม่ติดป้าย Amezon | DH4: Non Logo | DI4: ติดป้าย Amezon | DJ4: ไม่ติดป้าย Amezon | DK4: Non Logo | DL4: ติดป้าย Amezon | DM4: ไม่ติดป้าย Amezon | DN4: Non Logo
A5: 1004061 | B5: ชิฟฟ่อนเค้ก สอดไส้ครีมมะพร้าว (2 ชิ้น) | H5: 1004061 | I5: ชิฟฟ่อนเค้ก สอดไส้ครีมมะพร้าว (2 ชิ้น) | O5: 1004061 | P5: ชิฟฟ่อนเค้ก สอดไส้ครีมมะพร้าว (2 ชิ้น) | V5: 1004061 | W5: ชิฟฟ่อนเค้ก สอดไส้ครีมมะพร้าว (2 ชิ้น) | AC5: 1004061 | AD5: ชิฟฟ่อนเค้ก สอดไส้ครีมมะพร้าว (2 ชิ้น) | AJ5: 1004061 | AK5: ชิฟฟ่อนเค้ก สอดไส้ครีมมะพร้าว (2 ชิ้น) | AQ5: 1004061 | AR5: ชิฟฟ่อนเค้ก สอดไส้ครีมมะพร้าว (2 ชิ้น) | AW5: 0 | AX5: 0 | AY5: 0 | AZ5: 0 | BA5: 0 | BC5: 10 | BE5: 10 | BF5: 0 | BG5: 0 | BH5: 0 | BI5: 0 | BJ5: 10 | BK5: 0 | BO5: 0 | BP5: 0 | BQ5: 0 | BR5: 0 | BS5: 0 | BT5: 0 | BU5: 0 | BZ5: 10 | CL5: 10
A6: 1004071 | B6: คัพเค้กกล้วยหอมไส้ครีมเนยสด (4 ชิ้น) | H6: 1004071 | I6: คัพเค้กกล้วยหอมไส้ครีมเนยสด (4 ชิ้น) | O6: 1004071 | P6: คัพเค้กกล้วยหอมไส้ครีมเนยสด (4 ชิ้น) | V6: 1004071 | W6: คัพเค้กกล้วยหอมไส้ครีมเนยสด (4 ชิ้น) | AC6: 1004071 | AD6: คัพเค้กกล้วยหอมไส้ครีมเนยสด (4 ชิ้น) | AJ6: 1004071 | AK6: คัพเค้กกล้วยหอมไส้ครีมเนยสด (4 ชิ้น) | AQ6: 1004071 | AR6: คัพเค้กกล้วยหอมไส้ครีมเนยสด (4 ชิ้น) | AW6: 0 | AX6: 0 | AY6: 0 | AZ6: 0 | BA6: 0 | BE6: 0 | BF6: 0 | BG6: 0 | BH6: 0 | BI6: 0 | BJ6: 0 | BK6: 0 | BO6: 0 | BP6: 0 | BQ6: 0 | BR6: 0 | BS6: 0 | BT6: 0 | BU6: 0
A7: 1004070 | B7: คัพเค้กมะพร้าวไส้ครีมเนยสด (4 ชิ้น) | H7: 1004070 | I7: คัพเค้กมะพร้าวไส้ครีมเนยสด (4 ชิ้น) | O7: 1004070 | P7: คัพเค้กมะพร้าวไส้ครีมเนยสด (4 ชิ้น) | V7: 1004070 | W7: คัพเค้กมะพร้าวไส้ครีมเนยสด (4 ชิ้น) | AC7: 1004070 | AD7: คัพเค้กมะพร้าวไส้ครีมเนยสด (4 ชิ้น) | AJ7: 1004070 | AK7: คัพเค้กมะพร้าวไส้ครีมเนยสด (4 ชิ้น) | AQ7: 1004070 | AR7: คัพเค้กมะพร้าวไส้ครีมเนยสด (4 ชิ้น) | AW7: 0 | AX7: 0 | AY7: 0 | AZ7: 0 | BA7: 0 | BE7: 0 | BF7: 0 | BG7: 0 | BH7: 0 | BI7: 0 | BJ7: 0 | BK7: 0 | BO7: 0 | BP7: 0 | BQ7: 0 | BR7: 0 | BS7: 0 | BT7: 0 | BU7: 0
