Workbook

Sheet DATA POS
A1: รหัสสินค้า | B1: ชื่อสินค้า | C1: หมวดหมู่สินค้า | D1: หน่วยสินค้า | E1: ราคาขาย | F1: ราคาซื้อ | G1: Min | H1: Max | I1: หมายเหตุ | J1: สถานะ
B2: มะม่วงหนึบ | C2: หมวดอื่นๆ | D2: กล่อง | E2: 40.00 | F2: 0.00 | G2: 0 | H2: 0 | J2: ใช้งาน
A3: 0109256601 | B3: กระเช้าสำเร็จรูป | C3: หมวดอื่นๆ | D3: กระเช้า | E3: 800.00 | F3: 0.00 | G3: 0 | H3: 0 | J3: ใช้งาน
A4: 0109256602 | B4: เซ็ตของขวัญ | C4: หมวดอื่นๆ | D4: กล่อง | E4: 260.00 | F4: 0.00 | G4: 0 | H4: 0 | J4: ใช้งาน
A5: 01-SU-0025-1 | B5: น้ำแดงเฮลบลูบอย | C5: เครื่องดื่ม | D5: ขวด | E5: 58.00 | F5: 0.00 | G5: 0 | H5: 0 | J5: ใช้งาน
A6: 02102566 | B6: เปี๊ยะมินิ | C6: หมวดอื่นๆ | D6: กล่อง | E6: 25.00 | F6: 0.00 | G6: 0 | H6: 0 | J6: ใช้งาน
A7: 02-BB01 | B7: กล่องเค้กเบาหวิวทุเรียน 100g. New | C7: กล่องโมเดล | D7: กล่อง | E7: 20.00 | F7: 0.00 | G7: 0 | H7: 0 | J7: ใช้งาน
A8: 02-BB02 | B8: กล่องเค้กเบาหวิวเผือกมะพร้าวอ่อน 100g. New | C8: กล่องโมเดล | D8: กล่อง | E8: 20.00 | F8: 0.00 | G8: 0 | H8: 0 | J8: ใช้งาน
A9: 02-BB03 | B9: กล่องเค้กเบาหวิวกล้วยมะพร้าวเผา 100g. New | C9: กล่องโมเดล | D9: กล่อง | E9: 20.00 | F9: 0.00 | G9: 0 | H9: 0 | J9: ใช้งาน
A10: 02-BB05 | B10: กล่องเค้กเบาหวิวรสกาแฟ 100g New | C10: กล่องโมเดล | D10: กล่อง | E10: 20.00 | F10: 0.00 | G10: 0 | H10: 0 | J10: ใช้งาน
A11: 02-BB07 | B11: กล่องเค้กเบาหวิวรสกาแฟ 300g. New | C11: กล่องโมเดล | D11: กล่อง | E11: 20.00 | F11: 0.00 | G11: 0 | H11: 0 | J11: ใช้งาน
A12: 02-BB09 | B12: กล่องเค้กเบาหวิวรสเนยนม 110g. New | C12: กล่องโมเดล | D12: กล่อง | E12: 20.00 | F12: 0.00 | G12: 0 | H12: 0 | J12: ใช้งาน
A13: 02-BB11 | B13: กล่องเค้กเบาหวิวรสเนยนม 300g. New | C13: กล่องโมเดล | D13: กล่อง | E13: 20.00 | F13: 0.00 | G13: 0 | H13: 0 | J13: ใช้งาน
A14: 02-BB14 | B14: กล่องเค้กเบาหวิวรสใบเตย 300g. New | C14: กล่องโมเดล | D14: กล่อง | E14: 20.00 | F14: 0.00 | G14: 0 | H14: 0 | J14: ใช้งาน
... A76: 1113178 | B76: เค้กลอดช่องกล่องกลม 1 ปอนด์ 265 กรัม | C76: เค้ก | D76: กล่อง | E76: 0.00 | F76: 0.00 | G76: 0 | H76: 0 | J76: ใช้งาน
A77: 1113179 | B77: เค้กลอดช่องกล่องกลม 2 ปอนด์ 325 กรัม | C77: เค้ก | D77: กล่อง | E77: 240.00 | F77: 0.00 | G77: 0 | H77: 0 | I77: สินค้าระบายจากทางออนไลน์ ขาย 120 บาท | J77: ใช้งาน
A78: 1113185 | B78: ข้าวเกรียบว่าว (กระปุก) | C78: ขนมปัง แซนวิส | D78: กระปุก | E78: 40.00 | F78: 0.00 | G78: 0 | H78: 0 | J78: ใช้งาน
A79: 1113191 | B79: เค้กตะโก้เผือกหอม 120 กรัม | C79: เค้ก | D79: กล่อง | E79: 35.00 | F79: 0.00 | G79: 0 | H79: 0 | J79: ใช้งาน
A80: 1113192 | B80: ปังนุ่มมะพร้าว 100 กรัม | C80: ขนมปัง แซนวิส | D80: กล่อง | E80: 35.00 | F80: 0.00 | G80: 0 | H80: 0 | I80: บิ๊กซี | J80: ใช้งาน
A81: 1113193 | B81: ปังนุ่มชาไทย 100 กรัม | C81: ขนมปัง แซนวิส | D81: กล่อง | E81: 35.00 | F81: 0.00 | G81: 0 | H81: 0 | I81: บิ๊กซี | J81: ใช้งาน
A82: 1113194 | B82: บานอฟฟี่ 140 กรัม | C82: เค้ก | D82: กล่อง | E82: 45.00 | F82: 0.00 | G82: 0 | H82: 0 | I82: ราคาเต็ม 45 บาท , ราคาของระบาย 20 บาท | J82: ใช้งาน
A83: 1114024 | B83: สังขยา 1 ชิ้น | C83: ขนมปัง แซนวิส | D83: ชิ้น | E83: 10.00 | F83: 0.00 | G83: 0 | H83: 0 | J83: ใช้งาน
A84: 11140500 | B84: ขนมปังเลเยอร์ | C84: ขนมปัง แซนวิส | D84: ถุง | E84: 65.00 | F84: 0.00 | G84: 0 | H84: 0 | J84: ใช้งาน
A85: 1114056 | B85: ขนมปุยฝ้าย คละรส (4 ชิ้น) | C85: ขนมปัง แซนวิส | D85: กล่อง | E85: 50.00 | F85: 0.00 | G85: 0 | H85: 0 | J85: ใช้งาน
A86: 1114057 | B86: ขนมปุยฝ้าย สีชมพู (1 ปอนด์) | C86: ขนมปัง แซนวิส | D86: กล่อง | E86: 60.00 | F86: 0.00 | G86: 0 | H86: 0 | J86: ใช้งาน
A87: 1114058 | B87: ขนมปุยฝ้าย สีชมพู (4 ชิ้น) | C87: ขนมปัง แซนวิส | D87: กล่อง | E87: 50.00 | F87: 0.00 | G87: 0 | H87: 0 | J87: ใช้งาน
A88: 1114059 | B88: ขนมปุยฝ้าย สีขาว (1 ปอนด์) | C88: ขนมปัง แซนวิส | D88: กล่อง | E88: 60.00 | F88: 0.00 | G88: 0 | H88: 0 | J88: ใช้งาน
A89: 1114060 | B89: ขนมปุยฝ้าย สีขาว (4 ชิ้น) | C89: ขนมปัง แซนวิส | D89: กล่อง | E89: 50.00 | F89: 0.00 | G89: 0 | H89: 0 | J89: ใช้งาน
A90: 1124024 | B90: ขนมปังไส้ฝอยทอง (ชิ้น) | C90: ขนมปัง แซนวิส | D90: ชิ้น | E90: 30.00 | F90: 0.00 | G90: 0 | H90: 0 | J90: ใช้งาน
A91: 1124037 | B91: ขนมปังไส้พริกเผาไก่หยอง (ชิ้น) | C91: ขนมปัง แซนวิส | D91: ชิ้น | E91: 30.00 | F91: 0.00 | G91: 0 | H91: 0 | J91: ใช้งาน
A92: 1124038 | B92: ขนมปังไส้แยมบลูเบอร์รี่ (ชิ้น) | C92: ขนมปัง แซนวิส | D92: ชิ้น | E92: 30.00 | F92: 0.00 | G92: 0 | H92: 0 | J92: ใช้งาน
A93: 1124039 | B93: ขนมปังไส้แยมสตรอเบอร์รี่ (ชิ้น) | C93: ขนมปัง แซนวิส | D93: ชิ้น | E93: 30.00 | F93: 0.00 | G93: 0 | H93: 0 | J93: ใช้งาน
A94: 1124040 | B94: ขนมปังไส้ลูกเกดฝอยทอง (ชิ้น) | C94: ขนมปัง แซนวิส | D94: ชิ้น | E94: 30.00 | F94: 0.00 | G94: 0 | H94: 0 | J94: ใช้งาน
... A96: 1200032 | B96: (NP)มาม่อนคัฟ รวมรส (6ชิ้น) | C96: หนองพงนก | D96: กล่อง | E96: 80.00 | F96: 0.00 | G96: 0 | H96: 0 | J96: ใช้งาน
A97: 1200092 | B97: ท๊อฟฟี่ถั่ว (กิโล) | D97: กิโลกรัม | E97: 200.00 | F97: 0.00 | G97: 0 | H97: 0 | J97: ใช้งาน
A98: 1300005 | B98: เค้กมะพร้าวลาวา 85 กรัม | C98: เค้ก | D98: กล่อง | E98: 35.00 | F98: 0.00 | G98: 0 | H98: 0 | J98: ใช้งาน
A99: 1300006 | B99: แซนด์วิช แฮมไข่ดาว | C99: ขนมปัง แซนวิส | D99: กล่อง | E99: 35.00 | F99: 0.00 | G99: 0 | H99: 0 | J99: ใช้งาน
A100: 13082000 | B100: หนังสือนิทาน วาดภาพ | C100: รพ.สินแพทย์ | D100: ชิ้น | E100: 20.00 | F100: 0.00 | G100: 0 | H100: 0 | J100: ใช้งาน
A101: 13082001 | B101: ห้องครัว | C101: รพ.สินแพทย์ | D101: กล่อง | E101: 450.00 | F101: 0.00 | G101: 0 | H101: 0 | J101: ใช้งาน
A102: 13082002 | B102: ฮีโร่แผง 150 | C102: รพ.สินแพทย์ | D102: ชิ้น | E102: 150.00 | F102: 0.00 | G102: 0 | H102: 0 | J102: ใช้งาน
...

Sheet ต้นทุนพี่ตุ๊ก
A1: รหัสสินค้า | B1: ชื่อสินค้า | C1: ราคาต้นทุน
A2: 1111001 | B2: ชิฟฟ่อนเค้ก 1 ชิ้น
A3: 1111010 | B3: ชิฟฟ่อนเค้กสอดไส้แยม 1 ชิ้น
A4: 1112539 | B4: ชิฟฟ่อนเค้กสอดไส้ เมล่อน (3 ชิ้น)
A5: 20055116 | B5: ชิฟฟ่อนเค้กสอดไส้ครีมมะพร้าว 120g.
A6: 20055119 | B6: ชิฟฟ่อนเค้กฝอยทอง 95g.
A7: 1124027 | B7: ครีมฮอร์นใบเตย จัมโบ้ 65g.
A8: 1124029 | B8: ครีมฮอร์นชาไทย จัมโบ้ 65g.
A9: 20055115 | B9: ครีมฮอร์นคิทแคท 70g.
A10: 1200019 | B10: NP เค้กโบราณครีม 6 ชิ้น
A11: 1200020 | B11: NP เเค้กโบราณผลไม้ 6 ชิ้น
A12: 5002400 | B12: เค้กลาวา ฝอยทอง เล็ก
A13: 1113011 | B13: เค้กลาวา ฝอยทอง ใหญ่
A14: 1113010 | B14: เค้กลาวา ฝอยทองทูโทน ใหญ่
A15: 20054637 | B15: เอแคลร์คิทแคท 55g.
A16: 20056257 | B16: เอแคลร์ชาไทย 125g.
A17: 20054638 | B17: เครปเค้กคิทแคท 65g.
A18: 1113194 | B18: บานอฟฟี่ 140 กรัม
A19: 1006979 | B19: คัพเค้กไส้คัสตาร์ด
A20: 1300005 | B20: เค้กมะพร้าวลาวา 85 กรัม
A21: 1113157 | B21: เค้กลอดช่อง 85 กรัม
A22: 1113178 | B22: เค้กลอดช่องกล่องกลม 1 ปอนด์ 265 กรัม
A23: 1113179 | B23: เค้กลอดช่องกล่องกลม 2 ปอนด์ 325 กรัม
A24: 20053053 | B24: เค้กทุเรียน 90 กรัม
A25: 20055951 | B25: เค้กบัวลอยมะพร้าวอ่อน 100 กรัม
A26: 1113004 | B26: เค้กสามเหลี่ยม รสฝอยทองใบเตย
A27: 1111410 | B27: เค้กวันเกิดมะพร้าวอ่อน 1/2 ปอนด์
A28: 1111406 | B28: เค้กวันเกิดมะพร้าวอ่อน 1 ปอนด์
A29: 1111410 | B29: เค้กวันเกิด 1/2 ปอนด์ ธรรมดา
A30: 1113114 | B30: เค้กวันเกิด 1 ปอนด์ ธรรมดา
A31: 1200003 | B31: ท๊อฟฟี่ถั่ว (กระเช้า)
A32: 1200002 | B32: ท๊อฟฟี่ถั่ว (กล่อง)
A33: 1200001 | B33: คอนเฟลกคาราเมล (เล็ก)
A34: 1006002 | B34: วุ้นฝอยทอง (N)
A35: 25661201 | B35: วุ้นแฟนซี (N)
A36: 1113192 | B36: ปังนุ่มมะพร้าว 100 กรัม
A37: 1113193 | B37: ปังนุ่มชาไทย 100 กรัม
A38: 1113084 | B38: ขนมปังเนยนิ่ม (2 ชิ้น)
A39: 1124002 | B39: ขนมปังสังขยาใบเตยนมสด 4 ชิ้น
A40: 1113110 | B40: ขนมปังไก่หยองน้ำสลัด
...

Sheet สรุป
A2: บูธ EVENT MakroHoReCa17 31 ต.ค. 67 -4 พ.ย. 67 | Q2: บูธ EVENT MakroHoReCa17 31 ต.ค. 67 -4 พ.ย. 67
A3: ลำดับ | B3: รหัสสินค้า (POS) | C3: รายการ | D3: หน่วย | E3: ยกมา | F3: รับ | G3: รวม | H3: เปลี่ยน/ | I3: โยกย้าย / ระบาย | J3: คงเหลือ | K3: รายการขาย | N3: หมายเหตุ | O3: ราคาต้นทุน | P3: ยอดรวมต้นทุนสินค้า | Q3: วันที่ | R3: ยอดเงิน | S3: ส่วนลด | T3: สแกนใช้สิทธิ์ | U3: ค่าโอนเงิน | V3: ค่าใช้จ่ายอื่นๆ | W3: โอนหน้าร้าน | X3: รับสุทธิ | Y3: ยอดโอนเงิน | Z3: โอนเกิน/โอนขาด | AA3: วัน | AB3: รวมยอดขายหลังหักค่าใช้จ่าย
H4: คืน/เสีย | K4: จำนวน | L4: @ | M4: เป็นเงิน
A5: 1 | B5: 8857125001328 | C5: ชิฟฟ่อนเค้ก รวมรส (4 ชิ้น) | D5: กล่อง | E5: =+ยกมา!J5 -> 0 | F5: =+'31.'!F5+'1'!F5+'2'!F5+'3'!F5 -> 15 | G5: =+E5+F5 -> 15 | H5: =+'31.'!H5+'1'!H5+'2'!H5+'3'!H5 -> 0 | I5: =+'31.'!I5+'1'!I5+'2'!I5+'3'!I5 -> 0 | J5: =E5+F5-H5-K5-I5 -> 0 | K5: =+'31.'!K5+'1'!K5+'2'!K5+'3'!K5 -> 15 | L5: 50 | M5: =+'31.'!M5+'1'!M5+'2'!M5+'3'!M5 -> 750 | O5: 22.48 | P5: =+K5*O5 -> 337.2 | Q5: 31 | R5: =+'31.'!N242 -> 15735 | S5: =+'31.'!N247 -> 1850 | T5: =+'31.'!N245 -> 0 | U5: =+'31.'!N243 -> 0 | V5: =+'31.'!N246 -> 0 | W5: =+'31.'!N244 -> 10370 | X5: =+R5-S5-T5-U5-V5-W5 -> 3515 | Y5: =+'31.'!N249 -> 3273 | Z5: =+Y5-X5 -> -242 | AA5: พฤหัสบดี | AB5: =+W5+Y5 -> 13643 | AC5: =+W5+Y5+Z5 -> 13401
A6: 2 | B6: 8857125001311 | C6: ชิฟฟ่อนเค้ก รวมรส (8 ชิ้น) | D6: กล่อง | E6: =+ยกมา!J6 -> 0 | F6: =+'31.'!F6+'1'!F6+'2'!F6+'3'!F6 -> 15 | G6: =+E6+F6 -> 15 | H6: =+'31.'!H6+'1'!H6+'2'!H6+'3'!H6 -> 0 | I6: =+'31.'!I6+'1'!I6+'2'!I6+'3'!I6 -> 0 | J6: =E6+F6-H6-K6-I6 -> 5 | K6: =+'31.'!K6+'1'!K6+'2'!K6+'3'!K6 -> 10 | L6: 100 | M6: =+'31.'!M6+'1'!M6+'2'!M6+'3'!M6 -> 1000 | O6: 39.29 | P6: =+K6*O6 -> 392.9 | Q6: 1 | R6: =+'1'!N242 -> 0 | S6: =+'1'!N247 -> 0 | T6: =+'1'!N245 -> 0 | U6: =+'1'!N243 -> 0 | V6: =+'1'!N246 -> 0 | W6: =+'1'!N244 -> 0 | X6: =+R6-S6-T6-U6-V6-W6 -> 0 | Y6: =+'1'!N249 -> 0 | Z6: =+Y6-X6 -> 0 | AA6: ศุกร์ | AB6: =+W6+Y6 -> 0 | AC6: =+W6+Y6+Z6 -> 0
A7: 3 | B7: 8857125003841 | C7: ชิฟฟ่อนเค้ก รสกาแฟ (4 ชิ้น) | D7: ชิ้น | E7: =+ยกมา!J7 -> 0 | F7: =+'31.'!F7+'1'!F7+'2'!F7+'3'!F7 -> 5 | G7: =+E7+F7 -> 5 | H7: =+'31.'!H7+'1'!H7+'2'!H7+'3'!H7 -> 0 | I7: =+'31.'!I7+'1'!I7+'2'!I7+'3'!I7 -> 0 | J7: =E7+F7-H7-K7-I7 -> 1 | K7: =+'31.'!K7+'1'!K7+'2'!K7+'3'!K7 -> 4 | L7: 50 | M7: =+'31.'!M7+'1'!M7+'2'!M7+'3'!M7 -> 200 | O7: 26.11 | P7: =+K7*O7 -> 104.44 | Q7: 2 | R7: =+'2'!N242 -> 0 | S7: =+'2'!N247 -> 0 | T7: =+'2'!N245 -> 0 | U7: =+'2'!N243 -> 0 | V7: =+'2'!N246 -> 0 | W7: =+'2'!N244 -> 0 | X7: =+R7-S7-T7-U7-V7-W7 -> 0 | Y7: =+'2'!N249 -> 0 | Z7: =+Y7-X7 -> 0 | AA7: เสาร์ | AB7: =+W7+Y7 -> 0 | AC7: =+W7+Y7+Z7 -> 0
A8: 4 | B8: 8857125003827 | C8: ชิฟฟ่อนเค้ก รสกาแฟ (8 ชิ้น) | D8: กล่อง | E8: =+ยกมา!J8 -> 0 | F8: =+'31.'!F8+'1'!F8+'2'!F8+'3'!F8 -> 0 | G8: =+E8+F8 -> 0 | H8: =+'31.'!H8+'1'!H8+'2'!H8+'3'!H8 -> 0 | I8: =+'31.'!I8+'1'!I8+'2'!I8+'3'!I8 -> 0 | J8: =E8+F8-H8-K8-I8 -> 0 | K8: =+'31.'!K8+'1'!K8+'2'!K8+'3'!K8 -> 0 | L8: 100 | M8: =+'31.'!M8+'1'!M8+'2'!M8+'3'!M8 -> 0 | O8: 33.89 | P8: =+K8*O8 -> 0 | Q8: 3 | R8: =+'3'!N242 -> 0 | S8: =+'3'!N247 -> 0 | T8: =+'3'!N245 -> 0 | U8: =+'3'!N243 -> 0 | V8: =+'3'!N246 -> 0 | W8: =+'3'!N244 -> 0 | X8: =+R8-S8-T8-U8-V8-W8 -> 0 | Y8: =+'3'!N249 -> 0 | Z8: =+Y8-X8 -> 0 | AA8: อาทิตย์ | AB8: =+W8+Y8 -> 0 | AC8: =+W8+Y8+Z8 -> 0
A9: 5 | B9: 8857125002257 | C9: ชิฟฟ่อนเค้ก 1 ชิ้น | D9: ชิ้น | E9: =+ยกมา!J9 -> 0 | F9: =+'31.'!F9+'1'!F9+'2'!F9+'3'!F9 -> 0 | G9: =+E9+F9 -> 0 | H9: =+'31.'!H9+'1'!H9+'2'!H9+'3'!H9 -> 0 | I9: =+'31.'!I9+'1'!I9+'2'!I9+'3'!I9 -> 0 | J9: =E9+F9-H9-K9-I9 -> 0 | K9: =+'31.'!K9+'1'!K9+'2'!K9+'3'!K9 -> 0 | L9: 10 | M9: =+'31.'!M9+'1'!M9+'2'!M9+'3'!M9 -> 0 | P9: =+K9*O9 -> 0 | R9: =SUM(R5:R8) -> 15735 | S9: =SUM(S5:S8) -> 1850 | T9: =SUM(T5:T8) -> 0 | U9: =SUM(U5:U8) -> 0 | V9: =SUM(V5:V8) -> 0 | W9: =SUM(W5:W8) -> 10370 | X9: =SUM(X5:X8) -> 3515 | Y9: =SUM(Y5:Y8) -> 3273 | ... AB9: =SUM(AB5:AB8) -> 13643
A10: 6 | B10: 8857125002264 | C10: ชิฟฟ่อนเค้กสอดไส้แยม 1 ชิ้น | D10: ชิ้น | E10: =+ยกมา!J10 -> 0 | F10: =+'31.'!F10+'1'!F10+'2'!F10+'3'!F10 -> 0 | G10: =+E10+F10 -> 0 | H10: =+'31.'!H10+'1'!H10+'2'!H10+'3'!H10 -> 0 | I10: =+'31.'!I10+'1'!I10+'2'!I10+'3'!I10 -> 0 | J10: =E10+F10-H10-K10-I10 -> 0 | K10: =+'31.'!K10+'1'!K10+'2'!K10+'3'!K10 -> 0 | L10: 15 | M10: =+'31.'!M10+'1'!M10+'2'!M10+'3'!M10 -> 0 | P10: =+K10*O10 -> 0
A11: 7 | B11: 8857125001830 | C11: ชิฟฟ่อนเค้กสอดไส้ รวมรส (3 ชิ้น) | D11: กล่อง | E11: =+ยกมา!J11 -> 0 | F11: =+'31.'!F11+'1'!F11+'2'!F11+'3'!F11 -> 10 | G11: =+E11+F11 -> 10 | H11: =+'31.'!H11+'1'!H11+'2'!H11+'3'!H11 -> 0 | I11: =+'31.'!I11+'1'!I11+'2'!I11+'3'!I11 -> 0 | J11: =E11+F11-H11-K11-I11 -> 4 | K11: =+'31.'!K11+'1'!K11+'2'!K11+'3'!K11 -> 6 | L11: 50 | M11: =+'31.'!M11+'1'!M11+'2'!M11+'3'!M11 -> 300 | O11: 16.94 | P11: =+K11*O11 -> 101.64 | AA11: ขาด
A12: 8 | B12: 1112539 | C12: ชิฟฟ่อนเค้กสอดไส้ เมล่อน (3 ชิ้น) | D12: กล่อง | E12: =+ยกมา!J12 -> 0 | F12: =+'31.'!F12+'1'!F12+'2'!F12+'3'!F12 -> 0 | G12: =+E12+F12 -> 0 | H12: =+'31.'!H12+'1'!H12+'2'!H12+'3'!H12 -> 0 | I12: =+'31.'!I12+'1'!I12+'2'!I12+'3'!I12 -> 0 | J12: =E12+F12-H12-K12-I12 -> 0 | K12: =+'31.'!K12+'1'!K12+'2'!K12+'3'!K12 -> 0 | L12: 50 | M12: =+'31.'!M12+'1'!M12+'2'!M12+'3'!M12 -> 0 | P12: =+K12*O12 -> 0 | R12: 06 | S12: NOTE : | T12: ค่าคอมมิชชั่นพิเศษ วันจันทร์ - ศุกร์ ยอดขายหลังหักค่าใช้จ่ายเกิน 7,000 บาท รับค่าคอมมิชชั่น (พิเศษ) 100 บาท | AA12: =3273-6270 -> -2997
A13: 9 | B13: 8857125000055 | C13: ชิฟฟ่อนเค้กสอดไส้แยม รสบลูเบอร์รี่ (3 ชิ้น) | D13: กล่อง | E13: =+ยกมา!J13 -> 0 | F13: =+'31.'!F13+'1'!F13+'2'!F13+'3'!F13 -> 0 | G13: =+E13+F13 -> 0 | H13: =+'31.'!H13+'1'!H13+'2'!H13+'3'!H13 -> 0 | I13: =+'31.'!I13+'1'!I13+'2'!I13+'3'!I13 -> 0 | J13: =E13+F13-H13-K13-I13 -> 0 | K13: =+'31.'!K13+'1'!K13+'2'!K13+'3'!K13 -> 0 | L13: 50 | M13: =+'31.'!M13+'1'!M13+'2'!M13+'3'!M13 -> 0 | O13: 17.32 | P13: =+K13*O13 -> 0 | T13: ค่าคอมมิชชั่นพิเศษ วันเสาร์ - อาทิตย์ ยอดขายหลังหักค่าใช้จ่ายเกิน 10,000 บาท รับค่าคอมมิชชั่น (พิเศษ) 100 บาท
A14: 10 | B14: 8857125000987 | C14: ชิฟฟ่อนเค้กสอดไส้แยม รสส้ม (3 ชิ้น) | D14: กล่อง | E14: =+ยกมา!J14 -> 0 | F14: =+'31.'!F14+'1'!F14+'2'!F14+'3'!F14 -> 5 | G14: =+E14+F14 -> 5 | H14: =+'31.'!H14+'1'!H14+'2'!H14+'3'!H14 -> 0 | I14: =+'31.'!I14+'1'!I14+'2'!I14+'3'!I14 -> 0 | J14: =E14+F14-H14-K14-I14 -> 2 | K14: =+'31.'!K14+'1'!K14+'2'!K14+'3'!K14 -> 3 | L14: 50 | M14: =+'31.'!M14+'1'!M14+'2'!M14+'3'!M14 -> 150 | O14: 21.22 | P14: =+K14*O14 -> 63.66 | T14: ** วันที่ได้ค่าคอมมิชชั่นพิเศษไฮไลท์ด้วยสีเหลือง
A15: 11 | B15: 8857125000246 | C15: ชิฟฟ่อนเค้กหน้าฝอยทอง สอดไส้แยมส้ม (3 ชิ้น) | D15: กล่อง | E15: =+ยกมา!J15 -> 0 | F15: =+'31.'!F15+'1'!F15+'2'!F15+'3'!F15 -> 0 | G15: =+E15+F15 -> 0 | H15: =+'31.'!H15+'1'!H15+'2'!H15+'3'!H15 -> 0 | I15: =+'31.'!I15+'1'!I15+'2'!I15+'3'!I15 -> 0 | J15: =E15+F15-H15-K15-I15 -> 0 | K15: =+'31.'!K15+'1'!K15+'2'!K15+'3'!K15 -> 0 | L15: 50 | M15: =+'31.'!M15+'1'!M15+'2'!M15+'3'!M15 -> 0 | O15: 24.37 | P15: =+K15*O15 -> 0
A16: 12 | C16: ชิฟฟ่อนเค้กหน้าฝอยทองทูโทน สอดไส้แยมส้ม (3 ชิ้น) | D16: กล่อง | E16: =+ยกมา!J16 -> 0 | F16: =+'31.'!F16+'1'!F16+'2'!F16+'3'!F16 -> 0 | G16: =+E16+F16 -> 0 | H16: =+'31.'!H16+'1'!H16+'2'!H16+'3'!H16 -> 0 | I16: =+'31.'!I16+'1'!I16+'2'!I16+'3'!I16 -> 0 | J16: =E16+F16-H16-K16-I16 -> 0 | K16: =+'31.'!K16+'1'!K16+'2'!K16+'3'!K16 -> 0 | L16: 50 | M16: =+'31.'!M16+'1'!M16+'2'!M16+'3'!M16 -> 0 | P16: =+K16*O16 -> 0
A17: 13 | B17: 8857125000024 | C17: ชิฟฟ่อนเค้กสอดไส้แยม รสสตรอว์เบอรี่ (3 ชิ้น) | D17: กล่อง | E17: =+ยกมา!J17 -> 0 | F17: =+'31.'!F17+'1'!F17+'2'!F17+'3'!F17 -> 0 | G17: =+E17+F17 -> 0 | H17: =+'31.'!H17+'1'!H17+'2'!H17+'3'!H17 -> 0 | I17: =+'31.'!I17+'1'!I17+'2'!I17+'3'!I17 -> 0 | J17: =E17+F17-H17-K17-I17 -> 0 | K17: =+'31.'!K17+'1'!K17+'2'!K17+'3'!K17 -> 0 | L17: 50 | M17: =+'31.'!M17+'1'!M17+'2'!M17+'3'!M17 -> 0 | O17: 15.05 | P17: =+K17*O17 -> 0
A18: 14 | B18: 8857125000086 | C18: ชิฟฟ่อนเค้กสอดไส้ เนยมะพร้าว (3 ชิ้น) | D18: กล่อง | E18: =+ยกมา!J18 -> 0 | F18: =+'31.'!F18+'1'!F18+'2'!F18+'3'!F18 -> 5 | G18: =+E18+F18 -> 5 | H18: =+'31.'!H18+'1'!H18+'2'!H18+'3'!H18 -> 0 | I18: =+'31.'!I18+'1'!I18+'2'!I18+'3'!I18 -> 0 | J18: =E18+F18-H18-K18-I18 -> 4 | K18: =+'31.'!K18+'1'!K18+'2'!K18+'3'!K18 -> 1 | L18: 50 | M18: =+'31.'!M18+'1'!M18+'2'!M18+'3'!M18 -> 50 | O18: 18.77 | P18: =+K18*O18 -> 18.77
A19: 15 | B19: 8857125000239 | C19: ชิฟฟ่อนเค้กสอดไส้ นมชมพูฮอกไกโด (3 ชิ้น) | D19: กล่อง | E19: =+ยกมา!J19 -> 0 | F19: =+'31.'!F19+'1'!F19+'2'!F19+'3'!F19 -> 0 | G19: =+E19+F19 -> 0 | H19: =+'31.'!H19+'1'!H19+'2'!H19+'3'!H19 -> 0 | I19: =+'31.'!I19+'1'!I19+'2'!I19+'3'!I19 -> 0 | J19: =E19+F19-H19-K19-I19 -> 0 | K19: =+'31.'!K19+'1'!K19+'2'!K19+'3'!K19 -> 0 | L19: 50 | M19: =+'31.'!M19+'1'!M19+'2'!M19+'3'!M19 -> 0 | O19: 19.04 | P19: =+K19*O19 -> 0
A20: 16 | B20: 8857125001816 | C20: ชิฟฟ่อน สอดไส้ (ล) 4 ชิ้น ครีมมะพร้าว | D20: กล่อง | E20: =+ยกมา!J20 -> 0 | F20: =+'31.'!F20+'1'!F20+'2'!F20+'3'!F20 -> 5 | G20: =+E20+F20 -> 5 | H20: =+'31.'!H20+'1'!H20+'2'!H20+'3'!H20 -> 0 | I20: =+'31.'!I20+'1'!I20+'2'!I20+'3'!I20 -> 0 | J20: =E20+F20-H20-K20-I20 -> 0 | K20: =+'31.'!K20+'1'!K20+'2'!K20+'3'!K20 -> 5 | L20: 65 | M20: =+'31.'!M20+'1'!M20+'2'!M20+'3'!M20 -> 325 | O20: 22.25 | P20: =+K20*O20 -> 111.25
A21: 17 | B21: 8857125001021 | C21: ชิฟฟ่อน สอดไส้ (ก) 5 ชิ้น ครีมมะพร้าว | D21: กล่อง | E21: =+ยกมา!J21 -> 0 | F21: =+'31.'!F21+'1'!F21+'2'!F21+'3'!F21 -> 0 | G21: =+E21+F21 -> 0 | H21: =+'31.'!H21+'1'!H21+'2'!H21+'3'!H21 -> 0 | I21: =+'31.'!I21+'1'!I21+'2'!I21+'3'!I21 -> 0 | J21: =E21+F21-H21-K21-I21 -> 0 | K21: =+'31.'!K21+'1'!K21+'2'!K21+'3'!K21 -> 0 | L21: 85 | M21: =+'31.'!M21+'1'!M21+'2'!M21+'3'!M21 -> 0 | O21: 22.85 | P21: =+K21*O21 -> 0
A22: 18 | B22: 8857125000956 | C22: ชิฟฟ่อนเค้กสอดไส้ รวมรส (6 ชิ้น) | D22: กล่อง | E22: =+ยกมา!J22 -> 0 | F22: =+'31.'!F22+'1'!F22+'2'!F22+'3'!F22 -> 10 | G22: =+E22+F22 -> 10 | H22: =+'31.'!H22+'1'!H22+'2'!H22+'3'!H22 -> 0 | I22: =+'31.'!I22+'1'!I22+'2'!I22+'3'!I22 -> 0 | J22: =E22+F22-H22-K22-I22 -> 4 | K22: =+'31.'!K22+'1'!K22+'2'!K22+'3'!K22 -> 6 | L22: 100 | M22: =+'31.'!M22+'1'!M22+'2'!M22+'3'!M22 -> 600 | O22: 26.6 | P22: =+K22*O22 -> 159.6
A23: 19 | B23: 8857125000918 | C23: ชิฟฟ่อนเค้กสอดไส้แยม รสส้ม (6 ชิ้น) | D23: กล่อง | E23: =+ยกมา!J23 -> 0 | F23: =+'31.'!F23+'1'!F23+'2'!F23+'3'!F23 -> 0 | G23: =+E23+F23 -> 0 | H23: =+'31.'!H23+'1'!H23+'2'!H23+'3'!H23 -> 0 | I23: =+'31.'!I23+'1'!I23+'2'!I23+'3'!I23 -> 0 | J23: =E23+F23-H23-K23-I23 -> 0 | K23: =+'31.'!K23+'1'!K23+'2'!K23+'3'!K23 -> 0 | L23: 100 | M23: =+'31.'!M23+'1'!M23+'2'!M23+'3'!M23 -> 0 | O23: 42.24 | P23: =+K23*O23 -> 0
A24: 20 | B24: 8857125000970 | C24: ชิฟฟ่อนเค้กหน้าฝอยทอง สอดไส้แยมส้ม (6 ชิ้น) | D24: กล่อง | E24: =+ยกมา!J24 -> 0 | F24: =+'31.'!F24+'1'!F24+'2'!F24+'3'!F24 -> 5 | G24: =+E24+F24 -> 5 | H24: =+'31.'!H24+'1'!H24+'2'!H24+'3'!H24 -> 0 | I24: =+'31.'!I24+'1'!I24+'2'!I24+'3'!I24 -> 0 | J24: =E24+F24-H24-K24-I24 -> 5 | K24: =+'31.'!K24+'1'!K24+'2'!K24+'3'!K24 -> 0 | L24: 100 | M24: =+'31.'!M24+'1'!M24+'2'!M24+'3'!M24 -> 0 | O24: 40.51 | P24: =+K24*O24 -> 0
A25: 21 | B25: 8857125003810 | C25: ชิฟฟ่อนเค้กหน้าฝอยทองทูโทน สอดไส้แยมส้ม (6 ชิ้น) | D25: กล่อง | E25: =+ยกมา!J25 -> 0 | F25: =+'31.'!F25+'1'!F25+'2'!F25+'3'!F25 -> 5 | G25: =+E25+F25 -> 5 | H25: =+'31.'!H25+'1'!H25+'2'!H25+'3'!H25 -> 0 | I25: =+'31.'!I25+'1'!I25+'2'!I25+'3'!I25 -> 0 | J25: =E25+F25-H25-K25-I25 -> 5 | K25: =+'31.'!K25+'1'!K25+'2'!K25+'3'!K25 -> 0 | L25: 100 | M25: =+'31.'!M25+'1'!M25+'2'!M25+'3'!M25 -> 0 | O25: 39.77 | P25: =+K25*O25 -> 0
A26: 22 | B26: 8857125000963 | C26: ชิฟฟ่อนเค้กสอดไส้ นมชมพูฮอกไกโด (6 ชิ้น) | D26: กล่อง | E26: =+ยกมา!J26 -> 0 | F26: =+'31.'!F26+'1'!F26+'2'!F26+'3'!F26 -> 0 | G26: =+E26+F26 -> 0 | H26: =+'31.'!H26+'1'!H26+'2'!H26+'3'!H26 -> 0 | I26: =+'31.'!I26+'1'!I26+'2'!I26+'3'!I26 -> 0 | J26: =E26+F26-H26-K26-I26 -> 0 | K26: =+'31.'!K26+'1'!K26+'2'!K26+'3'!K26 -> 0 | L26: 100 | M26: =+'31.'!M26+'1'!M26+'2'!M26+'3'!M26 -> 0 | O26: 35.39 | P26: =+K26*O26 -> 0
A27: 23 | B27: 8857125000932 | C27: ชิฟฟ่อนเค้กสอดไส้แยม รสบลูเบอร์รี่ (6 ชิ้น) | D27: กล่อง | E27: =+ยกมา!J27 -> 0 | F27: =+'31.'!F27+'1'!F27+'2'!F27+'3'!F27 -> 0 | G27: =+E27+F27 -> 0 | H27: =+'31.'!H27+'1'!H27+'2'!H27+'3'!H27 -> 0 | I27: =+'31.'!I27+'1'!I27+'2'!I27+'3'!I27 -> 0 | J27: =E27+F27-H27-K27-I27 -> 0 | K27: =+'31.'!K27+'1'!K27+'2'!K27+'3'!K27 -> 0 | L27: 100 | M27: =+'31.'!M27+'1'!M27+'2'!M27+'3'!M27 -> 0 | O27: 31.62 | P27: =+K27*O27 -> 0
A28: 24 | B28: 8857125000895 | C28: ชิฟฟ่อนเค้กสอดไส้ เนยมะพร้าว (6 ชิ้น) | D28: กล่อง | E28: =+ยกมา!J28 -> 0 | F28: =+'31.'!F28+'1'!F28+'2'!F28+'3'!F28 -> 5 | G28: =+E28+F28 -> 5 | H28: =+'31.'!H28+'1'!H28+'2'!H28+'3'!H28 -> 0 | I28: =+'31.'!I28+'1'!I28+'2'!I28+'3'!I28 -> 0 | J28: =E28+F28-H28-K28-I28 -> 5 | K28: =+'31.'!K28+'1'!K28+'2'!K28+'3'!K28 -> 0 | L28: 100 | M28: =+'31.'!M28+'1'!M28+'2'!M28+'3'!M28 -> 0 | O28: 31.97 | P28: =+K28*O28 -> 0
A29: 25 | B29: 8857125000901 | C29: ชิฟฟ่อนเค้กสอดไส้แยม รสสตรอว์เบอรี่ (6 ชิ้น) | D29: กล่อง | E29: =+ยกมา!J29 -> 0 | F29: =+'31.'!F29+'1'!F29+'2'!F29+'3'!F29 -> 0 | G29: =+E29+F29 -> 0 | H29: =+'31.'!H29+'1'!H29+'2'!H29+'3'!H29 -> 0 | I29: =+'31.'!I29+'1'!I29+'2'!I29+'3'!I29 -> 0 | J29: =E29+F29-H29-K29-I29 -> 0 | K29: =+'31.'!K29+'1'!K29+'2'!K29+'3'!K29 -> 0 | L29: 100 | M29: =+'31.'!M29+'1'!M29+'2'!M29+'3'!M29 -> 0 | O29: 21.27 | P29: =+K29*O29 -> 0
A30: 26 | B30: 8857125001571 | C30: ชิฟฟอนเค้ก รสมะลิ 8ชิ้น (ห่อซีน) | D30: กล่อง | E30: =+ยกมา!J30 -> 0 | F30: =+'31.'!F30+'1'!F30+'2'!F30+'3'!F30 -> 0 | G30: =+E30+F30 -> 0 | H30: =+'31.'!H30+'1'!H30+'2'!H30+'3'!H30 -> 0 | I30: =+'31.'!I30+'1'!I30+'2'!I30+'3'!I30 -> 0 | J30: =E30+F30-H30-K30-I30 -> 0 | K30: =+'31.'!K30+'1'!K30+'2'!K30+'3'!K30 -> 0 | L30: 100 | M30: =+'31.'!M30+'1'!M30+'2'!M30+'3'!M30 -> 0 | O30: 34.26 | P30: =+K30*O30 -> 0
A31: 27 | B31: 8857125002127 | C31: ชิฟฟ่อนรวมรส ยอดฮิต (8 ชิ้น) | D31: กล่อง | E31: =+ยกมา!J31 -> 0 | F31: =+'31.'!F31+'1'!F31+'2'!F31+'3'!F31 -> 10 | G31: =+E31+F31 -> 10 | H31: =+'31.'!H31+'1'!H31+'2'!H31+'3'!H31 -> 0 | I31: =+'31.'!I31+'1'!I31+'2'!I31+'3'!I31 -> 0 | J31: =E31+F31-H31-K31-I31 -> 4 | K31: =+'31.'!K31+'1'!K31+'2'!K31+'3'!K31 -> 6 | L31: 100 | M31: =+'31.'!M31+'1'!M31+'2'!M31+'3'!M31 -> 600 | O31: 38.46 | P31: =+K31*O31 -> 230.76
A32: 28 | B32: 8857125000130 | C32: ชิฟฟ่อนเค้ก วรรณวนัช (สอดไส้รวมรส 8 ชิ้น) | D32: กล่อง | E32: =+ยกมา!J32 -> 0 | F32: =+'31.'!F32+'1'!F32+'2'!F32+'3'!F32 -> 0 | G32: =+E32+F32 -> 0 | H32: =+'31.'!H32+'1'!H32+'2'!H32+'3'!H32 -> 0 | I32: =+'31.'!I32+'1'!I32+'2'!I32+'3'!I32 -> 0 | J32: =E32+F32-H32-K32-I32 -> 0 | K32: =+'31.'!K32+'1'!K32+'2'!K32+'3'!K32 -> 0 | L32: 130 | M32: =+'31.'!M32+'1'!M32+'2'!M32+'3'!M32 -> 0 | O32: 46.37 | P32: =+K32*O32 -> 0
A33: 29 | B33: 8857125003773 | C33: ชิฟฟ่อนเค้กมะพร้าวสอดไส้ครีมมะพร้าวล้วน (8 ชิ้น) | D33: กล่อง | E33: =+ยกมา!J33 -> 0 | F33: =+'31.'!F33+'1'!F33+'2'!F33+'3'!F33 -> 0 | G33: =+E33+F33 -> 0 | H33: =+'31.'!H33+'1'!H33+'2'!H33+'3'!H33 -> 0 | I33: =+'31.'!I33+'1'!I33+'2'!I33+'3'!I33 -> 0 | J33: =E33+F33-H33-K33-I33 -> 0 | K33: =+'31.'!K33+'1'!K33+'2'!K33+'3'!K33 -> 0 | L33: 130 | M33: =+'31.'!M33+'1'!M33+'2'!M33+'3'!M33 -> 0 | O33: 38.9 | P33: =+K33*O33 -> 0
A34: 30 | B34: 8857125001366 | C34: ชิฟฟ่อนเค้กใบเตยสอดไส้ครีมมะพร้าวล้วน (8 ชิ้น) | D34: กล่อง | E34: =+ยกมา!J34 -> 0 | F34: =+'31.'!F34+'1'!F34+'2'!F34+'3'!F34 -> 0 | G34: =+E34+F34 -> 0 | H34: =+'31.'!H34+'1'!H34+'2'!H34+'3'!H34 -> 0 | I34: =+'31.'!I34+'1'!I34+'2'!I34+'3'!I34 -> 0 | J34: =E34+F34-H34-K34-I34 -> 0 | K34: =+'31.'!K34+'1'!K34+'2'!K34+'3'!K34 -> 0 | L34: 130 | M34: =+'31.'!M34+'1'!M34+'2'!M34+'3'!M34 -> 0 | O34: 38.07 | P34: =+K34*O34 -> 0
A35: 31 | B35: 8857125001397 | C35: ชิฟฟ่อนเค้กใบเตยทูโทนและสอดไส้ครีมมะพร้าว (8 ชิ้น) | D35: กล่อง | E35: =+ยกมา!J35 -> 0 | F35: =+'31.'!F35+'1'!F35+'2'!F35+'3'!F35 -> 0 | G35: =+E35+F35 -> 0 | H35: =+'31.'!H35+'1'!H35+'2'!H35+'3'!H35 -> 0 | I35: =+'31.'!I35+'1'!I35+'2'!I35+'3'!I35 -> 0 | J35: =E35+F35-H35-K35-I35 -> 0 | K35: =+'31.'!K35+'1'!K35+'2'!K35+'3'!K35 -> 0 | L35: 130 | M35: =+'31.'!M35+'1'!M35+'2'!M35+'3'!M35 -> 0 | O35: 40.8 | P35: =+K35*O35 -> 0
A36: 32 | B36: 885712004534 | C36: ชิฟฟ่อนเค้กสอดไส้ครีมมะพร้าว 120g. | D36: ชิ้น | E36: =+ยกมา!J36 -> 0 | F36: =+'31.'!F36+'1'!F36+'2'!F36+'3'!F36 -> 0 | G36: =+E36+F36 -> 0 | H36: =+'31.'!H36+'1'!H36+'2'!H36+'3'!H36 -> 0 | I36: =+'31.'!I36+'1'!I36+'2'!I36+'3'!I36 -> 0 | J36: =E36+F36-H36-K36-I36 -> 0 | K36: =+'31.'!K36+'1'!K36+'2'!K36+'3'!K36 -> 0 | L36: 35 | M36: =+'31.'!M36+'1'!M36+'2'!M36+'3'!M36 -> 0 | P36: =+K36*O36 -> 0
A37: 33 | B37: 20055119 | C37: ชิฟฟ่อนเค้กฝอยทอง 95g. | D37: กล่อง | E37: =+ยกมา!J37 -> 0 | F37: =+'31.'!F37+'1'!F37+'2'!F37+'3'!F37 -> 0 | G37: =+E37+F37 -> 0 | H37: =+'31.'!H37+'1'!H37+'2'!H37+'3'!H37 -> 0 | I37: =+'31.'!I37+'1'!I37+'2'!I37+'3'!I37 -> 0 | J37: =E37+F37-H37-K37-I37 -> 0 | K37: =+'31.'!K37+'1'!K37+'2'!K37+'3'!K37 -> 0 | L37: 35 | M37: =+'31.'!M37+'1'!M37+'2'!M37+'3'!M37 -> 0 | P37: =+K37*O37 -> 0
A38: 34 | C38: ชิฟฟ่อนหม้อแกง | D38: กล่อง | E38: =+ยกมา!J38 -> 0 | F38: =+'31.'!F38+'1'!F38+'2'!F38+'3'!F38 -> 0 | G38: =+E38+F38 -> 0 | H38: =+'31.'!H38+'1'!H38+'2'!H38+'3'!H38 -> 0 | I38: =+'31.'!I38+'1'!I38+'2'!I38+'3'!I38 -> 0 | J38: =E38+F38-H38-K38-I38 -> 0 | K38: =+'31.'!K38+'1'!K38+'2'!K38+'3'!K38 -> 0 | L38: 35 | M38: =+'31.'!M38+'1'!M38+'2'!M38+'3'!M38 -> 0 | P38: =+K38*O38 -> 0
A39: 35 | B39: 8857125000611 | C39: ครีมฮอร์น วนิลา | D39: กล่อง | E39: =+ยกมา!J39 -> 0 | F39: =+'31.'!F39+'1'!F39+'2'!F39+'3'!F39 -> 5 | G39: =+E39+F39 -> 5 | H39: =+'31.'!H39+'1'!H39+'2'!H39+'3'!H39 -> 3 | I39: =+'31.'!I39+'1'!I39+'2'!I39+'3'!I39 -> 0 | J39: =E39+F39-H39-K39-I39 -> 0 | K39: =+'31.'!K39+'1'!K39+'2'!K39+'3'!K39 -> 2 | L39: 50 | M39: =+'31.'!M39+'1'!M39+'2'!M39+'3'!M39 -> 100 | O39: 27.84 | P39: =+K39*O39 -> 55.68
A40: 36 | B40: 8857125000604 | C40: ครีมฮอร์น ใบเตย | D40: กล่อง | E40: =+ยกมา!J40 -> 0 | F40: =+'31.'!F40+'1'!F40+'2'!F40+'3'!F40 -> 5 | G40: =+E40+F40 -> 5 | H40: =+'31.'!H40+'1'!H40+'2'!H40+'3'!H40 -> 4 | I40: =+'31.'!I40+'1'!I40+'2'!I40+'3'!I40 -> 0 | J40: =E40+F40-H40-K40-I40 -> 0 | K40: =+'31.'!K40+'1'!K40+'2'!K40+'3'!K40 -> 1 | L40: 50 | M40: =+'31.'!M40+'1'!M40+'2'!M40+'3'!M40 -> 50 | O40: 27.12 | P40: =+K40*O40 -> 27.12
A41: 37 | B41: 8857125000598 | C41: ครีมฮอร์น ช็อคโกแลต | D41: กล่อง | E41: =+ยกมา!J41 -> 0 | F41: =+'31.'!F41+'1'!F41+'2'!F41+'3'!F41 -> 5 | G41: =+E41+F41 -> 5 | H41: =+'31.'!H41+'1'!H41+'2'!H41+'3'!H41 -> 4 | I41: =+'31.'!I41+'1'!I41+'2'!I41+'3'!I41 -> 0 | J41: =E41+F41-H41-K41-I41 -> 0 | K41: =+'31.'!K41+'1'!K41+'2'!K41+'3'!K41 -> 1 | L41: 50 | M41: =+'31.'!M41+'1'!M41+'2'!M41+'3'!M41 -> 50 | O41: 15.42 | P41: =+K41*O41 -> 15.42
...

Sheet ยกมา
A2: บูธ EVENT MakroHoReCa17 31 ต.ค. 67 -4 พ.ย. 67
A3: ลำดับ | B3: รหัสสินค้า (POS) | C3: รายการ | D3: หน่วย | E3: ยกมา | F3: รับ | G3: รวม | H3: เปลี่ยน/ | I3: โยกย้าย / ระบาย | J3: คงเหลือ | K3: รายการขาย | N3: หมายเหตุ | O3: ส่วนลด | Q3: ราคาต้นทุน | R3: ยอดรวมต้นทุนสินค้า
H4: คืน/เสีย | K4: จำนวน | L4: @ | M4: เป็นเงิน
A5: 1 | B5: 8857125001328 | C5: ชิฟฟ่อนเค้ก รวมรส (4 ชิ้น) | D5: กล่อง | F5: 0 | G5: =E5+F5 -> 0 | H5: 0 | I5: 0 | J5: =+G5-H5-K5-I5 -> 0 | L5: 50 | M5: =+L5*K5 -> 0 | N5: - | P5: =SUM(M5-O5) -> 0 | Q5: 22.48 | R5: =+K5*Q5 -> 0
A6: 2 | B6: 8857125001311 | C6: ชิฟฟ่อนเค้ก รวมรส (8 ชิ้น) | D6: กล่อง | F6: 0 | G6: =E6+F6 -> 0 | H6: 0 | I6: 0 | J6: =+G6-H6-K6-I6 -> 0 | L6: 100 | M6: =+L6*K6 -> 0 | N6: - | P6: =SUM(M6-O6) -> 0 | Q6: 39.29 | R6: =+K6*Q6 -> 0
A7: 3 | B7: 8857125003841 | C7: ชิฟฟ่อนเค้ก รสกาแฟ (4 ชิ้น) | D7: ชิ้น | F7: 0 | G7: =E7+F7 -> 0 | H7: 0 | I7: 0 | J7: =+G7-H7-K7-I7 -> 0 | L7: 50 | M7: =+L7*K7 -> 0 | N7: - | P7: =SUM(M7-O7) -> 0 | Q7: 26.11 | R7: =+K7*Q7 -> 0
A8: 4 | B8: 8857125003827 | C8: ชิฟฟ่อนเค้ก รสกาแฟ (8 ชิ้น) | D8: กล่อง | F8: 0 | G8: =E8+F8 -> 0 | H8: 0 | I8: 0 | J8: =+G8-H8-K8-I8 -> 0 | L8: 100 | M8: =+L8*K8 -> 0 | N8: - | P8: =SUM(M8-O8) -> 0 | Q8: 33.89 | R8: =+K8*Q8 -> 0
A9: 5 | B9: 8857125002257 | C9: ชิฟฟ่อนเค้ก 1 ชิ้น | D9: ชิ้น | F9: 0 | G9: =E9+F9 -> 0 | H9: 0 | I9: 0 | J9: =+G9-H9-K9-I9 -> 0 | L9: 10 | M9: =+L9*K9 -> 0 | N9: - | P9: =SUM(M9-O9) -> 0 | R9: =+K9*Q9 -> 0
A10: 6 | B10: 8857125002264 | C10: ชิฟฟ่อนเค้กสอดไส้แยม 1 ชิ้น | D10: ชิ้น | F10: 0 | G10: =E10+F10 -> 0 | H10: 0 | I10: 0 | J10: =+G10-H10-K10-I10 -> 0 | L10: 15 | M10: =+L10*K10 -> 0 | N10: - | P10: =SUM(M10-O10) -> 0 | R10: =+K10*Q10 -> 0
A11: 7 | B11: 8857125001830 | C11: ชิฟฟ่อนเค้กสอดไส้ รวมรส (3 ชิ้น) | D11: กล่อง | F11: 0 | G11: =E11+F11 -> 0 | H11: 0 | I11: 0 | J11: =+G11-H11-K11-I11 -> 0 | L11: 50 | M11: =+L11*K11 -> 0 | N11: - | P11: =SUM(M11-O11) -> 0 | Q11: 16.94 | R11: =+K11*Q11 -> 0
A12: 8 | B12: 1112539 | C12: ชิฟฟ่อนเค้กสอดไส้ เมล่อน (3 ชิ้น) | D12: กล่อง | F12: 0 | G12: =E12+F12 -> 0 | H12: 0 | I12: 0 | J12: =+G12-H12-K12-I12 -> 0 | L12: 50 | M12: =+L12*K12 -> 0 | N12: - | P12: =SUM(M12-O12) -> 0 | R12: =+K12*Q12 -> 0
A13: 9 | B13: 8857125000055 | C13: ชิฟฟ่อนเค้กสอดไส้แยม รสบลูเบอร์รี่ (3 ชิ้น) | D13: กล่อง | F13: 0 | G13: =E13+F13 -> 0 | H13: 0 | I13: 0 | J13: =+G13-H13-K13-I13 -> 0 | L13: 50 | M13: =+L13*K13 -> 0 | N13: - | P13: =SUM(M13-O13) -> 0 | Q13: 17.32 | R13: =+K13*Q13 -> 0
A14: 10 | B14: 8857125000987 | C14: ชิฟฟ่อนเค้กสอดไส้แยม รสส้ม (3 ชิ้น) | D14: กล่อง | F14: 0 | G14: =E14+F14 -> 0 | H14: 0 | I14: 0 | J14: =+G14-H14-K14-I14 -> 0 | L14: 50 | M14: =+L14*K14 -> 0 | N14: - | P14: =SUM(M14-O14) -> 0 | Q14: 21.22 | R14: =+K14*Q14 -> 0
A15: 11 | B15: 8857125000246 | C15: ชิฟฟ่อนเค้กหน้าฝอยทอง สอดไส้แยมส้ม (3 ชิ้น) | D15: กล่อง | F15: 0 | G15: =E15+F15 -> 0 | H15: 0 | I15: 0 | J15: =+G15-H15-K15-I15 -> 0 | L15: 50 | M15: =+L15*K15 -> 0 | N15: - | P15: =SUM(M15-O15) -> 0 | Q15: 24.37 | R15: =+K15*Q15 -> 0
A16: 12 | C16: ชิฟฟ่อนเค้กหน้าฝอยทองทูโทน สอดไส้แยมส้ม (3 ชิ้น) | D16: กล่อง | F16: 0 | G16: =E16+F16 -> 0 | H16: 0 | I16: 0 | J16: =+G16-H16-K16-I16 -> 0 | L16: 50 | M16: =+L16*K16 -> 0 | N16: - | P16: =SUM(M16-O16) -> 0 | R16: =+K16*Q16 -> 0
A17: 13 | B17: 8857125000024 | C17: ชิฟฟ่อนเค้กสอดไส้แยม รสสตรอว์เบอรี่ (3 ชิ้น) | D17: กล่อง | F17: 0 | G17: =E17+F17 -> 0 | H17: 0 | I17: 0 | J17: =+G17-H17-K17-I17 -> 0 | L17: 50 | M17: =+L17*K17 -> 0 | N17: - | P17: =SUM(M17-O17) -> 0 | Q17: 15.05 | R17: =+K17*Q17 -> 0
A18: 14 | B18: 8857125000086 | C18: ชิฟฟ่อนเค้กสอดไส้ เนยมะพร้าว (3 ชิ้น) | D18: กล่อง | F18: 0 | G18: =E18+F18 -> 0 | H18: 0 | I18: 0 | J18: =+G18-H18-K18-I18 -> 0 | L18: 50 | M18: =+L18*K18 -> 0 | N18: - | P18: =SUM(M18-O18) -> 0 | Q18: 18.77 | R18: =+K18*Q18 -> 0
A19: 15 | B19: 8857125000239 | C19: ชิฟฟ่อนเค้กสอดไส้ นมชมพูฮอกไกโด (3 ชิ้น) | D19: กล่อง | F19: 0 | G19: =E19+F19 -> 0 | H19: 0 | I19: 0 | J19: =+G19-H19-K19-I19 -> 0 | L19: 50 | M19: =+L19*K19 -> 0 | N19: - | P19: =SUM(M19-O19) -> 0 | Q19: 19.04 | R19: =+K19*Q19 -> 0
A20: 16 | B20: 8857125001816 | C20: ชิฟฟ่อน สอดไส้ (ล) 4 ชิ้น ครีมมะพร้าว | D20: กล่อง | F20: 0 | G20: =E20+F20 -> 0 | H20: 0 | I20: 0 | J20: =+G20-H20-K20-I20 -> 0 | L20: 65 | M20: =+L20*K20 -> 0 | N20: - | P20: =SUM(M20-O20) -> 0 | Q20: 22.25 | R20: =+K20*Q20 -> 0
A21: 17 | B21: 8857125001021 | C21: ชิฟฟ่อน สอดไส้ (ก) 5 ชิ้น ครีมมะพร้าว | D21: กล่อง | F21: 0 | G21: =E21+F21 -> 0 | H21: 0 | I21: 0 | J21: =+G21-H21-K21-I21 -> 0 | L21: 85 | M21: =+L21*K21 -> 0 | N21: - | P21: =SUM(M21-O21) -> 0 | Q21: 22.85 | R21: =+K21*Q21 -> 0
A22: 18 | B22: 8857125000956 | C22: ชิฟฟ่อนเค้กสอดไส้ รวมรส (6 ชิ้น) | D22: กล่อง | F22: 0 | G22: =E22+F22 -> 0 | H22: 0 | I22: 0 | J22: =+G22-H22-K22-I22 -> 0 | L22: 100 | M22: =+L22*K22 -> 0 | N22: - | P22: =SUM(M22-O22) -> 0 | Q22: 26.6 | R22: =+K22*Q22 -> 0
A23: 19 | B23: 8857125000918 | C23: ชิฟฟ่อนเค้กสอดไส้แยม รสส้ม (6 ชิ้น) | D23: กล่อง | F23: 0 | G23: =E23+F23 -> 0 | H23: 0 | I23: 0 | J23: =+G23-H23-K23-I23 -> 0 | L23: 100 | M23: =+L23*K23 -> 0 | N23: - | P23: =SUM(M23-O23) -> 0 | Q23: 42.24 | R23: =+K23*Q23 -> 0
A24: 20 | B24: 8857125000970 | C24: ชิฟฟ่อนเค้กหน้าฝอยทอง สอดไส้แยมส้ม (6 ชิ้น) | D24: กล่อง | F24: 0 | G24: =E24+F24 -> 0 | H24: 0 | I24: 0 | J24: =+G24-H24-K24-I24 -> 0 | L24: 100 | M24: =+L24*K24 -> 0 | N24: - | P24: =SUM(M24-O24) -> 0 | Q24: 40.51 | R24: =+K24*Q24 -> 0
A25: 21 | B25: 8857125003810 | C25: ชิฟฟ่อนเค้กหน้าฝอยทองทูโทน สอดไส้แยมส้ม (6 ชิ้น) | D25: กล่อง | F25: 0 | G25: =E25+F25 -> 0 | H25: 0 | I25: 0 | J25: =+G25-H25-K25-I25 -> 0 | L25: 100 | M25: =+L25*K25 -> 0 | N25: - | P25: =SUM(M25-O25) -> 0 | Q25: 39.77 | R25: =+K25*Q25 -> 0
A26: 22 | B26: 8857125000963 | C26: ชิฟฟ่อนเค้กสอดไส้ นมชมพูฮอกไกโด (6 ชิ้น) | D26: กล่อง | F26: 0 | G26: =E26+F26 -> 0 | H26: 0 | I26: 0 | J26: =+G26-H26-K26-I26 -> 0 | L26: 100 | M26: =+L26*K26 -> 0 | N26: - | P26: =SUM(M26-O26) -> 0 | Q26: 35.39 | R26: =+K26*Q26 -> 0
A27: 23 | B27: 8857125000932 | C27: ชิฟฟ่อนเค้กสอดไส้แยม รสบลูเบอร์รี่ (6 ชิ้น) | D27: กล่อง | F27: 0 | G27: =E27+F27 -> 0 | H27: 0 | I27: 0 | J27: =+G27-H27-K27-I27 -> 0 | L27: 100 | M27: =+L27*K27 -> 0 | N27: - | P27: =SUM(M27-O27) -> 0 | Q27: 31.62 | R27: =+K27*Q27 -> 0
A28: 24 | B28: 8857125000895 | C28: ชิฟฟ่อนเค้กสอดไส้ เนยมะพร้าว (6 ชิ้น) | D28: กล่อง | F28: 0 | G28: =E28+F28 -> 0 | H28: 0 | I28: 0 | J28: =+G28-H28-K28-I28 -> 0 | L28: 100 | M28: =+L28*K28 -> 0 | N28: - | P28: =SUM(M28-O28) -> 0 | Q28: 31.97 | R28: =+K28*Q28 -> 0
A29: 25 | B29: 8857125000901 | C29: ชิฟฟ่อนเค้กสอดไส้แยม รสสตรอว์เบอรี่ (6 ชิ้น) | D29: กล่อง | F29: 0 | G29: =E29+F29 -> 0 | H29: 0 | I29: 0 | J29: =+G29-H29-K29-I29 -> 0 | L29: 100 | M29: =+L29*K29 -> 0 | N29: - | P29: =SUM(M29-O29) -> 0 | Q29: 21.27 | R29: =+K29*Q29 -> 0
A30: 26 | B30: 8857125001571 | C30: ชิฟฟอนเค้ก รสมะลิ 8ชิ้น (ห่อซีน) | D30: กล่อง | F30: 0 | G30: =E30+F30 -> 0 | H30: 0 | I30: 0 | J30: =+G30-H30-K30-I30 -> 0 | L30: 100 | M30: =+L30*K30 -> 0 | N30: - | P30: =SUM(M30-O30) -> 0 | Q30: 34.26 | R30: =+K30*Q30 -> 0
A31: 27 | B31: 8857125002127 | C31: ชิฟฟ่อนรวมรส ยอดฮิต (8 ชิ้น) | D31: กล่อง | F31: 0 | G31: =E31+F31 -> 0 | H31: 0 | I31: 0 | J31: =+G31-H31-K31-I31 -> 0 | L31: 100 | M31: =+L31*K31 -> 0 | N31: - | P31: =SUM(M31-O31) -> 0 | Q31: 38.46 | R31: =+K31*Q31 -> 0
A32: 28 | B32: 8857125000130 | C32: ชิฟฟ่อนเค้ก วรรณวนัช (สอดไส้รวมรส 8 ชิ้น) | D32: กล่อง | F32: 0 | G32: =E32+F32 -> 0 | H32: 0 | I32: 0 | J32: =+G32-H32-K32-I32 -> 0 | L32: 130 | M32: =+L32*K32 -> 0 | N32: - | P32: =SUM(M32-O32) -> 0 | Q32: 46.37 | R32: =+K32*Q32 -> 0
A33: 29 | B33: 8857125003773 | C33: ชิฟฟ่อนเค้กมะพร้าวสอดไส้ครีมมะพร้าวล้วน (8 ชิ้น) | D33: กล่อง | F33: 0 | G33: =E33+F33 -> 0 | H33: 0 | I33: 0 | J33: =+G33-H33-K33-I33 -> 0 | L33: 130 | M33: =+L33*K33 -> 0 | N33: - | P33: =SUM(M33-O33) -> 0 | Q33: 38.9 | R33: =+K33*Q33 -> 0
A34: 30 | B34: 8857125001366 | C34: ชิฟฟ่อนเค้กใบเตยสอดไส้ครีมมะพร้าวล้วน (8 ชิ้น) | D34: กล่อง | F34: 0 | G34: =E34+F34 -> 0 | H34: 0 | I34: 0 | J34: =+G34-H34-K34-I34 -> 0 | L34: 130 | M34: =+L34*K34 -> 0 | N34: - | P34: =SUM(M34-O34) -> 0 | Q34: 38.07 | R34: =+K34*Q34 -> 0
A35: 31 | B35: 8857125001397 | C35: ชิฟฟ่อนเค้กใบเตยทูโทนและสอดไส้ครีมมะพร้าว (8 ชิ้น) | D35: กล่อง | F35: 0 | G35: =E35+F35 -> 0 | H35: 0 | I35: 0 | J35: =+G35-H35-K35-I35 -> 0 | L35: 130 | M35: =+L35*K35 -> 0 | N35: - | P35: =SUM(M35-O35) -> 0 | Q35: 40.8 | R35: =+K35*Q35 -> 0
A36: 32 | B36: 885712004534 | C36: ชิฟฟ่อนเค้กสอดไส้ครีมมะพร้าว 120g. | D36: ชิ้น | F36: 0 | G36: =E36+F36 -> 0 | H36: 0 | I36: 0 | J36: =+G36-H36-K36-I36 -> 0 | L36: 35 | M36: =+L36*K36 -> 0 | N36: - | P36: =SUM(M36-O36) -> 0 | R36: =+K36*Q36 -> 0
A37: 33 | B37: 20055119 | C37: ชิฟฟ่อนเค้กฝอยทอง 95g. | D37: กล่อง | F37: 0 | G37: =E37+F37 -> 0 | H37: 0 | I37: 0 | J37: =+G37-H37-K37-I37 -> 0 | L37: 35 | M37: =+L37*K37 -> 0 | N37: - | P37: =SUM(M37-O37) -> 0 | R37: =+K37*Q37 -> 0
A38: 34 | C38: ชิฟฟ่อนหม้อแกง | D38: กล่อง | F38: 0 | G38: =E38+F38 -> 0 | H38: 0 | I38: 0 | J38: =+G38-H38-K38-I38 -> 0 | L38: 35 | M38: =+L38*K38 -> 0 | N38: - | P38: =SUM(M38-O38) -> 0 | R38: =+K38*Q38 -> 0
A39: 35 | B39: 8857125000611 | C39: ครีมฮอร์น วนิลา | D39: กล่อง | F39: 0 | G39: =E39+F39 -> 0 | H39: 0 | I39: 0 | J39: =+G39-H39-K39-I39 -> 0 | L39: 50 | M39: =+L39*K39 -> 0 | N39: - | P39: =SUM(M39-O39) -> 0 | Q39: 27.84 | R39: =+K39*Q39 -> 0
A40: 36 | B40: 8857125000604 | C40: ครีมฮอร์น ใบเตย | D40: กล่อง | F40: 0 | G40: =E40+F40 -> 0 | H40: 0 | I40: 0 | J40: =+G40-H40-K40-I40 -> 0 | L40: 50 | M40: =+L40*K40 -> 0 | N40: - | P40: =SUM(M40-O40) -> 0 | Q40: 27.12 | R40: =+K40*Q40 -> 0
A41: 37 | B41: 8857125000598 | C41: ครีมฮอร์น ช็อคโกแลต | D41: กล่อง | F41: 0 | G41: =E41+F41 -> 0 | H41: 0 | I41: 0 | J41: =+G41-H41-K41-I41 -> 0 | L41: 50 | M41: =+L41*K41 -> 0 | N41: - | P41: =SUM(M41-O41) -> 0 | Q41: 15.42 | R41: =+K41*Q41 -> 0
...

Sheet 31.
A2: บูธ EVENT MakroHoReCa17 31 ต.ค. 67 -4 พ.ย. 67
A3: ลำดับ | B3: รหัสสินค้า (POS) | C3: รายการ | D3: หน่วย | E3: ยกมา | F3: รับ | G3: รวม | H3: เปลี่ยน/ | I3: โยกย้าย / ระบาย | J3: คงเหลือ | K3: รายการขาย | N3: หมายเหตุ | O3: ส่วนลด | Q3: ราคาต้นทุน | R3: ยอดรวมต้นทุนสินค้า
H4: คืน/เสีย | K4: จำนวน | L4: @ | M4: เป็นเงิน
A5: 1 | B5: 8857125001328 | C5: ชิฟฟ่อนเค้ก รวมรส (4 ชิ้น) | D5: กล่อง | E5: =+ยกมา!J5 -> 0 | F5: 15 | G5: =E5+F5 -> 15 | H5: 0 | I5: 0 | J5: =+G5-H5-K5-I5 -> 0 | K5: 15 | L5: 50 | M5: =+L5*K5 -> 750 | N5: - | P5: =SUM(M5-O5) -> 750 | Q5: 22.48 | R5: =+K5*Q5 -> 337.2
A6: 2 | B6: 8857125001311 | C6: ชิฟฟ่อนเค้ก รวมรส (8 ชิ้น) | D6: กล่อง | E6: =+ยกมา!J6 -> 0 | F6: 15 | G6: =E6+F6 -> 15 | H6: 0 | I6: 0 | J6: =+G6-H6-K6-I6 -> 5 | K6: 10 | L6: 100 | M6: =+L6*K6 -> 1000 | N6: ของรางวัล 3 , ลดราคา 6 | O6: 400 | P6: =SUM(M6-O6) -> 600 | Q6: 39.29 | R6: =+K6*Q6 -> 392.9
A7: 3 | B7: 8857125003841 | C7: ชิฟฟ่อนเค้ก รสกาแฟ (4 ชิ้น) | D7: ชิ้น | E7: =+ยกมา!J7 -> 0 | F7: 5 | G7: =E7+F7 -> 5 | H7: 0 | I7: 0 | J7: =+G7-H7-K7-I7 -> 1 | K7: 4 | L7: 50 | M7: =+L7*K7 -> 200 | N7: - | P7: =SUM(M7-O7) -> 200 | Q7: 26.11 | R7: =+K7*Q7 -> 104.44
A8: 4 | B8: 8857125003827 | C8: ชิฟฟ่อนเค้ก รสกาแฟ (8 ชิ้น) | D8: กล่อง | E8: =+ยกมา!J8 -> 0 | F8: 0 | G8: =E8+F8 -> 0 | H8: 0 | I8: 0 | J8: =+G8-H8-K8-I8 -> 0 | L8: 100 | M8: =+L8*K8 -> 0 | N8: - | P8: =SUM(M8-O8) -> 0 | Q8: 33.89 | R8: =+K8*Q8 -> 0
A9: 5 | B9: 8857125002257 | C9: ชิฟฟ่อนเค้ก 1 ชิ้น | D9: ชิ้น | E9: =+ยกมา!J9 -> 0 | F9: 0 | G9: =E9+F9 -> 0 | H9: 0 | I9: 0 | J9: =+G9-H9-K9-I9 -> 0 | L9: 10 | M9: =+L9*K9 -> 0 | N9: - | P9: =SUM(M9-O9) -> 0 | R9: =+K9*Q9 -> 0
A10: 6 | B10: 8857125002264 | C10: ชิฟฟ่อนเค้กสอดไส้แยม 1 ชิ้น | D10: ชิ้น | E10: =+ยกมา!J10 -> 0 | F10: 0 | G10: =E10+F10 -> 0 | H10: 0 | I10: 0 | J10: =+G10-H10-K10-I10 -> 0 | L10: 15 | M10: =+L10*K10 -> 0 | N10: - | P10: =SUM(M10-O10) -> 0 | R10: =+K10*Q10 -> 0
A11: 7 | B11: 8857125001830 | C11: ชิฟฟ่อนเค้กสอดไส้ รวมรส (3 ชิ้น) | D11: กล่อง | E11: =+ยกมา!J11 -> 0 | F11: 10 | G11: =E11+F11 -> 10 | H11: 0 | I11: 0 | J11: =+G11-H11-K11-I11 -> 4 | K11: 6 | L11: 50 | M11: =+L11*K11 -> 300 | N11: - | P11: =SUM(M11-O11) -> 300 | Q11: 16.94 | R11: =+K11*Q11 -> 101.64
A12: 8 | B12: 1112539 | C12: ชิฟฟ่อนเค้กสอดไส้ เมล่อน (3 ชิ้น) | D12: กล่อง | E12: =+ยกมา!J12 -> 0 | F12: 0 | G12: =E12+F12 -> 0 | H12: 0 | I12: 0 | J12: =+G12-H12-K12-I12 -> 0 | L12: 50 | M12: =+L12*K12 -> 0 | N12: - | P12: =SUM(M12-O12) -> 0 | R12: =+K12*Q12 -> 0
A13: 9 | B13: 8857125000055 | C13: ชิฟฟ่อนเค้กสอดไส้แยม รสบลูเบอร์รี่ (3 ชิ้น) | D13: กล่อง | E13: =+ยกมา!J13 -> 0 | F13: 0 | G13: =E13+F13 -> 0 | H13: 0 | I13: 0 | J13: =+G13-H13-K13-I13 -> 0 | L13: 50 | M13: =+L13*K13 -> 0 | N13: - | P13: =SUM(M13-O13) -> 0 | Q13: 17.32 | R13: =+K13*Q13 -> 0
A14: 10 | B14: 8857125000987 | C14: ชิฟฟ่อนเค้กสอดไส้แยม รสส้ม (3 ชิ้น) | D14: กล่อง | E14: =+ยกมา!J14 -> 0 | F14: 5 | G14: =E14+F14 -> 5 | H14: 0 | I14: 0 | J14: =+G14-H14-K14-I14 -> 2 | K14: 3 | L14: 50 | M14: =+L14*K14 -> 150 | N14: - | P14: =SUM(M14-O14) -> 150 | Q14: 21.22 | R14: =+K14*Q14 -> 63.66
A15: 11 | B15: 8857125000246 | C15: ชิฟฟ่อนเค้กหน้าฝอยทอง สอดไส้แยมส้ม (3 ชิ้น) | D15: กล่อง | E15: =+ยกมา!J15 -> 0 | F15: 0 | G15: =E15+F15 -> 0 | H15: 0 | I15: 0 | J15: =+G15-H15-K15-I15 -> 0 | L15: 50 | M15: =+L15*K15 -> 0 | N15: - | P15: =SUM(M15-O15) -> 0 | Q15: 24.37 | R15: =+K15*Q15 -> 0
A16: 12 | C16: ชิฟฟ่อนเค้กหน้าฝอยทองทูโทน สอดไส้แยมส้ม (3 ชิ้น) | D16: กล่อง | E16: =+ยกมา!J16 -> 0 | F16: 0 | G16: =E16+F16 -> 0 | H16: 0 | I16: 0 | J16: =+G16-H16-K16-I16 -> 0 | L16: 50 | M16: =+L16*K16 -> 0 | N16: - | P16: =SUM(M16-O16) -> 0 | R16: =+K16*Q16 -> 0
A17: 13 | B17: 8857125000024 | C17: ชิฟฟ่อนเค้กสอดไส้แยม รสสตรอว์เบอรี่ (3 ชิ้น) | D17: กล่อง | E17: =+ยกมา!J17 -> 0 | F17: 0 | G17: =E17+F17 -> 0 | H17: 0 | I17: 0 | J17: =+G17-H17-K17-I17 -> 0 | L17: 50 | M17: =+L17*K17 -> 0 | N17: - | P17: =SUM(M17-O17) -> 0 | Q17: 15.05 | R17: =+K17*Q17 -> 0
A18: 14 | B18: 8857125000086 | C18: ชิฟฟ่อนเค้กสอดไส้ เนยมะพร้าว (3 ชิ้น) | D18: กล่อง | E18: =+ยกมา!J18 -> 0 | F18: 5 | G18: =E18+F18 -> 5 | H18: 0 | I18: 0 | J18: =+G18-H18-K18-I18 -> 4 | K18: 1 | L18: 50 | M18: =+L18*K18 -> 50 | N18: - | P18: =SUM(M18-O18) -> 50 | Q18: 18.77 | R18: =+K18*Q18 -> 18.77
A19: 15 | B19: 8857125000239 | C19: ชิฟฟ่อนเค้กสอดไส้ นมชมพูฮอกไกโด (3 ชิ้น) | D19: กล่อง | E19: =+ยกมา!J19 -> 0 | F19: 0 | G19: =E19+F19 -> 0 | H19: 0 | I19: 0 | J19: =+G19-H19-K19-I19 -> 0 | L19: 50 | M19: =+L19*K19 -> 0 | N19: - | P19: =SUM(M19-O19) -> 0 | Q19: 19.04 | R19: =+K19*Q19 -> 0
A20: 16 | B20: 8857125001816 | C20: ชิฟฟ่อน สอดไส้ (ล) 4 ชิ้น ครีมมะพร้าว | D20: กล่อง | E20: =+ยกมา!J20 -> 0 | F20: 5 | G20: =E20+F20 -> 5 | H20: 0 | I20: 0 | J20: =+G20-H20-K20-I20 -> 0 | K20: 5 | L20: 65 | M20: =+L20*K20 -> 325 | N20: - | P20: =SUM(M20-O20) -> 325 | Q20: 22.25 | R20: =+K20*Q20 -> 111.25
A21: 17 | B21: 8857125001021 | C21: ชิฟฟ่อน สอดไส้ (ก) 5 ชิ้น ครีมมะพร้าว | D21: กล่อง | E21: =+ยกมา!J21 -> 0 | F21: 0 | G21: =E21+F21 -> 0 | H21: 0 | I21: 0 | J21: =+G21-H21-K21-I21 -> 0 | L21: 85 | M21: =+L21*K21 -> 0 | N21: - | P21: =SUM(M21-O21) -> 0 | Q21: 22.85 | R21: =+K21*Q21 -> 0
A22: 18 | B22: 8857125000956 | C22: ชิฟฟ่อนเค้กสอดไส้ รวมรส (6 ชิ้น) | D22: กล่อง | E22: =+ยกมา!J22 -> 0 | F22: 10 | G22: =E22+F22 -> 10 | H22: 0 | I22: 0 | J22: =+G22-H22-K22-I22 -> 4 | K22: 6 | L22: 100 | M22: =+L22*K22 -> 600 | N22: ลดราคา 6 | O22: 100 | P22: =SUM(M22-O22) -> 500 | Q22: 26.6 | R22: =+K22*Q22 -> 159.6
A23: 19 | B23: 8857125000918 | C23: ชิฟฟ่อนเค้กสอดไส้แยม รสส้ม (6 ชิ้น) | D23: กล่อง | E23: =+ยกมา!J23 -> 0 | F23: 0 | G23: =E23+F23 -> 0 | H23: 0 | I23: 0 | J23: =+G23-H23-K23-I23 -> 0 | L23: 100 | M23: =+L23*K23 -> 0 | N23: - | P23: =SUM(M23-O23) -> 0 | Q23: 42.24 | R23: =+K23*Q23 -> 0
A24: 20 | B24: 8857125000970 | C24: ชิฟฟ่อนเค้กหน้าฝอยทอง สอดไส้แยมส้ม (6 ชิ้น) | D24: กล่อง | E24: =+ยกมา!J24 -> 0 | F24: 5 | G24: =E24+F24 -> 5 | H24: 0 | I24: 0 | J24: =+G24-H24-K24-I24 -> 5 | L24: 100 | M24: =+L24*K24 -> 0 | N24: - | P24: =SUM(M24-O24) -> 0 | Q24: 40.51 | R24: =+K24*Q24 -> 0
A25: 21 | B25: 8857125003810 | C25: ชิฟฟ่อนเค้กหน้าฝอยทองทูโทน สอดไส้แยมส้ม (6 ชิ้น) | D25: กล่อง | E25: =+ยกมา!J25 -> 0 | F25: 5 | G25: =E25+F25 -> 5 | H25: 0 | I25: 0 | J25: =+G25-H25-K25-I25 -> 5 | L25: 100 | M25: =+L25*K25 -> 0 | N25: - | P25: =SUM(M25-O25) -> 0 | Q25: 39.77 | R25: =+K25*Q25 -> 0
A26: 22 | B26: 8857125000963 | C26: ชิฟฟ่อนเค้กสอดไส้ นมชมพูฮอกไกโด (6 ชิ้น) | D26: กล่อง | E26: =+ยกมา!J26 -> 0 | F26: 0 | G26: =E26+F26 -> 0 | H26: 0 | I26: 0 | J26: =+G26-H26-K26-I26 -> 0 | L26: 100 | M26: =+L26*K26 -> 0 | N26: - | P26: =SUM(M26-O26) -> 0 | Q26: 35.39 | R26: =+K26*Q26 -> 0
A27: 23 | B27: 8857125000932 | C27: ชิฟฟ่อนเค้กสอดไส้แยม รสบลูเบอร์รี่ (6 ชิ้น) | D27: กล่อง | E27: =+ยกมา!J27 -> 0 | F27: 0 | G27: =E27+F27 -> 0 | H27: 0 | I27: 0 | J27: =+G27-H27-K27-I27 -> 0 | L27: 100 | M27: =+L27*K27 -> 0 | N27: - | P27: =SUM(M27-O27) -> 0 | Q27: 31.62 | R27: =+K27*Q27 -> 0
A28: 24 | B28: 8857125000895 | C28: ชิฟฟ่อนเค้กสอดไส้ เนยมะพร้าว (6 ชิ้น) | D28: กล่อง | E28: =+ยกมา!J28 -> 0 | F28: 5 | G28: =E28+F28 -> 5 | H28: 0 | I28: 0 | J28: =+G28-H28-K28-I28 -> 5 | L28: 100 | M28: =+L28*K28 -> 0 | N28: - | P28: =SUM(M28-O28) -> 0 | Q28: 31.97 | R28: =+K28*Q28 -> 0
A29: 25 | B29: 8857125000901 | C29: ชิฟฟ่อนเค้กสอดไส้แยม รสสตรอว์เบอรี่ (6 ชิ้น) | D29: กล่อง | E29: =+ยกมา!J29 -> 0 | F29: 0 | G29: =E29+F29 -> 0 | H29: 0 | I29: 0 | J29: =+G29-H29-K29-I29 -> 0 | L29: 100 | M29: =+L29*K29 -> 0 | N29: - | P29: =SUM(M29-O29) -> 0 | Q29: 21.27 | R29: =+K29*Q29 -> 0
A30: 26 | B30: 8857125001571 | C30: ชิฟฟอนเค้ก รสมะลิ 8ชิ้น (ห่อซีน) | D30: กล่อง | E30: =+ยกมา!J30 -> 0 | F30: 0 | G30: =E30+F30 -> 0 | H30: 0 | I30: 0 | J30: =+G30-H30-K30-I30 -> 0 | L30: 100 | M30: =+L30*K30 -> 0 | N30: - | P30: =SUM(M30-O30) -> 0 | Q30: 34.26 | R30: =+K30*Q30 -> 0
A31: 27 | B31: 8857125002127 | C31: ชิฟฟ่อนรวมรส ยอดฮิต (8 ชิ้น) | D31: กล่อง | E31: =+ยกมา!J31 -> 0 | F31: 10 | G31: =E31+F31 -> 10 | H31: 0 | I31: 0 | J31: =+G31-H31-K31-I31 -> 4 | K31: 6 | L31: 100 | M31: =+L31*K31 -> 600 | N31: ลดราคา 6 | O31: 100 | P31: =SUM(M31-O31) -> 500 | Q31: 38.46 | R31: =+K31*Q31 -> 230.76
A32: 28 | B32: 8857125000130 | C32: ชิฟฟ่อนเค้ก วรรณวนัช (สอดไส้รวมรส 8 ชิ้น) | D32: กล่อง | E32: =+ยกมา!J32 -> 0 | F32: 0 | G32: =E32+F32 -> 0 | H32: 0 | I32: 0 | J32: =+G32-H32-K32-I32 -> 0 | L32: 130 | M32: =+L32*K32 -> 0 | N32: - | P32: =SUM(M32-O32) -> 0 | Q32: 46.37 | R32: =+K32*Q32 -> 0
A33: 29 | B33: 8857125003773 | C33: ชิฟฟ่อนเค้กมะพร้าวสอดไส้ครีมมะพร้าวล้วน (8 ชิ้น) | D33: กล่อง | E33: =+ยกมา!J33 -> 0 | F33: 0 | G33: =E33+F33 -> 0 | H33: 0 | I33: 0 | J33: =+G33-H33-K33-I33 -> 0 | L33: 130 | M33: =+L33*K33 -> 0 | N33: - | P33: =SUM(M33-O33) -> 0 | Q33: 38.9 | R33: =+K33*Q33 -> 0
A34: 30 | B34: 8857125001366 | C34: ชิฟฟ่อนเค้กใบเตยสอดไส้ครีมมะพร้าวล้วน (8 ชิ้น) | D34: กล่อง | E34: =+ยกมา!J34 -> 0 | F34: 0 | G34: =E34+F34 -> 0 | H34: 0 | I34: 0 | J34: =+G34-H34-K34-I34 -> 0 | L34: 130 | M34: =+L34*K34 -> 0 | N34: - | P34: =SUM(M34-O34) -> 0 | Q34: 38.07 | R34: =+K34*Q34 -> 0
A35: 31 | B35: 8857125001397 | C35: ชิฟฟ่อนเค้กใบเตยทูโทนและสอดไส้ครีมมะพร้าว (8 ชิ้น) | D35: กล่อง | E35: =+ยกมา!J35 -> 0 | F35: 0 | G35: =E35+F35 -> 0 | H35: 0 | I35: 0 | J35: =+G35-H35-K35-I35 -> 0 | L35: 130 | M35: =+L35*K35 -> 0 | N35: - | P35: =SUM(M35-O35) -> 0 | Q35: 40.8 | R35: =+K35*Q35 -> 0
A36: 32 | B36: 885712004534 | C36: ชิฟฟ่อนเค้กสอดไส้ครีมมะพร้าว 120g. | D36: ชิ้น | E36: =+ยกมา!J36 -> 0 | F36: 0 | G36: =E36+F36 -> 0 | H36: 0 | I36: 0 | J36: =+G36-H36-K36-I36 -> 0 | L36: 35 | M36: =+L36*K36 -> 0 | N36: - | P36: =SUM(M36-O36) -> 0 | R36: =+K36*Q36 -> 0
A37: 33 | B37: 20055119 | C37: ชิฟฟ่อนเค้กฝอยทอง 95g. | D37: กล่อง | E37: =+ยกมา!J37 -> 0 | F37: 0 | G37: =E37+F37 -> 0 | H37: 0 | I37: 0 | J37: =+G37-H37-K37-I37 -> 0 | L37: 35 | M37: =+L37*K37 -> 0 | N37: - | P37: =SUM(M37-O37) -> 0 | R37: =+K37*Q37 -> 0
A38: 34 | C38: ชิฟฟ่อนหม้อแกง | D38: กล่อง | E38: =+ยกมา!J38 -> 0 | F38: 0 | G38: =E38+F38 -> 0 | H38: 0 | I38: 0 | J38: =+G38-H38-K38-I38 -> 0 | L38: 35 | M38: =+L38*K38 -> 0 | N38: - | P38: =SUM(M38-O38) -> 0 | R38: =+K38*Q38 -> 0
A39: 35 | B39: 8857125000611 | C39: ครีมฮอร์น วนิลา | D39: กล่อง | E39: =+ยกมา!J39 -> 0 | F39: 5 | G39: =E39+F39 -> 5 | H39: 3 | I39: 0 | J39: =+G39-H39-K39-I39 -> 0 | K39: 2 | L39: 50 | M39: =+L39*K39 -> 100 | N39: เปรี๊ยวคืน 3 | P39: =SUM(M39-O39) -> 100 | Q39: 27.84 | R39: =+K39*Q39 -> 55.68
A40: 36 | B40: 8857125000604 | C40: ครีมฮอร์น ใบเตย | D40: กล่อง | E40: =+ยกมา!J40 -> 0 | F40: 5 | G40: =E40+F40 -> 5 | H40: 4 | I40: 0 | J40: =+G40-H40-K40-I40 -> 0 | K40: 1 | L40: 50 | M40: =+L40*K40 -> 50 | N40: เปรี๊ยวคืน 4 | P40: =SUM(M40-O40) -> 50 | Q40: 27.12 | R40: =+K40*Q40 -> 27.12
A41: 37 | B41: 8857125000598 | C41: ครีมฮอร์น ช็อคโกแลต | D41: กล่อง | E41: =+ยกมา!J41 -> 0 | F41: 5 | G41: =E41+F41 -> 5 | H41: 4 | I41: 0 | J41: =+G41-H41-K41-I41 -> 0 | K41: 1 | L41: 50 | M41: =+L41*K41 -> 50 | N41: เปรี๊ยวคืน 4 | P41: =SUM(M41-O41) -> 50 | Q41: 15.42 | R41: =+K41*Q41 -> 15.42
...

Sheet 1
A2: บูธ EVENT MakroHoReCa17 31 ต.ค. 67 -4 พ.ย. 67
A3: ลำดับ | B3: รหัสสินค้า (POS) | C3: รายการ | D3: หน่วย | E3: ยกมา | F3: รับ | G3: รวม | H3: เปลี่ยน/ | I3: โยกย้าย / ระบาย | J3: คงเหลือ | K3: รายการขาย | N3: หมายเหตุ | O3: ส่วนลด | Q3: ราคาต้นทุน | R3: ยอดรวมต้นทุนสินค้า
H4: คืน/เสีย | K4: จำนวน | L4: @ | M4: เป็นเงิน
A5: 1 | B5: 8857125001328 | C5: ชิฟฟ่อนเค้ก รวมรส (4 ชิ้น) | D5: กล่อง | E5: =+'31.'!J5 -> 0 | F5: 0 | G5: =E5+F5 -> 0 | H5: 0 | I5: 0 | J5: =+G5-H5-K5-I5 -> 0 | L5: 50 | M5: =+L5*K5 -> 0 | N5: - | P5: =SUM(M5-O5) -> 0 | Q5: 22.48 | R5: =+K5*Q5 -> 0
A6: 2 | B6: 8857125001311 | C6: ชิฟฟ่อนเค้ก รวมรส (8 ชิ้น) | D6: กล่อง | E6: =+'31.'!J6 -> 5 | F6: 0 | G6: =E6+F6 -> 5 | H6: 0 | I6: 0 | J6: =+G6-H6-K6-I6 -> 5 | L6: 100 | M6: =+L6*K6 -> 0 | N6: - | P6: =SUM(M6-O6) -> 0 | Q6: 39.29 | R6: =+K6*Q6 -> 0
A7: 3 | B7: 8857125003841 | C7: ชิฟฟ่อนเค้ก รสกาแฟ (4 ชิ้น) | D7: ชิ้น | E7: =+'31.'!J7 -> 1 | F7: 0 | G7: =E7+F7 -> 1 | H7: 0 | I7: 0 | J7: =+G7-H7-K7-I7 -> 1 | L7: 50 | M7: =+L7*K7 -> 0 | N7: - | P7: =SUM(M7-O7) -> 0 | Q7: 26.11 | R7: =+K7*Q7 -> 0
A8: 4 | B8: 8857125003827 | C8: ชิฟฟ่อนเค้ก รสกาแฟ (8 ชิ้น) | D8: กล่อง | E8: =+'31.'!J8 -> 0 | F8: 0 | G8: =E8+F8 -> 0 | H8: 0 | I8: 0 | J8: =+G8-H8-K8-I8 -> 0 | L8: 100 | M8: =+L8*K8 -> 0 | N8: - | P8: =SUM(M8-O8) -> 0 | Q8: 33.89 | R8: =+K8*Q8 -> 0
A9: 5 | B9: 8857125002257 | C9: ชิฟฟ่อนเค้ก 1 ชิ้น | D9: ชิ้น | E9: =+'31.'!J9 -> 0 | F9: 0 | G9: =E9+F9 -> 0 | H9: 0 | I9: 0 | J9: =+G9-H9-K9-I9 -> 0 | L9: 10 | M9: =+L9*K9 -> 0 | N9: - | P9: =SUM(M9-O9) -> 0 | R9: =+K9*Q9 -> 0
A10: 6 | B10: 8857125002264 | C10: ชิฟฟ่อนเค้กสอดไส้แยม 1 ชิ้น | D10: ชิ้น | E10: =+'31.'!J10 -> 0 | F10: 0 | G10: =E10+F10 -> 0 | H10: 0 | I10: 0 | J10: =+G10-H10-K10-I10 -> 0 | L10: 15 | M10: =+L10*K10 -> 0 | N10: - | P10: =SUM(M10-O10) -> 0 | R10: =+K10*Q10 -> 0
A11: 7 | B11: 8857125001830 | C11: ชิฟฟ่อนเค้กสอดไส้ รวมรส (3 ชิ้น) | D11: กล่อง | E11: =+'31.'!J11 -> 4 | F11: 0 | G11: =E11+F11 -> 4 | H11: 0 | I11: 0 | J11: =+G11-H11-K11-I11 -> 4 | L11: 50 | M11: =+L11*K11 -> 0 | N11: - | P11: =SUM(M11-O11) -> 0 | Q11: 16.94 | R11: =+K11*Q11 -> 0
A12: 8 | B12: 1112539 | C12: ชิฟฟ่อนเค้กสอดไส้ เมล่อน (3 ชิ้น) | D12: กล่อง | E12: =+'31.'!J12 -> 0 | F12: 0 | G12: =E12+F12 -> 0 | H12: 0 | I12: 0 | J12: =+G12-H12-K12-I12 -> 0 | L12: 50 | M12: =+L12*K12 -> 0 | N12: - | P12: =SUM(M12-O12) -> 0 | R12: =+K12*Q12 -> 0
A13: 9 | B13: 8857125000055 | C13: ชิฟฟ่อนเค้กสอดไส้แยม รสบลูเบอร์รี่ (3 ชิ้น) | D13: กล่อง | E13: =+'31.'!J13 -> 0 | F13: 0 | G13: =E13+F13 -> 0 | H13: 0 | I13: 0 | J13: =+G13-H13-K13-I13 -> 0 | L13: 50 | M13: =+L13*K13 -> 0 | N13: - | P13: =SUM(M13-O13) -> 0 | Q13: 17.32 | R13: =+K13*Q13 -> 0
A14: 10 | B14: 8857125000987 | C14: ชิฟฟ่อนเค้กสอดไส้แยม รสส้ม (3 ชิ้น) | D14: กล่อง | E14: =+'31.'!J14 -> 2 | F14: 0 | G14: =E14+F14 -> 2 | H14: 0 | I14: 0 | J14: =+G14-H14-K14-I14 -> 2 | L14: 50 | M14: =+L14*K14 -> 0 | N14: - | P14: =SUM(M14-O14) -> 0 | Q14: 21.22 | R14: =+K14*Q14 -> 0
A15: 11 | B15: 8857125000246 | C15: ชิฟฟ่อนเค้กหน้าฝอยทอง สอดไส้แยมส้ม (3 ชิ้น) | D15: กล่อง | E15: =+'31.'!J15 -> 0 | F15: 0 | G15: =E15+F15 -> 0 | H15: 0 | I15: 0 | J15: =+G15-H15-K15-I15 -> 0 | L15: 50 | M15: =+L15*K15 -> 0 | N15: - | P15: =SUM(M15-O15) -> 0 | Q15: 24.37 | R15: =+K15*Q15 -> 0
A16: 12 | C16: ชิฟฟ่อนเค้กหน้าฝอยทองทูโทน สอดไส้แยมส้ม (3 ชิ้น) | D16: กล่อง | E16: =+'31.'!J16 -> 0 | F16: 0 | G16: =E16+F16 -> 0 | H16: 0 | I16: 0 | J16: =+G16-H16-K16-I16 -> 0 | L16: 50 | M16: =+L16*K16 -> 0 | N16: - | P16: =SUM(M16-O16) -> 0 | R16: =+K16*Q16 -> 0
A17: 13 | B17: 8857125000024 | C17: ชิฟฟ่อนเค้กสอดไส้แยม รสสตรอว์เบอรี่ (3 ชิ้น) | D17: กล่อง | E17: =+'31.'!J17 -> 0 | F17: 0 | G17: =E17+F17 -> 0 | H17: 0 | I17: 0 | J17: =+G17-H17-K17-I17 -> 0 | L17: 50 | M17: =+L17*K17 -> 0 | N17: - | P17: =SUM(M17-O17) -> 0 | Q17: 15.05 | R17: =+K17*Q17 -> 0
A18: 14 | B18: 8857125000086 | C18: ชิฟฟ่อนเค้กสอดไส้ เนยมะพร้าว (3 ชิ้น) | D18: กล่อง | E18: =+'31.'!J18 -> 4 | F18: 0 | G18: =E18+F18 -> 4 | H18: 0 | I18: 0 | J18: =+G18-H18-K18-I18 -> 4 | L18: 50 | M18: =+L18*K18 -> 0 | N18: - | P18: =SUM(M18-O18) -> 0 | Q18: 18.77 | R18: =+K18*Q18 -> 0
A19: 15 | B19: 8857125000239 | C19: ชิฟฟ่อนเค้กสอดไส้ นมชมพูฮอกไกโด (3 ชิ้น) | D19: กล่อง | E19: =+'31.'!J19 -> 0 | F19: 0 | G19: =E19+F19 -> 0 | H19: 0 | I19: 0 | J19: =+G19-H19-K19-I19 -> 0 | L19: 50 | M19: =+L19*K19 -> 0 | N19: - | P19: =SUM(M19-O19) -> 0 | Q19: 19.04 | R19: =+K19*Q19 -> 0
A20: 16 | B20: 8857125001816 | C20: ชิฟฟ่อน สอดไส้ (ล) 4 ชิ้น ครีมมะพร้าว | D20: กล่อง | E20: =+'31.'!J20 -> 0 | F20: 0 | G20: =E20+F20 -> 0 | H20: 0 | I20: 0 | J20: =+G20-H20-K20-I20 -> 0 | L20: 65 | M20: =+L20*K20 -> 0 | N20: - | P20: =SUM(M20-O20) -> 0 | Q20: 22.25 | R20: =+K20*Q20 -> 0
A21: 17 | B21: 8857125001021 | C21: ชิฟฟ่อน สอดไส้ (ก) 5 ชิ้น ครีมมะพร้าว | D21: กล่อง | E21: =+'31.'!J21 -> 0 | F21: 0 | G21: =E21+F21 -> 0 | H21: 0 | I21: 0 | J21: =+G21-H21-K21-I21 -> 0 | L21: 85 | M21: =+L21*K21 -> 0 | N21: - | P21: =SUM(M21-O21) -> 0 | Q21: 22.85 | R21: =+K21*Q21 -> 0
A22: 18 | B22: 8857125000956 | C22: ชิฟฟ่อนเค้กสอดไส้ รวมรส (6 ชิ้น) | D22: กล่อง | E22: =+'31.'!J22 -> 4 | F22: 0 | G22: =E22+F22 -> 4 | H22: 0 | I22: 0 | J22: =+G22-H22-K22-I22 -> 4 | L22: 100 | M22: =+L22*K22 -> 0 | N22: - | P22: =SUM(M22-O22) -> 0 | Q22: 26.6 | R22: =+K22*Q22 -> 0
A23: 19 | B23: 8857125000918 | C23: ชิฟฟ่อนเค้กสอดไส้แยม รสส้ม (6 ชิ้น) | D23: กล่อง | E23: =+'31.'!J23 -> 0 | F23: 0 | G23: =E23+F23 -> 0 | H23: 0 | I23: 0 | J23: =+G23-H23-K23-I23 -> 0 | L23: 100 | M23: =+L23*K23 -> 0 | N23: - | P23: =SUM(M23-O23) -> 0 | Q23: 42.24 | R23: =+K23*Q23 -> 0
A24: 20 | B24: 8857125000970 | C24: ชิฟฟ่อนเค้กหน้าฝอยทอง สอดไส้แยมส้ม (6 ชิ้น) | D24: กล่อง | E24: =+'31.'!J24 -> 5 | F24: 0 | G24: =E24+F24 -> 5 | H24: 0 | I24: 0 | J24: =+G24-H24-K24-I24 -> 5 | L24: 100 | M24: =+L24*K24 -> 0 | N24: - | P24: =SUM(M24-O24) -> 0 | Q24: 40.51 | R24: =+K24*Q24 -> 0
A25: 21 | B25: 8857125003810 | C25: ชิฟฟ่อนเค้กหน้าฝอยทองทูโทน สอดไส้แยมส้ม (6 ชิ้น) | D25: กล่อง | E25: =+'31.'!J25 -> 5 | F25: 0 | G25: =E25+F25 -> 5 | H25: 0 | I25: 0 | J25: =+G25-H25-K25-I25 -> 5 | L25: 100 | M25: =+L25*K25 -> 0 | N25: - | P25: =SUM(M25-O25) -> 0 | Q25: 39.77 | R25: =+K25*Q25 -> 0
A26: 22 | B26: 8857125000963 | C26: ชิฟฟ่อนเค้กสอดไส้ นมชมพูฮอกไกโด (6 ชิ้น) | D26: กล่อง | E26: =+'31.'!J26 -> 0 | F26: 0 | G26: =E26+F26 -> 0 | H26: 0 | I26: 0 | J26: =+G26-H26-K26-I26 -> 0 | L26: 100 | M26: =+L26*K26 -> 0 | N26: - | P26: =SUM(M26-O26) -> 0 | Q26: 35.39 | R26: =+K26*Q26 -> 0
A27: 23 | B27: 8857125000932 | C27: ชิฟฟ่อนเค้กสอดไส้แยม รสบลูเบอร์รี่ (6 ชิ้น) | D27: กล่อง | E27: =+'31.'!J27 -> 0 | F27: 0 | G27: =E27+F27 -> 0 | H27: 0 | I27: 0 | J27: =+G27-H27-K27-I27 -> 0 | L27: 100 | M27: =+L27*K27 -> 0 | N27: - | P27: =SUM(M27-O27) -> 0 | Q27: 31.62 | R27: =+K27*Q27 -> 0
A28: 24 | B28: 8857125000895 | C28: ชิฟฟ่อนเค้กสอดไส้ เนยมะพร้าว (6 ชิ้น) | D28: กล่อง | E28: =+'31.'!J28 -> 5 | F28: 0 | G28: =E28+F28 -> 5 | H28: 0 | I28: 0 | J28: =+G28-H28-K28-I28 -> 5 | L28: 100 | M28: =+L28*K28 -> 0 | N28: - | P28: =SUM(M28-O28) -> 0 | Q28: 31.97 | R28: =+K28*Q28 -> 0
A29: 25 | B29: 8857125000901 | C29: ชิฟฟ่อนเค้กสอดไส้แยม รสสตรอว์เบอรี่ (6 ชิ้น) | D29: กล่อง | E29: =+'31.'!J29 -> 0 | F29: 0 | G29: =E29+F29 -> 0 | H29: 0 | I29: 0 | J29: =+G29-H29-K29-I29 -> 0 | L29: 100 | M29: =+L29*K29 -> 0 | N29: - | P29: =SUM(M29-O29) -> 0 | Q29: 21.27 | R29: =+K29*Q29 -> 0
A30: 26 | B30: 8857125001571 | C30: ชิฟฟอนเค้ก รสมะลิ 8ชิ้น (ห่อซีน) | D30: กล่อง | E30: =+'31.'!J30 -> 0 | F30: 0 | G30: =E30+F30 -> 0 | H30: 0 | I30: 0 | J30: =+G30-H30-K30-I30 -> 0 | L30: 100 | M30: =+L30*K30 -> 0 | N30: - | P30: =SUM(M30-O30) -> 0 | Q30: 34.26 | R30: =+K30*Q30 -> 0
A31: 27 | B31: 8857125002127 | C31: ชิฟฟ่อนรวมรส ยอดฮิต (8 ชิ้น) | D31: กล่อง | E31: =+'31.'!J31 -> 4 | F31: 0 | G31: =E31+F31 -> 4 | H31: 0 | I31: 0 | J31: =+G31-H31-K31-I31 -> 4 | L31: 100 | M31: =+L31*K31 -> 0 | N31: - | P31: =SUM(M31-O31) -> 0 | Q31: 38.46 | R31: =+K31*Q31 -> 0
A32: 28 | B32: 8857125000130 | C32: ชิฟฟ่อนเค้ก วรรณวนัช (สอดไส้รวมรส 8 ชิ้น) | D32: กล่อง | E32: =+'31.'!J32 -> 0 | F32: 0 | G32: =E32+F32 -> 0 | H32: 0 | I32: 0 | J32: =+G32-H32-K32-I32 -> 0 | L32: 130 | M32: =+L32*K32 -> 0 | N32: - | P32: =SUM(M32-O32) -> 0 | Q32: 46.37 | R32: =+K32*Q32 -> 0
A33: 29 | B33: 8857125003773 | C33: ชิฟฟ่อนเค้กมะพร้าวสอดไส้ครีมมะพร้าวล้วน (8 ชิ้น) | D33: กล่อง | E33: =+'31.'!J33 -> 0 | F33: 0 | G33: =E33+F33 -> 0 | H33: 0 | I33: 0 | J33: =+G33-H33-K33-I33 -> 0 | L33: 130 | M33: =+L33*K33 -> 0 | N33: - | P33: =SUM(M33-O33) -> 0 | Q33: 38.9 | R33: =+K33*Q33 -> 0
A34: 30 | B34: 8857125001366 | C34: ชิฟฟ่อนเค้กใบเตยสอดไส้ครีมมะพร้าวล้วน (8 ชิ้น) | D34: กล่อง | E34: =+'31.'!J34 -> 0 | F34: 0 | G34: =E34+F34 -> 0 | H34: 0 | I34: 0 | J34: =+G34-H34-K34-I34 -> 0 | L34: 130 | M34: =+L34*K34 -> 0 | N34: - | P34: =SUM(M34-O34) -> 0 | Q34: 38.07 | R34: =+K34*Q34 -> 0
A35: 31 | B35: 8857125001397 | C35: ชิฟฟ่อนเค้กใบเตยทูโทนและสอดไส้ครีมมะพร้าว (8 ชิ้น) | D35: กล่อง | E35: =+'31.'!J35 -> 0 | F35: 0 | G35: =E35+F35 -> 0 | H35: 0 | I35: 0 | J35: =+G35-H35-K35-I35 -> 0 | L35: 130 | M35: =+L35*K35 -> 0 | N35: - | P35: =SUM(M35-O35) -> 0 | Q35: 40.8 | R35: =+K35*Q35 -> 0
A36: 32 | B36: 885712004534 | C36: ชิฟฟ่อนเค้กสอดไส้ครีมมะพร้าว 120g. | D36: ชิ้น | E36: =+'31.'!J36 -> 0 | F36: 0 | G36: =E36+F36 -> 0 | H36: 0 | I36: 0 | J36: =+G36-H36-K36-I36 -> 0 | L36: 35 | M36: =+L36*K36 -> 0 | N36: - | P36: =SUM(M36-O36) -> 0 | R36: =+K36*Q36 -> 0
A37: 33 | B37: 20055119 | C37: ชิฟฟ่อนเค้กฝอยทอง 95g. | D37: กล่อง | E37: =+'31.'!J37 -> 0 | F37: 0 | G37: =E37+F37 -> 0 | H37: 0 | I37: 0 | J37: =+G37-H37-K37-I37 -> 0 | L37: 35 | M37: =+L37*K37 -> 0 | N37: - | P37: =SUM(M37-O37) -> 0 | R37: =+K37*Q37 -> 0
A38: 34 | C38: ชิฟฟ่อนหม้อแกง | D38: กล่อง | E38: =+'31.'!J38 -> 0 | F38: 0 | G38: =E38+F38 -> 0 | H38: 0 | I38: 0 | J38: =+G38-H38-K38-I38 -> 0 | L38: 35 | M38: =+L38*K38 -> 0 | N38: - | P38: =SUM(M38-O38) -> 0 | R38: =+K38*Q38 -> 0
A39: 35 | B39: 8857125000611 | C39: ครีมฮอร์น วนิลา | D39: กล่อง | E39: =+'31.'!J39 -> 0 | F39: 0 | G39: =E39+F39 -> 0 | H39: 0 | I39: 0 | J39: =+G39-H39-K39-I39 -> 0 | L39: 50 | M39: =+L39*K39 -> 0 | N39: - | P39: =SUM(M39-O39) -> 0 | Q39: 27.84 | R39: =+K39*Q39 -> 0
A40: 36 | B40: 8857125000604 | C40: ครีมฮอร์น ใบเตย | D40: กล่อง | E40: =+'31.'!J40 -> 0 | F40: 0 | G40: =E40+F40 -> 0 | H40: 0 | I40: 0 | J40: =+G40-H40-K40-I40 -> 0 | L40: 50 | M40: =+L40*K40 -> 0 | N40: - | P40: =SUM(M40-O40) -> 0 | Q40: 27.12 | R40: =+K40*Q40 -> 0
A41: 37 | B41: 8857125000598 | C41: ครีมฮอร์น ช็อคโกแลต | D41: กล่อง | E41: =+'31.'!J41 -> 0 | F41: 0 | G41: =E41+F41 -> 0 | H41: 0 | I41: 0 | J41: =+G41-H41-K41-I41 -> 0 | L41: 50 | M41: =+L41*K41 -> 0 | N41: - | P41: =SUM(M41-O41) -> 0 | Q41: 15.42 | R41: =+K41*Q41 -> 0
...

Sheet 2
A2: บูธ EVENT MakroHoReCa17 31 ต.ค. 67 -4 พ.ย. 67
A3: ลำดับ | B3: รหัสสินค้า (POS) | C3: รายการ | D3: หน่วย | E3: ยกมา | F3: รับ | G3: รวม | H3: เปลี่ยน/ | I3: โยกย้าย / ระบาย | J3: คงเหลือ | K3: รายการขาย | N3: หมายเหตุ | O3: ส่วนลด | Q3: ราคาต้นทุน | R3: ยอดรวมต้นทุนสินค้า
H4: คืน/เสีย | K4: จำนวน | L4: @ | M4: เป็นเงิน
A5: 1 | B5: 8857125001328 | C5: ชิฟฟ่อนเค้ก รวมรส (4 ชิ้น) | D5: กล่อง | E5: =+'1'!J5 -> 0 | F5: 0 | G5: =E5+F5 -> 0 | H5: 0 | I5: 0 | J5: =+G5-H5-K5-I5 -> 0 | L5: 50 | M5: =+L5*K5 -> 0 | N5: - | P5: =SUM(M5-O5) -> 0 | Q5: 22.48 | R5: =+K5*Q5 -> 0
A6: 2 | B6: 8857125001311 | C6: ชิฟฟ่อนเค้ก รวมรส (8 ชิ้น) | D6: กล่อง | E6: =+'1'!J6 -> 5 | F6: 0 | G6: =E6+F6 -> 5 | H6: 0 | I6: 0 | J6: =+G6-H6-K6-I6 -> 5 | L6: 100 | M6: =+L6*K6 -> 0 | N6: - | P6: =SUM(M6-O6) -> 0 | Q6: 39.29 | R6: =+K6*Q6 -> 0
A7: 3 | B7: 8857125003841 | C7: ชิฟฟ่อนเค้ก รสกาแฟ (4 ชิ้น) | D7: ชิ้น | E7: =+'1'!J7 -> 1 | F7: 0 | G7: =E7+F7 -> 1 | H7: 0 | I7: 0 | J7: =+G7-H7-K7-I7 -> 1 | L7: 50 | M7: =+L7*K7 -> 0 | N7: - | P7: =SUM(M7-O7) -> 0 | Q7: 26.11 | R7: =+K7*Q7 -> 0
A8: 4 | B8: 8857125003827 | C8: ชิฟฟ่อนเค้ก รสกาแฟ (8 ชิ้น) | D8: กล่อง | E8: =+'1'!J8 -> 0 | F8: 0 | G8: =E8+F8 -> 0 | H8: 0 | I8: 0 | J8: =+G8-H8-K8-I8 -> 0 | L8: 100 | M8: =+L8*K8 -> 0 | N8: - | P8: =SUM(M8-O8) -> 0 | Q8: 33.89 | R8: =+K8*Q8 -> 0
A9: 5 | B9: 8857125002257 | C9: ชิฟฟ่อนเค้ก 1 ชิ้น | D9: ชิ้น | E9: =+'1'!J9 -> 0 | F9: 0 | G9: =E9+F9 -> 0 | H9: 0 | I9: 0 | J9: =+G9-H9-K9-I9 -> 0 | L9: 10 | M9: =+L9*K9 -> 0 | N9: - | P9: =SUM(M9-O9) -> 0 | R9: =+K9*Q9 -> 0
A10: 6 | B10: 8857125002264 | C10: ชิฟฟ่อนเค้กสอดไส้แยม 1 ชิ้น | D10: ชิ้น | E10: =+'1'!J10 -> 0 | F10: 0 | G10: =E10+F10 -> 0 | H10: 0 | I10: 0 | J10: =+G10-H10-K10-I10 -> 0 | L10: 15 | M10: =+L10*K10 -> 0 | N10: - | P10: =SUM(M10-O10) -> 0 | R10: =+K10*Q10 -> 0
A11: 7 | B11: 8857125001830 | C11: ชิฟฟ่อนเค้กสอดไส้ รวมรส (3 ชิ้น) | D11: กล่อง | E11: =+'1'!J11 -> 4 | F11: 0 | G11: =E11+F11 -> 4 | H11: 0 | I11: 0 | J11: =+G11-H11-K11-I11 -> 4 | L11: 50 | M11: =+L11*K11 -> 0 | N11: - | P11: =SUM(M11-O11) -> 0 | Q11: 16.94 | R11: =+K11*Q11 -> 0
A12: 8 | B12: 1112539 | C12: ชิฟฟ่อนเค้กสอดไส้ เมล่อน (3 ชิ้น) | D12: กล่อง | E12: =+'1'!J12 -> 0 | F12: 0 | G12: =E12+F12 -> 0 | H12: 0 | I12: 0 | J12: =+G12-H12-K12-I12 -> 0 | L12: 50 | M12: =+L12*K12 -> 0 | N12: - | P12: =SUM(M12-O12) -> 0 | R12: =+K12*Q12 -> 0
