Workbook

Sheet ออเดอร์จัดส่ง มี.ค. 69
A1: วันที่ | B1: กล่อง | N1: จัดส่งสำเร็จ | V1: จัดส่งไม่สำเร็จ | AC1: หมายเหตุ
N2: วันที่ | O2: กล่อง | V2: วันที่ | W2: กล่อง | AC2: วันที่ | AD2: กล่อง
B3: lazada | C3: ค้างส่ง L | D3: shopee | E3: ค้างส่ง S | F3: tiktok | G3: ค้างส่ง T | H3: ช้อยส์ | I3: ค้างส่ง ช้อยส์ | J3: ปณ | K3: ค้างส่ง ปณ | L3: ฝากส่ง | O3: lazada | P3: shopee | Q3: tiktok | R3: ช้อยส์ | S3: ปณ | T3: ฝากส่ง | W3: lazada | X3: shopee | Y3: tiktok | Z3: ช้อยส์ | AA3: ปณ | AD3: lazada | AE3: shopee | AF3: tiktok | AG3: ช้อยส์ | AH3: ปณ
A4: 1 | B4: 17 | C4: 0 | D4: 26 | E4: 1 | F4: 92 | G4: 0 | J4: 22 | K4: 0 | L4: 0 | N4: 1 | O4: 17 | P4: 25 | Q4: 89 | S4: 14 | T4: 0 | V4: 1 | W4: 0 | X4: 0 | Y4: 2 | AA4: 8 | AC4: 1 | AE4: ยกเลิก 1 บิล (1-1=0) | AF4: ยกเลิก 1 (3-1=2) 2 บิล ปิดไม่ได้ ขาดเปี๊ยะ ทุกรส ของไม่ออก | AH4: 8 บิล ขาดเปี๊ยะ ทุกรส ของไม่ออก
A5: 2 | B5: 19 | C5: 0 | D5: 59 | E5: 0 | F5: 126 | G5: 5 | J5: 25 | K5: 8 | L5: 2 | N5: 2 | O5: 19 | P5: 59 | Q5: 127 | S5: 33 | T5: 2 | V5: 2 | W5: 0 | X5: 0 | Y5: 0 | AA5: 0 | AC5: 2 | AF5: ยกเลิก 1 (1-1=0)
A6: 3 | B6: 31 | C6: 0 | D6: 45 | E6: 0 | F6: 135 | G6: 0 | J6: 7 | K6: 0 | L6: 20 | N6: 3 | O6: 31 | P6: 45 | Q6: 135 | S6: 7 | T6: 20 | V6: 3 | W6: 0 | X6: 0 | Y6: 0 | AA6: 0 | AC6: 3
A7: 4 | B7: 24 | C7: 0 | D7: 37 | E7: 0 | F7: 159 | G7: 0 | J7: 4 | K7: 0 | L7: 6 | N7: 4 | O7: 24 | P7: 36 | Q7: 145 | S7: 4 | T7: 6 | V7: 4 | W7: 0 | X7: 1 | Y7: 13 | AA7: 0 | AC7: 4 | AE7: ค้าง 1 บิล ขาดเบาหวิว ของไม่ออก | AF7: ยกเลิก 1 บิล ค้าง 13 บิล ขาดเบาหวิวคละรส ของไม่ออก
A8: 5 | B8: 16 | C8: 0 | D8: 37 | E8: 1 | F8: 87 | G8: 13 | J8: 2 | K8: 0 | L8: 7 | N8: 5 | O8: 15 | P8: 38 | Q8: 100 | S8: 2 | T8: 7 | V8: 5 | W8: 0 | X8: 0 | Y8: 0 | AA8: 0 | AC8: 5 | AD8: ยกเลิก 1 (1-1=0)
A9: 6 | B9: 21 | C9: 0 | D9: 35 | E9: 0 | F9: 227 | G9: 0 | J9: 8 | K9: 0 | L9: 2 | N9: 6 | O9: 20 | P9: 35 | Q9: 226 | S9: 8 | T9: 2 | V9: 6 | W9: 0 | X9: 0 | Y9: 0 | AA9: 0 | AC9: 6 | AD9: ยกเลิก 1 (1-1=0) | AF9: ยกเลิก 1 บิล (1-1=0)
A10: 7 | B10: 12 | C10: 0 | D10: 43 | E10: 0 | F10: 141 | G10: 0 | J10: 7 | K10: 0 | L10: 2 | N10: 7 | O10: 11 | P10: 43 | Q10: 132 | S10: 7 | T10: 2 | V10: 7 | W10: 1 | X10: 0 | Y10: 7 | AA10: 0 | AC10: 7 | AD10: ค้าง 1 บิล ขาดเปี๊ยะ | AF10: ยกเลิก 2 บิล (9-2=7) ค้าง 7 บิล *ขาด เปี๊ยะ เบาหวิว
A11: 8 | B11: 14 | C11: 1 | D11: 44 | E11: 0 | F11: 105 | G11: 7 | J11: 20 | K11: 0 | L11: 1 | N11: 8 | O11: 9 | P11: 38 | Q11: 88 | S11: 1 | T11: 1 | V11: 8 | W11: 6 | X11: 6 | Y11: 22 | AA11: 19 | AC11: 8 | AD11: ค้าง 6 บิล ขาดเปี๊ยะ ของไม่ออก | AE11: ค้าง 6 บิล ขาดเปี๊ยะ และเบาหวิวกาแฟ ของไม่ออก | AF11: ยกเลิก 2 บิล (24-2=22) ค้าง 22 บิล ขาดเปี๊ยะของไม่ออก | AH11: ค้าง 19 บิล ขาดเปี๊ยะของไม่ออก
A12: 9 | B12: 14 | C12: 6 | D12: 48 | E12: 6 | F12: 145 | G12: 22 | J12: 15 | K12: 19 | L12: 2 | N12: 9 | O12: 19 | P12: 54 | Q12: 167 | S12: 34 | T12: 2 | V12: 9 | W12: 0 | X12: 0 | Y12: 0 | AA12: 0 | AC12: 9 | AD12: ยกเลิก 1 (1-1=0)
A13: 10 | B13: 24 | C13: 0 | D13: 59 | E13: 0 | F13: 120 | G13: 0 | J13: 20 | K13: 0 | L13: 2 | N13: 10 | O13: 24 | P13: 59 | Q13: 120 | S13: 20 | T13: 2 | V13: 10 | W13: 0 | X13: 0 | Y13: 0 | AA13: 0 | AC13: 10
A14: 11 | B14: 25 | C14: 0 | D14: 30 | E14: 0 | F14: 123 | G14: 0 | J14: 10 | K14: 0 | L14: 0 | N14: 11 | O14: 25 | P14: 30 | Q14: 123 | S14: 10 | T14: 0 | V14: 11 | W14: 0 | X14: 0 | Y14: 0 | AA14: 0 | AC14: 11
A15: 12 | B15: 23 | C15: 0 | D15: 27 | E15: 0 | F15: 117 | G15: 0 | J15: 0 | K15: 0 | L15: 4 | N15: 12 | O15: 22 | P15: 27 | Q15: 117 | S15: 0 | T15: 4 | V15: 12 | W15: 0 | X15: 0 | Y15: 0 | AA15: 0 | AC15: 12 | AD15: ยกเลิก 1 บิล (1-1=0)
A16: 13 | B16: 17 | C16: 0 | D16: 33 | E16: 0 | F16: 114 | G16: 0 | J16: 11 | K16: 0 | L16: 3 | N16: 13 | O16: 17 | P16: 33 | Q16: 113 | S16: 11 | T16: 3 | V16: 13 | W16: 0 | X16: 0 | Y16: 0 | AA16: 0 | AC16: 13 | AF16: ยกเลิก 1 บิล (1-1=0)
A17: 14 | B17: 20 | C17: 0 | D17: 39 | E17: 0 | F17: 123 | G17: 0 | J17: 11 | K17: 0 | L17: 0 | N17: 14 | O17: 20 | P17: 39 | Q17: 123 | S17: 11 | T17: 0 | V17: 14 | W17: 0 | X17: 0 | Y17: 0 | AA17: 0 | AC17: 14
A18: 15 | B18: 30 | C18: 0 | D18: 29 | E18: 0 | F18: 88 | G18: 0 | J18: 30 | K18: 0 | L18: 0 | N18: 15 | O18: 30 | P18: 29 | Q18: 87 | S18: 0 | T18: 0 | V18: 15 | W18: 0 | X18: 0 | Y18: 0 | AA18: 30 | AC18: 15 | AF18: ยกเลิก 1 (1-1=0) | AH18: แพคจบ ปณ. หยุด ไม่ได้เข้ารับ
A19: 16 | B19: 17 | C19: 0 | D19: 35 | E19: 0 | F19: 173 | G19: 0 | J19: 42 | K19: 30 | L19: 4 | N19: 16 | O19: 17 | P19: 34 | Q19: 172 | S19: 72 | T19: 4 | V19: 16 | W19: 0 | X19: 0 | Y19: 0 | AA19: 0 | AC19: 16 | AE19: ยกเลิก 1 (1-1=0) | AF19: ยกเลิก 1 (1-1=0)
A20: 17 | B20: 30 | C20: 0 | D20: 23 | E20: 0 | F20: 138 | G20: 0 | J20: 23 | K20: 0 | L20: 5 | N20: 17 | O20: 30 | P20: 23 | Q20: 137 | S20: 23 | T20: 5 | V20: 17 | W20: 0 | X20: 0 | Y20: 0 | AA20: 0 | AC20: 17 | AF20: ยกเลิก 1 (1-1=0)
A21: 18 | B21: 32 | C21: 0 | D21: 48 | E21: 0 | F21: 145 | G21: 0 | J21: 14 | K21: 0 | L21: 1 | N21: 18 | O21: 32 | P21: 47 | Q21: 144 | S21: 14 | T21: 1 | V21: 18 | W21: 0 | X21: 0 | Y21: 0 | AA21: 0 | AC21: 18 | AE21: ยกเลิก 1 (1-1=0) | AF21: ยกเลิก 1 (1-1=0)
A22: 19 | B22: 27 | C22: 0 | D22: 37 | E22: 0 | F22: 107 | G22: 0 | J22: 17 | K22: 0 | L22: 4 | N22: 19 | O22: 27 | P22: 37 | Q22: 106 | S22: 17 | T22: 4 | V22: 19 | W22: 0 | X22: 0 | Y22: 0 | AA22: 0 | AC22: 19 | AF22: ยกเลิก 1 (1-1=0)
A23: 20 | B23: 18 | C23: 0 | D23: 23 | E23: 0 | F23: 81 | G23: 0 | J23: 25 | K23: 0 | L23: 8 | N23: 20 | O23: 18 | P23: 23 | Q23: 79 | S23: 22 | T23: 8 | V23: 20 | W23: 0 | X23: 0 | Y23: 0 | AA23: 3 | AC23: 20 | AF23: ยกเลิก 2 (2-2=0) | AH23: ค้าง 3 บิล ขาดเปี๊ยะงาดำ ของไม่ออก
A24: 21 | B24: 13 | C24: 0 | D24: 45 | E24: 0 | F24: 154 | G24: 0 | J24: 6 | K24: 3 | L24: 1 | N24: 21 | O24: 13 | P24: 45 | Q24: 151 | S24: 9 | T24: 1 | V24: 21 | W24: 0 | X24: 0 | Y24: 0 | AA24: 0 | AC24: 21 | AF24: ยกเลิก 3 (3-3=0)
A25: 22 | B25: 16 | C25: 0 | D25: 28 | E25: 0 | F25: 303 | G25: 0 | J25: 7 | K25: 0 | L25: 0 | N25: 22 | O25: 16 | P25: 28 | Q25: 243 | S25: 7 | T25: 0 | V25: 22 | W25: 0 | X25: 0 | Y25: 56 | AA25: 0 | AC25: 22 | AF25: ยกเลิก 4 (60-4=56) บิลค้าง 56 บิล ขาดเบาหวิวทุกรส ของไม่พอ
A26: 23 | B26: 17 | C26: 0 | D26: 34 | E26: 0 | F26: 179 | G26: 56 | J26: 9 | K26: 0 | L26: 0 | N26: 23 | O26: 17 | P26: 34 | Q26: 230 | S26: 0 | T26: 0 | V26: 23 | W26: 0 | X26: 0 | Y26: 2 | AA26: 9 | AC26: 23 | AF26: ยกเลิก 3 (5-3=2) บิลค้าง 2 บิล ขาด ปังพิซซ่า มินิบัน ชิฟฟอนไก่หยอง ของไม่ออก | AH26: ค้าง 9 บิล ขาด ปังพิสซ่า มินิบัน ชิฟฟอนไก่หยอง ของไม่ออก
A27: 24 | B27: 6 | C27: 0 | D27: 27 | E27: 0 | F27: 168 | G27: 2 | J27: 6 | K27: 9 | L27: 4 | N27: 24 | O27: 6 | P27: 27 | Q27: 168 | S27: 10 | T27: 4 | V27: 24 | W27: 0 | X27: 0 | Y27: 0 | AA27: 1 | AC27: 24 | AF27: ยกเลิก 2 (2-2=0) | AH27: ค้าง 1 บิล รอเบอร์โทรลูกค้า
A28: 25 | B28: 32 | C28: 0 | D28: 30 | E28: 0 | F28: 197 | G28: 0 | J28: 44 | K28: 1 | L28: 2 | N28: 25 | O28: 32 | P28: 29 | Q28: 192 | S28: 45 | T28: 2 | V28: 25 | W28: 0 | X28: 0 | Y28: 0 | AA28: 0 | AC28: 25 | AF28: ยกเลิก 5 (5-5=0)
A29: 26 | B29: 21 | C29: 0 | D29: 45 | E29: 0 | F29: 156 | G29: 0 | J29: 5 | K29: 0 | L29: 3 | N29: 26 | O29: 21 | P29: 43 | Q29: 156 | S29: 5 | T29: 3 | V29: 26 | W29: 0 | X29: 0 | Y29: 0 | AA29: 0 | AC29: 26 | AE29: ยกเลิก 2 (2-2=0)
A30: 27 | B30: 19 | C30: 0 | D30: 48 | E30: 0 | F30: 135 | G30: 0 | J30: 8 | K30: 0 | L30: 4 | N30: 27 | O30: 19 | P30: 48 | Q30: 133 | S30: 8 | T30: 4 | V30: 27 | W30: 0 | X30: 0 | Y30: 0 | AA30: 0 | AC30: 27 | AF30: ยกเลิก 2 (2-2=0)
A31: 28 | B31: 18 | C31: 0 | D31: 30 | E31: 0 | F31: 97 | G31: 0 | J31: 8 | K31: 0 | L31: 1 | N31: 28 | O31: 18 | P31: 30 | Q31: 96 | S31: 8 | T31: 1 | V31: 28 | W31: 0 | X31: 0 | Y31: 0 | AA31: 0 | AC31: 28 | AF31: ยกเลิก 1 (1-1=0)
A32: 29 | B32: 15 | C32: 0 | D32: 17 | E32: 0 | F32: 176 | G32: 0 | J32: 31 | K32: 0 | L32: 0 | N32: 29 | O32: 15 | P32: 16 | Q32: 171 | S32: 27 | T32: 0 | V32: 29 | W32: 0 | X32: 0 | Y32: 5 | AA32: 4 | AC32: 29 | AE32: ยกเลิก 1 (1-1=0) | AF32: บิลค้าง 5 บิล *ขาดปังพิสซ่า ของไม่ออก | AH32: บิลค้าง 4 บิล *ขาดปังพิสซ่าของไม่ออก
A33: 30 | B33: 13 | C33: 0 | D33: 47 | E33: 0 | F33: 185 | G33: 5 | J33: 7 | K33: 4 | L33: 1 | N33: 30 | O33: 13 | P33: 47 | Q33: 188 | S33: 11 | T33: 4 | V33: 30 | W33: 0 | X33: 0 | Y33: 0 | AA33: 0 | AC33: 30 | AF33: ยกเลิก 2 (2-2=0)
A34: 31 | B34: 12 | C34: 0 | D34: 42 | E34: 0 | F34: 175 | G34: 0 | J34: 100 | K34: 0 | L34: 0 | N34: 31 | O34: 12 | P34: 42 | Q34: 167 | S34: 90 | T34: 0 | V34: 31 | W34: 0 | X34: 0 | Y34: 8 | AA34: 10 | AC34: 31 | AF34: บิลค้าง 8 บิล *ปังพิสซ่า ไก่หยองพริกเผา | AH34: บิลค้าง 10 บิล *ปังพิสซ่า ไก่หยองพริกเผา
A35: รวม | B35: =SUM(B4:B34) -> 613 | C35: =SUM(C4:C34) -> 7 | D35: =SUM(D4:D34) -> 1150 | E35: =SUM(E4:E34) -> 8 | F35: =SUM(F4:F34) -> 4471 | G35: =SUM(G4:G34) -> 110 | H35: 0 | J35: 407 | L35: 63 | N35: รวม | O35: =SUM(O4:O34) -> 609 | P35: =SUM(P4:P34) -> 1143 | Q35: =SUM(Q4:Q34) -> 4425 | R35: =SUM(R4:R34) -> 0 | S35: =SUM(S4:S34) -> 530 | T35: =SUM(T4:T34) -> 92 | V35: รวม | W35: =SUM(W4:W34) -> 7 | X35: =SUM(X4:X34) -> 7 | Y35: =SUM(Y4:Y34) -> 115 | Z35: =SUM(Z4:Z34) -> 0 | AA35: =SUM(AA4:AA34) -> 84 | AC35: รวม | AD35: =SUM(AD4:AD34) -> 0 | AE35: =SUM(AE4:AE34) -> 0 | AF35: =SUM(AF4:AF34) -> 0 | AG35: =SUM(AG4:AG34) -> 0 | AH35: =SUM(AH4:AH34) -> 0

Sheet สรุป
A1: สรุปรายการของตีกลับของช่องทางออนไลน์ เดือนมีนาคม 2569
A2: แพลตฟอร์ม | B2: สาเหตุการตีกลับ | L2: รวม | M2: ยอดเงิน
B3: ปฏิเสธ , ยกเลิก | D3: ติดต่อไม่ได้ , ไม่รับโทรศัพท์ | F3: ส่งของไปซ้ำ | H3: เกินเวลานัดส่งพัสดุ | J3: สลิปปลอม
B4: จำนวนออเดอร์ | C4: ยอดขาย | D4: จำนวนออเดอร์ | E4: ยอดขาย | F4: จำนวนออเดอร์ | G4: ยอดขาย | H4: จำนวนออเดอร์ | I4: ยอดขาย | J4: จำนวนออเดอร์ | K4: ยอดขาย
A5: Lazada | B5: 8 | C5: 1885.96 | D5: 0 | E5: 0 | F5: 0 | G5: 0 | H5: 0 | I5: 0 | J5: 0 | K5: 0 | L5: =+B5+D5+F5+H5+J5 -> 8 | M5: =+C5+E5+G5+I5+K5 -> 1885.96
A6: Shopee | B6: 4 | C6: 449 | D6: 1 | E6: 116 | F6: 0 | G6: 0 | H6: 0 | I6: 0 | J6: 0 | K6: 0 | L6: =+B6+D6+F6+H6+J6 -> 5 | M6: =+C6+E6+G6+I6+K6 -> 565
A7: TikTok | B7: 45 | C7: 7355.65 | D7: 3 | E7: 432.5 | F7: 0 | G7: 0 | H7: 0 | I7: 0 | J7: 0 | K7: 0 | L7: =+B7+D7+F7+H7+J7 -> 48 | M7: =+C7+E7+G7+I7+K7 -> 7788.15
A8: Facebook , Facebook Live , Line , Line OA (ไปรษณีย์) | B8: 5 | C8: 859 | D8: 1 | E8: 179 | F8: 0 | G8: 0 | H8: 0 | I8: 0 | J8: 0 | K8: 0 | L8: =+B8+D8+F8+H8+J8 -> 6 | M8: =+C8+E8+G8+I8+K8 -> 1038
A9: ยอมรวมทั้งหมด | B9: =SUM(B5:B8) -> 62 | C9: =SUM(C5:C8) -> 10549.61 | D9: =SUM(D5:D8) -> 5 | E9: =SUM(E5:E8) -> 727.5 | F9: =SUM(F5:F8) -> 0 | G9: =SUM(G5:G8) -> 0 | H9: =SUM(H5:H8) -> 0 | I9: =SUM(I5:I8) -> 0 | ... M9: =SUM(M5:M8) -> 11277.11 | N9: บาท

Sheet สรุปรายการสินค้า
A1: สรุปรายการสินค้าที่ตีกลับมารวมทุกช่องทางขายออนไลน์ เดือนมีนาคม 69
A2: ลำดับ | B2: รายการ | C2: จำนวน | D2: หมายเหตุ
A3: 1 | B3: ชิฟฟอนแยกชิ้น (ไม่ไส้) | C3: =+รายการสินค้าตีกลับ!B35 -> 0
A4: 2 | B4: ชิฟฟอนแยกชิ้น (ไส้) | C4: =+รายการสินค้าตีกลับ!C35 -> 0
A5: 3 | B5: ชิฟฟอน 8 ชิ้น (ชมพู) | C5: =+รายการสินค้าตีกลับ!D35 -> 18
A6: 4 | B6: ชิฟฟอนยอดฮิต | C6: =+รายการสินค้าตีกลับ!E35 -> 2
A7: 5 | B7: ชิฟฟอนไส้แยม 6 ชิ้น | C7: =+รายการสินค้าตีกลับ!F35 -> 5
A8: 6 | B8: ชิฟฟอน 4 ชิ้น | C8: =+รายการสินค้าตีกลับ!G35 -> 0
A9: 7 | B9: ชิฟฟอนไส้แยม 3 ชิ้น | C9: =+รายการสินค้าตีกลับ!I35 -> 165
A10: 8 | B10: เบาหวิว ล | C10: =+รายการสินค้าตีกลับ!J35 -> 0
A11: 9 | B11: เปี๊ยะ 450 กรัม | C11: =+รายการสินค้าตีกลับ!L35 -> 0
A12: 10 | B12: เค้กหวิวถาด | C12: =+รายการสินค้าตีกลับ!M35 -> 0
A13: 11 | B13: เปี๊ยะ ล | C13: =+รายการสินค้าตีกลับ!N35 -> 0
A14: 12 | B14: เปี๊ยะโมจิ ล | C14: =+รายการสินค้าตีกลับ!O35 -> 0
A15: 13 | B15: เปี๊ยะ ญ | C15: =+รายการสินค้าตีกลับ!P35 -> 0
A16: 14 | B16: เปี๊ยะโมจิ ญ | C16: =+รายการสินค้าตีกลับ!Q35 -> 0
A17: 15 | B17: พายสัปรด กล่อง | C17: 0
A18: 16 | B18: พายสัปรด ชิ้น | C18: 0
A19: 17 | B19: คุกกี้เนย | C19: =+รายการสินค้าตีกลับ!R35 -> 0
A20: 18 | B20: คุกกี้เนย 4 ชิ้น/กล่อง | C20: =+รายการสินค้าตีกลับ!S35 -> 0
A21: 19 | B21: ปังกรอบคาราเมล | C21: 0
A22: 20 | B22: ปังเนยน้ำตาล | C22: 0
A23: 21 | B23: ปังเนยนิ่ม กล่อง 2 ชิ้น | C23: 0
A24: 22 | B24: ปังเนยนิ่ม กล่อง 3 ชิ้น | C24: 0
A25: 23 | B25: ปังเนยนิ่มถุง5ชิ้น | C25: 0
A26: 24 | B26: ปังสตรอบูล | C26: 0
A27: 25 | B27: ปังไก่หยอง | C27: 0
A28: 26 | B28: ปังทวิต | C28: 0
A29: 27 | B29: ปังแถว | C29: =+รายการสินค้าตีกลับ!Y35 -> 0
A30: 28 | B30: คอนเฟล็ก | C30: 0
A31: 29 | B31: เมอแรงค์ | C31: 0
A32: 30 | B32: ท๊อฟฟี่ถั่ว กล่อง | C32: 0
A33: 31 | B33: แซนวิส | C33: 0
A34: 32 | B34: ปังปลา กก. | C34: 0
A35: 33 | B35: เศษขนมปังปลา | C35: =+รายการสินค้าตีกลับ!AC35 -> 1
A36: 34 | B36: ครีมฮอร์น | C36: =+รายการสินค้าตีกลับ!AD35 -> 0
A37: 35
A38: 36
B39: ยอดรวม | C39: =SUM(C3:C38) -> 191 | D39: ชิ้น

Sheet จำนวนกล่องตีกลับ
A1: สรุปรายการสินค้าที่ตีกลับมานับเป็นจำนวน (กล่อง) เดือนมีนาคม 2569
A2: ของตีกลับ
A3: วันที่ | B3: จำนวนกล่อง
B4: lazada | C4: shopee | D4: tiktok | E4: ปณ
A5: 1
A6: 2
A7: 3 | D7: 1
A8: 4 | C8: 1 | D8: 6
A9: 5 | D9: 5
A10: 6 | D10: 4
A11: 7 | B11: 1 | D11: 1
A12: 8 | B12: 1 | D12: 3
A13: 9
A14: 10 | D14: 1
A15: 11 | B15: 1 | C15: 2 | D15: 3 | E15: 1
A16: 12 | B16: 1 | D16: 1
A17: 13
A18: 14
A19: 15 | C19: 2 | D19: 1
A20: 16
A21: 17
A22: 18 | D22: 2
A23: 19 | B23: 1
A24: 20 | D24: 1
A25: 21
A26: 22 | B26: 1 | D26: 2 | E26: 2
A27: 23 | B27: 2 | E27: 1
A28: 24 | D28: 6
A29: 25 | E29: 1
A30: 26 | D30: 2
A31: 27 | D31: 2
A32: 28
A33: 29 | D33: 3
A34: 30 | D34: 2
A35: 31 | D35: 3
A36: รวม | B36: =SUM(B5:B35) -> 8 | C36: =SUM(C5:C35) -> 5 | D36: =SUM(D5:D35) -> 49 | E36: =SUM(E5:E35) -> 5 | F36: กล่อง

Sheet Lazada
A1: รายการของตีกลับช่องทาง LAZADA เดือนมีนาคม 2569 | H1: รวม | I1: =SUBTOTAL(9,I4:I11989) -> 1885.96 | J1: บาท
A2: ลำดับ | B2: วันที่ตีกลับ | C2: เลขที่ออเดอร์ | D2: เลขที่พัสดุ | E2: ผู้ให้บริการจัดส่ง | F2: ร้านค้า | G2: ชื่อลูกค้า | I2: ยอดคำสั่งซื้อ | J2: สาเหตุการตีกลับ | K2: หมายเหตุ | N2: หัวข้อการสาเหตุตีของกลับ | O2: ชื่อร้าน | P2: ชื่อขนส่ง
G3: ชื่อ | H3: นามสกุล
A4: 1 | B4: 244533 | C4: 1087036732966013 | D4: LEXPU0662518508 | E4: LEX TH | F4: วรรณวนัช (0944831646)ร้าน 3 | G4: ศิริวรรณ | H4: เจริญดี | I4: 266.8 | J4: ปฏิเสธ , ยกเลิก | N4: ปฏิเสธ , ยกเลิก | O4: วรรณวนัช เบเกอรี่ (ร้านที่ 1 ร้านหลัก) | P4: LEX TH
A5: 2 | B5: 244564 | C5: 1080428490724023 | D5: LEXPU0664503546 | E5: LEX TH | F5: วรรณวนัช (0944831646)ร้าน 3 | G5: ภูผา | I5: 529.18 | J5: ปฏิเสธ , ยกเลิก | N5: ติดต่อไม่ได้ , ไม่รับโทรศัพท์ | O5: ของฝากวรรณวนัช (cakewanwanach.lzd) | P5: Flash Express Thailand
A6: 3 | B6: 244656 | C6: 1079016837968444 | D6: LEXPU0662576121 | E6: LEX TH | F6: วรรณวนัช (0944831646)ร้าน 3 | G6: ธนกฤต | H6: เงินถ้วน | I6: 155 | J6: ปฏิเสธ , ยกเลิก | N6: ส่งของไปซ้ำ | O6: วรรณวนัช ชิฟฟ่อน (chiffonlazada) | P6: Kerry_dropoff
A7: 4 | B7: 244686 | C7: 1086019194353575 | D7: LEXPU0661369635 | E7: LEX TH | F7: วรรณวนัช (0944831646)ร้าน 3 | G7: โชคชัยตั้งพงษ์จำเริญ | I7: 211.5 | J7: ปฏิเสธ , ยกเลิก | N7: ลูกค้าแจ้งว่าไม่ได้สั่ง | O7: วรรณวนัช (0944831646)ร้าน 3
A8: 5 | B8: 19/3/2569 | C8: 1090528787865523 | D8: LEXPU0667338697 | E8: LEX TH | F8: วรรณวนัช (0944831646)ร้าน 3 | G8: อุมา | H8: นุชหมอน | I8: 195.48 | J8: ปฏิเสธ , ยกเลิก | O8: ชิฟฟ่อน กำแพงแสน (chiffonk.kps) ร้าน 6
A9: 6 | B9: 22/3/2569 | C9: 1090876909312542 | D9: LEXPU0668043403 | E9: LEX TH | F9: วรรณวนัช (0944831646)ร้าน 3 | G9: วราภรณ์ | H9: ชะเวียตะคุ | I9: 111 | J9: ปฏิเสธ , ยกเลิก | O9: วรรณวนัช ของอร่อย (cakewanwanach.kps) ร้าน 8
A10: 7 | B10: 23/3/69 | C10: 1090465507232339 | D10: LEXPU0667332536 | E10: LEX TH | F10: วรรณวนัช (0944831646)ร้าน 3 | G10: ถิระธนา | H10: วรรณรัตน์ | I10: 154 | J10: ปฏิเสธ , ยกเลิก | O10: ของฝาก นครปฐม (khongfhak.kps)
A11: 8 | B11: 23/3/69 | C11: 1082362887132339 | D11: LEXPU0667421991 | E11: LEX TH | F11: วรรณวนัช เบเกอรี่ (ร้านที่ 1 ร้านหลัก) | G11: ถิระธนา | H11: วรรณรัตน์ | I11: 263 | J11: ปฏิเสธ , ยกเลิก | O11: วรรณวนัช ไทยแลนด์ (chiffon.kps)
O12: ของอร่อยกำแพงแสน (kahnomcake.lzd)ร้าน 9
O13: ชิฟฟ่อน เบเกอรี่ (wanwanachcake)ร้าน 10

Sheet Shopee
A1: รายการของตีกลับช่องทาง SHOPEE เดือนมีนาคม 2569 | H1: รวม | I1: =SUBTOTAL(9,I4:I12000) -> 116 | J1: บาท
A2: ลำดับ | B2: วันที่ตีกลับ | C2: เลขที่ออเดอร์ | D2: เลขที่พัสดุ | E2: ผู้ให้บริการจัดส่ง | F2: ร้านค้า | G2: ชื่อลูกค้า | I2: ยอดคำสั่งซื้อ | J2: สาเหตุการตีกลับ | K2: หมายเหตุ | M2: หัวข้อการสาเหตุตีของกลับ | N2: ชื่อร้าน | O2: ชื่อขนส่ง
G3: ชื่อ | H3: นามสกุล
A4: 1 | B4: 244442 | C4: 260226QAXAPQD0 | D4: TH265354556583I | E4: SPX Express | F4: ร้านที่ 1 | I4: 116 | J4: ติดต่อไม่ได้ , ไม่รับโทรศัพท์ | M4: ปฏิเสธ , ยกเลิก | N4: ร้านที่ 1 | O4: LEX TH
A5: 2 | B5: 244656 | C5: 2603059VJBAJPR | D5: TH30048EVXST7I | E5: SPX Express | F5: ร้านที่ 1 | I5: 107 | J5: ปฏิเสธ , ยกเลิก | M5: ติดต่อไม่ได้ , ไม่รับโทรศัพท์ | N5: ร้านที่ 2 | O5: Flash Express Thailand
A6: 3 | B6: 244656 | C6: 260307H8U6G932 | D6: TH269519118585Y | E6: SPX Express | F6: ร้านที่ 1 | I6: 129 | J6: ปฏิเสธ , ยกเลิก | M6: ส่งของไปซ้ำ | O6: Kerry_dropoff
A7: 4 | B7: 15/3/2569 | C7: 260308KRXUEUMD | D7: TH2620483405266 | E7: SPX Express | F7: ร้านที่ 1 | I7: 104 | J7: ปฏิเสธ , ยกเลิก | M7: ลูกค้าแจ้งว่าไม่ได้สั่ง | O7: J&T
A8: 5 | B8: 15/3/2570 | C8: 260311STVQU3AQ | D8: TH269105667383P | E8: SPX Express | F8: ร้านที่ 1 | I8: 159 | J8: ปฏิเสธ , ยกเลิก | O8: SPX Express
A9: 6
A10: 7
A12: ** NOTE | B12: ชื่อลูกค้า ไม่มีในข้อมูล Shopee

Sheet TikTok
A1: รายการของตีกลับช่องทาง TikTok เดือนมีนาคม 2569 | H1: รวม | I1: =SUBTOTAL(9,I4:I12000) -> 432.5 | J1: บาท
A2: ลำดับ | B2: วันที่ตีกลับ | C2: เลขที่ออเดอร์ | D2: เลขที่พัสดุ | E2: ผู้ให้บริการจัดส่ง | F2: ร้านค้า | G2: ชื่อลูกค้า | I2: ยอดคำสั่งซื้อ | J2: สาเหตุการตีกลับ | K2: หมายเหตุ | M2: หัวข้อการสาเหตุตีของกลับ | N2: ชื่อร้าน | O2: ชื่อขนส่ง
G3: ชื่อ | H3: นามสกุล
A4: 1 | B4: 244411 | C4: 582764106280502451 | D4: 792232958602 | E4: J&T Express | F4: วรรณวนัชเบเกอรี่ (พี่กุ๊ก) | I4: 99 | J4: ปฏิเสธ | M4: ปฏิเสธ , ยกเลิก | N4: วรรณวนัชเบเกอรี่ (พี่กุ๊ก) | O4: LEX TH
A5: 2 | B5: 244442 | C5: 582774387214485490 | D5: 792263196093 | E5: J&T Express | F5: วรรณวนัชเบเกอรี่ (พี่กุ๊ก) | I5: 181 | J5: ปฏิเสธ | M5: ติดต่อไม่ได้ , ไม่รับโทรศัพท์ | N5: วรรณวนัช เบเกอรี่ (แอม) | O5: Flash Express Thailand
A6: 3 | B6: 244442 | C6: 582753777314727026 | D6: 792177391014 | E6: J&T Express | F6: วรรณวนัชเบเกอรี่ (พี่กุ๊ก) | I6: 120 | J6: ปฏิเสธ | M6: ส่งของไปซ้ำ | N6: วรรณวนัช โรงงานจำหน่ายโดยตรง (นุ่น) | O6: Kerry_dropoff
A7: 4 | B7: 244442 | C7: 582709299491931268 | D7: 792046079764 | E7: J&T Express | F7: วรรณวนัชเบเกอรี่ (พี่กุ๊ก) | I7: 186 | J7: ปฏิเสธ | M7: ลูกค้าแจ้งว่าไม่ได้สั่ง | N7: ของฝากวรรณวนัช By:แอดอั้ม (อั้ม) | O7: J&T Express
A8: 5 | B8: 244442 | C8: 582773812778533955 | D8: 792374626153 | E8: J&T Express | F8: วรรณวนัชเบเกอรี่ (พี่กุ๊ก) | I8: 178 | J8: ปฏิเสธ | M8: เกินเวลานัดรับพัสดุ | N8: ชิฟฟ่อนเค้กวรรณวนัช (พี่เอฟ)
A9: 6 | B9: 244442 | C9: 582793928442808215 | D9: 792378665691 | E9: J&T Express | F9: วรรณวนัชเบเกอรี่ (พี่กุ๊ก) | I9: 139 | J9: ปฏิเสธ | M9: เบอร์ผิด
A10: 7 | B10: 244442 | C10: 582783396804200226 | D10: 792298179035 | E10: J&T Express | F10: วรรณวนัชเบเกอรี่ (พี่กุ๊ก) | I10: 181 | J10: ปฏิเสธ
A11: 8 | B11: 244472 | C11: 582856457971205159 | D11: 792536555495 | E11: J&T Express | F11: วรรณวนัชเบเกอรี่ (พี่กุ๊ก) | I11: 181 | J11: ปฏิเสธ
A12: 9 | B12: 244472 | C12: 582851359220860251 | D12: 792559368403 | E12: J&T Express | F12: วรรณวนัชเบเกอรี่ (พี่กุ๊ก) | I12: 200 | J12: ปฏิเสธ
A13: 10 | B13: 244472 | C13: 582798740460176995 | D13: 792389315664 | E13: J&T Express | F13: วรรณวนัชเบเกอรี่ (พี่กุ๊ก) | I13: 166.52 | J13: ปฏิเสธ
A14: 11 | B14: 244472 | C14: 582851351936730459 | D14: 792561860473 | E14: J&T Express | F14: วรรณวนัชเบเกอรี่ (พี่กุ๊ก) | I14: 200 | J14: ปฏิเสธ
A15: 12 | B15: 244472 | C15: 582815321285232182 | D15: 792426596275 | E15: J&T Express | F15: วรรณวนัชเบเกอรี่ (พี่กุ๊ก) | I15: 129 | J15: ปฏิเสธ
A16: 13 | B16: 244503 | C16: 582847219098551643 | D16: 792573549423 | E16: J&T Express | F16: วรรณวนัชเบเกอรี่ (พี่กุ๊ก) | I16: 360 | J16: ปฏิเสธ
A17: 14 | B17: 244503 | C17: 582788689343121050 | D17: 792323946212 | E17: J&T Express | F17: วรรณวนัชเบเกอรี่ (พี่กุ๊ก) | I17: 100 | J17: ติดต่อไม่ได้ , ไม่รับโทรศัพท์
A18: 15 | B18: 244503 | C18: 582817404945925445 | D18: 792420740355 | E18: J&T Express | F18: วรรณวนัชเบเกอรี่ (พี่กุ๊ก) | I18: 176 | J18: ปฏิเสธ
A19: 16 | B19: 244503 | C19: 582775971712304194 | D19: 792285186033 | E19: J&T Express | F19: วรรณวนัชเบเกอรี่ (พี่กุ๊ก) | I19: 99 | J19: ปฏิเสธ
A20: 17 | B20: 244564 | C20: 582887848378664550 | D20: 792673802896 | E20: J&T Express | F20: วรรณวนัชเบเกอรี่ (พี่กุ๊ก) | I20: 176 | J20: ปฏิเสธ
A21: 18 | B21: 244564 | C21: 582887830868035174 | D21: 792636105800 | E21: J&T Express | F21: วรรณวนัชเบเกอรี่ (พี่กุ๊ก) | I21: 176 | J21: ปฏิเสธ
... A27: 24 | B27: 244686 | C27: 582964436574635447 | D27: 792995491142 | E27: J&T Express | F27: วรรณวนัชเบเกอรี่ (พี่กุ๊ก) | I27: 181 | J27: ปฏิเสธ
A28: 25 | B28: 15/3/2569 | C28: 582977055275911137 | D28: 792940730794 | E28: J&T Express | F28: วรรณวนัชเบเกอรี่ (พี่กุ๊ก) | I28: 195 | J28: ปฏิเสธ
A29: 26 | B29: 18/3/2569 | C29: 582953934471858135 | D29: 792968299196 | E29: J&T Express | F29: วรรณวนัชเบเกอรี่ (พี่กุ๊ก) | I29: 181 | J29: ปฏิเสธ
A30: 27 | B30: 18/3/2569 | C30: 582974677448426980 | D30: 792961920774 | E30: J&T Express | F30: วรรณวนัชเบเกอรี่ (พี่กุ๊ก) | I30: 181 | J30: ปฏิเสธ
A31: 28 | B31: 20/3/2569 | C31: 583059587749938673 | D31: 793288985484 | E31: J&T Express | F31: วรรณวนัชเบเกอรี่ (พี่กุ๊ก) | I31: 129 | J31: ปฏิเสธ
A32: 29 | B32: 22/3/2569 | C32: 583087197042673640 | D32: 793312218193 | E32: J&T Express | F32: วรรณวนัชเบเกอรี่ (พี่กุ๊ก) | I32: 181 | J32: ติดต่อไม่ได้ , ไม่รับโทรศัพท์
A33: 30 | B33: 22/3/2569 | C33: 583094177653425921 | D33: 793386582612 | E33: J&T Express | F33: วรรณวนัชเบเกอรี่ (พี่กุ๊ก) | I33: 180 | J33: ปฏิเสธ
A34: 31 | B34: 24/3/2569 | C34: 583165318212716221 | D34: 793676953436 | E34: J&T Express | F34: ของฝากวรรณวนัช By:แอดอั้ม (อั้ม) | I34: 100 | J34: ปฏิเสธ
A35: 32 | B35: 24/3/2569 | C35: 583097275166852728 | D35: 793301115843 | E35: J&T Express | F35: วรรณวนัชเบเกอรี่ (พี่กุ๊ก) | I35: 181 | J35: ปฏิเสธ
A36: 33 | B36: 24/3/2569 | C36: 583121739372463460 | D36: 793493663896 | E36: J&T Express | F36: วรรณวนัชเบเกอรี่ (พี่กุ๊ก) | I36: 192.31 | J36: ปฏิเสธ
A37: 34 | B37: 24/3/2569 | C37: 583135127952000389 | D37: 793529050300 | E37: J&T Express | F37: วรรณวนัชเบเกอรี่ (พี่กุ๊ก) | I37: 100 | J37: ปฏิเสธ
A38: 35 | B38: 24/3/2569 | C38: 583117188267738123 | D38: 793487882353 | E38: J&T Express | F38: วรรณวนัชเบเกอรี่ (พี่กุ๊ก) | I38: 78.2 | J38: ปฏิเสธ
A39: 36 | B39: 24/3/2569 | C39: 583165325114836669 | D39: 793689550463 | E39: J&T Express | F39: ของฝากวรรณวนัช By:แอดอั้ม (อั้ม) | I39: 100 | J39: ปฏิเสธ
... A51: 48 | B51: 31/3/2569 | C51: 583313664859015153 | D51: - | E51: J&T Express | F51: ของฝากวรรณวนัช By:แอดอั้ม (อั้ม) | I51: 151.5 | J51: ติดต่อไม่ได้ , ไม่รับโทรศัพท์
A52: 49
A53: 50
A54: 51
A55: 52
A56: 53
...

Sheet ไปรษณีย์
A1: รายการของตีกลับช่องทาง Facebook , Facebook Live , Line , Line OA (ไปรษณีย์) เดือนมีนาคม 2569 | H1: รวม | I1: =SUBTOTAL(9,I4:I11953) -> 179 | J1: บาท
A2: ลำดับ | B2: วันที่ตีกลับ | C2: เลขที่ออเดอร์ | D2: เลขที่พัสดุ | E2: ผู้ให้บริการจัดส่ง | F2: ร้านค้า | G2: ชื่อลูกค้า | I2: ยอดคำสั่งซื้อ | J2: สาเหตุการตีกลับ | K2: หมายเหตุ | M2: หัวข้อการสาเหตุตีของกลับ | N2: ร้านค้า | O2: ชื่อขนส่ง
G3: ชื่อ | H3: นามสกุล
A4: 1 | B4: 244533 | C4: GVM92 | D4: WA095601113TH | E4: ไปรษณีย์ไทย | F4: Facebook | G4: พี่เจี๊ยบ | I4: 150 | J4: เกินเวลานัดรับ | M4: ปฏิเสธ , ยกเลิก | N4: Facebook | O4: LEX TH
A5: 2 | B5: 244656 | C5: GVX32 | D5: WA097150853TH | E5: ไปรษณีย์ไทย | F5: Facebook | G5: วชิ | H5: วชิ | I5: 215 | J5: ปฏิเสธ , ยกเลิก | M5: ติดต่อไม่ได้ , ไม่รับโทรศัพท์ | N5: Facebook Live | O5: Flash Express Thailand
A6: 3 | B6: 22/3/2569 | C6: GXB33 | D6: WA107827880TH | E6: ไปรษณีย์ไทย | F6: Facebook | G6: แมวเหมียว | I6: 179 | J6: ปฏิเสธ , ยกเลิก | M6: ส่งของไปซ้ำ | N6: Line | O6: Kerry_dropoff
A7: 4 | B7: 22/3/2569 | C7: GWZ25 | D7: WA107604627TH | E7: ไปรษณีย์ไทย | F7: Facebook | G7: ส่งร้านครัวเม็ดทราย | I7: 100 | J7: ปฏิเสธ , ยกเลิก | M7: ลูกค้าแจ้งว่าไม่ได้สั่ง | N7: Line OA | O7: J&T Express
A8: 5 | B8: 23/3/2569 | C8: GXB82 | D8: WA107827805TH | E8: ไปรษณีย์ไทย | F8: Facebook | G8: วิศิษฐ์ | H8: ธรรมศรีสวัสดิ์ | I8: 179 | J8: ติดต่อไม่ได้ , ไม่รับโทรศัพท์ | M8: ลูกค้าตีกลับ เนื่องจาก มดขึ้นขนม ขนมมีรสฟาดเฟื่อน | N8: Phone | O8: ไปรษณีย์ไทย
A9: 6 | B9: 25/3/2569 | C9: GXP52 | D9: WA109567737TH | E9: ไปรษณีย์ไทย | F9: Facebook | G9: น.ส. กาญจนา | H9: อิ่มมา | I9: 215 | J9: ปฏิเสธ , ยกเลิก | M9: สลิปปลอม
M10: เกินเวลานัดรับ

Sheet รายการสินค้าตีกลับ
A1: รายการสินค้าที่ตีกลับมารวมทุกช่องทางขายออนไลน์ เดือนมีนาคม 2569
A2: วันที่ | B2: สินค้าที่ตีกลับ | AE2: ยอดรวม/วัน (ทุกรายการ)
B3: ชิฟฟอนแยกชิ้น (ไม่ไส้) | C3: ชิฟฟอนแยกชิ้น (ไส้) | D3: ชิฟฟอน 8 ชิ้น (ชมพู) | E3: ชิฟฟอนยอดฮิต | F3: ชิฟฟอนไส้แยม 6 ชิ้น | G3: ชิฟฟอน 4 ชิ้น | H3: ชิฟฟอนไส้ 3 ชิ้น | I3: เบาหวิว ล | J3: เบาหวิว ญ | K3: เปี๊ยะ 450 กรัม | L3: เค้กหวิวถาด | M3: เปี๊ยะ ล | N3: เปี๊ยะโมจิ ล | O3: เปี๊ยะ ญ | P3: เปี๊ยะโมจิ ญ | Q3: คุกกี้เนย | R3: คุกกี้เนย 4 ชิ้น/กล่อง | S3: ปังเนยน้ำตาล | T3: ปังพิซซ่า | U3: ปังสตรอบูล | V3: ปังไก่หยอง | W3: ปังทวิต | X3: ปังแถว | Y3: คอนเฟล็ก | Z3: คุกกี้ฮ่องกง(ชิ้น) | AA3: แซนวิส | AB3: เศษขนมปังปลา | AC3: ครีมฮอร์น | AD3: ครีมฮอร์น
A4: 244409 | AE4: =SUM(B4:AD4) -> 0
A5: 244410 | AE5: =SUM(B5:AD5) -> 0
A6: 244411 | K6: 1 | AE6: =SUM(B6:AD6) -> 1
A7: 244412 | D7: 2 | I7: 18 | K7: 1 | AB7: 5 | AE7: =SUM(B7:AD7) -> 26
A8: 244413 | I8: 24 | K8: 1 | AE8: =SUM(B8:AD8) -> 25
A9: 244414 | D9: 6 | H9: 3 | K9: 1 | AE9: =SUM(B9:AD9) -> 10
A10: 244415 | D10: 3 | I10: 3 | AE10: =SUM(B10:AD10) -> 6
A11: 244416 | D11: 6 | I11: 3 | K11: 5 | AE11: =SUM(B11:AD11) -> 14
A12: 244417 | AE12: =SUM(B12:AD12) -> 0
A13: 244418 | K13: 1 | AE13: =SUM(B13:AD13) -> 1
A14: 244419 | H14: 3 | I14: 15 | K14: 3 | AE14: =SUM(B14:AD14) -> 21
A15: 244420 | E15: 1 | F15: 1 | I15: 6 | AE15: =SUM(B15:AD15) -> 8
A16: 244421 | AE16: =SUM(B16:AD16) -> 0
A17: 244422 | AE17: =SUM(B17:AD17) -> 0
A18: 244423 | I18: 3 | K18: 2 | AE18: =SUM(B18:AD18) -> 5
A19: 244424 | AE19: =SUM(B19:AD19) -> 0
A20: 244425 | AE20: =SUM(B20:AD20) -> 0
A21: 244426 | I21: 12 | AE21: =SUM(B21:AD21) -> 12
A22: 244427 | D22: 1 | E22: 1 | F22: 1 | AE22: =SUM(B22:AD22) -> 3
A23: 244428 | K23: 1 | AE23: =SUM(B23:AD23) -> 1
A24: 244429 | AE24: =SUM(B24:AD24) -> 0
A25: 244430 | I25: 12 | K25: 1 | T25: 3 | Z25: 2 | AE25: =SUM(B25:AD25) -> 18
A26: 244431 | K26: 3 | Z26: 2 | AE26: =SUM(B26:AD26) -> 5
A27: 244432 | I27: 21 | T27: 3 | AE27: =SUM(B27:AD27) -> 24
A28: 244433 | K28: 2 | AE28: =SUM(B28:AD28) -> 2
A29: 244434 | I29: 12 | AE29: =SUM(B29:AD29) -> 12
A30: 244435 | I30: 6 | AE30: =SUM(B30:AD30) -> 6
A31: 244436 | AE31: =SUM(B31:AD31) -> 0
A32: 244437 | F32: 3 | I32: 12 | AE32: =SUM(B32:AD32) -> 15
A33: 244438 | I33: 6 | K33: 1 | AE33: =SUM(B33:AD33) -> 7
A34: 244439 | I34: 12 | AB34: 1 | AC34: 1 | AE34: =SUM(B34:AD34) -> 14
A35: รวม | B35: =SUM(B4:B34) -> 0 | C35: =SUM(C4:C34) -> 0 | D35: =SUM(D4:D34) -> 18 | E35: =SUM(E4:E34) -> 2 | F35: =SUM(F4:F34) -> 5 | G35: =SUM(G4:G34) -> 0 | H35: =SUM(H4:H34) -> 6 | I35: =SUM(I4:I34) -> 165 | ... N35: =SUM(N4:N34) -> 0 | O35: =SUM(P4:P25) -> 0 | P35: =SUM(P4:P34) -> 0 | Q35: =SUM(Q4:Q34) -> 0 | R35: =SUM(R4:R34) -> 0 | S35: =SUM(S4:S34) -> 0 | T35: =SUM(T4:T34) -> 6 | U35: =SUM(U4:U34) -> 0 | V35: =SUM(V4:V34) -> 0 | W35: =SUM(W4:W34) -> 0 | ... AC35: =SUM(AC4:AC34) -> 1 | AE35: =SUM(B35:AC35) -> 236
