Workbook

Sheet สรุป
A1: ข้อมูลการเก็บเงินปลายทาง (COD) ปี 2567
A2: เดือน | B2: Total Order / จำนวนออเดอร์ | C2: COD Amount / ยอดรวม COD | D2: Deduct | E2: Total Amount / ยอดรวม COD | G2: ยอดลดหนี้ COD
A3: มกราคม | B3: =+'Summary ม.ค.'!G42 -> 1173 | C3: =+'Summary ม.ค.'!H42 -> 499912 | D3: =+'Summary ม.ค.'!I42 -> 0 | E3: =+'Summary ม.ค.'!J42 -> 499912 | G3: =+[1]สรุป!$B$3 -> 14096
A4: กุมภาพันธ์ | B4: =+'Summary ก.พ.'!G36 -> 827 | C4: =+'Summary ก.พ.'!H36 -> 274032 | D4: =+'Summary ก.พ.'!I36 -> 0 | E4: =+'Summary ก.พ.'!J36 -> 274032 | G4: =+[1]สรุป!$B$4 -> 12471
A5: มีนาคม | B5: =+'Summary มี.ค.'!G36 -> 870 | C5: =+'Summary มี.ค.'!H36 -> 201150 | D5: =+'Summary มี.ค.'!I36 -> 0 | E5: =+'Summary มี.ค.'!J36 -> 201150 | G5: =+[1]สรุป!$B$5 -> 13643
A6: เมษายน | B6: =+'Summary เม.ย.'!G44 -> 470 | C6: =+'Summary เม.ย.'!H44 -> 131334 | D6: =+'Summary เม.ย.'!I44 -> 0 | E6: =+'Summary เม.ย.'!J44 -> 131334 | G6: =+[1]สรุป!$B$6 -> 9603
A7: พฤษภาคม | B7: 152 | C7: =+'Summary พ.ค.'!H34 -> 45005 | D7: =+'Summary พ.ค.'!I34 -> 0 | E7: =+'Summary พ.ค.'!J34 -> 45005 | G7: =+[1]สรุป!$B$7 -> 2369
A8: มิถุนายน | B8: =+'Summary มิ.ย.'!G33 -> 551 | C8: =+'Summary มิ.ย.'!H33 -> 127508 | D8: =+'Summary มิ.ย.'!I33 -> 0 | E8: =+'Summary มิ.ย.'!J33 -> 127508 | G8: =+[1]สรุป!$B$8 -> 5332
A9: กรกฎาคม | B9: =+'Summary ก.ค.'!G34 -> 938 | C9: =+'Summary ก.ค.'!H34 -> 190115 | D9: =+'Summary มิ.ย.'!I33 -> 0 | E9: =+'Summary ก.ค.'!J34 -> 190115 | G9: =+[1]สรุป!$B$9 -> 1402
A10: สิงหาคม | B10: =+'Summary ส.ค.'!G35 -> 2290 | C10: =+'Summary ส.ค.'!H35 -> 437163 | D10: =+'Summary ส.ค.'!I35 -> 0 | E10: =+'Summary ส.ค.'!J35 -> 437163 | G10: 0
A11: กันยายน | B11: =+'Summary ก.ย.'!G35 -> 1273 | C11: =+'Summary ก.ย.'!H35 -> 230753 | D11: =+'Summary ก.ย.'!I35 -> 0 | E11: =+'Summary ก.ย.'!J35 -> 230753 | G11: =+[2]สรุป!$B$11 -> 27460
A12: ตุลาคม | B12: =+'Summary ต.ค.'!G35 -> 1023 | C12: =+'Summary ต.ค.'!H35 -> 193223 | D12: =+'Summary ต.ค.'!I35 -> 0 | E12: =+'Summary ต.ค.'!J35 -> 193223 | G12: =+[2]สรุป!$B$12 -> 12130
A13: พฤศจิกายน | B13: =+'Summary พ.ย.'!G35 -> 229 | C13: =+'Summary พ.ย.'!H35 -> 69835 | D13: =+'Summary พ.ย.'!I35 -> 0 | E13: =+'Summary พ.ย.'!J35 -> 69835 | G13: =+[2]สรุป!$B$13 -> 6680
A14: ธันวาคม | B14: =+'Summary ธ.ค.'!G35 -> 212 | C14: =+'Summary ธ.ค.'!H35 -> 93577.5 | D14: =+'Summary ธ.ค.'!I35 -> 0 | E14: =+'Summary ธ.ค.'!J35 -> 93577.5 | G14: =+[2]สรุป!$B$14 -> 2100
A15: ยอดรวม | B15: =SUM(B3:B14) -> 10008 | C15: =SUM(C3:C14) -> 2493607.5 | D15: =SUM(D3:D14) -> 0 | E15: =SUM(E3:E14) -> 2493607.5 | F15: บาท | G15: =SUM(G3:G14) -> 107286

Sheet ธ.ค.
A1: ข้อมูลการเก็บเงินปลายทาง (COD) แบบแยกรายละเอียด เดือนธันวาคม 2567
A2: ลำดับ | B2: วันที่ | C2: Email | D2: Facebook Page | E2: Order No. / เลขที่ออเดอร์ | F2: Tracking No. / เลขพัสดุ | G2: recipientName / ชื่อลูกค้า | H2: Amount / ยอด COD
A3: 1 | B3: 243953 | C3: suckjakkure@hotmail.com | D3: FACEBOOK | F3: JA101594895TH | G3: อาภาศิริ นิลถนอม | H3: 228
A4: 2 | B4: 243953 | C4: suckjakkure@hotmail.com | D4: FACEBOOK | F4: JA101231051TH | G4: ภทรชนก ศรีวิลัย | H4: 130
A5: 3 | B5: 243953 | C5: suckjakkure@hotmail.com | D5: FACEBOOK | F5: JA100986440TH | G5: สังวาลย์ โพธิ์เย็น | H5: 230
A6: 4 | B6: 243953 | C6: suckjakkure@hotmail.com | D6: FACEBOOK | F6: JA102033344TH | G6: งอร ผลคำสุข | H6: 230
A7: 5 | B7: 243955 | C7: suckjakkure@hotmail.com | D7: FACEBOOK | F7: JA102352475TH | G7: ดานี. วัชราเกียรติ | H7: 230
A8: 6 | B8: 243955 | C8: suckjakkure@hotmail.com | D8: FACEBOOK | F8: JA102033392TH | G8: จตุพร นาชัยพูล | H8: 230
A9: 7 | B9: 243955 | C9: suckjakkure@hotmail.com | D9: FACEBOOK | F9: JA102033361TH | G9: มรรยาท ศรีเศรษฐนิล | H9: 430
A10: 8 | B10: 243955 | C10: suckjakkure@hotmail.com | D10: FACEBOOK | F10: JA102352498TH | G10: ปัญญวลัญญ์. อุนทะอ่อน. | H10: 160
A11: 9 | B11: 243955 | C11: suckjakkure@hotmail.com | D11: FACEBOOK | F11: JA102352515TH | G11: สุภาพร จุติชัย | H11: 230
A12: 10 | B12: 243955 | C12: suckjakkure@hotmail.com | D12: FACEBOOK | F12: JA102352484TH | G12: วิลาวรรณ คุณวิวัฒน์ | H12: 230
A13: 11 | B13: 243955 | C13: suckjakkure@hotmail.com | D13: FACEBOOK | F13: JA102352538TH | G13: นงนุช ตันติวรสิทธิ์ | H13: 230
A14: 12 | B14: 243955 | C14: suckjakkure@hotmail.com | D14: FACEBOOK | F14: JA100986232TH | G14: หิรัณญ์ชกรณ์ สุขสอาด | H14: 230
... A207: 205 | B207: 243982 | C207: suckjakkure@hotmail.com | D207: FACEBOOK | F207: JA111323115TH | G207: ถนอมศรี ศรีสังข์ | H207: 280
A208: 206 | B208: 243983 | C208: suckjakkure@hotmail.com | D208: FACEBOOK | F208: TH29036MNCM91A | G208: Nw Srp 1 | H208: 1090.0
A209: 207 | B209: 243983 | C209: suckjakkure@hotmail.com | D209: FACEBOOK | F209: TH29036MNCMB2A | G209: Nw Srp 2 | H209: 1090.0
A210: 208 | B210: 243983 | C210: suckjakkure@hotmail.com | D210: FACEBOOK | F210: TH29036MNCMC0A | G210: Nw Srp 3 | H210: 1090.0
A211: 209 | B211: 243983 | C211: suckjakkure@hotmail.com | D211: FACEBOOK | F211: TH29036MNCMC4A | G211: Nw Srp 4 | H211: 1090.0
A212: 210 | B212: 243983 | C212: suckjakkure@hotmail.com | D212: FACEBOOK | F212: TH29036MNCME2A | G212: Nw Srp 5 | H212: 1090.0
A213: 211 | B213: 243983 | C213: suckjakkure@hotmail.com | D213: FACEBOOK | F213: JA111323013TH | G213: หยาด หยาด | H213: 280
G232: ยอดรวม | H232: =SUM(H3:H231) -> 87879.5 | I232: บาท

Sheet Summary ธ.ค.
B1: ข้อมูลการเก็บเงินปลายทาง (COD) แบบรวมยอดประจำวัน เดือนธันวาคม 2567 | K1: ตรวจในสเตทเม้น
A2: ลำดับ | B2: วันที่ | C2: Email | D2: Tel | E2: Bank Account Number / เลขที่บัญชี | F2: Bank Account Name / ชื่อธนาคาร | G2: Total Order / จำนวนออเดอร์ | H2: COD Amount / ยอดรวม COD | I2: Deduct | J2: Total Amount / ยอดรวม COD | K2: วันที่เงินเข้า | L2: ยอดเข้า | M2: หมายเหตุ
B3: 243953 | C3: suckjakkure@hotmail.com | D3: 0642427575 | E3: 4311469006 | F3: ธนาคารไทยพาณิชย์ (SCB) | G3: 4 | H3: 818 | I3: 0 | J3: 818 | K3: 243953 | L3: 818 | M3: =+L3-J3 -> 0
B4: 243954 | C4: ไม่มียอด COD | K4: 243954 | L4: 0 | M4: =+L4-J4 -> 0
B5: 243955 | C5: suckjakkure@hotmail.com | D5: 0642427575 | E5: 4311469006 | F5: ธนาคารไทยพาณิชย์ (SCB) | G5: 19 | H5: 6346 | I5: 0 | J5: 6346 | K5: 243955 | L5: 6346 | M5: =+L5-J5 -> 0
B6: 243956 | C6: suckjakkure@hotmail.com | D6: 0642427575 | E6: 4311469006 | F6: ธนาคารไทยพาณิชย์ (SCB) | G6: 12 | H6: 3656 | I6: 0 | J6: 3656 | K6: 243956 | L6: 3656 | M6: =+L6-J6 -> 0
B7: 243957 | C7: suckjakkure@hotmail.com | D7: 0642427575 | E7: 4311469006 | F7: ธนาคารไทยพาณิชย์ (SCB) | G7: 16 | H7: 4430 | I7: 0 | J7: 4430 | K7: 243957 | L7: 4430 | M7: =+L7-J7 -> 0
B8: 243958 | C8: suckjakkure@hotmail.com | D8: 0642427575 | E8: 4311469006 | F8: ธนาคารไทยพาณิชย์ (SCB) | G8: 3 | H8: 1090 | I8: 0 | J8: 1090 | K8: 243958 | L8: 1090 | M8: =+L8-J8 -> 0
B9: 243959 | C9: suckjakkure@hotmail.com | D9: 0642427575 | E9: 4311469006 | F9: ธนาคารไทยพาณิชย์ (SCB) | G9: 17 | H9: 5910 | I9: 0 | J9: 5910 | K9: 243959 | L9: 5910 | M9: =+L9-J9 -> 0
B10: 243960 | C10: suckjakkure@hotmail.com | D10: 0642427575 | E10: 4311469006 | F10: ธนาคารไทยพาณิชย์ (SCB) | G10: 4 | H10: 1078 | I10: 0 | J10: 1078 | K10: 243960 | L10: 1078 | M10: =+L10-J10 -> 0
B11: 243961 | C11: suckjakkure@hotmail.com | D11: 0642427575 | E11: 4311469006 | F11: ธนาคารไทยพาณิชย์ (SCB) | G11: 2 | H11: 610 | I11: 0 | J11: 610 | K11: 243961 | L11: 610 | M11: =+L11-J11 -> 0
B12: 243962 | C12: suckjakkure@hotmail.com | D12: 0642427575 | E12: 4311469006 | F12: ธนาคารไทยพาณิชย์ (SCB) | G12: 4 | H12: 1400 | I12: 0 | J12: 1400 | K12: 243962 | L12: 1400 | M12: =+L12-J12 -> 0
B13: 243963 | C13: suckjakkure@hotmail.com | D13: 0642427575 | E13: 4311469006 | F13: ธนาคารไทยพาณิชย์ (SCB) | G13: 3 | H13: 890 | I13: 0 | J13: 890 | K13: 243963 | L13: 890 | M13: =+L13-J13 -> 0
B14: 243964 | C14: suckjakkure@hotmail.com | D14: 0642427575 | E14: 4311469006 | F14: ธนาคารไทยพาณิชย์ (SCB) | G14: 5 | H14: 1150 | I14: 0 | J14: 1150 | K14: 243964 | L14: 1150 | M14: =+L14-J14 -> 0
B15: 243965 | C15: suckjakkure@hotmail.com | D15: 0642427575 | E15: 4311469006 | F15: ธนาคารไทยพาณิชย์ (SCB) | G15: 8 | H15: 2805 | I15: 0 | J15: 2805 | K15: 243965 | L15: 2805 | M15: =+L15-J15 -> 0
B16: 243966 | C16: suckjakkure@hotmail.com | D16: 0642427575 | E16: 4311469006 | F16: ธนาคารไทยพาณิชย์ (SCB) | G16: 8 | H16: 2820 | I16: 0 | J16: 2820 | K16: 243966 | L16: 2820 | M16: =+L16-J16 -> 0
... B19: 243969 | C19: suckjakkure@hotmail.com | D19: 0642427575 | E19: 4311469006 | F19: ธนาคารไทยพาณิชย์ (SCB) | G19: 3 | H19: 2190 | I19: 0 | J19: 2190 | K19: 243969 | L19: 2190 | M19: =+L19-J19 -> 0
B20: 243970 | C20: ไม่มียอด COD | K20: 243970 | L20: 0 | M20: =+L20-J20 -> 0
B21: 243971 | C21: suckjakkure@hotmail.com | D21: 0642427575 | E21: 4311469006 | F21: ธนาคารไทยพาณิชย์ (SCB) | G21: 1 | H21: 780 | I21: 0 | J21: 780 | K21: 243971 | L21: 780 | M21: =+L21-J21 -> 0
B22: 243972 | C22: suckjakkure@hotmail.com | D22: 0642427575 | E22: 4311469006 | F22: ธนาคารไทยพาณิชย์ (SCB) | G22: 5 | H22: 2890 | I22: 0 | J22: 2890 | K22: 243972 | L22: 2890 | M22: =+L22-J22 -> 0
B23: 243973 | C23: suckjakkure@hotmail.com | D23: 0642427575 | E23: 4311469006 | F23: ธนาคารไทยพาณิชย์ (SCB) | G23: 6 | H23: 2380 | I23: 0 | J23: 2380 | K23: 243973 | L23: 2380 | M23: =+L23-J23 -> 0
B24: 243974 | C24: suckjakkure@hotmail.com | D24: 0642427575 | E24: 4311469006 | F24: ธนาคารไทยพาณิชย์ (SCB) | G24: 6 | H24: 1940 | I24: 0 | J24: 1940 | K24: 243974 | L24: 1940 | M24: =+L24-J24 -> 0
B25: 243975 | C25: suckjakkure@hotmail.com | D25: 0642427575 | E25: 4311469006 | F25: ธนาคารไทยพาณิชย์ (SCB) | G25: 1 | H25: 590 | I25: 0 | J25: 590 | K25: 243975 | L25: 590 | M25: =+L25-J25 -> 0
B26: 243976 | C26: suckjakkure@hotmail.com | D26: 0642427575 | E26: 4311469006 | F26: ธนาคารไทยพาณิชย์ (SCB) | G26: 8 | H26: 5170 | I26: 0 | J26: 5170 | K26: 243976 | L26: 5170 | M26: =+L26-J26 -> 0
B27: 243977 | C27: suckjakkure@hotmail.com | D27: 0642427575 | E27: 4311469006 | F27: ธนาคารไทยพาณิชย์ (SCB) | G27: 14 | H27: 7464 | I27: 0 | J27: 7464 | K27: 243977 | L27: 7464 | M27: =+L27-J27 -> 0
B28: 243978 | C28: suckjakkure@hotmail.com | D28: 0642427575 | E28: 4311469006 | F28: ธนาคารไทยพาณิชย์ (SCB) | G28: 9 | H28: 4160 | I28: 0 | J28: 4160 | K28: 243978 | L28: 4160 | M28: =+L28-J28 -> 0
B29: 243979 | C29: suckjakkure@hotmail.com | D29: 0642427575 | E29: 4311469006 | F29: ธนาคารไทยพาณิชย์ (SCB) | G29: 13 | H29: 8806 | I29: 0 | J29: 8806 | K29: 243979 | L29: 8806 | M29: =+L29-J29 -> 0
B30: 243980 | C30: suckjakkure@hotmail.com | D30: 0642427575 | E30: 4311469006 | F30: ธนาคารไทยพาณิชย์ (SCB) | G30: 14 | H30: 7518.5 | I30: 0 | J30: 7518.5 | K30: 243980 | L30: 7518.5 | M30: =+L30-J30 -> 0
B31: 243981 | C31: suckjakkure@hotmail.com | D31: 0642427575 | E31: 4311469006 | F31: ธนาคารไทยพาณิชย์ (SCB) | G31: 12 | H31: 7446 | I31: 0 | J31: 7446 | K31: 243981 | L31: 7446 | M31: =+L31-J31 -> 0
B32: 243982 | C32: suckjakkure@hotmail.com | D32: 0642427575 | E32: 4311469006 | F32: ธนาคารไทยพาณิชย์ (SCB) | G32: 4 | H32: 1420 | I32: 0 | J32: 1420 | K32: 243982 | L32: 1420 | M32: =+L32-J32 -> 0
... B34: 243983 | C34: suckjakkure@hotmail.com | D34: 0642427575 | E34: 4311469006 | F34: ธนาคารไทยพาณิชย์ (SCB) | G34: 1 | H34: 280 | I34: 0 | J34: 280 | K34: 243983 | L34: 280 | M34: =+L34-J34 -> 0
F35: ยอดรวม | G35: =SUM(G3:G34) -> 212 | H35: =SUM(H3:H34) -> 93577.5 | I35: =SUM(I3:I34) -> 0 | J35: =SUM(J3:J34) -> 93577.5 | K35: บาท | L35: =SUM(L3:L34) -> 93577.5 | M35: บาท

Sheet พ.ย.
A1: ข้อมูลการเก็บเงินปลายทาง (COD) แบบแยกรายละเอียด เดือนพฤศจิกายน 2567
A2: ลำดับ | B2: วันที่ | C2: Email | D2: Facebook Page | E2: Order No. / เลขที่ออเดอร์ | F2: Tracking No. / เลขพัสดุ | G2: recipientName / ชื่อลูกค้า | H2: Amount / ยอด COD
A3: 1 | B3: 243923 | C3: suckjakkure@hotmail.com | D3: FACEBOOK | F3: JA087749245TH | G3: อารีรัตน์ ธนพิทักษ์ | H3: 130
A4: 2 | B4: 243923 | C4: suckjakkure@hotmail.com | D4: FACEBOOK | F4: JA088637109TH | G4: วีรยา ทรงดาวเรือง | H4: 280
A5: 3 | B5: 243923 | C5: suckjakkure@hotmail.com | D5: FACEBOOK | F5: JA088637041TH | G5: ชุลีย์ เจริญ | H5: 180
A6: 4 | B6: 243923 | C6: suckjakkure@hotmail.com | D6: FACEBOOK | F6: JA088637072TH | G6: พรหมไหม | H6: 130
A7: 5 | B7: 243923 | C7: suckjakkure@hotmail.com | D7: FACEBOOK | F7: JA088307266TH | G7: สุพิวรรณ เอี่ยมลิ้ม | H7: 210
A8: 6 | B8: 243923 | C8: suckjakkure@hotmail.com | D8: FACEBOOK | F8: JA088637130TH | G8: สุเทพ ธรรมจันทร์ | H8: 130
A9: 7 | B9: 243923 | C9: suckjakkure@hotmail.com | D9: FACEBOOK | F9: JA088307371TH | G9: พิศมัยมงคลเกตุ | H9: 130
A10: 8 | B10: 243923 | C10: suckjakkure@hotmail.com | D10: FACEBOOK | F10: JA088637086TH | G10: อนุ นุ่มอุปถัมภ์ | H10: 130
A11: 9 | B11: 243923 | C11: suckjakkure@hotmail.com | D11: FACEBOOK | F11: JA088637055TH | G11: โสภา อึ๊งเจริญสุรศักดิ์ | H11: 130
A12: 10 | B12: 243923 | C12: suckjakkure@hotmail.com | D12: FACEBOOK | F12: JA088307306TH | G12: คุณนภา ย่อยฉิมพลี | H12: 180
A13: 11 | B13: 243923 | C13: suckjakkure@hotmail.com | D13: FACEBOOK | F13: JA087749262TH | G13: ศิริรัตน์ แซ่ลิ้ม | H13: 180
A14: 12 | B14: 243923 | C14: suckjakkure@hotmail.com | D14: FACEBOOK | F14: JA088307323TH | G14: กุสุมา_พลเขตร | H14: 130
... A231: 229 | B231: 243952 | C231: suckjakkure@hotmail.com | D231: FACEBOOK | F231: JA101594949TH | G231: อุไรวรรณ นวมนิ่มอนงค์ | H231: 330
G232: ยอดรวม | H232: =SUM(H3:H231) -> 69835 | I232: บาท

Sheet Summary พ.ย.
B1: ข้อมูลการเก็บเงินปลายทาง (COD) แบบรวมยอดประจำวัน เดือนพฤศจิกายน 2567 | K1: ตรวจในสเตทเม้น
A2: ลำดับ | B2: วันที่ | C2: Email | D2: Tel | E2: Bank Account Number / เลขที่บัญชี | F2: Bank Account Name / ชื่อธนาคาร | G2: Total Order / จำนวนออเดอร์ | H2: COD Amount / ยอดรวม COD | I2: Deduct | J2: Total Amount / ยอดรวม COD | K2: วันที่เงินเข้า | L2: ยอดเข้า | M2: หมายเหตุ
B3: 243923 | C3: suckjakkure@hotmail.com | D3: 0642427575 | E3: 4311469006 | F3: ธนาคารไทยพาณิชย์ (SCB) | G3: 19 | H3: 3440 | I3: 0 | J3: 3440 | K3: 243923 | L3: 3440 | M3: =+L3-J3 -> 0
B4: 243924 | C4: suckjakkure@hotmail.com | D4: 0642427575 | E4: 4311469006 | F4: ธนาคารไทยพาณิชย์ (SCB) | G4: 17 | H4: 3479 | I4: 0 | J4: 3479 | K4: 243924 | L4: 3479 | M4: =+L4-J4 -> 0
B5: 243925 | C5: suckjakkure@hotmail.com | D5: 0642427575 | E5: 4311469006 | F5: ธนาคารไทยพาณิชย์ (SCB) | G5: 7 | H5: 1860 | I5: 0 | J5: 1860 | K5: 243925 | L5: 1860 | M5: =+L5-J5 -> 0
B6: 243926 | C6: ไม่ยอดเก็บ COD | K6: 243926 | M6: =+L6-J6 -> 0
B7: 243927 | C7: suckjakkure@hotmail.com | D7: 0642427575 | E7: 4311469006 | F7: ธนาคารไทยพาณิชย์ (SCB) | G7: 14 | H7: 4440 | I7: 0 | J7: 4440 | K7: 243927 | L7: 4440 | M7: =+L7-J7 -> 0
B8: 243928 | C8: suckjakkure@hotmail.com | D8: 0642427575 | E8: 4311469006 | F8: ธนาคารไทยพาณิชย์ (SCB) | G8: 12 | H8: 2390 | I8: 0 | J8: 2390 | K8: 243928 | L8: 2390 | M8: =+L8-J8 -> 0
B9: 243929 | C9: suckjakkure@hotmail.com | D9: 0642427575 | E9: 4311469006 | F9: ธนาคารไทยพาณิชย์ (SCB) | G9: 15 | H9: 4030 | I9: 0 | J9: 4030 | K9: 243929 | L9: 4030 | M9: =+L9-J9 -> 0
B10: 243930 | C10: suckjakkure@hotmail.com | D10: 0642427575 | E10: 4311469006 | F10: ธนาคารไทยพาณิชย์ (SCB) | G10: 12 | H10: 5269 | I10: 0 | J10: 5269 | K10: 243930 | L10: 5269 | M10: =+L10-J10 -> 0
B11: 243931 | C11: suckjakkure@hotmail.com | D11: 0642427575 | E11: 4311469006 | F11: ธนาคารไทยพาณิชย์ (SCB) | G11: 16 | H11: 6690 | I11: 0 | J11: 6690 | K11: 243931 | L11: 6690 | M11: =+L11-J11 -> 0
B12: 243932 | C12: suckjakkure@hotmail.com | D12: 0642427575 | E12: 4311469006 | F12: ธนาคารไทยพาณิชย์ (SCB) | G12: 4 | H12: 1900 | I12: 0 | J12: 1900 | K12: 243932 | L12: 1900 | M12: =+L12-J12 -> 0
B13: 243933 | C13: suckjakkure@hotmail.com | D13: 0642427575 | E13: 4311469006 | F13: ธนาคารไทยพาณิชย์ (SCB) | G13: 1 | H13: 330 | I13: 0 | J13: 330 | K13: 243933 | L13: 330 | M13: =+L13-J13 -> 0
B14: 243934 | C14: suckjakkure@hotmail.com | D14: 0642427575 | E14: 4311469006 | F14: ธนาคารไทยพาณิชย์ (SCB) | G14: 7 | H14: 4010 | I14: 0 | J14: 4010 | K14: 243934 | L14: 4010 | M14: =+L14-J14 -> 0
B15: 243935 | C15: suckjakkure@hotmail.com | D15: 0642427575 | E15: 4311469006 | F15: ธนาคารไทยพาณิชย์ (SCB) | G15: 4 | H15: 1120 | I15: 0 | J15: 1120 | K15: 243935 | L15: 1120 | M15: =+L15-J15 -> 0
B16: 243936 | C16: suckjakkure@hotmail.com | D16: 0642427575 | E16: 4311469006 | F16: ธนาคารไทยพาณิชย์ (SCB) | G16: 4 | H16: 1650 | I16: 0 | J16: 1650 | K16: 243936 | L16: 1650 | M16: =+L16-J16 -> 0
B17: 243937 | C17: suckjakkure@hotmail.com | D17: 0642427575 | E17: 4311469006 | F17: ธนาคารไทยพาณิชย์ (SCB) | G17: 1 | H17: 1030 | I17: 0 | J17: 1030 | K17: 243937 | L17: 1030 | M17: =+L17-J17 -> 0
B18: 243938 | C18: suckjakkure@hotmail.com | D18: 0642427575 | E18: 4311469006 | F18: ธนาคารไทยพาณิชย์ (SCB) | G18: 4 | H18: 2120 | I18: 0 | J18: 2120 | K18: 243938 | L18: 2120 | M18: =+L18-J18 -> 0
B19: 243939 | C19: suckjakkure@hotmail.com | D19: 0642427575 | E19: 4311469006 | F19: ธนาคารไทยพาณิชย์ (SCB) | G19: 6 | H19: 1230 | I19: 0 | J19: 1230 | K19: 243939 | L19: 1230 | M19: =+L19-J19 -> 0
B20: 243940 | C20: ไม่ยอดเก็บ COD | K20: 243940 | L20: 0 | M20: =+L20-J20 -> 0
B21: 243941 | C21: suckjakkure@hotmail.com | D21: 0642427575 | E21: 4311469006 | F21: ธนาคารไทยพาณิชย์ (SCB) | G21: 5 | H21: 1780 | I21: 0 | J21: 1780 | K21: 243941 | L21: 1780 | M21: =+L21-J21 -> 0
B22: 243942 | C22: suckjakkure@hotmail.com | D22: 0642427575 | E22: 4311469006 | F22: ธนาคารไทยพาณิชย์ (SCB) | G22: 3 | H22: 1270 | I22: 0 | J22: 1270 | K22: 243942 | L22: 1270 | M22: =+L22-J22 -> 0
B23: 243943 | C23: suckjakkure@hotmail.com | D23: 0642427575 | E23: 4311469006 | F23: ธนาคารไทยพาณิชย์ (SCB) | G23: 5 | H23: 820 | I23: 0 | J23: 820 | K23: 243943 | L23: 820 | M23: =+L23-J23 -> 0
B24: 243944 | C24: suckjakkure@hotmail.com | D24: 0642427575 | E24: 4311469006 | F24: ธนาคารไทยพาณิชย์ (SCB) | G24: 4 | H24: 710 | I24: 0 | J24: 710 | K24: 243944 | L24: 710 | M24: =+L24-J24 -> 0
B25: 243945 | C25: suckjakkure@hotmail.com | D25: 0642427575 | E25: 4311469006 | F25: ธนาคารไทยพาณิชย์ (SCB) | G25: 7 | H25: 2130 | I25: 0 | J25: 2130 | K25: 243945 | L25: 2130 | M25: =+L25-J25 -> 0
B26: 243946 | C26: suckjakkure@hotmail.com | D26: 0642427575 | E26: 4311469006 | F26: ธนาคารไทยพาณิชย์ (SCB) | G26: 5 | H26: 1300 | I26: 0 | J26: 1300 | K26: 243946 | L26: 1300 | M26: =+L26-J26 -> 0
B27: 243947 | C27: suckjakkure@hotmail.com | D27: 0642427575 | E27: 4311469006 | F27: ธนาคารไทยพาณิชย์ (SCB) | G27: 1 | H27: 230 | I27: 0 | J27: 230 | K27: 243947 | L27: 230 | M27: =+L27-J27 -> 0
B28: 243948 | C28: suckjakkure@hotmail.com | D28: 0642427575 | E28: 4311469006 | F28: ธนาคารไทยพาณิชย์ (SCB) | G28: 3 | H28: 640 | I28: 0 | J28: 640 | K28: 243948 | L28: 640 | M28: =+L28-J28 -> 0
B29: 243949 | C29: suckjakkure@hotmail.com | D29: 0642427575 | E29: 4311469006 | F29: ธนาคารไทยพาณิชย์ (SCB) | G29: 7 | H29: 1800 | I29: 0 | J29: 1800 | K29: 243949 | L29: 1800 | M29: =+L29-J29 -> 0
B30: 243950 | C30: suckjakkure@hotmail.com | D30: 0642427575 | E30: 4311469006 | F30: ธนาคารไทยพาณิชย์ (SCB) | G30: 10 | H30: 2600 | I30: 0 | J30: 2600 | K30: 243950 | L30: 2600 | M30: =+L30-J30 -> 0
B31: 243951 | C31: suckjakkure@hotmail.com | D31: 0642427575 | E31: 4311469006 | F31: ธนาคารไทยพาณิชย์ (SCB) | G31: 9 | H31: 2320 | I31: 0 | J31: 2320 | K31: 243951 | L31: 2320 | M31: =+L31-J31 -> 0
B32: 243952 | C32: suckjakkure@hotmail.com | D32: 0642427575 | E32: 4311469006 | F32: ธนาคารไทยพาณิชย์ (SCB) | G32: 27 | H32: 9247 | I32: 0 | J32: 9247 | K32: 243952 | L32: 9247 | M32: =+L32-J32 -> 0
B33: 243953 | K33: 243953 | M33: =+L33-J33 -> 0
B34: 243954 | K34: 243954 | M34: =+L34-J34 -> 0
F35: ยอดรวม | G35: =SUM(G3:G34) -> 229 | H35: =SUM(H3:H34) -> 69835 | I35: =SUM(I3:I34) -> 0 | J35: =SUM(J3:J34) -> 69835 | K35: บาท | L35: =SUM(L3:L34) -> 69835 | M35: บาท

Sheet ต.ค.
A1: ข้อมูลการเก็บเงินปลายทาง (COD) แบบแยกรายละเอียด เดือนตุลาคม 2567
A2: ลำดับ | B2: วันที่ | C2: Email | D2: Facebook Page | E2: Order No. / เลขที่ออเดอร์ | F2: Tracking No. / เลขพัสดุ | G2: recipientName / ชื่อลูกค้า | H2: Amount / ยอด COD
A3: 1 | B3: 243892 | C3: suckjakkure@hotmail.com | D3: FACEBOOK | F3: JA070224005TH | G3: ญดา คำแสน | H3: 230
A4: 2 | B4: 243892 | C4: suckjakkure@hotmail.com | D4: FACEBOOK | F4: JA070621179TH | G4: นายวัชระ ท้วมเทียบ | H4: 330
A5: 3 | B5: 243892 | C5: suckjakkure@hotmail.com | D5: FACEBOOK | F5: JA070621196TH | G5: กุ้งนาง | H5: 130
A6: 4 | B6: 243892 | C6: suckjakkure@hotmail.com | D6: FACEBOOK | F6: JA070621267TH | G6: ศรีวรรณ-สาเกิด | H6: 330
A7: 5 | B7: 243892 | C7: suckjakkure@hotmail.com | D7: FACEBOOK | F7: JA070621148TH | G7: คุณระเบียบ จิตรนอก | H7: 130
A8: 6 | B8: 243892 | C8: suckjakkure@hotmail.com | D8: FACEBOOK | F8: JA070621205TH | G8: RN | H8: 230
A9: 7 | B9: 243892 | C9: suckjakkure@hotmail.com | D9: FACEBOOK | F9: JA070621372TH | G9: อมร แสงพิทักษ์ | H9: 230
A10: 8 | B10: 243892 | C10: suckjakkure@hotmail.com | D10: FACEBOOK | F10: JA070621369TH | G10: จันทนา อุดมขันติโยธิน | H10: 330
A11: 9 | B11: 243892 | C11: suckjakkure@hotmail.com | D11: FACEBOOK | F11: JA070363231TH | G11: นิตยา ไชยสิทธิ์ | H11: 165
A12: 10 | B12: 243892 | C12: suckjakkure@hotmail.com | D12: FACEBOOK | F12: JA070363143TH | G12: จงกลรัตน์ ฉัตรฉิมพลี | H12: 130
A13: 11 | B13: 243892 | C13: suckjakkure@hotmail.com | D13: FACEBOOK | F13: JA070366683TH | G13: ชื่อ.สุมาลี.ศรีสวัสดิ์ | H13: 130
A14: 12 | B14: 243892 | C14: suckjakkure@hotmail.com | D14: FACEBOOK | F14: JA070224075TH | G14: Jen Jenjira | H14: 230
... A1025: 1023 | B1025: 243922 | C1025: suckjakkure@hotmail.com | D1025: FACEBOOK | F1025: JA087924085TH | G1025: สุนทรี กาเมืองลือ | H1025: 130
G1026: ยอดรวม | H1026: =SUM(H3:H1025) -> 193223 | I1026: บาท

Sheet Summary ต.ค.
B1: ข้อมูลการเก็บเงินปลายทาง (COD) แบบรวมยอดประจำวัน เดือนตุลาคม 2567 | K1: ตรวจในสเตทเม้น
A2: ลำดับ | B2: วันที่ | C2: Email | D2: Tel | E2: Bank Account Number / เลขที่บัญชี | F2: Bank Account Name / ชื่อธนาคาร | G2: Total Order / จำนวนออเดอร์ | H2: COD Amount / ยอดรวม COD | I2: Deduct | J2: Total Amount / ยอดรวม COD | K2: วันที่เงินเข้า | L2: ยอดเข้า | M2: หมายเหตุ
B3: 243892 | C3: suckjakkure@hotmail.com | D3: 0642427575 | E3: 4311469006 | F3: ธนาคารไทยพาณิชย์ (SCB) | G3: 28 | H3: 5775 | I3: 0 | J3: 5775 | K3: 243892 | L3: 5775 | M3: =+L3-J3 -> 0
B4: 243893 | C4: suckjakkure@hotmail.com | D4: 0642427575 | E4: 4311469006 | F4: ธนาคารไทยพาณิชย์ (SCB) | G4: 37 | H4: 7210 | I4: 0 | J4: 7210 | K4: 243893 | L4: 7210 | M4: =+L4-J4 -> 0
B5: 243894 | C5: suckjakkure@hotmail.com | D5: 0642427575 | E5: 4311469006 | F5: ธนาคารไทยพาณิชย์ (SCB) | G5: 36 | H5: 6630 | I5: 0 | J5: 6630 | K5: 243894 | L5: 6630 | M5: =+L5-J5 -> 0
B6: 243895 | C6: suckjakkure@hotmail.com | D6: 0642427575 | E6: 4311469006 | F6: ธนาคารไทยพาณิชย์ (SCB) | G6: 41 | H6: 8410 | I6: 0 | J6: 8410 | K6: 243895 | L6: 8410 | M6: =+L6-J6 -> 0
B7: 243896 | C7: suckjakkure@hotmail.com | D7: 0642427575 | E7: 4311469006 | F7: ธนาคารไทยพาณิชย์ (SCB) | G7: 25 | H7: 5980 | I7: 0 | J7: 5980 | K7: 243896 | L7: 5980 | M7: =+L7-J7 -> 0
B8: 243897 | C8: suckjakkure@hotmail.com | D8: 0642427575 | E8: 4311469006 | F8: ธนาคารไทยพาณิชย์ (SCB) | G8: 7 | H8: 1110 | I8: 0 | J8: 1110 | K8: 243897 | L8: 1110 | M8: =+L8-J8 -> 0
B9: 243898 | C9: ไม่ยอดเก็บ COD | K9: 243898 | L9: 0 | M9: =+L9-J9 -> 0
B10: 243899 | C10: suckjakkure@hotmail.com | D10: 0642427575 | E10: 4311469006 | F10: ธนาคารไทยพาณิชย์ (SCB) | G10: 10 | H10: 2490 | I10: 0 | J10: 2490 | K10: 243899 | L10: 2490 | M10: =+L10-J10 -> 0
B11: 243900 | C11: suckjakkure@hotmail.com | D11: 0642427575 | E11: 4311469006 | F11: ธนาคารไทยพาณิชย์ (SCB) | G11: 17 | H11: 4060 | I11: 0 | J11: 4060 | K11: 243900 | L11: 4060 | M11: =+L11-J11 -> 0
B12: 243901 | C12: suckjakkure@hotmail.com | D12: 0642427575 | E12: 4311469006 | F12: ธนาคารไทยพาณิชย์ (SCB) | G12: 15 | H12: 4320 | I12: 0 | J12: 4320 | K12: 243901 | L12: 4320 | M12: =+L12-J12 -> 0
B13: 243902 | C13: suckjakkure@hotmail.com | D13: 0642427575 | E13: 4311469006 | F13: ธนาคารไทยพาณิชย์ (SCB) | G13: 66 | H13: 10900 | I13: 0 | J13: 10900 | K13: 243902 | L13: 10900 | M13: =+L13-J13 -> 0
B14: 243903 | C14: suckjakkure@hotmail.com | D14: 0642427575 | E14: 4311469006 | F14: ธนาคารไทยพาณิชย์ (SCB) | G14: 98 | H14: 17920 | I14: 0 | J14: 17920 | K14: 243903 | L14: 17920 | M14: =+L14-J14 -> 0
B15: 243904 | C15: suckjakkure@hotmail.com | D15: 0642427575 | E15: 4311469006 | F15: ธนาคารไทยพาณิชย์ (SCB) | G15: 61 | H15: 10130 | I15: 0 | J15: 10130 | K15: 243904 | L15: 10130 | M15: =+L15-J15 -> 0
B16: 243905 | C16: ไม่ยอดเก็บ COD | K16: 243905 | M16: =+L16-J16 -> 0
B17: 243906 | C17: ไม่ยอดเก็บ COD | K17: 243906 | M17: =+L17-J17 -> 0
B18: 243907 | C18: suckjakkure@hotmail.com | D18: 0642427575 | E18: 4311469006 | F18: ธนาคารไทยพาณิชย์ (SCB) | G18: 67 | H18: 11390 | I18: 0 | J18: 11390 | K18: 243907 | L18: 11390 | M18: =+L18-J18 -> 0
B19: 243908 | C19: suckjakkure@hotmail.com | D19: 0642427575 | E19: 4311469006 | F19: ธนาคารไทยพาณิชย์ (SCB) | G19: 19 | H19: 3870 | I19: 0 | J19: 3870 | K19: 243908 | L19: 3870 | M19: =+L19-J19 -> 0
B20: 243909 | C20: suckjakkure@hotmail.com | D20: 0642427575 | E20: 4311469006 | F20: ธนาคารไทยพาณิชย์ (SCB) | G20: 42 | H20: 6860 | I20: 0 | J20: 6860 | K20: 243909 | L20: 6860 | M20: =+L20-J20 -> 0
B21: 243910 | C21: suckjakkure@hotmail.com | D21: 0642427575 | E21: 4311469006 | F21: ธนาคารไทยพาณิชย์ (SCB) | G21: 100 | H21: 15750 | I21: 0 | J21: 15750 | K21: 243910 | L21: 15750 | M21: =+L21-J21 -> 0
B22: 243911 | C22: suckjakkure@hotmail.com | D22: 0642427575 | E22: 4311469006 | F22: ธนาคารไทยพาณิชย์ (SCB) | G22: 56 | H22: 9180 | I22: 0 | J22: 9180 | K22: 243911 | L22: 9180 | M22: =+L22-J22 -> 0
B23: 243912 | C23: suckjakkure@hotmail.com | D23: 0642427575 | E23: 4311469006 | F23: ธนาคารไทยพาณิชย์ (SCB) | G23: 18 | H23: 4560 | I23: 0 | J23: 4560 | K23: 243912 | L23: 4560 | M23: =+L23-J23 -> 0
B24: 243913 | C24: suckjakkure@hotmail.com | D24: 0642427575 | E24: 4311469006 | F24: ธนาคารไทยพาณิชย์ (SCB) | G24: 63 | H24: 10290 | I24: 0 | J24: 10290 | K24: 243913 | L24: 10290 | M24: =+L24-J24 -> 0
B25: 243914 | C25: suckjakkure@hotmail.com | D25: 0642427575 | E25: 4311469006 | F25: ธนาคารไทยพาณิชย์ (SCB) | G25: 70 | H25: 12100 | I25: 0 | J25: 12100 | K25: 243914 | L25: 12100 | M25: =+L25-J25 -> 0
B26: 243915 | C26: suckjakkure@hotmail.com | D26: 0642427575 | E26: 4311469006 | F26: ธนาคารไทยพาณิชย์ (SCB) | G26: 15 | H26: 2750 | I26: 0 | J26: 2750 | K26: 243915 | L26: 2750 | M26: =+L26-J26 -> 0
B27: 243916 | C27: suckjakkure@hotmail.com | D27: 0642427575 | E27: 4311469006 | F27: ธนาคารไทยพาณิชย์ (SCB) | G27: 39 | H27: 7470 | I27: 0 | J27: 7470 | K27: 243916 | L27: 7470 | M27: =+L27-J27 -> 0
B28: 243917 | C28: suckjakkure@hotmail.com | D28: 0642427575 | E28: 4311469006 | F28: ธนาคารไทยพาณิชย์ (SCB) | G28: 17 | H28: 3558 | I28: 0 | J28: 3558 | K28: 243917 | L28: 3558 | M28: =+L28-J28 -> 0
B29: 243918 | C29: suckjakkure@hotmail.com | D29: 0642427575 | E29: 4311469006 | F29: ธนาคารไทยพาณิชย์ (SCB) | G29: 12 | H29: 2010 | I29: 0 | J29: 2010 | K29: 243918 | L29: 2010 | M29: =+L29-J29 -> 0
... B33: 243922 | C33: suckjakkure@hotmail.com | D33: 0642427575 | E33: 4311469006 | F33: ธนาคารไทยพาณิชย์ (SCB) | G33: 15 | H33: 3800 | I33: 0 | J33: 3800 | K33: 243922 | L33: 3800 | M33: =+L33-J33 -> 0
B34: 243923 | K34: 243923 | M34: =+L34-J34 -> 0
F35: ยอดรวม | G35: =SUM(G3:G34) -> 1023 | H35: =SUM(H3:H34) -> 193223 | I35: =SUM(I3:I34) -> 0 | J35: =SUM(J3:J34) -> 193223 | K35: บาท | L35: =SUM(L3:L34) -> 193223 | M35: บาท

Sheet ก.ย.
A1: ข้อมูลการเก็บเงินปลายทาง (COD) แบบแยกรายละเอียด เดือนกันยายน 2567
A2: ลำดับ | B2: วันที่ | C2: Email | D2: Facebook Page | E2: Order No. / เลขที่ออเดอร์ | F2: Tracking No. / เลขพัสดุ | G2: recipientName / ชื่อลูกค้า | H2: Amount / ยอด COD
A3: 1 | B3: 243862 | C3: suckjakkure@hotmail.com | D3: FACEBOOK | F3: JA054995481TH | G3: สมหมาย ปัญญา | H3: 230
A4: 2 | B4: 243862 | C4: suckjakkure@hotmail.com | D4: FACEBOOK | F4: JA054994923TH | G4: ทองสุข พาพันธุ์ | H4: 130
A5: 3 | B5: 243862 | C5: suckjakkure@hotmail.com | D5: FACEBOOK | F5: JA054995036TH | G5: วัลภา พาหุสุวัณโณ | H5: 430
A6: 4 | B6: 243862 | C6: suckjakkure@hotmail.com | D6: FACEBOOK | F6: JA054431278TH | G6: สมพร ศรีสมุทร | H6: 130
A7: 5 | B7: 243862 | C7: suckjakkure@hotmail.com | D7: FACEBOOK | F7: JA054995075TH | G7: พี่ตา | H7: 130
A8: 6 | B8: 243862 | C8: suckjakkure@hotmail.com | D8: FACEBOOK | F8: JA054994937TH | G8: ไพเราะ | H8: 130
A9: 7 | B9: 243862 | C9: suckjakkure@hotmail.com | D9: FACEBOOK | F9: JA054995053TH | G9: สุรชัย | H9: 130
A10: 8 | B10: 243862 | C10: suckjakkure@hotmail.com | D10: FACEBOOK | F10: JA054691030TH | G10: คุณวีนา | H10: 230
A11: 9 | B11: 243862 | C11: suckjakkure@hotmail.com | D11: FACEBOOK | F11: JA054994945TH | G11: เอกชัย ภัทราพันธ์มณี | H11: 130
A12: 10 | B12: 243862 | C12: suckjakkure@hotmail.com | D12: FACEBOOK | F12: JA054994968TH | G12: พิมพร | H12: 130
A13: 11 | B13: 243862 | C13: suckjakkure@hotmail.com | D13: FACEBOOK | F13: JA054691454TH | G13: นิสา สาทะเล | H13: 430
A14: 12 | B14: 243862 | C14: suckjakkure@hotmail.com | D14: FACEBOOK | F14: JA054691542TH | G14: สายสมรแซ่เบ๊ | H14: 130
... A1275: 1273 | B1275: 243891 | C1275: suckjakkure@hotmail.com | D1275: FACEBOOK | F1275: JA069485255TH | G1275: จิ้ว-ชิดเชื้อ | H1275: 130
G1276: ยอดรวม | H1276: =SUM(H3:H1275) -> 230753 | I1276: บาท

Sheet Summary ก.ย.
B1: ข้อมูลการเก็บเงินปลายทาง (COD) แบบรวมยอดประจำวัน เดือนกันยายน 2567 | K1: ตรวจในสเตทเม้น
A2: ลำดับ | B2: วันที่ | C2: Email | D2: Tel | E2: Bank Account Number / เลขที่บัญชี | F2: Bank Account Name / ชื่อธนาคาร | G2: Total Order / จำนวนออเดอร์ | H2: COD Amount / ยอดรวม COD | I2: Deduct | J2: Total Amount / ยอดรวม COD | K2: วันที่เงินเข้า | L2: ยอดเข้า | M2: หมายเหตุ
B3: 243862 | C3: suckjakkure@hotmail.com | D3: 0642427575 | E3: 4311469006 | F3: ธนาคารไทยพาณิชย์ (SCB) | G3: 32 | H3: 5310 | I3: 0 | J3: 5310 | K3: 243862 | L3: 5310 | M3: =+L3-J3 -> 0
B4: 243863 | C4: ไม่ยอดเก็บ COD | K4: 243863 | L4: 0 | M4: =+L4-J4 -> 0
B5: 243864 | C5: suckjakkure@hotmail.com | D5: 0642427575 | E5: 4311469006 | F5: ธนาคารไทยพาณิชย์ (SCB) | G5: 63 | H5: 11290 | I5: 0 | J5: 11290 | K5: 243864 | L5: 11290 | M5: =+L5-J5 -> 0
B6: 243865 | C6: suckjakkure@hotmail.com | D6: 0642427575 | E6: 4311469006 | F6: ธนาคารไทยพาณิชย์ (SCB) | G6: 72 | H6: 12310 | I6: 0 | J6: 12310 | K6: 243865 | L6: 12310 | M6: =+L6-J6 -> 0
B7: 243866 | C7: suckjakkure@hotmail.com | D7: 0642427575 | E7: 4311469006 | F7: ธนาคารไทยพาณิชย์ (SCB) | G7: 39 | H7: 6000 | I7: 0 | J7: 6000 | K7: 243866 | L7: 6000 | M7: =+L7-J7 -> 0
B8: 243867 | C8: suckjakkure@hotmail.com | D8: 0642427575 | E8: 4311469006 | F8: ธนาคารไทยพาณิชย์ (SCB) | G8: 67 | H8: 11860 | I8: 0 | J8: 11860 | K8: 243867 | L8: 11860 | M8: =+L8-J8 -> 0
B9: 243868 | C9: suckjakkure@hotmail.com | D9: 0642427575 | E9: 4311469006 | F9: ธนาคารไทยพาณิชย์ (SCB) | G9: 67 | H9: 11225 | I9: 0 | J9: 11225 | K9: 243868 | L9: 11225 | M9: =+L9-J9 -> 0
B10: 243869 | C10: suckjakkure@hotmail.com | D10: 0642427575 | E10: 4311469006 | F10: ธนาคารไทยพาณิชย์ (SCB) | G10: 30 | H10: 5000 | I10: 0 | J10: 5000 | K10: 243869 | L10: 5000 | M10: =+L10-J10 -> 0
B11: 243870 | C11: suckjakkure@hotmail.com | D11: 0642427575 | E11: 4311469006 | F11: ธนาคารไทยพาณิชย์ (SCB) | G11: 5 | H11: 850 | I11: 0 | J11: 850 | K11: 243870 | L11: 850 | M11: =+L11-J11 -> 0
B12: 243871 | C12: suckjakkure@hotmail.com | D12: 0642427575 | E12: 4311469006 | F12: ธนาคารไทยพาณิชย์ (SCB) | G12: 41 | H12: 6980 | I12: 0 | J12: 6980 | K12: 243871 | L12: 6980 | M12: =+L12-J12 -> 0
B13: 243872 | C13: suckjakkure@hotmail.com | D13: 0642427575 | E13: 4311469006 | F13: ธนาคารไทยพาณิชย์ (SCB) | G13: 58 | H13: 10178 | I13: 0 | J13: 10178 | K13: 243872 | L13: 10178 | M13: =+L13-J13 -> 0
B14: 243873 | C14: suckjakkure@hotmail.com | D14: 0642427575 | E14: 4311469006 | F14: ธนาคารไทยพาณิชย์ (SCB) | G14: 65 | H14: 13370 | I14: 0 | J14: 13370 | K14: 243873 | L14: 13370 | M14: =+L14-J14 -> 0
B15: 243874 | C15: suckjakkure@hotmail.com | D15: 0642427575 | E15: 4311469006 | F15: ธนาคารไทยพาณิชย์ (SCB) | G15: 72 | H15: 12736 | I15: 0 | J15: 12736 | K15: 243874 | L15: 12736 | M15: =+L15-J15 -> 0
B16: 243875 | C16: suckjakkure@hotmail.com | D16: 0642427575 | E16: 4311469006 | F16: ธนาคารไทยพาณิชย์ (SCB) | G16: 85 | H16: 16222 | I16: 0 | J16: 16222 | K16: 243875 | L16: 16222 | M16: =+L16-J16 -> 0
... B19: 243878 | C19: suckjakkure@hotmail.com | D19: 0642427575 | E19: 4311469006 | F19: ธนาคารไทยพาณิชย์ (SCB) | G19: 68 | H19: 12984 | I19: 0 | J19: 12984 | K19: 243878 | L19: 12984 | M19: =+L19-J19 -> 0
B20: 243879 | C20: ไม่ยอดเก็บ COD | K20: 243879 | L20: 0 | M20: =+L20-J20 -> 0
B21: 243880 | C21: suckjakkure@hotmail.com | D21: 0642427575 | E21: 4311469006 | F21: ธนาคารไทยพาณิชย์ (SCB) | G21: 86 | H21: 14700 | I21: 0 | J21: 14700 | K21: 243880 | L21: 14700 | M21: =+L21-J21 -> 0
B22: 243881 | C22: suckjakkure@hotmail.com | D22: 0642427575 | E22: 4311469006 | F22: ธนาคารไทยพาณิชย์ (SCB) | G22: 84 | H22: 14920 | I22: 0 | J22: 14920 | K22: 243881 | L22: 14920 | M22: =+L22-J22 -> 0
B23: 243882 | C23: suckjakkure@hotmail.com | D23: 0642427575 | E23: 4311469006 | F23: ธนาคารไทยพาณิชย์ (SCB) | G23: 43 | H23: 7990 | I23: 0 | J23: 7990 | K23: 243882 | L23: 7990 | M23: =+L23-J23 -> 0
B24: 243883 | C24: suckjakkure@hotmail.com | D24: 0642427575 | E24: 4311469006 | F24: ธนาคารไทยพาณิชย์ (SCB) | G24: 39 | H24: 8240 | I24: 0 | J24: 8240 | K24: 243883 | L24: 8240 | M24: =+L24-J24 -> 0
B25: 243884 | C25: suckjakkure@hotmail.com | D25: 0642427575 | E25: 4311469006 | F25: ธนาคารไทยพาณิชย์ (SCB) | G25: 8 | H25: 1140 | I25: 0 | J25: 1140 | K25: 243884 | L25: 1140 | M25: =+L25-J25 -> 0
B26: 243885 | C26: suckjakkure@hotmail.com | D26: 0642427575 | E26: 4311469006 | F26: ธนาคารไทยพาณิชย์ (SCB) | G26: 51 | H26: 9330 | I26: 0 | J26: 9330 | K26: 243885 | L26: 9330 | M26: =+L26-J26 -> 0
B27: 243886 | C27: suckjakkure@hotmail.com | D27: 0642427575 | E27: 4311469006 | F27: ธนาคารไทยพาณิชย์ (SCB) | G27: 58 | H27: 11810 | I27: 0 | J27: 11810 | K27: 243886 | L27: 11810 | M27: =+L27-J27 -> 0
B28: 243887 | C28: suckjakkure@hotmail.com | D28: 0642427575 | E28: 4311469006 | F28: ธนาคารไทยพาณิชย์ (SCB) | G28: 55 | H28: 9450 | I28: 0 | J28: 9450 | K28: 243887 | L28: 9450 | M28: =+L28-J28 -> 0
B29: 243888 | C29: ไม่ยอดเก็บ COD | K29: 243888 | L29: 0 | M29: =+L29-J29 -> 0
B30: 243889 | C30: ไม่ยอดเก็บ COD | K30: 243889 | L30: 0 | M30: =+L30-J30 -> 0
B31: 243890 | C31: suckjakkure@hotmail.com | D31: 0642427575 | E31: 4311469006 | F31: ธนาคารไทยพาณิชย์ (SCB) | G31: 30 | H31: 6120 | I31: 0 | J31: 6120 | K31: 243890 | L31: 6120 | M31: =+L31-J31 -> 0
B32: 243891 | C32: suckjakkure@hotmail.com | D32: 0642427575 | E32: 4311469006 | F32: ธนาคารไทยพาณิชย์ (SCB) | G32: 4 | H32: 620 | I32: 0 | J32: 620 | K32: 243891 | L32: 620 | M32: =+L32-J32 -> 0
B33: 243892 | K33: 243892 | M33: =+L33-J33 -> 0
B34: 243893 | K34: 243893 | M34: =+L34-J34 -> 0
F35: ยอดรวม | G35: =SUM(G3:G34) -> 1273 | H35: =SUM(H3:H34) -> 230753 | I35: =SUM(I3:I34) -> 0 | J35: =SUM(J3:J34) -> 230753 | K35: บาท | L35: =SUM(L3:L34) -> 230753 | M35: บาท

Sheet ส.ค.
A1: ข้อมูลการเก็บเงินปลายทาง (COD) แบบแยกรายละเอียด เดือนสิงหาคม 2567
A2: ลำดับ | B2: วันที่ | C2: Email | D2: Facebook Page | E2: Order No. / เลขที่ออเดอร์ | F2: Tracking No. / เลขพัสดุ | G2: recipientName / ชื่อลูกค้า | H2: Amount / ยอด COD
A3: 1 | B3: 243831 | C3: suckjakkure@hotmail.com | D3: FACEBOOK | F3: JA043329519TH | G3: วศินี | H3: 130
A4: 2 | B4: 243831 | C4: suckjakkure@hotmail.com | D4: FACEBOOK | F4: JA043374521TH | G4: สุกัญญา สังข์ประเสริฐ | H4: 130
A5: 3 | B5: 243831 | C5: suckjakkure@hotmail.com | D5: FACEBOOK | F5: JA043374138TH | G5: พัชนี เกียรติเดชาวิทย์ | H5: 130
A6: 4 | B6: 243831 | C6: suckjakkure@hotmail.com | D6: FACEBOOK | F6: JA043680535TH | G6: พัชราพร | H6: 130
A7: 5 | B7: 243831 | C7: suckjakkure@hotmail.com | D7: FACEBOOK | F7: JA043661111TH | G7: นนทกาญจน์ อุ่นจันทร์ | H7: 130
A8: 6 | B8: 243831 | C8: suckjakkure@hotmail.com | D8: FACEBOOK | F8: JA043207753TH | G8: สุภาพ แก้วก้อ | H8: 130
A9: 7 | B9: 243831 | C9: suckjakkure@hotmail.com | D9: FACEBOOK | F9: JA043784504TH | G9: วลัยลักษณ์ | H9: 230
A10: 8 | B10: 243831 | C10: suckjakkure@hotmail.com | D10: FACEBOOK | F10: JA043208189TH | G10: ลัดดา ชิว | H10: 130
A11: 9 | B11: 243831 | C11: suckjakkure@hotmail.com | D11: FACEBOOK | F11: JA043207957TH | G11: ทิพวรรณ | H11: 230
A12: 10 | B12: 243831 | C12: suckjakkure@hotmail.com | D12: FACEBOOK | F12: JA043207872TH | G12: ยุพร ชีบุญ | H12: 130
A13: 11 | B13: 243831 | C13: suckjakkure@hotmail.com | D13: FACEBOOK | F13: JA043784274TH | G13: นนทิยา วงศ์อุบล | H13: 230
A14: 12 | B14: 243831 | C14: suckjakkure@hotmail.com | D14: FACEBOOK | F14: JA043374314TH | G14: ศิริพรศรี | H14: 130
... A1521: 1519 | B1521: 243847 | C1521: suckjakkure@hotmail.com | D1521: FACEBOOK | F1521: JA050895050TH | G1521: นิชนิภา พาพันธ์ | H1521: 130
A1522: 1520 | B1522: 243848 | C1522: suckjakkure@hotmail.com | D1522: FACEBOOK | E1522: KTINTER66bc0e35775ddb0012d13382 | F1522: TH390460415F4D | G1522: ธนา พรหมเวช | H1522: 130
A1523: 1521 | B1523: 243848 | C1523: suckjakkure@hotmail.com | D1523: FACEBOOK | F1523: JA050895117TH | G1523: รุ่ง | H1523: 230
A1524: 1522 | B1524: 243848 | C1524: suckjakkure@hotmail.com | D1524: FACEBOOK | F1524: JA050577365TH | G1524: รัศมิ์ลภัส | H1524: 230
A1525: 1523 | B1525: 243848 | C1525: suckjakkure@hotmail.com | D1525: FACEBOOK | F1525: JA050577414TH | G1525: ร้าน cp pork shop วุฒิชัย เชื้อคำเพ็ง | H1525: 130
A1526: 1524 | B1526: 243848 | C1526: suckjakkure@hotmail.com | D1526: FACEBOOK | F1526: JA050577431TH | G1526: พัชราภาณ์ ไชยเหมาะ | H1526: 130
A1527: 1525 | B1527: 243848 | C1527: suckjakkure@hotmail.com | D1527: FACEBOOK | F1527: JA050895205TH | G1527: คุณสิริพร | H1527: 480
A1528: 1526 | B1528: 243848 | C1528: suckjakkure@hotmail.com | D1528: FACEBOOK | F1528: JA051236195TH | G1528: นิศากานต์ พิสุทธิ์ไพศาล | H1528: 330
A1529: 1527 | B1529: 243848 | C1529: suckjakkure@hotmail.com | D1529: FACEBOOK | F1529: JA051235950TH | G1529: อำนวย | H1529: 180
A1530: 1528 | B1530: 243848 | C1530: suckjakkure@hotmail.com | D1530: FACEBOOK | F1530: JA050896280TH | G1530: กันนิกา จบสี | H1530: 130
A1531: 1529 | B1531: 243848 | C1531: suckjakkure@hotmail.com | D1531: FACEBOOK | F1531: JA051235756TH | G1531: อารี ขาวขำ | H1531: 230
A1532: 1530 | B1532: 243848 | C1532: suckjakkure@hotmail.com | D1532: FACEBOOK | F1532: JA051236235TH | G1532: ประนอม เกตุแก้ว | H1532: 130
A1533: 1531 | B1533: 243848 | C1533: suckjakkure@hotmail.com | D1533: FACEBOOK | F1533: JA050895908TH | G1533: คุณตรัยเทพ กุมถะ | H1533: 300
A1534: 1532 | B1534: 243848 | C1534: suckjakkure@hotmail.com | D1534: FACEBOOK | F1534: JA050896165TH | G1534: ลัดดาพวงแก้ว | H1534: 130
... A2292: 2290 | B2292: 243861 | C2292: suckjakkure@hotmail.com | D2292: FACEBOOK | F2292: JA054431383TH | G2292: สุมาลี กิจสมุทร์ | H2292: 130
G2293: ยอดรวม | H2293: =SUM(H3:H2292) -> 437163

Sheet Summary ส.ค.
B1: ข้อมูลการเก็บเงินปลายทาง (COD) แบบรวมยอดประจำวัน เดือนสิงหาคม 2567 | K1: ตรวจในสเตทเม้น
A2: ลำดับ | B2: วันที่ | C2: Email | D2: Tel | E2: Bank Account Number / เลขที่บัญชี | F2: Bank Account Name / ชื่อธนาคาร | G2: Total Order / จำนวนออเดอร์ | H2: COD Amount / ยอดรวม COD | I2: Deduct | J2: Total Amount / ยอดรวม COD | K2: วันที่เงินเข้า | L2: ยอดเข้า | M2: หมายเหตุ
B3: 243831 | C3: suckjakkure@hotmail.com | D3: 0642427575 | E3: 4311469006 | F3: ธนาคารไทยพาณิชย์ (SCB) | G3: 136 | H3: 22930 | I3: 0 | J3: 22930 | K3: 243831 | L3: 22930 | M3: =+L3-J3 -> 0
B4: 243832 | C4: suckjakkure@hotmail.com | D4: 0642427575 | E4: 4311469006 | F4: ธนาคารไทยพาณิชย์ (SCB) | G4: 177 | H4: 32059 | I4: 0 | J4: 32059 | K4: 243832 | L4: 32059 | M4: =+L4-J4 -> 0
B5: 243833 | C5: suckjakkure@hotmail.com | D5: 0642427575 | E5: 4311469006 | F5: ธนาคารไทยพาณิชย์ (SCB) | G5: 169 | H5: 31510 | I5: 0 | J5: 31510 | K5: 243833 | L5: 31510 | M5: =+L5-J5 -> 0
B6: 243834 | C6: suckjakkure@hotmail.com | D6: 0642427575 | E6: 4311469006 | F6: ธนาคารไทยพาณิชย์ (SCB) | G6: 70 | H6: 13150 | I6: 0 | J6: 13150 | K6: 243834 | L6: 13150 | M6: =+L6-J6 -> 0
B7: 243835 | C7: suckjakkure@hotmail.com | D7: 0642427575 | E7: 4311469006 | F7: ธนาคารไทยพาณิชย์ (SCB) | G7: 14 | H7: 2920 | I7: 0 | J7: 2920 | K7: 243835 | L7: 2920 | M7: =+L7-J7 -> 0
B8: 243836 | C8: suckjakkure@hotmail.com | D8: 0642427575 | E8: 4311469006 | F8: ธนาคารไทยพาณิชย์ (SCB) | G8: 110 | H8: 19135 | I8: 0 | J8: 19135 | K8: 243836 | L8: 19135 | M8: =+L8-J8 -> 0
B9: 243837 | C9: suckjakkure@hotmail.com | D9: 0642427575 | E9: 4311469006 | F9: ธนาคารไทยพาณิชย์ (SCB) | G9: 83 | H9: 14080 | I9: 0 | J9: 14080 | K9: 243837 | L9: 14080 | M9: =+L9-J9 -> 0
B10: 243838 | C10: suckjakkure@hotmail.com | D10: 0642427575 | E10: 4311469006 | F10: ธนาคารไทยพาณิชย์ (SCB) | G10: 105 | H10: 18400 | I10: 0 | J10: 18400 | K10: 243838 | L10: 18400 | M10: =+L10-J10 -> 0
B11: 243839 | C11: suckjakkure@hotmail.com | D11: 0642427575 | E11: 4311469006 | F11: ธนาคารไทยพาณิชย์ (SCB) | G11: 101 | H11: 20610 | I11: 0 | J11: 20610 | K11: 243839 | L11: 20610 | M11: =+L11-J11 -> 0
B12: 243840 | C12: suckjakkure@hotmail.com | D12: 0642427575 | E12: 4311469006 | F12: ธนาคารไทยพาณิชย์ (SCB) | G12: 114 | H12: 25750 | I12: 0 | J12: 25750 | K12: 243840 | L12: 25750 | M12: =+L12-J12 -> 0
B13: 243841 | C13: suckjakkure@hotmail.com | D13: 0642427575 | E13: 4311469006 | F13: ธนาคารไทยพาณิชย์ (SCB) | G13: 42 | H13: 9510 | I13: 0 | J13: 9510 | K13: 243841 | L13: 9510 | M13: =+L13-J13 -> 0
B14: 243842 | C14: suckjakkure@hotmail.com | D14: 0642427575 | E14: 4311469006 | F14: ธนาคารไทยพาณิชย์ (SCB) | G14: 27 | H14: 5059 | I14: 0 | J14: 5059 | K14: 243842 | L14: 5059 | M14: =+L14-J14 -> 0
... B30: 243857 | C30: suckjakkure@hotmail.com | D30: 0642427575 | E30: 4311469006 | F30: ธนาคารไทยพาณิชย์ (SCB) | G30: 51 | H30: 8430 | I30: 0 | J30: 8430 | K30: 243857 | L30: 8430 | M30: =+L30-J30 -> 0
B31: 243858 | C31: ไม่ยอดเก็บ COD | K31: 243858 | M31: =+L31-J31 -> 0
B32: 243859 | C32: suckjakkure@hotmail.com | D32: 0642427575 | E32: 4311469006 | F32: ธนาคารไทยพาณิชย์ (SCB) | G32: 73 | H32: 16345 | I32: 0 | J32: 16345 | K32: 243859 | L32: 16345 | M32: =+L32-J32 -> 0
B33: 243860 | C33: suckjakkure@hotmail.com | D33: 0642427575 | E33: 4311469006 | F33: ธนาคารไทยพาณิชย์ (SCB) | G33: 70 | H33: 13000 | I33: 0 | J33: 13000 | K33: 243860 | L33: 13000 | M33: =+L33-J33 -> 0
B34: 243861 | C34: suckjakkure@hotmail.com | D34: 0642427575 | E34: 4311469006 | F34: ธนาคารไทยพาณิชย์ (SCB) | G34: 87 | H34: 15810 | I34: 0 | J34: 15810 | K34: 243861 | L34: 15810 | M34: =+L34-J34 -> 0
F35: ยอดรวม | G35: =SUM(G3:G34) -> 2290 | H35: =SUM(H3:H34) -> 437163 | I35: =SUM(I3:I34) -> 0 | J35: =SUM(J3:J34) -> 437163 | K35: บาท | L35: =SUM(L3:L34) -> 437163 | M35: บาท

Sheet ก.ค.
A1: ข้อมูลการเก็บเงินปลายทาง (COD) แบบแยกรายละเอียด เดือนกรกฏาคม 2567
A2: ลำดับ | B2: วันที่ | C2: Email | D2: Facebook Page | E2: Order No. / เลขที่ออเดอร์ | F2: Tracking No. / เลขพัสดุ | G2: recipientName / ชื่อลูกค้า | H2: Amount / ยอด COD
A3: 1 | B3: 243800 | C3: suckjakkure@hotmail.com | D3: FACEBOOK | F3: JA034630527TH | G3: นางสาวชัชฎาภรณ์ อุดมลาภ | H3: 130
A4: 2 | B4: 243800 | C4: suckjakkure@hotmail.com | D4: FACEBOOK | F4: JA035188006TH | G4: พรทิพย์ อิฐรัตน์ | H4: 130
A5: 3 | B5: 243800 | C5: suckjakkure@hotmail.com | D5: FACEBOOK | F5: JA035187972TH | G5: สายชล | H5: 230
A6: 4 | B6: 243801 | C6: suckjakkure@hotmail.com | D6: FACEBOOK | F6: JA035454470TH | G6: Ao | H6: 130
A7: 5 | B7: 243801 | C7: suckjakkure@hotmail.com | D7: FACEBOOK | F7: JA034911054TH | G7: Kunthida Pasim | H7: 130
A8: 6 | B8: 243801 | C8: suckjakkure@hotmail.com | D8: FACEBOOK | F8: JA035187941TH | G8: มัทนา ป่าเกลือ | H8: 209
A9: 7 | B9: 243801 | C9: suckjakkure@hotmail.com | D9: FACEBOOK | F9: JA035454523TH | G9: มณีกานต์ ไชยฤทธิ์ | H9: 253
A10: 8 | B10: 243801 | C10: suckjakkure@hotmail.com | D10: FACEBOOK | F10: JA035187969TH | G10: วาสนา บุญเนียม | H10: 530
A11: 9 | B11: 243801 | C11: suckjakkure@hotmail.com | D11: FACEBOOK | F11: JA034911037TH | G11: น.ส ทิพานันท์ แสงแก้ว | H11: 130
A12: 10 | B12: 243801 | C12: suckjakkure@hotmail.com | D12: FACEBOOK | F12: JA035187986TH | G12: รอนิง | H12: 170
A13: 11 | B13: 243802 | C13: suckjakkure@hotmail.com | D13: FACEBOOK | F13: JA035866232TH | G13: วิไลวรรณ | H13: 150
A14: 12 | B14: 243802 | C14: suckjakkure@hotmail.com | D14: FACEBOOK | F14: JA035866325TH | G14: น้องคูแปง | H14: 208
... A940: 938 | B940: 243830 | C940: suckjakkure@hotmail.com | D940: FACEBOOK | F940: JA042773880TH | G940: จินตนา ซ้ายหั่น | H940: 130
G941: ยอดรวม | H941: =SUM(H3:H940) -> 190115

Sheet Summary ก.ค.
B1: ข้อมูลการเก็บเงินปลายทาง (COD) แบบรวมยอดประจำวัน เดือนกรกฎาคม 2567 | K1: ตรวจในสเตทเม้น
A2: ลำดับ | B2: วันที่ | C2: Email | D2: Tel | E2: Bank Account Number / เลขที่บัญชี | F2: Bank Account Name / ชื่อธนาคาร | G2: Total Order / จำนวนออเดอร์ | H2: COD Amount / ยอดรวม COD | I2: Deduct | J2: Total Amount / ยอดรวม COD | K2: วันที่เงินเข้า | L2: ยอดเข้า | M2: หมายเหตุ
B3: 243800 | C3: suckjakkure@hotmail.com | D3: 0642427575 | E3: 4311469006 | F3: ธนาคารไทยพาณิชย์ (SCB) | G3: 3 | H3: 490 | I3: 0 | J3: 490 | K3: 243800 | L3: 490 | M3: =+L3-J3 -> 0
B4: 243801 | C4: suckjakkure@hotmail.com | D4: 0642427575 | E4: 4311469006 | F4: ธนาคารไทยพาณิชย์ (SCB) | G4: 7 | H4: 1552 | I4: 0 | J4: 1552 | K4: 243801 | L4: 1552 | M4: =+L4-J4 -> 0
B5: 243802 | C5: suckjakkure@hotmail.com | D5: 0642427575 | E5: 4311469006 | F5: ธนาคารไทยพาณิชย์ (SCB) | G5: 15 | H5: 3360 | I5: 0 | J5: 3360 | K5: 243802 | L5: 3360 | M5: =+L5-J5 -> 0
B6: 243803 | C6: suckjakkure@hotmail.com | D6: 0642427575 | E6: 4311469006 | F6: ธนาคารไทยพาณิชย์ (SCB) | G6: 13 | H6: 3289 | I6: 0 | J6: 3289 | K6: 243803 | L6: 3289 | M6: =+L6-J6 -> 0
B7: 243804 | C7: suckjakkure@hotmail.com | D7: 0642427575 | E7: 4311469006 | F7: ธนาคารไทยพาณิชย์ (SCB) | G7: 13 | H7: 2875 | I7: 0 | J7: 2875 | K7: 243804 | L7: 2875 | M7: =+L7-J7 -> 0
B8: 243805 | C8: suckjakkure@hotmail.com | D8: 0642427575 | E8: 4311469006 | F8: ธนาคารไทยพาณิชย์ (SCB) | G8: 4 | H8: 1077 | I8: 0 | J8: 1077 | K8: 243805 | L8: 1077 | M8: =+L8-J8 -> 0
B9: 243806 | C9: suckjakkure@hotmail.com | D9: 0642427575 | E9: 4311469006 | F9: ธนาคารไทยพาณิชย์ (SCB) | G9: 3 | H9: 680 | I9: 0 | J9: 680 | K9: 243806 | L9: 680 | M9: =+L9-J9 -> 0
B10: 243807 | C10: ไม่ยอดเก็บ COD | K10: 243807 | L10: 0 | M10: =+L10-J10 -> 0
B11: 243808 | C11: suckjakkure@hotmail.com | D11: 0642427575 | E11: 4311469006 | F11: ธนาคารไทยพาณิชย์ (SCB) | G11: 2 | H11: 510 | I11: 0 | J11: 510 | K11: 243808 | L11: 510 | M11: =+L11-J11 -> 0
B12: 243809 | C12: suckjakkure@hotmail.com | D12: 0642427575 | E12: 4311469006 | F12: ธนาคารไทยพาณิชย์ (SCB) | G12: 1 | H12: 180 | I12: 0 | J12: 180 | K12: 243809 | L12: 180 | M12: =+L12-J12 -> 0
B13: 243810 | C13: suckjakkure@hotmail.com | D13: 0642427575 | E13: 4311469006 | F13: ธนาคารไทยพาณิชย์ (SCB) | G13: 14 | H13: 2610 | I13: 0 | J13: 2610 | K13: 243810 | L13: 2610 | M13: =+L13-J13 -> 0
B14: 243811 | C14: suckjakkure@hotmail.com | D14: 0642427575 | E14: 4311469006 | F14: ธนาคารไทยพาณิชย์ (SCB) | G14: 34 | H14: 6110 | I14: 0 | J14: 6110 | K14: 243811 | L14: 6110 | M14: =+L14-J14 -> 0
B15: 243812 | C15: suckjakkure@hotmail.com | D15: 0642427575 | E15: 4311469006 | F15: ธนาคารไทยพาณิชย์ (SCB) | G15: 64 | H15: 11700 | I15: 0 | J15: 11700 | K15: 243812 | L15: 11700 | M15: =+L15-J15 -> 0
B16: 243813 | C16: suckjakkure@hotmail.com | D16: 0642427575 | E16: 4311469006 | F16: ธนาคารไทยพาณิชย์ (SCB) | G16: 50 | H16: 9580 | I16: 0 | J16: 9580 | K16: 243813 | L16: 9580 | M16: =+L16-J16 -> 0
B17: 243814 | C17: suckjakkure@hotmail.com | D17: 0642427575 | E17: 4311469006 | F17: ธนาคารไทยพาณิชย์ (SCB) | G17: 2 | H17: 360 | I17: 0 | J17: 360 | K17: 243814 | L17: 360 | M17: =+L17-J17 -> 0
B18: 243815 | C18: suckjakkure@hotmail.com | D18: 0642427575 | E18: 4311469006 | F18: ธนาคารไทยพาณิชย์ (SCB) | G18: 77 | H18: 18000 | I18: 0 | J18: 18000 | K18: 243815 | L18: 18000 | M18: =+L18-J18 -> 0
B19: 243816 | C19: suckjakkure@hotmail.com | D19: 0642427575 | E19: 4311469006 | F19: ธนาคารไทยพาณิชย์ (SCB) | G19: 84 | H19: 15820 | I19: 0 | J19: 15820 | K19: 243816 | L19: 15820 | M19: =+L19-J19 -> 0
B20: 243817 | C20: suckjakkure@hotmail.com | D20: 0642427575 | E20: 4311469006 | F20: ธนาคารไทยพาณิชย์ (SCB) | G20: 63 | H20: 10970 | I20: 0 | J20: 10970 | K20: 243817 | L20: 10970 | M20: =+L20-J20 -> 0
B21: 243818 | C21: suckjakkure@hotmail.com | D21: 0642427575 | E21: 4311469006 | F21: ธนาคารไทยพาณิชย์ (SCB) | G21: 63 | H21: 11965 | I21: 0 | J21: 11965 | K21: 243818 | L21: 11965 | M21: =+L21-J21 -> 0
B22: 243819 | C22: suckjakkure@hotmail.com | D22: 0642427575 | E22: 4311469006 | F22: ธนาคารไทยพาณิชย์ (SCB) | G22: 54 | H22: 10440 | I22: 0 | J22: 10440 | K22: 243819 | L22: 10440 | M22: =+L22-J22 -> 0
... B25: 243822 | C25: suckjakkure@hotmail.com | D25: 0642427575 | E25: 4311469006 | F25: ธนาคารไทยพาณิชย์ (SCB) | G25: 17 | H25: 3910 | I25: 0 | J25: 3910 | K25: 243822 | L25: 3910 | M25: =+L25-J25 -> 0
B26: 243823 | C26: ไม่ยอดเก็บ COD | K26: 243823 | L26: 0 | M26: =+L26-J26 -> 0
B27: 243824 | C27: suckjakkure@hotmail.com | D27: 0642427575 | E27: 4311469006 | F27: ธนาคารไทยพาณิชย์ (SCB) | G27: 39 | H27: 7695 | I27: 0 | J27: 7695 | K27: 243824 | L27: 7695 | M27: =+L27-J27 -> 0
B28: 243825 | C28: suckjakkure@hotmail.com | D28: 0642427575 | E28: 4311469006 | F28: ธนาคารไทยพาณิชย์ (SCB) | G28: 41 | H28: 9349 | I28: 0 | J28: 9349 | K28: 243825 | L28: 9349 | M28: =+L28-J28 -> 0
B29: 243826 | C29: suckjakkure@hotmail.com | D29: 0642427575 | E29: 4311469006 | F29: ธนาคารไทยพาณิชย์ (SCB) | G29: 86 | H29: 16929 | I29: 0 | J29: 16929 | K29: 243826 | L29: 16929 | M29: =+L29-J29 -> 0
B30: 243827 | C30: suckjakkure@hotmail.com | D30: 0642427575 | E30: 4311469006 | F30: ธนาคารไทยพาณิชย์ (SCB) | G30: 64 | H30: 11870 | I30: 0 | J30: 11870 | K30: 243827 | L30: 11870 | M30: =+L30-J30 -> 0
B31: 243828 | C31: suckjakkure@hotmail.com | D31: 0642427575 | E31: 4311469006 | F31: ธนาคารไทยพาณิชย์ (SCB) | G31: 20 | H31: 3100 | I31: 0 | J31: 3100 | K31: 243828 | L31: 3100 | M31: =+L31-J31 -> 0
B32: 243829 | C32: suckjakkure@hotmail.com | D32: 0642427575 | E32: 4311469006 | F32: ธนาคารไทยพาณิชย์ (SCB) | G32: 8 | H32: 1440 | I32: 0 | J32: 1440 | K32: 243829 | L32: 1440 | M32: =+L32-J32 -> 0
B33: 243830 | C33: suckjakkure@hotmail.com | D33: 0642427575 | E33: 4311469006 | F33: ธนาคารไทยพาณิชย์ (SCB) | G33: 36 | H33: 8679 | I33: 0 | J33: 8679 | K33: 243830 | L33: 8679 | M33: =+L33-J33 -> 0
F34: ยอดรวม | G34: =SUM(G3:G33) -> 938 | H34: =SUM(H3:H33) -> 190115 | I34: =SUM(I3:I33) -> 0 | J34: =SUM(J3:J33) -> 190115 | K34: บาท | L34: =SUM(L3:L33) -> 190115 | M34: บาท

Sheet มิ.ย.
A1: ข้อมูลการเก็บเงินปลายทาง (COD) แบบแยกรายละเอียด เดือนมิถุนายน 2567
A2: ลำดับ | B2: วันที่ | C2: Email | D2: Facebook Page | E2: Order No. / เลขที่ออเดอร์ | F2: Tracking No. / เลขพัสดุ | G2: recipientName / ชื่อลูกค้า | H2: Amount / ยอด COD
A3: 1 | B3: 243770 | C3: suckjakkure@hotmail.com | D3: FACEBOOK | F3: EA981716274TH | G3: พัชณี | H3: 180
A4: 2 | B4: 243770 | C4: suckjakkure@hotmail.com | D4: FACEBOOK | F4: EA982158872TH | G4: คุณหน่อย | H4: 200
A5: 3 | B5: 243772 | C5: suckjakkure@hotmail.com | D5: FACEBOOK | F5: EA982027280TH | G5: นางสาวพรหมภัสสร | H5: 630
A6: 4 | B6: 243772 | C6: suckjakkure@hotmail.com | D6: FACEBOOK | F6: EA982282248TH | G6: น้องพริกหวาน กัญญพัชร | H6: 510
A7: 5 | B7: 243773 | C7: suckjakkure@hotmail.com | D7: FACEBOOK | F7: EA982622794TH | G7: ส่งอทิพรกันตะกูล | H7: 130
A8: 6 | B8: 243774 | C8: suckjakkure@hotmail.com | D8: FACEBOOK | F8: EA983031440TH | G8: น.ส ภาณุมาส ศรีมาพักร์ | H8: 230
A9: 7 | B9: 243775 | C9: suckjakkure@hotmail.com | D9: FACEBOOK | F9: EA983031467TH | G9: กรรณิการ์ จ่ายพอควร | H9: 180
A10: 8 | B10: 243775 | C10: suckjakkure@hotmail.com | D10: FACEBOOK | F10: EA983383849TH | G10: .กนกวรรณ อินพเนาว์ | H10: 180
A11: 9 | B11: 243775 | C11: suckjakkure@hotmail.com | D11: FACEBOOK | F11: EA983383852TH | G11: บริษัทบางพลีใหญ่เพลส จำกัด | H11: 230
A12: 10 | B12: 243775 | C12: suckjakkure@hotmail.com | D12: FACEBOOK | F12: EA983031475TH | G12: ปุณยนุช | H12: 130
A13: 11 | B13: 243776 | C13: suckjakkure@hotmail.com | D13: FACEBOOK | F13: EA983714228TH | G13: อรอุมา | H13: 180
A14: 12 | B14: 243776 | C14: suckjakkure@hotmail.com | D14: FACEBOOK | F14: EA983714280TH | G14: ปัท?มาภรณ์? เต?มะ?ศิริ | H14: 130
... A658: 656 | B658: 243799 | C658: suckjakkure@hotmail.com | D658: FACEBOOK | F658: JA035187955TH | G658: คุณเรวดี เพ็ชรแก้ว | H658: 298
G659: ยอดรวม | H659: =SUM(H3:H658) -> 158315

Sheet Summary มิ.ย.
B1: ข้อมูลการเก็บเงินปลายทาง (COD) แบบรวมยอดประจำวัน เดือนมิถุนายน 2567 | K1: ตรวจในสเตทเม้น
A2: ลำดับ | B2: วันที่ | C2: Email | D2: Tel | E2: Bank Account Number / เลขที่บัญชี | F2: Bank Account Name / ชื่อธนาคาร | G2: Total Order / จำนวนออเดอร์ | H2: COD Amount / ยอดรวม COD | I2: Deduct | J2: Total Amount / ยอดรวม COD | K2: วันที่เงินเข้า | L2: ยอดเข้า | M2: หมายเหตุ
B3: 243770 | C3: suckjakkure@hotmail.com | D3: 0642427575 | E3: 4311469006 | F3: ธนาคารไทยพาณิชย์ (SCB) | G3: 2 | H3: 380 | I3: 0 | J3: 380 | K3: 243770 | L3: 380 | M3: =+L3-J3 -> 0
B4: 243771 | C4: ไม่มียอด COD | K4: 243771 | M4: =+L4-J4 -> 0
B5: 243772 | C5: suckjakkure@hotmail.com | D5: 0642427575 | E5: 4311469006 | F5: ธนาคารไทยพาณิชย์ (SCB) | G5: 2 | H5: 1140 | I5: 0 | J5: 1140 | K5: 243772 | L5: 1140 | M5: =+L5-J5 -> 0
B6: 243773 | C6: suckjakkure@hotmail.com | D6: 0642427575 | E6: 4311469006 | F6: ธนาคารไทยพาณิชย์ (SCB) | G6: 1 | H6: 130 | I6: 0 | J6: 130 | K6: 243773 | L6: 130 | M6: =+L6-J6 -> 0
B7: 243774 | C7: suckjakkure@hotmail.com | D7: 0642427575 | E7: 4311469006 | F7: ธนาคารไทยพาณิชย์ (SCB) | G7: 1 | H7: 230 | I7: 0 | J7: 230 | K7: 243774 | L7: 230 | M7: =+L7-J7 -> 0
B8: 243775 | C8: suckjakkure@hotmail.com | D8: 0642427575 | E8: 4311469006 | F8: ธนาคารไทยพาณิชย์ (SCB) | G8: 4 | H8: 720 | I8: 0 | J8: 720 | K8: 243775 | L8: 720 | M8: =+L8-J8 -> 0
B9: 243776 | C9: suckjakkure@hotmail.com | D9: 0642427575 | E9: 4311469006 | F9: ธนาคารไทยพาณิชย์ (SCB) | G9: 8 | H9: 1470 | I9: 0 | J9: 1470 | K9: 243776 | L9: 1470 | M9: =+L9-J9 -> 0
B10: 243777 | C10: suckjakkure@hotmail.com | D10: 0642427575 | E10: 4311469006 | F10: ธนาคารไทยพาณิชย์ (SCB) | G10: 19 | H10: 3920 | I10: 0 | J10: 3920 | K10: 243777 | L10: 3920 | M10: =+L10-J10 -> 0
B11: 243778 | C11: suckjakkure@hotmail.com | D11: 0642427575 | E11: 4311469006 | F11: ธนาคารไทยพาณิชย์ (SCB) | G11: 15 | H11: 2580 | I11: 0 | J11: 2580 | K11: 243778 | L11: 2580 | M11: =+L11-J11 -> 0
B12: 243779 | C12: suckjakkure@hotmail.com | D12: 0642427575 | E12: 4311469006 | F12: ธนาคารไทยพาณิชย์ (SCB) | G12: 2 | H12: 260 | I12: 0 | J12: 260 | K12: 243779 | L12: 260 | M12: =+L12-J12 -> 0
B13: 243780 | C13: suckjakkure@hotmail.com | D13: 0642427575 | E13: 4311469006 | F13: ธนาคารไทยพาณิชย์ (SCB) | G13: 36 | H13: 6180 | I13: 0 | J13: 6180 | K13: 243780 | L13: 6180 | M13: =+L13-J13 -> 0
B14: 243781 | C14: suckjakkure@hotmail.com | D14: 0642427575 | E14: 4311469006 | F14: ธนาคารไทยพาณิชย์ (SCB) | G14: 40 | H14: 6910 | I14: 0 | J14: 6910 | K14: 243781 | L14: 6910 | M14: =+L14-J14 -> 0
B15: 243782 | C15: suckjakkure@hotmail.com | D15: 0642427575 | E15: 4311469006 | F15: ธนาคารไทยพาณิชย์ (SCB) | G15: 67 | H15: 16136 | I15: 0 | J15: 16136 | K15: 243782 | L15: 16136 | M15: =+L15-J15 -> 0
B16: 243783 | C16: suckjakkure@hotmail.com | D16: 0642427575 | E16: 4311469006 | F16: ธนาคารไทยพาณิชย์ (SCB) | G16: 56 | H16: 13390 | I16: 0 | J16: 13390 | K16: 243783 | L16: 13390 | M16: =+L16-J16 -> 0
... B27: 243794 | C27: suckjakkure@hotmail.com | D27: 0642427575 | E27: 4311469006 | F27: ธนาคารไทยพาณิชย์ (SCB) | G27: 22 | H27: 5438 | I27: 0 | J27: 5438 | K27: 243794 | L27: 5438 | M27: =+L27-J27 -> 0
B28: 243795 | C28: suckjakkure@hotmail.com | D28: 0642427575 | E28: 4311469006 | F28: ธนาคารไทยพาณิชย์ (SCB) | G28: 27 | H28: 7017 | I28: 0 | J28: 7017 | K28: 243795 | L28: 7017 | M28: =+L28-J28 -> 0
B29: 243796 | C29: suckjakkure@hotmail.com | D29: 0642427575 | E29: 4311469006 | F29: ธนาคารไทยพาณิชย์ (SCB) | G29: 28 | H29: 7034 | I29: 0 | J29: 7034 | K29: 243796 | L29: 7034 | M29: =+L29-J29 -> 0
B30: 243797 | C30: suckjakkure@hotmail.com | D30: 0642427575 | E30: 4311469006 | F30: ธนาคารไทยพาณิชย์ (SCB) | G30: 25 | H30: 7580 | I30: 0 | J30: 7580 | K30: 243797 | L30: 7580 | M30: =+L30-J30 -> 0
B31: 243798 | C31: suckjakkure@hotmail.com | D31: 0642427575 | E31: 4311469006 | F31: ธนาคารไทยพาณิชย์ (SCB) | G31: 21 | H31: 8064 | I31: 0 | J31: 8064 | K31: 243798 | L31: 8064 | M31: =+L31-J31 -> 0
B32: 243799 | C32: suckjakkure@hotmail.com | D32: 0642427575 | E32: 4311469006 | F32: ธนาคารไทยพาณิชย์ (SCB) | G32: 4 | H32: 1112 | I32: 0 | J32: 1112 | K32: 243799 | L32: 1112 | M32: =+L32-J32 -> 0
F33: ยอดรวม | G33: =SUM(G3:G32) -> 551 | H33: =SUM(H3:H32) -> 127508 | I33: =SUM(I3:I32) -> 0 | J33: =SUM(J3:J32) -> 127508 | K33: บาท | L33: =SUM(L3:L32) -> 158315 | M33: บาท

Sheet พ.ค.
A1: ข้อมูลการเก็บเงินปลายทาง (COD) แบบแยกรายละเอียด เดือนพฤษภาคม 2567
A2: ลำดับ | B2: วันที่ | C2: Email | D2: Facebook Page | E2: Order No. / เลขที่ออเดอร์ | F2: Tracking No. / เลขพัสดุ | G2: recipientName / ชื่อลูกค้า | H2: Amount / ยอด COD
A3: 1 | B3: 243739 | C3: suckjakkure@hotmail.com | D3: FACEBOOK | F3: EA971778331TH | G3: รัชติญา จันทร์ไตรัต | H3: 480
A4: 2 | B4: 243739 | C4: suckjakkure@hotmail.com | D4: FACEBOOK | F4: EA972083715TH | G4: อภิชาติ..ยอดทอง | H4: 160
A5: 3 | B5: 243739 | C5: suckjakkure@hotmail.com | D5: FACEBOOK | F5: EA971185877TH | G5: น.ส | H5: 480
A6: 4 | B6: 243739 | C6: suckjakkure@hotmail.com | D6: FACEBOOK | F6: EA972169411TH | G6: ต่าย | H6: 250
A7: 5 | B7: 243739 | C7: suckjakkure@hotmail.com | D7: FACEBOOK | F7: EA972083755TH | G7: ศิวภรณ์ ทองคำ | H7: 160
A8: 6 | B8: 243739 | C8: suckjakkure@hotmail.com | D8: FACEBOOK | F8: EA972355396TH | G8: นางวรรณภา บุญไพโรจน์ | H8: 180
A9: 7 | B9: 243739 | C9: suckjakkure@hotmail.com | D9: FACEBOOK | F9: EA971778402TH | G9: ครูบาแชค | H9: 180
A10: 8 | B10: 243739 | C10: suckjakkure@hotmail.com | D10: FACEBOOK | F10: EA972083786TH | G10: ชัย วิทย์ไชยพิมพ์ | H10: 180
A11: 9 | B11: 243739 | C11: suckjakkure@hotmail.com | D11: FACEBOOK | F11: EA972083772TH | G11: อุไร อินทรโชติ | H11: 330
A12: 10 | B12: 243739 | C12: suckjakkure@hotmail.com | D12: FACEBOOK | F12: EA972550744TH | G12: ชลิตา เหมฤดี | H12: 180
A13: 11 | B13: 243739 | C13: suckjakkure@hotmail.com | D13: FACEBOOK | F13: EA972355351TH | G13: แจ้ | H13: 590
A14: 12 | B14: 243739 | C14: suckjakkure@hotmail.com | D14: FACEBOOK | F14: EA972355379TH | G14: คุณพิสิษฐ์ซ.เลือดหมูคุณศรี | H14: 300
... A161: 159 | B161: 243768 | C161: suckjakkure@hotmail.com | D161: FACEBOOK | F161: EA981058348TH | G161: สุรเชษฐ์ รัตนพิทักษ์ | H161: 180
A162: 160
A163: 161
A164: 162
A165: 163
A166: 164
A167: 165
A168: 166
A169: 167
A170: 168
A171: 169
A172: 170
A173: 171
... A862: 860
G863: ยอดรวม | H863: =SUM(H3:H862) -> 45005

Sheet Summary พ.ค.
B1: ข้อมูลการเก็บเงินปลายทาง (COD) แบบรวมยอดประจำวัน เดือนพฤษภาคม 2567 | K1: ตรวจในสเตทเม้น
A2: ลำดับ | B2: วันที่ | C2: Email | D2: Tel | E2: Bank Account Number / เลขที่บัญชี | F2: Bank Account Name / ชื่อธนาคาร | G2: Total Order / จำนวนออเดอร์ | H2: COD Amount / ยอดรวม COD | I2: Deduct | J2: Total Amount / ยอดรวม COD | K2: วันที่เงินเข้า | L2: ยอดเข้า | M2: หมายเหตุ
B3: 243739 | C3: suckjakkure@hotmail.com | D3: 0642427575 | E3: 4311469006 | F3: ธนาคารไทยพาณิชย์ (SCB) | G3: 13 | H3: 3650 | I3: 0 | J3: 3650 | K3: 243739 | L3: 3650 | M3: =+L3-J3 -> 0
B4: 243740 | C4: suckjakkure@hotmail.com | D4: 0642427575 | E4: 4311469006 | F4: ธนาคารไทยพาณิชย์ (SCB) | G4: 3 | H4: 1410 | I4: 0 | J4: 1410 | K4: 243740 | L4: 1410 | M4: =+L4-J4 -> 0
B5: 243741 | C5: suckjakkure@hotmail.com | D5: 0642427575 | E5: 4311469006 | F5: ธนาคารไทยพาณิชย์ (SCB) | G5: 18 | H5: 3701 | I5: 0 | J5: 3701 | K5: 243741 | L5: 3701 | M5: =+L5-J5 -> 0
B6: 243742 | C6: suckjakkure@hotmail.com | D6: 0642427575 | E6: 4311469006 | F6: ธนาคารไทยพาณิชย์ (SCB) | G6: 23 | H6: 6457 | I6: 0 | J6: 6457 | K6: 243742 | L6: 6457 | M6: =+L6-J6 -> 0
B7: 243743 | C7: suckjakkure@hotmail.com | D7: 0642427575 | E7: 4311469006 | F7: ธนาคารไทยพาณิชย์ (SCB) | G7: 4 | H7: 850 | I7: 0 | J7: 850 | K7: 243743 | L7: 850 | M7: =+L7-J7 -> 0
B8: 243744 | C8: suckjakkure@hotmail.com | D8: 0642427575 | E8: 4311469006 | F8: ธนาคารไทยพาณิชย์ (SCB) | G8: 6 | H8: 1970 | I8: 0 | J8: 1970 | K8: 243744 | L8: 1970 | M8: =+L8-J8 -> 0
