Workbook

Sheet สรุป
A1: ข้อมูลการเก็บเงินปลายทาง (COD) ปี 2568
A2: ลำดับ | B2: Total Order / จำนวนออเดอร์ | C2: COD Amount / ยอดรวม COD | D2: Deduct | E2: Total Amount / ยอดรวม COD | G2: ยอดลดหนี้ COD
A3: 1 | B3: =+'Summary ม.ค.'!G37 -> 474 | C3: =+'Summary ม.ค.'!H37 -> 233401 | D3: =+'Summary ม.ค.'!I37 -> 0 | E3: =+'Summary ม.ค.'!J37 -> 233401 | G3: =+[1]สรุป!$B$3 -> 0
A4: 2 | B4: =+'Summary ก.พ.'!G31 -> 264 | C4: =+'Summary ก.พ.'!H31 -> 61187 | D4: =+'Summary ก.พ.'!I31 -> 0 | E4: =+'Summary ก.พ.'!J31 -> 61187 | G4: 2853
A5: 3 | B5: =+'Summary มี.ค.'!G36 -> 374 | C5: =+'Summary มี.ค.'!H36 -> 101510 | D5: =+'Summary มี.ค.'!I36 -> 0 | E5: =+'Summary มี.ค.'!J36 -> 101510 | G5: =+[1]สรุป!$B$5 -> 0
A6: 4 | B6: =+'Summary เม.ย.'!G36 -> 428 | C6: =+'Summary เม.ย.'!H36 -> 115672 | D6: =+'Summary เม.ย.'!I36 -> 0 | E6: =+'Summary เม.ย.'!J36 -> 115672 | G6: =+[1]สรุป!$B$6 -> 0
A7: 5 | B7: =+'Summary พ.ค.'!G34 -> 200 | C7: =+'Summary พ.ค.'!H34 -> 54991 | D7: =+'Summary พ.ค.'!I34 -> 0 | E7: =+'Summary พ.ค.'!J34 -> 54991 | G7: 2264
A8: 6 | B8: =+'Summary มิ.ย.'!G33 -> 359 | C8: =+'Summary มิ.ย.'!H33 -> 90000 | D8: =+'Summary มิ.ย.'!I33 -> 0 | E8: =+'Summary มิ.ย.'!J33 -> 90000 | G8: =+'[2]มิ.ย.'!$G$2 -> 0
A9: 7 | B9: =+'Summary ก.ค.'!G34 -> 344 | C9: =+'Summary ก.ค.'!H34 -> 86672 | D9: =+'Summary มิ.ย.'!I33 -> 0 | E9: =+'Summary ก.ค.'!J34 -> 86672 | G9: 0
A10: 8 | B10: =+'Summary ส.ค.'!G39 -> 480 | C10: =+'Summary ส.ค.'!H39 -> 123860 | D10: =+'Summary ส.ค.'!I39 -> 0 | E10: =+'Summary ส.ค.'!J39 -> 123860 | G10: 0
A11: 9 | B11: =+'Summary ก.ย.'!G35 -> 323 | C11: =+'Summary ก.ย.'!H35 -> 99658 | D11: =+'Summary ก.ย.'!I35 -> 0 | E11: =+'Summary ก.ย.'!J35 -> 99658 | G11: 0
A12: 10 | B12: =+'Summary ต.ค.'!G35 -> 283 | C12: =+'Summary ต.ค.'!H35 -> 76274 | D12: =+'Summary ต.ค.'!I35 -> 0 | E12: =+'Summary ต.ค.'!J35 -> 76274
A13: 11 | B13: =+'Summary พ.ย.'!G35 -> 192 | C13: =+'Summary พ.ย.'!H35 -> 49540 | D13: =+'Summary พ.ย.'!I35 -> 0 | E13: =+'Summary พ.ย.'!J35 -> 49540
A14: 12 | B14: =+'Summary ธ.ค.'!G35 -> 115 | C14: =+'Summary ธ.ค.'!H35 -> 37714 | D14: =+'Summary ธ.ค.'!I35 -> 0 | E14: =+'Summary ธ.ค.'!J35 -> 37714
A15: 13 | B15: =SUM(B3:B14) -> 3836 | C15: =SUM(C3:C14) -> 1130479 | D15: =SUM(D3:D14) -> 0 | E15: =SUM(E3:E14) -> 1130479 | F15: บาท | G15: =SUM(G3:G14) -> 5117

Sheet ธ.ค.
A1: ข้อมูลการเก็บเงินปลายทาง (COD) แบบแยกรายละเอียด เดือนธันวาคม 2568
A2: ลำดับ | B2: วันที่ | C2: Email | D2: Facebook Page | E2: Order No. / เลขที่ออเดอร์ | F2: Tracking No. / เลขพัสดุ | G2: recipientName / ชื่อลูกค้า | H2: Amount / ยอด COD
A3: 1 | B3: 244026 | C3: suckjakkure@hotmail.com | D3: FACEBOOK | F3: WA046651657TH | G3: โดนัท | H3: 648
A4: 2 | B4: 244055 | C4: suckjakkure@hotmail.com | D4: FACEBOOK | F4: WA047489493TH | G4: สุดา นิลเพ็ชร | H4: 215
A5: 3 | B5: 244055 | C5: suckjakkure@hotmail.com | D5: FACEBOOK | F5: WA047195375TH | G5: สุนีรัตน์ เหล่าโก้ก | H5: 215
A6: 4 | B6: 244116 | C6: suckjakkure@hotmail.com | D6: FACEBOOK | F6: WA047787126TH | G6: ศุภษิต นทีกุลเจริญ | H6: 215
A7: 5 | B7: 244116 | C7: suckjakkure@hotmail.com | D7: FACEBOOK | F7: WA048452225TH | G7: ศิริพร แจ่มสว่าง | H7: 215
A8: 6 | B8: 244116 | C8: suckjakkure@hotmail.com | D8: FACEBOOK | F8: WA048623614TH | G8: บุญพอ | H8: 199
A9: 7 | B9: 244116 | C9: suckjakkure@hotmail.com | D9: FACEBOOK | F9: WA048623631TH | G9: นงนุช ตันติวรสิทธิ์ | H9: 199
A10: 8 | B10: 244116 | C10: suckjakkure@hotmail.com | D10: FACEBOOK | F10: WA048452248TH | G10: ประภา น้อยชม | H10: 199
A11: 9 | B11: 244116 | C11: suckjakkure@hotmail.com | D11: FACEBOOK | F11: WA048452234TH | G11: ดารณี ปลื้มถนอม | H11: 199
A12: 10 | B12: 244147 | C12: suckjakkure@hotmail.com | D12: FACEBOOK | F12: WA048452217TH | G12: ธัญสิทธิ์ ปิติพรเมธาวีร์ | H12: 199
A13: 11 | B13: 244147 | C13: suckjakkure@hotmail.com | D13: FACEBOOK | F13: WA048452265TH | G13: เยี่ยมศรี_กฤตสิน | H13: 430
A14: 12 | B14: 244147 | C14: suckjakkure@hotmail.com | D14: FACEBOOK | F14: WA048961594TH | G14: พรทิพย์ สัมโปสะเสน | H14: 398
... A34: 32 | B34: 244177 | C34: suckjakkure@hotmail.com | D34: FACEBOOK | F34: WA059748677TH | G34: อัญชลี กิจวิริยะ | H34: 199
A35: 33 | B35: 244208 | C35: suckjakkure@hotmail.com | D35: FACEBOOK | F35: WA048623645TH | G35: =SUM(G3:G34) -> 0 | H35: =SUM(H3:H34) -> 7957 | I35: =SUM(I3:I34) -> 0 | J35: =SUM(J3:J34) -> 0 | L35: =SUM(L3:L34) -> 0
A36: 34 | B36: 244239 | C36: suckjakkure@hotmail.com | D36: FACEBOOK | F36: WA060007757TH | G36: กรณ์กาญจน์ สิทธิสำอางค์ | H36: 398
A37: 35 | B37: 244239 | C37: suckjakkure@hotmail.com | D37: FACEBOOK | F37: WA059748632TH | G37: สุรีรัตน์ ใจยินดี | H37: 215
A38: 36 | B38: 244239 | C38: suckjakkure@hotmail.com | D38: FACEBOOK | F38: WA059748629TH | G38: กานต์ สุขศรีชวลิต | H38: 215
A39: 37 | B39: 244239 | C39: suckjakkure@hotmail.com | D39: FACEBOOK | F39: WA060007791TH | G39: นาง ละมัยเวชก่ามา | H39: 199
A40: 38 | B40: 244239 | C40: suckjakkure@hotmail.com | D40: FACEBOOK | F40: WA048961617TH | G40: สุดารัตน์ ศรีสำราญ | H40: 199
A41: 39 | B41: 244239 | C41: suckjakkure@hotmail.com | D41: FACEBOOK | F41: WA048972929TH | G41: จรรยา สัตนาโค | H41: 199
A42: 40 | B42: 244239 | C42: suckjakkure@hotmail.com | D42: FACEBOOK | F42: WA060007805TH | G42: คุณอ้อม เพชรเครือ | H42: 199
A43: 41 | B43: 244239 | C43: suckjakkure@hotmail.com | D43: FACEBOOK | F43: WA059748615TH | G43: บงกชธร พิมพา | H43: 977
A44: 42 | B44: 244239 | C44: suckjakkure@hotmail.com | D44: FACEBOOK | F44: WA060007765TH | G44: คุณแอม | H44: 199
A45: 43 | B45: 244239 | C45: suckjakkure@hotmail.com | D45: FACEBOOK | F45: WA048961577TH | G45: นางสาวเจนจิรา นาครัตน์ | H45: 199
A46: 44 | B46: 244269 | C46: suckjakkure@hotmail.com | D46: FACEBOOK | F46: WA060007774TH | G46: คุณเอ้ | H46: 199
A47: 45 | B47: 244269 | C47: suckjakkure@hotmail.com | D47: FACEBOOK | F47: WA060007788TH | G47: นส.อาทิตย์ญา.เรืองเนตร | H47: 199
... A50: 48 | B50: 244330 | C50: suckjakkure@hotmail.com | D50: FACEBOOK | F50: WA048452251TH | G50: เล็ก | H50: 199
A51: 49 | B51: 13/12/2568 | C51: suckjakkure@hotmail.com | D51: FACEBOOK | F51: WA061110778TH | G51: คุณเดชา | H51: 215
A52: 50 | B52: 13/12/2568 | C52: suckjakkure@hotmail.com | D52: FACEBOOK | F52: WA061110747TH | G52: หวล-ตะโฉ | H52: 215
A53: 51 | B53: 13/12/2568 | C53: suckjakkure@hotmail.com | D53: FACEBOOK | F53: WA061112164TH | G53: ชูชาติ วิชิต | H53: 315
A54: 52 | B54: 14/12/2568 | C54: suckjakkure@hotmail.com | D54: FACEBOOK | F54: WA061652460TH | G54: กรณ์กาญจน์ สิทธิสำอางค์ | H54: 300
A55: 53 | B55: 14/12/2568 | C55: suckjakkure@hotmail.com | D55: FACEBOOK | F55: WA061652495TH | G55: นงนุช ตันติวรสิทธิ์ | H55: 299
A56: 54 | B56: 14/12/2568 | C56: suckjakkure@hotmail.com | D56: FACEBOOK | F56: WA061652500TH | G56: อมร ร่มใจ | H56: 199
A57: 55 | B57: 14/12/2568 | C57: suckjakkure@hotmail.com | D57: FACEBOOK | F57: WA061656210TH | G57: ภัทริยา ปานกุล | H57: 215
A58: 56 | B58: 14/12/2568 | C58: suckjakkure@hotmail.com | D58: FACEBOOK | F58: WA061652487TH | G58: Chudmongkol Mungkunkumsaw | H58: 430
A59: 57 | B59: 14/12/2568 | C59: suckjakkure@hotmail.com | D59: FACEBOOK | F59: WA061656206TH | G59: ยุวดี | H59: 430
A60: 58 | B60: 15/12/2568 | C60: suckjakkure@hotmail.com | D60: FACEBOOK | F60: WA061912275TH | G60: คุณรัชนี ราชู | H60: 950
A61: 59 | B61: 15/12/2568 | C61: suckjakkure@hotmail.com | D61: FACEBOOK | F61: WA061652473TH | G61: จิตรา | H61: 299
...

Sheet Summary ธ.ค.
A1: ข้อมูลการเก็บเงินปลายทาง (COD) แบบรวมยอดประจำวัน เดือนธันวาคม 2568 | K1: ตรวจในสเตทเม้น
A2: ลำดับ | B2: วันที่ | C2: Email | D2: Tel | E2: Bank Account Number / เลขที่บัญชี | F2: Bank Account Name / ชื่อธนาคาร | G2: Total Order / จำนวนออเดอร์ | H2: COD Amount / ยอดรวม COD | I2: Deduct | J2: Total Amount / ยอดรวม COD | K2: วันที่เงินเข้า | L2: ยอดเข้า | M2: หมายเหตุ
A3: 1 | B3: 244319 | C3: ไม่มียอดเก็บ COD | K3: 244319 | M3: =+L3-J3 -> 0
A4: 2 | B4: 244320 | C4: suckjakkure@hotmail.com | D4: 642427575 | E4: 4311469006 | F4: ธนาคารไทยพาณิชย์ (SCB) | G4: 1 | H4: 648 | I4: 0 | J4: 648 | K4: 244320 | L4: 648 | M4: =+L4-J4 -> 0
A5: 3 | B5: 244321 | C5: suckjakkure@hotmail.com | D5: 642427575 | E5: 4311469006 | F5: ธนาคารไทยพาณิชย์ (SCB) | G5: 2 | H5: 430 | I5: 0 | J5: 430 | K5: 244321 | L5: 430 | M5: =+L5-J5 -> 0
A6: 4 | B6: 244322 | C6: ไม่มียอดเก็บ COD | K6: 244322 | M6: =+L6-J6 -> 0
A7: 5 | B7: 244323 | C7: suckjakkure@hotmail.com | D7: 642427575 | E7: 4311469006 | F7: ธนาคารไทยพาณิชย์ (SCB) | G7: 6 | H7: 1226 | I7: 0 | J7: 1226 | K7: 244323 | L7: 1226 | M7: =+L7-J7 -> 0
A8: 6 | B8: 244324 | C8: suckjakkure@hotmail.com | D8: 642427575 | E8: 4311469006 | F8: ธนาคารไทยพาณิชย์ (SCB) | G8: 10 | H8: 2851 | I8: 0 | J8: 2851 | K8: 244324 | L8: 2851 | M8: =+L8-J8 -> 0
A9: 7 | B9: 244325 | C9: suckjakkure@hotmail.com | D9: 642427575 | E9: 4311469006 | F9: ธนาคารไทยพาณิชย์ (SCB) | G9: 13 | H9: 2802 | I9: 0 | J9: 2802 | K9: 244325 | L9: 2802 | M9: =+L9-J9 -> 0
A10: 8 | B10: 244326 | C10: suckjakkure@hotmail.com | D10: 642427575 | E10: 4311469006 | F10: ธนาคารไทยพาณิชย์ (SCB) | G10: 1 | H10: 398 | I10: 0 | J10: 398 | K10: 244326 | L10: 398 | M10: =+L10-J10 -> 0
A11: 9 | B11: 244327 | C11: suckjakkure@hotmail.com | D11: 642427575 | E11: 4311469006 | F11: ธนาคารไทยพาณิชย์ (SCB) | G11: 10 | H11: 2999 | I11: 0 | J11: 2999 | K11: 244327 | L11: 2999 | M11: =+L11-J11 -> 0
A12: 10 | B12: 244328 | C12: suckjakkure@hotmail.com | D12: 642427575 | E12: 4311469006 | F12: ธนาคารไทยพาณิชย์ (SCB) | G12: 2 | H12: 398 | I12: 0 | J12: 398 | K12: 244328 | L12: 398 | M12: =+L12-J12 -> 0
A13: 11 | B13: 244329 | C13: ไม่มียอดเก็บ COD | K13: 244329 | M13: =+L13-J13 -> 0
A14: 12 | B14: 244330 | C14: suckjakkure@hotmail.com | D14: 642427575 | E14: 4311469006 | F14: ธนาคารไทยพาณิชย์ (SCB) | G14: 3 | H14: 813 | I14: 0 | J14: 813 | K14: 244330 | L14: 813 | M14: =+L14-J14 -> 0
A15: 13 | B15: 244331 | C15: suckjakkure@hotmail.com | D15: 642427575 | E15: 4311469006 | F15: ธนาคารไทยพาณิชย์ (SCB) | G15: 3 | H15: 745 | I15: 0 | J15: 745 | K15: 244331 | L15: 745 | M15: =+L15-J15 -> 0
A16: 14 | B16: 244332 | C16: suckjakkure@hotmail.com | D16: 642427575 | E16: 4311469006 | F16: ธนาคารไทยพาณิชย์ (SCB) | G16: 6 | H16: 1873 | I16: 0 | J16: 1873 | K16: 244332 | L16: 1873 | M16: =+L16-J16 -> 0
A17: 15 | B17: 244333 | C17: suckjakkure@hotmail.com | D17: 642427575 | E17: 4311469006 | F17: ธนาคารไทยพาณิชย์ (SCB) | G17: 2 | H17: 1249 | I17: 0 | J17: 1249 | K17: 244333 | L17: 1249 | M17: =+L17-J17 -> 0
A18: 16 | B18: 244334 | C18: suckjakkure@hotmail.com | D18: 642427575 | E18: 4311469006 | F18: ธนาคารไทยพาณิชย์ (SCB) | G18: 2 | H18: 430 | I18: 0 | J18: 430 | K18: 244334 | L18: 430 | M18: =+L18-J18 -> 0
A19: 17 | B19: 244335 | C19: suckjakkure@hotmail.com | D19: 642427575 | E19: 4311469006 | F19: ธนาคารไทยพาณิชย์ (SCB) | G19: 2 | H19: 514 | I19: 0 | J19: 514 | K19: 244335 | L19: 514 | M19: =+L19-J19 -> 0
A20: 18 | B20: 244336 | C20: suckjakkure@hotmail.com | D20: 642427575 | E20: 4311469006 | F20: ธนาคารไทยพาณิชย์ (SCB) | G20: 7 | H20: 1489 | I20: 0 | J20: 1489 | K20: 244336 | L20: 1489 | M20: =+L20-J20 -> 0
A21: 19 | B21: 244337 | C21: suckjakkure@hotmail.com | D21: 642427575 | E21: 4311469006 | F21: ธนาคารไทยพาณิชย์ (SCB) | G21: 5 | H21: 1290 | I21: 0 | J21: 1290 | K21: 244337 | L21: 1290 | M21: =+L21-J21 -> 0
A22: 20 | B22: 244338 | C22: suckjakkure@hotmail.com | D22: 642427575 | E22: 4311469006 | F22: ธนาคารไทยพาณิชย์ (SCB) | G22: 3 | H22: 1841 | I22: 0 | J22: 1841 | K22: 244338 | L22: 1841 | M22: =+L22-J22 -> 0
A23: 21 | B23: 244339 | C23: suckjakkure@hotmail.com | D23: 642427575 | E23: 4311469006 | F23: ธนาคารไทยพาณิชย์ (SCB) | G23: 5 | H23: 1075 | I23: 0 | J23: 1075 | K23: 244339 | L23: 1075 | M23: =+L23-J23 -> 0
A24: 22 | B24: 244340 | C24: suckjakkure@hotmail.com | D24: 642427575 | E24: 4311469006 | F24: ธนาคารไทยพาณิชย์ (SCB) | G24: 2 | H24: 498 | I24: 0 | J24: 498 | K24: 244340 | L24: 498 | M24: =+L24-J24 -> 0
A25: 23 | B25: 244341 | C25: suckjakkure@hotmail.com | D25: 642427575 | E25: 4311469006 | F25: ธนาคารไทยพาณิชย์ (SCB) | G25: 1 | H25: 215 | I25: 0 | J25: 215 | K25: 244341 | L25: 215 | M25: =+L25-J25 -> 0
... A34: 32 | B34: 244349 | C34: suckjakkure@hotmail.com | D34: 642427575 | E34: 4311469006 | F34: ธนาคารไทยพาณิชย์ (SCB) | G34: 3 | H34: 1720 | I34: 0 | J34: 1720 | K34: 244349 | L34: 1720 | M34: =+L34-J34 -> 0
F35: ยอดรวม | G35: =SUM(G3:G34) -> 115 | H35: =SUM(H3:H34) -> 37714 | I35: =SUM(I3:I34) -> 0 | J35: =SUM(J3:J34) -> 37714 | K35: บาท | L35: =SUM(L3:L34) -> 37714 | M35: บาท

Sheet พ.ย.
A1: ข้อมูลการเก็บเงินปลายทาง (COD) แบบแยกรายละเอียด เดือนพฤศจิกายน 2568
A2: ลำดับ | B2: วันที่ | C2: Email | D2: Facebook Page | E2: Order No. / เลขที่ออเดอร์ | F2: Tracking No. / เลขพัสดุ | G2: recipientName / ชื่อลูกค้า | H2: Amount / ยอด COD
A3: 1 | B3: 243994 | C3: suckjakkure@hotmail.com | D3: FACEBOOK | F3: WA038464153TH | G3: ขนพ ชีวอารี | H3: 399
A4: 2 | B4: 243994 | C4: suckjakkure@hotmail.com | D4: FACEBOOK | F4: WA038464215TH | G4: คุณวรรณ | H4: 215
A5: 3 | B5: 243994 | C5: suckjakkure@hotmail.com | D5: FACEBOOK | F5: WA038464175TH | G5: กร ทิงสวย | H5: 399
A6: 4 | B6: 243994 | C6: suckjakkure@hotmail.com | D6: FACEBOOK | F6: WA038464136TH | G6: เธียรชัย โสภาชื่น | H6: 399
A7: 5 | B7: 243994 | C7: suckjakkure@hotmail.com | D7: FACEBOOK | F7: WA038464119TH | G7: พิศน์ชญาณ์ ประสานศิลป์ | H7: 748
A8: 6 | B8: 243994 | C8: suckjakkure@hotmail.com | D8: FACEBOOK | F8: WA038853255TH | G8: Wattana Khongnoy | H8: 215
A9: 7 | B9: 243994 | C9: suckjakkure@hotmail.com | D9: FACEBOOK | F9: WA038853238TH | G9: ขวัญจิต | H9: 150
A10: 8 | B10: 243994 | C10: suckjakkure@hotmail.com | D10: FACEBOOK | F10: WA038853224TH | G10: คุณสุชารัตน์ ปิติกรวุฒิวัฒน์ | H10: 399
A11: 9 | B11: 243994 | C11: suckjakkure@hotmail.com | D11: FACEBOOK | F11: WA038464198TH | G11: Pradid Jaidee | H11: 399
A12: 10 | B12: 243994 | C12: suckjakkure@hotmail.com | D12: FACEBOOK | F12: WA038853241TH | G12: นงนุช ตันติวรสิทธิ์ | H12: 299
A13: 11 | B13: 243994 | C13: suckjakkure@hotmail.com | D13: FACEBOOK | F13: WA038464207TH | G13: วันชัย มาตุภูมานนท์ | H13: 215
A14: 12 | B14: 243994 | C14: suckjakkure@hotmail.com | D14: FACEBOOK | F14: WA038464079TH | G14: จิรดา รอดเจริญ | H14: 215
... A34: 32 | B34: 244085 | C34: suckjakkure@hotmail.com | D34: FACEBOOK | F34: WA039298568TH | G34: สุรสิทธิ์ หัทยาสมบูรณ์ | H34: 399
A35: 33 | B35: 244115 | C35: suckjakkure@hotmail.com | D35: FACEBOOK | F35: WA039144473TH | G35: =SUM(G3:G34) -> 0 | H35: =SUM(H3:H34) -> 10454 | I35: =SUM(I3:I34) -> 0 | J35: =SUM(J3:J34) -> 0 | L35: =SUM(L3:L34) -> 0
A36: 34 | B36: 244115 | C36: suckjakkure@hotmail.com | D36: FACEBOOK | F36: WA039673087TH | G36: ลดาวัลย์ รุ่งเรืองผล | H36: 150
A37: 35 | B37: 244115 | C37: suckjakkure@hotmail.com | D37: FACEBOOK | F37: WA039298554TH | G37: เพียร แสงศรี | H37: 399
A38: 36 | B38: 244115 | C38: suckjakkure@hotmail.com | D38: FACEBOOK | F38: WA038853272TH | G38: มัสยา ยอดชาญ | H38: 399
A39: 37 | B39: 244115 | C39: suckjakkure@hotmail.com | D39: FACEBOOK | F39: WA039298611TH | G39: น.ส.บุณยนุช เข็มปัญญา | H39: 215
A40: 38 | B40: 244115 | C40: suckjakkure@hotmail.com | D40: FACEBOOK | F40: WA039424147TH | G40: วิโรจน์ ปาปะไกร | H40: 215
A41: 39 | B41: 244146 | C41: suckjakkure@hotmail.com | D41: FACEBOOK | F41: WA040713407TH | G41: จรูญรัตน์ แสงสว่างแอน | H41: 299
A42: 40 | B42: 244146 | C42: suckjakkure@hotmail.com | D42: FACEBOOK | F42: WA040713415TH | G42: เนาวรัตน์ | H42: 299
A43: 41 | B43: 244146 | C43: suckjakkure@hotmail.com | D43: FACEBOOK | F43: WA039833305TH | G43: กาญจนา สุขมาก | H43: 215
A44: 42 | B44: 244146 | C44: suckjakkure@hotmail.com | D44: FACEBOOK | F44: WA039424133TH | G44: ุคุณจรัสศรี ทองสุข | H44: 215
A45: 43 | B45: 244146 | C45: suckjakkure@hotmail.com | D45: FACEBOOK | F45: WA040713441TH | G45: นางสาวศรีสกุล แดงไสว | H45: 625
A46: 44 | B46: 244146 | C46: suckjakkure@hotmail.com | D46: FACEBOOK | F46: WA039833291TH | G46: เจ๊เอ๋ร้านช่างเลี้ยงยางซิ่ง | H46: 399
A47: 45 | B47: 244176 | C47: suckjakkure@hotmail.com | D47: FACEBOOK | F47: WA040996884TH | G47: วลัยรัตน์ ดำรงศิลป์ | H47: 199
... A71: 69 | B71: 244329 | C71: suckjakkure@hotmail.com | D71: FACEBOOK | F71: WA042167995TH | G71: พัฒน์รวี เกียรติแสงทอง | H71: 199
A72: 70 | B72: 13/11/2568 | C72: suckjakkure@hotmail.com | D72: FACEBOOK | F72: WA042167942TH | G72: วาสนา | H72: 398
A73: 71 | B73: 13/11/2568 | C73: suckjakkure@hotmail.com | D73: FACEBOOK | F73: WA042655239TH | G73: ลดาวัลย์ รุ่งเรืองผล | H73: 200
A74: 72 | B74: 13/11/2568 | C74: suckjakkure@hotmail.com | D74: FACEBOOK | F74: WA042655295TH | G74: นิตยาพร ยุทธตระกูล | H74: 119
A75: 73 | B75: 13/11/2568 | C75: suckjakkure@hotmail.com | D75: FACEBOOK | F75: WA042167960TH | G75: น.ส.จิตสนา ปราศอภิชฌา | H75: 199
A76: 74 | B76: 13/11/2568 | C76: suckjakkure@hotmail.com | D76: FACEBOOK | F76: WA042655327TH | G76: ชนิกานต์ สีเหล็กเพชร | H76: 199
A77: 75 | B77: 14/11/2568 | C77: suckjakkure@hotmail.com | D77: FACEBOOK | F77: WA042934397TH | G77: นกคงทอง แซ่เตียว | H77: 399
A78: 76 | B78: 14/11/2568 | C78: suckjakkure@hotmail.com | D78: FACEBOOK | F78: WA042934281TH | G78: วลัยรัตน์ ดำรงศิลป์ | H78: 199
A79: 77 | B79: 14/11/2568 | C79: suckjakkure@hotmail.com | D79: FACEBOOK | F79: WA042934468TH | G79: กลอยใจ พรมกสิกร | H79: 199
A80: 78 | B80: 14/11/2568 | C80: suckjakkure@hotmail.com | D80: FACEBOOK | F80: WA042934406TH | G80: สุวรรณดี มนต์เกษมศิริ | H80: 199
A81: 79 | B81: 14/11/2568 | C81: suckjakkure@hotmail.com | D81: FACEBOOK | F81: WA042934366TH | G81: ลลวลัย สุขเกษม | H81: 199
A82: 80 | B82: 14/11/2568 | C82: suckjakkure@hotmail.com | D82: FACEBOOK | F82: WA042934349TH | G82: เกียง | H82: 199
...

Sheet Summary พ.ย.
A1: ข้อมูลการเก็บเงินปลายทาง (COD) แบบรวมยอดประจำวัน เดือนพฤศจิกายน 2568 | K1: ตรวจในสเตทเม้น
A2: ลำดับ | B2: วันที่ | C2: Email | D2: Tel | E2: Bank Account Number / เลขที่บัญชี | F2: Bank Account Name / ชื่อธนาคาร | G2: Total Order / จำนวนออเดอร์ | H2: COD Amount / ยอดรวม COD | I2: Deduct | J2: Total Amount / ยอดรวม COD | K2: วันที่เงินเข้า | L2: ยอดเข้า | M2: หมายเหตุ
A3: 1 | B3: 244289 | C3: suckjakkure@hotmail.com | D3: 642427575 | E3: 4311469006 | F3: ธนาคารไทยพาณิชย์ (SCB) | G3: 18 | H3: 5676 | I3: 0 | J3: 5676 | K3: 244289 | L3: 5676 | M3: =+L3-J3 -> 0
A4: 2 | B4: 244290 | C4: suckjakkure@hotmail.com | D4: 642427575 | E4: 4311469006 | F4: ธนาคารไทยพาณิชย์ (SCB) | G4: 6 | H4: 2439 | I4: 0 | J4: 2439 | K4: 244290 | L4: 2439 | M4: =+L4-J4 -> 0
A5: 3 | B5: 244291 | C5: suckjakkure@hotmail.com | D5: 642427575 | E5: 4311469006 | F5: ธนาคารไทยพาณิชย์ (SCB) | G5: 1 | H5: 399 | I5: 0 | J5: 399 | K5: 244291 | L5: 399 | M5: =+L5-J5 -> 0
A6: 4 | B6: 244292 | C6: suckjakkure@hotmail.com | D6: 642427575 | E6: 4311469006 | F6: ธนาคารไทยพาณิชย์ (SCB) | G6: 7 | H6: 1940 | I6: 0 | J6: 1940 | K6: 244292 | L6: 1940 | M6: =+L6-J6 -> 0
A7: 5 | B7: 244293 | C7: suckjakkure@hotmail.com | D7: 642427575 | E7: 4311469006 | F7: ธนาคารไทยพาณิชย์ (SCB) | G7: 6 | H7: 1593 | I7: 0 | J7: 1593 | K7: 244293 | L7: 1593 | M7: =+L7-J7 -> 0
A8: 6 | B8: 244294 | C8: suckjakkure@hotmail.com | D8: 642427575 | E8: 4311469006 | F8: ธนาคารไทยพาณิชย์ (SCB) | G8: 6 | H8: 2052 | I8: 0 | J8: 2052 | K8: 244294 | L8: 2052 | M8: =+L8-J8 -> 0
A9: 7 | B9: 244295 | C9: suckjakkure@hotmail.com | D9: 642427575 | E9: 4311469006 | F9: ธนาคารไทยพาณิชย์ (SCB) | G9: 10 | H9: 2254 | I9: 0 | J9: 2254 | K9: 244295 | L9: 2254 | M9: =+L9-J9 -> 0
A10: 8 | B10: 244296 | C10: suckjakkure@hotmail.com | D10: 642427575 | E10: 4311469006 | F10: ธนาคารไทยพาณิชย์ (SCB) | G10: 6 | H10: 1809 | I10: 0 | J10: 1809 | K10: 244296 | L10: 1809 | M10: =+L10-J10 -> 0
A11: 9 | B11: 244297 | C11: suckjakkure@hotmail.com | D11: 642427575 | E11: 4311469006 | F11: ธนาคารไทยพาณิชย์ (SCB) | G11: 3 | H11: 613 | I11: 0 | J11: 613 | K11: 244297 | L11: 613 | M11: =+L11-J11 -> 0
A12: 10 | B12: 244298 | C12: ไม่มียอดเก็บ COD | K12: 244298 | M12: =+L12-J12 -> 0
A13: 11 | B13: 244299 | C13: suckjakkure@hotmail.com | D13: 642427575 | E13: 4311469006 | F13: ธนาคารไทยพาณิชย์ (SCB) | G13: 3 | H13: 729 | I13: 0 | J13: 729 | K13: 244299 | L13: 729 | M13: =+L13-J13 -> 0
A14: 12 | B14: 244300 | C14: suckjakkure@hotmail.com | D14: 642427575 | E14: 4311469006 | F14: ธนาคารไทยพาณิชย์ (SCB) | G14: 3 | H14: 613 | I14: 0 | J14: 613 | K14: 244300 | L14: 613 | M14: =+L14-J14 -> 0
A15: 13 | B15: 244301 | C15: suckjakkure@hotmail.com | D15: 642427575 | E15: 4311469006 | F15: ธนาคารไทยพาณิชย์ (SCB) | G15: 5 | H15: 1115 | I15: 0 | J15: 1115 | K15: 244301 | L15: 1115 | M15: =+L15-J15 -> 0
A16: 14 | B16: 244302 | C16: suckjakkure@hotmail.com | D16: 642427575 | E16: 4311469006 | F16: ธนาคารไทยพาณิชย์ (SCB) | G16: 17 | H16: 3981 | I16: 0 | J16: 3981 | K16: 244302 | L16: 3981 | M16: =+L16-J16 -> 0
A17: 15 | B17: 244303 | C17: suckjakkure@hotmail.com | D17: 642427575 | E17: 4311469006 | F17: ธนาคารไทยพาณิชย์ (SCB) | G17: 28 | H17: 6401 | I17: 0 | J17: 6401 | K17: 244303 | L17: 6401 | M17: =+L17-J17 -> 0
A18: 16 | B18: 244304 | C18: suckjakkure@hotmail.com | D18: 642427575 | E18: 4311469006 | F18: ธนาคารไทยพาณิชย์ (SCB) | G18: 9 | H18: 2151 | I18: 0 | J18: 2151 | K18: 244304 | L18: 2151 | M18: =+L18-J18 -> 0
A19: 17 | B19: 244305 | C19: ไม่มียอดเก็บ COD | K19: 244305 | M19: =+L19-J19 -> 0
A20: 18 | B20: 244306 | C20: suckjakkure@hotmail.com | D20: 642427575 | E20: 4311469006 | F20: ธนาคารไทยพาณิชย์ (SCB) | G20: 7 | H20: 1758 | I20: 0 | J20: 1758 | K20: 244306 | L20: 1758 | M20: =+L20-J20 -> 0
A21: 19 | B21: 244307 | C21: suckjakkure@hotmail.com | D21: 642427575 | E21: 4311469006 | F21: ธนาคารไทยพาณิชย์ (SCB) | G21: 6 | H21: 1442 | I21: 0 | J21: 1442 | K21: 244307 | L21: 1442 | M21: =+L21-J21 -> 0
A22: 20 | B22: 244308 | C22: suckjakkure@hotmail.com | D22: 642427575 | E22: 4311469006 | F22: ธนาคารไทยพาณิชย์ (SCB) | G22: 2 | H22: 414 | I22: 0 | J22: 414 | K22: 244308 | L22: 414 | M22: =+L22-J22 -> 0
A23: 21 | B23: 244309 | C23: suckjakkure@hotmail.com | D23: 642427575 | E23: 4311469006 | F23: ธนาคารไทยพาณิชย์ (SCB) | G23: 3 | H23: 629 | I23: 0 | J23: 629 | K23: 244309 | L23: 629 | M23: =+L23-J23 -> 0
A24: 22 | B24: 244310 | C24: suckjakkure@hotmail.com | D24: 642427575 | E24: 4311469006 | F24: ธนาคารไทยพาณิชย์ (SCB) | G24: 9 | H24: 2150 | I24: 0 | J24: 2150 | K24: 244310 | L24: 2150 | M24: =+L24-J24 -> 0
A25: 23 | B25: 244311 | C25: suckjakkure@hotmail.com | D25: 642427575 | E25: 4311469006 | F25: ธนาคารไทยพาณิชย์ (SCB) | G25: 15 | H25: 4085 | I25: 0 | J25: 4085 | K25: 244311 | L25: 4085 | M25: =+L25-J25 -> 0
A26: 24 | B26: 244312 | C26: ไม่มียอดเก็บ COD | K26: 244312 | M26: =+L26-J26 -> 0
A27: 25 | B27: 244313 | C27: suckjakkure@hotmail.com | D27: 642427575 | E27: 4311469006 | F27: ธนาคารไทยพาณิชย์ (SCB) | G27: 8 | H27: 1704 | I27: 0 | J27: 1704 | K27: 244313 | L27: 1704 | M27: =+L27-J27 -> 0
A28: 26 | B28: 244314 | C28: suckjakkure@hotmail.com | D28: 642427575 | E28: 4311469006 | F28: ธนาคารไทยพาณิชย์ (SCB) | G28: 6 | H28: 1290 | I28: 0 | J28: 1290 | K28: 244314 | L28: 1290 | M28: =+L28-J28 -> 0
A29: 27 | B29: 244315 | C29: suckjakkure@hotmail.com | D29: 642427575 | E29: 4311469006 | F29: ธนาคารไทยพาณิชย์ (SCB) | G29: 2 | H29: 614 | I29: 0 | J29: 614 | K29: 244315 | L29: 614 | M29: =+L29-J29 -> 0
A30: 28 | B30: 244316 | C30: suckjakkure@hotmail.com | D30: 642427575 | E30: 4311469006 | F30: ธนาคารไทยพาณิชย์ (SCB) | G30: 2 | H30: 645 | I30: 0 | J30: 645 | K30: 244316 | L30: 645 | M30: =+L30-J30 -> 0
A31: 29 | B31: 244317 | C31: suckjakkure@hotmail.com | D31: 642427575 | E31: 4311469006 | F31: ธนาคารไทยพาณิชย์ (SCB) | G31: 4 | H31: 1044 | I31: 0 | J31: 1044 | K31: 244317 | L31: 1044 | M31: =+L31-J31 -> 0
A32: 30 | B32: 244318 | C32: ไม่มียอดเก็บ COD | K32: 244318 | M32: =+L32-J32 -> 0
A33: 31 | B33: 244319 | K33: 244319 | M33: =+L33-J33 -> 0
A34: 32 | B34: 244320 | K34: 244320 | M34: =+L34-J34 -> 0
F35: ยอดรวม | G35: =SUM(G3:G34) -> 192 | H35: =SUM(H3:H34) -> 49540 | I35: =SUM(I3:I34) -> 0 | J35: =SUM(J3:J34) -> 49540 | K35: บาท | L35: =SUM(L3:L34) -> 49540 | M35: บาท

Sheet ต.ค.
A1: ข้อมูลการเก็บเงินปลายทาง (COD) แบบแยกรายละเอียด เดือนตุลาคม 2568
A2: ลำดับ | B2: วันที่ | C2: Email | D2: Facebook Page | E2: Order No. / เลขที่ออเดอร์ | F2: Tracking No. / เลขพัสดุ | G2: recipientName / ชื่อลูกค้า | H2: Amount / ยอด COD
A3: 1 | B3: 243993 | C3: suckjakkure@hotmail.com | D3: FACEBOOK | F3: WA016964095TH | G3: ประภาพรรณ | H3: 1197
A4: 2 | B4: 243993 | C4: suckjakkure@hotmail.com | D4: FACEBOOK | F4: WA016964064TH | G4: Thanapat Pichet | H4: 215
A5: 3 | B5: 243993 | C5: suckjakkure@hotmail.com | D5: FACEBOOK | F5: WA016964081TH | G5: นายสุรชัย สุภธีระ | H5: 120
A6: 4 | B6: 243993 | C6: suckjakkure@hotmail.com | D6: FACEBOOK | F6: WA030341207TH | G6: ดารณีใจดีทอง | H6: 430
A7: 5 | B7: 243993 | C7: suckjakkure@hotmail.com | D7: FACEBOOK | F7: WA016672477TH | G7: Suphaphich Khosa | H7: 399
A8: 6 | B8: 243993 | C8: suckjakkure@hotmail.com | D8: FACEBOOK | F8: WA016673203TH | G8: นางญาณิศา โมทอง | H8: 215
A9: 7 | B9: 243993 | C9: suckjakkure@hotmail.com | D9: FACEBOOK | F9: WA030341224TH | G9: สุนันท์ ร้านเสริมสวยโมเดร์น | H9: 215
A10: 8 | B10: 243993 | C10: suckjakkure@hotmail.com | D10: FACEBOOK | F10: WA016672446TH | G10: นิมลรัตน์ | H10: 299
A11: 9 | B11: 243993 | C11: suckjakkure@hotmail.com | D11: FACEBOOK | F11: WA016964055TH | G11: สุนีย์ ยึหมาด | H11: 299
A12: 10 | B12: 244024 | C12: suckjakkure@hotmail.com | D12: FACEBOOK | F12: WA030341198TH | G12: สุภาพร อติสกุล | H12: 215
A13: 11 | B13: 244024 | C13: suckjakkure@hotmail.com | D13: FACEBOOK | F13: WA016964078TH | G13: กานท์ดา-ชูชวลิต | H13: 150
A14: 12 | B14: 244024 | C14: suckjakkure@hotmail.com | D14: FACEBOOK | F14: WA030725238TH | G14: กมลวรรณ กองแก้ว | H14: 215
... A34: 32 | B34: 244084 | C34: suckjakkure@hotmail.com | D34: FACEBOOK | F34: WA031334410TH | G34: มณฑา บริบูรณ์ธรกิจ | H34: 215
A35: 33 | B35: 244084 | C35: suckjakkure@hotmail.com | D35: FACEBOOK | F35: WA031334370TH | G35: =SUM(G3:G34) -> 0 | H35: =SUM(H3:H34) -> 11029 | I35: =SUM(I3:I34) -> 0 | J35: =SUM(J3:J34) -> 0 | L35: =SUM(L3:L34) -> 0
A36: 34 | B36: 244084 | C36: suckjakkure@hotmail.com | D36: FACEBOOK | F36: WA031095860TH | G36: รฏิพร มาตา | H36: 399
A37: 35 | B37: 244084 | C37: suckjakkure@hotmail.com | D37: FACEBOOK | F37: WA030725326TH | G37: นส.เพ็ญพิชชา วังคีรี{N.ว่าน.} | H37: 150
A38: 36 | B38: 244084 | C38: suckjakkure@hotmail.com | D38: FACEBOOK | F38: WA031334499TH | G38: ปูเปรี้ยว อวบระยะสุดท้าย | H38: 299
A39: 37 | B39: 244084 | C39: suckjakkure@hotmail.com | D39: FACEBOOK | F39: WA031334485TH | G39: หยาด | H39: 315
A40: 38 | B40: 244084 | C40: suckjakkure@hotmail.com | D40: FACEBOOK | F40: WA031334423TH | G40: ประภัสสร | H40: 150
A41: 39 | B41: 244114 | C41: suckjakkure@hotmail.com | D41: FACEBOOK | F41: WA031634445TH | G41: รัชนี ราชู | H41: 319
A42: 40 | B42: 244114 | C42: suckjakkure@hotmail.com | D42: FACEBOOK | F42: WA031634374TH | G42: ไชยา.แสงทอง | H42: 215
A43: 41 | B43: 244114 | C43: suckjakkure@hotmail.com | D43: FACEBOOK | F43: WA031334437TH | G43: พัชรี พลาน้อย | H43: 430
A44: 42 | B44: 244114 | C44: suckjakkure@hotmail.com | D44: FACEBOOK | F44: WA031634388TH | G44: มาติกา ค้ำชู | H44: 399
A45: 43 | B45: 244114 | C45: suckjakkure@hotmail.com | D45: FACEBOOK | F45: WA031634414TH | G45: จตุพร น้อยโสภณ | H45: 399
A46: 44 | B46: 244114 | C46: suckjakkure@hotmail.com | D46: FACEBOOK | F46: WA031334471TH | G46: รัตติกาล แก้วสุข | H46: 150
A47: 45 | B47: 244114 | C47: suckjakkure@hotmail.com | D47: FACEBOOK | F47: WA031634431TH | G47: ณัฐพร นิ่มวนาดอน | H47: 399
... A126: 124 | B126: 244328 | C126: suckjakkure@hotmail.com | D126: FACEBOOK | F126: WA033746594TH | G126: แม่บังเอิญ เปียผ่อง | H126: 399
A127: 125 | B127: 13/10/2568 | C127: suckjakkure@hotmail.com | D127: FACEBOOK | F127: WA033746515TH | G127: คุณเอ้ | H127: 215
A128: 126 | B128: 13/10/2568 | C128: suckjakkure@hotmail.com | D128: FACEBOOK | F128: WA033864429TH | G128: นภวรรณ รัตนัย | H128: 349
A129: 127 | B129: 13/10/2568 | C129: suckjakkure@hotmail.com | D129: FACEBOOK | F129: WA033746585TH | G129: สุรีรัตน์ ศรีอุทัย | H129: 215
A130: 128 | B130: 13/10/2568 | C130: suckjakkure@hotmail.com | D130: FACEBOOK | F130: WA033625295TH | G130: น.ส.สุธีรา เขื่อนขันธ์เจริญ | H130: 215
A131: 129 | B131: 13/10/2568 | C131: suckjakkure@hotmail.com | D131: FACEBOOK | F131: WA033625300TH | G131: คุณรัศมี วางอภัย | H131: 215
A132: 130 | B132: 13/10/2568 | C132: suckjakkure@hotmail.com | D132: FACEBOOK | F132: WA033746501TH | G132: แสงเดือนผลโพธิ์ | H132: 215
A133: 131 | B133: 13/10/2568 | C133: suckjakkure@hotmail.com | D133: FACEBOOK | F133: WA033746563TH | G133: แสงเดือนผลโพธิ์ | H133: 215
A134: 132 | B134: 14/10/2568 | C134: suckjakkure@hotmail.com | D134: FACEBOOK | F134: WA033864389TH | G134: กมลนัยน์ สุนันท์ | H134: 399
A135: 133 | B135: 14/10/2568 | C135: suckjakkure@hotmail.com | D135: FACEBOOK | F135: WA032940910TH | G135: นิภาพร แสนอุ้ม | H135: 550
A136: 134 | B136: 15/10/2568 | C136: suckjakkure@hotmail.com | D136: FACEBOOK | F136: WA033625358TH | G136: อรจันทร์ เศรษฐ์จำนงค์ | H136: 430
A137: 135 | B137: 15/10/2568 | C137: suckjakkure@hotmail.com | D137: FACEBOOK | F137: WA034071006TH | G137: เฉลียว นามสุข | H137: 430
...

Sheet Summary ต.ค.
A1: ข้อมูลการเก็บเงินปลายทาง (COD) แบบรวมยอดประจำวัน เดือนตุลาคม 2568 | K1: ตรวจในสเตทเม้น
A2: ลำดับ | B2: วันที่ | C2: Email | D2: Tel | E2: Bank Account Number / เลขที่บัญชี | F2: Bank Account Name / ชื่อธนาคาร | G2: Total Order / จำนวนออเดอร์ | H2: COD Amount / ยอดรวม COD | I2: Deduct | J2: Total Amount / ยอดรวม COD | K2: วันที่เงินเข้า | L2: ยอดเข้า | M2: หมายเหตุ
A3: 1 | B3: 244258 | C3: suckjakkure@hotmail.com | D3: 642427575 | E3: 4311469006 | F3: ธนาคารไทยพาณิชย์ (SCB) | G3: 9 | H3: 3389 | I3: 0 | J3: 3389 | K3: 244258 | L3: 3389 | M3: =+L3-J3 -> 0
A4: 2 | B4: 244259 | C4: suckjakkure@hotmail.com | D4: 642427575 | E4: 4311469006 | F4: ธนาคารไทยพาณิชย์ (SCB) | G4: 7 | H4: 2319 | I4: 0 | J4: 2319 | K4: 244259 | L4: 2319 | M4: =+L4-J4 -> 0
A5: 3 | B5: 244260 | C5: suckjakkure@hotmail.com | D5: 642427575 | E5: 4311469006 | F5: ธนาคารไทยพาณิชย์ (SCB) | G5: 7 | H5: 2166 | I5: 0 | J5: 2166 | K5: 244260 | L5: 2166 | M5: =+L5-J5 -> 0
A6: 4 | B6: 244261 | C6: suckjakkure@hotmail.com | D6: 642427575 | E6: 4311469006 | F6: ธนาคารไทยพาณิชย์ (SCB) | G6: 15 | H6: 4683 | I6: 0 | J6: 4683 | K6: 244261 | L6: 4683 | M6: =+L6-J6 -> 0
A7: 5 | B7: 244262 | C7: suckjakkure@hotmail.com | D7: 642427575 | E7: 4311469006 | F7: ธนาคารไทยพาณิชย์ (SCB) | G7: 8 | H7: 2461 | I7: 0 | J7: 2461 | K7: 244262 | L7: 2461 | M7: =+L7-J7 -> 0
A8: 6 | B8: 244263 | C8: suckjakkure@hotmail.com | D8: 642427575 | E8: 4311469006 | F8: ธนาคารไทยพาณิชย์ (SCB) | G8: 2 | H8: 798 | I8: 0 | J8: 798 | K8: 244263 | L8: 798 | M8: =+L8-J8 -> 0
A9: 7 | B9: 244264 | C9: suckjakkure@hotmail.com | D9: 642427575 | E9: 4311469006 | F9: ธนาคารไทยพาณิชย์ (SCB) | G9: 5 | H9: 1611 | I9: 0 | J9: 1611 | K9: 244264 | L9: 1611 | M9: =+L9-J9 -> 0
A10: 8 | B10: 244265 | C10: suckjakkure@hotmail.com | D10: 642427575 | E10: 4311469006 | F10: ธนาคารไทยพาณิชย์ (SCB) | G10: 14 | H10: 4399 | I10: 0 | J10: 4399 | K10: 244265 | L10: 4399 | M10: =+L10-J10 -> 0
A11: 9 | B11: 244266 | C11: suckjakkure@hotmail.com | D11: 642427575 | E11: 4311469006 | F11: ธนาคารไทยพาณิชย์ (SCB) | G11: 10 | H11: 3123 | I11: 0 | J11: 3123 | K11: 244266 | L11: 3123 | M11: =+L11-J11 -> 0
A12: 10 | B12: 244267 | C12: suckjakkure@hotmail.com | D12: 642427575 | E12: 4311469006 | F12: ธนาคารไทยพาณิชย์ (SCB) | G12: 10 | H12: 3761 | I12: 0 | J12: 3761 | K12: 244267 | L12: 3761 | M12: =+L12-J12 -> 0
A13: 11 | B13: 244268 | C13: suckjakkure@hotmail.com | D13: 642427575 | E13: 4311469006 | F13: ธนาคารไทยพาณิชย์ (SCB) | G13: 21 | H13: 5971 | I13: 0 | J13: 5971 | K13: 244268 | L13: 5971 | M13: =+L13-J13 -> 0
A14: 12 | B14: 244269 | C14: suckjakkure@hotmail.com | D14: 642427575 | E14: 4311469006 | F14: ธนาคารไทยพาณิชย์ (SCB) | G14: 16 | H14: 3891 | I14: 0 | J14: 3891 | K14: 244269 | L14: 3891 | M14: =+L14-J14 -> 0
... A33: 31 | B33: 244288 | C33: suckjakkure@hotmail.com | D33: 642427575 | E33: 4311469006 | F33: ธนาคารไทยพาณิชย์ (SCB) | G33: 3 | H33: 829 | I33: 0 | J33: 829 | K33: 244288 | L33: 829 | M33: =+L33-J33 -> 0
A34: 32 | B34: 244289 | K34: 244289 | M34: =+L34-J34 -> 0
F35: ยอดรวม | G35: =SUM(G3:G34) -> 283 | H35: =SUM(H3:H34) -> 76274 | I35: =SUM(I3:I34) -> 0 | J35: =SUM(J3:J34) -> 76274 | K35: บาท | L35: =SUM(L3:L34) -> 76274 | M35: บาท

Sheet ก.ย.
A1: ข้อมูลการเก็บเงินปลายทาง (COD) แบบแยกรายละเอียด เดือนกันยายน 2568
A2: ลำดับ | B2: วันที่ | C2: Email | D2: Facebook Page | E2: Order No. / เลขที่ออเดอร์ | F2: Tracking No. / เลขพัสดุ | G2: recipientName / ชื่อลูกค้า | H2: Amount / ยอด COD
A3: 1 | B3: 244023 | C3: suckjakkure@hotmail.com | D3: FACEBOOK | F3: WA008635194TH | G3: โอ้เอ้ | H3: 120
A4: 2 | B4: 244023 | C4: suckjakkure@hotmail.com | D4: FACEBOOK | F4: WA008635203TH | G4: อนุรักษ์ หมื่นนาค | H4: 219
A5: 3 | B5: 244023 | C5: suckjakkure@hotmail.com | D5: FACEBOOK | F5: WA008635185TH | G5: นุชนาฎ อภัยรุณ | H5: 120
A6: 4 | B6: 244052 | C6: suckjakkure@hotmail.com | D6: FACEBOOK | F6: WA009219306TH | G6: บรรจง | H6: 215
A7: 5 | B7: 244052 | C7: suckjakkure@hotmail.com | D7: FACEBOOK | F7: WA009006751TH | G7: นวภัสร์ ธรรมณัฐนันท์ | H7: 219
A8: 6 | B8: 244052 | C8: suckjakkure@hotmail.com | D8: FACEBOOK | F8: WA009219323TH | G8: มณฑา บริบูรณ์ธรกิจ | H8: 415
A9: 7 | B9: 244052 | C9: suckjakkure@hotmail.com | D9: FACEBOOK | F9: WA009006765TH | G9: Sunun Nun | H9: 215
A10: 8 | B10: 244052 | C10: suckjakkure@hotmail.com | D10: FACEBOOK | F10: WA009006748TH | G10: คุณอุษณีย์ สนธิเณร | H10: 215
A11: 9 | B11: 244083 | C11: suckjakkure@hotmail.com | D11: FACEBOOK | F11: WA009219345TH | G11: นายวัชระ ท้วมเทียบ | H11: 215
A12: 10 | B12: 244083 | C12: suckjakkure@hotmail.com | D12: FACEBOOK | F12: WA009585596TH | G12: กฤชพรหอสุวรรณ | H12: 215
A13: 11 | B13: 244083 | C13: suckjakkure@hotmail.com | D13: FACEBOOK | F13: JA282477523TH | G13: รินทร์ลิตา เพ็ชรรัตน์ | H13: 265
A14: 12 | B14: 244083 | C14: suckjakkure@hotmail.com | D14: FACEBOOK | F14: WA009585619TH | G14: กาญจนา แสวง | H14: 215
... A34: 32 | B34: 244113 | C34: suckjakkure@hotmail.com | D34: FACEBOOK | F34: WA009943378TH | G34: คุณต้อง | H34: 369
A35: 33 | B35: 244113 | C35: suckjakkure@hotmail.com | D35: FACEBOOK | F35: WA009585503TH | G35: =SUM(G3:G34) -> 0 | H35: =SUM(H3:H34) -> 10609 | I35: =SUM(I3:I34) -> 0 | J35: =SUM(J3:J34) -> 0 | L35: =SUM(L3:L34) -> 0
A36: 34 | B36: 244113 | C36: suckjakkure@hotmail.com | D36: FACEBOOK | F36: WA009585534TH | G36: ร้านอุดมศักดิ์เกษตรยนต์ | H36: 1075
A37: 35 | B37: 244113 | C37: suckjakkure@hotmail.com | D37: FACEBOOK | F37: WA009943608TH | G37: ก้อย ท้ายซอย | H37: 215
A38: 36 | B38: 244113 | C38: suckjakkure@hotmail.com | D38: FACEBOOK | F38: WA009585525TH | G38: Pongsit Choomkui | H38: 215
A39: 37 | B39: 244144 | C39: suckjakkure@hotmail.com | D39: FACEBOOK | F39: WA009943333TH | G39: ชุติมณฑน์ บรรจง | H39: 369
A40: 38 | B40: 244144 | C40: suckjakkure@hotmail.com | D40: FACEBOOK | F40: WA009943642TH | G40: เกศิณี บุญถนอม | H40: 369
A41: 39 | B41: 244144 | C41: suckjakkure@hotmail.com | D41: FACEBOOK | F41: WA009943554TH | G41: ศศิรัศมิ์ จุ้ยส่องแก้ว | H41: 215
A42: 40 | B42: 244144 | C42: suckjakkure@hotmail.com | D42: FACEBOOK | F42: WA009980628TH | G42: ชนาภัทร | H42: 369
A43: 41 | B43: 244144 | C43: suckjakkure@hotmail.com | D43: FACEBOOK | F43: WA009585582TH | G43: เจ๊เอ๋ร้านช่างเลี้ยงยางซิ่ง | H43: 215
A44: 42 | B44: 244144 | C44: suckjakkure@hotmail.com | D44: FACEBOOK | F44: WA009585517TH | G44: มนัส คําทิพย์ | H44: 430
A45: 43 | B45: 244144 | C45: suckjakkure@hotmail.com | D45: FACEBOOK | F45: WA009943497TH | G45: ศิริพร บริสุทธิ์ | H45: 1107
A46: 44 | B46: 244144 | C46: suckjakkure@hotmail.com | D46: FACEBOOK | F46: WA009943483TH | G46: ยุพิน โสส้มกบ | H46: 369
A47: 45 | B47: 244144 | C47: suckjakkure@hotmail.com | D47: FACEBOOK | F47: WA009980702TH | G47: วนิดา ยาประโคน | H47: 215
... A170: 168 | B170: 244327 | C170: suckjakkure@hotmail.com | D170: FACEBOOK | F170: WA011601624TH | G170: สิน ยอดพรมทอง | H170: 299
A171: 169 | B171: 13/9/2568 | C171: suckjakkure@hotmail.com | D171: FACEBOOK | F171: WA011601465TH | G171: ชบา ศรีวิชัย | H171: 299
A172: 170 | B172: 13/9/2568 | C172: suckjakkure@hotmail.com | D172: FACEBOOK | F172: WA011937950TH | G172: คุณจุไรรัตน์ ธนูทอง | H172: 299
A173: 171 | B173: 13/9/2568 | C173: suckjakkure@hotmail.com | D173: FACEBOOK | F173: WA011601641TH | G173: สุปรียา เหมะ | H173: 299
A174: 172 | B174: 13/9/2568 | C174: suckjakkure@hotmail.com | D174: FACEBOOK | F174: WA011938080TH | G174: อุทัยรัตน์ เพ็ชเย็น | H174: 299
A175: 173 | B175: 13/9/2568 | C175: suckjakkure@hotmail.com | D175: FACEBOOK | F175: WA011601434TH | G175: มณีกาญจน์ เด่นสม | H175: 299
A176: 174 | B176: 13/9/2568 | C176: suckjakkure@hotmail.com | D176: FACEBOOK | F176: WA011601615TH | G176: อัญญาณี นิลเกตุแก้ว | H176: 729
A177: 175 | B177: 13/9/2568 | C177: suckjakkure@hotmail.com | D177: FACEBOOK | F177: WA011938059TH | G177: สุไกย๊ะป,าหนะ | H177: 299
A178: 176 | B178: 13/9/2568 | C178: suckjakkure@hotmail.com | D178: FACEBOOK | F178: WA011601584TH | G178: นางสาวเกศน์กาญจน์ ศิริภัทร์วรสกุล | H178: 299
A179: 177 | B179: 13/9/2568 | C179: suckjakkure@hotmail.com | D179: FACEBOOK | F179: WA011601540TH | G179: ร้านไก่อย่างTWO GIRLS | H179: 299
A180: 178 | B180: 13/9/2568 | C180: suckjakkure@hotmail.com | D180: FACEBOOK | F180: WA011601519TH | G180: Jirawadee Lclinrot | H180: 215
A181: 179 | B181: 13/9/2568 | C181: suckjakkure@hotmail.com | D181: FACEBOOK | F181: WA011938005TH | G181: รำไพ สุวรรณโชติ | H181: 299
...

Sheet Summary ก.ย.
B1: ข้อมูลการเก็บเงินปลายทาง (COD) แบบรวมยอดประจำวัน เดือนกันยายน 2568 | K1: ตรวจในสเตทเม้น
A2: ลำดับ | B2: วันที่ | C2: Email | D2: Tel | E2: Bank Account Number / เลขที่บัญชี | F2: Bank Account Name / ชื่อธนาคาร | G2: Total Order / จำนวนออเดอร์ | H2: COD Amount / ยอดรวม COD | I2: Deduct | J2: Total Amount / ยอดรวม COD | K2: วันที่เงินเข้า | L2: ยอดเข้า | M2: หมายเหตุ
A3: 1 | B3: 244228 | C3: ไม่มียอดเก็บ COD | K3: 244228 | M3: =+L3-J3 -> 0
A4: 2 | B4: 244229 | C4: suckjakkure@hotmail.com | D4: 642427575 | E4: 4311469006 | F4: ธนาคารไทยพาณิชย์ (SCB) | G4: 3 | H4: 459 | I4: 0 | J4: 459 | K4: 244229 | L4: 459 | M4: =+L4-J4 -> 0
A5: 3 | B5: 244230 | C5: suckjakkure@hotmail.com | D5: 642427575 | E5: 4311469006 | F5: ธนาคารไทยพาณิชย์ (SCB) | G5: 5 | H5: 1279 | I5: 0 | J5: 1279 | K5: 244230 | L5: 1279 | M5: =+L5-J5 -> 0
A6: 4 | B6: 244231 | C6: suckjakkure@hotmail.com | D6: 642427575 | E6: 4311469006 | F6: ธนาคารไทยพาณิชย์ (SCB) | G6: 8 | H6: 1755 | I6: 0 | J6: 1755 | K6: 244231 | L6: 1755 | M6: =+L6-J6 -> 0
A7: 5 | B7: 244232 | C7: suckjakkure@hotmail.com | D7: 642427575 | E7: 4311469006 | F7: ธนาคารไทยพาณิชย์ (SCB) | G7: 20 | H7: 9359 | I7: 0 | J7: 9359 | K7: 244232 | L7: 9359 | M7: =+L7-J7 -> 0
A8: 6 | B8: 244233 | C8: suckjakkure@hotmail.com | D8: 642427575 | E8: 4311469006 | F8: ธนาคารไทยพาณิชย์ (SCB) | G8: 41 | H8: 14537 | I8: 0 | J8: 14537 | K8: 244233 | L8: 14537 | M8: =+L8-J8 -> 0
A9: 7 | B9: 244234 | C9: suckjakkure@hotmail.com | D9: 642427575 | E9: 4311469006 | F9: ธนาคารไทยพาณิชย์ (SCB) | G9: 7 | H9: 2043 | I9: 0 | J9: 2043 | K9: 244234 | L9: 2043 | M9: =+L9-J9 -> 0
A10: 8 | B10: 244235 | C10: suckjakkure@hotmail.com | D10: 642427575 | E10: 4311469006 | F10: ธนาคารไทยพาณิชย์ (SCB) | G10: 1 | H10: 369 | I10: 0 | J10: 369 | K10: 244235 | L10: 369 | M10: =+L10-J10 -> 0
A11: 9 | B11: 244236 | C11: suckjakkure@hotmail.com | D11: 642427575 | E11: 4311469006 | F11: ธนาคารไทยพาณิชย์ (SCB) | G11: 9 | H11: 2541 | I11: 0 | J11: 2541 | K11: 244236 | L11: 2541 | M11: =+L11-J11 -> 0
A12: 10 | B12: 244237 | C12: suckjakkure@hotmail.com | D12: 642427575 | E12: 4311469006 | F12: ธนาคารไทยพาณิชย์ (SCB) | G12: 19 | H12: 5114 | I12: 0 | J12: 5114 | K12: 244237 | L12: 5114 | M12: =+L12-J12 -> 0
A13: 11 | B13: 244238 | C13: suckjakkure@hotmail.com | D13: 642427575 | E13: 4311469006 | F13: ธนาคารไทยพาณิชย์ (SCB) | G13: 31 | H13: 9412 | I13: 0 | J13: 9412 | K13: 244238 | L13: 9412 | M13: =+L13-J13 -> 0
A14: 12 | B14: 244239 | C14: suckjakkure@hotmail.com | D14: 642427575 | E14: 4311469006 | F14: ธนาคารไทยพาณิชย์ (SCB) | G14: 24 | H14: 6926 | I14: 0 | J14: 6926 | K14: 244239 | L14: 6926 | M14: =+L14-J14 -> 0
A15: 13 | B15: 244240 | C15: suckjakkure@hotmail.com | D15: 642427575 | E15: 4311469006 | F15: ธนาคารไทยพาณิชย์ (SCB) | G15: 19 | H15: 6242 | I15: 0 | J15: 6242 | K15: 244240 | L15: 6242 | M15: =+L15-J15 -> 0
... A23: 21 | B23: 244248 | C23: suckjakkure@hotmail.com | D23: 642427575 | E23: 4311469006 | F23: ธนาคารไทยพาณิชย์ (SCB) | G23: 6 | H23: 2333 | I23: 0 | J23: 2333 | K23: 244248 | L23: 2333 | M23: =+L23-J23 -> 0
A24: 22 | B24: 244249 | C24: ไม่มียอดเก็บ COD | K24: 244249 | M24: =+L24-J24 -> 0
A25: 23 | B25: 244250 | C25: suckjakkure@hotmail.com | D25: 642427575 | E25: 4311469006 | F25: ธนาคารไทยพาณิชย์ (SCB) | G25: 7 | H25: 1648 | I25: 0 | J25: 1648 | K25: 244250 | L25: 1648 | M25: =+L25-J25 -> 0
A26: 24 | B26: 244251 | C26: suckjakkure@hotmail.com | D26: 642427575 | E26: 4311469006 | F26: ธนาคารไทยพาณิชย์ (SCB) | G26: 7 | H26: 2273 | I26: 0 | J26: 2273 | K26: 244251 | L26: 2273 | M26: =+L26-J26 -> 0
A27: 25 | B27: 244252 | C27: suckjakkure@hotmail.com | D27: 642427575 | E27: 4311469006 | F27: ธนาคารไทยพาณิชย์ (SCB) | G27: 3 | H27: 897 | I27: 0 | J27: 897 | K27: 244252 | L27: 897 | M27: =+L27-J27 -> 0
A28: 26 | B28: 244253 | C28: suckjakkure@hotmail.com | D28: 642427575 | E28: 4311469006 | F28: ธนาคารไทยพาณิชย์ (SCB) | G28: 6 | H28: 1776 | I28: 0 | J28: 1776 | K28: 244253 | L28: 1776 | M28: =+L28-J28 -> 0
A29: 27 | B29: 244254 | C29: suckjakkure@hotmail.com | D29: 642427575 | E29: 4311469006 | F29: ธนาคารไทยพาณิชย์ (SCB) | G29: 4 | H29: 1710 | I29: 0 | J29: 1710 | K29: 244254 | L29: 1710 | M29: =+L29-J29 -> 0
A30: 28 | B30: 244255 | C30: suckjakkure@hotmail.com | D30: 642427575 | E30: 4311469006 | F30: ธนาคารไทยพาณิชย์ (SCB) | G30: 2 | H30: 475 | I30: 0 | J30: 475 | K30: 244255 | L30: 475 | M30: =+L30-J30 -> 0
A31: 29 | B31: 244256 | C31: suckjakkure@hotmail.com | D31: 642427575 | E31: 4311469006 | F31: ธนาคารไทยพาณิชย์ (SCB) | G31: 3 | H31: 3299 | I31: 0 | J31: 3299 | K31: 244256 | L31: 3299 | M31: =+L31-J31 -> 0
A32: 30 | B32: 244257 | C32: suckjakkure@hotmail.com | D32: 642427575 | E32: 4311469006 | F32: ธนาคารไทยพาณิชย์ (SCB) | G32: 6 | H32: 1563 | I32: 0 | J32: 1563 | K32: 244257 | L32: 1563 | M32: =+L32-J32 -> 0
A33: 31 | B33: 244258 | K33: 244258 | M33: =+L33-J33 -> 0
A34: 32 | B34: 244259 | K34: 244259 | M34: =+L34-J34 -> 0
F35: ยอดรวม | G35: =SUM(G3:G34) -> 323 | H35: =SUM(H3:H34) -> 99658 | I35: =SUM(I3:I34) -> 0 | J35: =SUM(J3:J34) -> 99658 | K35: บาท | L35: =SUM(L3:L34) -> 99658 | M35: บาท

Sheet ส.ค.
A1: ข้อมูลการเก็บเงินปลายทาง (COD) แบบแยกรายละเอียด เดือนสิงหาคม 2568
A2: ลำดับ | B2: วันที่ | C2: Email | D2: Facebook Page | E2: Order No. / เลขที่ออเดอร์ | F2: Tracking No. / เลขพัสดุ | G2: recipientName / ชื่อลูกค้า | H2: Amount / ยอด COD
A3: 1 | B3: 244197 | C3: suckjakkure@hotmail.com | D3: FACEBOOK | F3: JA274602255TH | G3: ทิพณัฐชา วงศ์ศิริวัฒน์ | H3: 220
A4: 2 | B4: 244197 | C4: suckjakkure@hotmail.com | D4: FACEBOOK | F4: JA262985760TH | G4: รัชดา บุญสมาน | H4: 215
A5: 3 | B5: 244197 | C5: suckjakkure@hotmail.com | D5: FACEBOOK | F5: JA262985800TH | G5: วันทนีย์ สีพุฒิ | H5: 215
A6: 4 | B6: 244197 | C6: suckjakkure@hotmail.com | D6: FACEBOOK | F6: JA262985795TH | G6: น้องนาง สุขโข | H6: 219
A7: 5 | B7: 244197 | C7: suckjakkure@hotmail.com | D7: FACEBOOK | F7: JA262985742TH | G7: เบญจวรรณ ตั้งเรืองสุวรรณ | H7: 219
A8: 6 | B8: 244198 | C8: suckjakkure@hotmail.com | D8: FACEBOOK | F8: JA262985725TH | G8: ชนาภา | H8: 200
A9: 7 | B9: 244198 | C9: suckjakkure@hotmail.com | D9: FACEBOOK | F9: JA274602269TH | G9: ดร.เล็ก มนัญญา | H9: 319
A10: 8 | B10: 244198 | C10: suckjakkure@hotmail.com | D10: FACEBOOK | F10: JA262985827TH | G10: วีรปริยา สิทธิไกรพงษ์ | H10: 215
A11: 9 | B11: 244198 | C11: suckjakkure@hotmail.com | D11: FACEBOOK | F11: JA262985787TH | G11: วาสนา | H11: 215
A12: 10 | B12: 244198 | C12: suckjakkure@hotmail.com | D12: FACEBOOK | F12: JA274826173TH | G12: ทราย | H12: 215
A13: 11 | B13: 244198 | C13: suckjakkure@hotmail.com | D13: FACEBOOK | F13: JA274955323TH | G13: พรภาดากุล อรพินทร์ | H13: 215
A14: 12 | B14: 244198 | C14: suckjakkure@hotmail.com | D14: FACEBOOK | F14: JA274602272TH | G14: อุษณี ทองหล่อ | H14: 315
A15: 13 | B15: 244199 | C15: suckjakkure@hotmail.com | D15: FACEBOOK | E15: KTINTER6886cee9f173329bc718d6d1 | F15: TH16027J1CUM2D | G15: คุณแต๋ม | H15: 309
A16: 14 | B16: 244199 | C16: suckjakkure@hotmail.com | D16: FACEBOOK | F16: JA262985773TH | G16: นฤมล เดือนขาว | H16: 215
A17: 15 | B17: 244199 | C17: suckjakkure@hotmail.com | D17: FACEBOOK | F17: JA274826160TH | G17: แอน | H17: 215
A18: 16 | B18: 244199 | C18: suckjakkure@hotmail.com | D18: FACEBOOK | F18: JA275285576TH | G18: มาลินี นิลนพคุณ | H18: 219
A19: 17 | B19: 244199 | C19: suckjakkure@hotmail.com | D19: FACEBOOK | F19: JA275285562TH | G19: ศรีสมเจตน์ | H19: 199
A20: 18 | B20: 244201 | C20: suckjakkure@hotmail.com | D20: FACEBOOK | F20: JA275352925TH | G20: ร้านสายใจ | H20: 230
A21: 19 | B21: 244201 | C21: suckjakkure@hotmail.com | D21: FACEBOOK | F21: JA274955310TH | G21: ประกอบ | H21: 215
A22: 20 | B22: 244201 | C22: suckjakkure@hotmail.com | D22: FACEBOOK | F22: JA275285559TH | G22: ไข่มุก | H22: 219
A23: 21 | B23: 244203 | C23: suckjakkure@hotmail.com | D23: FACEBOOK | F23: JA276542214TH | G23: Pkkid Pkkid กมลลักษณ์ ลายนอก | H23: 450
A24: 22 | B24: 244203 | C24: suckjakkure@hotmail.com | D24: FACEBOOK | F24: JA276542421TH | G24: วิสูตร งิ้วแหลม | H24: 215
A25: 23 | B25: 244203 | C25: suckjakkure@hotmail.com | D25: FACEBOOK | F25: JA276542302TH | G25: สมลักษณ์ ธนกิจโกศล | H25: 219
A26: 24 | B26: 244203 | C26: suckjakkure@hotmail.com | D26: FACEBOOK | F26: JA276542378TH | G26: วิมล | H26: 315
A27: 25 | B27: 244204 | C27: suckjakkure@hotmail.com | D27: FACEBOOK | F27: JA276857712TH | G27: Jajar Suchada | H27: 215
... A34: 32 | B34: 244205 | C34: suckjakkure@hotmail.com | D34: FACEBOOK | F34: JA276542449TH | G34: อุไรวรรณ หล้าสวย | H34: 215
A35: 33 | B35: 244205 | C35: suckjakkure@hotmail.com | D35: FACEBOOK | F35: JA277201066TH | G35: =SUM(G3:G34) -> 0 | H35: =SUM(H3:H34) -> 7729 | I35: =SUM(I3:I34) -> 0 | J35: =SUM(J3:J34) -> 0 | L35: =SUM(L3:L34) -> 0
A36: 34 | B36: 244205 | C36: suckjakkure@hotmail.com | D36: FACEBOOK | F36: JA277201123TH | G36: ศรีสมร ไพรอนันต์ | H36: 200
A37: 35 | B37: 244205 | C37: suckjakkure@hotmail.com | D37: FACEBOOK | F37: JA277201273TH | G37: สุจิรา ลาภหลาย | H37: 200
A38: 36 | B38: 244205 | C38: suckjakkure@hotmail.com | D38: FACEBOOK | F38: JA277201375TH | G38: ปราโมทย์ Pramote Bukkol | H38: 215
A39: 37 | B39: 244205 | C39: suckjakkure@hotmail.com | D39: FACEBOOK | F39: JA277200905TH | G39: สายใจ สำเริง | H39: 215
A40: 38 | B40: 244205 | C40: suckjakkure@hotmail.com | D40: FACEBOOK | F40: JA277201239TH | G40: จิรัฐติกาล รักษาทรัพย์ | H40: 215
A41: 39 | B41: 244205 | C41: suckjakkure@hotmail.com | D41: FACEBOOK | F41: JA276857726TH | G41: นายวัชระ ท้วมเทียบ | H41: 215
A42: 40 | B42: 244205 | C42: suckjakkure@hotmail.com | D42: FACEBOOK | F42: JA277200919TH | G42: กาญจนา อาจคงหาญ | H42: 215
A43: 41 | B43: 244205 | C43: suckjakkure@hotmail.com | D43: FACEBOOK | F43: JA277201300TH | G43: ขวัญจิต.รัศมีรังษีเหลือง | H43: 200
A44: 42 | B44: 244205 | C44: suckjakkure@hotmail.com | D44: FACEBOOK | F44: JA277201185TH | G44: จารุณี สมน้อย | H44: 200
A45: 43 | B45: 244205 | C45: suckjakkure@hotmail.com | D45: FACEBOOK | F45: JA277201110TH | G45: น้ำตาล | H45: 800
A46: 44 | B46: 244205 | C46: suckjakkure@hotmail.com | D46: FACEBOOK | F46: JA277201211TH | G46: ศิรินภา | H46: 215
...

Sheet Summary ส.ค.
B1: ข้อมูลการเก็บเงินปลายทาง (COD) แบบรวมยอดประจำวัน เดือนสิงหาคม 2568 | K1: ตรวจในสเตทเม้น
A2: ลำดับ | B2: วันที่ | C2: Email | D2: Tel | E2: Bank Account Number / เลขที่บัญชี | F2: Bank Account Name / ชื่อธนาคาร | G2: Total Order / จำนวนออเดอร์ | H2: COD Amount / ยอดรวม COD | I2: Deduct | J2: Total Amount / ยอดรวม COD | K2: วันที่เงินเข้า | L2: ยอดเข้า | M2: หมายเหตุ
A3: 1 | B3: 244197 | C3: suckjakkure@hotmail.com | D3: 0642427575 | E3: 4311469006 | F3: ธนาคารไทยพาณิชย์ (SCB) | G3: 5 | H3: 1088 | I3: 0 | J3: 1088 | K3: 244197 | L3: 1088 | M3: =+L3-J3 -> 0
A4: 2 | B4: 244198 | C4: suckjakkure@hotmail.com | D4: 0642427575 | E4: 4311469006 | F4: ธนาคารไทยพาณิชย์ (SCB) | G4: 7 | H4: 1694 | I4: 0 | J4: 1694 | K4: 244198 | L4: 1694 | M4: =+L4-J4 -> 0
A5: 3 | B5: 244199 | C5: suckjakkure@hotmail.com | D5: 0642427575 | E5: 4311469006 | F5: ธนาคารไทยพาณิชย์ (SCB) | G5: 1 | H5: 309 | I5: 0 | J5: 309 | K5: 244199 | L5: 309 | M5: =+L5-J5 -> 0
A6: 4 | B6: 244199 | C6: suckjakkure@hotmail.com | D6: 0642427575 | E6: 4311469006 | F6: ธนาคารไทยพาณิชย์ (SCB) | G6: 4 | H6: 848 | I6: 0 | J6: 848 | K6: 244199 | L6: 848 | M6: =+L6-J6 -> 0
A7: 5 | B7: 244200 | C7: ไม่มียอดเก็บ COD | K7: 244200 | L7: 0 | M7: =+L7-J7 -> 0
A8: 6 | B8: 244201 | C8: suckjakkure@hotmail.com | D8: 0642427575 | E8: 4311469006 | F8: ธนาคารไทยพาณิชย์ (SCB) | G8: 3 | H8: 664 | I8: 0 | J8: 664 | K8: 244201 | L8: 664 | M8: =+L8-J8 -> 0
A9: 7 | B9: 244202 | C9: ไม่มียอดเก็บ COD | K9: 244202 | L9: 0 | M9: =+L9-J9 -> 0
A10: 8 | B10: 244203 | C10: suckjakkure@hotmail.com | D10: 0642427575 | E10: 4311469006 | F10: ธนาคารไทยพาณิชย์ (SCB) | G10: 4 | H10: 1199 | I10: 0 | J10: 1199 | K10: 244203 | L10: 1199 | M10: =+L10-J10 -> 0
A11: 9 | B11: 244204 | C11: suckjakkure@hotmail.com | D11: 0642427575 | E11: 4311469006 | F11: ธนาคารไทยพาณิชย์ (SCB) | G11: 3 | H11: 649 | I11: 0 | J11: 649 | K11: 244204 | L11: 649 | M11: =+L11-J11 -> 0
A12: 10 | B12: 244205 | C12: suckjakkure@hotmail.com | D12: 0642427575 | E12: 4311469006 | F12: ธนาคารไทยพาณิชย์ (SCB) | G12: 28 | H12: 9008 | I12: 0 | J12: 9008 | K12: 244205 | L12: 9008 | M12: =+L12-J12 -> 0
A13: 11 | B13: 244206 | C13: suckjakkure@hotmail.com | D13: 0642427575 | E13: 4311469006 | F13: ธนาคารไทยพาณิชย์ (SCB) | G13: 21 | H13: 5447 | I13: 0 | J13: 5447 | K13: 244206 | L13: 5447 | M13: =+L13-J13 -> 0
A14: 12 | B14: 244207 | C14: suckjakkure@hotmail.com | D14: 0642427575 | E14: 4311469006 | F14: ธนาคารไทยพาณิชย์ (SCB) | G14: 7 | H14: 1730 | I14: 0 | J14: 1730 | K14: 244207 | L14: 1730 | M14: =+L14-J14 -> 0
A15: 13 | B15: 244208 | C15: suckjakkure@hotmail.com | D15: 0642427575 | E15: 4311469006 | F15: ธนาคารไทยพาณิชย์ (SCB) | G15: 67 | H15: 15956 | I15: 0 | J15: 15956 | K15: 244208 | L15: 15956 | M15: =+L15-J15 -> 0
A16: 14 | B16: 244209 | C16: suckjakkure@hotmail.com | D16: 0642427575 | E16: 4311469006 | F16: ธนาคารไทยพาณิชย์ (SCB) | G16: 10 | H16: 3615 | I16: 0 | J16: 3615 | K16: 244209 | L16: 3615 | M16: =+L16-J16 -> 0
A17: 15 | B17: 244210 | C17: suckjakkure@hotmail.com | D17: 0642427575 | E17: 4311469006 | F17: ธนาคารไทยพาณิชย์ (SCB) | G17: 6 | H17: 1249 | I17: 0 | J17: 1249 | K17: 244210 | L17: 1249 | M17: =+L17-J17 -> 0
A18: 16 | B18: 244210 | C18: suckjakkure@hotmail.com | D18: 0642427575 | E18: 4311469006 | F18: ธนาคารไทยพาณิชย์ (SCB) | G18: 15 | H18: 3184 | I18: 0 | J18: 3184 | K18: 244210 | L18: 3184 | M18: =+L18-J18 -> 0
A19: 17 | B19: 244211 | C19: suckjakkure@hotmail.com | D19: 0642427575 | E19: 4311469006 | F19: ธนาคารไทยพาณิชย์ (SCB) | G19: 2 | H19: 400 | I19: 0 | J19: 400 | K19: 244211 | L19: 400 | M19: =+L19-J19 -> 0
A20: 18 | B20: 244211 | C20: suckjakkure@hotmail.com | D20: 0642427575 | E20: 4311469006 | F20: ธนาคารไทยพาณิชย์ (SCB) | G20: 10 | H20: 2260 | I20: 0 | J20: 2260 | K20: 244211 | L20: 2260 | M20: =+L20-J20 -> 0
A21: 19 | B21: 244212 | C21: suckjakkure@hotmail.com | D21: 0642427575 | E21: 4311469006 | F21: ธนาคารไทยพาณิชย์ (SCB) | G21: 3 | H21: 889 | I21: 0 | J21: 889 | K21: 244212 | L21: 889 | M21: =+L21-J21 -> 0
... A23: 21 | B23: 244213 | C23: suckjakkure@hotmail.com | D23: 0642427575 | E23: 4311469006 | F23: ธนาคารไทยพาณิชย์ (SCB) | G23: 1 | H23: 215 | I23: 0 | J23: 215 | K23: 244213 | L23: 215 | M23: =+L23-J23 -> 0
A24: 22 | B24: 244214 | C24: ไม่มียอดเก็บ COD | K24: 244214 | L24: 0 | M24: =+L24-J24 -> 0
A25: 23 | B25: 244215 | C25: suckjakkure@hotmail.com | D25: 0642427575 | E25: 4311469006 | F25: ธนาคารไทยพาณิชย์ (SCB) | G25: 1 | H25: 215 | I25: 0 | J25: 215 | K25: 244215 | L25: 215 | M25: =+L25-J25 -> 0
A26: 24 | B26: 244216 | C26: suckjakkure@hotmail.com | D26: 0642427575 | E26: 4311469006 | F26: ธนาคารไทยพาณิชย์ (SCB) | G26: 1 | H26: 170 | I26: 0 | J26: 170 | K26: 244216 | L26: 170 | M26: =+L26-J26 -> 0
A27: 25 | B27: 244217 | C27: suckjakkure@hotmail.com | D27: 0642427575 | E27: 4311469006 | F27: ธนาคารไทยพาณิชย์ (SCB) | G27: 1 | H27: 215 | I27: 0 | J27: 215 | K27: 244217 | L27: 215 | M27: =+L27-J27 -> 0
A28: 26 | B28: 244218 | C28: ไม่มียอดเก็บ COD | K28: 244218 | L28: 0 | M28: =+L28-J28 -> 0
A29: 27 | B29: 244219 | C29: suckjakkure@hotmail.com | D29: 642427575 | E29: 4311469006 | F29: ธนาคารไทยพาณิชย์ (SCB) | G29: 8 | H29: 2853 | I29: 0 | J29: 2853 | K29: 244219 | L29: 2853 | M29: =+L29-J29 -> 0
A30: 28 | B30: 244220 | C30: suckjakkure@hotmail.com | D30: 642427575 | E30: 4311469006 | F30: ธนาคารไทยพาณิชย์ (SCB) | G30: 9 | H30: 1900 | I30: 0 | J30: 1900 | K30: 244220 | L30: 1900 | M30: =+L30-J30 -> 0
A31: 29 | B31: 244221 | C31: suckjakkure@hotmail.com | D31: 642427575 | E31: 4311469006 | F31: ธนาคารไทยพาณิชย์ (SCB) | G31: 1 | H31: 215 | I31: 0 | J31: 215 | K31: 244221 | L31: 215 | M31: =+L31-J31 -> 0
A32: 30 | B32: 244222 | C32: suckjakkure@hotmail.com | D32: 642427575 | E32: 4311469006 | F32: ธนาคารไทยพาณิชย์ (SCB) | G32: 9 | H32: 2228 | I32: 0 | J32: 2228 | K32: 244222 | L32: 2228 | M32: =+L32-J32 -> 0
A33: 31 | B33: 244223 | C33: suckjakkure@hotmail.com | D33: 642427575 | E33: 4311469006 | F33: ธนาคารไทยพาณิชย์ (SCB) | G33: 3 | H33: 900 | I33: 0 | J33: 900 | K33: 244223 | L33: 900 | M33: =+L33-J33 -> 0
A34: 32 | B34: 244224 | C34: suckjakkure@hotmail.com | D34: 642427575 | E34: 4311469006 | F34: ธนาคารไทยพาณิชย์ (SCB) | G34: 4 | H34: 1259 | I34: 0 | J34: 1259 | K34: 244224 | L34: 1259 | M34: =+L34-J34 -> 0
B35: 244225 | C35: suckjakkure@hotmail.com | D35: 642427575 | E35: 4311469006 | F35: ธนาคารไทยพาณิชย์ (SCB) | G35: =SUM(G3:G34) -> 238 | H35: =SUM(H3:H34) -> 61493 | I35: =SUM(I3:I34) -> 0 | J35: =SUM(J3:J34) -> 61493 | K35: 244225 | L35: =SUM(L3:L34) -> 61493 | M35: =+L35-J35 -> 0
B36: 244226 | C36: suckjakkure@hotmail.com | D36: 642427575 | E36: 4311469006 | F36: ธนาคารไทยพาณิชย์ (SCB) | G36: 2 | H36: 495 | I36: 0 | J36: 495 | K36: 244226 | L36: 495 | M36: =+L36-J36 -> 0
B37: 244227 | C37: suckjakkure@hotmail.com | D37: 642427575 | E37: 4311469006 | F37: ธนาคารไทยพาณิชย์ (SCB) | G37: 2 | H37: 379 | I37: 0 | J37: 379 | K37: 244227 | L37: 379 | M37: =+L37-J37 -> 0
B38: 244228 | K38: 244228 | M38: =+L38-J38 -> 0
F39: ยอดรวม | G39: =SUM(G3:G38) -> 480 | H39: =SUM(H3:H38) -> 123860 | I39: =SUM(I3:I38) -> 0 | J39: =SUM(J3:J38) -> 123860 | K39: บาท | L39: =SUM(L3:L38) -> 123860 | M39: บาท

Sheet ก.ค.
A1: ข้อมูลการเก็บเงินปลายทาง (COD) แบบแยกรายละเอียด เดือนกรกฎาคม 2568
A2: ลำดับ | B2: วันที่ | C2: Email | D2: Facebook Page | E2: Order No. / เลขที่ออเดอร์ | F2: Tracking No. / เลขพัสดุ | G2: recipientName / ชื่อลูกค้า | H2: Amount / ยอด COD
A3: 1 | B3: 244166 | C3: suckjakkure@hotmail.com | D3: FACEBOOK | F3: JA254343066TH | G3: ลักษณ์กมล สกุลตั้งพัฒนะกูล | H3: 215
A4: 2 | B4: 244166 | C4: suckjakkure@hotmail.com | D4: FACEBOOK | F4: JA254342848TH | G4: อรอนงค์ เจริญผ่อง | H4: 215
A5: 3 | B5: 244166 | C5: suckjakkure@hotmail.com | D5: FACEBOOK | F5: JA254343035TH | G5: ???? ??? ?? ??? | H5: 215
A6: 4 | B6: 244166 | C6: suckjakkure@hotmail.com | D6: FACEBOOK | F6: JA254342817TH | G6: สายทิพย์ ณะน่าน | H6: 215
A7: 5 | B7: 244166 | C7: suckjakkure@hotmail.com | D7: FACEBOOK | F7: JA254342879TH | G7: อุษา พุทธา | H7: 215
A8: 6 | B8: 244166 | C8: suckjakkure@hotmail.com | D8: FACEBOOK | F8: JA254342922TH | G8: น้ำเย็น | H8: 215
A9: 7 | B9: 244166 | C9: suckjakkure@hotmail.com | D9: FACEBOOK | F9: JA254342834TH | G9: สุภาพร สาประเสริฐ | H9: 215
A10: 8 | B10: 244166 | C10: suckjakkure@hotmail.com | D10: FACEBOOK | F10: JA254342825TH | G10: คลอใจ | H10: 215
A11: 9 | B11: 244166 | C11: suckjakkure@hotmail.com | D11: FACEBOOK | F11: JA254024221TH | G11: นายดำ ประมูล | H11: 170
A12: 10 | B12: 244166 | C12: suckjakkure@hotmail.com | D12: FACEBOOK | F12: JA253761494TH | G12: ธมกร นาครินทร์ | H12: 170
A13: 11 | B13: 244166 | C13: suckjakkure@hotmail.com | D13: FACEBOOK | F13: JA253761619TH | G13: นายนราดร บุตรสันติ์ | H13: 215
A14: 12 | B14: 244166 | C14: suckjakkure@hotmail.com | D14: FACEBOOK | F14: JA254342975TH | G14: ภาวนา บริบูรณ์ | H14: 215
... A34: 32 | B34: 244167 | C34: suckjakkure@hotmail.com | D34: FACEBOOK | F34: JA254343052TH | G34: เดือน โยธาฤทธิ์ | H34: 215
A35: 33 | B35: 244167 | C35: suckjakkure@hotmail.com | D35: FACEBOOK | F35: JA254342919TH | G35: =SUM(G3:G34) -> 0 | H35: =SUM(H3:H34) -> 7173 | I35: =SUM(I3:I34) -> 0 | J35: =SUM(J3:J34) -> 0 | L35: =SUM(L3:L34) -> 0
A36: 34 | B36: 244167 | C36: suckjakkure@hotmail.com | D36: FACEBOOK | F36: JA254342953TH | G36: โกมินทร์ มีมั่งคั่ง | H36: 215
A37: 35 | B37: 244167 | C37: suckjakkure@hotmail.com | D37: FACEBOOK | F37: JA254757709TH | G37: พลเทพ เทพเสนา | H37: 320
A38: 36 | B38: 244167 | C38: suckjakkure@hotmail.com | D38: FACEBOOK | F38: JA254757726TH | G38: อัมพร บุบผา | H38: 215
A39: 37 | B39: 244167 | C39: suckjakkure@hotmail.com | D39: FACEBOOK | F39: JA253761415TH | G39: สุภัทรา มะตะราช | H39: 215
A40: 38 | B40: 244167 | C40: suckjakkure@hotmail.com | D40: FACEBOOK | F40: JA253761565TH | G40: คีง | H40: 430
A41: 39 | B41: 244167 | C41: suckjakkure@hotmail.com | D41: FACEBOOK | F41: JA253761344TH | G41: จันทรา ผาแก้ว | H41: 215
A42: 40 | B42: 244167 | C42: suckjakkure@hotmail.com | D42: FACEBOOK | F42: JA254342851TH | G42: ภาสินี นิลคง | H42: 215
A43: 41 | B43: 244167 | C43: suckjakkure@hotmail.com | D43: FACEBOOK | F43: JA253761503TH | G43: น.ส.สุพัตรา มากจันทร์ | H43: 215
A44: 42 | B44: 244167 | C44: suckjakkure@hotmail.com | D44: FACEBOOK | F44: JA253761049TH | G44: เสาวภา ไพบูลย์ | H44: 215
A45: 43 | B45: 244167 | C45: suckjakkure@hotmail.com | D45: FACEBOOK | F45: JA254343049TH | G45: วันดีดำคง | H45: 215
A46: 44 | B46: 244168 | C46: suckjakkure@hotmail.com | D46: FACEBOOK | F46: JA255169911TH | G46: สุภัสรา บัวประสาน | H46: 215
A47: 45 | B47: 244168 | C47: suckjakkure@hotmail.com | D47: FACEBOOK | F47: JA255169868TH | G47: ณัฐชดา พันธุ์หินลาด | H47: 215
... A231: 229 | B231: 244181 | C231: suckjakkure@hotmail.com | D231: FACEBOOK | F231: JA258813560TH | G231: นางสาวศดานันท์ จันทรมานิต | H231: 1000
A232: 230 | B232: 244181 | C232: suckjakkure@hotmail.com | D232: FACEBOOK | F232: JA258813587TH | G232: นางสาวศดานันท์ จันทรมานิต | H232: 1175 | I232: บาท
A233: 231 | B233: 244181 | C233: suckjakkure@hotmail.com | D233: FACEBOOK | F233: JA257278786TH | G233: ชนัญชิดา เฉลยพิศ | H233: 215
A234: 232 | B234: 244181 | C234: suckjakkure@hotmail.com | D234: FACEBOOK | F234: JA258320984TH | G234: แสงดาว_จำรัสลาภ | H234: 215
A235: 233 | B235: 244181 | C235: suckjakkure@hotmail.com | D235: FACEBOOK | F235: JA258071465TH | G235: สุกัญญา คำประกายกุล | H235: 215
A236: 234 | B236: 244181 | C236: suckjakkure@hotmail.com | D236: FACEBOOK | F236: JA258320967TH | G236: จินตนา ของทิพย์ | H236: 219
A237: 235 | B237: 244181 | C237: suckjakkure@hotmail.com | D237: FACEBOOK | F237: JA258813511TH | G237: สรรเสริญ ใจเย็น | H237: 215
A238: 236 | B238: 244181 | C238: suckjakkure@hotmail.com | D238: FACEBOOK | F238: JA258071479TH | G238: ธนศร | H238: 215
A239: 237 | B239: 244181 | C239: suckjakkure@hotmail.com | D239: FACEBOOK | F239: JA258813627TH | G239: ยุพา สงเคราะห์ | H239: 215
A240: 238 | B240: 244182 | C240: suckjakkure@hotmail.com | D240: FACEBOOK | F240: JA259166972TH | G240: คุณยอด ฤทธิ์ฉ่ำ | H240: 215
A241: 239 | B241: 244182 | C241: suckjakkure@hotmail.com | D241: FACEBOOK | F241: JA259167045TH | G241: อนุรี สายกลิ่น | H241: 215
A242: 240 | B242: 244182 | C242: suckjakkure@hotmail.com | D242: FACEBOOK | F242: JA257278698TH | G242: รินทร์ลิตา เพ็ชรรัตน์ | H242: 215
...

Sheet Summary ก.ค.
B1: ข้อมูลการเก็บเงินปลายทาง (COD) แบบรวมยอดประจำวัน เดือนกรกฎาคม 2568 | K1: ตรวจในสเตทเม้น
