Workbook

Sheet สรุป
A1: ข้อมูลการเก็บเงินปลายทาง (COD) ปี 2569
A2: ลำดับ | B2: Total Order / จำนวนออเดอร์ | C2: COD Amount / ยอดรวม COD | D2: Deduct | E2: Total Amount / ยอดรวม COD | G2: ยอดลดหนี้ COD
A3: 1 | B3: =+'Summary ม.ค.'!G39 -> 196 | C3: =+'Summary ม.ค.'!H39 -> 61722 | D3: =+'Summary ม.ค.'!I39 -> 0 | E3: =+'Summary ม.ค.'!J39 -> 61722 | G3: 0
A4: 2 | B4: 322 | C4: 96400 | D4: 0 | E4: 96400 | G4: 0
A5: 3 | B5: 309 | C5: 68833 | D5: 0 | E5: 68833 | G5: 0
A6: 4 | B6: =+' Summary เม.ย.'!G38 -> 528 | C6: =+' Summary เม.ย.'!H38 -> 125946 | D6: =+' Summary เม.ย.'!I38 -> 0 | E6: =+' Summary เม.ย.'!J38 -> 125946 | G6: 0
A7: 5 | B7: =+'Summary พ.ค.'!G34 -> 530 | C7: =+'Summary พ.ค.'!H34 -> 122657 | D7: =+'Summary พ.ค.'!I34 -> 0 | E7: =+'Summary พ.ค.'!J34 -> 122657 | G7: 0
A8: 6 | B8: =+'Summary มิ.ย.'!G33 -> 326 | C8: =+'Summary มิ.ย.'!H33 -> 66099 | D8: =+'Summary มิ.ย.'!I33 -> 0 | E8: =+'Summary มิ.ย.'!J33 -> 66099 | G8: 0
A9: 7
A10: 8
A11: 9
A12: 10
A13: 11
A14: 12
A15: 13 | B15: =SUM(B3:B14) -> 2211 | C15: =SUM(C3:C14) -> 541657 | D15: =SUM(D3:D14) -> 0 | E15: =SUM(E3:E14) -> 541657 | F15: บาท | G15: =SUM(G3:G14) -> 0

Sheet ม.ค.
A1: ข้อมูลการเก็บเงินปลายทาง (COD) แบบแยกรายละเอียด เดือนมกราคม 2569
A2: ลำดับ | B2: วันที่ | C2: Email | D2: Facebook Page | E2: Order No. / เลขที่ออเดอร์ | F2: Tracking No. / เลขพัสดุ | G2: recipientName / ชื่อลูกค้า | H2: Amount / ยอด COD
A3: 1 | B3: 244350 | C3: suckjakkure@hotmail.com | D3: FACEBOOK | E3: KTINTER694f31c0310f038ccca1157e | F3: TH2719862SSQ0A | G3: เป็นเพียงผู้หญิง ที่ยืนฉี่ข้างเทอร์ | H3: 798
A4: 2 | B4: 244350 | C4: suckjakkure@hotmail.com | D4: FACEBOOK | E4: KTINTER694f324e310f038ccca1476b | F4: TH2917862SSN7E | G4: สุภัสรา บัวประสาน | H4: 399
A5: 3 | B5: 244350 | C5: suckjakkure@hotmail.com | D5: FACEBOOK | E5: KTINTER694f3221276951836e6450e5 | F5: TH4704862SSP3A | G5: ผ่องฉวีวรรณ์ | H5: 215
A6: 4 | B6: 244350 | C6: suckjakkure@hotmail.com | D6: FACEBOOK | F6: WA066776316TH | G6: จารึก | H6: 199
A7: 5 | B7: 244350 | C7: suckjakkure@hotmail.com | D7: FACEBOOK | F7: WA066776452TH | G7: นาง รุจิภาสินี นิยมวัน | H7: 199
A8: 6 | B8: 244350 | C8: suckjakkure@hotmail.com | D8: FACEBOOK | F8: WA066776483TH | G8: ปัญญา ยศวิไล | H8: 995
A9: 7 | B9: 244350 | C9: suckjakkure@hotmail.com | D9: FACEBOOK | F9: WA066776333TH | G9: ทิตยา โปรณะ | H9: 199
A10: 8 | B10: 244350 | C10: suckjakkure@hotmail.com | D10: FACEBOOK | F10: WA066657248TH | G10: มลฤดี คงบรรจง | H10: 750
A11: 9 | B11: 244350 | C11: suckjakkure@hotmail.com | D11: FACEBOOK | F11: WA066776554TH | G11: คุณ สกุล สังข์มงคล | H11: 199
A12: 10 | B12: 244350 | C12: suckjakkure@hotmail.com | D12: FACEBOOK | F12: WA066776302TH | G12: จิระวัฒ ลี้รักสิทธิ์ | H12: 199
A13: 11 | B13: 244350 | C13: suckjakkure@hotmail.com | D13: FACEBOOK | F13: WA066776259TH | G13: คุณ นก | H13: 199
A14: 12 | B14: 244350 | C14: suckjakkure@hotmail.com | D14: FACEBOOK | F14: WA066776421TH | G14: นาย ธงไชย วงศ์ธีระธนากร | H14: 199
A15: 13 | B15: 244350 | C15: suckjakkure@hotmail.com | D15: FACEBOOK | F15: WA066776355TH | G15: ไลลา วีระมงคล | H15: 199
A16: 14 | B16: 244350 | C16: suckjakkure@hotmail.com | D16: FACEBOOK | F16: WA066776320TH | G16: นิศาชล เปี่ยมประถม | H16: 199
A17: 15 | B17: 244350 | C17: suckjakkure@hotmail.com | D17: FACEBOOK | F17: WA066776435TH | G17: มาลี อำพนวิพุธ | H17: 215
... A28: 26 | B28: 244381 | C28: suckjakkure@hotmail.com | D28: FACEBOOK | F28: WA066776165TH | G28: ปาริชาต กล้าหาญ | H28: 199
A29: 27 | B29: 244409 | C29: suckjakkure@hotmail.com | D29: FACEBOOK | E29: KTINTER69538efb310f038cccf197c4 | F29: TH010586BUTV9D1 | G29: ภาพิมล. วรสุข | H29: 398
A30: 28 | B30: 244409 | C30: suckjakkure@hotmail.com | D30: FACEBOOK | E30: KTINTER69538f4edaefa73df4e008d9 | F30: TH050186BUTU7Q | G30: วันชัย นกแก้ว | H30: 399
A31: 29 | B31: 244409 | C31: suckjakkure@hotmail.com | D31: FACEBOOK | E31: KTINTER6954b9b6daefa73df422b68f | F31: TH150186DYH97I | G31: เดือนเพ็ญ กรงเข็ม | H31: 430
A32: 30 | B32: 244409 | C32: suckjakkure@hotmail.com | D32: FACEBOOK | E32: KTINTER69538f10daefa73df4dfe8eb | F32: TH180186BUTV4B | G32: เจตนิพิฐ นิมาภาศ | H32: 215
A33: 31 | B33: 244409 | C33: suckjakkure@hotmail.com | D33: FACEBOOK | E33: KTINTER6954771bdaefa73df40dc04f | F33: TH200186CXM49E | G33: Thanapat Pichet | H33: 199
A34: 32 | B34: 244409 | C34: suckjakkure@hotmail.com | D34: FACEBOOK | E34: KTINTER6954b9d5daefa73df422c26b | F34: TH260586DYHA8C | G34: นางสาว วาสนา ทูคำมี | H34: 199
A35: 33 | B35: 244409 | C35: suckjakkure@hotmail.com | D35: FACEBOOK | F35: WA066776157TH | G35: ชนะพัฒน์ ตากรวด | H35: 200
A36: 34 | B36: 244409 | C36: suckjakkure@hotmail.com | D36: FACEBOOK | F36: WA066776537TH | G36: มะณีวัน ลำใย | H36: 199
A37: 35 | B37: 244409 | C37: suckjakkure@hotmail.com | D37: FACEBOOK | F37: WA066776404TH | G37: ยุพาวรรณ ตันสุวรรณ์ | H37: 199
A38: 36 | B38: 244409 | C38: suckjakkure@hotmail.com | D38: FACEBOOK | F38: WA066776470TH | G38: อรสา​อรุณ​ไพร | H38: 199
A39: 37 | B39: 244440 | C39: suckjakkure@hotmail.com | D39: FACEBOOK | E39: KTINTER69538e7f310f038cccf17632 | F39: TH010386BUTY1D1 | G39: Be Happy Nee | H39: 399
A40: 38 | B40: 244440 | C40: suckjakkure@hotmail.com | D40: FACEBOOK | E40: KTINTER69538fd0310f038cccf1e780 | F40: TH010686BUTQ9C | G40: อุษณีษ์ สุทธิสารสุนทร | H40: 398
A41: 39 | B41: 244440 | C41: suckjakkure@hotmail.com | D41: FACEBOOK | E41: KTINTER6954dd68310f038ccc3ce79c | F41: TH180586E0US0C | G41: เสรี-ช่วยชูกลิ่น | H41: 399
A42: 40 | B42: 244440 | C42: suckjakkure@hotmail.com | D42: FACEBOOK | E42: KTINTER69538f5e3b6108789209c129 | F42: TH410186BUTU3N | G42: ณัชชนม์ ภวภูตานนท์ | H42: 399
A43: 41 | B43: 244440 | C43: suckjakkure@hotmail.com | D43: FACEBOOK | E43: KTINTER6954dd5b87add4c4b9d34a74 | F43: TH410486E0UR9A | G43: รำพรรณ. ชาญวิรัตน์ | H43: 399
A44: 42 | B44: 244440 | C44: suckjakkure@hotmail.com | D44: FACEBOOK | E44: KTINTER69538ee2310f038cccf19324 | F44: TH520186BUTW6C | G44: ชีวรรณเทียมทินกฤต | H44: 199
A45: 43 | B45: 244470 | C45: suckjakkure@hotmail.com | D45: FACEBOOK | E45: KTINTER69538e993b6108789209700f | F45: TH013986BUTX6E | G45: น้ำค้าง สิงห์ราช | H45: 399
A46: 44 | B46: 244470 | C46: suckjakkure@hotmail.com | D46: FACEBOOK | E46: KTINTER6954b9e9daefa73df422c8ab | F46: TH101186DYHB1F | G46: Jiranun Naksiri | H46: 399
A47: 45 | B47: 244470 | C47: suckjakkure@hotmail.com | D47: FACEBOOK | F47: WA067364585TH | G47: พัชรา ตรีพุท | H47: 399
A48: 46 | B48: 244470 | C48: suckjakkure@hotmail.com | D48: FACEBOOK | F48: WA067364651TH | G48: ประสงค์ อภิวัฒน์ชาติ | H48: 215
A49: 47 | B49: 244470 | C49: suckjakkure@hotmail.com | D49: FACEBOOK | F49: WA066776418TH | G49: นรินทร์ทิพย์ ชไนเดอร์ จูเนียร์ | H49: 398
A50: 48 | B50: 244470 | C50: suckjakkure@hotmail.com | D50: FACEBOOK | F50: WA066776571TH | G50: คุณ เอ้ | H50: 199
...

Sheet Summary ม.ค.
A1: ข้อมูลการเก็บเงินปลายทาง (COD) แบบรวมยอดประจำวัน เดือนมกราคม 2569 | K1: ตรวจในสเตทเม้น
A2: ลำดับ | B2: วันที่ | C2: Email | D2: Tel | E2: Bank Account Number / เลขที่บัญชี | F2: Bank Account Name / ชื่อธนาคาร | G2: Total Order / จำนวนออเดอร์ | H2: COD Amount / ยอดรวม COD | I2: Deduct | J2: Total Amount / ยอดรวม COD | K2: วันที่เงินเข้า | L2: ยอดเข้า | M2: หมายเหตุ
A3: 1 | B3: 244350 | C3: suckjakkure@hotmail.com | D3: 642427575 | E3: 4311469006 | F3: ธนาคารไทยพาณิชย์ (SCB) | G3: 3 | H3: 1412 | I3: 0 | J3: 1412 | K3: 244350 | L3: 1412 | M3: =+J3-L3 -> 0
A4: 2 | B4: 244350 | C4: suckjakkure@hotmail.com | D4: 642427575 | E4: 4311469006 | F4: ธนาคารไทยพาณิชย์ (SCB) | G4: 15 | H4: 4348 | I4: 0 | J4: 4348 | K4: 244350 | L4: 4348 | M4: =+J4-L4 -> 0
A5: 3 | B5: 244351 | C5: suckjakkure@hotmail.com | D5: 642427575 | E5: 4311469006 | F5: ธนาคารไทยพาณิชย์ (SCB) | G5: 8 | H5: 2489 | I5: 0 | J5: 2489 | K5: 244351 | L5: 2489 | M5: =+J5-L5 -> 0
A6: 4 | B6: 244352 | C6: suckjakkure@hotmail.com | D6: 642427575 | E6: 4311469006 | F6: ธนาคารไทยพาณิชย์ (SCB) | G6: 6 | H6: 1840 | I6: 0 | J6: 1840 | K6: 244352 | L6: 1840 | M6: =+J6-L6 -> 0
A7: 5 | B7: 244352 | C7: suckjakkure@hotmail.com | D7: 642427575 | E7: 4311469006 | F7: ธนาคารไทยพาณิชย์ (SCB) | G7: 4 | H7: 797 | I7: 0 | J7: 797 | K7: 244352 | L7: 797 | M7: =+J7-L7 -> 0
A8: 6 | B8: 244353 | C8: suckjakkure@hotmail.com | D8: 642427575 | E8: 4311469006 | F8: ธนาคารไทยพาณิชย์ (SCB) | G8: 6 | H8: 2193 | I8: 0 | J8: 2193 | K8: 244353 | L8: 2193 | M8: =+J8-L8 -> 0
A9: 7 | B9: 244354 | C9: suckjakkure@hotmail.com | D9: 642427575 | E9: 4311469006 | F9: ธนาคารไทยพาณิชย์ (SCB) | G9: 2 | H9: 798 | I9: 0 | J9: 798 | K9: 244354 | L9: 798 | M9: =+J9-L9 -> 0
A10: 8 | B10: 244354 | C10: suckjakkure@hotmail.com | D10: 642427575 | E10: 4311469006 | F10: ธนาคารไทยพาณิชย์ (SCB) | G10: 12 | H10: 3034 | I10: 0 | J10: 3034 | K10: 244354 | L10: 3034 | M10: =+J10-L10 -> 0
A11: 9 | B11: 244355 | C11: suckjakkure@hotmail.com | D11: 642427575 | E11: 4311469006 | F11: ธนาคารไทยพาณิชย์ (SCB) | G11: 2 | H11: 629 | I11: 0 | J11: 629 | K11: 244355 | L11: 629 | M11: =+J11-L11 -> 0
A12: 10 | B12: 244355 | C12: suckjakkure@hotmail.com | D12: 642427575 | E12: 4311469006 | F12: ธนาคารไทยพาณิชย์ (SCB) | G12: 7 | H12: 2155 | I12: 0 | J12: 2155 | K12: 244355 | L12: 2155 | M12: =+J12-L12 -> 0
A13: 11 | B13: 244356 | C13: suckjakkure@hotmail.com | D13: 642427575 | E13: 4311469006 | F13: ธนาคารไทยพาณิชย์ (SCB) | G13: 2 | H13: 1399 | I13: 0 | J13: 1399 | K13: 244356 | L13: 1399 | M13: =+J13-L13 -> 0
A14: 12 | B14: 244357 | C14: suckjakkure@hotmail.com | D14: 642427575 | E14: 4311469006 | F14: ธนาคารไทยพาณิชย์ (SCB) | G14: 4 | H14: 828 | I14: 0 | J14: 828 | K14: 244357 | L14: 828 | M14: =+J14-L14 -> 0
... A18: 16 | B18: 244360 | C18: suckjakkure@hotmail.com | D18: 642427575 | E18: 4311469006 | F18: ธนาคารไทยพาณิชย์ (SCB) | G18: 3 | H18: 1013 | I18: 0 | J18: 1013 | K18: 244360 | L18: 1013 | M18: =+J18-L18 -> 0
A19: 17 | B19: 244361 | C19: ไม่มียอดเก็บ COD | K19: 244361 | M19: =+J19-L19 -> 0
A20: 18 | B20: 244362 | C20: suckjakkure@hotmail.com | D20: 642427575 | E20: 4311469006 | F20: ธนาคารไทยพาณิชย์ (SCB) | G20: 2 | H20: 595 | I20: 0 | J20: 595 | K20: 244362 | L20: 595 | M20: =+J20-L20 -> 0
A21: 19 | B21: 244363 | C21: suckjakkure@hotmail.com | D21: 642427575 | E21: 4311469006 | F21: ธนาคารไทยพาณิชย์ (SCB) | G21: 7 | H21: 4788 | I21: 0 | J21: 4788 | K21: 244363 | L21: 4788 | M21: =+J21-L21 -> 0
A22: 20 | B22: 244364 | C22: suckjakkure@hotmail.com | D22: 642427575 | E22: 4311469006 | F22: ธนาคารไทยพาณิชย์ (SCB) | G22: 2 | H22: 2210 | I22: 0 | J22: 2210 | K22: 244364 | L22: 2210 | M22: =+J22-L22 -> 0
A23: 21 | B23: 244365 | C23: suckjakkure@hotmail.com | D23: 642427575 | E23: 4311469006 | F23: ธนาคารไทยพาณิชย์ (SCB) | G23: 7 | H23: 1575 | I23: 0 | J23: 1575 | K23: 244365 | L23: 1575 | M23: =+J23-L23 -> 0
A24: 22 | B24: 244366 | C24: suckjakkure@hotmail.com | D24: 642427575 | E24: 4311469006 | F24: ธนาคารไทยพาณิชย์ (SCB) | G24: 4 | H24: 944 | I24: 0 | J24: 944 | K24: 244366 | L24: 944 | M24: =+J24-L24 -> 0
A25: 23 | B25: 244367 | C25: ไม่มียอดเก็บ COD | K25: 244367 | M25: =+J25-L25 -> 0
A26: 24 | B26: 244368 | C26: suckjakkure@hotmail.com | D26: 642427575 | E26: 4311469006 | F26: ธนาคารไทยพาณิชย์ (SCB) | G26: 3 | H26: 645 | I26: 0 | J26: 645 | K26: 244368 | L26: 645 | M26: =+J26-L26 -> 0
A27: 25 | B27: 244369 | C27: suckjakkure@hotmail.com | D27: 642427575 | E27: 4311469006 | F27: ธนาคารไทยพาณิชย์ (SCB) | G27: 8 | H27: 3207 | I27: 0 | J27: 3207 | K27: 244369 | L27: 3207 | M27: =+J27-L27 -> 0
A28: 26 | B28: 244370 | C28: suckjakkure@hotmail.com | D28: 642427575 | E28: 4311469006 | F28: ธนาคารไทยพาณิชย์ (SCB) | G28: 8 | H28: 2276 | I28: 0 | J28: 2276 | K28: 244370 | L28: 2276 | M28: =+J28-L28 -> 0
A29: 27 | B29: 244371 | C29: suckjakkure@hotmail.com | D29: 642427575 | E29: 4311469006 | F29: ธนาคารไทยพาณิชย์ (SCB) | G29: 4 | H29: 1128 | I29: 0 | J29: 1128 | K29: 244371 | L29: 1128 | M29: =+J29-L29 -> 0
A30: 28 | B30: 244372 | C30: suckjakkure@hotmail.com | D30: 642427575 | E30: 4311469006 | F30: ธนาคารไทยพาณิชย์ (SCB) | G30: 3 | H30: 913 | I30: 0 | J30: 913 | K30: 244372 | L30: 913 | M30: =+J30-L30 -> 0
A31: 29 | B31: 244373 | C31: suckjakkure@hotmail.com | D31: 642427575 | E31: 4311469006 | F31: ธนาคารไทยพาณิชย์ (SCB) | G31: 8 | H31: 2058 | I31: 0 | J31: 2058 | K31: 244373 | L31: 2058 | M31: =+J31-L31 -> 0
A32: 30 | B32: 244374 | C32: suckjakkure@hotmail.com | D32: 642427575 | E32: 4311469006 | F32: ธนาคารไทยพาณิชย์ (SCB) | G32: 6 | H32: 1225 | I32: 0 | J32: 1225 | K32: 244374 | L32: 1225 | M32: =+J32-L32 -> 0
A33: 31 | B33: 244375 | C33: suckjakkure@hotmail.com | D33: 642427575 | E33: 4311469006 | F33: ธนาคารไทยพาณิชย์ (SCB) | G33: 3 | H33: 729 | I33: 0 | J33: 729 | K33: 244375 | L33: 729 | M33: =+J33-L33 -> 0
A34: 32 | B34: 244376 | C34: suckjakkure@hotmail.com | D34: 642427575 | E34: 4311469006 | F34: ธนาคารไทยพาณิชย์ (SCB) | G34: 5 | H34: 1327 | I34: 0 | J34: 1327 | K34: 244376 | L34: 1327 | M34: =+J34-L34 -> 0
A35: 33 | B35: 244377 | C35: suckjakkure@hotmail.com | D35: 642427575 | E35: 4311469006 | F35: ธนาคารไทยพาณิชย์ (SCB) | G35: 7 | H35: 1718 | I35: 0 | J35: 1718 | K35: 244377 | L35: 1718 | M35: =+J35-L35 -> 0
A36: 34 | B36: 244378 | C36: suckjakkure@hotmail.com | D36: 642427575 | E36: 4311469006 | F36: ธนาคารไทยพาณิชย์ (SCB) | G36: 8 | H36: 2259 | I36: 0 | J36: 2259 | K36: 244378 | L36: 2259 | M36: =+J36-L36 -> 0
A37: 35 | B37: 244379 | C37: suckjakkure@hotmail.com | D37: 642427575 | E37: 4311469006 | F37: ธนาคารไทยพาณิชย์ (SCB) | G37: 8 | H37: 2439 | I37: 0 | J37: 2439 | K37: 244379 | L37: 2439 | M37: =+J37-L37 -> 0
A38: 36 | B38: 244380 | C38: suckjakkure@hotmail.com | D38: 642427575 | E38: 4311469006 | F38: ธนาคารไทยพาณิชย์ (SCB) | G38: 14 | H38: 3829 | I38: 0 | J38: 3829 | K38: 244380 | L38: 3829 | M38: =+J38-L38 -> 0
F39: ยอดรวม | G39: =SUM(G3:G38) -> 196 | H39: =SUM(H3:H38) -> 61722 | I39: =SUM(I3:I38) -> 0 | J39: =SUM(J3:J38) -> 61722 | K39: บาท | L39: =SUM(L3:L38) -> 61722 | M39: บาท

Sheet ก.พ.
A1: ข้อมูลการเก็บเงินปลายทาง (COD) แบบแยกรายละเอียด เดือนกุมภาพันธ์ 2569
A2: ลำดับ | B2: วันที่ | C2: Email | D2: Facebook Page | E2: Order No. / เลขที่ออเดอร์ | F2: Tracking No. / เลขพัสดุ | G2: recipientName / ชื่อลูกค้า | H2: Amount / ยอด COD
A3: 1 | B3: 244351 | C3: suckjakkure@hotmail.com | D3: FACEBOOK | F3: WA084387286TH | G3: สมัย จันทะบัณฑิต | H3: 299
A4: 2 | B4: 244351 | C4: suckjakkure@hotmail.com | D4: FACEBOOK | F4: WA085178973TH | G4: ไอรีน ตะเภาพงศ์ | H4: 299
A5: 3 | B5: 244351 | C5: suckjakkure@hotmail.com | D5: FACEBOOK | F5: WA085178995TH | G5: กันยารัตน์ จิตรานุเคราะห์ | H5: 215
A6: 4 | B6: 244351 | C6: suckjakkure@hotmail.com | D6: FACEBOOK | F6: WA084788576TH | G6: ไอรีน ตะเภาพงศ์ | H6: 215
A7: 5 | B7: 244351 | C7: suckjakkure@hotmail.com | D7: FACEBOOK | F7: WA085178956TH | G7: เสรี-ช่วยชูกลิ่น | H7: 399
A8: 6 | B8: 244410 | C8: suckjakkure@hotmail.com | D8: FACEBOOK | F8: WA085529649TH | G8: วาริน. คชเผือก | H8: 215
A9: 7 | B9: 244410 | C9: suckjakkure@hotmail.com | D9: FACEBOOK | F9: WA084788580TH | G9: Kob Danna | H9: 299
A10: 8 | B10: 244441 | C10: suckjakkure@hotmail.com | D10: FACEBOOK | F10: WA086195859TH | G10: Sariyong Israsena Na Ayudhya | H10: 329
A11: 9 | B11: 244441 | C11: suckjakkure@hotmail.com | D11: FACEBOOK | F11: WA086251635TH | G11: เนาวรัตน่ จันทร่สมปอง | H11: 215
A12: 10 | B12: 244441 | C12: suckjakkure@hotmail.com | D12: FACEBOOK | F12: WA086195893TH | G12: นพมาศ หงษาชาติ | H12: 299
A13: 11 | B13: 244441 | C13: suckjakkure@hotmail.com | D13: FACEBOOK | F13: WA085903984TH | G13: ร้านซ่อมมอไซด์ช่างหวอทางไปวังน้ำดำ | H13: 215
A14: 12 | B14: 244441 | C14: suckjakkure@hotmail.com | D14: FACEBOOK | F14: WA085529652TH | G14: บุณยนุช เข็มปัญญา | H14: 399
... A75: 73 | B75: 244685 | C75: suckjakkure@hotmail.com | D75: FACEBOOK | F75: WA089717727TH | G75: พ.ต.ท.อดุลย์ คลังนาค | H75: 215
A76: 74 | B76: 13/2/2569 | C76: suckjakkure@hotmail.com | D76: FACEBOOK | F76: WA091075624TH | G76: รานี วิโรจน์ธรรม | H76: 215
A77: 75 | B77: 13/2/2569 | C77: suckjakkure@hotmail.com | D77: FACEBOOK | F77: WA090686284TH | G77: วราภรณ์ วิรัตกพันธ์ | H77: 215
A78: 76 | B78: 13/2/2569 | C78: suckjakkure@hotmail.com | D78: FACEBOOK | F78: WA090686050TH | G78: มัตติกา สุขแสน | H78: 159
A79: 77 | B79: 13/2/2569 | C79: suckjakkure@hotmail.com | D79: FACEBOOK | F79: WA091075730TH | G79: ฐิติวุฒิ งามจิตจรุง | H79: 215
A80: 78 | B80: 13/2/2569 | C80: suckjakkure@hotmail.com | D80: FACEBOOK | F80: WA091075669TH | G80: สมจิตต์ | H80: 215
A81: 79 | B81: 13/2/2569 | C81: suckjakkure@hotmail.com | D81: FACEBOOK | F81: WA091094115TH | G81: จันทิมา ธาราวัชรศาสตร์ | H81: 215
A82: 80 | B82: 13/2/2569 | C82: suckjakkure@hotmail.com | D82: FACEBOOK | F82: WA091094124TH | G82: คุณ นวลปรางค์ อัมพวัน | H82: 215
A83: 81 | B83: 13/2/2569 | C83: suckjakkure@hotmail.com | D83: FACEBOOK | F83: WA090256951TH | G83: ธัชนันท์ เพ็ชรเอี่ยม | H83: 215
A84: 82 | B84: 13/2/2569 | C84: suckjakkure@hotmail.com | D84: FACEBOOK | F84: WA090686094TH | G84: มณี เจ้าประเสริฐ | H84: 486
A85: 83 | B85: 13/2/2569 | C85: suckjakkure@hotmail.com | D85: FACEBOOK | F85: WA091075765TH | G85: นาย พลศักดิ์. เผ่ากันทรากร | H85: 1075
A86: 84 | B86: 13/2/2569 | C86: suckjakkure@hotmail.com | D86: FACEBOOK | F86: WA091075774TH | G86: เยี่ยมศรี_กฤตสิน | H86: 430
A87: 85 | B87: 13/2/2569 | C87: suckjakkure@hotmail.com | D87: FACEBOOK | F87: WA090256917TH | G87: ณัฐชรีพร ศรีสวัสดิ์ | H87: 215
... A151: 149 | B151: 16/2/2569 | C151: suckjakkure@hotmail.com | D151: FACEBOOK | F151: WA091967255TH | G151: ร้านอาหารแจ่มแมว | H151: 215
A152: 150 | B152: 17/2/2569 | C152: suckjakkure@hotmail.com | D152: FACEBOOK | E152: KTINTER699004d78479f711e80f1f87 | F152: TH01058CD9V45B1 | G152: Narapat Datong | H152: 215
A153: 151 | B153: 17/2/2569 | C153: suckjakkure@hotmail.com | D153: FACEBOOK | E153: KTINTER699005238479f711e80f364a | F153: TH01208CD9V22A1 | G153: Chantra Kongthongluk | H153: 215
A154: 152 | B154: 17/2/2569 | C154: suckjakkure@hotmail.com | D154: FACEBOOK | E154: KTINTER699004823310743f2efba09a | F154: TH01258CD9V82D | G154: อฑิยา จิรานิรัชพรกุล | H154: 430
A155: 153 | B155: 17/2/2569 | C155: suckjakkure@hotmail.com | D155: FACEBOOK | E155: KTINTER6990050e3310743f2efbdb31 | F155: TH01518CD9V28B | G155: ศิวพลอย กุลจรัสพิมาน | H155: 430
A156: 154 | B156: 17/2/2569 | C156: suckjakkure@hotmail.com | D156: FACEBOOK | E156: KTINTER6990055cf944a8f16e2f166b | F156: TH18048CD9UX2A1 | G156: อมรรัตน์ กองแก้ว | H156: 215
A157: 155 | B157: 17/2/2569 | C157: suckjakkure@hotmail.com | D157: FACEBOOK | E157: KTINTER699004e9f944a8f16e2edf2e | F157: TH20088CD9V38B | G157: ดวงตะวัน | H157: 215
A158: 156 | B158: 17/2/2569 | C158: suckjakkure@hotmail.com | D158: FACEBOOK | E158: KTINTER699004f8f944a8f16e2ee426 | F158: TH61018CD9V33A0 | G158: คุณ วณิชยา อำไพ | H158: 215
A159: 157 | B159: 18/2/2569 | C159: suckjakkure@hotmail.com | D159: FACEBOOK | E159: KTINTER699004957d7529a7dde47385 | F159: TH10038CD9V79E | G159: นฤพันธ์ อุไรลักษมี | H159: 215
A160: 158 | B160: 18/2/2569 | C160: suckjakkure@hotmail.com | D160: FACEBOOK | E160: KTINTER69900530f944a8f16e2efc67 | F160: TH33078CD9V15B | G160: วงษ์เดือน ใสสว่าง | H160: 215
A161: 159 | B161: 18/2/2569 | C161: suckjakkure@hotmail.com | D161: FACEBOOK | E161: KTINTER699004a67d7529a7dde47888 | F161: TH47148CD9V71J | G161: กัญญาพัชร. นิลาด | H161: 215
A162: 160 | B162: 18/2/2569 | C162: suckjakkure@hotmail.com | D162: FACEBOOK | E162: KTINTER699005448479f711e80f44d5 | F162: TH47158CD9UZ8G | G162: Moddang Munesane | H162: 486
A163: 161 | B163: 18/2/2569 | C163: suckjakkure@hotmail.com | D163: FACEBOOK | E163: KTINTER699004cc8479f711e80f1be2 | F163: TH57078CD9V52A | G163: ปุณณภา เบญจมาศ | H163: 215
...

Sheet Summary ก.พ.
A1: ข้อมูลการเก็บเงินปลายทาง (COD) แบบรวมยอดประจำวัน เดือนกุมภาพันธ์ 2569 | K1: ตรวจในสเตทเม้น
A2: ลำดับ | B2: วันที่ | C2: Email | D2: Tel | E2: Bank Account Number / เลขที่บัญชี | F2: Bank Account Name / ชื่อธนาคาร | G2: Total Order / จำนวนออเดอร์ | H2: COD Amount / ยอดรวม COD | I2: Deduct | J2: Total Amount / ยอดรวม COD | K2: วันที่เงินเข้า | L2: ยอดเข้า | M2: หมายเหตุ
A3: 1 | B3: 244350 | C3: suckjakkure@hotmail.com | D3: 642427575 | E3: 4311469006 | F3: ธนาคารไทยพาณิชย์ (SCB) | G3: 5 | H3: 1427 | I3: 0 | J3: 1427 | K3: 244350 | L3: 1427 | M3: =+J3-L3 -> 0
A4: 3 | B4: 244351 | C4: ไม่มียอดเก็บ COD | K4: 244351 | M4: =+J4-L4 -> 0
A5: 4 | B5: 244352 | C5: suckjakkure@hotmail.com | D5: 642427575 | E5: 4311469006 | F5: ธนาคารไทยพาณิชย์ (SCB) | G5: 2 | H5: 514 | I5: 0 | J5: 514 | K5: 244352 | L5: 514 | M5: =+J5-L5 -> 0
A6: 6 | B6: 244353 | C6: suckjakkure@hotmail.com | D6: 642427575 | E6: 4311469006 | F6: ธนาคารไทยพาณิชย์ (SCB) | G6: 6 | H6: 1943 | I6: 0 | J6: 1943 | K6: 244353 | L6: 1943 | M6: =+J6-L6 -> 0
A7: 7 | B7: 244354 | C7: suckjakkure@hotmail.com | D7: 642427575 | E7: 4311469006 | F7: ธนาคารไทยพาณิชย์ (SCB) | G7: 4 | H7: 1039 | I7: 0 | J7: 1039 | K7: 244354 | L7: 1039 | M7: =+J7-L7 -> 0
A8: 8 | B8: 244355 | C8: suckjakkure@hotmail.com | D8: 642427575 | E8: 4311469006 | F8: ธนาคารไทยพาณิชย์ (SCB) | G8: 14 | H8: 5501 | I8: 0 | J8: 5501 | K8: 244355 | L8: 5501 | M8: =+J8-L8 -> 0
A9: 9 | B9: 244356 | C9: suckjakkure@hotmail.com | D9: 642427575 | E9: 4311469006 | F9: ธนาคารไทยพาณิชย์ (SCB) | G9: 11 | H9: 4546 | I9: 0 | J9: 4546 | K9: 244356 | L9: 4546 | M9: =+J9-L9 -> 0
A10: 10 | B10: 244357 | C10: suckjakkure@hotmail.com | D10: 642427575 | E10: 4311469006 | F10: ธนาคารไทยพาณิชย์ (SCB) | G10: 6 | H10: 1887 | I10: 0 | J10: 1887 | K10: 244357 | L10: 1887 | M10: =+J10-L10 -> 0
A11: 11 | B11: 244358 | C11: suckjakkure@hotmail.com | D11: 642427575 | E11: 4311469006 | F11: ธนาคารไทยพาณิชย์ (SCB) | G11: 2 | H11: 645 | I11: 0 | J11: 645 | K11: 244358 | L11: 645 | M11: =+J11-L11 -> 0
A12: 12 | B12: 244359 | C12: suckjakkure@hotmail.com | D12: 642427575 | E12: 4311469006 | F12: ธนาคารไทยพาณิชย์ (SCB) | G12: 9 | H12: 3125 | I12: 0 | J12: 3125 | K12: 244359 | L12: 3125 | M12: =+J12-L12 -> 0
A13: 13 | B13: 244360 | C13: suckjakkure@hotmail.com | D13: 642427575 | E13: 4311469006 | F13: ธนาคารไทยพาณิชย์ (SCB) | G13: 2 | H13: 754 | I13: 0 | J13: 754 | K13: 244360 | L13: 754 | M13: =+J13-L13 -> 0
A14: 14 | B14: 244361 | C14: suckjakkure@hotmail.com | D14: 642427575 | E14: 4311469006 | F14: ธนาคารไทยพาณิชย์ (SCB) | G14: 12 | H14: 4982 | I14: 0 | J14: 4982 | K14: 244361 | L14: 4982 | M14: =+J14-L14 -> 0
A15: 15 | B15: 244362 | C15: suckjakkure@hotmail.com | D15: 642427575 | E15: 4311469006 | F15: ธนาคารไทยพาณิชย์ (SCB) | G15: 17 | H15: 5709 | I15: 0 | J15: 5709 | K15: 244362 | L15: 5709 | M15: =+J15-L15 -> 0
A16: 16 | B16: 244363 | C16: suckjakkure@hotmail.com | D16: 642427575 | E16: 4311469006 | F16: ธนาคารไทยพาณิชย์ (SCB) | G16: 32 | H16: 10059 | I16: 0 | J16: 10059 | K16: 244363 | L16: 10059 | M16: =+J16-L16 -> 0
... A30: 30 | B30: 244405 | C30: suckjakkure@hotmail.com | D30: 642427575 | E30: 4311469006 | F30: ธนาคารไทยพาณิชย์ (SCB) | G30: 5 | H30: 1075 | I30: 0 | J30: 1075 | K30: 244405 | L30: 1075 | M30: =+J30-L30 -> 0
A31: 31 | B31: 26/2/2569 | C31: suckjakkure@hotmail.com | D31: 642427575 | E31: 4311469006 | F31: ธนาคารไทยพาณิชย์ (SCB) | G31: 15 | H31: 2992 | I31: 0 | J31: 2992 | K31: 26/2/2569 | L31: 2992 | M31: =+J31-L31 -> 0
A32: 32 | B32: 27/2/2569 | C32: suckjakkure@hotmail.com | D32: 642427575 | E32: 4311469006 | F32: ธนาคารไทยพาณิชย์ (SCB) | G32: 7 | H32: 1437 | I32: 0 | J32: 1437 | K32: 27/2/2569 | L32: 1437 | M32: =+J32-L32 -> 0
A33: 33 | B33: 28/2/2569 | C33: suckjakkure@hotmail.com | D33: 642427575 | E33: 4311469006 | F33: ธนาคารไทยพาณิชย์ (SCB) | G33: 11 | H33: 2475 | I33: 0 | J33: 2475 | K33: 28/2/2569 | L33: 2475 | M33: =+J33-L33 -> 0
F34: ยอดรวม | G34: =SUM(G3:G33) -> 322 | H34: =SUM(H3:H33) -> 96400 | I34: =SUM(I3:I33) -> 0 | J34: =SUM(J3:J33) -> 96400 | K34: บาท | L34: =SUM(L3:L33) -> 96400 | M34: บาท

Sheet มี.ค.
A1: ข้อมูลการเก็บเงินปลายทาง (COD) แบบแยกรายละเอียด เดือนมีนาคม 2569
A2: ลำดับ | B2: วันที่ | C2: Email | D2: Facebook Page | E2: Order No. / เลขที่ออเดอร์ | F2: Tracking No. / เลขพัสดุ | G2: recipientName / ชื่อลูกค้า | H2: Amount / ยอด COD
A3: 1 | B3: 244352 | C3: suckjakkure@hotmail.com | D3: FACEBOOK | F3: WA095045375TH | G3: ชนกันต์ เพ็งพืช | H3: 215
A4: 2 | B4: 244352 | C4: suckjakkure@hotmail.com | D4: FACEBOOK | F4: WA096084013TH | G4: จารุณี สมน้อย | H4: 198
A5: 3 | B5: 244352 | C5: suckjakkure@hotmail.com | D5: FACEBOOK | F5: WA096083993TH | G5: ปัญญา กฤตหัสต์ | H5: 99
A6: 4 | B6: 244383 | C6: suckjakkure@hotmail.com | D6: FACEBOOK | F6: WA095601135TH | G6: นาย เชาวน์ ลิขนะจุล | H6: 99
A7: 5 | B7: 244411 | C7: suckjakkure@hotmail.com | D7: FACEBOOK | F7: WA096397816TH | G7: รุ่งทิวา ถาวร | H7: 215
A8: 6 | B8: 244411 | C8: suckjakkure@hotmail.com | D8: FACEBOOK | F8: WA096397745TH | G8: สุพรรษา ปิยะวงษ์ | H8: 215
A9: 7 | B9: 244411 | C9: suckjakkure@hotmail.com | D9: FACEBOOK | F9: WA096397731TH | G9: จิตติมา กุลกั้ง | H9: 198
A10: 8 | B10: 244411 | C10: suckjakkure@hotmail.com | D10: FACEBOOK | F10: WA096677895TH | G10: ศิราภรณ์ผิวงาม | H10: 215
A11: 9 | B11: 244411 | C11: suckjakkure@hotmail.com | D11: FACEBOOK | F11: WA096397780TH | G11: แพรวพรรณ มณีโชติ | H11: 99
A12: 10 | B12: 244411 | C12: suckjakkure@hotmail.com | D12: FACEBOOK | F12: WA095601144TH | G12: เสมอเทพ เสมอตน | H12: 215
A13: 11 | B13: 244442 | C13: suckjakkure@hotmail.com | D13: FACEBOOK | F13: WA096938984TH | G13: สว.ตู่ พื้นผา | H13: 430
A14: 12 | B14: 244442 | C14: suckjakkure@hotmail.com | D14: FACEBOOK | F14: WA096397762TH | G14: ศศิกานต์ พรหมมี | H14: 215
... A106: 104 | B106: 244686 | C106: suckjakkure@hotmail.com | D106: FACEBOOK | F106: WA105998175TH | G106: ปัทมนันท์ แก้วทะโร | H106: 215
A107: 105 | B107: 13/3/2569 | C107: suckjakkure@hotmail.com | D107: FACEBOOK | F107: WA106339015TH | G107: เฉลิมพล. ประเสริฐพรรณ | H107: 215
A108: 106 | B108: 13/3/2569 | C108: suckjakkure@hotmail.com | D108: FACEBOOK | F108: WA106639531TH | G108: Sorapat Chillananda | H108: 215
A109: 107 | B109: 13/3/2569 | C109: suckjakkure@hotmail.com | D109: FACEBOOK | F109: WA106638845TH | G109: อัญชุลี มัคคีธรรม | H109: 499
A110: 108 | B110: 13/3/2569 | C110: suckjakkure@hotmail.com | D110: FACEBOOK | F110: WA106638814TH | G110: รัตติกาลแก้วดวงเล็ก | H110: 399
A111: 109 | B111: 13/3/2569 | C111: suckjakkure@hotmail.com | D111: FACEBOOK | F111: WA106338908TH | G111: สมพิศ จันบุญแย้ม | H111: 215
A112: 110 | B112: 13/3/2569 | C112: suckjakkure@hotmail.com | D112: FACEBOOK | F112: WA106338939TH | G112: Aum Parinda (ณัฎฐ์นรี) | H112: 215
A113: 111 | B113: 13/3/2569 | C113: suckjakkure@hotmail.com | D113: FACEBOOK | F113: WA106342054TH | G113: วรรณภา สุครีพ | H113: 215
A114: 112 | B114: 13/3/2569 | C114: suckjakkure@hotmail.com | D114: FACEBOOK | F114: WA106338960TH | G114: นาย ประเวศ มหามิตร | H114: 215
A115: 113 | B115: 13/3/2569 | C115: suckjakkure@hotmail.com | D115: FACEBOOK | F115: WA105791555TH | G115: ศิริดารา บรรพตธรรม | H115: 215
A116: 114 | B116: 13/3/2569 | C116: suckjakkure@hotmail.com | D116: FACEBOOK | F116: WA105998161TH | G116: แสงเดือน กมลหาญ | H116: 215
A117: 115 | B117: 13/3/2569 | C117: suckjakkure@hotmail.com | D117: FACEBOOK | F117: WA105791516TH | G117: พระอุบล วราสโภ | H117: 215
A118: 116 | B118: 13/3/2569 | C118: suckjakkure@hotmail.com | D118: FACEBOOK | F118: WA105791564TH | G118: ผ่องพรรณ สร้อยมุข | H118: 215
... A311: 309 | B311: 31/3/2569 | C311: suckjakkure@hotmail.com | D311: FACEBOOK | F311: WA111511405TH | G311: ประทุม อาทยะกุล | H311: 215
A312: 310
A313: 311
A314: 312
A315: 313
A316: 314
A317: 315
A318: 316
A319: 317
A320: 318
A321: 319
A322: 320
A323: 321
...

Sheet Summary มี.ค.
A1: ข้อมูลการเก็บเงินปลายทาง (COD) แบบรวมยอดประจำวัน เดือนมีนาคม2569 | K1: ตรวจในสเตทเม้น
A2: ลำดับ | B2: วันที่ | C2: Email | D2: Tel | E2: Bank Account Number / เลขที่บัญชี | F2: Bank Account Name / ชื่อธนาคาร | G2: Total Order / จำนวนออเดอร์ | H2: COD Amount / ยอดรวม COD | I2: Deduct | J2: Total Amount / ยอดรวม COD | K2: วันที่เงินเข้า | L2: ยอดเข้า | M2: หมายเหตุ
A3: 1 | B3: 244350 | C3: suckjakkure@hotmail.com | D3: 642427575 | E3: 4311469006 | F3: ธนาคารไทยพาณิชย์ (SCB) | G3: 3 | H3: 512 | I3: 0 | J3: 512 | K3: 244350 | L3: 512 | M3: =+J3-L3 -> 0
A4: 2 | B4: 244350 | K4: 244350 | M4: =+J4-L4 -> 0
A5: 3 | B5: 244351 | C5: suckjakkure@hotmail.com | D5: 642427575 | E5: 4311469006 | F5: ธนาคารไทยพาณิชย์ (SCB) | G5: 1 | H5: 99 | I5: 0 | J5: 99 | K5: 244351 | L5: 99 | M5: =+J5-L5 -> 0
A6: 4 | B6: 244352 | C6: suckjakkure@hotmail.com | D6: 642427575 | E6: 4311469006 | F6: ธนาคารไทยพาณิชย์ (SCB) | G6: 6 | H6: 1157 | I6: 0 | J6: 1157 | K6: 244352 | L6: 1157 | M6: =+J6-L6 -> 0
A7: 5 | B7: 244352 | K7: 244352 | M7: =+J7-L7 -> 0
A8: 6 | B8: 244353 | C8: suckjakkure@hotmail.com | D8: 642427575 | E8: 4311469006 | F8: ธนาคารไทยพาณิชย์ (SCB) | G8: 17 | H8: 3984 | I8: 0 | J8: 3984 | K8: 244353 | L8: 3984 | M8: =+J8-L8 -> 0
A9: 7 | B9: 244354 | C9: suckjakkure@hotmail.com | D9: 642427575 | E9: 4311469006 | F9: ธนาคารไทยพาณิชย์ (SCB) | G9: 21 | H9: 5428 | I9: 0 | J9: 5428 | K9: 244354 | L9: 5428 | M9: =+J9-L9 -> 0
A10: 8 | B10: 244354 | K10: 244354 | M10: =+J10-L10 -> 0
A11: 9 | B11: 244355 | C11: suckjakkure@hotmail.com | D11: 642427575 | E11: 4311469006 | F11: ธนาคารไทยพาณิชย์ (SCB) | G11: 13 | H11: 3436 | I11: 0 | J11: 3436 | K11: 244355 | L11: 3436 | M11: =+J11-L11 -> 0
A12: 10 | B12: 244355 | K12: 244355 | M12: =+J12-L12 -> 0
A13: 11 | B13: 244356 | C13: suckjakkure@hotmail.com | D13: 642427575 | E13: 4311469006 | F13: ธนาคารไทยพาณิชย์ (SCB) | G13: 3 | H13: 645 | I13: 0 | J13: 645 | K13: 244356 | L13: 645 | M13: =+J13-L13 -> 0
A14: 12 | B14: 244357 | C14: suckjakkure@hotmail.com | D14: 642427575 | E14: 4311469006 | F14: ธนาคารไทยพาณิชย์ (SCB) | G14: 3 | H14: 645 | I14: 0 | J14: 645 | K14: 244357 | L14: 645 | M14: =+J14-L14 -> 0
A15: 13 | B15: 244357 | K15: 244357 | M15: =+J15-L15 -> 0
A16: 14 | B16: 244358 | C16: suckjakkure@hotmail.com | D16: 642427575 | E16: 4311469006 | F16: ธนาคารไทยพาณิชย์ (SCB) | G16: 5 | H16: 1184 | I16: 0 | J16: 1184 | K16: 244358 | L16: 1184 | M16: =+J16-L16 -> 0
A17: 15 | B17: 244359 | C17: suckjakkure@hotmail.com | D17: 642427575 | E17: 4311469006 | F17: ธนาคารไทยพาณิชย์ (SCB) | G17: 2 | H17: 645 | I17: 0 | J17: 645 | K17: 244359 | L17: 645 | M17: =+J17-L17 -> 0
A18: 16 | B18: 244360 | C18: suckjakkure@hotmail.com | D18: 642427575 | E18: 4311469006 | F18: ธนาคารไทยพาณิชย์ (SCB) | G18: 16 | H18: 3554 | I18: 0 | J18: 3554 | K18: 244360 | L18: 3554 | M18: =+J18-L18 -> 0
A19: 17 | B19: 244361 | C19: suckjakkure@hotmail.com | D19: 642427575 | E19: 4311469006 | F19: ธนาคารไทยพาณิชย์ (SCB) | G19: 14 | H19: 3444 | I19: 0 | J19: 3444 | K19: 244361 | L19: 3444 | M19: =+J19-L19 -> 0
A20: 18 | B20: 244362 | C20: suckjakkure@hotmail.com | D20: 642427575 | E20: 4311469006 | F20: ธนาคารไทยพาณิชย์ (SCB) | G20: 16 | H20: 3908 | I20: 0 | J20: 3908 | K20: 244362 | L20: 3908 | M20: =+J20-L20 -> 0
A21: 19 | B21: 244363 | C21: suckjakkure@hotmail.com | D21: 642427575 | E21: 4311469006 | F21: ธนาคารไทยพาณิชย์ (SCB) | G21: 9 | H21: 1935 | I21: 0 | J21: 1935 | K21: 244363 | L21: 1935 | M21: =+J21-L21 -> 0
A22: 20 | B22: 244364 | C22: suckjakkure@hotmail.com | D22: 642427575 | E22: 4311469006 | F22: ธนาคารไทยพาณิชย์ (SCB) | G22: 4 | H22: 1075 | I22: 0 | J22: 1075 | K22: 244364 | L22: 1075 | M22: =+J22-L22 -> 0
A23: 21 | B23: 244365 | C23: suckjakkure@hotmail.com | D23: 642427575 | E23: 4311469006 | F23: ธนาคารไทยพาณิชย์ (SCB) | G23: 3 | H23: 680 | I23: 0 | J23: 680 | K23: 244365 | L23: 680 | M23: =+J23-L23 -> 0
A24: 22 | B24: 244366 | C24: suckjakkure@hotmail.com | D24: 642427575 | E24: 4311469006 | F24: ธนาคารไทยพาณิชย์ (SCB) | G24: 7 | H24: 1482 | I24: 0 | J24: 1482 | K24: 244366 | L24: 1482 | M24: =+J24-L24 -> 0
A25: 23 | B25: 244367 | C25: suckjakkure@hotmail.com | D25: 642427575 | E25: 4311469006 | F25: ธนาคารไทยพาณิชย์ (SCB) | G25: 21 | H25: 5398 | I25: 0 | J25: 5398 | K25: 244367 | L25: 5398 | M25: =+J25-L25 -> 0
A26: 24 | B26: 244368 | C26: suckjakkure@hotmail.com | D26: 642427575 | E26: 4311469006 | F26: ธนาคารไทยพาณิชย์ (SCB) | G26: 24 | H26: 4799 | I26: 0 | J26: 4799 | K26: 244368 | L26: 4799 | M26: =+J26-L26 -> 0
A27: 25 | B27: 244369 | C27: suckjakkure@hotmail.com | D27: 642427575 | E27: 4311469006 | F27: ธนาคารไทยพาณิชย์ (SCB) | G27: 14 | H27: 2347 | I27: 0 | J27: 2347 | K27: 244369 | L27: 2347 | M27: =+J27-L27 -> 0
... A38: 36 | B38: 244380 | C38: suckjakkure@hotmail.com | D38: 642427575 | E38: 4311469006 | F38: ธนาคารไทยพาณิชย์ (SCB) | G38: 7 | H38: 1375 | I38: 0 | J38: 1375 | K38: 244380 | L38: 1375 | M38: =+J38-L38 -> 0
F39: ยอดรวม | G39: =SUM(G3:G38) -> 309 | H39: =SUM(H3:H38) -> 68833 | I39: =SUM(I3:I38) -> 0 | J39: =SUM(J3:J38) -> 68833 | K39: บาท | L39: =SUM(L3:L38) -> 68833 | M39: บาท

Sheet เม.ย.
A1: ข้อมูลการเก็บเงินปลายทาง (COD) แบบแยกรายละเอียด เดือนเมษายน 2569
A2: ลำดับ | B2: วันที่ | C2: Email | D2: Facebook Page | E2: Order No. / เลขที่ออเดอร์ | F2: Tracking No. / เลขพัสดุ | G2: recipientName / ชื่อลูกค้า | H2: Amount / ยอด COD
A3: 1 | B3: 244353 | C3: suckjakkure@hotmail.com | D3: FACEBOOK | F3: WA111795313TH | G3: สุจิตรา ไชยโชติ | H3: 199
A4: 2 | B4: 244353 | C4: suckjakkure@hotmail.com | D4: FACEBOOK | F4: WA111795256TH | G4: วรรณเพ็ญ แซ่โอ้ว | H4: 199
A5: 3 | B5: 244353 | C5: suckjakkure@hotmail.com | D5: FACEBOOK | F5: WA111795239TH | G5: คุณ อัมพาพันธ์ ปิ่นเสถียรเกส | H5: 199
A6: 4 | B6: 244353 | C6: suckjakkure@hotmail.com | D6: FACEBOOK | F6: WA111795273TH | G6: อนันต์ วงษ์คำ | H6: 398
A7: 5 | B7: 244353 | C7: suckjakkure@hotmail.com | D7: FACEBOOK | F7: WA111795123TH | G7: นวพรรณ โพธิวัฒน์โสภา | H7: 215
A8: 6 | B8: 244353 | C8: suckjakkure@hotmail.com | D8: FACEBOOK | F8: WA111795097TH | G8: วิภารัตน์ ชัยเกษตรทรัพย์ | H8: 100
A9: 7 | B9: 244353 | C9: suckjakkure@hotmail.com | D9: FACEBOOK | F9: WA111795260TH | G9: ชุลีพร หอมหวาน | H9: 199
A10: 8 | B10: 244353 | C10: suckjakkure@hotmail.com | D10: FACEBOOK | F10: WA111795106TH | G10: เยาวนารถบุญเพ็ง | H10: 200
A11: 9 | B11: 244353 | C11: suckjakkure@hotmail.com | D11: FACEBOOK | F11: WA111795335TH | G11: แพรวาเผือกไพบูลย์ | H11: 199
A12: 10 | B12: 244353 | C12: suckjakkure@hotmail.com | D12: FACEBOOK | F12: WA111795287TH | G12: กันญา จันทนโชติวงศ์ | H12: 199
A13: 11 | B13: 244353 | C13: suckjakkure@hotmail.com | D13: FACEBOOK | F13: WA111795375TH | G13: สุวิมล เจริญสุข | H13: 199
A14: 12 | B14: 244353 | C14: suckjakkure@hotmail.com | D14: FACEBOOK | F14: WA111976196TH | G14: อัมราห้วยทราย | H14: 199
... A292: 290 | B292: 244687 | C292: suckjakkure@hotmail.com | D292: FACEBOOK | F292: WA120287380TH | G292: Nattawut Yangyuen | H292: 270
A293: 291 | B293: 13/4/2569 | C293: suckjakkure@hotmail.com | D293: FACEBOOK | F293: WA119989902TH | G293: วาสนา พะกะยะ | H293: 270
A294: 292 | B294: 13/4/2569 | C294: suckjakkure@hotmail.com | D294: FACEBOOK | F294: WA120287359TH | G294: สมชาย ฤกษ์เสือ | H294: 270
A295: 293 | B295: 14/4/2569 | C295: suckjakkure@hotmail.com | D295: FACEBOOK | F295: TH01218KGDVQ5B0 | G295: ศิวชัย | H295: 330
A296: 294 | B296: 14/4/2569 | C296: suckjakkure@hotmail.com | D296: FACEBOOK | F296: TH01388KGDVK5A | G296: ปรานี | H296: 330
A297: 295 | B297: 14/4/2569 | C297: suckjakkure@hotmail.com | D297: FACEBOOK | F297: TH01478KGDVJ9C0 | G297: ศิริจันทร์ กลิ่นรัตน์ | H297: 270
A298: 296 | B298: 14/4/2569 | C298: suckjakkure@hotmail.com | D298: FACEBOOK | F298: TH01518KGDVW7A | G298: รุ่งฤดี จีนสุข | H298: 330
A299: 297 | B299: 14/4/2569 | C299: suckjakkure@hotmail.com | D299: FACEBOOK | F299: TH03038KGDVJ7C | G299: วาสนา โพธิ์ศรี | H299: 270
A300: 298 | B300: 14/4/2569 | C300: suckjakkure@hotmail.com | D300: FACEBOOK | F300: TH03068KGDVW5D0 | G300: นาง สมหมาย โพธิมาก | H300: 270
A301: 299 | B301: 14/4/2569 | C301: suckjakkure@hotmail.com | D301: FACEBOOK | F301: TH04048KGDVH9A | G301: พรทิพย์ | H301: 300
A302: 300 | B302: 14/4/2569 | C302: suckjakkure@hotmail.com | D302: FACEBOOK | F302: TH05018KGDVM7Q | G302: เมทิกา | H302: 215
A303: 301 | B303: 14/4/2569 | C303: suckjakkure@hotmail.com | D303: FACEBOOK | F303: TH13028KGP5U2F | G303: สมศักดิ์...ทองสกุลพันธ์ | H303: 270
A304: 302 | B304: 14/4/2569 | C304: suckjakkure@hotmail.com | D304: FACEBOOK | F304: TH14018KGDVY1J | G304: วิภา | H304: 270
... A360: 358 | B360: 16/4/2569 | C360: suckjakkure@hotmail.com | D360: FACEBOOK | F360: WA119378358TH | G360: นุสรา ธรรมประดิษฐ์ | H360: 199
A361: 359 | B361: 17/4/2569 | C361: suckjakkure@hotmail.com | D361: FACEBOOK | E361: KTINTER69dc90149f256a4476095e4e | F361: TH05018KQE1W8E | G361: Soontaree Pongnusont | H361: 270
A362: 360 | B362: 17/4/2569 | C362: suckjakkure@hotmail.com | D362: FACEBOOK | E362: KTINTER69db0f9770405a4172d42a19 | F362: TH09058KM3QG7A | G362: ญาตินันท์ เวียงทองชุติไชย | H362: 270
A363: 361 | B363: 17/4/2569 | C363: suckjakkure@hotmail.com | D363: FACEBOOK | E363: KTINTER69dc34db9f256a4476df8982 | F363: TH15068KNPH90F | G363: K'วีณา ชนะกิจการโชค | H363: 1250
A364: 362 | B364: 17/4/2569 | C364: suckjakkure@hotmail.com | D364: FACEBOOK | E364: KTINTER69dc9157fdf8e209f55d0953 | F364: TH20018KQE1U6D | G364: ดร. ปัทมนันท์ หิรัญธีรวัฒน์ | H364: 220
A365: 363 | B365: 17/4/2569 | C365: suckjakkure@hotmail.com | D365: FACEBOOK | E365: KTINTER69dc8ff99f256a44760950fe | F365: TH27018KQE1X1M | G365: นัยรัตน์ ชวนะ | H365: 220
A366: 364 | B366: 17/4/2569 | C366: suckjakkure@hotmail.com | D366: FACEBOOK | E366: KTINTER69dc8f7f9f256a4476090ad7 | F366: TH27208KQE1Y7A | G366: ยุพิน หวานสูงเนิน | H366: 215
A367: 365 | B367: 17/4/2569 | C367: suckjakkure@hotmail.com | D367: FACEBOOK | E367: KTINTER69dc349c9f256a4476df6a42 | F367: TH38018KNPH92Q | G367: คุณ ทัศนีย์ | H367: 215
A368: 366 | B368: 17/4/2569 | C368: suckjakkure@hotmail.com | D368: FACEBOOK | E368: KTINTER69db0ee19890b0d429e3e3e2 | F368: TH64088KM3QH4J | G368: จารึก วงษ์ไว | H368: 300
A369: 367 | B369: 17/4/2569 | C369: suckjakkure@hotmail.com | D369: FACEBOOK | E369: KTINTER69dc35879f256a4476dfcfda | F369: TH70068KNPH78A | G369: ครูรัชนี นวลย่อง | H369: 270
A370: 368 | B370: 17/4/2569 | C370: suckjakkure@hotmail.com | D370: FACEBOOK | F370: WA119715435TH | G370: สายชล | H370: 270
A371: 369 | B371: 17/4/2569 | C371: suckjakkure@hotmail.com | D371: FACEBOOK | F371: WA119701144TH | G371: สายชล | H371: 440
A372: 370 | B372: 17/4/2569 | C372: suckjakkure@hotmail.com | D372: FACEBOOK | F372: WA120290741TH | G372: ร้านพรชัย การยาง | H372: 270
...

Sheet  Summary เม.ย.
A1: ข้อมูลการเก็บเงินปลายทาง (COD) แบบรวมยอดประจำวัน เดือนเมษายน 2569 | K1: ตรวจในสเตทเม้น
A2: ลำดับ | B2: วันที่ | C2: Email | D2: Tel | E2: Bank Account Number / เลขที่บัญชี | F2: Bank Account Name / ชื่อธนาคาร | G2: Total Order / จำนวนออเดอร์ | H2: COD Amount / ยอดรวม COD | I2: Deduct | J2: Total Amount / ยอดรวม COD | K2: วันที่เงินเข้า | L2: ยอดเข้า | M2: หมายเหตุ
A3: 1 | B3: 244440 | C3: suckjakkure@hotmail.com | D3: 642427575 | E3: 4311469006 | F3: ธนาคารไทยพาณิชย์ (SCB) | G3: 17 | H3: 3564 | I3: 0 | J3: 3564 | K3: 244440 | L3: 3564 | M3: =+J3-L3 -> 0
A4: 2 | B4: 244441 | C4: suckjakkure@hotmail.com | D4: 642427575 | E4: 4311469006 | F4: ธนาคารไทยพาณิชย์ (SCB) | G4: 40 | H4: 8678 | I4: 0 | J4: 8678 | K4: 244441 | L4: 8678 | M4: =+J4-L4 -> 0
A5: 3 | B5: 244442 | C5: suckjakkure@hotmail.com | D5: 642427575 | E5: 4311469006 | F5: ธนาคารไทยพาณิชย์ (SCB) | G5: 46 | H5: 9316 | I5: 0 | J5: 9316 | K5: 244442 | L5: 9316 | M5: =+J5-L5 -> 0
A6: 4 | B6: 244443 | C6: suckjakkure@hotmail.com | D6: 642427575 | E6: 4311469006 | F6: ธนาคารไทยพาณิชย์ (SCB) | G6: 26 | H6: 5418 | I6: 0 | J6: 5418 | K6: 244443 | L6: 5418 | M6: =+J6-L6 -> 0
A7: 5 | B7: 244444 | C7: suckjakkure@hotmail.com | D7: 642427575 | E7: 4311469006 | F7: ธนาคารไทยพาณิชย์ (SCB) | G7: 26 | H7: 4516 | I7: 0 | J7: 4516 | K7: 244444 | L7: 4516 | M7: =+J7-L7 -> 0
A8: 6 | B8: 244445 | C8: suckjakkure@hotmail.com | D8: 642427575 | E8: 4311469006 | F8: ธนาคารไทยพาณิชย์ (SCB) | G8: 4 | H8: 598 | I8: 0 | J8: 598 | K8: 244445 | L8: 598 | M8: =+J8-L8 -> 0
A9: 7 | B9: 244446 | C9: suckjakkure@hotmail.com | D9: 642427575 | E9: 4311469006 | F9: ธนาคารไทยพาณิชย์ (SCB) | G9: 28 | H9: 5352 | I9: 0 | J9: 5352 | K9: 244446 | L9: 5352 | M9: =+J9-L9 -> 0
A10: 8 | B10: 244447 | C10: suckjakkure@hotmail.com | D10: 642427575 | E10: 4311469006 | F10: ธนาคารไทยพาณิชย์ (SCB) | G10: 26 | H10: 5373 | I10: 0 | J10: 5373 | K10: 244447 | L10: 5373 | M10: =+J10-L10 -> 0
A11: 9 | B11: 244448 | C11: suckjakkure@hotmail.com | D11: 642427575 | E11: 4311469006 | F11: ธนาคารไทยพาณิชย์ (SCB) | G11: 25 | H11: 5109 | I11: 0 | J11: 5109 | K11: 244448 | L11: 5109 | M11: =+J11-L11 -> 0
A12: 10 | B12: 244449 | C12: suckjakkure@hotmail.com | D12: 642427575 | E12: 4311469006 | F12: ธนาคารไทยพาณิชย์ (SCB) | G12: 18 | H12: 5014 | I12: 0 | J12: 5014 | K12: 244449 | L12: 5014 | M12: =+J12-L12 -> 0
A13: 11 | B13: 244450 | C13: suckjakkure@hotmail.com | D13: 642427575 | E13: 4311469006 | F13: ธนาคารไทยพาณิชย์ (SCB) | G13: 21 | H13: 6281 | I13: 0 | J13: 6281 | K13: 244450 | L13: 6281 | M13: =+J13-L13 -> 0
A14: 12 | B14: 244451 | C14: suckjakkure@hotmail.com | D14: 642427575 | E14: 4311469006 | F14: ธนาคารไทยพาณิชย์ (SCB) | G14: 13 | H14: 3860 | I14: 0 | J14: 3860 | K14: 244451 | L14: 3860 | M14: =+J14-L14 -> 0
... A37: 35 | B37: 244469 | C37: suckjakkure@hotmail.com | D37: 642427575 | E37: 4311469006 | F37: ธนาคารไทยพาณิชย์ (SCB) | G37: 31 | H37: 7230 | I37: 0 | J37: 7230 | K37: 244469 | L37: 7230 | M37: =+J37-L37 -> 0
F38: ยอดรวม | G38: =SUM(G3:G37) -> 528 | H38: =SUM(H3:H37) -> 125946 | I38: =SUM(I3:I37) -> 0 | J38: =SUM(J3:J37) -> 125946 | K38: บาท | L38: =SUM(L3:L37) -> 125946 | M38: บาท

Sheet พ.ค.
A1: ข้อมูลการเก็บเงินปลายทาง (COD) แบบแยกรายละเอียด เดือนพฤษภาคม 2569
A2: ลำดับ | B2: วันที่ | C2: Email | D2: Facebook Page | E2: Order No. / เลขที่ออเดอร์ | F2: Tracking No. / เลขพัสดุ | G2: recipientName / ชื่อลูกค้า | H2: Amount / ยอด COD
A3: 1 | B3: 244354 | C3: suckjakkure@hotmail.com | D3: FACEBOOK | F3: WA124213467TH | G3: ข้าวแกง บ้านบ้านสุโขทัย | H3: 330
A4: 2 | B4: 244354 | C4: suckjakkure@hotmail.com | D4: FACEBOOK | F4: WA124478420TH | G4: ชื่อ พรรษกร ประดู่ทอง (ปุ๊) | H4: 100
A5: 3 | B5: 244354 | C5: suckjakkure@hotmail.com | D5: FACEBOOK | F5: WA124213436TH | G5: ขวัญทิพย์ ยาอยู่สุข | H5: 100
A6: 4 | B6: 244354 | C6: suckjakkure@hotmail.com | D6: FACEBOOK | F6: WA124213572TH | G6: ชาคริต | H6: 220
A7: 5 | B7: 244354 | C7: suckjakkure@hotmail.com | D7: FACEBOOK | F7: WA124213507TH | G7: จารุวรรณ | H7: 220
A8: 6 | B8: 244354 | C8: suckjakkure@hotmail.com | D8: FACEBOOK | F8: WA124213878TH | G8: พระวัชรินทร์ ศรีสัตบุตร | H8: 100
A9: 7 | B9: 244354 | C9: suckjakkure@hotmail.com | D9: FACEBOOK | F9: WA124478380TH | G9: อุทุมพร โกศล | H9: 220
A10: 8 | B10: 244354 | C10: suckjakkure@hotmail.com | D10: FACEBOOK | F10: WA124478331TH | G10: วนิดา รุจิรวณิช | H10: 220
A11: 9 | B11: 244354 | C11: suckjakkure@hotmail.com | D11: FACEBOOK | F11: WA123974161TH | G11: พิมพร บุษยพันธุ์ | H11: 100
A12: 10 | B12: 244354 | C12: suckjakkure@hotmail.com | D12: FACEBOOK | F12: WA124213586TH | G12: กิจจณัฐ ศักดาวัฒนานนท์ | H12: 215
A13: 11 | B13: 244354 | C13: suckjakkure@hotmail.com | D13: FACEBOOK | F13: WA124213657TH | G13: อ้อยใจ แสงชมภู | H13: 220
A14: 12 | B14: 244354 | C14: suckjakkure@hotmail.com | D14: FACEBOOK | F14: WA124213453TH | G14: คุณ สุขุมาภรณ์ กิตติวงศากูล | H14: 215
... A216: 214 | B216: 244688 | C216: suckjakkure@hotmail.com | D216: FACEBOOK | F216: WA127051953TH | G216: ละออทิพย์ วงศ์อนันต์ | H216: 100
A217: 215 | B217: 13/5/2569 | C217: suckjakkure@hotmail.com | D217: FACEBOOK | F217: WA127051984TH | G217: คุณ ณัฐชา คำบ่อ | H217: 220
A218: 216 | B218: 13/5/2569 | C218: suckjakkure@hotmail.com | D218: FACEBOOK | F218: WA127051967TH | G218: สุติการณ์ อินทรสุวรรณ | H218: 220
A219: 217 | B219: 13/5/2569 | C219: suckjakkure@hotmail.com | D219: FACEBOOK | F219: WA127052035TH | G219: นาย เศรษฐบุตร คงปะทิว | H219: 215
A220: 218 | B220: 13/5/2569 | C220: suckjakkure@hotmail.com | D220: FACEBOOK | F220: WA127068083TH | G220: ศิรแระภา สดแสงจันทร์ | H220: 100
A221: 219 | B221: 13/5/2569 | C221: suckjakkure@hotmail.com | D221: FACEBOOK | F221: WA126523682TH | G221: สมพงษ์ | H221: 220
A222: 220 | B222: 13/5/2569 | C222: suckjakkure@hotmail.com | D222: FACEBOOK | F222: WA137123685TH | G222: มีนา,ครุฑหอม | H222: 199
A223: 221 | B223: 13/5/2569 | C223: suckjakkure@hotmail.com | D223: FACEBOOK | F223: WA137123703TH | G223: คุณ ศรีสมร ศิริปัญจนะ | H223: 199
A224: 222 | B224: 13/5/2569 | C224: suckjakkure@hotmail.com | D224: FACEBOOK | F224: WA137123629TH | G224: คุณ สมบัติ ลอนหิน | H224: 199
A225: 223 | B225: 13/5/2569 | C225: suckjakkure@hotmail.com | D225: FACEBOOK | F225: WA137271004TH | G225: อาภรณ๋ ศรีศัมภุวงศ์ | H225: 260
A226: 224 | B226: 13/5/2569 | C226: suckjakkure@hotmail.com | D226: FACEBOOK | F226: WA137123589TH | G226: นางสาวปาลินี บุญส่ง | H226: 215
A227: 225 | B227: 13/5/2569 | C227: suckjakkure@hotmail.com | D227: FACEBOOK | F227: WA137123558TH | G227: ลักษมณ มั่นคง | H227: 220
A228: 226 | B228: 13/5/2569 | C228: suckjakkure@hotmail.com | D228: FACEBOOK | F228: WA137123527TH | G228: ชูเกียรติ รัตนเสรีเกียรติ | H228: 330
... A532: 530 | B532: 31/5/2569 | C532: suckjakkure@hotmail.com | D532: FACEBOOK | F532: WA142052939TH | G532: สมทรง อิทธิเมธีอมร | H532: 199
A533: 531
A534: 532
A535: 533
A536: 534
A537: 535
A538: 536
A539: 537
A540: 538
A541: 539
A542: 540
A543: 541
A544: 542
...

Sheet Summary พ.ค.
A1: ข้อมูลการเก็บเงินปลายทาง (COD) แบบรวมยอดประจำวัน เดือนพฤษภาคม2569 | K1: ตรวจในสเตทเม้น
A2: ลำดับ | B2: วันที่ | C2: Email | D2: Tel | E2: Bank Account Number / เลขที่บัญชี | F2: Bank Account Name / ชื่อธนาคาร | G2: Total Order / จำนวนออเดอร์ | H2: COD Amount / ยอดรวม COD | I2: Deduct | J2: Total Amount / ยอดรวม COD | K2: วันที่เงินเข้า | L2: ยอดเข้า | M2: หมายเหตุ
A3: 1 | B3: 244470 | C3: suckjakkure@hotmail.com | D3: 642427575 | E3: 4311469006 | F3: ธนาคารไทยพาณิชย์ (SCB) | G3: 32 | H3: 6210 | I3: 0 | J3: 6210 | K3: 244354 | L3: 6210 | M3: =+J3-L3 -> 0
A4: 2 | B4: 244471 | C4: suckjakkure@hotmail.com | D4: 642427575 | E4: 4311469006 | F4: ธนาคารไทยพาณิชย์ (SCB) | G4: 9 | H4: 2210 | I4: 0 | J4: 2210 | K4: 244385 | L4: 2210 | M4: =+J4-L4 -> 0
A5: 3 | B5: 244472 | C5: suckjakkure@hotmail.com | D5: 642427575 | E5: 4311469006 | F5: ธนาคารไทยพาณิชย์ (SCB) | G5: 14 | H5: 3210 | I5: 0 | J5: 3210 | K5: 244413 | L5: 3210 | M5: =+J5-L5 -> 0
A6: 4 | B6: 244473 | C6: suckjakkure@hotmail.com | D6: 642427575 | E6: 4311469006 | F6: ธนาคารไทยพาณิชย์ (SCB) | G6: 3 | H6: 585 | I6: 0 | J6: 585 | K6: 244444 | L6: 585 | M6: =+J6-L6 -> 0
A7: 5 | B7: 244474 | C7: suckjakkure@hotmail.com | D7: 642427575 | E7: 4311469006 | F7: ธนาคารไทยพาณิชย์ (SCB) | G7: 26 | H7: 6695 | I7: 0 | J7: 6695 | K7: 244474 | L7: 6695 | M7: =+J7-L7 -> 0
A8: 6 | B8: 244475 | C8: suckjakkure@hotmail.com | D8: 642427575 | E8: 4311469006 | F8: ธนาคารไทยพาณิชย์ (SCB) | G8: 14 | H8: 3400 | I8: 0 | J8: 3400 | K8: 244505 | L8: 3400 | M8: =+J8-L8 -> 0
A9: 7 | B9: 244476 | C9: suckjakkure@hotmail.com | D9: 642427575 | E9: 4311469006 | F9: ธนาคารไทยพาณิชย์ (SCB) | G9: 21 | H9: 4874 | I9: 0 | J9: 4874 | K9: 244535 | L9: 4874 | M9: =+J9-L9 -> 0
A10: 8 | B10: 244477 | C10: suckjakkure@hotmail.com | D10: 642427575 | E10: 4311469006 | F10: ธนาคารไทยพาณิชย์ (SCB) | G10: 18 | H10: 4765 | I10: 0 | J10: 4765 | K10: 244566 | L10: 4765 | M10: =+J10-L10 -> 0
A11: 9 | B11: 244478 | C11: suckjakkure@hotmail.com | D11: 642427575 | E11: 4311469006 | F11: ธนาคารไทยพาณิชย์ (SCB) | G11: 43 | H11: 9292 | I11: 0 | J11: 9292 | K11: 244597 | L11: 9292 | M11: =+J11-L11 -> 0
A12: 10 | B12: 244479 | C12: suckjakkure@hotmail.com | D12: 642427575 | E12: 4311469006 | F12: ธนาคารไทยพาณิชย์ (SCB) | G12: 17 | H12: 3406 | I12: 0 | J12: 3406 | K12: 244627 | L12: 3406 | M12: =+J12-L12 -> 0
A13: 11 | B13: 244480 | C13: suckjakkure@hotmail.com | D13: 642427575 | E13: 4311469006 | F13: ธนาคารไทยพาณิชย์ (SCB) | G13: 3 | H13: 415 | I13: 0 | J13: 415 | K13: 244658 | L13: 415 | M13: =+J13-L13 -> 0
A14: 12 | B14: 244481 | C14: suckjakkure@hotmail.com | D14: 642427575 | E14: 4311469006 | F14: ธนาคารไทยพาณิชย์ (SCB) | G14: 14 | H14: 2464 | I14: 0 | J14: 2464 | K14: 244688 | L14: 2464 | M14: =+J14-L14 -> 0
A15: 13 | B15: 244482 | C15: suckjakkure@hotmail.com | D15: 642427575 | E15: 4311469006 | F15: ธนาคารไทยพาณิชย์ (SCB) | G15: 21 | H15: 4306 | I15: 0 | J15: 4306 | K15: 13/5/2569 | L15: 4306 | M15: =+J15-L15 -> 0
A16: 14 | B16: 14/5/2569 | C16: suckjakkure@hotmail.com | D16: 642427575 | E16: 4311469006 | F16: ธนาคารไทยพาณิชย์ (SCB) | G16: 12 | H16: 2371 | I16: 0 | J16: 2371 | K16: 14/5/2569 | L16: 2371 | M16: =+J16-L16 -> 0
A17: 15 | B17: 15/5/2569 | C17: suckjakkure@hotmail.com | D17: 642427575 | E17: 4311469006 | F17: ธนาคารไทยพาณิชย์ (SCB) | G17: 25 | H17: 5604 | I17: 0 | J17: 5604 | K17: 15/5/2569 | L17: 5604 | M17: =+J17-L17 -> 0
A18: 16 | B18: 16/5/2569 | C18: suckjakkure@hotmail.com | D18: 642427575 | E18: 4311469006 | F18: ธนาคารไทยพาณิชย์ (SCB) | G18: 31 | H18: 7234 | I18: 0 | J18: 7234 | K18: 16/5/2569 | L18: 7234 | M18: =+J18-L18 -> 0
A19: 17 | B19: 17/5/2569 | C19: suckjakkure@hotmail.com | D19: 642427575 | E19: 4311469006 | F19: ธนาคารไทยพาณิชย์ (SCB) | G19: 19 | H19: 4879 | I19: 0 | J19: 4879 | K19: 17/5/2569 | L19: 4879 | M19: =+J19-L19 -> 0
A20: 18 | B20: 18/5/2569 | C20: suckjakkure@hotmail.com | D20: 642427575 | E20: 4311469006 | F20: ธนาคารไทยพาณิชย์ (SCB) | G20: 4 | H20: 801 | I20: 0 | J20: 801 | K20: 18/5/2569 | L20: 801 | M20: =+J20-L20 -> 0
A21: 19 | B21: 19/5/2569 | C21: suckjakkure@hotmail.com | D21: 642427575 | E21: 4311469006 | F21: ธนาคารไทยพาณิชย์ (SCB) | G21: 24 | H21: 6533 | I21: 0 | J21: 6533 | K21: 19/5/2569 | L21: 6533 | M21: =+J21-L21 -> 0
A22: 20 | B22: 20/5/2569 | C22: suckjakkure@hotmail.com | D22: 642427575 | E22: 4311469006 | F22: ธนาคารไทยพาณิชย์ (SCB) | G22: 16 | H22: 4426 | I22: 0 | J22: 4426 | K22: 20/5/2569 | L22: 4426 | M22: =+J22-L22 -> 0
A23: 21 | B23: 21/5/2569 | C23: suckjakkure@hotmail.com | D23: 642427575 | E23: 4311469006 | F23: ธนาคารไทยพาณิชย์ (SCB) | G23: 11 | H23: 2405 | I23: 0 | J23: 2405 | K23: 21/5/2569 | L23: 2405 | M23: =+J23-L23 -> 0
A24: 22 | B24: 22/5/2569 | C24: suckjakkure@hotmail.com | D24: 642427575 | E24: 4311469006 | F24: ธนาคารไทยพาณิชย์ (SCB) | G24: 23 | H24: 5552 | I24: 0 | J24: 5552 | K24: 22/5/2569 | L24: 5552 | M24: =+J24-L24 -> 0
A25: 23 | B25: 23/5/2569 | C25: suckjakkure@hotmail.com | D25: 642427575 | E25: 4311469006 | F25: ธนาคารไทยพาณิชย์ (SCB) | G25: 28 | H25: 6610 | I25: 0 | J25: 6610 | K25: 23/5/2569 | L25: 6610 | M25: =+J25-L25 -> 0
A26: 24 | B26: 24/5/2569 | C26: suckjakkure@hotmail.com | D26: 642427575 | E26: 4311469006 | F26: ธนาคารไทยพาณิชย์ (SCB) | G26: 15 | H26: 3065 | I26: 0 | J26: 3065 | K26: 24/5/2569 | L26: 3065 | M26: =+J26-L26 -> 0
A27: 25 | B27: 25/5/2569 | C27: suckjakkure@hotmail.com | D27: 642427575 | E27: 4311469006 | F27: ธนาคารไทยพาณิชย์ (SCB) | G27: 6 | H27: 1733 | I27: 0 | J27: 1733 | K27: 25/5/2569 | L27: 1733 | M27: =+J27-L27 -> 0
... A33: 31 | B33: 31/5/2569 | C33: suckjakkure@hotmail.com | D33: 642427575 | E33: 4311469006 | F33: ธนาคารไทยพาณิชย์ (SCB) | G33: 3 | H33: 854 | I33: 0 | J33: 854 | K33: 31/5/2569 | L33: 854 | M33: =+J33-L33 -> 0
F34: ยอดรวม | G34: =SUM(G3:G33) -> 530 | H34: =SUM(H3:H33) -> 122657 | I34: =SUM(I3:I33) -> 0 | J34: =SUM(J3:J33) -> 122657 | K34: บาท | L34: =SUM(L3:L33) -> 122657 | M34: บาท

Sheet มิ.ย.
A1: ข้อมูลการเก็บเงินปลายทาง (COD) แบบแยกรายละเอียด เดือนมิถุนายน 2569
A2: ลำดับ | B2: วันที่ | C2: Email | D2: Facebook Page | E2: Order No. / เลขที่ออเดอร์ | F2: Tracking No. / เลขพัสดุ | G2: recipientName / ชื่อลูกค้า | H2: Amount / ยอด COD
A3: 1 | B3: 244355 | C3: suckjakkure@hotmail.com | D3: FACEBOOK | F3: WA141493798TH | G3: น.ส. สุธีรา เขื่อนขันธ์เจริญ | H3: 199
A4: 2 | B4: 244386 | C4: suckjakkure@hotmail.com | D4: FACEBOOK | F4: WA142304663TH | G4: หนุ่ม คลังเคอรี่บ่อนไก่ | H4: 199
A5: 3 | B5: 244386 | C5: suckjakkure@hotmail.com | D5: FACEBOOK | F5: WA142304650TH | G5: มานิดา อัศวางกูร | H5: 199
A6: 4 | B6: 244386 | C6: suckjakkure@hotmail.com | D6: FACEBOOK | F6: WA142304629TH | G6: กัณกมล เรืองกิจ | H6: 215
A7: 5 | B7: 244386 | C7: suckjakkure@hotmail.com | D7: FACEBOOK | F7: WA142304703TH | G7: นพมาศ ทองวิบูลย์ | H7: 199
A8: 6 | B8: 244386 | C8: suckjakkure@hotmail.com | D8: FACEBOOK | F8: WA142304685TH | G8: Baan thai living | H8: 199
A9: 7 | B9: 244386 | C9: suckjakkure@hotmail.com | D9: FACEBOOK | F9: WA142304632TH | G9: บุญจิรา ไกรวิทย์ | H9: 199
A10: 8 | B10: 244386 | C10: suckjakkure@hotmail.com | D10: FACEBOOK | F10: WA141760658TH | G10: คุณ ณัฐชา คำบ่อ | H10: 100
A11: 9 | B11: 244445 | C11: suckjakkure@hotmail.com | D11: FACEBOOK | F11: WA142829017TH | G11: Ben Jawan | H11: 100
A12: 10 | B12: 244445 | C12: suckjakkure@hotmail.com | D12: FACEBOOK | F12: WA142592148TH | G12: สุจิตรา ไชยโชติ | H12: 199
A13: 11 | B13: 244445 | C13: suckjakkure@hotmail.com | D13: FACEBOOK | F13: WA143065219TH | G13: คุณ ชมัยพร( พี่กบ) | H13: 199
A14: 12 | B14: 244445 | C14: suckjakkure@hotmail.com | D14: FACEBOOK | F14: WA143065236TH | G14: ลดาวัลย์ รุ่งเรืองผล | H14: 150
... A136: 134 | B136: 244689 | C136: suckjakkure@hotmail.com | D136: FACEBOOK | F136: WA144650869TH | G136: นันทนา จิตมุสิก | H136: 220
A137: 135 | B137: 13/6/2569 | C137: suckjakkure@hotmail.com | D137: FACEBOOK | F137: WA145271261TH | G137: อารยา เกตุพันธ์ | H137: 199
A138: 136 | B138: 13/6/2569 | C138: suckjakkure@hotmail.com | D138: FACEBOOK | F138: WA144985292TH | G138: วิจิตรา ประสพ | H138: 220
A139: 137 | B139: 13/6/2569 | C139: suckjakkure@hotmail.com | D139: FACEBOOK | F139: WA144985377TH | G139: ธีระ ธุระพ่อค้า | H139: 199
A140: 138 | B140: 13/6/2569 | C140: suckjakkure@hotmail.com | D140: FACEBOOK | F140: WA144985301TH | G140: เบญจมาส เจ๊ะยะหลี | H140: 330
A141: 139 | B141: 13/6/2569 | C141: suckjakkure@hotmail.com | D141: FACEBOOK | F141: WA145271332TH | G141: San Sannee | H141: 199
A142: 140 | B142: 13/6/2569 | C142: suckjakkure@hotmail.com | D142: FACEBOOK | F142: WA145538150TH | G142: กิตติ วิมไตรเมต | H142: 220
A143: 141 | B143: 13/6/2569 | C143: suckjakkure@hotmail.com | D143: FACEBOOK | F143: WA145671600TH | G143: ธิดา ตันติวิริยะกุล | H143: 199
A144: 142 | B144: 13/6/2569 | C144: suckjakkure@hotmail.com | D144: FACEBOOK | F144: WA145271363TH | G144: พรนิภา ทองคำชู | H144: 199
A145: 143 | B145: 13/6/2569 | C145: suckjakkure@hotmail.com | D145: FACEBOOK | F145: WA145538185TH | G145: วันเพ็ญ อินทรัตน์ | H145: 199
A146: 144 | B146: 13/6/2569 | C146: suckjakkure@hotmail.com | D146: FACEBOOK | F146: WA145271292TH | G146: ขวัญจิต | H146: 199
A147: 145 | B147: 13/6/2569 | C147: suckjakkure@hotmail.com | D147: FACEBOOK | F147: WA145672962TH | G147: สมจิตต์ ปลอดประดิษฐ์ | H147: 398
A148: 146 | B148: 13/6/2569 | C148: suckjakkure@hotmail.com | D148: FACEBOOK | F148: WA145538248TH | G148: สุรีพร เพรชประพักตร์ | H148: 100
... A328: 326 | B328: 30/6/2569 | C328: suckjakkure@hotmail.com | D328: FACEBOOK | F328: WA161431599TH | G328: วรรณา. สุวรรณโณ | H328: 199
A329: 327
A330: 328
A331: 329
A332: 330
A333: 331
A334: 332
A335: 333
A336: 334
A337: 335
A338: 336
A339: 337
A340: 338
...

Sheet Summary มิ.ย.
A1: ข้อมูลการเก็บเงินปลายทาง (COD) แบบรวมยอดประจำวัน เดือนมิถุนายน2569 | K1: ตรวจในสเตทเม้น
A2: ลำดับ | B2: วันที่ | C2: Email | D2: Tel | E2: Bank Account Number / เลขที่บัญชี | F2: Bank Account Name / ชื่อธนาคาร | G2: Total Order / จำนวนออเดอร์ | H2: COD Amount / ยอดรวม COD | I2: Deduct | J2: Total Amount / ยอดรวม COD | K2: วันที่เงินเข้า | L2: ยอดเข้า | M2: หมายเหตุ
A3: 1 | B3: 244501 | C3: suckjakkure@hotmail.com | D3: 642427575 | E3: 4311469006 | F3: ธนาคารไทยพาณิชย์ (SCB) | G3: 1 | H3: 199 | I3: 0 | J3: 199 | K3: 244501 | L3: 199 | M3: =+J3-L3 -> 0
A4: 2 | B4: 244502 | C4: suckjakkure@hotmail.com | D4: 642427575 | E4: 4311469006 | F4: ธนาคารไทยพาณิชย์ (SCB) | G4: 7 | H4: 1310 | I4: 0 | J4: 1310 | K4: 244502 | L4: 1310 | M4: =+J4-L4 -> 0
A5: 3 | B5: 244503 | C5: ไม่มียอดเก็บ COD | K5: 244503 | M5: =+J5-L5 -> 0
A6: 4 | B6: 244504 | C6: suckjakkure@hotmail.com | D6: 642427575 | E6: 4311469006 | F6: ธนาคารไทยพาณิชย์ (SCB) | G6: 7 | H6: 1332 | I6: 0 | J6: 1332 | K6: 244504 | L6: 1332 | M6: =+J6-L6 -> 0
A7: 5 | B7: 244505 | C7: suckjakkure@hotmail.com | D7: 642427575 | E7: 4311469006 | F7: ธนาคารไทยพาณิชย์ (SCB) | G7: 12 | H7: 2621 | I7: 0 | J7: 2621 | K7: 244505 | L7: 2621 | M7: =+J7-L7 -> 0
A8: 6 | B8: 244506 | C8: suckjakkure@hotmail.com | D8: 642427575 | E8: 4311469006 | F8: ธนาคารไทยพาณิชย์ (SCB) | G8: 31 | H8: 6114 | I8: 0 | J8: 6114 | K8: 244506 | L8: 6114 | M8: =+J8-L8 -> 0
A9: 7 | B9: 244507 | C9: suckjakkure@hotmail.com | D9: 642427575 | E9: 4311469006 | F9: ธนาคารไทยพาณิชย์ (SCB) | G9: 26 | H9: 4753 | I9: 0 | J9: 4753 | K9: 244507 | L9: 4753 | M9: =+J9-L9 -> 0
A10: 8 | B10: 244508 | C10: suckjakkure@hotmail.com | D10: 642427575 | E10: 4311469006 | F10: ธนาคารไทยพาณิชย์ (SCB) | G10: 7 | H10: 1327 | I10: 0 | J10: 1327 | K10: 244508 | L10: 1327 | M10: =+J10-L10 -> 0
A11: 9 | B11: 244509 | C11: suckjakkure@hotmail.com | D11: 642427575 | E11: 4311469006 | F11: ธนาคารไทยพาณิชย์ (SCB) | G11: 12 | H11: 2625 | I11: 0 | J11: 2625 | K11: 244509 | L11: 2625 | M11: =+J11-L11 -> 0
A12: 10 | B12: 244510 | C12: suckjakkure@hotmail.com | D12: 642427575 | E12: 4311469006 | F12: ธนาคารไทยพาณิชย์ (SCB) | G12: 6 | H12: 1062 | I12: 0 | J12: 1062 | K12: 244510 | L12: 1062 | M12: =+J12-L12 -> 0
A13: 11 | B13: 244511 | C13: suckjakkure@hotmail.com | D13: 642427575 | E13: 4311469006 | F13: ธนาคารไทยพาณิชย์ (SCB) | G13: 13 | H13: 2738 | I13: 0 | J13: 2738 | K13: 244511 | L13: 2738 | M13: =+J13-L13 -> 0
A14: 12 | B14: 244512 | C14: suckjakkure@hotmail.com | D14: 642427575 | E14: 4311469006 | F14: ธนาคารไทยพาณิชย์ (SCB) | G14: 12 | H14: 2233 | I14: 0 | J14: 2233 | K14: 244512 | L14: 2233 | M14: =+J14-L14 -> 0
A15: 13 | B15: 244513 | C15: suckjakkure@hotmail.com | D15: 642427575 | E15: 4311469006 | F15: ธนาคารไทยพาณิชย์ (SCB) | G15: 24 | H15: 4976 | I15: 0 | J15: 4976 | K15: 244513 | L15: 4976 | M15: =+J15-L15 -> 0
A16: 14 | B16: 244514 | C16: suckjakkure@hotmail.com | D16: 642427575 | E16: 4311469006 | F16: ธนาคารไทยพาณิชย์ (SCB) | G16: 9 | H16: 1667 | I16: 0 | J16: 1667 | K16: 244514 | L16: 1667 | M16: =+J16-L16 -> 0
A17: 15 | B17: 244515 | C17: suckjakkure@hotmail.com | D17: 642427575 | E17: 4311469006 | F17: ธนาคารไทยพาณิชย์ (SCB) | G17: 6 | H17: 1226 | I17: 0 | J17: 1226 | K17: 244515 | L17: 1226 | M17: =+J17-L17 -> 0
... A32: 30 | B32: 244530 | C32: suckjakkure@hotmail.com | D32: 642427575 | E32: 4311469006 | F32: ธนาคารไทยพาณิชย์ (SCB) | G32: 4 | H32: 614 | I32: 0 | J32: 614 | K32: 244530 | L32: 614 | M32: =+J32-L32 -> 0
F33: ยอดรวม | G33: =SUM(G3:G32) -> 326 | H33: =SUM(H3:H32) -> 66099 | I33: =SUM(I3:I32) -> 0 | J33: =SUM(J3:J32) -> 66099 | K33: บาท | L33: =SUM(L3:L32) -> 66099 | M33: บาท

Sheet ก.ค.
A1: ข้อมูลการเก็บเงินปลายทาง (COD) แบบแยกรายละเอียด เดือนกรกฎาคม 2569
A2: ลำดับ | B2: วันที่ | C2: Email | D2: Facebook Page | E2: Order No. / เลขที่ออเดอร์ | F2: Tracking No. / เลขพัสดุ | G2: recipientName / ชื่อลูกค้า | H2: Amount / ยอด COD
A3: 1
A4: 2
A5: 3
A6: 4
A7: 5
A8: 6
A9: 7
A10: 8
A11: 9
A12: 10
A13: 11
A14: 12
... A239: 237
G240: ยอดรวม | H240: =SUM(H3:H239) -> 0 | I240: บาท

Sheet Summary ก.ค.
A1: ข้อมูลการเก็บเงินปลายทาง (COD) แบบรวมยอดประจำวัน เดือนกรกฎาคม 2569 | K1: ตรวจในสเตทเม้น
A2: ลำดับ | B2: วันที่ | C2: Email | D2: Tel | E2: Bank Account Number / เลขที่บัญชี | F2: Bank Account Name / ชื่อธนาคาร | G2: Total Order / จำนวนออเดอร์ | H2: COD Amount / ยอดรวม COD | I2: Deduct | J2: Total Amount / ยอดรวม COD | K2: วันที่เงินเข้า | L2: ยอดเข้า | M2: หมายเหตุ
A3: 1 | B3: 244350 | K3: 244350 | M3: =+J3-L3 -> 0
A4: 2 | B4: 244350 | K4: 244350 | M4: =+J4-L4 -> 0
A5: 3 | B5: 244351 | K5: 244351 | M5: =+J5-L5 -> 0
A6: 4 | B6: 244352 | K6: 244352 | M6: =+J6-L6 -> 0
A7: 5 | B7: 244352 | K7: 244352 | M7: =+J7-L7 -> 0
A8: 6 | B8: 244353 | K8: 244353 | M8: =+J8-L8 -> 0
A9: 7 | B9: 244354 | K9: 244354 | M9: =+J9-L9 -> 0
A10: 8 | B10: 244354 | K10: 244354 | M10: =+J10-L10 -> 0
A11: 9 | B11: 244355 | K11: 244355 | M11: =+J11-L11 -> 0
A12: 10 | B12: 244355 | K12: 244355 | M12: =+J12-L12 -> 0
A13: 11 | B13: 244356 | K13: 244356 | M13: =+J13-L13 -> 0
A14: 12 | B14: 244357 | K14: 244357 | M14: =+J14-L14 -> 0
... A38: 36 | B38: 244380 | K38: 244380 | M38: =+J38-L38 -> 0
