Workbook

Sheet Month
A1: ลำดับ | B1: ทีมโทร | C1: บูธ | D1: online | E1: Modern Trade | F1: รหัส | G1: ชื่อสินค้า | H1: ลูกค้า | I1: ขนาดบรรจุ | N1: week 1 (วันที่ 1-7 มี.ค. 2569)
I2: จำนวน(ชิ้น) | J2: หน่วย(กล่อง) | K2: วัน | N2: วันอาทิตย์ | R2: ยอดจริง | X2: วันจันทร์ | AB2: ยอดจริง | AH2: วันอังคาร | AL2: ยอดจริง | AR2: วันพุธ | AV2: ยอดจริง | BB2: วันพฤหัสบดี | BF2: ยอดจริง | BL2: วันศุกร์ | BP2: ยอดจริง | BV2: เสาร์ | BZ2: ยอดจริง
K3: วันที่ | N3: 4 | X3: 5 | AH3: 6 | AR3: 7 | BB3: 8 | BL3: 9 | BV3: 10
K4: ติดป้าย Amezon | L4: ไม่ติดป้าย Amezon | M4: Non Logo | N4: ติดป้าย Amezon | O4: ไม่ติดป้าย Amezon | P4: Non Logo | Q4: รวม | R4: ติดป้าย Amezon | S4: ไม่ติดป้าย Amezon | T4: Non Logo | U4: ติดป้าย Amezon | V4: ไม่ติดป้าย Amezon | W4: Non Logo | X4: ติดป้าย Amezon | Y4: ไม่ติดป้าย Amezon | Z4: Non Logo | AA4: รวม | AB4: ติดป้าย Amezon | AC4: ไม่ติดป้าย Amezon | AD4: Non Logo | AE4: ติดป้าย Amezon | AF4: ไม่ติดป้าย Amezon | AG4: Non Logo | AH4: ติดป้าย Amezon | AI4: ไม่ติดป้าย Amezon | AJ4: Non Logo | AK4: รวม | AL4: ติดป้าย Amezon | AM4: ไม่ติดป้าย Amezon | AN4: Non Logo | AO4: ติดป้าย Amezon | AP4: ไม่ติดป้าย Amezon | AQ4: Non Logo | AR4: ติดป้าย Amezon | AS4: ไม่ติดป้าย Amezon | AT4: Non Logo | AU4: รวม | AV4: ติดป้าย Amezon | AW4: ไม่ติดป้าย Amezon | AX4: Non Logo | AY4: ติดป้าย Amezon | AZ4: ไม่ติดป้าย Amezon | BA4: Non Logo | BB4: ติดป้าย Amezon | BC4: ไม่ติดป้าย Amezon | BD4: Non Logo | BE4: รวม | BF4: ติดป้าย Amezon | BG4: ไม่ติดป้าย Amezon | BH4: Non Logo | BI4: ติดป้าย Amezon | BJ4: ไม่ติดป้าย Amezon | BK4: Non Logo | BL4: ติดป้าย Amezon | BM4: ไม่ติดป้าย Amezon | BN4: Non Logo | BO4: รวม | BP4: ติดป้าย Amezon | BQ4: ไม่ติดป้าย Amezon | BR4: Non Logo | BS4: ติดป้าย Amezon | BT4: ไม่ติดป้าย Amezon | BU4: Non Logo | BV4: ติดป้าย Amezon | BW4: ไม่ติดป้าย Amezon | BX4: Non Logo | BY4: รวม | BZ4: ติดป้าย Amezon | CA4: ไม่ติดป้าย Amezon | CB4: Non Logo | CC4: ติดป้าย Amezon | CD4: ไม่ติดป้าย Amezon | CE4: Non Logo
A5: 1 | F5: 1113036 | G5: ช็อกบอล | H5: Aeon | K5: =SUM(N5,X5,AH5,AR5,BB5,BL5,BV5) -> 0 | L5: =SUM(O5,Y5,AI5,AS5,BC5,BM5,BW5) -> 0 | O5: 0 | Q5: =SUM(N5:P5) -> 0 | R5: =SUMIF('ยอดจริง Week 1'!A:A,'Week 1'!F5,'ยอดจริง Week 1'!C:C) -> 0 | S5: =SUMIF('ยอดจริง Week 1'!A:A,'Week 1'!F5,'ยอดจริง Week 1'!D:D) -> 0 | T5: =SUMIF('ยอดจริง Week 1'!A:A,'Week 1'!F5,'ยอดจริง Week 1'!E:E) -> 0 | U5: =N5-R5 -> 0 | V5: =O5-S5 -> 0 | W5: =P5-T5 -> 0 | Y5: 0 | AA5: =SUM(X5:Z5) -> 0 | AB5: =SUMIF('ยอดจริง Week 1'!H:H,'Week 1'!F5,'ยอดจริง Week 1'!J:J) -> 0 | AC5: =SUMIF('ยอดจริง Week 1'!H:H,'Week 1'!F5,'ยอดจริง Week 1'!K:K) -> 0 | AD5: =SUMIF('ยอดจริง Week 1'!H:H,'Week 1'!F5,'ยอดจริง Week 1'!L:L) -> 0 | AE5: =X5-AB5 -> 0 | AF5: =Y5-AC5 -> 0 | AG5: =Z5-AD5 -> 0 | AI5: 0 | AK5: =SUM(AH5:AJ5) -> 0 | AL5: =SUMIF('ยอดจริง Week 1'!O:O,'Week 1'!F5,'ยอดจริง Week 1'!Q:Q) -> 0 | AM5: =SUMIF('ยอดจริง Week 1'!O:O,'Week 1'!F5,'ยอดจริง Week 1'!R:R) -> 0 | AN5: =SUMIF('ยอดจริง Week 1'!O:O,'Week 1'!F5,'ยอดจริง Week 1'!S:S) -> 0 | AO5: =AH5-AL5 -> 0 | AP5: =AI5-AM5 -> 0 | AQ5: =AJ5-AN5 -> 0 | AS5: 0 | AU5: =SUM(AR5:AT5) -> 0 | AV5: =SUMIF('ยอดจริง Week 1'!V:V,'Week 1'!F5,'ยอดจริง Week 1'!X:X) -> 0 | AW5: =SUMIF('ยอดจริง Week 1'!V:V,'Week 1'!F5,'ยอดจริง Week 1'!Y:Y) -> 0 | AX5: =SUMIF('ยอดจริง Week 1'!V:V,'Week 1'!F5,'ยอดจริง Week 1'!Z:Z) -> 0 | AY5: =AR5-AV5 -> 0 | AZ5: =AS5-AW5 -> 0 | BA5: =AT5-AX5 -> 0 | BE5: =SUM(BB5:BD5) -> 0 | BF5: =SUMIF('ยอดจริง Week 1'!AC:AC,'Week 1'!F5,'ยอดจริง Week 1'!AE:AE) -> 0 | BG5: =SUMIF('ยอดจริง Week 1'!AC:AC,'Week 1'!F5,'ยอดจริง Week 1'!AF:AF) -> 0 | BH5: =SUMIF('ยอดจริง Week 1'!AC:AC,'Week 1'!F5,'ยอดจริง Week 1'!AG:AG) -> 0 | BI5: =BB5-BF5 -> 0 | BJ5: =BC5-BG5 -> 0 | BK5: =BD5-BH5 -> 0 | BO5: =SUM(BL5:BN5) -> 0 | BP5: =SUMIF('ยอดจริง Week 1'!AJ:AJ,'Week 1'!F5,'ยอดจริง Week 1'!AL:AL) -> 0 | BQ5: =SUMIF('ยอดจริง Week 1'!AJ:AJ,'Week 1'!F5,'ยอดจริง Week 1'!AM:AM) -> 0 | BR5: =SUMIF('ยอดจริง Week 1'!AJ:AJ,'Week 1'!F5,'ยอดจริง Week 1'!AN:AN) -> 0 | BS5: =BL5-BP5 -> 0 | BT5: =BM5-BQ5 -> 0 | BU5: =BN5-BR5 -> 0 | BY5: =SUM(BV5:BX5) -> 0 | BZ5: =SUMIF('ยอดจริง Week 1'!AQ:AQ,'Week 1'!F5,'ยอดจริง Week 1'!AS:AS) -> 0 | CA5: =SUMIF('ยอดจริง Week 1'!AQ:AQ,'Week 1'!F5,'ยอดจริง Week 1'!AT:AT) -> 0 | CB5: =SUMIF('ยอดจริง Week 1'!AQ:AQ,'Week 1'!F5,'ยอดจริง Week 1'!AU:AU) -> 0 | CC5: =BV5-BZ5 -> 0 | CD5: =BW5-CA5 -> 0 | CE5: =BX5-CB5 -> 0
A6: 2 | F6: 1111001 | G6: ชิฟฟ่อนเค้ก (1 ชิ้น) | H6: Aeon | K6: =SUM(N6,X6,AH6,AR6,BB6,BL6,BV6) -> 0 | L6: =SUM(O6,Y6,AI6,AS6,BC6,BM6,BW6) -> 0 | Q6: =SUM(N6:P6) -> 0 | R6: =SUMIF('ยอดจริง Week 1'!A:A,'Week 1'!F6,'ยอดจริง Week 1'!C:C) -> 0 | S6: =SUMIF('ยอดจริง Week 1'!A:A,'Week 1'!F6,'ยอดจริง Week 1'!D:D) -> 0 | T6: =SUMIF('ยอดจริง Week 1'!A:A,'Week 1'!F6,'ยอดจริง Week 1'!E:E) -> 0 | U6: =N6-R6 -> 0 | V6: =O6-S6 -> 0 | W6: =P6-T6 -> 0 | Y6: 0 | AA6: =SUM(X6:Z6) -> 0 | AB6: =SUMIF('ยอดจริง Week 1'!H:H,'Week 1'!F6,'ยอดจริง Week 1'!J:J) -> 0 | AC6: =SUMIF('ยอดจริง Week 1'!H:H,'Week 1'!F6,'ยอดจริง Week 1'!K:K) -> 0 | AD6: =SUMIF('ยอดจริง Week 1'!H:H,'Week 1'!F6,'ยอดจริง Week 1'!L:L) -> 0 | AE6: =X6-AB6 -> 0 | AF6: =Y6-AC6 -> 0 | AG6: =Z6-AD6 -> 0 | AI6: 0 | AK6: =SUM(AH6:AJ6) -> 0 | AL6: =SUMIF('ยอดจริง Week 1'!O:O,'Week 1'!F6,'ยอดจริง Week 1'!Q:Q) -> 0 | AM6: =SUMIF('ยอดจริง Week 1'!O:O,'Week 1'!F6,'ยอดจริง Week 1'!R:R) -> 0 | AN6: =SUMIF('ยอดจริง Week 1'!O:O,'Week 1'!F6,'ยอดจริง Week 1'!S:S) -> 0 | AO6: =AH6-AL6 -> 0 | AP6: =AI6-AM6 -> 0 | AQ6: =AJ6-AN6 -> 0 | AS6: 0 | AU6: =SUM(AR6:AT6) -> 0 | AV6: =SUMIF('ยอดจริง Week 1'!V:V,'Week 1'!F6,'ยอดจริง Week 1'!X:X) -> 0 | AW6: =SUMIF('ยอดจริง Week 1'!V:V,'Week 1'!F6,'ยอดจริง Week 1'!Y:Y) -> 0 | AX6: =SUMIF('ยอดจริง Week 1'!V:V,'Week 1'!F6,'ยอดจริง Week 1'!Z:Z) -> 0 | AY6: =AR6-AV6 -> 0 | AZ6: =AS6-AW6 -> 0 | BA6: =AT6-AX6 -> 0 | BE6: =SUM(BB6:BD6) -> 0 | BF6: =SUMIF('ยอดจริง Week 1'!AC:AC,'Week 1'!F6,'ยอดจริง Week 1'!AE:AE) -> 0 | BG6: =SUMIF('ยอดจริง Week 1'!AC:AC,'Week 1'!F6,'ยอดจริง Week 1'!AF:AF) -> 0 | BH6: =SUMIF('ยอดจริง Week 1'!AC:AC,'Week 1'!F6,'ยอดจริง Week 1'!AG:AG) -> 0 | BI6: =BB6-BF6 -> 0 | BJ6: =BC6-BG6 -> 0 | BK6: =BD6-BH6 -> 0 | BO6: =SUM(BL6:BN6) -> 0 | BP6: =SUMIF('ยอดจริง Week 1'!AJ:AJ,'Week 1'!F6,'ยอดจริง Week 1'!AL:AL) -> 0 | BQ6: =SUMIF('ยอดจริง Week 1'!AJ:AJ,'Week 1'!F6,'ยอดจริง Week 1'!AM:AM) -> 0 | BR6: =SUMIF('ยอดจริง Week 1'!AJ:AJ,'Week 1'!F6,'ยอดจริง Week 1'!AN:AN) -> 0 | BS6: =BL6-BP6 -> 0 | BT6: =BM6-BQ6 -> 0 | BU6: =BN6-BR6 -> 0 | BY6: =SUM(BV6:BX6) -> 0 | BZ6: =SUMIF('ยอดจริง Week 1'!AQ:AQ,'Week 1'!F6,'ยอดจริง Week 1'!AS:AS) -> 0 | CA6: =SUMIF('ยอดจริง Week 1'!AQ:AQ,'Week 1'!F6,'ยอดจริง Week 1'!AT:AT) -> 0 | CB6: =SUMIF('ยอดจริง Week 1'!AQ:AQ,'Week 1'!F6,'ยอดจริง Week 1'!AU:AU) -> 0 | CC6: =BV6-BZ6 -> 0 | CD6: =BW6-CA6 -> 0 | CE6: =BX6-CB6 -> 0
A7: 3 | F7: 1004055 | G7: ชิฟฟ่อนเค้ก วรรณวนัช (รวมรส 4 ชิ้น) | K7: =SUM(N7,X7,AH7,AR7,BB7,BL7,BV7) -> 0 | L7: =SUM(O7,Y7,AI7,AS7,BC7,BM7,BW7) -> 0 | Q7: =SUM(N7:P7) -> 0 | R7: =SUMIF('ยอดจริง Week 1'!A:A,'Week 1'!F7,'ยอดจริง Week 1'!C:C) -> 0 | S7: =SUMIF('ยอดจริง Week 1'!A:A,'Week 1'!F7,'ยอดจริง Week 1'!D:D) -> 0 | T7: =SUMIF('ยอดจริง Week 1'!A:A,'Week 1'!F7,'ยอดจริง Week 1'!E:E) -> 0 | U7: =N7-R7 -> 0 | V7: =O7-S7 -> 0 | W7: =P7-T7 -> 0 | Y7: 0 | AA7: =SUM(X7:Z7) -> 0 | AB7: =SUMIF('ยอดจริง Week 1'!H:H,'Week 1'!F7,'ยอดจริง Week 1'!J:J) -> 0 | AC7: =SUMIF('ยอดจริง Week 1'!H:H,'Week 1'!F7,'ยอดจริง Week 1'!K:K) -> 0 | AD7: =SUMIF('ยอดจริง Week 1'!H:H,'Week 1'!F7,'ยอดจริง Week 1'!L:L) -> 0 | AE7: =X7-AB7 -> 0 | AF7: =Y7-AC7 -> 0 | AG7: =Z7-AD7 -> 0 | AI7: 0 | AK7: =SUM(AH7:AJ7) -> 0 | AL7: =SUMIF('ยอดจริง Week 1'!O:O,'Week 1'!F7,'ยอดจริง Week 1'!Q:Q) -> 0 | AM7: =SUMIF('ยอดจริง Week 1'!O:O,'Week 1'!F7,'ยอดจริง Week 1'!R:R) -> 0 | AN7: =SUMIF('ยอดจริง Week 1'!O:O,'Week 1'!F7,'ยอดจริง Week 1'!S:S) -> 0 | AO7: =AH7-AL7 -> 0 | AP7: =AI7-AM7 -> 0 | AQ7: =AJ7-AN7 -> 0 | AS7: 0 | AU7: =SUM(AR7:AT7) -> 0 | AV7: =SUMIF('ยอดจริง Week 1'!V:V,'Week 1'!F7,'ยอดจริง Week 1'!X:X) -> 0 | AW7: =SUMIF('ยอดจริง Week 1'!V:V,'Week 1'!F7,'ยอดจริง Week 1'!Y:Y) -> 0 | AX7: =SUMIF('ยอดจริง Week 1'!V:V,'Week 1'!F7,'ยอดจริง Week 1'!Z:Z) -> 0 | AY7: =AR7-AV7 -> 0 | AZ7: =AS7-AW7 -> 0 | BA7: =AT7-AX7 -> 0 | BE7: =SUM(BB7:BD7) -> 0 | BF7: =SUMIF('ยอดจริง Week 1'!AC:AC,'Week 1'!F7,'ยอดจริง Week 1'!AE:AE) -> 0 | BG7: =SUMIF('ยอดจริง Week 1'!AC:AC,'Week 1'!F7,'ยอดจริง Week 1'!AF:AF) -> 0 | BH7: =SUMIF('ยอดจริง Week 1'!AC:AC,'Week 1'!F7,'ยอดจริง Week 1'!AG:AG) -> 0 | BI7: =BB7-BF7 -> 0 | BJ7: =BC7-BG7 -> 0 | BK7: =BD7-BH7 -> 0 | BO7: =SUM(BL7:BN7) -> 0 | BP7: =SUMIF('ยอดจริง Week 1'!AJ:AJ,'Week 1'!F7,'ยอดจริง Week 1'!AL:AL) -> 0 | BQ7: =SUMIF('ยอดจริง Week 1'!AJ:AJ,'Week 1'!F7,'ยอดจริง Week 1'!AM:AM) -> 0 | BR7: =SUMIF('ยอดจริง Week 1'!AJ:AJ,'Week 1'!F7,'ยอดจริง Week 1'!AN:AN) -> 0 | BS7: =BL7-BP7 -> 0 | BT7: =BM7-BQ7 -> 0 | BU7: =BN7-BR7 -> 0 | BY7: =SUM(BV7:BX7) -> 0 | BZ7: =SUMIF('ยอดจริง Week 1'!AQ:AQ,'Week 1'!F7,'ยอดจริง Week 1'!AS:AS) -> 0 | CA7: =SUMIF('ยอดจริง Week 1'!AQ:AQ,'Week 1'!F7,'ยอดจริง Week 1'!AT:AT) -> 0 | CB7: =SUMIF('ยอดจริง Week 1'!AQ:AQ,'Week 1'!F7,'ยอดจริง Week 1'!AU:AU) -> 0 | CC7: =BV7-BZ7 -> 0 | CD7: =BW7-CA7 -> 0 | CE7: =BX7-CB7 -> 0
A8: 4 | F8: 1111002 | G8: ชิฟฟ่อนเค้ก วรรณวนัช (รวมรส 8 ชิ้น) | H8: Lotus | K8: =SUM(N8,X8,AH8,AR8,BB8,BL8,BV8) -> 0 | L8: =SUM(O8,Y8,AI8,AS8,BC8,BM8,BW8) -> 0 | Q8: =SUM(N8:P8) -> 0 | R8: =SUMIF('ยอดจริง Week 1'!A:A,'Week 1'!F8,'ยอดจริง Week 1'!C:C) -> 0 | S8: =SUMIF('ยอดจริง Week 1'!A:A,'Week 1'!F8,'ยอดจริง Week 1'!D:D) -> 0 | T8: =SUMIF('ยอดจริง Week 1'!A:A,'Week 1'!F8,'ยอดจริง Week 1'!E:E) -> 0 | U8: =N8-R8 -> 0 | V8: =O8-S8 -> 0 | W8: =P8-T8 -> 0 | Y8: 0 | AA8: =SUM(X8:Z8) -> 0 | AB8: =SUMIF('ยอดจริง Week 1'!H:H,'Week 1'!F8,'ยอดจริง Week 1'!J:J) -> 0 | AC8: =SUMIF('ยอดจริง Week 1'!H:H,'Week 1'!F8,'ยอดจริง Week 1'!K:K) -> 0 | AD8: =SUMIF('ยอดจริง Week 1'!H:H,'Week 1'!F8,'ยอดจริง Week 1'!L:L) -> 0 | AE8: =X8-AB8 -> 0 | AF8: =Y8-AC8 -> 0 | AG8: =Z8-AD8 -> 0 | AI8: 0 | AK8: =SUM(AH8:AJ8) -> 0 | AL8: =SUMIF('ยอดจริง Week 1'!O:O,'Week 1'!F8,'ยอดจริง Week 1'!Q:Q) -> 0 | AM8: =SUMIF('ยอดจริง Week 1'!O:O,'Week 1'!F8,'ยอดจริง Week 1'!R:R) -> 0 | AN8: =SUMIF('ยอดจริง Week 1'!O:O,'Week 1'!F8,'ยอดจริง Week 1'!S:S) -> 0 | AO8: =AH8-AL8 -> 0 | AP8: =AI8-AM8 -> 0 | AQ8: =AJ8-AN8 -> 0 | AS8: 0 | AU8: =SUM(AR8:AT8) -> 0 | AV8: =SUMIF('ยอดจริง Week 1'!V:V,'Week 1'!F8,'ยอดจริง Week 1'!X:X) -> 0 | AW8: =SUMIF('ยอดจริง Week 1'!V:V,'Week 1'!F8,'ยอดจริง Week 1'!Y:Y) -> 0 | AX8: =SUMIF('ยอดจริง Week 1'!V:V,'Week 1'!F8,'ยอดจริง Week 1'!Z:Z) -> 0 | AY8: =AR8-AV8 -> 0 | AZ8: =AS8-AW8 -> 0 | BA8: =AT8-AX8 -> 0 | BE8: =SUM(BB8:BD8) -> 0 | BF8: =SUMIF('ยอดจริง Week 1'!AC:AC,'Week 1'!F8,'ยอดจริง Week 1'!AE:AE) -> 0 | BG8: =SUMIF('ยอดจริง Week 1'!AC:AC,'Week 1'!F8,'ยอดจริง Week 1'!AF:AF) -> 0 | BH8: =SUMIF('ยอดจริง Week 1'!AC:AC,'Week 1'!F8,'ยอดจริง Week 1'!AG:AG) -> 0 | BI8: =BB8-BF8 -> 0 | BJ8: =BC8-BG8 -> 0 | BK8: =BD8-BH8 -> 0 | BO8: =SUM(BL8:BN8) -> 0 | BP8: =SUMIF('ยอดจริง Week 1'!AJ:AJ,'Week 1'!F8,'ยอดจริง Week 1'!AL:AL) -> 0 | BQ8: =SUMIF('ยอดจริง Week 1'!AJ:AJ,'Week 1'!F8,'ยอดจริง Week 1'!AM:AM) -> 0 | BR8: =SUMIF('ยอดจริง Week 1'!AJ:AJ,'Week 1'!F8,'ยอดจริง Week 1'!AN:AN) -> 0 | BS8: =BL8-BP8 -> 0 | BT8: =BM8-BQ8 -> 0 | BU8: =BN8-BR8 -> 0 | BY8: =SUM(BV8:BX8) -> 0 | BZ8: =SUMIF('ยอดจริง Week 1'!AQ:AQ,'Week 1'!F8,'ยอดจริง Week 1'!AS:AS) -> 0 | CA8: =SUMIF('ยอดจริง Week 1'!AQ:AQ,'Week 1'!F8,'ยอดจริง Week 1'!AT:AT) -> 0 | CB8: =SUMIF('ยอดจริง Week 1'!AQ:AQ,'Week 1'!F8,'ยอดจริง Week 1'!AU:AU) -> 0 | CC8: =BV8-BZ8 -> 0 | CD8: =BW8-CA8 -> 0 | CE8: =BX8-CB8 -> 0
A9: 5 | F9: 1111055 | G9: วรรณวนัช ชิฟฟ่อนรวมรส 8 ชิ้น | H9: Makro | K9: =SUM(N9,X9,AH9,AR9,BB9,BL9,BV9) -> 0 | L9: =SUM(O9,Y9,AI9,AS9,BC9,BM9,BW9) -> 0 | Q9: =SUM(N9:P9) -> 0 | R9: =SUMIF('ยอดจริง Week 1'!A:A,'Week 1'!F9,'ยอดจริง Week 1'!C:C) -> 0 | S9: =SUMIF('ยอดจริง Week 1'!A:A,'Week 1'!F9,'ยอดจริง Week 1'!D:D) -> 0 | T9: =SUMIF('ยอดจริง Week 1'!A:A,'Week 1'!F9,'ยอดจริง Week 1'!E:E) -> 0 | U9: =N9-R9 -> 0 | V9: =O9-S9 -> 0 | W9: =P9-T9 -> 0 | Y9: 0 | AA9: =SUM(X9:Z9) -> 0 | AB9: =SUMIF('ยอดจริง Week 1'!H:H,'Week 1'!F9,'ยอดจริง Week 1'!J:J) -> 0 | AC9: =SUMIF('ยอดจริง Week 1'!H:H,'Week 1'!F9,'ยอดจริง Week 1'!K:K) -> 0 | AD9: =SUMIF('ยอดจริง Week 1'!H:H,'Week 1'!F9,'ยอดจริง Week 1'!L:L) -> 0 | AE9: =X9-AB9 -> 0 | AF9: =Y9-AC9 -> 0 | AG9: =Z9-AD9 -> 0 | AI9: 0 | AK9: =SUM(AH9:AJ9) -> 0 | AL9: =SUMIF('ยอดจริง Week 1'!O:O,'Week 1'!F9,'ยอดจริง Week 1'!Q:Q) -> 0 | AM9: =SUMIF('ยอดจริง Week 1'!O:O,'Week 1'!F9,'ยอดจริง Week 1'!R:R) -> 0 | AN9: =SUMIF('ยอดจริง Week 1'!O:O,'Week 1'!F9,'ยอดจริง Week 1'!S:S) -> 0 | AO9: =AH9-AL9 -> 0 | AP9: =AI9-AM9 -> 0 | AQ9: =AJ9-AN9 -> 0 | AS9: 0 | AU9: =SUM(AR9:AT9) -> 0 | AV9: =SUMIF('ยอดจริง Week 1'!V:V,'Week 1'!F9,'ยอดจริง Week 1'!X:X) -> 0 | AW9: =SUMIF('ยอดจริง Week 1'!V:V,'Week 1'!F9,'ยอดจริง Week 1'!Y:Y) -> 0 | AX9: =SUMIF('ยอดจริง Week 1'!V:V,'Week 1'!F9,'ยอดจริง Week 1'!Z:Z) -> 0 | AY9: =AR9-AV9 -> 0 | AZ9: =AS9-AW9 -> 0 | BA9: =AT9-AX9 -> 0 | BE9: =SUM(BB9:BD9) -> 0 | BF9: =SUMIF('ยอดจริง Week 1'!AC:AC,'Week 1'!F9,'ยอดจริง Week 1'!AE:AE) -> 0 | BG9: =SUMIF('ยอดจริง Week 1'!AC:AC,'Week 1'!F9,'ยอดจริง Week 1'!AF:AF) -> 0 | BH9: =SUMIF('ยอดจริง Week 1'!AC:AC,'Week 1'!F9,'ยอดจริง Week 1'!AG:AG) -> 0 | BI9: =BB9-BF9 -> 0 | BJ9: =BC9-BG9 -> 0 | BK9: =BD9-BH9 -> 0 | BO9: =SUM(BL9:BN9) -> 0 | BP9: =SUMIF('ยอดจริง Week 1'!AJ:AJ,'Week 1'!F9,'ยอดจริง Week 1'!AL:AL) -> 0 | BQ9: =SUMIF('ยอดจริง Week 1'!AJ:AJ,'Week 1'!F9,'ยอดจริง Week 1'!AM:AM) -> 0 | BR9: =SUMIF('ยอดจริง Week 1'!AJ:AJ,'Week 1'!F9,'ยอดจริง Week 1'!AN:AN) -> 0 | BS9: =BL9-BP9 -> 0 | BT9: =BM9-BQ9 -> 0 | BU9: =BN9-BR9 -> 0 | BY9: =SUM(BV9:BX9) -> 0 | BZ9: =SUMIF('ยอดจริง Week 1'!AQ:AQ,'Week 1'!F9,'ยอดจริง Week 1'!AS:AS) -> 0 | CA9: =SUMIF('ยอดจริง Week 1'!AQ:AQ,'Week 1'!F9,'ยอดจริง Week 1'!AT:AT) -> 0 | CB9: =SUMIF('ยอดจริง Week 1'!AQ:AQ,'Week 1'!F9,'ยอดจริง Week 1'!AU:AU) -> 0 | CC9: =BV9-BZ9 -> 0 | CD9: =BW9-CA9 -> 0 | CE9: =BX9-CB9 -> 0
A10: 6 | F10: 1111030 | G10: ชิฟฟ่อนเค้ก รสกาแฟ (8 ชิ้น) | K10: =SUM(N10,X10,AH10,AR10,BB10,BL10,BV10) -> 0 | L10: =SUM(O10,Y10,AI10,AS10,BC10,BM10,BW10) -> 0 | Q10: =SUM(N10:P10) -> 0 | R10: =SUMIF('ยอดจริง Week 1'!A:A,'Week 1'!F10,'ยอดจริง Week 1'!C:C) -> 0 | S10: =SUMIF('ยอดจริง Week 1'!A:A,'Week 1'!F10,'ยอดจริง Week 1'!D:D) -> 0 | T10: =SUMIF('ยอดจริง Week 1'!A:A,'Week 1'!F10,'ยอดจริง Week 1'!E:E) -> 0 | U10: =N10-R10 -> 0 | V10: =O10-S10 -> 0 | W10: =P10-T10 -> 0 | Y10: 0 | AA10: =SUM(X10:Z10) -> 0 | AB10: =SUMIF('ยอดจริง Week 1'!H:H,'Week 1'!F10,'ยอดจริง Week 1'!J:J) -> 0 | AC10: =SUMIF('ยอดจริง Week 1'!H:H,'Week 1'!F10,'ยอดจริง Week 1'!K:K) -> 0 | AD10: =SUMIF('ยอดจริง Week 1'!H:H,'Week 1'!F10,'ยอดจริง Week 1'!L:L) -> 0 | AE10: =X10-AB10 -> 0 | AF10: =Y10-AC10 -> 0 | AG10: =Z10-AD10 -> 0 | AI10: 0 | AK10: =SUM(AH10:AJ10) -> 0 | AL10: =SUMIF('ยอดจริง Week 1'!O:O,'Week 1'!F10,'ยอดจริง Week 1'!Q:Q) -> 0 | AM10: =SUMIF('ยอดจริง Week 1'!O:O,'Week 1'!F10,'ยอดจริง Week 1'!R:R) -> 0 | AN10: =SUMIF('ยอดจริง Week 1'!O:O,'Week 1'!F10,'ยอดจริง Week 1'!S:S) -> 0 | AO10: =AH10-AL10 -> 0 | AP10: =AI10-AM10 -> 0 | AQ10: =AJ10-AN10 -> 0 | AS10: 0 | AU10: =SUM(AR10:AT10) -> 0 | AV10: =SUMIF('ยอดจริง Week 1'!V:V,'Week 1'!F10,'ยอดจริง Week 1'!X:X) -> 0 | AW10: =SUMIF('ยอดจริง Week 1'!V:V,'Week 1'!F10,'ยอดจริง Week 1'!Y:Y) -> 0 | AX10: =SUMIF('ยอดจริง Week 1'!V:V,'Week 1'!F10,'ยอดจริง Week 1'!Z:Z) -> 0 | AY10: =AR10-AV10 -> 0 | AZ10: =AS10-AW10 -> 0 | BA10: =AT10-AX10 -> 0 | BE10: =SUM(BB10:BD10) -> 0 | BF10: =SUMIF('ยอดจริง Week 1'!AC:AC,'Week 1'!F10,'ยอดจริง Week 1'!AE:AE) -> 0 | BG10: =SUMIF('ยอดจริง Week 1'!AC:AC,'Week 1'!F10,'ยอดจริง Week 1'!AF:AF) -> 0 | BH10: =SUMIF('ยอดจริง Week 1'!AC:AC,'Week 1'!F10,'ยอดจริง Week 1'!AG:AG) -> 0 | BI10: =BB10-BF10 -> 0 | BJ10: =BC10-BG10 -> 0 | BK10: =BD10-BH10 -> 0 | BO10: =SUM(BL10:BN10) -> 0 | BP10: =SUMIF('ยอดจริง Week 1'!AJ:AJ,'Week 1'!F10,'ยอดจริง Week 1'!AL:AL) -> 0 | BQ10: =SUMIF('ยอดจริง Week 1'!AJ:AJ,'Week 1'!F10,'ยอดจริง Week 1'!AM:AM) -> 0 | BR10: =SUMIF('ยอดจริง Week 1'!AJ:AJ,'Week 1'!F10,'ยอดจริง Week 1'!AN:AN) -> 0 | BS10: =BL10-BP10 -> 0 | BT10: =BM10-BQ10 -> 0 | BU10: =BN10-BR10 -> 0 | BY10: =SUM(BV10:BX10) -> 0 | BZ10: =SUMIF('ยอดจริง Week 1'!AQ:AQ,'Week 1'!F10,'ยอดจริง Week 1'!AS:AS) -> 0 | CA10: =SUMIF('ยอดจริง Week 1'!AQ:AQ,'Week 1'!F10,'ยอดจริง Week 1'!AT:AT) -> 0 | CB10: =SUMIF('ยอดจริง Week 1'!AQ:AQ,'Week 1'!F10,'ยอดจริง Week 1'!AU:AU) -> 0 | CC10: =BV10-BZ10 -> 0 | CD10: =BW10-CA10 -> 0 | CE10: =BX10-CB10 -> 0
A11: 7 | F11: 1111036 | G11: ชิฟฟอนเค้ก วรรณวนัช ห่อกระดาษ (รวมรส 4 ชิ้น) | K11: =SUM(N11,X11,AH11,AR11,BB11,BL11,BV11) -> 0 | L11: =SUM(O11,Y11,AI11,AS11,BC11,BM11,BW11) -> 0 | O11: 0 | Q11: =SUM(N11:P11) -> 0 | R11: =SUMIF('ยอดจริง Week 1'!A:A,'Week 1'!F11,'ยอดจริง Week 1'!C:C) -> 0 | S11: =SUMIF('ยอดจริง Week 1'!A:A,'Week 1'!F11,'ยอดจริง Week 1'!D:D) -> 0 | T11: =SUMIF('ยอดจริง Week 1'!A:A,'Week 1'!F11,'ยอดจริง Week 1'!E:E) -> 0 | U11: =N11-R11 -> 0 | V11: =O11-S11 -> 0 | W11: =P11-T11 -> 0 | Y11: 0 | AA11: =SUM(X11:Z11) -> 0 | AB11: =SUMIF('ยอดจริง Week 1'!H:H,'Week 1'!F11,'ยอดจริง Week 1'!J:J) -> 0 | AC11: =SUMIF('ยอดจริง Week 1'!H:H,'Week 1'!F11,'ยอดจริง Week 1'!K:K) -> 0 | AD11: =SUMIF('ยอดจริง Week 1'!H:H,'Week 1'!F11,'ยอดจริง Week 1'!L:L) -> 0 | AE11: =X11-AB11 -> 0 | AF11: =Y11-AC11 -> 0 | AG11: =Z11-AD11 -> 0 | AI11: 0 | AK11: =SUM(AH11:AJ11) -> 0 | AL11: =SUMIF('ยอดจริง Week 1'!O:O,'Week 1'!F11,'ยอดจริง Week 1'!Q:Q) -> 0 | AM11: =SUMIF('ยอดจริง Week 1'!O:O,'Week 1'!F11,'ยอดจริง Week 1'!R:R) -> 0 | AN11: =SUMIF('ยอดจริง Week 1'!O:O,'Week 1'!F11,'ยอดจริง Week 1'!S:S) -> 0 | AO11: =AH11-AL11 -> 0 | AP11: =AI11-AM11 -> 0 | AQ11: =AJ11-AN11 -> 0 | AS11: 0 | AU11: =SUM(AR11:AT11) -> 0 | AV11: =SUMIF('ยอดจริง Week 1'!V:V,'Week 1'!F11,'ยอดจริง Week 1'!X:X) -> 0 | AW11: =SUMIF('ยอดจริง Week 1'!V:V,'Week 1'!F11,'ยอดจริง Week 1'!Y:Y) -> 0 | AX11: =SUMIF('ยอดจริง Week 1'!V:V,'Week 1'!F11,'ยอดจริง Week 1'!Z:Z) -> 0 | AY11: =AR11-AV11 -> 0 | AZ11: =AS11-AW11 -> 0 | BA11: =AT11-AX11 -> 0 | BE11: =SUM(BB11:BD11) -> 0 | BF11: =SUMIF('ยอดจริง Week 1'!AC:AC,'Week 1'!F11,'ยอดจริง Week 1'!AE:AE) -> 0 | BG11: =SUMIF('ยอดจริง Week 1'!AC:AC,'Week 1'!F11,'ยอดจริง Week 1'!AF:AF) -> 0 | BH11: =SUMIF('ยอดจริง Week 1'!AC:AC,'Week 1'!F11,'ยอดจริง Week 1'!AG:AG) -> 0 | BI11: =BB11-BF11 -> 0 | BJ11: =BC11-BG11 -> 0 | BK11: =BD11-BH11 -> 0 | BO11: =SUM(BL11:BN11) -> 0 | BP11: =SUMIF('ยอดจริง Week 1'!AJ:AJ,'Week 1'!F11,'ยอดจริง Week 1'!AL:AL) -> 0 | BQ11: =SUMIF('ยอดจริง Week 1'!AJ:AJ,'Week 1'!F11,'ยอดจริง Week 1'!AM:AM) -> 0 | BR11: =SUMIF('ยอดจริง Week 1'!AJ:AJ,'Week 1'!F11,'ยอดจริง Week 1'!AN:AN) -> 0 | BS11: =BL11-BP11 -> 0 | BT11: =BM11-BQ11 -> 0 | BU11: =BN11-BR11 -> 0 | BY11: =SUM(BV11:BX11) -> 0 | BZ11: =SUMIF('ยอดจริง Week 1'!AQ:AQ,'Week 1'!F11,'ยอดจริง Week 1'!AS:AS) -> 0 | CA11: =SUMIF('ยอดจริง Week 1'!AQ:AQ,'Week 1'!F11,'ยอดจริง Week 1'!AT:AT) -> 0 | CB11: =SUMIF('ยอดจริง Week 1'!AQ:AQ,'Week 1'!F11,'ยอดจริง Week 1'!AU:AU) -> 0 | CC11: =BV11-BZ11 -> 0 | CD11: =BW11-CA11 -> 0 | CE11: =BX11-CB11 -> 0
A12: 8 | F12: 1111037 | G12: ชิฟฟอนเค้ก วรรณวนัช ห่อกระดาษ (รวมรส 8 ชิ้น) | K12: =SUM(N12,X12,AH12,AR12,BB12,BL12,BV12) -> 0 | L12: =SUM(O12,Y12,AI12,AS12,BC12,BM12,BW12) -> 0 | O12: 0 | Q12: =SUM(N12:P12) -> 0 | R12: =SUMIF('ยอดจริง Week 1'!A:A,'Week 1'!F12,'ยอดจริง Week 1'!C:C) -> 0 | S12: =SUMIF('ยอดจริง Week 1'!A:A,'Week 1'!F12,'ยอดจริง Week 1'!D:D) -> 0 | T12: =SUMIF('ยอดจริง Week 1'!A:A,'Week 1'!F12,'ยอดจริง Week 1'!E:E) -> 0 | U12: =N12-R12 -> 0 | V12: =O12-S12 -> 0 | W12: =P12-T12 -> 0 | Y12: 0 | AA12: =SUM(X12:Z12) -> 0 | AB12: =SUMIF('ยอดจริง Week 1'!H:H,'Week 1'!F12,'ยอดจริง Week 1'!J:J) -> 0 | AC12: =SUMIF('ยอดจริง Week 1'!H:H,'Week 1'!F12,'ยอดจริง Week 1'!K:K) -> 0 | AD12: =SUMIF('ยอดจริง Week 1'!H:H,'Week 1'!F12,'ยอดจริง Week 1'!L:L) -> 0 | AE12: =X12-AB12 -> 0 | AF12: =Y12-AC12 -> 0 | AG12: =Z12-AD12 -> 0 | AI12: 0 | AK12: =SUM(AH12:AJ12) -> 0 | AL12: =SUMIF('ยอดจริง Week 1'!O:O,'Week 1'!F12,'ยอดจริง Week 1'!Q:Q) -> 0 | AM12: =SUMIF('ยอดจริง Week 1'!O:O,'Week 1'!F12,'ยอดจริง Week 1'!R:R) -> 0 | AN12: =SUMIF('ยอดจริง Week 1'!O:O,'Week 1'!F12,'ยอดจริง Week 1'!S:S) -> 0 | AO12: =AH12-AL12 -> 0 | AP12: =AI12-AM12 -> 0 | AQ12: =AJ12-AN12 -> 0 | AS12: 0 | AU12: =SUM(AR12:AT12) -> 0 | AV12: =SUMIF('ยอดจริง Week 1'!V:V,'Week 1'!F12,'ยอดจริง Week 1'!X:X) -> 0 | AW12: =SUMIF('ยอดจริง Week 1'!V:V,'Week 1'!F12,'ยอดจริง Week 1'!Y:Y) -> 0 | AX12: =SUMIF('ยอดจริง Week 1'!V:V,'Week 1'!F12,'ยอดจริง Week 1'!Z:Z) -> 0 | AY12: =AR12-AV12 -> 0 | AZ12: =AS12-AW12 -> 0 | BA12: =AT12-AX12 -> 0 | BE12: =SUM(BB12:BD12) -> 0 | BF12: =SUMIF('ยอดจริง Week 1'!AC:AC,'Week 1'!F12,'ยอดจริง Week 1'!AE:AE) -> 0 | BG12: =SUMIF('ยอดจริง Week 1'!AC:AC,'Week 1'!F12,'ยอดจริง Week 1'!AF:AF) -> 0 | BH12: =SUMIF('ยอดจริง Week 1'!AC:AC,'Week 1'!F12,'ยอดจริง Week 1'!AG:AG) -> 0 | BI12: =BB12-BF12 -> 0 | BJ12: =BC12-BG12 -> 0 | BK12: =BD12-BH12 -> 0 | BO12: =SUM(BL12:BN12) -> 0 | BP12: =SUMIF('ยอดจริง Week 1'!AJ:AJ,'Week 1'!F12,'ยอดจริง Week 1'!AL:AL) -> 0 | BQ12: =SUMIF('ยอดจริง Week 1'!AJ:AJ,'Week 1'!F12,'ยอดจริง Week 1'!AM:AM) -> 0 | BR12: =SUMIF('ยอดจริง Week 1'!AJ:AJ,'Week 1'!F12,'ยอดจริง Week 1'!AN:AN) -> 0 | BS12: =BL12-BP12 -> 0 | BT12: =BM12-BQ12 -> 0 | BU12: =BN12-BR12 -> 0 | BY12: =SUM(BV12:BX12) -> 0 | BZ12: =SUMIF('ยอดจริง Week 1'!AQ:AQ,'Week 1'!F12,'ยอดจริง Week 1'!AS:AS) -> 0 | CA12: =SUMIF('ยอดจริง Week 1'!AQ:AQ,'Week 1'!F12,'ยอดจริง Week 1'!AT:AT) -> 0 | CB12: =SUMIF('ยอดจริง Week 1'!AQ:AQ,'Week 1'!F12,'ยอดจริง Week 1'!AU:AU) -> 0 | CC12: =BV12-BZ12 -> 0 | CD12: =BW12-CA12 -> 0 | CE12: =BX12-CB12 -> 0
A13: 9 | F13: 1111040 | G13: ชิฟฟอนเค้กวรรณวนัช ห่อซีน (รวมรส 4 ชิ้น) | K13: =SUM(N13,X13,AH13,AR13,BB13,BL13,BV13) -> 0 | L13: =SUM(O13,Y13,AI13,AS13,BC13,BM13,BW13) -> 0 | O13: 0 | Q13: =SUM(N13:P13) -> 0 | R13: =SUMIF('ยอดจริง Week 1'!A:A,'Week 1'!F13,'ยอดจริง Week 1'!C:C) -> 0 | S13: =SUMIF('ยอดจริง Week 1'!A:A,'Week 1'!F13,'ยอดจริง Week 1'!D:D) -> 0 | T13: =SUMIF('ยอดจริง Week 1'!A:A,'Week 1'!F13,'ยอดจริง Week 1'!E:E) -> 0 | U13: =N13-R13 -> 0 | V13: =O13-S13 -> 0 | W13: =P13-T13 -> 0 | Y13: 0 | AA13: =SUM(X13:Z13) -> 0 | AB13: =SUMIF('ยอดจริง Week 1'!H:H,'Week 1'!F13,'ยอดจริง Week 1'!J:J) -> 0 | AC13: =SUMIF('ยอดจริง Week 1'!H:H,'Week 1'!F13,'ยอดจริง Week 1'!K:K) -> 0 | AD13: =SUMIF('ยอดจริง Week 1'!H:H,'Week 1'!F13,'ยอดจริง Week 1'!L:L) -> 0 | AE13: =X13-AB13 -> 0 | AF13: =Y13-AC13 -> 0 | AG13: =Z13-AD13 -> 0 | AI13: 0 | AK13: =SUM(AH13:AJ13) -> 0 | AL13: =SUMIF('ยอดจริง Week 1'!O:O,'Week 1'!F13,'ยอดจริง Week 1'!Q:Q) -> 0 | AM13: =SUMIF('ยอดจริง Week 1'!O:O,'Week 1'!F13,'ยอดจริง Week 1'!R:R) -> 0 | AN13: =SUMIF('ยอดจริง Week 1'!O:O,'Week 1'!F13,'ยอดจริง Week 1'!S:S) -> 0 | AO13: =AH13-AL13 -> 0 | AP13: =AI13-AM13 -> 0 | AQ13: =AJ13-AN13 -> 0 | AS13: 0 | AU13: =SUM(AR13:AT13) -> 0 | AV13: =SUMIF('ยอดจริง Week 1'!V:V,'Week 1'!F13,'ยอดจริง Week 1'!X:X) -> 0 | AW13: =SUMIF('ยอดจริง Week 1'!V:V,'Week 1'!F13,'ยอดจริง Week 1'!Y:Y) -> 0 | AX13: =SUMIF('ยอดจริง Week 1'!V:V,'Week 1'!F13,'ยอดจริง Week 1'!Z:Z) -> 0 | AY13: =AR13-AV13 -> 0 | AZ13: =AS13-AW13 -> 0 | BA13: =AT13-AX13 -> 0 | BE13: =SUM(BB13:BD13) -> 0 | BF13: =SUMIF('ยอดจริง Week 1'!AC:AC,'Week 1'!F13,'ยอดจริง Week 1'!AE:AE) -> 0 | BG13: =SUMIF('ยอดจริง Week 1'!AC:AC,'Week 1'!F13,'ยอดจริง Week 1'!AF:AF) -> 0 | BH13: =SUMIF('ยอดจริง Week 1'!AC:AC,'Week 1'!F13,'ยอดจริง Week 1'!AG:AG) -> 0 | BI13: =BB13-BF13 -> 0 | BJ13: =BC13-BG13 -> 0 | BK13: =BD13-BH13 -> 0 | BO13: =SUM(BL13:BN13) -> 0 | BP13: =SUMIF('ยอดจริง Week 1'!AJ:AJ,'Week 1'!F13,'ยอดจริง Week 1'!AL:AL) -> 0 | BQ13: =SUMIF('ยอดจริง Week 1'!AJ:AJ,'Week 1'!F13,'ยอดจริง Week 1'!AM:AM) -> 0 | BR13: =SUMIF('ยอดจริง Week 1'!AJ:AJ,'Week 1'!F13,'ยอดจริง Week 1'!AN:AN) -> 0 | BS13: =BL13-BP13 -> 0 | BT13: =BM13-BQ13 -> 0 | BU13: =BN13-BR13 -> 0 | BY13: =SUM(BV13:BX13) -> 0 | BZ13: =SUMIF('ยอดจริง Week 1'!AQ:AQ,'Week 1'!F13,'ยอดจริง Week 1'!AS:AS) -> 0 | CA13: =SUMIF('ยอดจริง Week 1'!AQ:AQ,'Week 1'!F13,'ยอดจริง Week 1'!AT:AT) -> 0 | CB13: =SUMIF('ยอดจริง Week 1'!AQ:AQ,'Week 1'!F13,'ยอดจริง Week 1'!AU:AU) -> 0 | CC13: =BV13-BZ13 -> 0 | CD13: =BW13-CA13 -> 0 | CE13: =BX13-CB13 -> 0
A14: 10 | F14: 1111039 | G14: ชิฟฟอนเค้ก วรรรณวนัช ห่อซีน (รวมรส 8 ชิ้น) | K14: =SUM(N14,X14,AH14,AR14,BB14,BL14,BV14) -> 0 | L14: =SUM(O14,Y14,AI14,AS14,BC14,BM14,BW14) -> 0 | O14: 0 | Q14: =SUM(N14:P14) -> 0 | R14: =SUMIF('ยอดจริง Week 1'!A:A,'Week 1'!F14,'ยอดจริง Week 1'!C:C) -> 0 | S14: =SUMIF('ยอดจริง Week 1'!A:A,'Week 1'!F14,'ยอดจริง Week 1'!D:D) -> 0 | T14: =SUMIF('ยอดจริง Week 1'!A:A,'Week 1'!F14,'ยอดจริง Week 1'!E:E) -> 0 | U14: =N14-R14 -> 0 | V14: =O14-S14 -> 0 | W14: =P14-T14 -> 0 | Y14: 0 | AA14: =SUM(X14:Z14) -> 0 | AB14: =SUMIF('ยอดจริง Week 1'!H:H,'Week 1'!F14,'ยอดจริง Week 1'!J:J) -> 0 | AC14: =SUMIF('ยอดจริง Week 1'!H:H,'Week 1'!F14,'ยอดจริง Week 1'!K:K) -> 0 | AD14: =SUMIF('ยอดจริง Week 1'!H:H,'Week 1'!F14,'ยอดจริง Week 1'!L:L) -> 0 | AE14: =X14-AB14 -> 0 | AF14: =Y14-AC14 -> 0 | AG14: =Z14-AD14 -> 0 | AI14: 0 | AK14: =SUM(AH14:AJ14) -> 0 | AL14: =SUMIF('ยอดจริง Week 1'!O:O,'Week 1'!F14,'ยอดจริง Week 1'!Q:Q) -> 0 | AM14: =SUMIF('ยอดจริง Week 1'!O:O,'Week 1'!F14,'ยอดจริง Week 1'!R:R) -> 0 | AN14: =SUMIF('ยอดจริง Week 1'!O:O,'Week 1'!F14,'ยอดจริง Week 1'!S:S) -> 0 | AO14: =AH14-AL14 -> 0 | AP14: =AI14-AM14 -> 0 | AQ14: =AJ14-AN14 -> 0 | AS14: 0 | AU14: =SUM(AR14:AT14) -> 0 | AV14: =SUMIF('ยอดจริง Week 1'!V:V,'Week 1'!F14,'ยอดจริง Week 1'!X:X) -> 0 | AW14: =SUMIF('ยอดจริง Week 1'!V:V,'Week 1'!F14,'ยอดจริง Week 1'!Y:Y) -> 0 | AX14: =SUMIF('ยอดจริง Week 1'!V:V,'Week 1'!F14,'ยอดจริง Week 1'!Z:Z) -> 0 | AY14: =AR14-AV14 -> 0 | AZ14: =AS14-AW14 -> 0 | BA14: =AT14-AX14 -> 0 | BE14: =SUM(BB14:BD14) -> 0 | BF14: =SUMIF('ยอดจริง Week 1'!AC:AC,'Week 1'!F14,'ยอดจริง Week 1'!AE:AE) -> 0 | BG14: =SUMIF('ยอดจริง Week 1'!AC:AC,'Week 1'!F14,'ยอดจริง Week 1'!AF:AF) -> 0 | BH14: =SUMIF('ยอดจริง Week 1'!AC:AC,'Week 1'!F14,'ยอดจริง Week 1'!AG:AG) -> 0 | BI14: =BB14-BF14 -> 0 | BJ14: =BC14-BG14 -> 0 | BK14: =BD14-BH14 -> 0 | BO14: =SUM(BL14:BN14) -> 0 | BP14: =SUMIF('ยอดจริง Week 1'!AJ:AJ,'Week 1'!F14,'ยอดจริง Week 1'!AL:AL) -> 0 | BQ14: =SUMIF('ยอดจริง Week 1'!AJ:AJ,'Week 1'!F14,'ยอดจริง Week 1'!AM:AM) -> 0 | BR14: =SUMIF('ยอดจริง Week 1'!AJ:AJ,'Week 1'!F14,'ยอดจริง Week 1'!AN:AN) -> 0 | BS14: =BL14-BP14 -> 0 | BT14: =BM14-BQ14 -> 0 | BU14: =BN14-BR14 -> 0 | BY14: =SUM(BV14:BX14) -> 0 | BZ14: =SUMIF('ยอดจริง Week 1'!AQ:AQ,'Week 1'!F14,'ยอดจริง Week 1'!AS:AS) -> 0 | CA14: =SUMIF('ยอดจริง Week 1'!AQ:AQ,'Week 1'!F14,'ยอดจริง Week 1'!AT:AT) -> 0 | CB14: =SUMIF('ยอดจริง Week 1'!AQ:AQ,'Week 1'!F14,'ยอดจริง Week 1'!AU:AU) -> 0 | CC14: =BV14-BZ14 -> 0 | CD14: =BW14-CA14 -> 0 | CE14: =BX14-CB14 -> 0
A15: 11 | F15: 1111041 | G15: ชิฟฟอนเค้ก วรรณวนัช กาแฟล้วน(รวมรส 4 ชิ้น) | K15: =SUM(N15,X15,AH15,AR15,BB15,BL15,BV15) -> 0 | L15: =SUM(O15,Y15,AI15,AS15,BC15,BM15,BW15) -> 0 | O15: 0 | Q15: =SUM(N15:P15) -> 0 | R15: =SUMIF('ยอดจริง Week 1'!A:A,'Week 1'!F15,'ยอดจริง Week 1'!C:C) -> 0 | S15: =SUMIF('ยอดจริง Week 1'!A:A,'Week 1'!F15,'ยอดจริง Week 1'!D:D) -> 0 | T15: =SUMIF('ยอดจริง Week 1'!A:A,'Week 1'!F15,'ยอดจริง Week 1'!E:E) -> 0 | U15: =N15-R15 -> 0 | V15: =O15-S15 -> 0 | W15: =P15-T15 -> 0 | Y15: 0 | AA15: =SUM(X15:Z15) -> 0 | AB15: =SUMIF('ยอดจริง Week 1'!H:H,'Week 1'!F15,'ยอดจริง Week 1'!J:J) -> 0 | AC15: =SUMIF('ยอดจริง Week 1'!H:H,'Week 1'!F15,'ยอดจริง Week 1'!K:K) -> 0 | AD15: =SUMIF('ยอดจริง Week 1'!H:H,'Week 1'!F15,'ยอดจริง Week 1'!L:L) -> 0 | AE15: =X15-AB15 -> 0 | AF15: =Y15-AC15 -> 0 | AG15: =Z15-AD15 -> 0 | AI15: 0 | AK15: =SUM(AH15:AJ15) -> 0 | AL15: =SUMIF('ยอดจริง Week 1'!O:O,'Week 1'!F15,'ยอดจริง Week 1'!Q:Q) -> 0 | AM15: =SUMIF('ยอดจริง Week 1'!O:O,'Week 1'!F15,'ยอดจริง Week 1'!R:R) -> 0 | AN15: =SUMIF('ยอดจริง Week 1'!O:O,'Week 1'!F15,'ยอดจริง Week 1'!S:S) -> 0 | AO15: =AH15-AL15 -> 0 | AP15: =AI15-AM15 -> 0 | AQ15: =AJ15-AN15 -> 0 | AS15: 0 | AU15: =SUM(AR15:AT15) -> 0 | AV15: =SUMIF('ยอดจริง Week 1'!V:V,'Week 1'!F15,'ยอดจริง Week 1'!X:X) -> 0 | AW15: =SUMIF('ยอดจริง Week 1'!V:V,'Week 1'!F15,'ยอดจริง Week 1'!Y:Y) -> 0 | AX15: =SUMIF('ยอดจริง Week 1'!V:V,'Week 1'!F15,'ยอดจริง Week 1'!Z:Z) -> 0 | AY15: =AR15-AV15 -> 0 | AZ15: =AS15-AW15 -> 0 | BA15: =AT15-AX15 -> 0 | BE15: =SUM(BB15:BD15) -> 0 | BF15: =SUMIF('ยอดจริง Week 1'!AC:AC,'Week 1'!F15,'ยอดจริง Week 1'!AE:AE) -> 0 | BG15: =SUMIF('ยอดจริง Week 1'!AC:AC,'Week 1'!F15,'ยอดจริง Week 1'!AF:AF) -> 0 | BH15: =SUMIF('ยอดจริง Week 1'!AC:AC,'Week 1'!F15,'ยอดจริง Week 1'!AG:AG) -> 0 | BI15: =BB15-BF15 -> 0 | BJ15: =BC15-BG15 -> 0 | BK15: =BD15-BH15 -> 0 | BO15: =SUM(BL15:BN15) -> 0 | BP15: =SUMIF('ยอดจริง Week 1'!AJ:AJ,'Week 1'!F15,'ยอดจริง Week 1'!AL:AL) -> 0 | BQ15: =SUMIF('ยอดจริง Week 1'!AJ:AJ,'Week 1'!F15,'ยอดจริง Week 1'!AM:AM) -> 0 | BR15: =SUMIF('ยอดจริง Week 1'!AJ:AJ,'Week 1'!F15,'ยอดจริง Week 1'!AN:AN) -> 0 | BS15: =BL15-BP15 -> 0 | BT15: =BM15-BQ15 -> 0 | BU15: =BN15-BR15 -> 0 | BY15: =SUM(BV15:BX15) -> 0 | BZ15: =SUMIF('ยอดจริง Week 1'!AQ:AQ,'Week 1'!F15,'ยอดจริง Week 1'!AS:AS) -> 0 | CA15: =SUMIF('ยอดจริง Week 1'!AQ:AQ,'Week 1'!F15,'ยอดจริง Week 1'!AT:AT) -> 0 | CB15: =SUMIF('ยอดจริง Week 1'!AQ:AQ,'Week 1'!F15,'ยอดจริง Week 1'!AU:AU) -> 0 | CC15: =BV15-BZ15 -> 0 | CD15: =BW15-CA15 -> 0 | CE15: =BX15-CB15 -> 0
A16: 12 | F16: 1111043 | G16: ชิฟฟ่อนรสมะลิ 8 ชิ้น ห่อ ซีน | K16: =SUM(N16,X16,AH16,AR16,BB16,BL16,BV16) -> 0 | L16: =SUM(O16,Y16,AI16,AS16,BC16,BM16,BW16) -> 0 | Q16: =SUM(N16:P16) -> 0 | R16: =SUMIF('ยอดจริง Week 1'!A:A,'Week 1'!F16,'ยอดจริง Week 1'!C:C) -> 0 | S16: =SUMIF('ยอดจริง Week 1'!A:A,'Week 1'!F16,'ยอดจริง Week 1'!D:D) -> 0 | T16: =SUMIF('ยอดจริง Week 1'!A:A,'Week 1'!F16,'ยอดจริง Week 1'!E:E) -> 0 | U16: =N16-R16 -> 0 | V16: =O16-S16 -> 0 | W16: =P16-T16 -> 0 | Y16: 0 | AA16: =SUM(X16:Z16) -> 0 | AB16: =SUMIF('ยอดจริง Week 1'!H:H,'Week 1'!F16,'ยอดจริง Week 1'!J:J) -> 0 | AC16: =SUMIF('ยอดจริง Week 1'!H:H,'Week 1'!F16,'ยอดจริง Week 1'!K:K) -> 0 | AD16: =SUMIF('ยอดจริง Week 1'!H:H,'Week 1'!F16,'ยอดจริง Week 1'!L:L) -> 0 | AE16: =X16-AB16 -> 0 | AF16: =Y16-AC16 -> 0 | AG16: =Z16-AD16 -> 0 | AI16: 0 | AK16: =SUM(AH16:AJ16) -> 0 | AL16: =SUMIF('ยอดจริง Week 1'!O:O,'Week 1'!F16,'ยอดจริง Week 1'!Q:Q) -> 0 | AM16: =SUMIF('ยอดจริง Week 1'!O:O,'Week 1'!F16,'ยอดจริง Week 1'!R:R) -> 0 | AN16: =SUMIF('ยอดจริง Week 1'!O:O,'Week 1'!F16,'ยอดจริง Week 1'!S:S) -> 0 | AO16: =AH16-AL16 -> 0 | AP16: =AI16-AM16 -> 0 | AQ16: =AJ16-AN16 -> 0 | AS16: 0 | AU16: =SUM(AR16:AT16) -> 0 | AV16: =SUMIF('ยอดจริง Week 1'!V:V,'Week 1'!F16,'ยอดจริง Week 1'!X:X) -> 0 | AW16: =SUMIF('ยอดจริง Week 1'!V:V,'Week 1'!F16,'ยอดจริง Week 1'!Y:Y) -> 0 | AX16: =SUMIF('ยอดจริง Week 1'!V:V,'Week 1'!F16,'ยอดจริง Week 1'!Z:Z) -> 0 | AY16: =AR16-AV16 -> 0 | AZ16: =AS16-AW16 -> 0 | BA16: =AT16-AX16 -> 0 | BE16: =SUM(BB16:BD16) -> 0 | BF16: =SUMIF('ยอดจริง Week 1'!AC:AC,'Week 1'!F16,'ยอดจริง Week 1'!AE:AE) -> 0 | BG16: =SUMIF('ยอดจริง Week 1'!AC:AC,'Week 1'!F16,'ยอดจริง Week 1'!AF:AF) -> 0 | BH16: =SUMIF('ยอดจริง Week 1'!AC:AC,'Week 1'!F16,'ยอดจริง Week 1'!AG:AG) -> 0 | BI16: =BB16-BF16 -> 0 | BJ16: =BC16-BG16 -> 0 | BK16: =BD16-BH16 -> 0 | BO16: =SUM(BL16:BN16) -> 0 | BP16: =SUMIF('ยอดจริง Week 1'!AJ:AJ,'Week 1'!F16,'ยอดจริง Week 1'!AL:AL) -> 0 | BQ16: =SUMIF('ยอดจริง Week 1'!AJ:AJ,'Week 1'!F16,'ยอดจริง Week 1'!AM:AM) -> 0 | BR16: =SUMIF('ยอดจริง Week 1'!AJ:AJ,'Week 1'!F16,'ยอดจริง Week 1'!AN:AN) -> 0 | BS16: =BL16-BP16 -> 0 | BT16: =BM16-BQ16 -> 0 | BU16: =BN16-BR16 -> 0 | BY16: =SUM(BV16:BX16) -> 0 | BZ16: =SUMIF('ยอดจริง Week 1'!AQ:AQ,'Week 1'!F16,'ยอดจริง Week 1'!AS:AS) -> 0 | CA16: =SUMIF('ยอดจริง Week 1'!AQ:AQ,'Week 1'!F16,'ยอดจริง Week 1'!AT:AT) -> 0 | CB16: =SUMIF('ยอดจริง Week 1'!AQ:AQ,'Week 1'!F16,'ยอดจริง Week 1'!AU:AU) -> 0 | CC16: =BV16-BZ16 -> 0 | CD16: =BW16-CA16 -> 0 | CE16: =BX16-CB16 -> 0
A17: 13 | F17: 1113091 | G17: (BC) ชิฟฟ่อนรวมรส 4 ชิ้น | H17: BC | K17: =SUM(N17,X17,AH17,AR17,BB17,BL17,BV17) -> 0 | L17: =SUM(O17,Y17,AI17,AS17,BC17,BM17,BW17) -> 0 | Q17: =SUM(N17:P17) -> 0 | R17: =SUMIF('ยอดจริง Week 1'!A:A,'Week 1'!F17,'ยอดจริง Week 1'!C:C) -> 0 | S17: =SUMIF('ยอดจริง Week 1'!A:A,'Week 1'!F17,'ยอดจริง Week 1'!D:D) -> 0 | T17: =SUMIF('ยอดจริง Week 1'!A:A,'Week 1'!F17,'ยอดจริง Week 1'!E:E) -> 0 | U17: =N17-R17 -> 0 | V17: =O17-S17 -> 0 | W17: =P17-T17 -> 0 | Y17: 0 | AA17: =SUM(X17:Z17) -> 0 | AB17: =SUMIF('ยอดจริง Week 1'!H:H,'Week 1'!F17,'ยอดจริง Week 1'!J:J) -> 0 | AC17: =SUMIF('ยอดจริง Week 1'!H:H,'Week 1'!F17,'ยอดจริง Week 1'!K:K) -> 0 | AD17: =SUMIF('ยอดจริง Week 1'!H:H,'Week 1'!F17,'ยอดจริง Week 1'!L:L) -> 0 | AE17: =X17-AB17 -> 0 | AF17: =Y17-AC17 -> 0 | AG17: =Z17-AD17 -> 0 | AI17: 0 | AK17: =SUM(AH17:AJ17) -> 0 | AL17: =SUMIF('ยอดจริง Week 1'!O:O,'Week 1'!F17,'ยอดจริง Week 1'!Q:Q) -> 0 | AM17: =SUMIF('ยอดจริง Week 1'!O:O,'Week 1'!F17,'ยอดจริง Week 1'!R:R) -> 0 | AN17: =SUMIF('ยอดจริง Week 1'!O:O,'Week 1'!F17,'ยอดจริง Week 1'!S:S) -> 0 | AO17: =AH17-AL17 -> 0 | AP17: =AI17-AM17 -> 0 | AQ17: =AJ17-AN17 -> 0 | AS17: 0 | AU17: =SUM(AR17:AT17) -> 0 | AV17: =SUMIF('ยอดจริง Week 1'!V:V,'Week 1'!F17,'ยอดจริง Week 1'!X:X) -> 0 | AW17: =SUMIF('ยอดจริง Week 1'!V:V,'Week 1'!F17,'ยอดจริง Week 1'!Y:Y) -> 0 | AX17: =SUMIF('ยอดจริง Week 1'!V:V,'Week 1'!F17,'ยอดจริง Week 1'!Z:Z) -> 0 | AY17: =AR17-AV17 -> 0 | AZ17: =AS17-AW17 -> 0 | BA17: =AT17-AX17 -> 0 | BE17: =SUM(BB17:BD17) -> 0 | BF17: =SUMIF('ยอดจริง Week 1'!AC:AC,'Week 1'!F17,'ยอดจริง Week 1'!AE:AE) -> 0 | BG17: =SUMIF('ยอดจริง Week 1'!AC:AC,'Week 1'!F17,'ยอดจริง Week 1'!AF:AF) -> 0 | BH17: =SUMIF('ยอดจริง Week 1'!AC:AC,'Week 1'!F17,'ยอดจริง Week 1'!AG:AG) -> 0 | BI17: =BB17-BF17 -> 0 | BJ17: =BC17-BG17 -> 0 | BK17: =BD17-BH17 -> 0 | BO17: =SUM(BL17:BN17) -> 0 | BP17: =SUMIF('ยอดจริง Week 1'!AJ:AJ,'Week 1'!F17,'ยอดจริง Week 1'!AL:AL) -> 0 | BQ17: =SUMIF('ยอดจริง Week 1'!AJ:AJ,'Week 1'!F17,'ยอดจริง Week 1'!AM:AM) -> 0 | BR17: =SUMIF('ยอดจริง Week 1'!AJ:AJ,'Week 1'!F17,'ยอดจริง Week 1'!AN:AN) -> 0 | BS17: =BL17-BP17 -> 0 | BT17: =BM17-BQ17 -> 0 | BU17: =BN17-BR17 -> 0 | BY17: =SUM(BV17:BX17) -> 0 | BZ17: =SUMIF('ยอดจริง Week 1'!AQ:AQ,'Week 1'!F17,'ยอดจริง Week 1'!AS:AS) -> 0 | CA17: =SUMIF('ยอดจริง Week 1'!AQ:AQ,'Week 1'!F17,'ยอดจริง Week 1'!AT:AT) -> 0 | CB17: =SUMIF('ยอดจริง Week 1'!AQ:AQ,'Week 1'!F17,'ยอดจริง Week 1'!AU:AU) -> 0 | CC17: =BV17-BZ17 -> 0 | CD17: =BW17-CA17 -> 0 | CE17: =BX17-CB17 -> 0
A18: 14 | F18: 1113083 | G18: (BC) ชิฟฟ่อนฝอยทอง 1 ชิ้น ไม่มีไส้ | K18: =SUM(N18,X18,AH18,AR18,BB18,BL18,BV18) -> 0 | L18: =SUM(O18,Y18,AI18,AS18,BC18,BM18,BW18) -> 0 | Q18: =SUM(N18:P18) -> 0 | R18: =SUMIF('ยอดจริง Week 1'!A:A,'Week 1'!F18,'ยอดจริง Week 1'!C:C) -> 0 | S18: =SUMIF('ยอดจริง Week 1'!A:A,'Week 1'!F18,'ยอดจริง Week 1'!D:D) -> 0 | T18: =SUMIF('ยอดจริง Week 1'!A:A,'Week 1'!F18,'ยอดจริง Week 1'!E:E) -> 0 | U18: =N18-R18 -> 0 | V18: =O18-S18 -> 0 | W18: =P18-T18 -> 0 | Y18: 0 | AA18: =SUM(X18:Z18) -> 0 | AB18: =SUMIF('ยอดจริง Week 1'!H:H,'Week 1'!F18,'ยอดจริง Week 1'!J:J) -> 0 | AC18: =SUMIF('ยอดจริง Week 1'!H:H,'Week 1'!F18,'ยอดจริง Week 1'!K:K) -> 0 | AD18: =SUMIF('ยอดจริง Week 1'!H:H,'Week 1'!F18,'ยอดจริง Week 1'!L:L) -> 0 | AE18: =X18-AB18 -> 0 | AF18: =Y18-AC18 -> 0 | AG18: =Z18-AD18 -> 0 | AI18: 0 | AK18: =SUM(AH18:AJ18) -> 0 | AL18: =SUMIF('ยอดจริง Week 1'!O:O,'Week 1'!F18,'ยอดจริง Week 1'!Q:Q) -> 0 | AM18: =SUMIF('ยอดจริง Week 1'!O:O,'Week 1'!F18,'ยอดจริง Week 1'!R:R) -> 0 | AN18: =SUMIF('ยอดจริง Week 1'!O:O,'Week 1'!F18,'ยอดจริง Week 1'!S:S) -> 0 | AO18: =AH18-AL18 -> 0 | AP18: =AI18-AM18 -> 0 | AQ18: =AJ18-AN18 -> 0 | AS18: 0 | AU18: =SUM(AR18:AT18) -> 0 | AV18: =SUMIF('ยอดจริง Week 1'!V:V,'Week 1'!F18,'ยอดจริง Week 1'!X:X) -> 0 | AW18: =SUMIF('ยอดจริง Week 1'!V:V,'Week 1'!F18,'ยอดจริง Week 1'!Y:Y) -> 0 | AX18: =SUMIF('ยอดจริง Week 1'!V:V,'Week 1'!F18,'ยอดจริง Week 1'!Z:Z) -> 0 | AY18: =AR18-AV18 -> 0 | AZ18: =AS18-AW18 -> 0 | BA18: =AT18-AX18 -> 0 | BE18: =SUM(BB18:BD18) -> 0 | BF18: =SUMIF('ยอดจริง Week 1'!AC:AC,'Week 1'!F18,'ยอดจริง Week 1'!AE:AE) -> 0 | BG18: =SUMIF('ยอดจริง Week 1'!AC:AC,'Week 1'!F18,'ยอดจริง Week 1'!AF:AF) -> 0 | BH18: =SUMIF('ยอดจริง Week 1'!AC:AC,'Week 1'!F18,'ยอดจริง Week 1'!AG:AG) -> 0 | BI18: =BB18-BF18 -> 0 | BJ18: =BC18-BG18 -> 0 | BK18: =BD18-BH18 -> 0 | BO18: =SUM(BL18:BN18) -> 0 | BP18: =SUMIF('ยอดจริง Week 1'!AJ:AJ,'Week 1'!F18,'ยอดจริง Week 1'!AL:AL) -> 0 | BQ18: =SUMIF('ยอดจริง Week 1'!AJ:AJ,'Week 1'!F18,'ยอดจริง Week 1'!AM:AM) -> 0 | BR18: =SUMIF('ยอดจริง Week 1'!AJ:AJ,'Week 1'!F18,'ยอดจริง Week 1'!AN:AN) -> 0 | BS18: =BL18-BP18 -> 0 | BT18: =BM18-BQ18 -> 0 | BU18: =BN18-BR18 -> 0 | BY18: =SUM(BV18:BX18) -> 0 | BZ18: =SUMIF('ยอดจริง Week 1'!AQ:AQ,'Week 1'!F18,'ยอดจริง Week 1'!AS:AS) -> 0 | CA18: =SUMIF('ยอดจริง Week 1'!AQ:AQ,'Week 1'!F18,'ยอดจริง Week 1'!AT:AT) -> 0 | CB18: =SUMIF('ยอดจริง Week 1'!AQ:AQ,'Week 1'!F18,'ยอดจริง Week 1'!AU:AU) -> 0 | CC18: =BV18-BZ18 -> 0 | CD18: =BW18-CA18 -> 0 | CE18: =BX18-CB18 -> 0
A19: 15 | F19: 1111057 | G19: ชิฟฟอนแยกชิ้น กาแฟ | K19: =SUM(N19,X19,AH19,AR19,BB19,BL19,BV19) -> 0 | L19: =SUM(O19,Y19,AI19,AS19,BC19,BM19,BW19) -> 0 | Q19: =SUM(N19:P19) -> 0 | R19: =SUMIF('ยอดจริง Week 1'!A:A,'Week 1'!F19,'ยอดจริง Week 1'!C:C) -> 0 | S19: =SUMIF('ยอดจริง Week 1'!A:A,'Week 1'!F19,'ยอดจริง Week 1'!D:D) -> 0 | T19: =SUMIF('ยอดจริง Week 1'!A:A,'Week 1'!F19,'ยอดจริง Week 1'!E:E) -> 0 | U19: =N19-R19 -> 0 | V19: =O19-S19 -> 0 | W19: =P19-T19 -> 0 | Y19: 0 | AA19: =SUM(X19:Z19) -> 0 | AB19: =SUMIF('ยอดจริง Week 1'!H:H,'Week 1'!F19,'ยอดจริง Week 1'!J:J) -> 0 | AC19: =SUMIF('ยอดจริง Week 1'!H:H,'Week 1'!F19,'ยอดจริง Week 1'!K:K) -> 0 | AD19: =SUMIF('ยอดจริง Week 1'!H:H,'Week 1'!F19,'ยอดจริง Week 1'!L:L) -> 0 | AE19: =X19-AB19 -> 0 | AF19: =Y19-AC19 -> 0 | AG19: =Z19-AD19 -> 0 | AI19: 0 | AK19: =SUM(AH19:AJ19) -> 0 | AL19: =SUMIF('ยอดจริง Week 1'!O:O,'Week 1'!F19,'ยอดจริง Week 1'!Q:Q) -> 0 | AM19: =SUMIF('ยอดจริง Week 1'!O:O,'Week 1'!F19,'ยอดจริง Week 1'!R:R) -> 0 | AN19: =SUMIF('ยอดจริง Week 1'!O:O,'Week 1'!F19,'ยอดจริง Week 1'!S:S) -> 0 | AO19: =AH19-AL19 -> 0 | AP19: =AI19-AM19 -> 0 | AQ19: =AJ19-AN19 -> 0 | AS19: 0 | AU19: =SUM(AR19:AT19) -> 0 | AV19: =SUMIF('ยอดจริง Week 1'!V:V,'Week 1'!F19,'ยอดจริง Week 1'!X:X) -> 0 | AW19: =SUMIF('ยอดจริง Week 1'!V:V,'Week 1'!F19,'ยอดจริง Week 1'!Y:Y) -> 0 | AX19: =SUMIF('ยอดจริง Week 1'!V:V,'Week 1'!F19,'ยอดจริง Week 1'!Z:Z) -> 0 | AY19: =AR19-AV19 -> 0 | AZ19: =AS19-AW19 -> 0 | BA19: =AT19-AX19 -> 0 | BE19: =SUM(BB19:BD19) -> 0 | BF19: =SUMIF('ยอดจริง Week 1'!AC:AC,'Week 1'!F19,'ยอดจริง Week 1'!AE:AE) -> 0 | BG19: =SUMIF('ยอดจริง Week 1'!AC:AC,'Week 1'!F19,'ยอดจริง Week 1'!AF:AF) -> 0 | BH19: =SUMIF('ยอดจริง Week 1'!AC:AC,'Week 1'!F19,'ยอดจริง Week 1'!AG:AG) -> 0 | BI19: =BB19-BF19 -> 0 | BJ19: =BC19-BG19 -> 0 | BK19: =BD19-BH19 -> 0 | BO19: =SUM(BL19:BN19) -> 0 | BP19: =SUMIF('ยอดจริง Week 1'!AJ:AJ,'Week 1'!F19,'ยอดจริง Week 1'!AL:AL) -> 0 | BQ19: =SUMIF('ยอดจริง Week 1'!AJ:AJ,'Week 1'!F19,'ยอดจริง Week 1'!AM:AM) -> 0 | BR19: =SUMIF('ยอดจริง Week 1'!AJ:AJ,'Week 1'!F19,'ยอดจริง Week 1'!AN:AN) -> 0 | BS19: =BL19-BP19 -> 0 | BT19: =BM19-BQ19 -> 0 | BU19: =BN19-BR19 -> 0 | BY19: =SUM(BV19:BX19) -> 0 | BZ19: =SUMIF('ยอดจริง Week 1'!AQ:AQ,'Week 1'!F19,'ยอดจริง Week 1'!AS:AS) -> 0 | CA19: =SUMIF('ยอดจริง Week 1'!AQ:AQ,'Week 1'!F19,'ยอดจริง Week 1'!AT:AT) -> 0 | CB19: =SUMIF('ยอดจริง Week 1'!AQ:AQ,'Week 1'!F19,'ยอดจริง Week 1'!AU:AU) -> 0 | CC19: =BV19-BZ19 -> 0 | CD19: =BW19-CA19 -> 0 | CE19: =BX19-CB19 -> 0
A20: 16 | F20: 1111058 | G20: ชิฟฟอนแยกชิ้น ชาเขียว | K20: =SUM(N20,X20,AH20,AR20,BB20,BL20,BV20) -> 0 | L20: =SUM(O20,Y20,AI20,AS20,BC20,BM20,BW20) -> 0 | Q20: =SUM(N20:P20) -> 0 | R20: =SUMIF('ยอดจริง Week 1'!A:A,'Week 1'!F20,'ยอดจริง Week 1'!C:C) -> 0 | S20: =SUMIF('ยอดจริง Week 1'!A:A,'Week 1'!F20,'ยอดจริง Week 1'!D:D) -> 0 | T20: =SUMIF('ยอดจริง Week 1'!A:A,'Week 1'!F20,'ยอดจริง Week 1'!E:E) -> 0 | U20: =N20-R20 -> 0 | V20: =O20-S20 -> 0 | W20: =P20-T20 -> 0 | Y20: 0 | AA20: =SUM(X20:Z20) -> 0 | AB20: =SUMIF('ยอดจริง Week 1'!H:H,'Week 1'!F20,'ยอดจริง Week 1'!J:J) -> 0 | AC20: =SUMIF('ยอดจริง Week 1'!H:H,'Week 1'!F20,'ยอดจริง Week 1'!K:K) -> 0 | AD20: =SUMIF('ยอดจริง Week 1'!H:H,'Week 1'!F20,'ยอดจริง Week 1'!L:L) -> 0 | AE20: =X20-AB20 -> 0 | AF20: =Y20-AC20 -> 0 | AG20: =Z20-AD20 -> 0 | AI20: 0 | AK20: =SUM(AH20:AJ20) -> 0 | AL20: =SUMIF('ยอดจริง Week 1'!O:O,'Week 1'!F20,'ยอดจริง Week 1'!Q:Q) -> 0 | AM20: =SUMIF('ยอดจริง Week 1'!O:O,'Week 1'!F20,'ยอดจริง Week 1'!R:R) -> 0 | AN20: =SUMIF('ยอดจริง Week 1'!O:O,'Week 1'!F20,'ยอดจริง Week 1'!S:S) -> 0 | AO20: =AH20-AL20 -> 0 | AP20: =AI20-AM20 -> 0 | AQ20: =AJ20-AN20 -> 0 | AS20: 0 | AU20: =SUM(AR20:AT20) -> 0 | AV20: =SUMIF('ยอดจริง Week 1'!V:V,'Week 1'!F20,'ยอดจริง Week 1'!X:X) -> 0 | AW20: =SUMIF('ยอดจริง Week 1'!V:V,'Week 1'!F20,'ยอดจริง Week 1'!Y:Y) -> 0 | AX20: =SUMIF('ยอดจริง Week 1'!V:V,'Week 1'!F20,'ยอดจริง Week 1'!Z:Z) -> 0 | AY20: =AR20-AV20 -> 0 | AZ20: =AS20-AW20 -> 0 | BA20: =AT20-AX20 -> 0 | BE20: =SUM(BB20:BD20) -> 0 | BF20: =SUMIF('ยอดจริง Week 1'!AC:AC,'Week 1'!F20,'ยอดจริง Week 1'!AE:AE) -> 0 | BG20: =SUMIF('ยอดจริง Week 1'!AC:AC,'Week 1'!F20,'ยอดจริง Week 1'!AF:AF) -> 0 | BH20: =SUMIF('ยอดจริง Week 1'!AC:AC,'Week 1'!F20,'ยอดจริง Week 1'!AG:AG) -> 0 | BI20: =BB20-BF20 -> 0 | BJ20: =BC20-BG20 -> 0 | BK20: =BD20-BH20 -> 0 | BO20: =SUM(BL20:BN20) -> 0 | BP20: =SUMIF('ยอดจริง Week 1'!AJ:AJ,'Week 1'!F20,'ยอดจริง Week 1'!AL:AL) -> 0 | BQ20: =SUMIF('ยอดจริง Week 1'!AJ:AJ,'Week 1'!F20,'ยอดจริง Week 1'!AM:AM) -> 0 | BR20: =SUMIF('ยอดจริง Week 1'!AJ:AJ,'Week 1'!F20,'ยอดจริง Week 1'!AN:AN) -> 0 | BS20: =BL20-BP20 -> 0 | BT20: =BM20-BQ20 -> 0 | BU20: =BN20-BR20 -> 0 | BY20: =SUM(BV20:BX20) -> 0 | BZ20: =SUMIF('ยอดจริง Week 1'!AQ:AQ,'Week 1'!F20,'ยอดจริง Week 1'!AS:AS) -> 0 | CA20: =SUMIF('ยอดจริง Week 1'!AQ:AQ,'Week 1'!F20,'ยอดจริง Week 1'!AT:AT) -> 0 | CB20: =SUMIF('ยอดจริง Week 1'!AQ:AQ,'Week 1'!F20,'ยอดจริง Week 1'!AU:AU) -> 0 | CC20: =BV20-BZ20 -> 0 | CD20: =BW20-CA20 -> 0 | CE20: =BX20-CB20 -> 0
A21: 17 | F21: 1111059 | G21: ชิฟฟอนแยกชิ้น ใบเตย | K21: =SUM(N21,X21,AH21,AR21,BB21,BL21,BV21) -> 0 | L21: =SUM(O21,Y21,AI21,AS21,BC21,BM21,BW21) -> 0 | Q21: =SUM(N21:P21) -> 0 | R21: =SUMIF('ยอดจริง Week 1'!A:A,'Week 1'!F21,'ยอดจริง Week 1'!C:C) -> 0 | S21: =SUMIF('ยอดจริง Week 1'!A:A,'Week 1'!F21,'ยอดจริง Week 1'!D:D) -> 0 | T21: =SUMIF('ยอดจริง Week 1'!A:A,'Week 1'!F21,'ยอดจริง Week 1'!E:E) -> 0 | U21: =N21-R21 -> 0 | V21: =O21-S21 -> 0 | W21: =P21-T21 -> 0 | Y21: 0 | AA21: =SUM(X21:Z21) -> 0 | AB21: =SUMIF('ยอดจริง Week 1'!H:H,'Week 1'!F21,'ยอดจริง Week 1'!J:J) -> 0 | AC21: =SUMIF('ยอดจริง Week 1'!H:H,'Week 1'!F21,'ยอดจริง Week 1'!K:K) -> 0 | AD21: =SUMIF('ยอดจริง Week 1'!H:H,'Week 1'!F21,'ยอดจริง Week 1'!L:L) -> 0 | AE21: =X21-AB21 -> 0 | AF21: =Y21-AC21 -> 0 | AG21: =Z21-AD21 -> 0 | AI21: 0 | AK21: =SUM(AH21:AJ21) -> 0 | AL21: =SUMIF('ยอดจริง Week 1'!O:O,'Week 1'!F21,'ยอดจริง Week 1'!Q:Q) -> 0 | AM21: =SUMIF('ยอดจริง Week 1'!O:O,'Week 1'!F21,'ยอดจริง Week 1'!R:R) -> 0 | AN21: =SUMIF('ยอดจริง Week 1'!O:O,'Week 1'!F21,'ยอดจริง Week 1'!S:S) -> 0 | AO21: =AH21-AL21 -> 0 | AP21: =AI21-AM21 -> 0 | AQ21: =AJ21-AN21 -> 0 | AS21: 0 | AU21: =SUM(AR21:AT21) -> 0 | AV21: =SUMIF('ยอดจริง Week 1'!V:V,'Week 1'!F21,'ยอดจริง Week 1'!X:X) -> 0 | AW21: =SUMIF('ยอดจริง Week 1'!V:V,'Week 1'!F21,'ยอดจริง Week 1'!Y:Y) -> 0 | AX21: =SUMIF('ยอดจริง Week 1'!V:V,'Week 1'!F21,'ยอดจริง Week 1'!Z:Z) -> 0 | AY21: =AR21-AV21 -> 0 | AZ21: =AS21-AW21 -> 0 | BA21: =AT21-AX21 -> 0 | BE21: =SUM(BB21:BD21) -> 0 | BF21: =SUMIF('ยอดจริง Week 1'!AC:AC,'Week 1'!F21,'ยอดจริง Week 1'!AE:AE) -> 0 | BG21: =SUMIF('ยอดจริง Week 1'!AC:AC,'Week 1'!F21,'ยอดจริง Week 1'!AF:AF) -> 0 | BH21: =SUMIF('ยอดจริง Week 1'!AC:AC,'Week 1'!F21,'ยอดจริง Week 1'!AG:AG) -> 0 | BI21: =BB21-BF21 -> 0 | BJ21: =BC21-BG21 -> 0 | BK21: =BD21-BH21 -> 0 | BO21: =SUM(BL21:BN21) -> 0 | BP21: =SUMIF('ยอดจริง Week 1'!AJ:AJ,'Week 1'!F21,'ยอดจริง Week 1'!AL:AL) -> 0 | BQ21: =SUMIF('ยอดจริง Week 1'!AJ:AJ,'Week 1'!F21,'ยอดจริง Week 1'!AM:AM) -> 0 | BR21: =SUMIF('ยอดจริง Week 1'!AJ:AJ,'Week 1'!F21,'ยอดจริง Week 1'!AN:AN) -> 0 | BS21: =BL21-BP21 -> 0 | BT21: =BM21-BQ21 -> 0 | BU21: =BN21-BR21 -> 0 | BY21: =SUM(BV21:BX21) -> 0 | BZ21: =SUMIF('ยอดจริง Week 1'!AQ:AQ,'Week 1'!F21,'ยอดจริง Week 1'!AS:AS) -> 0 | CA21: =SUMIF('ยอดจริง Week 1'!AQ:AQ,'Week 1'!F21,'ยอดจริง Week 1'!AT:AT) -> 0 | CB21: =SUMIF('ยอดจริง Week 1'!AQ:AQ,'Week 1'!F21,'ยอดจริง Week 1'!AU:AU) -> 0 | CC21: =BV21-BZ21 -> 0 | CD21: =BW21-CA21 -> 0 | CE21: =BX21-CB21 -> 0
A22: 18 | F22: 1111060 | G22: ชิฟฟอนแยกชิ้น กล้วยหอม | K22: =SUM(N22,X22,AH22,AR22,BB22,BL22,BV22) -> 0 | L22: =SUM(O22,Y22,AI22,AS22,BC22,BM22,BW22) -> 0 | Q22: =SUM(N22:P22) -> 0 | R22: =SUMIF('ยอดจริง Week 1'!A:A,'Week 1'!F22,'ยอดจริง Week 1'!C:C) -> 0 | S22: =SUMIF('ยอดจริง Week 1'!A:A,'Week 1'!F22,'ยอดจริง Week 1'!D:D) -> 0 | T22: =SUMIF('ยอดจริง Week 1'!A:A,'Week 1'!F22,'ยอดจริง Week 1'!E:E) -> 0 | U22: =N22-R22 -> 0 | V22: =O22-S22 -> 0 | W22: =P22-T22 -> 0 | Y22: 0 | AA22: =SUM(X22:Z22) -> 0 | AB22: =SUMIF('ยอดจริง Week 1'!H:H,'Week 1'!F22,'ยอดจริง Week 1'!J:J) -> 0 | AC22: =SUMIF('ยอดจริง Week 1'!H:H,'Week 1'!F22,'ยอดจริง Week 1'!K:K) -> 0 | AD22: =SUMIF('ยอดจริง Week 1'!H:H,'Week 1'!F22,'ยอดจริง Week 1'!L:L) -> 0 | AE22: =X22-AB22 -> 0 | AF22: =Y22-AC22 -> 0 | AG22: =Z22-AD22 -> 0 | AI22: 0 | AK22: =SUM(AH22:AJ22) -> 0 | AL22: =SUMIF('ยอดจริง Week 1'!O:O,'Week 1'!F22,'ยอดจริง Week 1'!Q:Q) -> 0 | AM22: =SUMIF('ยอดจริง Week 1'!O:O,'Week 1'!F22,'ยอดจริง Week 1'!R:R) -> 0 | AN22: =SUMIF('ยอดจริง Week 1'!O:O,'Week 1'!F22,'ยอดจริง Week 1'!S:S) -> 0 | AO22: =AH22-AL22 -> 0 | AP22: =AI22-AM22 -> 0 | AQ22: =AJ22-AN22 -> 0 | AS22: 0 | AU22: =SUM(AR22:AT22) -> 0 | AV22: =SUMIF('ยอดจริง Week 1'!V:V,'Week 1'!F22,'ยอดจริง Week 1'!X:X) -> 0 | AW22: =SUMIF('ยอดจริง Week 1'!V:V,'Week 1'!F22,'ยอดจริง Week 1'!Y:Y) -> 0 | AX22: =SUMIF('ยอดจริง Week 1'!V:V,'Week 1'!F22,'ยอดจริง Week 1'!Z:Z) -> 0 | AY22: =AR22-AV22 -> 0 | AZ22: =AS22-AW22 -> 0 | BA22: =AT22-AX22 -> 0 | BE22: =SUM(BB22:BD22) -> 0 | BF22: =SUMIF('ยอดจริง Week 1'!AC:AC,'Week 1'!F22,'ยอดจริง Week 1'!AE:AE) -> 0 | BG22: =SUMIF('ยอดจริง Week 1'!AC:AC,'Week 1'!F22,'ยอดจริง Week 1'!AF:AF) -> 0 | BH22: =SUMIF('ยอดจริง Week 1'!AC:AC,'Week 1'!F22,'ยอดจริง Week 1'!AG:AG) -> 0 | BI22: =BB22-BF22 -> 0 | BJ22: =BC22-BG22 -> 0 | BK22: =BD22-BH22 -> 0 | BO22: =SUM(BL22:BN22) -> 0 | BP22: =SUMIF('ยอดจริง Week 1'!AJ:AJ,'Week 1'!F22,'ยอดจริง Week 1'!AL:AL) -> 0 | BQ22: =SUMIF('ยอดจริง Week 1'!AJ:AJ,'Week 1'!F22,'ยอดจริง Week 1'!AM:AM) -> 0 | BR22: =SUMIF('ยอดจริง Week 1'!AJ:AJ,'Week 1'!F22,'ยอดจริง Week 1'!AN:AN) -> 0 | BS22: =BL22-BP22 -> 0 | BT22: =BM22-BQ22 -> 0 | BU22: =BN22-BR22 -> 0 | BY22: =SUM(BV22:BX22) -> 0 | BZ22: =SUMIF('ยอดจริง Week 1'!AQ:AQ,'Week 1'!F22,'ยอดจริง Week 1'!AS:AS) -> 0 | CA22: =SUMIF('ยอดจริง Week 1'!AQ:AQ,'Week 1'!F22,'ยอดจริง Week 1'!AT:AT) -> 0 | CB22: =SUMIF('ยอดจริง Week 1'!AQ:AQ,'Week 1'!F22,'ยอดจริง Week 1'!AU:AU) -> 0 | CC22: =BV22-BZ22 -> 0 | CD22: =BW22-CA22 -> 0 | CE22: =BX22-CB22 -> 0
A23: 19 | F23: 1111061 | G23: ชิฟฟอนแยกชิ้น ชาไทย | K23: =SUM(N23,X23,AH23,AR23,BB23,BL23,BV23) -> 0 | L23: =SUM(O23,Y23,AI23,AS23,BC23,BM23,BW23) -> 0 | Q23: =SUM(N23:P23) -> 0 | R23: =SUMIF('ยอดจริง Week 1'!A:A,'Week 1'!F23,'ยอดจริง Week 1'!C:C) -> 0 | S23: =SUMIF('ยอดจริง Week 1'!A:A,'Week 1'!F23,'ยอดจริง Week 1'!D:D) -> 0 | T23: =SUMIF('ยอดจริง Week 1'!A:A,'Week 1'!F23,'ยอดจริง Week 1'!E:E) -> 0 | U23: =N23-R23 -> 0 | V23: =O23-S23 -> 0 | W23: =P23-T23 -> 0 | Y23: 0 | AA23: =SUM(X23:Z23) -> 0 | AB23: =SUMIF('ยอดจริง Week 1'!H:H,'Week 1'!F23,'ยอดจริง Week 1'!J:J) -> 0 | AC23: =SUMIF('ยอดจริง Week 1'!H:H,'Week 1'!F23,'ยอดจริง Week 1'!K:K) -> 0 | AD23: =SUMIF('ยอดจริง Week 1'!H:H,'Week 1'!F23,'ยอดจริง Week 1'!L:L) -> 0 | AE23: =X23-AB23 -> 0 | AF23: =Y23-AC23 -> 0 | AG23: =Z23-AD23 -> 0 | AI23: 0 | AK23: =SUM(AH23:AJ23) -> 0 | AL23: =SUMIF('ยอดจริง Week 1'!O:O,'Week 1'!F23,'ยอดจริง Week 1'!Q:Q) -> 0 | AM23: =SUMIF('ยอดจริง Week 1'!O:O,'Week 1'!F23,'ยอดจริง Week 1'!R:R) -> 0 | AN23: =SUMIF('ยอดจริง Week 1'!O:O,'Week 1'!F23,'ยอดจริง Week 1'!S:S) -> 0 | AO23: =AH23-AL23 -> 0 | AP23: =AI23-AM23 -> 0 | AQ23: =AJ23-AN23 -> 0 | AS23: 0 | AU23: =SUM(AR23:AT23) -> 0 | AV23: =SUMIF('ยอดจริง Week 1'!V:V,'Week 1'!F23,'ยอดจริง Week 1'!X:X) -> 0 | AW23: =SUMIF('ยอดจริง Week 1'!V:V,'Week 1'!F23,'ยอดจริง Week 1'!Y:Y) -> 0 | AX23: =SUMIF('ยอดจริง Week 1'!V:V,'Week 1'!F23,'ยอดจริง Week 1'!Z:Z) -> 0 | AY23: =AR23-AV23 -> 0 | AZ23: =AS23-AW23 -> 0 | BA23: =AT23-AX23 -> 0 | BE23: =SUM(BB23:BD23) -> 0 | BF23: =SUMIF('ยอดจริง Week 1'!AC:AC,'Week 1'!F23,'ยอดจริง Week 1'!AE:AE) -> 0 | BG23: =SUMIF('ยอดจริง Week 1'!AC:AC,'Week 1'!F23,'ยอดจริง Week 1'!AF:AF) -> 0 | BH23: =SUMIF('ยอดจริง Week 1'!AC:AC,'Week 1'!F23,'ยอดจริง Week 1'!AG:AG) -> 0 | BI23: =BB23-BF23 -> 0 | BJ23: =BC23-BG23 -> 0 | BK23: =BD23-BH23 -> 0 | BO23: =SUM(BL23:BN23) -> 0 | BP23: =SUMIF('ยอดจริง Week 1'!AJ:AJ,'Week 1'!F23,'ยอดจริง Week 1'!AL:AL) -> 0 | BQ23: =SUMIF('ยอดจริง Week 1'!AJ:AJ,'Week 1'!F23,'ยอดจริง Week 1'!AM:AM) -> 0 | BR23: =SUMIF('ยอดจริง Week 1'!AJ:AJ,'Week 1'!F23,'ยอดจริง Week 1'!AN:AN) -> 0 | BS23: =BL23-BP23 -> 0 | BT23: =BM23-BQ23 -> 0 | BU23: =BN23-BR23 -> 0 | BY23: =SUM(BV23:BX23) -> 0 | BZ23: =SUMIF('ยอดจริง Week 1'!AQ:AQ,'Week 1'!F23,'ยอดจริง Week 1'!AS:AS) -> 0 | CA23: =SUMIF('ยอดจริง Week 1'!AQ:AQ,'Week 1'!F23,'ยอดจริง Week 1'!AT:AT) -> 0 | CB23: =SUMIF('ยอดจริง Week 1'!AQ:AQ,'Week 1'!F23,'ยอดจริง Week 1'!AU:AU) -> 0 | CC23: =BV23-BZ23 -> 0 | CD23: =BW23-CA23 -> 0 | CE23: =BX23-CB23 -> 0
A24: 20 | F24: 1111062 | G24: ชิฟฟอนแยกชิ้น โกโก้ | K24: =SUM(N24,X24,AH24,AR24,BB24,BL24,BV24) -> 0 | L24: =SUM(O24,Y24,AI24,AS24,BC24,BM24,BW24) -> 0 | Q24: =SUM(N24:P24) -> 0 | R24: =SUMIF('ยอดจริง Week 1'!A:A,'Week 1'!F24,'ยอดจริง Week 1'!C:C) -> 0 | S24: =SUMIF('ยอดจริง Week 1'!A:A,'Week 1'!F24,'ยอดจริง Week 1'!D:D) -> 0 | T24: =SUMIF('ยอดจริง Week 1'!A:A,'Week 1'!F24,'ยอดจริง Week 1'!E:E) -> 0 | U24: =N24-R24 -> 0 | V24: =O24-S24 -> 0 | W24: =P24-T24 -> 0 | Y24: 0 | AA24: =SUM(X24:Z24) -> 0 | AB24: =SUMIF('ยอดจริง Week 1'!H:H,'Week 1'!F24,'ยอดจริง Week 1'!J:J) -> 0 | AC24: =SUMIF('ยอดจริง Week 1'!H:H,'Week 1'!F24,'ยอดจริง Week 1'!K:K) -> 0 | AD24: =SUMIF('ยอดจริง Week 1'!H:H,'Week 1'!F24,'ยอดจริง Week 1'!L:L) -> 0 | AE24: =X24-AB24 -> 0 | AF24: =Y24-AC24 -> 0 | AG24: =Z24-AD24 -> 0 | AI24: 0 | AK24: =SUM(AH24:AJ24) -> 0 | AL24: =SUMIF('ยอดจริง Week 1'!O:O,'Week 1'!F24,'ยอดจริง Week 1'!Q:Q) -> 0 | AM24: =SUMIF('ยอดจริง Week 1'!O:O,'Week 1'!F24,'ยอดจริง Week 1'!R:R) -> 0 | AN24: =SUMIF('ยอดจริง Week 1'!O:O,'Week 1'!F24,'ยอดจริง Week 1'!S:S) -> 0 | AO24: =AH24-AL24 -> 0 | AP24: =AI24-AM24 -> 0 | AQ24: =AJ24-AN24 -> 0 | AS24: 0 | AU24: =SUM(AR24:AT24) -> 0 | AV24: =SUMIF('ยอดจริง Week 1'!V:V,'Week 1'!F24,'ยอดจริง Week 1'!X:X) -> 0 | AW24: =SUMIF('ยอดจริง Week 1'!V:V,'Week 1'!F24,'ยอดจริง Week 1'!Y:Y) -> 0 | AX24: =SUMIF('ยอดจริง Week 1'!V:V,'Week 1'!F24,'ยอดจริง Week 1'!Z:Z) -> 0 | AY24: =AR24-AV24 -> 0 | AZ24: =AS24-AW24 -> 0 | BA24: =AT24-AX24 -> 0 | BE24: =SUM(BB24:BD24) -> 0 | BF24: =SUMIF('ยอดจริง Week 1'!AC:AC,'Week 1'!F24,'ยอดจริง Week 1'!AE:AE) -> 0 | BG24: =SUMIF('ยอดจริง Week 1'!AC:AC,'Week 1'!F24,'ยอดจริง Week 1'!AF:AF) -> 0 | BH24: =SUMIF('ยอดจริง Week 1'!AC:AC,'Week 1'!F24,'ยอดจริง Week 1'!AG:AG) -> 0 | BI24: =BB24-BF24 -> 0 | BJ24: =BC24-BG24 -> 0 | BK24: =BD24-BH24 -> 0 | BO24: =SUM(BL24:BN24) -> 0 | BP24: =SUMIF('ยอดจริง Week 1'!AJ:AJ,'Week 1'!F24,'ยอดจริง Week 1'!AL:AL) -> 0 | BQ24: =SUMIF('ยอดจริง Week 1'!AJ:AJ,'Week 1'!F24,'ยอดจริง Week 1'!AM:AM) -> 0 | BR24: =SUMIF('ยอดจริง Week 1'!AJ:AJ,'Week 1'!F24,'ยอดจริง Week 1'!AN:AN) -> 0 | BS24: =BL24-BP24 -> 0 | BT24: =BM24-BQ24 -> 0 | BU24: =BN24-BR24 -> 0 | BY24: =SUM(BV24:BX24) -> 0 | BZ24: =SUMIF('ยอดจริง Week 1'!AQ:AQ,'Week 1'!F24,'ยอดจริง Week 1'!AS:AS) -> 0 | CA24: =SUMIF('ยอดจริง Week 1'!AQ:AQ,'Week 1'!F24,'ยอดจริง Week 1'!AT:AT) -> 0 | CB24: =SUMIF('ยอดจริง Week 1'!AQ:AQ,'Week 1'!F24,'ยอดจริง Week 1'!AU:AU) -> 0 | CC24: =BV24-BZ24 -> 0 | CD24: =BW24-CA24 -> 0 | CE24: =BX24-CB24 -> 0
A25: 21 | F25: 1111063 | G25: ชิฟฟอนแยกชิ้น ส้ม | K25: =SUM(N25,X25,AH25,AR25,BB25,BL25,BV25) -> 0 | L25: =SUM(O25,Y25,AI25,AS25,BC25,BM25,BW25) -> 0 | Q25: =SUM(N25:P25) -> 0 | R25: =SUMIF('ยอดจริง Week 1'!A:A,'Week 1'!F25,'ยอดจริง Week 1'!C:C) -> 0 | S25: =SUMIF('ยอดจริง Week 1'!A:A,'Week 1'!F25,'ยอดจริง Week 1'!D:D) -> 0 | T25: =SUMIF('ยอดจริง Week 1'!A:A,'Week 1'!F25,'ยอดจริง Week 1'!E:E) -> 0 | U25: =N25-R25 -> 0 | V25: =O25-S25 -> 0 | W25: =P25-T25 -> 0 | Y25: 0 | AA25: =SUM(X25:Z25) -> 0 | AB25: =SUMIF('ยอดจริง Week 1'!H:H,'Week 1'!F25,'ยอดจริง Week 1'!J:J) -> 0 | AC25: =SUMIF('ยอดจริง Week 1'!H:H,'Week 1'!F25,'ยอดจริง Week 1'!K:K) -> 0 | AD25: =SUMIF('ยอดจริง Week 1'!H:H,'Week 1'!F25,'ยอดจริง Week 1'!L:L) -> 0 | AE25: =X25-AB25 -> 0 | AF25: =Y25-AC25 -> 0 | AG25: =Z25-AD25 -> 0 | AI25: 0 | AK25: =SUM(AH25:AJ25) -> 0 | AL25: =SUMIF('ยอดจริง Week 1'!O:O,'Week 1'!F25,'ยอดจริง Week 1'!Q:Q) -> 0 | AM25: =SUMIF('ยอดจริง Week 1'!O:O,'Week 1'!F25,'ยอดจริง Week 1'!R:R) -> 0 | AN25: =SUMIF('ยอดจริง Week 1'!O:O,'Week 1'!F25,'ยอดจริง Week 1'!S:S) -> 0 | AO25: =AH25-AL25 -> 0 | AP25: =AI25-AM25 -> 0 | AQ25: =AJ25-AN25 -> 0 | AS25: 0 | AU25: =SUM(AR25:AT25) -> 0 | AV25: =SUMIF('ยอดจริง Week 1'!V:V,'Week 1'!F25,'ยอดจริง Week 1'!X:X) -> 0 | AW25: =SUMIF('ยอดจริง Week 1'!V:V,'Week 1'!F25,'ยอดจริง Week 1'!Y:Y) -> 0 | AX25: =SUMIF('ยอดจริง Week 1'!V:V,'Week 1'!F25,'ยอดจริง Week 1'!Z:Z) -> 0 | AY25: =AR25-AV25 -> 0 | AZ25: =AS25-AW25 -> 0 | BA25: =AT25-AX25 -> 0 | BE25: =SUM(BB25:BD25) -> 0 | BF25: =SUMIF('ยอดจริง Week 1'!AC:AC,'Week 1'!F25,'ยอดจริง Week 1'!AE:AE) -> 0 | BG25: =SUMIF('ยอดจริง Week 1'!AC:AC,'Week 1'!F25,'ยอดจริง Week 1'!AF:AF) -> 0 | BH25: =SUMIF('ยอดจริง Week 1'!AC:AC,'Week 1'!F25,'ยอดจริง Week 1'!AG:AG) -> 0 | BI25: =BB25-BF25 -> 0 | BJ25: =BC25-BG25 -> 0 | BK25: =BD25-BH25 -> 0 | BO25: =SUM(BL25:BN25) -> 0 | BP25: =SUMIF('ยอดจริง Week 1'!AJ:AJ,'Week 1'!F25,'ยอดจริง Week 1'!AL:AL) -> 0 | BQ25: =SUMIF('ยอดจริง Week 1'!AJ:AJ,'Week 1'!F25,'ยอดจริง Week 1'!AM:AM) -> 0 | BR25: =SUMIF('ยอดจริง Week 1'!AJ:AJ,'Week 1'!F25,'ยอดจริง Week 1'!AN:AN) -> 0 | BS25: =BL25-BP25 -> 0 | BT25: =BM25-BQ25 -> 0 | BU25: =BN25-BR25 -> 0 | BY25: =SUM(BV25:BX25) -> 0 | BZ25: =SUMIF('ยอดจริง Week 1'!AQ:AQ,'Week 1'!F25,'ยอดจริง Week 1'!AS:AS) -> 0 | CA25: =SUMIF('ยอดจริง Week 1'!AQ:AQ,'Week 1'!F25,'ยอดจริง Week 1'!AT:AT) -> 0 | CB25: =SUMIF('ยอดจริง Week 1'!AQ:AQ,'Week 1'!F25,'ยอดจริง Week 1'!AU:AU) -> 0 | CC25: =BV25-BZ25 -> 0 | CD25: =BW25-CA25 -> 0 | CE25: =BX25-CB25 -> 0
A26: 22 | F26: 1111064 | G26: ชิฟฟอนแยกชิ้น เผือก | K26: =SUM(N26,X26,AH26,AR26,BB26,BL26,BV26) -> 0 | L26: =SUM(O26,Y26,AI26,AS26,BC26,BM26,BW26) -> 0 | Q26: =SUM(N26:P26) -> 0 | R26: =SUMIF('ยอดจริง Week 1'!A:A,'Week 1'!F26,'ยอดจริง Week 1'!C:C) -> 0 | S26: =SUMIF('ยอดจริง Week 1'!A:A,'Week 1'!F26,'ยอดจริง Week 1'!D:D) -> 0 | T26: =SUMIF('ยอดจริง Week 1'!A:A,'Week 1'!F26,'ยอดจริง Week 1'!E:E) -> 0 | U26: =N26-R26 -> 0 | V26: =O26-S26 -> 0 | W26: =P26-T26 -> 0 | Y26: 0 | AA26: =SUM(X26:Z26) -> 0 | AB26: =SUMIF('ยอดจริง Week 1'!H:H,'Week 1'!F26,'ยอดจริง Week 1'!J:J) -> 0 | AC26: =SUMIF('ยอดจริง Week 1'!H:H,'Week 1'!F26,'ยอดจริง Week 1'!K:K) -> 0 | AD26: =SUMIF('ยอดจริง Week 1'!H:H,'Week 1'!F26,'ยอดจริง Week 1'!L:L) -> 0 | AE26: =X26-AB26 -> 0 | AF26: =Y26-AC26 -> 0 | AG26: =Z26-AD26 -> 0 | AI26: 0 | AK26: =SUM(AH26:AJ26) -> 0 | AL26: =SUMIF('ยอดจริง Week 1'!O:O,'Week 1'!F26,'ยอดจริง Week 1'!Q:Q) -> 0 | AM26: =SUMIF('ยอดจริง Week 1'!O:O,'Week 1'!F26,'ยอดจริง Week 1'!R:R) -> 0 | AN26: =SUMIF('ยอดจริง Week 1'!O:O,'Week 1'!F26,'ยอดจริง Week 1'!S:S) -> 0 | AO26: =AH26-AL26 -> 0 | AP26: =AI26-AM26 -> 0 | AQ26: =AJ26-AN26 -> 0 | AS26: 0 | AU26: =SUM(AR26:AT26) -> 0 | AV26: =SUMIF('ยอดจริง Week 1'!V:V,'Week 1'!F26,'ยอดจริง Week 1'!X:X) -> 0 | AW26: =SUMIF('ยอดจริง Week 1'!V:V,'Week 1'!F26,'ยอดจริง Week 1'!Y:Y) -> 0 | AX26: =SUMIF('ยอดจริง Week 1'!V:V,'Week 1'!F26,'ยอดจริง Week 1'!Z:Z) -> 0 | AY26: =AR26-AV26 -> 0 | AZ26: =AS26-AW26 -> 0 | BA26: =AT26-AX26 -> 0 | BE26: =SUM(BB26:BD26) -> 0 | BF26: =SUMIF('ยอดจริง Week 1'!AC:AC,'Week 1'!F26,'ยอดจริง Week 1'!AE:AE) -> 0 | BG26: =SUMIF('ยอดจริง Week 1'!AC:AC,'Week 1'!F26,'ยอดจริง Week 1'!AF:AF) -> 0 | BH26: =SUMIF('ยอดจริง Week 1'!AC:AC,'Week 1'!F26,'ยอดจริง Week 1'!AG:AG) -> 0 | BI26: =BB26-BF26 -> 0 | BJ26: =BC26-BG26 -> 0 | BK26: =BD26-BH26 -> 0 | BO26: =SUM(BL26:BN26) -> 0 | BP26: =SUMIF('ยอดจริง Week 1'!AJ:AJ,'Week 1'!F26,'ยอดจริง Week 1'!AL:AL) -> 0 | BQ26: =SUMIF('ยอดจริง Week 1'!AJ:AJ,'Week 1'!F26,'ยอดจริง Week 1'!AM:AM) -> 0 | BR26: =SUMIF('ยอดจริง Week 1'!AJ:AJ,'Week 1'!F26,'ยอดจริง Week 1'!AN:AN) -> 0 | BS26: =BL26-BP26 -> 0 | BT26: =BM26-BQ26 -> 0 | BU26: =BN26-BR26 -> 0 | BY26: =SUM(BV26:BX26) -> 0 | BZ26: =SUMIF('ยอดจริง Week 1'!AQ:AQ,'Week 1'!F26,'ยอดจริง Week 1'!AS:AS) -> 0 | CA26: =SUMIF('ยอดจริง Week 1'!AQ:AQ,'Week 1'!F26,'ยอดจริง Week 1'!AT:AT) -> 0 | CB26: =SUMIF('ยอดจริง Week 1'!AQ:AQ,'Week 1'!F26,'ยอดจริง Week 1'!AU:AU) -> 0 | CC26: =BV26-BZ26 -> 0 | CD26: =BW26-CA26 -> 0 | CE26: =BX26-CB26 -> 0
A27: 23 | F27: 1111065 | G27: ชิฟฟอนแยกชิ้น สับปะรด | K27: =SUM(N27,X27,AH27,AR27,BB27,BL27,BV27) -> 0 | L27: =SUM(O27,Y27,AI27,AS27,BC27,BM27,BW27) -> 0 | Q27: =SUM(N27:P27) -> 0 | R27: =SUMIF('ยอดจริง Week 1'!A:A,'Week 1'!F27,'ยอดจริง Week 1'!C:C) -> 0 | S27: =SUMIF('ยอดจริง Week 1'!A:A,'Week 1'!F27,'ยอดจริง Week 1'!D:D) -> 0 | T27: =SUMIF('ยอดจริง Week 1'!A:A,'Week 1'!F27,'ยอดจริง Week 1'!E:E) -> 0 | U27: =N27-R27 -> 0 | V27: =O27-S27 -> 0 | W27: =P27-T27 -> 0 | Y27: 0 | AA27: =SUM(X27:Z27) -> 0 | AB27: =SUMIF('ยอดจริง Week 1'!H:H,'Week 1'!F27,'ยอดจริง Week 1'!J:J) -> 0 | AC27: =SUMIF('ยอดจริง Week 1'!H:H,'Week 1'!F27,'ยอดจริง Week 1'!K:K) -> 0 | AD27: =SUMIF('ยอดจริง Week 1'!H:H,'Week 1'!F27,'ยอดจริง Week 1'!L:L) -> 0 | AE27: =X27-AB27 -> 0 | AF27: =Y27-AC27 -> 0 | AG27: =Z27-AD27 -> 0 | AI27: 0 | AK27: =SUM(AH27:AJ27) -> 0 | AL27: =SUMIF('ยอดจริง Week 1'!O:O,'Week 1'!F27,'ยอดจริง Week 1'!Q:Q) -> 0 | AM27: =SUMIF('ยอดจริง Week 1'!O:O,'Week 1'!F27,'ยอดจริง Week 1'!R:R) -> 0 | AN27: =SUMIF('ยอดจริง Week 1'!O:O,'Week 1'!F27,'ยอดจริง Week 1'!S:S) -> 0 | AO27: =AH27-AL27 -> 0 | AP27: =AI27-AM27 -> 0 | AQ27: =AJ27-AN27 -> 0 | AS27: 0 | AU27: =SUM(AR27:AT27) -> 0 | AV27: =SUMIF('ยอดจริง Week 1'!V:V,'Week 1'!F27,'ยอดจริง Week 1'!X:X) -> 0 | AW27: =SUMIF('ยอดจริง Week 1'!V:V,'Week 1'!F27,'ยอดจริง Week 1'!Y:Y) -> 0 | AX27: =SUMIF('ยอดจริง Week 1'!V:V,'Week 1'!F27,'ยอดจริง Week 1'!Z:Z) -> 0 | AY27: =AR27-AV27 -> 0 | AZ27: =AS27-AW27 -> 0 | BA27: =AT27-AX27 -> 0 | BE27: =SUM(BB27:BD27) -> 0 | BF27: =SUMIF('ยอดจริง Week 1'!AC:AC,'Week 1'!F27,'ยอดจริง Week 1'!AE:AE) -> 0 | BG27: =SUMIF('ยอดจริง Week 1'!AC:AC,'Week 1'!F27,'ยอดจริง Week 1'!AF:AF) -> 0 | BH27: =SUMIF('ยอดจริง Week 1'!AC:AC,'Week 1'!F27,'ยอดจริง Week 1'!AG:AG) -> 0 | BI27: =BB27-BF27 -> 0 | BJ27: =BC27-BG27 -> 0 | BK27: =BD27-BH27 -> 0 | BO27: =SUM(BL27:BN27) -> 0 | BP27: =SUMIF('ยอดจริง Week 1'!AJ:AJ,'Week 1'!F27,'ยอดจริง Week 1'!AL:AL) -> 0 | BQ27: =SUMIF('ยอดจริง Week 1'!AJ:AJ,'Week 1'!F27,'ยอดจริง Week 1'!AM:AM) -> 0 | BR27: =SUMIF('ยอดจริง Week 1'!AJ:AJ,'Week 1'!F27,'ยอดจริง Week 1'!AN:AN) -> 0 | BS27: =BL27-BP27 -> 0 | BT27: =BM27-BQ27 -> 0 | BU27: =BN27-BR27 -> 0 | BY27: =SUM(BV27:BX27) -> 0 | BZ27: =SUMIF('ยอดจริง Week 1'!AQ:AQ,'Week 1'!F27,'ยอดจริง Week 1'!AS:AS) -> 0 | CA27: =SUMIF('ยอดจริง Week 1'!AQ:AQ,'Week 1'!F27,'ยอดจริง Week 1'!AT:AT) -> 0 | CB27: =SUMIF('ยอดจริง Week 1'!AQ:AQ,'Week 1'!F27,'ยอดจริง Week 1'!AU:AU) -> 0 | CC27: =BV27-BZ27 -> 0 | CD27: =BW27-CA27 -> 0 | CE27: =BX27-CB27 -> 0
