Workbook

Sheet Summary
B1: Amazon | H1: ร้านขายของฝาก
B2: เดือน | C2: ลูกค้าใหม่ | D2: ลูกค้าหาย | E2: เพิ่ม/ลดสุทธิ | H2: เดือน | I2: ลูกค้าใหม่ | J2: ลูกค้าหาย | K2: เพิ่ม/ลดสุทธิ
B3: 1 | C3: =COUNTIF(Amazon!$M:$M,"ลูกค้าใหม่เดือน "&B3) -> 0 | D3: =COUNTIF(Amazon!$N:$N,"หายเดือน "&B3) -> 0 | E3: =C3-D3 -> 0 | H3: 1 | I3: =COUNTIF(ร้านขายของฝาก!$M:$M,"ลูกค้าใหม่เดือน "&H3) -> 0 | J3: =COUNTIF(ร้านขายของฝาก!$N:$N,"หายเดือน "&H3) -> 0 | K3: =I3-J3 -> 0
B4: 2 | C4: =COUNTIF(Amazon!$M:$M,"ลูกค้าใหม่เดือน "&B4) -> 137 | D4: =COUNTIF(Amazon!$N:$N,"หายเดือน "&B4) -> 69 | E4: =C4-D4 -> 68 | H4: 2 | I4: =COUNTIF(ร้านขายของฝาก!$M:$M,"ลูกค้าใหม่เดือน "&H4) -> 3 | J4: =COUNTIF(ร้านขายของฝาก!$N:$N,"หายเดือน "&H4) -> 3 | K4: =I4-J4 -> 0
B5: 3 | C5: =COUNTIF(Amazon!$M:$M,"ลูกค้าใหม่เดือน "&B5) -> 73 | D5: =COUNTIF(Amazon!$N:$N,"หายเดือน "&B5) -> 86 | E5: =C5-D5 -> -13 | H5: 3 | I5: =COUNTIF(ร้านขายของฝาก!$M:$M,"ลูกค้าใหม่เดือน "&H5) -> 0 | J5: =COUNTIF(ร้านขายของฝาก!$N:$N,"หายเดือน "&H5) -> 3 | K5: =I5-J5 -> -3
B6: 4 | C6: =COUNTIF(Amazon!$M:$M,"ลูกค้าใหม่เดือน "&B6) -> 90 | D6: =COUNTIF(Amazon!$N:$N,"หายเดือน "&B6) -> 113 | E6: =C6-D6 -> -23 | H6: 4 | I6: =COUNTIF(ร้านขายของฝาก!$M:$M,"ลูกค้าใหม่เดือน "&H6) -> 0 | J6: =COUNTIF(ร้านขายของฝาก!$N:$N,"หายเดือน "&H6) -> 3 | K6: =I6-J6 -> -3
B7: 5 | C7: =COUNTIF(Amazon!$M:$M,"ลูกค้าใหม่เดือน "&B7) -> 62 | D7: =COUNTIF(Amazon!$N:$N,"หายเดือน "&B7) -> 81 | E7: =C7-D7 -> -19 | H7: 5 | I7: =COUNTIF(ร้านขายของฝาก!$M:$M,"ลูกค้าใหม่เดือน "&H7) -> 0 | J7: =COUNTIF(ร้านขายของฝาก!$N:$N,"หายเดือน "&H7) -> 3 | K7: =I7-J7 -> -3
B8: 6 | C8: =COUNTIF(Amazon!$M:$M,"ลูกค้าใหม่เดือน "&B8) -> 85 | D8: =COUNTIF(Amazon!$N:$N,"หายเดือน "&B8) -> 112 | E8: =C8-D8 -> -27 | H8: 6 | I8: =COUNTIF(ร้านขายของฝาก!$M:$M,"ลูกค้าใหม่เดือน "&H8) -> 1 | J8: =COUNTIF(ร้านขายของฝาก!$N:$N,"หายเดือน "&H8) -> 5 | K8: =I8-J8 -> -4
B9: 7 | C9: =COUNTIF(Amazon!$M:$M,"ลูกค้าใหม่เดือน "&B9) -> 18 | D9: =COUNTIF(Amazon!$N:$N,"หายเดือน "&B9) -> 333 | E9: =C9-D9 -> -315 | H9: 7 | I9: =COUNTIF(ร้านขายของฝาก!$M:$M,"ลูกค้าใหม่เดือน "&H9) -> 1 | J9: =COUNTIF(ร้านขายของฝาก!$N:$N,"หายเดือน "&H9) -> 16 | K9: =I9-J9 -> -15
B10: Total | C10: =SUM(C3:C9) -> 465 | D10: =SUM(D3:D9) -> 794 | E10: =SUM(E3:E9) -> -329 | H10: Total | I10: =SUM(I3:I9) -> 5 | J10: =SUM(J3:J9) -> 33 | K10: =SUM(K3:K9) -> -28

Sheet Amazon
A1: รหัสสาขาใหม่ | B1: ชื่อสาขา_new | C1: จังหวัด1 | D1: อำเภอ2 | E1: 1 | F1: 2 | G1: 3 | H1: 4 | I1: 5 | J1: 6 | K1: 7 | L1: Grand Total | M1: ลูกค้าใหม่ | N1: ลูกค้าที่หายไป
A2: 10375 | B2: 10375 เค้กบ้านแม่ (ลาดหลุมแก้ว) | C2: ปทุมธานี | D2: ลาดหลุมแก้ว | E2: 6000 | F2: 2560 | G2: 1600 | H2: 3520 | I2: 4960 | J2: 2240 | K2: 1600 | L2: 22480
A3: 10500 | B3: 10500 บริษัท วัน วัน วัน คอฟฟี่ จำกัด (สำนักงานใหญ่) | C3: นครปฐม | D3: สามพราน | E3: 4295 | F3: 4738 | G3: 4937 | H3: 4065 | I3: 4517 | J3: 6335 | K3: 1848 | L3: 30735
A4: CD0112 | B4: หจก.เชียงใหม่สหชัยวัฒนา | C4: เชียงใหม่ | D4: สันทราย | E4: 5479.24 | F4: 1968.62 | G4: 1187.34 | H4: 5232.52 | I4: 5371.3 | L4: 19239.02 | N4: หายเดือน 6
A5: CD0113 | B5: หจก.ลักกี้สกายเอนเนอร์จี | C5: เชียงราย | D5: เมืองเชียงราย | E5: 9185.29 | F5: 7860.94 | G5: 4252.35 | H5: 4127.89 | L5: 25426.47 | N5: หายเดือน 5
A6: CD0114 | B6: บจ.เคยูออยล์ | C6: เชียงราย | D6: เมืองเชียงราย | E6: 4884.15 | F6: 3447.47 | G6: 2360.07 | K6: 2341.86 | L6: 13033.55
A7: CD0120 | B7: บจ.เอสที คอฟฟี่ | C7: พิษณุโลก | D7: เมืองพิษณุโลก | E7: 15706.13 | F7: 18166.43 | G7: 16465.53 | H7: 21583.46 | I7: 13060.72 | J7: 11599.71 | K7: 5269.81 | L7: 101851.79
A8: CD0136 | B8: หจก.อิ่มรักษ์ ณ เกาะแก้ว | C8: ภูเก็ต | D8: เมืองภูเก็ต | E8: 7711.93 | F8: 3447.43 | G8: 4592.52 | L8: 15751.88 | N8: หายเดือน 4
A9: CD0137 | B9: หจก.สตูลปิโตรเลี่ยม | C9: สงขลา | D9: หาดใหญ่ | E9: 8990.73 | F9: 7098.37 | G9: 8920.82 | H9: 8255.7 | I9: 7162.27 | J9: 9115.31 | K9: 3544.67 | L9: 53087.87
A10: CD0148 | B10: หจก.ศิริชัย อมรา | C10: สุราษฎร์ธานี | D10: พุนพิน | E10: 4073.25 | F10: 3927.48 | G10: 5282.19 | H10: 4076.24 | I10: 3280.44 | J10: 4191.69 | K10: 2013.87 | L10: 26845.16
A11: CD1236 | B11: บจ.เอ็นวายพี95 | C11: สมุทรปราการ | D11: บางพลี | E11: 1719.33 | F11: 989.45 | G11: 3317.87 | H11: 2976.06 | I11: 2302.72 | J11: 1462.33 | K11: 737.59 | L11: 13505.35
A12: CD1396 | B12: CD1396 หจก.ปัญญามอเตอร์ | C12: อุตรดิตถ์ | D12: เมืองอุตรดิตถ์ | E12: 3373.35 | F12: 2104.96 | G12: 1704.06 | H12: 2660.85 | I12: 2399.56 | J12: 3395.86 | K12: 2108.02 | L12: 17746.66
A13: CD1519 | B13: สถานีบริการน้ำมันเชื้อเพลิงสวัสดิกา | C13: สุราษฎร์ธานี | D13: พุนพิน | E13: 4899.42 | F13: 4717.16 | G13: 4619.98 | H13: 4701.91 | I13: 3216.66 | J13: 4167.4 | K13: 1646.28 | L13: 27968.81
A14: CD3575 | B14: หจก.ทูเจ บราเธอร์ | C14: เชียงใหม่ | D14: เมืองเชียงใหม่ | K14: 1023.59 | L14: 1023.59 | M14: ลูกค้าใหม่เดือน 7
A15: CD4165 | B15: ห้างหุ่นส่วนจำกัด เอส แอล พี คาเฟ่ | C15: สุโขทัย | D15: สวรรคโลก | E15: 4735.43 | F15: 2682.08 | G15: 3037.51 | H15: 3210.59 | I15: 3845.34 | J15: 3733.01 | K15: 1746.53 | L15: 22990.49
A16: CD4450 | B16: หจก.เจ้าขุนเขา | C16: ประจวบคีรีขันธ์ | D16: เมืองประจวบคีรีขันธ์ | E16: 5173.41 | F16: 7442.72 | G16: 5990.67 | H16: 7373.33 | I16: 8802.25 | J16: 4764.78 | K16: 3731.64 | L16: 43278.8
A17: CD5437 | B17: บจ.นวประชา 2025 | C17: นครปฐม | D17: เมืองนครปฐม | E17: 1843.73 | F17: 2369.23 | G17: 3086.06 | H17: 2281.11 | I17: 750.26 | J17: 2454.27 | K17: 1637.19 | L17: 14421.85
A18: DD0112 | B18: หจก.เชียงใหม่สหชัยวัฒนา | C18: เชียงใหม่ | D18: สันทราย | J18: 6121.74 | L18: 6121.74 | M18: ลูกค้าใหม่เดือน 6 | N18: หายเดือน 7
A19: DD0127 | B19: หจก.ศรีสมวงศ์เซอร์วิส ชัยภูมิ | C19: ชัยภูมิ | D19: เมืองชัยภูมิ | E19: 3231.85 | F19: 865.68 | G19: 1941.02 | L19: 6038.55 | N19: หายเดือน 4
A20: DD0145 | B20: บจ.ทรัพย์พจนา | C20: กรุงเทพมหานคร | D20: ลาดพร้าว | E20: 719.6 | L20: 719.6 | N20: หายเดือน 2
A21: DD0149 | B21: หจก.กรุงธน ฟู๊ดส์ แอนด์ เบฟเวอร์เรจ | C21: กรุงเทพมหานคร | D21: คันนายาว | E21: 6575.95 | F21: 4932.72 | G21: 4121.72 | H21: 3875.72 | I21: 5968.5 | J21: 5792.3 | K21: 2991.85 | L21: 34258.76
A22: DD0159 | B22: บจ.สุเพ็ชร | C22: กรุงเทพมหานคร | D22: ทวีวัฒนา | E22: 4349.7 | F22: 1263.59 | G22: 841.37 | H22: 3966.9 | I22: 3976.06 | J22: 2843.09 | L22: 17240.71 | N22: หายเดือน 7
A23: DD0160 | B23: หจก.นพสร | C23: กรุงเทพมหานคร | D23: บางแค | E23: 6673.19 | F23: 6980 | G23: 7754.59 | H23: 4847.72 | I23: 6190.28 | J23: 8152.45 | K23: 3511.24 | L23: 44109.47
A24: DD0161 | B24: หจก.ถาวร คอฟฟี่ | C24: กรุงเทพมหานคร | D24: บางแค | E24: 2591 | F24: 1017.58 | G24: 1023.64 | H24: 1795.17 | I24: 2922.07 | J24: 1193.75 | K24: 1931.86 | L24: 12475.07
A25: DD0165 | B25: หจก.กรุงธน ฟู๊ดส์ แอนด์ เบฟเวอร์เรจ | C25: นนทบุรี | D25: ไทรน้อย | E25: 7754.49 | F25: 12459.34 | G25: 15448.22 | H25: 13179.36 | I25: 10749.38 | J25: 12082.77 | K25: 4167.31 | L25: 75840.87
A26: DD0167 | B26: หจก.ชาดำปู 2011 | C26: ปทุมธานี | D26: สามโคก | E26: 7136.89 | F26: 6607.47 | G26: 6286.22 | H26: 8660.9 | I26: 6286.22 | J26: 4117.14 | K26: 2058.57 | L26: 41153.41
A27: DD0169 | B27: หจก.เอสแอนด์บี คอฟฟี่ | C27: ปทุมธานี | D27: เมืองปทุมธานี | E27: 5177.94 | F27: 7265.44 | G27: 5090.61 | H27: 6463.56 | I27: 2836.96 | J27: 7353.58 | K27: 3079.93 | L27: 37268.02
A28: DD0172 | B28: บจ.เอสเอสเอ็ม คาเฟ่ | C28: ปทุมธานี | D28: ธัญบุรี | E28: 2606.07 | F28: 3939.48 | G28: 3590.19 | H28: 4765.68 | I28: 1637.15 | J28: 2660.77 | K28: 1072.2 | L28: 20271.54
A29: DD0179 | B29: หจก.ฐิติ คอฟฟี่ | C29: เพชรบุรี | D29: ชะอำ | E29: 2694.17 | F29: 1457.94 | G29: 2211.2 | I29: 725.93 | J29: 738.09 | K29: 735.02 | L29: 8562.35
A30: DD0181 | B30: หจก.ฐิติ คอฟฟี่ | C30: เพชรบุรี | D30: ชะอำ | E30: 2861.22 | L30: 2861.22 | N30: หายเดือน 2
A31: DD0182 | B31: หจก.ปลา88 | C31: กาญจนบุรี | D31: ท่ามะกา | E31: 2897.71 | F31: 2809.61 | G31: 3772.48 | H31: 4899.35 | I31: 3259.16 | J31: 3863.59 | K31: 1710.06 | L31: 23211.96
A32: DD0183 | B32: บจ.นภาริณ คอฟฟี่ | C32: กาญจนบุรี | D32: ท่าม่วง | E32: 5279.25 | F32: 5339.9 | G32: 4817.42 | H32: 6214.67 | I32: 4832.62 | J32: 4647.34 | K32: 1682.75 | L32: 32813.95
A33: DD0185 | B33: DD0185 หจก. สงวนทรัพย์พัฒนา | C33: ราชบุรี | D33: เมืองราชบุรี | E33: 7148.2 | F33: 7116.92 | G33: 4222.21 | H33: 4797.45 | I33: 3442.54 | J33: 6185.22 | K33: 1834.57 | L33: 34747.11
A34: DD0186 | B34: หจก.คอฟฟี่ การ์เด้น | C34: ราชบุรี | D34: เมืองราชบุรี | E34: 5385.45 | F34: 4966.31 | G34: 4875.13 | H34: 3219.74 | I34: 4541.03 | J34: 4747.57 | K34: 1834.6 | L34: 29569.83
A35: DD0189 | B35: หจก.คอฟฟี่อินการ์เด้น | C35: จันทบุรี | D35: ท่าใหม่ | E35: 9935.28 | F35: 8954.17 | G35: 10904.25 | H35: 11557.37 | I35: 11809.56 | J35: 5713.36 | K35: 3483.91 | L35: 62357.9
A36: DD0190 | B36: บจ.กาแฟ มาคอว์ | C36: ชลบุรี | D36: เมืองชลบุรี | I36: 2493.82 | J36: 1962.26 | K36: 1467.14 | L36: 5923.22 | M36: ลูกค้าใหม่เดือน 5
A37: DD0192 | B37: บจ.ดี ดี 192 | C37: ชลบุรี | D37: บางละมุง | E37: 1524.8 | F37: 2758.02 | G37: 3450.49 | H37: 2627.35 | I37: 2882.51 | J37: 3972.97 | K37: 1543 | L37: 18759.14
A38: DD0193 | B38: บจ.จันทร์เพ็ญคอฟฟี | C38: ชลบุรี | D38: ศรีราชา | E38: 5929.14 | F38: 5692.22 | G38: 6178.24 | H38: 4635.2 | I38: 5382.42 | J38: 6658.12 | K38: 2830.88 | L38: 37306.22
A39: DD0196 | B39: บจ.ซีเอ็ม คอฟฟี่ | C39: นครนายก | D39: องครักษ์ | E39: 9653.09 | F39: 9079.04 | G39: 9856.66 | H39: 9000.04 | I39: 8231.59 | J39: 8936.3 | K39: 2943.35 | L39: 57700.07
A40: DD0197 | B40: หจก.ศรีเสาวภาคอฟฟี่ | C40: นครนายก | D40: องครักษ์ | E40: 8817.57 | F40: 10129.69 | G40: 10254.24 | H40: 12766.05 | I40: 8586.67 | J40: 11511.71 | L40: 62065.93 | N40: หายเดือน 7
...

Sheet ร้านขายของฝาก
A1: รหัสสาขาใหม่ | B1: ชื่อสาขา_new | C1: จังหวัด1 | D1: อำเภอ2 | E1: 1 | F1: 2 | G1: 3 | H1: 4 | I1: 5 | J1: 6 | K1: 7 | L1: Grand Total | M1: ลูกค้าใหม่ | N1: ลูกค้าที่หายไป
A2: 000009 | B2: 000009 ร้าน บ้านขนมภูรุ้ง | C2: บุรีรัมย์ | D2: นางรอง | E2: 1625 | F2: 1170 | H2: 2580 | I2: 725 | J2: 1860 | K2: 1545 | L2: 9505 | M2: {=_xlfn.LET(_xlpm.sales,E2:K2,_xlpm.firstsale,IFERROR(_xlfn.XMATCH(TRUE,_xlpm.sales>0),0),IF(_xlpm.firstsale>1,"ลูกค้าใหม่เดือน "&INDEX($E$1:$K$1,1,_xlpm.firstsale),""))} | N2: {=IF(K2>0,"",IFERROR("หายเดือน "&INDEX($E$1:$K$1,1,LOOKUP(2,1/(E2:K2>0),COLUMN(E2:K2)-COLUMN(E2)+1)+1),""))}
A3: 000016 | B3: พนักงาน - บจก.วรรณวนัช เบเกอรี่ | C3: นครปฐม | D3: กำแพงแสน | E3: 28080 | F3: 13937 | G3: 23782 | H3: 21776 | I3: 19852 | J3: 26319 | K3: 11185 | L3: 144931 | M3: {=_xlfn.LET(_xlpm.sales,E3:K3,_xlpm.firstsale,IFERROR(_xlfn.XMATCH(TRUE,_xlpm.sales>0),0),IF(_xlpm.firstsale>1,"ลูกค้าใหม่เดือน "&INDEX($E$1:$K$1,1,_xlpm.firstsale),""))} | N3: {=IF(K3>0,"",IFERROR("หายเดือน "&INDEX($E$1:$K$1,1,LOOKUP(2,1/(E3:K3>0),COLUMN(E3:K3)-COLUMN(E3)+1)+1),""))}
A4: 00006 | B4: 00006 บริษัท สุขสมบูรณ์ (1999) จำกัด สุขสมบูรณ์เขาสวนกวาง | C4: อุดรธานี | D4: เมืองอุดรธานี | E4: 7105 | F4: 3670 | G4: 4130 | H4: 6000 | I4: 1720 | J4: 1764 | K4: 940 | L4: 25329 | M4: {=_xlfn.LET(_xlpm.sales,E4:K4,_xlpm.firstsale,IFERROR(_xlfn.XMATCH(TRUE,_xlpm.sales>0),0),IF(_xlpm.firstsale>1,"ลูกค้าใหม่เดือน "&INDEX($E$1:$K$1,1,_xlpm.firstsale),""))} | N4: {=IF(K4>0,"",IFERROR("หายเดือน "&INDEX($E$1:$K$1,1,LOOKUP(2,1/(E4:K4>0),COLUMN(E4:K4)-COLUMN(E4)+1)+1),""))}
A5: 01130 | B5: 01130 บริษัท เคเอเอ็น คาเฟ่ จำกัด | C5: กรุงเทพมหานคร | D5: ดอนเมือง | E5: 1690 | F5: 1640 | G5: 2550 | H5: 1720 | I5: 1585 | J5: 1015 | K5: 1675 | L5: 11875 | M5: {=_xlfn.LET(_xlpm.sales,E5:K5,_xlpm.firstsale,IFERROR(_xlfn.XMATCH(TRUE,_xlpm.sales>0),0),IF(_xlpm.firstsale>1,"ลูกค้าใหม่เดือน "&INDEX($E$1:$K$1,1,_xlpm.firstsale),""))} | N5: {=IF(K5>0,"",IFERROR("หายเดือน "&INDEX($E$1:$K$1,1,LOOKUP(2,1/(E5:K5>0),COLUMN(E5:K5)-COLUMN(E5)+1)+1),""))}
A6: 01132 | B6: 01132 ร้าน โรงพยาบาลธรรมศาสตร์ | C6: ปทุมธานี | D6: คลองหลวง | E6: 17545 | F6: 16305 | G6: 18090 | H6: 14360 | I6: 18210 | J6: 22035 | K6: 8330 | L6: 114875 | M6: {=_xlfn.LET(_xlpm.sales,E6:K6,_xlpm.firstsale,IFERROR(_xlfn.XMATCH(TRUE,_xlpm.sales>0),0),IF(_xlpm.firstsale>1,"ลูกค้าใหม่เดือน "&INDEX($E$1:$K$1,1,_xlpm.firstsale),""))} | N6: {=IF(K6>0,"",IFERROR("หายเดือน "&INDEX($E$1:$K$1,1,LOOKUP(2,1/(E6:K6>0),COLUMN(E6:K6)-COLUMN(E6)+1)+1),""))}
A7: 07890 | B7: 07890 ร้าน เสี่ยใหญ่หมูสด | C7: ราชบุรี | D7: โพธาราม | E7: 6750 | F7: 6450 | G7: 7075 | H7: 9300 | L7: 29575 | M7: {=_xlfn.LET(_xlpm.sales,E7:K7,_xlpm.firstsale,IFERROR(_xlfn.XMATCH(TRUE,_xlpm.sales>0),0),IF(_xlpm.firstsale>1,"ลูกค้าใหม่เดือน "&INDEX($E$1:$K$1,1,_xlpm.firstsale),""))} | N7: {=IF(K7>0,"",IFERROR("หายเดือน "&INDEX($E$1:$K$1,1,LOOKUP(2,1/(E7:K7>0),COLUMN(E7:K7)-COLUMN(E7)+1)+1),""))} -> หายเดือน 5
A8: 08186 | B8: 08186 บริษัท บี.เอส. เจนเนอเรชั่น จำกัด | C8: สมุทรสาคร | D8: เมืองสมุทรสาคร | E8: 1830 | F8: 1700 | G8: 1890 | H8: 2585 | L8: 8005 | M8: {=_xlfn.LET(_xlpm.sales,E8:K8,_xlpm.firstsale,IFERROR(_xlfn.XMATCH(TRUE,_xlpm.sales>0),0),IF(_xlpm.firstsale>1,"ลูกค้าใหม่เดือน "&INDEX($E$1:$K$1,1,_xlpm.firstsale),""))} | N8: {=IF(K8>0,"",IFERROR("หายเดือน "&INDEX($E$1:$K$1,1,LOOKUP(2,1/(E8:K8>0),COLUMN(E8:K8)-COLUMN(E8)+1)+1),""))} -> หายเดือน 5
A9: 10011 | B9: 10011 บริษัท สถานีอร่อย (ไทยแลนด์) จำกัด | C9: กรุงเทพมหานคร | D9: วัฒนา | E9: 25926 | F9: 17648 | G9: 19656 | H9: 17266 | I9: 15750 | J9: 14922 | K9: 13646 | L9: 124814 | M9: {=_xlfn.LET(_xlpm.sales,E9:K9,_xlpm.firstsale,IFERROR(_xlfn.XMATCH(TRUE,_xlpm.sales>0),0),IF(_xlpm.firstsale>1,"ลูกค้าใหม่เดือน "&INDEX($E$1:$K$1,1,_xlpm.firstsale),""))} | N9: {=IF(K9>0,"",IFERROR("หายเดือน "&INDEX($E$1:$K$1,1,LOOKUP(2,1/(E9:K9>0),COLUMN(E9:K9)-COLUMN(E9)+1)+1),""))}
A10: 10012 | B10: 10012 คุณ แดง | C10: กรุงเทพมหานคร | D10: บางคอแหลม | E10: 26737 | F10: 19222 | G10: 20429 | H10: 17662 | I10: 21908 | J10: 34343 | K10: 14005 | L10: 154306 | M10: {=_xlfn.LET(_xlpm.sales,E10:K10,_xlpm.firstsale,IFERROR(_xlfn.XMATCH(TRUE,_xlpm.sales>0),0),IF(_xlpm.firstsale>1,"ลูกค้าใหม่เดือน "&INDEX($E$1:$K$1,1,_xlpm.firstsale),""))} | N10: {=IF(K10>0,"",IFERROR("หายเดือน "&INDEX($E$1:$K$1,1,LOOKUP(2,1/(E10:K10>0),COLUMN(E10:K10)-COLUMN(E10)+1)+1),""))}
A11: 10015 | B11: 10015 ร้าน รักษ์บ้านเกิด | C11: นครปฐม | D11: สามพราน | E11: 535 | L11: 535 | M11: {=_xlfn.LET(_xlpm.sales,E11:K11,_xlpm.firstsale,IFERROR(_xlfn.XMATCH(TRUE,_xlpm.sales>0),0),IF(_xlpm.firstsale>1,"ลูกค้าใหม่เดือน "&INDEX($E$1:$K$1,1,_xlpm.firstsale),""))} | N11: {=IF(K11>0,"",IFERROR("หายเดือน "&INDEX($E$1:$K$1,1,LOOKUP(2,1/(E11:K11>0),COLUMN(E11:K11)-COLUMN(E11)+1)+1),""))} -> หายเดือน 2
A12: 100251 | B12: 100251 เจ้หมวย(น้องสาวเจ้) | C12: นครปฐม | D12: กำแพงแสน | E12: 1300 | F12: 1400 | G12: 1465 | H12: 1150 | I12: 700 | K12: 1600 | L12: 7615 | M12: {=_xlfn.LET(_xlpm.sales,E12:K12,_xlpm.firstsale,IFERROR(_xlfn.XMATCH(TRUE,_xlpm.sales>0),0),IF(_xlpm.firstsale>1,"ลูกค้าใหม่เดือน "&INDEX($E$1:$K$1,1,_xlpm.firstsale),""))} | N12: {=IF(K12>0,"",IFERROR("หายเดือน "&INDEX($E$1:$K$1,1,LOOKUP(2,1/(E12:K12>0),COLUMN(E12:K12)-COLUMN(E12)+1)+1),""))}
A13: 10027 | B13: 10027 ร้าน กิจเจริญ | C13: นครปฐม | D13: กำแพงแสน | E13: 35350 | F13: 14850 | G13: 14050 | H13: 16960 | I13: 8940 | J13: 20820 | K13: 7900 | L13: 118870 | M13: {=_xlfn.LET(_xlpm.sales,E13:K13,_xlpm.firstsale,IFERROR(_xlfn.XMATCH(TRUE,_xlpm.sales>0),0),IF(_xlpm.firstsale>1,"ลูกค้าใหม่เดือน "&INDEX($E$1:$K$1,1,_xlpm.firstsale),""))} | N13: {=IF(K13>0,"",IFERROR("หายเดือน "&INDEX($E$1:$K$1,1,LOOKUP(2,1/(E13:K13>0),COLUMN(E13:K13)-COLUMN(E13)+1)+1),""))}
A14: 10039 | B14: 10039 บริษัท ศรีฟ้าโฟรเซนฟู้ด จำกัด | C14: กาญจนบุรี | D14: ท่าม่วง | E14: 32050 | F14: 15705 | G14: 19005 | H14: 21975 | I14: 11260 | J14: 3325 | L14: 103320 | M14: {=_xlfn.LET(_xlpm.sales,E14:K14,_xlpm.firstsale,IFERROR(_xlfn.XMATCH(TRUE,_xlpm.sales>0),0),IF(_xlpm.firstsale>1,"ลูกค้าใหม่เดือน "&INDEX($E$1:$K$1,1,_xlpm.firstsale),""))} | N14: {=IF(K14>0,"",IFERROR("หายเดือน "&INDEX($E$1:$K$1,1,LOOKUP(2,1/(E14:K14>0),COLUMN(E14:K14)-COLUMN(E14)+1)+1),""))} -> หายเดือน 7
A15: 10046 | B15: 10046 บริษัท ศรีฟ้าโฟรเซนฟู้ด จำกัด | C15: กาญจนบุรี | D15: เมืองกาญจนบุรี | E15: 30775 | F15: 16275 | G15: 14450 | H15: 22675 | I15: 6550 | J15: 2100 | L15: 92825 | M15: {=_xlfn.LET(_xlpm.sales,E15:K15,_xlpm.firstsale,IFERROR(_xlfn.XMATCH(TRUE,_xlpm.sales>0),0),IF(_xlpm.firstsale>1,"ลูกค้าใหม่เดือน "&INDEX($E$1:$K$1,1,_xlpm.firstsale),""))} | N15: {=IF(K15>0,"",IFERROR("หายเดือน "&INDEX($E$1:$K$1,1,LOOKUP(2,1/(E15:K15>0),COLUMN(E15:K15)-COLUMN(E15)+1)+1),""))} -> หายเดือน 7
A16: 10048 | B16: 10048 บริษัท แม่พเยาว์ ไทยโปรดักส์ จำกัด | C16: กาญจนบุรี | D16: ท่าม่วง | E16: 4810 | F16: 1240 | G16: 1325 | L16: 7375 | M16: {=_xlfn.LET(_xlpm.sales,E16:K16,_xlpm.firstsale,IFERROR(_xlfn.XMATCH(TRUE,_xlpm.sales>0),0),IF(_xlpm.firstsale>1,"ลูกค้าใหม่เดือน "&INDEX($E$1:$K$1,1,_xlpm.firstsale),""))} | N16: {=IF(K16>0,"",IFERROR("หายเดือน "&INDEX($E$1:$K$1,1,LOOKUP(2,1/(E16:K16>0),COLUMN(E16:K16)-COLUMN(E16)+1)+1),""))} -> หายเดือน 4
A17: 10051 | B17: 10051 บริษัท วุ้นเส้นท่าเรือพระแท่น จำกัด | C17: กาญจนบุรี | D17: ท่ามะกา | E17: 7000 | F17: 3500 | G17: 5600 | H17: 5600 | I17: 4200 | J17: 4900 | K17: 2800 | L17: 33600 | M17: {=_xlfn.LET(_xlpm.sales,E17:K17,_xlpm.firstsale,IFERROR(_xlfn.XMATCH(TRUE,_xlpm.sales>0),0),IF(_xlpm.firstsale>1,"ลูกค้าใหม่เดือน "&INDEX($E$1:$K$1,1,_xlpm.firstsale),""))} | N17: {=IF(K17>0,"",IFERROR("หายเดือน "&INDEX($E$1:$K$1,1,LOOKUP(2,1/(E17:K17>0),COLUMN(E17:K17)-COLUMN(E17)+1)+1),""))}
A18: 10052 | B18: 10052 ร้าน ของฝากวุ้นเส้นท่าเรือพระแท่น | C18: กาญจนบุรี | D18: เมืองกาญจนบุรี | E18: 4200 | F18: 2800 | G18: 4200 | H18: 3500 | J18: 4200 | K18: 1400 | L18: 20300 | M18: {=_xlfn.LET(_xlpm.sales,E18:K18,_xlpm.firstsale,IFERROR(_xlfn.XMATCH(TRUE,_xlpm.sales>0),0),IF(_xlpm.firstsale>1,"ลูกค้าใหม่เดือน "&INDEX($E$1:$K$1,1,_xlpm.firstsale),""))} | N18: {=IF(K18>0,"",IFERROR("หายเดือน "&INDEX($E$1:$K$1,1,LOOKUP(2,1/(E18:K18>0),COLUMN(E18:K18)-COLUMN(E18)+1)+1),""))}
A19: 10062 | B19: 10062 บริษัท พรอำภา จำกัด | C19: พระนครศรีอยุธยา | D19: บางประอิน | E19: 2200 | F19: 1600 | G19: 1080 | H19: 1400 | I19: 3140 | J19: 1600 | K19: 800 | L19: 11820 | M19: {=_xlfn.LET(_xlpm.sales,E19:K19,_xlpm.firstsale,IFERROR(_xlfn.XMATCH(TRUE,_xlpm.sales>0),0),IF(_xlpm.firstsale>1,"ลูกค้าใหม่เดือน "&INDEX($E$1:$K$1,1,_xlpm.firstsale),""))} | N19: {=IF(K19>0,"",IFERROR("หายเดือน "&INDEX($E$1:$K$1,1,LOOKUP(2,1/(E19:K19>0),COLUMN(E19:K19)-COLUMN(E19)+1)+1),""))}
A20: 10064 | B20: 10064 ร้าน คุณตุ๊ก บิ๊กซีคลอง4 (ชาดาภัค6972) | C20: ปทุมธานี | D20: ลำลูกกา | E20: 6890 | F20: 4480 | G20: 5275 | H20: 7300 | I20: 4740 | J20: 7300 | K20: 2735 | L20: 38720 | M20: {=_xlfn.LET(_xlpm.sales,E20:K20,_xlpm.firstsale,IFERROR(_xlfn.XMATCH(TRUE,_xlpm.sales>0),0),IF(_xlpm.firstsale>1,"ลูกค้าใหม่เดือน "&INDEX($E$1:$K$1,1,_xlpm.firstsale),""))} | N20: {=IF(K20>0,"",IFERROR("หายเดือน "&INDEX($E$1:$K$1,1,LOOKUP(2,1/(E20:K20>0),COLUMN(E20:K20)-COLUMN(E20)+1)+1),""))}
A21: 10065 | B21: 10065 ร้าน ศรีสยาม (องครักษ์9842) | C21: นครนายก | D21: องครักษ์ | E21: 3350 | F21: 2300 | G21: 3150 | H21: 2000 | I21: 1500 | J21: 3750 | L21: 16050 | M21: {=_xlfn.LET(_xlpm.sales,E21:K21,_xlpm.firstsale,IFERROR(_xlfn.XMATCH(TRUE,_xlpm.sales>0),0),IF(_xlpm.firstsale>1,"ลูกค้าใหม่เดือน "&INDEX($E$1:$K$1,1,_xlpm.firstsale),""))} | N21: {=IF(K21>0,"",IFERROR("หายเดือน "&INDEX($E$1:$K$1,1,LOOKUP(2,1/(E21:K21>0),COLUMN(E21:K21)-COLUMN(E21)+1)+1),""))} -> หายเดือน 7
A22: 10067 | B22: 10067 คุณ ฝ้าย | C22: นครนายก | D22: บ้านนา | E22: 40450 | F22: 21300 | G22: 21800 | H22: 39100 | I22: 33600 | J22: 22850 | K22: 15450 | L22: 194550 | M22: {=_xlfn.LET(_xlpm.sales,E22:K22,_xlpm.firstsale,IFERROR(_xlfn.XMATCH(TRUE,_xlpm.sales>0),0),IF(_xlpm.firstsale>1,"ลูกค้าใหม่เดือน "&INDEX($E$1:$K$1,1,_xlpm.firstsale),""))} | N22: {=IF(K22>0,"",IFERROR("หายเดือน "&INDEX($E$1:$K$1,1,LOOKUP(2,1/(E22:K22>0),COLUMN(E22:K22)-COLUMN(E22)+1)+1),""))}
A23: 10068 | B23: 10068 ร้าน โลตัสคลอง6 (ลำลูกกาบ้านฟ้า) | C23: ปทุมธานี | D23: ลำลูกกา | E23: 6660 | F23: 4640 | G23: 5220 | H23: 8895 | I23: 4900 | J23: 7160 | K23: 2795 | L23: 40270 | M23: {=_xlfn.LET(_xlpm.sales,E23:K23,_xlpm.firstsale,IFERROR(_xlfn.XMATCH(TRUE,_xlpm.sales>0),0),IF(_xlpm.firstsale>1,"ลูกค้าใหม่เดือน "&INDEX($E$1:$K$1,1,_xlpm.firstsale),""))} | N23: {=IF(K23>0,"",IFERROR("หายเดือน "&INDEX($E$1:$K$1,1,LOOKUP(2,1/(E23:K23>0),COLUMN(E23:K23)-COLUMN(E23)+1)+1),""))}
A24: 10070 | B24: 10070 บริษัท พันธ์เจริญกรุ๊ป จำกัด (สำนักงานใหญ่) | C24: พระนครศรีอยุธยา | D24: วังน้อย | E24: 83475 | F24: 31150 | G24: 28575 | H24: 37925 | I24: 29025 | J24: 31205 | K24: 12235 | L24: 253590 | M24: {=_xlfn.LET(_xlpm.sales,E24:K24,_xlpm.firstsale,IFERROR(_xlfn.XMATCH(TRUE,_xlpm.sales>0),0),IF(_xlpm.firstsale>1,"ลูกค้าใหม่เดือน "&INDEX($E$1:$K$1,1,_xlpm.firstsale),""))} | N24: {=IF(K24>0,"",IFERROR("หายเดือน "&INDEX($E$1:$K$1,1,LOOKUP(2,1/(E24:K24>0),COLUMN(E24:K24)-COLUMN(E24)+1)+1),""))}
A25: 10071 | B25: 10071 บริษัท พันธ์เจริญกรุ๊ป จำกัด (สาขา00002) | C25: พระนครศรีอยุธยา | D25: วังน้อย | E25: 38465 | F25: 26395 | G25: 39245 | H25: 48115 | I25: 35665 | J25: 38088 | K25: 17395 | L25: 243368 | M25: {=_xlfn.LET(_xlpm.sales,E25:K25,_xlpm.firstsale,IFERROR(_xlfn.XMATCH(TRUE,_xlpm.sales>0),0),IF(_xlpm.firstsale>1,"ลูกค้าใหม่เดือน "&INDEX($E$1:$K$1,1,_xlpm.firstsale),""))} | N25: {=IF(K25>0,"",IFERROR("หายเดือน "&INDEX($E$1:$K$1,1,LOOKUP(2,1/(E25:K25>0),COLUMN(E25:K25)-COLUMN(E25)+1)+1),""))}
A26: 10072 | B26: 10072 บริษัท พันธ์เจริญกรุ๊ป จำกัด (สาขา00003) | C26: พระนครศรีอยุธยา | D26: วังน้อย | E26: 98950 | F26: 30025 | G26: 36325 | H26: 59850 | I26: 47850 | J26: 31750 | K26: 17240 | L26: 321990 | M26: {=_xlfn.LET(_xlpm.sales,E26:K26,_xlpm.firstsale,IFERROR(_xlfn.XMATCH(TRUE,_xlpm.sales>0),0),IF(_xlpm.firstsale>1,"ลูกค้าใหม่เดือน "&INDEX($E$1:$K$1,1,_xlpm.firstsale),""))} | N26: {=IF(K26>0,"",IFERROR("หายเดือน "&INDEX($E$1:$K$1,1,LOOKUP(2,1/(E26:K26>0),COLUMN(E26:K26)-COLUMN(E26)+1)+1),""))}
A27: 10073 | B27: 10073 บริษัท สยาม ออลล์ จำกัด (สาขา 00005) | C27: นครราชสีมา | D27: สีคิ้ว | E27: 2000 | F27: 1400 | G27: 1400 | H27: 1400 | I27: 1400 | J27: 1400 | L27: 9000 | M27: {=_xlfn.LET(_xlpm.sales,E27:K27,_xlpm.firstsale,IFERROR(_xlfn.XMATCH(TRUE,_xlpm.sales>0),0),IF(_xlpm.firstsale>1,"ลูกค้าใหม่เดือน "&INDEX($E$1:$K$1,1,_xlpm.firstsale),""))} | N27: {=IF(K27>0,"",IFERROR("หายเดือน "&INDEX($E$1:$K$1,1,LOOKUP(2,1/(E27:K27>0),COLUMN(E27:K27)-COLUMN(E27)+1)+1),""))} -> หายเดือน 7
A28: 10074 | B28: 10074 บริษัท สยาม ออลล์ จำกัด (สำนักงานใหญ่) | C28: นครราชสีมา | D28: ด่านขุนทด | E28: 1150 | F28: 700 | G28: 1100 | H28: 1050 | I28: 840 | J28: 840 | K28: 350 | L28: 6030 | M28: {=_xlfn.LET(_xlpm.sales,E28:K28,_xlpm.firstsale,IFERROR(_xlfn.XMATCH(TRUE,_xlpm.sales>0),0),IF(_xlpm.firstsale>1,"ลูกค้าใหม่เดือน "&INDEX($E$1:$K$1,1,_xlpm.firstsale),""))} | N28: {=IF(K28>0,"",IFERROR("หายเดือน "&INDEX($E$1:$K$1,1,LOOKUP(2,1/(E28:K28>0),COLUMN(E28:K28)-COLUMN(E28)+1)+1),""))}
A29: 10075 | B29: 10075 ปึงหงี่เชียง (ส.น.ญ ) | C29: นครราชสีมา | D29: เมืองนครราชสีมา | E29: 46895 | F29: 17375 | G29: 34900 | H29: 29400 | I29: 16350 | L29: 144920 | M29: {=_xlfn.LET(_xlpm.sales,E29:K29,_xlpm.firstsale,IFERROR(_xlfn.XMATCH(TRUE,_xlpm.sales>0),0),IF(_xlpm.firstsale>1,"ลูกค้าใหม่เดือน "&INDEX($E$1:$K$1,1,_xlpm.firstsale),""))} | N29: {=IF(K29>0,"",IFERROR("หายเดือน "&INDEX($E$1:$K$1,1,LOOKUP(2,1/(E29:K29>0),COLUMN(E29:K29)-COLUMN(E29)+1)+1),""))} -> หายเดือน 6
A30: 10078 | B30: 10078 บ.ไทยสงวนโภชนา จำกัด | C30: นครราชสีมา | D30: เมืองนครราชสีมา | E30: 116000 | F30: 81900 | G30: 106150 | H30: 140700 | I30: 105900 | J30: 100350 | K30: 40350 | L30: 691350 | M30: {=_xlfn.LET(_xlpm.sales,E30:K30,_xlpm.firstsale,IFERROR(_xlfn.XMATCH(TRUE,_xlpm.sales>0),0),IF(_xlpm.firstsale>1,"ลูกค้าใหม่เดือน "&INDEX($E$1:$K$1,1,_xlpm.firstsale),""))} | N30: {=IF(K30>0,"",IFERROR("หายเดือน "&INDEX($E$1:$K$1,1,LOOKUP(2,1/(E30:K30>0),COLUMN(E30:K30)-COLUMN(E30)+1)+1),""))}
A31: 10079 | B31: 10079 บริษัท น้ำมันสยามด่านขุนทด จำกัด (สำนักงานใหญ่) | C31: นครราชสีมา | D31: ด่านขุนทด | E31: 1350 | F31: 2750 | G31: 2750 | H31: 4800 | I31: 2050 | J31: 2750 | K31: 700 | L31: 17150 | M31: {=_xlfn.LET(_xlpm.sales,E31:K31,_xlpm.firstsale,IFERROR(_xlfn.XMATCH(TRUE,_xlpm.sales>0),0),IF(_xlpm.firstsale>1,"ลูกค้าใหม่เดือน "&INDEX($E$1:$K$1,1,_xlpm.firstsale),""))} | N31: {=IF(K31>0,"",IFERROR("หายเดือน "&INDEX($E$1:$K$1,1,LOOKUP(2,1/(E31:K31>0),COLUMN(E31:K31)-COLUMN(E31)+1)+1),""))}
A32: 10081 | B32: 10081 หจก. ชาดำปู 2011 | C32: ปทุมธานี | D32: สามโคก | E32: 1885 | F32: 2075 | G32: 1320 | H32: 2635 | I32: 3765 | J32: 3020 | K32: 1885 | L32: 16585 | M32: {=_xlfn.LET(_xlpm.sales,E32:K32,_xlpm.firstsale,IFERROR(_xlfn.XMATCH(TRUE,_xlpm.sales>0),0),IF(_xlpm.firstsale>1,"ลูกค้าใหม่เดือน "&INDEX($E$1:$K$1,1,_xlpm.firstsale),""))} | N32: {=IF(K32>0,"",IFERROR("หายเดือน "&INDEX($E$1:$K$1,1,LOOKUP(2,1/(E32:K32>0),COLUMN(E32:K32)-COLUMN(E32)+1)+1),""))}
A33: 10082 | B33: 10082 ของฝากผู้ใหญ่เกษม | C33: นครราชสีมา | D33: ปากช่อง | E33: 110125 | F33: 111925 | G33: 142950 | H33: 157475 | I33: 124050 | J33: 98150 | K33: 31750 | L33: 776425 | M33: {=_xlfn.LET(_xlpm.sales,E33:K33,_xlpm.firstsale,IFERROR(_xlfn.XMATCH(TRUE,_xlpm.sales>0),0),IF(_xlpm.firstsale>1,"ลูกค้าใหม่เดือน "&INDEX($E$1:$K$1,1,_xlpm.firstsale),""))} | N33: {=IF(K33>0,"",IFERROR("หายเดือน "&INDEX($E$1:$K$1,1,LOOKUP(2,1/(E33:K33>0),COLUMN(E33:K33)-COLUMN(E33)+1)+1),""))}
A34: 10083 | B34: 10083 หวาน หวาน มิลค์แลนด์ อาทิตย์ไฮเวย์ (ร้านนมมิลค์แลน์) | C34: นครราชสีมา | D34: เมืองนครราชสีมา | E34: 3649 | F34: 3436 | G34: 3938 | H34: 3081 | I34: 1901 | J34: 2807 | K34: 1463 | L34: 20275 | M34: {=_xlfn.LET(_xlpm.sales,E34:K34,_xlpm.firstsale,IFERROR(_xlfn.XMATCH(TRUE,_xlpm.sales>0),0),IF(_xlpm.firstsale>1,"ลูกค้าใหม่เดือน "&INDEX($E$1:$K$1,1,_xlpm.firstsale),""))} | N34: {=IF(K34>0,"",IFERROR("หายเดือน "&INDEX($E$1:$K$1,1,LOOKUP(2,1/(E34:K34>0),COLUMN(E34:K34)-COLUMN(E34)+1)+1),""))}
A35: 10090 | B35: 10090 ร้าน เพชรอำพร2 **โทรรับออเดอร์ทุกครั้ง 098-1535559** | C35: ราชบุรี | D35: ปากท่อ | E35: 7000 | F35: 2850 | G35: 4300 | H35: 6850 | I35: 3950 | J35: 5050 | K35: 2200 | L35: 32200 | M35: {=_xlfn.LET(_xlpm.sales,E35:K35,_xlpm.firstsale,IFERROR(_xlfn.XMATCH(TRUE,_xlpm.sales>0),0),IF(_xlpm.firstsale>1,"ลูกค้าใหม่เดือน "&INDEX($E$1:$K$1,1,_xlpm.firstsale),""))} | N35: {=IF(K35>0,"",IFERROR("หายเดือน "&INDEX($E$1:$K$1,1,LOOKUP(2,1/(E35:K35>0),COLUMN(E35:K35)-COLUMN(E35)+1)+1),""))}
A36: 10105 | B36: 10105 ร้าน กาแฟอินทผาลัม | C36: นนทบุรี | D36: ปากเกร็ด | F36: 3600 | H36: 3600 | J36: 3600 | L36: 10800 | M36: {=_xlfn.LET(_xlpm.sales,E36:K36,_xlpm.firstsale,IFERROR(_xlfn.XMATCH(TRUE,_xlpm.sales>0),0),IF(_xlpm.firstsale>1,"ลูกค้าใหม่เดือน "&INDEX($E$1:$K$1,1,_xlpm.firstsale),""))} -> ลูกค้าใหม่เดือน 2 | N36: {=IF(K36>0,"",IFERROR("หายเดือน "&INDEX($E$1:$K$1,1,LOOKUP(2,1/(E36:K36>0),COLUMN(E36:K36)-COLUMN(E36)+1)+1),""))} -> หายเดือน 7
A37: 10107 | B37: 10107 บริษัท เอกชัย สาลี่สุพรรณ จำกัด | C37: สุพรรณบุรี | D37: เมืองสุพรรณ | E37: 82300 | F37: 42800 | G37: 36400 | H37: 50000 | I37: 52650 | J37: 31150 | K37: 16900 | L37: 312200 | M37: {=_xlfn.LET(_xlpm.sales,E37:K37,_xlpm.firstsale,IFERROR(_xlfn.XMATCH(TRUE,_xlpm.sales>0),0),IF(_xlpm.firstsale>1,"ลูกค้าใหม่เดือน "&INDEX($E$1:$K$1,1,_xlpm.firstsale),""))} | N37: {=IF(K37>0,"",IFERROR("หายเดือน "&INDEX($E$1:$K$1,1,LOOKUP(2,1/(E37:K37>0),COLUMN(E37:K37)-COLUMN(E37)+1)+1),""))}
A38: 10108 | B38: 10108 บริษัท เอกชัย สาลี่สุพรรณ จำกัด | C38: สุพรรณบุรี | D38: เมืองสุพรรณ | E38: 8400 | F38: 9800 | G38: 5600 | H38: 14000 | I38: 12600 | J38: 9800 | K38: 2100 | L38: 62300 | M38: {=_xlfn.LET(_xlpm.sales,E38:K38,_xlpm.firstsale,IFERROR(_xlfn.XMATCH(TRUE,_xlpm.sales>0),0),IF(_xlpm.firstsale>1,"ลูกค้าใหม่เดือน "&INDEX($E$1:$K$1,1,_xlpm.firstsale),""))} | N38: {=IF(K38>0,"",IFERROR("หายเดือน "&INDEX($E$1:$K$1,1,LOOKUP(2,1/(E38:K38>0),COLUMN(E38:K38)-COLUMN(E38)+1)+1),""))}
A39: 10113 | B39: 10113 คุณ สุ2 | C39: พระนครศรีอยุธยา | D39: บางปะอิน | E39: 4530 | F39: 3630 | G39: 1970 | H39: 5545 | I39: 1815 | J39: 1620 | K39: 1825 | L39: 20935 | M39: {=_xlfn.LET(_xlpm.sales,E39:K39,_xlpm.firstsale,IFERROR(_xlfn.XMATCH(TRUE,_xlpm.sales>0),0),IF(_xlpm.firstsale>1,"ลูกค้าใหม่เดือน "&INDEX($E$1:$K$1,1,_xlpm.firstsale),""))} | N39: {=IF(K39>0,"",IFERROR("หายเดือน "&INDEX($E$1:$K$1,1,LOOKUP(2,1/(E39:K39>0),COLUMN(E39:K39)-COLUMN(E39)+1)+1),""))}
A40: 10114 | B40: 10114 ร้าน LOVE PATTY (2121) | C40: พระนครศรีอยุธยา | D40: เมืองพระนครศรีอยุธยา | E40: 10375 | G40: 3060 | H40: 3275 | I40: 3525 | J40: 3875 | K40: 1786 | L40: 25896 | M40: {=_xlfn.LET(_xlpm.sales,E40:K40,_xlpm.firstsale,IFERROR(_xlfn.XMATCH(TRUE,_xlpm.sales>0),0),IF(_xlpm.firstsale>1,"ลูกค้าใหม่เดือน "&INDEX($E$1:$K$1,1,_xlpm.firstsale),""))} | N40: {=IF(K40>0,"",IFERROR("หายเดือน "&INDEX($E$1:$K$1,1,LOOKUP(2,1/(E40:K40>0),COLUMN(E40:K40)-COLUMN(E40)+1)+1),""))}
...
