Workbook

Sheet Summary
A1: Sales Visit Summary
A3: รายการ | B3: จำนวน
A4: จำนวนครั้งที่เข้าพบ | B4: =COUNTA('Sales Visit Tracker'!A4:A10050) -> 85
A5: ปิดการขายแล้ว | B5: =COUNTIF('Sales Visit Tracker'!H4:H10050,"ปิดการขายแล้ว")+COUNTIF('Sales Visit Tracker'!H4:H10050,"Won") -> 28
A6: ยังไม่ปิด | B6: =COUNTIF('Sales Visit Tracker'!H4:H10050,"ยังไม่ปิด")+COUNTIF('Sales Visit Tracker'!H4:H10050,"ติดตามต่อ")+COUNTIF('Sales Visit Tracker'!H4:H10050,"Follow Up") -> 44
A7: รออนุมัติ | B7: =COUNTIF('Sales Visit Tracker'!H4:H10050,"รออนุมัติ") -> 0
A8: ไม่ผ่าน | B8: =COUNTIF('Sales Visit Tracker'!H4:H10050,"ไม่ผ่าน")+COUNTIF('Sales Visit Tracker'!H4:H10050,"Lost")+COUNTIF('Sales Visit Tracker'!H4:H10050,"ไม่สนใจ")+COUNTIF('Sales Visit Tracker'!H4:H10050,"ไม่มีการขาย") -> 0
A9: Conversion Rate | B9: =IFERROR(B5/B4,0) -> 0.32941176
A12: Pipeline | B12: จำนวน
A13: Open | B13: =COUNTIF('Sales Visit Tracker'!H4:H10050,"Open") -> 0
A14: Follow Up | B14: =COUNTIF('Sales Visit Tracker'!H4:H10050,"ติดตามต่อ")+COUNTIF('Sales Visit Tracker'!H4:H10050,"Follow Up") -> 44
A15: Won | B15: =COUNTIF('Sales Visit Tracker'!H4:H10050,"ปิดการขายแล้ว")+COUNTIF('Sales Visit Tracker'!H4:H10050,"Won") -> 28
A16: Lost | B16: =COUNTIF('Sales Visit Tracker'!H4:H10050,"ไม่ผ่าน")+COUNTIF('Sales Visit Tracker'!H4:H10050,"Lost")+COUNTIF('Sales Visit Tracker'!H4:H10050,"ไม่สนใจ")+COUNTIF('Sales Visit Tracker'!H4:H10050,"ไม่มีการขาย") -> 0
B17: จำนวน
A19: สนใจ | B19: =COUNTIF('Sales Visit Tracker'!F4:F10055,"สนใจ") -> 28 | C19: =B19/$B$4 -> 0.32941176
A20: รอตัดสินใจ | B20: =COUNTIF('Sales Visit Tracker'!F4:F10056,"รอตัดสินใจ") -> 16 | C20: =B20/$B$4 -> 0.18823529
A21: ไม่สนใจ | B21: =COUNTIF('Sales Visit Tracker'!F4:F10057,"ไม่สนใจ") -> 3 | C21: =B21/$B$4 -> 0.035294118
A22: นัดติดตามต่อ | B22: =COUNTIF('Sales Visit Tracker'!F4:F10058,"นัดติดตามต่อ") -> 1 | C22: =B22/$B$4 -> 0.011764706
A62: =IF($B$5=0,"",MIN('Sales Visit Tracker'!$A$4:$A$10050)+29) -> 46239 | B62: =IF(A62="","",COUNTIF('Sales Visit Tracker'!$A$4:$A$10050,A62)) -> 0
A63: =IF($B$5=0,"",MIN('Sales Visit Tracker'!$A$4:$A$10050)+30) -> 46240 | B63: =IF(A63="","",COUNTIF('Sales Visit Tracker'!$A$4:$A$10050,A63)) -> 0

Sheet Sales Visit Tracker
A1: Sales Visit Tracker
A2: แบบฟอร์มติดตามการเข้าพบลูกค้า/สาขา สำหรับทีมขาย
A3: วันเดือนปี | B3: รหัสร้านค้า | C3: ชื่อร้านค้า/สาขา | D3: ไปเพราะอะไร | E3: ตัวอย่างมีอะไรบ้าง | F3: ผลการไปวันดังกล่าว | G3: Call เพื่อติดตาม | H3: ปิดการขายแล้ว | I3: หมายเหตุ | J3: ชื่อเซลส์
A4: 46210 | B4: SD3647 | C4: ท่าเรือราชวงศ์ | D4: เปิดร้านใหม่ | F4: สนใจ | G4: โทรแล้ว | H4: ติดตามต่อ | I4: สนใจแบบซื้อขาด /สั่งรอบวันศุกร์ ส่งวันจันทร์ / นำขนมแจกชิมให้เทสวันศุกร์ | K4: **** ใส่สีแดงคือร้านที่มีการสั่งซื้อแล้วหลังจากเข้าไปคุย***
A5: 46210 | B5: SC 4541 | C5: MRT วัดมังกร | D5: เปิดร้านใหม่ | F5: สนใจ | G5: โทรแล้ว | H5: รอตัดสินใจ | I5: ระบบ CoCo ปิดชั่วคราว /สนใจสั่งขนมหลังจากระบบเปิด
A6: 46210 | B6: SD3981 | C6: วัดไตรมิตร | D6: เปิดร้านใหม่ | F6: สนใจ | H6: ติดตามต่อ | I6: ลูกสนใจซื้อขาด / ตู้เย็นมีขนาดจำกัด / ต้องสลับโบว์ ภัทราและ Factory ซึ่งตู้ใส่ได้ทีละ 2แบรนด์ / จะลองสั่งมา วันจันทร์ ส่งวันพฤหัส
A7: 46210 | B7: SD3360 | C7: CAT TOWER บางรัก | D7: เปิดร้านใหม่ | F7: รอตัดสินใจ | H7: ติดตามต่อ | I7: สนใจขนมประเภทแซนวิช / รสชาติไม่หวานมาก / เคยสั่งไปแล้วขายไม่ค่อยออกเลยหยุดสั่ง / ตู้เย็นมี 2 ตู้
A8: 46211 | B8: SD3363 | C8: อาคารพาณิชย์ สาทร 11 | D8: เปิดร้านใหม่ | F8: สนใจ | H8: ปิดการขายแล้ว | I8: สนใจรอบสั่งวันศุกร์ ส่งวันจันทร์ (อยากได้ขนมช่วงเช้า ร้านเปิด 7 โมง) / นำขนมเทสมาให้วันจันทร์
A9: 46211 | B9: SD3660 | C9: ไทยซีซี ทาวเวอร์ | D9: เปิดร้านใหม่ | F9: ไม่สนใจ | H9: ไม่ปิดการขาย | I9: ไม่สนใจ 100% เนื่องจากมีร้านขนมอบสดมาเปิดติดร้านทั้ง 2 ฝั่ง ทำให้ร้านขายขนมไม่ดี
A10: 46211 | B10: SD1180 | C10: ซี.พี . ทาวน์เวอร์ 1 (สีลม) | D10: เปิดร้านใหม่ | F10: นัดติดตามต่อ | H10: ติดตามต่อ | I10: ไปไม่ทันเวลาเปิดทำการ
A11: 46211 | B11: SD5448 | C11: อาคาร สาธร ซิตี้ ทาวเวอร์ | D11: เปิดร้านใหม่ | F11: สนใจ | H11: ปิดการขายแล้ว | I11: สนใจรอบสั่งวันศุกร์ ส่งวันจันทร์ (อยากได้ขนมช่วงเช้า ร้านเปิด 7 โมง สามารถมาวางไว้หน้าร้านได้ แต่แช่เย็นให้ด้วย) / นำขนมเทสมาให้วันจันทร์ / ขนมที่ขายดีจะเป็นประเภทแซนวิช
A12: 46211 | B12: SD0932 | C12: สีลมคอมเพล็กซ์ ชั้น 4 | D12: เปิดร้านใหม่ | F12: รอตัดสินใจ | H12: ติดตามต่อ | I12: อยากได้ขั้นต่ำ 500-800 บาท (ปุ๊มแอนด์ป๊อป 500 บาท ) / ในห้างมีร้านเป็นตัวเลือกจำนวนมาก / สนใจรอบสั่งวันศุกร์ ส่งวันจันทร์
A13: 46211 | B13: SD3141 | C13: BTS ช่องนนทรี | D13: เปิดร้านใหม่ | F13: รอตัดสินใจ | G13: โทรแล้ว | H13: ติดตามต่อ | I13: รอลูกค้าเลือกขนมที่สนใจ และนำไปให้เทสวันจันทร์
A14: 46211 | B14: SD3106 | C14: SVL House เอสวีแอล | D14: เปิดร้านใหม่ | F14: รอตัดสินใจ | H14: ติดตามต่อ | I14: รอ ผจก ตัดสินใจ
A15: 46213 | B15: SD3647 | C15: ท่าเรือราชวงศ์ | D15: เปิดร้านใหม่ | E15: เอแคลร์นมสด (8 ชิ้น) | F15: สั่งซื้อแล้ว | H15: ปิดการขายแล้ว | I15: รอบสั่ง 10/07/69
E16: ครีมฮอร์น วนิลา
E17: ขนมปังเนยนิ่ม
E18: ขนมปังสังขยา 6 ชิ้น
E19: ชิฟฟ่อนเค้ก รวมรส (4 ชิ้น)
A20: 46213 | B20: SC 4541 | C20: MRT วัดมังกร | D20: เปิดร้านใหม่ | E20: ครีมฮอร์น วนิลา | F20: สนใจ | H20: ติดตามต่อ | I20: รอระบบ Coco เปิด ทางร้านพร้อมสั่ง
E21: ชิฟฟ่อนเค้ก รวมรส (4 ชิ้น)
E23: ขนมปังเนยนิ่ม
E24: เอแคลร์นมสด (8 ชิ้น)
A25: 46213 | B25: SD3981 | C25: วัดไตรมิตร | D25: เปิดร้านใหม่ | E25: คัพเค้กมะพร้าวไส้ครีมเนยสด (4 ชิ้น) | F25: สั่งซื้อแล้ว | H25: ปิดการขายแล้ว | I25: รอบสั่ง 10/07/69
E26: แซนด์วิชปูอัด ไร้ขอบ
E29: เอแคลร์ชาไทย
A30: 46213 | B30: SD3360 | C30: CAT TOWER บางรัก | D30: เปิดร้านใหม่ | E30: ขนมปังเนยนิ่ม | F30: ไม่สนใจ | H30: ไม่ปิดการขาย | I30: ทางร้านลดซัพจากเดิมลง เพราะขายไม่ดี
E31: ครีมฮอร์น วนิลา
E33: คัพเค้กมะพร้าวไส้ครีมเนยสด (4 ชิ้น)
E34: แซนด์วิชปูอัด ไร้ขอบ
E35: แซนด์วิชแฮมชีส_WWN ไร้ขอบ
A36: 46213 | B36: SD1180 | C36: ซี.พี . ทาวน์เวอร์ 1 (สีลม) | D36: เปิดร้านใหม่ | F36: ขอชิมเพิ่ม | H36: ติดตามต่อ
A37: 46215 | B37: SD3536 | C37: สนามฟุตบอล The Blue Arena | D37: เปิดร้านใหม่ | F37: ไม่สนใจ | G37: ติดต่อไม่ได้ | H37: ติดตามต่อ | I37: *พนักงานแจ้งว่าเคยสั่งและหยุดสั่งไปเป็นปีแล้วเนื่องจากทางผู้จัดการร้านไม่ให้สั่ง เพราะขนมขายออกยาก *พนักงานร้านให้เบอร์ติดต่อทางผู้จัดการมาแทน *พนักงานพยายามปฏิเสธการคุยทุกรูปแบบ *ดำเนินการโทรหาผู้จัดการร้านภายหลัง
A38: 46215 | B38: SD2666 | C38: Big C สมุทรปราการ | D38: เปิดร้านใหม่ | F38: ขอชิมเพิ่ม | G38: โทรแล้ว | H38: ติดตามต่อ | I38: *ทางร้านเคยสั่งมาแล้วแต่ไม่ค่อยตอบโจทย์ลูกค้า *เสนอให้ทางร้านลองเปิดใจและเลือกขนมเพื่อมาเทสก่อนก่อนสั่งขายอีกรอบ *ผู้จัดการร้านเป็นคนตัดสินใจให้
A39: 46215 | B39: RM3793 | C39: *** ขึ้นรหัส OS**** | D39: เปิดร้านใหม่ | F39: สนใจ | G39: นัดโทรอีกครั้ง | H39: ติดตามต่อ | I39: *ยังไม่เคยสั่งของ wwn มาก่อน *ให้คุยกับเจ้าของร้าน *เจ้าของร้านให้ร้าน rm3724 ตัดสินใจเลือกขนมเทสแทน
A40: 46215 | B40: DD4039 | C40: สถานีบริการ หจก.สมจิตรบริการ | D40: เปิดร้านใหม่ | F40: สั่งซื้อแล้ว | G40: โทรแล้ว | H40: ปิดการขายแล้ว | I40: *หยุดสั่งไป 1 รอบเพราะว่าเคยเจอขนมเปรี้ยวก่อนวันหมดอายุทำเครมกับแอดมินแต่ไม่มีการตอบกลับ *ลูกค้าเลือกขนมที่จะมาเทสแล้วส่งให้มาเทสอีกทีวันอาทิตย์หน้า ขนมที่ขายดีจะเป็นขนมปังเนยนิ่ม แซนวิชและเอแคร์
A41: 46215 | B41: SD3292 | C41: โรงพยาบาลสมุทรปราการ | D41: เปิดร้านใหม่ | F41: ขอชิมเพิ่ม | G41: โทรแล้ว | H41: ติดตามต่อ | I41: *ให้ติดต่อผ่านผู้จัดการ เนื่องจากผู้จัดการอยู่นนทบุรีและไม่เข้าสาขานี้พนักงานเลยให้ไลน์มา แต่ยังโทรไม่รับ / *ขนมที่ร้านนี้จะมีของอเมซอนชิวเล้าและโอ้กะจู๋ เนื่องจากร้านอยู่หน้าโรงพยาบาลจึงแนะนำขนมที่สามารถเยี่ยมคนไข้ได้ *ให้พนักงานเลือกขนมที่สนใจและนำมาให้ชิมวันอาทิตย์หน้า
A42: 46215 | B42: SD5372 | C42: Cafe Amazon ตลาดคิงคองมาร์เก็ต | D42: เปิดร้านใหม่ | F42: สั่งซื้อแล้ว | G42: โทรแล้ว | H42: ปิดการขายแล้ว | I42: *ลูกค้าสั่งอยู่แล้ว แต่บางทีนานๆสั่งที ครีมฮอร์นขายดี *เคยเจอปัญหาเค้กโบราณติดสติ๊กเกอร์ไม่แน่น เพราะลูกค้าหยิบหรือพนักงานหยิบแล้วมันหลุด *ขนส่งกับแอดมินไม่มีปัญหา
A43: 46215 | B43: SD5210 | C43: Café Amazon ซอยโนรี | D43: เปิดร้านใหม่ | F43: ขอชิมเพิ่ม | G43: โทรแล้ว | H43: ติดตามต่อ | I43: *สนใจขนมหลายตัว เพื่อเปลี่ยนกับเจ้าอื่น มีสาขา อุ่นนารี อีก 1 สาขา ****ลูกค้าจะสั่งทุกอาทิย์****
A44: 46215 | B44: RM3724 | C44: PTTRM สมุทรปราการ-นาวี | D44: เปิดร้านใหม่ | F44: ขอชิมเพิ่ม | G44: นัดโทรอีกครั้ง | H44: ติดตามต่อ | I44: *ลูกค้ามี 2 ร้านแล้วยังไม่เคยสั่งของ wwn *ถ้าหากสั่งจะสั่งทั้ง 2 ร้าน *ปกติลูกค้าสั่งแค่ภัทรากับของ Factoryรอบสั่งไม่ซ้ำกับทั้ง 2 แบรนด์
...

Sheet Dropdown Lists
A1: สินค้า | B1: ไปเพราะอะไร | C1: ผลการไป | D1: Call เพื่อติดตาม | E1: ปิดการขายแล้ว | F1: ชื่อเซลส์
A2: เอแคลร์นมสด (8 ชิ้น) | B2: นำเสนอสินค้าใหม่ | C2: สนใจ | D2: ยังไม่โทร | E2: ปิดการขายแล้ว | F2: Sales 1
A3: ครีมฮอร์น วนิลา | B3: ติดตามยอดขาย | C3: ขอชิมเพิ่ม | D3: โทรแล้ว | E3: ติดตามต่อ | F3: Sales 2
A4: ขนมปังเนยนิ่ม | B4: เปิดร้านใหม่ | C4: ขอราคา/ข้อมูลเพิ่ม | D4: นัดโทรอีกครั้ง | E4: รอตัดสินใจ | F4: Sales 3
A5: ขนมปังสังขยา 6 ชิ้น | B5: เก็บข้อมูลคู่แข่ง | C5: รอตัดสินใจ | D5: ติดต่อไม่ได้ | E5: ไม่ปิดการขาย | F5: Sales 4
A6: แซนด์วิช โฮวีททูน่า ไร้ขอบ | B6: แก้ไขปัญหาสินค้า | C6: สั่งซื้อแล้ว | F6: Sales 5
A7: ครีมฮอร์น ใบเตย | B7: ติดตามโปรโมชั่น | C7: ไม่สนใจ | F7: Sales 6
A8: ชิฟฟ่อนเค้ก รวมรส (4 ชิ้น) | B8: รับออเดอร์ | C8: นัดติดตามต่อ | F8: Sales 7
A9: แซนด์วิช โฮลวีทแฮมชีส ไร้ขอบ | B9: อื่นๆ | F9: Sales 8
A10: ขนมเปี๊ยะไส้ถั่วไข่เค็ม (4 ชิ้น) | F10: Sales 9
A11: แซนด์วิชปูอัด ไร้ขอบ | F11: Sales 10
A12: แซนด์วิชแฮมชีส_WWN ไร้ขอบ
A13: คัพเค้กมะพร้าวไส้ครีมเนยสด (4 ชิ้น)
A14: เอแคลร์ชาไทย
A15: แซนด์วิชปูอัดสาหร่าย ไร้ขอบ
A16: ขนมปังลาวาไข่เค็ม
