Workbook

Sheet DATA POS
A1: รหัสสินค้า | B1: ชื่อสินค้า | C1: หมวดหมู่สินค้า | D1: หน่วยสินค้า | E1: ราคาขาย | F1: ราคาซื้อ | G1: Min | H1: Max | I1: หมายเหตุ | J1: สถานะ
A2: บูธ หน้า ม.เกษตร วันที่ 1-28 ก.พ. 2568
A3: 0109256601 | B3: กระเช้าสำเร็จรูป | C3: หมวดอื่นๆ | D3: กระเช้า | E3: 800.00 | F3: 0.00 | G3: 0 | H3: 0 | J3: ใช้งาน
A4: 0109256602 | B4: เซ็ตของขวัญ | C4: หมวดอื่นๆ | D4: กล่อง | E4: 260.00 | F4: 0.00 | G4: 0 | H4: 0 | J4: ใช้งาน
A5: 01-SU-0025-1 | B5: น้ำแดงเฮลบลูบอย | C5: เครื่องดื่ม | D5: ขวด | F5: 0.00 | G5: 0 | H5: 0 | J5: ใช้งาน
A6: 02102566 | B6: เปี๊ยะมินิ | C6: หมวดอื่นๆ | D6: กล่อง | F6: 0.00 | G6: 0 | H6: 0 | J6: ใช้งาน
A7: 02-BB01 | B7: กล่องเค้กเบาหวิวทุเรียน 100g. New | C7: กล่องโมเดล | D7: กล่อง | F7: 0.00 | G7: 0 | H7: 0 | J7: ใช้งาน
A8: 02-BB02 | B8: กล่องเค้กเบาหวิวเผือกมะพร้าวอ่อน 100g. New | C8: กล่องโมเดล | D8: กล่อง | F8: 0.00 | G8: 0 | H8: 0 | J8: ใช้งาน
A9: 02-BB03 | B9: กล่องเค้กเบาหวิวกล้วยมะพร้าวเผา 100g. New | C9: กล่องโมเดล | D9: กล่อง | F9: 0.00 | G9: 0 | H9: 0 | J9: ใช้งาน
A10: 02-BB05 | B10: กล่องเค้กเบาหวิวรสกาแฟ 100g New | C10: กล่องโมเดล | D10: กล่อง | F10: 0.00 | G10: 0 | H10: 0 | J10: ใช้งาน
A11: 02-BB07 | B11: กล่องเค้กเบาหวิวรสกาแฟ 300g. New | C11: กล่องโมเดล | D11: กล่อง | F11: 0.00 | G11: 0 | H11: 0 | J11: ใช้งาน
A12: 02-BB09 | B12: กล่องเค้กเบาหวิวรสเนยนม 110g. New | C12: กล่องโมเดล | D12: กล่อง | F12: 0.00 | G12: 0 | H12: 0 | J12: ใช้งาน
A13: 02-BB11 | B13: กล่องเค้กเบาหวิวรสเนยนม 300g. New | C13: กล่องโมเดล | D13: กล่อง | F13: 0.00 | G13: 0 | H13: 0 | J13: ใช้งาน
A14: 02-BB14 | B14: กล่องเค้กเบาหวิวรสใบเตย 300g. New | C14: กล่องโมเดล | D14: กล่อง | F14: 0.00 | G14: 0 | H14: 0 | J14: ใช้งาน
A15: 02-BB15 | B15: กล่องเค้กเบาหวิวรสเตยหอม 100g. New | C15: กล่องโมเดล | D15: กล่อง | F15: 0.00 | G15: 0 | H15: 0 | J15: ใช้งาน
A16: 02-BB16 | B16: กล่องเค้กเบาหวิวรสฝอยทอง 100g. New | C16: กล่องโมเดล | D16: กล่อง | F16: 0.00 | G16: 0 | H16: 0 | J16: ใช้งาน
... A76: 1113178 | B76: เค้กลอดช่องกล่องกลม 1 ปอนด์ 265 กรัม | C76: เค้ก | D76: กล่อง | F76: 0.00 | G76: 0 | H76: 0 | J76: ใช้งาน
A77: 1113179 | B77: เค้กลอดช่องกล่องกลม 2 ปอนด์ 325 กรัม | C77: เค้ก | D77: กล่อง | F77: 0.00 | G77: 0 | H77: 0 | I77: สินค้าระบายจากทางออนไลน์ ขาย 120 บาท | J77: ใช้งาน
A78: 1113185 | B78: ข้าวเกรียบว่าว (กระปุก) | C78: ขนมปัง แซนวิส | D78: กระปุก | F78: 0.00 | G78: 0 | H78: 0 | J78: ใช้งาน
A79: 1113191 | B79: เค้กตะโก้เผือกหอม 120 กรัม | C79: เค้ก | D79: กล่อง | F79: 0.00 | G79: 0 | H79: 0 | J79: ใช้งาน
A80: 1113192 | B80: ปังนุ่มมะพร้าว 100 กรัม | C80: ขนมปัง แซนวิส | D80: กล่อง | F80: 0.00 | G80: 0 | H80: 0 | I80: บิ๊กซี | J80: ใช้งาน
A81: 1113193 | B81: ปังนุ่มชาไทย 100 กรัม | C81: ขนมปัง แซนวิส | D81: กล่อง | F81: 0.00 | G81: 0 | H81: 0 | I81: บิ๊กซี | J81: ใช้งาน
A82: 1113194 | B82: บานอฟฟี่ 140 กรัม | C82: เค้ก | D82: กล่อง | F82: 0.00 | G82: 0 | H82: 0 | I82: ราคาเต็ม 45 บาท , ราคาของระบาย 20 บาท | J82: ใช้งาน
A83: 1114024 | B83: สังขยา 1 ชิ้น | C83: ขนมปัง แซนวิส | D83: ชิ้น | F83: 0.00 | G83: 0 | H83: 0 | J83: ใช้งาน
A84: 11140500 | B84: ขนมปังเลเยอร์ | C84: ขนมปัง แซนวิส | D84: ถุง | F84: 0.00 | G84: 0 | H84: 0 | J84: ใช้งาน
A85: 1114056 | B85: ขนมปุยฝ้าย คละรส (4 ชิ้น) | C85: ขนมปัง แซนวิส | D85: กล่อง | F85: 0.00 | G85: 0 | H85: 0 | J85: ใช้งาน
A86: 1114057 | B86: ขนมปุยฝ้าย สีชมพู (1 ปอนด์) | C86: ขนมปัง แซนวิส | D86: กล่อง | F86: 0.00 | G86: 0 | H86: 0 | J86: ใช้งาน
A87: 1114058 | B87: ขนมปุยฝ้าย สีชมพู (4 ชิ้น) | C87: ขนมปัง แซนวิส | D87: กล่อง | F87: 0.00 | G87: 0 | H87: 0 | J87: ใช้งาน
A88: 1114059 | B88: ขนมปุยฝ้าย สีขาว (1 ปอนด์) | C88: ขนมปัง แซนวิส | D88: กล่อง | F88: 0.00 | G88: 0 | H88: 0 | J88: ใช้งาน
A89: 1114060 | B89: ขนมปุยฝ้าย สีขาว (4 ชิ้น) | C89: ขนมปัง แซนวิส | D89: กล่อง | F89: 0.00 | G89: 0 | H89: 0 | J89: ใช้งาน
A90: 1124024 | B90: ขนมปังไส้ฝอยทอง (ชิ้น) | C90: ขนมปัง แซนวิส | D90: ชิ้น | F90: 0.00 | G90: 0 | H90: 0 | J90: ใช้งาน
A91: 1124037 | B91: ขนมปังไส้พริกเผาไก่หยอง (ชิ้น) | C91: ขนมปัง แซนวิส | D91: ชิ้น | F91: 0.00 | G91: 0 | H91: 0 | J91: ใช้งาน
A92: 1124038 | B92: ขนมปังไส้แยมบลูเบอร์รี่ (ชิ้น) | C92: ขนมปัง แซนวิส | D92: ชิ้น | F92: 0.00 | G92: 0 | H92: 0 | J92: ใช้งาน
A93: 1124039 | B93: ขนมปังไส้แยมสตรอเบอร์รี่ (ชิ้น) | C93: ขนมปัง แซนวิส | D93: ชิ้น | F93: 0.00 | G93: 0 | H93: 0 | J93: ใช้งาน
A94: 1124040 | B94: ขนมปังไส้ลูกเกดฝอยทอง (ชิ้น) | C94: ขนมปัง แซนวิส | D94: ชิ้น | F94: 0.00 | G94: 0 | H94: 0 | J94: ใช้งาน
... A96: 1200032 | B96: (NP)มาม่อนคัฟ รวมรส (6ชิ้น) | C96: หนองพงนก | D96: กล่อง | F96: 0.00 | G96: 0 | H96: 0 | J96: ใช้งาน
A97: 1200092 | B97: ท๊อฟฟี่ถั่ว (กิโล) | D97: กิโลกรัม | F97: 0.00 | G97: 0 | H97: 0 | J97: ใช้งาน
A98: 1300005 | B98: เค้กมะพร้าวลาวา 85 กรัม | C98: เค้ก | D98: กล่อง | F98: 0.00 | G98: 0 | H98: 0 | J98: ใช้งาน
A99: 1300006 | B99: แซนด์วิช แฮมไข่ดาว | C99: ขนมปัง แซนวิส | D99: กล่อง | F99: 0.00 | G99: 0 | H99: 0 | J99: ใช้งาน
A100: 13082000 | B100: หนังสือนิทาน วาดภาพ | C100: รพ.สินแพทย์ | D100: ชิ้น | F100: 0.00 | G100: 0 | H100: 0 | J100: ใช้งาน
...

Sheet ต้นทุนพี่ตุ๊ก
A1: รหัสสินค้า | B1: ชื่อสินค้า | C1: ราคาต้นทุน
A2: 1111001 | B2: ชิฟฟ่อนเค้ก 1 ชิ้น
A3: 1111010 | B3: ชิฟฟ่อนเค้กสอดไส้แยม 1 ชิ้น
A4: 1112539 | B4: ชิฟฟ่อนเค้กสอดไส้ เมล่อน (3 ชิ้น)
A5: 20055116 | B5: ชิฟฟ่อนเค้กสอดไส้ครีมมะพร้าว 120g.
A6: 20055119 | B6: ชิฟฟ่อนเค้กฝอยทอง 95g.
A7: 1124027 | B7: ครีมฮอร์นใบเตย จัมโบ้ 65g.
A8: 1124029 | B8: ครีมฮอร์นชาไทย จัมโบ้ 65g.
A9: 20055115 | B9: ครีมฮอร์นคิทแคท 70g.
A10: 1200019 | B10: NP เค้กโบราณครีม 6 ชิ้น
A11: 1200020 | B11: NP เเค้กโบราณผลไม้ 6 ชิ้น
A12: 5002400 | B12: เค้กลาวา ฝอยทอง เล็ก
A13: 1113011 | B13: เค้กลาวา ฝอยทอง ใหญ่
A14: 1113010 | B14: เค้กลาวา ฝอยทองทูโทน ใหญ่
A15: 20054637 | B15: เอแคลร์คิทแคท 55g.
A16: 20056257 | B16: เอแคลร์ชาไทย 125g.
A17: 20054638 | B17: เครปเค้กคิทแคท 65g.
A18: 1113194 | B18: บานอฟฟี่ 140 กรัม
A19: 1006979 | B19: คัพเค้กไส้คัสตาร์ด
A20: 1300005 | B20: เค้กมะพร้าวลาวา 85 กรัม
A21: 1113157 | B21: เค้กลอดช่อง 85 กรัม
A22: 1113178 | B22: เค้กลอดช่องกล่องกลม 1 ปอนด์ 265 กรัม
A23: 1113179 | B23: เค้กลอดช่องกล่องกลม 2 ปอนด์ 325 กรัม
A24: 20053053 | B24: เค้กทุเรียน 90 กรัม
A25: 20055951 | B25: เค้กบัวลอยมะพร้าวอ่อน 100 กรัม
A26: 1113004 | B26: เค้กสามเหลี่ยม รสฝอยทองใบเตย
A27: 1111410 | B27: เค้กวันเกิดมะพร้าวอ่อน 1/2 ปอนด์
A28: 1111406 | B28: เค้กวันเกิดมะพร้าวอ่อน 1 ปอนด์
A29: 1111410 | B29: เค้กวันเกิด 1/2 ปอนด์ ธรรมดา
A30: 1113114 | B30: เค้กวันเกิด 1 ปอนด์ ธรรมดา
A31: 1200003 | B31: ท๊อฟฟี่ถั่ว (กระเช้า)
A32: 1200002 | B32: ท๊อฟฟี่ถั่ว (กล่อง)
A33: 1200001 | B33: คอนเฟลกคาราเมล (เล็ก)
A34: 1006002 | B34: วุ้นฝอยทอง (N)
A35: 25661201 | B35: วุ้นแฟนซี (N)
A36: 1113192 | B36: ปังนุ่มมะพร้าว 100 กรัม
A37: 1113193 | B37: ปังนุ่มชาไทย 100 กรัม
A38: 1113084 | B38: ขนมปังเนยนิ่ม (2 ชิ้น)
A39: 1124002 | B39: ขนมปังสังขยาใบเตยนมสด 4 ชิ้น
A40: 1113110 | B40: ขนมปังไก่หยองน้ำสลัด
...

Sheet สรุป
A2: บูธ หน้า ม.เกษตร วันที่ 1-30 กันยายน 2568 | Q2: สรุปยอดขาย บูธ หน้า ม.เกษตร วันที่ 1-30 กันยายน 2568
A3: ลำดับ | B3: รหัสสินค้า (POS) | C3: รายการ | D3: หน่วย | E3: ยกมา | F3: รับ | G3: รวม | H3: เปลี่ยน/ | I3: โยกย้าย / ระบาย | J3: คงเหลือ | K3: รายการขาย | N3: หมายเหตุ | O3: ราคาต้นทุน | P3: ยอดรวมต้นทุนสินค้า | Q3: วันที่ | R3: ยอดเงิน | S3: ส่วนลด | T3: สแกนใช้สิทธิ์ | U3: ค่าโอนเงิน | V3: ค่าใช้จ่ายอื่นๆ | W3: โอนหน้าร้าน | X3: รับสุทธิ | Y3: ยอดโอนเงิน | Z3: โอนเกิน/โอนขาด | AA3: วัน | AB3: รวมยอดขายหลังหักค่าใช้จ่าย
H4: คืน/เสีย | K4: จำนวน | L4: @ | M4: เป็นเงิน
A5: 1 | B5: 8857125001328 | C5: ชิฟฟ่อนเค้ก รวมรส (4 ชิ้น) | D5: กล่อง | E5: =+ยกมา!J5 -> 36 | F5: =+ยกมา!F5+'1'!F5+'2'!F5+'3'!F5+'4'!F5+'5'!F5+'6'!F5+'7'!F5+'8'!F5+'9'!F5+'10'!F5+'11'!F5+'12'!F5+'13'!F5+'14'!F5+'15'!F5+'16'!F5+'17'!F5+'18'!F5+'19'!F5+'20'!F5+'21'!F5+'22'!F5+'23'!F5+'24'!F5+'25'!F5+'26'!F5+'27'!F5+'28'!F5+'29'!F5+'30'!F5+'31.'!F5 -> 43 | G5: =+E5+F5 -> 79 | H5: =+'1'!H5+'2'!H5+'3'!H5+'4'!H5+'5'!H5+'6'!H5+'7'!H5+'8'!H5+'9'!H5+'10'!H5+'11'!H5+'12'!H5+'13'!H5+'14'!H5+'15'!H5+'16'!H5+'17'!H5+'18'!H5+'19'!H5+'20'!H5+'21'!H5+'22'!H5+'23'!H5+'24'!H5+'25'!H5+'26'!H5+'27'!H5+'28'!H5+'29'!H5+'30'!H5+'31.'!H5 -> 0 | I5: =+'1'!I5+'2'!I5+'3'!I5+'4'!I5+'5'!I5+'6'!I5+'7'!I5+'8'!I5+'9'!I5+'10'!I5+'11'!I5+'12'!I5+'13'!I5+'14'!I5+'15'!I5+'16'!I5+'17'!I5+'18'!I5+'19'!I5+'20'!I5+'21'!I5+'22'!I5+'23'!I5+'24'!I5+'25'!I5+'26'!I5+'27'!I5+'28'!I5+'29'!I5+'30'!I5+'31.'!I5 -> 0 | J5: =+ยกมา!J5+'1'!J5+'2'!J5+'3'!J5+'4'!J5+'5'!J5+'6'!J5+'7'!J5+'8'!J5+'9'!J5+'10'!J5+'11'!J5+'12'!J5+'13'!J5+'14'!J5+'15'!J5+'16'!J5+'17'!J5+'18'!K5+'19'!J5+'20'!J5+'21'!J5+'22'!J5+'23'!J5+'24'!J5+'25'!J5+'26'!J5+'27'!J5+'28'!J5+'29'!J5+'30'!J5+'31.'!J5 -> 660 | K5: =+'1'!K5+'2'!K5+'3'!K5+'4'!K5+'5'!K5+'6'!K5+'7'!K5+'8'!K5+'9'!K5+'10'!K5+'11'!K5+'12'!K5+'13'!K5+'14'!K5+'15'!K5+'16'!K5+'17'!K5+'18'!K5+'19'!K5+'20'!K5+'21'!K5+'22'!K5+'23'!K5+'24'!K5+'25'!K5+'26'!K5+'27'!K5+'28'!K5+'29'!K5+'30'!K5+'31.'!K5 -> 53 | L5: 50 | M5: =+'1'!M5+'2'!M5+'3'!M5+'4'!M5+'5'!M5+'6'!M5+'7'!M5+'8'!M5+'9'!M5+'10'!M5+'11'!M5+'12'!M5+'13'!M5+'14'!M5+'15'!M5+'16'!M5+'17'!M5+'18'!M5+'19'!M5+'20'!M5+'21'!M5+'22'!M5+'23'!M5+'24'!M5+'25'!M5+'26'!M5+'27'!M5+'28'!M5+'29'!M5+'30'!M5+'31.'!M5 -> 2650 | O5: 18.97 | P5: =+K5*O5 -> 1005.41 | Q5: 1 | R5: =+'1'!N256 -> 2280 | S5: =+'1'!N261 -> 250 | T5: =+'1'!N259 -> 0 | U5: =+'1'!N257 -> 0 | V5: =+'1'!N260 -> 0 | W5: =+'1'!N258 -> 1830 | X5: =+R5-S5-T5-U5-V5-W5 -> 200 | Y5: =+'1'!N263 -> 200 | Z5: =+Y5-X5 -> 0 | AA5: จันทร์ | AB5: =+W5+Y5 -> 2030 | AC5: =+W5+Y5+Z5 -> 2030
A6: 2 | B6: 8857125001311 | C6: ชิฟฟ่อนเค้ก รวมรส (8 ชิ้น) | D6: กล่อง | E6: =+ยกมา!J6 -> 114 | F6: =+ยกมา!F6+'1'!F6+'2'!F6+'3'!F6+'4'!F6+'5'!F6+'6'!F6+'7'!F6+'8'!F6+'9'!F6+'10'!F6+'11'!F6+'12'!F6+'13'!F6+'14'!F6+'15'!F6+'16'!F6+'17'!F6+'18'!F6+'19'!F6+'20'!F6+'21'!F6+'22'!F6+'23'!F6+'24'!F6+'25'!F6+'26'!F6+'27'!F6+'28'!F6+'29'!F6+'30'!F6+'31.'!F6 -> 170 | G6: =+E6+F6 -> 284 | H6: =+'1'!H6+'2'!H6+'3'!H6+'4'!H6+'5'!H6+'6'!H6+'7'!H6+'8'!H6+'9'!H6+'10'!H6+'11'!H6+'12'!H6+'13'!H6+'14'!H6+'15'!H6+'16'!H6+'17'!H6+'18'!H6+'19'!H6+'20'!H6+'21'!H6+'22'!H6+'23'!H6+'24'!H6+'25'!H6+'26'!H6+'27'!H6+'28'!H6+'29'!H6+'30'!H6+'31.'!H6 -> 0 | I6: =+'1'!I6+'2'!I6+'3'!I6+'4'!I6+'5'!I6+'6'!I6+'7'!I6+'8'!I6+'9'!I6+'10'!I6+'11'!I6+'12'!I6+'13'!I6+'14'!I6+'15'!I6+'16'!I6+'17'!I6+'18'!I6+'19'!I6+'20'!I6+'21'!I6+'22'!I6+'23'!I6+'24'!I6+'25'!I6+'26'!I6+'27'!I6+'28'!I6+'29'!I6+'30'!I6+'31.'!I6 -> 0 | J6: =+ยกมา!J6+'1'!J6+'2'!J6+'3'!J6+'4'!J6+'5'!J6+'6'!J6+'7'!J6+'8'!J6+'9'!J6+'10'!J6+'11'!J6+'12'!J6+'13'!J6+'14'!J6+'15'!J6+'16'!J6+'17'!J6+'18'!K6+'19'!J6+'20'!J6+'21'!J6+'22'!J6+'23'!J6+'24'!J6+'25'!J6+'26'!J6+'27'!J6+'28'!J6+'29'!J6+'30'!J6+'31.'!J6 -> 3048 | K6: =+'1'!K6+'2'!K6+'3'!K6+'4'!K6+'5'!K6+'6'!K6+'7'!K6+'8'!K6+'9'!K6+'10'!K6+'11'!K6+'12'!K6+'13'!K6+'14'!K6+'15'!K6+'16'!K6+'17'!K6+'18'!K6+'19'!K6+'20'!K6+'21'!K6+'22'!K6+'23'!K6+'24'!K6+'25'!K6+'26'!K6+'27'!K6+'28'!K6+'29'!K6+'30'!K6+'31.'!K6 -> 200 | L6: 100 | M6: =+'1'!M6+'2'!M6+'3'!M6+'4'!M6+'5'!M6+'6'!M6+'7'!M6+'8'!M6+'9'!M6+'10'!M6+'11'!M6+'12'!M6+'13'!M6+'14'!M6+'15'!M6+'16'!M6+'17'!M6+'18'!M6+'19'!M6+'20'!M6+'21'!M6+'22'!M6+'23'!M6+'24'!M6+'25'!M6+'26'!M6+'27'!M6+'28'!M6+'29'!M6+'30'!M6+'31.'!M6 -> 20000 | O6: 36.43 | P6: =+K6*O6 -> 7286 | Q6: 2 | R6: =+'2'!N256 -> 4488 | S6: =+'2'!N261 -> 380 | T6: =+'2'!N259 -> 0 | U6: =+'2'!N257 -> 0 | V6: =+'2'!N260 -> 50 | W6: =+'2'!N258 -> 1508 | X6: =+R6-S6-T6-U6-V6-W6 -> 2550 | Y6: =+'2'!N263 -> 2550 | Z6: =+Y6-X6 -> 0 | AA6: อังคาร | AB6: =+W6+Y6 -> 4058 | AC6: =+W6+Y6+Z6 -> 4058
A7: 3 | B7: 8857125003841 | C7: ชิฟฟ่อนเค้ก รสกาแฟ (4 ชิ้น) | D7: ชิ้น | E7: =+ยกมา!J7 -> 0 | F7: =+ยกมา!F7+'1'!F7+'2'!F7+'3'!F7+'4'!F7+'5'!F7+'6'!F7+'7'!F7+'8'!F7+'9'!F7+'10'!F7+'11'!F7+'12'!F7+'13'!F7+'14'!F7+'15'!F7+'16'!F7+'17'!F7+'18'!F7+'19'!F7+'20'!F7+'21'!F7+'22'!F7+'23'!F7+'24'!F7+'25'!F7+'26'!F7+'27'!F7+'28'!F7+'29'!F7+'30'!F7+'31.'!F7 -> 0 | G7: =+E7+F7 -> 0 | H7: =+'1'!H7+'2'!H7+'3'!H7+'4'!H7+'5'!H7+'6'!H7+'7'!H7+'8'!H7+'9'!H7+'10'!H7+'11'!H7+'12'!H7+'13'!H7+'14'!H7+'15'!H7+'16'!H7+'17'!H7+'18'!H7+'19'!H7+'20'!H7+'21'!H7+'22'!H7+'23'!H7+'24'!H7+'25'!H7+'26'!H7+'27'!H7+'28'!H7+'29'!H7+'30'!H7+'31.'!H7 -> 0 | I7: =+'1'!I7+'2'!I7+'3'!I7+'4'!I7+'5'!I7+'6'!I7+'7'!I7+'8'!I7+'9'!I7+'10'!I7+'11'!I7+'12'!I7+'13'!I7+'14'!I7+'15'!I7+'16'!I7+'17'!I7+'18'!I7+'19'!I7+'20'!I7+'21'!I7+'22'!I7+'23'!I7+'24'!I7+'25'!I7+'26'!I7+'27'!I7+'28'!I7+'29'!I7+'30'!I7+'31.'!I7 -> 0 | J7: =+ยกมา!J7+'1'!J7+'2'!J7+'3'!J7+'4'!J7+'5'!J7+'6'!J7+'7'!J7+'8'!J7+'9'!J7+'10'!J7+'11'!J7+'12'!J7+'13'!J7+'14'!J7+'15'!J7+'16'!J7+'17'!J7+'18'!K7+'19'!J7+'20'!J7+'21'!J7+'22'!J7+'23'!J7+'24'!J7+'25'!J7+'26'!J7+'27'!J7+'28'!J7+'29'!J7+'30'!J7+'31.'!J7 -> 0 | K7: =+'1'!K7+'2'!K7+'3'!K7+'4'!K7+'5'!K7+'6'!K7+'7'!K7+'8'!K7+'9'!K7+'10'!K7+'11'!K7+'12'!K7+'13'!K7+'14'!K7+'15'!K7+'16'!K7+'17'!K7+'18'!K7+'19'!K7+'20'!K7+'21'!K7+'22'!K7+'23'!K7+'24'!K7+'25'!K7+'26'!K7+'27'!K7+'28'!K7+'29'!K7+'30'!K7+'31.'!K7 -> 0 | L7: 50 | M7: =+'1'!M7+'2'!M7+'3'!M7+'4'!M7+'5'!M7+'6'!M7+'7'!M7+'8'!M7+'9'!M7+'10'!M7+'11'!M7+'12'!M7+'13'!M7+'14'!M7+'15'!M7+'16'!M7+'17'!M7+'18'!M7+'19'!M7+'20'!M7+'21'!M7+'22'!M7+'23'!M7+'24'!M7+'25'!M7+'26'!M7+'27'!M7+'28'!M7+'29'!M7+'30'!M7+'31.'!M7 -> 0 | O7: 26.11 | P7: =+K7*O7 -> 0 | Q7: 3 | R7: =+'3'!N256 -> 1017 | S7: =+'3'!N261 -> 402 | T7: =+'3'!N259 -> 0 | U7: =+'3'!N257 -> 0 | V7: =+'3'!N260 -> 49 | W7: =+'3'!N258 -> 80 | X7: =+R7-S7-T7-U7-V7-W7 -> 486 | Y7: =+'3'!N263 -> 486 | Z7: =+Y7-X7 -> 0 | AA7: พุธ | AB7: =+W7+Y7 -> 566 | AC7: =+W7+Y7+Z7 -> 566
A8: 4 | B8: 8857125003827 | C8: ชิฟฟ่อนเค้ก รสกาแฟ (8 ชิ้น) | D8: กล่อง | E8: =+ยกมา!J8 -> 0 | F8: =+ยกมา!F8+'1'!F8+'2'!F8+'3'!F8+'4'!F8+'5'!F8+'6'!F8+'7'!F8+'8'!F8+'9'!F8+'10'!F8+'11'!F8+'12'!F8+'13'!F8+'14'!F8+'15'!F8+'16'!F8+'17'!F8+'18'!F8+'19'!F8+'20'!F8+'21'!F8+'22'!F8+'23'!F8+'24'!F8+'25'!F8+'26'!F8+'27'!F8+'28'!F8+'29'!F8+'30'!F8+'31.'!F8 -> 5 | G8: =+E8+F8 -> 5 | H8: =+'1'!H8+'2'!H8+'3'!H8+'4'!H8+'5'!H8+'6'!H8+'7'!H8+'8'!H8+'9'!H8+'10'!H8+'11'!H8+'12'!H8+'13'!H8+'14'!H8+'15'!H8+'16'!H8+'17'!H8+'18'!H8+'19'!H8+'20'!H8+'21'!H8+'22'!H8+'23'!H8+'24'!H8+'25'!H8+'26'!H8+'27'!H8+'28'!H8+'29'!H8+'30'!H8+'31.'!H8 -> 0 | I8: =+'1'!I8+'2'!I8+'3'!I8+'4'!I8+'5'!I8+'6'!I8+'7'!I8+'8'!I8+'9'!I8+'10'!I8+'11'!I8+'12'!I8+'13'!I8+'14'!I8+'15'!I8+'16'!I8+'17'!I8+'18'!I8+'19'!I8+'20'!I8+'21'!I8+'22'!I8+'23'!I8+'24'!I8+'25'!I8+'26'!I8+'27'!I8+'28'!I8+'29'!I8+'30'!I8+'31.'!I8 -> 0 | J8: =+ยกมา!J8+'1'!J8+'2'!J8+'3'!J8+'4'!J8+'5'!J8+'6'!J8+'7'!J8+'8'!J8+'9'!J8+'10'!J8+'11'!J8+'12'!J8+'13'!J8+'14'!J8+'15'!J8+'16'!J8+'17'!J8+'18'!K8+'19'!J8+'20'!J8+'21'!J8+'22'!J8+'23'!J8+'24'!J8+'25'!J8+'26'!J8+'27'!J8+'28'!J8+'29'!J8+'30'!J8+'31.'!J8 -> 44 | K8: =+'1'!K8+'2'!K8+'3'!K8+'4'!K8+'5'!K8+'6'!K8+'7'!K8+'8'!K8+'9'!K8+'10'!K8+'11'!K8+'12'!K8+'13'!K8+'14'!K8+'15'!K8+'16'!K8+'17'!K8+'18'!K8+'19'!K8+'20'!K8+'21'!K8+'22'!K8+'23'!K8+'24'!K8+'25'!K8+'26'!K8+'27'!K8+'28'!K8+'29'!K8+'30'!K8+'31.'!K8 -> 5 | L8: 100 | M8: =+'1'!M8+'2'!M8+'3'!M8+'4'!M8+'5'!M8+'6'!M8+'7'!M8+'8'!M8+'9'!M8+'10'!M8+'11'!M8+'12'!M8+'13'!M8+'14'!M8+'15'!M8+'16'!M8+'17'!M8+'18'!M8+'19'!M8+'20'!M8+'21'!M8+'22'!M8+'23'!M8+'24'!M8+'25'!M8+'26'!M8+'27'!M8+'28'!M8+'29'!M8+'30'!M8+'31.'!M8 -> 300 | O8: 33.89 | P8: =+K8*O8 -> 169.45 | Q8: 4 | R8: =+'4'!N256 -> 3518 | S8: =+'4'!N261 -> 518 | T8: =+'4'!N259 -> 0 | U8: =+'4'!N257 -> 0 | V8: =+'4'!N260 -> 170 | W8: =+'4'!N258 -> 1825 | X8: =+R8-S8-T8-U8-V8-W8 -> 1005 | Y8: =+'4'!N263 -> 1005 | Z8: =+Y8-X8 -> 0 | AA8: พฤหัสบดี | AB8: =+W8+Y8 -> 2830 | AC8: =+W8+Y8+Z8 -> 2830
A9: 5 | B9: 8857125002257 | C9: ชิฟฟ่อนเค้ก 1 ชิ้น | D9: ชิ้น | E9: =+ยกมา!J9 -> 0 | F9: =+ยกมา!F9+'1'!F9+'2'!F9+'3'!F9+'4'!F9+'5'!F9+'6'!F9+'7'!F9+'8'!F9+'9'!F9+'10'!F9+'11'!F9+'12'!F9+'13'!F9+'14'!F9+'15'!F9+'16'!F9+'17'!F9+'18'!F9+'19'!F9+'20'!F9+'21'!F9+'22'!F9+'23'!F9+'24'!F9+'25'!F9+'26'!F9+'27'!F9+'28'!F9+'29'!F9+'30'!F9+'31.'!F9 -> 0 | G9: =+E9+F9 -> 0 | H9: =+'1'!H9+'2'!H9+'3'!H9+'4'!H9+'5'!H9+'6'!H9+'7'!H9+'8'!H9+'9'!H9+'10'!H9+'11'!H9+'12'!H9+'13'!H9+'14'!H9+'15'!H9+'16'!H9+'17'!H9+'18'!H9+'19'!H9+'20'!H9+'21'!H9+'22'!H9+'23'!H9+'24'!H9+'25'!H9+'26'!H9+'27'!H9+'28'!H9+'29'!H9+'30'!H9+'31.'!H9 -> 0 | I9: =+'1'!I9+'2'!I9+'3'!I9+'4'!I9+'5'!I9+'6'!I9+'7'!I9+'8'!I9+'9'!I9+'10'!I9+'11'!I9+'12'!I9+'13'!I9+'14'!I9+'15'!I9+'16'!I9+'17'!I9+'18'!I9+'19'!I9+'20'!I9+'21'!I9+'22'!I9+'23'!I9+'24'!I9+'25'!I9+'26'!I9+'27'!I9+'28'!I9+'29'!I9+'30'!I9+'31.'!I9 -> 0 | J9: =+ยกมา!J9+'1'!J9+'2'!J9+'3'!J9+'4'!J9+'5'!J9+'6'!J9+'7'!J9+'8'!J9+'9'!J9+'10'!J9+'11'!J9+'12'!J9+'13'!J9+'14'!J9+'15'!J9+'16'!J9+'17'!J9+'18'!K9+'19'!J9+'20'!J9+'21'!J9+'22'!J9+'23'!J9+'24'!J9+'25'!J9+'26'!J9+'27'!J9+'28'!J9+'29'!J9+'30'!J9+'31.'!J9 -> 0 | K9: =+'1'!K9+'2'!K9+'3'!K9+'4'!K9+'5'!K9+'6'!K9+'7'!K9+'8'!K9+'9'!K9+'10'!K9+'11'!K9+'12'!K9+'13'!K9+'14'!K9+'15'!K9+'16'!K9+'17'!K9+'18'!K9+'19'!K9+'20'!K9+'21'!K9+'22'!K9+'23'!K9+'24'!K9+'25'!K9+'26'!K9+'27'!K9+'28'!K9+'29'!K9+'30'!K9+'31.'!K9 -> 0 | L9: 10 | M9: =+'1'!M9+'2'!M9+'3'!M9+'4'!M9+'5'!M9+'6'!M9+'7'!M9+'8'!M9+'9'!M9+'10'!M9+'11'!M9+'12'!M9+'13'!M9+'14'!M9+'15'!M9+'16'!M9+'17'!M9+'18'!M9+'19'!M9+'20'!M9+'21'!M9+'22'!M9+'23'!M9+'24'!M9+'25'!M9+'26'!M9+'27'!M9+'28'!M9+'29'!M9+'30'!M9+'31.'!M9 -> 0 | P9: =+K9*O9 -> 0 | Q9: 5 | R9: =+'5'!N256 -> 6684 | S9: =+'5'!N261 -> 1611 | T9: =+'5'!N259 -> 0 | U9: =+'5'!N257 -> 0 | V9: =+'5'!N260 -> 0 | W9: =+'5'!N258 -> 2830 | X9: =+R9-S9-T9-U9-V9-W9 -> 2243 | Y9: =+'5'!N263 -> 2243 | Z9: =+Y9-X9 -> 0 | AA9: ศุกร์ | AB9: =+W9+Y9 -> 5073 | AC9: =+W9+Y9+Z9 -> 5073
A10: 6 | B10: 8857125002264 | C10: ชิฟฟ่อนเค้กสอดไส้แยม 1 ชิ้น | D10: ชิ้น | E10: =+ยกมา!J10 -> 0 | F10: =+ยกมา!F10+'1'!F10+'2'!F10+'3'!F10+'4'!F10+'5'!F10+'6'!F10+'7'!F10+'8'!F10+'9'!F10+'10'!F10+'11'!F10+'12'!F10+'13'!F10+'14'!F10+'15'!F10+'16'!F10+'17'!F10+'18'!F10+'19'!F10+'20'!F10+'21'!F10+'22'!F10+'23'!F10+'24'!F10+'25'!F10+'26'!F10+'27'!F10+'28'!F10+'29'!F10+'30'!F10+'31.'!F10 -> 0 | G10: =+E10+F10 -> 0 | H10: =+'1'!H10+'2'!H10+'3'!H10+'4'!H10+'5'!H10+'6'!H10+'7'!H10+'8'!H10+'9'!H10+'10'!H10+'11'!H10+'12'!H10+'13'!H10+'14'!H10+'15'!H10+'16'!H10+'17'!H10+'18'!H10+'19'!H10+'20'!H10+'21'!H10+'22'!H10+'23'!H10+'24'!H10+'25'!H10+'26'!H10+'27'!H10+'28'!H10+'29'!H10+'30'!H10+'31.'!H10 -> 0 | I10: =+'1'!I10+'2'!I10+'3'!I10+'4'!I10+'5'!I10+'6'!I10+'7'!I10+'8'!I10+'9'!I10+'10'!I10+'11'!I10+'12'!I10+'13'!I10+'14'!I10+'15'!I10+'16'!I10+'17'!I10+'18'!I10+'19'!I10+'20'!I10+'21'!I10+'22'!I10+'23'!I10+'24'!I10+'25'!I10+'26'!I10+'27'!I10+'28'!I10+'29'!I10+'30'!I10+'31.'!I10 -> 0 | J10: =+ยกมา!J10+'1'!J10+'2'!J10+'3'!J10+'4'!J10+'5'!J10+'6'!J10+'7'!J10+'8'!J10+'9'!J10+'10'!J10+'11'!J10+'12'!J10+'13'!J10+'14'!J10+'15'!J10+'16'!J10+'17'!J10+'18'!K10+'19'!J10+'20'!J10+'21'!J10+'22'!J10+'23'!J10+'24'!J10+'25'!J10+'26'!J10+'27'!J10+'28'!J10+'29'!J10+'30'!J10+'31.'!J10 -> 0 | K10: =+'1'!K10+'2'!K10+'3'!K10+'4'!K10+'5'!K10+'6'!K10+'7'!K10+'8'!K10+'9'!K10+'10'!K10+'11'!K10+'12'!K10+'13'!K10+'14'!K10+'15'!K10+'16'!K10+'17'!K10+'18'!K10+'19'!K10+'20'!K10+'21'!K10+'22'!K10+'23'!K10+'24'!K10+'25'!K10+'26'!K10+'27'!K10+'28'!K10+'29'!K10+'30'!K10+'31.'!K10 -> 0 | L10: 15 | M10: =+'1'!M10+'2'!M10+'3'!M10+'4'!M10+'5'!M10+'6'!M10+'7'!M10+'8'!M10+'9'!M10+'10'!M10+'11'!M10+'12'!M10+'13'!M10+'14'!M10+'15'!M10+'16'!M10+'17'!M10+'18'!M10+'19'!M10+'20'!M10+'21'!M10+'22'!M10+'23'!M10+'24'!M10+'25'!M10+'26'!M10+'27'!M10+'28'!M10+'29'!M10+'30'!M10+'31.'!M10 -> 0 | P10: =+K10*O10 -> 0 | Q10: 6 | R10: =+'6'!N256 -> 1415 | S10: =+'6'!N261 -> 152 | T10: =+'6'!N259 -> 0 | U10: =+'6'!N257 -> 0 | V10: =+'6'!N260 -> 0 | W10: =+'6'!N258 -> 570 | X10: =+R10-S10-T10-U10-V10-W10 -> 693 | Y10: =+'6'!N263 -> 693 | Z10: =+Y10-X10 -> 0 | AA10: เสาร์ | AB10: =+W10+Y10 -> 1263 | AC10: =+W10+Y10+Z10 -> 1263
A11: 7 | B11: 8857125001830 | C11: ชิฟฟ่อนเค้กสอดไส้ รวมรส (3 ชิ้น) | D11: กล่อง | E11: =+ยกมา!J11 -> 5 | F11: =+ยกมา!F11+'1'!F11+'2'!F11+'3'!F11+'4'!F11+'5'!F11+'6'!F11+'7'!F11+'8'!F11+'9'!F11+'10'!F11+'11'!F11+'12'!F11+'13'!F11+'14'!F11+'15'!F11+'16'!F11+'17'!F11+'18'!F11+'19'!F11+'20'!F11+'21'!F11+'22'!F11+'23'!F11+'24'!F11+'25'!F11+'26'!F11+'27'!F11+'28'!F11+'29'!F11+'30'!F11+'31.'!F11 -> 10 | G11: =+E11+F11 -> 15 | H11: =+'1'!H11+'2'!H11+'3'!H11+'4'!H11+'5'!H11+'6'!H11+'7'!H11+'8'!H11+'9'!H11+'10'!H11+'11'!H11+'12'!H11+'13'!H11+'14'!H11+'15'!H11+'16'!H11+'17'!H11+'18'!H11+'19'!H11+'20'!H11+'21'!H11+'22'!H11+'23'!H11+'24'!H11+'25'!H11+'26'!H11+'27'!H11+'28'!H11+'29'!H11+'30'!H11+'31.'!H11 -> 0 | I11: =+'1'!I11+'2'!I11+'3'!I11+'4'!I11+'5'!I11+'6'!I11+'7'!I11+'8'!I11+'9'!I11+'10'!I11+'11'!I11+'12'!I11+'13'!I11+'14'!I11+'15'!I11+'16'!I11+'17'!I11+'18'!I11+'19'!I11+'20'!I11+'21'!I11+'22'!I11+'23'!I11+'24'!I11+'25'!I11+'26'!I11+'27'!I11+'28'!I11+'29'!I11+'30'!I11+'31.'!I11 -> 0 | J11: =+ยกมา!J11+'1'!J11+'2'!J11+'3'!J11+'4'!J11+'5'!J11+'6'!J11+'7'!J11+'8'!J11+'9'!J11+'10'!J11+'11'!J11+'12'!J11+'13'!J11+'14'!J11+'15'!J11+'16'!J11+'17'!J11+'18'!K11+'19'!J11+'20'!J11+'21'!J11+'22'!J11+'23'!J11+'24'!J11+'25'!J11+'26'!J11+'27'!J11+'28'!J11+'29'!J11+'30'!J11+'31.'!J11 -> 96 | K11: =+'1'!K11+'2'!K11+'3'!K11+'4'!K11+'5'!K11+'6'!K11+'7'!K11+'8'!K11+'9'!K11+'10'!K11+'11'!K11+'12'!K11+'13'!K11+'14'!K11+'15'!K11+'16'!K11+'17'!K11+'18'!K11+'19'!K11+'20'!K11+'21'!K11+'22'!K11+'23'!K11+'24'!K11+'25'!K11+'26'!K11+'27'!K11+'28'!K11+'29'!K11+'30'!K11+'31.'!K11 -> 11 | L11: 50 | M11: =+'1'!M11+'2'!M11+'3'!M11+'4'!M11+'5'!M11+'6'!M11+'7'!M11+'8'!M11+'9'!M11+'10'!M11+'11'!M11+'12'!M11+'13'!M11+'14'!M11+'15'!M11+'16'!M11+'17'!M11+'18'!M11+'19'!M11+'20'!M11+'21'!M11+'22'!M11+'23'!M11+'24'!M11+'25'!M11+'26'!M11+'27'!M11+'28'!M11+'29'!M11+'30'!M11+'31.'!M11 -> 550 | O11: 19.36 | P11: =+K11*O11 -> 212.96 | Q11: 7 | R11: =+'7'!N256 -> 4785 | S11: =+'7'!N261 -> 890 | T11: =+'7'!N259 -> 0 | U11: =+'7'!N257 -> 0 | V11: =+'7'!N260 -> 0 | W11: =+'7'!N258 -> 2105 | X11: =+R11-S11-T11-U11-V11-W11 -> 1790 | Y11: =+'7'!N263 -> 1790 | Z11: =+Y11-X11 -> 0 | AA11: อาทิตย์ | AB11: =+W11+Y11 -> 3895 | AC11: =+W11+Y11+Z11 -> 3895
A12: 8 | B12: 1112539 | C12: ชิฟฟ่อนเค้กสอดไส้ เมล่อน (3 ชิ้น) | D12: กล่อง | E12: =+ยกมา!J12 -> 0 | F12: =+ยกมา!F12+'1'!F12+'2'!F12+'3'!F12+'4'!F12+'5'!F12+'6'!F12+'7'!F12+'8'!F12+'9'!F12+'10'!F12+'11'!F12+'12'!F12+'13'!F12+'14'!F12+'15'!F12+'16'!F12+'17'!F12+'18'!F12+'19'!F12+'20'!F12+'21'!F12+'22'!F12+'23'!F12+'24'!F12+'25'!F12+'26'!F12+'27'!F12+'28'!F12+'29'!F12+'30'!F12+'31.'!F12 -> 0 | G12: =+E12+F12 -> 0 | H12: =+'1'!H12+'2'!H12+'3'!H12+'4'!H12+'5'!H12+'6'!H12+'7'!H12+'8'!H12+'9'!H12+'10'!H12+'11'!H12+'12'!H12+'13'!H12+'14'!H12+'15'!H12+'16'!H12+'17'!H12+'18'!H12+'19'!H12+'20'!H12+'21'!H12+'22'!H12+'23'!H12+'24'!H12+'25'!H12+'26'!H12+'27'!H12+'28'!H12+'29'!H12+'30'!H12+'31.'!H12 -> 0 | I12: =+'1'!I12+'2'!I12+'3'!I12+'4'!I12+'5'!I12+'6'!I12+'7'!I12+'8'!I12+'9'!I12+'10'!I12+'11'!I12+'12'!I12+'13'!I12+'14'!I12+'15'!I12+'16'!I12+'17'!I12+'18'!I12+'19'!I12+'20'!I12+'21'!I12+'22'!I12+'23'!I12+'24'!I12+'25'!I12+'26'!I12+'27'!I12+'28'!I12+'29'!I12+'30'!I12+'31.'!I12 -> 0 | J12: =+ยกมา!J12+'1'!J12+'2'!J12+'3'!J12+'4'!J12+'5'!J12+'6'!J12+'7'!J12+'8'!J12+'9'!J12+'10'!J12+'11'!J12+'12'!J12+'13'!J12+'14'!J12+'15'!J12+'16'!J12+'17'!J12+'18'!K12+'19'!J12+'20'!J12+'21'!J12+'22'!J12+'23'!J12+'24'!J12+'25'!J12+'26'!J12+'27'!J12+'28'!J12+'29'!J12+'30'!J12+'31.'!J12 -> 0 | K12: =+'1'!K12+'2'!K12+'3'!K12+'4'!K12+'5'!K12+'6'!K12+'7'!K12+'8'!K12+'9'!K12+'10'!K12+'11'!K12+'12'!K12+'13'!K12+'14'!K12+'15'!K12+'16'!K12+'17'!K12+'18'!K12+'19'!K12+'20'!K12+'21'!K12+'22'!K12+'23'!K12+'24'!K12+'25'!K12+'26'!K12+'27'!K12+'28'!K12+'29'!K12+'30'!K12+'31.'!K12 -> 0 | L12: 50 | M12: =+'1'!M12+'2'!M12+'3'!M12+'4'!M12+'5'!M12+'6'!M12+'7'!M12+'8'!M12+'9'!M12+'10'!M12+'11'!M12+'12'!M12+'13'!M12+'14'!M12+'15'!M12+'16'!M12+'17'!M12+'18'!M12+'19'!M12+'20'!M12+'21'!M12+'22'!M12+'23'!M12+'24'!M12+'25'!M12+'26'!M12+'27'!M12+'28'!M12+'29'!M12+'30'!M12+'31.'!M12 -> 0 | P12: =+K12*O12 -> 0 | Q12: 8 | R12: =+'8'!N256 -> 3425 | S12: =+'8'!N261 -> 135 | T12: =+'8'!N257 -> 0 | U12: =+'8'!N257 -> 0 | V12: =+'8'!N260 -> 0 | W12: =+'8'!N258 -> 2625 | X12: =+R12-S12-T12-U12-V12-W12 -> 665 | Y12: =+'8'!N263 -> 665 | Z12: =+Y12-X12 -> 0 | AA12: จันทร์ | AB12: =+W12+Y12 -> 3290 | AC12: =+W12+Y12+Z12 -> 3290
A13: 9 | B13: 8857125000055 | C13: ชิฟฟ่อนเค้กสอดไส้แยม รสบลูเบอร์รี่ (3 ชิ้น) | D13: กล่อง | E13: =+ยกมา!J13 -> 0 | F13: =+ยกมา!F13+'1'!F13+'2'!F13+'3'!F13+'4'!F13+'5'!F13+'6'!F13+'7'!F13+'8'!F13+'9'!F13+'10'!F13+'11'!F13+'12'!F13+'13'!F13+'14'!F13+'15'!F13+'16'!F13+'17'!F13+'18'!F13+'19'!F13+'20'!F13+'21'!F13+'22'!F13+'23'!F13+'24'!F13+'25'!F13+'26'!F13+'27'!F13+'28'!F13+'29'!F13+'30'!F13+'31.'!F13 -> 0 | G13: =+E13+F13 -> 0 | H13: =+'1'!H13+'2'!H13+'3'!H13+'4'!H13+'5'!H13+'6'!H13+'7'!H13+'8'!H13+'9'!H13+'10'!H13+'11'!H13+'12'!H13+'13'!H13+'14'!H13+'15'!H13+'16'!H13+'17'!H13+'18'!H13+'19'!H13+'20'!H13+'21'!H13+'22'!H13+'23'!H13+'24'!H13+'25'!H13+'26'!H13+'27'!H13+'28'!H13+'29'!H13+'30'!H13+'31.'!H13 -> 0 | I13: =+'1'!I13+'2'!I13+'3'!I13+'4'!I13+'5'!I13+'6'!I13+'7'!I13+'8'!I13+'9'!I13+'10'!I13+'11'!I13+'12'!I13+'13'!I13+'14'!I13+'15'!I13+'16'!I13+'17'!I13+'18'!I13+'19'!I13+'20'!I13+'21'!I13+'22'!I13+'23'!I13+'24'!I13+'25'!I13+'26'!I13+'27'!I13+'28'!I13+'29'!I13+'30'!I13+'31.'!I13 -> 0 | J13: =+ยกมา!J13+'1'!J13+'2'!J13+'3'!J13+'4'!J13+'5'!J13+'6'!J13+'7'!J13+'8'!J13+'9'!J13+'10'!J13+'11'!J13+'12'!J13+'13'!J13+'14'!J13+'15'!J13+'16'!J13+'17'!J13+'18'!K13+'19'!J13+'20'!J13+'21'!J13+'22'!J13+'23'!J13+'24'!J13+'25'!J13+'26'!J13+'27'!J13+'28'!J13+'29'!J13+'30'!J13+'31.'!J13 -> 0 | K13: =+'1'!K13+'2'!K13+'3'!K13+'4'!K13+'5'!K13+'6'!K13+'7'!K13+'8'!K13+'9'!K13+'10'!K13+'11'!K13+'12'!K13+'13'!K13+'14'!K13+'15'!K13+'16'!K13+'17'!K13+'18'!K13+'19'!K13+'20'!K13+'21'!K13+'22'!K13+'23'!K13+'24'!K13+'25'!K13+'26'!K13+'27'!K13+'28'!K13+'29'!K13+'30'!K13+'31.'!K13 -> 0 | L13: 50 | M13: =+'1'!M13+'2'!M13+'3'!M13+'4'!M13+'5'!M13+'6'!M13+'7'!M13+'8'!M13+'9'!M13+'10'!M13+'11'!M13+'12'!M13+'13'!M13+'14'!M13+'15'!M13+'16'!M13+'17'!M13+'18'!M13+'19'!M13+'20'!M13+'21'!M13+'22'!M13+'23'!M13+'24'!M13+'25'!M13+'26'!M13+'27'!M13+'28'!M13+'29'!M13+'30'!M13+'31.'!M13 -> 0 | O13: 19.82 | P13: =+K13*O13 -> 0 | Q13: 9 | R13: =+'9'!N256 -> 4020 | S13: =+'9'!N261 -> 905 | T13: =+'9'!N257 -> 0 | U13: =+'9'!N257 -> 0 | V13: =+'9'!N260 -> 0 | W13: =+'9'!N258 -> 1205 | X13: =+R13-S13-T13-U13-V13-W13 -> 1910 | Y13: =+'9'!N263 -> 1910 | Z13: =+Y13-X13 -> 0 | AA13: อังคาร | AB13: =+W13+Y13 -> 3115 | AC13: =+W13+Y13+Z13 -> 3115
A14: 10 | B14: 8857125000987 | C14: ชิฟฟ่อนเค้กสอดไส้แยม รสส้ม (3 ชิ้น) | D14: กล่อง | E14: =+ยกมา!J14 -> 0 | F14: =+ยกมา!F14+'1'!F14+'2'!F14+'3'!F14+'4'!F14+'5'!F14+'6'!F14+'7'!F14+'8'!F14+'9'!F14+'10'!F14+'11'!F14+'12'!F14+'13'!F14+'14'!F14+'15'!F14+'16'!F14+'17'!F14+'18'!F14+'19'!F14+'20'!F14+'21'!F14+'22'!F14+'23'!F14+'24'!F14+'25'!F14+'26'!F14+'27'!F14+'28'!F14+'29'!F14+'30'!F14+'31.'!F14 -> 0 | G14: =+E14+F14 -> 0 | H14: =+'1'!H14+'2'!H14+'3'!H14+'4'!H14+'5'!H14+'6'!H14+'7'!H14+'8'!H14+'9'!H14+'10'!H14+'11'!H14+'12'!H14+'13'!H14+'14'!H14+'15'!H14+'16'!H14+'17'!H14+'18'!H14+'19'!H14+'20'!H14+'21'!H14+'22'!H14+'23'!H14+'24'!H14+'25'!H14+'26'!H14+'27'!H14+'28'!H14+'29'!H14+'30'!H14+'31.'!H14 -> 0 | I14: =+'1'!I14+'2'!I14+'3'!I14+'4'!I14+'5'!I14+'6'!I14+'7'!I14+'8'!I14+'9'!I14+'10'!I14+'11'!I14+'12'!I14+'13'!I14+'14'!I14+'15'!I14+'16'!I14+'17'!I14+'18'!I14+'19'!I14+'20'!I14+'21'!I14+'22'!I14+'23'!I14+'24'!I14+'25'!I14+'26'!I14+'27'!I14+'28'!I14+'29'!I14+'30'!I14+'31.'!I14 -> 0 | J14: =+ยกมา!J14+'1'!J14+'2'!J14+'3'!J14+'4'!J14+'5'!J14+'6'!J14+'7'!J14+'8'!J14+'9'!J14+'10'!J14+'11'!J14+'12'!J14+'13'!J14+'14'!J14+'15'!J14+'16'!J14+'17'!J14+'18'!K14+'19'!J14+'20'!J14+'21'!J14+'22'!J14+'23'!J14+'24'!J14+'25'!J14+'26'!J14+'27'!J14+'28'!J14+'29'!J14+'30'!J14+'31.'!J14 -> 0 | K14: =+'1'!K14+'2'!K14+'3'!K14+'4'!K14+'5'!K14+'6'!K14+'7'!K14+'8'!K14+'9'!K14+'10'!K14+'11'!K14+'12'!K14+'13'!K14+'14'!K14+'15'!K14+'16'!K14+'17'!K14+'18'!K14+'19'!K14+'20'!K14+'21'!K14+'22'!K14+'23'!K14+'24'!K14+'25'!K14+'26'!K14+'27'!K14+'28'!K14+'29'!K14+'30'!K14+'31.'!K14 -> 0 | L14: 50 | M14: =+'1'!M14+'2'!M14+'3'!M14+'4'!M14+'5'!M14+'6'!M14+'7'!M14+'8'!M14+'9'!M14+'10'!M14+'11'!M14+'12'!M14+'13'!M14+'14'!M14+'15'!M14+'16'!M14+'17'!M14+'18'!M14+'19'!M14+'20'!M14+'21'!M14+'22'!M14+'23'!M14+'24'!M14+'25'!M14+'26'!M14+'27'!M14+'28'!M14+'29'!M14+'30'!M14+'31.'!M14 -> 0 | O14: 19.41 | P14: =+K14*O14 -> 0 | Q14: 10 | R14: =+'10'!N256 -> 4090 | S14: =+'10'!N261 -> 1404 | T14: =+'10'!N259 -> 0 | U14: =+'10'!N257 -> 0 | V14: =+'10'!N260 -> 0 | W14: =+'10'!N258 -> 1863 | X14: =+R14-S14-T14-U14-V14-W14 -> 823 | Y14: =+'10'!N263 -> 823 | Z14: =+Y14-X14 -> 0 | AA14: พุธ | AB14: =+W14+Y14 -> 2686 | AC14: =+W14+Y14+Z14 -> 2686
A15: 11 | B15: 8857125000246 | C15: ชิฟฟ่อนเค้กหน้าฝอยทอง สอดไส้แยมส้ม (3 ชิ้น) | D15: กล่อง | E15: =+ยกมา!J15 -> 0 | F15: =+ยกมา!F15+'1'!F15+'2'!F15+'3'!F15+'4'!F15+'5'!F15+'6'!F15+'7'!F15+'8'!F15+'9'!F15+'10'!F15+'11'!F15+'12'!F15+'13'!F15+'14'!F15+'15'!F15+'16'!F15+'17'!F15+'18'!F15+'19'!F15+'20'!F15+'21'!F15+'22'!F15+'23'!F15+'24'!F15+'25'!F15+'26'!F15+'27'!F15+'28'!F15+'29'!F15+'30'!F15+'31.'!F15 -> 0 | G15: =+E15+F15 -> 0 | H15: =+'1'!H15+'2'!H15+'3'!H15+'4'!H15+'5'!H15+'6'!H15+'7'!H15+'8'!H15+'9'!H15+'10'!H15+'11'!H15+'12'!H15+'13'!H15+'14'!H15+'15'!H15+'16'!H15+'17'!H15+'18'!H15+'19'!H15+'20'!H15+'21'!H15+'22'!H15+'23'!H15+'24'!H15+'25'!H15+'26'!H15+'27'!H15+'28'!H15+'29'!H15+'30'!H15+'31.'!H15 -> 0 | I15: =+'1'!I15+'2'!I15+'3'!I15+'4'!I15+'5'!I15+'6'!I15+'7'!I15+'8'!I15+'9'!I15+'10'!I15+'11'!I15+'12'!I15+'13'!I15+'14'!I15+'15'!I15+'16'!I15+'17'!I15+'18'!I15+'19'!I15+'20'!I15+'21'!I15+'22'!I15+'23'!I15+'24'!I15+'25'!I15+'26'!I15+'27'!I15+'28'!I15+'29'!I15+'30'!I15+'31.'!I15 -> 0 | J15: =+ยกมา!J15+'1'!J15+'2'!J15+'3'!J15+'4'!J15+'5'!J15+'6'!J15+'7'!J15+'8'!J15+'9'!J15+'10'!J15+'11'!J15+'12'!J15+'13'!J15+'14'!J15+'15'!J15+'16'!J15+'17'!J15+'18'!K15+'19'!J15+'20'!J15+'21'!J15+'22'!J15+'23'!J15+'24'!J15+'25'!J15+'26'!J15+'27'!J15+'28'!J15+'29'!J15+'30'!J15+'31.'!J15 -> 0 | K15: =+'1'!K15+'2'!K15+'3'!K15+'4'!K15+'5'!K15+'6'!K15+'7'!K15+'8'!K15+'9'!K15+'10'!K15+'11'!K15+'12'!K15+'13'!K15+'14'!K15+'15'!K15+'16'!K15+'17'!K15+'18'!K15+'19'!K15+'20'!K15+'21'!K15+'22'!K15+'23'!K15+'24'!K15+'25'!K15+'26'!K15+'27'!K15+'28'!K15+'29'!K15+'30'!K15+'31.'!K15 -> 0 | L15: 50 | M15: =+'1'!M15+'2'!M15+'3'!M15+'4'!M15+'5'!M15+'6'!M15+'7'!M15+'8'!M15+'9'!M15+'10'!M15+'11'!M15+'12'!M15+'13'!M15+'14'!M15+'15'!M15+'16'!M15+'17'!M15+'18'!M15+'19'!M15+'20'!M15+'21'!M15+'22'!M15+'23'!M15+'24'!M15+'25'!M15+'26'!M15+'27'!M15+'28'!M15+'29'!M15+'30'!M15+'31.'!M15 -> 0 | O15: 22.41 | P15: =+K15*O15 -> 0 | Q15: 11 | R15: =+'11'!N256 -> 4500 | S15: =+'11'!N261 -> 746 | T15: =+'11'!N259 -> 0 | U15: =+'11'!N257 -> 0 | V15: =+'11'!N260 -> 0 | W15: =+'11'!N258 -> 3108 | X15: =+R15-S15-T15-U15-V15-W15 -> 646 | Y15: =+'11'!N263 -> 646 | Z15: =+Y15-X15 -> 0 | AA15: พฤหัสบดี | AB15: =+W15+Y15 -> 3754 | AC15: =+W15+Y15+Z15 -> 3754
A16: 12 | C16: ชิฟฟ่อนเค้กหน้าฝอยทองทูโทน สอดไส้แยมส้ม (3 ชิ้น) | D16: กล่อง | E16: =+ยกมา!J16 -> 0 | F16: =+ยกมา!F16+'1'!F16+'2'!F16+'3'!F16+'4'!F16+'5'!F16+'6'!F16+'7'!F16+'8'!F16+'9'!F16+'10'!F16+'11'!F16+'12'!F16+'13'!F16+'14'!F16+'15'!F16+'16'!F16+'17'!F16+'18'!F16+'19'!F16+'20'!F16+'21'!F16+'22'!F16+'23'!F16+'24'!F16+'25'!F16+'26'!F16+'27'!F16+'28'!F16+'29'!F16+'30'!F16+'31.'!F16 -> 0 | G16: =+E16+F16 -> 0 | H16: =+'1'!H16+'2'!H16+'3'!H16+'4'!H16+'5'!H16+'6'!H16+'7'!H16+'8'!H16+'9'!H16+'10'!H16+'11'!H16+'12'!H16+'13'!H16+'14'!H16+'15'!H16+'16'!H16+'17'!H16+'18'!H16+'19'!H16+'20'!H16+'21'!H16+'22'!H16+'23'!H16+'24'!H16+'25'!H16+'26'!H16+'27'!H16+'28'!H16+'29'!H16+'30'!H16+'31.'!H16 -> 0 | I16: =+'1'!I16+'2'!I16+'3'!I16+'4'!I16+'5'!I16+'6'!I16+'7'!I16+'8'!I16+'9'!I16+'10'!I16+'11'!I16+'12'!I16+'13'!I16+'14'!I16+'15'!I16+'16'!I16+'17'!I16+'18'!I16+'19'!I16+'20'!I16+'21'!I16+'22'!I16+'23'!I16+'24'!I16+'25'!I16+'26'!I16+'27'!I16+'28'!I16+'29'!I16+'30'!I16+'31.'!I16 -> 0 | J16: =+ยกมา!J16+'1'!J16+'2'!J16+'3'!J16+'4'!J16+'5'!J16+'6'!J16+'7'!J16+'8'!J16+'9'!J16+'10'!J16+'11'!J16+'12'!J16+'13'!J16+'14'!J16+'15'!J16+'16'!J16+'17'!J16+'18'!K16+'19'!J16+'20'!J16+'21'!J16+'22'!J16+'23'!J16+'24'!J16+'25'!J16+'26'!J16+'27'!J16+'28'!J16+'29'!J16+'30'!J16+'31.'!J16 -> 0 | K16: =+'1'!K16+'2'!K16+'3'!K16+'4'!K16+'5'!K16+'6'!K16+'7'!K16+'8'!K16+'9'!K16+'10'!K16+'11'!K16+'12'!K16+'13'!K16+'14'!K16+'15'!K16+'16'!K16+'17'!K16+'18'!K16+'19'!K16+'20'!K16+'21'!K16+'22'!K16+'23'!K16+'24'!K16+'25'!K16+'26'!K16+'27'!K16+'28'!K16+'29'!K16+'30'!K16+'31.'!K16 -> 0 | L16: 50 | M16: =+'1'!M16+'2'!M16+'3'!M16+'4'!M16+'5'!M16+'6'!M16+'7'!M16+'8'!M16+'9'!M16+'10'!M16+'11'!M16+'12'!M16+'13'!M16+'14'!M16+'15'!M16+'16'!M16+'17'!M16+'18'!M16+'19'!M16+'20'!M16+'21'!M16+'22'!M16+'23'!M16+'24'!M16+'25'!M16+'26'!M16+'27'!M16+'28'!M16+'29'!M16+'30'!M16+'31.'!M16 -> 0 | P16: =+K16*O16 -> 0 | Q16: 12 | R16: =+'12'!N256 -> 2815 | S16: =+'12'!N261 -> 305 | T16: =+'12'!N259 -> 0 | U16: =+'12'!N257 -> 0 | V16: =+'12'!N260 -> 0 | W16: =+'12'!N258 -> 1255 | X16: =+R16-S16-T16-U16-V16-W16 -> 1255 | Y16: =+'12'!N263 -> 1255 | Z16: =+Y16-X16 -> 0 | AA16: ศุกร์ | AB16: =+W16+Y16 -> 2510 | AC16: =+W16+Y16+Z16 -> 2510
A17: 13 | B17: 8857125000024 | C17: ชิฟฟ่อนเค้กสอดไส้แยม รสสตรอว์เบอรี่ (3 ชิ้น) | D17: กล่อง | E17: =+ยกมา!J17 -> 0 | F17: =+ยกมา!F17+'1'!F17+'2'!F17+'3'!F17+'4'!F17+'5'!F17+'6'!F17+'7'!F17+'8'!F17+'9'!F17+'10'!F17+'11'!F17+'12'!F17+'13'!F17+'14'!F17+'15'!F17+'16'!F17+'17'!F17+'18'!F17+'19'!F17+'20'!F17+'21'!F17+'22'!F17+'23'!F17+'24'!F17+'25'!F17+'26'!F17+'27'!F17+'28'!F17+'29'!F17+'30'!F17+'31.'!F17 -> 0 | G17: =+E17+F17 -> 0 | H17: =+'1'!H17+'2'!H17+'3'!H17+'4'!H17+'5'!H17+'6'!H17+'7'!H17+'8'!H17+'9'!H17+'10'!H17+'11'!H17+'12'!H17+'13'!H17+'14'!H17+'15'!H17+'16'!H17+'17'!H17+'18'!H17+'19'!H17+'20'!H17+'21'!H17+'22'!H17+'23'!H17+'24'!H17+'25'!H17+'26'!H17+'27'!H17+'28'!H17+'29'!H17+'30'!H17+'31.'!H17 -> 0 | I17: =+'1'!I17+'2'!I17+'3'!I17+'4'!I17+'5'!I17+'6'!I17+'7'!I17+'8'!I17+'9'!I17+'10'!I17+'11'!I17+'12'!I17+'13'!I17+'14'!I17+'15'!I17+'16'!I17+'17'!I17+'18'!I17+'19'!I17+'20'!I17+'21'!I17+'22'!I17+'23'!I17+'24'!I17+'25'!I17+'26'!I17+'27'!I17+'28'!I17+'29'!I17+'30'!I17+'31.'!I17 -> 0 | J17: =+ยกมา!J17+'1'!J17+'2'!J17+'3'!J17+'4'!J17+'5'!J17+'6'!J17+'7'!J17+'8'!J17+'9'!J17+'10'!J17+'11'!J17+'12'!J17+'13'!J17+'14'!J17+'15'!J17+'16'!J17+'17'!J17+'18'!K17+'19'!J17+'20'!J17+'21'!J17+'22'!J17+'23'!J17+'24'!J17+'25'!J17+'26'!J17+'27'!J17+'28'!J17+'29'!J17+'30'!J17+'31.'!J17 -> 0 | K17: =+'1'!K17+'2'!K17+'3'!K17+'4'!K17+'5'!K17+'6'!K17+'7'!K17+'8'!K17+'9'!K17+'10'!K17+'11'!K17+'12'!K17+'13'!K17+'14'!K17+'15'!K17+'16'!K17+'17'!K17+'18'!K17+'19'!K17+'20'!K17+'21'!K17+'22'!K17+'23'!K17+'24'!K17+'25'!K17+'26'!K17+'27'!K17+'28'!K17+'29'!K17+'30'!K17+'31.'!K17 -> 0 | L17: 50 | M17: =+'1'!M17+'2'!M17+'3'!M17+'4'!M17+'5'!M17+'6'!M17+'7'!M17+'8'!M17+'9'!M17+'10'!M17+'11'!M17+'12'!M17+'13'!M17+'14'!M17+'15'!M17+'16'!M17+'17'!M17+'18'!M17+'19'!M17+'20'!M17+'21'!M17+'22'!M17+'23'!M17+'24'!M17+'25'!M17+'26'!M17+'27'!M17+'28'!M17+'29'!M17+'30'!M17+'31.'!M17 -> 0 | O17: 4 | P17: =+K17*O17 -> 0 | Q17: 13 | R17: =+'13'!N256 -> 2220 | S17: =+'13'!N261 -> 254 | T17: =+'13'!N259 -> 0 | U17: =+'13'!N257 -> 0 | V17: =+'13'!N260 -> 0 | W17: =+'13'!N258 -> 1616 | X17: =+R17-S17-T17-U17-V17-W17 -> 350 | Y17: =+'13'!N263 -> 350 | Z17: =+Y17-X17 -> 0 | AA17: เสาร์ | AB17: =+W17+Y17 -> 1966 | AC17: =+W17+Y17+Z17 -> 1966
A18: 14 | B18: 8857125000086 | C18: ชิฟฟ่อนเค้กสอดไส้ เนยมะพร้าว (3 ชิ้น) | D18: กล่อง | E18: =+ยกมา!J18 -> 3 | F18: =+ยกมา!F18+'1'!F18+'2'!F18+'3'!F18+'4'!F18+'5'!F18+'6'!F18+'7'!F18+'8'!F18+'9'!F18+'10'!F18+'11'!F18+'12'!F18+'13'!F18+'14'!F18+'15'!F18+'16'!F18+'17'!F18+'18'!F18+'19'!F18+'20'!F18+'21'!F18+'22'!F18+'23'!F18+'24'!F18+'25'!F18+'26'!F18+'27'!F18+'28'!F18+'29'!F18+'30'!F18+'31.'!F18 -> 8 | G18: =+E18+F18 -> 11 | H18: =+'1'!H18+'2'!H18+'3'!H18+'4'!H18+'5'!H18+'6'!H18+'7'!H18+'8'!H18+'9'!H18+'10'!H18+'11'!H18+'12'!H18+'13'!H18+'14'!H18+'15'!H18+'16'!H18+'17'!H18+'18'!H18+'19'!H18+'20'!H18+'21'!H18+'22'!H18+'23'!H18+'24'!H18+'25'!H18+'26'!H18+'27'!H18+'28'!H18+'29'!H18+'30'!H18+'31.'!H18 -> 3 | I18: =+'1'!I18+'2'!I18+'3'!I18+'4'!I18+'5'!I18+'6'!I18+'7'!I18+'8'!I18+'9'!I18+'10'!I18+'11'!I18+'12'!I18+'13'!I18+'14'!I18+'15'!I18+'16'!I18+'17'!I18+'18'!I18+'19'!I18+'20'!I18+'21'!I18+'22'!I18+'23'!I18+'24'!I18+'25'!I18+'26'!I18+'27'!I18+'28'!I18+'29'!I18+'30'!I18+'31.'!I18 -> 0 | J18: =+ยกมา!J18+'1'!J18+'2'!J18+'3'!J18+'4'!J18+'5'!J18+'6'!J18+'7'!J18+'8'!J18+'9'!J18+'10'!J18+'11'!J18+'12'!J18+'13'!J18+'14'!J18+'15'!J18+'16'!J18+'17'!J18+'18'!K18+'19'!J18+'20'!J18+'21'!J18+'22'!J18+'23'!J18+'24'!J18+'25'!J18+'26'!J18+'27'!J18+'28'!J18+'29'!J18+'30'!J18+'31.'!J18 -> 56 | K18: =+'1'!K18+'2'!K18+'3'!K18+'4'!K18+'5'!K18+'6'!K18+'7'!K18+'8'!K18+'9'!K18+'10'!K18+'11'!K18+'12'!K18+'13'!K18+'14'!K18+'15'!K18+'16'!K18+'17'!K18+'18'!K18+'19'!K18+'20'!K18+'21'!K18+'22'!K18+'23'!K18+'24'!K18+'25'!K18+'26'!K18+'27'!K18+'28'!K18+'29'!K18+'30'!K18+'31.'!K18 -> 5 | L18: 50 | M18: =+'1'!M18+'2'!M18+'3'!M18+'4'!M18+'5'!M18+'6'!M18+'7'!M18+'8'!M18+'9'!M18+'10'!M18+'11'!M18+'12'!M18+'13'!M18+'14'!M18+'15'!M18+'16'!M18+'17'!M18+'18'!M18+'19'!M18+'20'!M18+'21'!M18+'22'!M18+'23'!M18+'24'!M18+'25'!M18+'26'!M18+'27'!M18+'28'!M18+'29'!M18+'30'!M18+'31.'!M18 -> 250 | O18: 19.12 | P18: =+K18*O18 -> 95.6 | Q18: 14 | R18: =+'14'!N256 -> 6925 | S18: =+'14'!N261 -> 449 | T18: =+'14'!N259 -> 0 | U18: =+'14'!N257 -> 0 | V18: =+'14'!N260 -> 40 | W18: =+'14'!N258 -> 6306 | X18: =+R18-S18-T18-U18-V18-W18 -> 130 | Y18: =+'14'!N263 -> 130 | Z18: =+Y18-X18 -> 0 | AA18: อาทิตย์ | AB18: =+W18+Y18 -> 6436 | AC18: =+W18+Y18+Z18 -> 6436
A19: 15 | B19: 8857125000239 | C19: ชิฟฟ่อนเค้กสอดไส้ นมชมพูฮอกไกโด (3 ชิ้น) | D19: กล่อง | E19: =+ยกมา!J19 -> 0 | F19: =+ยกมา!F19+'1'!F19+'2'!F19+'3'!F19+'4'!F19+'5'!F19+'6'!F19+'7'!F19+'8'!F19+'9'!F19+'10'!F19+'11'!F19+'12'!F19+'13'!F19+'14'!F19+'15'!F19+'16'!F19+'17'!F19+'18'!F19+'19'!F19+'20'!F19+'21'!F19+'22'!F19+'23'!F19+'24'!F19+'25'!F19+'26'!F19+'27'!F19+'28'!F19+'29'!F19+'30'!F19+'31.'!F19 -> 0 | G19: =+E19+F19 -> 0 | H19: =+'1'!H19+'2'!H19+'3'!H19+'4'!H19+'5'!H19+'6'!H19+'7'!H19+'8'!H19+'9'!H19+'10'!H19+'11'!H19+'12'!H19+'13'!H19+'14'!H19+'15'!H19+'16'!H19+'17'!H19+'18'!H19+'19'!H19+'20'!H19+'21'!H19+'22'!H19+'23'!H19+'24'!H19+'25'!H19+'26'!H19+'27'!H19+'28'!H19+'29'!H19+'30'!H19+'31.'!H19 -> 0 | I19: =+'1'!I19+'2'!I19+'3'!I19+'4'!I19+'5'!I19+'6'!I19+'7'!I19+'8'!I19+'9'!I19+'10'!I19+'11'!I19+'12'!I19+'13'!I19+'14'!I19+'15'!I19+'16'!I19+'17'!I19+'18'!I19+'19'!I19+'20'!I19+'21'!I19+'22'!I19+'23'!I19+'24'!I19+'25'!I19+'26'!I19+'27'!I19+'28'!I19+'29'!I19+'30'!I19+'31.'!I19 -> 0 | J19: =+ยกมา!J19+'1'!J19+'2'!J19+'3'!J19+'4'!J19+'5'!J19+'6'!J19+'7'!J19+'8'!J19+'9'!J19+'10'!J19+'11'!J19+'12'!J19+'13'!J19+'14'!J19+'15'!J19+'16'!J19+'17'!J19+'18'!K19+'19'!J19+'20'!J19+'21'!J19+'22'!J19+'23'!J19+'24'!J19+'25'!J19+'26'!J19+'27'!J19+'28'!J19+'29'!J19+'30'!J19+'31.'!J19 -> 0 | K19: =+'1'!K19+'2'!K19+'3'!K19+'4'!K19+'5'!K19+'6'!K19+'7'!K19+'8'!K19+'9'!K19+'10'!K19+'11'!K19+'12'!K19+'13'!K19+'14'!K19+'15'!K19+'16'!K19+'17'!K19+'18'!K19+'19'!K19+'20'!K19+'21'!K19+'22'!K19+'23'!K19+'24'!K19+'25'!K19+'26'!K19+'27'!K19+'28'!K19+'29'!K19+'30'!K19+'31.'!K19 -> 0 | L19: 50 | M19: =+'1'!M19+'2'!M19+'3'!M19+'4'!M19+'5'!M19+'6'!M19+'7'!M19+'8'!M19+'9'!M19+'10'!M19+'11'!M19+'12'!M19+'13'!M19+'14'!M19+'15'!M19+'16'!M19+'17'!M19+'18'!M19+'19'!M19+'20'!M19+'21'!M19+'22'!M19+'23'!M19+'24'!M19+'25'!M19+'26'!M19+'27'!M19+'28'!M19+'29'!M19+'30'!M19+'31.'!M19 -> 0 | O19: 20.37 | P19: =+K19*O19 -> 0 | Q19: 15 | R19: =+'15'!N256 -> 2090 | S19: =+'15'!N261 -> 75 | T19: =+'15'!N259 -> 0 | U19: =+'15'!N257 -> 0 | V19: =+'15'!N260 -> 6 | W19: =+'15'!N258 -> 1085 | X19: =+R19-S19-T19-U19-V19-W19 -> 924 | Y19: =+'15'!N263 -> 924 | Z19: =+Y19-X19 -> 0 | AA19: จันทร์ | AB19: =+W19+Y19 -> 2009 | AC19: =+W19+Y19+Z19 -> 2009
A20: 16 | B20: 8857125001816 | C20: ชิฟฟ่อน สอดไส้ (ล) 4 ชิ้น ครีมมะพร้าว | D20: กล่อง | E20: =+ยกมา!J20 -> 0 | F20: =+ยกมา!F20+'1'!F20+'2'!F20+'3'!F20+'4'!F20+'5'!F20+'6'!F20+'7'!F20+'8'!F20+'9'!F20+'10'!F20+'11'!F20+'12'!F20+'13'!F20+'14'!F20+'15'!F20+'16'!F20+'17'!F20+'18'!F20+'19'!F20+'20'!F20+'21'!F20+'22'!F20+'23'!F20+'24'!F20+'25'!F20+'26'!F20+'27'!F20+'28'!F20+'29'!F20+'30'!F20+'31.'!F20 -> 12 | G20: =+E20+F20 -> 12 | H20: =+'1'!H20+'2'!H20+'3'!H20+'4'!H20+'5'!H20+'6'!H20+'7'!H20+'8'!H20+'9'!H20+'10'!H20+'11'!H20+'12'!H20+'13'!H20+'14'!H20+'15'!H20+'16'!H20+'17'!H20+'18'!H20+'19'!H20+'20'!H20+'21'!H20+'22'!H20+'23'!H20+'24'!H20+'25'!H20+'26'!H20+'27'!H20+'28'!H20+'29'!H20+'30'!H20+'31.'!H20 -> 0 | I20: =+'1'!I20+'2'!I20+'3'!I20+'4'!I20+'5'!I20+'6'!I20+'7'!I20+'8'!I20+'9'!I20+'10'!I20+'11'!I20+'12'!I20+'13'!I20+'14'!I20+'15'!I20+'16'!I20+'17'!I20+'18'!I20+'19'!I20+'20'!I20+'21'!I20+'22'!I20+'23'!I20+'24'!I20+'25'!I20+'26'!I20+'27'!I20+'28'!I20+'29'!I20+'30'!I20+'31.'!I20 -> 0 | J20: =+ยกมา!J20+'1'!J20+'2'!J20+'3'!J20+'4'!J20+'5'!J20+'6'!J20+'7'!J20+'8'!J20+'9'!J20+'10'!J20+'11'!J20+'12'!J20+'13'!J20+'14'!J20+'15'!J20+'16'!J20+'17'!J20+'18'!K20+'19'!J20+'20'!J20+'21'!J20+'22'!J20+'23'!J20+'24'!J20+'25'!J20+'26'!J20+'27'!J20+'28'!J20+'29'!J20+'30'!J20+'31.'!J20 -> 33 | K20: =+'1'!K20+'2'!K20+'3'!K20+'4'!K20+'5'!K20+'6'!K20+'7'!K20+'8'!K20+'9'!K20+'10'!K20+'11'!K20+'12'!K20+'13'!K20+'14'!K20+'15'!K20+'16'!K20+'17'!K20+'18'!K20+'19'!K20+'20'!K20+'21'!K20+'22'!K20+'23'!K20+'24'!K20+'25'!K20+'26'!K20+'27'!K20+'28'!K20+'29'!K20+'30'!K20+'31.'!K20 -> 12 | L20: 65 | M20: =+'1'!M20+'2'!M20+'3'!M20+'4'!M20+'5'!M20+'6'!M20+'7'!M20+'8'!M20+'9'!M20+'10'!M20+'11'!M20+'12'!M20+'13'!M20+'14'!M20+'15'!M20+'16'!M20+'17'!M20+'18'!M20+'19'!M20+'20'!M20+'21'!M20+'22'!M20+'23'!M20+'24'!M20+'25'!M20+'26'!M20+'27'!M20+'28'!M20+'29'!M20+'30'!M20+'31.'!M20 -> 780 | O20: 22.25 | P20: =+K20*O20 -> 267 | Q20: 16 | R20: =+'16'!N256 -> 5135 | S20: =+'16'!N261 -> 889 | T20: =+'16'!N259 -> 0 | U20: =+'16'!N257 -> 0 | V20: =+'16'!N260 -> 0 | W20: =+'16'!N258 -> 2396 | X20: =+R20-S20-T20-U20-V20-W20 -> 1850 | Y20: =+'16'!N263 -> 1850 | Z20: =+Y20-X20 -> 0 | AA20: อังคาร | AB20: =+W20+Y20 -> 4246 | AC20: =+W20+Y20+Z20 -> 4246
A21: 17 | B21: 8857125001021 | C21: ชิฟฟ่อน สอดไส้ (ก) 5 ชิ้น ครีมมะพร้าว | D21: กล่อง | E21: =+ยกมา!J21 -> 3 | F21: =+ยกมา!F21+'1'!F21+'2'!F21+'3'!F21+'4'!F21+'5'!F21+'6'!F21+'7'!F21+'8'!F21+'9'!F21+'10'!F21+'11'!F21+'12'!F21+'13'!F21+'14'!F21+'15'!F21+'16'!F21+'17'!F21+'18'!F21+'19'!F21+'20'!F21+'21'!F21+'22'!F21+'23'!F21+'24'!F21+'25'!F21+'26'!F21+'27'!F21+'28'!F21+'29'!F21+'30'!F21+'31.'!F21 -> 12 | G21: =+E21+F21 -> 15 | H21: =+'1'!H21+'2'!H21+'3'!H21+'4'!H21+'5'!H21+'6'!H21+'7'!H21+'8'!H21+'9'!H21+'10'!H21+'11'!H21+'12'!H21+'13'!H21+'14'!H21+'15'!H21+'16'!H21+'17'!H21+'18'!H21+'19'!H21+'20'!H21+'21'!H21+'22'!H21+'23'!H21+'24'!H21+'25'!H21+'26'!H21+'27'!H21+'28'!H21+'29'!H21+'30'!H21+'31.'!H21 -> 1 | I21: =+'1'!I21+'2'!I21+'3'!I21+'4'!I21+'5'!I21+'6'!I21+'7'!I21+'8'!I21+'9'!I21+'10'!I21+'11'!I21+'12'!I21+'13'!I21+'14'!I21+'15'!I21+'16'!I21+'17'!I21+'18'!I21+'19'!I21+'20'!I21+'21'!I21+'22'!I21+'23'!I21+'24'!I21+'25'!I21+'26'!I21+'27'!I21+'28'!I21+'29'!I21+'30'!I21+'31.'!I21 -> 0 | J21: =+ยกมา!J21+'1'!J21+'2'!J21+'3'!J21+'4'!J21+'5'!J21+'6'!J21+'7'!J21+'8'!J21+'9'!J21+'10'!J21+'11'!J21+'12'!J21+'13'!J21+'14'!J21+'15'!J21+'16'!J21+'17'!J21+'18'!K21+'19'!J21+'20'!J21+'21'!J21+'22'!J21+'23'!J21+'24'!J21+'25'!J21+'26'!J21+'27'!J21+'28'!J21+'29'!J21+'30'!J21+'31.'!J21 -> 92 | K21: =+'1'!K21+'2'!K21+'3'!K21+'4'!K21+'5'!K21+'6'!K21+'7'!K21+'8'!K21+'9'!K21+'10'!K21+'11'!K21+'12'!K21+'13'!K21+'14'!K21+'15'!K21+'16'!K21+'17'!K21+'18'!K21+'19'!K21+'20'!K21+'21'!K21+'22'!K21+'23'!K21+'24'!K21+'25'!K21+'26'!K21+'27'!K21+'28'!K21+'29'!K21+'30'!K21+'31.'!K21 -> 10 | L21: 85 | M21: =+'1'!M21+'2'!M21+'3'!M21+'4'!M21+'5'!M21+'6'!M21+'7'!M21+'8'!M21+'9'!M21+'10'!M21+'11'!M21+'12'!M21+'13'!M21+'14'!M21+'15'!M21+'16'!M21+'17'!M21+'18'!M21+'19'!M21+'20'!M21+'21'!M21+'22'!M21+'23'!M21+'24'!M21+'25'!M21+'26'!M21+'27'!M21+'28'!M21+'29'!M21+'30'!M21+'31.'!M21 -> 850 | O21: 22.85 | P21: =+K21*O21 -> 228.5 | Q21: 17 | R21: =+'17'!N256 -> 2175 | S21: =+'17'!N261 -> 605 | T21: =+'1'!N275 -> 0 | U21: =+'1'!N273 -> 0 | V21: =+'17'!N260 -> 0 | W21: =+'17'!N258 -> 515 | X21: =+R21-S21-T21-U21-V21-W21 -> 1055 | Y21: =+'17'!N263 -> 1055 | Z21: =+Y21-X21 -> 0 | AA21: พุธ | AB21: =+W21+Y21 -> 1570 | AC21: =+W21+Y21+Z21 -> 1570
A22: 18 | B22: 8857125000956 | C22: ชิฟฟ่อนเค้กสอดไส้ รวมรส (6 ชิ้น) | D22: กล่อง | E22: =+ยกมา!J22 -> 18 | F22: =+ยกมา!F22+'1'!F22+'2'!F22+'3'!F22+'4'!F22+'5'!F22+'6'!F22+'7'!F22+'8'!F22+'9'!F22+'10'!F22+'11'!F22+'12'!F22+'13'!F22+'14'!F22+'15'!F22+'16'!F22+'17'!F22+'18'!F22+'19'!F22+'20'!F22+'21'!F22+'22'!F22+'23'!F22+'24'!F22+'25'!F22+'26'!F22+'27'!F22+'28'!F22+'29'!F22+'30'!F22+'31.'!F22 -> 97 | G22: =+E22+F22 -> 115 | H22: =+'1'!H22+'2'!H22+'3'!H22+'4'!H22+'5'!H22+'6'!H22+'7'!H22+'8'!H22+'9'!H22+'10'!H22+'11'!H22+'12'!H22+'13'!H22+'14'!H22+'15'!H22+'16'!H22+'17'!H22+'18'!H22+'19'!H22+'20'!H22+'21'!H22+'22'!H22+'23'!H22+'24'!H22+'25'!H22+'26'!H22+'27'!H22+'28'!H22+'29'!H22+'30'!H22+'31.'!H22 -> 0 | I22: =+'1'!I22+'2'!I22+'3'!I22+'4'!I22+'5'!I22+'6'!I22+'7'!I22+'8'!I22+'9'!I22+'10'!I22+'11'!I22+'12'!I22+'13'!I22+'14'!I22+'15'!I22+'16'!I22+'17'!I22+'18'!I22+'19'!I22+'20'!I22+'21'!I22+'22'!I22+'23'!I22+'24'!I22+'25'!I22+'26'!I22+'27'!I22+'28'!I22+'29'!I22+'30'!I22+'31.'!I22 -> 0 | J22: =+ยกมา!J22+'1'!J22+'2'!J22+'3'!J22+'4'!J22+'5'!J22+'6'!J22+'7'!J22+'8'!J22+'9'!J22+'10'!J22+'11'!J22+'12'!J22+'13'!J22+'14'!J22+'15'!J22+'16'!J22+'17'!J22+'18'!K22+'19'!J22+'20'!J22+'21'!J22+'22'!J22+'23'!J22+'24'!J22+'25'!J22+'26'!J22+'27'!J22+'28'!J22+'29'!J22+'30'!J22+'31.'!J22 -> 622 | K22: =+'1'!K22+'2'!K22+'3'!K22+'4'!K22+'5'!K22+'6'!K22+'7'!K22+'8'!K22+'9'!K22+'10'!K22+'11'!K22+'12'!K22+'13'!K22+'14'!K22+'15'!K22+'16'!K22+'17'!K22+'18'!K22+'19'!K22+'20'!K22+'21'!K22+'22'!K22+'23'!K22+'24'!K22+'25'!K22+'26'!K22+'27'!K22+'28'!K22+'29'!K22+'30'!K22+'31.'!K22 -> 70 | L22: 100 | M22: =+'1'!M22+'2'!M22+'3'!M22+'4'!M22+'5'!M22+'6'!M22+'7'!M22+'8'!M22+'9'!M22+'10'!M22+'11'!M22+'12'!M22+'13'!M22+'14'!M22+'15'!M22+'16'!M22+'17'!M22+'18'!M22+'19'!M22+'20'!M22+'21'!M22+'22'!M22+'23'!M22+'24'!M22+'25'!M22+'26'!M22+'27'!M22+'28'!M22+'29'!M22+'30'!M22+'31.'!M22 -> 7000 | O22: 27.98 | P22: =+K22*O22 -> 1958.6 | Q22: 18 | R22: =+'18'!N256 -> 5965 | S22: =+'18'!N261 -> 1735 | T22: =+'1'!N276 -> 0 | U22: =+'1'!N274 -> 0 | V22: =+'18'!N260 -> 120 | W22: =+'18'!N258 -> 2585 | X22: =+R22-S22-T22-U22-V22-W22 -> 1525 | Y22: =+'18'!N263 -> 1525 | Z22: =+Y22-X22 -> 0 | AA22: พฤหัสบดี | AB22: =+W22+Y22 -> 4110 | AC22: =+W22+Y22+Z22 -> 4110
A23: 19 | B23: 8857125000918 | C23: ชิฟฟ่อนเค้กสอดไส้แยม รสส้ม (6 ชิ้น) | D23: กล่อง | E23: =+ยกมา!J23 -> 0 | F23: =+ยกมา!F23+'1'!F23+'2'!F23+'3'!F23+'4'!F23+'5'!F23+'6'!F23+'7'!F23+'8'!F23+'9'!F23+'10'!F23+'11'!F23+'12'!F23+'13'!F23+'14'!F23+'15'!F23+'16'!F23+'17'!F23+'18'!F23+'19'!F23+'20'!F23+'21'!F23+'22'!F23+'23'!F23+'24'!F23+'25'!F23+'26'!F23+'27'!F23+'28'!F23+'29'!F23+'30'!F23+'31.'!F23 -> 0 | G23: =+E23+F23 -> 0 | H23: =+'1'!H23+'2'!H23+'3'!H23+'4'!H23+'5'!H23+'6'!H23+'7'!H23+'8'!H23+'9'!H23+'10'!H23+'11'!H23+'12'!H23+'13'!H23+'14'!H23+'15'!H23+'16'!H23+'17'!H23+'18'!H23+'19'!H23+'20'!H23+'21'!H23+'22'!H23+'23'!H23+'24'!H23+'25'!H23+'26'!H23+'27'!H23+'28'!H23+'29'!H23+'30'!H23+'31.'!H23 -> 0 | I23: =+'1'!I23+'2'!I23+'3'!I23+'4'!I23+'5'!I23+'6'!I23+'7'!I23+'8'!I23+'9'!I23+'10'!I23+'11'!I23+'12'!I23+'13'!I23+'14'!I23+'15'!I23+'16'!I23+'17'!I23+'18'!I23+'19'!I23+'20'!I23+'21'!I23+'22'!I23+'23'!I23+'24'!I23+'25'!I23+'26'!I23+'27'!I23+'28'!I23+'29'!I23+'30'!I23+'31.'!I23 -> 0 | J23: =+ยกมา!J23+'1'!J23+'2'!J23+'3'!J23+'4'!J23+'5'!J23+'6'!J23+'7'!J23+'8'!J23+'9'!J23+'10'!J23+'11'!J23+'12'!J23+'13'!J23+'14'!J23+'15'!J23+'16'!J23+'17'!J23+'18'!K23+'19'!J23+'20'!J23+'21'!J23+'22'!J23+'23'!J23+'24'!J23+'25'!J23+'26'!J23+'27'!J23+'28'!J23+'29'!J23+'30'!J23+'31.'!J23 -> 0 | K23: =+'1'!K23+'2'!K23+'3'!K23+'4'!K23+'5'!K23+'6'!K23+'7'!K23+'8'!K23+'9'!K23+'10'!K23+'11'!K23+'12'!K23+'13'!K23+'14'!K23+'15'!K23+'16'!K23+'17'!K23+'18'!K23+'19'!K23+'20'!K23+'21'!K23+'22'!K23+'23'!K23+'24'!K23+'25'!K23+'26'!K23+'27'!K23+'28'!K23+'29'!K23+'30'!K23+'31.'!K23 -> 0 | L23: 100 | M23: =+'1'!M23+'2'!M23+'3'!M23+'4'!M23+'5'!M23+'6'!M23+'7'!M23+'8'!M23+'9'!M23+'10'!M23+'11'!M23+'12'!M23+'13'!M23+'14'!M23+'15'!M23+'16'!M23+'17'!M23+'18'!M23+'19'!M23+'20'!M23+'21'!M23+'22'!M23+'23'!M23+'24'!M23+'25'!M23+'26'!M23+'27'!M23+'28'!M23+'29'!M23+'30'!M23+'31.'!M23 -> 0 | O23: 29.74 | P23: =+K23*O23 -> 0 | Q23: 19 | R23: =+'19'!N256 -> 3615 | S23: =+'19'!N261 -> 691 | T23: =+'1'!N277 -> 0 | U23: =+'1'!N275 -> 0 | V23: =+'19'!N260 -> 0 | W23: =+'19'!N258 -> 1960 | X23: =+R23-S23-T23-U23-V23-W23 -> 964 | Y23: =+'19'!N263 -> 964 | Z23: =+Y23-X23 -> 0 | AA23: ศุกร์ | AB23: =+W23+Y23 -> 2924 | AC23: =+W23+Y23+Z23 -> 2924
A24: 20 | B24: 8857125000970 | C24: ชิฟฟ่อนเค้กหน้าฝอยทอง สอดไส้แยมส้ม (6 ชิ้น) | D24: กล่อง | E24: =+ยกมา!J24 -> 0 | F24: =+ยกมา!F24+'1'!F24+'2'!F24+'3'!F24+'4'!F24+'5'!F24+'6'!F24+'7'!F24+'8'!F24+'9'!F24+'10'!F24+'11'!F24+'12'!F24+'13'!F24+'14'!F24+'15'!F24+'16'!F24+'17'!F24+'18'!F24+'19'!F24+'20'!F24+'21'!F24+'22'!F24+'23'!F24+'24'!F24+'25'!F24+'26'!F24+'27'!F24+'28'!F24+'29'!F24+'30'!F24+'31.'!F24 -> 17 | G24: =+E24+F24 -> 17 | H24: =+'1'!H24+'2'!H24+'3'!H24+'4'!H24+'5'!H24+'6'!H24+'7'!H24+'8'!H24+'9'!H24+'10'!H24+'11'!H24+'12'!H24+'13'!H24+'14'!H24+'15'!H24+'16'!H24+'17'!H24+'18'!H24+'19'!H24+'20'!H24+'21'!H24+'22'!H24+'23'!H24+'24'!H24+'25'!H24+'26'!H24+'27'!H24+'28'!H24+'29'!H24+'30'!H24+'31.'!H24 -> 0 | I24: =+'1'!I24+'2'!I24+'3'!I24+'4'!I24+'5'!I24+'6'!I24+'7'!I24+'8'!I24+'9'!I24+'10'!I24+'11'!I24+'12'!I24+'13'!I24+'14'!I24+'15'!I24+'16'!I24+'17'!I24+'18'!I24+'19'!I24+'20'!I24+'21'!I24+'22'!I24+'23'!I24+'24'!I24+'25'!I24+'26'!I24+'27'!I24+'28'!I24+'29'!I24+'30'!I24+'31.'!I24 -> 0 | J24: =+ยกมา!J24+'1'!J24+'2'!J24+'3'!J24+'4'!J24+'5'!J24+'6'!J24+'7'!J24+'8'!J24+'9'!J24+'10'!J24+'11'!J24+'12'!J24+'13'!J24+'14'!J24+'15'!J24+'16'!J24+'17'!J24+'18'!K24+'19'!J24+'20'!J24+'21'!J24+'22'!J24+'23'!J24+'24'!J24+'25'!J24+'26'!J24+'27'!J24+'28'!J24+'29'!J24+'30'!J24+'31.'!J24 -> 101 | K24: =+'1'!K24+'2'!K24+'3'!K24+'4'!K24+'5'!K24+'6'!K24+'7'!K24+'8'!K24+'9'!K24+'10'!K24+'11'!K24+'12'!K24+'13'!K24+'14'!K24+'15'!K24+'16'!K24+'17'!K24+'18'!K24+'19'!K24+'20'!K24+'21'!K24+'22'!K24+'23'!K24+'24'!K24+'25'!K24+'26'!K24+'27'!K24+'28'!K24+'29'!K24+'30'!K24+'31.'!K24 -> 10 | L24: 100 | M24: =+'1'!M24+'2'!M24+'3'!M24+'4'!M24+'5'!M24+'6'!M24+'7'!M24+'8'!M24+'9'!M24+'10'!M24+'11'!M24+'12'!M24+'13'!M24+'14'!M24+'15'!M24+'16'!M24+'17'!M24+'18'!M24+'19'!M24+'20'!M24+'21'!M24+'22'!M24+'23'!M24+'24'!M24+'25'!M24+'26'!M24+'27'!M24+'28'!M24+'29'!M24+'30'!M24+'31.'!M24 -> 1000 | O24: 38.66 | P24: =+K24*O24 -> 386.6 | Q24: 20 | R24: =+'20'!N256 -> 2335 | S24: =+'20'!N261 -> 212 | T24: =+'1'!N278 -> 0 | U24: =+'1'!N276 -> 0 | V24: =+'1'!N279 -> 0 | W24: =+'20'!N258 -> 1050 | X24: =+R24-S24-T24-U24-V24-W24 -> 1073 | Y24: =+'20'!N263 -> 1073 | Z24: =+Y24-X24 -> 0 | AA24: เสาร์ | AB24: =+W24+Y24 -> 2123 | AC24: =+W24+Y24+Z24 -> 2123
A25: 21 | B25: 8857125003810 | C25: ชิฟฟ่อนเค้กหน้าฝอยทองทูโทน สอดไส้แยมส้ม (6 ชิ้น) | D25: กล่อง | E25: =+ยกมา!J25 -> 2 | F25: =+ยกมา!F25+'1'!F25+'2'!F25+'3'!F25+'4'!F25+'5'!F25+'6'!F25+'7'!F25+'8'!F25+'9'!F25+'10'!F25+'11'!F25+'12'!F25+'13'!F25+'14'!F25+'15'!F25+'16'!F25+'17'!F25+'18'!F25+'19'!F25+'20'!F25+'21'!F25+'22'!F25+'23'!F25+'24'!F25+'25'!F25+'26'!F25+'27'!F25+'28'!F25+'29'!F25+'30'!F25+'31.'!F25 -> 0 | G25: =+E25+F25 -> 2 | H25: =+'1'!H25+'2'!H25+'3'!H25+'4'!H25+'5'!H25+'6'!H25+'7'!H25+'8'!H25+'9'!H25+'10'!H25+'11'!H25+'12'!H25+'13'!H25+'14'!H25+'15'!H25+'16'!H25+'17'!H25+'18'!H25+'19'!H25+'20'!H25+'21'!H25+'22'!H25+'23'!H25+'24'!H25+'25'!H25+'26'!H25+'27'!H25+'28'!H25+'29'!H25+'30'!H25+'31.'!H25 -> 0 | I25: =+'1'!I25+'2'!I25+'3'!I25+'4'!I25+'5'!I25+'6'!I25+'7'!I25+'8'!I25+'9'!I25+'10'!I25+'11'!I25+'12'!I25+'13'!I25+'14'!I25+'15'!I25+'16'!I25+'17'!I25+'18'!I25+'19'!I25+'20'!I25+'21'!I25+'22'!I25+'23'!I25+'24'!I25+'25'!I25+'26'!I25+'27'!I25+'28'!I25+'29'!I25+'30'!I25+'31.'!I25 -> 0 | J25: =+ยกมา!J25+'1'!J25+'2'!J25+'3'!J25+'4'!J25+'5'!J25+'6'!J25+'7'!J25+'8'!J25+'9'!J25+'10'!J25+'11'!J25+'12'!J25+'13'!J25+'14'!J25+'15'!J25+'16'!J25+'17'!J25+'18'!K25+'19'!J25+'20'!J25+'21'!J25+'22'!J25+'23'!J25+'24'!J25+'25'!J25+'26'!J25+'27'!J25+'28'!J25+'29'!J25+'30'!J25+'31.'!J25 -> 60 | K25: =+'1'!K25+'2'!K25+'3'!K25+'4'!K25+'5'!K25+'6'!K25+'7'!K25+'8'!K25+'9'!K25+'10'!K25+'11'!K25+'12'!K25+'13'!K25+'14'!K25+'15'!K25+'16'!K25+'17'!K25+'18'!K25+'19'!K25+'20'!K25+'21'!K25+'22'!K25+'23'!K25+'24'!K25+'25'!K25+'26'!K25+'27'!K25+'28'!K25+'29'!K25+'30'!K25+'31.'!K25 -> 0 | L25: 100 | M25: =+'1'!M25+'2'!M25+'3'!M25+'4'!M25+'5'!M25+'6'!M25+'7'!M25+'8'!M25+'9'!M25+'10'!M25+'11'!M25+'12'!M25+'13'!M25+'14'!M25+'15'!M25+'16'!M25+'17'!M25+'18'!M25+'19'!M25+'20'!M25+'21'!M25+'22'!M25+'23'!M25+'24'!M25+'25'!M25+'26'!M25+'27'!M25+'28'!M25+'29'!M25+'30'!M25+'31.'!M25 -> 0 | O25: 39.77 | P25: =+K25*O25 -> 0 | Q25: 21 | R25: =+'21'!N256 -> 4350 | S25: =+'21'!N261 -> 801 | T25: =+'1'!N279 -> 0 | U25: =+'1'!N277 -> 0 | V25: =+'1'!N280 -> 0 | W25: =+'21'!N258 -> 2844 | X25: =+R25-S25-T25-U25-V25-W25 -> 705 | Y25: =+'21'!N263 -> 705 | Z25: =+Y25-X25 -> 0 | AA25: อาทิตย์ | AB25: =+W25+Y25 -> 3549 | AC25: =+W25+Y25+Z25 -> 3549
A26: 22 | B26: 8857125000963 | C26: ชิฟฟ่อนเค้กสอดไส้ นมชมพูฮอกไกโด (6 ชิ้น) | D26: กล่อง | E26: =+ยกมา!J26 -> 0 | F26: =+ยกมา!F26+'1'!F26+'2'!F26+'3'!F26+'4'!F26+'5'!F26+'6'!F26+'7'!F26+'8'!F26+'9'!F26+'10'!F26+'11'!F26+'12'!F26+'13'!F26+'14'!F26+'15'!F26+'16'!F26+'17'!F26+'18'!F26+'19'!F26+'20'!F26+'21'!F26+'22'!F26+'23'!F26+'24'!F26+'25'!F26+'26'!F26+'27'!F26+'28'!F26+'29'!F26+'30'!F26+'31.'!F26 -> 8 | G26: =+E26+F26 -> 8 | H26: =+'1'!H26+'2'!H26+'3'!H26+'4'!H26+'5'!H26+'6'!H26+'7'!H26+'8'!H26+'9'!H26+'10'!H26+'11'!H26+'12'!H26+'13'!H26+'14'!H26+'15'!H26+'16'!H26+'17'!H26+'18'!H26+'19'!H26+'20'!H26+'21'!H26+'22'!H26+'23'!H26+'24'!H26+'25'!H26+'26'!H26+'27'!H26+'28'!H26+'29'!H26+'30'!H26+'31.'!H26 -> 0 | I26: =+'1'!I26+'2'!I26+'3'!I26+'4'!I26+'5'!I26+'6'!I26+'7'!I26+'8'!I26+'9'!I26+'10'!I26+'11'!I26+'12'!I26+'13'!I26+'14'!I26+'15'!I26+'16'!I26+'17'!I26+'18'!I26+'19'!I26+'20'!I26+'21'!I26+'22'!I26+'23'!I26+'24'!I26+'25'!I26+'26'!I26+'27'!I26+'28'!I26+'29'!I26+'30'!I26+'31.'!I26 -> 0 | J26: =+ยกมา!J26+'1'!J26+'2'!J26+'3'!J26+'4'!J26+'5'!J26+'6'!J26+'7'!J26+'8'!J26+'9'!J26+'10'!J26+'11'!J26+'12'!J26+'13'!J26+'14'!J26+'15'!J26+'16'!J26+'17'!J26+'18'!K26+'19'!J26+'20'!J26+'21'!J26+'22'!J26+'23'!J26+'24'!J26+'25'!J26+'26'!J26+'27'!J26+'28'!J26+'29'!J26+'30'!J26+'31.'!J26 -> 55 | K26: =+'1'!K26+'2'!K26+'3'!K26+'4'!K26+'5'!K26+'6'!K26+'7'!K26+'8'!K26+'9'!K26+'10'!K26+'11'!K26+'12'!K26+'13'!K26+'14'!K26+'15'!K26+'16'!K26+'17'!K26+'18'!K26+'19'!K26+'20'!K26+'21'!K26+'22'!K26+'23'!K26+'24'!K26+'25'!K26+'26'!K26+'27'!K26+'28'!K26+'29'!K26+'30'!K26+'31.'!K26 -> 4 | L26: 100 | M26: =+'1'!M26+'2'!M26+'3'!M26+'4'!M26+'5'!M26+'6'!M26+'7'!M26+'8'!M26+'9'!M26+'10'!M26+'11'!M26+'12'!M26+'13'!M26+'14'!M26+'15'!M26+'16'!M26+'17'!M26+'18'!M26+'19'!M26+'20'!M26+'21'!M26+'22'!M26+'23'!M26+'24'!M26+'25'!M26+'26'!M26+'27'!M26+'28'!M26+'29'!M26+'30'!M26+'31.'!M26 -> 400 | O26: 32.97 | P26: =+K26*O26 -> 131.88 | Q26: 22 | R26: =+'22'!N256 -> 2135 | S26: =+'22'!N261 -> 541 | T26: =+'1'!N280 -> 0 | U26: =+'1'!N278 -> 0 | V26: =+'1'!N281 -> 0 | W26: =+'22'!N258 -> 644 | X26: =+R26-S26-T26-U26-V26-W26 -> 950 | Y26: =+'22'!N263 -> 950 | Z26: =+Y26-X26 -> 0 | AA26: จันทร์ | AB26: =+W26+Y26 -> 1594 | AC26: =+W26+Y26+Z26 -> 1594
A27: 23 | B27: 8857125000932 | C27: ชิฟฟ่อนเค้กสอดไส้แยม รสบลูเบอร์รี่ (6 ชิ้น) | D27: กล่อง | E27: =+ยกมา!J27 -> 0 | F27: =+ยกมา!F27+'1'!F27+'2'!F27+'3'!F27+'4'!F27+'5'!F27+'6'!F27+'7'!F27+'8'!F27+'9'!F27+'10'!F27+'11'!F27+'12'!F27+'13'!F27+'14'!F27+'15'!F27+'16'!F27+'17'!F27+'18'!F27+'19'!F27+'20'!F27+'21'!F27+'22'!F27+'23'!F27+'24'!F27+'25'!F27+'26'!F27+'27'!F27+'28'!F27+'29'!F27+'30'!F27+'31.'!F27 -> 0 | G27: =+E27+F27 -> 0 | H27: =+'1'!H27+'2'!H27+'3'!H27+'4'!H27+'5'!H27+'6'!H27+'7'!H27+'8'!H27+'9'!H27+'10'!H27+'11'!H27+'12'!H27+'13'!H27+'14'!H27+'15'!H27+'16'!H27+'17'!H27+'18'!H27+'19'!H27+'20'!H27+'21'!H27+'22'!H27+'23'!H27+'24'!H27+'25'!H27+'26'!H27+'27'!H27+'28'!H27+'29'!H27+'30'!H27+'31.'!H27 -> 0 | I27: =+'1'!I27+'2'!I27+'3'!I27+'4'!I27+'5'!I27+'6'!I27+'7'!I27+'8'!I27+'9'!I27+'10'!I27+'11'!I27+'12'!I27+'13'!I27+'14'!I27+'15'!I27+'16'!I27+'17'!I27+'18'!I27+'19'!I27+'20'!I27+'21'!I27+'22'!I27+'23'!I27+'24'!I27+'25'!I27+'26'!I27+'27'!I27+'28'!I27+'29'!I27+'30'!I27+'31.'!I27 -> 0 | J27: =+ยกมา!J27+'1'!J27+'2'!J27+'3'!J27+'4'!J27+'5'!J27+'6'!J27+'7'!J27+'8'!J27+'9'!J27+'10'!J27+'11'!J27+'12'!J27+'13'!J27+'14'!J27+'15'!J27+'16'!J27+'17'!J27+'18'!K27+'19'!J27+'20'!J27+'21'!J27+'22'!J27+'23'!J27+'24'!J27+'25'!J27+'26'!J27+'27'!J27+'28'!J27+'29'!J27+'30'!J27+'31.'!J27 -> 0 | K27: =+'1'!K27+'2'!K27+'3'!K27+'4'!K27+'5'!K27+'6'!K27+'7'!K27+'8'!K27+'9'!K27+'10'!K27+'11'!K27+'12'!K27+'13'!K27+'14'!K27+'15'!K27+'16'!K27+'17'!K27+'18'!K27+'19'!K27+'20'!K27+'21'!K27+'22'!K27+'23'!K27+'24'!K27+'25'!K27+'26'!K27+'27'!K27+'28'!K27+'29'!K27+'30'!K27+'31.'!K27 -> 0 | L27: 100 | M27: =+'1'!M27+'2'!M27+'3'!M27+'4'!M27+'5'!M27+'6'!M27+'7'!M27+'8'!M27+'9'!M27+'10'!M27+'11'!M27+'12'!M27+'13'!M27+'14'!M27+'15'!M27+'16'!M27+'17'!M27+'18'!M27+'19'!M27+'20'!M27+'21'!M27+'22'!M27+'23'!M27+'24'!M27+'25'!M27+'26'!M27+'27'!M27+'28'!M27+'29'!M27+'30'!M27+'31.'!M27 -> 0 | O27: 30.83 | P27: =+K27*O27 -> 0 | Q27: 23 | R27: =+'23'!N256 -> 4025 | S27: =+'23'!N261 -> 482 | T27: =+'1'!N281 -> 0 | U27: =+'1'!N279 -> 0 | V27: =+'1'!N282 -> 0 | W27: =+'23'!N258 -> 2613 | X27: =+R27-S27-T27-U27-V27-W27 -> 930 | Y27: =+'23'!N263 -> 930 | Z27: =+Y27-X27 -> 0 | AA27: อังคาร | AB27: =+W27+Y27 -> 3543 | AC27: =+W27+Y27+Z27 -> 3543
A28: 24 | B28: 8857125000895 | C28: ชิฟฟ่อนเค้กสอดไส้ เนยมะพร้าว (6 ชิ้น) | D28: กล่อง | E28: =+ยกมา!J28 -> 0 | F28: =+ยกมา!F28+'1'!F28+'2'!F28+'3'!F28+'4'!F28+'5'!F28+'6'!F28+'7'!F28+'8'!F28+'9'!F28+'10'!F28+'11'!F28+'12'!F28+'13'!F28+'14'!F28+'15'!F28+'16'!F28+'17'!F28+'18'!F28+'19'!F28+'20'!F28+'21'!F28+'22'!F28+'23'!F28+'24'!F28+'25'!F28+'26'!F28+'27'!F28+'28'!F28+'29'!F28+'30'!F28+'31.'!F28 -> 9 | G28: =+E28+F28 -> 9 | H28: =+'1'!H28+'2'!H28+'3'!H28+'4'!H28+'5'!H28+'6'!H28+'7'!H28+'8'!H28+'9'!H28+'10'!H28+'11'!H28+'12'!H28+'13'!H28+'14'!H28+'15'!H28+'16'!H28+'17'!H28+'18'!H28+'19'!H28+'20'!H28+'21'!H28+'22'!H28+'23'!H28+'24'!H28+'25'!H28+'26'!H28+'27'!H28+'28'!H28+'29'!H28+'30'!H28+'31.'!H28 -> 0 | I28: =+'1'!I28+'2'!I28+'3'!I28+'4'!I28+'5'!I28+'6'!I28+'7'!I28+'8'!I28+'9'!I28+'10'!I28+'11'!I28+'12'!I28+'13'!I28+'14'!I28+'15'!I28+'16'!I28+'17'!I28+'18'!I28+'19'!I28+'20'!I28+'21'!I28+'22'!I28+'23'!I28+'24'!I28+'25'!I28+'26'!I28+'27'!I28+'28'!I28+'29'!I28+'30'!I28+'31.'!I28 -> 0 | J28: =+ยกมา!J28+'1'!J28+'2'!J28+'3'!J28+'4'!J28+'5'!J28+'6'!J28+'7'!J28+'8'!J28+'9'!J28+'10'!J28+'11'!J28+'12'!J28+'13'!J28+'14'!J28+'15'!J28+'16'!J28+'17'!J28+'18'!K28+'19'!J28+'20'!J28+'21'!J28+'22'!J28+'23'!J28+'24'!J28+'25'!J28+'26'!J28+'27'!J28+'28'!J28+'29'!J28+'30'!J28+'31.'!J28 -> 38 | K28: =+'1'!K28+'2'!K28+'3'!K28+'4'!K28+'5'!K28+'6'!K28+'7'!K28+'8'!K28+'9'!K28+'10'!K28+'11'!K28+'12'!K28+'13'!K28+'14'!K28+'15'!K28+'16'!K28+'17'!K28+'18'!K28+'19'!K28+'20'!K28+'21'!K28+'22'!K28+'23'!K28+'24'!K28+'25'!K28+'26'!K28+'27'!K28+'28'!K28+'29'!K28+'30'!K28+'31.'!K28 -> 7 | L28: 100 | M28: =+'1'!M28+'2'!M28+'3'!M28+'4'!M28+'5'!M28+'6'!M28+'7'!M28+'8'!M28+'9'!M28+'10'!M28+'11'!M28+'12'!M28+'13'!M28+'14'!M28+'15'!M28+'16'!M28+'17'!M28+'18'!M28+'19'!M28+'20'!M28+'21'!M28+'22'!M28+'23'!M28+'24'!M28+'25'!M28+'26'!M28+'27'!M28+'28'!M28+'29'!M28+'30'!M28+'31.'!M28 -> 700 | O28: 30.86 | P28: =+K28*O28 -> 216.02 | Q28: 24 | R28: =+'24'!N256 -> 2090 | S28: =+'24'!N261 -> 236 | T28: =+'1'!N282 -> 0 | U28: =+'1'!N280 -> 0 | V28: =+'1'!N283 -> 0 | W28: =+'24'!N258 -> 560 | X28: =+R28-S28-T28-U28-V28-W28 -> 1294 | Y28: =+'24'!N263 -> 1294 | Z28: =+Y28-X28 -> 0 | AA28: พุธ | AB28: =+W28+Y28 -> 1854 | AC28: =+W28+Y28+Z28 -> 1854
