Workbook

Sheet DATA POS
A1: รหัสสินค้า | B1: ชื่อสินค้า | C1: หมวดหมู่สินค้า | D1: หน่วยสินค้า | E1: ราคาขาย | F1: ราคาซื้อ | G1: Min | H1: Max | I1: หมายเหตุ | J1: สถานะ
B2: มะม่วงหนึบ | C2: หมวดอื่นๆ | D2: กล่อง | E2: 40.00 | F2: 0.00 | G2: 0 | H2: 0 | J2: ใช้งาน
A3: 0109256601 | B3: กระเช้าสำเร็จรูป | C3: หมวดอื่นๆ | D3: กระเช้า | E3: 800.00 | F3: 0.00 | G3: 0 | H3: 0 | J3: ใช้งาน
A4: 0109256602 | B4: เซ็ตของขวัญ | C4: หมวดอื่นๆ | D4: กล่อง | E4: 260.00 | F4: 0.00 | G4: 0 | H4: 0 | J4: ใช้งาน
A5: 01-SU-0025-1 | B5: น้ำแดงเฮลบลูบอย | C5: เครื่องดื่ม | D5: ขวด | E5: 58.00 | F5: 0.00 | G5: 0 | H5: 0 | J5: ใช้งาน
A6: 02102566 | B6: เปี๊ยะมินิ | C6: หมวดอื่นๆ | D6: กล่อง | E6: 25.00 | F6: 0.00 | G6: 0 | H6: 0 | J6: ใช้งาน
A7: 02-BB01 | B7: กล่องเค้กเบาหวิวทุเรียน 100g. New | C7: กล่องโมเดล | D7: กล่อง | E7: 20.00 | F7: 0.00 | G7: 0 | H7: 0 | J7: ใช้งาน
A8: 02-BB02 | B8: กล่องเค้กเบาหวิวเผือกมะพร้าวอ่อน 100g. New | C8: กล่องโมเดล | D8: กล่อง | E8: 20.00 | F8: 0.00 | G8: 0 | H8: 0 | J8: ใช้งาน
A9: 02-BB03 | B9: กล่องเค้กเบาหวิวกล้วยมะพร้าวเผา 100g. New | C9: กล่องโมเดล | D9: กล่อง | E9: 20.00 | F9: 0.00 | G9: 0 | H9: 0 | J9: ใช้งาน
A10: 02-BB05 | B10: กล่องเค้กเบาหวิวรสกาแฟ 100g New | C10: กล่องโมเดล | D10: กล่อง | E10: 20.00 | F10: 0.00 | G10: 0 | H10: 0 | J10: ใช้งาน
A11: 02-BB07 | B11: กล่องเค้กเบาหวิวรสกาแฟ 300g. New | C11: กล่องโมเดล | D11: กล่อง | E11: 20.00 | F11: 0.00 | G11: 0 | H11: 0 | J11: ใช้งาน
A12: 02-BB09 | B12: กล่องเค้กเบาหวิวรสเนยนม 110g. New | C12: กล่องโมเดล | D12: กล่อง | E12: 20.00 | F12: 0.00 | G12: 0 | H12: 0 | J12: ใช้งาน
A13: 02-BB11 | B13: กล่องเค้กเบาหวิวรสเนยนม 300g. New | C13: กล่องโมเดล | D13: กล่อง | E13: 20.00 | F13: 0.00 | G13: 0 | H13: 0 | J13: ใช้งาน
A14: 02-BB14 | B14: กล่องเค้กเบาหวิวรสใบเตย 300g. New | C14: กล่องโมเดล | D14: กล่อง | E14: 20.00 | F14: 0.00 | G14: 0 | H14: 0 | J14: ใช้งาน
... A76: 1113178 | B76: เค้กลอดช่องกล่องกลม 1 ปอนด์ 265 กรัม | C76: เค้ก | D76: กล่อง | E76: 0.00 | F76: 0.00 | G76: 0 | H76: 0 | J76: ใช้งาน
A77: 1113179 | B77: เค้กลอดช่องกล่องกลม 2 ปอนด์ 325 กรัม | C77: เค้ก | D77: กล่อง | E77: 240.00 | F77: 0.00 | G77: 0 | H77: 0 | I77: สินค้าระบายจากทางออนไลน์ ขาย 120 บาท | J77: ใช้งาน
A78: 1113185 | B78: ข้าวเกรียบว่าว (กระปุก) | C78: ขนมปัง แซนวิส | D78: กระปุก | E78: 40.00 | F78: 0.00 | G78: 0 | H78: 0 | J78: ใช้งาน
A79: 1113191 | B79: เค้กตะโก้เผือกหอม 120 กรัม | C79: เค้ก | D79: กล่อง | E79: 35.00 | F79: 0.00 | G79: 0 | H79: 0 | J79: ใช้งาน
A80: 1113192 | B80: ปังนุ่มมะพร้าว 100 กรัม | C80: ขนมปัง แซนวิส | D80: กล่อง | E80: 35.00 | F80: 0.00 | G80: 0 | H80: 0 | I80: บิ๊กซี | J80: ใช้งาน
A81: 1113193 | B81: ปังนุ่มชาไทย 100 กรัม | C81: ขนมปัง แซนวิส | D81: กล่อง | E81: 35.00 | F81: 0.00 | G81: 0 | H81: 0 | I81: บิ๊กซี | J81: ใช้งาน
A82: 1113194 | B82: บานอฟฟี่ 140 กรัม | C82: เค้ก | D82: กล่อง | E82: 45.00 | F82: 0.00 | G82: 0 | H82: 0 | I82: ราคาเต็ม 45 บาท , ราคาของระบาย 20 บาท | J82: ใช้งาน
A83: 1114024 | B83: สังขยา 1 ชิ้น | C83: ขนมปัง แซนวิส | D83: ชิ้น | E83: 10.00 | F83: 0.00 | G83: 0 | H83: 0 | J83: ใช้งาน
A84: 11140500 | B84: ขนมปังเลเยอร์ | C84: ขนมปัง แซนวิส | D84: ถุง | E84: 65.00 | F84: 0.00 | G84: 0 | H84: 0 | J84: ใช้งาน
A85: 1114056 | B85: ขนมปุยฝ้าย คละรส (4 ชิ้น) | C85: ขนมปัง แซนวิส | D85: กล่อง | E85: 50.00 | F85: 0.00 | G85: 0 | H85: 0 | J85: ใช้งาน
A86: 1114057 | B86: ขนมปุยฝ้าย สีชมพู (1 ปอนด์) | C86: ขนมปัง แซนวิส | D86: กล่อง | E86: 60.00 | F86: 0.00 | G86: 0 | H86: 0 | J86: ใช้งาน
A87: 1114058 | B87: ขนมปุยฝ้าย สีชมพู (4 ชิ้น) | C87: ขนมปัง แซนวิส | D87: กล่อง | E87: 50.00 | F87: 0.00 | G87: 0 | H87: 0 | J87: ใช้งาน
A88: 1114059 | B88: ขนมปุยฝ้าย สีขาว (1 ปอนด์) | C88: ขนมปัง แซนวิส | D88: กล่อง | E88: 60.00 | F88: 0.00 | G88: 0 | H88: 0 | J88: ใช้งาน
A89: 1114060 | B89: ขนมปุยฝ้าย สีขาว (4 ชิ้น) | C89: ขนมปัง แซนวิส | D89: กล่อง | E89: 50.00 | F89: 0.00 | G89: 0 | H89: 0 | J89: ใช้งาน
A90: 1124024 | B90: ขนมปังไส้ฝอยทอง (ชิ้น) | C90: ขนมปัง แซนวิส | D90: ชิ้น | E90: 30.00 | F90: 0.00 | G90: 0 | H90: 0 | J90: ใช้งาน
A91: 1124037 | B91: ขนมปังไส้พริกเผาไก่หยอง (ชิ้น) | C91: ขนมปัง แซนวิส | D91: ชิ้น | E91: 30.00 | F91: 0.00 | G91: 0 | H91: 0 | J91: ใช้งาน
A92: 1124038 | B92: ขนมปังไส้แยมบลูเบอร์รี่ (ชิ้น) | C92: ขนมปัง แซนวิส | D92: ชิ้น | E92: 30.00 | F92: 0.00 | G92: 0 | H92: 0 | J92: ใช้งาน
A93: 1124039 | B93: ขนมปังไส้แยมสตรอเบอร์รี่ (ชิ้น) | C93: ขนมปัง แซนวิส | D93: ชิ้น | E93: 30.00 | F93: 0.00 | G93: 0 | H93: 0 | J93: ใช้งาน
A94: 1124040 | B94: ขนมปังไส้ลูกเกดฝอยทอง (ชิ้น) | C94: ขนมปัง แซนวิส | D94: ชิ้น | E94: 30.00 | F94: 0.00 | G94: 0 | H94: 0 | J94: ใช้งาน
... A96: 1200032 | B96: (NP)มาม่อนคัฟ รวมรส (6ชิ้น) | C96: หนองพงนก | D96: กล่อง | E96: 80.00 | F96: 0.00 | G96: 0 | H96: 0 | J96: ใช้งาน
A97: 1200092 | B97: ท๊อฟฟี่ถั่ว (กิโล) | D97: กิโลกรัม | E97: 200.00 | F97: 0.00 | G97: 0 | H97: 0 | J97: ใช้งาน
A98: 1300005 | B98: เค้กมะพร้าวลาวา 85 กรัม | C98: เค้ก | D98: กล่อง | E98: 35.00 | F98: 0.00 | G98: 0 | H98: 0 | J98: ใช้งาน
A99: 1300006 | B99: แซนด์วิช แฮมไข่ดาว | C99: ขนมปัง แซนวิส | D99: กล่อง | E99: 35.00 | F99: 0.00 | G99: 0 | H99: 0 | J99: ใช้งาน
A100: 13082000 | B100: หนังสือนิทาน วาดภาพ | C100: รพ.สินแพทย์ | D100: ชิ้น | E100: 20.00 | F100: 0.00 | G100: 0 | H100: 0 | J100: ใช้งาน
A101: 13082001 | B101: ห้องครัว | C101: รพ.สินแพทย์ | D101: กล่อง | E101: 450.00 | F101: 0.00 | G101: 0 | H101: 0 | J101: ใช้งาน
A102: 13082002 | B102: ฮีโร่แผง 150 | C102: รพ.สินแพทย์ | D102: ชิ้น | E102: 150.00 | F102: 0.00 | G102: 0 | H102: 0 | J102: ใช้งาน
...

Sheet ต้นทุนพี่ตุ๊ก
A1: รหัสสินค้า | B1: ชื่อสินค้า | C1: ราคาต้นทุน
A2: 1111001 | B2: ชิฟฟ่อนเค้ก 1 ชิ้น
A3: 1111010 | B3: ชิฟฟ่อนเค้กสอดไส้แยม 1 ชิ้น
A4: 1112539 | B4: ชิฟฟ่อนเค้กสอดไส้ เมล่อน (3 ชิ้น)
A5: 20055116 | B5: ชิฟฟ่อนเค้กสอดไส้ครีมมะพร้าว 120g.
A6: 20055119 | B6: ชิฟฟ่อนเค้กฝอยทอง 95g.
A7: 1124027 | B7: ครีมฮอร์นใบเตย จัมโบ้ 65g.
A8: 1124029 | B8: ครีมฮอร์นชาไทย จัมโบ้ 65g.
A9: 20055115 | B9: ครีมฮอร์นคิทแคท 70g.
A10: 1200019 | B10: NP เค้กโบราณครีม 6 ชิ้น
A11: 1200020 | B11: NP เเค้กโบราณผลไม้ 6 ชิ้น
A12: 5002400 | B12: เค้กลาวา ฝอยทอง เล็ก
A13: 1113011 | B13: เค้กลาวา ฝอยทอง ใหญ่
A14: 1113010 | B14: เค้กลาวา ฝอยทองทูโทน ใหญ่
A15: 20054637 | B15: เอแคลร์คิทแคท 55g.
A16: 20056257 | B16: เอแคลร์ชาไทย 125g.
A17: 20054638 | B17: เครปเค้กคิทแคท 65g.
A18: 1113194 | B18: บานอฟฟี่ 140 กรัม
A19: 1006979 | B19: คัพเค้กไส้คัสตาร์ด
A20: 1300005 | B20: เค้กมะพร้าวลาวา 85 กรัม
A21: 1113157 | B21: เค้กลอดช่อง 85 กรัม
A22: 1113178 | B22: เค้กลอดช่องกล่องกลม 1 ปอนด์ 265 กรัม
A23: 1113179 | B23: เค้กลอดช่องกล่องกลม 2 ปอนด์ 325 กรัม
A24: 20053053 | B24: เค้กทุเรียน 90 กรัม
A25: 20055951 | B25: เค้กบัวลอยมะพร้าวอ่อน 100 กรัม
A26: 1113004 | B26: เค้กสามเหลี่ยม รสฝอยทองใบเตย
A27: 1111410 | B27: เค้กวันเกิดมะพร้าวอ่อน 1/2 ปอนด์
A28: 1111406 | B28: เค้กวันเกิดมะพร้าวอ่อน 1 ปอนด์
A29: 1111410 | B29: เค้กวันเกิด 1/2 ปอนด์ ธรรมดา
A30: 1113114 | B30: เค้กวันเกิด 1 ปอนด์ ธรรมดา
A31: 1200003 | B31: ท๊อฟฟี่ถั่ว (กระเช้า)
A32: 1200002 | B32: ท๊อฟฟี่ถั่ว (กล่อง)
A33: 1200001 | B33: คอนเฟลกคาราเมล (เล็ก)
A34: 1006002 | B34: วุ้นฝอยทอง (N)
A35: 25661201 | B35: วุ้นแฟนซี (N)
A36: 1113192 | B36: ปังนุ่มมะพร้าว 100 กรัม
A37: 1113193 | B37: ปังนุ่มชาไทย 100 กรัม
A38: 1113084 | B38: ขนมปังเนยนิ่ม (2 ชิ้น)
A39: 1124002 | B39: ขนมปังสังขยาใบเตยนมสด 4 ชิ้น
A40: 1113110 | B40: ขนมปังไก่หยองน้ำสลัด
...

Sheet สรุป
A2: บูธ EVENT งานเกษตรแฟร์กำแพงแสน 30 พ.ย. 67 - 10 ธ.ค. 67 | Q2: บูธ EVENT งานเกษตรแฟร์กำแพงแสน 30 พ.ย. 67 - 10 ธ.ค. 67
A3: ลำดับ | B3: รหัสสินค้า (POS) | C3: รายการ | D3: หน่วย | E3: ยกมา | F3: รับ | G3: รวม | H3: เปลี่ยน/ | I3: โยกย้าย / ระบาย | J3: คงเหลือ | K3: รายการขาย | N3: หมายเหตุ | O3: ราคาต้นทุน | P3: ยอดรวมต้นทุนสินค้า | Q3: วันที่ | R3: ยอดเงิน | S3: ส่วนลด | T3: สแกนใช้สิทธิ์ | U3: ค่าโอนเงิน | V3: ค่าใช้จ่ายอื่นๆ | W3: โอนหน้าร้าน | X3: รับสุทธิ | Y3: ยอดเงินสด | Z3: โอนเกิน/โอนขาด | AA3: วัน | AB3: รวมยอดขายหลังหักค่าใช้จ่าย
H4: คืน/เสีย | K4: จำนวน | L4: @ | M4: เป็นเงิน
A5: 1 | B5: 8857125001328 | C5: ชิฟฟ่อนเค้ก รวมรส (4 ชิ้น) | D5: กล่อง | E5: =+ยกมา!J5 -> 0 | F5: =+'30'!F5+'1'!F5+'2'!F5+'3'!F5+'4'!F5+'5'!F5+'6'!F5+'7'!F5+'8'!F5+'9'!F5+'10'!F5 -> 148 | G5: =+E5+F5 -> 148 | H5: =+'30'!H5+'1'!H5+'2'!H5+'3'!H5+'4'!H5+'5'!H5+'6'!H5+'7'!H5+'8'!H5+'9'!H5+'10'!H5 -> 0 | I5: =+'30'!I5+'1'!I5+'2'!I5+'3'!I5+'4'!I5+'5'!I5+'6'!I5+'7'!I5+'8'!I5+'9'!I5+'10'!I5 -> 0 | J5: =E5+F5-H5-K5-I5 -> 0 | K5: =+'30'!K5+'1'!K5+'2'!K5+'3'!K5+'4'!K5+'5'!K5+'6'!K5+'7'!K5+'8'!K5+'9'!K5+'10'!K5 -> 148 | L5: 50 | M5: =+'30'!M5+'1'!M5+'2'!M5+'3'!M5+'4'!M5+'5'!M5+'6'!M5+'7'!M5+'8'!M5+'9'!M5+'10'!M5 -> 7400 | O5: 22.48 | P5: =+K5*O5 -> 3327.04 | Q5: 30 | R5: =+'30'!N262 -> 5650 | S5: =+'30'!N267 -> 0 | T5: =+'30'!N265 -> 0 | U5: =+'30'!N263 -> 0 | V5: =+'30'!N266 -> 0 | W5: =+'30'!N264 -> 2295 | X5: =+R5-S5-T5-U5-V5-W5 -> 3355 | Y5: =+'30'!N269 -> 3345 | Z5: =+Y5-X5 -> -10 | AA5: อาทิตย์ | AB5: =+W5+Y5 -> 5640 | AC5: =+W5+Y5+Z5 -> 5630
A6: 2 | B6: 8857125001311 | C6: ชิฟฟ่อนเค้ก รวมรส (8 ชิ้น) | D6: กล่อง | E6: =+ยกมา!J6 -> 0 | F6: =+'30'!F6+'1'!F6+'2'!F6+'3'!F6+'4'!F6+'5'!F6+'6'!F6+'7'!F6+'8'!F6+'9'!F6+'10'!F6 -> 500 | G6: =+E6+F6 -> 500 | H6: =+'30'!H6+'1'!H6+'2'!H6+'3'!H6+'4'!H6+'5'!H6+'6'!H6+'7'!H6+'8'!H6+'9'!H6+'10'!H6 -> 0 | I6: =+'30'!I6+'1'!I6+'2'!I6+'3'!I6+'4'!I6+'5'!I6+'6'!I6+'7'!I6+'8'!I6+'9'!I6+'10'!I6 -> 62 | J6: =E6+F6-H6-K6-I6 -> 67 | K6: =+'30'!K6+'1'!K6+'2'!K6+'3'!K6+'4'!K6+'5'!K6+'6'!K6+'7'!K6+'8'!K6+'9'!K6+'10'!K6 -> 371 | L6: 100 | M6: =+'30'!M6+'1'!M6+'2'!M6+'3'!M6+'4'!M6+'5'!M6+'6'!M6+'7'!M6+'8'!M6+'9'!M6+'10'!M6 -> 37100 | O6: 39.29 | P6: =+K6*O6 -> 14576.59 | Q6: 1 | R6: =+'1'!N262 -> 20215 | S6: =+'1'!N267 -> 265 | T6: =+'1'!N265 -> 0 | U6: =+'1'!N263 -> 0 | V6: =+'1'!N266 -> 0 | W6: =+'1'!N264 -> 6175 | X6: =+R6-S6-T6-U6-V6-W6 -> 13775 | Y6: =+'1'!N269 -> 13795 | Z6: =+Y6-X6 -> 20 | AA6: จันทร์ | AB6: =+W6+Y6 -> 19970 | AC6: =+W6+Y6+Z6 -> 19990
A7: 3 | B7: 8857125003841 | C7: ชิฟฟ่อนเค้ก รสกาแฟ (4 ชิ้น) | D7: ชิ้น | E7: =+ยกมา!J7 -> 0 | F7: =+'30'!F7+'1'!F7+'2'!F7+'3'!F7+'4'!F7+'5'!F7+'6'!F7+'7'!F7+'8'!F7+'9'!F7+'10'!F7 -> 0 | G7: =+E7+F7 -> 0 | H7: =+'30'!H7+'1'!H7+'2'!H7+'3'!H7+'4'!H7+'5'!H7+'6'!H7+'7'!H7+'8'!H7+'9'!H7+'10'!H7 -> 0 | I7: =+'30'!I7+'1'!I7+'2'!I7+'3'!I7+'4'!I7+'5'!I7+'6'!I7+'7'!I7+'8'!I7+'9'!I7+'10'!I7 -> 0 | J7: =E7+F7-H7-K7-I7 -> 0 | K7: =+'30'!K7+'1'!K7+'2'!K7+'3'!K7+'4'!K7+'5'!K7+'6'!K7+'7'!K7+'8'!K7+'9'!K7+'10'!K7 -> 0 | L7: 50 | M7: =+'30'!M7+'1'!M7+'2'!M7+'3'!M7+'4'!M7+'5'!M7+'6'!M7+'7'!M7+'8'!M7+'9'!M7+'10'!M7 -> 0 | O7: 26.11 | P7: =+K7*O7 -> 0 | Q7: 2 | R7: =+'2'!N262 -> 14793 | S7: =+'2'!N267 -> 378 | T7: =+'2'!N265 -> 0 | U7: =+'2'!N263 -> 0 | V7: =+'2'!N266 -> 0 | W7: =+'2'!N264 -> 4370 | X7: =+R7-S7-T7-U7-V7-W7 -> 10045 | Y7: =+'2'!N269 -> 10025 | Z7: =+Y7-X7 -> -20 | AA7: อังคาร | AB7: =+W7+Y7 -> 14395 | AC7: =+W7+Y7+Z7 -> 14375
A8: 4 | B8: 8857125003827 | C8: ชิฟฟ่อนเค้ก รสกาแฟ (8 ชิ้น) | D8: กล่อง | E8: =+ยกมา!J8 -> 0 | F8: =+'30'!F8+'1'!F8+'2'!F8+'3'!F8+'4'!F8+'5'!F8+'6'!F8+'7'!F8+'8'!F8+'9'!F8+'10'!F8 -> 0 | G8: =+E8+F8 -> 0 | H8: =+'30'!H8+'1'!H8+'2'!H8+'3'!H8+'4'!H8+'5'!H8+'6'!H8+'7'!H8+'8'!H8+'9'!H8+'10'!H8 -> 0 | I8: =+'30'!I8+'1'!I8+'2'!I8+'3'!I8+'4'!I8+'5'!I8+'6'!I8+'7'!I8+'8'!I8+'9'!I8+'10'!I8 -> 0 | J8: =E8+F8-H8-K8-I8 -> 0 | K8: =+'30'!K8+'1'!K8+'2'!K8+'3'!K8+'4'!K8+'5'!K8+'6'!K8+'7'!K8+'8'!K8+'9'!K8+'10'!K8 -> 0 | L8: 100 | M8: =+'30'!M8+'1'!M8+'2'!M8+'3'!M8+'4'!M8+'5'!M8+'6'!M8+'7'!M8+'8'!M8+'9'!M8+'10'!M8 -> 0 | O8: 33.89 | P8: =+K8*O8 -> 0 | Q8: 3 | R8: =+'3'!N262 -> 16346 | S8: =+'3'!N267 -> 2071 | T8: =+'3'!N265 -> 0 | U8: =+'3'!N263 -> 0 | V8: =+'3'!N266 -> 0 | W8: =+'3'!N264 -> 5335 | X8: =+R8-S8-T8-U8-V8-W8 -> 8940 | Y8: =+'3'!N269 -> 8945 | Z8: =+Y8-X8 -> 5 | AA8: พุธ | AB8: =+W8+Y8 -> 14280 | AC8: =+W8+Y8+Z8 -> 14285
A9: 5 | B9: 8857125002257 | C9: ชิฟฟ่อนเค้ก 1 ชิ้น | D9: ชิ้น | E9: =+ยกมา!J9 -> 0 | F9: =+'30'!F9+'1'!F9+'2'!F9+'3'!F9+'4'!F9+'5'!F9+'6'!F9+'7'!F9+'8'!F9+'9'!F9+'10'!F9 -> 250 | G9: =+E9+F9 -> 250 | H9: =+'30'!H9+'1'!H9+'2'!H9+'3'!H9+'4'!H9+'5'!H9+'6'!H9+'7'!H9+'8'!H9+'9'!H9+'10'!H9 -> 0 | I9: =+'30'!I9+'1'!I9+'2'!I9+'3'!I9+'4'!I9+'5'!I9+'6'!I9+'7'!I9+'8'!I9+'9'!I9+'10'!I9 -> 0 | J9: =E9+F9-H9-K9-I9 -> 0 | K9: =+'30'!K9+'1'!K9+'2'!K9+'3'!K9+'4'!K9+'5'!K9+'6'!K9+'7'!K9+'8'!K9+'9'!K9+'10'!K9 -> 250 | L9: 10 | M9: =+'30'!M9+'1'!M9+'2'!M9+'3'!M9+'4'!M9+'5'!M9+'6'!M9+'7'!M9+'8'!M9+'9'!M9+'10'!M9 -> 2500 | O9: 4.5 | P9: =+K9*O9 -> 1125 | Q9: 4 | R9: =+'4'!N262 -> 23944 | S9: =+'4'!N267 -> 2829 | T9: =+'4'!N265 -> 0 | U9: =+'4'!N263 -> 0 | V9: =+'4'!N266 -> 0 | W9: =+'4'!N264 -> 7015 | X9: =+R9-S9-T9-U9-V9-W9 -> 14100 | Y9: =+'4'!N269 -> 13390 | Z9: =+Y9-X9 -> -710 | AA9: พฤหัสบดี | AB9: =+W9+Y9 -> 20405 | AC9: =+W9+Y9+Z9 -> 19695
A10: 6 | B10: 8857125002264 | C10: ชิฟฟ่อนเค้กสอดไส้แยม 1 ชิ้น | D10: ชิ้น | E10: =+ยกมา!J10 -> 0 | F10: =+'30'!F10+'1'!F10+'2'!F10+'3'!F10+'4'!F10+'5'!F10+'6'!F10+'7'!F10+'8'!F10+'9'!F10+'10'!F10 -> 0 | G10: =+E10+F10 -> 0 | H10: =+'30'!H10+'1'!H10+'2'!H10+'3'!H10+'4'!H10+'5'!H10+'6'!H10+'7'!H10+'8'!H10+'9'!H10+'10'!H10 -> 0 | I10: =+'30'!I10+'1'!I10+'2'!I10+'3'!I10+'4'!I10+'5'!I10+'6'!I10+'7'!I10+'8'!I10+'9'!I10+'10'!I10 -> 0 | J10: =E10+F10-H10-K10-I10 -> 0 | K10: =+'30'!K10+'1'!K10+'2'!K10+'3'!K10+'4'!K10+'5'!K10+'6'!K10+'7'!K10+'8'!K10+'9'!K10+'10'!K10 -> 0 | L10: 15 | M10: =+'30'!M10+'1'!M10+'2'!M10+'3'!M10+'4'!M10+'5'!M10+'6'!M10+'7'!M10+'8'!M10+'9'!M10+'10'!M10 -> 0 | O10: 4.5 | P10: =+K10*O10 -> 0 | Q10: 5 | R10: =+'5'!N262 -> 37925 | S10: =+'5'!N267 -> 4895 | T10: =+'5'!N265 -> 0 | U10: =+'5'!N263 -> 0 | V10: =+'5'!N266 -> 0 | W10: =+'5'!N264 -> 7595 | X10: =+R10-S10-T10-U10-V10-W10 -> 25435 | Y10: =+'5'!N269 -> 24785 | Z10: =+Y10-X10 -> -650 | AA10: ศุกร์ | AB10: =+W10+Y10 -> 32380 | AC10: =+W10+Y10+Z10 -> 31730
A11: 7 | B11: 8857125001830 | C11: ชิฟฟ่อนเค้กสอดไส้ รวมรส (3 ชิ้น) | D11: กล่อง | E11: =+ยกมา!J11 -> 0 | F11: =+'30'!F11+'1'!F11+'2'!F11+'3'!F11+'4'!F11+'5'!F11+'6'!F11+'7'!F11+'8'!F11+'9'!F11+'10'!F11 -> 90 | G11: =+E11+F11 -> 90 | H11: =+'30'!H11+'1'!H11+'2'!H11+'3'!H11+'4'!H11+'5'!H11+'6'!H11+'7'!H11+'8'!H11+'9'!H11+'10'!H11 -> 0 | I11: =+'30'!I11+'1'!I11+'2'!I11+'3'!I11+'4'!I11+'5'!I11+'6'!I11+'7'!I11+'8'!I11+'9'!I11+'10'!I11 -> 0 | J11: =E11+F11-H11-K11-I11 -> 12 | K11: =+'30'!K11+'1'!K11+'2'!K11+'3'!K11+'4'!K11+'5'!K11+'6'!K11+'7'!K11+'8'!K11+'9'!K11+'10'!K11 -> 78 | L11: 50 | M11: =+'30'!M11+'1'!M11+'2'!M11+'3'!M11+'4'!M11+'5'!M11+'6'!M11+'7'!M11+'8'!M11+'9'!M11+'10'!M11 -> 3900 | O11: 16.94 | P11: =+K11*O11 -> 1321.32 | Q11: 6 | R11: =+'6'!N262 -> 24381 | S11: =+'6'!N267 -> 2246 | T11: =+'6'!N265 -> 0 | U11: =+'6'!N263 -> 0 | V11: =+'6'!N266 -> 0 | W11: =+'6'!N264 -> 8855 | X11: =+R11-S11-T11-U11-V11-W11 -> 13280 | Y11: =+'6'!N269 -> 13110 | Z11: =+Y11-X11 -> -170 | AA11: เสาร์ | AB11: =+W11+Y11 -> 21965 | AC11: =+W11+Y11+Z11 -> 21795
A12: 8 | B12: 1112539 | C12: ชิฟฟ่อนเค้กสอดไส้ เมล่อน (3 ชิ้น) | D12: กล่อง | E12: =+ยกมา!J12 -> 0 | F12: =+'30'!F12+'1'!F12+'2'!F12+'3'!F12+'4'!F12+'5'!F12+'6'!F12+'7'!F12+'8'!F12+'9'!F12+'10'!F12 -> 0 | G12: =+E12+F12 -> 0 | H12: =+'30'!H12+'1'!H12+'2'!H12+'3'!H12+'4'!H12+'5'!H12+'6'!H12+'7'!H12+'8'!H12+'9'!H12+'10'!H12 -> 0 | I12: =+'30'!I12+'1'!I12+'2'!I12+'3'!I12+'4'!I12+'5'!I12+'6'!I12+'7'!I12+'8'!I12+'9'!I12+'10'!I12 -> 0 | J12: =E12+F12-H12-K12-I12 -> 0 | K12: =+'30'!K12+'1'!K12+'2'!K12+'3'!K12+'4'!K12+'5'!K12+'6'!K12+'7'!K12+'8'!K12+'9'!K12+'10'!K12 -> 0 | L12: 50 | M12: =+'30'!M12+'1'!M12+'2'!M12+'3'!M12+'4'!M12+'5'!M12+'6'!M12+'7'!M12+'8'!M12+'9'!M12+'10'!M12 -> 0 | O12: 16.5 | P12: =+K12*O12 -> 0 | Q12: 7 | R12: =+'7'!N262 -> 38696 | S12: =+'7'!N267 -> 6471 | T12: =+'7'!N265 -> 0 | U12: =+'7'!N263 -> 0 | V12: =+'7'!N266 -> 2800 | W12: =+'7'!N264 -> 9040 | X12: =+R12-S12-T12-U12-V12-W12 -> 20385 | Y12: =+'7'!N269 -> 20385 | Z12: =+Y12-X12 -> 0 | AA12: อาทิตย์ | AB12: =+W12+Y12 -> 29425 | AC12: =+W12+Y12+Z12 -> 29425
A13: 9 | B13: 8857125000055 | C13: ชิฟฟ่อนเค้กสอดไส้แยม รสบลูเบอร์รี่ (3 ชิ้น) | D13: กล่อง | E13: =+ยกมา!J13 -> 0 | F13: =+'30'!F13+'1'!F13+'2'!F13+'3'!F13+'4'!F13+'5'!F13+'6'!F13+'7'!F13+'8'!F13+'9'!F13+'10'!F13 -> 0 | G13: =+E13+F13 -> 0 | H13: =+'30'!H13+'1'!H13+'2'!H13+'3'!H13+'4'!H13+'5'!H13+'6'!H13+'7'!H13+'8'!H13+'9'!H13+'10'!H13 -> 0 | I13: =+'30'!I13+'1'!I13+'2'!I13+'3'!I13+'4'!I13+'5'!I13+'6'!I13+'7'!I13+'8'!I13+'9'!I13+'10'!I13 -> 0 | J13: =E13+F13-H13-K13-I13 -> 0 | K13: =+'30'!K13+'1'!K13+'2'!K13+'3'!K13+'4'!K13+'5'!K13+'6'!K13+'7'!K13+'8'!K13+'9'!K13+'10'!K13 -> 0 | L13: 50 | M13: =+'30'!M13+'1'!M13+'2'!M13+'3'!M13+'4'!M13+'5'!M13+'6'!M13+'7'!M13+'8'!M13+'9'!M13+'10'!M13 -> 0 | O13: 17.32 | P13: =+K13*O13 -> 0 | Q13: 8 | R13: =+'8'!N262 -> 26565 | S13: =+'8'!N267 -> 4960 | T13: =+'8'!N265 -> 0 | U13: =+'8'!N263 -> 0 | V13: =+'8'!N266 -> 0 | W13: =+'8'!N264 -> 5240 | X13: =+R13-S13-T13-U13-V13-W13 -> 16365 | Y13: =+'8'!N269 -> 16165 | Z13: =+Y13-X13 -> -200 | AA13: จันทร์ | AB13: =+W13+Y13 -> 21405 | AC13: =+W13+Y13+Z13 -> 21205
A14: 10 | B14: 8857125000987 | C14: ชิฟฟ่อนเค้กสอดไส้แยม รสส้ม (3 ชิ้น) | D14: กล่อง | E14: =+ยกมา!J14 -> 0 | F14: =+'30'!F14+'1'!F14+'2'!F14+'3'!F14+'4'!F14+'5'!F14+'6'!F14+'7'!F14+'8'!F14+'9'!F14+'10'!F14 -> 0 | G14: =+E14+F14 -> 0 | H14: =+'30'!H14+'1'!H14+'2'!H14+'3'!H14+'4'!H14+'5'!H14+'6'!H14+'7'!H14+'8'!H14+'9'!H14+'10'!H14 -> 0 | I14: =+'30'!I14+'1'!I14+'2'!I14+'3'!I14+'4'!I14+'5'!I14+'6'!I14+'7'!I14+'8'!I14+'9'!I14+'10'!I14 -> 0 | J14: =E14+F14-H14-K14-I14 -> 0 | K14: =+'30'!K14+'1'!K14+'2'!K14+'3'!K14+'4'!K14+'5'!K14+'6'!K14+'7'!K14+'8'!K14+'9'!K14+'10'!K14 -> 0 | L14: 50 | M14: =+'30'!M14+'1'!M14+'2'!M14+'3'!M14+'4'!M14+'5'!M14+'6'!M14+'7'!M14+'8'!M14+'9'!M14+'10'!M14 -> 0 | O14: 21.22 | P14: =+K14*O14 -> 0 | Q14: 9 | R14: =+'9'!N262 -> 19040 | S14: =+'9'!N267 -> 3185 | T14: =+'9'!N265 -> 0 | U14: =+'9'!N263 -> 0 | V14: =+'9'!N266 -> 0 | W14: =+'9'!N264 -> 5500 | X14: =+R14-S14-T14-U14-V14-W14 -> 10355 | Y14: =+'9'!N269 -> 10010 | Z14: =+Y14-X14 -> -345 | AA14: อังคาร | AB14: =+W14+Y14 -> 15510 | AC14: =+W14+Y14+Z14 -> 15165
A15: 11 | B15: 8857125000246 | C15: ชิฟฟ่อนเค้กหน้าฝอยทอง สอดไส้แยมส้ม (3 ชิ้น) | D15: กล่อง | E15: =+ยกมา!J15 -> 0 | F15: =+'30'!F15+'1'!F15+'2'!F15+'3'!F15+'4'!F15+'5'!F15+'6'!F15+'7'!F15+'8'!F15+'9'!F15+'10'!F15 -> 40 | G15: =+E15+F15 -> 40 | H15: =+'30'!H15+'1'!H15+'2'!H15+'3'!H15+'4'!H15+'5'!H15+'6'!H15+'7'!H15+'8'!H15+'9'!H15+'10'!H15 -> 0 | I15: =+'30'!I15+'1'!I15+'2'!I15+'3'!I15+'4'!I15+'5'!I15+'6'!I15+'7'!I15+'8'!I15+'9'!I15+'10'!I15 -> 0 | J15: =E15+F15-H15-K15-I15 -> 0 | K15: =+'30'!K15+'1'!K15+'2'!K15+'3'!K15+'4'!K15+'5'!K15+'6'!K15+'7'!K15+'8'!K15+'9'!K15+'10'!K15 -> 40 | L15: 50 | M15: =+'30'!M15+'1'!M15+'2'!M15+'3'!M15+'4'!M15+'5'!M15+'6'!M15+'7'!M15+'8'!M15+'9'!M15+'10'!M15 -> 2000 | O15: 24.37 | P15: =+K15*O15 -> 974.8 | Q15: 10 | R15: =+'10'!N262 -> 35495 | S15: =+'10'!N267 -> 10206 | T15: =+'10'!N265 -> 0 | U15: =+'10'!N263 -> 0 | V15: =+'10'!N266 -> 0 | W15: =+'10'!N264 -> 5500 | X15: =+R15-S15-T15-U15-V15-W15 -> 19789 | Y15: =+'10'!N269 -> 18825 | Z15: =+Y15-X15 -> -964 | AA15: พุธ | AB15: =+W15+Y15 -> 24325 | AC15: =+W15+Y15+Z15 -> 23361
A16: 12 | C16: ชิฟฟ่อนเค้กหน้าฝอยทองทูโทน สอดไส้แยมส้ม (3 ชิ้น) | D16: กล่อง | E16: =+ยกมา!J16 -> 0 | F16: =+'30'!F16+'1'!F16+'2'!F16+'3'!F16+'4'!F16+'5'!F16+'6'!F16+'7'!F16+'8'!F16+'9'!F16+'10'!F16 -> 0 | G16: =+E16+F16 -> 0 | H16: =+'30'!H16+'1'!H16+'2'!H16+'3'!H16+'4'!H16+'5'!H16+'6'!H16+'7'!H16+'8'!H16+'9'!H16+'10'!H16 -> 0 | I16: =+'30'!I16+'1'!I16+'2'!I16+'3'!I16+'4'!I16+'5'!I16+'6'!I16+'7'!I16+'8'!I16+'9'!I16+'10'!I16 -> 0 | J16: =E16+F16-H16-K16-I16 -> 0 | K16: =+'30'!K16+'1'!K16+'2'!K16+'3'!K16+'4'!K16+'5'!K16+'6'!K16+'7'!K16+'8'!K16+'9'!K16+'10'!K16 -> 0 | L16: 50 | M16: =+'30'!M16+'1'!M16+'2'!M16+'3'!M16+'4'!M16+'5'!M16+'6'!M16+'7'!M16+'8'!M16+'9'!M16+'10'!M16 -> 0 | O16: 0 | P16: =+K16*O16 -> 0 | R16: =SUM(R5:R15) -> 263050 | S16: =SUM(S5:S15) -> 37506 | T16: =SUM(T5:T15) -> 0 | U16: =SUM(U5:U15) -> 0 | V16: =SUM(V5:V15) -> 2800 | W16: =SUM(W5:W15) -> 66920 | X16: =SUM(X5:X15) -> 155824 | Y16: =SUM(Y5:Y15) -> 152780 | ... AB16: =SUM(AB5:AB15) -> 219700
A17: 13 | B17: 8857125000024 | C17: ชิฟฟ่อนเค้กสอดไส้แยม รสสตรอว์เบอรี่ (3 ชิ้น) | D17: กล่อง | E17: =+ยกมา!J17 -> 0 | F17: =+'30'!F17+'1'!F17+'2'!F17+'3'!F17+'4'!F17+'5'!F17+'6'!F17+'7'!F17+'8'!F17+'9'!F17+'10'!F17 -> 0 | G17: =+E17+F17 -> 0 | H17: =+'30'!H17+'1'!H17+'2'!H17+'3'!H17+'4'!H17+'5'!H17+'6'!H17+'7'!H17+'8'!H17+'9'!H17+'10'!H17 -> 0 | I17: =+'30'!I17+'1'!I17+'2'!I17+'3'!I17+'4'!I17+'5'!I17+'6'!I17+'7'!I17+'8'!I17+'9'!I17+'10'!I17 -> 0 | J17: =E17+F17-H17-K17-I17 -> 0 | K17: =+'30'!K17+'1'!K17+'2'!K17+'3'!K17+'4'!K17+'5'!K17+'6'!K17+'7'!K17+'8'!K17+'9'!K17+'10'!K17 -> 0 | L17: 50 | M17: =+'30'!M17+'1'!M17+'2'!M17+'3'!M17+'4'!M17+'5'!M17+'6'!M17+'7'!M17+'8'!M17+'9'!M17+'10'!M17 -> 0 | O17: 15.05 | P17: =+K17*O17 -> 0
A18: 14 | B18: 8857125000086 | C18: ชิฟฟ่อนเค้กสอดไส้ เนยมะพร้าว (3 ชิ้น) | D18: กล่อง | E18: =+ยกมา!J18 -> 0 | F18: =+'30'!F18+'1'!F18+'2'!F18+'3'!F18+'4'!F18+'5'!F18+'6'!F18+'7'!F18+'8'!F18+'9'!F18+'10'!F18 -> 40 | G18: =+E18+F18 -> 40 | H18: =+'30'!H18+'1'!H18+'2'!H18+'3'!H18+'4'!H18+'5'!H18+'6'!H18+'7'!H18+'8'!H18+'9'!H18+'10'!H18 -> 0 | I18: =+'30'!I18+'1'!I18+'2'!I18+'3'!I18+'4'!I18+'5'!I18+'6'!I18+'7'!I18+'8'!I18+'9'!I18+'10'!I18 -> 0 | J18: =E18+F18-H18-K18-I18 -> 0 | K18: =+'30'!K18+'1'!K18+'2'!K18+'3'!K18+'4'!K18+'5'!K18+'6'!K18+'7'!K18+'8'!K18+'9'!K18+'10'!K18 -> 40 | L18: 50 | M18: =+'30'!M18+'1'!M18+'2'!M18+'3'!M18+'4'!M18+'5'!M18+'6'!M18+'7'!M18+'8'!M18+'9'!M18+'10'!M18 -> 2000 | O18: 18.77 | P18: =+K18*O18 -> 750.8
A19: 15 | B19: 8857125000239 | C19: ชิฟฟ่อนเค้กสอดไส้ นมชมพูฮอกไกโด (3 ชิ้น) | D19: กล่อง | E19: =+ยกมา!J19 -> 0 | F19: =+'30'!F19+'1'!F19+'2'!F19+'3'!F19+'4'!F19+'5'!F19+'6'!F19+'7'!F19+'8'!F19+'9'!F19+'10'!F19 -> 0 | G19: =+E19+F19 -> 0 | H19: =+'30'!H19+'1'!H19+'2'!H19+'3'!H19+'4'!H19+'5'!H19+'6'!H19+'7'!H19+'8'!H19+'9'!H19+'10'!H19 -> 0 | I19: =+'30'!I19+'1'!I19+'2'!I19+'3'!I19+'4'!I19+'5'!I19+'6'!I19+'7'!I19+'8'!I19+'9'!I19+'10'!I19 -> 0 | J19: =E19+F19-H19-K19-I19 -> 0 | K19: =+'30'!K19+'1'!K19+'2'!K19+'3'!K19+'4'!K19+'5'!K19+'6'!K19+'7'!K19+'8'!K19+'9'!K19+'10'!K19 -> 0 | L19: 50 | M19: =+'30'!M19+'1'!M19+'2'!M19+'3'!M19+'4'!M19+'5'!M19+'6'!M19+'7'!M19+'8'!M19+'9'!M19+'10'!M19 -> 0 | O19: 19.04 | P19: =+K19*O19 -> 0
A20: 16 | B20: 8857125001816 | C20: ชิฟฟ่อน สอดไส้ (ล) 4 ชิ้น ครีมมะพร้าว | D20: กล่อง | E20: =+ยกมา!J20 -> 0 | F20: =+'30'!F20+'1'!F20+'2'!F20+'3'!F20+'4'!F20+'5'!F20+'6'!F20+'7'!F20+'8'!F20+'9'!F20+'10'!F20 -> 13 | G20: =+E20+F20 -> 13 | H20: =+'30'!H20+'1'!H20+'2'!H20+'3'!H20+'4'!H20+'5'!H20+'6'!H20+'7'!H20+'8'!H20+'9'!H20+'10'!H20 -> 0 | I20: =+'30'!I20+'1'!I20+'2'!I20+'3'!I20+'4'!I20+'5'!I20+'6'!I20+'7'!I20+'8'!I20+'9'!I20+'10'!I20 -> 1 | J20: =E20+F20-H20-K20-I20 -> 0 | K20: =+'30'!K20+'1'!K20+'2'!K20+'3'!K20+'4'!K20+'5'!K20+'6'!K20+'7'!K20+'8'!K20+'9'!K20+'10'!K20 -> 12 | L20: 65 | M20: =+'30'!M20+'1'!M20+'2'!M20+'3'!M20+'4'!M20+'5'!M20+'6'!M20+'7'!M20+'8'!M20+'9'!M20+'10'!M20 -> 780 | O20: 22.25 | P20: =+K20*O20 -> 267
A21: 17 | B21: 8857125001021 | C21: ชิฟฟ่อน สอดไส้ (ก) 5 ชิ้น ครีมมะพร้าว | D21: กล่อง | E21: =+ยกมา!J21 -> 0 | F21: =+'30'!F21+'1'!F21+'2'!F21+'3'!F21+'4'!F21+'5'!F21+'6'!F21+'7'!F21+'8'!F21+'9'!F21+'10'!F21 -> 5 | G21: =+E21+F21 -> 5 | H21: =+'30'!H21+'1'!H21+'2'!H21+'3'!H21+'4'!H21+'5'!H21+'6'!H21+'7'!H21+'8'!H21+'9'!H21+'10'!H21 -> 0 | I21: =+'30'!I21+'1'!I21+'2'!I21+'3'!I21+'4'!I21+'5'!I21+'6'!I21+'7'!I21+'8'!I21+'9'!I21+'10'!I21 -> 0 | J21: =E21+F21-H21-K21-I21 -> 0 | K21: =+'30'!K21+'1'!K21+'2'!K21+'3'!K21+'4'!K21+'5'!K21+'6'!K21+'7'!K21+'8'!K21+'9'!K21+'10'!K21 -> 5 | L21: 85 | M21: =+'30'!M21+'1'!M21+'2'!M21+'3'!M21+'4'!M21+'5'!M21+'6'!M21+'7'!M21+'8'!M21+'9'!M21+'10'!M21 -> 425 | O21: 22.85 | P21: =+K21*O21 -> 114.25
A22: 18 | B22: 8857125000956 | C22: ชิฟฟ่อนเค้กสอดไส้ รวมรส (6 ชิ้น) | D22: กล่อง | E22: =+ยกมา!J22 -> 0 | F22: =+'30'!F22+'1'!F22+'2'!F22+'3'!F22+'4'!F22+'5'!F22+'6'!F22+'7'!F22+'8'!F22+'9'!F22+'10'!F22 -> 280 | G22: =+E22+F22 -> 280 | H22: =+'30'!H22+'1'!H22+'2'!H22+'3'!H22+'4'!H22+'5'!H22+'6'!H22+'7'!H22+'8'!H22+'9'!H22+'10'!H22 -> 0 | I22: =+'30'!I22+'1'!I22+'2'!I22+'3'!I22+'4'!I22+'5'!I22+'6'!I22+'7'!I22+'8'!I22+'9'!I22+'10'!I22 -> 10 | J22: =E22+F22-H22-K22-I22 -> 77 | K22: =+'30'!K22+'1'!K22+'2'!K22+'3'!K22+'4'!K22+'5'!K22+'6'!K22+'7'!K22+'8'!K22+'9'!K22+'10'!K22 -> 193 | L22: 100 | M22: =+'30'!M22+'1'!M22+'2'!M22+'3'!M22+'4'!M22+'5'!M22+'6'!M22+'7'!M22+'8'!M22+'9'!M22+'10'!M22 -> 19300 | O22: 26.6 | P22: =+K22*O22 -> 5133.8
A23: 19 | B23: 8857125000918 | C23: ชิฟฟ่อนเค้กสอดไส้แยม รสส้ม (6 ชิ้น) | D23: กล่อง | E23: =+ยกมา!J23 -> 0 | F23: =+'30'!F23+'1'!F23+'2'!F23+'3'!F23+'4'!F23+'5'!F23+'6'!F23+'7'!F23+'8'!F23+'9'!F23+'10'!F23 -> 0 | G23: =+E23+F23 -> 0 | H23: =+'30'!H23+'1'!H23+'2'!H23+'3'!H23+'4'!H23+'5'!H23+'6'!H23+'7'!H23+'8'!H23+'9'!H23+'10'!H23 -> 0 | I23: =+'30'!I23+'1'!I23+'2'!I23+'3'!I23+'4'!I23+'5'!I23+'6'!I23+'7'!I23+'8'!I23+'9'!I23+'10'!I23 -> 0 | J23: =E23+F23-H23-K23-I23 -> 0 | K23: =+'30'!K23+'1'!K23+'2'!K23+'3'!K23+'4'!K23+'5'!K23+'6'!K23+'7'!K23+'8'!K23+'9'!K23+'10'!K23 -> 0 | L23: 100 | M23: =+'30'!M23+'1'!M23+'2'!M23+'3'!M23+'4'!M23+'5'!M23+'6'!M23+'7'!M23+'8'!M23+'9'!M23+'10'!M23 -> 0 | O23: 42.24 | P23: =+K23*O23 -> 0
A24: 20 | B24: 8857125000970 | C24: ชิฟฟ่อนเค้กหน้าฝอยทอง สอดไส้แยมส้ม (6 ชิ้น) | D24: กล่อง | E24: =+ยกมา!J24 -> 0 | F24: =+'30'!F24+'1'!F24+'2'!F24+'3'!F24+'4'!F24+'5'!F24+'6'!F24+'7'!F24+'8'!F24+'9'!F24+'10'!F24 -> 60 | G24: =+E24+F24 -> 60 | H24: =+'30'!H24+'1'!H24+'2'!H24+'3'!H24+'4'!H24+'5'!H24+'6'!H24+'7'!H24+'8'!H24+'9'!H24+'10'!H24 -> 0 | I24: =+'30'!I24+'1'!I24+'2'!I24+'3'!I24+'4'!I24+'5'!I24+'6'!I24+'7'!I24+'8'!I24+'9'!I24+'10'!I24 -> 0 | J24: =E24+F24-H24-K24-I24 -> 20 | K24: =+'30'!K24+'1'!K24+'2'!K24+'3'!K24+'4'!K24+'5'!K24+'6'!K24+'7'!K24+'8'!K24+'9'!K24+'10'!K24 -> 40 | L24: 100 | M24: =+'30'!M24+'1'!M24+'2'!M24+'3'!M24+'4'!M24+'5'!M24+'6'!M24+'7'!M24+'8'!M24+'9'!M24+'10'!M24 -> 4000 | O24: 40.51 | P24: =+K24*O24 -> 1620.4
A25: 21 | B25: 8857125003810 | C25: ชิฟฟ่อนเค้กหน้าฝอยทองทูโทน สอดไส้แยมส้ม (6 ชิ้น) | D25: กล่อง | E25: =+ยกมา!J25 -> 0 | F25: =+'30'!F25+'1'!F25+'2'!F25+'3'!F25+'4'!F25+'5'!F25+'6'!F25+'7'!F25+'8'!F25+'9'!F25+'10'!F25 -> 0 | G25: =+E25+F25 -> 0 | H25: =+'30'!H25+'1'!H25+'2'!H25+'3'!H25+'4'!H25+'5'!H25+'6'!H25+'7'!H25+'8'!H25+'9'!H25+'10'!H25 -> 0 | I25: =+'30'!I25+'1'!I25+'2'!I25+'3'!I25+'4'!I25+'5'!I25+'6'!I25+'7'!I25+'8'!I25+'9'!I25+'10'!I25 -> 0 | J25: =E25+F25-H25-K25-I25 -> 0 | K25: =+'30'!K25+'1'!K25+'2'!K25+'3'!K25+'4'!K25+'5'!K25+'6'!K25+'7'!K25+'8'!K25+'9'!K25+'10'!K25 -> 0 | L25: 100 | M25: =+'30'!M25+'1'!M25+'2'!M25+'3'!M25+'4'!M25+'5'!M25+'6'!M25+'7'!M25+'8'!M25+'9'!M25+'10'!M25 -> 0 | O25: 39.77 | P25: =+K25*O25 -> 0
A26: 22 | B26: 8857125000963 | C26: ชิฟฟ่อนเค้กสอดไส้ นมชมพูฮอกไกโด (6 ชิ้น) | D26: กล่อง | E26: =+ยกมา!J26 -> 0 | F26: =+'30'!F26+'1'!F26+'2'!F26+'3'!F26+'4'!F26+'5'!F26+'6'!F26+'7'!F26+'8'!F26+'9'!F26+'10'!F26 -> 40 | G26: =+E26+F26 -> 40 | H26: =+'30'!H26+'1'!H26+'2'!H26+'3'!H26+'4'!H26+'5'!H26+'6'!H26+'7'!H26+'8'!H26+'9'!H26+'10'!H26 -> 0 | I26: =+'30'!I26+'1'!I26+'2'!I26+'3'!I26+'4'!I26+'5'!I26+'6'!I26+'7'!I26+'8'!I26+'9'!I26+'10'!I26 -> 0 | J26: =E26+F26-H26-K26-I26 -> 27 | K26: =+'30'!K26+'1'!K26+'2'!K26+'3'!K26+'4'!K26+'5'!K26+'6'!K26+'7'!K26+'8'!K26+'9'!K26+'10'!K26 -> 13 | L26: 100 | M26: =+'30'!M26+'1'!M26+'2'!M26+'3'!M26+'4'!M26+'5'!M26+'6'!M26+'7'!M26+'8'!M26+'9'!M26+'10'!M26 -> 1300 | O26: 35.39 | P26: =+K26*O26 -> 460.07
A27: 23 | B27: 8857125000932 | C27: ชิฟฟ่อนเค้กสอดไส้แยม รสบลูเบอร์รี่ (6 ชิ้น) | D27: กล่อง | E27: =+ยกมา!J27 -> 0 | F27: =+'30'!F27+'1'!F27+'2'!F27+'3'!F27+'4'!F27+'5'!F27+'6'!F27+'7'!F27+'8'!F27+'9'!F27+'10'!F27 -> 0 | G27: =+E27+F27 -> 0 | H27: =+'30'!H27+'1'!H27+'2'!H27+'3'!H27+'4'!H27+'5'!H27+'6'!H27+'7'!H27+'8'!H27+'9'!H27+'10'!H27 -> 0 | I27: =+'30'!I27+'1'!I27+'2'!I27+'3'!I27+'4'!I27+'5'!I27+'6'!I27+'7'!I27+'8'!I27+'9'!I27+'10'!I27 -> 0 | J27: =E27+F27-H27-K27-I27 -> 0 | K27: =+'30'!K27+'1'!K27+'2'!K27+'3'!K27+'4'!K27+'5'!K27+'6'!K27+'7'!K27+'8'!K27+'9'!K27+'10'!K27 -> 0 | L27: 100 | M27: =+'30'!M27+'1'!M27+'2'!M27+'3'!M27+'4'!M27+'5'!M27+'6'!M27+'7'!M27+'8'!M27+'9'!M27+'10'!M27 -> 0 | O27: 31.62 | P27: =+K27*O27 -> 0
A28: 24 | B28: 8857125000895 | C28: ชิฟฟ่อนเค้กสอดไส้ เนยมะพร้าว (6 ชิ้น) | D28: กล่อง | E28: =+ยกมา!J28 -> 0 | F28: =+'30'!F28+'1'!F28+'2'!F28+'3'!F28+'4'!F28+'5'!F28+'6'!F28+'7'!F28+'8'!F28+'9'!F28+'10'!F28 -> 50 | G28: =+E28+F28 -> 50 | H28: =+'30'!H28+'1'!H28+'2'!H28+'3'!H28+'4'!H28+'5'!H28+'6'!H28+'7'!H28+'8'!H28+'9'!H28+'10'!H28 -> 0 | I28: =+'30'!I28+'1'!I28+'2'!I28+'3'!I28+'4'!I28+'5'!I28+'6'!I28+'7'!I28+'8'!I28+'9'!I28+'10'!I28 -> 2 | J28: =E28+F28-H28-K28-I28 -> 5 | K28: =+'30'!K28+'1'!K28+'2'!K28+'3'!K28+'4'!K28+'5'!K28+'6'!K28+'7'!K28+'8'!K28+'9'!K28+'10'!K28 -> 43 | L28: 100 | M28: =+'30'!M28+'1'!M28+'2'!M28+'3'!M28+'4'!M28+'5'!M28+'6'!M28+'7'!M28+'8'!M28+'9'!M28+'10'!M28 -> 4300 | O28: 31.97 | P28: =+K28*O28 -> 1374.71
A29: 25 | B29: 8857125000901 | C29: ชิฟฟ่อนเค้กสอดไส้แยม รสสตรอว์เบอรี่ (6 ชิ้น) | D29: กล่อง | E29: =+ยกมา!J29 -> 0 | F29: =+'30'!F29+'1'!F29+'2'!F29+'3'!F29+'4'!F29+'5'!F29+'6'!F29+'7'!F29+'8'!F29+'9'!F29+'10'!F29 -> 0 | G29: =+E29+F29 -> 0 | H29: =+'30'!H29+'1'!H29+'2'!H29+'3'!H29+'4'!H29+'5'!H29+'6'!H29+'7'!H29+'8'!H29+'9'!H29+'10'!H29 -> 0 | I29: =+'30'!I29+'1'!I29+'2'!I29+'3'!I29+'4'!I29+'5'!I29+'6'!I29+'7'!I29+'8'!I29+'9'!I29+'10'!I29 -> 0 | J29: =E29+F29-H29-K29-I29 -> 0 | K29: =+'30'!K29+'1'!K29+'2'!K29+'3'!K29+'4'!K29+'5'!K29+'6'!K29+'7'!K29+'8'!K29+'9'!K29+'10'!K29 -> 0 | L29: 100 | M29: =+'30'!M29+'1'!M29+'2'!M29+'3'!M29+'4'!M29+'5'!M29+'6'!M29+'7'!M29+'8'!M29+'9'!M29+'10'!M29 -> 0 | O29: 21.27 | P29: =+K29*O29 -> 0
A30: 26 | B30: 8857125001571 | C30: ชิฟฟอนเค้ก รสมะลิ 8ชิ้น (ห่อซีน) | D30: กล่อง | E30: =+ยกมา!J30 -> 0 | F30: =+'30'!F30+'1'!F30+'2'!F30+'3'!F30+'4'!F30+'5'!F30+'6'!F30+'7'!F30+'8'!F30+'9'!F30+'10'!F30 -> 0 | G30: =+E30+F30 -> 0 | H30: =+'30'!H30+'1'!H30+'2'!H30+'3'!H30+'4'!H30+'5'!H30+'6'!H30+'7'!H30+'8'!H30+'9'!H30+'10'!H30 -> 0 | I30: =+'30'!I30+'1'!I30+'2'!I30+'3'!I30+'4'!I30+'5'!I30+'6'!I30+'7'!I30+'8'!I30+'9'!I30+'10'!I30 -> 0 | J30: =E30+F30-H30-K30-I30 -> 0 | K30: =+'30'!K30+'1'!K30+'2'!K30+'3'!K30+'4'!K30+'5'!K30+'6'!K30+'7'!K30+'8'!K30+'9'!K30+'10'!K30 -> 0 | L30: 100 | M30: =+'30'!M30+'1'!M30+'2'!M30+'3'!M30+'4'!M30+'5'!M30+'6'!M30+'7'!M30+'8'!M30+'9'!M30+'10'!M30 -> 0 | O30: 34.26 | P30: =+K30*O30 -> 0
A31: 27 | B31: 8857125002127 | C31: ชิฟฟ่อนรวมรส ยอดฮิต (8 ชิ้น) | D31: กล่อง | E31: =+ยกมา!J31 -> 0 | F31: =+'30'!F31+'1'!F31+'2'!F31+'3'!F31+'4'!F31+'5'!F31+'6'!F31+'7'!F31+'8'!F31+'9'!F31+'10'!F31 -> 225 | G31: =+E31+F31 -> 225 | H31: =+'30'!H31+'1'!H31+'2'!H31+'3'!H31+'4'!H31+'5'!H31+'6'!H31+'7'!H31+'8'!H31+'9'!H31+'10'!H31 -> 0 | I31: =+'30'!I31+'1'!I31+'2'!I31+'3'!I31+'4'!I31+'5'!I31+'6'!I31+'7'!I31+'8'!I31+'9'!I31+'10'!I31 -> 22 | J31: =E31+F31-H31-K31-I31 -> 47 | K31: =+'30'!K31+'1'!K31+'2'!K31+'3'!K31+'4'!K31+'5'!K31+'6'!K31+'7'!K31+'8'!K31+'9'!K31+'10'!K31 -> 156 | L31: 100 | M31: =+'30'!M31+'1'!M31+'2'!M31+'3'!M31+'4'!M31+'5'!M31+'6'!M31+'7'!M31+'8'!M31+'9'!M31+'10'!M31 -> 15600 | O31: 38.46 | P31: =+K31*O31 -> 5999.76
A32: 28 | B32: 8857125000130 | C32: ชิฟฟ่อนเค้ก วรรณวนัช (สอดไส้รวมรส 8 ชิ้น) | D32: กล่อง | E32: =+ยกมา!J32 -> 0 | F32: =+'30'!F32+'1'!F32+'2'!F32+'3'!F32+'4'!F32+'5'!F32+'6'!F32+'7'!F32+'8'!F32+'9'!F32+'10'!F32 -> 17 | G32: =+E32+F32 -> 17 | H32: =+'30'!H32+'1'!H32+'2'!H32+'3'!H32+'4'!H32+'5'!H32+'6'!H32+'7'!H32+'8'!H32+'9'!H32+'10'!H32 -> 0 | I32: =+'30'!I32+'1'!I32+'2'!I32+'3'!I32+'4'!I32+'5'!I32+'6'!I32+'7'!I32+'8'!I32+'9'!I32+'10'!I32 -> 0 | J32: =E32+F32-H32-K32-I32 -> 8 | K32: =+'30'!K32+'1'!K32+'2'!K32+'3'!K32+'4'!K32+'5'!K32+'6'!K32+'7'!K32+'8'!K32+'9'!K32+'10'!K32 -> 9 | L32: 130 | M32: =+'30'!M32+'1'!M32+'2'!M32+'3'!M32+'4'!M32+'5'!M32+'6'!M32+'7'!M32+'8'!M32+'9'!M32+'10'!M32 -> 1170 | O32: 46.37 | P32: =+K32*O32 -> 417.33
A33: 29 | B33: 8857125003773 | C33: ชิฟฟ่อนเค้กมะพร้าวสอดไส้ครีมมะพร้าวล้วน (8 ชิ้น) | D33: กล่อง | E33: =+ยกมา!J33 -> 0 | F33: =+'30'!F33+'1'!F33+'2'!F33+'3'!F33+'4'!F33+'5'!F33+'6'!F33+'7'!F33+'8'!F33+'9'!F33+'10'!F33 -> 17 | G33: =+E33+F33 -> 17 | H33: =+'30'!H33+'1'!H33+'2'!H33+'3'!H33+'4'!H33+'5'!H33+'6'!H33+'7'!H33+'8'!H33+'9'!H33+'10'!H33 -> 0 | I33: =+'30'!I33+'1'!I33+'2'!I33+'3'!I33+'4'!I33+'5'!I33+'6'!I33+'7'!I33+'8'!I33+'9'!I33+'10'!I33 -> 0 | J33: =E33+F33-H33-K33-I33 -> 0 | K33: =+'30'!K33+'1'!K33+'2'!K33+'3'!K33+'4'!K33+'5'!K33+'6'!K33+'7'!K33+'8'!K33+'9'!K33+'10'!K33 -> 17 | L33: 130 | M33: =+'30'!M33+'1'!M33+'2'!M33+'3'!M33+'4'!M33+'5'!M33+'6'!M33+'7'!M33+'8'!M33+'9'!M33+'10'!M33 -> 2210 | O33: 38.9 | P33: =+K33*O33 -> 661.3
A34: 30 | B34: 8857125001366 | C34: ชิฟฟ่อนเค้กใบเตยสอดไส้ครีมมะพร้าวล้วน (8 ชิ้น) | D34: กล่อง | E34: =+ยกมา!J34 -> 0 | F34: =+'30'!F34+'1'!F34+'2'!F34+'3'!F34+'4'!F34+'5'!F34+'6'!F34+'7'!F34+'8'!F34+'9'!F34+'10'!F34 -> 0 | G34: =+E34+F34 -> 0 | H34: =+'30'!H34+'1'!H34+'2'!H34+'3'!H34+'4'!H34+'5'!H34+'6'!H34+'7'!H34+'8'!H34+'9'!H34+'10'!H34 -> 0 | I34: =+'30'!I34+'1'!I34+'2'!I34+'3'!I34+'4'!I34+'5'!I34+'6'!I34+'7'!I34+'8'!I34+'9'!I34+'10'!I34 -> 0 | J34: =E34+F34-H34-K34-I34 -> 0 | K34: =+'30'!K34+'1'!K34+'2'!K34+'3'!K34+'4'!K34+'5'!K34+'6'!K34+'7'!K34+'8'!K34+'9'!K34+'10'!K34 -> 0 | L34: 130 | M34: =+'30'!M34+'1'!M34+'2'!M34+'3'!M34+'4'!M34+'5'!M34+'6'!M34+'7'!M34+'8'!M34+'9'!M34+'10'!M34 -> 0 | O34: 38.07 | P34: =+K34*O34 -> 0
A35: 31 | B35: 8857125001397 | C35: ชิฟฟ่อนเค้กใบเตยทูโทนและสอดไส้ครีมมะพร้าว (8 ชิ้น) | D35: กล่อง | E35: =+ยกมา!J35 -> 0 | F35: =+'30'!F35+'1'!F35+'2'!F35+'3'!F35+'4'!F35+'5'!F35+'6'!F35+'7'!F35+'8'!F35+'9'!F35+'10'!F35 -> 0 | G35: =+E35+F35 -> 0 | H35: =+'30'!H35+'1'!H35+'2'!H35+'3'!H35+'4'!H35+'5'!H35+'6'!H35+'7'!H35+'8'!H35+'9'!H35+'10'!H35 -> 0 | I35: =+'30'!I35+'1'!I35+'2'!I35+'3'!I35+'4'!I35+'5'!I35+'6'!I35+'7'!I35+'8'!I35+'9'!I35+'10'!I35 -> 0 | J35: =E35+F35-H35-K35-I35 -> 0 | K35: =+'30'!K35+'1'!K35+'2'!K35+'3'!K35+'4'!K35+'5'!K35+'6'!K35+'7'!K35+'8'!K35+'9'!K35+'10'!K35 -> 0 | L35: 130 | M35: =+'30'!M35+'1'!M35+'2'!M35+'3'!M35+'4'!M35+'5'!M35+'6'!M35+'7'!M35+'8'!M35+'9'!M35+'10'!M35 -> 0 | O35: 40.8 | P35: =+K35*O35 -> 0
A36: 32 | B36: 885712004534 | C36: ชิฟฟ่อนเค้กสอดไส้ครีมมะพร้าว 120g. | D36: ชิ้น | E36: =+ยกมา!J36 -> 0 | F36: =+'30'!F36+'1'!F36+'2'!F36+'3'!F36+'4'!F36+'5'!F36+'6'!F36+'7'!F36+'8'!F36+'9'!F36+'10'!F36 -> 0 | G36: =+E36+F36 -> 0 | H36: =+'30'!H36+'1'!H36+'2'!H36+'3'!H36+'4'!H36+'5'!H36+'6'!H36+'7'!H36+'8'!H36+'9'!H36+'10'!H36 -> 0 | I36: =+'30'!I36+'1'!I36+'2'!I36+'3'!I36+'4'!I36+'5'!I36+'6'!I36+'7'!I36+'8'!I36+'9'!I36+'10'!I36 -> 0 | J36: =E36+F36-H36-K36-I36 -> 0 | K36: =+'30'!K36+'1'!K36+'2'!K36+'3'!K36+'4'!K36+'5'!K36+'6'!K36+'7'!K36+'8'!K36+'9'!K36+'10'!K36 -> 0 | L36: 35 | M36: =+'30'!M36+'1'!M36+'2'!M36+'3'!M36+'4'!M36+'5'!M36+'6'!M36+'7'!M36+'8'!M36+'9'!M36+'10'!M36 -> 0 | O36: 0 | P36: =+K36*O36 -> 0
A37: 33 | B37: 20055119 | C37: ชิฟฟ่อนเค้กฝอยทอง 95g. | D37: กล่อง | E37: =+ยกมา!J37 -> 0 | F37: =+'30'!F37+'1'!F37+'2'!F37+'3'!F37+'4'!F37+'5'!F37+'6'!F37+'7'!F37+'8'!F37+'9'!F37+'10'!F37 -> 0 | G37: =+E37+F37 -> 0 | H37: =+'30'!H37+'1'!H37+'2'!H37+'3'!H37+'4'!H37+'5'!H37+'6'!H37+'7'!H37+'8'!H37+'9'!H37+'10'!H37 -> 0 | I37: =+'30'!I37+'1'!I37+'2'!I37+'3'!I37+'4'!I37+'5'!I37+'6'!I37+'7'!I37+'8'!I37+'9'!I37+'10'!I37 -> 0 | J37: =E37+F37-H37-K37-I37 -> 0 | K37: =+'30'!K37+'1'!K37+'2'!K37+'3'!K37+'4'!K37+'5'!K37+'6'!K37+'7'!K37+'8'!K37+'9'!K37+'10'!K37 -> 0 | L37: 35 | M37: =+'30'!M37+'1'!M37+'2'!M37+'3'!M37+'4'!M37+'5'!M37+'6'!M37+'7'!M37+'8'!M37+'9'!M37+'10'!M37 -> 0 | O37: 0 | P37: =+K37*O37 -> 0
A38: 34 | B38: 8857125001267 | C38: ชิฟฟ่อนหม้อแกง | D38: กล่อง | E38: =+ยกมา!J38 -> 0 | F38: =+'30'!F38+'1'!F38+'2'!F38+'3'!F38+'4'!F38+'5'!F38+'6'!F38+'7'!F38+'8'!F38+'9'!F38+'10'!F38 -> 0 | G38: =+E38+F38 -> 0 | H38: =+'30'!H38+'1'!H38+'2'!H38+'3'!H38+'4'!H38+'5'!H38+'6'!H38+'7'!H38+'8'!H38+'9'!H38+'10'!H38 -> 0 | I38: =+'30'!I38+'1'!I38+'2'!I38+'3'!I38+'4'!I38+'5'!I38+'6'!I38+'7'!I38+'8'!I38+'9'!I38+'10'!I38 -> 0 | J38: =E38+F38-H38-K38-I38 -> 0 | K38: =+'30'!K38+'1'!K38+'2'!K38+'3'!K38+'4'!K38+'5'!K38+'6'!K38+'7'!K38+'8'!K38+'9'!K38+'10'!K38 -> 0 | L38: 35 | M38: =+'30'!M38+'1'!M38+'2'!M38+'3'!M38+'4'!M38+'5'!M38+'6'!M38+'7'!M38+'8'!M38+'9'!M38+'10'!M38 -> 0 | O38: 30.43 | P38: =+K38*O38 -> 0
A39: 35 | B39: 8857125000611 | C39: ครีมฮอร์น วนิลา | D39: กล่อง | E39: =+ยกมา!J39 -> 0 | F39: =+'30'!F39+'1'!F39+'2'!F39+'3'!F39+'4'!F39+'5'!F39+'6'!F39+'7'!F39+'8'!F39+'9'!F39+'10'!F39 -> 109 | G39: =+E39+F39 -> 109 | H39: =+'30'!H39+'1'!H39+'2'!H39+'3'!H39+'4'!H39+'5'!H39+'6'!H39+'7'!H39+'8'!H39+'9'!H39+'10'!H39 -> 0 | I39: =+'30'!I39+'1'!I39+'2'!I39+'3'!I39+'4'!I39+'5'!I39+'6'!I39+'7'!I39+'8'!I39+'9'!I39+'10'!I39 -> 2 | J39: =E39+F39-H39-K39-I39 -> 10 | K39: =+'30'!K39+'1'!K39+'2'!K39+'3'!K39+'4'!K39+'5'!K39+'6'!K39+'7'!K39+'8'!K39+'9'!K39+'10'!K39 -> 97 | L39: 50 | M39: =+'30'!M39+'1'!M39+'2'!M39+'3'!M39+'4'!M39+'5'!M39+'6'!M39+'7'!M39+'8'!M39+'9'!M39+'10'!M39 -> 4850 | O39: 27.84 | P39: =+K39*O39 -> 2700.48
A40: 36 | B40: 8857125000604 | C40: ครีมฮอร์น ใบเตย | D40: กล่อง | E40: =+ยกมา!J40 -> 0 | F40: =+'30'!F40+'1'!F40+'2'!F40+'3'!F40+'4'!F40+'5'!F40+'6'!F40+'7'!F40+'8'!F40+'9'!F40+'10'!F40 -> 59 | G40: =+E40+F40 -> 59 | H40: =+'30'!H40+'1'!H40+'2'!H40+'3'!H40+'4'!H40+'5'!H40+'6'!H40+'7'!H40+'8'!H40+'9'!H40+'10'!H40 -> 1 | I40: =+'30'!I40+'1'!I40+'2'!I40+'3'!I40+'4'!I40+'5'!I40+'6'!I40+'7'!I40+'8'!I40+'9'!I40+'10'!I40 -> 0 | J40: =E40+F40-H40-K40-I40 -> 8 | K40: =+'30'!K40+'1'!K40+'2'!K40+'3'!K40+'4'!K40+'5'!K40+'6'!K40+'7'!K40+'8'!K40+'9'!K40+'10'!K40 -> 50 | L40: 50 | M40: =+'30'!M40+'1'!M40+'2'!M40+'3'!M40+'4'!M40+'5'!M40+'6'!M40+'7'!M40+'8'!M40+'9'!M40+'10'!M40 -> 2500 | O40: 27.12 | P40: =+K40*O40 -> 1356
A41: 37 | B41: 8857125000598 | C41: ครีมฮอร์น ช็อคโกแลต | D41: กล่อง | E41: =+ยกมา!J41 -> 0 | F41: =+'30'!F41+'1'!F41+'2'!F41+'3'!F41+'4'!F41+'5'!F41+'6'!F41+'7'!F41+'8'!F41+'9'!F41+'10'!F41 -> 30 | G41: =+E41+F41 -> 30 | H41: =+'30'!H41+'1'!H41+'2'!H41+'3'!H41+'4'!H41+'5'!H41+'6'!H41+'7'!H41+'8'!H41+'9'!H41+'10'!H41 -> 0 | I41: =+'30'!I41+'1'!I41+'2'!I41+'3'!I41+'4'!I41+'5'!I41+'6'!I41+'7'!I41+'8'!I41+'9'!I41+'10'!I41 -> 0 | J41: =E41+F41-H41-K41-I41 -> 1 | K41: =+'30'!K41+'1'!K41+'2'!K41+'3'!K41+'4'!K41+'5'!K41+'6'!K41+'7'!K41+'8'!K41+'9'!K41+'10'!K41 -> 29 | L41: 50 | M41: =+'30'!M41+'1'!M41+'2'!M41+'3'!M41+'4'!M41+'5'!M41+'6'!M41+'7'!M41+'8'!M41+'9'!M41+'10'!M41 -> 1450 | O41: 15.42 | P41: =+K41*O41 -> 447.18
...

Sheet สรุปการขาย
A1: สรุปค่าใช้จ่าย คำนวนกำไร
A2: NO | B2: รายการ | C2: ยอดเงิน | D2: หมายเหตุ | F2: ยอดขาย | G2: =+สรุป!AB16 -> 219700 | H2: บาท
A3: 1 | B3: ต้นทุนขนม | C3: =+สรุป!P260 -> 112418.59 | F3: ยอดค่าใช้จ่าย | G3: =+C8 -> 186418.59 | H3: บาท
A4: 2 | B4: ค่าแรงพนักงาน | C4: =+ค่าแรงพนักงาน!C6 -> 15200 | F4: สรุปกำไร | G4: =+G2-G3 -> 33281.41 | H4: บาท
A5: 3 | B5: ค่าเช่า OTOP | C5: 45000
A6: 4 | B6: ค่าไฟ | C6: 2800
A7: 5 | B7: ค่าอินฟลูเอนเซอร์ | C7: =7000+4000 -> 11000
C8: =SUM(C3:C7) -> 186418.59
C11: 7 | D11: 8 | E11: 9 | F11: 10 | G11: 11 | H11: 12 | I11: 13 | J11: 14 | K11: 15 | L11: 16 | M11: 17 | N11: 18 | O11: 19 | P11: 20 | Q11: 21 | R11: 22

Sheet ค่าเช่าบูธ
A1: รายการเช่า - ขาย ล็อคงานเกษตรแฟร์
A2: NO | B2: รายการ | C2: ค่าเช่าบูธ | D2: ขายบูธ | E2: กำไร | F2: หมายเหตุ | H2: ค่าใช้จ่าย + ค่าเช่า | I2: =+C8+C15 -> 125870 | J2: บาท
A3: 1 | B3: ค่าเช่า 1 | C3: 16500 | D3: 28000 | E3: =+D3-C3 -> 11500 | H3: รายได้ขายล็อค | I3: =+D8 -> 158000 | J3: บาท
A4: 2 | B4: ค่าเช่า 2 | C4: 16500 | D4: 25000 | E4: =+D4-C4 -> 8500 | H4: สรุปกำไรขายล็อค | I4: =+I3-I2 -> 32130 | J4: บาท
A5: 3 | B5: ค่าเช่า 3 | C5: 16500 | D5: 27000 | E5: =+D5-C5 -> 10500
A6: 4 | B6: ค่าเช่า 4 | C6: 16500 | D6: 28000 | E6: =+D6-C6 -> 11500
A7: 5 | B7: ค่าเช่า 5 | C7: 24000 | D7: 50000 | E7: =+D7-C7 -> 26000 | F7: โซน 1
B8: ยอดรวม | C8: =SUM(C3:C7) -> 90000 | D8: =SUM(D3:D7) -> 158000 | E8: =SUM(E3:E7) -> 68000 | F8: บาท
A10: ค่าใช้จ่ายเพิ่มเติม การประมูลล็อค
A11: 1 | B11: ค่าเข้างานประมูลล็อค 19 คน | C11: 22800 | D11: =+C11/19 -> 1200
A12: 2 | B12: ค่านายหน้า | C12: 1000
A13: 3 | B13: ค่าไฟ | C13: 2570
A14: 4 | B14: ค่าแรง 19 คน เฉลี่ยคนล่ะ 500 บาท | C14: =500*19 -> 9500
C15: =SUM(C11:C14) -> 35870

Sheet ค่าแรงพนักงาน
A1: รายชื่อพนักงานที่ทำงานเกษตรแฟร์ ปี 2567
A2: No. | B2: ชื่อ | C2: ค่าแรง | D2: หมายเหตุ
A3: 1 | B3: แจม | C3: =600*11 -> 6600 | D3: วันละ 600 บาท = 11 วัน
A4: 2 | B4: พี่น้อย | C4: =600*7 -> 4200 | D4: วันละ 600 บาท = 7 วัน
A5: 3 | B5: กาน | C5: =400*11 -> 4400 | D5: วันละ 400 บาท = 11 วัน
B6: ยอดรวม | C6: =SUM(C3:C5) -> 15200 | D6: บาท

Sheet ยกมา
A2: บูธ EVENT งานเกษตรแฟร์กำแพงแสน 30 พ.ย. 67 - 10 ธ.ค. 67
A3: ลำดับ | B3: รหัสสินค้า (POS) | C3: รายการ | D3: หน่วย | E3: ยกมา | F3: รับ | G3: รวม | H3: เปลี่ยน/ | I3: โยกย้าย / ระบาย | J3: คงเหลือ | K3: รายการขาย | N3: หมายเหตุ | O3: ส่วนลด | Q3: ราคาต้นทุน | R3: ยอดรวมต้นทุนสินค้า
H4: คืน/เสีย | K4: จำนวน | L4: @ | M4: เป็นเงิน
A5: 1 | B5: 8857125001328 | C5: ชิฟฟ่อนเค้ก รวมรส (4 ชิ้น) | D5: กล่อง | G5: =E5+F5 -> 0 | H5: 0 | I5: 0 | J5: =+G5-H5-K5-I5 -> 0 | L5: 50 | M5: =+L5*K5 -> 0 | N5: - | P5: =SUM(M5-O5) -> 0 | Q5: 22.48 | R5: =+K5*Q5 -> 0
A6: 2 | B6: 8857125001311 | C6: ชิฟฟ่อนเค้ก รวมรส (8 ชิ้น) | D6: กล่อง | G6: =E6+F6 -> 0 | H6: 0 | I6: 0 | J6: =+G6-H6-K6-I6 -> 0 | L6: 100 | M6: =+L6*K6 -> 0 | N6: - | P6: =SUM(M6-O6) -> 0 | Q6: 39.29 | R6: =+K6*Q6 -> 0
A7: 3 | B7: 8857125003841 | C7: ชิฟฟ่อนเค้ก รสกาแฟ (4 ชิ้น) | D7: ชิ้น | G7: =E7+F7 -> 0 | H7: 0 | I7: 0 | J7: =+G7-H7-K7-I7 -> 0 | L7: 50 | M7: =+L7*K7 -> 0 | N7: - | P7: =SUM(M7-O7) -> 0 | Q7: 26.11 | R7: =+K7*Q7 -> 0
A8: 4 | B8: 8857125003827 | C8: ชิฟฟ่อนเค้ก รสกาแฟ (8 ชิ้น) | D8: กล่อง | G8: =E8+F8 -> 0 | H8: 0 | I8: 0 | J8: =+G8-H8-K8-I8 -> 0 | L8: 100 | M8: =+L8*K8 -> 0 | N8: - | P8: =SUM(M8-O8) -> 0 | Q8: 33.89 | R8: =+K8*Q8 -> 0
A9: 5 | B9: 8857125002257 | C9: ชิฟฟ่อนเค้ก 1 ชิ้น | D9: ชิ้น | G9: =E9+F9 -> 0 | H9: 0 | I9: 0 | J9: =+G9-H9-K9-I9 -> 0 | L9: 10 | M9: =+L9*K9 -> 0 | N9: - | P9: =SUM(M9-O9) -> 0 | R9: =+K9*Q9 -> 0
A10: 6 | B10: 8857125002264 | C10: ชิฟฟ่อนเค้กสอดไส้แยม 1 ชิ้น | D10: ชิ้น | G10: =E10+F10 -> 0 | H10: 0 | I10: 0 | J10: =+G10-H10-K10-I10 -> 0 | L10: 15 | M10: =+L10*K10 -> 0 | N10: - | P10: =SUM(M10-O10) -> 0 | R10: =+K10*Q10 -> 0
A11: 7 | B11: 8857125001830 | C11: ชิฟฟ่อนเค้กสอดไส้ รวมรส (3 ชิ้น) | D11: กล่อง | G11: =E11+F11 -> 0 | H11: 0 | I11: 0 | J11: =+G11-H11-K11-I11 -> 0 | L11: 50 | M11: =+L11*K11 -> 0 | N11: - | P11: =SUM(M11-O11) -> 0 | Q11: 16.94 | R11: =+K11*Q11 -> 0
A12: 8 | B12: 1112539 | C12: ชิฟฟ่อนเค้กสอดไส้ เมล่อน (3 ชิ้น) | D12: กล่อง | G12: =E12+F12 -> 0 | H12: 0 | I12: 0 | J12: =+G12-H12-K12-I12 -> 0 | L12: 50 | M12: =+L12*K12 -> 0 | N12: - | P12: =SUM(M12-O12) -> 0 | R12: =+K12*Q12 -> 0
A13: 9 | B13: 8857125000055 | C13: ชิฟฟ่อนเค้กสอดไส้แยม รสบลูเบอร์รี่ (3 ชิ้น) | D13: กล่อง | G13: =E13+F13 -> 0 | H13: 0 | I13: 0 | J13: =+G13-H13-K13-I13 -> 0 | L13: 50 | M13: =+L13*K13 -> 0 | N13: - | P13: =SUM(M13-O13) -> 0 | Q13: 17.32 | R13: =+K13*Q13 -> 0
A14: 10 | B14: 8857125000987 | C14: ชิฟฟ่อนเค้กสอดไส้แยม รสส้ม (3 ชิ้น) | D14: กล่อง | G14: =E14+F14 -> 0 | H14: 0 | I14: 0 | J14: =+G14-H14-K14-I14 -> 0 | L14: 50 | M14: =+L14*K14 -> 0 | N14: - | P14: =SUM(M14-O14) -> 0 | Q14: 21.22 | R14: =+K14*Q14 -> 0
A15: 11 | B15: 8857125000246 | C15: ชิฟฟ่อนเค้กหน้าฝอยทอง สอดไส้แยมส้ม (3 ชิ้น) | D15: กล่อง | G15: =E15+F15 -> 0 | H15: 0 | I15: 0 | J15: =+G15-H15-K15-I15 -> 0 | L15: 50 | M15: =+L15*K15 -> 0 | N15: - | P15: =SUM(M15-O15) -> 0 | Q15: 24.37 | R15: =+K15*Q15 -> 0
A16: 12 | C16: ชิฟฟ่อนเค้กหน้าฝอยทองทูโทน สอดไส้แยมส้ม (3 ชิ้น) | D16: กล่อง | G16: =E16+F16 -> 0 | H16: 0 | I16: 0 | J16: =+G16-H16-K16-I16 -> 0 | L16: 50 | M16: =+L16*K16 -> 0 | N16: - | P16: =SUM(M16-O16) -> 0 | R16: =+K16*Q16 -> 0
A17: 13 | B17: 8857125000024 | C17: ชิฟฟ่อนเค้กสอดไส้แยม รสสตรอว์เบอรี่ (3 ชิ้น) | D17: กล่อง | G17: =E17+F17 -> 0 | H17: 0 | I17: 0 | J17: =+G17-H17-K17-I17 -> 0 | L17: 50 | M17: =+L17*K17 -> 0 | N17: - | P17: =SUM(M17-O17) -> 0 | Q17: 15.05 | R17: =+K17*Q17 -> 0
A18: 14 | B18: 8857125000086 | C18: ชิฟฟ่อนเค้กสอดไส้ เนยมะพร้าว (3 ชิ้น) | D18: กล่อง | G18: =E18+F18 -> 0 | H18: 0 | I18: 0 | J18: =+G18-H18-K18-I18 -> 0 | L18: 50 | M18: =+L18*K18 -> 0 | N18: - | P18: =SUM(M18-O18) -> 0 | Q18: 18.77 | R18: =+K18*Q18 -> 0
A19: 15 | B19: 8857125000239 | C19: ชิฟฟ่อนเค้กสอดไส้ นมชมพูฮอกไกโด (3 ชิ้น) | D19: กล่อง | G19: =E19+F19 -> 0 | H19: 0 | I19: 0 | J19: =+G19-H19-K19-I19 -> 0 | L19: 50 | M19: =+L19*K19 -> 0 | N19: - | P19: =SUM(M19-O19) -> 0 | Q19: 19.04 | R19: =+K19*Q19 -> 0
A20: 16 | B20: 8857125001816 | C20: ชิฟฟ่อน สอดไส้ (ล) 4 ชิ้น ครีมมะพร้าว | D20: กล่อง | G20: =E20+F20 -> 0 | H20: 0 | I20: 0 | J20: =+G20-H20-K20-I20 -> 0 | L20: 65 | M20: =+L20*K20 -> 0 | N20: - | P20: =SUM(M20-O20) -> 0 | Q20: 22.25 | R20: =+K20*Q20 -> 0
A21: 17 | B21: 8857125001021 | C21: ชิฟฟ่อน สอดไส้ (ก) 5 ชิ้น ครีมมะพร้าว | D21: กล่อง | G21: =E21+F21 -> 0 | H21: 0 | I21: 0 | J21: =+G21-H21-K21-I21 -> 0 | L21: 85 | M21: =+L21*K21 -> 0 | N21: - | P21: =SUM(M21-O21) -> 0 | Q21: 22.85 | R21: =+K21*Q21 -> 0
A22: 18 | B22: 8857125000956 | C22: ชิฟฟ่อนเค้กสอดไส้ รวมรส (6 ชิ้น) | D22: กล่อง | G22: =E22+F22 -> 0 | H22: 0 | I22: 0 | J22: =+G22-H22-K22-I22 -> 0 | L22: 100 | M22: =+L22*K22 -> 0 | N22: - | P22: =SUM(M22-O22) -> 0 | Q22: 26.6 | R22: =+K22*Q22 -> 0
A23: 19 | B23: 8857125000918 | C23: ชิฟฟ่อนเค้กสอดไส้แยม รสส้ม (6 ชิ้น) | D23: กล่อง | G23: =E23+F23 -> 0 | H23: 0 | I23: 0 | J23: =+G23-H23-K23-I23 -> 0 | L23: 100 | M23: =+L23*K23 -> 0 | N23: - | P23: =SUM(M23-O23) -> 0 | Q23: 42.24 | R23: =+K23*Q23 -> 0
A24: 20 | B24: 8857125000970 | C24: ชิฟฟ่อนเค้กหน้าฝอยทอง สอดไส้แยมส้ม (6 ชิ้น) | D24: กล่อง | G24: =E24+F24 -> 0 | H24: 0 | I24: 0 | J24: =+G24-H24-K24-I24 -> 0 | L24: 100 | M24: =+L24*K24 -> 0 | N24: - | P24: =SUM(M24-O24) -> 0 | Q24: 40.51 | R24: =+K24*Q24 -> 0
A25: 21 | B25: 8857125003810 | C25: ชิฟฟ่อนเค้กหน้าฝอยทองทูโทน สอดไส้แยมส้ม (6 ชิ้น) | D25: กล่อง | G25: =E25+F25 -> 0 | H25: 0 | I25: 0 | J25: =+G25-H25-K25-I25 -> 0 | L25: 100 | M25: =+L25*K25 -> 0 | N25: - | P25: =SUM(M25-O25) -> 0 | Q25: 39.77 | R25: =+K25*Q25 -> 0
A26: 22 | B26: 8857125000963 | C26: ชิฟฟ่อนเค้กสอดไส้ นมชมพูฮอกไกโด (6 ชิ้น) | D26: กล่อง | G26: =E26+F26 -> 0 | H26: 0 | I26: 0 | J26: =+G26-H26-K26-I26 -> 0 | L26: 100 | M26: =+L26*K26 -> 0 | N26: - | P26: =SUM(M26-O26) -> 0 | Q26: 35.39 | R26: =+K26*Q26 -> 0
A27: 23 | B27: 8857125000932 | C27: ชิฟฟ่อนเค้กสอดไส้แยม รสบลูเบอร์รี่ (6 ชิ้น) | D27: กล่อง | G27: =E27+F27 -> 0 | H27: 0 | I27: 0 | J27: =+G27-H27-K27-I27 -> 0 | L27: 100 | M27: =+L27*K27 -> 0 | N27: - | P27: =SUM(M27-O27) -> 0 | Q27: 31.62 | R27: =+K27*Q27 -> 0
A28: 24 | B28: 8857125000895 | C28: ชิฟฟ่อนเค้กสอดไส้ เนยมะพร้าว (6 ชิ้น) | D28: กล่อง | G28: =E28+F28 -> 0 | H28: 0 | I28: 0 | J28: =+G28-H28-K28-I28 -> 0 | L28: 100 | M28: =+L28*K28 -> 0 | N28: - | P28: =SUM(M28-O28) -> 0 | Q28: 31.97 | R28: =+K28*Q28 -> 0
A29: 25 | B29: 8857125000901 | C29: ชิฟฟ่อนเค้กสอดไส้แยม รสสตรอว์เบอรี่ (6 ชิ้น) | D29: กล่อง | G29: =E29+F29 -> 0 | H29: 0 | I29: 0 | J29: =+G29-H29-K29-I29 -> 0 | L29: 100 | M29: =+L29*K29 -> 0 | N29: - | P29: =SUM(M29-O29) -> 0 | Q29: 21.27 | R29: =+K29*Q29 -> 0
A30: 26 | B30: 8857125001571 | C30: ชิฟฟอนเค้ก รสมะลิ 8ชิ้น (ห่อซีน) | D30: กล่อง | G30: =E30+F30 -> 0 | H30: 0 | I30: 0 | J30: =+G30-H30-K30-I30 -> 0 | L30: 100 | M30: =+L30*K30 -> 0 | N30: - | P30: =SUM(M30-O30) -> 0 | Q30: 34.26 | R30: =+K30*Q30 -> 0
A31: 27 | B31: 8857125002127 | C31: ชิฟฟ่อนรวมรส ยอดฮิต (8 ชิ้น) | D31: กล่อง | G31: =E31+F31 -> 0 | H31: 0 | I31: 0 | J31: =+G31-H31-K31-I31 -> 0 | L31: 100 | M31: =+L31*K31 -> 0 | N31: - | P31: =SUM(M31-O31) -> 0 | Q31: 38.46 | R31: =+K31*Q31 -> 0
A32: 28 | B32: 8857125000130 | C32: ชิฟฟ่อนเค้ก วรรณวนัช (สอดไส้รวมรส 8 ชิ้น) | D32: กล่อง | G32: =E32+F32 -> 0 | H32: 0 | I32: 0 | J32: =+G32-H32-K32-I32 -> 0 | L32: 130 | M32: =+L32*K32 -> 0 | N32: - | P32: =SUM(M32-O32) -> 0 | Q32: 46.37 | R32: =+K32*Q32 -> 0
A33: 29 | B33: 8857125003773 | C33: ชิฟฟ่อนเค้กมะพร้าวสอดไส้ครีมมะพร้าวล้วน (8 ชิ้น) | D33: กล่อง | G33: =E33+F33 -> 0 | H33: 0 | I33: 0 | J33: =+G33-H33-K33-I33 -> 0 | L33: 130 | M33: =+L33*K33 -> 0 | N33: - | P33: =SUM(M33-O33) -> 0 | Q33: 38.9 | R33: =+K33*Q33 -> 0
A34: 30 | B34: 8857125001366 | C34: ชิฟฟ่อนเค้กใบเตยสอดไส้ครีมมะพร้าวล้วน (8 ชิ้น) | D34: กล่อง | G34: =E34+F34 -> 0 | H34: 0 | I34: 0 | J34: =+G34-H34-K34-I34 -> 0 | L34: 130 | M34: =+L34*K34 -> 0 | N34: - | P34: =SUM(M34-O34) -> 0 | Q34: 38.07 | R34: =+K34*Q34 -> 0
A35: 31 | B35: 8857125001397 | C35: ชิฟฟ่อนเค้กใบเตยทูโทนและสอดไส้ครีมมะพร้าว (8 ชิ้น) | D35: กล่อง | G35: =E35+F35 -> 0 | H35: 0 | I35: 0 | J35: =+G35-H35-K35-I35 -> 0 | L35: 130 | M35: =+L35*K35 -> 0 | N35: - | P35: =SUM(M35-O35) -> 0 | Q35: 40.8 | R35: =+K35*Q35 -> 0
A36: 32 | B36: 885712004534 | C36: ชิฟฟ่อนเค้กสอดไส้ครีมมะพร้าว 120g. | D36: ชิ้น | G36: =E36+F36 -> 0 | H36: 0 | I36: 0 | J36: =+G36-H36-K36-I36 -> 0 | L36: 35 | M36: =+L36*K36 -> 0 | N36: - | P36: =SUM(M36-O36) -> 0 | R36: =+K36*Q36 -> 0
A37: 33 | B37: 20055119 | C37: ชิฟฟ่อนเค้กฝอยทอง 95g. | D37: กล่อง | G37: =E37+F37 -> 0 | H37: 0 | I37: 0 | J37: =+G37-H37-K37-I37 -> 0 | L37: 35 | M37: =+L37*K37 -> 0 | N37: - | P37: =SUM(M37-O37) -> 0 | R37: =+K37*Q37 -> 0
A38: 34 | B38: 8857125001267 | C38: ชิฟฟ่อนหม้อแกง | D38: กล่อง | G38: =E38+F38 -> 0 | H38: 0 | I38: 0 | J38: =+G38-H38-K38-I38 -> 0 | L38: 35 | M38: =+L38*K38 -> 0 | N38: - | P38: =SUM(M38-O38) -> 0 | R38: =+K38*Q38 -> 0
A39: 35 | B39: 8857125000611 | C39: ครีมฮอร์น วนิลา | D39: กล่อง | G39: =E39+F39 -> 0 | H39: 0 | I39: 0 | J39: =+G39-H39-K39-I39 -> 0 | L39: 50 | M39: =+L39*K39 -> 0 | N39: - | P39: =SUM(M39-O39) -> 0 | Q39: 27.84 | R39: =+K39*Q39 -> 0
A40: 36 | B40: 8857125000604 | C40: ครีมฮอร์น ใบเตย | D40: กล่อง | G40: =E40+F40 -> 0 | H40: 0 | I40: 0 | J40: =+G40-H40-K40-I40 -> 0 | L40: 50 | M40: =+L40*K40 -> 0 | N40: - | P40: =SUM(M40-O40) -> 0 | Q40: 27.12 | R40: =+K40*Q40 -> 0
A41: 37 | B41: 8857125000598 | C41: ครีมฮอร์น ช็อคโกแลต | D41: กล่อง | G41: =E41+F41 -> 0 | H41: 0 | I41: 0 | J41: =+G41-H41-K41-I41 -> 0 | L41: 50 | M41: =+L41*K41 -> 0 | N41: - | P41: =SUM(M41-O41) -> 0 | Q41: 15.42 | R41: =+K41*Q41 -> 0
...

Sheet 30
A2: บูธ EVENT งานเกษตรแฟร์กำแพงแสน 30 พ.ย. 67 - 10 ธ.ค. 67
A3: ลำดับ | B3: รหัสสินค้า (POS) | C3: รายการ | D3: หน่วย | E3: ยกมา | F3: รับ | G3: รวม | H3: เปลี่ยน/ | I3: โยกย้าย / ระบาย | J3: คงเหลือ | K3: รายการขาย | N3: หมายเหตุ | O3: ส่วนลด | Q3: ราคาต้นทุน | R3: ยอดรวมต้นทุนสินค้า
H4: คืน/เสีย | K4: จำนวน | L4: @ | M4: เป็นเงิน
A5: 1 | B5: 8857125001328 | C5: ชิฟฟ่อนเค้ก รวมรส (4 ชิ้น) | D5: กล่อง | F5: 50 | G5: =E5+F5 -> 50 | H5: 0 | I5: 0 | J5: =+G5-H5-K5-I5 -> 48 | K5: 2 | L5: 50 | M5: =+L5*K5 -> 100 | N5: - | P5: =SUM(M5-O5) -> 100 | Q5: 22.48 | R5: =+K5*Q5 -> 44.96
A6: 2 | B6: 8857125001311 | C6: ชิฟฟ่อนเค้ก รวมรส (8 ชิ้น) | D6: กล่อง | F6: 100 | G6: =E6+F6 -> 100 | H6: 0 | I6: 0 | J6: =+G6-H6-K6-I6 -> 92 | K6: 8 | L6: 100 | M6: =+L6*K6 -> 800 | N6: - | P6: =SUM(M6-O6) -> 800 | Q6: 39.29 | R6: =+K6*Q6 -> 314.32
A7: 3 | B7: 8857125003841 | C7: ชิฟฟ่อนเค้ก รสกาแฟ (4 ชิ้น) | D7: ชิ้น | G7: =E7+F7 -> 0 | H7: 0 | I7: 0 | J7: =+G7-H7-K7-I7 -> 0 | L7: 50 | M7: =+L7*K7 -> 0 | N7: - | P7: =SUM(M7-O7) -> 0 | Q7: 26.11 | R7: =+K7*Q7 -> 0
A8: 4 | B8: 8857125003827 | C8: ชิฟฟ่อนเค้ก รสกาแฟ (8 ชิ้น) | D8: กล่อง | G8: =E8+F8 -> 0 | H8: 0 | I8: 0 | J8: =+G8-H8-K8-I8 -> 0 | L8: 100 | M8: =+L8*K8 -> 0 | N8: - | P8: =SUM(M8-O8) -> 0 | Q8: 33.89 | R8: =+K8*Q8 -> 0
A9: 5 | B9: 8857125002257 | C9: ชิฟฟ่อนเค้ก 1 ชิ้น | D9: ชิ้น | G9: =E9+F9 -> 0 | H9: 0 | I9: 0 | J9: =+G9-H9-K9-I9 -> 0 | L9: 10 | M9: =+L9*K9 -> 0 | N9: - | P9: =SUM(M9-O9) -> 0 | R9: =+K9*Q9 -> 0
A10: 6 | B10: 8857125002264 | C10: ชิฟฟ่อนเค้กสอดไส้แยม 1 ชิ้น | D10: ชิ้น | G10: =E10+F10 -> 0 | H10: 0 | I10: 0 | J10: =+G10-H10-K10-I10 -> 0 | L10: 15 | M10: =+L10*K10 -> 0 | N10: - | P10: =SUM(M10-O10) -> 0 | R10: =+K10*Q10 -> 0
A11: 7 | B11: 8857125001830 | C11: ชิฟฟ่อนเค้กสอดไส้ รวมรส (3 ชิ้น) | D11: กล่อง | F11: 20 | G11: =E11+F11 -> 20 | H11: 0 | I11: 0 | J11: =+G11-H11-K11-I11 -> 15 | K11: 5 | L11: 50 | M11: =+L11*K11 -> 250 | N11: - | P11: =SUM(M11-O11) -> 250 | Q11: 16.94 | R11: =+K11*Q11 -> 84.7
A12: 8 | B12: 1112539 | C12: ชิฟฟ่อนเค้กสอดไส้ เมล่อน (3 ชิ้น) | D12: กล่อง | G12: =E12+F12 -> 0 | H12: 0 | I12: 0 | J12: =+G12-H12-K12-I12 -> 0 | L12: 50 | M12: =+L12*K12 -> 0 | N12: - | P12: =SUM(M12-O12) -> 0 | R12: =+K12*Q12 -> 0
A13: 9 | B13: 8857125000055 | C13: ชิฟฟ่อนเค้กสอดไส้แยม รสบลูเบอร์รี่ (3 ชิ้น) | D13: กล่อง | G13: =E13+F13 -> 0 | H13: 0 | I13: 0 | J13: =+G13-H13-K13-I13 -> 0 | L13: 50 | M13: =+L13*K13 -> 0 | N13: - | P13: =SUM(M13-O13) -> 0 | Q13: 17.32 | R13: =+K13*Q13 -> 0
A14: 10 | B14: 8857125000987 | C14: ชิฟฟ่อนเค้กสอดไส้แยม รสส้ม (3 ชิ้น) | D14: กล่อง | G14: =E14+F14 -> 0 | H14: 0 | I14: 0 | J14: =+G14-H14-K14-I14 -> 0 | L14: 50 | M14: =+L14*K14 -> 0 | N14: - | P14: =SUM(M14-O14) -> 0 | Q14: 21.22 | R14: =+K14*Q14 -> 0
A15: 11 | B15: 8857125000246 | C15: ชิฟฟ่อนเค้กหน้าฝอยทอง สอดไส้แยมส้ม (3 ชิ้น) | D15: กล่อง | G15: =E15+F15 -> 0 | H15: 0 | I15: 0 | J15: =+G15-H15-K15-I15 -> 0 | L15: 50 | M15: =+L15*K15 -> 0 | N15: - | P15: =SUM(M15-O15) -> 0 | Q15: 24.37 | R15: =+K15*Q15 -> 0
A16: 12 | C16: ชิฟฟ่อนเค้กหน้าฝอยทองทูโทน สอดไส้แยมส้ม (3 ชิ้น) | D16: กล่อง | G16: =E16+F16 -> 0 | H16: 0 | I16: 0 | J16: =+G16-H16-K16-I16 -> 0 | L16: 50 | M16: =+L16*K16 -> 0 | N16: - | P16: =SUM(M16-O16) -> 0 | R16: =+K16*Q16 -> 0
A17: 13 | B17: 8857125000024 | C17: ชิฟฟ่อนเค้กสอดไส้แยม รสสตรอว์เบอรี่ (3 ชิ้น) | D17: กล่อง | G17: =E17+F17 -> 0 | H17: 0 | I17: 0 | J17: =+G17-H17-K17-I17 -> 0 | L17: 50 | M17: =+L17*K17 -> 0 | N17: - | P17: =SUM(M17-O17) -> 0 | Q17: 15.05 | R17: =+K17*Q17 -> 0
A18: 14 | B18: 8857125000086 | C18: ชิฟฟ่อนเค้กสอดไส้ เนยมะพร้าว (3 ชิ้น) | D18: กล่อง | G18: =E18+F18 -> 0 | H18: 0 | I18: 0 | J18: =+G18-H18-K18-I18 -> 0 | L18: 50 | M18: =+L18*K18 -> 0 | N18: - | P18: =SUM(M18-O18) -> 0 | Q18: 18.77 | R18: =+K18*Q18 -> 0
A19: 15 | B19: 8857125000239 | C19: ชิฟฟ่อนเค้กสอดไส้ นมชมพูฮอกไกโด (3 ชิ้น) | D19: กล่อง | G19: =E19+F19 -> 0 | H19: 0 | I19: 0 | J19: =+G19-H19-K19-I19 -> 0 | L19: 50 | M19: =+L19*K19 -> 0 | N19: - | P19: =SUM(M19-O19) -> 0 | Q19: 19.04 | R19: =+K19*Q19 -> 0
A20: 16 | B20: 8857125001816 | C20: ชิฟฟ่อน สอดไส้ (ล) 4 ชิ้น ครีมมะพร้าว | D20: กล่อง | F20: 5 | G20: =E20+F20 -> 5 | H20: 0 | I20: 0 | J20: =+G20-H20-K20-I20 -> 4 | K20: 1 | L20: 65 | M20: =+L20*K20 -> 65 | N20: - | P20: =SUM(M20-O20) -> 65 | Q20: 22.25 | R20: =+K20*Q20 -> 22.25
A21: 17 | B21: 8857125001021 | C21: ชิฟฟ่อน สอดไส้ (ก) 5 ชิ้น ครีมมะพร้าว | D21: กล่อง | F21: 5 | G21: =E21+F21 -> 5 | H21: 0 | I21: 0 | J21: =+G21-H21-K21-I21 -> 4 | K21: 1 | L21: 85 | M21: =+L21*K21 -> 85 | N21: - | P21: =SUM(M21-O21) -> 85 | Q21: 22.85 | R21: =+K21*Q21 -> 22.85
A22: 18 | B22: 8857125000956 | C22: ชิฟฟ่อนเค้กสอดไส้ รวมรส (6 ชิ้น) | D22: กล่อง | F22: 50 | G22: =E22+F22 -> 50 | H22: 0 | I22: 0 | J22: =+G22-H22-K22-I22 -> 46 | K22: 4 | L22: 100 | M22: =+L22*K22 -> 400 | N22: - | P22: =SUM(M22-O22) -> 400 | Q22: 26.6 | R22: =+K22*Q22 -> 106.4
A23: 19 | B23: 8857125000918 | C23: ชิฟฟ่อนเค้กสอดไส้แยม รสส้ม (6 ชิ้น) | D23: กล่อง | G23: =E23+F23 -> 0 | H23: 0 | I23: 0 | J23: =+G23-H23-K23-I23 -> 0 | L23: 100 | M23: =+L23*K23 -> 0 | N23: - | P23: =SUM(M23-O23) -> 0 | Q23: 42.24 | R23: =+K23*Q23 -> 0
A24: 20 | B24: 8857125000970 | C24: ชิฟฟ่อนเค้กหน้าฝอยทอง สอดไส้แยมส้ม (6 ชิ้น) | D24: กล่อง | G24: =E24+F24 -> 0 | H24: 0 | I24: 0 | J24: =+G24-H24-K24-I24 -> 0 | L24: 100 | M24: =+L24*K24 -> 0 | N24: - | P24: =SUM(M24-O24) -> 0 | Q24: 40.51 | R24: =+K24*Q24 -> 0
A25: 21 | B25: 8857125003810 | C25: ชิฟฟ่อนเค้กหน้าฝอยทองทูโทน สอดไส้แยมส้ม (6 ชิ้น) | D25: กล่อง | G25: =E25+F25 -> 0 | H25: 0 | I25: 0 | J25: =+G25-H25-K25-I25 -> 0 | L25: 100 | M25: =+L25*K25 -> 0 | N25: - | P25: =SUM(M25-O25) -> 0 | Q25: 39.77 | R25: =+K25*Q25 -> 0
A26: 22 | B26: 8857125000963 | C26: ชิฟฟ่อนเค้กสอดไส้ นมชมพูฮอกไกโด (6 ชิ้น) | D26: กล่อง | G26: =E26+F26 -> 0 | H26: 0 | I26: 0 | J26: =+G26-H26-K26-I26 -> 0 | L26: 100 | M26: =+L26*K26 -> 0 | N26: - | P26: =SUM(M26-O26) -> 0 | Q26: 35.39 | R26: =+K26*Q26 -> 0
A27: 23 | B27: 8857125000932 | C27: ชิฟฟ่อนเค้กสอดไส้แยม รสบลูเบอร์รี่ (6 ชิ้น) | D27: กล่อง | G27: =E27+F27 -> 0 | H27: 0 | I27: 0 | J27: =+G27-H27-K27-I27 -> 0 | L27: 100 | M27: =+L27*K27 -> 0 | N27: - | P27: =SUM(M27-O27) -> 0 | Q27: 31.62 | R27: =+K27*Q27 -> 0
A28: 24 | B28: 8857125000895 | C28: ชิฟฟ่อนเค้กสอดไส้ เนยมะพร้าว (6 ชิ้น) | D28: กล่อง | G28: =E28+F28 -> 0 | H28: 0 | I28: 0 | J28: =+G28-H28-K28-I28 -> 0 | L28: 100 | M28: =+L28*K28 -> 0 | N28: - | P28: =SUM(M28-O28) -> 0 | Q28: 31.97 | R28: =+K28*Q28 -> 0
A29: 25 | B29: 8857125000901 | C29: ชิฟฟ่อนเค้กสอดไส้แยม รสสตรอว์เบอรี่ (6 ชิ้น) | D29: กล่อง | G29: =E29+F29 -> 0 | H29: 0 | I29: 0 | J29: =+G29-H29-K29-I29 -> 0 | L29: 100 | M29: =+L29*K29 -> 0 | N29: - | P29: =SUM(M29-O29) -> 0 | Q29: 21.27 | R29: =+K29*Q29 -> 0
A30: 26 | B30: 8857125001571 | C30: ชิฟฟอนเค้ก รสมะลิ 8ชิ้น (ห่อซีน) | D30: กล่อง | G30: =E30+F30 -> 0 | H30: 0 | I30: 0 | J30: =+G30-H30-K30-I30 -> 0 | L30: 100 | M30: =+L30*K30 -> 0 | N30: - | P30: =SUM(M30-O30) -> 0 | Q30: 34.26 | R30: =+K30*Q30 -> 0
A31: 27 | B31: 8857125002127 | C31: ชิฟฟ่อนรวมรส ยอดฮิต (8 ชิ้น) | D31: กล่อง | F31: 20 | G31: =E31+F31 -> 20 | H31: 0 | I31: 0 | J31: =+G31-H31-K31-I31 -> 16 | K31: 4 | L31: 100 | M31: =+L31*K31 -> 400 | N31: - | P31: =SUM(M31-O31) -> 400 | Q31: 38.46 | R31: =+K31*Q31 -> 153.84
A32: 28 | B32: 8857125000130 | C32: ชิฟฟ่อนเค้ก วรรณวนัช (สอดไส้รวมรส 8 ชิ้น) | D32: กล่อง | F32: 2 | G32: =E32+F32 -> 2 | H32: 0 | I32: 0 | J32: =+G32-H32-K32-I32 -> 2 | L32: 130 | M32: =+L32*K32 -> 0 | N32: - | P32: =SUM(M32-O32) -> 0 | Q32: 46.37 | R32: =+K32*Q32 -> 0
A33: 29 | B33: 8857125003773 | C33: ชิฟฟ่อนเค้กมะพร้าวสอดไส้ครีมมะพร้าวล้วน (8 ชิ้น) | D33: กล่อง | F33: 10 | G33: =E33+F33 -> 10 | H33: 0 | I33: 0 | J33: =+G33-H33-K33-I33 -> 10 | L33: 130 | M33: =+L33*K33 -> 0 | N33: - | P33: =SUM(M33-O33) -> 0 | Q33: 38.9 | R33: =+K33*Q33 -> 0
A34: 30 | B34: 8857125001366 | C34: ชิฟฟ่อนเค้กใบเตยสอดไส้ครีมมะพร้าวล้วน (8 ชิ้น) | D34: กล่อง | G34: =E34+F34 -> 0 | H34: 0 | I34: 0 | J34: =+G34-H34-K34-I34 -> 0 | L34: 130 | M34: =+L34*K34 -> 0 | N34: - | P34: =SUM(M34-O34) -> 0 | Q34: 38.07 | R34: =+K34*Q34 -> 0
A35: 31 | B35: 8857125001397 | C35: ชิฟฟ่อนเค้กใบเตยทูโทนและสอดไส้ครีมมะพร้าว (8 ชิ้น) | D35: กล่อง | G35: =E35+F35 -> 0 | H35: 0 | I35: 0 | J35: =+G35-H35-K35-I35 -> 0 | L35: 130 | M35: =+L35*K35 -> 0 | N35: - | P35: =SUM(M35-O35) -> 0 | Q35: 40.8 | R35: =+K35*Q35 -> 0
A36: 32 | B36: 885712004534 | C36: ชิฟฟ่อนเค้กสอดไส้ครีมมะพร้าว 120g. | D36: ชิ้น | G36: =E36+F36 -> 0 | H36: 0 | I36: 0 | J36: =+G36-H36-K36-I36 -> 0 | L36: 35 | M36: =+L36*K36 -> 0 | N36: - | P36: =SUM(M36-O36) -> 0 | R36: =+K36*Q36 -> 0
A37: 33 | B37: 20055119 | C37: ชิฟฟ่อนเค้กฝอยทอง 95g. | D37: กล่อง | G37: =E37+F37 -> 0 | H37: 0 | I37: 0 | J37: =+G37-H37-K37-I37 -> 0 | L37: 35 | M37: =+L37*K37 -> 0 | N37: - | P37: =SUM(M37-O37) -> 0 | R37: =+K37*Q37 -> 0
A38: 34 | B38: 8857125001267 | C38: ชิฟฟ่อนหม้อแกง | D38: กล่อง | G38: =E38+F38 -> 0 | H38: 0 | I38: 0 | J38: =+G38-H38-K38-I38 -> 0 | L38: 35 | M38: =+L38*K38 -> 0 | N38: - | P38: =SUM(M38-O38) -> 0 | Q38: 30.43 | R38: =+K38*Q38 -> 0
A39: 35 | B39: 8857125000611 | C39: ครีมฮอร์น วนิลา | D39: กล่อง | F39: 20 | G39: =E39+F39 -> 20 | H39: 0 | I39: 0 | J39: =+G39-H39-K39-I39 -> 16 | K39: 4 | L39: 50 | M39: =+L39*K39 -> 200 | N39: - | P39: =SUM(M39-O39) -> 200 | Q39: 27.84 | R39: =+K39*Q39 -> 111.36
A40: 36 | B40: 8857125000604 | C40: ครีมฮอร์น ใบเตย | D40: กล่อง | F40: 15 | G40: =E40+F40 -> 15 | H40: 0 | I40: 0 | J40: =+G40-H40-K40-I40 -> 13 | K40: 2 | L40: 50 | M40: =+L40*K40 -> 100 | N40: - | P40: =SUM(M40-O40) -> 100 | Q40: 27.12 | R40: =+K40*Q40 -> 54.24
A41: 37 | B41: 8857125000598 | C41: ครีมฮอร์น ช็อคโกแลต | D41: กล่อง | F41: 15 | G41: =E41+F41 -> 15 | H41: 0 | I41: 0 | J41: =+G41-H41-K41-I41 -> 14 | K41: 1 | L41: 50 | M41: =+L41*K41 -> 50 | N41: - | P41: =SUM(M41-O41) -> 50 | Q41: 15.42 | R41: =+K41*Q41 -> 15.42
...

Sheet 1
A2: บูธ EVENT งานเกษตรแฟร์กำแพงแสน 30 พ.ย. 67 - 10 ธ.ค. 67
A3: ลำดับ | B3: รหัสสินค้า (POS) | C3: รายการ | D3: หน่วย | E3: ยกมา | F3: รับ | G3: รวม | H3: เปลี่ยน/ | I3: โยกย้าย / ระบาย | J3: คงเหลือ | K3: รายการขาย | N3: หมายเหตุ | O3: ส่วนลด | Q3: ราคาต้นทุน | R3: ยอดรวมต้นทุนสินค้า
