Workbook

Sheet สรุป
A1: สรุปรายการของตีกลับของช่องทางออนไลน์ เดือนกรกฎาคม 2567
A2: แพลตฟอร์ม | B2: สาเหตุการตีกลับ | L2: รวม | M2: ยอดเงิน
B3: ปฏิเสธ , ยกเลิก | D3: ติดต่อไม่ได้ , ไม่รับโทรศัพท์ | F3: ส่งของไปซ้ำ | H3: เกินเวลานัดส่งพัสดุ | J3: ลูกค้าตีกลับ เนื่องจาก มดขึ้นขนม ขนมมีรสฟาดเฟื่อน
B4: จำนวนออเดอร์ | C4: ยอดขาย | D4: จำนวนออเดอร์ | E4: ยอดขาย | F4: จำนวนออเดอร์ | G4: ยอดขาย | H4: จำนวนออเดอร์ | I4: ยอดขาย | J4: จำนวนออเดอร์ | K4: ยอดขาย
A5: Lazada | B5: 6 | C5: 669.19 | D5: 1 | E5: 129.35 | F5: 1 | G5: 95.97 | H5: 0 | I5: 0 | J5: 0 | K5: 0 | L5: =+B5+D5+F5+H5+J5 -> 8 | M5: =+C5+E5+G5+I5+K5 -> 894.51
A6: Shopee | B6: 9 | C6: 1745 | D6: 1 | E6: 39 | F6: 0 | G6: 0 | H6: 0 | I6: 0 | J6: 0 | K6: 0 | L6: =+B6+D6+F6+H6+J6 -> 10 | M6: =+C6+E6+G6+I6+K6 -> 1784
A7: TikTok | B7: 106 | C7: 19011 | D7: 6 | E7: 950 | F7: 0 | G7: 0 | H7: 4 | I7: 1302 | J7: 0 | K7: 0 | L7: =+B7+D7+F7+H7+J7 -> 116 | M7: =+C7+E7+G7+I7+K7 -> 21263
A8: Facebook , Facebook Live , Line , Line OA (ไปรษณีย์) | B8: 16 | C8: 2868 | D8: 22 | E8: 4024 | F8: 5 | G8: 1000 | H8: 0 | I8: 0 | J8: 0 | K8: 0 | L8: =+B8+D8+F8+H8+J8 -> 43 | M8: =+C8+E8+G8+I8+K8 -> 7892
A9: ยอมรวมทั้งหมด | B9: =SUM(B5:B8) -> 137 | C9: =SUM(C5:C8) -> 24293.19 | D9: =SUM(D5:D8) -> 30 | E9: =SUM(E5:E8) -> 5142.35 | F9: =SUM(F5:F8) -> 6 | G9: =SUM(G5:G8) -> 1095.97 | H9: =SUM(H5:H8) -> 4 | I9: =SUM(I5:I8) -> 1302 | ... M9: =SUM(M5:M8) -> 31833.51 | N9: บาท

Sheet สรุปรายการสินค้า
A1: สรุปรายการสินค้าที่ตีกลับมารวมทุกช่องทางขายออนไลน์ เดือนกรกฎาคม 2567
A2: ลำดับ | B2: รายการ | C2: จำนวน | D2: หมายเหตุ
A3: 1 | B3: ชิฟฟอนแยกชิ้น | C3: =+รายการสินค้าตีกลับ!B35 -> 246
A4: 2 | B4: ชิฟฟอน 8 ชิ้น | C4: =+รายการสินค้าตีกลับ!C35 -> 13
A5: 3 | B5: ชิฟฟอน 4 ชิ้น | C5: =+รายการสินค้าตีกลับ!D35 -> 134
A6: 4 | B6: ชิฟฟอนไส้แยม 6 ชิ้น | C6: =+รายการสินค้าตีกลับ!E35 -> 2
A7: 5 | B7: ชิฟฟอนไส้แยม 3 ชิ้น | C7: =+รายการสินค้าตีกลับ!F35 -> 222
A8: 6 | B8: เบาหวิว ล | C8: =+รายการสินค้าตีกลับ!G35 -> 123
A9: 7 | B9: เบาหวิว ญ | C9: =+รายการสินค้าตีกลับ!H35 -> 0
A10: 8 | B10: เปี๊ยะ ล | C10: =+รายการสินค้าตีกลับ!I35 -> 35
A11: 9 | B11: เปี๊ยะโมจิ ล | C11: =+รายการสินค้าตีกลับ!J35 -> 0
A12: 10 | B12: เปี๊ยะ ญ | C12: =+รายการสินค้าตีกลับ!K35 -> 0
A13: 11 | B13: เปี๊ยะโมจิ ญ | C13: =+รายการสินค้าตีกลับ!L35 -> 0
A14: 12 | B14: พายสัปปะรด | C14: =+รายการสินค้าตีกลับ!M35 -> 0
A15: 13 | B15: คุกกี้เนย | C15: =+รายการสินค้าตีกลับ!N35 -> 1
A16: 14 | B16: คุกกี้เนย 4 ชิ้น/กล่อง | C16: =+รายการสินค้าตีกลับ!O35 -> 0
A17: 15 | B17: ปังกรอบคาราเมล | C17: =+รายการสินค้าตีกลับ!P35 -> 0
A18: 16 | B18: ปังเนยน้ำตาล | C18: =+รายการสินค้าตีกลับ!Q35 -> 6
A19: 17 | B19: ปังเนยนิ่ม กล่อง 2 ชิ้น | C19: =+รายการสินค้าตีกลับ!R35 -> 0
A20: 18 | B20: ปังเนยนิ่ม กล่อง 3 ชิ้น | C20: =+รายการสินค้าตีกลับ!S35 -> 0
A21: 19 | B21: ปังเนยนิ่มถุง5ชิ้น | C21: =+รายการสินค้าตีกลับ!T35 -> 0
A22: 20 | B22: ปังสตรอบูล | C22: =+รายการสินค้าตีกลับ!U35 -> 0
A23: 21 | B23: ปังไก่หยอง | C23: =+รายการสินค้าตีกลับ!V35 -> 0
A24: 22 | B24: ปังทวิต | C24: =+รายการสินค้าตีกลับ!W35 -> 0
A25: 23 | B25: ปังแถว | C25: =+รายการสินค้าตีกลับ!Y35 -> 27
A26: 24 | B26: เปี๊ยะลาวา | C26: =+รายการสินค้าตีกลับ!Z35 -> 0
A27: 25 | B27: คอนเฟล็ก | C27: =+รายการสินค้าตีกลับ!AA35 -> 1
A28: 26 | B28: ไดฟูกุ | C28: =+รายการสินค้าตีกลับ!AB35 -> 0
A29: 27 | B29: ปังเลเยอร์ | C29: =+รายการสินค้าตีกลับ!AC35 -> 0
A30: 28 | B30: เมอแรงค์ | C30: =+รายการสินค้าตีกลับ!AD35 -> 1
A31: 29 | B31: ท๊อฟฟี่ถั่ว กล่อง | C31: =+รายการสินค้าตีกลับ!AE35 -> 8
A32: 30 | B32: ครีมฮอนร์จัมโบ้ | C32: =+รายการสินค้าตีกลับ!AF35 -> 0
A33: 31 | B33: ครีมฮอร์น | C33: =+รายการสินค้าตีกลับ!AG35 -> 177
B34: ยอดรวม | C34: =SUM(C3:C33) -> 996 | D34: ชิ้น

Sheet Lazada
A1: รายการของตีกลับช่องทาง LAZADA เดือนกรกฏาคม 2567
A2: ลำดับ | B2: วันที่ตีกลับ | C2: เลขที่ออเดอร์ | D2: เลขที่พัสดุ | E2: ผู้ให้บริการจัดส่ง | F2: ร้านค้า | G2: ชื่อลูกค้า | I2: ยอดคำสั่งซื้อ | J2: สาเหตุการตีกลับ | K2: หมายเหตุ | N2: หัวข้อการสาเหตุตีของกลับ | O2: ชื่อร้าน | P2: ชื่อขนส่ง
G3: ชื่อ
A4: 1 | B4: 243803 | C4: 875611899840058 | D4: LEXPU0360463897 | E4: LEX TH | F4: วรรณวนัช เบเกอรี่ (ร้านที่ 1 ร้านหลัก) | G4: น้องบลู | I4: 129.35 | J4: ติดต่อไม่ได้ , ไม่รับโทรศัพท์ | N4: ปฏิเสธ , ยกเลิก | O4: วรรณวนัช เบเกอรี่ (ร้านที่ 1 ร้านหลัก) | P4: LEX TH
A5: 2 | B5: 243810 | C5: 879534670380417 | D5: LEXPU0364250441 | E5: LEX TH | F5: วรรณวนัช เบเกอรี่ (ร้านที่ 1 ร้านหลัก) | I5: 67.4 | J5: ปฏิเสธ , ยกเลิก | N5: ติดต่อไม่ได้ , ไม่รับโทรศัพท์ | O5: ของฝากวรรณวนัช (cakewanwanach.lzd) | P5: Flash Express Thailand
A6: 3 | B6: 243817 | C6: 881533611352471 | D6: LEXPU0366636162 | E6: LEX TH | F6: วรรณวนัช เบเกอรี่ (ร้านที่ 1 ร้านหลัก) | G6: อนวรรษ | H6: บุญยะรัตศิริ | I6: 95.97 | J6: ส่งของไปซ้ำ | N6: ส่งของไปซ้ำ | O6: วรรณวนัช ชิฟฟ่อน (chiffonlazada) | P6: Kerry_dropoff
A7: 4 | B7: 243820 | C7: 884230021964901 | D7: TH52015W95FA2B | E7: LEX TH | F7: วรรณวนัช เบเกอรี่ (ร้านที่ 1 ร้านหลัก) | G7: ชัยเลิศ | H7: สุขสันต์อนันต์ | I7: 207.08 | J7: ปฏิเสธ , ยกเลิก | N7: ลูกค้าแจ้งว่าไม่ได้สั่ง | O7: วรรณวนัช (0944831646)
A8: 5 | B8: 243821 | C8: 890038153708951 | D8: LEXDO0107131394 | E8: LEX TH | F8: วรรณวนัช เบเกอรี่ (ร้านที่ 1 ร้านหลัก) | G8: นันท์ภัส | H8: พานทอง | I8: 27.52 | J8: ปฏิเสธ , ยกเลิก | O8: ชิฟฟ่อน กำแพงแสน (chiffonk.kps)
A9: 6 | B9: 243821 | C9: 890041722520160 | D9: LEXDO0107131160 | E9: LEX TH | F9: วรรณวนัช เบเกอรี่ (ร้านที่ 1 ร้านหลัก) | G9: นันท์ภัส | H9: พานทอง | I9: 27.09 | J9: ปฏิเสธ , ยกเลิก | O9: วรรณวนัช ของอร่อย (cakewanwanach.kps)
A10: 7 | B10: 243822 | C10: 889509325725584 | D10: KERPU0104320550 | E10: LEX TH | F10: วรรณวนัช เบเกอรี่ (ร้านที่ 1 ร้านหลัก) | G10: น.ส.สาวิตรี | H10: หลอมทอง | I10: 180 | J10: ปฏิเสธ , ยกเลิก | O10: ของฝาก นครปฐม (khongfhak.kps)
A11: 8 | B11: 243828 | C11: 890962162816001 | D11: KERDO0130702075 | E11: LEX TH | F11: วรรณวนัช เบเกอรี่ (ร้านที่ 1 ร้านหลัก) | G11: นิรุตร์ | H11: แก้วสิทธิ์ | I11: 190.1 | J11: ปฏิเสธ , ยกเลิก | O11: วรรณวนัช ไทยแลนด์ (chiffon.kps)
H12: รวม | I12: =SUM(I4:I11) -> 924.51 | J12: บาท | O12: ของอร่อยกำแพงแสน (kahnomcake.lzd)
O13: ชิฟฟ่อน เบเกอรี่ (wanwanachcake)

Sheet Shopee
A1: รายการของตีกลับช่องทาง SHOPEE เดือนกรกฏาคม 2567
A2: ลำดับ | B2: วันที่ตีกลับ | C2: เลขที่ออเดอร์ | D2: เลขที่พัสดุ | E2: ผู้ให้บริการจัดส่ง | F2: ร้านค้า | G2: ชื่อลูกค้า | I2: ยอดคำสั่งซื้อ | J2: สาเหตุการตีกลับ | K2: หมายเหตุ | M2: หัวข้อการสาเหตุตีของกลับ | N2: ชื่อร้าน | O2: ชื่อขนส่ง
G3: ชื่อ | H3: นามสกุล
A4: 1 | B4: 243808 | C4: 240625VBHK329S | D4: TH241156683069M | E4: SPX Express | F4: ร้านที่ 1 | I4: 39 | J4: ติดต่อไม่ได้ , ไม่รับโทรศัพท์ | M4: ปฏิเสธ , ยกเลิก | N4: ร้านที่ 1 | O4: LEX TH
A5: 2 | B5: 243808 | C5: 240704NU5XFDFK | D5: TH248794780774S | E5: SPX Express | F5: ร้านที่ 1 | I5: 260 | J5: ปฏิเสธ , ยกเลิก | M5: ติดต่อไม่ได้ , ไม่รับโทรศัพท์ | N5: ร้านที่ 2 | O5: Flash Express Thailand
A6: 3 | B6: 243808 | C6: 240630CPV75XMJ | D6: TH240898013014E | E6: SPX Express | F6: ร้านที่ 1 | I6: 255 | J6: ปฏิเสธ , ยกเลิก | M6: ส่งของไปซ้ำ | O6: Kerry_dropoff
A7: 4 | B7: 243820 | C7: 240624TYN80NF9 | D7: TH240845741180N | E7: SPX Express | F7: ร้านที่ 2 | I7: 150 | J7: ปฏิเสธ , ยกเลิก | M7: ลูกค้าแจ้งว่าไม่ได้สั่ง | O7: J&T
A8: 5 | B8: 243820 | C8: 240625UXS30T4K | D8: TH248591581856X | E8: SPX Express | F8: ร้านที่ 1 | I8: 117 | J8: ปฏิเสธ , ยกเลิก | O8: SPX Express
A9: 6 | B9: 243820 | C9: 240712DKRGEM0U | D9: TH2476588077808 | E9: SPX Express | F9: ร้านที่ 1 | I9: 33 | J9: ปฏิเสธ , ยกเลิก
A10: 7 | B10: 243820 | C10: 2407108CRUR65R | D10: TH247940875563W | E10: SPX Express | F10: ร้านที่ 1 | I10: 50 | J10: ปฏิเสธ , ยกเลิก
A11: 8 | B11: 243820 | C11: 2407070VYP82FK | D11: TH241581472370X | E11: SPX Express | F11: ร้านที่ 1 | I11: 420 | J11: ปฏิเสธ , ยกเลิก
A12: 9 | B12: 243820 | C12: 240704P0DKU59A | D12: TH246633326977M | E12: SPX Express | F12: ร้านที่ 1 | I12: 117 | J12: ปฏิเสธ , ยกเลิก
A13: 10 | B13: 243820 | C13: 240703KKGR2G8C | D13: TH244221373371G | E13: SPX Express | F13: ร้านที่ 1 | I13: 343 | J13: ปฏิเสธ , ยกเลิก
A14: 11
A15: 12
A16: 13
H17: รวม | I17: =SUM(I4:I16) -> 1784 | J17: บาท
A18: ** NOTE | B18: ชื่อลูกค้า ไม่มีในข้อมูล Shopee

Sheet TikTok
A1: รายการของตีกลับช่องทาง TikTok เดือนกรกฏาคม 2567
A2: ลำดับ | B2: วันที่ตีกลับ | C2: เลขที่ออเดอร์ | D2: เลขที่พัสดุ | E2: ผู้ให้บริการจัดส่ง | F2: ร้านค้า | G2: ชื่อลูกค้า | I2: ยอดคำสั่งซื้อ | J2: สาเหตุการตีกลับ | K2: หมายเหตุ | M2: หัวข้อการสาเหตุตีของกลับ | N2: ชื่อร้าน | O2: ชื่อขนส่ง
G3: ชื่อ | H3: นามสกุล
A4: 1 | B4: 243800 | C4: 578973508848486569 | D4: THT660810ATTU7Z | E4: Flash Express Thailand | F4: วรรณวนัชเบเกอรี่ (พี่กุ๊ก) | I4: 50 | J4: ปฏิเสธ , ยกเลิก | M4: ปฏิเสธ , ยกเลิก | N4: วรรณวนัชเบเกอรี่ (พี่กุ๊ก) | O4: LEX TH
A5: 2 | B5: 243800 | C5: 578970563073575438 | D5: THT4301106KB38Z | E5: Flash Express Thailand | F5: วรรณวนัชเบเกอรี่ (พี่กุ๊ก) | I5: 96 | J5: ปฏิเสธ , ยกเลิก | M5: ติดต่อไม่ได้ , ไม่รับโทรศัพท์ | N5: วรรณวนัช เบเกอรี่ (แอม) | O5: Flash Express Thailand
A6: 3 | B6: 243800 | C6: 578870866867226853 | D6: 748156553900 | E6: J&T Express | F6: วรรณวนัชเบเกอรี่ (พี่กุ๊ก) | I6: 50 | J6: ปฏิเสธ , ยกเลิก | M6: ส่งของไปซ้ำ | N6: วรรณวนัช โรงงานจำหน่ายโดยตรง (นุ่น) | O6: Kerry_dropoff
A7: 4 | B7: 243803 | C7: 578986786482391477 | D7: 750369113410 | E7: J&T Express | F7: วรรณวนัชเบเกอรี่ (พี่กุ๊ก) | I7: 218 | J7: ปฏิเสธ , ยกเลิก | M7: ลูกค้าแจ้งว่าไม่ได้สั่ง | N7: ของฝากวรรณวนัช By:แอดอั้ม (อั้ม) | O7: J&T Express
A8: 5 | B8: 243803 | C8: 578966286533888653 | D8: 750286345535 | E8: J&T Express | F8: วรรณวนัชเบเกอรี่ (พี่กุ๊ก) | I8: 156 | J8: ติดต่อไม่ได้ , ไม่รับโทรศัพท์ | M8: เกินเวลานัดรับพัสดุ | N8: ชิฟฟ่อนเค้กวรรณวนัช (พี่เอฟ)
A9: 6 | B9: 243803 | C9: 578968088195467990 | D9: 750294354666 | E9: J&T Express | F9: วรรณวนัชเบเกอรี่ (พี่กุ๊ก) | I9: 104 | J9: ปฏิเสธ , ยกเลิก
A10: 7 | B10: 243803 | C10: 578970489290983667 | D10: 750282219713 | E10: J&T Express | F10: วรรณวนัชเบเกอรี่ (พี่กุ๊ก) | I10: 141 | J10: ปฏิเสธ , ยกเลิก | L10: 579009115947895127
A11: 8 | B11: 243803 | C11: 578977783223257396 | D11: 750338731122 | E11: J&T Express | F11: วรรณวนัชเบเกอรี่ (พี่กุ๊ก) | I11: 120 | J11: ปฏิเสธ , ยกเลิก
A12: 9 | B12: 243803 | C12: 578971554420263569 | D12: 750263143722 | E12: J&T Express | F12: วรรณวนัชเบเกอรี่ (พี่กุ๊ก) | I12: 270 | J12: ปฏิเสธ , ยกเลิก
A13: 10 | B13: 243803 | C13: 578966289206381197 | D13: 750242680692 | E13: J&T Express | F13: วรรณวนัชเบเกอรี่ (พี่กุ๊ก) | I13: 244 | J13: ปฏิเสธ , ยกเลิก
A14: 11 | B14: 243803 | C14: 578977220174187238 | D14: 750369548235 | E14: J&T Express | F14: วรรณวนัชเบเกอรี่ (พี่กุ๊ก) | I14: 606 | J14: เกินเวลานัดรับพัสดุ
A15: 12 | B15: 243808 | C15: 579013318290934063 | D15: THT58011144Q50Z | E15: Flash Express Thailand | F15: วรรณวนัชเบเกอรี่ (พี่กุ๊ก) | I15: 148 | J15: ปฏิเสธ , ยกเลิก
A16: 13 | B16: 243808 | C16: 578994762989733980 | D16: 750376120712 | E16: J&T Express | F16: วรรณวนัชเบเกอรี่ (พี่กุ๊ก) | I16: 106 | J16: ปฏิเสธ , ยกเลิก
A17: 14 | B17: 243808 | C17: 578988043874175953 | D17: 750308704493 | E17: J&T Express | F17: วรรณวนัชเบเกอรี่ (พี่กุ๊ก) | I17: 270 | J17: ปฏิเสธ , ยกเลิก
A18: 15 | B18: 243808 | C18: 579009115947895127 | D18: THT0203110ZF07Z | E18: Flash Express Thailand | F18: วรรณวนัชเบเกอรี่ (พี่กุ๊ก) | I18: 145 | J18: ปฏิเสธ , ยกเลิก
A19: 16 | B19: 243808 | C19: 579032023087352581 | D19: THT150111DK8E6Z | E19: Flash Express Thailand | F19: วรรณวนัชเบเกอรี่ (พี่กุ๊ก) | I19: 200 | J19: ปฏิเสธ , ยกเลิก | L19: 579029981754657204
A20: 17 | B20: 243808 | C20: 579029557417904577 | D20: 750587131291 | E20: J&T Express | F20: วรรณวนัชเบเกอรี่ (พี่กุ๊ก) | I20: 86 | J20: ปฏิเสธ , ยกเลิก
A21: 18 | B21: 243808 | C21: 578994466392213644 | D21: 750386419786 | E21: J&T Express | F21: วรรณวนัชเบเกอรี่ (พี่กุ๊ก) | I21: 145 | J21: ปฏิเสธ , ยกเลิก
A22: 19 | B22: 243808 | C22: 578882580269140047 | D22: 748203006611 | E22: J&T Express | F22: วรรณวนัชเบเกอรี่ (พี่กุ๊ก) | I22: 106 | J22: ปฏิเสธ , ยกเลิก
A23: 20 | B23: 243808 | C23: 579029981754657204 | D23: THT440111DJJP3Z | E23: Flash Express Thailand | F23: วรรณวนัชเบเกอรี่ (พี่กุ๊ก) | I23: 210 | J23: ปฏิเสธ , ยกเลิก
A24: 21 | B24: 243808 | C24: 579011746136754193 | D24: 750437015440 | E24: J&T Express | F24: วรรณวนัชเบเกอรี่ (พี่กุ๊ก) | I24: 106 | J24: ปฏิเสธ , ยกเลิก
A25: 22 | B25: 243808 | C25: 579022555292338897 | D25: THT301111BBT37Z | E25: Flash Express Thailand | F25: วรรณวนัชเบเกอรี่ (พี่กุ๊ก) | I25: 236 | J25: ติดต่อไม่ได้ , ไม่รับโทรศัพท์
A26: 23 | B26: 243808 | C26: 579022555292338897 | D26: THT301111BBT37Z | E26: Flash Express Thailand | F26: วรรณวนัชเบเกอรี่ (พี่กุ๊ก) | I26: 236 | J26: ปฏิเสธ , ยกเลิก
A27: 24 | B27: 243810 | C27: 579027574865037773 | D27: 750541317120 | E27: J&T Express | F27: วรรณวนัชเบเกอรี่ (พี่กุ๊ก) | I27: 145 | J27: ปฏิเสธ , ยกเลิก
A28: 25 | B28: 243810 | C28: 579011812280535072 | D28: THT0101111AG74Z | E28: Flash Express Thailand | F28: วรรณวนัชเบเกอรี่ (พี่กุ๊ก) | I28: 106 | J28: ปฏิเสธ , ยกเลิก
A29: 26 | B29: 243810 | C29: 578986027406821393 | D29: 750368407471 | E29: J&T Express | F29: วรรณวนัชเบเกอรี่ (พี่กุ๊ก) | I29: 70 | J29: ปฏิเสธ , ยกเลิก
A30: 27 | B30: 243810 | C30: 579027500310104400 | D30: THT210311DCY16Z | E30: Flash Express Thailand | F30: วรรณวนัชเบเกอรี่ (พี่กุ๊ก) | I30: 106 | J30: ปฏิเสธ , ยกเลิก
A31: 28 | B31: 243810 | C31: 579025254975899742 | D31: 750516190001 | E31: J&T Express | F31: วรรณวนัชเบเกอรี่ (พี่กุ๊ก) | I31: 300 | J31: ปฏิเสธ , ยกเลิก
... A119: 116 | B119: 243828 | C119: 579065535558224686 | D119: THT014311Z0G28Z | E119: Flash Express Thailand | F119: วรรณวนัชเบเกอรี่ (พี่กุ๊ก) | I119: 150 | J119: ปฏิเสธ , ยกเลิก
H120: รวม | I120: =SUM(I4:I119) -> 21263 | J120: บาท
A127: ** NOTE | B127: ชื่อลูกค้า ไม่มีในข้อมูล TikTok

Sheet ไปรษณีย์
A1: รายการของตีกลับช่องทาง Facebook , Facebook Live , Line , Line OA (ไปรษณีย์) เดือนกรกฏาคม 2567
A2: ลำดับ | B2: วันที่ตีกลับ | C2: เลขที่ออเดอร์ | D2: เลขที่พัสดุ | E2: ผู้ให้บริการจัดส่ง | F2: ร้านค้า | G2: ชื่อลูกค้า | I2: ยอดคำสั่งซื้อ | J2: สาเหตุการตีกลับ | K2: หมายเหตุ | M2: หัวข้อการสาเหตุตีของกลับ | N2: ร้านค้า | O2: ชื่อขนส่ง
G3: ชื่อ | H3: นามสกุล
A4: 1 | B4: 1/07/2567 | C4: DBP19 | D4: EA987545706TH | E4: ไปรษณีย์ไทย | F4: Facebook | G4: สุพรรษา | I4: 120 | J4: ปฏิเสธ , ยกเลิก | M4: ปฏิเสธ , ยกเลิก | N4: Facebook | O4: LEX TH
A5: 2 | B5: 1/07/2567 | C5: DDB52 | D5: JA034911071TH | E5: ไปรษณีย์ไทย | F5: Facebook | G5: จันจุรี | H5: เขียวคำปัน | I5: 130 | J5: ปฏิเสธ , ยกเลิก | M5: ติดต่อไม่ได้ , ไม่รับโทรศัพท์ | N5: Facebook Live | O5: Flash Express Thailand
A6: 3 | B6: 1/07/2567 | C6: DBR37 | D6: EA987850952TH | E6: ไปรษณีย์ไทย | F6: Facebook | G6: รจพร | H6: สกนธวุฒิ | I6: 180 | J6: ปฏิเสธ , ยกเลิก | M6: ส่งของไปซ้ำ | N6: Line | O6: Kerry_dropoff
A7: 4 | B7: 1/07/2567 | C7: DBU4 | D7: EA988095963TH | E7: ไปรษณีย์ไทย | F7: Facebook | G7: วิชิต | I7: 229 | J7: ปฏิเสธ , ยกเลิก | M7: ลูกค้าแจ้งว่าไม่ได้สั่ง | N7: Line OA | O7: J&T Express
A8: 5 | B8: 1/07/2567 | C8: DBW34 | D8: EA988104501TH | E8: ไปรษณีย์ไทย | F8: Facebook | G8: อิศราภรณ์ | I8: 210 | J8: ปฏิเสธ , ยกเลิก | M8: ลูกค้าตีกลับ เนื่องจาก มดขึ้นขนม ขนมมีรสฟาดเฟื่อน | N8: Phone | O8: ไปรษณีย์ไทย
A9: 6 | B9: 1/07/2567 | C9: DBU3 | D9: EA988095950TH | E9: ไปรษณีย์ไทย | F9: Facebook | G9: อ้อ | I9: 130 | J9: ปฏิเสธ , ยกเลิก
A10: 7 | B10: 9/07/2567 | C10: DCY70 | D10: JA035454452TH | E10: ไปรษณีย์ไทย | F10: Facebook | G10: ชนิศรณ์ | H10: สทธิประภาพันธ์ | I10: 259 | J10: ปฏิเสธ , ยกเลิก
A11: 8 | B11: 9/07/2567 | C11: DDB52 | D11: JA035864395TH | E11: ไปรษณีย์ไทย | F11: Facebook | G11: ณัฐพร | H11: ศีลาเจริญ | I11: 259 | J11: ติดต่อไม่ได้ , ไม่รับโทรศัพท์
A12: 9 | B12: 14/07/2567 | C12: DCB82 | D12: EA988626193TH | E12: ไปรษณีย์ไทย | F12: Facebook | G12: สุจิตรา | H12: งามละมัย | I12: 165 | J12: ติดต่อไม่ได้ , ไม่รับโทรศัพท์
A13: 10 | B13: 14/07/2567 | C13: DFJ71 | D13: JA038491410TH | E13: ไปรษณีย์ไทย | F13: Facebook | G13: สวรส | H13: ศรีเมฆ | I13: 230 | J13: ส่งของไปซ้ำ
A14: 11 | B14: 15/07/2567 | C14: DFH40 | D14: JA038198912TH | E14: ไปรษณีย์ไทย | F14: Facebook | G14: นพรัตน์ | H14: รจรากูลนาคจู | I14: 180 | J14: ปฏิเสธ , ยกเลิก
A15: 12 | B15: 15/07/2567 | C15: DFO1 | D15: JA038776037TH | E15: ไปรษณีย์ไทย | F15: Facebook | G15: ลัดดา | H15: ขันโท | I15: 130 | J15: ส่งของไปซ้ำ
A16: 13 | B16: 15/07/2567 | C16: DDX82 | D16: JA036772196TH | E16: ไปรษณีย์ไทย | F16: Facebook | G16: ปุรยวีร์ | H16: วรพิพัฒน์ | I16: 280 | J16: ส่งของไปซ้ำ
A17: 14 | B17: 15/07/2567 | C17: DFN62 | D17: JA038491511TH | E17: ไปรษณีย์ไทย | F17: Facebook | G17: อารยา | H17: เลิศไพศาลศิลป์ | I17: 130 | J17: ส่งของไปซ้ำ
A18: 15 | B18: 15/07/2567 | C18: DFJ20 | D18: JA038491397TH | E18: ไปรษณีย์ไทย | F18: Facebook | G18: นันทนิษฎ์ | I18: 230 | J18: ส่งของไปซ้ำ
A19: 16 | B19: 18/07/2567 | C19: DFZ26 | D19: JA039310017TH | E19: ไปรษณีย์ไทย | F19: Facebook | G19: คุณสุทธิภรณ์ | H19: สุขเกษม | I19: 130 | J19: ปฏิเสธ , ยกเลิก
A20: 17 | B20: 18/07/2567 | C20: DFN94 | D20: JB008651775TH | E20: ไปรษณีย์ไทย | F20: Facebook | G20: บ้านน้องไอด้า | H20: แม่วิ | I20: 120 | J20: ปฏิเสธ , ยกเลิก
A21: 18 | B21: 243818 | C21: DGE50 | D21: JA039600986TH | E21: ไปรษณีย์ไทย | F21: Facebook | G21: ณัฐวุฒิ | H21: บุญสวัสดิ์ | I21: 230 | J21: ติดต่อไม่ได้ , ไม่รับโทรศัพท์
A22: 19 | B22: 243821 | C22: CZI2 | D22: EA983714364TH | E22: ไปรษณีย์ไทย | F22: Facebook | G22: ภูวณัฏฐ์ | I22: 130 | J22: ติดต่อไม่ได้ , ไม่รับโทรศัพท์
A23: 20 | B23: 243822 | C23: DGD85 | D23: JA039601142TH | E23: ไปรษณีย์ไทย | F23: Facebook | G23: จุฑารัตน์ | H23: นวลทิม | I23: =IFERROR(VLOOKUP(C23,'ชินิตี้ ก.ค.'!A:L,12,0),"0") -> 230 | J23: ติดต่อไม่ได้ , ไม่รับโทรศัพท์
A24: 21 | B24: 243822 | C24: DHN95 | D24: JA040351552TH | E24: ไปรษณีย์ไทย | F24: Facebook | G24: สมเกียรติ | H24: วิบูลย์วีรรัตน์ | I24: =IFERROR(VLOOKUP(C24,'ชินิตี้ ก.ค.'!A:L,12,0),"0") -> 130 | J24: ติดต่อไม่ได้ , ไม่รับโทรศัพท์
A25: 22 | B25: 243822 | C25: DFN89 | D25: JA038776054TH | E25: ไปรษณีย์ไทย | F25: Facebook | G25: นางปัญญารัตน์ | H25: เตียวิเศษ | I25: =IFERROR(VLOOKUP(C25,'ชินิตี้ ก.ค.'!A:L,12,0),"0") -> 130 | J25: ปฏิเสธ , ยกเลิก
A26: 23 | B26: 243822 | C26: DFV94 | D26: JA039053106TH | E26: ไปรษณีย์ไทย | F26: Facebook | G26: สุพรรษา | H26: อิสรา | I26: =IFERROR(VLOOKUP(C26,'ชินิตี้ ก.ค.'!A:L,12,0),"0") -> 530 | J26: ปฏิเสธ , ยกเลิก
A27: 24 | B27: 243822 | C27: DHD56 | D27: JA040050932TH | E27: ไปรษณีย์ไทย | F27: Facebook | G27: ธาลิณี | H27: กัญญาชาติ | I27: =IFERROR(VLOOKUP(C27,'ชินิตี้ ก.ค.'!A:L,12,0),"0") -> 130 | J27: ปฏิเสธ , ยกเลิก
A28: 25 | B28: 243822 | C28: DFL63 | D28: JA038491542TH | E28: ไปรษณีย์ไทย | F28: Facebook | G28: สุภาพร | H28: แมงทับทอง | I28: =IFERROR(VLOOKUP(C28,'ชินิตี้ ก.ค.'!A:L,12,0),"0") -> 130 | J28: ติดต่อไม่ได้ , ไม่รับโทรศัพท์
A29: 26 | B29: 243822 | C29: DFU99 | D29: JA039054089TH | E29: ไปรษณีย์ไทย | F29: Facebook | G29: เฟิน | I29: =IFERROR(VLOOKUP(C29,'ชินิตี้ ก.ค.'!A:L,12,0),"0") -> 130 | J29: ปฏิเสธ , ยกเลิก
A30: 27 | B30: 243822 | C30: DHX38 | D30: JA041179754TH | E30: ไปรษณีย์ไทย | F30: Facebook | G30: สุรินทร์ | H30: ไพรจิต | I30: =IFERROR(VLOOKUP(C30,'ชินิตี้ ก.ค.'!A:L,12,0),"0") -> 230 | J30: ติดต่อไม่ได้ , ไม่รับโทรศัพท์
A31: 28 | B31: 243822 | C31: DHP43 | D31: JA040639834TH | E31: ไปรษณีย์ไทย | F31: Facebook | G31: คุณเฉิดไฉไล | H31: ฉ่ำใจนาญ | I31: =IFERROR(VLOOKUP(C31,'ชินิตี้ ก.ค.'!A:L,12,0),"0") -> 130 | J31: ติดต่อไม่ได้ , ไม่รับโทรศัพท์
A32: 29 | B32: 243823 | C32: DHX94 | D32: JA041179771TH | E32: ไปรษณีย์ไทย | F32: Facebook | G32: คุณวรรณศิลป์ | H32: ผลดี | I32: =IFERROR(VLOOKUP(C32,'ชินิตี้ ก.ค.'!A:L,12,0),"0") -> 130 | J32: ติดต่อไม่ได้ , ไม่รับโทรศัพท์
A33: 30 | B33: 243823 | C33: DFK90 | D33: JA038491587TH | E33: ไปรษณีย์ไทย | F33: Facebook | G33: อุไรวรรณ | H33: นุชเจิญ | I33: =IFERROR(VLOOKUP(C33,'ชินิตี้ ก.ค.'!A:L,12,0),"0") -> 130 | J33: ติดต่อไม่ได้ , ไม่รับโทรศัพท์
A34: 31 | B34: 243823 | C34: DGA90 | D34: JA039309711TH | E34: ไปรษณีย์ไทย | F34: Facebook | G34: อุไรวรรณ | I34: =IFERROR(VLOOKUP(C34,'ชินิตี้ ก.ค.'!A:L,12,0),"0") -> 330 | J34: ติดต่อไม่ได้ , ไม่รับโทรศัพท์
A35: 32 | B35: 243823 | C35: DHZ21 | D35: JA041180125TH | E35: ไปรษณีย์ไทย | F35: Facebook | G35: ภูวณัฏฐ์ | I35: =IFERROR(VLOOKUP(C35,'ชินิตี้ ก.ค.'!A:L,12,0),"0") -> 130 | J35: ปฏิเสธ , ยกเลิก
A36: 33 | B36: 243825 | C36: DIC22 | D36: JA041390305TH | E36: ไปรษณีย์ไทย | F36: Facebook | G36: พี่เบ็ญ | I36: =IFERROR(VLOOKUP(C36,'ชินิตี้ ก.ค.'!A:L,12,0),"0") -> 130 | J36: ปฏิเสธ , ยกเลิก
A37: 34 | B37: 243825 | C37: DHY41 | D37: JA041179913TH | E37: ไปรษณีย์ไทย | F37: Facebook | G37: ชณิศรณ์ | H37: สทธิประภาพันธ์ | I37: =IFERROR(VLOOKUP(C37,'ชินิตี้ ก.ค.'!A:L,12,0),"0") -> 130 | J37: ติดต่อไม่ได้ , ไม่รับโทรศัพท์
A38: 35 | B38: 243825 | C38: DHU1 | D38: JA040927291TH | E38: ไปรษณีย์ไทย | F38: Facebook | G38: ตุ๊กตา | I38: =IFERROR(VLOOKUP(C38,'ชินิตี้ ก.ค.'!A:L,12,0),"0") -> 130 | J38: ติดต่อไม่ได้ , ไม่รับโทรศัพท์
A39: 36 | B39: 243825 | C39: DHN93 | D39: JA040351566TH | E39: ไปรษณีย์ไทย | F39: Facebook | G39: น.ส.ประไพพร | H39: ข่มอารมณ์ | I39: =IFERROR(VLOOKUP(C39,'ชินิตี้ ก.ค.'!A:L,12,0),"0") -> 130 | J39: ติดต่อไม่ได้ , ไม่รับโทรศัพท์
A40: 37 | B40: 243829 | C40: DIN59 | D40: JA042219401TH | E40: ไปรษณีย์ไทย | F40: Facebook | G40: แหว | H40: ภูมิโคกรักษ์ | I40: =IFERROR(VLOOKUP(C40,'ชินิตี้ ก.ค.'!A:L,12,0),"0") -> 230 | J40: ติดต่อไม่ได้ , ไม่รับโทรศัพท์
...

Sheet รายการสินค้าตีกลับ
A1: รายการสินค้าที่ตีกลับมารวมทุกช่องทางขายออนไลน์ เดือนกรกฎาคม 2567
A2: วันที่ | B2: รายการ | AH2: ยอดรวม/วัน (ทุกรายการ)
B3: ชิฟฟอนแยกชิ้น | C3: ชิฟฟอน 8 ชิ้น | D3: ชิฟฟอน 4 ชิ้น | E3: ชิฟฟอนไส้แยม 6 ชิ้น | F3: ชิฟฟอนไส้แยม 3 ชิ้น | G3: เบาหวิว ล | H3: เบาหวิว ญ | I3: เค้กหวิวถาด | J3: เปี๊ยะ ล | K3: เปี๊ยะโมจิ ล | L3: เปี๊ยะ ญ | M3: เปี๊ยะโมจิ ญ | N3: พายสัปรด | O3: คุกกี้เนย | P3: คุกกี้เนย 4 ชิ้น/กล่อง | Q3: ปังกรอบคาราเมล | R3: ปังเนยน้ำตาล | S3: ปังเนยนิ่ม กล่อง 2 ชิ้น | T3: ปังเนยนิ่ม กล่อง 3 ชิ้น | U3: ปังเนยนิ่มถุง5ชิ้น | V3: ปังสตรอบูล | W3: ปังไก่หยอง | X3: ปังทวิต | Y3: ปังแถว | Z3: เปี๊ยะลาวา | AA3: คอนเฟล็ก | AB3: ไดฟูกุ | AC3: ปังเลเยอร์ | AD3: เมอแรงค์ | AE3: ท๊อฟฟี่ถั่ว กล่อง | AF3: ครีมฮอนร์จัมโบ้ | AG3: ครีมฮอร์น
A4: 243800 | B4: 1 | I4: 25 | AG4: 18 | AH4: =SUM(B4:AG4) -> 44
A5: 243801 | AH5: =SUM(B5:AG5) -> 0
A6: 243802 | AH6: =SUM(B6:AG6) -> 0
A7: 243803 | B7: 98 | G7: 3 | AG7: 40 | AH7: =SUM(B7:AG7) -> 141
A8: 243804 | AH8: =SUM(B8:AG8) -> 0
A9: 243805 | AH9: =SUM(B9:AG9) -> 0
A10: 243806 | AH10: =SUM(B10:AG10) -> 0
A11: 243807 | AH11: =SUM(B11:AG11) -> 0
A12: 243808 | B12: 70 | C12: 2 | E12: 2 | G12: 13 | I12: 10 | N12: 1 | Q12: 3 | AG12: 21 | AH12: =SUM(B12:AG12) -> 122
A13: 243809 | AH13: =SUM(B13:AG13) -> 0
A14: 243810 | D14: 3 | F14: 12 | G14: 2 | AG14: 17 | AH14: =SUM(B14:AG14) -> 34
A15: 243811 | AH15: =SUM(B15:AG15) -> 0
A16: 243812 | AH16: =SUM(B16:AG16) -> 0
A17: 243813 | C17: 1 | D17: 12 | F17: 27 | G17: 3 | AG17: 27 | AH17: =SUM(B17:AG17) -> 70
A18: 243814 | D18: 3 | G18: 9 | AE18: 3 | AG18: 12 | AH18: =SUM(B18:AG18) -> 27
A19: 243815 | AH19: =SUM(B19:AG19) -> 0
A20: 243816 | AH20: =SUM(B20:AG20) -> 0
A21: 243817 | D21: 6 | F21: 15 | AA21: 1 | AG21: 3 | AH21: =SUM(B21:AG21) -> 25
A22: 243818 | D22: 19 | F22: 15 | G22: 6 | Q22: 3 | AE22: 1 | AG22: 3 | AH22: =SUM(B22:AG22) -> 47
A23: 243819 | AH23: =SUM(B23:AG23) -> 0
A24: 243820 | B24: 27 | C24: 7 | D24: 39 | F24: 81 | G24: 23 | Y24: 5 | AD24: 1 | AE24: 1 | AG24: 23 | AH24: =SUM(B24:AG24) -> 207
A25: 243821 | G25: 8 | Y25: 2 | AG25: 3 | AH25: =SUM(B25:AG25) -> 13
A26: 243822 | B26: 50 | D26: 14 | F26: 16 | G26: 9 | Y26: 6 | AH26: =SUM(B26:AG26) -> 95
A27: 243823 | D27: 4 | F27: 2 | G27: 12 | AH27: =SUM(B27:AG27) -> 18
A28: 243824 | AH28: =SUM(B28:AG28) -> 0
A29: 243825 | D29: 3 | F29: 3 | G29: 6 | AH29: =SUM(B29:AG29) -> 12
A30: 243826 | AH30: =SUM(B30:AG30) -> 0
A31: 243827 | C31: 3 | D31: 25 | F31: 45 | G31: 5 | Y31: 8 | AG31: 10 | AH31: =SUM(B31:AG31) -> 96
A32: 243828 | Y32: 6 | AE32: 3 | AH32: =SUM(B32:AG32) -> 9
A33: 243829 | D33: 6 | F33: 6 | G33: 24 | AH33: =SUM(B33:AG33) -> 36
A34: 243830 | AH34: =SUM(B34:AG34) -> 0
A35: ยอดรวมทั้งเดือน | B35: =SUM(B4:B34) -> 246 | C35: =SUM(C4:C34) -> 13 | D35: =SUM(D4:D34) -> 134 | E35: =SUM(E4:E34) -> 2 | F35: =SUM(F4:F34) -> 222 | G35: =SUM(G4:G34) -> 123 | H35: =SUM(H4:H34) -> 0 | I35: =SUM(I4:I34) -> 35 | ... AG35: =SUM(AG4:AG34) -> 177 | AH35: =SUM(B35:AG35) -> 996

Sheet ชินิตี้ ก.ค.
A1: เลขที่ออเดอร์ | B1: ชื่อ | C1: ช่องทางติดต่อ | D1: ชื่อตามช่องทางติดต่อ | E1: ขนส่ง | F1: วันที่สร้าง | G1: วันที่โอน | H1: เลขที่ออเดอร์ในแพตฟอร์ม | I1: หมายเลขพัสดุ | J1: ค่าส่งที่เก็บลูกค้า | K1: ค่าส่งที่ร้านจ่าย | L1: ยอดขาย | M1: หมายเหตุ | N1: รายละเอียดการโอนเงิน เกิน / ขาด และอื่น ๆ
A2: DDG93 | B2: ธ******์ | C2: Shopee | D2: goodbyedong | E2: SPX Express | F2: 01/07/2024 00:00 | G2: 01/07/2024 00:00 | H2: 240701DJ16DGSH | I2: TH2442383967173 | J2: 0 | K2: 2 | L2: 15
A3: DDG94 | B3: ฮ******) | C3: Shopee | D3: yusandimon | E3: SPX Express | F3: 01/07/2024 00:20 | G3: 01/07/2024 00:20 | H3: 240701DJEPE08M | I3: TH244476709179O | J3: 7 | K3: 57 | L3: 204
A4: DDG96 | B4: บ******ด | C4: Shopee | D4: wiwatsresaard | E4: SPX Express | F4: 01/07/2024 00:22 | G4: 01/07/2024 00:22 | H4: 240701DK16MNKS | I4: TH240639579250G | J4: 0 | K4: 11 | L4: 73
A5: DDG97 | B5: ส******ณ | C5: Shopee | D5: suphatsara_por | E5: SPX Express | F5: 01/07/2024 00:23 | G5: 01/07/2024 00:23 | H5: 240701DJYP1T84 | I5: TH245426460864G | J5: 7 | K5: 16 | L5: 56
A6: DDG99 | B6: อ******น | C6: Shopee | D6: arreeya123 | E6: SPX Express | F6: 01/07/2024 01:57 | G6: 01/07/2024 02:12 | H6: 240701DRHJFV5C | I6: TH247115673207O | J6: 0 | K6: 28 | L6: 191
A7: DDH0 | B7: น***สภณวิชญ์ ค***พิทักษ์ | C7: Tiktok | D7: 7495211159497967661 | E7: J&T COD | F7: 01/07/2024 02:00 | G7: 01/07/2024 02:00 | H7: 579008287573968941 | I7: 750431218202 | J7: 0 | K7: 0 | L7: 150
A8: DDH1 | B8: นิตยา เนตรรัศมี | C8: Lazada | E8: Kerry_dropoff | F8: 01/07/2024 02:48 | G8: 01/07/2024 02:48 | H8: 883723778319739 | I8: LEXPU0362538135 | J8: 45 | K8: 45 | L8: 119.4
A9: DDH2 | B9: ManatnJ | C9: Lazada | E9: Kerry_dropoff | F9: 01/07/2024 06:21 | G9: 01/07/2024 06:21 | H9: 878163831899494 | I9: LEXPU0362543666 | J9: 15 | K9: 15 | L9: 49.81
A10: DDH3 | B10: อนันต์ เปียมัน | C10: Lazada | E10: Kerry_dropoff | F10: 01/07/2024 06:28 | G10: 01/07/2024 06:29 | H10: 883744771794956 | I10: LEXPU0362589015 | J10: 45 | K10: 45 | L10: 125.07
A11: DDH4 | B11: มะนิท ลุนหนุด | C11: Lazada | E11: Kerry_dropoff | F11: 01/07/2024 06:58 | G11: 01/07/2024 06:58 | H11: 883752332031951 | I11: LEXPU0363027257 | J11: 24 | K11: 24 | L11: 192.64
A12: DDH5 | B12: อ******์ | C12: Shopee | D12: audsanai | E12: SPX Express | F12: 01/07/2024 07:15 | G12: 01/07/2024 07:38 | H12: 240701E9XT9S50 | I12: TH241245971206U | J12: 0 | K12: 18 | L12: 120
A13: DDH6 | B13: เ******ิ | C13: Shopee | D13: chollapuii | E13: SPX Express | F13: 01/07/2024 07:18 | G13: 01/07/2024 07:18 | H13: 240701EA7JNUK5 | I13: TH247025396074R | J13: 64 | K13: 94 | L13: 254
A14: DDH7 | B14: น***า แ***ง้ว | C14: Tiktok | D14: 7494019186864850558 | E14: Flash Express Thailand COD | F14: 01/07/2024 07:23 | G14: 01/07/2024 07:23 | H14: 579008581808982654 | I14: THT01221114EM9Z | J14: 0 | K14: 0 | L14: 200
A15: DDH8 | B15: เ***ร์ | C15: Tiktok | D15: 7494516313698568219 | E15: Flash Express Thailand COD | F15: 01/07/2024 07:30 | G15: 01/07/2024 07:30 | H15: 579008595018418203 | I15: THT10021112US4Z | J15: 0 | K15: 0 | L15: 165
A16: DDH10 | B16: Partypantita Phetkhum | C16: Lazada | E16: Kerry_dropoff | F16: 01/07/2024 07:32 | G16: 01/07/2024 07:32 | H16: 878180407945793 | I16: TH64095UFARS4C | J16: 0 | K16: 0 | L16: 58.97
A17: DDH9 | B17: เพ็ญภิญญา แสนศรีจันทร์ | C17: Facebook Live | D17: กัณฐ์ ประเสริฐสังข์ | E17: EMS | F17: 01/07/2024 07:32 | G17: 01/07/2024 07:45 | H17: - | I17: JB006823835TH | J17: 20 | K17: 0 | L17: 120 | M17: 5/1
A18: DDH11 | B18: เ***ิรา ห***ดง | C18: Tiktok | D18: 7494074694159796180 | E18: J&T Express | F18: 01/07/2024 07:33 | G18: 01/07/2024 07:37 | H18: 579008601925651412 | I18: 750464002455 | J18: 45 | K18: 0 | L18: 165
A19: DDH12 | B19: จ***นา | C19: Tiktok | D19: 7495646551096920872 | E19: J&T COD | F19: 01/07/2024 07:34 | G19: 01/07/2024 07:34 | H19: 579008604340587304 | I19: 750485007451 | J19: 6 | K19: 0 | L19: 91
A20: DDH14 | B20: อ***า เ***ญญา | C20: Tiktok | D20: 7494499495524469111 | E20: Flash Express Thailand COD | F20: 01/07/2024 07:39 | G20: 01/07/2024 07:39 | H20: 579008611056847223 | I20: THT01231119PK4Z | J20: 6 | K20: 0 | L20: 106
A21: DDH15 | B21: บ***ตี พ***์บำรุง | C21: Tiktok | D21: 7494510519848766248 | E21: J&T COD | F21: 01/07/2024 07:43 | G21: 01/07/2024 07:43 | H21: 579008620519066408 | I21: 750428795373 | J21: 6 | K21: 0 | L21: 126
A22: DDH16 | B22: น***าวอริสรา ม***ุนทด | C22: Tiktok | D22: 7494014159356920850 | E22: J&T Express | F22: 01/07/2024 07:46 | G22: 01/07/2024 07:47 | H22: 579008627206424594 | I22: 750445200433 | J22: 6 | K22: 0 | L22: 86
A23: DDH17 | B23: ว** ช***งคราม | C23: Tiktok | D23: 7494474925090048876 | E23: J&T Express | F23: 01/07/2024 07:48 | G23: 01/07/2024 07:49 | H23: 579008631262317420 | I23: 750469509436 | J23: 6 | K23: 0 | L23: 91
A24: DDH18 | B24: น***น้ำเหนือ | C24: Tiktok | D24: 7495052877751093812 | E24: J&T COD | F24: 01/07/2024 07:53 | G24: 01/07/2024 07:52 | H24: 579008638455417396 | I24: 750422493380 | J24: 6 | K24: 0 | L24: 136
A25: DDH19 | B25: เ***ิรา ท***ิ่ง | C25: Tiktok | D25: 7494022295421617978 | E25: J&T COD | F25: 01/07/2024 07:56 | G25: 01/07/2024 07:56 | H25: 579008645340236602 | I25: 750434490374 | J25: 0 | K25: 0 | L25: 180
A26: DDH21 | B26: คุณแม่สุดา ยิ้มแย้ม | C26: Lazada | E26: Kerry_dropoff | F26: 01/07/2024 08:00 | G26: 01/07/2024 08:00 | H26: 878181635171631 | I26: TH29095UEV5F6J | J26: 19 | K26: 19 | L26: 284.37
A27: DDH23 | B27: ส***ดา ม***คง | C27: Tiktok | D27: 7494006681405588955 | E27: J&T COD | F27: 01/07/2024 08:08 | G27: 01/07/2024 08:07 | H27: 579008669350857179 | I27: 750480906442 | J27: 6 | K27: 0 | L27: 86
A28: DDH26 | B28: ห** ศ***อง | C28: Tiktok | D28: 7495599665721280843 | E28: J&T COD | F28: 01/07/2024 08:10 | G28: 01/07/2024 08:10 | H28: 579008675681438027 | I28: 750429898374 | J28: 45 | K28: 0 | L28: 165
A29: DDH25 | B29: น***ตน์ เ***รวรชัย | C29: Tiktok | D29: 7494193383423249006 | E29: Flash Express Thailand COD | F29: 01/07/2024 08:10 | G29: 01/07/2024 08:10 | H29: 579008675012250222 | I29: THT02011114TB1Z | J29: 6 | K29: 0 | L29: 126
A30: DDH28 | B30: อ***สา | C30: Tiktok | D30: 7494310111777491867 | E30: J&T Express | F30: 01/07/2024 08:16 | G30: 01/07/2024 08:16 | H30: 579008690872290203 | I30: 750433591375 | J30: 0 | K30: 0 | L30: 180
A31: DDH29 | B31: พ***ษฐ์ | C31: Tiktok | D31: 7494012138756802508 | E31: Flash Express Thailand | F31: 01/07/2024 08:17 | G31: 01/07/2024 08:17 | H31: 579008688687844300 | I31: THT011611183R4Z | J31: 6 | K31: 0 | L31: 91
A32: DDH31 | B32: ค***ิรัช เ***ภักดีกูล | C32: Tiktok | D32: 7495135616375818719 | E32: J&T Express | F32: 01/07/2024 08:21 | G32: 01/07/2024 08:21 | H32: 579008697167677919 | I32: 750449301431 | J32: 6 | K32: 0 | L32: 86
A33: DDH30 | B33: ฉ***รรณ น***าลี | C33: Tiktok | D33: 7494585099614194182 | E33: Flash Express Thailand | F33: 01/07/2024 08:21 | G33: 01/07/2024 08:21 | H33: 579008700393753094 | I33: THT63051117XQ6Z | J33: 0 | K33: 0 | L33: 170
A34: DDH33 | B34: วัลลภาชูหน้า | C34: Facebook Live | D34: วัลลภา ชูหน้า | E34: EMS | F34: 01/07/2024 08:29 | G34: 01/07/2024 08:29 | H34: - | I34: JB006823844TH | J34: 20 | K34: 0 | L34: 120 | M34: 6/1
A35: DDH35 | B35: น***า ช***นะ | C35: Tiktok | D35: 7494741205067205573 | E35: J&T COD | F35: 01/07/2024 08:31 | G35: 01/07/2024 08:31 | H35: 579008720652962757 | I35: 750427802434 | J35: 6 | K35: 0 | L35: 141
A36: DDH38 | B36: สมพิศ นิมิตศรีสุวรรณ | C36: Lazada | E36: Kerry_dropoff | F36: 01/07/2024 08:40 | G36: 01/07/2024 08:40 | H36: 878194822561615 | I36: LEXPU0363049298 | J36: 19 | K36: 19 | L36: 195.74
A37: DDH39 | B37: พรพรรณ ชมภูพื้น | C37: Lazada | E37: Kerry_dropoff | F37: 01/07/2024 08:43 | G37: 01/07/2024 08:46 | H37: 878187088297615 | I37: LEXDO0105791104 | J37: 5 | K37: 5 | L37: 265.6
A38: DDH40 | B38: น***ตร พ***นอก | C38: Tiktok | D38: 7494026209704510831 | E38: J&T COD | F38: 01/07/2024 08:44 | G38: 01/07/2024 08:44 | H38: 579008750781761903 | I38: 750457400442 | J38: 6 | K38: 0 | L38: 86
A39: DDH42 | B39: พ***า บ***งคชาธาร | C39: Tiktok | D39: 7494038290505107276 | E39: Flash Express Thailand COD | F39: 01/07/2024 08:49 | G39: 01/07/2024 08:49 | H39: 579008767433542476 | I39: THT13041114DK6Z | J39: 0 | K39: 0 | L39: 160
A40: DDH44 | B40: น******ง | C40: Shopee | D40: kanyarat___yok | E40: SPX Express | F40: 01/07/2024 08:55 | G40: 01/07/2024 08:55 | H40: 240701EFVXRQGE | I40: TH243127443497P | J40: 7 | K40: 19 | L40: 80
...
